<mujoco model="humanoid">
  <compiler angle="radian" assetdir="assets" balanceinertia="true" inertiafromgeom="false"/>

  <option timestep="0.005" density="1.2" viscosity="2e-05"/>

  <size nkey="1"/>

  <visual>
    <quality shadowsize="8192"/>
    <map shadowclip="0.5"/>
  </visual>

  <default>
    <default class="/">
      <joint armature="0.01" damping="0.01" frictionloss="0.1"/>
      <geom contype="0" conaffinity="0" group="1" solref="-1000 -80"/>
      <site size="0.01 0.005 0.005" group="5"/>
      <general forcelimited="true" biastype="affine" gainprm="30" biasprm="0 -30 -0.5"/>
      <default class="foot">
        <geom size="0.099 0.0178 0.021" type="box" condim="6" group="4" priority="1" solimp="0.015 1 0.021"/>
      </default>
      <default class="reward_collision_sphere">
        <geom group="5" rgba="1 0 0 1"/>
      </default>
    </default>
  </default>

  <asset>
    <texture type="skybox" colorspace="auto" name="//unnamed_texture_0" builtin="gradient" rgb1="0.95 0.95 0.95" rgb2="0.95 0.95 0.95" width="100" height="600"/>
    <texture type="2d" colorspace="auto" name="texplane" builtin="checker" rgb1="0.345 0.575 0.748" rgb2="0.345 0.575 0.748" markrgb="1 1 1" width="512" height="512"/>
    <material name="MatPlane" class="/" texture="texplane" texuniform="true" texrepeat="2 2" specular="0.9"/>
    <mesh name="torso" class="/" file="torso.stl" scale="0.001 0.001 0.001"/>
    <mesh name="left_hip_yaw" class="/" file="left_hip_yaw.stl" scale="0.001 0.001 0.001"/>
    <mesh name="left_hip_abad" class="/" file="left_hip_abad.stl" scale="0.001 0.001 0.001"/>
    <mesh name="left_leg_upper" class="/" file="left_leg_upper.stl" scale="0.001 0.001 0.001"/>
    <mesh name="left_leg_lower" class="/" file="left_leg_lower.stl" scale="0.001 0.001 0.001"/>
    <mesh name="left_foot" class="/" file="left_foot.stl" scale="0.001 0.001 0.001"/>
    <mesh name="left_hip_yaw1" class="/" content_type="model/stl" file="left_hip_yaw.stl" scale="0.001 -0.001 0.001"/>
    <mesh name="left_hip_abad1" class="/" content_type="model/stl" file="left_hip_abad.stl" scale="0.001 -0.001 0.001"/>
    <mesh name="left_leg_upper1" class="/" content_type="model/stl" file="left_leg_upper.stl" scale="0.001 -0.001 0.001"/>
    <mesh name="left_leg_lower1" class="/" content_type="model/stl" file="left_leg_lower.stl" scale="0.001 -0.001 0.001"/>
    <mesh name="left_foot1" class="/" content_type="model/stl" file="left_foot.stl" scale="0.001 -0.001 0.001"/>
    <mesh name="left_shoulder1" class="/" file="left_shoulder1.stl" scale="0.001 0.001 0.001"/>
    <mesh name="left_shoulder2" class="/" file="left_shoulder2.stl" scale="0.001 0.001 0.001"/>
    <mesh name="left_shoulder3" class="/" file="left_shoulder3.stl" scale="0.001 0.001 0.001"/>
    <mesh name="left_forearm" class="/" file="left_forearm.stl" scale="0.001 0.001 0.001"/>
    <mesh name="left_shoulder11" class="/" content_type="model/stl" file="left_shoulder1.stl" scale="0.001 -0.001 0.001"/>
    <mesh name="left_shoulder21" class="/" content_type="model/stl" file="left_shoulder2.stl" scale="0.001 -0.001 0.001"/>
    <mesh name="left_shoulder31" class="/" content_type="model/stl" file="left_shoulder3.stl" scale="0.001 -0.001 0.001"/>
  </asset>

  <worldbody>
    <geom name="floor" class="/" size="100 100 0.125" type="plane" group="0" material="MatPlane"/>
    <light name="toplight_shadow" class="/" pos="0 0 5" dir="0.0990148 0.0990148 -0.990148" type="directional" ambient="0.04 0.04 0.04" diffuse="0.55 0.55 0.55" specular="0.12 0.12 0.12"/>
    <light name="toplight_fill" class="/" pos="0 0 5" dir="0.0990148 0.0990148 -0.990148" type="directional" castshadow="false" ambient="0.04 0.04 0.04" diffuse="0.3 0.3 0.3" specular="0.08 0.08 0.08"/>
    <body name="trunk" pos="0.00158916 -0.000541706 -0.00229249" quat="1 -3.66136e-05 -1.22651e-05 4.13543e-05">
      <inertial pos="0.0134033 0.000372899 0.0899977" quat="0.999922 -0.00256646 0.0119663 0.00242355" mass="6.18944" diaginertia="0.492262 0.0963521 0.00677039"/>
      <joint name="//unnamed_joint_0" type="free"/>
      <geom name="//unnamed_geom_1" class="/" type="mesh" density="0" rgba="0.752941 0.752941 0.752941 1" mesh="torso"/>
      <geom name="//unnamed_geom_2" class="/" size="0.0712539 0.142508 0.166259" pos="0.028715 0 0.0478874" type="box" group="3" rgba="0.752941 0.752941 0.752941 1"/>
      <geom name="//unnamed_geom_3" class="reward_collision_sphere" size="0.137758" pos="0 0 0.0897889"/>
      <site name="imu" class="/" pos="0.00438389 0.0119061 0.118096" size="0.00950053"/>
      <camera name="track" class="/" pos="0 -2.00617 0" quat="0.707107 0.707107 0 0" mode="trackcom"/>
      <camera name="ego_camera" class="/" pos="0.0561816 0 0.179578" quat="-0.5 -0.5 0.5 0.5"/>
      <body name="left_hip_yaw" pos="0.00596361 0.0858918 0.00731806" quat="0.996191 0.000135932 -0.0871973 8.9567e-05">
        <inertial pos="-0.0806716 -0.00118865 -0.0348615" quat="0.948058 -0.0207077 -0.317419 -0.00128957" mass="0.701329" diaginertia="0.0057423 0.00140644 6.05453e-05"/>
        <joint name="left_hip_yaw" class="/" pos="0 0 0" axis="0.00156296 -0.0025914 -0.999995" stiffness="0.00698384" range="-2.98138 3.00232" armature="0.00686956" damping="0.00932722" frictionloss="0.0876414"/>
        <geom name="//unnamed_geom_4" class="/" type="mesh" density="0" rgba="0.2 0.2 0.2 1" mesh="left_hip_yaw"/>
        <body name="left_hip_abad" pos="-0.0773203 0.000944737 -0.0484795" quat="0.976239 7.4646e-05 0.216697 0.000366322">
          <inertial pos="0.0862905 -0.012671 -0.000655729" quat="0.58063 0.405253 0.405905 0.577823" mass="1.05347" diaginertia="0.0103284 0.00200505 0.000136481"/>
          <joint name="left_hip_abad" class="/" pos="0 0 0" axis="-0.999997 -0.00124206 -0.00230602" range="-3.09967 2.99683" armature="0.0105706" damping="0.0140965" frictionloss="0.0936465"/>
          <geom name="//unnamed_geom_5" class="/" type="mesh" density="0" rgba="0.2 0.2 0.2 1" mesh="left_hip_abad"/>
          <body name="left_upper_leg" pos="0.108849 -0.00500882 -0.0106059" quat="0.991531 0.000579147 -0.129865 0.000964866">
            <inertial pos="0.0021338 0.0216261 -0.0494955" quat="0.727013 0.0339716 -0.052104 0.6838" mass="2.27006" diaginertia="0.0783682 0.0253089 0.000271505"/>
            <joint name="left_hip_pitch" class="/" pos="0 0 0" axis="-0.00540729 0.999945 0.00895118" stiffness="0.0165446" range="-2.96647 2.97619" armature="0.0121339" damping="0.00675442" frictionloss="0.0957538"/>
            <geom name="//unnamed_geom_6" class="/" type="mesh" density="0" rgba="0.752941 0.752941 0.752941 1" mesh="left_leg_upper"/>
            <geom name="//unnamed_geom_7" class="reward_collision_sphere" size="0.0665037" pos="-0.0187272 0.0150463 0.00897889"/>
            <geom name="//unnamed_geom_8" class="reward_collision_sphere" size="0.0190011" pos="-0.0998783 -0.0300926 0.0478874"/>
            <body name="left_lower_leg" pos="-0.0131512 0.00287675 -0.145178" quat="1 6.18983e-05 0.000254247 0.000121527">
              <inertial pos="0.0043223 -0.00441317 -0.0809937" quat="0.999418 -0.00654228 -0.0126228 0.0310066" mass="0.309139" diaginertia="0.00829506 0.0029828 1.74097e-05"/>
              <joint name="left_knee" class="/" pos="0 0 0" axis="0.00503685 0.999981 -0.00348005" stiffness="0.0118778" range="0.00125844 3.02791" armature="0.0106104" damping="0.00777832" frictionloss="0.106924"/>
              <geom name="//unnamed_geom_9" class="/" type="mesh" density="0" rgba="0.752941 0.752941 0.752941 1" mesh="left_leg_lower"/>
              <geom name="//unnamed_geom_10" class="reward_collision_sphere" size="0.0408523"/>
              <body name="left_foot" pos="-0.0017746 0.000745745 -0.165823" quat="1 -0.000175578 0.000253099 -0.000241401">
                <inertial pos="0.0227121 -0.00179664 -0.00778546" quat="0.515641 0.481913 0.481542 0.519608" mass="0.255703" diaginertia="0.0814876 0.0270844 0.00211764"/>
                <joint name="left_ankle" class="/" pos="0 0 0" axis="-0.00570449 0.99998 -0.00289477" range="-1.48104 1.39036" armature="0.00948491" damping="0" frictionloss="0.106545"/>
                <geom name="//unnamed_geom_11" class="/" type="mesh" density="0" rgba="0.2 0.2 0.2 1" mesh="left_foot"/>
                <geom name="left_foot" class="foot" size="0.0968046 0.0172017 0.0217789" pos="0.0349574 0 -0.0149648" quat="0.707109 0.707105 0 0"/>
                <geom name="//unnamed_geom_13" class="reward_collision_sphere" size="0.0237513" pos="0.0349574 0 -0.0119719"/>
                <geom name="//unnamed_geom_14" class="reward_collision_sphere" size="0.0237513" pos="0.124848 0 -0.0149648"/>
                <geom name="//unnamed_geom_15" class="reward_collision_sphere" size="0.0237513" pos="-0.0561816 0 -0.0149648"/>
                <site name="left_foot" class="foot" pos="0.0349574 0 -0.0149648" quat="0.707109 0.707105 0 0" size="0.00950053"/>
              </body>
            </body>
          </body>
        </body>
      </body>
      <body name="right_hip_yaw" pos="-0.000117326 -0.0858 0.00780817" quat="0.996217 0.000232841 -0.0868944 -0.000134578">
        <inertial pos="-0.0784753 -0.00349225 -0.0377276" quat="0.950034 -0.00550241 0.31205 -0.00540321" mass="0.730964" diaginertia="0.00569991 0.00144128 6.30491e-05"/>
        <joint name="right_hip_yaw" class="/" pos="0 0 0" axis="0.00277091 0.00423431 -0.999987" stiffness="0.00422876" range="-3.04849 2.95071" armature="0.00943901" damping="0.0212267" frictionloss="0.102681"/>
        <geom name="//unnamed_geom_16" class="/" type="mesh" density="0" rgba="0.2 0.2 0.2 1" mesh="left_hip_yaw1"/>
        <body name="right_hip_abad" pos="-0.0805922 -0.0062462 -0.0436573" quat="0.976296 9.27661e-08 0.216441 1.02807e-05">
          <inertial pos="0.0808504 0.0154685 0.00183606" quat="0.410662 0.574334 0.578768 0.408074" mass="0.998134" diaginertia="0.00974307 0.00201485 0.000135306"/>
          <joint name="right_hip_abad" class="/" pos="0 0 0" axis="-0.999997 -0.00140268 -0.00206433" range="-3.0351 2.98288" armature="0.00960358" damping="0.00505523" frictionloss="0.0984117"/>
          <geom name="//unnamed_geom_17" class="/" type="mesh" density="0" rgba="0.2 0.2 0.2 1" mesh="left_hip_abad1"/>
          <body name="right_upper_leg" pos="0.115331 0.000331936 -0.0130098" quat="0.991083 -0.000526192 -0.133248 -0.000182588">
            <inertial pos="0.00324374 -0.0256519 -0.0451118" quat="0.687008 0.0716942 -0.0331435 0.722345" mass="2.03075" diaginertia="0.0720271 0.0233265 0.000260306"/>
            <joint name="right_hip_pitch" class="/" pos="0 0 0" axis="0.00258857 -0.999997 -0.000459429" range="-3.06262 3.03721" armature="0.0114722" damping="0" frictionloss="0.0931726"/>
            <geom name="//unnamed_geom_18" class="/" type="mesh" density="0" rgba="0.752941 0.752941 0.752941 1" mesh="left_leg_upper1"/>
            <geom name="//unnamed_geom_19" class="reward_collision_sphere" size="0.0665037" pos="-0.0187272 -0.0150463 0.00897889"/>
            <geom name="//unnamed_geom_20" class="reward_collision_sphere" size="0.0190011" pos="-0.0998783 0.0300926 0.0478874"/>
            <body name="right_lower_leg" pos="-0.015777 -0.00206211 -0.153912" quat="1 -2.33874e-05 -3.95136e-05 0.000262661">
              <inertial pos="0.00868529 0.00120571 -0.0773416" quat="0.998927 0.00165343 0.0209331 -0.041283" mass="0.302253" diaginertia="0.00922502 0.00294181 1.79593e-05"/>
              <joint name="right_knee" class="/" pos="0 0 0" axis="-0.00317175 -0.999957 0.00872641" range="-2.99483 0.00692806" armature="0.00828399" damping="0.0359099" frictionloss="0.10349"/>
              <geom name="//unnamed_geom_21" class="/" type="mesh" density="0" rgba="0.752941 0.752941 0.752941 1" mesh="left_leg_lower1"/>
              <geom name="//unnamed_geom_22" class="reward_collision_sphere" size="0.0408523"/>
              <body name="right_foot" pos="-0.00140681 -0.0021652 -0.160486" quat="0.999997 -0.000669219 0.00108012 0.0018797">
                <inertial pos="0.0266034 0.00250055 -0.00775727" quat="0.483659 0.510049 0.518233 0.487195" mass="0.222772" diaginertia="0.0801129 0.0255336 0.00205391"/>
                <joint name="right_ankle" class="/" pos="0 0 0" axis="0.000243632 -1 -0.000603371" stiffness="0.00326428" range="-1.38821 1.56332" armature="0.0119282" damping="0.0148166" frictionloss="0.0874193"/>
                <geom name="//unnamed_geom_23" class="/" type="mesh" density="0" rgba="0.2 0.2 0.2 1" mesh="left_foot1"/>
                <geom name="right_foot" class="foot" size="0.104908 0.0146481 0.0177878" pos="0.0349574 0 -0.0149648" quat="0.707109 0.707105 0 0"/>
                <geom name="//unnamed_geom_25" class="reward_collision_sphere" size="0.0237513" pos="0.0349574 0 -0.0119719"/>
                <geom name="//unnamed_geom_26" class="reward_collision_sphere" size="0.0237513" pos="0.124848 0 -0.0149648"/>
                <geom name="//unnamed_geom_27" class="reward_collision_sphere" size="0.0237513" pos="-0.0561816 0 -0.0149648"/>
                <site name="right_foot" class="foot" pos="0.0349574 0 -0.0149648" quat="0.707109 0.707105 0 0" size="0.00950053"/>
              </body>
            </body>
          </body>
        </body>
      </body>
      <body name="left_shoulder" pos="0.0196679 0.177329 0.180007" quat="1 0.000681651 -7.20769e-05 8.06231e-05">
        <inertial pos="0.00926102 0.0529592 -0.001502" quat="0.718155 0.695521 0.0190271 0.0118636" mass="0.636709" diaginertia="0.00403622 0.000845778 5.58863e-05"/>
        <joint name="left_shoulder_pitch" class="/" pos="0 0 0" axis="0.0164616 0.999402 -0.030399" range="-3.01115 3.00895" armature="0.00976156" damping="0.0116137" frictionloss="0.0835063"/>
        <geom name="//unnamed_geom_28" class="/" type="mesh" density="0" rgba="0.2 0.2 0.2 1" mesh="left_shoulder1"/>
        <body name="left_shoulder_2" pos="-0.000574882 0.0597339 -0.00391625" quat="1 -2.38883e-05 5.87988e-05 4.25034e-05">
          <inertial pos="0.00255722 0.000795728 -0.0500729" quat="0.0129504 0.75805 0.00465448 0.652051" mass="0.686245" diaginertia="0.00405001 0.00125601 8.74344e-05"/>
          <joint name="left_shoulder_abad" class="/" pos="0 0 0" axis="-0.999938 0.00845162 -0.00730094" range="-3.05059 2.97936" armature="0.011876" damping="0.000684813" frictionloss="0.0985199"/>
          <geom name="//unnamed_geom_29" class="/" type="mesh" density="0" rgba="0.752941 0.752941 0.752941 1" mesh="left_shoulder2"/>
          <body name="left_upper_arm" pos="-0.00162144 -0.00271934 -0.0613509" quat="1 0.000274355 5.01303e-05 -0.000194818">
            <inertial pos="-0.00133548 -0.0121686 -0.0368741" quat="0.709242 -0.0222813 0.0285265 0.704035" mass="0.811109" diaginertia="0.005423 0.00138565 6.1358e-05"/>
            <joint name="left_shoulder_yaw" class="/" pos="0 0 0" axis="0.00305205 -0.000492903 0.999995" stiffness="0.00541593" range="-2.95154 2.9505" armature="0.00961567" damping="0" frictionloss="0.0980097"/>
            <geom name="//unnamed_geom_30" class="/" type="mesh" density="0" rgba="0.752941 0.752941 0.752941 1" mesh="left_shoulder3"/>
            <geom name="//unnamed_geom_31" class="reward_collision_sphere" size="0.0570032" pos="-0.0124848 -0.0100309 -0.0299296"/>
            <body name="left_lower_arm" pos="0.00125204 0.00025597 -0.0915302" quat="1 3.29797e-05 -0.000420689 0.000136862">
              <inertial pos="-0.00838337 1.09762e-05 -0.059276" quat="0.70699 0.00443721 0.0051385 0.707191" mass="0.298728" diaginertia="0.0108861 0.00362804 5.78247e-06"/>
              <joint name="left_elbow" class="/" pos="0 0 0" axis="-0.00783671 0.99996 -0.0042531" stiffness="0.00702058" range="-2.95507 3.04319" armature="0.00869819" damping="0.00416562" frictionloss="0.0898823"/>
              <geom name="//unnamed_geom_32" class="/" type="mesh" density="0" rgba="0.752941 0.752941 0.752941 1" mesh="left_forearm"/>
              <geom name="//unnamed_geom_33" class="/" size="0.0237513 0.00712539" pos="0 0 -0.16162" quat="0.707109 0.707105 0 0" type="cylinder" group="3"/>
              <geom name="//unnamed_geom_34" class="reward_collision_sphere" size="0.0237513"/>
              <geom name="//unnamed_geom_35" class="reward_collision_sphere" size="0.0209012" pos="0 0 -0.167606"/>
            </body>
          </body>
        </body>
      </body>
      <body name="right_shoulder" pos="0.0215076 -0.173075 0.179739" quat="1 0.000146948 -0.000736672 0.00046203">
        <inertial pos="0.0106986 -0.0533953 0.00241427" quat="0.716904 0.696886 -0.0118656 -0.0160771" mass="0.714056" diaginertia="0.00413471 0.000945653 5.87697e-05"/>
        <joint name="right_shoulder_pitch" class="/" pos="0 0 0" axis="0.0132693 -0.999901 0.00459145" range="-2.96544 2.99322" armature="0.0103894" damping="0.0076844" frictionloss="0.0960878"/>
        <geom name="//unnamed_geom_36" class="/" type="mesh" density="0" rgba="0.2 0.2 0.2 1" mesh="left_shoulder11"/>
        <body name="right_shoulder_2" pos="-0.00360394 -0.0605713 0.00109988" quat="0.999999 0.000580376 -3.96083e-06 0.00125064">
          <inertial pos="-0.00431973 -0.000594343 -0.0495687" quat="0.00487349 0.65255 0.0411019 0.756614" mass="0.710575" diaginertia="0.00362926 0.00123054 9.1424e-05"/>
          <joint name="right_shoulder_abad" class="/" pos="0 0 0" axis="-0.999997 -0.00202906 -0.00163464" stiffness="0.000534362" range="-2.98799 3.00729" armature="0.00885367" damping="0.0155505" frictionloss="0.105209"/>
          <geom name="//unnamed_geom_37" class="/" type="mesh" density="0" rgba="0.752941 0.752941 0.752941 1" mesh="left_shoulder21"/>
          <body name="right_upper_arm" pos="-0.00171834 0.0001348 -0.061462" quat="0.999999 0.00166284 0.000294562 -0.000206563">
            <inertial pos="-3.34392e-05 0.0112105 -0.0362153" quat="0.708022 -0.0274094 0.0125221 0.705547" mass="0.745299" diaginertia="0.004808 0.00130775 6.09197e-05"/>
            <joint name="right_shoulder_yaw" class="/" pos="0 0 0" axis="-0.0253221 -0.0045538 0.999669" stiffness="0.00340196" range="-2.95742 2.93515" armature="0.0104661" damping="0.0343949" frictionloss="0.106983"/>
            <geom name="//unnamed_geom_38" class="/" type="mesh" density="0" rgba="0.752941 0.752941 0.752941 1" mesh="left_shoulder31"/>
            <geom name="//unnamed_geom_39" class="reward_collision_sphere" size="0.0570032" pos="-0.0124848 0.0100309 -0.0299296"/>
            <body name="right_lower_arm" pos="-0.00242358 0.00303463 -0.0968176" quat="1 2.14651e-06 3.30217e-05 -3.86742e-05">
              <inertial pos="-0.0118752 -0.00156718 -0.0576893" quat="0.706942 0.0026318 0.00404186 0.707255" mass="0.297183" diaginertia="0.011447 0.00355569 6.20083e-06"/>
              <joint name="right_elbow" class="/" pos="0 0 0" axis="0.0025123 -0.999997 -0.000144166" range="-3.10453 3.01207" armature="0.00940284" damping="0" frictionloss="0.0962023"/>
              <geom name="//unnamed_geom_40" class="/" type="mesh" density="0" rgba="0.752941 0.752941 0.752941 1" mesh="left_forearm"/>
              <geom name="//unnamed_geom_41" class="/" size="0.0237513 0.00712539" pos="0 0 -0.16162" quat="0.707109 0.707105 0 0" type="cylinder" group="3"/>
              <geom name="//unnamed_geom_42" class="reward_collision_sphere" size="0.0237513"/>
              <geom name="//unnamed_geom_43" class="reward_collision_sphere" size="0.0209012" pos="0 0 -0.167606"/>
            </body>
          </body>
        </body>
      </body>
    </body>
  </worldbody>

  <contact>
    <pair class="/" geom1="floor" geom2="left_foot" name="//unnamed_contact_0"/>
    <pair class="/" geom1="floor" geom2="right_foot" name="//unnamed_contact_1"/>
  </contact>

  <actuator>
    <general name="left_hip_yaw" class="/" joint="left_hip_yaw" forcerange="-31.3511 31.3511" gainprm="30.8563" biasprm="0 -30.8563 -0.479746"/>
    <general name="left_hip_abad" class="/" joint="left_hip_abad" forcerange="-38.5857 38.5857" gainprm="30.8563" biasprm="0 -30.8563 -0.479746"/>
    <general name="left_hip_pitch" class="/" joint="left_hip_pitch" forcerange="-80.8354 80.8354" gainprm="30.8563" biasprm="0 -30.8563 -0.479746"/>
    <general name="left_knee" class="/" joint="left_knee" forcerange="-131.66 131.66" gainprm="30.8563" biasprm="0 -30.8563 -0.479746"/>
    <general name="left_ankle" class="/" joint="left_ankle" forcerange="-59.52 59.52" gainprm="30.8563" biasprm="0 -30.8563 -0.479746"/>
    <general name="right_hip_yaw" class="/" joint="right_hip_yaw" forcerange="-35.6395 35.6395" gainprm="30.8563" biasprm="0 -30.8563 -0.479746"/>
    <general name="right_hip_abad" class="/" joint="right_hip_abad" forcerange="-32.0427 32.0427" gainprm="30.8563" biasprm="0 -30.8563 -0.479746"/>
    <general name="right_hip_pitch" class="/" joint="right_hip_pitch" forcerange="-70.879 70.879" gainprm="30.8563" biasprm="0 -30.8563 -0.479746"/>
    <general name="right_knee" class="/" joint="right_knee" forcerange="-122.674 122.674" gainprm="30.8563" biasprm="0 -30.8563 -0.479746"/>
    <general name="right_ankle" class="/" joint="right_ankle" forcerange="-70.5405 70.5405" gainprm="30.8563" biasprm="0 -30.8563 -0.479746"/>
    <general name="left_shoulder_pitch" class="/" joint="left_shoulder_pitch" forcerange="-30.2868 30.2868" gainprm="30.8563" biasprm="0 -30.8563 -0.479746"/>
    <general name="left_shoulder_abad" class="/" joint="left_shoulder_abad" forcerange="-33.215 33.215" gainprm="30.8563" biasprm="0 -30.8563 -0.479746"/>
    <general name="left_shoulder_yaw" class="/" joint="left_shoulder_yaw" forcerange="-29.2721 29.2721" gainprm="30.8563" biasprm="0 -30.8563 -0.479746"/>
    <general name="left_elbow" class="/" joint="left_elbow" forcerange="-53.1459 53.1459" gainprm="30.8563" biasprm="0 -30.8563 -0.479746"/>
    <general name="right_shoulder_pitch" class="/" joint="right_shoulder_pitch" forcerange="-28.4026 28.4026" gainprm="30.8563" biasprm="0 -30.8563 -0.479746"/>
    <general name="right_shoulder_abad" class="/" joint="right_shoulder_abad" forcerange="-32.6597 32.6597" gainprm="30.8563" biasprm="0 -30.8563 -0.479746"/>
    <general name="right_shoulder_yaw" class="/" joint="right_shoulder_yaw" forcerange="-31.3213 31.3213" gainprm="30.8563" biasprm="0 -30.8563 -0.479746"/>
    <general name="right_elbow" class="/" joint="right_elbow" forcerange="-50.8871 50.8871" gainprm="30.8563" biasprm="0 -30.8563 -0.479746"/>
  </actuator>

  <sensor>
    <gyro site="imu" name="imu_angular_velocity"/>
    <velocimeter site="imu" name="imu_linear_velocity"/>
    <framelinvel objtype="site" objname="left_foot" name="left_foot_global_linear_velocity"/>
    <framelinvel objtype="site" objname="right_foot" name="right_foot_global_linear_velocity"/>
  </sensor>

  <keyframe>
    <key name="home" qpos="0 0 0.656 1 0 0 0 0 0 -0.4 0.8 -0.4 0 0 0.4 -0.8 0.4 0 -0.05 0 -0.75 0 0.05 0 0.75"/>
  </keyframe>
</mujoco>
