<mujoco model="humanoid">
  <compiler angle="radian" assetdir="assets" balanceinertia="true" inertiafromgeom="false"/>

  <option timestep="0.005" density="1.2" viscosity="2e-05"/>

  <size nkey="1"/>

  <visual>
    <quality shadowsize="8192"/>
    <map shadowclip="0.5"/>
  </visual>

  <default>
    <default class="/">
      <joint armature="0.01" damping="0.01" frictionloss="0.1"/>
      <geom contype="0" conaffinity="0" group="1" solref="-1000 -80"/>
      <site size="0.01 0.005 0.005" group="5"/>
      <general forcelimited="true" biastype="affine" gainprm="30" biasprm="0 -30 -0.5"/>
      <default class="foot">
        <geom size="0.099 0.0178 0.021" type="box" condim="6" group="4" priority="1" solimp="0.015 1 0.021"/>
      </default>
      <default class="reward_collision_sphere">
        <geom group="5" rgba="1 0 0 1"/>
      </default>
    </default>
  </default>

  <asset>
    <texture type="skybox" colorspace="auto" name="//unnamed_texture_0" builtin="gradient" rgb1="0.95 0.95 0.95" rgb2="0.95 0.95 0.95" width="100" height="600"/>
    <texture type="2d" colorspace="auto" name="texplane" builtin="checker" rgb1="0.345 0.575 0.748" rgb2="0.345 0.575 0.748" markrgb="1 1 1" width="512" height="512"/>
    <material name="MatPlane" class="/" texture="texplane" texuniform="true" texrepeat="2 2" specular="0.9"/>
    <mesh name="torso" class="/" file="torso.stl" scale="0.001 0.001 0.001"/>
    <mesh name="left_hip_yaw" class="/" file="left_hip_yaw.stl" scale="0.001 0.001 0.001"/>
    <mesh name="left_hip_abad" class="/" file="left_hip_abad.stl" scale="0.001 0.001 0.001"/>
    <mesh name="left_leg_upper" class="/" file="left_leg_upper.stl" scale="0.001 0.001 0.001"/>
    <mesh name="left_leg_lower" class="/" file="left_leg_lower.stl" scale="0.001 0.001 0.001"/>
    <mesh name="left_foot" class="/" file="left_foot.stl" scale="0.001 0.001 0.001"/>
    <mesh name="left_hip_yaw1" class="/" content_type="model/stl" file="left_hip_yaw.stl" scale="0.001 -0.001 0.001"/>
    <mesh name="left_hip_abad1" class="/" content_type="model/stl" file="left_hip_abad.stl" scale="0.001 -0.001 0.001"/>
    <mesh name="left_leg_upper1" class="/" content_type="model/stl" file="left_leg_upper.stl" scale="0.001 -0.001 0.001"/>
    <mesh name="left_leg_lower1" class="/" content_type="model/stl" file="left_leg_lower.stl" scale="0.001 -0.001 0.001"/>
    <mesh name="left_foot1" class="/" content_type="model/stl" file="left_foot.stl" scale="0.001 -0.001 0.001"/>
    <mesh name="left_shoulder1" class="/" file="left_shoulder1.stl" scale="0.001 0.001 0.001"/>
    <mesh name="left_shoulder2" class="/" file="left_shoulder2.stl" scale="0.001 0.001 0.001"/>
    <mesh name="left_shoulder3" class="/" file="left_shoulder3.stl" scale="0.001 0.001 0.001"/>
    <mesh name="left_forearm" class="/" file="left_forearm.stl" scale="0.001 0.001 0.001"/>
    <mesh name="left_shoulder11" class="/" content_type="model/stl" file="left_shoulder1.stl" scale="0.001 -0.001 0.001"/>
    <mesh name="left_shoulder21" class="/" content_type="model/stl" file="left_shoulder2.stl" scale="0.001 -0.001 0.001"/>
    <mesh name="left_shoulder31" class="/" content_type="model/stl" file="left_shoulder3.stl" scale="0.001 -0.001 0.001"/>
  </asset>

  <worldbody>
    <geom name="floor" class="/" size="100 100 0.125" type="plane" group="0" material="MatPlane"/>
    <light name="toplight_shadow" class="/" pos="0 0 5" dir="0.0990148 0.0990148 -0.990148" type="directional" ambient="0.04 0.04 0.04" diffuse="0.55 0.55 0.55" specular="0.12 0.12 0.12"/>
    <light name="toplight_fill" class="/" pos="0 0 5" dir="0.0990148 0.0990148 -0.990148" type="directional" castshadow="false" ambient="0.04 0.04 0.04" diffuse="0.3 0.3 0.3" specular="0.08 0.08 0.08"/>
    <body name="trunk" pos="-0.00054837 0.000637539 -0.000397967" quat="1 -1.09359e-05 3.27485e-05 3.93109e-06">
      <inertial pos="0.00914097 0.00187053 0.123402" quat="0.999999 -0.000599964 -8.62276e-05 -0.00129892" mass="7.25075" diaginertia="0.115521 0.213643 0.0335905"/>
      <joint name="//unnamed_joint_0" type="free"/>
      <geom name="//unnamed_geom_1" class="/" type="mesh" density="0" rgba="0.752941 0.752941 0.752941 1" mesh="torso"/>
      <geom name="//unnamed_geom_2" class="/" size="0.0722173 0.144435 0.168507" pos="0.0212073 0 0.0650207" type="box" group="3" rgba="0.752941 0.752941 0.752941 1"/>
      <geom name="//unnamed_geom_3" class="reward_collision_sphere" size="0.13962" pos="0 0 0.121914"/>
      <site name="imu" class="/" pos="0.000409238 0.00146307 0.111041" size="0.00962898"/>
      <camera name="track" class="/" pos="0 -2.30776 0" quat="0.707107 0.707107 0 0" mode="trackcom"/>
      <camera name="ego_camera" class="/" pos="0.0414925 0 0.243828" quat="-0.5 -0.5 0.5 0.5"/>
      <body name="left_hip_yaw" pos="-0.00142945 0.0932702 -0.00165757" quat="0.996201 -7.02292e-05 -0.0870878 6.51802e-05">
        <inertial pos="-0.0605798 0.00064359 -0.0536684" quat="0.947945 -0.00533047 -0.318387 -0.00141095" mass="0.753154" diaginertia="0.00126986 0.00277972 0.000274539"/>
        <joint name="left_hip_yaw" class="/" pos="0 0 0" axis="0.00188807 0.0010793 -0.999998" stiffness="0.00236526" range="-3.01513 2.99832" armature="0.0106292" damping="0.0109268" frictionloss="0.101031"/>
        <geom name="//unnamed_geom_4" class="/" type="mesh" density="0" rgba="0.2 0.2 0.2 1" mesh="left_hip_yaw"/>
        <body name="left_hip_abad" pos="-0.0598013 -0.000718482 -0.0591142" quat="0.976367 0.00023344 0.216121 -0.000117184">
          <inertial pos="0.0613231 -0.0150348 0.000235191" quat="0.578526 0.406078 0.410909 0.575815" mass="1.05562" diaginertia="0.00218761 0.00405123 0.000602501"/>
          <joint name="left_hip_abad" class="/" pos="0 0 0" axis="-0.999998 -0.00165819 0.00107808" range="-2.9596 2.99028" armature="0.00979511" damping="0.0107671" frictionloss="0.098648"/>
          <geom name="//unnamed_geom_5" class="/" type="mesh" density="0" rgba="0.2 0.2 0.2 1" mesh="left_hip_abad"/>
          <body name="left_upper_leg" pos="0.0815073 -0.00209108 -0.00955565" quat="0.991383 0.000176349 -0.130992 -0.000306476">
            <inertial pos="-0.00223673 0.0319033 -0.0633593" quat="0.729473 0.0357987 -0.0485237 0.681346" mass="2.35823" diaginertia="0.017815 0.0495796 0.00123197"/>
            <joint name="left_hip_pitch" class="/" pos="0 0 0" axis="-0.00411612 0.999992 -9.12884e-05" range="-3.01513 3.01634" armature="0.00857769" damping="0.00892145" frictionloss="0.0949242"/>
            <geom name="//unnamed_geom_6" class="/" type="mesh" density="0" rgba="0.752941 0.752941 0.752941 1" mesh="left_leg_upper"/>
            <geom name="//unnamed_geom_7" class="reward_collision_sphere" size="0.0674028" pos="-0.0138308 0.0173082 0.0121914"/>
            <geom name="//unnamed_geom_8" class="reward_collision_sphere" size="0.019258" pos="-0.0737644 -0.0346164 0.0650207"/>
            <body name="left_lower_leg" pos="-0.0124847 -0.000915058 -0.203398" quat="1 -4.62328e-05 -0.000186069 -6.72454e-05">
              <inertial pos="0.00437043 0.00247724 -0.106127" quat="0.998705 -0.00168446 -0.017203 0.0478502" mass="0.303535" diaginertia="0.00202749 0.00611234 8.41412e-05"/>
              <joint name="left_knee" class="/" pos="0 0 0" axis="0.00403848 0.999988 0.00294026" range="-0.00029411 2.97944" armature="0.00923228" damping="0.0111876" frictionloss="0.0946143"/>
              <geom name="//unnamed_geom_9" class="/" type="mesh" density="0" rgba="0.752941 0.752941 0.752941 1" mesh="left_leg_lower"/>
              <geom name="//unnamed_geom_10" class="reward_collision_sphere" size="0.0414046"/>
              <body name="left_foot" pos="0.000562821 -0.000290798 -0.225324" quat="1 0.000244735 0.000192117 0.00022029">
                <inertial pos="0.0232077 0.00111847 -0.0112109" quat="0.519417 0.479417 0.480175 0.51942" mass="0.243672" diaginertia="0.01798 0.0558232 0.00945943"/>
                <joint name="left_ankle" class="/" pos="0 0 0" axis="0.00242868 0.999995 -0.00207172" stiffness="0.0110237" range="-1.5059 1.54145" armature="0.00980178" damping="0.00402932" frictionloss="0.0931968"/>
                <geom name="//unnamed_geom_11" class="/" type="mesh" density="0" rgba="0.2 0.2 0.2 1" mesh="left_foot"/>
                <geom name="left_foot" class="foot" size="0.104093 0.0171017 0.0203911" pos="0.0258175 0 -0.020319" quat="0.707109 0.707105 0 0"/>
                <geom name="//unnamed_geom_13" class="reward_collision_sphere" size="0.0240724" pos="0.0258175 0 -0.0162552"/>
                <geom name="//unnamed_geom_14" class="reward_collision_sphere" size="0.0240724" pos="0.0922055 0 -0.020319"/>
                <geom name="//unnamed_geom_15" class="reward_collision_sphere" size="0.0240724" pos="-0.0414925 0 -0.020319"/>
                <site name="left_foot" class="foot" pos="0.0258175 0 -0.020319" quat="0.707109 0.707105 0 0" size="0.00962898"/>
              </body>
            </body>
          </body>
        </body>
      </body>
      <body name="right_hip_yaw" pos="0.00127716 -0.0935833 -0.00127837" quat="0.996202 -0.000189446 -0.0870744 0.000233789">
        <inertial pos="-0.0613848 0.0016261 -0.0521012" quat="0.950015 -0.00264763 0.312181 -0.00283453" mass="0.737597" diaginertia="0.00126487 0.0027206 0.000268049"/>
        <joint name="right_hip_yaw" class="/" pos="0 0 0" axis="0.000484078 -0.000906168 -0.999999" range="-2.98954 3.00929" armature="0.00940813" damping="0.00347781" frictionloss="0.098576"/>
        <geom name="//unnamed_geom_16" class="/" type="mesh" density="0" rgba="0.2 0.2 0.2 1" mesh="left_hip_yaw1"/>
        <body name="right_hip_abad" pos="-0.0586504 0.00169586 -0.0624471" quat="0.976293 -1.69891e-05 0.216453 -9.73025e-06">
          <inertial pos="0.0634107 0.0153426 0.000532858" quat="0.411106 0.574441 0.578637 0.407662" mass="1.07155" diaginertia="0.0022712 0.00408572 0.000611183"/>
          <joint name="right_hip_abad" class="/" pos="0 0 0" axis="-0.999999 -0.000920083 0.000625082" range="-3.01016 2.99807" armature="0.00981024" damping="0.0116592" frictionloss="0.0964406"/>
          <geom name="//unnamed_geom_17" class="/" type="mesh" density="0" rgba="0.2 0.2 0.2 1" mesh="left_hip_abad1"/>
          <body name="right_upper_leg" pos="0.0790741 0.00220413 -0.0110922" quat="0.991532 -0.000210384 -0.129863 0.000728285">
            <inertial pos="-0.0027877 -0.0298838 -0.0651755" quat="0.68521 0.0494712 -0.0263644 0.726185" mass="2.41639" diaginertia="0.0179833 0.0509688 0.00124529"/>
            <joint name="right_hip_pitch" class="/" pos="0 0 0" axis="-0.000224576 -1 0.000790003" stiffness="0.00463366" range="-2.97312 2.9784" armature="0.00879691" damping="0.0154761" frictionloss="0.096276"/>
            <geom name="//unnamed_geom_18" class="/" type="mesh" density="0" rgba="0.752941 0.752941 0.752941 1" mesh="left_leg_upper1"/>
            <geom name="//unnamed_geom_19" class="reward_collision_sphere" size="0.0674028" pos="-0.0138308 -0.0173082 0.0121914"/>
            <geom name="//unnamed_geom_20" class="reward_collision_sphere" size="0.019258" pos="-0.0737644 0.0346164 0.0650207"/>
            <body name="right_lower_leg" pos="-0.0125173 -0.000866718 -0.201133" quat="1 0.000187718 8.00537e-05 -0.000180144">
              <inertial pos="0.00385431 -0.000984387 -0.107961" quat="0.998709 0.00473986 0.0128888 -0.0489149" mass="0.308337" diaginertia="0.0019768 0.0060728 8.28973e-05"/>
              <joint name="right_knee" class="/" pos="0 0 0" axis="-0.000393186 -1 0.000341244" range="-2.99374 -0.00477525" armature="0.00988951" damping="0.00417614" frictionloss="0.0987648"/>
              <geom name="//unnamed_geom_21" class="/" type="mesh" density="0" rgba="0.752941 0.752941 0.752941 1" mesh="left_leg_lower1"/>
              <geom name="//unnamed_geom_22" class="reward_collision_sphere" size="0.0414046"/>
              <body name="right_foot" pos="0.000470337 -0.000846827 -0.228211" quat="1 -0.000463058 -0.000758449 -0.000452498">
                <inertial pos="0.0219124 -0.000650753 -0.0114277" quat="0.479687 0.519479 0.519319 0.479948" mass="0.256398" diaginertia="0.0180765 0.0565835 0.00957116"/>
                <joint name="right_ankle" class="/" pos="0 0 0" axis="0.000966972 -0.999998 0.00148683" range="-1.54337 1.47253" armature="0.00862799" damping="0.00702526" frictionloss="0.0939912"/>
                <geom name="//unnamed_geom_23" class="/" type="mesh" density="0" rgba="0.2 0.2 0.2 1" mesh="left_foot1"/>
                <geom name="right_foot" class="foot" size="0.102229 0.0176802 0.0204247" pos="0.0258175 0 -0.020319" quat="0.707109 0.707105 0 0"/>
                <geom name="//unnamed_geom_25" class="reward_collision_sphere" size="0.0240724" pos="0.0258175 0 -0.0162552"/>
                <geom name="//unnamed_geom_26" class="reward_collision_sphere" size="0.0240724" pos="0.0922055 0 -0.020319"/>
                <geom name="//unnamed_geom_27" class="reward_collision_sphere" size="0.0240724" pos="-0.0414925 0 -0.020319"/>
                <site name="right_foot" class="foot" pos="0.0258175 0 -0.020319" quat="0.707109 0.707105 0 0" size="0.00962898"/>
              </body>
            </body>
          </body>
        </body>
      </body>
      <body name="left_shoulder" pos="0.0194697 0.203255 0.248377" quat="1 -0.00042448 -0.000185331 -0.000191681">
        <inertial pos="0.00900172 0.0613664 -0.000406196" quat="0.711292 0.702699 0.0117056 0.0119175" mass="0.71647" diaginertia="0.00091785 0.00178894 0.000270982"/>
        <joint name="left_shoulder_pitch" class="/" pos="0 0 0" axis="-0.00181171 0.999958 0.00893885" stiffness="0.00370256" range="-2.99913 3.00535" armature="0.00969412" damping="0.0046567" frictionloss="0.0952918"/>
        <geom name="//unnamed_geom_28" class="/" type="mesh" density="0" rgba="0.2 0.2 0.2 1" mesh="left_shoulder1"/>
        <body name="left_shoulder_2" pos="0.000689011 0.0669904 0.00186998" quat="1 4.30852e-05 1.02593e-05 -8.89551e-06">
          <inertial pos="-0.000182665 0.000275246 -0.0664532" quat="0.0124325 0.75728 0.000555173 0.652972" mass="0.71193" diaginertia="0.00080145 0.0023391 0.000399332"/>
          <joint name="left_shoulder_abad" class="/" pos="0 0 0" axis="-0.99999 -0.00319052 0.00303796" stiffness="0.00331106" range="-2.99769 3.00402" armature="0.00863014" damping="0.0127341" frictionloss="0.0954752"/>
          <geom name="//unnamed_geom_29" class="/" type="mesh" density="0" rgba="0.752941 0.752941 0.752941 1" mesh="left_shoulder2"/>
          <body name="left_upper_arm" pos="0.00153288 0.00159011 -0.0836379" quat="1 -0.000114676 0.000285548 0.000154576">
            <inertial pos="-0.000436643 -0.0208151 -0.0512789" quat="0.708627 -0.0192831 0.0199343 0.705038" mass="0.806029" diaginertia="0.00121623 0.00276279 0.000279979"/>
            <joint name="left_shoulder_yaw" class="/" pos="0 0 0" axis="0.00112215 -0.000628602 0.999999" range="-2.9974 3.01196" armature="0.00975601" damping="0.0121924" frictionloss="0.0959561"/>
            <geom name="//unnamed_geom_30" class="/" type="mesh" density="0" rgba="0.752941 0.752941 0.752941 1" mesh="left_shoulder3"/>
            <geom name="//unnamed_geom_31" class="reward_collision_sphere" size="0.0577739" pos="-0.00922055 -0.0115388 -0.040638"/>
            <body name="left_lower_arm" pos="2.93024e-05 0.000266796 -0.129261" quat="1 -3.37349e-05 9.60935e-05 1.89877e-05">
              <inertial pos="-0.00657654 0.000260256 -0.0819692" quat="0.707201 0.00456909 0.00470344 0.706982" mass="0.312164" diaginertia="0.00246221 0.00734039 2.77941e-05"/>
              <joint name="left_elbow" class="/" pos="0 0 0" axis="0.00387761 0.999988 0.00282573" range="-3.01964 3.00932" armature="0.0101347" damping="0.00846911" frictionloss="0.095305"/>
              <geom name="//unnamed_geom_32" class="/" type="mesh" density="0" rgba="0.752941 0.752941 0.752941 1" mesh="left_forearm"/>
              <geom name="//unnamed_geom_33" class="/" size="0.0240724 0.00722173" pos="0 0 -0.219445" quat="0.707109 0.707105 0 0" type="cylinder" group="3"/>
              <geom name="//unnamed_geom_34" class="reward_collision_sphere" size="0.0240724"/>
              <geom name="//unnamed_geom_35" class="reward_collision_sphere" size="0.0211838" pos="0 0 -0.227573"/>
            </body>
          </body>
        </body>
      </body>
      <body name="right_shoulder" pos="0.0186536 -0.204503 0.247992" quat="1 -8.35077e-06 -3.69442e-05 6.52597e-05">
        <inertial pos="0.00886991 -0.0616816 -0.000866156" quat="0.709971 0.70388 -0.016401 -0.0149733" mass="0.695488" diaginertia="0.000911529 0.00173411 0.000270189"/>
        <joint name="right_shoulder_pitch" class="/" pos="0 0 0" axis="-0.00171692 -0.999997 -0.00153286" stiffness="0.00886175" range="-3.02043 3.00943" armature="0.00928447" damping="0.00610788" frictionloss="0.0977498"/>
        <geom name="//unnamed_geom_36" class="/" type="mesh" density="0" rgba="0.2 0.2 0.2 1" mesh="left_shoulder11"/>
        <body name="right_shoulder_2" pos="0.00101253 -0.0648925 -0.00029882" quat="1 -0.000374653 0.000280372 0.00042922">
          <inertial pos="0.00140218 0.000383653 -0.0675825" quat="-0.00565733 0.64707 0.00750209 0.762373" mass="0.701651" diaginertia="0.000836015 0.00236057 0.000392109"/>
          <joint name="right_shoulder_abad" class="/" pos="0 0 0" axis="-0.999996 -0.00135281 0.00231738" stiffness="0.00322412" range="-2.9961 2.99919" armature="0.00944705" damping="0.00500338" frictionloss="0.0986321"/>
          <geom name="//unnamed_geom_37" class="/" type="mesh" density="0" rgba="0.752941 0.752941 0.752941 1" mesh="left_shoulder21"/>
          <body name="right_upper_arm" pos="-0.000144708 -0.000195102 -0.0836873" quat="1 0.000481538 -0.000516733 0.000303268">
            <inertial pos="-0.000114794 0.0210516 -0.0508973" quat="0.705014 -0.0201937 0.0220899 0.708561" mass="0.833645" diaginertia="0.00126683 0.00282716 0.000280485"/>
            <joint name="right_shoulder_yaw" class="/" pos="0 0 0" axis="-0.00911239 0.00520995 0.999945" stiffness="0.00245711" range="-3.018 3.02686" armature="0.0098546" damping="0" frictionloss="0.0954881"/>
            <geom name="//unnamed_geom_38" class="/" type="mesh" density="0" rgba="0.752941 0.752941 0.752941 1" mesh="left_shoulder31"/>
            <geom name="//unnamed_geom_39" class="reward_collision_sphere" size="0.0577739" pos="-0.00922055 0.0115388 -0.040638"/>
            <body name="right_lower_arm" pos="-0.000578925 0.000970597 -0.127502" quat="1 2.91603e-05 -0.000147681 6.58219e-06">
              <inertial pos="-0.00534432 -0.000529817 -0.0822427" quat="0.706556 0.0024357 0.00304936 0.707646" mass="0.313315" diaginertia="0.00238965 0.00739566 2.69453e-05"/>
              <joint name="right_elbow" class="/" pos="0 0 0" axis="-0.000515067 -0.999998 0.00200063" stiffness="0.00993155" range="-2.95919 2.99981" armature="0.00957914" damping="0.0136864" frictionloss="0.097018"/>
              <geom name="//unnamed_geom_40" class="/" type="mesh" density="0" rgba="0.752941 0.752941 0.752941 1" mesh="left_forearm"/>
              <geom name="//unnamed_geom_41" class="/" size="0.0240724 0.00722173" pos="0 0 -0.219445" quat="0.707109 0.707105 0 0" type="cylinder" group="3"/>
              <geom name="//unnamed_geom_42" class="reward_collision_sphere" size="0.0240724"/>
              <geom name="//unnamed_geom_43" class="reward_collision_sphere" size="0.0211838" pos="0 0 -0.227573"/>
            </body>
          </body>
        </body>
      </body>
    </body>
  </worldbody>

  <contact>
    <pair class="/" geom1="floor" geom2="left_foot" name="//unnamed_contact_0"/>
    <pair class="/" geom1="floor" geom2="right_foot" name="//unnamed_contact_1"/>
  </contact>

  <actuator>
    <general name="left_hip_yaw" class="/" joint="left_hip_yaw" forcerange="-32.7612 32.7612" gainprm="28.8507" biasprm="0 -28.8507 -0.48229"/>
    <general name="left_hip_abad" class="/" joint="left_hip_abad" forcerange="-30.4589 30.4589" gainprm="28.8507" biasprm="0 -28.8507 -0.48229"/>
    <general name="left_hip_pitch" class="/" joint="left_hip_pitch" forcerange="-63.9861 63.9861" gainprm="28.8507" biasprm="0 -28.8507 -0.48229"/>
    <general name="left_knee" class="/" joint="left_knee" forcerange="-136.718 136.718" gainprm="28.8507" biasprm="0 -28.8507 -0.48229"/>
    <general name="left_ankle" class="/" joint="left_ankle" forcerange="-67.664 67.664" gainprm="28.8507" biasprm="0 -28.8507 -0.48229"/>
    <general name="right_hip_yaw" class="/" joint="right_hip_yaw" forcerange="-31.2479 31.2479" gainprm="28.8507" biasprm="0 -28.8507 -0.48229"/>
    <general name="right_hip_abad" class="/" joint="right_hip_abad" forcerange="-32.8518 32.8518" gainprm="28.8507" biasprm="0 -28.8507 -0.48229"/>
    <general name="right_hip_pitch" class="/" joint="right_hip_pitch" forcerange="-68.1818 68.1818" gainprm="28.8507" biasprm="0 -28.8507 -0.48229"/>
    <general name="right_knee" class="/" joint="right_knee" forcerange="-139.792 139.792" gainprm="28.8507" biasprm="0 -28.8507 -0.48229"/>
    <general name="right_ankle" class="/" joint="right_ankle" forcerange="-64.616 64.616" gainprm="28.8507" biasprm="0 -28.8507 -0.48229"/>
    <general name="left_shoulder_pitch" class="/" joint="left_shoulder_pitch" forcerange="-33.9725 33.9725" gainprm="28.8507" biasprm="0 -28.8507 -0.48229"/>
    <general name="left_shoulder_abad" class="/" joint="left_shoulder_abad" forcerange="-32.5861 32.5861" gainprm="28.8507" biasprm="0 -28.8507 -0.48229"/>
    <general name="left_shoulder_yaw" class="/" joint="left_shoulder_yaw" forcerange="-34.0177 34.0177" gainprm="28.8507" biasprm="0 -28.8507 -0.48229"/>
    <general name="left_elbow" class="/" joint="left_elbow" forcerange="-52.628 52.628" gainprm="28.8507" biasprm="0 -28.8507 -0.48229"/>
    <general name="right_shoulder_pitch" class="/" joint="right_shoulder_pitch" forcerange="-34.3954 34.3954" gainprm="28.8507" biasprm="0 -28.8507 -0.48229"/>
    <general name="right_shoulder_abad" class="/" joint="right_shoulder_abad" forcerange="-32.7039 32.7039" gainprm="28.8507" biasprm="0 -28.8507 -0.48229"/>
    <general name="right_shoulder_yaw" class="/" joint="right_shoulder_yaw" forcerange="-32.7466 32.7466" gainprm="28.8507" biasprm="0 -28.8507 -0.48229"/>
    <general name="right_elbow" class="/" joint="right_elbow" forcerange="-52.6908 52.6908" gainprm="28.8507" biasprm="0 -28.8507 -0.48229"/>
  </actuator>

  <sensor>
    <gyro site="imu" name="imu_angular_velocity"/>
    <velocimeter site="imu" name="imu_linear_velocity"/>
    <framelinvel objtype="site" objname="left_foot" name="left_foot_global_linear_velocity"/>
    <framelinvel objtype="site" objname="right_foot" name="right_foot_global_linear_velocity"/>
  </sensor>

  <keyframe>
    <key name="home" qpos="0 0 0.656 1 0 0 0 0 0 -0.4 0.8 -0.4 0 0 0.4 -0.8 0.4 0 -0.05 0 -0.75 0 0.05 0 0.75"/>
  </keyframe>
</mujoco>
