<mujoco model="humanoid">
  <compiler angle="radian" assetdir="assets" balanceinertia="true" inertiafromgeom="false"/>

  <option timestep="0.005" density="1.2" viscosity="2e-05"/>

  <size nkey="1"/>

  <visual>
    <quality shadowsize="8192"/>
    <map shadowclip="0.5"/>
  </visual>

  <default>
    <default class="/">
      <joint armature="0.01" damping="0.01" frictionloss="0.1"/>
      <geom contype="0" conaffinity="0" group="1" solref="-1000 -80"/>
      <site size="0.01 0.005 0.005" group="5"/>
      <general forcelimited="true" biastype="affine" gainprm="30" biasprm="0 -30 -0.5"/>
      <default class="foot">
        <geom size="0.099 0.0178 0.021" type="box" condim="6" group="4" priority="1" solimp="0.015 1 0.021"/>
      </default>
      <default class="reward_collision_sphere">
        <geom group="5" rgba="1 0 0 1"/>
      </default>
    </default>
  </default>

  <asset>
    <texture type="skybox" colorspace="auto" name="//unnamed_texture_0" builtin="gradient" rgb1="0.95 0.95 0.95" rgb2="0.95 0.95 0.95" width="100" height="600"/>
    <texture type="2d" colorspace="auto" name="texplane" builtin="checker" rgb1="0.345 0.575 0.748" rgb2="0.345 0.575 0.748" markrgb="1 1 1" width="512" height="512"/>
    <material name="MatPlane" class="/" texture="texplane" texuniform="true" texrepeat="2 2" specular="0.9"/>
    <mesh name="torso" class="/" file="torso.stl" scale="0.001 0.001 0.001"/>
    <mesh name="left_hip_yaw" class="/" file="left_hip_yaw.stl" scale="0.001 0.001 0.001"/>
    <mesh name="left_hip_abad" class="/" file="left_hip_abad.stl" scale="0.001 0.001 0.001"/>
    <mesh name="left_leg_upper" class="/" file="left_leg_upper.stl" scale="0.001 0.001 0.001"/>
    <mesh name="left_leg_lower" class="/" file="left_leg_lower.stl" scale="0.001 0.001 0.001"/>
    <mesh name="left_foot" class="/" file="left_foot.stl" scale="0.001 0.001 0.001"/>
    <mesh name="left_hip_yaw1" class="/" content_type="model/stl" file="left_hip_yaw.stl" scale="0.001 -0.001 0.001"/>
    <mesh name="left_hip_abad1" class="/" content_type="model/stl" file="left_hip_abad.stl" scale="0.001 -0.001 0.001"/>
    <mesh name="left_leg_upper1" class="/" content_type="model/stl" file="left_leg_upper.stl" scale="0.001 -0.001 0.001"/>
    <mesh name="left_leg_lower1" class="/" content_type="model/stl" file="left_leg_lower.stl" scale="0.001 -0.001 0.001"/>
    <mesh name="left_foot1" class="/" content_type="model/stl" file="left_foot.stl" scale="0.001 -0.001 0.001"/>
    <mesh name="left_shoulder1" class="/" file="left_shoulder1.stl" scale="0.001 0.001 0.001"/>
    <mesh name="left_shoulder2" class="/" file="left_shoulder2.stl" scale="0.001 0.001 0.001"/>
    <mesh name="left_shoulder3" class="/" file="left_shoulder3.stl" scale="0.001 0.001 0.001"/>
    <mesh name="left_forearm" class="/" file="left_forearm.stl" scale="0.001 0.001 0.001"/>
    <mesh name="left_shoulder11" class="/" content_type="model/stl" file="left_shoulder1.stl" scale="0.001 -0.001 0.001"/>
    <mesh name="left_shoulder21" class="/" content_type="model/stl" file="left_shoulder2.stl" scale="0.001 -0.001 0.001"/>
    <mesh name="left_shoulder31" class="/" content_type="model/stl" file="left_shoulder3.stl" scale="0.001 -0.001 0.001"/>
  </asset>

  <worldbody>
    <geom name="floor" class="/" size="100 100 0.125" type="plane" group="0" material="MatPlane"/>
    <light name="toplight_shadow" class="/" pos="0 0 5" dir="0.0990148 0.0990148 -0.990148" type="directional" ambient="0.04 0.04 0.04" diffuse="0.55 0.55 0.55" specular="0.12 0.12 0.12"/>
    <light name="toplight_fill" class="/" pos="0 0 5" dir="0.0990148 0.0990148 -0.990148" type="directional" castshadow="false" ambient="0.04 0.04 0.04" diffuse="0.3 0.3 0.3" specular="0.08 0.08 0.08"/>
    <body name="trunk" pos="-0.000467856 -0.000247406 -0.00232562" quat="1 0.000121821 6.30471e-05 -5.8021e-05">
      <inertial pos="0.0135471 -0.00148818 0.145943" quat="0.999913 0.00649441 -0.00998512 0.00575107" mass="11.0827" diaginertia="0.479754 0.194887 0.0809262"/>
      <joint name="//unnamed_joint_0" type="free"/>
      <geom name="//unnamed_geom_1" class="/" type="mesh" density="0" rgba="0.752941 0.752941 0.752941 1" mesh="torso"/>
      <geom name="//unnamed_geom_2" class="/" size="0.083323 0.166646 0.19442" pos="0.0283723 0 0.0772608" type="box" group="3" rgba="0.752941 0.752941 0.752941 1"/>
      <geom name="//unnamed_geom_3" class="reward_collision_sphere" size="0.161091" pos="0 0 0.144864"/>
      <site name="imu" class="/" pos="0.00395115 -0.00878569 0.142344" size="0.0111097"/>
      <camera name="track" class="/" pos="0 -2.26717 0" quat="0.707107 0.707107 0 0" mode="trackcom"/>
      <camera name="ego_camera" class="/" pos="0.055511 0 0.289728" quat="-0.5 -0.5 0.5 0.5"/>
      <body name="left_hip_yaw" pos="-0.00163592 0.0952782 0.00159891" quat="0.996194 3.1e-05 -0.0871589 -6.95374e-05">
        <inertial pos="-0.0804143 -0.00133854 -0.0615143" quat="0.948537 0.00203262 -0.316464 0.0111304" mass="1.21623" diaginertia="0.00541921 0.00260365 0.000667785"/>
        <joint name="left_hip_yaw" class="/" pos="0 0 0" axis="-0.00290088 0.00171269 -0.999994" stiffness="0.0166532" range="-2.9863 2.9528" armature="0.0125149" damping="0.0107511" frictionloss="0.110661"/>
        <geom name="//unnamed_geom_4" class="/" type="mesh" density="0" rgba="0.2 0.2 0.2 1" mesh="left_hip_yaw"/>
        <body name="left_hip_abad" pos="-0.0812847 0.00221318 -0.0718644" quat="0.976146 0.000210647 0.217113 -0.000276085">
          <inertial pos="0.080555 -0.0136303 0.000153633" quat="0.580047 0.408193 0.407454 0.575244" mass="1.66353" diaginertia="0.00912816 0.00374045 0.0013913"/>
          <joint name="left_hip_abad" class="/" pos="0 0 0" axis="-1 -5.55296e-06 5.48224e-06" range="-2.94726 3.04534" armature="0.00972648" damping="0.011475" frictionloss="0.110287"/>
          <geom name="//unnamed_geom_5" class="/" type="mesh" density="0" rgba="0.2 0.2 0.2 1" mesh="left_hip_abad"/>
          <body name="left_upper_leg" pos="0.110504 -0.00519072 -0.0118365" quat="0.991372 8.71952e-05 -0.131076 -0.000523949">
            <inertial pos="0.00127269 0.0322321 -0.0735827" quat="0.730082 0.0462861 -0.0554338 0.679533" mass="3.41021" diaginertia="0.0718495 0.0432864 0.00293986"/>
            <joint name="left_hip_pitch" class="/" pos="0 0 0" axis="0.00624091 0.999973 -0.00376567" stiffness="0.0087962" range="-3.04168 2.94392" armature="0.0124416" damping="0.00730167" frictionloss="0.112129"/>
            <geom name="//unnamed_geom_6" class="/" type="mesh" density="0" rgba="0.752941 0.752941 0.752941 1" mesh="left_leg_upper"/>
            <geom name="//unnamed_geom_7" class="reward_collision_sphere" size="0.0777682" pos="-0.0185037 0.0170038 0.0144864"/>
            <geom name="//unnamed_geom_8" class="reward_collision_sphere" size="0.0222195" pos="-0.0986862 -0.0340075 0.0772608"/>
            <body name="left_lower_leg" pos="-0.0121671 0.00298469 -0.241002" quat="0.999999 0.000414223 -0.000664533 -0.000876811">
              <inertial pos="0.00930135 -1.75456e-05 -0.124337" quat="0.998511 0.00250157 -0.021718 0.0499717" mass="0.466603" diaginertia="0.00809058 0.00560064 0.000194456"/>
              <joint name="left_knee" class="/" pos="0 0 0" axis="-0.0058568 0.999951 -0.00800316" range="0.0176396 2.95164" armature="0.01211" damping="0.0231776" frictionloss="0.109384"/>
              <geom name="//unnamed_geom_9" class="/" type="mesh" density="0" rgba="0.752941 0.752941 0.752941 1" mesh="left_leg_lower"/>
              <geom name="//unnamed_geom_10" class="reward_collision_sphere" size="0.0477719"/>
              <body name="left_foot" pos="-0.00196378 -0.0018878 -0.270321" quat="1 0.000471274 -0.000435227 -0.000199537">
                <inertial pos="0.0254841 -0.00199502 -0.0122554" quat="0.520127 0.478482 0.47781 0.521748" mass="0.39354" diaginertia="0.075247 0.049396 0.0222772"/>
                <joint name="left_ankle" class="/" pos="0 0 0" axis="-0.0103555 0.999944 0.00198261" range="-1.53909 1.53982" armature="0.0109052" damping="0.0113701" frictionloss="0.113847"/>
                <geom name="//unnamed_geom_11" class="/" type="mesh" density="0" rgba="0.2 0.2 0.2 1" mesh="left_foot"/>
                <geom name="left_foot" class="foot" size="0.0995368 0.0206143 0.0223203" pos="0.0345402 0 -0.024144" quat="0.707109 0.707105 0 0"/>
                <geom name="//unnamed_geom_13" class="reward_collision_sphere" size="0.0277743" pos="0.0345402 0 -0.0193152"/>
                <geom name="//unnamed_geom_14" class="reward_collision_sphere" size="0.0277743" pos="0.123358 0 -0.024144"/>
                <geom name="//unnamed_geom_15" class="reward_collision_sphere" size="0.0277743" pos="-0.055511 0 -0.024144"/>
                <site name="left_foot" class="foot" pos="0.0345402 0 -0.024144" quat="0.707109 0.707105 0 0" size="0.0111097"/>
              </body>
            </body>
          </body>
        </body>
      </body>
      <body name="right_hip_yaw" pos="4.47682e-05 -0.0960933 -0.00175111" quat="0.996153 0.000445245 -0.0876315 0.000401995">
        <inertial pos="-0.0812826 -0.000984876 -0.0626728" quat="0.949872 -0.00911356 0.312336 -0.0103039" mass="1.15183" diaginertia="0.00526519 0.00256527 0.000616233"/>
        <joint name="right_hip_yaw" class="/" pos="0 0 0" axis="0.00482078 0.00716801 -0.999963" stiffness="0.0130385" range="-2.99374 3.04662" armature="0.0107325" damping="0.00710013" frictionloss="0.10844"/>
        <geom name="//unnamed_geom_16" class="/" type="mesh" density="0" rgba="0.2 0.2 0.2 1" mesh="left_hip_yaw1"/>
        <body name="right_hip_abad" pos="-0.0786601 -0.000628984 -0.0728591" quat="0.97623 -0.000313658 0.216735 0.000146828">
          <inertial pos="0.0819702 0.0157422 -0.00157164" quat="0.411743 0.574786 0.578386 0.406888" mass="1.62619" diaginertia="0.00914925 0.00346607 0.00136081"/>
          <joint name="right_hip_abad" class="/" pos="0 0 0" axis="-0.999991 0.00331316 0.00246731" stiffness="0.0204095" range="-2.94646 3.00347" armature="0.0114249" damping="0.000638378" frictionloss="0.106629"/>
          <geom name="//unnamed_geom_17" class="/" type="mesh" density="0" rgba="0.2 0.2 0.2 1" mesh="left_hip_abad1"/>
          <body name="right_upper_leg" pos="0.108566 0.00543734 -0.0142948" quat="0.991309 -0.00028796 -0.13155 7.0647e-05">
            <inertial pos="-0.00375712 -0.029473 -0.0758768" quat="0.675722 0.0490354 -0.0275615 0.735007" mass="3.59472" diaginertia="0.077433 0.0471783 0.00291035"/>
            <joint name="right_hip_pitch" class="/" pos="0 0 0" axis="0.00185732 -0.999998 -0.000126139" stiffness="0.0123511" range="-2.9934 3.00937" armature="0.0122311" damping="0.0112832" frictionloss="0.125929"/>
            <geom name="//unnamed_geom_18" class="/" type="mesh" density="0" rgba="0.752941 0.752941 0.752941 1" mesh="left_leg_upper1"/>
            <geom name="//unnamed_geom_19" class="reward_collision_sphere" size="0.0777682" pos="-0.0185037 -0.0170038 0.0144864"/>
            <geom name="//unnamed_geom_20" class="reward_collision_sphere" size="0.0222195" pos="-0.0986862 0.0340075 0.0772608"/>
            <body name="right_lower_leg" pos="-0.0141851 -0.00283685 -0.241599" quat="1 -8.43274e-06 -0.000188229 0.000345187">
              <inertial pos="0.00620229 -5.06879e-05 -0.124636" quat="0.998832 0.00512772 0.0152347 -0.0455637" mass="0.48713" diaginertia="0.0083321 0.00572211 0.000204718"/>
              <joint name="right_knee" class="/" pos="0 0 0" axis="-0.00795279 -0.999967 -0.00155449" range="-3.00442 0.0499023" armature="0.0122874" damping="0.0366565" frictionloss="0.0988214"/>
              <geom name="//unnamed_geom_21" class="/" type="mesh" density="0" rgba="0.752941 0.752941 0.752941 1" mesh="left_leg_lower1"/>
              <geom name="//unnamed_geom_22" class="reward_collision_sphere" size="0.0477719"/>
              <body name="right_foot" pos="-0.00162663 -0.0029867 -0.270713" quat="1 1.21693e-05 6.02011e-05 -2.53764e-06">
                <inertial pos="0.0307973 0.00201449 -0.0112617" quat="0.488268 0.517054 0.514908 0.478664" mass="0.372466" diaginertia="0.0745207 0.0485733 0.0217134"/>
                <joint name="right_ankle" class="/" pos="0 0 0" axis="-0.0130614 -0.999894 0.00639183" stiffness="0.0118641" range="-1.55217 1.54869" armature="0.0115929" damping="0.0086303" frictionloss="0.124286"/>
                <geom name="//unnamed_geom_23" class="/" type="mesh" density="0" rgba="0.2 0.2 0.2 1" mesh="left_foot1"/>
                <geom name="right_foot" class="foot" size="0.0848389 0.0195336 0.0252152" pos="0.0345402 0 -0.024144" quat="0.707109 0.707105 0 0"/>
                <geom name="//unnamed_geom_25" class="reward_collision_sphere" size="0.0277743" pos="0.0345402 0 -0.0193152"/>
                <geom name="//unnamed_geom_26" class="reward_collision_sphere" size="0.0277743" pos="0.123358 0 -0.024144"/>
                <geom name="//unnamed_geom_27" class="reward_collision_sphere" size="0.0277743" pos="-0.055511 0 -0.024144"/>
                <site name="right_foot" class="foot" pos="0.0345402 0 -0.024144" quat="0.707109 0.707105 0 0" size="0.0111097"/>
              </body>
            </body>
          </body>
        </body>
      </body>
      <body name="left_shoulder" pos="0.0263039 0.196864 0.296258" quat="1 -7.66141e-05 -3.46629e-06 2.60617e-05">
        <inertial pos="0.0114623 0.0619152 -0.00241469" quat="0.712481 0.701451 0.0123695 0.0135648" mass="1.07292" diaginertia="0.00404615 0.00162077 0.000641501"/>
        <joint name="left_shoulder_pitch" class="/" pos="0 0 0" axis="-0.0010439 0.999992 -0.00389984" range="-2.99912 2.99998" armature="0.0101815" damping="0.0184035" frictionloss="0.0965806"/>
        <geom name="//unnamed_geom_28" class="/" type="mesh" density="0" rgba="0.2 0.2 0.2 1" mesh="left_shoulder1"/>
        <body name="left_shoulder_2" pos="-0.000908724 0.0668493 -0.00198354" quat="1 9.03398e-05 -0.000200793 0.000194899">
          <inertial pos="-0.00219581 -0.00259933 -0.0801282" quat="0.00988382 0.759271 0.00168747 0.650698" mass="1.11373" diaginertia="0.00358555 0.00215688 0.000950098"/>
          <joint name="left_shoulder_abad" class="/" pos="0 0 0" axis="-0.999984 -0.00476729 0.00294436" range="-2.95843 3.04013" armature="0.0111069" damping="0" frictionloss="0.0988037"/>
          <geom name="//unnamed_geom_29" class="/" type="mesh" density="0" rgba="0.752941 0.752941 0.752941 1" mesh="left_shoulder2"/>
          <body name="left_upper_arm" pos="-0.0024601 -0.000258291 -0.0981291" quat="0.999999 0.000515015 0.00075145 0.000957739">
            <inertial pos="0.000275218 -0.0205757 -0.061206" quat="0.715759 -0.0248573 0.0253071 0.697446" mass="1.26347" diaginertia="0.0051688 0.00265673 0.000652391"/>
            <joint name="left_shoulder_yaw" class="/" pos="0 0 0" axis="0.000910709 -0.000867238 0.999999" range="-2.99512 2.99181" armature="0.0123965" damping="0.00386471" frictionloss="0.121321"/>
            <geom name="//unnamed_geom_30" class="/" type="mesh" density="0" rgba="0.752941 0.752941 0.752941 1" mesh="left_shoulder3"/>
            <geom name="//unnamed_geom_31" class="reward_collision_sphere" size="0.0666584" pos="-0.0123358 -0.0113358 -0.048288"/>
            <body name="left_lower_arm" pos="-0.00183112 0.00215725 -0.153196" quat="0.999999 0.000975635 0.000341829 0.000878139">
              <inertial pos="-0.00955575 0.000105067 -0.094336" quat="0.703119 -0.00657368 0.00539371 0.711022" mass="0.46415" diaginertia="0.0106243 0.00649086 6.36253e-05"/>
              <joint name="left_elbow" class="/" pos="0 0 0" axis="0.00428205 0.999914 -0.0123762" range="-2.99393 2.99369" armature="0.0125265" damping="0.0210818" frictionloss="0.121969"/>
              <geom name="//unnamed_geom_32" class="/" type="mesh" density="0" rgba="0.752941 0.752941 0.752941 1" mesh="left_forearm"/>
              <geom name="//unnamed_geom_33" class="/" size="0.0277743 0.0083323" pos="0 0 -0.260755" quat="0.707109 0.707105 0 0" type="cylinder" group="3"/>
              <geom name="//unnamed_geom_34" class="reward_collision_sphere" size="0.0277743"/>
              <geom name="//unnamed_geom_35" class="reward_collision_sphere" size="0.0244414" pos="0 0 -0.270413"/>
            </body>
          </body>
        </body>
      </body>
      <body name="right_shoulder" pos="0.0212642 -0.197858 0.295889" quat="0.999999 -0.000634766 -0.00109816 -0.000948262">
        <inertial pos="0.0126407 -0.0601509 -0.00155654" quat="0.701666 0.712053 -0.0208143 -0.014556" mass="1.11648" diaginertia="0.00391472 0.00170917 0.000654367"/>
        <joint name="right_shoulder_pitch" class="/" pos="0 0 0" axis="-0.00412631 -0.999991 0.000570374" stiffness="0.0142376" range="-3.03332 2.96162" armature="0.00966454" damping="0.020846" frictionloss="0.109403"/>
        <geom name="//unnamed_geom_36" class="/" type="mesh" density="0" rgba="0.2 0.2 0.2 1" mesh="left_shoulder11"/>
        <body name="right_shoulder_2" pos="0.000820993 -0.0650294 0.00109639" quat="1 1.51181e-05 -5.7362e-05 5.41129e-05">
          <inertial pos="0.00219485 -0.00299919 -0.0797594" quat="0.000332912 0.653883 0.0126538 0.75649" mass="1.14145" diaginertia="0.00375234 0.00221682 0.00101008"/>
          <joint name="right_shoulder_abad" class="/" pos="0 0 0" axis="-0.999998 -0.0011886 0.00177311" range="-3.02288 2.95871" armature="0.0104487" damping="0.0324782" frictionloss="0.112043"/>
          <geom name="//unnamed_geom_37" class="/" type="mesh" density="0" rgba="0.752941 0.752941 0.752941 1" mesh="left_shoulder21"/>
          <body name="right_upper_arm" pos="-0.00203997 0.00304841 -0.097817" quat="0.999999 0.000687431 -0.000904859 -0.000628643">
            <inertial pos="0.00143315 0.0204132 -0.0618484" quat="0.706091 -0.0219205 0.0220621 0.707438" mass="1.18648" diaginertia="0.00493468 0.00236385 0.000664484"/>
            <joint name="right_shoulder_yaw" class="/" pos="0 0 0" axis="-0.00325362 -0.00070059 0.999994" range="-3.04408 3.0088" armature="0.0105278" damping="0.0244704" frictionloss="0.107112"/>
            <geom name="//unnamed_geom_38" class="/" type="mesh" density="0" rgba="0.752941 0.752941 0.752941 1" mesh="left_shoulder31"/>
            <geom name="//unnamed_geom_39" class="reward_collision_sphere" size="0.0666584" pos="-0.0123358 0.0113358 -0.048288"/>
            <body name="right_lower_arm" pos="-0.00167023 0.00215242 -0.14981" quat="1 0.000145027 0.00015125 7.27516e-05">
              <inertial pos="-0.00661208 -0.0016254 -0.0960972" quat="0.706642 0.00441503 0.0068986 0.707524" mass="0.491962" diaginertia="0.0106394 0.00697538 6.70748e-05"/>
              <joint name="right_elbow" class="/" pos="0 0 0" axis="-0.00474075 -0.999989 -0.000497893" range="-3.02436 3.03403" armature="0.0101712" damping="0.0061007" frictionloss="0.125075"/>
              <geom name="//unnamed_geom_40" class="/" type="mesh" density="0" rgba="0.752941 0.752941 0.752941 1" mesh="left_forearm"/>
              <geom name="//unnamed_geom_41" class="/" size="0.0277743 0.0083323" pos="0 0 -0.260755" quat="0.707109 0.707105 0 0" type="cylinder" group="3"/>
              <geom name="//unnamed_geom_42" class="reward_collision_sphere" size="0.0277743"/>
              <geom name="//unnamed_geom_43" class="reward_collision_sphere" size="0.0244414" pos="0 0 -0.270413"/>
            </body>
          </body>
        </body>
      </body>
    </body>
  </worldbody>

  <contact>
    <pair class="/" geom1="floor" geom2="left_foot" name="//unnamed_contact_0"/>
    <pair class="/" geom1="floor" geom2="right_foot" name="//unnamed_contact_1"/>
  </contact>

  <actuator>
    <general name="left_hip_yaw" class="/" joint="left_hip_yaw" forcerange="-38.3314 38.3314" gainprm="34.7527" biasprm="0 -34.7527 -0.513693"/>
    <general name="left_hip_abad" class="/" joint="left_hip_abad" forcerange="-38.8549 38.8549" gainprm="34.7527" biasprm="0 -34.7527 -0.513693"/>
    <general name="left_hip_pitch" class="/" joint="left_hip_pitch" forcerange="-81.9356 81.9356" gainprm="34.7527" biasprm="0 -34.7527 -0.513693"/>
    <general name="left_knee" class="/" joint="left_knee" forcerange="-160.206 160.206" gainprm="34.7527" biasprm="0 -34.7527 -0.513693"/>
    <general name="left_ankle" class="/" joint="left_ankle" forcerange="-75.4875 75.4875" gainprm="34.7527" biasprm="0 -34.7527 -0.513693"/>
    <general name="right_hip_yaw" class="/" joint="right_hip_yaw" forcerange="-37.5933 37.5933" gainprm="34.7527" biasprm="0 -34.7527 -0.513693"/>
    <general name="right_hip_abad" class="/" joint="right_hip_abad" forcerange="-38.8306 38.8306" gainprm="34.7527" biasprm="0 -34.7527 -0.513693"/>
    <general name="right_hip_pitch" class="/" joint="right_hip_pitch" forcerange="-74.6296 74.6296" gainprm="34.7527" biasprm="0 -34.7527 -0.513693"/>
    <general name="right_knee" class="/" joint="right_knee" forcerange="-144.79 144.79" gainprm="34.7527" biasprm="0 -34.7527 -0.513693"/>
    <general name="right_ankle" class="/" joint="right_ankle" forcerange="-67.9998 67.9998" gainprm="34.7527" biasprm="0 -34.7527 -0.513693"/>
    <general name="left_shoulder_pitch" class="/" joint="left_shoulder_pitch" forcerange="-37.9469 37.9469" gainprm="34.7527" biasprm="0 -34.7527 -0.513693"/>
    <general name="left_shoulder_abad" class="/" joint="left_shoulder_abad" forcerange="-35.696 35.696" gainprm="34.7527" biasprm="0 -34.7527 -0.513693"/>
    <general name="left_shoulder_yaw" class="/" joint="left_shoulder_yaw" forcerange="-35.0028 35.0028" gainprm="34.7527" biasprm="0 -34.7527 -0.513693"/>
    <general name="left_elbow" class="/" joint="left_elbow" forcerange="-65.3902 65.3902" gainprm="34.7527" biasprm="0 -34.7527 -0.513693"/>
    <general name="right_shoulder_pitch" class="/" joint="right_shoulder_pitch" forcerange="-34.7953 34.7953" gainprm="34.7527" biasprm="0 -34.7527 -0.513693"/>
    <general name="right_shoulder_abad" class="/" joint="right_shoulder_abad" forcerange="-36.6033 36.6033" gainprm="34.7527" biasprm="0 -34.7527 -0.513693"/>
    <general name="right_shoulder_yaw" class="/" joint="right_shoulder_yaw" forcerange="-40.141 40.141" gainprm="34.7527" biasprm="0 -34.7527 -0.513693"/>
    <general name="right_elbow" class="/" joint="right_elbow" forcerange="-60.3457 60.3457" gainprm="34.7527" biasprm="0 -34.7527 -0.513693"/>
  </actuator>

  <sensor>
    <gyro site="imu" name="imu_angular_velocity"/>
    <velocimeter site="imu" name="imu_linear_velocity"/>
    <framelinvel objtype="site" objname="left_foot" name="left_foot_global_linear_velocity"/>
    <framelinvel objtype="site" objname="right_foot" name="right_foot_global_linear_velocity"/>
  </sensor>

  <keyframe>
    <key name="home" qpos="0 0 0.656 1 0 0 0 0 0 -0.4 0.8 -0.4 0 0 0.4 -0.8 0.4 0 -0.05 0 -0.75 0 0.05 0 0.75"/>
  </keyframe>
</mujoco>
