<mujoco model="humanoid">
  <compiler angle="radian" assetdir="assets" balanceinertia="true" inertiafromgeom="false"/>

  <option timestep="0.005" density="1.2" viscosity="2e-05"/>

  <size nkey="1"/>

  <visual>
    <quality shadowsize="8192"/>
    <map shadowclip="0.5"/>
  </visual>

  <default>
    <default class="/">
      <joint armature="0.01" damping="0.01" frictionloss="0.1"/>
      <geom contype="0" conaffinity="0" group="1" solref="-1000 -80"/>
      <site size="0.01 0.005 0.005" group="5"/>
      <general forcelimited="true" biastype="affine" gainprm="30" biasprm="0 -30 -0.5"/>
      <default class="foot">
        <geom size="0.099 0.0178 0.021" type="box" condim="6" group="4" priority="1" solimp="0.015 1 0.021"/>
      </default>
      <default class="reward_collision_sphere">
        <geom group="5" rgba="1 0 0 1"/>
      </default>
    </default>
  </default>

  <asset>
    <texture type="skybox" colorspace="auto" name="//unnamed_texture_0" builtin="gradient" rgb1="0.95 0.95 0.95" rgb2="0.95 0.95 0.95" width="100" height="600"/>
    <texture type="2d" colorspace="auto" name="texplane" builtin="checker" rgb1="0.345 0.575 0.748" rgb2="0.345 0.575 0.748" markrgb="1 1 1" width="512" height="512"/>
    <material name="MatPlane" class="/" texture="texplane" texuniform="true" texrepeat="2 2" specular="0.9"/>
    <mesh name="torso" class="/" file="torso.stl" scale="0.001 0.001 0.001"/>
    <mesh name="left_hip_yaw" class="/" file="left_hip_yaw.stl" scale="0.001 0.001 0.001"/>
    <mesh name="left_hip_abad" class="/" file="left_hip_abad.stl" scale="0.001 0.001 0.001"/>
    <mesh name="left_leg_upper" class="/" file="left_leg_upper.stl" scale="0.001 0.001 0.001"/>
    <mesh name="left_leg_lower" class="/" file="left_leg_lower.stl" scale="0.001 0.001 0.001"/>
    <mesh name="left_foot" class="/" file="left_foot.stl" scale="0.001 0.001 0.001"/>
    <mesh name="left_hip_yaw1" class="/" content_type="model/stl" file="left_hip_yaw.stl" scale="0.001 -0.001 0.001"/>
    <mesh name="left_hip_abad1" class="/" content_type="model/stl" file="left_hip_abad.stl" scale="0.001 -0.001 0.001"/>
    <mesh name="left_leg_upper1" class="/" content_type="model/stl" file="left_leg_upper.stl" scale="0.001 -0.001 0.001"/>
    <mesh name="left_leg_lower1" class="/" content_type="model/stl" file="left_leg_lower.stl" scale="0.001 -0.001 0.001"/>
    <mesh name="left_foot1" class="/" content_type="model/stl" file="left_foot.stl" scale="0.001 -0.001 0.001"/>
    <mesh name="left_shoulder1" class="/" file="left_shoulder1.stl" scale="0.001 0.001 0.001"/>
    <mesh name="left_shoulder2" class="/" file="left_shoulder2.stl" scale="0.001 0.001 0.001"/>
    <mesh name="left_shoulder3" class="/" file="left_shoulder3.stl" scale="0.001 0.001 0.001"/>
    <mesh name="left_forearm" class="/" file="left_forearm.stl" scale="0.001 0.001 0.001"/>
    <mesh name="left_shoulder11" class="/" content_type="model/stl" file="left_shoulder1.stl" scale="0.001 -0.001 0.001"/>
    <mesh name="left_shoulder21" class="/" content_type="model/stl" file="left_shoulder2.stl" scale="0.001 -0.001 0.001"/>
    <mesh name="left_shoulder31" class="/" content_type="model/stl" file="left_shoulder3.stl" scale="0.001 -0.001 0.001"/>
  </asset>

  <worldbody>
    <geom name="floor" class="/" size="100 100 0.125" type="plane" group="0" material="MatPlane"/>
    <light name="toplight_shadow" class="/" pos="0 0 5" dir="0.0990148 0.0990148 -0.990148" type="directional" ambient="0.04 0.04 0.04" diffuse="0.55 0.55 0.55" specular="0.12 0.12 0.12"/>
    <light name="toplight_fill" class="/" pos="0 0 5" dir="0.0990148 0.0990148 -0.990148" type="directional" castshadow="false" ambient="0.04 0.04 0.04" diffuse="0.3 0.3 0.3" specular="0.08 0.08 0.08"/>
    <body name="trunk" pos="-5.08507e-05 0.000498917 -0.014362" quat="1 -4.4966e-05 -0.000369645 -7.54452e-05">
      <inertial pos="0.0114186 0.00550416 0.0958492" quat="0.999755 -0.0216928 -0.00417778 0.00151963" mass="12.7347" diaginertia="0.529425 0.968252 0.00943516"/>
      <joint name="//unnamed_joint_0" type="free"/>
      <geom name="//unnamed_geom_1" class="/" type="mesh" density="0" rgba="0.752941 0.752941 0.752941 1" mesh="torso"/>
      <geom name="//unnamed_geom_2" class="/" size="0.0835998 0.1672 0.195066" pos="0.027461 0 0.0498527" type="box" group="3" rgba="0.752941 0.752941 0.752941 1"/>
      <geom name="//unnamed_geom_3" class="reward_collision_sphere" size="0.161626" pos="0 0 0.0934738"/>
      <site name="imu" class="/" pos="-0.00175199 -0.0683532 0.0995884" size="0.0111466"/>
      <camera name="track" class="/" pos="0 -3.05375 0" quat="0.707107 0.707107 0 0" mode="trackcom"/>
      <camera name="ego_camera" class="/" pos="0.0537281 0 0.186948" quat="-0.5 -0.5 0.5 0.5"/>
      <body name="left_hip_yaw" pos="-0.00476111 0.139117 -0.00402351" quat="0.996194 6.32581e-05 -0.0871592 -0.00011682">
        <inertial pos="-0.0802122 0.00954407 -0.0394177" quat="0.956954 0.0204407 -0.289109 -0.0154148" mass="1.32958" diaginertia="0.00492375 0.0109716 7.09988e-05"/>
        <joint name="left_hip_yaw" class="/" pos="0 0 0" axis="0.00246878 -0.0158173 -0.999872" stiffness="0.0611589" range="-3.02174 3.14556" armature="0.00901101" damping="0.0278966" frictionloss="0.174294"/>
        <geom name="//unnamed_geom_4" class="/" type="mesh" density="0" rgba="0.2 0.2 0.2 1" mesh="left_hip_yaw"/>
        <body name="left_hip_abad" pos="-0.0717326 -0.00414771 -0.0536803" quat="0.977592 -0.00241452 0.210492 0.00125142">
          <inertial pos="0.0881056 -0.0214092 -0.000224996" quat="0.578992 0.40862 0.409719 0.574393" mass="1.96911" diaginertia="0.00874704 0.0147581 0.000179586"/>
          <joint name="left_hip_abad" class="/" pos="0 0 0" axis="-0.999998 -0.000901303 0.0015006" range="-3.08822 2.92445" armature="0.0131791" damping="0.0117593" frictionloss="0.173864"/>
          <geom name="//unnamed_geom_5" class="/" type="mesh" density="0" rgba="0.2 0.2 0.2 1" mesh="left_hip_abad"/>
          <body name="left_upper_leg" pos="0.116855 -0.0186868 -0.012017" quat="0.991103 -0.00445357 -0.132954 0.00421434">
            <inertial pos="-0.00850458 0.0546232 -0.0545163" quat="0.735695 0.0478914 -0.024197 0.675184" mass="4.22678" diaginertia="0.0726851 0.242337 0.000327739"/>
            <joint name="left_hip_pitch" class="/" pos="0 0 0" axis="0.0493003 0.998651 0.016297" range="-2.83926 3.09834" armature="0.00775437" damping="0.0107016" frictionloss="0.0494186"/>
            <geom name="//unnamed_geom_6" class="/" type="mesh" density="0" rgba="0.752941 0.752941 0.752941 1" mesh="left_leg_upper"/>
            <geom name="//unnamed_geom_7" class="reward_collision_sphere" size="0.0780265" pos="-0.0179094 0.0229032 0.00934738"/>
            <geom name="//unnamed_geom_8" class="reward_collision_sphere" size="0.0222933" pos="-0.0955167 -0.0458063 0.0498527"/>
            <body name="left_lower_leg" pos="-0.000569877 -0.00456285 -0.143396" quat="0.999994 0.000373327 -0.000453741 0.00341482">
              <inertial pos="0.00142032 -0.0114095 -0.0867587" quat="0.999325 0.032337 0.00412872 0.0169239" mass="0.478793" diaginertia="0.00788957 0.0223914 1.90297e-05"/>
              <joint name="left_knee" class="/" pos="0 0 0" axis="-0.0124281 0.999923 0.000569945" stiffness="0.0195121" range="-0.199448 3.14614" armature="0.00974918" damping="0" frictionloss="0.110199"/>
              <geom name="//unnamed_geom_9" class="/" type="mesh" density="0" rgba="0.752941 0.752941 0.752941 1" mesh="left_leg_lower"/>
              <geom name="//unnamed_geom_10" class="reward_collision_sphere" size="0.0479306"/>
              <body name="left_foot" pos="-0.000356249 0.00731244 -0.173134" quat="0.999999 -0.000639442 0.000697751 0.000354548">
                <inertial pos="0.0326605 0.00303112 -0.0185332" quat="0.519728 0.480317 0.480079 0.518365" mass="0.362845" diaginertia="0.0719917 0.246906 0.00281474"/>
                <joint name="left_ankle" class="/" pos="0 0 0" axis="0.0608582 0.997487 0.0362848" stiffness="0.00190807" range="-1.3339 1.34098" armature="0.0107197" damping="0" frictionloss="0.117183"/>
                <geom name="//unnamed_geom_11" class="/" type="mesh" density="0" rgba="0.2 0.2 0.2 1" mesh="left_foot"/>
                <geom name="left_foot" class="foot" size="0.121221 0.0132992 0.0234824" pos="0.0334308 0 -0.015579" quat="0.707109 0.707105 0 0"/>
                <geom name="//unnamed_geom_13" class="reward_collision_sphere" size="0.0278666" pos="0.0334308 0 -0.0124632"/>
                <geom name="//unnamed_geom_14" class="reward_collision_sphere" size="0.0278666" pos="0.119396 0 -0.015579"/>
                <geom name="//unnamed_geom_15" class="reward_collision_sphere" size="0.0278666" pos="-0.0537281 0 -0.015579"/>
                <site name="left_foot" class="foot" pos="0.0334308 0 -0.015579" quat="0.707109 0.707105 0 0" size="0.0111466"/>
              </body>
            </body>
          </body>
        </body>
      </body>
      <body name="right_hip_yaw" pos="-0.000612172 -0.119707 -0.0144771" quat="0.996501 0.00254575 -0.0835396 -7.03245e-05">
        <inertial pos="-0.0781804 0.00141202 -0.0381938" quat="0.965619 -0.0314828 0.256321 -0.0298163" mass="0.860024" diaginertia="0.00380982 0.0088463 4.92331e-05"/>
        <joint name="right_hip_yaw" class="/" pos="0 0 0" axis="0.0206397 0.0349558 -0.999176" range="-2.99295 2.85616" armature="0.0112405" damping="0.0200063" frictionloss="0.171153"/>
        <geom name="//unnamed_geom_16" class="/" type="mesh" density="0" rgba="0.2 0.2 0.2 1" mesh="left_hip_yaw1"/>
        <body name="right_hip_abad" pos="-0.079027 -0.000450513 -0.0512115" quat="0.975496 -0.001831 0.219959 0.00482358">
          <inertial pos="0.0829908 0.019003 0.00872213" quat="0.41099 0.573366 0.579219 0.408466" mass="2.07573" diaginertia="0.00873898 0.0183517 0.000190005"/>
          <joint name="right_hip_abad" class="/" pos="0 0 0" axis="-0.998032 -0.00663413 -0.0623492" stiffness="0.0681196" range="-3.1069 2.99711" armature="0.0105133" damping="0.0363838" frictionloss="0.11728"/>
          <geom name="//unnamed_geom_17" class="/" type="mesh" density="0" rgba="0.2 0.2 0.2 1" mesh="left_hip_abad1"/>
          <body name="right_upper_leg" pos="0.0954876 -0.00185615 -0.0100319" quat="0.991302 0.00566191 -0.131421 0.00413063">
            <inertial pos="0.00286669 -0.0403678 -0.0480034" quat="0.681264 0.0439189 -0.0481544 0.729131" mass="3.63307" diaginertia="0.060377 0.185171 0.000327966"/>
            <joint name="right_hip_pitch" class="/" pos="0 0 0" axis="-0.0132858 -0.998391 -0.0551333" range="-3.00195 3.01909" armature="0.0189181" damping="0.00806543" frictionloss="0.0864386"/>
            <geom name="//unnamed_geom_18" class="/" type="mesh" density="0" rgba="0.752941 0.752941 0.752941 1" mesh="left_leg_upper1"/>
            <geom name="//unnamed_geom_19" class="reward_collision_sphere" size="0.0780265" pos="-0.0179094 -0.0229032 0.00934738"/>
            <geom name="//unnamed_geom_20" class="reward_collision_sphere" size="0.0222933" pos="-0.0955167 0.0458063 0.0498527"/>
            <body name="right_lower_leg" pos="-0.0184472 0.00671088 -0.155325" quat="0.999987 -0.0037121 -0.00329663 -0.00140147">
              <inertial pos="0.00574297 -0.0113522 -0.0889234" quat="0.99886 0.00610077 0.0157785 -0.0446385" mass="0.406967" diaginertia="0.00762767 0.0278716 1.91157e-05"/>
              <joint name="right_knee" class="/" pos="0 0 0" axis="-0.0473388 -0.997703 -0.0484612" stiffness="0.018087" range="-3.02839 -0.130807" armature="0.00611621" damping="0.0831875" frictionloss="0.032115"/>
              <geom name="//unnamed_geom_21" class="/" type="mesh" density="0" rgba="0.752941 0.752941 0.752941 1" mesh="left_leg_lower1"/>
              <geom name="//unnamed_geom_22" class="reward_collision_sphere" size="0.0479306"/>
              <body name="right_foot" pos="0.00946736 0.00434174 -0.17385" quat="1 0.000194253 0.000362008 -3.8086e-05">
                <inertial pos="0.0233694 -0.00256817 -0.0112758" quat="0.481801 0.52854 0.509277 0.478696" mass="0.420323" diaginertia="0.070543 0.274907 0.00278027"/>
                <joint name="right_ankle" class="/" pos="0 0 0" axis="-0.0183606 -0.999659 -0.0185917" stiffness="0.0681643" range="-1.37564 1.42064" armature="0.010887" damping="0.0088656" frictionloss="0.0916335"/>
                <geom name="//unnamed_geom_23" class="/" type="mesh" density="0" rgba="0.2 0.2 0.2 1" mesh="left_foot1"/>
                <geom name="right_foot" class="foot" size="0.0507121 0.0110776 0.0177789" pos="0.0334308 0 -0.015579" quat="0.707109 0.707105 0 0"/>
                <geom name="//unnamed_geom_25" class="reward_collision_sphere" size="0.0278666" pos="0.0334308 0 -0.0124632"/>
                <geom name="//unnamed_geom_26" class="reward_collision_sphere" size="0.0278666" pos="0.119396 0 -0.015579"/>
                <geom name="//unnamed_geom_27" class="reward_collision_sphere" size="0.0278666" pos="-0.0537281 0 -0.015579"/>
                <site name="right_foot" class="foot" pos="0.0334308 0 -0.015579" quat="0.707109 0.707105 0 0" size="0.0111466"/>
              </body>
            </body>
          </body>
        </body>
      </body>
      <body name="left_shoulder" pos="0.0191288 0.275223 0.184339" quat="0.999984 0.00410272 0.00379896 -0.000839406">
        <inertial pos="0.00989454 0.0948587 0.00612704" quat="0.711768 0.702163 0.0144289 0.0120718" mass="1.13184" diaginertia="0.00315181 0.00570307 7.03591e-05"/>
        <joint name="left_shoulder_pitch" class="/" pos="0 0 0" axis="0.00798267 0.999961 -0.00380673" stiffness="0.0280533" range="-2.76918 3.01602" armature="0.00368204" damping="0.00315155" frictionloss="0.146568"/>
        <geom name="//unnamed_geom_28" class="/" type="mesh" density="0" rgba="0.2 0.2 0.2 1" mesh="left_shoulder1"/>
        <body name="left_shoulder_2" pos="-0.0120644 0.101498 0.00479227" quat="1 6.00404e-05 7.42905e-05 -0.000308891">
          <inertial pos="0.00687448 0.00565963 -0.05176" quat="0.0763803 0.755608 0.00155804 0.650553" mass="1.12289" diaginertia="0.00350909 0.0108881 0.000122099"/>
          <joint name="left_shoulder_abad" class="/" pos="0 0 0" axis="-0.99881 -0.0356437 0.0333023" stiffness="0.0177539" range="-3.05955 2.83841" armature="0.00482205" damping="0.0507958" frictionloss="0.0321833"/>
          <geom name="//unnamed_geom_29" class="/" type="mesh" density="0" rgba="0.752941 0.752941 0.752941 1" mesh="left_shoulder2"/>
          <body name="left_upper_arm" pos="0.00595522 0.000189631 -0.064084" quat="0.999997 -0.000179359 0.00065783 0.0022372">
            <inertial pos="0.0116666 -0.0224459 -0.039188" quat="0.722588 -0.000975751 0.000945822 0.691278" mass="1.26401" diaginertia="0.00393149 0.00922087 7.01968e-05"/>
            <joint name="left_shoulder_yaw" class="/" pos="0 0 0" axis="0.000644512 -0.000626606 1" stiffness="0.0201576" range="-3.01052 2.99474" armature="0.00778572" damping="0.00558957" frictionloss="0.0643621"/>
            <geom name="//unnamed_geom_30" class="/" type="mesh" density="0" rgba="0.752941 0.752941 0.752941 1" mesh="left_shoulder3"/>
            <geom name="//unnamed_geom_31" class="reward_collision_sphere" size="0.0668799" pos="-0.0119396 -0.0152688 -0.0311579"/>
            <body name="left_lower_arm" pos="-0.0136933 -0.00759319 -0.0960515" quat="0.999997 0.0015817 0.000743176 -0.00143593">
              <inertial pos="-0.0204255 -0.000477453 -0.0691486" quat="0.737784 -0.0237314 -0.0445097 0.67315" mass="0.405776" diaginertia="0.00818395 0.03319 6.18786e-06"/>
              <joint name="left_elbow" class="/" pos="0 0 0" axis="-0.00316556 0.999968 0.0073558" stiffness="0.0365973" range="-2.99545 3.00006" armature="0.0193844" damping="0" frictionloss="0.0964798"/>
              <geom name="//unnamed_geom_32" class="/" type="mesh" density="0" rgba="0.752941 0.752941 0.752941 1" mesh="left_forearm"/>
              <geom name="//unnamed_geom_33" class="/" size="0.0278666 0.00835998" pos="0 0 -0.168253" quat="0.707109 0.707105 0 0" type="cylinder" group="3"/>
              <geom name="//unnamed_geom_34" class="reward_collision_sphere" size="0.0278666"/>
              <geom name="//unnamed_geom_35" class="reward_collision_sphere" size="0.0245226" pos="0 0 -0.174484"/>
            </body>
          </body>
        </body>
      </body>
      <body name="right_shoulder" pos="0.0273267 -0.277558 0.202545" quat="0.999998 0.000644772 0.00132321 0.00100217">
        <inertial pos="0.00161737 -0.0815763 0.00658033" quat="0.72409 0.68968 -0.00498856 0.00315463" mass="0.993007" diaginertia="0.00332805 0.0058698 6.48468e-05"/>
        <joint name="right_shoulder_pitch" class="/" pos="0 0 0" axis="-0.00601477 -0.998745 0.0497256" range="-3.27108 3.16738" armature="0.0133958" damping="8.05599e-05" frictionloss="0.107016"/>
        <geom name="//unnamed_geom_36" class="/" type="mesh" density="0" rgba="0.2 0.2 0.2 1" mesh="left_shoulder11"/>
        <body name="right_shoulder_2" pos="-0.00893566 -0.0875819 -0.00932749" quat="0.999985 -0.00172654 0.0037107 0.00377027">
          <inertial pos="-0.0032063 0.00561964 -0.0516869" quat="0.00250905 0.650664 0.0138436 0.759236" mass="1.05764" diaginertia="0.00275604 0.00951042 9.04786e-05"/>
          <joint name="right_shoulder_abad" class="/" pos="0 0 0" axis="-0.999988 -0.00486085 0.00099375" stiffness="0.00245193" range="-3.25929 3.16303" armature="0.0170819" damping="0.0809474" frictionloss="0.10751"/>
          <geom name="//unnamed_geom_37" class="/" type="mesh" density="0" rgba="0.752941 0.752941 0.752941 1" mesh="left_shoulder21"/>
          <body name="right_upper_arm" pos="0.00369547 -0.0040132 -0.0735526" quat="0.999997 0.00106504 -0.00193157 -0.000851617">
            <inertial pos="-0.00916076 0.038781 -0.0388819" quat="0.705029 -0.0236781 0.0250908 0.708339" mass="1.12492" diaginertia="0.00469084 0.00973421 7.46551e-05"/>
            <joint name="right_shoulder_yaw" class="/" pos="0 0 0" axis="-0.00805161 -0.0582347 0.99827" stiffness="0.0357791" range="-2.84861 3.23985" armature="0.00351268" damping="0.0866893" frictionloss="0.169134"/>
            <geom name="//unnamed_geom_38" class="/" type="mesh" density="0" rgba="0.752941 0.752941 0.752941 1" mesh="left_shoulder31"/>
            <geom name="//unnamed_geom_39" class="reward_collision_sphere" size="0.0668799" pos="-0.0119396 0.0152688 -0.0311579"/>
            <body name="right_lower_arm" pos="-0.013213 -0.00804694 -0.105531" quat="1 -0.000434092 -0.000368585 -0.000216958">
              <inertial pos="-0.0117162 0.00881658 -0.072679" quat="0.707256 0.00460744 0.00452422 0.706928" mass="0.465414" diaginertia="0.00853408 0.0245486 6.97434e-06"/>
              <joint name="right_elbow" class="/" pos="0 0 0" axis="0.0343392 -0.998164 0.0499" stiffness="0.0527296" range="-2.96532 2.82735" armature="0.0119375" damping="0.0124762" frictionloss="0.0737751"/>
              <geom name="//unnamed_geom_40" class="/" type="mesh" density="0" rgba="0.752941 0.752941 0.752941 1" mesh="left_forearm"/>
              <geom name="//unnamed_geom_41" class="/" size="0.0278666 0.00835998" pos="0 0 -0.168253" quat="0.707109 0.707105 0 0" type="cylinder" group="3"/>
              <geom name="//unnamed_geom_42" class="reward_collision_sphere" size="0.0278666"/>
              <geom name="//unnamed_geom_43" class="reward_collision_sphere" size="0.0245226" pos="0 0 -0.174484"/>
            </body>
          </body>
        </body>
      </body>
    </body>
  </worldbody>

  <contact>
    <pair class="/" geom1="floor" geom2="left_foot" name="//unnamed_contact_0"/>
    <pair class="/" geom1="floor" geom2="right_foot" name="//unnamed_contact_1"/>
  </contact>

  <actuator>
    <general name="left_hip_yaw" class="/" joint="left_hip_yaw" forcerange="-38.1669 38.1669" gainprm="31.7112" biasprm="0 -31.7112 -0.610027"/>
    <general name="left_hip_abad" class="/" joint="left_hip_abad" forcerange="-23.178 23.178" gainprm="31.7112" biasprm="0 -31.7112 -0.610027"/>
    <general name="left_hip_pitch" class="/" joint="left_hip_pitch" forcerange="-48.6178 48.6178" gainprm="31.7112" biasprm="0 -31.7112 -0.610027"/>
    <general name="left_knee" class="/" joint="left_knee" forcerange="-163.401 163.401" gainprm="31.7112" biasprm="0 -31.7112 -0.610027"/>
    <general name="left_ankle" class="/" joint="left_ankle" forcerange="-43.5076 43.5076" gainprm="31.7112" biasprm="0 -31.7112 -0.610027"/>
    <general name="right_hip_yaw" class="/" joint="right_hip_yaw" forcerange="-38.6392 38.6392" gainprm="31.7112" biasprm="0 -31.7112 -0.610027"/>
    <general name="right_hip_abad" class="/" joint="right_hip_abad" forcerange="-38.0016 38.0016" gainprm="31.7112" biasprm="0 -31.7112 -0.610027"/>
    <general name="right_hip_pitch" class="/" joint="right_hip_pitch" forcerange="-38.9351 38.9351" gainprm="31.7112" biasprm="0 -31.7112 -0.610027"/>
    <general name="right_knee" class="/" joint="right_knee" forcerange="-204.661 204.661" gainprm="31.7112" biasprm="0 -31.7112 -0.610027"/>
    <general name="right_ankle" class="/" joint="right_ankle" forcerange="-94.3537 94.3537" gainprm="31.7112" biasprm="0 -31.7112 -0.610027"/>
    <general name="left_shoulder_pitch" class="/" joint="left_shoulder_pitch" forcerange="-54.4499 54.4499" gainprm="31.7112" biasprm="0 -31.7112 -0.610027"/>
    <general name="left_shoulder_abad" class="/" joint="left_shoulder_abad" forcerange="-40.6933 40.6933" gainprm="31.7112" biasprm="0 -31.7112 -0.610027"/>
    <general name="left_shoulder_yaw" class="/" joint="left_shoulder_yaw" forcerange="-41.9272 41.9272" gainprm="31.7112" biasprm="0 -31.7112 -0.610027"/>
    <general name="left_elbow" class="/" joint="left_elbow" forcerange="-41.766 41.766" gainprm="31.7112" biasprm="0 -31.7112 -0.610027"/>
    <general name="right_shoulder_pitch" class="/" joint="right_shoulder_pitch" forcerange="-17.8931 17.8931" gainprm="31.7112" biasprm="0 -31.7112 -0.610027"/>
    <general name="right_shoulder_abad" class="/" joint="right_shoulder_abad" forcerange="-20.2497 20.2497" gainprm="31.7112" biasprm="0 -31.7112 -0.610027"/>
    <general name="right_shoulder_yaw" class="/" joint="right_shoulder_yaw" forcerange="-57.2401 57.2401" gainprm="31.7112" biasprm="0 -31.7112 -0.610027"/>
    <general name="right_elbow" class="/" joint="right_elbow" forcerange="-63.658 63.658" gainprm="31.7112" biasprm="0 -31.7112 -0.610027"/>
  </actuator>

  <sensor>
    <gyro site="imu" name="imu_angular_velocity"/>
    <velocimeter site="imu" name="imu_linear_velocity"/>
    <framelinvel objtype="site" objname="left_foot" name="left_foot_global_linear_velocity"/>
    <framelinvel objtype="site" objname="right_foot" name="right_foot_global_linear_velocity"/>
  </sensor>

  <keyframe>
    <key name="home" qpos="0 0 0.656 1 0 0 0 0 0 -0.4 0.8 -0.4 0 0 0.4 -0.8 0.4 0 -0.05 0 -0.75 0 0.05 0 0.75"/>
  </keyframe>
</mujoco>
