<mujoco model="humanoid">
  <compiler angle="radian" assetdir="assets" balanceinertia="true" inertiafromgeom="false"/>

  <option timestep="0.005" density="1.2" viscosity="2e-05"/>

  <size nkey="1"/>

  <visual>
    <quality shadowsize="8192"/>
    <map shadowclip="0.5"/>
  </visual>

  <default>
    <default class="/">
      <joint armature="0.01" damping="0.01" frictionloss="0.1"/>
      <geom contype="0" conaffinity="0" group="1" solref="-1000 -80"/>
      <site size="0.01 0.005 0.005" group="5"/>
      <general forcelimited="true" biastype="affine" gainprm="30" biasprm="0 -30 -0.5"/>
      <default class="foot">
        <geom size="0.099 0.0178 0.021" type="box" condim="6" group="4" priority="1" solimp="0.015 1 0.021"/>
      </default>
      <default class="reward_collision_sphere">
        <geom group="5" rgba="1 0 0 1"/>
      </default>
    </default>
  </default>

  <asset>
    <texture type="skybox" colorspace="auto" name="//unnamed_texture_0" builtin="gradient" rgb1="0.95 0.95 0.95" rgb2="0.95 0.95 0.95" width="100" height="600"/>
    <texture type="2d" colorspace="auto" name="texplane" builtin="checker" rgb1="0.345 0.575 0.748" rgb2="0.345 0.575 0.748" markrgb="1 1 1" width="512" height="512"/>
    <material name="MatPlane" class="/" texture="texplane" texuniform="true" texrepeat="2 2" specular="0.9"/>
    <mesh name="torso" class="/" file="torso.stl" scale="0.001 0.001 0.001"/>
    <mesh name="left_hip_yaw" class="/" file="left_hip_yaw.stl" scale="0.001 0.001 0.001"/>
    <mesh name="left_hip_abad" class="/" file="left_hip_abad.stl" scale="0.001 0.001 0.001"/>
    <mesh name="left_leg_upper" class="/" file="left_leg_upper.stl" scale="0.001 0.001 0.001"/>
    <mesh name="left_leg_lower" class="/" file="left_leg_lower.stl" scale="0.001 0.001 0.001"/>
    <mesh name="left_foot" class="/" file="left_foot.stl" scale="0.001 0.001 0.001"/>
    <mesh name="left_hip_yaw1" class="/" content_type="model/stl" file="left_hip_yaw.stl" scale="0.001 -0.001 0.001"/>
    <mesh name="left_hip_abad1" class="/" content_type="model/stl" file="left_hip_abad.stl" scale="0.001 -0.001 0.001"/>
    <mesh name="left_leg_upper1" class="/" content_type="model/stl" file="left_leg_upper.stl" scale="0.001 -0.001 0.001"/>
    <mesh name="left_leg_lower1" class="/" content_type="model/stl" file="left_leg_lower.stl" scale="0.001 -0.001 0.001"/>
    <mesh name="left_foot1" class="/" content_type="model/stl" file="left_foot.stl" scale="0.001 -0.001 0.001"/>
    <mesh name="left_shoulder1" class="/" file="left_shoulder1.stl" scale="0.001 0.001 0.001"/>
    <mesh name="left_shoulder2" class="/" file="left_shoulder2.stl" scale="0.001 0.001 0.001"/>
    <mesh name="left_shoulder3" class="/" file="left_shoulder3.stl" scale="0.001 0.001 0.001"/>
    <mesh name="left_forearm" class="/" file="left_forearm.stl" scale="0.001 0.001 0.001"/>
    <mesh name="left_shoulder11" class="/" content_type="model/stl" file="left_shoulder1.stl" scale="0.001 -0.001 0.001"/>
    <mesh name="left_shoulder21" class="/" content_type="model/stl" file="left_shoulder2.stl" scale="0.001 -0.001 0.001"/>
    <mesh name="left_shoulder31" class="/" content_type="model/stl" file="left_shoulder3.stl" scale="0.001 -0.001 0.001"/>
  </asset>

  <worldbody>
    <geom name="floor" class="/" size="100 100 0.125" type="plane" group="0" material="MatPlane"/>
    <light name="toplight_shadow" class="/" pos="0 0 5" dir="0.0990148 0.0990148 -0.990148" type="directional" ambient="0.04 0.04 0.04" diffuse="0.55 0.55 0.55" specular="0.12 0.12 0.12"/>
    <light name="toplight_fill" class="/" pos="0 0 5" dir="0.0990148 0.0990148 -0.990148" type="directional" castshadow="false" ambient="0.04 0.04 0.04" diffuse="0.3 0.3 0.3" specular="0.08 0.08 0.08"/>
    <body name="trunk" pos="-0.000766711 0.000151326 0.00124678" quat="1 5.30764e-05 8.38412e-05 6.84758e-08">
      <inertial pos="0.0107212 0.000187673 0.158759" quat="0.999987 -0.00173663 -0.00292452 -0.00390403" mass="9.53434" diaginertia="0.316213 0.111377 0.110722"/>
      <joint name="//unnamed_joint_0" type="free"/>
      <geom name="//unnamed_geom_1" class="/" type="mesh" density="0" rgba="0.752941 0.752941 0.752941 1" mesh="torso"/>
      <geom name="//unnamed_geom_2" class="/" size="0.0802918 0.160584 0.187348" pos="0.0264051 0 0.0832076" type="box" group="3" rgba="0.752941 0.752941 0.752941 1"/>
      <geom name="//unnamed_geom_3" class="reward_collision_sphere" size="0.155231" pos="0 0 0.156014"/>
      <site name="imu" class="/" pos="0.00201712 0.0080099 0.158648" size="0.0107056"/>
      <camera name="track" class="/" pos="0 -2.04706 0" quat="0.707107 0.707107 0 0" mode="trackcom"/>
      <camera name="ego_camera" class="/" pos="0.0516621 0 0.312028" quat="-0.5 -0.5 0.5 0.5"/>
      <body name="left_hip_yaw" pos="0.00134476 0.0829448 0.00169522" quat="0.996196 -5.52893e-06 -0.0871424 4.75591e-05">
        <inertial pos="-0.0758257 -0.00305297 -0.065706" quat="0.947511 0.00749588 -0.319633 0.00128341" mass="1.01369" diaginertia="0.00363213 0.0015217 0.000942283"/>
        <joint name="left_hip_yaw" class="/" pos="0 0 0" axis="-0.00537826 -0.000824313 -0.999985" stiffness="0.00383851" range="-3.00983 2.94811" armature="0.0110993" damping="0.0036879" frictionloss="0.0935188"/>
        <geom name="//unnamed_geom_4" class="/" type="mesh" density="0" rgba="0.2 0.2 0.2 1" mesh="left_hip_yaw"/>
        <body name="left_hip_abad" pos="-0.075946 2.81528e-05 -0.0762278" quat="0.976205 0.000375093 0.216846 0.000623685">
          <inertial pos="0.074732 -0.0141823 3.7208e-06" quat="0.579408 0.409151 0.410359 0.573138" mass="1.45039" diaginertia="0.00656676 0.0023176 0.00203159"/>
          <joint name="left_hip_abad" class="/" pos="0 0 0" axis="-1 -0.000452373 -0.000340017" stiffness="0.00453158" range="-2.97743 3.00617" armature="0.0104885" damping="0.0114687" frictionloss="0.0933258"/>
          <geom name="//unnamed_geom_5" class="/" type="mesh" density="0" rgba="0.2 0.2 0.2 1" mesh="left_hip_abad"/>
          <body name="left_upper_leg" pos="0.100298 -0.00117502 -0.0132518" quat="0.991338 -8.12173e-05 -0.131339 -0.000124296">
            <inertial pos="0.00151485 0.025637 -0.0799456" quat="0.725049 0.0363917 -0.0425186 0.686419" mass="3.08778" diaginertia="0.0510286 0.0257859 0.00423051"/>
            <joint name="left_hip_pitch" class="/" pos="0 0 0" axis="-0.00178451 0.999855 0.016962" stiffness="0.0131773" range="-3.0569 2.96935" armature="0.0118934" damping="0.0153917" frictionloss="0.120826"/>
            <geom name="//unnamed_geom_6" class="/" type="mesh" density="0" rgba="0.752941 0.752941 0.752941 1" mesh="left_leg_upper"/>
            <geom name="//unnamed_geom_7" class="reward_collision_sphere" size="0.074939" pos="-0.0172207 0.015353 0.0156014"/>
            <geom name="//unnamed_geom_8" class="reward_collision_sphere" size="0.0214112" pos="-0.0918438 -0.0307059 0.0832076"/>
            <body name="left_lower_leg" pos="-0.0145721 0.000927928 -0.262316" quat="0.999999 -0.000175533 0.000697895 0.000964295">
              <inertial pos="0.00784891 0.00273101 -0.135558" quat="0.999228 -0.00568353 -0.0140924 0.036226" mass="0.427501" diaginertia="0.00571851 0.00342147 0.000295283"/>
              <joint name="left_knee" class="/" pos="0 0 0" axis="2.22631e-05 1 0.000225458" range="0.0541379 2.94683" armature="0.0104019" damping="0.0162501" frictionloss="0.10236"/>
              <geom name="//unnamed_geom_9" class="/" type="mesh" density="0" rgba="0.752941 0.752941 0.752941 1" mesh="left_leg_lower"/>
              <geom name="//unnamed_geom_10" class="reward_collision_sphere" size="0.046034"/>
              <body name="left_foot" pos="-9.65555e-05 -0.00222307 -0.288718" quat="1 0.000116749 -0.000325365 7.37536e-05">
                <inertial pos="0.0253909 0.000181725 -0.0114998" quat="0.518335 0.480725 0.481643 0.51793" mass="0.347378" diaginertia="0.052007 0.0292963 0.0317673"/>
                <joint name="left_ankle" class="/" pos="0 0 0" axis="0.00758376 0.999971 -0.000664543" range="-1.55709 1.55337" armature="0.0108387" damping="0.0225786" frictionloss="0.105511"/>
                <geom name="//unnamed_geom_11" class="/" type="mesh" density="0" rgba="0.2 0.2 0.2 1" mesh="left_foot"/>
                <geom name="left_foot" class="foot" size="0.0963498 0.0204589 0.0226355" pos="0.0321453 0 -0.0260024" quat="0.707109 0.707105 0 0"/>
                <geom name="//unnamed_geom_13" class="reward_collision_sphere" size="0.0267639" pos="0.0321453 0 -0.0208019"/>
                <geom name="//unnamed_geom_14" class="reward_collision_sphere" size="0.0267639" pos="0.114805 0 -0.0260024"/>
                <geom name="//unnamed_geom_15" class="reward_collision_sphere" size="0.0267639" pos="-0.0516621 0 -0.0260024"/>
                <site name="left_foot" class="foot" pos="0.0321453 0 -0.0260024" quat="0.707109 0.707105 0 0" size="0.0107056"/>
              </body>
            </body>
          </body>
        </body>
      </body>
      <body name="right_hip_yaw" pos="-0.000713766 -0.0862877 0.00196132" quat="0.996167 0.00126369 -0.087464 0.000585231">
        <inertial pos="-0.0742604 3.32027e-05 -0.0655173" quat="0.951168 0.000218114 0.308579 -0.00762399" mass="1.09012" diaginertia="0.00385708 0.00157363 0.00097657"/>
        <joint name="right_hip_yaw" class="/" pos="0 0 0" axis="-0.0127871 0.000691373 -0.999918" stiffness="0.00396738" range="-2.98201 3.05028" armature="0.0107106" damping="0.0142507" frictionloss="0.0927656"/>
        <geom name="//unnamed_geom_16" class="/" type="mesh" density="0" rgba="0.2 0.2 0.2 1" mesh="left_hip_yaw1"/>
        <body name="right_hip_abad" pos="-0.0742465 -0.00139636 -0.0765773" quat="0.976475 -0.000327875 0.21563 -0.000532423">
          <inertial pos="0.077044 0.0131433 -0.00267516" quat="0.412033 0.572708 0.581688 0.404813" mass="1.41464" diaginertia="0.00660818 0.0021603 0.00197508"/>
          <joint name="right_hip_abad" class="/" pos="0 0 0" axis="-0.999937 0.00278187 -0.0108456" stiffness="0.00628617" range="-2.96696 2.99949" armature="0.0101286" damping="0.0108524" frictionloss="0.109571"/>
          <geom name="//unnamed_geom_17" class="/" type="mesh" density="0" rgba="0.2 0.2 0.2 1" mesh="left_hip_abad1"/>
          <body name="right_upper_leg" pos="0.103099 0.00449163 -0.013966" quat="0.991466 0.00019318 -0.130363 -0.00062885">
            <inertial pos="-0.00190344 -0.0276655 -0.0824394" quat="0.681385 0.0485238 -0.034593 0.729495" mass="3.24289" diaginertia="0.0530969 0.0283473 0.00430834"/>
            <joint name="right_hip_pitch" class="/" pos="0 0 0" axis="-0.00794372 -0.999941 0.00745927" stiffness="0.00389139" range="-3.00307 2.99011" armature="0.00993994" damping="0.011759" frictionloss="0.113032"/>
            <geom name="//unnamed_geom_18" class="/" type="mesh" density="0" rgba="0.752941 0.752941 0.752941 1" mesh="left_leg_upper1"/>
            <geom name="//unnamed_geom_19" class="reward_collision_sphere" size="0.074939" pos="-0.0172207 -0.015353 0.0156014"/>
            <geom name="//unnamed_geom_20" class="reward_collision_sphere" size="0.0214112" pos="-0.0918438 0.0307059 0.0832076"/>
            <body name="right_lower_leg" pos="-0.0149136 -0.00271531 -0.258792" quat="0.999999 -0.00131608 -0.000544917 0.000137639">
              <inertial pos="0.00525223 0.00217928 -0.134484" quat="0.998864 0.00547231 0.0153262 -0.0447909" mass="0.435331" diaginertia="0.00565116 0.00320865 0.000293542"/>
              <joint name="right_knee" class="/" pos="0 0 0" axis="-0.00160371 -0.999958 0.00904947" range="-3.00049 0.0441671" armature="0.01234" damping="0.0209873" frictionloss="0.114136"/>
              <geom name="//unnamed_geom_21" class="/" type="mesh" density="0" rgba="0.752941 0.752941 0.752941 1" mesh="left_leg_lower1"/>
              <geom name="//unnamed_geom_22" class="reward_collision_sphere" size="0.046034"/>
              <body name="right_foot" pos="-0.00282316 -0.00123323 -0.289631" quat="1 0.000231738 -0.000213075 -0.00046196">
                <inertial pos="0.0273186 -0.000161691 -0.0143867" quat="0.479962 0.519878 0.518587 0.480033" mass="0.33675" diaginertia="0.0520993 0.0284229 0.0320609"/>
                <joint name="right_ankle" class="/" pos="0 0 0" axis="-0.00258763 -0.999943 0.0103958" range="-1.54232 1.50955" armature="0.011075" damping="0.0141925" frictionloss="0.109226"/>
                <geom name="//unnamed_geom_23" class="/" type="mesh" density="0" rgba="0.2 0.2 0.2 1" mesh="left_foot1"/>
                <geom name="right_foot" class="foot" size="0.0923824 0.0195414 0.0233193" pos="0.0321453 0 -0.0260024" quat="0.707109 0.707105 0 0"/>
                <geom name="//unnamed_geom_25" class="reward_collision_sphere" size="0.0267639" pos="0.0321453 0 -0.0208019"/>
                <geom name="//unnamed_geom_26" class="reward_collision_sphere" size="0.0267639" pos="0.114805 0 -0.0260024"/>
                <geom name="//unnamed_geom_27" class="reward_collision_sphere" size="0.0267639" pos="-0.0516621 0 -0.0260024"/>
                <site name="right_foot" class="foot" pos="0.0321453 0 -0.0260024" quat="0.707109 0.707105 0 0" size="0.0107056"/>
              </body>
            </body>
          </body>
        </body>
      </body>
      <body name="left_shoulder" pos="0.0234724 0.178096 0.318404" quat="0.999999 -0.000223378 0.000411979 0.00122077">
        <inertial pos="0.0120589 0.0526047 -0.00210498" quat="0.71058 0.703361 0.0153728 0.011045" mass="0.941444" diaginertia="0.002712 0.000989619 0.000929897"/>
        <joint name="left_shoulder_pitch" class="/" pos="0 0 0" axis="0.00311801 0.999994 0.00166945" range="-3.04956 3.00151" armature="0.0116391" damping="0.00623314" frictionloss="0.0952528"/>
        <geom name="//unnamed_geom_28" class="/" type="mesh" density="0" rgba="0.2 0.2 0.2 1" mesh="left_shoulder1"/>
        <body name="left_shoulder_2" pos="0.00193646 0.057193 -0.000699841" quat="1 0.000120481 -6.44408e-05 -0.000347898">
          <inertial pos="-0.00257304 -0.00170931 -0.0858447" quat="0.00892346 0.758455 -0.00954794 0.651594" mass="0.987235" diaginertia="0.00239789 0.00126997 0.00132839"/>
          <joint name="left_shoulder_abad" class="/" pos="0 0 0" axis="-0.999893 -0.00354726 0.0141996" range="-3.0009 3.05424" armature="0.0120569" damping="0" frictionloss="0.114108"/>
          <geom name="//unnamed_geom_29" class="/" type="mesh" density="0" rgba="0.752941 0.752941 0.752941 1" mesh="left_shoulder2"/>
          <body name="left_upper_arm" pos="-0.00107222 0.000331333 -0.10694" quat="1 -0.000241227 0.000229943 0.000626441">
            <inertial pos="-0.00242689 -0.01656 -0.0657967" quat="0.699542 -0.0233637 0.0223641 0.71386" mass="1.11576" diaginertia="0.00377438 0.00160549 0.00097392"/>
            <joint name="left_shoulder_yaw" class="/" pos="0 0 0" axis="0.00196027 0.00445693 0.999988" range="-3.00272 2.9842" armature="0.0118364" damping="0.00724176" frictionloss="0.122032"/>
            <geom name="//unnamed_geom_30" class="/" type="mesh" density="0" rgba="0.752941 0.752941 0.752941 1" mesh="left_shoulder3"/>
            <geom name="//unnamed_geom_31" class="reward_collision_sphere" size="0.0642335" pos="-0.0114805 -0.0102353 -0.0520047"/>
            <body name="left_lower_arm" pos="0.00149462 0.00272605 -0.162857" quat="1 0.000589298 -0.000278978 -0.000387824">
              <inertial pos="-0.00615426 2.27219e-05 -0.102453" quat="0.709583 -0.000138204 0.0038358 0.704611" mass="0.437668" diaginertia="0.00748197 0.00389556 9.67233e-05"/>
              <joint name="left_elbow" class="/" pos="0 0 0" axis="-0.000565074 0.999991 0.0041343" range="-2.98421 3.00559" armature="0.0101772" damping="0.0103184" frictionloss="0.105937"/>
              <geom name="//unnamed_geom_32" class="/" type="mesh" density="0" rgba="0.752941 0.752941 0.752941 1" mesh="left_forearm"/>
              <geom name="//unnamed_geom_33" class="/" size="0.0267639 0.00802918" pos="0 0 -0.280826" quat="0.707109 0.707105 0 0" type="cylinder" group="3"/>
              <geom name="//unnamed_geom_34" class="reward_collision_sphere" size="0.0267639"/>
              <geom name="//unnamed_geom_35" class="reward_collision_sphere" size="0.0235523" pos="0 0 -0.291227"/>
            </body>
          </body>
        </body>
      </body>
      <body name="right_shoulder" pos="0.0217255 -0.177206 0.315381" quat="1 0.000268131 0.000717732 0.000272858">
        <inertial pos="0.013529 -0.0546545 -0.0023084" quat="0.708923 0.705176 -0.0111448 -0.00553209" mass="0.994891" diaginertia="0.00270707 0.00103775 0.000940206"/>
        <joint name="right_shoulder_pitch" class="/" pos="0 0 0" axis="-0.00307303 -0.9999 -0.0137886" stiffness="0.0066455" range="-2.9671 2.94316" armature="0.0101963" damping="0.00912097" frictionloss="0.108105"/>
        <geom name="//unnamed_geom_36" class="/" type="mesh" density="0" rgba="0.2 0.2 0.2 1" mesh="left_shoulder11"/>
        <body name="right_shoulder_2" pos="0.00236946 -0.0586569 0.00275965" quat="0.999999 -0.000778899 -0.00031384 -0.000938684">
          <inertial pos="0.000446745 -0.00210363 -0.0860861" quat="0.00447078 0.651286 0.0125978 0.758715" mass="0.994" diaginertia="0.00250382 0.00134259 0.00144802"/>
          <joint name="right_shoulder_abad" class="/" pos="0 0 0" axis="-0.999998 0.000900705 0.00160876" stiffness="0.00598994" range="-2.96031 2.94385" armature="0.00906132" damping="0.0185313" frictionloss="0.101442"/>
          <geom name="//unnamed_geom_37" class="/" type="mesh" density="0" rgba="0.752941 0.752941 0.752941 1" mesh="left_shoulder21"/>
          <body name="right_upper_arm" pos="0.000577384 0.00149743 -0.103806" quat="1 0.000549381 -7.30762e-05 -0.000356184">
            <inertial pos="0.00262673 0.0152401 -0.0653004" quat="0.704351 -0.020701 0.0271876 0.709028" mass="1.11848" diaginertia="0.00352249 0.00150945 0.000959964"/>
            <joint name="right_shoulder_yaw" class="/" pos="0 0 0" axis="-0.00761709 -0.00675646 0.999948" range="-3.05306 2.95371" armature="0.0118432" damping="0.00530056" frictionloss="0.0924317"/>
            <geom name="//unnamed_geom_38" class="/" type="mesh" density="0" rgba="0.752941 0.752941 0.752941 1" mesh="left_shoulder31"/>
            <geom name="//unnamed_geom_39" class="reward_collision_sphere" size="0.0642335" pos="-0.0114805 0.0102353 -0.0520047"/>
            <body name="right_lower_arm" pos="0.00151669 0.00326618 -0.161238" quat="1 -0.000384605 -6.77192e-05 0.000350003">
              <inertial pos="-0.00817401 -0.00285031 -0.101667" quat="0.708722 0.00693417 0.00691569 0.70542" mass="0.437973" diaginertia="0.00737849 0.00420596 9.62677e-05"/>
              <joint name="right_elbow" class="/" pos="0 0 0" axis="-0.00286789 -0.999963 -0.0081095" range="-2.98321 3.05615" armature="0.0110808" damping="0.0154123" frictionloss="0.119847"/>
              <geom name="//unnamed_geom_40" class="/" type="mesh" density="0" rgba="0.752941 0.752941 0.752941 1" mesh="left_forearm"/>
              <geom name="//unnamed_geom_41" class="/" size="0.0267639 0.00802918" pos="0 0 -0.280826" quat="0.707109 0.707105 0 0" type="cylinder" group="3"/>
              <geom name="//unnamed_geom_42" class="reward_collision_sphere" size="0.0267639"/>
              <geom name="//unnamed_geom_43" class="reward_collision_sphere" size="0.0235523" pos="0 0 -0.291227"/>
            </body>
          </body>
        </body>
      </body>
    </body>
  </worldbody>

  <contact>
    <pair class="/" geom1="floor" geom2="left_foot" name="//unnamed_contact_0"/>
    <pair class="/" geom1="floor" geom2="right_foot" name="//unnamed_contact_1"/>
  </contact>

  <actuator>
    <general name="left_hip_yaw" class="/" joint="left_hip_yaw" forcerange="-37.5082 37.5082" gainprm="31.6438" biasprm="0 -31.6438 -0.514232"/>
    <general name="left_hip_abad" class="/" joint="left_hip_abad" forcerange="-40.3261 40.3261" gainprm="31.6438" biasprm="0 -31.6438 -0.514232"/>
    <general name="left_hip_pitch" class="/" joint="left_hip_pitch" forcerange="-84.8489 84.8489" gainprm="31.6438" biasprm="0 -31.6438 -0.514232"/>
    <general name="left_knee" class="/" joint="left_knee" forcerange="-152.713 152.713" gainprm="31.6438" biasprm="0 -31.6438 -0.514232"/>
    <general name="left_ankle" class="/" joint="left_ankle" forcerange="-79.3472 79.3472" gainprm="31.6438" biasprm="0 -31.6438 -0.514232"/>
    <general name="right_hip_yaw" class="/" joint="right_hip_yaw" forcerange="-37.779 37.779" gainprm="31.6438" biasprm="0 -31.6438 -0.514232"/>
    <general name="right_hip_abad" class="/" joint="right_hip_abad" forcerange="-36.9405 36.9405" gainprm="31.6438" biasprm="0 -31.6438 -0.514232"/>
    <general name="right_hip_pitch" class="/" joint="right_hip_pitch" forcerange="-81.5602 81.5602" gainprm="31.6438" biasprm="0 -31.6438 -0.514232"/>
    <general name="right_knee" class="/" joint="right_knee" forcerange="-138.282 138.282" gainprm="31.6438" biasprm="0 -31.6438 -0.514232"/>
    <general name="right_ankle" class="/" joint="right_ankle" forcerange="-66.4718 66.4718" gainprm="31.6438" biasprm="0 -31.6438 -0.514232"/>
    <general name="left_shoulder_pitch" class="/" joint="left_shoulder_pitch" forcerange="-33.0283 33.0283" gainprm="31.6438" biasprm="0 -31.6438 -0.514232"/>
    <general name="left_shoulder_abad" class="/" joint="left_shoulder_abad" forcerange="-37.2874 37.2874" gainprm="31.6438" biasprm="0 -31.6438 -0.514232"/>
    <general name="left_shoulder_yaw" class="/" joint="left_shoulder_yaw" forcerange="-36.7149 36.7149" gainprm="31.6438" biasprm="0 -31.6438 -0.514232"/>
    <general name="left_elbow" class="/" joint="left_elbow" forcerange="-65.0759 65.0759" gainprm="31.6438" biasprm="0 -31.6438 -0.514232"/>
    <general name="right_shoulder_pitch" class="/" joint="right_shoulder_pitch" forcerange="-38.2836 38.2836" gainprm="31.6438" biasprm="0 -31.6438 -0.514232"/>
    <general name="right_shoulder_abad" class="/" joint="right_shoulder_abad" forcerange="-39.2599 39.2599" gainprm="31.6438" biasprm="0 -31.6438 -0.514232"/>
    <general name="right_shoulder_yaw" class="/" joint="right_shoulder_yaw" forcerange="-34.1118 34.1118" gainprm="31.6438" biasprm="0 -31.6438 -0.514232"/>
    <general name="right_elbow" class="/" joint="right_elbow" forcerange="-61.2045 61.2045" gainprm="31.6438" biasprm="0 -31.6438 -0.514232"/>
  </actuator>

  <sensor>
    <gyro site="imu" name="imu_angular_velocity"/>
    <velocimeter site="imu" name="imu_linear_velocity"/>
    <framelinvel objtype="site" objname="left_foot" name="left_foot_global_linear_velocity"/>
    <framelinvel objtype="site" objname="right_foot" name="right_foot_global_linear_velocity"/>
  </sensor>

  <keyframe>
    <key name="home" qpos="0 0 0.656 1 0 0 0 0 0 -0.4 0.8 -0.4 0 0 0.4 -0.8 0.4 0 -0.05 0 -0.75 0 0.05 0 0.75"/>
  </keyframe>
</mujoco>
