<mujoco model="humanoid">
  <compiler angle="radian" assetdir="assets" balanceinertia="true" inertiafromgeom="false"/>

  <option timestep="0.005" density="1.2" viscosity="2e-05"/>

  <size nkey="1"/>

  <visual>
    <quality shadowsize="8192"/>
    <map shadowclip="0.5"/>
  </visual>

  <default>
    <default class="/">
      <joint armature="0.01" damping="0.01" frictionloss="0.1"/>
      <geom contype="0" conaffinity="0" group="1" solref="-1000 -80"/>
      <site size="0.01 0.005 0.005" group="5"/>
      <general forcelimited="true" biastype="affine" gainprm="30" biasprm="0 -30 -0.5"/>
      <default class="foot">
        <geom size="0.099 0.0178 0.021" type="box" condim="6" group="4" priority="1" solimp="0.015 1 0.021"/>
      </default>
      <default class="reward_collision_sphere">
        <geom group="5" rgba="1 0 0 1"/>
      </default>
    </default>
  </default>

  <asset>
    <texture type="skybox" colorspace="auto" name="//unnamed_texture_0" builtin="gradient" rgb1="0.95 0.95 0.95" rgb2="0.95 0.95 0.95" width="100" height="600"/>
    <texture type="2d" colorspace="auto" name="texplane" builtin="checker" rgb1="0.345 0.575 0.748" rgb2="0.345 0.575 0.748" markrgb="1 1 1" width="512" height="512"/>
    <material name="MatPlane" class="/" texture="texplane" texuniform="true" texrepeat="2 2" specular="0.9"/>
    <mesh name="torso" class="/" file="torso.stl" scale="0.001 0.001 0.001"/>
    <mesh name="left_hip_yaw" class="/" file="left_hip_yaw.stl" scale="0.001 0.001 0.001"/>
    <mesh name="left_hip_abad" class="/" file="left_hip_abad.stl" scale="0.001 0.001 0.001"/>
    <mesh name="left_leg_upper" class="/" file="left_leg_upper.stl" scale="0.001 0.001 0.001"/>
    <mesh name="left_leg_lower" class="/" file="left_leg_lower.stl" scale="0.001 0.001 0.001"/>
    <mesh name="left_foot" class="/" file="left_foot.stl" scale="0.001 0.001 0.001"/>
    <mesh name="left_hip_yaw1" class="/" content_type="model/stl" file="left_hip_yaw.stl" scale="0.001 -0.001 0.001"/>
    <mesh name="left_hip_abad1" class="/" content_type="model/stl" file="left_hip_abad.stl" scale="0.001 -0.001 0.001"/>
    <mesh name="left_leg_upper1" class="/" content_type="model/stl" file="left_leg_upper.stl" scale="0.001 -0.001 0.001"/>
    <mesh name="left_leg_lower1" class="/" content_type="model/stl" file="left_leg_lower.stl" scale="0.001 -0.001 0.001"/>
    <mesh name="left_foot1" class="/" content_type="model/stl" file="left_foot.stl" scale="0.001 -0.001 0.001"/>
    <mesh name="left_shoulder1" class="/" file="left_shoulder1.stl" scale="0.001 0.001 0.001"/>
    <mesh name="left_shoulder2" class="/" file="left_shoulder2.stl" scale="0.001 0.001 0.001"/>
    <mesh name="left_shoulder3" class="/" file="left_shoulder3.stl" scale="0.001 0.001 0.001"/>
    <mesh name="left_forearm" class="/" file="left_forearm.stl" scale="0.001 0.001 0.001"/>
    <mesh name="left_shoulder11" class="/" content_type="model/stl" file="left_shoulder1.stl" scale="0.001 -0.001 0.001"/>
    <mesh name="left_shoulder21" class="/" content_type="model/stl" file="left_shoulder2.stl" scale="0.001 -0.001 0.001"/>
    <mesh name="left_shoulder31" class="/" content_type="model/stl" file="left_shoulder3.stl" scale="0.001 -0.001 0.001"/>
  </asset>

  <worldbody>
    <geom name="floor" class="/" size="100 100 0.125" type="plane" group="0" material="MatPlane"/>
    <light name="toplight_shadow" class="/" pos="0 0 5" dir="0.0990148 0.0990148 -0.990148" type="directional" ambient="0.04 0.04 0.04" diffuse="0.55 0.55 0.55" specular="0.12 0.12 0.12"/>
    <light name="toplight_fill" class="/" pos="0 0 5" dir="0.0990148 0.0990148 -0.990148" type="directional" castshadow="false" ambient="0.04 0.04 0.04" diffuse="0.3 0.3 0.3" specular="0.08 0.08 0.08"/>
    <body name="trunk" pos="0.002625 0.000677854 0.000227918" quat="1 6.07136e-05 0.000164989 -0.00050405">
      <inertial pos="0.0107385 0.00308689 0.15371" quat="0.999978 -0.00639263 -0.00180391 -0.000669512" mass="10.0401" diaginertia="0.238068 0.200704 0.100695"/>
      <joint name="//unnamed_joint_0" type="free"/>
      <geom name="//unnamed_geom_1" class="/" type="mesh" density="0" rgba="0.752941 0.752941 0.752941 1" mesh="torso"/>
      <geom name="//unnamed_geom_2" class="/" size="0.0812339 0.162468 0.189546" pos="0.0247181 0 0.081732" type="box" group="3" rgba="0.752941 0.752941 0.752941 1"/>
      <geom name="//unnamed_geom_3" class="reward_collision_sphere" size="0.157052" pos="0 0 0.153247"/>
      <site name="imu" class="/" pos="0.00667937 0.0120656 0.146834" size="0.0108312"/>
      <camera name="track" class="/" pos="0 -2.30601 0" quat="0.707107 0.707107 0 0" mode="trackcom"/>
      <camera name="ego_camera" class="/" pos="0.0483615 0 0.306495" quat="-0.5 -0.5 0.5 0.5"/>
      <body name="left_hip_yaw" pos="-0.00114326 0.0964526 0.00113944" quat="0.996246 -0.000462291 -0.0865681 0.000423901">
        <inertial pos="-0.0726709 -0.00159199 -0.0625999" quat="0.949762 -0.0028483 -0.312956 0.00169684" mass="1.04752" diaginertia="0.00265101 0.00285095 0.000873247"/>
        <joint name="left_hip_yaw" class="/" pos="0 0 0" axis="-0.00345555 0.0104342 -0.99994" stiffness="0.00401295" range="-2.95484 2.96561" armature="0.0104193" damping="0.0291063" frictionloss="0.11722"/>
        <geom name="//unnamed_geom_4" class="/" type="mesh" density="0" rgba="0.2 0.2 0.2 1" mesh="left_hip_yaw"/>
        <body name="left_hip_abad" pos="-0.0716547 0.000972077 -0.0771101" quat="0.976379 8.89569e-05 0.216065 -0.000208946">
          <inertial pos="0.0736574 -0.0119772 -0.0022386" quat="0.57867 0.404586 0.413618 0.57478" mass="1.51484" diaginertia="0.00474935 0.00385729 0.00177892"/>
          <joint name="left_hip_abad" class="/" pos="0 0 0" axis="-0.999968 -0.00738406 0.00298713" stiffness="0.00880436" range="-2.9813 3.01044" armature="0.0106184" damping="0.025399" frictionloss="0.104377"/>
          <geom name="//unnamed_geom_5" class="/" type="mesh" density="0" rgba="0.2 0.2 0.2 1" mesh="left_hip_abad"/>
          <body name="left_upper_leg" pos="0.0961361 -0.00480353 -0.0153585" quat="0.991577 0.000223742 -0.129513 -0.00116504">
            <inertial pos="0.000904242 0.0295172 -0.0827519" quat="0.729781 0.0370751 -0.048671 0.680937" mass="3.48476" diaginertia="0.037319 0.0510696 0.00399738"/>
            <joint name="left_hip_pitch" class="/" pos="0 0 0" axis="-0.00265259 0.999996 -0.000188364" range="-2.96011 2.97595" armature="0.0131974" damping="0.0176389" frictionloss="0.109718"/>
            <geom name="//unnamed_geom_6" class="/" type="mesh" density="0" rgba="0.752941 0.752941 0.752941 1" mesh="left_leg_upper"/>
            <geom name="//unnamed_geom_7" class="reward_collision_sphere" size="0.0758183" pos="-0.0161205 0.0172951 0.0153247"/>
            <geom name="//unnamed_geom_8" class="reward_collision_sphere" size="0.0216624" pos="-0.0859759 -0.0345902 0.081732"/>
            <body name="left_lower_leg" pos="-0.0110896 -0.00351551 -0.256613" quat="1 -0.000241696 -0.000475805 -0.000433509">
              <inertial pos="0.00337931 0.0020394 -0.13529" quat="0.998749 -0.0062679 -0.0142668 0.0475123" mass="0.427872" diaginertia="0.004059 0.0058202 0.000264561"/>
              <joint name="left_knee" class="/" pos="0 0 0" axis="-0.00820405 0.999939 -0.00743694" range="-0.0528297 2.98467" armature="0.0111513" damping="0.0115465" frictionloss="0.109093"/>
              <geom name="//unnamed_geom_9" class="/" type="mesh" density="0" rgba="0.752941 0.752941 0.752941 1" mesh="left_leg_lower"/>
              <geom name="//unnamed_geom_10" class="reward_collision_sphere" size="0.0465741"/>
              <body name="left_foot" pos="-0.00149794 0.00148663 -0.282258" quat="1 -8.25655e-06 3.6704e-05 1.30195e-05">
                <inertial pos="0.0231144 0.00110571 -0.0142649" quat="0.520957 0.479428 0.48116 0.51695" mass="0.355954" diaginertia="0.040297 0.0550674 0.0307241"/>
                <joint name="left_ankle" class="/" pos="0 0 0" axis="0.00343506 0.999979 0.00554293" range="-1.50083 1.48291" armature="0.0117153" damping="0.0194936" frictionloss="0.118633"/>
                <geom name="//unnamed_geom_11" class="/" type="mesh" density="0" rgba="0.2 0.2 0.2 1" mesh="left_foot"/>
                <geom name="left_foot" class="foot" size="0.114449 0.0207574 0.0226887" pos="0.0300916 0 -0.0255412" quat="0.707109 0.707105 0 0"/>
                <geom name="//unnamed_geom_13" class="reward_collision_sphere" size="0.027078" pos="0.0300916 0 -0.020433"/>
                <geom name="//unnamed_geom_14" class="reward_collision_sphere" size="0.027078" pos="0.10747 0 -0.0255412"/>
                <geom name="//unnamed_geom_15" class="reward_collision_sphere" size="0.027078" pos="-0.0483615 0 -0.0255412"/>
                <site name="left_foot" class="foot" pos="0.0300916 0 -0.0255412" quat="0.707109 0.707105 0 0" size="0.0108312"/>
              </body>
            </body>
          </body>
        </body>
      </body>
      <body name="right_hip_yaw" pos="-0.00116372 -0.0926185 -0.00180313" quat="0.996136 -0.000915075 -0.0878138 0.000822149">
        <inertial pos="-0.0713763 -0.00250443 -0.0620163" quat="0.946305 -0.00288263 0.323262 0.000679289" mass="1.04033" diaginertia="0.00271834 0.00275693 0.000862947"/>
        <joint name="right_hip_yaw" class="/" pos="0 0 0" axis="0.0129088 0.00267516 -0.999913" range="-3.04274 2.9504" armature="0.00957404" damping="0.00710743" frictionloss="0.110608"/>
        <geom name="//unnamed_geom_16" class="/" type="mesh" density="0" rgba="0.2 0.2 0.2 1" mesh="left_hip_yaw1"/>
        <body name="right_hip_abad" pos="-0.0710923 -0.00310045 -0.079317" quat="0.976277 -0.000654234 0.216524 0.000836277">
          <inertial pos="0.0726202 0.013714 0.00271911" quat="0.412491 0.575816 0.578092 0.405089" mass="1.52083" diaginertia="0.00484463 0.00403749 0.00183757"/>
          <joint name="right_hip_abad" class="/" pos="0 0 0" axis="-0.999929 0.0113117 -0.00376089" range="-3.0053 2.95583" armature="0.0118287" damping="0.0384466" frictionloss="0.109167"/>
          <geom name="//unnamed_geom_17" class="/" type="mesh" density="0" rgba="0.2 0.2 0.2 1" mesh="left_hip_abad1"/>
          <body name="right_upper_leg" pos="0.0982697 0.00122271 -0.0135817" quat="0.991444 -3.57892e-05 -0.130529 5.03458e-05">
            <inertial pos="-0.000933331 -0.0301341 -0.0803544" quat="0.680852 0.0494354 -0.0341184 0.729954" mass="3.44986" diaginertia="0.0375884 0.0496884 0.00391211"/>
            <joint name="right_hip_pitch" class="/" pos="0 0 0" axis="-0.0043197 -0.999939 0.0102094" stiffness="0.00365637" range="-3.00007 3.0058" armature="0.00946006" damping="0.0116085" frictionloss="0.119013"/>
            <geom name="//unnamed_geom_18" class="/" type="mesh" density="0" rgba="0.752941 0.752941 0.752941 1" mesh="left_leg_upper1"/>
            <geom name="//unnamed_geom_19" class="reward_collision_sphere" size="0.0758183" pos="-0.0161205 -0.0172951 0.0153247"/>
            <geom name="//unnamed_geom_20" class="reward_collision_sphere" size="0.0216624" pos="-0.0859759 0.0345902 0.081732"/>
            <body name="right_lower_leg" pos="-0.0108947 -0.00117798 -0.253658" quat="1 -0.000291105 0.000493814 -3.25022e-05">
              <inertial pos="0.00390258 -0.00171853 -0.134745" quat="0.998712 0.00791791 0.0151312 -0.0477799" mass="0.438277" diaginertia="0.00420428 0.0059249 0.000259145"/>
              <joint name="right_knee" class="/" pos="0 0 0" axis="0.00148492 -0.999999 -0.00017263" stiffness="0.00377839" range="-2.99291 0.0476073" armature="0.00910215" damping="0.02567" frictionloss="0.106393"/>
              <geom name="//unnamed_geom_21" class="/" type="mesh" density="0" rgba="0.752941 0.752941 0.752941 1" mesh="left_leg_lower1"/>
              <geom name="//unnamed_geom_22" class="reward_collision_sphere" size="0.0465741"/>
              <body name="right_foot" pos="0.00167307 -0.00089396 -0.282862" quat="1 0.000121155 -0.000401143 -0.000887424">
                <inertial pos="0.0226329 -3.31338e-05 -0.0107208" quat="0.472442 0.514248 0.520522 0.49133" mass="0.337191" diaginertia="0.038711 0.05189 0.0295936"/>
                <joint name="right_ankle" class="/" pos="0 0 0" axis="0.00427849 -0.999958 0.00815656" range="-1.48407 1.49547" armature="0.00924209" damping="0.0264345" frictionloss="0.117627"/>
                <geom name="//unnamed_geom_23" class="/" type="mesh" density="0" rgba="0.2 0.2 0.2 1" mesh="left_foot1"/>
                <geom name="right_foot" class="foot" size="0.120282 0.0166629 0.0207278" pos="0.0300916 0 -0.0255412" quat="0.707109 0.707105 0 0"/>
                <geom name="//unnamed_geom_25" class="reward_collision_sphere" size="0.027078" pos="0.0300916 0 -0.020433"/>
                <geom name="//unnamed_geom_26" class="reward_collision_sphere" size="0.027078" pos="0.10747 0 -0.0255412"/>
                <geom name="//unnamed_geom_27" class="reward_collision_sphere" size="0.027078" pos="-0.0483615 0 -0.0255412"/>
                <site name="right_foot" class="foot" pos="0.0300916 0 -0.0255412" quat="0.707109 0.707105 0 0" size="0.0108312"/>
              </body>
            </body>
          </body>
        </body>
      </body>
      <body name="left_shoulder" pos="0.0199553 0.203458 0.313289" quat="0.999999 -0.000302891 0.00152276 -4.88847e-05">
        <inertial pos="0.00840416 0.0641667 -0.00261576" quat="0.715715 0.698196 0.0051183 0.0157599" mass="0.983271" diaginertia="0.00193076 0.00174187 0.00086637"/>
        <joint name="left_shoulder_pitch" class="/" pos="0 0 0" axis="-0.00728815 0.999965 0.00400181" range="-2.99883 3.02811" armature="0.0098179" damping="0.00685777" frictionloss="0.108819"/>
        <geom name="//unnamed_geom_28" class="/" type="mesh" density="0" rgba="0.2 0.2 0.2 1" mesh="left_shoulder1"/>
        <body name="left_shoulder_2" pos="0.00442769 0.0683289 -0.0012507" quat="1 -5.22027e-05 0.000377371 0.000594702">
          <inertial pos="0.000560921 -0.00106445 -0.0870336" quat="0.00577862 0.752551 0.00760923 0.658464" mass="0.993789" diaginertia="0.00181604 0.00230228 0.00125371"/>
          <joint name="left_shoulder_abad" class="/" pos="0 0 0" axis="-0.999864 0.0037801 0.0160445" range="-3.04283 2.94665" armature="0.0110598" damping="0.0144806" frictionloss="0.107813"/>
          <geom name="//unnamed_geom_29" class="/" type="mesh" density="0" rgba="0.752941 0.752941 0.752941 1" mesh="left_shoulder2"/>
          <body name="left_upper_arm" pos="-0.00173033 0.00228679 -0.108654" quat="1 -0.000106832 -1.25089e-05 -0.000946605">
            <inertial pos="0.0014681 -0.0194025 -0.0620573" quat="0.706896 -0.026803 0.0365433 0.705864" mass="1.18566" diaginertia="0.00259851 0.00295727 0.000937391"/>
            <joint name="left_shoulder_yaw" class="/" pos="0 0 0" axis="-0.00409038 0.0135543 0.9999" range="-2.99381 3.05111" armature="0.0105132" damping="0.0169883" frictionloss="0.112985"/>
            <geom name="//unnamed_geom_30" class="/" type="mesh" density="0" rgba="0.752941 0.752941 0.752941 1" mesh="left_shoulder3"/>
            <geom name="//unnamed_geom_31" class="reward_collision_sphere" size="0.0649871" pos="-0.010747 -0.0115301 -0.0510825"/>
            <body name="left_lower_arm" pos="0.00204492 0.002984 -0.159823" quat="0.999999 0.000698784 0.000925627 -0.000354561">
              <inertial pos="-0.00820387 -0.00441691 -0.101664" quat="0.707493 0.0100986 -0.00708694 0.706613" mass="0.43232" diaginertia="0.00494839 0.00677524 8.64408e-05"/>
              <joint name="left_elbow" class="/" pos="0 0 0" axis="0.0102616 0.999947 0.000985539" range="-3.04945 3.00811" armature="0.0106723" damping="0.0335934" frictionloss="0.0860628"/>
              <geom name="//unnamed_geom_32" class="/" type="mesh" density="0" rgba="0.752941 0.752941 0.752941 1" mesh="left_forearm"/>
              <geom name="//unnamed_geom_33" class="/" size="0.027078 0.00812339" pos="0 0 -0.275845" quat="0.707109 0.707105 0 0" type="cylinder" group="3"/>
              <geom name="//unnamed_geom_34" class="reward_collision_sphere" size="0.027078"/>
              <geom name="//unnamed_geom_35" class="reward_collision_sphere" size="0.0238286" pos="0 0 -0.286062"/>
            </body>
          </body>
        </body>
      </body>
      <body name="right_shoulder" pos="0.019683 -0.202389 0.308088" quat="1 0.000196608 2.92838e-05 0.000190053">
        <inertial pos="0.00731207 -0.0594547 0.00265036" quat="0.714304 0.699607 -0.00439282 -0.0173266" mass="1.00782" diaginertia="0.00185295 0.00173374 0.000835098"/>
        <joint name="right_shoulder_pitch" class="/" pos="0 0 0" axis="-0.000831402 -0.99999 0.00433841" range="-2.95472 3.00191" armature="0.0121069" damping="0.019264" frictionloss="0.0955239"/>
        <geom name="//unnamed_geom_36" class="/" type="mesh" density="0" rgba="0.2 0.2 0.2 1" mesh="left_shoulder11"/>
        <body name="right_shoulder_2" pos="0.00389809 -0.063251 0.0043347" quat="1 -1.59227e-05 3.11314e-05 3.9286e-05">
          <inertial pos="-0.00152215 -0.00171746 -0.0849424" quat="-0.00202199 0.654219 0.0168724 0.756114" mass="1.03442" diaginertia="0.00176405 0.00255216 0.00128271"/>
          <joint name="right_shoulder_abad" class="/" pos="0 0 0" axis="-0.99999 0.00424986 0.00147303" stiffness="0.00781612" range="-2.96273 2.96462" armature="0.0122007" damping="0" frictionloss="0.109866"/>
          <geom name="//unnamed_geom_37" class="/" type="mesh" density="0" rgba="0.752941 0.752941 0.752941 1" mesh="left_shoulder21"/>
          <body name="right_upper_arm" pos="0.000467022 -0.000309654 -0.105147" quat="0.999999 0.000235862 0.0008006 0.00115495">
            <inertial pos="0.00307723 0.0214344 -0.0620884" quat="0.697636 -0.0143902 0.0197676 0.716035" mass="1.16422" diaginertia="0.00271312 0.00271734 0.000896641"/>
            <joint name="right_shoulder_yaw" class="/" pos="0 0 0" axis="-0.00329811 0.00137653 0.999994" stiffness="0.0104552" range="-3.00481 2.97475" armature="0.0107228" damping="0.00991584" frictionloss="0.121119"/>
            <geom name="//unnamed_geom_38" class="/" type="mesh" density="0" rgba="0.752941 0.752941 0.752941 1" mesh="left_shoulder31"/>
            <geom name="//unnamed_geom_39" class="reward_collision_sphere" size="0.0649871" pos="-0.010747 0.0115301 -0.0510825"/>
            <body name="right_lower_arm" pos="0.000136173 -0.00206876 -0.159869" quat="1 0.000191147 0.000294401 -0.000254251">
              <inertial pos="-0.0088337 0.00095067 -0.105036" quat="0.709268 0.00927805 0.0006428 0.704878" mass="0.446784" diaginertia="0.00526885 0.00732435 8.16526e-05"/>
              <joint name="right_elbow" class="/" pos="0 0 0" axis="-0.00324457 -0.999906 0.0133585" stiffness="0.00649616" range="-3.04434 2.94851" armature="0.0118708" damping="0" frictionloss="0.0933702"/>
              <geom name="//unnamed_geom_40" class="/" type="mesh" density="0" rgba="0.752941 0.752941 0.752941 1" mesh="left_forearm"/>
              <geom name="//unnamed_geom_41" class="/" size="0.027078 0.00812339" pos="0 0 -0.275845" quat="0.707109 0.707105 0 0" type="cylinder" group="3"/>
              <geom name="//unnamed_geom_42" class="reward_collision_sphere" size="0.027078"/>
              <geom name="//unnamed_geom_43" class="reward_collision_sphere" size="0.0238286" pos="0 0 -0.286062"/>
            </body>
          </body>
        </body>
      </body>
    </body>
  </worldbody>

  <contact>
    <pair class="/" geom1="floor" geom2="left_foot" name="//unnamed_contact_0"/>
    <pair class="/" geom1="floor" geom2="right_foot" name="//unnamed_contact_1"/>
  </contact>

  <actuator>
    <general name="left_hip_yaw" class="/" joint="left_hip_yaw" forcerange="-37.2297 37.2297" gainprm="32.7344" biasprm="0 -32.7344 -0.559237"/>
    <general name="left_hip_abad" class="/" joint="left_hip_abad" forcerange="-40.7571 40.7571" gainprm="32.7344" biasprm="0 -32.7344 -0.559237"/>
    <general name="left_hip_pitch" class="/" joint="left_hip_pitch" forcerange="-74.4653 74.4653" gainprm="32.7344" biasprm="0 -32.7344 -0.559237"/>
    <general name="left_knee" class="/" joint="left_knee" forcerange="-168.437 168.437" gainprm="32.7344" biasprm="0 -32.7344 -0.559237"/>
    <general name="left_ankle" class="/" joint="left_ankle" forcerange="-75.4976 75.4976" gainprm="32.7344" biasprm="0 -32.7344 -0.559237"/>
    <general name="right_hip_yaw" class="/" joint="right_hip_yaw" forcerange="-40.1753 40.1753" gainprm="32.7344" biasprm="0 -32.7344 -0.559237"/>
    <general name="right_hip_abad" class="/" joint="right_hip_abad" forcerange="-40.2188 40.2188" gainprm="32.7344" biasprm="0 -32.7344 -0.559237"/>
    <general name="right_hip_pitch" class="/" joint="right_hip_pitch" forcerange="-75.5346 75.5346" gainprm="32.7344" biasprm="0 -32.7344 -0.559237"/>
    <general name="right_knee" class="/" joint="right_knee" forcerange="-152.417 152.417" gainprm="32.7344" biasprm="0 -32.7344 -0.559237"/>
    <general name="right_ankle" class="/" joint="right_ankle" forcerange="-70.6733 70.6733" gainprm="32.7344" biasprm="0 -32.7344 -0.559237"/>
    <general name="left_shoulder_pitch" class="/" joint="left_shoulder_pitch" forcerange="-33.3755 33.3755" gainprm="32.7344" biasprm="0 -32.7344 -0.559237"/>
    <general name="left_shoulder_abad" class="/" joint="left_shoulder_abad" forcerange="-38.8574 38.8574" gainprm="32.7344" biasprm="0 -32.7344 -0.559237"/>
    <general name="left_shoulder_yaw" class="/" joint="left_shoulder_yaw" forcerange="-36.5948 36.5948" gainprm="32.7344" biasprm="0 -32.7344 -0.559237"/>
    <general name="left_elbow" class="/" joint="left_elbow" forcerange="-55.2652 55.2652" gainprm="32.7344" biasprm="0 -32.7344 -0.559237"/>
    <general name="right_shoulder_pitch" class="/" joint="right_shoulder_pitch" forcerange="-40.1287 40.1287" gainprm="32.7344" biasprm="0 -32.7344 -0.559237"/>
    <general name="right_shoulder_abad" class="/" joint="right_shoulder_abad" forcerange="-33.2445 33.2445" gainprm="32.7344" biasprm="0 -32.7344 -0.559237"/>
    <general name="right_shoulder_yaw" class="/" joint="right_shoulder_yaw" forcerange="-35.7684 35.7684" gainprm="32.7344" biasprm="0 -32.7344 -0.559237"/>
    <general name="right_elbow" class="/" joint="right_elbow" forcerange="-58.7216 58.7216" gainprm="32.7344" biasprm="0 -32.7344 -0.559237"/>
  </actuator>

  <sensor>
    <gyro site="imu" name="imu_angular_velocity"/>
    <velocimeter site="imu" name="imu_linear_velocity"/>
    <framelinvel objtype="site" objname="left_foot" name="left_foot_global_linear_velocity"/>
    <framelinvel objtype="site" objname="right_foot" name="right_foot_global_linear_velocity"/>
  </sensor>

  <keyframe>
    <key name="home" qpos="0 0 0.656 1 0 0 0 0 0 -0.4 0.8 -0.4 0 0 0.4 -0.8 0.4 0 -0.05 0 -0.75 0 0.05 0 0.75"/>
  </keyframe>
</mujoco>
