<mujoco model="humanoid">
  <compiler angle="radian" assetdir="assets" balanceinertia="true" inertiafromgeom="false"/>

  <option timestep="0.005" density="1.2" viscosity="2e-05"/>

  <size nkey="1"/>

  <visual>
    <quality shadowsize="8192"/>
    <map shadowclip="0.5"/>
  </visual>

  <default>
    <default class="/">
      <joint armature="0.01" damping="0.01" frictionloss="0.1"/>
      <geom contype="0" conaffinity="0" group="1" solref="-1000 -80"/>
      <site size="0.01 0.005 0.005" group="5"/>
      <general forcelimited="true" biastype="affine" gainprm="30" biasprm="0 -30 -0.5"/>
      <default class="foot">
        <geom size="0.099 0.0178 0.021" type="box" condim="6" group="4" priority="1" solimp="0.015 1 0.021"/>
      </default>
      <default class="reward_collision_sphere">
        <geom group="5" rgba="1 0 0 1"/>
      </default>
    </default>
  </default>

  <asset>
    <texture type="skybox" colorspace="auto" name="//unnamed_texture_0" builtin="gradient" rgb1="0.95 0.95 0.95" rgb2="0.95 0.95 0.95" width="100" height="600"/>
    <texture type="2d" colorspace="auto" name="texplane" builtin="checker" rgb1="0.345 0.575 0.748" rgb2="0.345 0.575 0.748" markrgb="1 1 1" width="512" height="512"/>
    <material name="MatPlane" class="/" texture="texplane" texuniform="true" texrepeat="2 2" specular="0.9"/>
    <mesh name="torso" class="/" file="torso.stl" scale="0.001 0.001 0.001"/>
    <mesh name="left_hip_yaw" class="/" file="left_hip_yaw.stl" scale="0.001 0.001 0.001"/>
    <mesh name="left_hip_abad" class="/" file="left_hip_abad.stl" scale="0.001 0.001 0.001"/>
    <mesh name="left_leg_upper" class="/" file="left_leg_upper.stl" scale="0.001 0.001 0.001"/>
    <mesh name="left_leg_lower" class="/" file="left_leg_lower.stl" scale="0.001 0.001 0.001"/>
    <mesh name="left_foot" class="/" file="left_foot.stl" scale="0.001 0.001 0.001"/>
    <mesh name="left_hip_yaw1" class="/" content_type="model/stl" file="left_hip_yaw.stl" scale="0.001 -0.001 0.001"/>
    <mesh name="left_hip_abad1" class="/" content_type="model/stl" file="left_hip_abad.stl" scale="0.001 -0.001 0.001"/>
    <mesh name="left_leg_upper1" class="/" content_type="model/stl" file="left_leg_upper.stl" scale="0.001 -0.001 0.001"/>
    <mesh name="left_leg_lower1" class="/" content_type="model/stl" file="left_leg_lower.stl" scale="0.001 -0.001 0.001"/>
    <mesh name="left_foot1" class="/" content_type="model/stl" file="left_foot.stl" scale="0.001 -0.001 0.001"/>
    <mesh name="left_shoulder1" class="/" file="left_shoulder1.stl" scale="0.001 0.001 0.001"/>
    <mesh name="left_shoulder2" class="/" file="left_shoulder2.stl" scale="0.001 0.001 0.001"/>
    <mesh name="left_shoulder3" class="/" file="left_shoulder3.stl" scale="0.001 0.001 0.001"/>
    <mesh name="left_forearm" class="/" file="left_forearm.stl" scale="0.001 0.001 0.001"/>
    <mesh name="left_shoulder11" class="/" content_type="model/stl" file="left_shoulder1.stl" scale="0.001 -0.001 0.001"/>
    <mesh name="left_shoulder21" class="/" content_type="model/stl" file="left_shoulder2.stl" scale="0.001 -0.001 0.001"/>
    <mesh name="left_shoulder31" class="/" content_type="model/stl" file="left_shoulder3.stl" scale="0.001 -0.001 0.001"/>
  </asset>

  <worldbody>
    <geom name="floor" class="/" size="100 100 0.125" type="plane" group="0" material="MatPlane"/>
    <light name="toplight_shadow" class="/" pos="0 0 5" dir="0.0990148 0.0990148 -0.990148" type="directional" ambient="0.04 0.04 0.04" diffuse="0.55 0.55 0.55" specular="0.12 0.12 0.12"/>
    <light name="toplight_fill" class="/" pos="0 0 5" dir="0.0990148 0.0990148 -0.990148" type="directional" castshadow="false" ambient="0.04 0.04 0.04" diffuse="0.3 0.3 0.3" specular="0.08 0.08 0.08"/>
    <body name="trunk" pos="-0.00232973 0.0026971 8.15789e-05" quat="1 -0.000203751 0.00038476 -0.000201484">
      <inertial pos="0.0139901 0.00275248 0.140839" quat="0.999908 0.00731997 -0.00346402 -0.0108544" mass="10.0654" diaginertia="0.333914 0.236903 0.0642239"/>
      <joint name="//unnamed_joint_0" type="free"/>
      <geom name="//unnamed_geom_1" class="/" type="mesh" density="0" rgba="0.752941 0.752941 0.752941 1" mesh="torso"/>
      <geom name="//unnamed_geom_2" class="/" size="0.0812069 0.162414 0.189483" pos="0.0261834 0 0.0740014" type="box" group="3" rgba="0.752941 0.752941 0.752941 1"/>
      <geom name="//unnamed_geom_3" class="reward_collision_sphere" size="0.157" pos="0 0 0.138753"/>
      <site name="imu" class="/" pos="0.0121474 -0.00308538 0.12646" size="0.0108276"/>
      <camera name="track" class="/" pos="0 -2.3697 0" quat="0.707107 0.707107 0 0" mode="trackcom"/>
      <camera name="ego_camera" class="/" pos="0.0512284 0 0.277505" quat="-0.5 -0.5 0.5 0.5"/>
      <body name="left_hip_yaw" pos="0.00108785 0.0969324 -0.00260276" quat="0.996228 -0.000490121 -0.08677 0.000952816">
        <inertial pos="-0.0719071 0.000466038 -0.0584736" quat="0.94984 -0.00276634 -0.31272 0.00157726" mass="1.04569" diaginertia="0.00364049 0.00312721 0.000525901"/>
        <joint name="left_hip_yaw" class="/" pos="0 0 0" axis="0.00276967 0.00147479 -0.999995" range="-2.96831 2.95624" armature="0.0123249" damping="0.0110356" frictionloss="0.0940028"/>
        <geom name="//unnamed_geom_4" class="/" type="mesh" density="0" rgba="0.2 0.2 0.2 1" mesh="left_hip_yaw"/>
        <body name="left_hip_abad" pos="-0.0735446 -0.00218662 -0.066176" quat="0.976572 -0.000120073 0.215189 -0.000442883">
          <inertial pos="0.0737881 -0.0175142 0.00241625" quat="0.578141 0.406325 0.412987 0.574539" mass="1.50076" diaginertia="0.0064976 0.00476413 0.00118957"/>
          <joint name="left_hip_abad" class="/" pos="0 0 0" axis="-0.999985 0.00504952 0.00225359" stiffness="0.00779882" range="-3.0191 2.9409" armature="0.0109079" damping="0.0200629" frictionloss="0.11039"/>
          <geom name="//unnamed_geom_5" class="/" type="mesh" density="0" rgba="0.2 0.2 0.2 1" mesh="left_hip_abad"/>
          <body name="left_upper_leg" pos="0.102964 -0.000108431 -0.0150594" quat="0.991557 0.000274145 -0.129673 0.000121111">
            <inertial pos="0.000514535 0.0309746 -0.0740463" quat="0.730407 0.0317408 -0.0474618 0.680621" mass="3.3274" diaginertia="0.0521305 0.0586458 0.0023446"/>
            <joint name="left_hip_pitch" class="/" pos="0 0 0" axis="-0.0107446 0.999938 -0.0029569" range="-3.02089 3.0535" armature="0.0098277" damping="0.0225505" frictionloss="0.108998"/>
            <geom name="//unnamed_geom_6" class="/" type="mesh" density="0" rgba="0.752941 0.752941 0.752941 1" mesh="left_leg_upper"/>
            <geom name="//unnamed_geom_7" class="reward_collision_sphere" size="0.0757931" pos="-0.0170761 0.0177727 0.0138753"/>
            <geom name="//unnamed_geom_8" class="reward_collision_sphere" size="0.0216552" pos="-0.0910727 -0.0355455 0.0740014"/>
            <body name="left_lower_leg" pos="-0.0168655 0.00258233 -0.232713" quat="1 -0.00051218 -0.000280404 0.000259811">
              <inertial pos="0.00836097 0.00291341 -0.12139" quat="0.998739 0.00367823 -0.0163564 0.0473184" mass="0.453962" diaginertia="0.00563082 0.00705572 0.000159874"/>
              <joint name="left_knee" class="/" pos="0 0 0" axis="0.0015154 0.999996 -0.00222206" stiffness="0.000693899" range="-0.00633399 3.05395" armature="0.010775" damping="0.013007" frictionloss="0.109238"/>
              <geom name="//unnamed_geom_9" class="/" type="mesh" density="0" rgba="0.752941 0.752941 0.752941 1" mesh="left_leg_lower"/>
              <geom name="//unnamed_geom_10" class="reward_collision_sphere" size="0.0465586"/>
              <body name="left_foot" pos="0.00110844 -0.00221225 -0.257075" quat="1 -3.93729e-06 -2.20358e-05 5.00188e-06">
                <inertial pos="0.0266992 -0.00261322 -0.0155549" quat="0.512134 0.47316 0.484781 0.528039" mass="0.358706" diaginertia="0.0514178 0.062081 0.0184007"/>
                <joint name="left_ankle" class="/" pos="0 0 0" axis="-0.00821208 0.999894 -0.0119928" range="-1.55765 1.50936" armature="0.0121401" damping="0.0163178" frictionloss="0.102749"/>
                <geom name="//unnamed_geom_11" class="/" type="mesh" density="0" rgba="0.2 0.2 0.2 1" mesh="left_foot"/>
                <geom name="left_foot" class="foot" size="0.118332 0.0196327 0.0231949" pos="0.0318755 0 -0.0231254" quat="0.707109 0.707105 0 0"/>
                <geom name="//unnamed_geom_13" class="reward_collision_sphere" size="0.027069" pos="0.0318755 0 -0.0185004"/>
                <geom name="//unnamed_geom_14" class="reward_collision_sphere" size="0.027069" pos="0.113841 0 -0.0231254"/>
                <geom name="//unnamed_geom_15" class="reward_collision_sphere" size="0.027069" pos="-0.0512284 0 -0.0231254"/>
                <site name="left_foot" class="foot" pos="0.0318755 0 -0.0231254" quat="0.707109 0.707105 0 0" size="0.0108276"/>
              </body>
            </body>
          </body>
        </body>
      </body>
      <body name="right_hip_yaw" pos="0.000730854 -0.0960874 0.0022006" quat="0.996163 -0.000283594 -0.0875192 0.000297007">
        <inertial pos="-0.076967 0.00225887 -0.0614911" quat="0.949326 -0.00816705 0.314176 -0.00251255" mass="1.12202" diaginertia="0.00376963 0.00332213 0.000549782"/>
        <joint name="right_hip_yaw" class="/" pos="0 0 0" axis="-1.18779e-05 0.000106678 -1" stiffness="0.00469794" range="-3.0329 3.04746" armature="0.0122315" damping="0.0158975" frictionloss="0.0930087"/>
        <geom name="//unnamed_geom_16" class="/" type="mesh" density="0" rgba="0.2 0.2 0.2 1" mesh="left_hip_yaw1"/>
        <body name="right_hip_abad" pos="-0.0739157 0.00172109 -0.0698815" quat="0.976305 5.04202e-05 0.2164 0.000117589">
          <inertial pos="0.0754394 0.018191 0.00108285" quat="0.405787 0.581848 0.581681 0.398041" mass="1.5743" diaginertia="0.0063677 0.00478017 0.0011889"/>
          <joint name="right_hip_abad" class="/" pos="0 0 0" axis="-0.999924 -0.0120608 0.00237856" stiffness="0.0127645" range="-2.99661 3.01799" armature="0.0101575" damping="0.0195676" frictionloss="0.108895"/>
          <geom name="//unnamed_geom_17" class="/" type="mesh" density="0" rgba="0.2 0.2 0.2 1" mesh="left_hip_abad1"/>
          <body name="right_upper_leg" pos="0.102799 0.00247841 -0.0160843" quat="0.991442 -1.83748e-05 -0.130549 -5.22689e-05">
            <inertial pos="-0.0012411 -0.030652 -0.0732393" quat="0.680726 0.0483915 -0.0349366 0.730103" mass="3.54754" diaginertia="0.0504574 0.0611892 0.00243191"/>
            <joint name="right_hip_pitch" class="/" pos="0 0 0" axis="0.0053557 -0.999972 -0.00514388" range="-2.94312 2.99158" armature="0.0103512" damping="0" frictionloss="0.0945003"/>
            <geom name="//unnamed_geom_18" class="/" type="mesh" density="0" rgba="0.752941 0.752941 0.752941 1" mesh="left_leg_upper1"/>
            <geom name="//unnamed_geom_19" class="reward_collision_sphere" size="0.0757931" pos="-0.0170761 -0.0177727 0.0138753"/>
            <geom name="//unnamed_geom_20" class="reward_collision_sphere" size="0.0216552" pos="-0.0910727 0.0355455 0.0740014"/>
            <body name="right_lower_leg" pos="-0.0120529 -0.00107915 -0.231714" quat="1 4.81618e-05 -0.000209031 0.000320433">
              <inertial pos="0.00394516 -0.00299686 -0.12183" quat="0.998905 0.00575488 0.0141342 -0.0442273" mass="0.425489" diaginertia="0.00567434 0.0069349 0.0001596"/>
              <joint name="right_knee" class="/" pos="0 0 0" axis="-0.000127439 -0.999996 -0.0027466" range="-2.94458 -0.0122504" armature="0.0119441" damping="0.0166635" frictionloss="0.111223"/>
              <geom name="//unnamed_geom_21" class="/" type="mesh" density="0" rgba="0.752941 0.752941 0.752941 1" mesh="left_leg_lower1"/>
              <geom name="//unnamed_geom_22" class="reward_collision_sphere" size="0.0465586"/>
              <body name="right_foot" pos="0.00324578 -0.0013885 -0.254954" quat="0.999999 -0.000661143 0.000695356 -0.000881526">
                <inertial pos="0.0244297 -0.000337134 -0.0147499" quat="0.4848 0.525338 0.513013 0.475192" mass="0.363339" diaginertia="0.0505584 0.0629885 0.0183772"/>
                <joint name="right_ankle" class="/" pos="0 0 0" axis="0.00554917 -0.999985 -0.000365085" range="-1.51507 1.50834" armature="0.0121914" damping="0.00714908" frictionloss="0.0940706"/>
                <geom name="//unnamed_geom_23" class="/" type="mesh" density="0" rgba="0.2 0.2 0.2 1" mesh="left_foot1"/>
                <geom name="right_foot" class="foot" size="0.125484 0.0161301 0.0245819" pos="0.0318755 0 -0.0231254" quat="0.707109 0.707105 0 0"/>
                <geom name="//unnamed_geom_25" class="reward_collision_sphere" size="0.027069" pos="0.0318755 0 -0.0185004"/>
                <geom name="//unnamed_geom_26" class="reward_collision_sphere" size="0.027069" pos="0.113841 0 -0.0231254"/>
                <geom name="//unnamed_geom_27" class="reward_collision_sphere" size="0.027069" pos="-0.0512284 0 -0.0231254"/>
                <site name="right_foot" class="foot" pos="0.0318755 0 -0.0231254" quat="0.707109 0.707105 0 0" size="0.0108276"/>
              </body>
            </body>
          </body>
        </body>
      </body>
      <body name="left_shoulder" pos="0.0196648 0.208023 0.281687" quat="1 -1.59068e-07 1.22494e-06 -1.56004e-06">
        <inertial pos="0.0121994 0.0604349 0.00253695" quat="0.70998 0.703935 0.0151667 0.0132026" mass="0.973079" diaginertia="0.00263634 0.00203158 0.000502767"/>
        <joint name="left_shoulder_pitch" class="/" pos="0 0 0" axis="0.00620467 0.999935 -0.00958063" stiffness="0.0116159" range="-2.94291 3.04846" armature="0.0114599" damping="0.00932478" frictionloss="0.107814"/>
        <geom name="//unnamed_geom_28" class="/" type="mesh" density="0" rgba="0.2 0.2 0.2 1" mesh="left_shoulder1"/>
        <body name="left_shoulder_2" pos="-0.00073474 0.0674941 0.000900865" quat="1 8.14982e-05 4.29678e-05 -6.87563e-05">
          <inertial pos="-0.0028081 0.000724098 -0.0762752" quat="0.0158673 0.757661 -0.00147621 0.652454" mass="1.04013" diaginertia="0.00244731 0.00279592 0.00077759"/>
          <joint name="left_shoulder_abad" class="/" pos="0 0 0" axis="-0.999928 0.00800732 0.0088902" stiffness="0.00391218" range="-3.03493 2.99949" armature="0.00928383" damping="0.00628146" frictionloss="0.108215"/>
          <geom name="//unnamed_geom_29" class="/" type="mesh" density="0" rgba="0.752941 0.752941 0.752941 1" mesh="left_shoulder2"/>
          <body name="left_upper_arm" pos="-0.00164866 0.000892999 -0.0931312" quat="1 -0.000679869 0.000624019 -0.000176988">
            <inertial pos="0.00189001 -0.019341 -0.0587467" quat="0.707229 -0.0282292 0.0284874 0.705846" mass="1.12488" diaginertia="0.00345964 0.00306223 0.000505473"/>
            <joint name="left_shoulder_yaw" class="/" pos="0 0 0" axis="0.000198232 0.00014267 1" range="-3.00135 2.99914" armature="0.0106887" damping="0.001669" frictionloss="0.105929"/>
            <geom name="//unnamed_geom_30" class="/" type="mesh" density="0" rgba="0.752941 0.752941 0.752941 1" mesh="left_shoulder3"/>
            <geom name="//unnamed_geom_31" class="reward_collision_sphere" size="0.0649655" pos="-0.0113841 -0.0118485 -0.0462509"/>
            <body name="left_lower_arm" pos="-0.0017339 -0.00189488 -0.143142" quat="0.999999 0.000832304 0.000139288 -0.000729449">
              <inertial pos="-0.0051545 0.00132145 -0.0958074" quat="0.706435 0.00312354 0.00603878 0.707746" mass="0.44802" diaginertia="0.00688699 0.00866901 5.27453e-05"/>
              <joint name="left_elbow" class="/" pos="0 0 0" axis="0.00466422 0.999964 0.00712216" stiffness="0.0118771" range="-2.98857 3.00386" armature="0.0112579" damping="0.0058785" frictionloss="0.117274"/>
              <geom name="//unnamed_geom_32" class="/" type="mesh" density="0" rgba="0.752941 0.752941 0.752941 1" mesh="left_forearm"/>
              <geom name="//unnamed_geom_33" class="/" size="0.027069 0.00812069" pos="0 0 -0.249755" quat="0.707109 0.707105 0 0" type="cylinder" group="3"/>
              <geom name="//unnamed_geom_34" class="reward_collision_sphere" size="0.027069"/>
              <geom name="//unnamed_geom_35" class="reward_collision_sphere" size="0.0238207" pos="0 0 -0.259005"/>
            </body>
          </body>
        </body>
      </body>
      <body name="right_shoulder" pos="0.0237108 -0.208523 0.282266" quat="1 3.55141e-06 6.96963e-06 1.97641e-06">
        <inertial pos="0.0111442 -0.0610117 0.000724006" quat="0.709281 0.704573 -0.0181717 -0.0129388" mass="0.995204" diaginertia="0.00266267 0.00195742 0.000531058"/>
        <joint name="right_shoulder_pitch" class="/" pos="0 0 0" axis="0.00911365 -0.9999 0.0108328" stiffness="0.00931666" range="-3.01622 2.94312" armature="0.0111544" damping="0.00586188" frictionloss="0.10058"/>
        <geom name="//unnamed_geom_36" class="/" type="mesh" density="0" rgba="0.2 0.2 0.2 1" mesh="left_shoulder11"/>
        <body name="right_shoulder_2" pos="-0.00193725 -0.0700571 -0.00111886" quat="0.999999 -0.000389993 -0.000586009 0.000935777">
          <inertial pos="0.000590913 -0.00259509 -0.0737774" quat="-0.000434234 0.651444 0.0148987 0.75855" mass="1.01004" diaginertia="0.00252073 0.00275678 0.000787458"/>
          <joint name="right_shoulder_abad" class="/" pos="0 0 0" axis="-0.99999 -0.00386349 0.00213089" range="-2.95827 2.95648" armature="0.0108533" damping="0.011759" frictionloss="0.123286"/>
          <geom name="//unnamed_geom_37" class="/" type="mesh" density="0" rgba="0.752941 0.752941 0.752941 1" mesh="left_shoulder21"/>
          <body name="right_upper_arm" pos="0.00109316 0.00164022 -0.0948559" quat="1 0.000293197 0.000469845 5.15496e-06">
            <inertial pos="-0.00230751 0.0171766 -0.0574814" quat="0.70523 -0.0214968 0.0206275 0.708352" mass="1.13467" diaginertia="0.00337419 0.00320851 0.000528626"/>
            <joint name="right_shoulder_yaw" class="/" pos="0 0 0" axis="-0.00143689 -0.0130319 0.999914" range="-2.9899 3.02056" armature="0.0107001" damping="0.00730572" frictionloss="0.0951774"/>
            <geom name="//unnamed_geom_38" class="/" type="mesh" density="0" rgba="0.752941 0.752941 0.752941 1" mesh="left_shoulder31"/>
            <geom name="//unnamed_geom_39" class="reward_collision_sphere" size="0.0649655" pos="-0.0113841 0.0118485 -0.0462509"/>
            <body name="right_lower_arm" pos="0.00132882 0.00278649 -0.143159" quat="0.999999 -0.00125631 -0.000224316 0.00042582">
              <inertial pos="-0.00714875 -0.000936464 -0.0923271" quat="0.708207 0.00289782 0.00966532 0.705933" mass="0.427505" diaginertia="0.00689344 0.00839092 5.34964e-05"/>
              <joint name="right_elbow" class="/" pos="0 0 0" axis="-0.0114544 -0.999932 -0.00214986" stiffness="0.0145108" range="-2.98265 2.98457" armature="0.0117107" damping="0.0128977" frictionloss="0.120622"/>
              <geom name="//unnamed_geom_40" class="/" type="mesh" density="0" rgba="0.752941 0.752941 0.752941 1" mesh="left_forearm"/>
              <geom name="//unnamed_geom_41" class="/" size="0.027069 0.00812069" pos="0 0 -0.249755" quat="0.707109 0.707105 0 0" type="cylinder" group="3"/>
              <geom name="//unnamed_geom_42" class="reward_collision_sphere" size="0.027069"/>
              <geom name="//unnamed_geom_43" class="reward_collision_sphere" size="0.0238207" pos="0 0 -0.259005"/>
            </body>
          </body>
        </body>
      </body>
    </body>
  </worldbody>

  <contact>
    <pair class="/" geom1="floor" geom2="left_foot" name="//unnamed_contact_0"/>
    <pair class="/" geom1="floor" geom2="right_foot" name="//unnamed_contact_1"/>
  </contact>

  <actuator>
    <general name="left_hip_yaw" class="/" joint="left_hip_yaw" forcerange="-37.0325 37.0325" gainprm="32.4491" biasprm="0 -32.4491 -0.501268"/>
    <general name="left_hip_abad" class="/" joint="left_hip_abad" forcerange="-37.6908 37.6908" gainprm="32.4491" biasprm="0 -32.4491 -0.501268"/>
    <general name="left_hip_pitch" class="/" joint="left_hip_pitch" forcerange="-79.5339 79.5339" gainprm="32.4491" biasprm="0 -32.4491 -0.501268"/>
    <general name="left_knee" class="/" joint="left_knee" forcerange="-164.626 164.626" gainprm="32.4491" biasprm="0 -32.4491 -0.501268"/>
    <general name="left_ankle" class="/" joint="left_ankle" forcerange="-65.5908 65.5908" gainprm="32.4491" biasprm="0 -32.4491 -0.501268"/>
    <general name="right_hip_yaw" class="/" joint="right_hip_yaw" forcerange="-36.0603 36.0603" gainprm="32.4491" biasprm="0 -32.4491 -0.501268"/>
    <general name="right_hip_abad" class="/" joint="right_hip_abad" forcerange="-33.5739 33.5739" gainprm="32.4491" biasprm="0 -32.4491 -0.501268"/>
    <general name="right_hip_pitch" class="/" joint="right_hip_pitch" forcerange="-85.4413 85.4413" gainprm="32.4491" biasprm="0 -32.4491 -0.501268"/>
    <general name="right_knee" class="/" joint="right_knee" forcerange="-152.566 152.566" gainprm="32.4491" biasprm="0 -32.4491 -0.501268"/>
    <general name="right_ankle" class="/" joint="right_ankle" forcerange="-75.0068 75.0068" gainprm="32.4491" biasprm="0 -32.4491 -0.501268"/>
    <general name="left_shoulder_pitch" class="/" joint="left_shoulder_pitch" forcerange="-37.2736 37.2736" gainprm="32.4491" biasprm="0 -32.4491 -0.501268"/>
    <general name="left_shoulder_abad" class="/" joint="left_shoulder_abad" forcerange="-35.3321 35.3321" gainprm="32.4491" biasprm="0 -32.4491 -0.501268"/>
    <general name="left_shoulder_yaw" class="/" joint="left_shoulder_yaw" forcerange="-36.8954 36.8954" gainprm="32.4491" biasprm="0 -32.4491 -0.501268"/>
    <general name="left_elbow" class="/" joint="left_elbow" forcerange="-65.1758 65.1758" gainprm="32.4491" biasprm="0 -32.4491 -0.501268"/>
    <general name="right_shoulder_pitch" class="/" joint="right_shoulder_pitch" forcerange="-35.8924 35.8924" gainprm="32.4491" biasprm="0 -32.4491 -0.501268"/>
    <general name="right_shoulder_abad" class="/" joint="right_shoulder_abad" forcerange="-36.6833 36.6833" gainprm="32.4491" biasprm="0 -32.4491 -0.501268"/>
    <general name="right_shoulder_yaw" class="/" joint="right_shoulder_yaw" forcerange="-40.6144 40.6144" gainprm="32.4491" biasprm="0 -32.4491 -0.501268"/>
    <general name="right_elbow" class="/" joint="right_elbow" forcerange="-59.1367 59.1367" gainprm="32.4491" biasprm="0 -32.4491 -0.501268"/>
  </actuator>

  <sensor>
    <gyro site="imu" name="imu_angular_velocity"/>
    <velocimeter site="imu" name="imu_linear_velocity"/>
    <framelinvel objtype="site" objname="left_foot" name="left_foot_global_linear_velocity"/>
    <framelinvel objtype="site" objname="right_foot" name="right_foot_global_linear_velocity"/>
  </sensor>

  <keyframe>
    <key name="home" qpos="0 0 0.656 1 0 0 0 0 0 -0.4 0.8 -0.4 0 0 0.4 -0.8 0.4 0 -0.05 0 -0.75 0 0.05 0 0.75"/>
  </keyframe>
</mujoco>
