<mujoco model="humanoid">
  <compiler angle="radian" assetdir="assets" balanceinertia="true" inertiafromgeom="false"/>

  <option timestep="0.005" density="1.2" viscosity="2e-05"/>

  <size nkey="1"/>

  <visual>
    <quality shadowsize="8192"/>
    <map shadowclip="0.5"/>
  </visual>

  <default>
    <default class="/">
      <joint armature="0.01" damping="0.01" frictionloss="0.1"/>
      <geom contype="0" conaffinity="0" group="1" solref="-1000 -80"/>
      <site size="0.01 0.005 0.005" group="5"/>
      <general forcelimited="true" biastype="affine" gainprm="30" biasprm="0 -30 -0.5"/>
      <default class="foot">
        <geom size="0.099 0.0178 0.021" type="box" condim="6" group="4" priority="1" solimp="0.015 1 0.021"/>
      </default>
      <default class="reward_collision_sphere">
        <geom group="5" rgba="1 0 0 1"/>
      </default>
    </default>
  </default>

  <asset>
    <texture type="skybox" colorspace="auto" name="//unnamed_texture_0" builtin="gradient" rgb1="0.95 0.95 0.95" rgb2="0.95 0.95 0.95" width="100" height="600"/>
    <texture type="2d" colorspace="auto" name="texplane" builtin="checker" rgb1="0.345 0.575 0.748" rgb2="0.345 0.575 0.748" markrgb="1 1 1" width="512" height="512"/>
    <material name="MatPlane" class="/" texture="texplane" texuniform="true" texrepeat="2 2" specular="0.9"/>
    <mesh name="torso" class="/" file="torso.stl" scale="0.001 0.001 0.001"/>
    <mesh name="left_hip_yaw" class="/" file="left_hip_yaw.stl" scale="0.001 0.001 0.001"/>
    <mesh name="left_hip_abad" class="/" file="left_hip_abad.stl" scale="0.001 0.001 0.001"/>
    <mesh name="left_leg_upper" class="/" file="left_leg_upper.stl" scale="0.001 0.001 0.001"/>
    <mesh name="left_leg_lower" class="/" file="left_leg_lower.stl" scale="0.001 0.001 0.001"/>
    <mesh name="left_foot" class="/" file="left_foot.stl" scale="0.001 0.001 0.001"/>
    <mesh name="left_hip_yaw1" class="/" content_type="model/stl" file="left_hip_yaw.stl" scale="0.001 -0.001 0.001"/>
    <mesh name="left_hip_abad1" class="/" content_type="model/stl" file="left_hip_abad.stl" scale="0.001 -0.001 0.001"/>
    <mesh name="left_leg_upper1" class="/" content_type="model/stl" file="left_leg_upper.stl" scale="0.001 -0.001 0.001"/>
    <mesh name="left_leg_lower1" class="/" content_type="model/stl" file="left_leg_lower.stl" scale="0.001 -0.001 0.001"/>
    <mesh name="left_foot1" class="/" content_type="model/stl" file="left_foot.stl" scale="0.001 -0.001 0.001"/>
    <mesh name="left_shoulder1" class="/" file="left_shoulder1.stl" scale="0.001 0.001 0.001"/>
    <mesh name="left_shoulder2" class="/" file="left_shoulder2.stl" scale="0.001 0.001 0.001"/>
    <mesh name="left_shoulder3" class="/" file="left_shoulder3.stl" scale="0.001 0.001 0.001"/>
    <mesh name="left_forearm" class="/" file="left_forearm.stl" scale="0.001 0.001 0.001"/>
    <mesh name="left_shoulder11" class="/" content_type="model/stl" file="left_shoulder1.stl" scale="0.001 -0.001 0.001"/>
    <mesh name="left_shoulder21" class="/" content_type="model/stl" file="left_shoulder2.stl" scale="0.001 -0.001 0.001"/>
    <mesh name="left_shoulder31" class="/" content_type="model/stl" file="left_shoulder3.stl" scale="0.001 -0.001 0.001"/>
  </asset>

  <worldbody>
    <geom name="floor" class="/" size="100 100 0.125" type="plane" group="0" material="MatPlane"/>
    <light name="toplight_shadow" class="/" pos="0 0 5" dir="0.0990148 0.0990148 -0.990148" type="directional" ambient="0.04 0.04 0.04" diffuse="0.55 0.55 0.55" specular="0.12 0.12 0.12"/>
    <light name="toplight_fill" class="/" pos="0 0 5" dir="0.0990148 0.0990148 -0.990148" type="directional" castshadow="false" ambient="0.04 0.04 0.04" diffuse="0.3 0.3 0.3" specular="0.08 0.08 0.08"/>
    <body name="trunk" pos="0.000152677 0.00226049 -0.000194864" quat="1 -8.2118e-05 -5.97772e-05 0.000102959">
      <inertial pos="0.0127659 0.00384988 0.147426" quat="0.99999 -0.000246582 -0.0019655 -0.00392765" mass="10.231" diaginertia="0.29027 0.231686 0.0814514"/>
      <joint name="//unnamed_joint_0" type="free"/>
      <geom name="//unnamed_geom_1" class="/" type="mesh" density="0" rgba="0.752941 0.752941 0.752941 1" mesh="torso"/>
      <geom name="//unnamed_geom_2" class="/" size="0.0817083 0.163417 0.190653" pos="0.0255202 0 0.0779549" type="box" group="3" rgba="0.752941 0.752941 0.752941 1"/>
      <geom name="//unnamed_geom_3" class="reward_collision_sphere" size="0.157969" pos="0 0 0.146165"/>
      <site name="imu" class="/" pos="0.0129582 0.00730973 0.133322" size="0.0108944"/>
      <camera name="track" class="/" pos="0 -2.36864 0" quat="0.707107 0.707107 0 0" mode="trackcom"/>
      <camera name="ego_camera" class="/" pos="0.0499308 0 0.292331" quat="-0.5 -0.5 0.5 0.5"/>
      <body name="left_hip_yaw" pos="-8.30943e-05 0.0986968 -0.00113092" quat="0.996186 0.00014934 -0.0872595 -3.83395e-05">
        <inertial pos="-0.0723715 -0.00111966 -0.0598426" quat="0.949998 -0.00148059 -0.312246 0.00192314" mass="1.06445" diaginertia="0.00316629 0.00322482 0.000692089"/>
        <joint name="left_hip_yaw" class="/" pos="0 0 0" axis="-0.00102006 -0.00696492 -0.999975" range="-2.94381 2.94537" armature="0.0116217" damping="0.0207467" frictionloss="0.105474"/>
        <geom name="//unnamed_geom_4" class="/" type="mesh" density="0" rgba="0.2 0.2 0.2 1" mesh="left_hip_yaw"/>
        <body name="left_hip_abad" pos="-0.07364 -0.0008279 -0.0715104" quat="0.976498 -0.000199912 0.215524 0.000848299">
          <inertial pos="0.0736011 -0.0148832 0.000109286" quat="0.580554 0.405053 0.412619 0.573267" mass="1.52698" diaginertia="0.00564177 0.00454672 0.00145629"/>
          <joint name="left_hip_abad" class="/" pos="0 0 0" axis="-0.999999 -0.00107471 -0.000545324" stiffness="0.0126855" range="-3.00893 2.96924" armature="0.0110508" damping="0.0271094" frictionloss="0.104087"/>
          <geom name="//unnamed_geom_5" class="/" type="mesh" density="0" rgba="0.2 0.2 0.2 1" mesh="left_hip_abad"/>
          <body name="left_upper_leg" pos="0.100318 -0.00231085 -0.0160843" quat="0.991417 -0.000255882 -0.130737 0.000177203">
            <inertial pos="0.00169932 0.0307632 -0.0794559" quat="0.730608 0.0316191 -0.0468769 0.680452" mass="3.49422" diaginertia="0.044849 0.0591951 0.00311609"/>
            <joint name="left_hip_pitch" class="/" pos="0 0 0" axis="0.00871133 0.999962 -0.000298469" range="-2.98467 3.0192" armature="0.011687" damping="0.0241001" frictionloss="0.108095"/>
            <geom name="//unnamed_geom_6" class="/" type="mesh" density="0" rgba="0.752941 0.752941 0.752941 1" mesh="left_leg_upper"/>
            <geom name="//unnamed_geom_7" class="reward_collision_sphere" size="0.076261" pos="-0.0166436 0.0177648 0.0146165"/>
            <geom name="//unnamed_geom_8" class="reward_collision_sphere" size="0.0217889" pos="-0.0887659 -0.0355296 0.0779549"/>
            <body name="left_lower_leg" pos="-0.01403 -0.000612069 -0.245757" quat="1 -1.2131e-05 -4.1435e-05 -5.31594e-05">
              <inertial pos="0.00589689 0.00322171 -0.127917" quat="0.998502 0.00805744 -0.0168063 0.051452" mass="0.446336" diaginertia="0.0048211 0.00678103 0.00020867"/>
              <joint name="left_knee" class="/" pos="0 0 0" axis="-0.000895144 0.999967 0.0080756" stiffness="0.00428402" range="-0.0464463 3.02508" armature="0.0107981" damping="0.0166279" frictionloss="0.107344"/>
              <geom name="//unnamed_geom_9" class="/" type="mesh" density="0" rgba="0.752941 0.752941 0.752941 1" mesh="left_leg_lower"/>
              <geom name="//unnamed_geom_10" class="reward_collision_sphere" size="0.0468461"/>
              <body name="left_foot" pos="-0.000502737 -0.000534886 -0.269291" quat="1 -2.26922e-05 -8.06863e-05 -7.02443e-05">
                <inertial pos="0.0244342 -0.000995002 -0.0154033" quat="0.522902 0.47868 0.474465 0.521845" mass="0.364937" diaginertia="0.0471143 0.0623711 0.0240767"/>
                <joint name="left_ankle" class="/" pos="0 0 0" axis="-0.00365874 0.999909 -0.0129817" range="-1.53811 1.4852" armature="0.0124376" damping="0.0219279" frictionloss="0.112246"/>
                <geom name="//unnamed_geom_11" class="/" type="mesh" density="0" rgba="0.2 0.2 0.2 1" mesh="left_foot"/>
                <geom name="left_foot" class="foot" size="0.120133 0.0207877 0.0239515" pos="0.0310681 0 -0.0243609" quat="0.707109 0.707105 0 0"/>
                <geom name="//unnamed_geom_13" class="reward_collision_sphere" size="0.0272361" pos="0.0310681 0 -0.0194887"/>
                <geom name="//unnamed_geom_14" class="reward_collision_sphere" size="0.0272361" pos="0.110957 0 -0.0243609"/>
                <geom name="//unnamed_geom_15" class="reward_collision_sphere" size="0.0272361" pos="-0.0499308 0 -0.0243609"/>
                <site name="left_foot" class="foot" pos="0.0310681 0 -0.0243609" quat="0.707109 0.707105 0 0" size="0.0108944"/>
              </body>
            </body>
          </body>
        </body>
      </body>
      <body name="right_hip_yaw" pos="-0.000457168 -0.0948922 0.000409531" quat="0.996239 0.000648608 -0.0866317 0.00124467">
        <inertial pos="-0.0747231 -0.000136534 -0.0617429" quat="0.950743 0.0097382 0.309757 -0.00659127" mass="1.10471" diaginertia="0.00328383 0.00325994 0.000703302"/>
        <joint name="right_hip_yaw" class="/" pos="0 0 0" axis="-0.00987079 -0.000397515 -0.999951" range="-3.05529 2.99938" armature="0.0110163" damping="0.013237" frictionloss="0.100494"/>
        <geom name="//unnamed_geom_16" class="/" type="mesh" density="0" rgba="0.2 0.2 0.2 1" mesh="left_hip_yaw1"/>
        <body name="right_hip_abad" pos="-0.0733421 -0.000733309 -0.0751981" quat="0.976345 0.00100391 0.216217 -0.000201977">
          <inertial pos="0.0733883 0.0163488 0.00276473" quat="0.410529 0.582092 0.577067 0.399534" mass="1.57104" diaginertia="0.00566381 0.00468178 0.00148413"/>
          <joint name="right_hip_abad" class="/" pos="0 0 0" axis="-1 9.41509e-05 1.03943e-05" stiffness="0.00391634" range="-3.00328 2.98015" armature="0.0111488" damping="0.0307731" frictionloss="0.114224"/>
          <geom name="//unnamed_geom_17" class="/" type="mesh" density="0" rgba="0.2 0.2 0.2 1" mesh="left_hip_abad1"/>
          <body name="right_upper_leg" pos="0.101532 0.00064641 -0.0150784" quat="0.991448 1.25567e-06 -0.130506 4.18642e-05">
            <inertial pos="-0.000394067 -0.0314653 -0.076862" quat="0.679716 0.0522488 -0.031675 0.730926" mass="3.62161" diaginertia="0.0441765 0.0595078 0.00316666"/>
            <joint name="right_hip_pitch" class="/" pos="0 0 0" axis="-0.0091832 -0.999917 0.00903141" range="-2.96309 3.01092" armature="0.00945223" damping="0.00292763" frictionloss="0.106902"/>
            <geom name="//unnamed_geom_18" class="/" type="mesh" density="0" rgba="0.752941 0.752941 0.752941 1" mesh="left_leg_upper1"/>
            <geom name="//unnamed_geom_19" class="reward_collision_sphere" size="0.076261" pos="-0.0166436 -0.0177648 0.0146165"/>
            <geom name="//unnamed_geom_20" class="reward_collision_sphere" size="0.0217889" pos="-0.0887659 0.0355296 0.0779549"/>
            <body name="right_lower_leg" pos="-0.0106696 -0.00224442 -0.24311" quat="1 -1.88276e-05 -1.51931e-05 2.99873e-05">
              <inertial pos="0.00307312 -0.00303237 -0.128167" quat="0.998859 0.00549246 0.0154973 -0.0448272" mass="0.439559" diaginertia="0.00497031 0.00693831 0.000206337"/>
              <joint name="right_knee" class="/" pos="0 0 0" axis="0.000562287 -0.999997 0.00248195" range="-2.95897 0.029572" armature="0.0105678" damping="0.0257134" frictionloss="0.113297"/>
              <geom name="//unnamed_geom_21" class="/" type="mesh" density="0" rgba="0.752941 0.752941 0.752941 1" mesh="left_leg_lower1"/>
              <geom name="//unnamed_geom_22" class="reward_collision_sphere" size="0.0468461"/>
              <body name="right_foot" pos="0.00299231 -0.00219215 -0.268437" quat="1 -0.000188551 7.1279e-05 -2.79743e-05">
                <inertial pos="0.0226128 -0.00111946 -0.012636" quat="0.478871 0.521014 0.519277 0.479143" mass="0.3538" diaginertia="0.0448074 0.0602182 0.0235475"/>
                <joint name="right_ankle" class="/" pos="0 0 0" axis="0.00103145 -0.999999 0.00137733" range="-1.50947 1.51699" armature="0.0107732" damping="0.0171967" frictionloss="0.105788"/>
                <geom name="//unnamed_geom_23" class="/" type="mesh" density="0" rgba="0.2 0.2 0.2 1" mesh="left_foot1"/>
                <geom name="right_foot" class="foot" size="0.12495 0.0161209 0.0229655" pos="0.0310681 0 -0.0243609" quat="0.707109 0.707105 0 0"/>
                <geom name="//unnamed_geom_25" class="reward_collision_sphere" size="0.0272361" pos="0.0310681 0 -0.0194887"/>
                <geom name="//unnamed_geom_26" class="reward_collision_sphere" size="0.0272361" pos="0.110957 0 -0.0243609"/>
                <geom name="//unnamed_geom_27" class="reward_collision_sphere" size="0.0272361" pos="-0.0499308 0 -0.0243609"/>
                <site name="right_foot" class="foot" pos="0.0310681 0 -0.0243609" quat="0.707109 0.707105 0 0" size="0.0108944"/>
              </body>
            </body>
          </body>
        </body>
      </body>
      <body name="left_shoulder" pos="0.0194579 0.209281 0.298571" quat="0.999999 -0.000936117 0.000369541 -0.00036368">
        <inertial pos="0.0104055 0.063177 -5.8681e-05" quat="0.704295 0.709503 0.0176436 0.0162071" mass="0.987054" diaginertia="0.00230986 0.00200912 0.000667493"/>
        <joint name="left_shoulder_pitch" class="/" pos="0 0 0" axis="0.000607787 0.999919 -0.0126797" range="-2.96194 3.05185" armature="0.0106741" damping="0.00789885" frictionloss="0.108284"/>
        <geom name="//unnamed_geom_28" class="/" type="mesh" density="0" rgba="0.2 0.2 0.2 1" mesh="left_shoulder1"/>
        <body name="left_shoulder_2" pos="0.00207839 0.0691316 -0.000153781" quat="1 -0.000826701 -0.000170495 7.51607e-05">
          <inertial pos="-0.00140246 -0.000254113 -0.0824776" quat="0.00933693 0.756265 -0.0120504 0.654088" mass="1.04564" diaginertia="0.00217866 0.00271038 0.000996748"/>
          <joint name="left_shoulder_abad" class="/" pos="0 0 0" axis="-0.999996 0.00266855 -0.000657475" range="-3.05592 2.95758" armature="0.0100223" damping="0.0118212" frictionloss="0.108041"/>
          <geom name="//unnamed_geom_29" class="/" type="mesh" density="0" rgba="0.752941 0.752941 0.752941 1" mesh="left_shoulder2"/>
          <body name="left_upper_arm" pos="-0.00221292 0.00250754 -0.101178" quat="0.999999 0.000304978 0.00104258 -0.000775237">
            <inertial pos="0.0024883 -0.0195986 -0.0597539" quat="0.708765 -0.018456 0.0217061 0.704869" mass="1.16703" diaginertia="0.0030506 0.00324641 0.000696821"/>
            <joint name="left_shoulder_yaw" class="/" pos="0 0 0" axis="0.00974024 -0.0026684 0.999949" range="-2.99937 3.04064" armature="0.0109557" damping="0.0099186" frictionloss="0.10967"/>
            <geom name="//unnamed_geom_30" class="/" type="mesh" density="0" rgba="0.752941 0.752941 0.752941 1" mesh="left_shoulder3"/>
            <geom name="//unnamed_geom_31" class="reward_collision_sphere" size="0.0653666" pos="-0.0110957 -0.0118432 -0.0487218"/>
            <body name="left_lower_arm" pos="0.000169658 0.000610967 -0.15102" quat="1 -2.97534e-05 -2.51918e-05 2.83211e-05">
              <inertial pos="-0.00633496 -0.00177709 -0.0991369" quat="0.710126 0.0128085 0.0121581 0.703853" mass="0.444285" diaginertia="0.00583431 0.00813064 6.85382e-05"/>
              <joint name="left_elbow" class="/" pos="0 0 0" axis="-0.0134791 0.999907 -0.00222675" range="-3.0304 2.99492" armature="0.0114364" damping="0.0209581" frictionloss="0.101221"/>
              <geom name="//unnamed_geom_32" class="/" type="mesh" density="0" rgba="0.752941 0.752941 0.752941 1" mesh="left_forearm"/>
              <geom name="//unnamed_geom_33" class="/" size="0.0272361 0.00817083" pos="0 0 -0.263098" quat="0.707109 0.707105 0 0" type="cylinder" group="3"/>
              <geom name="//unnamed_geom_34" class="reward_collision_sphere" size="0.0272361"/>
              <geom name="//unnamed_geom_35" class="reward_collision_sphere" size="0.0239678" pos="0 0 -0.272842"/>
            </body>
          </body>
        </body>
      </body>
      <body name="right_shoulder" pos="0.0219339 -0.207592 0.295381" quat="1 4.08388e-05 3.16224e-05 -1.7369e-06">
        <inertial pos="0.00866756 -0.0602758 0.0025695" quat="0.703559 0.710529 -0.00879295 -0.00876271" mass="1.01799" diaginertia="0.00222888 0.00193005 0.00066956"/>
        <joint name="right_shoulder_pitch" class="/" pos="0 0 0" axis="-0.0115381 -0.99993 0.00257267" range="-2.97597 2.96426" armature="0.0121376" damping="0.015034" frictionloss="0.0938263"/>
        <geom name="//unnamed_geom_36" class="/" type="mesh" density="0" rgba="0.2 0.2 0.2 1" mesh="left_shoulder11"/>
        <body name="right_shoulder_2" pos="0.00116731 -0.0674871 0.00184709" quat="1 -0.000601129 0.000530943 -0.000261578">
          <inertial pos="-0.000549608 -0.00295571 -0.0790888" quat="0.000534311 0.651869 0.0123104 0.758231" mass="1.04387" diaginertia="0.0021637 0.00286578 0.00103538"/>
          <joint name="right_shoulder_abad" class="/" pos="0 0 0" axis="-0.999998 0.000258522 -0.00196985" range="-2.94415 2.94436" armature="0.0120163" damping="0" frictionloss="0.11997"/>
          <geom name="//unnamed_geom_37" class="/" type="mesh" density="0" rgba="0.752941 0.752941 0.752941 1" mesh="left_shoulder21"/>
          <body name="right_upper_arm" pos="0.00117923 0.00128536 -0.0995945" quat="0.999999 -0.00119819 8.23121e-05 0.000812576">
            <inertial pos="0.000486512 0.0195537 -0.0589483" quat="0.706136 -0.0174487 0.0137357 0.707727" mass="1.17748" diaginertia="0.00308707 0.00315248 0.000688734"/>
            <joint name="right_shoulder_yaw" class="/" pos="0 0 0" axis="0.000899862 0.0120283 0.999927" stiffness="0.00229969" range="-2.98221 3.00271" armature="0.0106756" damping="0.0131703" frictionloss="0.108624"/>
            <geom name="//unnamed_geom_38" class="/" type="mesh" density="0" rgba="0.752941 0.752941 0.752941 1" mesh="left_shoulder31"/>
            <geom name="//unnamed_geom_39" class="reward_collision_sphere" size="0.0653666" pos="-0.0110957 0.0118432 -0.0487218"/>
            <body name="right_lower_arm" pos="0.00114364 0.000364048 -0.151036" quat="0.999999 -0.000898523 0.000483625 -0.000600509">
              <inertial pos="-0.00770584 -0.000411946 -0.0993939" quat="0.707358 0.00438267 0.00471084 0.706827" mass="0.444428" diaginertia="0.00609914 0.00839362 6.69279e-05"/>
              <joint name="right_elbow" class="/" pos="0 0 0" axis="-0.000904658 -0.999999 0.00120712" stiffness="0.0135667" range="-3.02154 2.9485" armature="0.012288" damping="0.000813864" frictionloss="0.107516"/>
              <geom name="//unnamed_geom_40" class="/" type="mesh" density="0" rgba="0.752941 0.752941 0.752941 1" mesh="left_forearm"/>
              <geom name="//unnamed_geom_41" class="/" size="0.0272361 0.00817083" pos="0 0 -0.263098" quat="0.707109 0.707105 0 0" type="cylinder" group="3"/>
              <geom name="//unnamed_geom_42" class="reward_collision_sphere" size="0.0272361"/>
              <geom name="//unnamed_geom_43" class="reward_collision_sphere" size="0.0239678" pos="0 0 -0.272842"/>
            </body>
          </body>
        </body>
      </body>
    </body>
  </worldbody>

  <contact>
    <pair class="/" geom1="floor" geom2="left_foot" name="//unnamed_contact_0"/>
    <pair class="/" geom1="floor" geom2="right_foot" name="//unnamed_contact_1"/>
  </contact>

  <actuator>
    <general name="left_hip_yaw" class="/" joint="left_hip_yaw" forcerange="-36.9391 36.9391" gainprm="32.8262" biasprm="0 -32.8262 -0.531825"/>
    <general name="left_hip_abad" class="/" joint="left_hip_abad" forcerange="-40.7421 40.7421" gainprm="32.8262" biasprm="0 -32.8262 -0.531825"/>
    <general name="left_hip_pitch" class="/" joint="left_hip_pitch" forcerange="-77.7945 77.7945" gainprm="32.8262" biasprm="0 -32.8262 -0.531825"/>
    <general name="left_knee" class="/" joint="left_knee" forcerange="-172.628 172.628" gainprm="32.8262" biasprm="0 -32.8262 -0.531825"/>
    <general name="left_ankle" class="/" joint="left_ankle" forcerange="-70.1506 70.1506" gainprm="32.8262" biasprm="0 -32.8262 -0.531825"/>
    <general name="right_hip_yaw" class="/" joint="right_hip_yaw" forcerange="-39.1862 39.1862" gainprm="32.8262" biasprm="0 -32.8262 -0.531825"/>
    <general name="right_hip_abad" class="/" joint="right_hip_abad" forcerange="-37.0877 37.0877" gainprm="32.8262" biasprm="0 -32.8262 -0.531825"/>
    <general name="right_hip_pitch" class="/" joint="right_hip_pitch" forcerange="-81.706 81.706" gainprm="32.8262" biasprm="0 -32.8262 -0.531825"/>
    <general name="right_knee" class="/" joint="right_knee" forcerange="-147.456 147.456" gainprm="32.8262" biasprm="0 -32.8262 -0.531825"/>
    <general name="right_ankle" class="/" joint="right_ankle" forcerange="-73.6225 73.6225" gainprm="32.8262" biasprm="0 -32.8262 -0.531825"/>
    <general name="left_shoulder_pitch" class="/" joint="left_shoulder_pitch" forcerange="-34.5624 34.5624" gainprm="32.8262" biasprm="0 -32.8262 -0.531825"/>
    <general name="left_shoulder_abad" class="/" joint="left_shoulder_abad" forcerange="-37.2244 37.2244" gainprm="32.8262" biasprm="0 -32.8262 -0.531825"/>
    <general name="left_shoulder_yaw" class="/" joint="left_shoulder_yaw" forcerange="-37.2282 37.2282" gainprm="32.8262" biasprm="0 -32.8262 -0.531825"/>
    <general name="left_elbow" class="/" joint="left_elbow" forcerange="-60.7859 60.7859" gainprm="32.8262" biasprm="0 -32.8262 -0.531825"/>
    <general name="right_shoulder_pitch" class="/" joint="right_shoulder_pitch" forcerange="-38.9792 38.9792" gainprm="32.8262" biasprm="0 -32.8262 -0.531825"/>
    <general name="right_shoulder_abad" class="/" joint="right_shoulder_abad" forcerange="-34.0368 34.0368" gainprm="32.8262" biasprm="0 -32.8262 -0.531825"/>
    <general name="right_shoulder_yaw" class="/" joint="right_shoulder_yaw" forcerange="-38.8187 38.8187" gainprm="32.8262" biasprm="0 -32.8262 -0.531825"/>
    <general name="right_elbow" class="/" joint="right_elbow" forcerange="-61.297 61.297" gainprm="32.8262" biasprm="0 -32.8262 -0.531825"/>
  </actuator>

  <sensor>
    <gyro site="imu" name="imu_angular_velocity"/>
    <velocimeter site="imu" name="imu_linear_velocity"/>
    <framelinvel objtype="site" objname="left_foot" name="left_foot_global_linear_velocity"/>
    <framelinvel objtype="site" objname="right_foot" name="right_foot_global_linear_velocity"/>
  </sensor>

  <keyframe>
    <key name="home" qpos="0 0 0.656 1 0 0 0 0 0 -0.4 0.8 -0.4 0 0 0.4 -0.8 0.4 0 -0.05 0 -0.75 0 0.05 0 0.75"/>
  </keyframe>
</mujoco>
