<mujoco model="humanoid">
  <compiler angle="radian" assetdir="assets" balanceinertia="true" inertiafromgeom="false"/>

  <option timestep="0.005" density="1.2" viscosity="2e-05"/>

  <size nkey="1"/>

  <visual>
    <quality shadowsize="8192"/>
    <map shadowclip="0.5"/>
  </visual>

  <default>
    <default class="/">
      <joint armature="0.01" damping="0.01" frictionloss="0.1"/>
      <geom contype="0" conaffinity="0" group="1" solref="-1000 -80"/>
      <site size="0.01 0.005 0.005" group="5"/>
      <general forcelimited="true" biastype="affine" gainprm="30" biasprm="0 -30 -0.5"/>
      <default class="foot">
        <geom size="0.099 0.0178 0.021" type="box" condim="6" group="4" priority="1" solimp="0.015 1 0.021"/>
      </default>
      <default class="reward_collision_sphere">
        <geom group="5" rgba="1 0 0 1"/>
      </default>
    </default>
  </default>

  <asset>
    <texture type="skybox" colorspace="auto" name="//unnamed_texture_0" builtin="gradient" rgb1="0.95 0.95 0.95" rgb2="0.95 0.95 0.95" width="100" height="600"/>
    <texture type="2d" colorspace="auto" name="texplane" builtin="checker" rgb1="0.345 0.575 0.748" rgb2="0.345 0.575 0.748" markrgb="1 1 1" width="512" height="512"/>
    <material name="MatPlane" class="/" texture="texplane" texuniform="true" texrepeat="2 2" specular="0.9"/>
    <mesh name="torso" class="/" file="torso.stl" scale="0.001 0.001 0.001"/>
    <mesh name="left_hip_yaw" class="/" file="left_hip_yaw.stl" scale="0.001 0.001 0.001"/>
    <mesh name="left_hip_abad" class="/" file="left_hip_abad.stl" scale="0.001 0.001 0.001"/>
    <mesh name="left_leg_upper" class="/" file="left_leg_upper.stl" scale="0.001 0.001 0.001"/>
    <mesh name="left_leg_lower" class="/" file="left_leg_lower.stl" scale="0.001 0.001 0.001"/>
    <mesh name="left_foot" class="/" file="left_foot.stl" scale="0.001 0.001 0.001"/>
    <mesh name="left_hip_yaw1" class="/" content_type="model/stl" file="left_hip_yaw.stl" scale="0.001 -0.001 0.001"/>
    <mesh name="left_hip_abad1" class="/" content_type="model/stl" file="left_hip_abad.stl" scale="0.001 -0.001 0.001"/>
    <mesh name="left_leg_upper1" class="/" content_type="model/stl" file="left_leg_upper.stl" scale="0.001 -0.001 0.001"/>
    <mesh name="left_leg_lower1" class="/" content_type="model/stl" file="left_leg_lower.stl" scale="0.001 -0.001 0.001"/>
    <mesh name="left_foot1" class="/" content_type="model/stl" file="left_foot.stl" scale="0.001 -0.001 0.001"/>
    <mesh name="left_shoulder1" class="/" file="left_shoulder1.stl" scale="0.001 0.001 0.001"/>
    <mesh name="left_shoulder2" class="/" file="left_shoulder2.stl" scale="0.001 0.001 0.001"/>
    <mesh name="left_shoulder3" class="/" file="left_shoulder3.stl" scale="0.001 0.001 0.001"/>
    <mesh name="left_forearm" class="/" file="left_forearm.stl" scale="0.001 0.001 0.001"/>
    <mesh name="left_shoulder11" class="/" content_type="model/stl" file="left_shoulder1.stl" scale="0.001 -0.001 0.001"/>
    <mesh name="left_shoulder21" class="/" content_type="model/stl" file="left_shoulder2.stl" scale="0.001 -0.001 0.001"/>
    <mesh name="left_shoulder31" class="/" content_type="model/stl" file="left_shoulder3.stl" scale="0.001 -0.001 0.001"/>
  </asset>

  <worldbody>
    <geom name="floor" class="/" size="100 100 0.125" type="plane" group="0" material="MatPlane"/>
    <light name="toplight_shadow" class="/" pos="0 0 5" dir="0.0990148 0.0990148 -0.990148" type="directional" ambient="0.04 0.04 0.04" diffuse="0.55 0.55 0.55" specular="0.12 0.12 0.12"/>
    <light name="toplight_fill" class="/" pos="0 0 5" dir="0.0990148 0.0990148 -0.990148" type="directional" castshadow="false" ambient="0.04 0.04 0.04" diffuse="0.3 0.3 0.3" specular="0.08 0.08 0.08"/>
    <body name="trunk" pos="0.0180686 -0.0138595 0.000717907" quat="0.999996 -0.000479635 -0.000540593 0.00273716">
      <inertial pos="-0.00814436 -0.010971 0.22561" quat="0.996589 0.0468573 -0.0554579 0.0392279" mass="6.14719" diaginertia="0.0128345 0.0134207 0.559168"/>
      <joint name="//unnamed_joint_0" type="free"/>
      <geom name="//unnamed_geom_1" class="/" type="mesh" density="0" rgba="0.752941 0.752941 0.752941 1" mesh="torso"/>
      <geom name="//unnamed_geom_2" class="/" size="0.0699732 0.139946 0.163271" pos="0.0142273 0 0.120221" type="box" group="3" rgba="0.752941 0.752941 0.752941 1"/>
      <geom name="//unnamed_geom_3" class="reward_collision_sphere" size="0.135281" pos="0 0 0.225414"/>
      <site name="imu" class="/" pos="-0.0641732 -0.0386402 0.290028" size="0.00932975"/>
      <camera name="track" class="/" pos="0 -1.35517 0" quat="0.707107 0.707107 0 0" mode="trackcom"/>
      <camera name="ego_camera" class="/" pos="0.0278361 0 0.450828" quat="-0.5 -0.5 0.5 0.5"/>
      <body name="left_hip_yaw" pos="0.00710312 0.0552891 0.0165498" quat="0.995719 -0.00124377 -0.0922066 0.00637229">
        <inertial pos="-0.0483395 0.00444638 -0.10468" quat="0.949428 -0.00547056 -0.313924 -0.00275213" mass="0.817673" diaginertia="0.000197489 0.000187691 0.00633028"/>
        <joint name="left_hip_yaw" class="/" pos="0 0 0" axis="-0.0209712 -0.0365533 -0.999112" range="-3.22133 3.24252" armature="0.00184847" damping="0.0978461" frictionloss="0.172129"/>
        <geom name="//unnamed_geom_4" class="/" type="mesh" density="0" rgba="0.2 0.2 0.2 1" mesh="left_hip_yaw"/>
        <body name="left_hip_abad" pos="-0.0303297 0.0152871 -0.128221" quat="0.975981 0.00444698 0.217746 -0.00521644">
          <inertial pos="0.0581883 0.00964247 -0.0174242" quat="0.586346 0.394513 0.404247 0.580639" mass="0.98685" diaginertia="0.000289076 0.000252155 0.0112758"/>
          <joint name="left_hip_abad" class="/" pos="0 0 0" axis="-0.999375 0.0246777 0.0253016" range="-3.10598 3.31205" armature="0.00931298" damping="0" frictionloss="0.075878"/>
          <geom name="//unnamed_geom_5" class="/" type="mesh" density="0" rgba="0.2 0.2 0.2 1" mesh="left_hip_abad"/>
          <body name="left_upper_leg" pos="0.0424944 -0.0192962 -0.00764046" quat="0.991263 -0.00898835 -0.131592 0.000987797">
            <inertial pos="-0.012318 0.0201598 -0.107654" quat="0.718255 0.0165701 -0.0464779 0.694028" mass="2.18885" diaginertia="0.00221918 0.00288802 0.027039"/>
            <joint name="left_hip_pitch" class="/" pos="0 0 0" axis="-0.0291833 0.997972 -0.0565689" stiffness="0.00356636" range="-3.13881 2.67352" armature="0.0194524" damping="0" frictionloss="0.0968523"/>
            <geom name="//unnamed_geom_6" class="/" type="mesh" density="0" rgba="0.752941 0.752941 0.752941 1" mesh="left_leg_upper"/>
            <geom name="//unnamed_geom_7" class="reward_collision_sphere" size="0.0653083" pos="-0.00927869 0.0101638 0.0225414"/>
            <geom name="//unnamed_geom_8" class="reward_collision_sphere" size="0.0186595" pos="-0.0494864 -0.0203276 0.120221"/>
            <body name="left_lower_leg" pos="0.0104341 -0.0194404 -0.362858" quat="0.999997 0.00244033 -0.000194817 0.000221814">
              <inertial pos="-0.0142026 -0.0122982 -0.199466" quat="0.998283 -0.00672891 0.0197017 0.0547493" mass="0.215491" diaginertia="0.000242948 0.000308107 0.00173255"/>
              <joint name="left_knee" class="/" pos="0 0 0" axis="-0.0426182 0.998866 -0.0212297" stiffness="0.0224955" range="0.183919 2.68612" armature="0.0108039" damping="0.0195716" frictionloss="0.0878543"/>
              <geom name="//unnamed_geom_9" class="/" type="mesh" density="0" rgba="0.752941 0.752941 0.752941 1" mesh="left_leg_lower"/>
              <geom name="//unnamed_geom_10" class="reward_collision_sphere" size="0.0401179"/>
              <body name="left_foot" pos="0.00911325 0.0163275 -0.427704" quat="1 -8.68965e-05 -9.00557e-05 7.45576e-05">
                <inertial pos="0.0207869 0.0161331 -0.0061779" quat="0.572623 0.447469 0.434279 0.532236" mass="0.221025" diaginertia="0.00226622 0.00387087 0.174821"/>
                <joint name="left_ankle" class="/" pos="0 0 0" axis="-0.0513518 0.997956 -0.0380406" stiffness="0.0675476" range="-1.20383 1.42954" armature="0.00286046" damping="0" frictionloss="0.0625161"/>
                <geom name="//unnamed_geom_11" class="/" type="mesh" density="0" rgba="0.2 0.2 0.2 1" mesh="left_foot"/>
                <geom name="left_foot" class="foot" size="0.0864152 0.0110562 0.0172142" pos="0.0173202 0 -0.037569" quat="0.707109 0.707105 0 0"/>
                <geom name="//unnamed_geom_13" class="reward_collision_sphere" size="0.0233244" pos="0.0173202 0 -0.0300552"/>
                <geom name="//unnamed_geom_14" class="reward_collision_sphere" size="0.0233244" pos="0.0618579 0 -0.037569"/>
                <geom name="//unnamed_geom_15" class="reward_collision_sphere" size="0.0233244" pos="-0.0278361 0 -0.037569"/>
                <site name="left_foot" class="foot" pos="0.0173202 0 -0.037569" quat="0.707109 0.707105 0 0" size="0.00932975"/>
              </body>
            </body>
          </body>
        </body>
      </body>
      <body name="right_hip_yaw" pos="0.00859109 -0.0660651 -0.0169587" quat="0.996153 -0.00198071 -0.08748 0.00471973">
        <inertial pos="-0.0286814 -0.017804 -0.0770316" quat="0.952525 0.0255671 0.300808 0.0394678" mass="0.59328" diaginertia="0.000156952 0.00017528 0.00540483"/>
        <joint name="right_hip_yaw" class="/" pos="0 0 0" axis="0.0263057 0.0299912 -0.999204" stiffness="0.0327962" range="-2.7759 2.64205" armature="0.000367203" damping="0.0131098" frictionloss="0.164993"/>
        <geom name="//unnamed_geom_16" class="/" type="mesh" density="0" rgba="0.2 0.2 0.2 1" mesh="left_hip_yaw1"/>
        <body name="right_hip_abad" pos="-0.0299974 -0.0183115 -0.104708" quat="0.976233 -0.000412886 0.216722 0.00015278">
          <inertial pos="0.0463881 -0.00772304 -0.00960448" quat="0.460438 0.574375 0.573554 0.359341" mass="0.805924" diaginertia="0.000327917 0.000235078 0.0103076"/>
          <joint name="right_hip_abad" class="/" pos="0 0 0" axis="-0.996068 0.0872177 0.0155232" range="-2.96493 3.14152" armature="0.00681506" damping="0.0941001" frictionloss="0.113926"/>
          <geom name="//unnamed_geom_17" class="/" type="mesh" density="0" rgba="0.2 0.2 0.2 1" mesh="left_hip_abad1"/>
          <body name="right_upper_leg" pos="0.0460024 0.00142128 -0.00515192" quat="0.991337 -0.00114502 -0.131334 0.000554356">
            <inertial pos="0.00414973 -0.0222133 -0.120617" quat="0.694813 0.0373056 -0.0343811 0.717399" mass="1.50222" diaginertia="0.00229855 0.00230807 0.0215034"/>
            <joint name="right_hip_pitch" class="/" pos="0 0 0" axis="0.0505254 -0.998694 0.00760705" stiffness="0.0149714" range="-3.2964 3.08672" armature="0.0136576" damping="0.0878074" frictionloss="0.173999"/>
            <geom name="//unnamed_geom_18" class="/" type="mesh" density="0" rgba="0.752941 0.752941 0.752941 1" mesh="left_leg_upper1"/>
            <geom name="//unnamed_geom_19" class="reward_collision_sphere" size="0.0653083" pos="-0.00927869 -0.0101638 0.0225414"/>
            <geom name="//unnamed_geom_20" class="reward_collision_sphere" size="0.0186595" pos="-0.0494864 0.0203276 0.120221"/>
            <body name="right_lower_leg" pos="-0.0183423 -0.00126702 -0.380226" quat="0.999995 0.00106605 -0.00273646 -0.00122769">
              <inertial pos="0.0154198 0.0126516 -0.195863" quat="0.999188 0.012048 0.00558196 -0.038037" mass="0.323988" diaginertia="0.000257096 0.000430664 0.0017443"/>
              <joint name="right_knee" class="/" pos="0 0 0" axis="-0.012702 -0.999629 -0.0240792" range="-3.28558 -0.156809" armature="0" damping="0" frictionloss="0.116086"/>
              <geom name="//unnamed_geom_21" class="/" type="mesh" density="0" rgba="0.752941 0.752941 0.752941 1" mesh="left_leg_lower1"/>
              <geom name="//unnamed_geom_22" class="reward_collision_sphere" size="0.0401179"/>
              <body name="right_foot" pos="-0.0123848 -0.00105394 -0.431254" quat="0.999963 0.000539468 -0.00838194 0.00208099">
                <inertial pos="0.0257373 -0.0037598 -0.00187755" quat="0.41605 0.582198 0.499587 0.488222" mass="0.26841" diaginertia="0.0032268 0.00469849 0.232399"/>
                <joint name="right_ankle" class="/" pos="0 0 0" axis="0.0307666 -0.999514 -0.00506459" stiffness="0.0410085" range="-1.60777 1.59567" armature="0" damping="0.0989943" frictionloss="0.172566"/>
                <geom name="//unnamed_geom_23" class="/" type="mesh" density="0" rgba="0.2 0.2 0.2 1" mesh="left_foot1"/>
                <geom name="right_foot" class="foot" size="0.0601383 0.0224281 0.00662563" pos="0.0173202 0 -0.037569" quat="0.707109 0.707105 0 0"/>
                <geom name="//unnamed_geom_25" class="reward_collision_sphere" size="0.0233244" pos="0.0173202 0 -0.0300552"/>
                <geom name="//unnamed_geom_26" class="reward_collision_sphere" size="0.0233244" pos="0.0618579 0 -0.037569"/>
                <geom name="//unnamed_geom_27" class="reward_collision_sphere" size="0.0233244" pos="-0.0278361 0 -0.037569"/>
                <site name="right_foot" class="foot" pos="0.0173202 0 -0.037569" quat="0.707109 0.707105 0 0" size="0.00932975"/>
              </body>
            </body>
          </body>
        </body>
      </body>
      <body name="left_shoulder" pos="0.0237814 0.123902 0.448044" quat="0.999996 -0.0018073 -0.00159892 0.00166925">
        <inertial pos="0.010094 0.0546383 -0.0181503" quat="0.71079 0.700867 0.0277639 0.0528451" mass="0.723124" diaginertia="0.000125726 0.000119306 0.00688313"/>
        <joint name="left_shoulder_pitch" class="/" pos="0 0 0" axis="-0.0455196 0.998401 0.0335078" range="-3.2959 2.74786" armature="0.0126099" damping="0" frictionloss="0.0961362"/>
        <geom name="//unnamed_geom_28" class="/" type="mesh" density="0" rgba="0.2 0.2 0.2 1" mesh="left_shoulder1"/>
        <body name="left_shoulder_2" pos="0.0189242 0.03284 0.00685027" quat="0.999996 0.000405661 0.00274845 -0.000842049">
          <inertial pos="0.0153801 0.00245775 -0.11582" quat="-0.0128437 0.738891 -0.0295401 0.673054" mass="0.744149" diaginertia="0.000103694 0.00019592 0.00952161"/>
          <joint name="left_shoulder_abad" class="/" pos="0 0 0" axis="-0.99543 -0.0605663 -0.07383" stiffness="0.0314715" range="-2.77499 3.1727" armature="0.0165959" damping="0.0116159" frictionloss="0.0886164"/>
          <geom name="//unnamed_geom_29" class="/" type="mesh" density="0" rgba="0.752941 0.752941 0.752941 1" mesh="left_shoulder2"/>
          <body name="left_upper_arm" pos="0.00932895 -0.00939094 -0.173562" quat="0.999984 0.000594193 0.00547774 -0.0011154">
            <inertial pos="-0.0123414 -0.00921286 -0.103418" quat="0.766983 -0.0478438 0.0398877 0.638637" mass="0.864916" diaginertia="0.000155731 0.000214114 0.00909151"/>
            <joint name="left_shoulder_yaw" class="/" pos="0 0 0" axis="0.0276967 -0.022221 0.999369" stiffness="0.0583143" range="-3.03664 2.8256" armature="0.00886762" damping="0" frictionloss="0.106599"/>
            <geom name="//unnamed_geom_30" class="/" type="mesh" density="0" rgba="0.752941 0.752941 0.752941 1" mesh="left_shoulder3"/>
            <geom name="//unnamed_geom_31" class="reward_collision_sphere" size="0.0559785" pos="-0.00618579 -0.00677586 -0.0751381"/>
            <body name="left_lower_arm" pos="0.0157046 0.0182567 -0.249876" quat="0.999961 -0.00033374 -0.000755677 -0.008759">
              <inertial pos="-0.020162 -0.0199219 -0.134701" quat="0.724172 -0.0348161 0.00375054 0.68873" mass="0.312279" diaginertia="0.000411812 0.000423875 0.000582021"/>
              <joint name="left_elbow" class="/" pos="0 0 0" axis="-0.0027521 0.998443 -0.0557159" range="-2.84624 2.97428" armature="0.0109887" damping="0.113726" frictionloss="0.00111299"/>
              <geom name="//unnamed_geom_32" class="/" type="mesh" density="0" rgba="0.752941 0.752941 0.752941 1" mesh="left_forearm"/>
              <geom name="//unnamed_geom_33" class="/" size="0.0233244 0.00699732" pos="0 0 -0.405746" quat="0.707109 0.707105 0 0" type="cylinder" group="3"/>
              <geom name="//unnamed_geom_34" class="reward_collision_sphere" size="0.0233244"/>
              <geom name="//unnamed_geom_35" class="reward_collision_sphere" size="0.0205255" pos="0 0 -0.420773"/>
            </body>
          </body>
        </body>
      </body>
      <body name="right_shoulder" pos="-0.00203474 -0.122003 0.460622" quat="0.999997 0.0019866 -0.00114327 -0.000535684">
        <inertial pos="0.0127238 -0.0477295 -0.00959709" quat="0.732395 0.680681 0.0114235 0.0118481" mass="0.633946" diaginertia="8.82013e-05 0.000136144 0.00442426"/>
        <joint name="right_shoulder_pitch" class="/" pos="0 0 0" axis="0.0272209 -0.997723 0.0617" range="-3.15078 3.29975" armature="0.00530497" damping="0" frictionloss="0.143241"/>
        <geom name="//unnamed_geom_36" class="/" type="mesh" density="0" rgba="0.2 0.2 0.2 1" mesh="left_shoulder11"/>
        <body name="right_shoulder_2" pos="0.0195593 -0.0204891 0.0195141" quat="0.999977 0.00481373 -0.00437746 0.00206069">
          <inertial pos="-0.00130385 0.0126488 -0.13966" quat="0.0106925 0.646488 0.00625945 0.762823" mass="0.648336" diaginertia="7.39816e-05 0.000175696 0.00713089"/>
          <joint name="right_shoulder_abad" class="/" pos="0 0 0" axis="-0.999543 -0.029539 -0.00641459" stiffness="0.0783783" range="-3.23853 3.24343" armature="0.00574003" damping="0.0476629" frictionloss="0.0260434"/>
          <geom name="//unnamed_geom_37" class="/" type="mesh" density="0" rgba="0.752941 0.752941 0.752941 1" mesh="left_shoulder21"/>
          <body name="right_upper_arm" pos="-0.0101772 0.00395533 -0.156598" quat="0.999988 -0.00255117 0.00277032 -0.00307024">
            <inertial pos="0.0186662 0.0289169 -0.105203" quat="0.726893 -0.035614 0.042437 0.684513" mass="0.657808" diaginertia="0.000137389 0.000138145 0.00529519"/>
            <joint name="right_shoulder_yaw" class="/" pos="0 0 0" axis="0.0610969 0.0327745 0.997594" stiffness="0.0790847" range="-2.90575 3.11678" armature="0.00951109" damping="0.0276214" frictionloss="0.176132"/>
            <geom name="//unnamed_geom_38" class="/" type="mesh" density="0" rgba="0.752941 0.752941 0.752941 1" mesh="left_shoulder31"/>
            <geom name="//unnamed_geom_39" class="reward_collision_sphere" size="0.0559785" pos="-0.00618579 0.00677586 -0.0751381"/>
            <body name="right_lower_arm" pos="-0.0107439 -0.0173849 -0.249936" quat="0.999977 -0.00450033 -0.00365186 -0.00358906">
              <inertial pos="0.00125008 -0.00564542 -0.143082" quat="0.7273 0.0117974 0.00986334 0.686148" mass="0.341265" diaginertia="0.000309868 0.000522283 0.000449668"/>
              <joint name="right_elbow" class="/" pos="0 0 0" axis="0.0459316 -0.995959 -0.0771748" range="-2.85428 3.19862" armature="0.0045804" damping="0.0380364" frictionloss="0.00825811"/>
              <geom name="//unnamed_geom_40" class="/" type="mesh" density="0" rgba="0.752941 0.752941 0.752941 1" mesh="left_forearm"/>
              <geom name="//unnamed_geom_41" class="/" size="0.0233244 0.00699732" pos="0 0 -0.405746" quat="0.707109 0.707105 0 0" type="cylinder" group="3"/>
              <geom name="//unnamed_geom_42" class="reward_collision_sphere" size="0.0233244"/>
              <geom name="//unnamed_geom_43" class="reward_collision_sphere" size="0.0205255" pos="0 0 -0.420773"/>
            </body>
          </body>
        </body>
      </body>
    </body>
  </worldbody>

  <contact>
    <pair class="/" geom1="floor" geom2="left_foot" name="//unnamed_contact_0"/>
    <pair class="/" geom1="floor" geom2="right_foot" name="//unnamed_contact_1"/>
  </contact>

  <actuator>
    <general name="left_hip_yaw" class="/" joint="left_hip_yaw" forcerange="-32.7734 32.7734" gainprm="26.7579" biasprm="0 -26.7579 -0.657869"/>
    <general name="left_hip_abad" class="/" joint="left_hip_abad" forcerange="-20.1789 20.1789" gainprm="26.7579" biasprm="0 -26.7579 -0.657869"/>
    <general name="left_hip_pitch" class="/" joint="left_hip_pitch" forcerange="-61.0356 61.0356" gainprm="26.7579" biasprm="0 -26.7579 -0.657869"/>
    <general name="left_knee" class="/" joint="left_knee" forcerange="-78.253 78.253" gainprm="26.7579" biasprm="0 -26.7579 -0.657869"/>
    <general name="left_ankle" class="/" joint="left_ankle" forcerange="-100.896 100.896" gainprm="26.7579" biasprm="0 -26.7579 -0.657869"/>
    <general name="right_hip_yaw" class="/" joint="right_hip_yaw" forcerange="-22.3083 22.3083" gainprm="26.7579" biasprm="0 -26.7579 -0.657869"/>
    <general name="right_hip_abad" class="/" joint="right_hip_abad" forcerange="-52.9089 52.9089" gainprm="26.7579" biasprm="0 -26.7579 -0.657869"/>
    <general name="right_hip_pitch" class="/" joint="right_hip_pitch" forcerange="-27.7856 27.7856" gainprm="26.7579" biasprm="0 -26.7579 -0.657869"/>
    <general name="right_knee" class="/" joint="right_knee" forcerange="-120.208 120.208" gainprm="26.7579" biasprm="0 -26.7579 -0.657869"/>
    <general name="right_ankle" class="/" joint="right_ankle" forcerange="-58.0604 58.0604" gainprm="26.7579" biasprm="0 -26.7579 -0.657869"/>
    <general name="left_shoulder_pitch" class="/" joint="left_shoulder_pitch" forcerange="-41.6864 41.6864" gainprm="26.7579" biasprm="0 -26.7579 -0.657869"/>
    <general name="left_shoulder_abad" class="/" joint="left_shoulder_abad" forcerange="-24.3471 24.3471" gainprm="26.7579" biasprm="0 -26.7579 -0.657869"/>
    <general name="left_shoulder_yaw" class="/" joint="left_shoulder_yaw" forcerange="-31.3641 31.3641" gainprm="26.7579" biasprm="0 -26.7579 -0.657869"/>
    <general name="left_elbow" class="/" joint="left_elbow" forcerange="-18.2509 18.2509" gainprm="26.7579" biasprm="0 -26.7579 -0.657869"/>
    <general name="right_shoulder_pitch" class="/" joint="right_shoulder_pitch" forcerange="-22.7297 22.7297" gainprm="26.7579" biasprm="0 -26.7579 -0.657869"/>
    <general name="right_shoulder_abad" class="/" joint="right_shoulder_abad" forcerange="-42.4263 42.4263" gainprm="26.7579" biasprm="0 -26.7579 -0.657869"/>
    <general name="right_shoulder_yaw" class="/" joint="right_shoulder_yaw" forcerange="-12.9697 12.9697" gainprm="26.7579" biasprm="0 -26.7579 -0.657869"/>
    <general name="right_elbow" class="/" joint="right_elbow" forcerange="-48.43 48.43" gainprm="26.7579" biasprm="0 -26.7579 -0.657869"/>
  </actuator>

  <sensor>
    <gyro site="imu" name="imu_angular_velocity"/>
    <velocimeter site="imu" name="imu_linear_velocity"/>
    <framelinvel objtype="site" objname="left_foot" name="left_foot_global_linear_velocity"/>
    <framelinvel objtype="site" objname="right_foot" name="right_foot_global_linear_velocity"/>
  </sensor>

  <keyframe>
    <key name="home" qpos="0 0 0.656 1 0 0 0 0 0 -0.4 0.8 -0.4 0 0 0.4 -0.8 0.4 0 -0.05 0 -0.75 0 0.05 0 0.75"/>
  </keyframe>
</mujoco>
