<mujoco model="humanoid">
  <compiler angle="radian" assetdir="assets" balanceinertia="true" inertiafromgeom="false"/>

  <option timestep="0.005" density="1.2" viscosity="2e-05"/>

  <size nkey="1"/>

  <visual>
    <quality shadowsize="8192"/>
    <map shadowclip="0.5"/>
  </visual>

  <default>
    <default class="/">
      <joint armature="0.01" damping="0.01" frictionloss="0.1"/>
      <geom contype="0" conaffinity="0" group="1" solref="-1000 -80"/>
      <site size="0.01 0.005 0.005" group="5"/>
      <general forcelimited="true" biastype="affine" gainprm="30" biasprm="0 -30 -0.5"/>
      <default class="foot">
        <geom size="0.099 0.0178 0.021" type="box" condim="6" group="4" priority="1" solimp="0.015 1 0.021"/>
      </default>
      <default class="reward_collision_sphere">
        <geom group="5" rgba="1 0 0 1"/>
      </default>
    </default>
  </default>

  <asset>
    <texture type="skybox" colorspace="auto" name="//unnamed_texture_0" builtin="gradient" rgb1="0.95 0.95 0.95" rgb2="0.95 0.95 0.95" width="100" height="600"/>
    <texture type="2d" colorspace="auto" name="texplane" builtin="checker" rgb1="0.345 0.575 0.748" rgb2="0.345 0.575 0.748" markrgb="1 1 1" width="512" height="512"/>
    <material name="MatPlane" class="/" texture="texplane" texuniform="true" texrepeat="2 2" specular="0.9"/>
    <mesh name="torso" class="/" file="torso.stl" scale="0.001 0.001 0.001"/>
    <mesh name="left_hip_yaw" class="/" file="left_hip_yaw.stl" scale="0.001 0.001 0.001"/>
    <mesh name="left_hip_abad" class="/" file="left_hip_abad.stl" scale="0.001 0.001 0.001"/>
    <mesh name="left_leg_upper" class="/" file="left_leg_upper.stl" scale="0.001 0.001 0.001"/>
    <mesh name="left_leg_lower" class="/" file="left_leg_lower.stl" scale="0.001 0.001 0.001"/>
    <mesh name="left_foot" class="/" file="left_foot.stl" scale="0.001 0.001 0.001"/>
    <mesh name="left_hip_yaw1" class="/" content_type="model/stl" file="left_hip_yaw.stl" scale="0.001 -0.001 0.001"/>
    <mesh name="left_hip_abad1" class="/" content_type="model/stl" file="left_hip_abad.stl" scale="0.001 -0.001 0.001"/>
    <mesh name="left_leg_upper1" class="/" content_type="model/stl" file="left_leg_upper.stl" scale="0.001 -0.001 0.001"/>
    <mesh name="left_leg_lower1" class="/" content_type="model/stl" file="left_leg_lower.stl" scale="0.001 -0.001 0.001"/>
    <mesh name="left_foot1" class="/" content_type="model/stl" file="left_foot.stl" scale="0.001 -0.001 0.001"/>
    <mesh name="left_shoulder1" class="/" file="left_shoulder1.stl" scale="0.001 0.001 0.001"/>
    <mesh name="left_shoulder2" class="/" file="left_shoulder2.stl" scale="0.001 0.001 0.001"/>
    <mesh name="left_shoulder3" class="/" file="left_shoulder3.stl" scale="0.001 0.001 0.001"/>
    <mesh name="left_forearm" class="/" file="left_forearm.stl" scale="0.001 0.001 0.001"/>
    <mesh name="left_shoulder11" class="/" content_type="model/stl" file="left_shoulder1.stl" scale="0.001 -0.001 0.001"/>
    <mesh name="left_shoulder21" class="/" content_type="model/stl" file="left_shoulder2.stl" scale="0.001 -0.001 0.001"/>
    <mesh name="left_shoulder31" class="/" content_type="model/stl" file="left_shoulder3.stl" scale="0.001 -0.001 0.001"/>
  </asset>

  <worldbody>
    <geom name="floor" class="/" size="100 100 0.125" type="plane" group="0" material="MatPlane"/>
    <light name="toplight_shadow" class="/" pos="0 0 5" dir="0.0990148 0.0990148 -0.990148" type="directional" ambient="0.04 0.04 0.04" diffuse="0.55 0.55 0.55" specular="0.12 0.12 0.12"/>
    <light name="toplight_fill" class="/" pos="0 0 5" dir="0.0990148 0.0990148 -0.990148" type="directional" castshadow="false" ambient="0.04 0.04 0.04" diffuse="0.3 0.3 0.3" specular="0.08 0.08 0.08"/>
    <body name="trunk" pos="-0.00011486 0.000318946 -2.17115e-05" quat="1 1.31931e-05 -8.05583e-06 -3.26959e-05">
      <inertial pos="0.0104492 0.00112003 0.130241" quat="1 0.000107032 -5.06157e-05 -9.21382e-05" mass="8.46033" diaginertia="0.185351 0.230481 0.0435846"/>
      <joint name="//unnamed_joint_0" type="free"/>
      <geom name="//unnamed_geom_1" class="/" type="mesh" density="0" rgba="0.752941 0.752941 0.752941 1" mesh="torso"/>
      <geom name="//unnamed_geom_2" class="/" size="0.0765021 0.153004 0.178505" pos="0.023471 0 0.0687874" type="box" group="3" rgba="0.752941 0.752941 0.752941 1"/>
      <geom name="//unnamed_geom_3" class="reward_collision_sphere" size="0.147904" pos="0 0 0.128976"/>
      <site name="imu" class="/" pos="-0.000887004 -0.00114655 0.128717" size="0.0102003"/>
      <camera name="track" class="/" pos="0 -2.35953 0" quat="0.707107 0.707107 0 0" mode="trackcom"/>
      <camera name="ego_camera" class="/" pos="0.0459214 0 0.257953" quat="-0.5 -0.5 0.5 0.5"/>
      <body name="left_hip_yaw" pos="4.91477e-05 0.0962263 0.000905641" quat="0.996203 0.000327376 -0.0870599 0.000275477">
        <inertial pos="-0.0647017 0.000576503 -0.0545125" quat="0.951417 0.00427938 -0.30783 0.00528889" mass="0.903295" diaginertia="0.00211245 0.00315707 0.000367647"/>
        <joint name="left_hip_yaw" class="/" pos="0 0 0" axis="-0.00251113 -0.00207999 -0.999995" stiffness="0.000469092" range="-3.01562 2.98177" armature="0.00996546" damping="0.00533988" frictionloss="0.107729"/>
        <geom name="//unnamed_geom_4" class="/" type="mesh" density="0" rgba="0.2 0.2 0.2 1" mesh="left_hip_yaw"/>
        <body name="left_hip_abad" pos="-0.0642792 -0.000343132 -0.064952" quat="0.976329 0.000121281 0.216291 -0.000102841">
          <inertial pos="0.0705104 -0.0155372 -0.000860664" quat="0.577865 0.406565 0.412277 0.575157" mass="1.27336" diaginertia="0.00371385 0.00456234 0.000805104"/>
          <joint name="left_hip_abad" class="/" pos="0 0 0" axis="-0.99996 -0.00884668 0.000928468" stiffness="0.00205644" range="-3.00512 3.01974" armature="0.0106045" damping="0.0087033" frictionloss="0.1027"/>
          <geom name="//unnamed_geom_5" class="/" type="mesh" density="0" rgba="0.2 0.2 0.2 1" mesh="left_hip_abad"/>
          <body name="left_upper_leg" pos="0.0883282 -0.00404816 -0.0128115" quat="0.991439 -5.14147e-05 -0.130573 -4.22559e-05">
            <inertial pos="0.000142496 0.03119 -0.0670636" quat="0.730199 0.0343218 -0.0488994 0.680618" mass="2.79827" diaginertia="0.0292304 0.0557078 0.00163598"/>
            <joint name="left_hip_pitch" class="/" pos="0 0 0" axis="0.00120208 0.999977 -0.00661814" stiffness="0.00503226" range="-3.017 3.00314" armature="0.010008" damping="0.01308" frictionloss="0.0996356"/>
            <geom name="//unnamed_geom_6" class="/" type="mesh" density="0" rgba="0.752941 0.752941 0.752941 1" mesh="left_leg_upper"/>
            <geom name="//unnamed_geom_7" class="reward_collision_sphere" size="0.071402" pos="-0.0153071 0.0176965 0.0128976"/>
            <geom name="//unnamed_geom_8" class="reward_collision_sphere" size="0.0204006" pos="-0.0816381 -0.035393 0.0687874"/>
            <body name="left_lower_leg" pos="-0.0110995 -0.000139551 -0.213265" quat="1 7.23003e-06 -4.51298e-06 -9.82961e-06">
              <inertial pos="0.00509233 0.000335729 -0.11296" quat="0.998862 0.00531791 -0.0155035 0.0447858" mass="0.364212" diaginertia="0.00324564 0.00668943 0.000109228"/>
              <joint name="left_knee" class="/" pos="0 0 0" axis="-0.00144635 0.999999 0.000261555" range="-0.0133272 3.00589" armature="0.00976781" damping="0.00891757" frictionloss="0.101275"/>
              <geom name="//unnamed_geom_9" class="/" type="mesh" density="0" rgba="0.752941 0.752941 0.752941 1" mesh="left_leg_lower"/>
              <geom name="//unnamed_geom_10" class="reward_collision_sphere" size="0.0438612"/>
              <body name="left_foot" pos="-0.000199123 -0.000344526 -0.239747" quat="1 0.000147779 -0.000161335 4.05374e-05">
                <inertial pos="0.0224338 0.000351123 -0.0113493" quat="0.516527 0.477455 0.483284 0.521223" mass="0.301825" diaginertia="0.02998 0.0617303 0.0127865"/>
                <joint name="left_ankle" class="/" pos="0 0 0" axis="-0.00279182 0.999996 0.000468607" stiffness="0.00267041" range="-1.49827 1.49308" armature="0.0102345" damping="0.0111672" frictionloss="0.101208"/>
                <geom name="//unnamed_geom_11" class="/" type="mesh" density="0" rgba="0.2 0.2 0.2 1" mesh="left_foot"/>
                <geom name="left_foot" class="foot" size="0.10567 0.0177135 0.0200377" pos="0.0285733 0 -0.0214961" quat="0.707109 0.707105 0 0"/>
                <geom name="//unnamed_geom_13" class="reward_collision_sphere" size="0.0255007" pos="0.0285733 0 -0.0171968"/>
                <geom name="//unnamed_geom_14" class="reward_collision_sphere" size="0.0255007" pos="0.102048 0 -0.0214961"/>
                <geom name="//unnamed_geom_15" class="reward_collision_sphere" size="0.0255007" pos="-0.0459214 0 -0.0214961"/>
                <site name="left_foot" class="foot" pos="0.0285733 0 -0.0214961" quat="0.707109 0.707105 0 0" size="0.0102003"/>
              </body>
            </body>
          </body>
        </body>
      </body>
      <body name="right_hip_yaw" pos="0.000272473 -0.0966982 -0.000312916" quat="0.996196 -2.04588e-06 -0.0871418 1.05892e-05">
        <inertial pos="-0.0650312 -0.000497007 -0.0543805" quat="0.950028 -0.00310825 0.31214 -0.00222099" mass="0.910878" diaginertia="0.00207342 0.00308039 0.0003688"/>
        <joint name="right_hip_yaw" class="/" pos="0 0 0" axis="-9.26392e-05 -5.2463e-05 -1" stiffness="0.00756264" range="-3.00295 3.00201" armature="0.0100972" damping="0.0142211" frictionloss="0.0999292"/>
        <geom name="//unnamed_geom_16" class="/" type="mesh" density="0" rgba="0.2 0.2 0.2 1" mesh="left_hip_yaw1"/>
        <body name="right_hip_abad" pos="-0.0659018 -0.000127444 -0.0639556" quat="0.976293 3.38538e-05 0.216454 -2.55211e-06">
          <inertial pos="0.0695083 0.0143873 0.000782495" quat="0.41174 0.573956 0.576509 0.410708" mass="1.26715" diaginertia="0.0037125 0.00449643 0.000796844"/>
          <joint name="right_hip_abad" class="/" pos="0 0 0" axis="-0.999997 0.000102371 0.00232158" range="-2.98912 2.99691" armature="0.0104502" damping="0.00160965" frictionloss="0.101847"/>
          <geom name="//unnamed_geom_17" class="/" type="mesh" density="0" rgba="0.2 0.2 0.2 1" mesh="left_hip_abad1"/>
          <body name="right_upper_leg" pos="0.0903542 0.00274438 -0.0112461" quat="0.991438 1.00035e-05 -0.130575 0.000115824">
            <inertial pos="-0.000272067 -0.0297694 -0.0671352" quat="0.678017 0.0485953 -0.0366633 0.732521" mass="2.79586" diaginertia="0.0288547 0.0563598 0.00162507"/>
            <joint name="right_hip_pitch" class="/" pos="0 0 0" axis="0.0016221 -0.999993 -0.00336366" range="-3.01454 3.00299" armature="0.00945146" damping="0.0135861" frictionloss="0.102138"/>
            <geom name="//unnamed_geom_18" class="/" type="mesh" density="0" rgba="0.752941 0.752941 0.752941 1" mesh="left_leg_upper1"/>
            <geom name="//unnamed_geom_19" class="reward_collision_sphere" size="0.071402" pos="-0.0153071 -0.0176965 0.0128976"/>
            <geom name="//unnamed_geom_20" class="reward_collision_sphere" size="0.0204006" pos="-0.0816381 0.035393 0.0687874"/>
            <body name="right_lower_leg" pos="-0.0123404 0.00110563 -0.21419" quat="1 -9.05987e-06 -2.72564e-05 2.62309e-05">
              <inertial pos="0.00471653 -0.000647625 -0.112603" quat="0.998951 0.00109683 0.0144675 -0.0434368" mass="0.370561" diaginertia="0.00322347 0.00675393 0.000111209"/>
              <joint name="right_knee" class="/" pos="0 0 0" axis="7.96917e-05 -0.99998 0.00631143" stiffness="0.000291925" range="-2.99064 6.27002e-05" armature="0.0101001" damping="0.0148362" frictionloss="0.099472"/>
              <geom name="//unnamed_geom_21" class="/" type="mesh" density="0" rgba="0.752941 0.752941 0.752941 1" mesh="left_leg_lower1"/>
              <geom name="//unnamed_geom_22" class="reward_collision_sphere" size="0.0438612"/>
              <body name="right_foot" pos="0.00105488 -0.000280522 -0.239355" quat="1 -0.000225364 -0.000406648 0.000193909">
                <inertial pos="0.0224197 -0.000162798 -0.0115102" quat="0.480022 0.518982 0.519268 0.480205" mass="0.294875" diaginertia="0.029301 0.0623434 0.0128214"/>
                <joint name="right_ankle" class="/" pos="0 0 0" axis="-0.000344229 -1 -9.41713e-05" stiffness="0.00244184" range="-1.48889 1.51858" armature="0.00966973" damping="0.0148811" frictionloss="0.102478"/>
                <geom name="//unnamed_geom_23" class="/" type="mesh" density="0" rgba="0.2 0.2 0.2 1" mesh="left_foot1"/>
                <geom name="right_foot" class="foot" size="0.114811 0.0174024 0.022125" pos="0.0285733 0 -0.0214961" quat="0.707109 0.707105 0 0"/>
                <geom name="//unnamed_geom_25" class="reward_collision_sphere" size="0.0255007" pos="0.0285733 0 -0.0171968"/>
                <geom name="//unnamed_geom_26" class="reward_collision_sphere" size="0.0255007" pos="0.102048 0 -0.0214961"/>
                <geom name="//unnamed_geom_27" class="reward_collision_sphere" size="0.0255007" pos="-0.0459214 0 -0.0214961"/>
                <site name="right_foot" class="foot" pos="0.0285733 0 -0.0214961" quat="0.707109 0.707105 0 0" size="0.0102003"/>
              </body>
            </body>
          </body>
        </body>
      </body>
      <body name="left_shoulder" pos="0.0194088 0.207894 0.262802" quat="1 0.00011689 2.43378e-05 8.48851e-05">
        <inertial pos="0.00918968 0.0621721 0.000453497" quat="0.70508 0.70893 0.0131432 0.0103474" mass="0.833449" diaginertia="0.00153925 0.00199279 0.000361048"/>
        <joint name="left_shoulder_pitch" class="/" pos="0 0 0" axis="4.46252e-05 1 -0.000486565" stiffness="0.00718534" range="-3.02365 3.01128" armature="0.00996395" damping="0.00805484" frictionloss="0.103322"/>
        <geom name="//unnamed_geom_28" class="/" type="mesh" density="0" rgba="0.2 0.2 0.2 1" mesh="left_shoulder1"/>
        <body name="left_shoulder_2" pos="0.00107799 0.0683205 -0.000289597" quat="1 4.91786e-05 6.71666e-05 -8.57716e-05">
          <inertial pos="0.000218251 0.000122107 -0.0712653" quat="0.0148541 0.757727 -0.00445085 0.652388" mass="0.82734" diaginertia="0.00133941 0.00261284 0.000527144"/>
          <joint name="left_shoulder_abad" class="/" pos="0 0 0" axis="-0.999985 0.00201164 0.00501186" range="-2.98425 3.01549" armature="0.0101813" damping="0.0133007" frictionloss="0.106207"/>
          <geom name="//unnamed_geom_29" class="/" type="mesh" density="0" rgba="0.752941 0.752941 0.752941 1" mesh="left_shoulder2"/>
          <body name="left_upper_arm" pos="-0.0015148 0.000227145 -0.0881121" quat="1 -0.000137537 -6.5221e-05 -0.00010409">
            <inertial pos="0.000345111 -0.0201007 -0.0543377" quat="0.708356 -0.0221529 0.0205295 0.705209" mass="0.95949" diaginertia="0.00199396 0.00309284 0.00037192"/>
            <joint name="left_shoulder_yaw" class="/" pos="0 0 0" axis="-0.0055777 1.76846e-05 0.999984" stiffness="0.0075711" range="-3.00181 3.00319" armature="0.0101076" damping="0.00580939" frictionloss="0.101426"/>
            <geom name="//unnamed_geom_30" class="/" type="mesh" density="0" rgba="0.752941 0.752941 0.752941 1" mesh="left_shoulder3"/>
            <geom name="//unnamed_geom_31" class="reward_collision_sphere" size="0.0612017" pos="-0.0102048 -0.0117977 -0.0429921"/>
            <body name="left_lower_arm" pos="-0.00115124 0.000479697 -0.13592" quat="1 -1.16489e-05 -7.64098e-05 0.000124861">
              <inertial pos="-0.00706533 -0.000255289 -0.0859812" quat="0.708816 0.0034368 0.00598973 0.70536" mass="0.369729" diaginertia="0.00404194 0.00803774 3.62107e-05"/>
              <joint name="left_elbow" class="/" pos="0 0 0" axis="0.000138993 0.999996 -0.00276381" stiffness="0.00552889" range="-3.00227 3.0167" armature="0.0104507" damping="0.0129753" frictionloss="0.10688"/>
              <geom name="//unnamed_geom_32" class="/" type="mesh" density="0" rgba="0.752941 0.752941 0.752941 1" mesh="left_forearm"/>
              <geom name="//unnamed_geom_33" class="/" size="0.0255007 0.00765021" pos="0 0 -0.232157" quat="0.707109 0.707105 0 0" type="cylinder" group="3"/>
              <geom name="//unnamed_geom_34" class="reward_collision_sphere" size="0.0255007"/>
              <geom name="//unnamed_geom_35" class="reward_collision_sphere" size="0.0224406" pos="0 0 -0.240756"/>
            </body>
          </body>
        </body>
      </body>
      <body name="right_shoulder" pos="0.0193475 -0.207664 0.260672" quat="1 2.65703e-05 6.84788e-06 8.33114e-06">
        <inertial pos="0.00858897 -0.0634689 -0.000856268" quat="0.711591 0.702234 -0.0151881 -0.016587" mass="0.840191" diaginertia="0.00148667 0.00197419 0.000354816"/>
        <joint name="right_shoulder_pitch" class="/" pos="0 0 0" axis="2.38301e-05 -1 -6.56198e-06" range="-2.98626 2.97408" armature="0.0102952" damping="0.00976209" frictionloss="0.0940521"/>
        <geom name="//unnamed_geom_36" class="/" type="mesh" density="0" rgba="0.2 0.2 0.2 1" mesh="left_shoulder11"/>
        <body name="right_shoulder_2" pos="0.00019515 -0.0677496 9.72919e-05" quat="1 -0.000180628 4.70566e-05 -0.00012105">
          <inertial pos="-0.000813356 -0.000841009 -0.0706242" quat="-0.000262267 0.65473 0.0140133 0.755733" mass="0.853384" diaginertia="0.00139576 0.00267165 0.000533514"/>
          <joint name="right_shoulder_abad" class="/" pos="0 0 0" axis="-1 7.17811e-05 -0.000345834" stiffness="0.0103072" range="-3.024 2.99989" armature="0.00993237" damping="0.00925086" frictionloss="0.102161"/>
          <geom name="//unnamed_geom_37" class="/" type="mesh" density="0" rgba="0.752941 0.752941 0.752941 1" mesh="left_shoulder21"/>
          <body name="right_upper_arm" pos="0.00146222 0.00133951 -0.0879778" quat="1 -0.000116519 -0.00034496 -0.000108192">
            <inertial pos="-0.00123131 0.0195945 -0.0552657" quat="0.705459 -0.02151 0.0217245 0.708091" mass="0.970634" diaginertia="0.00204716 0.00313984 0.000378115"/>
            <joint name="right_shoulder_yaw" class="/" pos="0 0 0" axis="0.00206013 0.00068963 0.999998" stiffness="0.00260666" range="-2.99808 2.99274" armature="0.0106745" damping="0.00654341" frictionloss="0.101961"/>
            <geom name="//unnamed_geom_38" class="/" type="mesh" density="0" rgba="0.752941 0.752941 0.752941 1" mesh="left_shoulder31"/>
            <geom name="//unnamed_geom_39" class="reward_collision_sphere" size="0.0612017" pos="-0.0102048 0.0117977 -0.0429921"/>
            <body name="right_lower_arm" pos="0.00014286 0.00108815 -0.135667" quat="1 0.000234619 -1.9948e-05 1.093e-05">
              <inertial pos="-0.0075678 -6.29876e-05 -0.0868369" quat="0.707012 0.00357017 0.00693154 0.707159" mass="0.367425" diaginertia="0.00395962 0.00807769 3.53157e-05"/>
              <joint name="right_elbow" class="/" pos="0 0 0" axis="0.000413389 -1 0.000644117" range="-3.00139 2.9809" armature="0.00979287" damping="0.00812407" frictionloss="0.0986166"/>
              <geom name="//unnamed_geom_40" class="/" type="mesh" density="0" rgba="0.752941 0.752941 0.752941 1" mesh="left_forearm"/>
              <geom name="//unnamed_geom_41" class="/" size="0.0255007 0.00765021" pos="0 0 -0.232157" quat="0.707109 0.707105 0 0" type="cylinder" group="3"/>
              <geom name="//unnamed_geom_42" class="reward_collision_sphere" size="0.0255007"/>
              <geom name="//unnamed_geom_43" class="reward_collision_sphere" size="0.0224406" pos="0 0 -0.240756"/>
            </body>
          </body>
        </body>
      </body>
    </body>
  </worldbody>

  <contact>
    <pair class="/" geom1="floor" geom2="left_foot" name="//unnamed_contact_0"/>
    <pair class="/" geom1="floor" geom2="right_foot" name="//unnamed_contact_1"/>
  </contact>

  <actuator>
    <general name="left_hip_yaw" class="/" joint="left_hip_yaw" forcerange="-34.6676 34.6676" gainprm="30.0107" biasprm="0 -30.0107 -0.485425"/>
    <general name="left_hip_abad" class="/" joint="left_hip_abad" forcerange="-33.8237 33.8237" gainprm="30.0107" biasprm="0 -30.0107 -0.485425"/>
    <general name="left_hip_pitch" class="/" joint="left_hip_pitch" forcerange="-71.9335 71.9335" gainprm="30.0107" biasprm="0 -30.0107 -0.485425"/>
    <general name="left_knee" class="/" joint="left_knee" forcerange="-154.578 154.578" gainprm="30.0107" biasprm="0 -30.0107 -0.485425"/>
    <general name="left_ankle" class="/" joint="left_ankle" forcerange="-67.6615 67.6615" gainprm="30.0107" biasprm="0 -30.0107 -0.485425"/>
    <general name="right_hip_yaw" class="/" joint="right_hip_yaw" forcerange="-35.2738 35.2738" gainprm="30.0107" biasprm="0 -30.0107 -0.485425"/>
    <general name="right_hip_abad" class="/" joint="right_hip_abad" forcerange="-34.1272 34.1272" gainprm="30.0107" biasprm="0 -30.0107 -0.485425"/>
    <general name="right_hip_pitch" class="/" joint="right_hip_pitch" forcerange="-72.1384 72.1384" gainprm="30.0107" biasprm="0 -30.0107 -0.485425"/>
    <general name="right_knee" class="/" joint="right_knee" forcerange="-151.321 151.321" gainprm="30.0107" biasprm="0 -30.0107 -0.485425"/>
    <general name="right_ankle" class="/" joint="right_ankle" forcerange="-65.9982 65.9982" gainprm="30.0107" biasprm="0 -30.0107 -0.485425"/>
    <general name="left_shoulder_pitch" class="/" joint="left_shoulder_pitch" forcerange="-34.8077 34.8077" gainprm="30.0107" biasprm="0 -30.0107 -0.485425"/>
    <general name="left_shoulder_abad" class="/" joint="left_shoulder_abad" forcerange="-34.4159 34.4159" gainprm="30.0107" biasprm="0 -30.0107 -0.485425"/>
    <general name="left_shoulder_yaw" class="/" joint="left_shoulder_yaw" forcerange="-34.6963 34.6963" gainprm="30.0107" biasprm="0 -30.0107 -0.485425"/>
    <general name="left_elbow" class="/" joint="left_elbow" forcerange="-57.7117 57.7117" gainprm="30.0107" biasprm="0 -30.0107 -0.485425"/>
    <general name="right_shoulder_pitch" class="/" joint="right_shoulder_pitch" forcerange="-35.4495 35.4495" gainprm="30.0107" biasprm="0 -30.0107 -0.485425"/>
    <general name="right_shoulder_abad" class="/" joint="right_shoulder_abad" forcerange="-35.8825 35.8825" gainprm="30.0107" biasprm="0 -30.0107 -0.485425"/>
    <general name="right_shoulder_yaw" class="/" joint="right_shoulder_yaw" forcerange="-33.3916 33.3916" gainprm="30.0107" biasprm="0 -30.0107 -0.485425"/>
    <general name="right_elbow" class="/" joint="right_elbow" forcerange="-56.7024 56.7024" gainprm="30.0107" biasprm="0 -30.0107 -0.485425"/>
  </actuator>

  <sensor>
    <gyro site="imu" name="imu_angular_velocity"/>
    <velocimeter site="imu" name="imu_linear_velocity"/>
    <framelinvel objtype="site" objname="left_foot" name="left_foot_global_linear_velocity"/>
    <framelinvel objtype="site" objname="right_foot" name="right_foot_global_linear_velocity"/>
  </sensor>

  <keyframe>
    <key name="home" qpos="0 0 0.656 1 0 0 0 0 0 -0.4 0.8 -0.4 0 0 0.4 -0.8 0.4 0 -0.05 0 -0.75 0 0.05 0 0.75"/>
  </keyframe>
</mujoco>
