<mujoco model="humanoid">
  <compiler angle="radian" assetdir="assets" balanceinertia="true" inertiafromgeom="false"/>

  <option timestep="0.005" density="1.2" viscosity="2e-05"/>

  <size nkey="1"/>

  <visual>
    <quality shadowsize="8192"/>
    <map shadowclip="0.5"/>
  </visual>

  <default>
    <default class="/">
      <joint armature="0.01" damping="0.01" frictionloss="0.1"/>
      <geom contype="0" conaffinity="0" group="1" solref="-1000 -80"/>
      <site size="0.01 0.005 0.005" group="5"/>
      <general forcelimited="true" biastype="affine" gainprm="30" biasprm="0 -30 -0.5"/>
      <default class="foot">
        <geom size="0.099 0.0178 0.021" type="box" condim="6" group="4" priority="1" solimp="0.015 1 0.021"/>
      </default>
      <default class="reward_collision_sphere">
        <geom group="5" rgba="1 0 0 1"/>
      </default>
    </default>
  </default>

  <asset>
    <texture type="skybox" colorspace="auto" name="//unnamed_texture_0" builtin="gradient" rgb1="0.95 0.95 0.95" rgb2="0.95 0.95 0.95" width="100" height="600"/>
    <texture type="2d" colorspace="auto" name="texplane" builtin="checker" rgb1="0.345 0.575 0.748" rgb2="0.345 0.575 0.748" markrgb="1 1 1" width="512" height="512"/>
    <material name="MatPlane" class="/" texture="texplane" texuniform="true" texrepeat="2 2" specular="0.9"/>
    <mesh name="torso" class="/" file="torso.stl" scale="0.001 0.001 0.001"/>
    <mesh name="left_hip_yaw" class="/" file="left_hip_yaw.stl" scale="0.001 0.001 0.001"/>
    <mesh name="left_hip_abad" class="/" file="left_hip_abad.stl" scale="0.001 0.001 0.001"/>
    <mesh name="left_leg_upper" class="/" file="left_leg_upper.stl" scale="0.001 0.001 0.001"/>
    <mesh name="left_leg_lower" class="/" file="left_leg_lower.stl" scale="0.001 0.001 0.001"/>
    <mesh name="left_foot" class="/" file="left_foot.stl" scale="0.001 0.001 0.001"/>
    <mesh name="left_hip_yaw1" class="/" content_type="model/stl" file="left_hip_yaw.stl" scale="0.001 -0.001 0.001"/>
    <mesh name="left_hip_abad1" class="/" content_type="model/stl" file="left_hip_abad.stl" scale="0.001 -0.001 0.001"/>
    <mesh name="left_leg_upper1" class="/" content_type="model/stl" file="left_leg_upper.stl" scale="0.001 -0.001 0.001"/>
    <mesh name="left_leg_lower1" class="/" content_type="model/stl" file="left_leg_lower.stl" scale="0.001 -0.001 0.001"/>
    <mesh name="left_foot1" class="/" content_type="model/stl" file="left_foot.stl" scale="0.001 -0.001 0.001"/>
    <mesh name="left_shoulder1" class="/" file="left_shoulder1.stl" scale="0.001 0.001 0.001"/>
    <mesh name="left_shoulder2" class="/" file="left_shoulder2.stl" scale="0.001 0.001 0.001"/>
    <mesh name="left_shoulder3" class="/" file="left_shoulder3.stl" scale="0.001 0.001 0.001"/>
    <mesh name="left_forearm" class="/" file="left_forearm.stl" scale="0.001 0.001 0.001"/>
    <mesh name="left_shoulder11" class="/" content_type="model/stl" file="left_shoulder1.stl" scale="0.001 -0.001 0.001"/>
    <mesh name="left_shoulder21" class="/" content_type="model/stl" file="left_shoulder2.stl" scale="0.001 -0.001 0.001"/>
    <mesh name="left_shoulder31" class="/" content_type="model/stl" file="left_shoulder3.stl" scale="0.001 -0.001 0.001"/>
  </asset>

  <worldbody>
    <geom name="floor" class="/" size="100 100 0.125" type="plane" group="0" material="MatPlane"/>
    <light name="toplight_shadow" class="/" pos="0 0 5" dir="0.0990148 0.0990148 -0.990148" type="directional" ambient="0.04 0.04 0.04" diffuse="0.55 0.55 0.55" specular="0.12 0.12 0.12"/>
    <light name="toplight_fill" class="/" pos="0 0 5" dir="0.0990148 0.0990148 -0.990148" type="directional" castshadow="false" ambient="0.04 0.04 0.04" diffuse="0.3 0.3 0.3" specular="0.08 0.08 0.08"/>
    <body name="trunk" pos="-0.000500131 0.000119521 -0.00102677" quat="0.999999 -0.000353722 -0.000325078 -0.00119605">
      <inertial pos="0.00794973 0.00358744 0.129674" quat="0.999916 0.0113828 0.00621262 -0.000634682" mass="8.07387" diaginertia="0.135619 0.253666 0.0403555"/>
      <joint name="//unnamed_joint_0" type="free"/>
      <geom name="//unnamed_geom_1" class="/" type="mesh" density="0" rgba="0.752941 0.752941 0.752941 1" mesh="torso"/>
      <geom name="//unnamed_geom_2" class="/" size="0.0753003 0.150601 0.175701" pos="0.0219864 0 0.0683856" type="box" group="3" rgba="0.752941 0.752941 0.752941 1"/>
      <geom name="//unnamed_geom_3" class="reward_collision_sphere" size="0.145581" pos="0 0 0.128223"/>
      <site name="imu" class="/" pos="-0.00209381 -0.00147969 0.128195" size="0.01004"/>
      <camera name="track" class="/" pos="0 -2.40253 0" quat="0.707107 0.707107 0 0" mode="trackcom"/>
      <camera name="ego_camera" class="/" pos="0.0430168 0 0.256446" quat="-0.5 -0.5 0.5 0.5"/>
      <body name="left_hip_yaw" pos="-0.000496491 0.101034 -0.00149164" quat="0.996128 0.00118314 -0.0879073 -0.000268523">
        <inertial pos="-0.0655536 -0.00233121 -0.0556567" quat="0.94951 -0.00430099 -0.313699 0.00241148" mass="0.877289" diaginertia="0.00156649 0.00341661 0.000353256"/>
        <joint name="left_hip_yaw" class="/" pos="0 0 0" axis="0.00406873 0.0146227 -0.999885" stiffness="0.00318658" range="-2.95928 3.0454" armature="0.0107736" damping="0.0238672" frictionloss="0.108376"/>
        <geom name="//unnamed_geom_4" class="/" type="mesh" density="0" rgba="0.2 0.2 0.2 1" mesh="left_hip_yaw"/>
        <body name="left_hip_abad" pos="-0.0638812 0.00289226 -0.0616081" quat="0.976097 0.000221686 0.217335 -0.000477362">
          <inertial pos="0.0652738 -0.0155804 0.00273673" quat="0.5851 0.415088 0.407597 0.564999" mass="1.1835" diaginertia="0.0027642 0.0048082 0.000782702"/>
          <joint name="left_hip_abad" class="/" pos="0 0 0" axis="-0.999993 -0.000673308 -0.00362772" range="-2.98414 3.02891" armature="0.00870013" damping="0" frictionloss="0.0996043"/>
          <geom name="//unnamed_geom_5" class="/" type="mesh" density="0" rgba="0.2 0.2 0.2 1" mesh="left_hip_abad"/>
          <body name="left_upper_leg" pos="0.0849197 -0.00117237 -0.0127802" quat="0.99146 0.00136038 -0.130406 0.000604605">
            <inertial pos="-0.00343029 0.0298038 -0.0688387" quat="0.729264 0.0341532 -0.047761 0.681709" mass="2.66396" diaginertia="0.0210914 0.0635001 0.00158707"/>
            <joint name="left_hip_pitch" class="/" pos="0 0 0" axis="0.00212663 0.999928 0.0118199" stiffness="0.00677723" range="-2.96355 3.00444" armature="0.0115497" damping="0" frictionloss="0.0889189"/>
            <geom name="//unnamed_geom_6" class="/" type="mesh" density="0" rgba="0.752941 0.752941 0.752941 1" mesh="left_leg_upper"/>
            <geom name="//unnamed_geom_7" class="reward_collision_sphere" size="0.0702803" pos="-0.0143389 0.018019 0.0128223"/>
            <geom name="//unnamed_geom_8" class="reward_collision_sphere" size="0.0200801" pos="-0.0764743 -0.036038 0.0683856"/>
            <body name="left_lower_leg" pos="-0.0124018 0.00128293 -0.215642" quat="1 0.00054688 0.00022498 0.00027736">
              <inertial pos="0.00274858 -0.000472268 -0.113161" quat="0.998551 -0.000986698 -0.0268944 0.0465994" mass="0.363349" diaginertia="0.00246135 0.00736494 0.000112666"/>
              <joint name="left_knee" class="/" pos="0 0 0" axis="-0.00298621 0.999978 -0.00586251" stiffness="0.0136102" range="0.0314218 2.97301" armature="0.0113937" damping="0.00674513" frictionloss="0.0981848"/>
              <geom name="//unnamed_geom_9" class="/" type="mesh" density="0" rgba="0.752941 0.752941 0.752941 1" mesh="left_leg_lower"/>
              <geom name="//unnamed_geom_10" class="reward_collision_sphere" size="0.0431722"/>
              <body name="left_foot" pos="0.000557963 0.00217259 -0.236604" quat="0.999999 -0.00116198 -0.000352944 2.80317e-05">
                <inertial pos="0.0234563 -2.53236e-05 -0.00947757" quat="0.5218 0.483365 0.472779 0.520157" mass="0.270062" diaginertia="0.0210206 0.0659213 0.0122018"/>
                <joint name="left_ankle" class="/" pos="0 0 0" axis="0.00238482 0.999893 0.0144223" range="-1.50002 1.45121" armature="0.00977415" damping="0" frictionloss="0.105442"/>
                <geom name="//unnamed_geom_11" class="/" type="mesh" density="0" rgba="0.2 0.2 0.2 1" mesh="left_foot"/>
                <geom name="left_foot" class="foot" size="0.109447 0.0185527 0.0195098" pos="0.026766 0 -0.0213705" quat="0.707109 0.707105 0 0"/>
                <geom name="//unnamed_geom_13" class="reward_collision_sphere" size="0.0251001" pos="0.026766 0 -0.0170964"/>
                <geom name="//unnamed_geom_14" class="reward_collision_sphere" size="0.0251001" pos="0.0955928 0 -0.0213705"/>
                <geom name="//unnamed_geom_15" class="reward_collision_sphere" size="0.0251001" pos="-0.0430168 0 -0.0213705"/>
                <site name="left_foot" class="foot" pos="0.026766 0 -0.0213705" quat="0.707109 0.707105 0 0" size="0.01004"/>
              </body>
            </body>
          </body>
        </body>
      </body>
      <body name="right_hip_yaw" pos="-0.00267687 -0.100066 -0.00153596" quat="0.996192 -0.00125185 -0.0871753 -0.000532017">
        <inertial pos="-0.0647864 -0.00204558 -0.0557973" quat="0.950103 -0.00254751 0.311916 -0.00231397" mass="0.893456" diaginertia="0.00161321 0.00363717 0.00035851"/>
        <joint name="right_hip_yaw" class="/" pos="0 0 0" axis="0.000678724 -0.000200936 -1" stiffness="0.00766253" range="-3.00756 3.00939" armature="0.0097107" damping="0.00571679" frictionloss="0.105197"/>
        <geom name="//unnamed_geom_16" class="/" type="mesh" density="0" rgba="0.2 0.2 0.2 1" mesh="left_hip_yaw1"/>
        <body name="right_hip_abad" pos="-0.0608429 -0.00119624 -0.065262" quat="0.976563 0.000360988 0.21523 -0.000441404">
          <inertial pos="0.0630334 0.0139363 -0.00268625" quat="0.410622 0.575214 0.570187 0.418814" mass="1.19499" diaginertia="0.00258114 0.0048786 0.00075632"/>
          <joint name="right_hip_abad" class="/" pos="0 0 0" axis="-0.999999 -0.000700284 0.000744337" stiffness="0.0130478" range="-3.0072 3.05124" armature="0.00960461" damping="0.0119226" frictionloss="0.113647"/>
          <geom name="//unnamed_geom_17" class="/" type="mesh" density="0" rgba="0.2 0.2 0.2 1" mesh="left_hip_abad1"/>
          <body name="right_upper_leg" pos="0.0831619 0.00422084 -0.0149189" quat="0.991484 8.51351e-05 -0.130226 -0.000384451">
            <inertial pos="-0.00270209 -0.0341248 -0.0704346" quat="0.676217 0.0416104 -0.0398768 0.734445" mass="2.63773" diaginertia="0.02177 0.0592114 0.00165088"/>
            <joint name="right_hip_pitch" class="/" pos="0 0 0" axis="0.0122652 -0.999907 0.00595482" range="-2.96007 3.00464" armature="0.00949846" damping="0.0163604" frictionloss="0.0997224"/>
            <geom name="//unnamed_geom_18" class="/" type="mesh" density="0" rgba="0.752941 0.752941 0.752941 1" mesh="left_leg_upper1"/>
            <geom name="//unnamed_geom_19" class="reward_collision_sphere" size="0.0702803" pos="-0.0143389 -0.018019 0.0128223"/>
            <geom name="//unnamed_geom_20" class="reward_collision_sphere" size="0.0200801" pos="-0.0764743 0.036038 0.0683856"/>
            <body name="right_lower_leg" pos="-0.01123 0.000812288 -0.214327" quat="0.999999 0.00115332 -0.000330564 -0.000201522">
              <inertial pos="0.0067707 -0.000251353 -0.113349" quat="0.998628 0.0122314 0.0116412 -0.0495659" mass="0.362942" diaginertia="0.00233555 0.00750258 0.000108829"/>
              <joint name="right_knee" class="/" pos="0 0 0" axis="-0.00768004 -0.999962 -0.00422798" range="-3.02715 0.00866432" armature="0.00878463" damping="0.0209321" frictionloss="0.107703"/>
              <geom name="//unnamed_geom_21" class="/" type="mesh" density="0" rgba="0.752941 0.752941 0.752941 1" mesh="left_leg_lower1"/>
              <geom name="//unnamed_geom_22" class="reward_collision_sphere" size="0.0431722"/>
              <body name="right_foot" pos="-0.0025772 0.000543756 -0.237426" quat="0.999999 -0.000292427 0.000512691 0.00108331">
                <inertial pos="0.0240329 -0.000549275 -0.0119251" quat="0.480788 0.519355 0.518198 0.480191" mass="0.285054" diaginertia="0.0211627 0.0651945 0.0118905"/>
                <joint name="right_ankle" class="/" pos="0 0 0" axis="0.0114824 -0.999902 0.00799279" stiffness="0.00474416" range="-1.51582 1.44483" armature="0.0113873" damping="0.0207582" frictionloss="0.0868738"/>
                <geom name="//unnamed_geom_23" class="/" type="mesh" density="0" rgba="0.2 0.2 0.2 1" mesh="left_foot1"/>
                <geom name="right_foot" class="foot" size="0.114774 0.0191522 0.0213434" pos="0.026766 0 -0.0213705" quat="0.707109 0.707105 0 0"/>
                <geom name="//unnamed_geom_25" class="reward_collision_sphere" size="0.0251001" pos="0.026766 0 -0.0170964"/>
                <geom name="//unnamed_geom_26" class="reward_collision_sphere" size="0.0251001" pos="0.0955928 0 -0.0213705"/>
                <geom name="//unnamed_geom_27" class="reward_collision_sphere" size="0.0251001" pos="-0.0430168 0 -0.0213705"/>
                <site name="right_foot" class="foot" pos="0.026766 0 -0.0213705" quat="0.707109 0.707105 0 0" size="0.01004"/>
              </body>
            </body>
          </body>
        </body>
      </body>
      <body name="left_shoulder" pos="0.0187199 0.21143 0.257383" quat="1 3.64898e-05 -7.07598e-05 -9.14317e-05">
        <inertial pos="0.0104899 0.0632072 0.00247681" quat="0.712206 0.701621 0.0176499 0.0134021" mass="0.764003" diaginertia="0.00109073 0.00209796 0.000348891"/>
        <joint name="left_shoulder_pitch" class="/" pos="0 0 0" axis="-0.00347008 0.999994 -0.000652001" stiffness="0.00667988" range="-3.02781 3.04518" armature="0.0115342" damping="0.00968769" frictionloss="0.0865878"/>
        <geom name="//unnamed_geom_28" class="/" type="mesh" density="0" rgba="0.2 0.2 0.2 1" mesh="left_shoulder1"/>
        <body name="left_shoulder_2" pos="0.00149652 0.0665203 -0.00261611" quat="1 0.000490172 2.61647e-05 0.000110185">
          <inertial pos="0.00102828 -0.000559887 -0.0711503" quat="0.0165151 0.762238 0.00390409 0.647074" mass="0.821603" diaginertia="0.00100729 0.00297487 0.000490172"/>
          <joint name="left_shoulder_abad" class="/" pos="0 0 0" axis="-0.99992 0.000353518 0.0126764" stiffness="0.00936119" range="-2.96023 2.95869" armature="0.0101788" damping="0.000577935" frictionloss="0.0900036"/>
          <geom name="//unnamed_geom_29" class="/" type="mesh" density="0" rgba="0.752941 0.752941 0.752941 1" mesh="left_shoulder2"/>
          <body name="left_upper_arm" pos="-0.00091657 0.00287018 -0.0850706" quat="1 -0.000236195 0.000373272 -0.000532559">
            <inertial pos="0.00203553 -0.0168939 -0.0537858" quat="0.707564 -0.0224159 0.0206378 0.705993" mass="0.938475" diaginertia="0.00150783 0.00344168 0.000365292"/>
            <joint name="left_shoulder_yaw" class="/" pos="0 0 0" axis="0.00487666 0.0105497 0.999932" range="-3.00334 3.00909" armature="0.00965524" damping="0.00475518" frictionloss="0.0954768"/>
            <geom name="//unnamed_geom_30" class="/" type="mesh" density="0" rgba="0.752941 0.752941 0.752941 1" mesh="left_shoulder3"/>
            <geom name="//unnamed_geom_31" class="reward_collision_sphere" size="0.0602403" pos="-0.00955928 -0.0120127 -0.042741"/>
            <body name="left_lower_arm" pos="-0.00208051 -0.00162429 -0.133271" quat="1 0.000258842 -0.000111123 0.000121609">
              <inertial pos="-0.00639477 0.000414242 -0.0861249" quat="0.697266 0.00625685 0.0050496 0.716768" mass="0.359765" diaginertia="0.00284163 0.00895258 3.54887e-05"/>
              <joint name="left_elbow" class="/" pos="0 0 0" axis="-0.00649974 0.999943 0.00841851" stiffness="0.00133115" range="-2.97963 2.95881" armature="0.00955667" damping="0" frictionloss="0.0872564"/>
              <geom name="//unnamed_geom_32" class="/" type="mesh" density="0" rgba="0.752941 0.752941 0.752941 1" mesh="left_forearm"/>
              <geom name="//unnamed_geom_33" class="/" size="0.0251001 0.00753003" pos="0 0 -0.230801" quat="0.707109 0.707105 0 0" type="cylinder" group="3"/>
              <geom name="//unnamed_geom_34" class="reward_collision_sphere" size="0.0251001"/>
              <geom name="//unnamed_geom_35" class="reward_collision_sphere" size="0.0220881" pos="0 0 -0.23935"/>
            </body>
          </body>
        </body>
      </body>
      <body name="right_shoulder" pos="0.0183453 -0.211295 0.26286" quat="1 0.00012116 -0.000236986 0.000715528">
        <inertial pos="0.0115137 -0.0659671 0.00230818" quat="0.703657 0.710223 -0.0135409 -0.0163036" mass="0.779469" diaginertia="0.00111897 0.00216532 0.000342428"/>
        <joint name="right_shoulder_pitch" class="/" pos="0 0 0" axis="0.000350169 -0.999997 -0.00239155" stiffness="0.014833" range="-2.95961 2.97131" armature="0.0101091" damping="0.0112387" frictionloss="0.0956029"/>
        <geom name="//unnamed_geom_36" class="/" type="mesh" density="0" rgba="0.2 0.2 0.2 1" mesh="left_shoulder11"/>
        <body name="right_shoulder_2" pos="-0.000879573 -0.0689323 -0.00091927" quat="1 -2.71791e-09 3.15678e-08 -4.41686e-09">
          <inertial pos="0.00262561 0.0012262 -0.0714667" quat="0.00216119 0.652807 0.0140798 0.757391" mass="0.806222" diaginertia="0.00102046 0.00297035 0.000514512"/>
          <joint name="right_shoulder_abad" class="/" pos="0 0 0" axis="-1 0.000888323 8.53625e-05" stiffness="0.00263663" range="-3.02838 3.00352" armature="0.0102534" damping="0.00827325" frictionloss="0.0951306"/>
          <geom name="//unnamed_geom_37" class="/" type="mesh" density="0" rgba="0.752941 0.752941 0.752941 1" mesh="left_shoulder21"/>
          <body name="right_upper_arm" pos="0.000311377 -0.00230242 -0.0871279" quat="1 4.7235e-05 0.000139585 0.000343198">
            <inertial pos="0.00208075 0.0193876 -0.0558722" quat="0.705061 -0.0213721 0.022142 0.708479" mass="0.950134" diaginertia="0.0014518 0.00342822 0.00036636"/>
            <joint name="right_shoulder_yaw" class="/" pos="0 0 0" axis="-0.00615576 -0.000598543 0.999981" stiffness="0.0121307" range="-3.00426 3.02444" armature="0.00856984" damping="0.0115058" frictionloss="0.0994417"/>
            <geom name="//unnamed_geom_38" class="/" type="mesh" density="0" rgba="0.752941 0.752941 0.752941 1" mesh="left_shoulder31"/>
            <geom name="//unnamed_geom_39" class="reward_collision_sphere" size="0.0602403" pos="-0.00955928 0.0120127 -0.042741"/>
            <body name="right_lower_arm" pos="-0.00164688 -0.00034244 -0.133622" quat="1 -2.05618e-05 0.000436303 0.000118423">
              <inertial pos="-0.00406814 0.000123193 -0.0849921" quat="0.709634 0.00493572 -0.00142515 0.704552" mass="0.336403" diaginertia="0.00286419 0.0088452 3.60287e-05"/>
              <joint name="right_elbow" class="/" pos="0 0 0" axis="0.0123647 -0.999851 -0.0120437" range="-3.0046 3.05219" armature="0.0110126" damping="0.00533193" frictionloss="0.114636"/>
              <geom name="//unnamed_geom_40" class="/" type="mesh" density="0" rgba="0.752941 0.752941 0.752941 1" mesh="left_forearm"/>
              <geom name="//unnamed_geom_41" class="/" size="0.0251001 0.00753003" pos="0 0 -0.230801" quat="0.707109 0.707105 0 0" type="cylinder" group="3"/>
              <geom name="//unnamed_geom_42" class="reward_collision_sphere" size="0.0251001"/>
              <geom name="//unnamed_geom_43" class="reward_collision_sphere" size="0.0220881" pos="0 0 -0.23935"/>
            </body>
          </body>
        </body>
      </body>
    </body>
  </worldbody>

  <contact>
    <pair class="/" geom1="floor" geom2="left_foot" name="//unnamed_contact_0"/>
    <pair class="/" geom1="floor" geom2="right_foot" name="//unnamed_contact_1"/>
  </contact>

  <actuator>
    <general name="left_hip_yaw" class="/" joint="left_hip_yaw" forcerange="-33.9836 33.9836" gainprm="28.885" biasprm="0 -28.885 -0.490882"/>
    <general name="left_hip_abad" class="/" joint="left_hip_abad" forcerange="-31.6765 31.6765" gainprm="28.885" biasprm="0 -28.885 -0.490882"/>
    <general name="left_hip_pitch" class="/" joint="left_hip_pitch" forcerange="-66.048 66.048" gainprm="28.885" biasprm="0 -28.885 -0.490882"/>
    <general name="left_knee" class="/" joint="left_knee" forcerange="-148.046 148.046" gainprm="28.885" biasprm="0 -28.885 -0.490882"/>
    <general name="left_ankle" class="/" joint="left_ankle" forcerange="-69.3882 69.3882" gainprm="28.885" biasprm="0 -28.885 -0.490882"/>
    <general name="right_hip_yaw" class="/" joint="right_hip_yaw" forcerange="-33.5798 33.5798" gainprm="28.885" biasprm="0 -28.885 -0.490882"/>
    <general name="right_hip_abad" class="/" joint="right_hip_abad" forcerange="-37.9233 37.9233" gainprm="28.885" biasprm="0 -28.885 -0.490882"/>
    <general name="right_hip_pitch" class="/" joint="right_hip_pitch" forcerange="-79.7605 79.7605" gainprm="28.885" biasprm="0 -28.885 -0.490882"/>
    <general name="right_knee" class="/" joint="right_knee" forcerange="-129.918 129.918" gainprm="28.885" biasprm="0 -28.885 -0.490882"/>
    <general name="right_ankle" class="/" joint="right_ankle" forcerange="-64.5707 64.5707" gainprm="28.885" biasprm="0 -28.885 -0.490882"/>
    <general name="left_shoulder_pitch" class="/" joint="left_shoulder_pitch" forcerange="-33.7747 33.7747" gainprm="28.885" biasprm="0 -28.885 -0.490882"/>
    <general name="left_shoulder_abad" class="/" joint="left_shoulder_abad" forcerange="-32.8341 32.8341" gainprm="28.885" biasprm="0 -28.885 -0.490882"/>
    <general name="left_shoulder_yaw" class="/" joint="left_shoulder_yaw" forcerange="-34.1335 34.1335" gainprm="28.885" biasprm="0 -28.885 -0.490882"/>
    <general name="left_elbow" class="/" joint="left_elbow" forcerange="-49.3903 49.3903" gainprm="28.885" biasprm="0 -28.885 -0.490882"/>
    <general name="right_shoulder_pitch" class="/" joint="right_shoulder_pitch" forcerange="-31.9854 31.9854" gainprm="28.885" biasprm="0 -28.885 -0.490882"/>
    <general name="right_shoulder_abad" class="/" joint="right_shoulder_abad" forcerange="-36.4833 36.4833" gainprm="28.885" biasprm="0 -28.885 -0.490882"/>
    <general name="right_shoulder_yaw" class="/" joint="right_shoulder_yaw" forcerange="-37.3507 37.3507" gainprm="28.885" biasprm="0 -28.885 -0.490882"/>
    <general name="right_elbow" class="/" joint="right_elbow" forcerange="-49.5104 49.5104" gainprm="28.885" biasprm="0 -28.885 -0.490882"/>
  </actuator>

  <sensor>
    <gyro site="imu" name="imu_angular_velocity"/>
    <velocimeter site="imu" name="imu_linear_velocity"/>
    <framelinvel objtype="site" objname="left_foot" name="left_foot_global_linear_velocity"/>
    <framelinvel objtype="site" objname="right_foot" name="right_foot_global_linear_velocity"/>
  </sensor>

  <keyframe>
    <key name="home" qpos="0 0 0.656 1 0 0 0 0 0 -0.4 0.8 -0.4 0 0 0.4 -0.8 0.4 0 -0.05 0 -0.75 0 0.05 0 0.75"/>
  </keyframe>
</mujoco>
