<mujoco model="humanoid">
  <compiler angle="radian" assetdir="assets" balanceinertia="true" inertiafromgeom="false"/>

  <option timestep="0.005" density="1.2" viscosity="2e-05"/>

  <size nkey="1"/>

  <visual>
    <quality shadowsize="8192"/>
    <map shadowclip="0.5"/>
  </visual>

  <default>
    <default class="/">
      <joint armature="0.01" damping="0.01" frictionloss="0.1"/>
      <geom contype="0" conaffinity="0" group="1" solref="-1000 -80"/>
      <site size="0.01 0.005 0.005" group="5"/>
      <general forcelimited="true" biastype="affine" gainprm="30" biasprm="0 -30 -0.5"/>
      <default class="foot">
        <geom size="0.099 0.0178 0.021" type="box" condim="6" group="4" priority="1" solimp="0.015 1 0.021"/>
      </default>
      <default class="reward_collision_sphere">
        <geom group="5" rgba="1 0 0 1"/>
      </default>
    </default>
  </default>

  <asset>
    <texture type="skybox" colorspace="auto" name="//unnamed_texture_0" builtin="gradient" rgb1="0.95 0.95 0.95" rgb2="0.95 0.95 0.95" width="100" height="600"/>
    <texture type="2d" colorspace="auto" name="texplane" builtin="checker" rgb1="0.345 0.575 0.748" rgb2="0.345 0.575 0.748" markrgb="1 1 1" width="512" height="512"/>
    <material name="MatPlane" class="/" texture="texplane" texuniform="true" texrepeat="2 2" specular="0.9"/>
    <mesh name="torso" class="/" file="torso.stl" scale="0.001 0.001 0.001"/>
    <mesh name="left_hip_yaw" class="/" file="left_hip_yaw.stl" scale="0.001 0.001 0.001"/>
    <mesh name="left_hip_abad" class="/" file="left_hip_abad.stl" scale="0.001 0.001 0.001"/>
    <mesh name="left_leg_upper" class="/" file="left_leg_upper.stl" scale="0.001 0.001 0.001"/>
    <mesh name="left_leg_lower" class="/" file="left_leg_lower.stl" scale="0.001 0.001 0.001"/>
    <mesh name="left_foot" class="/" file="left_foot.stl" scale="0.001 0.001 0.001"/>
    <mesh name="left_hip_yaw1" class="/" content_type="model/stl" file="left_hip_yaw.stl" scale="0.001 -0.001 0.001"/>
    <mesh name="left_hip_abad1" class="/" content_type="model/stl" file="left_hip_abad.stl" scale="0.001 -0.001 0.001"/>
    <mesh name="left_leg_upper1" class="/" content_type="model/stl" file="left_leg_upper.stl" scale="0.001 -0.001 0.001"/>
    <mesh name="left_leg_lower1" class="/" content_type="model/stl" file="left_leg_lower.stl" scale="0.001 -0.001 0.001"/>
    <mesh name="left_foot1" class="/" content_type="model/stl" file="left_foot.stl" scale="0.001 -0.001 0.001"/>
    <mesh name="left_shoulder1" class="/" file="left_shoulder1.stl" scale="0.001 0.001 0.001"/>
    <mesh name="left_shoulder2" class="/" file="left_shoulder2.stl" scale="0.001 0.001 0.001"/>
    <mesh name="left_shoulder3" class="/" file="left_shoulder3.stl" scale="0.001 0.001 0.001"/>
    <mesh name="left_forearm" class="/" file="left_forearm.stl" scale="0.001 0.001 0.001"/>
    <mesh name="left_shoulder11" class="/" content_type="model/stl" file="left_shoulder1.stl" scale="0.001 -0.001 0.001"/>
    <mesh name="left_shoulder21" class="/" content_type="model/stl" file="left_shoulder2.stl" scale="0.001 -0.001 0.001"/>
    <mesh name="left_shoulder31" class="/" content_type="model/stl" file="left_shoulder3.stl" scale="0.001 -0.001 0.001"/>
  </asset>

  <worldbody>
    <geom name="floor" class="/" size="100 100 0.125" type="plane" group="0" material="MatPlane"/>
    <light name="toplight_shadow" class="/" pos="0 0 5" dir="0.0990148 0.0990148 -0.990148" type="directional" ambient="0.04 0.04 0.04" diffuse="0.55 0.55 0.55" specular="0.12 0.12 0.12"/>
    <light name="toplight_fill" class="/" pos="0 0 5" dir="0.0990148 0.0990148 -0.990148" type="directional" castshadow="false" ambient="0.04 0.04 0.04" diffuse="0.3 0.3 0.3" specular="0.08 0.08 0.08"/>
    <body name="trunk" pos="0.00102578 -0.00212183 -0.000654747" quat="1 -6.86209e-05 -0.000143503 -0.000222291">
      <inertial pos="0.00939142 0.00272428 0.128229" quat="0.999947 0.00942122 -0.00305702 -0.0026976" mass="6.34433" diaginertia="0.0906899 0.1375 0.0403679"/>
      <joint name="//unnamed_joint_0" type="free"/>
      <geom name="//unnamed_geom_1" class="/" type="mesh" density="0" rgba="0.752941 0.752941 0.752941 1" mesh="torso"/>
      <geom name="//unnamed_geom_2" class="/" size="0.0699963 0.139993 0.163325" pos="0.020319 0 0.0679763" type="box" group="3" rgba="0.752941 0.752941 0.752941 1"/>
      <geom name="//unnamed_geom_3" class="reward_collision_sphere" size="0.135326" pos="0 0 0.127456"/>
      <site name="imu" class="/" pos="0.000995487 -0.00505576 0.127147" size="0.00933284"/>
      <camera name="track" class="/" pos="0 -2.13343 0" quat="0.707107 0.707107 0 0" mode="trackcom"/>
      <camera name="ego_camera" class="/" pos="0.0397545 0 0.254911" quat="-0.5 -0.5 0.5 0.5"/>
      <body name="left_hip_yaw" pos="-0.000873496 0.086674 0.00239673" quat="0.996201 0.000223442 -0.0870762 0.000833892">
        <inertial pos="-0.0581485 0.000551799 -0.0545033" quat="0.951657 0.00268043 -0.307104 -0.00537113" mass="0.719006" diaginertia="0.00105218 0.00192659 0.000352942"/>
        <joint name="left_hip_yaw" class="/" pos="0 0 0" axis="-0.00172006 0.000975874 -0.999998" stiffness="0.0013484" range="-3.00558 3.00079" armature="0.00926841" damping="0.00721196" frictionloss="0.0940559"/>
        <geom name="//unnamed_geom_4" class="/" type="mesh" density="0" rgba="0.2 0.2 0.2 1" mesh="left_hip_yaw"/>
        <body name="left_hip_abad" pos="-0.0544146 -0.000763311 -0.0640286" quat="0.976237 0.00031694 0.216707 -0.000154251">
          <inertial pos="0.0584895 -0.0139535 0.000138802" quat="0.579146 0.407213 0.410824 0.574448" mass="0.979651" diaginertia="0.00178079 0.00282503 0.000745193"/>
          <joint name="left_hip_abad" class="/" pos="0 0 0" axis="-0.99999 -0.000813764 0.00438481" range="-3.00683 2.9776" armature="0.00931101" damping="0.00722022" frictionloss="0.0875277"/>
          <geom name="//unnamed_geom_5" class="/" type="mesh" density="0" rgba="0.2 0.2 0.2 1" mesh="left_hip_abad"/>
          <body name="left_upper_leg" pos="0.0787934 -0.00275918 -0.0130366" quat="0.991391 8.97356e-07 -0.130932 6.39428e-05">
            <inertial pos="0.000423322 0.0271544 -0.0678666" quat="0.730053 0.034253 -0.0485673 0.680802" mass="2.11144" diaginertia="0.0144131 0.0335628 0.00154831"/>
            <joint name="left_hip_pitch" class="/" pos="0 0 0" axis="-0.00096237 0.999998 -0.00186403" range="-3.00996 2.99881" armature="0.00963593" damping="0" frictionloss="0.0945924"/>
            <geom name="//unnamed_geom_6" class="/" type="mesh" density="0" rgba="0.752941 0.752941 0.752941 1" mesh="left_leg_upper"/>
            <geom name="//unnamed_geom_7" class="reward_collision_sphere" size="0.0653299" pos="-0.0132515 0.0160007 0.0127456"/>
            <geom name="//unnamed_geom_8" class="reward_collision_sphere" size="0.0186657" pos="-0.0706746 -0.0320015 0.0679763"/>
            <body name="left_lower_leg" pos="-0.00930124 -6.0361e-05 -0.211523" quat="0.999999 0.000595174 -0.000310676 0.000771412">
              <inertial pos="0.00455269 0.00245043 -0.109348" quat="0.998866 0.00564115 -0.0153766 0.0447007" mass="0.285689" diaginertia="0.00158959 0.00416562 0.000104326"/>
              <joint name="left_knee" class="/" pos="0 0 0" axis="-0.00425784 0.999991 0.000819049" stiffness="0.0120804" range="0.036102 3.00493" armature="0.00942863" damping="0.0189301" frictionloss="0.0919314"/>
              <geom name="//unnamed_geom_9" class="/" type="mesh" density="0" rgba="0.752941 0.752941 0.752941 1" mesh="left_leg_lower"/>
              <geom name="//unnamed_geom_10" class="reward_collision_sphere" size="0.0401312"/>
              <body name="left_foot" pos="0.00032092 3.67691e-05 -0.236782" quat="1 3.46982e-05 -2.79896e-05 2.76471e-05">
                <inertial pos="0.0203001 0.0006212 -0.0133935" quat="0.512406 0.483577 0.475508 0.526769" mass="0.229481" diaginertia="0.0148417 0.0377253 0.0124061"/>
                <joint name="left_ankle" class="/" pos="0 0 0" axis="-0.000284159 0.999999 0.00128083" range="-1.50699 1.47882" armature="0.0104635" damping="0.00486189" frictionloss="0.0895677"/>
                <geom name="//unnamed_geom_11" class="/" type="mesh" density="0" rgba="0.2 0.2 0.2 1" mesh="left_foot"/>
                <geom name="left_foot" class="foot" size="0.10594 0.0149452 0.0178469" pos="0.0247361 0 -0.0212426" quat="0.707109 0.707105 0 0"/>
                <geom name="//unnamed_geom_13" class="reward_collision_sphere" size="0.0233321" pos="0.0247361 0 -0.0169941"/>
                <geom name="//unnamed_geom_14" class="reward_collision_sphere" size="0.0233321" pos="0.0883433 0 -0.0212426"/>
                <geom name="//unnamed_geom_15" class="reward_collision_sphere" size="0.0233321" pos="-0.0397545 0 -0.0212426"/>
                <site name="left_foot" class="foot" pos="0.0247361 0 -0.0212426" quat="0.707109 0.707105 0 0" size="0.00933284"/>
              </body>
            </body>
          </body>
        </body>
      </body>
      <body name="right_hip_yaw" pos="-0.000549658 -0.0881532 -0.00196288" quat="0.996188 -1.49515e-05 -0.0872355 6.59043e-05">
        <inertial pos="-0.0588879 -0.000142332 -0.0542917" quat="0.950298 -0.00211907 0.311322 -0.00275559" mass="0.65721" diaginertia="0.000987941 0.00182703 0.000333652"/>
        <joint name="right_hip_yaw" class="/" pos="0 0 0" axis="0.000405465 -7.60458e-05 -1" range="-3.02619 3.0058" armature="0.00861232" damping="0.0128958" frictionloss="0.0940789"/>
        <geom name="//unnamed_geom_16" class="/" type="mesh" density="0" rgba="0.2 0.2 0.2 1" mesh="left_hip_yaw1"/>
        <body name="right_hip_abad" pos="-0.0564739 0.000487736 -0.0642025" quat="0.97616 0.00077754 0.217048 0.000578179">
          <inertial pos="0.0593607 0.0134114 -1.17474e-05" quat="0.410819 0.574621 0.578678 0.407641" mass="0.998013" diaginertia="0.00176719 0.00270012 0.000767541"/>
          <joint name="right_hip_abad" class="/" pos="0 0 0" axis="-1 -0.000109048 1.18816e-05" range="-3.02008 3.00909" armature="0.0100966" damping="0.0118205" frictionloss="0.0978929"/>
          <geom name="//unnamed_geom_17" class="/" type="mesh" density="0" rgba="0.2 0.2 0.2 1" mesh="left_hip_abad1"/>
          <body name="right_upper_leg" pos="0.0782543 0.00236084 -0.0107399" quat="0.991438 2.38737e-05 -0.130576 -4.37127e-05">
            <inertial pos="-5.16023e-05 -0.0280015 -0.0671172" quat="0.681502 0.0492714 -0.0342888 0.72935" mass="2.13398" diaginertia="0.0140892 0.033195 0.00153396"/>
            <joint name="right_hip_pitch" class="/" pos="0 0 0" axis="0.00102702 -0.999999 -0.00115892" stiffness="0.000644582" range="-3.04783 2.97235" armature="0.00925276" damping="0.0117462" frictionloss="0.0981703"/>
            <geom name="//unnamed_geom_18" class="/" type="mesh" density="0" rgba="0.752941 0.752941 0.752941 1" mesh="left_leg_upper1"/>
            <geom name="//unnamed_geom_19" class="reward_collision_sphere" size="0.0653299" pos="-0.0132515 -0.0160007 0.0127456"/>
            <geom name="//unnamed_geom_20" class="reward_collision_sphere" size="0.0186657" pos="-0.0706746 0.0320015 0.0679763"/>
            <body name="right_lower_leg" pos="-0.0128545 9.49998e-05 -0.212016" quat="1 0.00061686 0.000387713 -0.000101959">
              <inertial pos="0.00563516 -0.000507879 -0.111555" quat="0.998764 0.0028704 0.0195165 -0.045623" mass="0.290509" diaginertia="0.00160362 0.00404868 0.000104408"/>
              <joint name="right_knee" class="/" pos="0 0 0" axis="0.00108374 -0.999999 0.000339418" range="-2.98812 0.00010807" armature="0.0093062" damping="0.011114" frictionloss="0.0928419"/>
              <geom name="//unnamed_geom_21" class="/" type="mesh" density="0" rgba="0.752941 0.752941 0.752941 1" mesh="left_leg_lower1"/>
              <geom name="//unnamed_geom_22" class="reward_collision_sphere" size="0.0401312"/>
              <body name="right_foot" pos="0.00225912 0.00165129 -0.236733" quat="1 -0.00022604 -5.92699e-07 0.000190608">
                <inertial pos="0.0200877 0.00252328 -0.00957277" quat="0.4798 0.519449 0.519364 0.479818" mass="0.220655" diaginertia="0.0141912 0.0363195 0.0117089"/>
                <joint name="right_ankle" class="/" pos="0 0 0" axis="-0.00099076 -0.999999 0.000817131" stiffness="0.0114928" range="-1.49434 1.50646" armature="0.00918969" damping="0.00899474" frictionloss="0.0897828"/>
                <geom name="//unnamed_geom_23" class="/" type="mesh" density="0" rgba="0.2 0.2 0.2 1" mesh="left_foot1"/>
                <geom name="right_foot" class="foot" size="0.098133 0.0169023 0.0183567" pos="0.0247361 0 -0.0212426" quat="0.707109 0.707105 0 0"/>
                <geom name="//unnamed_geom_25" class="reward_collision_sphere" size="0.0233321" pos="0.0247361 0 -0.0169941"/>
                <geom name="//unnamed_geom_26" class="reward_collision_sphere" size="0.0233321" pos="0.0883433 0 -0.0212426"/>
                <geom name="//unnamed_geom_27" class="reward_collision_sphere" size="0.0233321" pos="-0.0397545 0 -0.0212426"/>
                <site name="right_foot" class="foot" pos="0.0247361 0 -0.0212426" quat="0.707109 0.707105 0 0" size="0.00933284"/>
              </body>
            </body>
          </body>
        </body>
      </body>
      <body name="left_shoulder" pos="0.0171909 0.187663 0.256307" quat="1 -5.94763e-05 -6.38252e-05 0.000171005">
        <inertial pos="0.0085909 0.0557766 -0.000523357" quat="0.710467 0.703462 0.0145465 0.0129145" mass="0.631692" diaginertia="0.000720262 0.0011476 0.000320334"/>
        <joint name="left_shoulder_pitch" class="/" pos="0 0 0" axis="0.000456477 0.999999 -0.00140902" range="-2.96713 3.0041" armature="0.00886249" damping="0.00255605" frictionloss="0.0957689"/>
        <geom name="//unnamed_geom_28" class="/" type="mesh" density="0" rgba="0.2 0.2 0.2 1" mesh="left_shoulder1"/>
        <body name="left_shoulder_2" pos="-0.00109692 0.0606004 0.000357841" quat="0.999999 0.00105409 3.42337e-05 8.1129e-05">
          <inertial pos="0.00193162 -0.000586177 -0.0699896" quat="0.0131649 0.75728 -0.000357268 0.652957" mass="0.644171" diaginertia="0.000674224 0.00162503 0.000502462"/>
          <joint name="left_shoulder_abad" class="/" pos="0 0 0" axis="-0.999952 -0.00427461 0.00878013" stiffness="0.00494612" range="-2.99844 2.99921" armature="0.00977416" damping="0.00432867" frictionloss="0.0960536"/>
          <geom name="//unnamed_geom_29" class="/" type="mesh" density="0" rgba="0.752941 0.752941 0.752941 1" mesh="left_shoulder2"/>
          <body name="left_upper_arm" pos="-0.00127157 0.00136757 -0.0875624" quat="1 -0.00019009 -0.000347312 -0.000369783">
            <inertial pos="-0.00126781 -0.0171293 -0.0531918" quat="0.708718 -0.0223961 0.0195292 0.704866" mass="0.736702" diaginertia="0.000982598 0.00186146 0.000350364"/>
            <joint name="left_shoulder_yaw" class="/" pos="0 0 0" axis="-0.000210609 0.00035401 1" stiffness="0.009447" range="-2.98049 3.0337" armature="0.00925314" damping="0.00320271" frictionloss="0.092837"/>
            <geom name="//unnamed_geom_30" class="/" type="mesh" density="0" rgba="0.752941 0.752941 0.752941 1" mesh="left_shoulder3"/>
            <geom name="//unnamed_geom_31" class="reward_collision_sphere" size="0.055997" pos="-0.00883433 -0.0106672 -0.0424852"/>
            <body name="left_lower_arm" pos="0.000891018 0.00079225 -0.134215" quat="1 8.68569e-05 -7.15328e-06 -6.66981e-05">
              <inertial pos="-0.00635225 -0.000101634 -0.0845642" quat="0.706032 -7.43397e-05 0.00651406 0.70815" mass="0.285724" diaginertia="0.00195897 0.00496163 3.33981e-05"/>
              <joint name="left_elbow" class="/" pos="0 0 0" axis="-0.00251779 0.99995 0.00970635" stiffness="0.00453026" range="-3.0159 2.95238" armature="0.00884617" damping="0" frictionloss="0.0840561"/>
              <geom name="//unnamed_geom_32" class="/" type="mesh" density="0" rgba="0.752941 0.752941 0.752941 1" mesh="left_forearm"/>
              <geom name="//unnamed_geom_33" class="/" size="0.0233321 0.00699963" pos="0 0 -0.22942" quat="0.707109 0.707105 0 0" type="cylinder" group="3"/>
              <geom name="//unnamed_geom_34" class="reward_collision_sphere" size="0.0233321"/>
              <geom name="//unnamed_geom_35" class="reward_collision_sphere" size="0.0205322" pos="0 0 -0.237917"/>
            </body>
          </body>
        </body>
      </body>
      <body name="right_shoulder" pos="0.017021 -0.187883 0.259704" quat="1 -0.000140882 6.19424e-05 0.00017815">
        <inertial pos="0.00616563 -0.0563097 0.00101577" quat="0.710877 0.703023 -0.0153815 -0.0133053" mass="0.639681" diaginertia="0.000732651 0.0011935 0.000346075"/>
        <joint name="right_shoulder_pitch" class="/" pos="0 0 0" axis="-0.00116936 -0.999998 0.00162659" range="-3.01276 2.97921" armature="0.00934689" damping="0.00455359" frictionloss="0.0926216"/>
        <geom name="//unnamed_geom_36" class="/" type="mesh" density="0" rgba="0.2 0.2 0.2 1" mesh="left_shoulder11"/>
        <body name="right_shoulder_2" pos="0.000847 -0.061215 9.85943e-05" quat="0.999999 0.000908053 0.00057555 0.000361048">
          <inertial pos="-0.000261272 -3.76151e-05 -0.0712765" quat="-0.000218593 0.653026 0.0134131 0.757217" mass="0.67062" diaginertia="0.000682882 0.00165139 0.000502158"/>
          <joint name="right_shoulder_abad" class="/" pos="0 0 0" axis="-1 0.000533894 2.32245e-05" stiffness="0.0111782" range="-2.96329 2.99213" armature="0.00948555" damping="0.0129068" frictionloss="0.0939823"/>
          <geom name="//unnamed_geom_37" class="/" type="mesh" density="0" rgba="0.752941 0.752941 0.752941 1" mesh="left_shoulder21"/>
          <body name="right_upper_arm" pos="0.000323016 -0.00168408 -0.0866734" quat="1 -0.000267689 -0.000852175 -0.000330609">
            <inertial pos="-0.00120566 0.0176217 -0.052807" quat="0.704767 -0.0223107 0.0215761 0.708759" mass="0.738887" diaginertia="0.000949153 0.00186527 0.000339568"/>
            <joint name="right_shoulder_yaw" class="/" pos="0 0 0" axis="-0.000827248 -0.000672257 0.999999" stiffness="0.0141808" range="-3.00437 3.04304" armature="0.0094958" damping="0.00945916" frictionloss="0.101443"/>
            <geom name="//unnamed_geom_38" class="/" type="mesh" density="0" rgba="0.752941 0.752941 0.752941 1" mesh="left_shoulder31"/>
            <geom name="//unnamed_geom_39" class="reward_collision_sphere" size="0.055997" pos="-0.00883433 0.0106672 -0.0424852"/>
            <body name="right_lower_arm" pos="-0.000883155 0.000678339 -0.133332" quat="1 8.46692e-05 -0.0009102 0.000223898">
              <inertial pos="-0.00591139 -0.00030477 -0.0851309" quat="0.713161 -0.00187614 -0.000998808 0.700997" mass="0.28107" diaginertia="0.00193103 0.00491339 3.40069e-05"/>
              <joint name="right_elbow" class="/" pos="0 0 0" axis="-0.00189086 -0.999986 -0.00498529" stiffness="0.00927742" range="-3.01353 2.97964" armature="0.00841834" damping="0.00796456" frictionloss="0.0948079"/>
              <geom name="//unnamed_geom_40" class="/" type="mesh" density="0" rgba="0.752941 0.752941 0.752941 1" mesh="left_forearm"/>
              <geom name="//unnamed_geom_41" class="/" size="0.0233321 0.00699963" pos="0 0 -0.22942" quat="0.707109 0.707105 0 0" type="cylinder" group="3"/>
              <geom name="//unnamed_geom_42" class="reward_collision_sphere" size="0.0233321"/>
              <geom name="//unnamed_geom_43" class="reward_collision_sphere" size="0.0205322" pos="0 0 -0.237917"/>
            </body>
          </body>
        </body>
      </body>
    </body>
  </worldbody>

  <contact>
    <pair class="/" geom1="floor" geom2="left_foot" name="//unnamed_contact_0"/>
    <pair class="/" geom1="floor" geom2="right_foot" name="//unnamed_contact_1"/>
  </contact>

  <actuator>
    <general name="left_hip_yaw" class="/" joint="left_hip_yaw" forcerange="-32.2851 32.2851" gainprm="27.6734" biasprm="0 -27.6734 -0.459642"/>
    <general name="left_hip_abad" class="/" joint="left_hip_abad" forcerange="-30.5789 30.5789" gainprm="27.6734" biasprm="0 -27.6734 -0.459642"/>
    <general name="left_hip_pitch" class="/" joint="left_hip_pitch" forcerange="-66.1624 66.1624" gainprm="27.6734" biasprm="0 -27.6734 -0.459642"/>
    <general name="left_knee" class="/" joint="left_knee" forcerange="-127.592 127.592" gainprm="27.6734" biasprm="0 -27.6734 -0.459642"/>
    <general name="left_ankle" class="/" joint="left_ankle" forcerange="-63.072 63.072" gainprm="27.6734" biasprm="0 -27.6734 -0.459642"/>
    <general name="right_hip_yaw" class="/" joint="right_hip_yaw" forcerange="-29.1104 29.1104" gainprm="27.6734" biasprm="0 -27.6734 -0.459642"/>
    <general name="right_hip_abad" class="/" joint="right_hip_abad" forcerange="-32.5162 32.5162" gainprm="27.6734" biasprm="0 -27.6734 -0.459642"/>
    <general name="right_hip_pitch" class="/" joint="right_hip_pitch" forcerange="-68.9943 68.9943" gainprm="27.6734" biasprm="0 -27.6734 -0.459642"/>
    <general name="right_knee" class="/" joint="right_knee" forcerange="-134.776 134.776" gainprm="27.6734" biasprm="0 -27.6734 -0.459642"/>
    <general name="right_ankle" class="/" joint="right_ankle" forcerange="-63.6496 63.6496" gainprm="27.6734" biasprm="0 -27.6734 -0.459642"/>
    <general name="left_shoulder_pitch" class="/" joint="left_shoulder_pitch" forcerange="-30.5936 30.5936" gainprm="27.6734" biasprm="0 -27.6734 -0.459642"/>
    <general name="left_shoulder_abad" class="/" joint="left_shoulder_abad" forcerange="-32.6549 32.6549" gainprm="27.6734" biasprm="0 -27.6734 -0.459642"/>
    <general name="left_shoulder_yaw" class="/" joint="left_shoulder_yaw" forcerange="-31.7821 31.7821" gainprm="27.6734" biasprm="0 -27.6734 -0.459642"/>
    <general name="left_elbow" class="/" joint="left_elbow" forcerange="-49.3716 49.3716" gainprm="27.6734" biasprm="0 -27.6734 -0.459642"/>
    <general name="right_shoulder_pitch" class="/" joint="right_shoulder_pitch" forcerange="-31.9571 31.9571" gainprm="27.6734" biasprm="0 -27.6734 -0.459642"/>
    <general name="right_shoulder_abad" class="/" joint="right_shoulder_abad" forcerange="-32.0834 32.0834" gainprm="27.6734" biasprm="0 -27.6734 -0.459642"/>
    <general name="right_shoulder_yaw" class="/" joint="right_shoulder_yaw" forcerange="-31.6253 31.6253" gainprm="27.6734" biasprm="0 -27.6734 -0.459642"/>
    <general name="right_elbow" class="/" joint="right_elbow" forcerange="-53.0586 53.0586" gainprm="27.6734" biasprm="0 -27.6734 -0.459642"/>
  </actuator>

  <sensor>
    <gyro site="imu" name="imu_angular_velocity"/>
    <velocimeter site="imu" name="imu_linear_velocity"/>
    <framelinvel objtype="site" objname="left_foot" name="left_foot_global_linear_velocity"/>
    <framelinvel objtype="site" objname="right_foot" name="right_foot_global_linear_velocity"/>
  </sensor>

  <keyframe>
    <key name="home" qpos="0 0 0.656 1 0 0 0 0 0 -0.4 0.8 -0.4 0 0 0.4 -0.8 0.4 0 -0.05 0 -0.75 0 0.05 0 0.75"/>
  </keyframe>
</mujoco>
