<mujoco model="humanoid">
  <compiler angle="radian" assetdir="assets" balanceinertia="true" inertiafromgeom="false"/>

  <option timestep="0.005" density="1.2" viscosity="2e-05"/>

  <size nkey="1"/>

  <visual>
    <quality shadowsize="8192"/>
    <map shadowclip="0.5"/>
  </visual>

  <default>
    <default class="/">
      <joint armature="0.01" damping="0.01" frictionloss="0.1"/>
      <geom contype="0" conaffinity="0" group="1" solref="-1000 -80"/>
      <site size="0.01 0.005 0.005" group="5"/>
      <general forcelimited="true" biastype="affine" gainprm="30" biasprm="0 -30 -0.5"/>
      <default class="foot">
        <geom size="0.099 0.0178 0.021" type="box" condim="6" group="4" priority="1" solimp="0.015 1 0.021"/>
      </default>
      <default class="reward_collision_sphere">
        <geom group="5" rgba="1 0 0 1"/>
      </default>
    </default>
  </default>

  <asset>
    <texture type="skybox" colorspace="auto" name="//unnamed_texture_0" builtin="gradient" rgb1="0.95 0.95 0.95" rgb2="0.95 0.95 0.95" width="100" height="600"/>
    <texture type="2d" colorspace="auto" name="texplane" builtin="checker" rgb1="0.345 0.575 0.748" rgb2="0.345 0.575 0.748" markrgb="1 1 1" width="512" height="512"/>
    <material name="MatPlane" class="/" texture="texplane" texuniform="true" texrepeat="2 2" specular="0.9"/>
    <mesh name="torso" class="/" file="torso.stl" scale="0.001 0.001 0.001"/>
    <mesh name="left_hip_yaw" class="/" file="left_hip_yaw.stl" scale="0.001 0.001 0.001"/>
    <mesh name="left_hip_abad" class="/" file="left_hip_abad.stl" scale="0.001 0.001 0.001"/>
    <mesh name="left_leg_upper" class="/" file="left_leg_upper.stl" scale="0.001 0.001 0.001"/>
    <mesh name="left_leg_lower" class="/" file="left_leg_lower.stl" scale="0.001 0.001 0.001"/>
    <mesh name="left_foot" class="/" file="left_foot.stl" scale="0.001 0.001 0.001"/>
    <mesh name="left_hip_yaw1" class="/" content_type="model/stl" file="left_hip_yaw.stl" scale="0.001 -0.001 0.001"/>
    <mesh name="left_hip_abad1" class="/" content_type="model/stl" file="left_hip_abad.stl" scale="0.001 -0.001 0.001"/>
    <mesh name="left_leg_upper1" class="/" content_type="model/stl" file="left_leg_upper.stl" scale="0.001 -0.001 0.001"/>
    <mesh name="left_leg_lower1" class="/" content_type="model/stl" file="left_leg_lower.stl" scale="0.001 -0.001 0.001"/>
    <mesh name="left_foot1" class="/" content_type="model/stl" file="left_foot.stl" scale="0.001 -0.001 0.001"/>
    <mesh name="left_shoulder1" class="/" file="left_shoulder1.stl" scale="0.001 0.001 0.001"/>
    <mesh name="left_shoulder2" class="/" file="left_shoulder2.stl" scale="0.001 0.001 0.001"/>
    <mesh name="left_shoulder3" class="/" file="left_shoulder3.stl" scale="0.001 0.001 0.001"/>
    <mesh name="left_forearm" class="/" file="left_forearm.stl" scale="0.001 0.001 0.001"/>
    <mesh name="left_shoulder11" class="/" content_type="model/stl" file="left_shoulder1.stl" scale="0.001 -0.001 0.001"/>
    <mesh name="left_shoulder21" class="/" content_type="model/stl" file="left_shoulder2.stl" scale="0.001 -0.001 0.001"/>
    <mesh name="left_shoulder31" class="/" content_type="model/stl" file="left_shoulder3.stl" scale="0.001 -0.001 0.001"/>
  </asset>

  <worldbody>
    <geom name="floor" class="/" size="100 100 0.125" type="plane" group="0" material="MatPlane"/>
    <light name="toplight_shadow" class="/" pos="0 0 5" dir="0.0990148 0.0990148 -0.990148" type="directional" ambient="0.04 0.04 0.04" diffuse="0.55 0.55 0.55" specular="0.12 0.12 0.12"/>
    <light name="toplight_fill" class="/" pos="0 0 5" dir="0.0990148 0.0990148 -0.990148" type="directional" castshadow="false" ambient="0.04 0.04 0.04" diffuse="0.3 0.3 0.3" specular="0.08 0.08 0.08"/>
    <body name="trunk" pos="0.000641482 0.00849516 0.000652218" quat="0.999999 -0.000327113 4.75382e-05 0.000950245">
      <inertial pos="0.0172297 -0.00624111 0.115352" quat="0.999147 0.0390522 0.0124566 -0.00496195" mass="13.1016" diaginertia="1.49819 0.240629 0.019393"/>
      <joint name="//unnamed_joint_0" type="free"/>
      <geom name="//unnamed_geom_1" class="/" type="mesh" density="0" rgba="0.752941 0.752941 0.752941 1" mesh="torso"/>
      <geom name="//unnamed_geom_2" class="/" size="0.0864277 0.172855 0.201665" pos="0.0353424 0 0.058358" type="box" group="3" rgba="0.752941 0.752941 0.752941 1"/>
      <geom name="//unnamed_geom_3" class="reward_collision_sphere" size="0.167093" pos="0 0 0.109421"/>
      <site name="imu" class="/" pos="-0.00623832 -0.00194204 0.110241" size="0.0115237"/>
      <camera name="track" class="/" pos="0 -2.38201 0" quat="0.707107 0.707107 0 0" mode="trackcom"/>
      <camera name="ego_camera" class="/" pos="0.0691481 0 0.218843" quat="-0.5 -0.5 0.5 0.5"/>
      <body name="left_hip_yaw" pos="0.0042333 0.0972456 -0.00849789" quat="0.996446 -0.00255282 -0.0841902 0.000104488">
        <inertial pos="-0.0964394 -0.00508361 -0.0479264" quat="0.936821 -0.0092092 -0.349271 0.0170825" mass="1.04656" diaginertia="0.0150425 0.00292213 0.000143892"/>
        <joint name="left_hip_yaw" class="/" pos="0 0 0" axis="-0.000572054 -0.000283785 -1" range="-3.03237 3.00557" armature="0.0114505" damping="0.00200712" frictionloss="0.107746"/>
        <geom name="//unnamed_geom_4" class="/" type="mesh" density="0" rgba="0.2 0.2 0.2 1" mesh="left_hip_yaw"/>
        <body name="left_hip_abad" pos="-0.108741 -0.000837871 -0.0497923" quat="0.976297 5.78872e-06 0.216436 1.75754e-05">
          <inertial pos="0.103187 -0.0155319 -8.95279e-05" quat="0.579341 0.40727 0.408992 0.575518" mass="1.84915" diaginertia="0.028852 0.00427369 0.000397994"/>
          <joint name="left_hip_abad" class="/" pos="0 0 0" axis="-0.999994 0.00331495 -0.00109784" range="-3.03703 2.9914" armature="0.00963594" damping="0.0331322" frictionloss="0.150193"/>
          <geom name="//unnamed_geom_5" class="/" type="mesh" density="0" rgba="0.2 0.2 0.2 1" mesh="left_hip_abad"/>
          <body name="left_upper_leg" pos="0.131388 -0.00430797 -0.0108177" quat="0.991347 0.000150497 -0.131266 0.000140111">
            <inertial pos="-0.007706 0.0359307 -0.0573743" quat="0.730038 0.0346532 -0.0483566 0.680812" mass="4.36986" diaginertia="0.210119 0.0628935 0.000751716"/>
            <joint name="left_hip_pitch" class="/" pos="0 0 0" axis="-0.00340531 0.999994 0.000156578" stiffness="0.0284396" range="-2.9815 2.99644" armature="0.0112336" damping="0.0646865" frictionloss="0.0911418"/>
            <geom name="//unnamed_geom_6" class="/" type="mesh" density="0" rgba="0.752941 0.752941 0.752941 1" mesh="left_leg_upper"/>
            <geom name="//unnamed_geom_7" class="reward_collision_sphere" size="0.0806658" pos="-0.0230494 0.0178651 0.0109421"/>
            <geom name="//unnamed_geom_8" class="reward_collision_sphere" size="0.0230474" pos="-0.12293 -0.0357302 0.058358"/>
            <body name="left_lower_leg" pos="-0.0280018 -0.00282886 -0.182839" quat="0.999992 0.00316952 0.00186725 -0.00133048">
              <inertial pos="0.00896438 -0.00745244 -0.106131" quat="0.999231 0.0136656 -0.0222856 0.0292164" mass="0.464588" diaginertia="0.0249882 0.00644203 4.76236e-05"/>
              <joint name="left_knee" class="/" pos="0 0 0" axis="-0.0135927 0.999907 0.000883587" range="-0.151821 2.97533" armature="0.0135852" damping="0" frictionloss="0.139573"/>
              <geom name="//unnamed_geom_9" class="/" type="mesh" density="0" rgba="0.752941 0.752941 0.752941 1" mesh="left_leg_lower"/>
              <geom name="//unnamed_geom_10" class="reward_collision_sphere" size="0.0495519"/>
              <body name="left_foot" pos="0.0037482 0.000701769 -0.201077" quat="1 5.28771e-05 -0.000231769 -0.000123945">
                <inertial pos="0.0319222 0.00187618 -0.00269568" quat="0.556156 0.462855 0.481038 0.495033" mass="0.412811" diaginertia="0.207075 0.057064 0.00501685"/>
                <joint name="left_ankle" class="/" pos="0 0 0" axis="-0.00382627 0.99996 -0.00806529" range="-1.56391 1.48689" armature="0.00585577" damping="0" frictionloss="0.105172"/>
                <geom name="//unnamed_geom_11" class="/" type="mesh" density="0" rgba="0.2 0.2 0.2 1" mesh="left_foot"/>
                <geom name="left_foot" class="foot" size="0.109867 0.0253623 0.0320256" pos="0.0430255 0 -0.0182369" quat="0.707109 0.707105 0 0"/>
                <geom name="//unnamed_geom_13" class="reward_collision_sphere" size="0.0288092" pos="0.0430255 0 -0.0145895"/>
                <geom name="//unnamed_geom_14" class="reward_collision_sphere" size="0.0288092" pos="0.153662 0 -0.0182369"/>
                <geom name="//unnamed_geom_15" class="reward_collision_sphere" size="0.0288092" pos="-0.0691481 0 -0.0182369"/>
                <site name="left_foot" class="foot" pos="0.0430255 0 -0.0182369" quat="0.707109 0.707105 0 0" size="0.0115237"/>
              </body>
            </body>
          </body>
        </body>
      </body>
      <body name="right_hip_yaw" pos="-0.000508673 -0.0987146 0.00707618" quat="0.996152 -0.000523791 -0.0876397 -0.000239587">
        <inertial pos="-0.0943522 -0.000837355 -0.047123" quat="0.950115 -0.00275034 0.311877 -0.0024347" mass="1.55014" diaginertia="0.0179621 0.00362057 0.000179717"/>
        <joint name="right_hip_yaw" class="/" pos="0 0 0" axis="-0.00037554 -0.000226836 -1" stiffness="0.0472513" range="-2.87311 2.97018" armature="0.0153769" damping="0.0215394" frictionloss="0.118993"/>
        <geom name="//unnamed_geom_16" class="/" type="mesh" density="0" rgba="0.2 0.2 0.2 1" mesh="left_hip_yaw1"/>
        <body name="right_hip_abad" pos="-0.101814 0.000141081 -0.0556002" quat="0.97591 -0.00428856 0.218131 -0.000683536">
          <inertial pos="0.102016 0.0202785 0.00174317" quat="0.411443 0.574418 0.578959 0.406898" mass="1.57932" diaginertia="0.0273139 0.00451686 0.000319937"/>
          <joint name="right_hip_abad" class="/" pos="0 0 0" axis="-0.999965 -0.00287858 0.00782226" range="-3.01884 2.98239" armature="0.0073546" damping="0.00952915" frictionloss="0.122355"/>
          <geom name="//unnamed_geom_17" class="/" type="mesh" density="0" rgba="0.2 0.2 0.2 1" mesh="left_hip_abad1"/>
          <body name="right_upper_leg" pos="0.13239 0.00461617 -0.0169029" quat="0.991517 0.000236379 -0.129964 -0.00192463">
            <inertial pos="0.000622021 -0.0292693 -0.0594995" quat="0.678636 0.0559338 -0.0371638 0.731398" mass="3.93604" diaginertia="0.21935 0.0562739 0.000726507"/>
            <joint name="right_hip_pitch" class="/" pos="0 0 0" axis="0.00392616 -0.999979 -0.00517915" stiffness="0.0177847" range="-2.79766 3.12419" armature="0.0116649" damping="0.0227414" frictionloss="0.0826304"/>
            <geom name="//unnamed_geom_18" class="/" type="mesh" density="0" rgba="0.752941 0.752941 0.752941 1" mesh="left_leg_upper1"/>
            <geom name="//unnamed_geom_19" class="reward_collision_sphere" size="0.0806658" pos="-0.0230494 -0.0178651 0.0109421"/>
            <geom name="//unnamed_geom_20" class="reward_collision_sphere" size="0.0230474" pos="-0.12293 0.0357302 0.058358"/>
            <body name="right_lower_leg" pos="-0.0126484 0.00195019 -0.184993" quat="0.999994 -0.00158008 -0.00219859 0.00228266">
              <inertial pos="0.00835626 -0.000471291 -0.097138" quat="0.99886 0.00568883 0.015261 -0.0448653" mass="0.46444" diaginertia="0.0262193 0.00683981 4.99257e-05"/>
              <joint name="right_knee" class="/" pos="0 0 0" axis="-0.00154528 -0.999934 0.0113525" range="-2.94979 0.0313616" armature="0.0115852" damping="0.0165869" frictionloss="0.115459"/>
              <geom name="//unnamed_geom_21" class="/" type="mesh" density="0" rgba="0.752941 0.752941 0.752941 1" mesh="left_leg_lower1"/>
              <geom name="//unnamed_geom_22" class="reward_collision_sphere" size="0.0495519"/>
              <body name="right_foot" pos="-0.0104505 -0.00792986 -0.205407" quat="0.999997 0.000765986 0.00232573 -0.000614743">
                <inertial pos="0.0338891 -0.0100208 -0.0188558" quat="0.480426 0.519241 0.51939 0.479388" mass="0.474939" diaginertia="0.265529 0.0738512 0.00617622"/>
                <joint name="right_ankle" class="/" pos="0 0 0" axis="-0.00304528 -0.999966 0.0076854" range="-1.51917 1.47121" armature="0.0119596" damping="0.0167681" frictionloss="0.144386"/>
                <geom name="//unnamed_geom_23" class="/" type="mesh" density="0" rgba="0.2 0.2 0.2 1" mesh="left_foot1"/>
                <geom name="right_foot" class="foot" size="0.0775528 0.015622 0.02174" pos="0.0430255 0 -0.0182369" quat="0.707109 0.707105 0 0"/>
                <geom name="//unnamed_geom_25" class="reward_collision_sphere" size="0.0288092" pos="0.0430255 0 -0.0145895"/>
                <geom name="//unnamed_geom_26" class="reward_collision_sphere" size="0.0288092" pos="0.153662 0 -0.0182369"/>
                <geom name="//unnamed_geom_27" class="reward_collision_sphere" size="0.0288092" pos="-0.0691481 0 -0.0182369"/>
                <site name="right_foot" class="foot" pos="0.0430255 0 -0.0182369" quat="0.707109 0.707105 0 0" size="0.0115237"/>
              </body>
            </body>
          </body>
        </body>
      </body>
      <body name="left_shoulder" pos="0.0237174 0.207564 0.231536" quat="0.999999 0.000184005 0.000337248 -0.00100589">
        <inertial pos="0.0102385 0.0610166 -0.00232688" quat="0.710004 0.703946 0.0144753 0.012074" mass="1.30548" diaginertia="0.0122941 0.00245952 0.000189753"/>
        <joint name="left_shoulder_pitch" class="/" pos="0 0 0" axis="0.00110647 0.999982 -0.00583528" stiffness="0.00244962" range="-3.13602 2.97778" armature="0.0108081" damping="0.0060995" frictionloss="0.126541"/>
        <geom name="//unnamed_geom_28" class="/" type="mesh" density="0" rgba="0.2 0.2 0.2 1" mesh="left_shoulder1"/>
        <body name="left_shoulder_2" pos="0.00653904 0.0676903 -0.00256333" quat="0.999992 0.00204291 -0.000297605 0.00351687">
          <inertial pos="-0.00814619 -0.00187101 -0.0618673" quat="0.0140187 0.757515 -0.000193724 0.652668" mass="1.2514" diaginertia="0.0111968 0.00307043 0.000233173"/>
          <joint name="left_shoulder_abad" class="/" pos="0 0 0" axis="-0.999306 -0.0100037 0.0358877" range="-2.99918 2.99597" armature="0.0115475" damping="0.00489022" frictionloss="0.12937"/>
          <geom name="//unnamed_geom_29" class="/" type="mesh" density="0" rgba="0.752941 0.752941 0.752941 1" mesh="left_shoulder2"/>
          <body name="left_upper_arm" pos="0.00768385 -0.00615384 -0.0702574" quat="0.999996 -0.00267479 0.00119541 0.000197048">
            <inertial pos="0.00569386 -0.0177067 -0.0440864" quat="0.704202 -0.0297771 0.0181901 0.709142" mass="1.4439" diaginertia="0.0157574 0.00349732 0.000170965"/>
            <joint name="left_shoulder_yaw" class="/" pos="0 0 0" axis="0.0109624 0.000307582 0.99994" range="-2.99333 2.85569" armature="0.0137905" damping="0" frictionloss="0.112108"/>
            <geom name="//unnamed_geom_30" class="/" type="mesh" density="0" rgba="0.752941 0.752941 0.752941 1" mesh="left_shoulder3"/>
            <geom name="//unnamed_geom_31" class="reward_collision_sphere" size="0.0691421" pos="-0.0153662 -0.0119101 -0.0364738"/>
            <body name="left_lower_arm" pos="-0.00618356 0.00200303 -0.113602" quat="1 1.36836e-05 -9.98245e-05 -0.000238963">
              <inertial pos="-0.00993706 -0.00146165 -0.0713411" quat="0.70453 0.00392729 0.00341258 0.709655" mass="0.554784" diaginertia="0.0314144 0.00865092 1.77716e-05"/>
              <joint name="left_elbow" class="/" pos="0 0 0" axis="0.00404471 0.999169 -0.0405643" stiffness="0.00544513" range="-3.04178 3.19541" armature="0.0109361" damping="0.0521028" frictionloss="0.161477"/>
              <geom name="//unnamed_geom_32" class="/" type="mesh" density="0" rgba="0.752941 0.752941 0.752941 1" mesh="left_forearm"/>
              <geom name="//unnamed_geom_33" class="/" size="0.0288092 0.00864277" pos="0 0 -0.196958" quat="0.707109 0.707105 0 0" type="cylinder" group="3"/>
              <geom name="//unnamed_geom_34" class="reward_collision_sphere" size="0.0288092"/>
              <geom name="//unnamed_geom_35" class="reward_collision_sphere" size="0.0253521" pos="0 0 -0.204253"/>
            </body>
          </body>
        </body>
      </body>
      <body name="right_shoulder" pos="0.0273813 -0.208621 0.21538" quat="0.999999 -0.00147703 -0.00021481 -8.8265e-05">
        <inertial pos="0.0225823 -0.060885 -0.000597988" quat="0.710602 0.703291 -0.0165322 -0.0123776" mass="1.20381" diaginertia="0.0116609 0.0020804 0.000134159"/>
        <joint name="right_shoulder_pitch" class="/" pos="0 0 0" axis="-0.00344728 -0.999994 0.000113594" stiffness="0.0422215" range="-2.98451 2.98825" armature="0.00933486" damping="0.000784455" frictionloss="0.125038"/>
        <geom name="//unnamed_geom_36" class="/" type="mesh" density="0" rgba="0.2 0.2 0.2 1" mesh="left_shoulder11"/>
        <body name="right_shoulder_2" pos="0.00105954 -0.0650662 -0.000817481" quat="0.999989 -0.00308189 -0.00362373 0.000409103">
          <inertial pos="0.00177131 0.0032276 -0.0618168" quat="-0.00482157 0.656195 0.0173887 0.754375" mass="1.04396" diaginertia="0.00973059 0.00247431 0.000231461"/>
          <joint name="right_shoulder_abad" class="/" pos="0 0 0" axis="-0.999999 -0.00143616 -0.000879173" range="-3.14868 3.022" armature="0.0109451" damping="0" frictionloss="0.134773"/>
          <geom name="//unnamed_geom_37" class="/" type="mesh" density="0" rgba="0.752941 0.752941 0.752941 1" mesh="left_shoulder21"/>
          <body name="right_upper_arm" pos="0.00175193 0.00829421 -0.0729777" quat="0.999993 -0.00169282 -0.0025665 0.00221523">
            <inertial pos="0.00514448 0.0194831 -0.0461587" quat="0.699634 -0.0282419 0.0315715 0.713244" mass="1.37257" diaginertia="0.0169147 0.00330823 0.000183972"/>
            <joint name="right_shoulder_yaw" class="/" pos="0 0 0" axis="0.00597258 -0.00400076 0.999974" range="-2.99974 2.82576" armature="0.00885024" damping="0.0161037" frictionloss="0.0732573"/>
            <geom name="//unnamed_geom_38" class="/" type="mesh" density="0" rgba="0.752941 0.752941 0.752941 1" mesh="left_shoulder31"/>
            <geom name="//unnamed_geom_39" class="reward_collision_sphere" size="0.0691421" pos="-0.0153662 0.0119101 -0.0364738"/>
            <body name="right_lower_arm" pos="0.00547674 0.000148436 -0.113041" quat="0.999993 -0.00122985 -0.00351366 0.000835648">
              <inertial pos="-0.0117722 0.00118574 -0.0738524" quat="0.688263 0.0108658 -0.0367107 0.724451" mass="0.532309" diaginertia="0.0300515 0.00897627 1.51602e-05"/>
              <joint name="right_elbow" class="/" pos="0 0 0" axis="0.00529107 -0.999947 0.00881575" range="-2.98932 2.9904" armature="0.0160328" damping="0.0173081" frictionloss="0.125198"/>
              <geom name="//unnamed_geom_40" class="/" type="mesh" density="0" rgba="0.752941 0.752941 0.752941 1" mesh="left_forearm"/>
              <geom name="//unnamed_geom_41" class="/" size="0.0288092 0.00864277" pos="0 0 -0.196958" quat="0.707109 0.707105 0 0" type="cylinder" group="3"/>
              <geom name="//unnamed_geom_42" class="reward_collision_sphere" size="0.0288092"/>
              <geom name="//unnamed_geom_43" class="reward_collision_sphere" size="0.0253521" pos="0 0 -0.204253"/>
            </body>
          </body>
        </body>
      </body>
    </body>
  </worldbody>

  <contact>
    <pair class="/" geom1="floor" geom2="left_foot" name="//unnamed_contact_0"/>
    <pair class="/" geom1="floor" geom2="right_foot" name="//unnamed_contact_1"/>
  </contact>

  <actuator>
    <general name="left_hip_yaw" class="/" joint="left_hip_yaw" forcerange="-43.1738 43.1738" gainprm="32.4597" biasprm="0 -32.4597 -0.591886"/>
    <general name="left_hip_abad" class="/" joint="left_hip_abad" forcerange="-38.7172 38.7172" gainprm="32.4597" biasprm="0 -32.4597 -0.591886"/>
    <general name="left_hip_pitch" class="/" joint="left_hip_pitch" forcerange="-86.4749 86.4749" gainprm="32.4597" biasprm="0 -32.4597 -0.591886"/>
    <general name="left_knee" class="/" joint="left_knee" forcerange="-202.017 202.017" gainprm="32.4597" biasprm="0 -32.4597 -0.591886"/>
    <general name="left_ankle" class="/" joint="left_ankle" forcerange="-78.1117 78.1117" gainprm="32.4597" biasprm="0 -32.4597 -0.591886"/>
    <general name="right_hip_yaw" class="/" joint="right_hip_yaw" forcerange="-51.9075 51.9075" gainprm="32.4597" biasprm="0 -32.4597 -0.591886"/>
    <general name="right_hip_abad" class="/" joint="right_hip_abad" forcerange="-32.109 32.109" gainprm="32.4597" biasprm="0 -32.4597 -0.591886"/>
    <general name="right_hip_pitch" class="/" joint="right_hip_pitch" forcerange="-88.6254 88.6254" gainprm="32.4597" biasprm="0 -32.4597 -0.591886"/>
    <general name="right_knee" class="/" joint="right_knee" forcerange="-162.179 162.179" gainprm="32.4597" biasprm="0 -32.4597 -0.591886"/>
    <general name="right_ankle" class="/" joint="right_ankle" forcerange="-76.8732 76.8732" gainprm="32.4597" biasprm="0 -32.4597 -0.591886"/>
    <general name="left_shoulder_pitch" class="/" joint="left_shoulder_pitch" forcerange="-47.3978 47.3978" gainprm="32.4597" biasprm="0 -32.4597 -0.591886"/>
    <general name="left_shoulder_abad" class="/" joint="left_shoulder_abad" forcerange="-31.5725 31.5725" gainprm="32.4597" biasprm="0 -32.4597 -0.591886"/>
    <general name="left_shoulder_yaw" class="/" joint="left_shoulder_yaw" forcerange="-39.0623 39.0623" gainprm="32.4597" biasprm="0 -32.4597 -0.591886"/>
    <general name="left_elbow" class="/" joint="left_elbow" forcerange="-61.4899 61.4899" gainprm="32.4597" biasprm="0 -32.4597 -0.591886"/>
    <general name="right_shoulder_pitch" class="/" joint="right_shoulder_pitch" forcerange="-41.8018 41.8018" gainprm="32.4597" biasprm="0 -32.4597 -0.591886"/>
    <general name="right_shoulder_abad" class="/" joint="right_shoulder_abad" forcerange="-43.817 43.817" gainprm="32.4597" biasprm="0 -32.4597 -0.591886"/>
    <general name="right_shoulder_yaw" class="/" joint="right_shoulder_yaw" forcerange="-41.7322 41.7322" gainprm="32.4597" biasprm="0 -32.4597 -0.591886"/>
    <general name="right_elbow" class="/" joint="right_elbow" forcerange="-67.8653 67.8653" gainprm="32.4597" biasprm="0 -32.4597 -0.591886"/>
  </actuator>

  <sensor>
    <gyro site="imu" name="imu_angular_velocity"/>
    <velocimeter site="imu" name="imu_linear_velocity"/>
    <framelinvel objtype="site" objname="left_foot" name="left_foot_global_linear_velocity"/>
    <framelinvel objtype="site" objname="right_foot" name="right_foot_global_linear_velocity"/>
  </sensor>

  <keyframe>
    <key name="home" qpos="0 0 0.656 1 0 0 0 0 0 -0.4 0.8 -0.4 0 0 0.4 -0.8 0.4 0 -0.05 0 -0.75 0 0.05 0 0.75"/>
  </keyframe>
</mujoco>
