<mujoco model="humanoid">
  <compiler angle="radian" assetdir="assets" balanceinertia="true" inertiafromgeom="false"/>

  <option timestep="0.005" density="1.2" viscosity="2e-05"/>

  <size nkey="1"/>

  <visual>
    <quality shadowsize="8192"/>
    <map shadowclip="0.5"/>
  </visual>

  <default>
    <default class="/">
      <joint armature="0.01" damping="0.01" frictionloss="0.1"/>
      <geom contype="0" conaffinity="0" group="1" solref="-1000 -80"/>
      <site size="0.01 0.005 0.005" group="5"/>
      <general forcelimited="true" biastype="affine" gainprm="30" biasprm="0 -30 -0.5"/>
      <default class="foot">
        <geom size="0.099 0.0178 0.021" type="box" condim="6" group="4" priority="1" solimp="0.015 1 0.021"/>
      </default>
      <default class="reward_collision_sphere">
        <geom group="5" rgba="1 0 0 1"/>
      </default>
    </default>
  </default>

  <asset>
    <texture type="skybox" colorspace="auto" name="//unnamed_texture_0" builtin="gradient" rgb1="0.95 0.95 0.95" rgb2="0.95 0.95 0.95" width="100" height="600"/>
    <texture type="2d" colorspace="auto" name="texplane" builtin="checker" rgb1="0.345 0.575 0.748" rgb2="0.345 0.575 0.748" markrgb="1 1 1" width="512" height="512"/>
    <material name="MatPlane" class="/" texture="texplane" texuniform="true" texrepeat="2 2" specular="0.9"/>
    <mesh name="torso" class="/" file="torso.stl" scale="0.001 0.001 0.001"/>
    <mesh name="left_hip_yaw" class="/" file="left_hip_yaw.stl" scale="0.001 0.001 0.001"/>
    <mesh name="left_hip_abad" class="/" file="left_hip_abad.stl" scale="0.001 0.001 0.001"/>
    <mesh name="left_leg_upper" class="/" file="left_leg_upper.stl" scale="0.001 0.001 0.001"/>
    <mesh name="left_leg_lower" class="/" file="left_leg_lower.stl" scale="0.001 0.001 0.001"/>
    <mesh name="left_foot" class="/" file="left_foot.stl" scale="0.001 0.001 0.001"/>
    <mesh name="left_hip_yaw1" class="/" content_type="model/stl" file="left_hip_yaw.stl" scale="0.001 -0.001 0.001"/>
    <mesh name="left_hip_abad1" class="/" content_type="model/stl" file="left_hip_abad.stl" scale="0.001 -0.001 0.001"/>
    <mesh name="left_leg_upper1" class="/" content_type="model/stl" file="left_leg_upper.stl" scale="0.001 -0.001 0.001"/>
    <mesh name="left_leg_lower1" class="/" content_type="model/stl" file="left_leg_lower.stl" scale="0.001 -0.001 0.001"/>
    <mesh name="left_foot1" class="/" content_type="model/stl" file="left_foot.stl" scale="0.001 -0.001 0.001"/>
    <mesh name="left_shoulder1" class="/" file="left_shoulder1.stl" scale="0.001 0.001 0.001"/>
    <mesh name="left_shoulder2" class="/" file="left_shoulder2.stl" scale="0.001 0.001 0.001"/>
    <mesh name="left_shoulder3" class="/" file="left_shoulder3.stl" scale="0.001 0.001 0.001"/>
    <mesh name="left_forearm" class="/" file="left_forearm.stl" scale="0.001 0.001 0.001"/>
    <mesh name="left_shoulder11" class="/" content_type="model/stl" file="left_shoulder1.stl" scale="0.001 -0.001 0.001"/>
    <mesh name="left_shoulder21" class="/" content_type="model/stl" file="left_shoulder2.stl" scale="0.001 -0.001 0.001"/>
    <mesh name="left_shoulder31" class="/" content_type="model/stl" file="left_shoulder3.stl" scale="0.001 -0.001 0.001"/>
  </asset>

  <worldbody>
    <geom name="floor" class="/" size="100 100 0.125" type="plane" group="0" material="MatPlane"/>
    <light name="toplight_shadow" class="/" pos="0 0 5" dir="0.0990148 0.0990148 -0.990148" type="directional" ambient="0.04 0.04 0.04" diffuse="0.55 0.55 0.55" specular="0.12 0.12 0.12"/>
    <light name="toplight_fill" class="/" pos="0 0 5" dir="0.0990148 0.0990148 -0.990148" type="directional" castshadow="false" ambient="0.04 0.04 0.04" diffuse="0.3 0.3 0.3" specular="0.08 0.08 0.08"/>
    <body name="trunk" pos="0.0174878 -0.00275921 0.0101518" quat="0.999996 0.00254751 0.00138302 0.00065652">
      <inertial pos="0.0228403 -0.0113103 0.138081" quat="0.996498 0.0372058 0.0649388 -0.0372803" mass="4.09559" diaginertia="0.252835 0.0175558 0.0314134"/>
      <joint name="//unnamed_joint_0" type="free"/>
      <geom name="//unnamed_geom_1" class="/" type="mesh" density="0" rgba="0.752941 0.752941 0.752941 1" mesh="torso"/>
      <geom name="//unnamed_geom_2" class="/" size="0.0650201 0.13004 0.151714" pos="0.0244044 0 0.0632406" type="box" group="3" rgba="0.752941 0.752941 0.752941 1"/>
      <geom name="//unnamed_geom_3" class="reward_collision_sphere" size="0.125706" pos="0 0 0.118576"/>
      <site name="imu" class="/" pos="0.0672365 -0.0811735 0.187862" size="0.00866935"/>
      <camera name="track" class="/" pos="0 -1.49847 0" quat="0.707107 0.707107 0 0" mode="trackcom"/>
      <camera name="ego_camera" class="/" pos="0.0477478 0 0.237152" quat="-0.5 -0.5 0.5 0.5"/>
      <body name="left_hip_yaw" pos="-0.0108099 0.0762832 -0.0130252" quat="0.996008 0.00111443 -0.0892532 0.000113597">
        <inertial pos="-0.0733639 -0.0126612 -0.0585276" quat="0.938433 0.014341 -0.345154 -0.00252742" mass="0.682007" diaginertia="0.00368791 0.000478507 0.000232871"/>
        <joint name="left_hip_yaw" class="/" pos="0 0 0" axis="-0.0014534 -0.0226295 -0.999743" range="-2.7288 3.24659" armature="0.0102951" damping="0.0048325" frictionloss="0.150644"/>
        <geom name="//unnamed_geom_4" class="/" type="mesh" density="0" rgba="0.2 0.2 0.2 1" mesh="left_hip_yaw"/>
        <body name="left_hip_abad" pos="-0.077804 -0.0101673 -0.0735962" quat="0.975102 -0.00425977 0.221709 0.00152165">
          <inertial pos="0.056218 0.00110658 -0.00848314" quat="0.576221 0.469819 0.369475 0.55743" mass="0.941659" diaginertia="0.00416231 0.000566955 0.000547159"/>
          <joint name="left_hip_abad" class="/" pos="0 0 0" axis="-0.997833 0.0502946 -0.0424138" stiffness="0.0983134" range="-3.06575 2.80195" armature="0.00125567" damping="0" frictionloss="0.11232"/>
          <geom name="//unnamed_geom_5" class="/" type="mesh" density="0" rgba="0.2 0.2 0.2 1" mesh="left_hip_abad"/>
          <body name="left_upper_leg" pos="0.100544 0.0115826 -0.0246461" quat="0.991139 -0.000133277 -0.132813 0.00222155">
            <inertial pos="0.00656467 0.0179402 -0.0773263" quat="0.729613 0.00143573 -0.0459893 0.682311" mass="1.90357" diaginertia="0.0290214 0.00689193 0.00134565"/>
            <joint name="left_hip_pitch" class="/" pos="0 0 0" axis="0.00804352 0.99895 0.0451114" stiffness="0.0184439" range="-3.21076 2.78119" armature="0.0159928" damping="0" frictionloss="0.0395319"/>
            <geom name="//unnamed_geom_6" class="/" type="mesh" density="0" rgba="0.752941 0.752941 0.752941 1" mesh="left_leg_upper"/>
            <geom name="//unnamed_geom_7" class="reward_collision_sphere" size="0.0606854" pos="-0.0159159 0.0112385 0.0118576"/>
            <geom name="//unnamed_geom_8" class="reward_collision_sphere" size="0.0173387" pos="-0.084885 -0.022477 0.0632406"/>
            <body name="left_lower_leg" pos="-0.0258894 -0.00410459 -0.204928" quat="1 -0.000500341 -0.000228482 0.00041169">
              <inertial pos="0.0090413 0.0190294 -0.116621" quat="0.999808 0.0185403 -0.00159129 -0.00611857" mass="0.165869" diaginertia="0.00449702 0.000524762 5.81591e-05"/>
              <joint name="left_knee" class="/" pos="0 0 0" axis="0.0177223 0.995969 -0.0879337" stiffness="0.035756" range="-0.00175992 3.03487" armature="0.0106597" damping="0" frictionloss="0.00541429"/>
              <geom name="//unnamed_geom_9" class="/" type="mesh" density="0" rgba="0.752941 0.752941 0.752941 1" mesh="left_leg_lower"/>
              <geom name="//unnamed_geom_10" class="reward_collision_sphere" size="0.0372782"/>
              <body name="left_foot" pos="0.00551898 -0.0153176 -0.216851" quat="0.999986 -0.00426466 0.00309792 0.000263752">
                <inertial pos="0.0425849 -0.0152772 -0.00791435" quat="0.539278 0.458846 0.470893 0.526212" mass="0.234909" diaginertia="0.0462565 0.00552046 0.00804542"/>
                <joint name="left_ankle" class="/" pos="0 0 0" axis="0.0815084 0.99582 0.0412181" stiffness="0.062461" range="-1.18579 1.49824" armature="0.00109537" damping="0" frictionloss="0.161544"/>
                <geom name="//unnamed_geom_11" class="/" type="mesh" density="0" rgba="0.2 0.2 0.2 1" mesh="left_foot"/>
                <geom name="left_foot" class="foot" size="0.139924 0.00854336 0.00956174" pos="0.0297098 0 -0.0197627" quat="0.707109 0.707105 0 0"/>
                <geom name="//unnamed_geom_13" class="reward_collision_sphere" size="0.0216734" pos="0.0297098 0 -0.0158102"/>
                <geom name="//unnamed_geom_14" class="reward_collision_sphere" size="0.0216734" pos="0.106106 0 -0.0197627"/>
                <geom name="//unnamed_geom_15" class="reward_collision_sphere" size="0.0216734" pos="-0.0477478 0 -0.0197627"/>
                <site name="left_foot" class="foot" pos="0.0297098 0 -0.0197627" quat="0.707109 0.707105 0 0" size="0.00866935"/>
              </body>
            </body>
          </body>
        </body>
      </body>
      <body name="right_hip_yaw" pos="0.000146834 -0.076739 -0.00207467" quat="0.996304 0.00656155 -0.0855133 -0.00471973">
        <inertial pos="-0.0824101 0.0199348 -0.048559" quat="0.950538 0.0617224 0.300091 0.0511284" mass="0.365312" diaginertia="0.00201756 0.000250102 0.000198988"/>
        <joint name="right_hip_yaw" class="/" pos="0 0 0" axis="0.00103338 0.00344341 -0.999994" range="-2.94991 2.78281" armature="0.0152578" damping="0.0307931" frictionloss="0.160817"/>
        <geom name="//unnamed_geom_16" class="/" type="mesh" density="0" rgba="0.2 0.2 0.2 1" mesh="left_hip_yaw1"/>
        <body name="right_hip_abad" pos="-0.0732884 -0.0173015 -0.066245" quat="0.975652 -0.00245888 0.21924 0.00556014">
          <inertial pos="0.0865745 0.0180664 -0.00195317" quat="0.415106 0.601127 0.550206 0.404484" mass="0.588149" diaginertia="0.0041254 0.000386411 0.000442729"/>
          <joint name="right_hip_abad" class="/" pos="0 0 0" axis="-0.999503 0.0306408 0.00747408" range="-2.6143 2.98123" armature="0.0128453" damping="0.00362616" frictionloss="0.10642"/>
          <geom name="//unnamed_geom_17" class="/" type="mesh" density="0" rgba="0.2 0.2 0.2 1" mesh="left_hip_abad1"/>
          <body name="right_upper_leg" pos="0.099474 0.0171397 0.00715656" quat="0.990859 0.00108788 -0.134807 -0.00499305">
            <inertial pos="-0.0107827 -0.00461986 -0.0469142" quat="0.683512 0.0424678 -0.0318746 0.728006" mass="2.10494" diaginertia="0.0435992 0.0058125 0.00123306"/>
            <joint name="right_hip_pitch" class="/" pos="0 0 0" axis="0.0817361 -0.996463 0.0194982" stiffness="0.0873459" range="-3.27895 2.83206" armature="0.0164123" damping="0.0533196" frictionloss="0.0932839"/>
            <geom name="//unnamed_geom_18" class="/" type="mesh" density="0" rgba="0.752941 0.752941 0.752941 1" mesh="left_leg_upper1"/>
            <geom name="//unnamed_geom_19" class="reward_collision_sphere" size="0.0606854" pos="-0.0159159 -0.0112385 0.0118576"/>
            <geom name="//unnamed_geom_20" class="reward_collision_sphere" size="0.0173387" pos="-0.084885 0.022477 0.0632406"/>
            <body name="right_lower_leg" pos="-0.0043945 -0.00367324 -0.211009" quat="0.999999 0.001526 0.000536135 -0.0001211">
              <inertial pos="0.0169128 0.0119323 -0.122346" quat="0.995438 0.014368 -0.0571745 -0.0750178" mass="0.154835" diaginertia="0.00372888 0.000631538 6.20653e-05"/>
              <joint name="right_knee" class="/" pos="0 0 0" axis="-0.0267859 -0.999109 0.0326024" range="-2.81508 -0.18456" armature="0.00155883" damping="0.0266517" frictionloss="0.127235"/>
              <geom name="//unnamed_geom_21" class="/" type="mesh" density="0" rgba="0.752941 0.752941 0.752941 1" mesh="left_leg_lower1"/>
              <geom name="//unnamed_geom_22" class="reward_collision_sphere" size="0.0372782"/>
              <body name="right_foot" pos="0.00732476 0.00292406 -0.205709" quat="0.999994 0.00166949 0.00180737 0.00232583">
                <inertial pos="0.0128428 0.00218153 -0.027829" quat="0.444055 0.501462 0.52334 0.52675" mass="0.216524" diaginertia="0.045686 0.00934158 0.0109871"/>
                <joint name="right_ankle" class="/" pos="0 0 0" axis="0.0140778 -0.999366 0.0326895" range="-1.10575 1.54813" armature="0.00791796" damping="0" frictionloss="0.0685809"/>
                <geom name="//unnamed_geom_23" class="/" type="mesh" density="0" rgba="0.2 0.2 0.2 1" mesh="left_foot1"/>
                <geom name="right_foot" class="foot" size="0.114968 0.0149781 0.00657118" pos="0.0297098 0 -0.0197627" quat="0.707109 0.707105 0 0"/>
                <geom name="//unnamed_geom_25" class="reward_collision_sphere" size="0.0216734" pos="0.0297098 0 -0.0158102"/>
                <geom name="//unnamed_geom_26" class="reward_collision_sphere" size="0.0216734" pos="0.106106 0 -0.0197627"/>
                <geom name="//unnamed_geom_27" class="reward_collision_sphere" size="0.0216734" pos="-0.0477478 0 -0.0197627"/>
                <site name="right_foot" class="foot" pos="0.0297098 0 -0.0197627" quat="0.707109 0.707105 0 0" size="0.00866935"/>
              </body>
            </body>
          </body>
        </body>
      </body>
      <body name="left_shoulder" pos="0.010522 0.138201 0.223991" quat="1 -0.000330633 0.000794529 -0.000385339">
        <inertial pos="0.0137091 0.0576198 -0.00580089" quat="0.722971 0.690218 0.0237358 0.018657" mass="0.713423" diaginertia="0.00202508 0.000241018 0.00023123"/>
        <joint name="left_shoulder_pitch" class="/" pos="0 0 0" axis="-0.0707274 0.997186 0.0248732" stiffness="0.0406593" range="-2.76638 3.08046" armature="0.00243896" damping="0" frictionloss="0.0554227"/>
        <geom name="//unnamed_geom_28" class="/" type="mesh" density="0" rgba="0.2 0.2 0.2 1" mesh="left_shoulder1"/>
        <body name="left_shoulder_2" pos="-0.00761802 0.0404013 0.0122142" quat="0.999988 0.00184837 -0.00381702 -0.00225492">
          <inertial pos="0.00773918 -0.0118327 -0.053562" quat="0.0302515 0.726593 -0.0112074 0.686311" mass="0.582838" diaginertia="0.00198036 0.000287433 0.000456097"/>
          <joint name="left_shoulder_abad" class="/" pos="0 0 0" axis="-0.999826 0.0181017 0.0044276" range="-2.85106 2.9158" armature="0.0168165" damping="0" frictionloss="0.0602533"/>
          <geom name="//unnamed_geom_29" class="/" type="mesh" density="0" rgba="0.752941 0.752941 0.752941 1" mesh="left_shoulder2"/>
          <body name="left_upper_arm" pos="-0.00609173 0.00475559 -0.061586" quat="0.999993 0.00159138 -0.000659113 0.00322367">
            <inertial pos="0.0157802 0.000268763 -0.0523382" quat="0.709712 -0.0179929 0.0204543 0.703965" mass="0.465687" diaginertia="0.00219007 0.000308301 0.000221028"/>
            <joint name="left_shoulder_yaw" class="/" pos="0 0 0" axis="-0.0653318 -0.00552793 0.997848" stiffness="0.0189404" range="-2.75252 3.24519" armature="0.00360715" damping="0.0309256" frictionloss="0.0602052"/>
            <geom name="//unnamed_geom_30" class="/" type="mesh" density="0" rgba="0.752941 0.752941 0.752941 1" mesh="left_shoulder3"/>
            <geom name="//unnamed_geom_31" class="reward_collision_sphere" size="0.0520161" pos="-0.0106106 -0.00749233 -0.0395254"/>
            <body name="left_lower_arm" pos="0.017851 -0.000895514 -0.136133" quat="0.99996 0.000307845 0.00162728 -0.0087675">
              <inertial pos="-0.0135853 -0.0167046 -0.0654991" quat="0.704073 0.0100634 0.0278898 0.709508" mass="0.24007" diaginertia="0.00326454 0.000805728 2.35564e-05"/>
              <joint name="left_elbow" class="/" pos="0 0 0" axis="-0.0493001 0.997037 0.0590523" range="-2.75612 3.10289" armature="0.0122329" damping="0.0838256" frictionloss="0.0938313"/>
              <geom name="//unnamed_geom_32" class="/" type="mesh" density="0" rgba="0.752941 0.752941 0.752941 1" mesh="left_forearm"/>
              <geom name="//unnamed_geom_33" class="/" size="0.0216734 0.00650201" pos="0 0 -0.213437" quat="0.707109 0.707105 0 0" type="cylinder" group="3"/>
              <geom name="//unnamed_geom_34" class="reward_collision_sphere" size="0.0216734"/>
              <geom name="//unnamed_geom_35" class="reward_collision_sphere" size="0.0190726" pos="0 0 -0.221342"/>
            </body>
          </body>
        </body>
      </body>
      <body name="right_shoulder" pos="0.0248964 -0.120184 0.244006" quat="0.99998 0.00341346 0.00527413 0.000966268">
        <inertial pos="0.026252 -0.0373903 0.0106125" quat="0.729553 0.679463 -0.0680062 0.0381743" mass="0.536026" diaginertia="0.00255652 0.000239225 0.000271626"/>
        <joint name="right_shoulder_pitch" class="/" pos="0 0 0" axis="0.0243755 -0.999592 0.0149119" stiffness="0.0693352" range="-2.76313 3.24061" armature="0.0125646" damping="0.0819539" frictionloss="0.00236506"/>
        <geom name="//unnamed_geom_36" class="/" type="mesh" density="0" rgba="0.2 0.2 0.2 1" mesh="left_shoulder11"/>
        <body name="right_shoulder_2" pos="0.00990771 -0.0546228 -0.00856769" quat="0.999999 -0.0011805 -0.000565129 0.000793073">
          <inertial pos="-0.0107602 0.0101467 -0.0754302" quat="-0.0138961 0.708964 0.0511469 0.703251" mass="0.604021" diaginertia="0.00164076 0.0002218 0.00041538"/>
          <joint name="right_shoulder_abad" class="/" pos="0 0 0" axis="-0.997345 0.0721581 0.00980857" stiffness="0.0727076" range="-3.21381 2.63749" armature="0.0109936" damping="0.0923601" frictionloss="0.0389587"/>
          <geom name="//unnamed_geom_37" class="/" type="mesh" density="0" rgba="0.752941 0.752941 0.752941 1" mesh="left_shoulder21"/>
          <body name="right_upper_arm" pos="-0.0137518 -0.0176972 -0.0826074" quat="0.999988 -0.00191111 -0.00121937 -0.00426158">
            <inertial pos="0.00908513 -0.0071805 -0.0545801" quat="0.707245 -0.101487 0.053958 0.697562" mass="0.584304" diaginertia="0.00321595 0.000299524 0.000319667"/>
            <joint name="right_shoulder_yaw" class="/" pos="0 0 0" axis="0.00907262 0.00369241 0.999952" range="-2.66335 2.912" armature="0.00878081" damping="0.0731532" frictionloss="0.0974497"/>
            <geom name="//unnamed_geom_38" class="/" type="mesh" density="0" rgba="0.752941 0.752941 0.752941 1" mesh="left_shoulder31"/>
            <geom name="//unnamed_geom_39" class="reward_collision_sphere" size="0.0520161" pos="-0.0106106 0.00749233 -0.0395254"/>
            <body name="right_lower_arm" pos="0.010927 -0.00502369 -0.106379" quat="0.999983 -0.00158521 -5.27086e-05 0.0055994">
              <inertial pos="-0.0179875 -0.0184377 -0.0890389" quat="0.707668 0.009704 0.00429629 0.706466" mass="0.167303" diaginertia="0.00339803 0.000545419 2.16451e-05"/>
              <joint name="right_elbow" class="/" pos="0 0 0" axis="-0.0620632 -0.995836 0.0667731" stiffness="0.0832838" range="-3.3387 3.29594" armature="0.00709213" damping="0" frictionloss="0.153515"/>
              <geom name="//unnamed_geom_40" class="/" type="mesh" density="0" rgba="0.752941 0.752941 0.752941 1" mesh="left_forearm"/>
              <geom name="//unnamed_geom_41" class="/" size="0.0216734 0.00650201" pos="0 0 -0.213437" quat="0.707109 0.707105 0 0" type="cylinder" group="3"/>
              <geom name="//unnamed_geom_42" class="reward_collision_sphere" size="0.0216734"/>
              <geom name="//unnamed_geom_43" class="reward_collision_sphere" size="0.0190726" pos="0 0 -0.221342"/>
            </body>
          </body>
        </body>
      </body>
    </body>
  </worldbody>

  <contact>
    <pair class="/" geom1="floor" geom2="left_foot" name="//unnamed_contact_0"/>
    <pair class="/" geom1="floor" geom2="right_foot" name="//unnamed_contact_1"/>
  </contact>

  <actuator>
    <general name="left_hip_yaw" class="/" joint="left_hip_yaw" forcerange="-47.4747 47.4747" gainprm="28.0919" biasprm="0 -28.0919 -0.447163"/>
    <general name="left_hip_abad" class="/" joint="left_hip_abad" forcerange="-43.7887 43.7887" gainprm="28.0919" biasprm="0 -28.0919 -0.447163"/>
    <general name="left_hip_pitch" class="/" joint="left_hip_pitch" forcerange="-20.8303 20.8303" gainprm="28.0919" biasprm="0 -28.0919 -0.447163"/>
    <general name="left_knee" class="/" joint="left_knee" forcerange="-178.389 178.389" gainprm="28.0919" biasprm="0 -28.0919 -0.447163"/>
    <general name="left_ankle" class="/" joint="left_ankle" forcerange="-30.8709 30.8709" gainprm="28.0919" biasprm="0 -28.0919 -0.447163"/>
    <general name="right_hip_yaw" class="/" joint="right_hip_yaw" forcerange="-9.59189 9.59189" gainprm="28.0919" biasprm="0 -28.0919 -0.447163"/>
    <general name="right_hip_abad" class="/" joint="right_hip_abad" forcerange="-24.8601 24.8601" gainprm="28.0919" biasprm="0 -28.0919 -0.447163"/>
    <general name="right_hip_pitch" class="/" joint="right_hip_pitch" forcerange="-81.6651 81.6651" gainprm="28.0919" biasprm="0 -28.0919 -0.447163"/>
    <general name="right_knee" class="/" joint="right_knee" forcerange="-81.5846 81.5846" gainprm="28.0919" biasprm="0 -28.0919 -0.447163"/>
    <general name="right_ankle" class="/" joint="right_ankle" forcerange="-52.9253 52.9253" gainprm="28.0919" biasprm="0 -28.0919 -0.447163"/>
    <general name="left_shoulder_pitch" class="/" joint="left_shoulder_pitch" forcerange="-44.475 44.475" gainprm="28.0919" biasprm="0 -28.0919 -0.447163"/>
    <general name="left_shoulder_abad" class="/" joint="left_shoulder_abad" forcerange="-12.7391 12.7391" gainprm="28.0919" biasprm="0 -28.0919 -0.447163"/>
    <general name="left_shoulder_yaw" class="/" joint="left_shoulder_yaw" forcerange="-35.6854 35.6854" gainprm="28.0919" biasprm="0 -28.0919 -0.447163"/>
    <general name="left_elbow" class="/" joint="left_elbow" forcerange="-34.4508 34.4508" gainprm="28.0919" biasprm="0 -28.0919 -0.447163"/>
    <general name="right_shoulder_pitch" class="/" joint="right_shoulder_pitch" forcerange="-10.0887 10.0887" gainprm="28.0919" biasprm="0 -28.0919 -0.447163"/>
    <general name="right_shoulder_abad" class="/" joint="right_shoulder_abad" forcerange="-41.1288 41.1288" gainprm="28.0919" biasprm="0 -28.0919 -0.447163"/>
    <general name="right_shoulder_yaw" class="/" joint="right_shoulder_yaw" forcerange="-37.1851 37.1851" gainprm="28.0919" biasprm="0 -28.0919 -0.447163"/>
    <general name="right_elbow" class="/" joint="right_elbow" forcerange="-44.9016 44.9016" gainprm="28.0919" biasprm="0 -28.0919 -0.447163"/>
  </actuator>

  <sensor>
    <gyro site="imu" name="imu_angular_velocity"/>
    <velocimeter site="imu" name="imu_linear_velocity"/>
    <framelinvel objtype="site" objname="left_foot" name="left_foot_global_linear_velocity"/>
    <framelinvel objtype="site" objname="right_foot" name="right_foot_global_linear_velocity"/>
  </sensor>

  <keyframe>
    <key name="home" qpos="0 0 0.656 1 0 0 0 0 0 -0.4 0.8 -0.4 0 0 0.4 -0.8 0.4 0 -0.05 0 -0.75 0 0.05 0 0.75"/>
  </keyframe>
</mujoco>
