<mujoco model="humanoid">
  <compiler angle="radian" assetdir="assets" balanceinertia="true" inertiafromgeom="false"/>

  <option timestep="0.005" density="1.2" viscosity="2e-05"/>

  <size nkey="1"/>

  <visual>
    <quality shadowsize="8192"/>
    <map shadowclip="0.5"/>
  </visual>

  <default>
    <default class="/">
      <joint armature="0.01" damping="0.01" frictionloss="0.1"/>
      <geom contype="0" conaffinity="0" group="1" solref="-1000 -80"/>
      <site size="0.01 0.005 0.005" group="5"/>
      <general forcelimited="true" biastype="affine" gainprm="30" biasprm="0 -30 -0.5"/>
      <default class="foot">
        <geom size="0.099 0.0178 0.021" type="box" condim="6" group="4" priority="1" solimp="0.015 1 0.021"/>
      </default>
      <default class="reward_collision_sphere">
        <geom group="5" rgba="1 0 0 1"/>
      </default>
    </default>
  </default>

  <asset>
    <texture type="skybox" colorspace="auto" name="//unnamed_texture_0" builtin="gradient" rgb1="0.95 0.95 0.95" rgb2="0.95 0.95 0.95" width="100" height="600"/>
    <texture type="2d" colorspace="auto" name="texplane" builtin="checker" rgb1="0.345 0.575 0.748" rgb2="0.345 0.575 0.748" markrgb="1 1 1" width="512" height="512"/>
    <material name="MatPlane" class="/" texture="texplane" texuniform="true" texrepeat="2 2" specular="0.9"/>
    <mesh name="torso" class="/" file="torso.stl" scale="0.001 0.001 0.001"/>
    <mesh name="left_hip_yaw" class="/" file="left_hip_yaw.stl" scale="0.001 0.001 0.001"/>
    <mesh name="left_hip_abad" class="/" file="left_hip_abad.stl" scale="0.001 0.001 0.001"/>
    <mesh name="left_leg_upper" class="/" file="left_leg_upper.stl" scale="0.001 0.001 0.001"/>
    <mesh name="left_leg_lower" class="/" file="left_leg_lower.stl" scale="0.001 0.001 0.001"/>
    <mesh name="left_foot" class="/" file="left_foot.stl" scale="0.001 0.001 0.001"/>
    <mesh name="left_hip_yaw1" class="/" content_type="model/stl" file="left_hip_yaw.stl" scale="0.001 -0.001 0.001"/>
    <mesh name="left_hip_abad1" class="/" content_type="model/stl" file="left_hip_abad.stl" scale="0.001 -0.001 0.001"/>
    <mesh name="left_leg_upper1" class="/" content_type="model/stl" file="left_leg_upper.stl" scale="0.001 -0.001 0.001"/>
    <mesh name="left_leg_lower1" class="/" content_type="model/stl" file="left_leg_lower.stl" scale="0.001 -0.001 0.001"/>
    <mesh name="left_foot1" class="/" content_type="model/stl" file="left_foot.stl" scale="0.001 -0.001 0.001"/>
    <mesh name="left_shoulder1" class="/" file="left_shoulder1.stl" scale="0.001 0.001 0.001"/>
    <mesh name="left_shoulder2" class="/" file="left_shoulder2.stl" scale="0.001 0.001 0.001"/>
    <mesh name="left_shoulder3" class="/" file="left_shoulder3.stl" scale="0.001 0.001 0.001"/>
    <mesh name="left_forearm" class="/" file="left_forearm.stl" scale="0.001 0.001 0.001"/>
    <mesh name="left_shoulder11" class="/" content_type="model/stl" file="left_shoulder1.stl" scale="0.001 -0.001 0.001"/>
    <mesh name="left_shoulder21" class="/" content_type="model/stl" file="left_shoulder2.stl" scale="0.001 -0.001 0.001"/>
    <mesh name="left_shoulder31" class="/" content_type="model/stl" file="left_shoulder3.stl" scale="0.001 -0.001 0.001"/>
  </asset>

  <worldbody>
    <geom name="floor" class="/" size="100 100 0.125" type="plane" group="0" material="MatPlane"/>
    <light name="toplight_shadow" class="/" pos="0 0 5" dir="0.0990148 0.0990148 -0.990148" type="directional" ambient="0.04 0.04 0.04" diffuse="0.55 0.55 0.55" specular="0.12 0.12 0.12"/>
    <light name="toplight_fill" class="/" pos="0 0 5" dir="0.0990148 0.0990148 -0.990148" type="directional" castshadow="false" ambient="0.04 0.04 0.04" diffuse="0.3 0.3 0.3" specular="0.08 0.08 0.08"/>
    <body name="trunk" pos="-0.00152695 0.000165262 0.000980906" quat="1 0.000202377 -5.83603e-05 0.000167121">
      <inertial pos="0.0105433 0.000184633 0.14019" quat="0.999981 0.00472424 -0.00289722 0.00268105" mass="7.51521" diaginertia="0.141564 0.129697 0.0660796"/>
      <joint name="//unnamed_joint_0" type="free"/>
      <geom name="//unnamed_geom_1" class="/" type="mesh" density="0" rgba="0.752941 0.752941 0.752941 1" mesh="torso"/>
      <geom name="//unnamed_geom_2" class="/" size="0.0737405 0.147481 0.172061" pos="0.0222352 0 0.0749356" type="box" group="3" rgba="0.752941 0.752941 0.752941 1"/>
      <geom name="//unnamed_geom_3" class="reward_collision_sphere" size="0.142565" pos="0 0 0.140504"/>
      <site name="imu" class="/" pos="0.00131449 0.00509322 0.14091" size="0.00983207"/>
      <camera name="track" class="/" pos="0 -2.09236 0" quat="0.707107 0.707107 0 0" mode="trackcom"/>
      <camera name="ego_camera" class="/" pos="0.0435036 0 0.281008" quat="-0.5 -0.5 0.5 0.5"/>
      <body name="left_hip_yaw" pos="-0.000394162 0.0856107 0.000283772" quat="0.996197 2.24994e-05 -0.087124 -2.01953e-05">
        <inertial pos="-0.0631491 -0.000841003 -0.0601062" quat="0.950136 -0.00225293 -0.311814 0.00286104" mass="0.780656" diaginertia="0.00156502 0.00164339 0.000556667"/>
        <joint name="left_hip_yaw" class="/" pos="0 0 0" axis="-0.00130591 -0.00113165 -0.999999" stiffness="0.000579416" range="-2.99491 3.01383" armature="0.00977651" damping="0.00918795" frictionloss="0.0966353"/>
        <geom name="//unnamed_geom_4" class="/" type="mesh" density="0" rgba="0.2 0.2 0.2 1" mesh="left_hip_yaw"/>
        <body name="left_hip_abad" pos="-0.0629608 -0.000655651 -0.069287" quat="0.976294 -1.83311e-05 0.216447 -7.28483e-06">
          <inertial pos="0.0657769 -0.0125939 -0.000466862" quat="0.577647 0.405651 0.412185 0.576085" mass="1.14874" diaginertia="0.00276977 0.0024989 0.00123496"/>
          <joint name="left_hip_abad" class="/" pos="0 0 0" axis="-0.999999 -0.000860492 0.000668674" range="-2.99929 2.97938" armature="0.0106108" damping="0.0111465" frictionloss="0.0956242"/>
          <geom name="//unnamed_geom_5" class="/" type="mesh" density="0" rgba="0.2 0.2 0.2 1" mesh="left_hip_abad"/>
          <body name="left_upper_leg" pos="0.0851187 -0.00253647 -0.0125894" quat="0.991431 -1.97061e-05 -0.130632 -0.000143947">
            <inertial pos="-0.000697722 0.0270715 -0.0732387" quat="0.729342 0.0335199 -0.0472251 0.681694" mass="2.4975" diaginertia="0.0227905 0.0306086 0.00253002"/>
            <joint name="left_hip_pitch" class="/" pos="0 0 0" axis="-0.00057808 0.999997 0.00250117" stiffness="0.000666886" range="-3.02192 2.97918" armature="0.00908223" damping="0.0184845" frictionloss="0.093451"/>
            <geom name="//unnamed_geom_6" class="/" type="mesh" density="0" rgba="0.752941 0.752941 0.752941 1" mesh="left_leg_upper"/>
            <geom name="//unnamed_geom_7" class="reward_collision_sphere" size="0.0688245" pos="-0.0145012 0.0156927 0.0140504"/>
            <geom name="//unnamed_geom_8" class="reward_collision_sphere" size="0.0196641" pos="-0.0773398 -0.0313854 0.0749356"/>
            <body name="left_lower_leg" pos="-0.0130921 -1.19842e-05 -0.234954" quat="1 -4.79939e-05 -5.53826e-06 2.6434e-06">
              <inertial pos="0.00527741 -0.00142541 -0.12386" quat="0.998994 0.00184389 -0.016674 0.0415847" mass="0.333909" diaginertia="0.00244414 0.00370424 0.000168254"/>
              <joint name="left_knee" class="/" pos="0 0 0" axis="0.00942549 0.999955 -0.000921388" stiffness="0.00119281" range="-0.000738294 3.00009" armature="0.0100241" damping="0.0160559" frictionloss="0.107821"/>
              <geom name="//unnamed_geom_9" class="/" type="mesh" density="0" rgba="0.752941 0.752941 0.752941 1" mesh="left_leg_lower"/>
              <geom name="//unnamed_geom_10" class="reward_collision_sphere" size="0.0422779"/>
              <body name="left_foot" pos="-5.24331e-05 0.000970076 -0.26085" quat="1 0.000157494 -5.54386e-05 -0.00047197">
                <inertial pos="0.0203884 0.000739381 -0.0128037" quat="0.521063 0.478141 0.478989 0.520042" mass="0.264158" diaginertia="0.0227564 0.034148 0.0192183"/>
                <joint name="left_ankle" class="/" pos="0 0 0" axis="-0.00308765 0.999946 0.00992853" stiffness="0.00060208" range="-1.51739 1.50113" armature="0.0106978" damping="0.00758291" frictionloss="0.0913932"/>
                <geom name="//unnamed_geom_11" class="/" type="mesh" density="0" rgba="0.2 0.2 0.2 1" mesh="left_foot"/>
                <geom name="left_foot" class="foot" size="0.0969824 0.0163702 0.0199832" pos="0.0270689 0 -0.0234174" quat="0.707109 0.707105 0 0"/>
                <geom name="//unnamed_geom_13" class="reward_collision_sphere" size="0.0245802" pos="0.0270689 0 -0.0187339"/>
                <geom name="//unnamed_geom_14" class="reward_collision_sphere" size="0.0245802" pos="0.0966747 0 -0.0234174"/>
                <geom name="//unnamed_geom_15" class="reward_collision_sphere" size="0.0245802" pos="-0.0435036 0 -0.0234174"/>
                <site name="left_foot" class="foot" pos="0.0270689 0 -0.0234174" quat="0.707109 0.707105 0 0" size="0.00983207"/>
              </body>
            </body>
          </body>
        </body>
      </body>
      <body name="right_hip_yaw" pos="0.000332124 -0.0860797 1.437e-05" quat="0.996231 -0.000378991 -0.0867414 0.000190178">
        <inertial pos="-0.063375 -0.00215348 -0.0601814" quat="0.950344 -0.00436817 0.311054 -0.00855541" mass="0.807649" diaginertia="0.00160695 0.00171245 0.000565273"/>
        <joint name="right_hip_yaw" class="/" pos="0 0 0" axis="3.34761e-05 -1.94361e-05 -1" stiffness="0.00100427" range="-3.00388 2.97972" armature="0.00950688" damping="0.00954096" frictionloss="0.0915109"/>
        <geom name="//unnamed_geom_16" class="/" type="mesh" density="0" rgba="0.2 0.2 0.2 1" mesh="left_hip_yaw1"/>
        <body name="right_hip_abad" pos="-0.0620505 0.000677659 -0.0702819" quat="0.976284 7.82112e-05 0.216492 -3.05477e-05">
          <inertial pos="0.064777 0.0140058 0.000314865" quat="0.411435 0.574058 0.578449 0.408136" mass="1.16707" diaginertia="0.00286598 0.00252121 0.00125527"/>
          <joint name="right_hip_abad" class="/" pos="0 0 0" axis="-0.999999 0.000206087 -0.00107059" range="-3.04155 2.99968" armature="0.0101323" damping="0.010194" frictionloss="0.0985041"/>
          <geom name="//unnamed_geom_17" class="/" type="mesh" density="0" rgba="0.2 0.2 0.2 1" mesh="left_hip_abad1"/>
          <body name="right_upper_leg" pos="0.0855372 0.00160166 -0.0150208" quat="0.991441 -0.000145887 -0.130557 -1.08608e-06">
            <inertial pos="-0.00182973 -0.0276607 -0.0748556" quat="0.68091 0.0486379 -0.034629 0.729929" mass="2.51322" diaginertia="0.0223625 0.0303543 0.00251279"/>
            <joint name="right_hip_pitch" class="/" pos="0 0 0" axis="0.00324091 -0.999977 -0.00590904" range="-3 2.99006" armature="0.00878714" damping="0.0167382" frictionloss="0.0984538"/>
            <geom name="//unnamed_geom_18" class="/" type="mesh" density="0" rgba="0.752941 0.752941 0.752941 1" mesh="left_leg_upper1"/>
            <geom name="//unnamed_geom_19" class="reward_collision_sphere" size="0.0688245" pos="-0.0145012 -0.0156927 0.0140504"/>
            <geom name="//unnamed_geom_20" class="reward_collision_sphere" size="0.0196641" pos="-0.0773398 0.0313854 0.0749356"/>
            <body name="right_lower_leg" pos="-0.0108842 -0.000679847 -0.233802" quat="1 -9.24079e-05 -3.0698e-05 -8.48254e-05">
              <inertial pos="0.00609526 0.000246186 -0.1215" quat="0.998849 0.00330777 0.0191115 -0.0438592" mass="0.33872" diaginertia="0.00249416 0.00373686 0.000176238"/>
              <joint name="right_knee" class="/" pos="0 0 0" axis="0.000711342 -1 -0.000328354" range="-2.98372 -0.0167973" armature="0.0103068" damping="0.0103438" frictionloss="0.102313"/>
              <geom name="//unnamed_geom_21" class="/" type="mesh" density="0" rgba="0.752941 0.752941 0.752941 1" mesh="left_leg_lower1"/>
              <geom name="//unnamed_geom_22" class="reward_collision_sphere" size="0.0422779"/>
              <body name="right_foot" pos="-0.000125872 -0.000299441 -0.261107" quat="1 9.34071e-05 0.000159954 -8.03493e-06">
                <inertial pos="0.0213664 -8.27507e-05 -0.0116869" quat="0.482502 0.517739 0.519764 0.478522" mass="0.258387" diaginertia="0.0221479 0.0327776 0.018854"/>
                <joint name="right_ankle" class="/" pos="0 0 0" axis="0.000382365 -0.999999 -0.00126224" stiffness="0.00345878" range="-1.54263 1.49694" armature="0.00987104" damping="0.0155039" frictionloss="0.0971119"/>
                <geom name="//unnamed_geom_23" class="/" type="mesh" density="0" rgba="0.2 0.2 0.2 1" mesh="left_foot1"/>
                <geom name="right_foot" class="foot" size="0.107773 0.0166353 0.0211128" pos="0.0270689 0 -0.0234174" quat="0.707109 0.707105 0 0"/>
                <geom name="//unnamed_geom_25" class="reward_collision_sphere" size="0.0245802" pos="0.0270689 0 -0.0187339"/>
                <geom name="//unnamed_geom_26" class="reward_collision_sphere" size="0.0245802" pos="0.0966747 0 -0.0234174"/>
                <geom name="//unnamed_geom_27" class="reward_collision_sphere" size="0.0245802" pos="-0.0435036 0 -0.0234174"/>
                <site name="right_foot" class="foot" pos="0.0270689 0 -0.0234174" quat="0.707109 0.707105 0 0" size="0.00983207"/>
              </body>
            </body>
          </body>
        </body>
      </body>
      <body name="left_shoulder" pos="0.0181471 0.183911 0.286163" quat="1 4.65138e-05 -0.000102735 3.32084e-05">
        <inertial pos="0.00940067 0.053753 0.0008587" quat="0.711178 0.702744 0.0152676 0.0119875" mass="0.746962" diaginertia="0.00115392 0.00109167 0.000544128"/>
        <joint name="left_shoulder_pitch" class="/" pos="0 0 0" axis="0.00290172 0.999995 -0.00131847" stiffness="0.00500655" range="-2.98121 3.00643" armature="0.0102581" damping="0.0102705" frictionloss="0.0991656"/>
        <geom name="//unnamed_geom_28" class="/" type="mesh" density="0" rgba="0.2 0.2 0.2 1" mesh="left_shoulder1"/>
        <body name="left_shoulder_2" pos="0.000730804 0.0601069 0.000881634" quat="1 0.000374036 1.31364e-06 0.000332308">
          <inertial pos="0.000136468 -0.000678851 -0.0765881" quat="0.0117023 0.757652 0.00418782 0.652541" mass="0.768875" diaginertia="0.00106113 0.00149071 0.000836734"/>
          <joint name="left_shoulder_abad" class="/" pos="0 0 0" axis="-1 3.86355e-05 0.000153593" stiffness="0.00376791" range="-3.001 2.99429" armature="0.00910452" damping="0.010935" frictionloss="0.100931"/>
          <geom name="//unnamed_geom_29" class="/" type="mesh" density="0" rgba="0.752941 0.752941 0.752941 1" mesh="left_shoulder2"/>
          <body name="left_upper_arm" pos="0.000390685 0.000392965 -0.0981731" quat="1 0.000154077 -2.49045e-06 -4.21401e-05">
            <inertial pos="-0.00113584 -0.0165985 -0.0590703" quat="0.708505 -0.0221403 0.0205831 0.705058" mass="0.879974" diaginertia="0.00156745 0.00168525 0.000585766"/>
            <joint name="left_shoulder_yaw" class="/" pos="0 0 0" axis="-0.000334568 0.000116293 1" stiffness="0.000753407" range="-2.98725 3.01387" armature="0.00970455" damping="0.00510863" frictionloss="0.100936"/>
            <geom name="//unnamed_geom_30" class="/" type="mesh" density="0" rgba="0.752941 0.752941 0.752941 1" mesh="left_shoulder3"/>
            <geom name="//unnamed_geom_31" class="reward_collision_sphere" size="0.0589924" pos="-0.00966747 -0.0104618 -0.0468347"/>
            <body name="left_lower_arm" pos="-0.00191614 5.95363e-06 -0.148445" quat="1 -0.000814856 0.000108031 9.77708e-05">
              <inertial pos="-0.00627903 0.00118808 -0.0940843" quat="0.707241 0.00371892 0.00472307 0.706947" mass="0.320455" diaginertia="0.00310618 0.00449411 5.5722e-05"/>
              <joint name="left_elbow" class="/" pos="0 0 0" axis="-0.0029894 0.999993 0.00202542" range="-2.98611 2.99419" armature="0.0101111" damping="0.00656244" frictionloss="0.0988696"/>
              <geom name="//unnamed_geom_32" class="/" type="mesh" density="0" rgba="0.752941 0.752941 0.752941 1" mesh="left_forearm"/>
              <geom name="//unnamed_geom_33" class="/" size="0.0245802 0.00737405" pos="0 0 -0.252908" quat="0.707109 0.707105 0 0" type="cylinder" group="3"/>
              <geom name="//unnamed_geom_34" class="reward_collision_sphere" size="0.0245802"/>
              <geom name="//unnamed_geom_35" class="reward_collision_sphere" size="0.0216306" pos="0 0 -0.262274"/>
            </body>
          </body>
        </body>
      </body>
      <body name="right_shoulder" pos="0.0185789 -0.183001 0.284259" quat="1 0.000254081 6.25623e-05 0.000368289">
        <inertial pos="0.0079868 -0.055911 0.000817469" quat="0.710136 0.70378 -0.0123578 -0.0157392" mass="0.743177" diaginertia="0.00114624 0.00108464 0.00054608"/>
        <joint name="right_shoulder_pitch" class="/" pos="0 0 0" axis="0.00118432 -0.999999 0.00101387" range="-2.98397 3.01451" armature="0.00964672" damping="0.00315606" frictionloss="0.108634"/>
        <geom name="//unnamed_geom_36" class="/" type="mesh" density="0" rgba="0.2 0.2 0.2 1" mesh="left_shoulder11"/>
        <body name="right_shoulder_2" pos="0.000369797 -0.0605386 -0.000739819" quat="1 3.61152e-05 -1.64334e-05 9.33683e-05">
          <inertial pos="-0.00122256 0.000763191 -0.0785007" quat="0.00178961 0.65802 0.00998752 0.752932" mass="0.75554" diaginertia="0.00105112 0.00147411 0.000800981"/>
          <joint name="right_shoulder_abad" class="/" pos="0 0 0" axis="-0.999998 -0.00149213 -0.00133745" range="-3.01932 3.03416" armature="0.0100124" damping="0.000973988" frictionloss="0.0934726"/>
          <geom name="//unnamed_geom_37" class="/" type="mesh" density="0" rgba="0.752941 0.752941 0.752941 1" mesh="left_shoulder21"/>
          <body name="right_upper_arm" pos="-0.000458605 0.00222408 -0.0961618" quat="1 -0.000303199 -0.00015324 0.000193878">
            <inertial pos="0.000561417 0.0193043 -0.0592665" quat="0.708874 -0.0260512 0.0203153 0.704561" mass="0.862565" diaginertia="0.00148053 0.0016712 0.000556385"/>
            <joint name="right_shoulder_yaw" class="/" pos="0 0 0" axis="0.00011152 -5.22303e-05 1" stiffness="0.00349642" range="-3.02548 2.9973" armature="0.00983461" damping="0.00556525" frictionloss="0.0972327"/>
            <geom name="//unnamed_geom_38" class="/" type="mesh" density="0" rgba="0.752941 0.752941 0.752941 1" mesh="left_shoulder31"/>
            <geom name="//unnamed_geom_39" class="reward_collision_sphere" size="0.0589924" pos="-0.00966747 0.0104618 -0.0468347"/>
            <body name="right_lower_arm" pos="0.000652536 0.000634663 -0.14928" quat="1 -0.000108883 -0.000423186 2.3337e-06">
              <inertial pos="-0.00791416 0.00200847 -0.0949575" quat="0.707271 0.00446514 0.00499568 0.706911" mass="0.33428" diaginertia="0.00306498 0.00459974 5.67626e-05"/>
              <joint name="right_elbow" class="/" pos="0 0 0" axis="0.00973534 -0.999929 0.00687962" range="-2.97388 2.99308" armature="0.00990579" damping="0.00738787" frictionloss="0.0951206"/>
              <geom name="//unnamed_geom_40" class="/" type="mesh" density="0" rgba="0.752941 0.752941 0.752941 1" mesh="left_forearm"/>
              <geom name="//unnamed_geom_41" class="/" size="0.0245802 0.00737405" pos="0 0 -0.252908" quat="0.707109 0.707105 0 0" type="cylinder" group="3"/>
              <geom name="//unnamed_geom_42" class="reward_collision_sphere" size="0.0245802"/>
              <geom name="//unnamed_geom_43" class="reward_collision_sphere" size="0.0216306" pos="0 0 -0.262274"/>
            </body>
          </body>
        </body>
      </body>
    </body>
  </worldbody>

  <contact>
    <pair class="/" geom1="floor" geom2="left_foot" name="//unnamed_contact_0"/>
    <pair class="/" geom1="floor" geom2="right_foot" name="//unnamed_contact_1"/>
  </contact>

  <actuator>
    <general name="left_hip_yaw" class="/" joint="left_hip_yaw" forcerange="-32.1024 32.1024" gainprm="29.4951" biasprm="0 -29.4951 -0.489636"/>
    <general name="left_hip_abad" class="/" joint="left_hip_abad" forcerange="-34.252 34.252" gainprm="29.4951" biasprm="0 -29.4951 -0.489636"/>
    <general name="left_hip_pitch" class="/" joint="left_hip_pitch" forcerange="-74.8514 74.8514" gainprm="29.4951" biasprm="0 -29.4951 -0.489636"/>
    <general name="left_knee" class="/" joint="left_knee" forcerange="-145.367 145.367" gainprm="29.4951" biasprm="0 -29.4951 -0.489636"/>
    <general name="left_ankle" class="/" joint="left_ankle" forcerange="-65.0785 65.0785" gainprm="29.4951" biasprm="0 -29.4951 -0.489636"/>
    <general name="right_hip_yaw" class="/" joint="right_hip_yaw" forcerange="-35.5221 35.5221" gainprm="29.4951" biasprm="0 -29.4951 -0.489636"/>
    <general name="right_hip_abad" class="/" joint="right_hip_abad" forcerange="-33.3197 33.3197" gainprm="29.4951" biasprm="0 -29.4951 -0.489636"/>
    <general name="right_hip_pitch" class="/" joint="right_hip_pitch" forcerange="-71.2437 71.2437" gainprm="29.4951" biasprm="0 -29.4951 -0.489636"/>
    <general name="right_knee" class="/" joint="right_knee" forcerange="-136.614 136.614" gainprm="29.4951" biasprm="0 -29.4951 -0.489636"/>
    <general name="right_ankle" class="/" joint="right_ankle" forcerange="-67.2499 67.2499" gainprm="29.4951" biasprm="0 -29.4951 -0.489636"/>
    <general name="left_shoulder_pitch" class="/" joint="left_shoulder_pitch" forcerange="-33.7238 33.7238" gainprm="29.4951" biasprm="0 -29.4951 -0.489636"/>
    <general name="left_shoulder_abad" class="/" joint="left_shoulder_abad" forcerange="-34.0564 34.0564" gainprm="29.4951" biasprm="0 -29.4951 -0.489636"/>
    <general name="left_shoulder_yaw" class="/" joint="left_shoulder_yaw" forcerange="-32.8148 32.8148" gainprm="29.4951" biasprm="0 -29.4951 -0.489636"/>
    <general name="left_elbow" class="/" joint="left_elbow" forcerange="-54.2236 54.2236" gainprm="29.4951" biasprm="0 -29.4951 -0.489636"/>
    <general name="right_shoulder_pitch" class="/" joint="right_shoulder_pitch" forcerange="-35.36 35.36" gainprm="29.4951" biasprm="0 -29.4951 -0.489636"/>
    <general name="right_shoulder_abad" class="/" joint="right_shoulder_abad" forcerange="-34.6742 34.6742" gainprm="29.4951" biasprm="0 -29.4951 -0.489636"/>
    <general name="right_shoulder_yaw" class="/" joint="right_shoulder_yaw" forcerange="-33.0258 33.0258" gainprm="29.4951" biasprm="0 -29.4951 -0.489636"/>
    <general name="right_elbow" class="/" joint="right_elbow" forcerange="-53.7695 53.7695" gainprm="29.4951" biasprm="0 -29.4951 -0.489636"/>
  </actuator>

  <sensor>
    <gyro site="imu" name="imu_angular_velocity"/>
    <velocimeter site="imu" name="imu_linear_velocity"/>
    <framelinvel objtype="site" objname="left_foot" name="left_foot_global_linear_velocity"/>
    <framelinvel objtype="site" objname="right_foot" name="right_foot_global_linear_velocity"/>
  </sensor>

  <keyframe>
    <key name="home" qpos="0 0 0.656 1 0 0 0 0 0 -0.4 0.8 -0.4 0 0 0.4 -0.8 0.4 0 -0.05 0 -0.75 0 0.05 0 0.75"/>
  </keyframe>
</mujoco>
