<mujoco model="humanoid">
  <compiler angle="radian" assetdir="assets" balanceinertia="true" inertiafromgeom="false"/>

  <option timestep="0.005" density="1.2" viscosity="2e-05"/>

  <size nkey="1"/>

  <visual>
    <quality shadowsize="8192"/>
    <map shadowclip="0.5"/>
  </visual>

  <default>
    <default class="/">
      <joint armature="0.01" damping="0.01" frictionloss="0.1"/>
      <geom contype="0" conaffinity="0" group="1" solref="-1000 -80"/>
      <site size="0.01 0.005 0.005" group="5"/>
      <general forcelimited="true" biastype="affine" gainprm="30" biasprm="0 -30 -0.5"/>
      <default class="foot">
        <geom size="0.099 0.0178 0.021" type="box" condim="6" group="4" priority="1" solimp="0.015 1 0.021"/>
      </default>
      <default class="reward_collision_sphere">
        <geom group="5" rgba="1 0 0 1"/>
      </default>
    </default>
  </default>

  <asset>
    <texture type="skybox" colorspace="auto" name="//unnamed_texture_0" builtin="gradient" rgb1="0.95 0.95 0.95" rgb2="0.95 0.95 0.95" width="100" height="600"/>
    <texture type="2d" colorspace="auto" name="texplane" builtin="checker" rgb1="0.345 0.575 0.748" rgb2="0.345 0.575 0.748" markrgb="1 1 1" width="512" height="512"/>
    <material name="MatPlane" class="/" texture="texplane" texuniform="true" texrepeat="2 2" specular="0.9"/>
    <mesh name="torso" class="/" file="torso.stl" scale="0.001 0.001 0.001"/>
    <mesh name="left_hip_yaw" class="/" file="left_hip_yaw.stl" scale="0.001 0.001 0.001"/>
    <mesh name="left_hip_abad" class="/" file="left_hip_abad.stl" scale="0.001 0.001 0.001"/>
    <mesh name="left_leg_upper" class="/" file="left_leg_upper.stl" scale="0.001 0.001 0.001"/>
    <mesh name="left_leg_lower" class="/" file="left_leg_lower.stl" scale="0.001 0.001 0.001"/>
    <mesh name="left_foot" class="/" file="left_foot.stl" scale="0.001 0.001 0.001"/>
    <mesh name="left_hip_yaw1" class="/" content_type="model/stl" file="left_hip_yaw.stl" scale="0.001 -0.001 0.001"/>
    <mesh name="left_hip_abad1" class="/" content_type="model/stl" file="left_hip_abad.stl" scale="0.001 -0.001 0.001"/>
    <mesh name="left_leg_upper1" class="/" content_type="model/stl" file="left_leg_upper.stl" scale="0.001 -0.001 0.001"/>
    <mesh name="left_leg_lower1" class="/" content_type="model/stl" file="left_leg_lower.stl" scale="0.001 -0.001 0.001"/>
    <mesh name="left_foot1" class="/" content_type="model/stl" file="left_foot.stl" scale="0.001 -0.001 0.001"/>
    <mesh name="left_shoulder1" class="/" file="left_shoulder1.stl" scale="0.001 0.001 0.001"/>
    <mesh name="left_shoulder2" class="/" file="left_shoulder2.stl" scale="0.001 0.001 0.001"/>
    <mesh name="left_shoulder3" class="/" file="left_shoulder3.stl" scale="0.001 0.001 0.001"/>
    <mesh name="left_forearm" class="/" file="left_forearm.stl" scale="0.001 0.001 0.001"/>
    <mesh name="left_shoulder11" class="/" content_type="model/stl" file="left_shoulder1.stl" scale="0.001 -0.001 0.001"/>
    <mesh name="left_shoulder21" class="/" content_type="model/stl" file="left_shoulder2.stl" scale="0.001 -0.001 0.001"/>
    <mesh name="left_shoulder31" class="/" content_type="model/stl" file="left_shoulder3.stl" scale="0.001 -0.001 0.001"/>
  </asset>

  <worldbody>
    <geom name="floor" class="/" size="100 100 0.125" type="plane" group="0" material="MatPlane"/>
    <light name="toplight_shadow" class="/" pos="0 0 5" dir="0.0990148 0.0990148 -0.990148" type="directional" ambient="0.04 0.04 0.04" diffuse="0.55 0.55 0.55" specular="0.12 0.12 0.12"/>
    <light name="toplight_fill" class="/" pos="0 0 5" dir="0.0990148 0.0990148 -0.990148" type="directional" castshadow="false" ambient="0.04 0.04 0.04" diffuse="0.3 0.3 0.3" specular="0.08 0.08 0.08"/>
    <body name="trunk" pos="0.000273273 -0.000214203 -0.00273261" quat="1 -0.000135768 2.77546e-05 5.85578e-06">
      <inertial pos="0.00687068 0.003641 0.153026" quat="0.999999 0.000880875 -0.000527671 -0.000746883" mass="9.28501" diaginertia="0.134829 0.22039 0.091086"/>
      <joint name="//unnamed_joint_0" type="free"/>
      <geom name="//unnamed_geom_1" class="/" type="mesh" density="0" rgba="0.752941 0.752941 0.752941 1" mesh="torso"/>
      <geom name="//unnamed_geom_2" class="/" size="0.0783832 0.156766 0.182894" pos="0.0221 0 0.080321" type="box" group="3" rgba="0.752941 0.752941 0.752941 1"/>
      <geom name="//unnamed_geom_3" class="reward_collision_sphere" size="0.151541" pos="0 0 0.150602"/>
      <site name="imu" class="/" pos="-0.010729 0.00299721 0.140786" size="0.0104511"/>
      <camera name="track" class="/" pos="0 -2.34089 0" quat="0.707107 0.707107 0 0" mode="trackcom"/>
      <camera name="ego_camera" class="/" pos="0.0432391 0 0.301204" quat="-0.5 -0.5 0.5 0.5"/>
      <body name="left_hip_yaw" pos="0.00296046 0.0949335 0.00206253" quat="0.996229 -6.64457e-05 -0.0867622 -0.000143206">
        <inertial pos="-0.0636518 0.00225858 -0.0624643" quat="0.949289 -0.00561701 -0.31429 -0.00637309" mass="0.987152" diaginertia="0.00154153 0.00302357 0.000807815"/>
        <joint name="left_hip_yaw" class="/" pos="0 0 0" axis="-0.00154299 0.00169703 -0.999997" stiffness="0.0103298" range="-3.04151 2.94864" armature="0.0102086" damping="0.00337858" frictionloss="0.0966561"/>
        <geom name="//unnamed_geom_4" class="/" type="mesh" density="0" rgba="0.2 0.2 0.2 1" mesh="left_hip_yaw"/>
        <body name="left_hip_abad" pos="-0.0586491 0.00315535 -0.0739341" quat="0.976479 -8.55735e-05 0.215615 0.000258749">
          <inertial pos="0.0658996 -0.0179682 0.00238512" quat="0.579187 0.410978 0.406237 0.574988" mass="1.32707" diaginertia="0.00283862 0.00421344 0.00175861"/>
          <joint name="left_hip_abad" class="/" pos="0 0 0" axis="-0.999941 -0.0102981 -0.00359026" stiffness="0.0184281" range="-3.00967 3.05035" armature="0.0103192" damping="0.00898027" frictionloss="0.103043"/>
          <geom name="//unnamed_geom_5" class="/" type="mesh" density="0" rgba="0.2 0.2 0.2 1" mesh="left_hip_abad"/>
          <body name="left_upper_leg" pos="0.0834467 -0.00506 -0.0121555" quat="0.991428 0.000462122 -0.130657 2.9119e-05">
            <inertial pos="-0.00278282 0.0309243 -0.0778217" quat="0.727007 0.035309 -0.0507493 0.683841" mass="2.95135" diaginertia="0.0207297 0.051834 0.0033892"/>
            <joint name="left_hip_pitch" class="/" pos="0 0 0" axis="0.00914422 0.999886 -0.012051" stiffness="0.00352809" range="-2.94662 3.05409" armature="0.0106867" damping="0.00416419" frictionloss="0.118988"/>
            <geom name="//unnamed_geom_6" class="/" type="mesh" density="0" rgba="0.752941 0.752941 0.752941 1" mesh="left_leg_upper"/>
            <geom name="//unnamed_geom_7" class="reward_collision_sphere" size="0.0731577" pos="-0.014413 0.0175567 0.0150602"/>
            <geom name="//unnamed_geom_8" class="reward_collision_sphere" size="0.0209022" pos="-0.0768695 -0.0351134 0.080321"/>
            <body name="left_lower_leg" pos="-0.00970794 -0.000690536 -0.247195" quat="1 2.81944e-06 -9.25643e-05 4.87162e-05">
              <inertial pos="0.00582662 0.00172778 -0.129592" quat="0.998537 -0.00203756 -0.00769804 0.0534752" mass="0.405108" diaginertia="0.00249388 0.006706 0.000251141"/>
              <joint name="left_knee" class="/" pos="0 0 0" axis="0.000595901 0.999995 0.00323405" range="0.00327037 2.9929" armature="0.0107934" damping="0.00798149" frictionloss="0.0981351"/>
              <geom name="//unnamed_geom_9" class="/" type="mesh" density="0" rgba="0.752941 0.752941 0.752941 1" mesh="left_leg_lower"/>
              <geom name="//unnamed_geom_10" class="reward_collision_sphere" size="0.0449397"/>
              <body name="left_foot" pos="2.1856e-05 0.001302 -0.278728" quat="0.999999 -0.00053252 0.00123286 -0.000125975">
                <inertial pos="0.0227671 0.00126663 -0.0132421" quat="0.520869 0.480415 0.477796 0.519238" mass="0.307583" diaginertia="0.021143 0.0585902 0.02786"/>
                <joint name="left_ankle" class="/" pos="0 0 0" axis="0.0017863 0.999994 0.00290905" range="-1.51885 1.50432" armature="0.00995529" damping="0.00385202" frictionloss="0.105175"/>
                <geom name="//unnamed_geom_11" class="/" type="mesh" density="0" rgba="0.2 0.2 0.2 1" mesh="left_foot"/>
                <geom name="left_foot" class="foot" size="0.108131 0.019921 0.0237998" pos="0.0269043 0 -0.0251003" quat="0.707109 0.707105 0 0"/>
                <geom name="//unnamed_geom_13" class="reward_collision_sphere" size="0.0261277" pos="0.0269043 0 -0.0200802"/>
                <geom name="//unnamed_geom_14" class="reward_collision_sphere" size="0.0261277" pos="0.0960869 0 -0.0251003"/>
                <geom name="//unnamed_geom_15" class="reward_collision_sphere" size="0.0261277" pos="-0.0432391 0 -0.0251003"/>
                <site name="left_foot" class="foot" pos="0.0269043 0 -0.0251003" quat="0.707109 0.707105 0 0" size="0.0104511"/>
              </body>
            </body>
          </body>
        </body>
      </body>
      <body name="right_hip_yaw" pos="0.00055288 -0.0948539 0.00110504" quat="0.996213 0.000194491 -0.0869473 -1.10797e-05">
        <inertial pos="-0.0605238 0.0022102 -0.0643432" quat="0.950292 -0.00301236 0.311339 -0.00220268" mass="0.99848" diaginertia="0.00158665 0.00301176 0.000802511"/>
        <joint name="right_hip_yaw" class="/" pos="0 0 0" axis="0.000537765 0.000398427 -1" stiffness="0.00102002" range="-3.00133 3.05455" armature="0.00989473" damping="0.0129662" frictionloss="0.104476"/>
        <geom name="//unnamed_geom_16" class="/" type="mesh" density="0" rgba="0.2 0.2 0.2 1" mesh="left_hip_yaw1"/>
        <body name="right_hip_abad" pos="-0.0622874 -0.00012929 -0.0762135" quat="0.976395 -0.000456995 0.215992 0.000804373">
          <inertial pos="0.0634989 0.0132244 6.52976e-05" quat="0.403119 0.57715 0.582725 0.405986" mass="1.36216" diaginertia="0.00266244 0.00433385 0.00172758"/>
          <joint name="right_hip_abad" class="/" pos="0 0 0" axis="-0.999998 8.23922e-05 -0.00221534" stiffness="0.0122977" range="-2.96628 2.99944" armature="0.00913778" damping="0.0114635" frictionloss="0.1088"/>
          <geom name="//unnamed_geom_17" class="/" type="mesh" density="0" rgba="0.2 0.2 0.2 1" mesh="left_hip_abad1"/>
          <body name="right_upper_leg" pos="0.0860735 0.00184782 -0.0127139" quat="0.991504 -0.000297586 -0.130074 0.00087426">
            <inertial pos="0.00174589 -0.0318566 -0.080298" quat="0.680959 0.0478468 -0.0343931 0.729947" mass="2.9677" diaginertia="0.0213352 0.0543031 0.00349397"/>
            <joint name="right_hip_pitch" class="/" pos="0 0 0" axis="8.14912e-05 -1 -7.2311e-05" stiffness="0.00505772" range="-2.96078 3.0407" armature="0.0114721" damping="0" frictionloss="0.103402"/>
            <geom name="//unnamed_geom_18" class="/" type="mesh" density="0" rgba="0.752941 0.752941 0.752941 1" mesh="left_leg_upper1"/>
            <geom name="//unnamed_geom_19" class="reward_collision_sphere" size="0.0731577" pos="-0.014413 -0.0175567 0.0150602"/>
            <geom name="//unnamed_geom_20" class="reward_collision_sphere" size="0.0209022" pos="-0.0768695 0.0351134 0.080321"/>
            <body name="right_lower_leg" pos="-0.0147709 -0.00124878 -0.248116" quat="1 0.000224796 0.000129449 -0.000337854">
              <inertial pos="0.00229934 -0.00306923 -0.133037" quat="0.998792 0.00193082 0.0176983 -0.0457918" mass="0.392495" diaginertia="0.00241525 0.00626878 0.000225917"/>
              <joint name="right_knee" class="/" pos="0 0 0" axis="0.0130689 -0.999906 0.00425899" stiffness="0.0111092" range="-3.05011 0.0482008" armature="0.010805" damping="0.00936609" frictionloss="0.0910584"/>
              <geom name="//unnamed_geom_21" class="/" type="mesh" density="0" rgba="0.752941 0.752941 0.752941 1" mesh="left_leg_lower1"/>
              <geom name="//unnamed_geom_22" class="reward_collision_sphere" size="0.0449397"/>
              <body name="right_foot" pos="-4.39097e-05 -0.000752672 -0.280783" quat="1 -8.99712e-05 -0.00037541 2.48023e-05">
                <inertial pos="0.0246041 -0.000211651 -0.0137574" quat="0.470885 0.527075 0.516525 0.483385" mass="0.322362" diaginertia="0.0225177 0.0592125 0.0281503"/>
                <joint name="right_ankle" class="/" pos="0 0 0" axis="-0.000551824 -0.999968 -0.00801466" range="-1.46032 1.50392" armature="0.0100417" damping="0.0121943" frictionloss="0.0994314"/>
                <geom name="//unnamed_geom_23" class="/" type="mesh" density="0" rgba="0.2 0.2 0.2 1" mesh="left_foot1"/>
                <geom name="right_foot" class="foot" size="0.0999178 0.0174661 0.0217176" pos="0.0269043 0 -0.0251003" quat="0.707109 0.707105 0 0"/>
                <geom name="//unnamed_geom_25" class="reward_collision_sphere" size="0.0261277" pos="0.0269043 0 -0.0200802"/>
                <geom name="//unnamed_geom_26" class="reward_collision_sphere" size="0.0261277" pos="0.0960869 0 -0.0251003"/>
                <geom name="//unnamed_geom_27" class="reward_collision_sphere" size="0.0261277" pos="-0.0432391 0 -0.0251003"/>
                <site name="right_foot" class="foot" pos="0.0269043 0 -0.0251003" quat="0.707109 0.707105 0 0" size="0.0104511"/>
              </body>
            </body>
          </body>
        </body>
      </body>
      <body name="left_shoulder" pos="0.020597 0.206375 0.305613" quat="1 0.000417476 -5.7618e-05 4.01312e-05">
        <inertial pos="0.009898 0.0623876 0.000200757" quat="0.713482 0.700347 0.0174432 0.0123667" mass="0.862469" diaginertia="0.00107207 0.00185444 0.000775687"/>
        <joint name="left_shoulder_pitch" class="/" pos="0 0 0" axis="-0.000266 0.999983 -0.00585823" range="-3.0533 3.01907" armature="0.0108048" damping="0.0147148" frictionloss="0.111776"/>
        <geom name="//unnamed_geom_28" class="/" type="mesh" density="0" rgba="0.2 0.2 0.2 1" mesh="left_shoulder1"/>
        <body name="left_shoulder_2" pos="0.000843637 0.066597 -0.00261477" quat="0.999999 -0.000253916 0.00105352 -0.000915351">
          <inertial pos="-0.00199948 0.00268941 -0.0857359" quat="0.00600087 0.763249 0.00673694 0.646042" mass="0.888642" diaginertia="0.000988466 0.00254198 0.00107882"/>
          <joint name="left_shoulder_abad" class="/" pos="0 0 0" axis="-0.999992 -0.00297498 -0.00259238" stiffness="0.00104147" range="-3.03129 2.98006" armature="0.0105114" damping="0.00868169" frictionloss="0.106675"/>
          <geom name="//unnamed_geom_29" class="/" type="mesh" density="0" rgba="0.752941 0.752941 0.752941 1" mesh="left_shoulder2"/>
          <body name="left_upper_arm" pos="-0.00100248 0.000893696 -0.101154" quat="1 -0.000491556 -0.000163937 -0.000315562">
            <inertial pos="-0.000884349 -0.0217228 -0.0631876" quat="0.707702 -0.0219042 0.0207708 0.705866" mass="1.02122" diaginertia="0.00142557 0.00302014 0.000779477"/>
            <joint name="left_shoulder_yaw" class="/" pos="0 0 0" axis="0.00287173 -0.0110277 0.999935" stiffness="0.00331104" range="-3.05072 2.94897" armature="0.0115539" damping="0.011444" frictionloss="0.106681"/>
            <geom name="//unnamed_geom_30" class="/" type="mesh" density="0" rgba="0.752941 0.752941 0.752941 1" mesh="left_shoulder3"/>
            <geom name="//unnamed_geom_31" class="reward_collision_sphere" size="0.0627066" pos="-0.00960869 -0.0117045 -0.0502006"/>
            <body name="left_lower_arm" pos="0.000788631 0.000573874 -0.155459" quat="1 -6.41286e-05 -0.000137158 -0.000187137">
              <inertial pos="-0.00643732 0.000231085 -0.102807" quat="0.70878 0.00252456 0.00639931 0.705396" mass="0.418799" diaginertia="0.00307254 0.00791199 7.90723e-05"/>
              <joint name="left_elbow" class="/" pos="0 0 0" axis="0.000292231 0.99999 -0.00441194" stiffness="0.0153379" range="-3.05227 3.00923" armature="0.00918629" damping="0.00178269" frictionloss="0.102737"/>
              <geom name="//unnamed_geom_32" class="/" type="mesh" density="0" rgba="0.752941 0.752941 0.752941 1" mesh="left_forearm"/>
              <geom name="//unnamed_geom_33" class="/" size="0.0261277 0.00783832" pos="0 0 -0.271083" quat="0.707109 0.707105 0 0" type="cylinder" group="3"/>
              <geom name="//unnamed_geom_34" class="reward_collision_sphere" size="0.0261277"/>
              <geom name="//unnamed_geom_35" class="reward_collision_sphere" size="0.0229924" pos="0 0 -0.281123"/>
            </body>
          </body>
        </body>
      </body>
      <body name="right_shoulder" pos="0.0195928 -0.208598 0.306006" quat="0.999999 0.000700037 0.0002686 0.000826596">
        <inertial pos="0.00846705 -0.06218 -0.00245267" quat="0.713169 0.700705 -0.0142596 -0.0140755" mass="0.905382" diaginertia="0.0010712 0.00185832 0.000752724"/>
        <joint name="right_shoulder_pitch" class="/" pos="0 0 0" axis="-0.00053106 -0.999999 -0.000942168" range="-3.05403 2.94766" armature="0.00976906" damping="0.0073947" frictionloss="0.0951793"/>
        <geom name="//unnamed_geom_36" class="/" type="mesh" density="0" rgba="0.2 0.2 0.2 1" mesh="left_shoulder11"/>
        <body name="right_shoulder_2" pos="-0.00254777 -0.064578 0.00242429" quat="1 -0.000171636 -2.93634e-05 5.26643e-05">
          <inertial pos="0.0026403 -0.00301929 -0.0804213" quat="-0.000488168 0.653433 0.0116825 0.756894" mass="0.902879" diaginertia="0.00101905 0.00264044 0.00116688"/>
          <joint name="right_shoulder_abad" class="/" pos="0 0 0" axis="-0.999968 0.00635426 0.00485919" range="-2.94396 2.98458" armature="0.010816" damping="0.0222963" frictionloss="0.118918"/>
          <geom name="//unnamed_geom_37" class="/" type="mesh" density="0" rgba="0.752941 0.752941 0.752941 1" mesh="left_shoulder21"/>
          <body name="right_upper_arm" pos="0.00187969 -0.000563292 -0.102594" quat="0.999999 0.00112133 0.000467164 -0.000655547">
            <inertial pos="-0.0027184 0.0174628 -0.0643014" quat="0.705042 -0.0220088 0.0224846 0.708468" mass="1.0383" diaginertia="0.00152262 0.00308611 0.000821823"/>
            <joint name="right_shoulder_yaw" class="/" pos="0 0 0" axis="0.000401285 0.000171099 1" range="-3.00375 2.98218" armature="0.0101876" damping="0.00321118" frictionloss="0.104009"/>
            <geom name="//unnamed_geom_38" class="/" type="mesh" density="0" rgba="0.752941 0.752941 0.752941 1" mesh="left_shoulder31"/>
            <geom name="//unnamed_geom_39" class="reward_collision_sphere" size="0.0627066" pos="-0.00960869 0.0117045 -0.0502006"/>
            <body name="right_lower_arm" pos="-0.00276795 0.00157697 -0.157424" quat="0.999999 -0.000724743 -0.00103523 -0.000478849">
              <inertial pos="-0.00411337 -0.00154659 -0.0981475" quat="0.706875 0.00318436 0.00427283 0.707318" mass="0.413507" diaginertia="0.00313754 0.00805876 7.77489e-05"/>
              <joint name="right_elbow" class="/" pos="0 0 0" axis="-0.00465547 -0.999989 -0.000284189" stiffness="0.00172567" range="-2.99759 2.97053" armature="0.0103623" damping="0.00479889" frictionloss="0.09866"/>
              <geom name="//unnamed_geom_40" class="/" type="mesh" density="0" rgba="0.752941 0.752941 0.752941 1" mesh="left_forearm"/>
              <geom name="//unnamed_geom_41" class="/" size="0.0261277 0.00783832" pos="0 0 -0.271083" quat="0.707109 0.707105 0 0" type="cylinder" group="3"/>
              <geom name="//unnamed_geom_42" class="reward_collision_sphere" size="0.0261277"/>
              <geom name="//unnamed_geom_43" class="reward_collision_sphere" size="0.0229924" pos="0 0 -0.281123"/>
            </body>
          </body>
        </body>
      </body>
    </body>
  </worldbody>

  <contact>
    <pair class="/" geom1="floor" geom2="left_foot" name="//unnamed_contact_0"/>
    <pair class="/" geom1="floor" geom2="right_foot" name="//unnamed_contact_1"/>
  </contact>

  <actuator>
    <general name="left_hip_yaw" class="/" joint="left_hip_yaw" forcerange="-34.7988 34.7988" gainprm="31.6624" biasprm="0 -31.6624 -0.512595"/>
    <general name="left_hip_abad" class="/" joint="left_hip_abad" forcerange="-32.5271 32.5271" gainprm="31.6624" biasprm="0 -31.6624 -0.512595"/>
    <general name="left_hip_pitch" class="/" joint="left_hip_pitch" forcerange="-74.0185 74.0185" gainprm="31.6624" biasprm="0 -31.6624 -0.512595"/>
    <general name="left_knee" class="/" joint="left_knee" forcerange="-134.601 134.601" gainprm="31.6624" biasprm="0 -31.6624 -0.512595"/>
    <general name="left_ankle" class="/" joint="left_ankle" forcerange="-77.3242 77.3242" gainprm="31.6624" biasprm="0 -31.6624 -0.512595"/>
    <general name="right_hip_yaw" class="/" joint="right_hip_yaw" forcerange="-34.6666 34.6666" gainprm="31.6624" biasprm="0 -31.6624 -0.512595"/>
    <general name="right_hip_abad" class="/" joint="right_hip_abad" forcerange="-34.3201 34.3201" gainprm="31.6624" biasprm="0 -31.6624 -0.512595"/>
    <general name="right_hip_pitch" class="/" joint="right_hip_pitch" forcerange="-69.1684 69.1684" gainprm="31.6624" biasprm="0 -31.6624 -0.512595"/>
    <general name="right_knee" class="/" joint="right_knee" forcerange="-163.869 163.869" gainprm="31.6624" biasprm="0 -31.6624 -0.512595"/>
    <general name="right_ankle" class="/" joint="right_ankle" forcerange="-70.6435 70.6435" gainprm="31.6624" biasprm="0 -31.6624 -0.512595"/>
    <general name="left_shoulder_pitch" class="/" joint="left_shoulder_pitch" forcerange="-32.7296 32.7296" gainprm="31.6624" biasprm="0 -31.6624 -0.512595"/>
    <general name="left_shoulder_abad" class="/" joint="left_shoulder_abad" forcerange="-37.2237 37.2237" gainprm="31.6624" biasprm="0 -31.6624 -0.512595"/>
    <general name="left_shoulder_yaw" class="/" joint="left_shoulder_yaw" forcerange="-35.59 35.59" gainprm="31.6624" biasprm="0 -31.6624 -0.512595"/>
    <general name="left_elbow" class="/" joint="left_elbow" forcerange="-60.8108 60.8108" gainprm="31.6624" biasprm="0 -31.6624 -0.512595"/>
    <general name="right_shoulder_pitch" class="/" joint="right_shoulder_pitch" forcerange="-35.0915 35.0915" gainprm="31.6624" biasprm="0 -31.6624 -0.512595"/>
    <general name="right_shoulder_abad" class="/" joint="right_shoulder_abad" forcerange="-31.8431 31.8431" gainprm="31.6624" biasprm="0 -31.6624 -0.512595"/>
    <general name="right_shoulder_yaw" class="/" joint="right_shoulder_yaw" forcerange="-33.9245 33.9245" gainprm="31.6624" biasprm="0 -31.6624 -0.512595"/>
    <general name="right_elbow" class="/" joint="right_elbow" forcerange="-58.2966 58.2966" gainprm="31.6624" biasprm="0 -31.6624 -0.512595"/>
  </actuator>

  <sensor>
    <gyro site="imu" name="imu_angular_velocity"/>
    <velocimeter site="imu" name="imu_linear_velocity"/>
    <framelinvel objtype="site" objname="left_foot" name="left_foot_global_linear_velocity"/>
    <framelinvel objtype="site" objname="right_foot" name="right_foot_global_linear_velocity"/>
  </sensor>

  <keyframe>
    <key name="home" qpos="0 0 0.656 1 0 0 0 0 0 -0.4 0.8 -0.4 0 0 0.4 -0.8 0.4 0 -0.05 0 -0.75 0 0.05 0 0.75"/>
  </keyframe>
</mujoco>
