<mujoco model="humanoid">
  <compiler angle="radian" assetdir="assets" balanceinertia="true" inertiafromgeom="false"/>

  <option timestep="0.005" density="1.2" viscosity="2e-05"/>

  <size nkey="1"/>

  <visual>
    <quality shadowsize="8192"/>
    <map shadowclip="0.5"/>
  </visual>

  <default>
    <default class="/">
      <joint armature="0.01" damping="0.01" frictionloss="0.1"/>
      <geom contype="0" conaffinity="0" group="1" solref="-1000 -80"/>
      <site size="0.01 0.005 0.005" group="5"/>
      <general forcelimited="true" biastype="affine" gainprm="30" biasprm="0 -30 -0.5"/>
      <default class="foot">
        <geom size="0.099 0.0178 0.021" type="box" condim="6" group="4" priority="1" solimp="0.015 1 0.021"/>
      </default>
      <default class="reward_collision_sphere">
        <geom group="5" rgba="1 0 0 1"/>
      </default>
    </default>
  </default>

  <asset>
    <texture type="skybox" colorspace="auto" name="//unnamed_texture_0" builtin="gradient" rgb1="0.95 0.95 0.95" rgb2="0.95 0.95 0.95" width="100" height="600"/>
    <texture type="2d" colorspace="auto" name="texplane" builtin="checker" rgb1="0.345 0.575 0.748" rgb2="0.345 0.575 0.748" markrgb="1 1 1" width="512" height="512"/>
    <material name="MatPlane" class="/" texture="texplane" texuniform="true" texrepeat="2 2" specular="0.9"/>
    <mesh name="torso" class="/" file="torso.stl" scale="0.001 0.001 0.001"/>
    <mesh name="left_hip_yaw" class="/" file="left_hip_yaw.stl" scale="0.001 0.001 0.001"/>
    <mesh name="left_hip_abad" class="/" file="left_hip_abad.stl" scale="0.001 0.001 0.001"/>
    <mesh name="left_leg_upper" class="/" file="left_leg_upper.stl" scale="0.001 0.001 0.001"/>
    <mesh name="left_leg_lower" class="/" file="left_leg_lower.stl" scale="0.001 0.001 0.001"/>
    <mesh name="left_foot" class="/" file="left_foot.stl" scale="0.001 0.001 0.001"/>
    <mesh name="left_hip_yaw1" class="/" content_type="model/stl" file="left_hip_yaw.stl" scale="0.001 -0.001 0.001"/>
    <mesh name="left_hip_abad1" class="/" content_type="model/stl" file="left_hip_abad.stl" scale="0.001 -0.001 0.001"/>
    <mesh name="left_leg_upper1" class="/" content_type="model/stl" file="left_leg_upper.stl" scale="0.001 -0.001 0.001"/>
    <mesh name="left_leg_lower1" class="/" content_type="model/stl" file="left_leg_lower.stl" scale="0.001 -0.001 0.001"/>
    <mesh name="left_foot1" class="/" content_type="model/stl" file="left_foot.stl" scale="0.001 -0.001 0.001"/>
    <mesh name="left_shoulder1" class="/" file="left_shoulder1.stl" scale="0.001 0.001 0.001"/>
    <mesh name="left_shoulder2" class="/" file="left_shoulder2.stl" scale="0.001 0.001 0.001"/>
    <mesh name="left_shoulder3" class="/" file="left_shoulder3.stl" scale="0.001 0.001 0.001"/>
    <mesh name="left_forearm" class="/" file="left_forearm.stl" scale="0.001 0.001 0.001"/>
    <mesh name="left_shoulder11" class="/" content_type="model/stl" file="left_shoulder1.stl" scale="0.001 -0.001 0.001"/>
    <mesh name="left_shoulder21" class="/" content_type="model/stl" file="left_shoulder2.stl" scale="0.001 -0.001 0.001"/>
    <mesh name="left_shoulder31" class="/" content_type="model/stl" file="left_shoulder3.stl" scale="0.001 -0.001 0.001"/>
  </asset>

  <worldbody>
    <geom name="floor" class="/" size="100 100 0.125" type="plane" group="0" material="MatPlane"/>
    <light name="toplight_shadow" class="/" pos="0 0 5" dir="0.0990148 0.0990148 -0.990148" type="directional" ambient="0.04 0.04 0.04" diffuse="0.55 0.55 0.55" specular="0.12 0.12 0.12"/>
    <light name="toplight_fill" class="/" pos="0 0 5" dir="0.0990148 0.0990148 -0.990148" type="directional" castshadow="false" ambient="0.04 0.04 0.04" diffuse="0.3 0.3 0.3" specular="0.08 0.08 0.08"/>
    <body name="trunk" pos="-0.0145328 -0.000633599 0.00757588" quat="0.999996 0.0022021 -0.000174827 0.00195579">
      <inertial pos="-0.00313584 -0.0106762 0.216486" quat="0.996853 -0.00309915 0.0380091 -0.06949" mass="19.4276" diaginertia="0.695218 0.724422 0.38065"/>
      <joint name="//unnamed_joint_0" type="free"/>
      <geom name="//unnamed_geom_1" class="/" type="mesh" density="0" rgba="0.752941 0.752941 0.752941 1" mesh="torso"/>
      <geom name="//unnamed_geom_2" class="/" size="0.103992 0.207985 0.242649" pos="0.0303206 0 0.105879" type="box" group="3" rgba="0.752941 0.752941 0.752941 1"/>
      <geom name="//unnamed_geom_3" class="reward_collision_sphere" size="0.201052" pos="0 0 0.198524"/>
      <site name="imu" class="/" pos="-0.0108878 -0.00432293 0.15647" size="0.0138657"/>
      <camera name="track" class="/" pos="0 -3.03584 0" quat="0.707107 0.707107 0 0" mode="trackcom"/>
      <camera name="ego_camera" class="/" pos="0.0593228 0 0.397048" quat="-0.5 -0.5 0.5 0.5"/>
      <body name="left_hip_yaw" pos="0.0100488 0.130697 -0.0124789" quat="0.996071 0.00570484 -0.0883692 -0.000510254">
        <inertial pos="-0.0828539 -0.000175829 -0.0825616" quat="0.953878 -0.00668215 -0.299921 -0.0109387" mass="1.70434" diaginertia="0.00730147 0.011139 0.00246628"/>
        <joint name="left_hip_yaw" class="/" pos="0 0 0" axis="-0.00300782 0.0250494 -0.999682" range="-2.98806 3.14071" armature="0.0140366" damping="0.0259313" frictionloss="0.163745"/>
        <geom name="//unnamed_geom_4" class="/" type="mesh" density="0" rgba="0.2 0.2 0.2 1" mesh="left_hip_yaw"/>
        <body name="left_hip_abad" pos="-0.0712151 0.00909673 -0.0871381" quat="0.975466 0.00150312 0.22009 -0.00491941">
          <inertial pos="0.101019 -0.0230534 0.000904024" quat="0.577005 0.403841 0.411898 0.578203" mass="2.95984" diaginertia="0.0151147 0.0183909 0.00919875"/>
          <joint name="left_hip_abad" class="/" pos="0 0 0" axis="-0.997586 -0.0271026 0.0639407" stiffness="0.0339356" range="-3.18778 3.27171" armature="0.00389327" damping="0.0833169" frictionloss="0.167319"/>
          <geom name="//unnamed_geom_5" class="/" type="mesh" density="0" rgba="0.2 0.2 0.2 1" mesh="left_hip_abad"/>
          <body name="left_upper_leg" pos="0.120393 0.00932281 -0.0334647" quat="0.991105 -0.00390511 -0.132999 -0.00250664">
            <inertial pos="0.0029083 0.0366981 -0.103343" quat="0.74435 0.02888 -0.0856022 0.66165" mass="5.52569" diaginertia="0.0802663 0.157888 0.00914021"/>
            <joint name="left_hip_pitch" class="/" pos="0 0 0" axis="-0.0299808 0.99929 0.022833" range="-3.16651 3.1556" armature="0.0250038" damping="0.0442753" frictionloss="0.141772"/>
            <geom name="//unnamed_geom_6" class="/" type="mesh" density="0" rgba="0.752941 0.752941 0.752941 1" mesh="left_leg_upper"/>
            <geom name="//unnamed_geom_7" class="reward_collision_sphere" size="0.0970596" pos="-0.0197743 0.0227688 0.0198524"/>
            <geom name="//unnamed_geom_8" class="reward_collision_sphere" size="0.0277313" pos="-0.105463 -0.0455375 0.105879"/>
            <body name="left_lower_leg" pos="-0.0330008 -0.0161987 -0.336756" quat="0.999968 -0.0024029 0.00039225 0.00758714">
              <inertial pos="0.0145285 0.0140687 -0.185113" quat="0.998847 -0.0316314 0.0357854 0.00481006" mass="1.04819" diaginertia="0.0129571 0.0252741 0.000924726"/>
              <joint name="left_knee" class="/" pos="0 0 0" axis="0.0266116 0.998262 0.0525799" stiffness="0.00537295" range="-0.286032 3.02549" armature="0.0131381" damping="0.0567226" frictionloss="0.136615"/>
              <geom name="//unnamed_geom_9" class="/" type="mesh" density="0" rgba="0.752941 0.752941 0.752941 1" mesh="left_leg_lower"/>
              <geom name="//unnamed_geom_10" class="reward_collision_sphere" size="0.0596223"/>
              <body name="left_foot" pos="-0.00705302 -0.00951066 -0.367809" quat="0.999999 0.00122418 0.000908374 -3.83579e-05">
                <inertial pos="0.044269 -0.0167988 -0.0112316" quat="0.498941 0.488667 0.459138 0.549049" mass="0.969942" diaginertia="0.133656 0.2357 0.146185"/>
                <joint name="left_ankle" class="/" pos="0 0 0" axis="0.039615 0.998295 -0.0428594" stiffness="0.0360863" range="-1.81412 1.41046" armature="0.0209823" damping="0.0425099" frictionloss="0.0716006"/>
                <geom name="//unnamed_geom_11" class="/" type="mesh" density="0" rgba="0.2 0.2 0.2 1" mesh="left_foot"/>
                <geom name="left_foot" class="foot" size="0.100728 0.0197445 0.0240525" pos="0.036912 0 -0.0330873" quat="0.707109 0.707105 0 0"/>
                <geom name="//unnamed_geom_13" class="reward_collision_sphere" size="0.0346641" pos="0.036912 0 -0.0264698"/>
                <geom name="//unnamed_geom_14" class="reward_collision_sphere" size="0.0346641" pos="0.131828 0 -0.0330873"/>
                <geom name="//unnamed_geom_15" class="reward_collision_sphere" size="0.0346641" pos="-0.0593228 0 -0.0330873"/>
                <site name="left_foot" class="foot" pos="0.036912 0 -0.0330873" quat="0.707109 0.707105 0 0" size="0.0138657"/>
              </body>
            </body>
          </body>
        </body>
      </body>
      <body name="right_hip_yaw" pos="-0.0154391 -0.123121 -0.0103632" quat="0.995942 -0.00296516 -0.0899452 -0.00107168">
        <inertial pos="-0.0767443 -0.0113417 -0.0849122" quat="0.958907 0.0200027 0.278257 0.0516713" mass="2.33393" diaginertia="0.00769006 0.0112627 0.00329482"/>
        <joint name="right_hip_yaw" class="/" pos="0 0 0" axis="-0.0365916 0.0461927 -0.998262" stiffness="0.00924619" range="-3.09072 3.11623" armature="0.00992728" damping="0.0516169" frictionloss="0.101801"/>
        <geom name="//unnamed_geom_16" class="/" type="mesh" density="0" rgba="0.2 0.2 0.2 1" mesh="left_hip_yaw1"/>
        <body name="right_hip_abad" pos="-0.0806773 -0.0161557 -0.103847" quat="0.976363 -0.000139625 0.216135 -0.000131328">
          <inertial pos="0.0987201 0.00335073 0.00237471" quat="0.441887 0.550972 0.598851 0.37755" mass="2.99289" diaginertia="0.0131133 0.0129196 0.00657477"/>
          <joint name="right_hip_abad" class="/" pos="0 0 0" axis="-0.997637 -0.0452206 -0.0517336" range="-2.98842 2.70529" armature="0.020127" damping="0.0789555" frictionloss="0.101884"/>
          <geom name="//unnamed_geom_17" class="/" type="mesh" density="0" rgba="0.2 0.2 0.2 1" mesh="left_hip_abad1"/>
          <body name="right_upper_leg" pos="0.131056 0.00624617 -0.00884175" quat="0.990575 0.00302331 -0.136927 0.00197">
            <inertial pos="0.00728797 -0.0400812 -0.0982961" quat="0.698471 0.0268542 0.0192224 0.714876" mass="6.48123" diaginertia="0.0882383 0.180625 0.0109641"/>
            <joint name="right_hip_pitch" class="/" pos="0 0 0" axis="0.0661248 -0.997806 0.0033603" stiffness="0.0505078" range="-2.66358 3.25118" armature="0.0177166" damping="0.0298602" frictionloss="0.139173"/>
            <geom name="//unnamed_geom_18" class="/" type="mesh" density="0" rgba="0.752941 0.752941 0.752941 1" mesh="left_leg_upper1"/>
            <geom name="//unnamed_geom_19" class="reward_collision_sphere" size="0.0970596" pos="-0.0197743 -0.0227688 0.0198524"/>
            <geom name="//unnamed_geom_20" class="reward_collision_sphere" size="0.0277313" pos="-0.105463 0.0455375 0.105879"/>
            <body name="right_lower_leg" pos="-0.0137975 0.00174282 -0.339131" quat="1 -0.000726627 -0.000415608 0.000388979">
              <inertial pos="-0.00105481 -0.0097628 -0.176659" quat="0.998909 0.00102229 0.0113008 -0.045298" mass="0.769311" diaginertia="0.0128752 0.019414 0.000915688"/>
              <joint name="right_knee" class="/" pos="0 0 0" axis="-0.0202391 -0.999504 -0.0241075" range="-2.7268 -0.143002" armature="0.0157587" damping="0.0570088" frictionloss="0.2563"/>
              <geom name="//unnamed_geom_21" class="/" type="mesh" density="0" rgba="0.752941 0.752941 0.752941 1" mesh="left_leg_lower1"/>
              <geom name="//unnamed_geom_22" class="reward_collision_sphere" size="0.0596223"/>
              <body name="right_foot" pos="0.000610075 -0.0154157 -0.359512" quat="0.999994 0.00103686 -0.00272847 0.00184733">
                <inertial pos="0.0200937 -0.00318301 -0.00343644" quat="0.477522 0.520532 0.52039 0.479806" mass="0.595568" diaginertia="0.101335 0.251525 0.115101"/>
                <joint name="right_ankle" class="/" pos="0 0 0" axis="-0.0220978 -0.999708 -0.00980723" stiffness="0.0540031" range="-1.52609 1.34133" armature="0.0245982" damping="0" frictionloss="0.118325"/>
                <geom name="//unnamed_geom_23" class="/" type="mesh" density="0" rgba="0.2 0.2 0.2 1" mesh="left_foot1"/>
                <geom name="right_foot" class="foot" size="0.0665696 0.0312672 0.0293403" pos="0.036912 0 -0.0330873" quat="0.707109 0.707105 0 0"/>
                <geom name="//unnamed_geom_25" class="reward_collision_sphere" size="0.0346641" pos="0.036912 0 -0.0264698"/>
                <geom name="//unnamed_geom_26" class="reward_collision_sphere" size="0.0346641" pos="0.131828 0 -0.0330873"/>
                <geom name="//unnamed_geom_27" class="reward_collision_sphere" size="0.0346641" pos="-0.0593228 0 -0.0330873"/>
                <site name="right_foot" class="foot" pos="0.036912 0 -0.0330873" quat="0.707109 0.707105 0 0" size="0.0138657"/>
              </body>
            </body>
          </body>
        </body>
      </body>
      <body name="left_shoulder" pos="0.040597 0.278439 0.387263" quat="1 3.22188e-05 0.000133598 8.09543e-05">
        <inertial pos="0.0128927 0.0770685 -0.00608362" quat="0.708615 0.705355 0.0121633 0.0138654" mass="1.86653" diaginertia="0.00465661 0.0079615 0.00366618"/>
        <joint name="left_shoulder_pitch" class="/" pos="0 0 0" axis="-0.0509695 0.998672 -0.0074592" stiffness="0.0420271" range="-3.2402 2.68636" armature="0.0133143" damping="0" frictionloss="0.143239"/>
        <geom name="//unnamed_geom_28" class="/" type="mesh" density="0" rgba="0.2 0.2 0.2 1" mesh="left_shoulder1"/>
        <body name="left_shoulder_2" pos="-0.0046995 0.0830807 -0.012493" quat="0.999998 0.00035727 0.000770509 -0.0017162">
          <inertial pos="0.0152392 0.000833431 -0.0933059" quat="0.00292116 0.763743 -0.00977797 0.64544" mass="2.24525" diaginertia="0.00572371 0.00939367 0.00393077"/>
          <joint name="left_shoulder_abad" class="/" pos="0 0 0" axis="-0.99996 0.00732551 -0.00519012" stiffness="0.00300293" range="-2.99472 2.75835" armature="0.0135046" damping="0.0499689" frictionloss="0.123535"/>
          <geom name="//unnamed_geom_29" class="/" type="mesh" density="0" rgba="0.752941 0.752941 0.752941 1" mesh="left_shoulder2"/>
          <body name="left_upper_arm" pos="0.00216809 0.00889857 -0.140121" quat="0.999979 0.00586575 -0.00182 0.00205854">
            <inertial pos="-0.0014328 -0.0253186 -0.0707884" quat="0.711585 -0.00198635 0.00849586 0.702546" mass="2.59356" diaginertia="0.007697 0.0155256 0.00386437"/>
            <joint name="left_shoulder_yaw" class="/" pos="0 0 0" axis="-0.0362083 0.0308817 0.998867" stiffness="0.0275666" range="-3.19923 3.22853" armature="0.0171073" damping="0" frictionloss="0.141189"/>
            <geom name="//unnamed_geom_30" class="/" type="mesh" density="0" rgba="0.752941 0.752941 0.752941 1" mesh="left_shoulder3"/>
            <geom name="//unnamed_geom_31" class="reward_collision_sphere" size="0.0831939" pos="-0.0131828 -0.0151792 -0.0661746"/>
            <body name="left_lower_arm" pos="0.0115255 0.00888588 -0.220289" quat="1 -0.000470696 -0.000754381 0.000382479">
              <inertial pos="-0.00261515 0.000288467 -0.132928" quat="0.686604 -0.034957 0.0658935 0.723195" mass="1.00367" diaginertia="0.0141319 0.037088 0.000360566"/>
              <joint name="left_elbow" class="/" pos="0 0 0" axis="0.0013231 0.999999 -0.000882179" range="-2.99395 2.80669" armature="0.0217993" damping="0.0720657" frictionloss="0.242115"/>
              <geom name="//unnamed_geom_32" class="/" type="mesh" density="0" rgba="0.752941 0.752941 0.752941 1" mesh="left_forearm"/>
              <geom name="//unnamed_geom_33" class="/" size="0.0346641 0.0103992" pos="0 0 -0.357343" quat="0.707109 0.707105 0 0" type="cylinder" group="3"/>
              <geom name="//unnamed_geom_34" class="reward_collision_sphere" size="0.0346641"/>
              <geom name="//unnamed_geom_35" class="reward_collision_sphere" size="0.0305044" pos="0 0 -0.370578"/>
            </body>
          </body>
        </body>
      </body>
      <body name="right_shoulder" pos="0.0330369 -0.254971 0.392991" quat="0.999983 -0.00386913 0.00300747 -0.00315416">
        <inertial pos="0.0246791 -0.0810616 0.0139924" quat="0.712321 0.701577 -0.0127205 -0.0150575" mass="1.69912" diaginertia="0.00555773 0.00696854 0.00312679"/>
        <joint name="right_shoulder_pitch" class="/" pos="0 0 0" axis="-0.0584102 -0.998093 -0.0199701" range="-2.92395 2.87211" armature="0.0105637" damping="0.0169226" frictionloss="0.225788"/>
        <geom name="//unnamed_geom_36" class="/" type="mesh" density="0" rgba="0.2 0.2 0.2 1" mesh="left_shoulder11"/>
        <body name="right_shoulder_2" pos="0.000591316 -0.0848838 0.00140908" quat="0.999998 -0.0014939 0.000942225 -0.000393478">
          <inertial pos="-0.0141036 -0.000101228 -0.110102" quat="0.00520391 0.647908 0.0198609 0.761442" mass="2.90733" diaginertia="0.00542027 0.00921684 0.0063939"/>
          <joint name="right_shoulder_abad" class="/" pos="0 0 0" axis="-0.999949 0.00286737 -0.00969743" stiffness="0.0570502" range="-3.01111 2.88604" armature="0.0165476" damping="0" frictionloss="0.125025"/>
          <geom name="//unnamed_geom_37" class="/" type="mesh" density="0" rgba="0.752941 0.752941 0.752941 1" mesh="left_shoulder21"/>
          <body name="right_upper_arm" pos="-0.0131512 0.00344481 -0.133365" quat="0.999987 0.000516612 0.00506262 0.00048092">
            <inertial pos="0.0149468 0.0180262 -0.0744048" quat="0.707905 -0.0320569 0.0232017 0.705198" mass="1.86804" diaginertia="0.00651213 0.00966899 0.00273052"/>
            <joint name="right_shoulder_yaw" class="/" pos="0 0 0" axis="-0.027306 0.0022776 0.999625" stiffness="0.0084437" range="-3.00582 3.0437" armature="0.00798237" damping="0.0762178" frictionloss="0.0946884"/>
            <geom name="//unnamed_geom_38" class="/" type="mesh" density="0" rgba="0.752941 0.752941 0.752941 1" mesh="left_shoulder31"/>
            <geom name="//unnamed_geom_39" class="reward_collision_sphere" size="0.0831939" pos="-0.0131828 0.0151792 -0.0661746"/>
            <body name="right_lower_arm" pos="0.0100372 0.00914198 -0.212405" quat="1 0.000289639 0.00041184 -0.000853908">
              <inertial pos="-0.00525745 0.00559086 -0.130726" quat="0.711617 0.0287452 -0.0362399 0.701043" mass="0.744192" diaginertia="0.0137085 0.020101 0.000265464"/>
              <joint name="right_elbow" class="/" pos="0 0 0" axis="0.0374319 -0.997842 -0.0539552" range="-3.01656 2.97527" armature="0.013398" damping="0" frictionloss="0.224519"/>
              <geom name="//unnamed_geom_40" class="/" type="mesh" density="0" rgba="0.752941 0.752941 0.752941 1" mesh="left_forearm"/>
              <geom name="//unnamed_geom_41" class="/" size="0.0346641 0.0103992" pos="0 0 -0.357343" quat="0.707109 0.707105 0 0" type="cylinder" group="3"/>
              <geom name="//unnamed_geom_42" class="reward_collision_sphere" size="0.0346641"/>
              <geom name="//unnamed_geom_43" class="reward_collision_sphere" size="0.0305044" pos="0 0 -0.370578"/>
            </body>
          </body>
        </body>
      </body>
    </body>
  </worldbody>

  <contact>
    <pair class="/" geom1="floor" geom2="left_foot" name="//unnamed_contact_0"/>
    <pair class="/" geom1="floor" geom2="right_foot" name="//unnamed_contact_1"/>
  </contact>

  <actuator>
    <general name="left_hip_yaw" class="/" joint="left_hip_yaw" forcerange="-57.9519 57.9519" gainprm="49.7354" biasprm="0 -49.7354 -0.434904"/>
    <general name="left_hip_abad" class="/" joint="left_hip_abad" forcerange="-61.4182 61.4182" gainprm="49.7354" biasprm="0 -49.7354 -0.434904"/>
    <general name="left_hip_pitch" class="/" joint="left_hip_pitch" forcerange="-137.448 137.448" gainprm="49.7354" biasprm="0 -49.7354 -0.434904"/>
    <general name="left_knee" class="/" joint="left_knee" forcerange="-229.847 229.847" gainprm="49.7354" biasprm="0 -49.7354 -0.434904"/>
    <general name="left_ankle" class="/" joint="left_ankle" forcerange="-86.5263 86.5263" gainprm="49.7354" biasprm="0 -49.7354 -0.434904"/>
    <general name="right_hip_yaw" class="/" joint="right_hip_yaw" forcerange="-21.6171 21.6171" gainprm="49.7354" biasprm="0 -49.7354 -0.434904"/>
    <general name="right_hip_abad" class="/" joint="right_hip_abad" forcerange="-43.7305 43.7305" gainprm="49.7354" biasprm="0 -49.7354 -0.434904"/>
    <general name="right_hip_pitch" class="/" joint="right_hip_pitch" forcerange="-127.308 127.308" gainprm="49.7354" biasprm="0 -49.7354 -0.434904"/>
    <general name="right_knee" class="/" joint="right_knee" forcerange="-129.465 129.465" gainprm="49.7354" biasprm="0 -49.7354 -0.434904"/>
    <general name="right_ankle" class="/" joint="right_ankle" forcerange="-71.7569 71.7569" gainprm="49.7354" biasprm="0 -49.7354 -0.434904"/>
    <general name="left_shoulder_pitch" class="/" joint="left_shoulder_pitch" forcerange="-47.2433 47.2433" gainprm="49.7354" biasprm="0 -49.7354 -0.434904"/>
    <general name="left_shoulder_abad" class="/" joint="left_shoulder_abad" forcerange="-59.4328 59.4328" gainprm="49.7354" biasprm="0 -49.7354 -0.434904"/>
    <general name="left_shoulder_yaw" class="/" joint="left_shoulder_yaw" forcerange="-69.9021 69.9021" gainprm="49.7354" biasprm="0 -49.7354 -0.434904"/>
    <general name="left_elbow" class="/" joint="left_elbow" forcerange="-42.0107 42.0107" gainprm="49.7354" biasprm="0 -49.7354 -0.434904"/>
    <general name="right_shoulder_pitch" class="/" joint="right_shoulder_pitch" forcerange="-30.0969 30.0969" gainprm="49.7354" biasprm="0 -49.7354 -0.434904"/>
    <general name="right_shoulder_abad" class="/" joint="right_shoulder_abad" forcerange="-63.0483 63.0483" gainprm="49.7354" biasprm="0 -49.7354 -0.434904"/>
    <general name="right_shoulder_yaw" class="/" joint="right_shoulder_yaw" forcerange="-52.143 52.143" gainprm="49.7354" biasprm="0 -49.7354 -0.434904"/>
    <general name="right_elbow" class="/" joint="right_elbow" forcerange="-93.0344 93.0344" gainprm="49.7354" biasprm="0 -49.7354 -0.434904"/>
  </actuator>

  <sensor>
    <gyro site="imu" name="imu_angular_velocity"/>
    <velocimeter site="imu" name="imu_linear_velocity"/>
    <framelinvel objtype="site" objname="left_foot" name="left_foot_global_linear_velocity"/>
    <framelinvel objtype="site" objname="right_foot" name="right_foot_global_linear_velocity"/>
  </sensor>

  <keyframe>
    <key name="home" qpos="0 0 0.656 1 0 0 0 0 0 -0.4 0.8 -0.4 0 0 0.4 -0.8 0.4 0 -0.05 0 -0.75 0 0.05 0 0.75"/>
  </keyframe>
</mujoco>
