<mujoco model="humanoid">
  <compiler angle="radian" assetdir="assets" balanceinertia="true" inertiafromgeom="false"/>

  <option timestep="0.005" density="1.2" viscosity="2e-05"/>

  <size nkey="1"/>

  <visual>
    <quality shadowsize="8192"/>
    <map shadowclip="0.5"/>
  </visual>

  <default>
    <default class="/">
      <joint armature="0.01" damping="0.01" frictionloss="0.1"/>
      <geom contype="0" conaffinity="0" group="1" solref="-1000 -80"/>
      <site size="0.01 0.005 0.005" group="5"/>
      <general forcelimited="true" biastype="affine" gainprm="30" biasprm="0 -30 -0.5"/>
      <default class="foot">
        <geom size="0.099 0.0178 0.021" type="box" condim="6" group="4" priority="1" solimp="0.015 1 0.021"/>
      </default>
      <default class="reward_collision_sphere">
        <geom group="5" rgba="1 0 0 1"/>
      </default>
    </default>
  </default>

  <asset>
    <texture type="skybox" colorspace="auto" name="//unnamed_texture_0" builtin="gradient" rgb1="0.95 0.95 0.95" rgb2="0.95 0.95 0.95" width="100" height="600"/>
    <texture type="2d" colorspace="auto" name="texplane" builtin="checker" rgb1="0.345 0.575 0.748" rgb2="0.345 0.575 0.748" markrgb="1 1 1" width="512" height="512"/>
    <material name="MatPlane" class="/" texture="texplane" texuniform="true" texrepeat="2 2" specular="0.9"/>
    <mesh name="torso" class="/" file="torso.stl" scale="0.001 0.001 0.001"/>
    <mesh name="left_hip_yaw" class="/" file="left_hip_yaw.stl" scale="0.001 0.001 0.001"/>
    <mesh name="left_hip_abad" class="/" file="left_hip_abad.stl" scale="0.001 0.001 0.001"/>
    <mesh name="left_leg_upper" class="/" file="left_leg_upper.stl" scale="0.001 0.001 0.001"/>
    <mesh name="left_leg_lower" class="/" file="left_leg_lower.stl" scale="0.001 0.001 0.001"/>
    <mesh name="left_foot" class="/" file="left_foot.stl" scale="0.001 0.001 0.001"/>
    <mesh name="left_hip_yaw1" class="/" content_type="model/stl" file="left_hip_yaw.stl" scale="0.001 -0.001 0.001"/>
    <mesh name="left_hip_abad1" class="/" content_type="model/stl" file="left_hip_abad.stl" scale="0.001 -0.001 0.001"/>
    <mesh name="left_leg_upper1" class="/" content_type="model/stl" file="left_leg_upper.stl" scale="0.001 -0.001 0.001"/>
    <mesh name="left_leg_lower1" class="/" content_type="model/stl" file="left_leg_lower.stl" scale="0.001 -0.001 0.001"/>
    <mesh name="left_foot1" class="/" content_type="model/stl" file="left_foot.stl" scale="0.001 -0.001 0.001"/>
    <mesh name="left_shoulder1" class="/" file="left_shoulder1.stl" scale="0.001 0.001 0.001"/>
    <mesh name="left_shoulder2" class="/" file="left_shoulder2.stl" scale="0.001 0.001 0.001"/>
    <mesh name="left_shoulder3" class="/" file="left_shoulder3.stl" scale="0.001 0.001 0.001"/>
    <mesh name="left_forearm" class="/" file="left_forearm.stl" scale="0.001 0.001 0.001"/>
    <mesh name="left_shoulder11" class="/" content_type="model/stl" file="left_shoulder1.stl" scale="0.001 -0.001 0.001"/>
    <mesh name="left_shoulder21" class="/" content_type="model/stl" file="left_shoulder2.stl" scale="0.001 -0.001 0.001"/>
    <mesh name="left_shoulder31" class="/" content_type="model/stl" file="left_shoulder3.stl" scale="0.001 -0.001 0.001"/>
  </asset>

  <worldbody>
    <geom name="floor" class="/" size="100 100 0.125" type="plane" group="0" material="MatPlane"/>
    <light name="toplight_shadow" class="/" pos="0 0 5" dir="0.0990148 0.0990148 -0.990148" type="directional" ambient="0.04 0.04 0.04" diffuse="0.55 0.55 0.55" specular="0.12 0.12 0.12"/>
    <light name="toplight_fill" class="/" pos="0 0 5" dir="0.0990148 0.0990148 -0.990148" type="directional" castshadow="false" ambient="0.04 0.04 0.04" diffuse="0.3 0.3 0.3" specular="0.08 0.08 0.08"/>
    <body name="trunk" pos="-0.0115868 0.00135589 0.00469148" quat="0.999999 -0.000425554 0.0014136 0.000393789">
      <inertial pos="0.000492558 -0.00787123 0.196106" quat="0.997915 0.0603414 -0.017735 -0.0145257" mass="17.3258" diaginertia="0.90116 0.514496 0.242577"/>
      <joint name="//unnamed_joint_0" type="free"/>
      <geom name="//unnamed_geom_1" class="/" type="mesh" density="0" rgba="0.752941 0.752941 0.752941 1" mesh="torso"/>
      <geom name="//unnamed_geom_2" class="/" size="0.0999819 0.199964 0.233291" pos="0.0319107 0 0.0966861" type="box" group="3" rgba="0.752941 0.752941 0.752941 1"/>
      <geom name="//unnamed_geom_3" class="reward_collision_sphere" size="0.193298" pos="0 0 0.181286"/>
      <site name="imu" class="/" pos="0.00185593 -0.00278135 0.153721" size="0.0133309"/>
      <camera name="track" class="/" pos="0 -2.80656 0" quat="0.707107 0.707107 0 0" mode="trackcom"/>
      <camera name="ego_camera" class="/" pos="0.062434 0 0.362573" quat="-0.5 -0.5 0.5 0.5"/>
      <body name="left_hip_yaw" pos="0.00912009 0.118585 -0.00957111" quat="0.996494 0.00259278 -0.0836198 -7.46539e-05">
        <inertial pos="-0.0902188 0.00160728 -0.0770613" quat="0.949787 -0.0044144 -0.312858 -0.00233084" mass="1.64304" diaginertia="0.00947077 0.00754589 0.00169647"/>
        <joint name="left_hip_yaw" class="/" pos="0 0 0" axis="0.00441935 0.0103361 -0.999937" stiffness="0.00467945" range="-2.97364 3.08347" armature="0.0137791" damping="0.0225008" frictionloss="0.139195"/>
        <geom name="//unnamed_geom_4" class="/" type="mesh" density="0" rgba="0.2 0.2 0.2 1" mesh="left_hip_yaw"/>
        <body name="left_hip_abad" pos="-0.0783081 0.00625595 -0.0814862" quat="0.97602 -0.00234366 0.21763 -0.00412726">
          <inertial pos="0.10277 -0.0189026 -0.000989327" quat="0.574814 0.411059 0.412866 0.574597" mass="2.6632" diaginertia="0.0189436 0.0120044 0.00547436"/>
          <joint name="left_hip_abad" class="/" pos="0 0 0" axis="-0.998503 -0.0269872 0.0475682" stiffness="0.0195655" range="-3.12945 3.2128" armature="0.00582163" damping="0.0664251" frictionloss="0.142431"/>
          <geom name="//unnamed_geom_5" class="/" type="mesh" density="0" rgba="0.2 0.2 0.2 1" mesh="left_hip_abad"/>
          <body name="left_upper_leg" pos="0.129107 0.00673369 -0.0289215" quat="0.991368 0.00301835 -0.131052 0.00224168">
            <inertial pos="-8.97627e-06 0.0363841 -0.0939374" quat="0.734889 0.0628502 -0.0529313 0.673191" mass="5.18592" diaginertia="0.112156 0.10858 0.00634903"/>
            <joint name="left_hip_pitch" class="/" pos="0 0 0" axis="0.00529936 0.999734 -0.0224289" stiffness="0.00319683" range="-3.10847 3.0978" armature="0.0219414" damping="0.0312224" frictionloss="0.123975"/>
            <geom name="//unnamed_geom_6" class="/" type="mesh" density="0" rgba="0.752941 0.752941 0.752941 1" mesh="left_leg_upper"/>
            <geom name="//unnamed_geom_7" class="reward_collision_sphere" size="0.0933165" pos="-0.0208113 0.0210492 0.0181286"/>
            <geom name="//unnamed_geom_8" class="reward_collision_sphere" size="0.0266618" pos="-0.110994 -0.0420983 0.0966861"/>
            <body name="left_lower_leg" pos="-0.0309285 -0.0132367 -0.305798" quat="0.999979 0.00237041 0.00530856 0.00287474">
              <inertial pos="0.0120174 0.0110767 -0.167064" quat="0.99824 -0.0479027 -0.0285245 0.0202005" mass="0.893968" diaginertia="0.0166826 0.0171148 0.000592225"/>
              <joint name="left_knee" class="/" pos="0 0 0" axis="-0.0386621 0.99898 0.0233242" stiffness="0.00120643" range="-0.226994 3.01061" armature="0.0116348" damping="0.0437672" frictionloss="0.142882"/>
              <geom name="//unnamed_geom_9" class="/" type="mesh" density="0" rgba="0.752941 0.752941 0.752941 1" mesh="left_leg_lower"/>
              <geom name="//unnamed_geom_10" class="reward_collision_sphere" size="0.057323"/>
              <body name="left_foot" pos="-0.00409582 -0.00658232 -0.336154" quat="1 -0.00013842 -4.09556e-06 3.62856e-05">
                <inertial pos="0.0428974 -0.0138426 -0.0124965" quat="0.53619 0.489026 0.461657 0.510124" mass="0.80768" diaginertia="0.161524 0.158884 0.0870396"/>
                <joint name="left_ankle" class="/" pos="0 0 0" axis="-0.0338414 0.999041 -0.0277667" stiffness="0.0216864" range="-1.75514 1.46503" armature="0.0181178" damping="0.0293823" frictionloss="0.0882755"/>
                <geom name="//unnamed_geom_11" class="/" type="mesh" density="0" rgba="0.2 0.2 0.2 1" mesh="left_foot"/>
                <geom name="left_foot" class="foot" size="0.111428 0.0187606 0.0202714" pos="0.0388478 0 -0.0302144" quat="0.707109 0.707105 0 0"/>
                <geom name="//unnamed_geom_13" class="reward_collision_sphere" size="0.0333273" pos="0.0388478 0 -0.0241715"/>
                <geom name="//unnamed_geom_14" class="reward_collision_sphere" size="0.0333273" pos="0.138742 0 -0.0302144"/>
                <geom name="//unnamed_geom_15" class="reward_collision_sphere" size="0.0333273" pos="-0.062434 0 -0.0302144"/>
                <site name="left_foot" class="foot" pos="0.0388478 0 -0.0302144" quat="0.707109 0.707105 0 0" size="0.0133309"/>
              </body>
            </body>
          </body>
        </body>
      </body>
      <body name="right_hip_yaw" pos="-0.0124561 -0.113577 -0.00740623" quat="0.996307 -0.000336502 -0.085829 0.00240369">
        <inertial pos="-0.0841886 -0.00841581 -0.075241" quat="0.936182 -0.0382521 0.349405 -0.00398717" mass="1.99114" diaginertia="0.00959113 0.00732175 0.00200727"/>
        <joint name="right_hip_yaw" class="/" pos="0 0 0" axis="-0.0305431 -0.0323923 -0.999008" stiffness="0.00026972" range="-3.03486 3.05949" armature="0.011398" damping="0.0345398" frictionloss="0.116688"/>
        <geom name="//unnamed_geom_16" class="/" type="mesh" density="0" rgba="0.2 0.2 0.2 1" mesh="left_hip_yaw1"/>
        <body name="right_hip_abad" pos="-0.0877206 -0.0131843 -0.0923367" quat="0.976203 0.000363236 0.216859 0.000584554">
          <inertial pos="0.10049 0.00480907 -8.68015e-05" quat="0.43754 0.582425 0.567768 0.383379" mass="2.78032" diaginertia="0.0169879 0.00943396 0.00437978"/>
          <joint name="right_hip_abad" class="/" pos="0 0 0" axis="-0.998544 0.0468419 -0.0267342" range="-2.9939 2.76419" armature="0.0175127" damping="0.0619743" frictionloss="0.116816"/>
          <geom name="//unnamed_geom_17" class="/" type="mesh" density="0" rgba="0.2 0.2 0.2 1" mesh="left_hip_abad1"/>
          <body name="right_upper_leg" pos="0.13427 0.0073778 -0.0100577" quat="0.992187 -0.000139075 -0.124752 -0.00107241">
            <inertial pos="0.00432793 -0.0363453 -0.0921107" quat="0.661239 0.0373667 0.00281763 0.749239" mass="5.99546" diaginertia="0.123005 0.130163 0.00754711"/>
            <joint name="right_hip_pitch" class="/" pos="0 0 0" axis="-0.0192967 -0.998679 -0.047618" stiffness="0.0360131" range="-2.7226 3.19256" armature="0.0150182" damping="0.0170798" frictionloss="0.143038"/>
            <geom name="//unnamed_geom_18" class="/" type="mesh" density="0" rgba="0.752941 0.752941 0.752941 1" mesh="left_leg_upper1"/>
            <geom name="//unnamed_geom_19" class="reward_collision_sphere" size="0.0933165" pos="-0.0208113 -0.0210492 0.0181286"/>
            <geom name="//unnamed_geom_20" class="reward_collision_sphere" size="0.0266618" pos="-0.110994 0.0420983 0.0966861"/>
            <body name="right_lower_leg" pos="-0.016715 0.000588697 -0.307571" quat="1 -0.000276438 -2.1984e-05 -0.000361265">
              <inertial pos="0.00221977 -0.00679935 -0.158904" quat="0.99875 0.00741301 0.0204396 -0.0450045" mass="0.73853" diaginertia="0.0167438 0.0141751 0.000584428"/>
              <joint name="right_knee" class="/" pos="0 0 0" axis="0.0184631 -0.999829 -0.000570319" stiffness="0.0032756" range="-2.78571 -0.085413" armature="0.0134208" damping="0.0396689" frictionloss="0.226716"/>
              <geom name="//unnamed_geom_21" class="/" type="mesh" density="0" rgba="0.752941 0.752941 0.752941 1" mesh="left_leg_lower1"/>
              <geom name="//unnamed_geom_22" class="reward_collision_sphere" size="0.057323"/>
              <body name="right_foot" pos="0.00121642 -0.0124635 -0.330332" quat="0.999998 0.00120914 -0.000620137 0.00150729">
                <inertial pos="0.0246157 -0.000451121 -0.00479115" quat="0.479681 0.519583 0.52075 0.478287" mass="0.559292" diaginertia="0.137071 0.166026 0.0713915"/>
                <joint name="right_ankle" class="/" pos="0 0 0" axis="0.0105022 -0.999933 0.00479125" stiffness="0.0396618" range="-1.47969 1.3989" armature="0.0215541" damping="0" frictionloss="0.131478"/>
                <geom name="//unnamed_geom_23" class="/" type="mesh" density="0" rgba="0.2 0.2 0.2 1" mesh="left_foot1"/>
                <geom name="right_foot" class="foot" size="0.0788228 0.0274172 0.0253418" pos="0.0388478 0 -0.0302144" quat="0.707109 0.707105 0 0"/>
                <geom name="//unnamed_geom_25" class="reward_collision_sphere" size="0.0333273" pos="0.0388478 0 -0.0241715"/>
                <geom name="//unnamed_geom_26" class="reward_collision_sphere" size="0.0333273" pos="0.138742 0 -0.0302144"/>
                <geom name="//unnamed_geom_27" class="reward_collision_sphere" size="0.0333273" pos="-0.062434 0 -0.0302144"/>
                <site name="right_foot" class="foot" pos="0.0388478 0 -0.0302144" quat="0.707109 0.707105 0 0" size="0.0133309"/>
              </body>
            </body>
          </body>
        </body>
      </body>
      <body name="left_shoulder" pos="0.0390321 0.255295 0.355303" quat="1 0.000747513 -0.000289414 0.000541173">
        <inertial pos="0.0130732 0.0737377 -0.00326531" quat="0.708208 0.705752 0.0107519 0.0154533" mass="1.72399" diaginertia="0.00625953 0.00519365 0.00225152"/>
        <joint name="left_shoulder_pitch" class="/" pos="0 0 0" axis="0.0353744 0.999326 0.00982232" stiffness="0.0273801" range="-3.18127 2.74561" armature="0.0138213" damping="0" frictionloss="0.142623"/>
        <geom name="//unnamed_geom_28" class="/" type="mesh" density="0" rgba="0.2 0.2 0.2 1" mesh="left_shoulder1"/>
        <body name="left_shoulder_2" pos="-0.00454636 0.0789687 -0.00953783" quat="0.999999 0.000165968 -0.000497835 0.00109335">
          <inertial pos="0.0122852 0.0022434 -0.0867439" quat="0.0145657 0.7585 -0.00291861 0.651503" mass="1.91588" diaginertia="0.007107 0.00618978 0.00258384"/>
          <joint name="left_shoulder_abad" class="/" pos="0 0 0" axis="-0.99999 -0.00440814 -0.00067052" range="-3.00431 2.81701" armature="0.0141899" damping="0.0341349" frictionloss="0.135756"/>
          <geom name="//unnamed_geom_29" class="/" type="mesh" density="0" rgba="0.752941 0.752941 0.752941 1" mesh="left_shoulder2"/>
          <body name="left_upper_arm" pos="-0.000314845 0.00594292 -0.125518" quat="0.999987 -0.00378271 0.00243622 -0.00220072">
            <inertial pos="-0.000685 -0.0222946 -0.0664651" quat="0.710116 -0.0169111 0.0284094 0.703308" mass="2.32599" diaginertia="0.0100318 0.00984614 0.00236419"/>
            <joint name="left_shoulder_yaw" class="/" pos="0 0 0" axis="-0.0149067 0.0294083 0.999456" stiffness="0.0131254" range="-3.14108 3.16976" armature="0.0145362" damping="0" frictionloss="0.123575"/>
            <geom name="//unnamed_geom_30" class="/" type="mesh" density="0" rgba="0.752941 0.752941 0.752941 1" mesh="left_shoulder3"/>
            <geom name="//unnamed_geom_31" class="reward_collision_sphere" size="0.0799855" pos="-0.0138742 -0.0140328 -0.0604288"/>
            <body name="left_lower_arm" pos="0.00867105 0.00592772 -0.19925" quat="1 -1.31454e-05 2.73593e-05 5.94713e-05">
              <inertial pos="-0.00599534 -0.00106788 -0.119079" quat="0.706028 0.00649363 -0.0576808 0.705801" mass="0.891259" diaginertia="0.018383 0.0234554 0.000214412"/>
              <joint name="left_elbow" class="/" pos="0 0 0" axis="-0.00880562 0.999929 -0.00797158" range="-3.01079 2.86476" armature="0.0188922" damping="0.0589785" frictionloss="0.213133"/>
              <geom name="//unnamed_geom_32" class="/" type="mesh" density="0" rgba="0.752941 0.752941 0.752941 1" mesh="left_forearm"/>
              <geom name="//unnamed_geom_33" class="/" size="0.0333273 0.00999819" pos="0 0 -0.326316" quat="0.707109 0.707105 0 0" type="cylinder" group="3"/>
              <geom name="//unnamed_geom_34" class="reward_collision_sphere" size="0.0333273"/>
              <geom name="//unnamed_geom_35" class="reward_collision_sphere" size="0.029328" pos="0 0 -0.338401"/>
            </body>
          </body>
        </body>
      </body>
      <body name="right_shoulder" pos="0.031713 -0.237752 0.360548" quat="0.999991 0.00138546 -0.00365941 0.00188837">
        <inertial pos="0.0223822 -0.0725792 0.0110426" quat="0.710533 0.703405 -0.0151535 -0.0115515" mass="1.53174" diaginertia="0.00683309 0.00470689 0.00197274"/>
        <joint name="right_shoulder_pitch" class="/" pos="0 0 0" axis="-0.007898 -0.998901 -0.0461924" stiffness="0.00394787" range="-2.98105 2.92781" armature="0.0120053" damping="0.0143753" frictionloss="0.197421"/>
        <geom name="//unnamed_geom_36" class="/" type="mesh" density="0" rgba="0.2 0.2 0.2 1" mesh="left_shoulder11"/>
        <body name="right_shoulder_2" pos="-0.00117019 -0.0810896 -0.000883491" quat="1 0.000288271 -0.00031321 -9.87065e-05">
          <inertial pos="-0.0111581 0.00156913 -0.0995033" quat="-0.00173172 0.651973 0.0135645 0.758119" mass="2.42371" diaginertia="0.00705411 0.00630935 0.00381046"/>
          <joint name="right_shoulder_abad" class="/" pos="0 0 0" axis="-0.999994 0.00261246 0.00220796" stiffness="0.0421438" range="-2.99321 2.94296" armature="0.014089" damping="0.00704602" frictionloss="0.136877"/>
          <geom name="//unnamed_geom_37" class="/" type="mesh" density="0" rgba="0.752941 0.752941 0.752941 1" mesh="left_shoulder21"/>
          <body name="right_upper_arm" pos="-0.0103867 0.000587864 -0.124224" quat="0.999993 0.00280665 0.00213634 -0.000924512">
            <inertial pos="0.0119879 0.0190105 -0.0700505" quat="0.704813 -0.0205401 0.0218249 0.70876" mass="1.80033" diaginertia="0.00867022 0.00677584 0.00186981"/>
            <joint name="right_shoulder_yaw" class="/" pos="0 0 0" axis="0.00825348 -0.0112979 0.999902" stiffness="0.0128304" range="-2.99234 2.99216" armature="0.00948448" damping="0.0630671" frictionloss="0.110082"/>
            <geom name="//unnamed_geom_38" class="/" type="mesh" density="0" rgba="0.752941 0.752941 0.752941 1" mesh="left_shoulder31"/>
            <geom name="//unnamed_geom_39" class="reward_collision_sphere" size="0.0799855" pos="-0.0138742 0.0140328 -0.0604288"/>
            <body name="right_lower_arm" pos="0.00717081 0.00621044 -0.191561" quat="1 -0.000183597 0.000298364 5.05337e-05">
              <inertial pos="-0.00854823 0.00275597 -0.121676" quat="0.720625 -0.00713198 -0.0203 0.692991" mass="0.715936" diaginertia="0.0178368 0.0147974 0.000181407"/>
              <joint name="right_elbow" class="/" pos="0 0 0" axis="0.0226899 -0.998684 -0.0459974" range="-3.00535 3.02186" armature="0.0125458" damping="0" frictionloss="0.196291"/>
              <geom name="//unnamed_geom_40" class="/" type="mesh" density="0" rgba="0.752941 0.752941 0.752941 1" mesh="left_forearm"/>
              <geom name="//unnamed_geom_41" class="/" size="0.0333273 0.00999819" pos="0 0 -0.326316" quat="0.707109 0.707105 0 0" type="cylinder" group="3"/>
              <geom name="//unnamed_geom_42" class="reward_collision_sphere" size="0.0333273"/>
              <geom name="//unnamed_geom_43" class="reward_collision_sphere" size="0.029328" pos="0 0 -0.338401"/>
            </body>
          </body>
        </body>
      </body>
    </body>
  </worldbody>

  <contact>
    <pair class="/" geom1="floor" geom2="left_foot" name="//unnamed_contact_0"/>
    <pair class="/" geom1="floor" geom2="right_foot" name="//unnamed_contact_1"/>
  </contact>

  <actuator>
    <general name="left_hip_yaw" class="/" joint="left_hip_yaw" forcerange="-50.8946 50.8946" gainprm="44.93" biasprm="0 -44.93 -0.454059"/>
    <general name="left_hip_abad" class="/" joint="left_hip_abad" forcerange="-54.1741 54.1741" gainprm="44.93" biasprm="0 -44.93 -0.454059"/>
    <general name="left_hip_pitch" class="/" joint="left_hip_pitch" forcerange="-121.752 121.752" gainprm="44.93" biasprm="0 -44.93 -0.454059"/>
    <general name="left_knee" class="/" joint="left_knee" forcerange="-202.307 202.307" gainprm="44.93" biasprm="0 -44.93 -0.454059"/>
    <general name="left_ankle" class="/" joint="left_ankle" forcerange="-92.0595 92.0595" gainprm="44.93" biasprm="0 -44.93 -0.454059"/>
    <general name="right_hip_yaw" class="/" joint="right_hip_yaw" forcerange="-25.7892 25.7892" gainprm="44.93" biasprm="0 -44.93 -0.454059"/>
    <general name="right_hip_abad" class="/" joint="right_hip_abad" forcerange="-42.3281 42.3281" gainprm="44.93" biasprm="0 -44.93 -0.454059"/>
    <general name="right_hip_pitch" class="/" joint="right_hip_pitch" forcerange="-112.386 112.386" gainprm="44.93" biasprm="0 -44.93 -0.454059"/>
    <general name="right_knee" class="/" joint="right_knee" forcerange="-145.402 145.402" gainprm="44.93" biasprm="0 -44.93 -0.454059"/>
    <general name="right_ankle" class="/" joint="right_ankle" forcerange="-78.6033 78.6033" gainprm="44.93" biasprm="0 -44.93 -0.454059"/>
    <general name="left_shoulder_pitch" class="/" joint="left_shoulder_pitch" forcerange="-47.2178 47.2178" gainprm="44.93" biasprm="0 -44.93 -0.454059"/>
    <general name="left_shoulder_abad" class="/" joint="left_shoulder_abad" forcerange="-52.274 52.274" gainprm="44.93" biasprm="0 -44.93 -0.454059"/>
    <general name="left_shoulder_yaw" class="/" joint="left_shoulder_yaw" forcerange="-62.2204 62.2204" gainprm="44.93" biasprm="0 -44.93 -0.454059"/>
    <general name="left_elbow" class="/" joint="left_elbow" forcerange="-48.4667 48.4667" gainprm="44.93" biasprm="0 -44.93 -0.454059"/>
    <general name="right_shoulder_pitch" class="/" joint="right_shoulder_pitch" forcerange="-33.8672 33.8672" gainprm="44.93" biasprm="0 -44.93 -0.454059"/>
    <general name="right_shoulder_abad" class="/" joint="right_shoulder_abad" forcerange="-55.6929 55.6929" gainprm="44.93" biasprm="0 -44.93 -0.454059"/>
    <general name="right_shoulder_yaw" class="/" joint="right_shoulder_yaw" forcerange="-45.6944 45.6944" gainprm="44.93" biasprm="0 -44.93 -0.454059"/>
    <general name="right_elbow" class="/" joint="right_elbow" forcerange="-81.6842 81.6842" gainprm="44.93" biasprm="0 -44.93 -0.454059"/>
  </actuator>

  <sensor>
    <gyro site="imu" name="imu_angular_velocity"/>
    <velocimeter site="imu" name="imu_linear_velocity"/>
    <framelinvel objtype="site" objname="left_foot" name="left_foot_global_linear_velocity"/>
    <framelinvel objtype="site" objname="right_foot" name="right_foot_global_linear_velocity"/>
  </sensor>

  <keyframe>
    <key name="home" qpos="0 0 0.656 1 0 0 0 0 0 -0.4 0.8 -0.4 0 0 0.4 -0.8 0.4 0 -0.05 0 -0.75 0 0.05 0 0.75"/>
  </keyframe>
</mujoco>
