<mujoco model="humanoid">
  <compiler angle="radian" assetdir="assets" balanceinertia="true" inertiafromgeom="false"/>

  <option timestep="0.005" density="1.2" viscosity="2e-05"/>

  <size nkey="1"/>

  <visual>
    <quality shadowsize="8192"/>
    <map shadowclip="0.5"/>
  </visual>

  <default>
    <default class="/">
      <joint armature="0.01" damping="0.01" frictionloss="0.1"/>
      <geom contype="0" conaffinity="0" group="1" solref="-1000 -80"/>
      <site size="0.01 0.005 0.005" group="5"/>
      <general forcelimited="true" biastype="affine" gainprm="30" biasprm="0 -30 -0.5"/>
      <default class="foot">
        <geom size="0.099 0.0178 0.021" type="box" condim="6" group="4" priority="1" solimp="0.015 1 0.021"/>
      </default>
      <default class="reward_collision_sphere">
        <geom group="5" rgba="1 0 0 1"/>
      </default>
    </default>
  </default>

  <asset>
    <texture type="skybox" colorspace="auto" name="//unnamed_texture_0" builtin="gradient" rgb1="0.95 0.95 0.95" rgb2="0.95 0.95 0.95" width="100" height="600"/>
    <texture type="2d" colorspace="auto" name="texplane" builtin="checker" rgb1="0.345 0.575 0.748" rgb2="0.345 0.575 0.748" markrgb="1 1 1" width="512" height="512"/>
    <material name="MatPlane" class="/" texture="texplane" texuniform="true" texrepeat="2 2" specular="0.9"/>
    <mesh name="torso" class="/" file="torso.stl" scale="0.001 0.001 0.001"/>
    <mesh name="left_hip_yaw" class="/" file="left_hip_yaw.stl" scale="0.001 0.001 0.001"/>
    <mesh name="left_hip_abad" class="/" file="left_hip_abad.stl" scale="0.001 0.001 0.001"/>
    <mesh name="left_leg_upper" class="/" file="left_leg_upper.stl" scale="0.001 0.001 0.001"/>
    <mesh name="left_leg_lower" class="/" file="left_leg_lower.stl" scale="0.001 0.001 0.001"/>
    <mesh name="left_foot" class="/" file="left_foot.stl" scale="0.001 0.001 0.001"/>
    <mesh name="left_hip_yaw1" class="/" content_type="model/stl" file="left_hip_yaw.stl" scale="0.001 -0.001 0.001"/>
    <mesh name="left_hip_abad1" class="/" content_type="model/stl" file="left_hip_abad.stl" scale="0.001 -0.001 0.001"/>
    <mesh name="left_leg_upper1" class="/" content_type="model/stl" file="left_leg_upper.stl" scale="0.001 -0.001 0.001"/>
    <mesh name="left_leg_lower1" class="/" content_type="model/stl" file="left_leg_lower.stl" scale="0.001 -0.001 0.001"/>
    <mesh name="left_foot1" class="/" content_type="model/stl" file="left_foot.stl" scale="0.001 -0.001 0.001"/>
    <mesh name="left_shoulder1" class="/" file="left_shoulder1.stl" scale="0.001 0.001 0.001"/>
    <mesh name="left_shoulder2" class="/" file="left_shoulder2.stl" scale="0.001 0.001 0.001"/>
    <mesh name="left_shoulder3" class="/" file="left_shoulder3.stl" scale="0.001 0.001 0.001"/>
    <mesh name="left_forearm" class="/" file="left_forearm.stl" scale="0.001 0.001 0.001"/>
    <mesh name="left_shoulder11" class="/" content_type="model/stl" file="left_shoulder1.stl" scale="0.001 -0.001 0.001"/>
    <mesh name="left_shoulder21" class="/" content_type="model/stl" file="left_shoulder2.stl" scale="0.001 -0.001 0.001"/>
    <mesh name="left_shoulder31" class="/" content_type="model/stl" file="left_shoulder3.stl" scale="0.001 -0.001 0.001"/>
  </asset>

  <worldbody>
    <geom name="floor" class="/" size="100 100 0.125" type="plane" group="0" material="MatPlane"/>
    <light name="toplight_shadow" class="/" pos="0 0 5" dir="0.0990148 0.0990148 -0.990148" type="directional" ambient="0.04 0.04 0.04" diffuse="0.55 0.55 0.55" specular="0.12 0.12 0.12"/>
    <light name="toplight_fill" class="/" pos="0 0 5" dir="0.0990148 0.0990148 -0.990148" type="directional" castshadow="false" ambient="0.04 0.04 0.04" diffuse="0.3 0.3 0.3" specular="0.08 0.08 0.08"/>
    <body name="trunk" pos="-0.00180614 -0.00049162 -0.0013297" quat="1 -0.000128324 0.000207914 -0.000275916">
      <inertial pos="0.012223 0.00251768 0.088865" quat="0.999916 0.00606021 -0.0114544 -1.21496e-05" mass="7.32546" diaginertia="0.206531 0.372869 0.00718866"/>
      <joint name="//unnamed_joint_0" type="free"/>
      <geom name="//unnamed_geom_1" class="/" type="mesh" density="0" rgba="0.752941 0.752941 0.752941 1" mesh="torso"/>
      <geom name="//unnamed_geom_2" class="/" size="0.0739443 0.147889 0.172537" pos="0.0242389 0 0.048187" type="box" group="3" rgba="0.752941 0.752941 0.752941 1"/>
      <geom name="//unnamed_geom_3" class="reward_collision_sphere" size="0.142959" pos="0 0 0.0903507"/>
      <site name="imu" class="/" pos="0.0129379 -0.00345516 0.0808197" size="0.00985924"/>
      <camera name="track" class="/" pos="0 -2.60314 0" quat="0.707107 0.707107 0 0" mode="trackcom"/>
      <camera name="ego_camera" class="/" pos="0.0474239 0 0.180701" quat="-0.5 -0.5 0.5 0.5"/>
      <body name="left_hip_yaw" pos="-0.0022998 0.104578 -7.99757e-05" quat="0.996206 -0.000539265 -0.0870294 -9.45464e-05">
        <inertial pos="-0.0679693 -0.000848435 -0.0365472" quat="0.950424 -0.00931488 -0.310749 0.00649795" mass="0.809193" diaginertia="0.00238272 0.00495072 5.82832e-05"/>
        <joint name="left_hip_yaw" class="/" pos="0 0 0" axis="0.0050376 0.0131652 -0.999901" stiffness="0.0150724" range="-2.95024 3.05242" armature="0.00994585" damping="0" frictionloss="0.103461"/>
        <geom name="//unnamed_geom_4" class="/" type="mesh" density="0" rgba="0.2 0.2 0.2 1" mesh="left_hip_yaw"/>
        <body name="left_hip_abad" pos="-0.068375 0.0028033 -0.0429786" quat="0.976495 -0.000169886 0.21554 -0.000329224">
          <inertial pos="0.0693498 -0.01683 -0.00174752" quat="0.584347 0.405778 0.406722 0.573114" mass="1.1202" diaginertia="0.00435723 0.00734773 0.000138153"/>
          <joint name="left_hip_abad" class="/" pos="0 0 0" axis="-0.99993 0.00869825 0.00796009" stiffness="0.00855239" range="-3.00279 3.04501" armature="0.010294" damping="0.0174363" frictionloss="0.0941507"/>
          <geom name="//unnamed_geom_5" class="/" type="mesh" density="0" rgba="0.2 0.2 0.2 1" mesh="left_hip_abad"/>
          <body name="left_upper_leg" pos="0.0920144 -0.00637879 -0.00900153" quat="0.991421 -0.000107762 -0.130705 0.000654634">
            <inertial pos="0.000425048 0.034428 -0.0466836" quat="0.729992 0.0360872 -0.0460092 0.680949" mass="2.61793" diaginertia="0.0346277 0.0919898 0.000276931"/>
            <joint name="left_hip_pitch" class="/" pos="0 0 0" axis="0.00427028 0.999903 -0.0132316" stiffness="0.00767793" range="-3.00223 2.97661" armature="0.0100985" damping="0.0102387" frictionloss="0.0997024"/>
            <geom name="//unnamed_geom_6" class="/" type="mesh" density="0" rgba="0.752941 0.752941 0.752941 1" mesh="left_leg_upper"/>
            <geom name="//unnamed_geom_7" class="reward_collision_sphere" size="0.0690147" pos="-0.015808 0.0195236 0.00903507"/>
            <geom name="//unnamed_geom_8" class="reward_collision_sphere" size="0.0197185" pos="-0.0843092 -0.0390471 0.048187"/>
            <body name="left_lower_leg" pos="-0.0145609 -0.00017817 -0.151428" quat="1 -7.44533e-05 -3.90047e-05 0.000532262">
              <inertial pos="0.00585778 -0.000382665 -0.0765949" quat="0.998859 0.00549038 -0.0152719 0.0449131" mass="0.324867" diaginertia="0.00372266 0.0112658 1.86164e-05"/>
              <joint name="left_knee" class="/" pos="0 0 0" axis="0.000656597 0.999999 -0.00135715" stiffness="0.00889254" range="0.0212248 3.01235" armature="0.00863618" damping="0.00783716" frictionloss="0.097272"/>
              <geom name="//unnamed_geom_9" class="/" type="mesh" density="0" rgba="0.752941 0.752941 0.752941 1" mesh="left_leg_lower"/>
              <geom name="//unnamed_geom_10" class="reward_collision_sphere" size="0.0423948"/>
              <body name="left_foot" pos="-0.00177982 -0.00211066 -0.16881" quat="0.999999 2.5029e-05 -0.00135391 0.000381172">
                <inertial pos="0.0209968 -0.00207889 -0.0108757" quat="0.520128 0.474651 0.478127 0.524945" mass="0.269037" diaginertia="0.0360522 0.103654 0.00217794"/>
                <joint name="left_ankle" class="/" pos="0 0 0" axis="-0.00566892 0.999936 -0.00980972" stiffness="0.00528663" range="-1.49188 1.48795" armature="0.00857482" damping="0.0132507" frictionloss="0.0991587"/>
                <geom name="//unnamed_geom_11" class="/" type="mesh" density="0" rgba="0.2 0.2 0.2 1" mesh="left_foot"/>
                <geom name="left_foot" class="foot" size="0.091955 0.0172876 0.0215233" pos="0.0295082 0 -0.0150584" quat="0.707109 0.707105 0 0"/>
                <geom name="//unnamed_geom_13" class="reward_collision_sphere" size="0.0246481" pos="0.0295082 0 -0.0120468"/>
                <geom name="//unnamed_geom_14" class="reward_collision_sphere" size="0.0246481" pos="0.105386 0 -0.0150584"/>
                <geom name="//unnamed_geom_15" class="reward_collision_sphere" size="0.0246481" pos="-0.0474239 0 -0.0150584"/>
                <site name="left_foot" class="foot" pos="0.0295082 0 -0.0150584" quat="0.707109 0.707105 0 0" size="0.00985924"/>
              </body>
            </body>
          </body>
        </body>
      </body>
      <body name="right_hip_yaw" pos="0.000173636 -0.109108 0.000710097" quat="0.996254 0.000869218 -0.0864678 0.000244252">
        <inertial pos="-0.0698046 -0.00116234 -0.0389765" quat="0.949303 -0.0126673 0.314032 -0.00689705" mass="0.817573" diaginertia="0.00252439 0.00525046 6.19563e-05"/>
        <joint name="right_hip_yaw" class="/" pos="0 0 0" axis="0.000644533 -0.00175875 -0.999998" stiffness="0.0108874" range="-2.97984 2.99889" armature="0.0098645" damping="0.00676072" frictionloss="0.0848102"/>
        <geom name="//unnamed_geom_16" class="/" type="mesh" density="0" rgba="0.2 0.2 0.2 1" mesh="left_hip_yaw1"/>
        <body name="right_hip_abad" pos="-0.0661282 -0.00116622 -0.0442011" quat="0.976295 1.87916e-06 0.216445 1.34088e-06">
          <inertial pos="0.0730833 0.0165876 -0.0014596" quat="0.40433 0.576945 0.573315 0.418284" mass="1.19483" diaginertia="0.00444715 0.00755652 0.000140556"/>
          <joint name="right_hip_abad" class="/" pos="0 0 0" axis="-1 -2.55495e-05 9.03792e-05" stiffness="0.00120532" range="-3.03218 3.03094" armature="0.00965336" damping="0.0100452" frictionloss="0.109475"/>
          <geom name="//unnamed_geom_17" class="/" type="mesh" density="0" rgba="0.2 0.2 0.2 1" mesh="left_hip_abad1"/>
          <body name="right_upper_leg" pos="0.091398 0.00227829 -0.0109823" quat="0.991419 0.000249102 -0.130725 -0.000125492">
            <inertial pos="-0.00104044 -0.031334 -0.0482913" quat="0.681054 0.0486051 -0.0345933 0.729799" mass="2.63779" diaginertia="0.0355671 0.0919829 0.000289124"/>
            <joint name="right_hip_pitch" class="/" pos="0 0 0" axis="0.00656303 -0.999972 0.00361411" stiffness="0.00811318" range="-3.05646 3.04521" armature="0.00850712" damping="0.0229929" frictionloss="0.0848088"/>
            <geom name="//unnamed_geom_18" class="/" type="mesh" density="0" rgba="0.752941 0.752941 0.752941 1" mesh="left_leg_upper1"/>
            <geom name="//unnamed_geom_19" class="reward_collision_sphere" size="0.0690147" pos="-0.015808 -0.0195236 0.00903507"/>
            <geom name="//unnamed_geom_20" class="reward_collision_sphere" size="0.0197185" pos="-0.0843092 0.0390471 0.048187"/>
            <body name="right_lower_leg" pos="-0.0173262 -0.000182625 -0.149412" quat="1 -0.000326345 5.82405e-05 -0.000176315">
              <inertial pos="0.00607466 -0.000386882 -0.0803099" quat="0.998187 0.00122849 0.0238028 -0.0552725" mass="0.35482" diaginertia="0.00407272 0.0111601 1.9489e-05"/>
              <joint name="right_knee" class="/" pos="0 0 0" axis="1.14471e-05 -1 -3.00781e-05" range="-2.95995 -0.00735636" armature="0.00941063" damping="0" frictionloss="0.107658"/>
              <geom name="//unnamed_geom_21" class="/" type="mesh" density="0" rgba="0.752941 0.752941 0.752941 1" mesh="left_leg_lower1"/>
              <geom name="//unnamed_geom_22" class="reward_collision_sphere" size="0.0423948"/>
              <body name="right_foot" pos="0.000420712 -0.00140324 -0.164789" quat="1 0.000103338 -0.000133796 -0.000230636">
                <inertial pos="0.0243519 -0.00207968 -0.00873565" quat="0.476517 0.519412 0.523318 0.478833" mass="0.283661" diaginertia="0.0360849 0.104387 0.00228648"/>
                <joint name="right_ankle" class="/" pos="0 0 0" axis="0.000702619 -1 -5.78328e-05" range="-1.55587 1.45396" armature="0.00995163" damping="0.0201476" frictionloss="0.0993293"/>
                <geom name="//unnamed_geom_23" class="/" type="mesh" density="0" rgba="0.2 0.2 0.2 1" mesh="left_foot1"/>
                <geom name="right_foot" class="foot" size="0.09706 0.0182912 0.0211421" pos="0.0295082 0 -0.0150584" quat="0.707109 0.707105 0 0"/>
                <geom name="//unnamed_geom_25" class="reward_collision_sphere" size="0.0246481" pos="0.0295082 0 -0.0120468"/>
                <geom name="//unnamed_geom_26" class="reward_collision_sphere" size="0.0246481" pos="0.105386 0 -0.0150584"/>
                <geom name="//unnamed_geom_27" class="reward_collision_sphere" size="0.0246481" pos="-0.0474239 0 -0.0150584"/>
                <site name="right_foot" class="foot" pos="0.0295082 0 -0.0150584" quat="0.707109 0.707105 0 0" size="0.00985924"/>
              </body>
            </body>
          </body>
        </body>
      </body>
      <body name="left_shoulder" pos="0.0168815 0.229708 0.182078" quat="1 3.6925e-05 0.000148663 7.58354e-05">
        <inertial pos="0.00728984 0.0681847 -0.00211579" quat="0.703661 0.710376 0.00846664 0.0124636" mass="0.73724" diaginertia="0.00176177 0.00323075 5.83433e-05"/>
        <joint name="left_shoulder_pitch" class="/" pos="0 0 0" axis="-0.00608426 0.999981 0.000853527" range="-2.99073 2.95396" armature="0.00938174" damping="0.0108608" frictionloss="0.108352"/>
        <geom name="//unnamed_geom_28" class="/" type="mesh" density="0" rgba="0.2 0.2 0.2 1" mesh="left_shoulder1"/>
        <body name="left_shoulder_2" pos="-1.6628e-05 0.0735995 0.00228567" quat="1 -7.44647e-05 -7.40269e-05 -2.77194e-05">
          <inertial pos="-0.00252652 0.000303366 -0.0507723" quat="0.0165873 0.75461 -0.00336635 0.655956" mass="0.77523" diaginertia="0.0016596 0.00436976 9.01774e-05"/>
          <joint name="left_shoulder_abad" class="/" pos="0 0 0" axis="-0.999986 -0.00288254 0.00443904" stiffness="0.0021791" range="-2.95384 2.94547" armature="0.0111359" damping="0.0239461" frictionloss="0.0985333"/>
          <geom name="//unnamed_geom_29" class="/" type="mesh" density="0" rgba="0.752941 0.752941 0.752941 1" mesh="left_shoulder2"/>
          <body name="left_upper_arm" pos="-0.00263486 0.000137301 -0.0594759" quat="1 -0.000125373 -0.000259124 -4.95881e-05">
            <inertial pos="0.0026979 -0.0213532 -0.0390921" quat="0.713128 -0.022154 0.0170574 0.700476" mass="0.889799" diaginertia="0.00234929 0.00530259 6.60212e-05"/>
            <joint name="left_shoulder_yaw" class="/" pos="0 0 0" axis="-0.0092837 -0.007983 0.999925" range="-2.99688 3.04951" armature="0.0110336" damping="0.002682" frictionloss="0.0906939"/>
            <geom name="//unnamed_geom_30" class="/" type="mesh" density="0" rgba="0.752941 0.752941 0.752941 1" mesh="left_shoulder3"/>
            <geom name="//unnamed_geom_31" class="reward_collision_sphere" size="0.0591555" pos="-0.0105386 -0.0130157 -0.0301169"/>
            <body name="left_lower_arm" pos="-0.00178927 -0.00200299 -0.0960064" quat="1 -3.87343e-07 -1.13561e-06 5.98769e-07">
              <inertial pos="-0.00992876 -0.000386346 -0.0597958" quat="0.708986 0.00443 1.15429e-05 0.705208" mass="0.338835" diaginertia="0.00462206 0.0137035 6.27694e-06"/>
              <joint name="left_elbow" class="/" pos="0 0 0" axis="-0.00630273 0.999957 -0.00680151" stiffness="0.0173359" range="-2.95163 2.98046" armature="0.0100048" damping="0.00613081" frictionloss="0.0993697"/>
              <geom name="//unnamed_geom_32" class="/" type="mesh" density="0" rgba="0.752941 0.752941 0.752941 1" mesh="left_forearm"/>
              <geom name="//unnamed_geom_33" class="/" size="0.0246481 0.00739443" pos="0 0 -0.162631" quat="0.707109 0.707105 0 0" type="cylinder" group="3"/>
              <geom name="//unnamed_geom_34" class="reward_collision_sphere" size="0.0246481"/>
              <geom name="//unnamed_geom_35" class="reward_collision_sphere" size="0.0216903" pos="0 0 -0.168655"/>
            </body>
          </body>
        </body>
      </body>
      <body name="right_shoulder" pos="0.0181577 -0.231432 0.180106" quat="1 -0.000359511 7.57329e-05 -8.22179e-05">
        <inertial pos="0.0086725 -0.0717129 0.000277271" quat="0.709982 0.704018 -0.0127307 -0.0110362" mass="0.744596" diaginertia="0.00185215 0.00329489 6.26116e-05"/>
        <joint name="right_shoulder_pitch" class="/" pos="0 0 0" axis="0.000626725 -0.999999 -0.000790036" stiffness="0.0125277" range="-2.96592 2.97177" armature="0.00966706" damping="0.0222074" frictionloss="0.109565"/>
        <geom name="//unnamed_geom_36" class="/" type="mesh" density="0" rgba="0.2 0.2 0.2 1" mesh="left_shoulder11"/>
        <body name="right_shoulder_2" pos="-0.00390507 -0.0757617 0.000695543" quat="1 -0.000481126 0.000301113 0.000357326">
          <inertial pos="-0.000292458 -0.00289265 -0.0487946" quat="-0.010691 0.655133 0.00431696 0.755426" mass="0.750644" diaginertia="0.00162163 0.00431713 9.31114e-05"/>
          <joint name="right_shoulder_abad" class="/" pos="0 0 0" axis="-0.999964 0.00840584 -0.00150907" stiffness="0.0110833" range="-2.99051 3.00708" armature="0.0101946" damping="0.00408446" frictionloss="0.0977467"/>
          <geom name="//unnamed_geom_37" class="/" type="mesh" density="0" rgba="0.752941 0.752941 0.752941 1" mesh="left_shoulder21"/>
          <body name="right_upper_arm" pos="0.0011788 -0.00214111 -0.0631581" quat="0.999999 -0.000766432 0.00103632 0.000252761">
            <inertial pos="0.000339953 0.0235252 -0.0380146" quat="0.700633 -0.0213148 0.0294502 0.712596" mass="0.857295" diaginertia="0.00233475 0.00503126 6.21366e-05"/>
            <joint name="right_shoulder_yaw" class="/" pos="0 0 0" axis="0.00635662 -0.00943291 0.999935" stiffness="0.0106056" range="-2.98376 3.00225" armature="0.00961539" damping="0.0147397" frictionloss="0.0928679"/>
            <geom name="//unnamed_geom_38" class="/" type="mesh" density="0" rgba="0.752941 0.752941 0.752941 1" mesh="left_shoulder31"/>
            <geom name="//unnamed_geom_39" class="reward_collision_sphere" size="0.0591555" pos="-0.0105386 0.0130157 -0.0301169"/>
            <body name="right_lower_arm" pos="-0.00284007 0.000235967 -0.0977874" quat="1 -0.000368244 7.13245e-06 0.000803473">
              <inertial pos="-0.0096196 4.37165e-05 -0.0583815" quat="0.70295 0.0150662 0.0109071 0.710996" mass="0.345287" diaginertia="0.0049111 0.0138747 6.3016e-06"/>
              <joint name="right_elbow" class="/" pos="0 0 0" axis="0.00345314 -0.999993 -0.00164785" range="-3.01362 2.9943" armature="0.0104754" damping="0" frictionloss="0.0990391"/>
              <geom name="//unnamed_geom_40" class="/" type="mesh" density="0" rgba="0.752941 0.752941 0.752941 1" mesh="left_forearm"/>
              <geom name="//unnamed_geom_41" class="/" size="0.0246481 0.00739443" pos="0 0 -0.162631" quat="0.707109 0.707105 0 0" type="cylinder" group="3"/>
              <geom name="//unnamed_geom_42" class="reward_collision_sphere" size="0.0246481"/>
              <geom name="//unnamed_geom_43" class="reward_collision_sphere" size="0.0216903" pos="0 0 -0.168655"/>
            </body>
          </body>
        </body>
      </body>
    </body>
  </worldbody>

  <contact>
    <pair class="/" geom1="floor" geom2="left_foot" name="//unnamed_contact_0"/>
    <pair class="/" geom1="floor" geom2="right_foot" name="//unnamed_contact_1"/>
  </contact>

  <actuator>
    <general name="left_hip_yaw" class="/" joint="left_hip_yaw" forcerange="-32.593 32.593" gainprm="33.0512" biasprm="0 -33.0512 -0.499267"/>
    <general name="left_hip_abad" class="/" joint="left_hip_abad" forcerange="-30.6568 30.6568" gainprm="33.0512" biasprm="0 -33.0512 -0.499267"/>
    <general name="left_hip_pitch" class="/" joint="left_hip_pitch" forcerange="-63.1061 63.1061" gainprm="33.0512" biasprm="0 -33.0512 -0.499267"/>
    <general name="left_knee" class="/" joint="left_knee" forcerange="-129.29 129.29" gainprm="33.0512" biasprm="0 -33.0512 -0.499267"/>
    <general name="left_ankle" class="/" joint="left_ankle" forcerange="-63.7986 63.7986" gainprm="33.0512" biasprm="0 -33.0512 -0.499267"/>
    <general name="right_hip_yaw" class="/" joint="right_hip_yaw" forcerange="-33.879 33.879" gainprm="33.0512" biasprm="0 -33.0512 -0.499267"/>
    <general name="right_hip_abad" class="/" joint="right_hip_abad" forcerange="-34.9355 34.9355" gainprm="33.0512" biasprm="0 -33.0512 -0.499267"/>
    <general name="right_hip_pitch" class="/" joint="right_hip_pitch" forcerange="-74.3287 74.3287" gainprm="33.0512" biasprm="0 -33.0512 -0.499267"/>
    <general name="right_knee" class="/" joint="right_knee" forcerange="-125.939 125.939" gainprm="33.0512" biasprm="0 -33.0512 -0.499267"/>
    <general name="right_ankle" class="/" joint="right_ankle" forcerange="-72.5456 72.5456" gainprm="33.0512" biasprm="0 -33.0512 -0.499267"/>
    <general name="left_shoulder_pitch" class="/" joint="left_shoulder_pitch" forcerange="-33.4593 33.4593" gainprm="33.0512" biasprm="0 -33.0512 -0.499267"/>
    <general name="left_shoulder_abad" class="/" joint="left_shoulder_abad" forcerange="-33.9764 33.9764" gainprm="33.0512" biasprm="0 -33.0512 -0.499267"/>
    <general name="left_shoulder_yaw" class="/" joint="left_shoulder_yaw" forcerange="-34.1526 34.1526" gainprm="33.0512" biasprm="0 -33.0512 -0.499267"/>
    <general name="left_elbow" class="/" joint="left_elbow" forcerange="-49.015 49.015" gainprm="33.0512" biasprm="0 -33.0512 -0.499267"/>
    <general name="right_shoulder_pitch" class="/" joint="right_shoulder_pitch" forcerange="-32.2637 32.2637" gainprm="33.0512" biasprm="0 -33.0512 -0.499267"/>
    <general name="right_shoulder_abad" class="/" joint="right_shoulder_abad" forcerange="-33.5553 33.5553" gainprm="33.0512" biasprm="0 -33.0512 -0.499267"/>
    <general name="right_shoulder_yaw" class="/" joint="right_shoulder_yaw" forcerange="-34.7089 34.7089" gainprm="33.0512" biasprm="0 -33.0512 -0.499267"/>
    <general name="right_elbow" class="/" joint="right_elbow" forcerange="-52.9319 52.9319" gainprm="33.0512" biasprm="0 -33.0512 -0.499267"/>
  </actuator>

  <sensor>
    <gyro site="imu" name="imu_angular_velocity"/>
    <velocimeter site="imu" name="imu_linear_velocity"/>
    <framelinvel objtype="site" objname="left_foot" name="left_foot_global_linear_velocity"/>
    <framelinvel objtype="site" objname="right_foot" name="right_foot_global_linear_velocity"/>
  </sensor>

  <keyframe>
    <key name="home" qpos="0 0 0.656 1 0 0 0 0 0 -0.4 0.8 -0.4 0 0 0.4 -0.8 0.4 0 -0.05 0 -0.75 0 0.05 0 0.75"/>
  </keyframe>
</mujoco>
