<mujoco model="humanoid">
  <compiler angle="radian" assetdir="assets" balanceinertia="true" inertiafromgeom="false"/>

  <option timestep="0.005" density="1.2" viscosity="2e-05"/>

  <size nkey="1"/>

  <visual>
    <quality shadowsize="8192"/>
    <map shadowclip="0.5"/>
  </visual>

  <default>
    <default class="/">
      <joint armature="0.01" damping="0.01" frictionloss="0.1"/>
      <geom contype="0" conaffinity="0" group="1" solref="-1000 -80"/>
      <site size="0.01 0.005 0.005" group="5"/>
      <general forcelimited="true" biastype="affine" gainprm="30" biasprm="0 -30 -0.5"/>
      <default class="foot">
        <geom size="0.099 0.0178 0.021" type="box" condim="6" group="4" priority="1" solimp="0.015 1 0.021"/>
      </default>
      <default class="reward_collision_sphere">
        <geom group="5" rgba="1 0 0 1"/>
      </default>
    </default>
  </default>

  <asset>
    <texture type="skybox" colorspace="auto" name="//unnamed_texture_0" builtin="gradient" rgb1="0.95 0.95 0.95" rgb2="0.95 0.95 0.95" width="100" height="600"/>
    <texture type="2d" colorspace="auto" name="texplane" builtin="checker" rgb1="0.345 0.575 0.748" rgb2="0.345 0.575 0.748" markrgb="1 1 1" width="512" height="512"/>
    <material name="MatPlane" class="/" texture="texplane" texuniform="true" texrepeat="2 2" specular="0.9"/>
    <mesh name="torso" class="/" file="torso.stl" scale="0.001 0.001 0.001"/>
    <mesh name="left_hip_yaw" class="/" file="left_hip_yaw.stl" scale="0.001 0.001 0.001"/>
    <mesh name="left_hip_abad" class="/" file="left_hip_abad.stl" scale="0.001 0.001 0.001"/>
    <mesh name="left_leg_upper" class="/" file="left_leg_upper.stl" scale="0.001 0.001 0.001"/>
    <mesh name="left_leg_lower" class="/" file="left_leg_lower.stl" scale="0.001 0.001 0.001"/>
    <mesh name="left_foot" class="/" file="left_foot.stl" scale="0.001 0.001 0.001"/>
    <mesh name="left_hip_yaw1" class="/" content_type="model/stl" file="left_hip_yaw.stl" scale="0.001 -0.001 0.001"/>
    <mesh name="left_hip_abad1" class="/" content_type="model/stl" file="left_hip_abad.stl" scale="0.001 -0.001 0.001"/>
    <mesh name="left_leg_upper1" class="/" content_type="model/stl" file="left_leg_upper.stl" scale="0.001 -0.001 0.001"/>
    <mesh name="left_leg_lower1" class="/" content_type="model/stl" file="left_leg_lower.stl" scale="0.001 -0.001 0.001"/>
    <mesh name="left_foot1" class="/" content_type="model/stl" file="left_foot.stl" scale="0.001 -0.001 0.001"/>
    <mesh name="left_shoulder1" class="/" file="left_shoulder1.stl" scale="0.001 0.001 0.001"/>
    <mesh name="left_shoulder2" class="/" file="left_shoulder2.stl" scale="0.001 0.001 0.001"/>
    <mesh name="left_shoulder3" class="/" file="left_shoulder3.stl" scale="0.001 0.001 0.001"/>
    <mesh name="left_forearm" class="/" file="left_forearm.stl" scale="0.001 0.001 0.001"/>
    <mesh name="left_shoulder11" class="/" content_type="model/stl" file="left_shoulder1.stl" scale="0.001 -0.001 0.001"/>
    <mesh name="left_shoulder21" class="/" content_type="model/stl" file="left_shoulder2.stl" scale="0.001 -0.001 0.001"/>
    <mesh name="left_shoulder31" class="/" content_type="model/stl" file="left_shoulder3.stl" scale="0.001 -0.001 0.001"/>
  </asset>

  <worldbody>
    <geom name="floor" class="/" size="100 100 0.125" type="plane" group="0" material="MatPlane"/>
    <light name="toplight_shadow" class="/" pos="0 0 5" dir="0.0990148 0.0990148 -0.990148" type="directional" ambient="0.04 0.04 0.04" diffuse="0.55 0.55 0.55" specular="0.12 0.12 0.12"/>
    <light name="toplight_fill" class="/" pos="0 0 5" dir="0.0990148 0.0990148 -0.990148" type="directional" castshadow="false" ambient="0.04 0.04 0.04" diffuse="0.3 0.3 0.3" specular="0.08 0.08 0.08"/>
    <body name="trunk" pos="-0.00275582 0.000329845 -0.00280361" quat="1 0.000227329 -0.000130655 -8.24193e-05">
      <inertial pos="0.0103439 0.00403944 0.110843" quat="0.999994 0.00206742 -0.000822697 -0.00251998" mass="8.02763" diaginertia="0.216034 0.276853 0.0215986"/>
      <joint name="//unnamed_joint_0" type="free"/>
      <geom name="//unnamed_geom_1" class="/" type="mesh" density="0" rgba="0.752941 0.752941 0.752941 1" mesh="torso"/>
      <geom name="//unnamed_geom_2" class="/" size="0.0758476 0.151695 0.176978" pos="0.0242498 0 0.0597164" type="box" group="3" rgba="0.752941 0.752941 0.752941 1"/>
      <geom name="//unnamed_geom_3" class="reward_collision_sphere" size="0.146639" pos="0 0 0.111968"/>
      <site name="imu" class="/" pos="0.0112039 0.0113636 0.0983193" size="0.010113"/>
      <camera name="track" class="/" pos="0 -2.46621 0" quat="0.707107 0.707107 0 0" mode="trackcom"/>
      <camera name="ego_camera" class="/" pos="0.0474453 0 0.223936" quat="-0.5 -0.5 0.5 0.5"/>
      <body name="left_hip_yaw" pos="-0.00401548 0.101435 0.00207666" quat="0.996258 -3.3812e-05 -0.0864273 -0.000945538">
        <inertial pos="-0.0672159 -0.00299791 -0.0456699" quat="0.952223 0.00203694 -0.305393 -0.00148668" mass="0.838456" diaginertia="0.00237116 0.00374561 0.000172854"/>
        <joint name="left_hip_yaw" class="/" pos="0 0 0" axis="0.00928324 0.0064377 -0.999936" stiffness="0.00637555" range="-2.94671 3.00854" armature="0.00897543" damping="0.00334019" frictionloss="0.100471"/>
        <geom name="//unnamed_geom_4" class="/" type="mesh" density="0" rgba="0.2 0.2 0.2 1" mesh="left_hip_yaw"/>
        <body name="left_hip_abad" pos="-0.0669794 0.000719954 -0.0539261" quat="0.976383 -0.00014562 0.216044 -0.00101657">
          <inertial pos="0.072574 -0.0160545 0.000516284" quat="0.579981 0.404214 0.412513 0.574513" mass="1.27531" diaginertia="0.0043087 0.00562996 0.000397954"/>
          <joint name="left_hip_abad" class="/" pos="0 0 0" axis="-0.99996 -0.000877541 0.00895484" range="-3.0008 3.00019" armature="0.0090108" damping="0.0064132" frictionloss="0.100132"/>
          <geom name="//unnamed_geom_5" class="/" type="mesh" density="0" rgba="0.2 0.2 0.2 1" mesh="left_hip_abad"/>
          <body name="left_upper_leg" pos="0.0914044 -0.00531537 -0.0136393" quat="0.991448 -1.10932e-05 -0.130499 7.96684e-06">
            <inertial pos="-0.00283852 0.0327247 -0.0560307" quat="0.727536 0.0312077 -0.050824 0.683472" mass="2.79497" diaginertia="0.0341578 0.0697352 0.000806542"/>
            <joint name="left_hip_pitch" class="/" pos="0 0 0" axis="0.0143163 0.999885 -0.00494469" range="-2.99808 2.94287" armature="0.00994338" damping="0.00223134" frictionloss="0.0958461"/>
            <geom name="//unnamed_geom_6" class="/" type="mesh" density="0" rgba="0.752941 0.752941 0.752941 1" mesh="left_leg_upper"/>
            <geom name="//unnamed_geom_7" class="reward_collision_sphere" size="0.0707911" pos="-0.0158151 0.0184966 0.0111968"/>
            <geom name="//unnamed_geom_8" class="reward_collision_sphere" size="0.020226" pos="-0.0843473 -0.0369932 0.0597164"/>
            <body name="left_lower_leg" pos="-0.0131227 0.000560464 -0.189061" quat="0.999999 0.000307668 -0.000614132 0.000851435">
              <inertial pos="0.00550281 0.000310003 -0.0959527" quat="0.998868 0.00582429 -0.0156185 0.0445603" mass="0.357064" diaginertia="0.00385423 0.00843024 5.45382e-05"/>
              <joint name="left_knee" class="/" pos="0 0 0" axis="0.000527203 1 -0.00083073" range="-0.020225 3.00863" armature="0.00979951" damping="0.00842657" frictionloss="0.102142"/>
              <geom name="//unnamed_geom_9" class="/" type="mesh" density="0" rgba="0.752941 0.752941 0.752941 1" mesh="left_leg_lower"/>
              <geom name="//unnamed_geom_10" class="reward_collision_sphere" size="0.0434859"/>
              <body name="left_foot" pos="0.000586917 -0.00197278 -0.20724" quat="1 -0.000270814 -0.000665919 -0.000540373">
                <inertial pos="0.0221007 0.000324286 -0.011989" quat="0.51146 0.478062 0.477863 0.530578" mass="0.300033" diaginertia="0.0376139 0.079374 0.00646332"/>
                <joint name="left_ankle" class="/" pos="0 0 0" axis="-0.00326039 0.999994 0.00134732" stiffness="0.00031092" range="-1.51104 1.4858" armature="0.00914802" damping="0.0056166" frictionloss="0.114261"/>
                <geom name="//unnamed_geom_11" class="/" type="mesh" density="0" rgba="0.2 0.2 0.2 1" mesh="left_foot"/>
                <geom name="left_foot" class="foot" size="0.0977917 0.0158971 0.0206107" pos="0.0295215 0 -0.0186614" quat="0.707109 0.707105 0 0"/>
                <geom name="//unnamed_geom_13" class="reward_collision_sphere" size="0.0252825" pos="0.0295215 0 -0.0149291"/>
                <geom name="//unnamed_geom_14" class="reward_collision_sphere" size="0.0252825" pos="0.105434 0 -0.0186614"/>
                <geom name="//unnamed_geom_15" class="reward_collision_sphere" size="0.0252825" pos="-0.0474453 0 -0.0186614"/>
                <site name="left_foot" class="foot" pos="0.0295215 0 -0.0186614" quat="0.707109 0.707105 0 0" size="0.010113"/>
              </body>
            </body>
          </body>
        </body>
      </body>
      <body name="right_hip_yaw" pos="-0.00320553 -0.100984 -0.00143273" quat="0.996206 -0.000252614 -0.0870203 0.000215914">
        <inertial pos="-0.0682587 0.000998301 -0.0466266" quat="0.949257 -0.015626 0.314099 -0.00290954" mass="0.871577" diaginertia="0.00254716 0.00389455 0.000185842"/>
        <joint name="right_hip_yaw" class="/" pos="0 0 0" axis="0.010723 -0.00797922 -0.999911" stiffness="0.0145973" range="-3.01942 3.00394" armature="0.0112731" damping="0.00229631" frictionloss="0.0936915"/>
        <geom name="//unnamed_geom_16" class="/" type="mesh" density="0" rgba="0.2 0.2 0.2 1" mesh="left_hip_yaw1"/>
        <body name="right_hip_abad" pos="-0.0664466 -0.00327254 -0.052606" quat="0.976097 -0.000683715 0.217335 -0.000477623">
          <inertial pos="0.0721249 0.0164048 -0.00248655" quat="0.407347 0.581152 0.574854 0.407276" mass="1.24987" diaginertia="0.00436866 0.00573676 0.000402117"/>
          <joint name="right_hip_abad" class="/" pos="0 0 0" axis="-0.999998 -0.0010606 -0.00153464" stiffness="0.0131453" range="-2.9643 3.0547" armature="0.0103018" damping="0.0106984" frictionloss="0.100473"/>
          <geom name="//unnamed_geom_17" class="/" type="mesh" density="0" rgba="0.2 0.2 0.2 1" mesh="left_hip_abad1"/>
          <body name="right_upper_leg" pos="0.0938267 0.00516428 -0.0127496" quat="0.991427 -0.000978126 -0.130656 -0.000341002">
            <inertial pos="-0.00214166 -0.029609 -0.0566383" quat="0.681067 0.0484325 -0.0348158 0.729788" mass="2.73421" diaginertia="0.0357039 0.0704895 0.000802642"/>
            <joint name="right_hip_pitch" class="/" pos="0 0 0" axis="0.00782813 -0.999952 0.00590364" range="-3.03339 3.04847" armature="0.00956317" damping="0.0223915" frictionloss="0.0938948"/>
            <geom name="//unnamed_geom_18" class="/" type="mesh" density="0" rgba="0.752941 0.752941 0.752941 1" mesh="left_leg_upper1"/>
            <geom name="//unnamed_geom_19" class="reward_collision_sphere" size="0.0707911" pos="-0.0158151 -0.0184966 0.0111968"/>
            <geom name="//unnamed_geom_20" class="reward_collision_sphere" size="0.020226" pos="-0.0843473 0.0369932 0.0597164"/>
            <body name="right_lower_leg" pos="-0.016649 0.00229371 -0.18263" quat="1 -0.000261576 4.53932e-05 0.000115247">
              <inertial pos="0.00827671 -0.000499989 -0.0961447" quat="0.998785 0.00712095 0.0223631 -0.0433405" mass="0.373898" diaginertia="0.00394081 0.00831436 5.56906e-05"/>
              <joint name="right_knee" class="/" pos="0 0 0" axis="0.00354901 -0.99998 0.00521679" range="-3.00525 0.00215277" armature="0.0101196" damping="0.00616628" frictionloss="0.115058"/>
              <geom name="//unnamed_geom_21" class="/" type="mesh" density="0" rgba="0.752941 0.752941 0.752941 1" mesh="left_leg_lower1"/>
              <geom name="//unnamed_geom_22" class="reward_collision_sphere" size="0.0434859"/>
              <body name="right_foot" pos="0.00112368 0.000936168 -0.207579" quat="1 7.87439e-05 3.81775e-06 -4.18766e-05">
                <inertial pos="0.0248199 0.000224435 -0.0130674" quat="0.473565 0.523363 0.528217 0.472031" mass="0.30633" diaginertia="0.0364513 0.0785065 0.00651921"/>
                <joint name="right_ankle" class="/" pos="0 0 0" axis="2.58886e-05 -1 -2.72757e-05" stiffness="0.00242572" range="-1.54422 1.49935" armature="0.0101575" damping="0.0242452" frictionloss="0.101023"/>
                <geom name="//unnamed_geom_23" class="/" type="mesh" density="0" rgba="0.2 0.2 0.2 1" mesh="left_foot1"/>
                <geom name="right_foot" class="foot" size="0.104898 0.0172749 0.0232349" pos="0.0295215 0 -0.0186614" quat="0.707109 0.707105 0 0"/>
                <geom name="//unnamed_geom_25" class="reward_collision_sphere" size="0.0252825" pos="0.0295215 0 -0.0149291"/>
                <geom name="//unnamed_geom_26" class="reward_collision_sphere" size="0.0252825" pos="0.105434 0 -0.0186614"/>
                <geom name="//unnamed_geom_27" class="reward_collision_sphere" size="0.0252825" pos="-0.0474453 0 -0.0186614"/>
                <site name="right_foot" class="foot" pos="0.0295215 0 -0.0186614" quat="0.707109 0.707105 0 0" size="0.010113"/>
              </body>
            </body>
          </body>
        </body>
      </body>
      <body name="left_shoulder" pos="0.0162724 0.21486 0.22785" quat="1 8.81472e-05 0.000175645 0.000106487">
        <inertial pos="0.0085894 0.0658064 -0.00186673" quat="0.710364 0.703568 0.0152297 0.011989" mass="0.783438" diaginertia="0.00178619 0.00246836 0.00016876"/>
        <joint name="left_shoulder_pitch" class="/" pos="0 0 0" axis="0.00531247 0.99997 -0.00559437" range="-3.00363 3.00041" armature="0.0111548" damping="0.00737351" frictionloss="0.114931"/>
        <geom name="//unnamed_geom_28" class="/" type="mesh" density="0" rgba="0.2 0.2 0.2 1" mesh="left_shoulder1"/>
        <body name="left_shoulder_2" pos="-0.000601756 0.0687136 0.00076659" quat="0.999999 0.00121991 -0.000332661 0.000432408">
          <inertial pos="-0.000969016 0.00265447 -0.0596182" quat="0.0142799 0.755705 0.00334674 0.654748" mass="0.862264" diaginertia="0.00167694 0.00336125 0.000256495"/>
          <joint name="left_shoulder_abad" class="/" pos="0 0 0" axis="-0.999987 -0.00162417 -0.00491664" range="-3.00088 2.96233" armature="0.0112629" damping="0.00705296" frictionloss="0.101613"/>
          <geom name="//unnamed_geom_29" class="/" type="mesh" density="0" rgba="0.752941 0.752941 0.752941 1" mesh="left_shoulder2"/>
          <body name="left_upper_arm" pos="-0.00127647 0.0030766 -0.0760815" quat="1 0.000145162 -8.08507e-05 -5.7158e-05">
            <inertial pos="0.00191775 -0.0228234 -0.0473285" quat="0.707092 -0.0238644 0.0234363 0.70633" mass="0.934152" diaginertia="0.00235876 0.00383756 0.000182849"/>
            <joint name="left_shoulder_yaw" class="/" pos="0 0 0" axis="-0.00846596 0.00699608 0.99994" range="-2.94892 3.00645" armature="0.0114477" damping="0" frictionloss="0.104701"/>
            <geom name="//unnamed_geom_30" class="/" type="mesh" density="0" rgba="0.752941 0.752941 0.752941 1" mesh="left_shoulder3"/>
            <geom name="//unnamed_geom_31" class="reward_collision_sphere" size="0.0606781" pos="-0.0105434 -0.0123311 -0.0373227"/>
            <body name="left_lower_arm" pos="-0.000353302 -0.000547471 -0.117227" quat="1 -0.000437618 -0.000177659 -9.73194e-05">
              <inertial pos="-0.00966618 -0.00089883 -0.0746122" quat="0.700756 0.0100783 -0.00410033 0.713318" mass="0.359077" diaginertia="0.00463368 0.0098979 1.7844e-05"/>
              <joint name="left_elbow" class="/" pos="0 0 0" axis="0.00124922 0.999996 0.00251395" stiffness="0.00840375" range="-2.99373 3.00958" armature="0.0102879" damping="0" frictionloss="0.100064"/>
              <geom name="//unnamed_geom_32" class="/" type="mesh" density="0" rgba="0.752941 0.752941 0.752941 1" mesh="left_forearm"/>
              <geom name="//unnamed_geom_33" class="/" size="0.0252825 0.00758476" pos="0 0 -0.201543" quat="0.707109 0.707105 0 0" type="cylinder" group="3"/>
              <geom name="//unnamed_geom_34" class="reward_collision_sphere" size="0.0252825"/>
              <geom name="//unnamed_geom_35" class="reward_collision_sphere" size="0.0222486" pos="0 0 -0.209007"/>
            </body>
          </body>
        </body>
      </body>
      <body name="right_shoulder" pos="0.0218276 -0.217464 0.226105" quat="1 1.75448e-05 -2.35707e-05 5.22349e-05">
        <inertial pos="0.00994238 -0.0677624 -0.000119503" quat="0.718123 0.695638 -0.00877807 -0.0176093" mass="0.815076" diaginertia="0.00178122 0.00245099 0.000180636"/>
        <joint name="right_shoulder_pitch" class="/" pos="0 0 0" axis="0.000669756 -0.999995 0.0031676" range="-2.94695 2.94213" armature="0.00872853" damping="0.0147092" frictionloss="0.114035"/>
        <geom name="//unnamed_geom_36" class="/" type="mesh" density="0" rgba="0.2 0.2 0.2 1" mesh="left_shoulder11"/>
        <body name="right_shoulder_2" pos="-0.000410844 -0.0733053 0.00273914" quat="1 -0.000188952 0.000136963 -0.000131007">
          <inertial pos="-0.00297989 -0.00223464 -0.0638459" quat="0.00297647 0.650566 0.00894748 0.759391" mass="0.809812" diaginertia="0.00163996 0.00327045 0.000271765"/>
          <joint name="right_shoulder_abad" class="/" pos="0 0 0" axis="-0.999993 0.00349183 -0.00167238" range="-3.02087 2.99024" armature="0.0100059" damping="0.0201209" frictionloss="0.0879896"/>
          <geom name="//unnamed_geom_37" class="/" type="mesh" density="0" rgba="0.752941 0.752941 0.752941 1" mesh="left_shoulder21"/>
          <body name="right_upper_arm" pos="0.000644302 -0.000311791 -0.0793809" quat="1 0.000419875 0.000211853 4.45555e-05">
            <inertial pos="-0.00136167 0.0199408 -0.0461534" quat="0.698283 -0.0300091 0.0235578 0.714805" mass="0.932718" diaginertia="0.0022671 0.00375265 0.00017166"/>
            <joint name="right_shoulder_yaw" class="/" pos="0 0 0" axis="0.00163052 8.9674e-05 0.999999" stiffness="0.00118329" range="-2.94568 3.00321" armature="0.0102903" damping="0.0234134" frictionloss="0.0870085"/>
            <geom name="//unnamed_geom_38" class="/" type="mesh" density="0" rgba="0.752941 0.752941 0.752941 1" mesh="left_shoulder31"/>
            <geom name="//unnamed_geom_39" class="reward_collision_sphere" size="0.0606781" pos="-0.0105434 0.0123311 -0.0373227"/>
            <body name="right_lower_arm" pos="-0.00191383 0.000235826 -0.119381" quat="0.999999 0.000257897 -0.000729848 -0.00114223">
              <inertial pos="-0.00742281 5.84071e-05 -0.072312" quat="0.706135 0.00141722 -0.00429238 0.708063" mass="0.361718" diaginertia="0.00493897 0.0105447 1.8768e-05"/>
              <joint name="right_elbow" class="/" pos="0 0 0" axis="0.00963495 -0.999947 0.00356666" range="-2.98884 3.04752" armature="0.00965753" damping="0.00211408" frictionloss="0.0884253"/>
              <geom name="//unnamed_geom_40" class="/" type="mesh" density="0" rgba="0.752941 0.752941 0.752941 1" mesh="left_forearm"/>
              <geom name="//unnamed_geom_41" class="/" size="0.0252825 0.00758476" pos="0 0 -0.201543" quat="0.707109 0.707105 0 0" type="cylinder" group="3"/>
              <geom name="//unnamed_geom_42" class="reward_collision_sphere" size="0.0252825"/>
              <geom name="//unnamed_geom_43" class="reward_collision_sphere" size="0.0222486" pos="0 0 -0.209007"/>
            </body>
          </body>
        </body>
      </body>
    </body>
  </worldbody>

  <contact>
    <pair class="/" geom1="floor" geom2="left_foot" name="//unnamed_contact_0"/>
    <pair class="/" geom1="floor" geom2="right_foot" name="//unnamed_contact_1"/>
  </contact>

  <actuator>
    <general name="left_hip_yaw" class="/" joint="left_hip_yaw" forcerange="-35.0952 35.0952" gainprm="31.5859" biasprm="0 -31.5859 -0.526083"/>
    <general name="left_hip_abad" class="/" joint="left_hip_abad" forcerange="-31.4987 31.4987" gainprm="31.5859" biasprm="0 -31.5859 -0.526083"/>
    <general name="left_hip_pitch" class="/" joint="left_hip_pitch" forcerange="-70.2662 70.2662" gainprm="31.5859" biasprm="0 -31.5859 -0.526083"/>
    <general name="left_knee" class="/" joint="left_knee" forcerange="-146.884 146.884" gainprm="31.5859" biasprm="0 -31.5859 -0.526083"/>
    <general name="left_ankle" class="/" joint="left_ankle" forcerange="-69.1261 69.1261" gainprm="31.5859" biasprm="0 -31.5859 -0.526083"/>
    <general name="right_hip_yaw" class="/" joint="right_hip_yaw" forcerange="-34.1213 34.1213" gainprm="31.5859" biasprm="0 -31.5859 -0.526083"/>
    <general name="right_hip_abad" class="/" joint="right_hip_abad" forcerange="-34.2139 34.2139" gainprm="31.5859" biasprm="0 -31.5859 -0.526083"/>
    <general name="right_hip_pitch" class="/" joint="right_hip_pitch" forcerange="-80.0017 80.0017" gainprm="31.5859" biasprm="0 -31.5859 -0.526083"/>
    <general name="right_knee" class="/" joint="right_knee" forcerange="-131.927 131.927" gainprm="31.5859" biasprm="0 -31.5859 -0.526083"/>
    <general name="right_ankle" class="/" joint="right_ankle" forcerange="-68.4224 68.4224" gainprm="31.5859" biasprm="0 -31.5859 -0.526083"/>
    <general name="left_shoulder_pitch" class="/" joint="left_shoulder_pitch" forcerange="-33.2384 33.2384" gainprm="31.5859" biasprm="0 -31.5859 -0.526083"/>
    <general name="left_shoulder_abad" class="/" joint="left_shoulder_abad" forcerange="-37.7653 37.7653" gainprm="31.5859" biasprm="0 -31.5859 -0.526083"/>
    <general name="left_shoulder_yaw" class="/" joint="left_shoulder_yaw" forcerange="-33.9886 33.9886" gainprm="31.5859" biasprm="0 -31.5859 -0.526083"/>
    <general name="left_elbow" class="/" joint="left_elbow" forcerange="-54.6977 54.6977" gainprm="31.5859" biasprm="0 -31.5859 -0.526083"/>
    <general name="right_shoulder_pitch" class="/" joint="right_shoulder_pitch" forcerange="-34.8358 34.8358" gainprm="31.5859" biasprm="0 -31.5859 -0.526083"/>
    <general name="right_shoulder_abad" class="/" joint="right_shoulder_abad" forcerange="-34.3957 34.3957" gainprm="31.5859" biasprm="0 -31.5859 -0.526083"/>
    <general name="right_shoulder_yaw" class="/" joint="right_shoulder_yaw" forcerange="-34.3121 34.3121" gainprm="31.5859" biasprm="0 -31.5859 -0.526083"/>
    <general name="right_elbow" class="/" joint="right_elbow" forcerange="-49.8457 49.8457" gainprm="31.5859" biasprm="0 -31.5859 -0.526083"/>
  </actuator>

  <sensor>
    <gyro site="imu" name="imu_angular_velocity"/>
    <velocimeter site="imu" name="imu_linear_velocity"/>
    <framelinvel objtype="site" objname="left_foot" name="left_foot_global_linear_velocity"/>
    <framelinvel objtype="site" objname="right_foot" name="right_foot_global_linear_velocity"/>
  </sensor>

  <keyframe>
    <key name="home" qpos="0 0 0.656 1 0 0 0 0 0 -0.4 0.8 -0.4 0 0 0.4 -0.8 0.4 0 -0.05 0 -0.75 0 0.05 0 0.75"/>
  </keyframe>
</mujoco>
