<mujoco model="humanoid">
  <compiler angle="radian" assetdir="assets" balanceinertia="true" inertiafromgeom="false"/>

  <option timestep="0.005" density="1.2" viscosity="2e-05"/>

  <size nkey="1"/>

  <visual>
    <quality shadowsize="8192"/>
    <map shadowclip="0.5"/>
  </visual>

  <default>
    <default class="/">
      <joint armature="0.01" damping="0.01" frictionloss="0.1"/>
      <geom contype="0" conaffinity="0" group="1" solref="-1000 -80"/>
      <site size="0.01 0.005 0.005" group="5"/>
      <general forcelimited="true" biastype="affine" gainprm="30" biasprm="0 -30 -0.5"/>
      <default class="foot">
        <geom size="0.099 0.0178 0.021" type="box" condim="6" group="4" priority="1" solimp="0.015 1 0.021"/>
      </default>
      <default class="reward_collision_sphere">
        <geom group="5" rgba="1 0 0 1"/>
      </default>
    </default>
  </default>

  <asset>
    <texture type="skybox" colorspace="auto" name="//unnamed_texture_0" builtin="gradient" rgb1="0.95 0.95 0.95" rgb2="0.95 0.95 0.95" width="100" height="600"/>
    <texture type="2d" colorspace="auto" name="texplane" builtin="checker" rgb1="0.345 0.575 0.748" rgb2="0.345 0.575 0.748" markrgb="1 1 1" width="512" height="512"/>
    <material name="MatPlane" class="/" texture="texplane" texuniform="true" texrepeat="2 2" specular="0.9"/>
    <mesh name="torso" class="/" file="torso.stl" scale="0.001 0.001 0.001"/>
    <mesh name="left_hip_yaw" class="/" file="left_hip_yaw.stl" scale="0.001 0.001 0.001"/>
    <mesh name="left_hip_abad" class="/" file="left_hip_abad.stl" scale="0.001 0.001 0.001"/>
    <mesh name="left_leg_upper" class="/" file="left_leg_upper.stl" scale="0.001 0.001 0.001"/>
    <mesh name="left_leg_lower" class="/" file="left_leg_lower.stl" scale="0.001 0.001 0.001"/>
    <mesh name="left_foot" class="/" file="left_foot.stl" scale="0.001 0.001 0.001"/>
    <mesh name="left_hip_yaw1" class="/" content_type="model/stl" file="left_hip_yaw.stl" scale="0.001 -0.001 0.001"/>
    <mesh name="left_hip_abad1" class="/" content_type="model/stl" file="left_hip_abad.stl" scale="0.001 -0.001 0.001"/>
    <mesh name="left_leg_upper1" class="/" content_type="model/stl" file="left_leg_upper.stl" scale="0.001 -0.001 0.001"/>
    <mesh name="left_leg_lower1" class="/" content_type="model/stl" file="left_leg_lower.stl" scale="0.001 -0.001 0.001"/>
    <mesh name="left_foot1" class="/" content_type="model/stl" file="left_foot.stl" scale="0.001 -0.001 0.001"/>
    <mesh name="left_shoulder1" class="/" file="left_shoulder1.stl" scale="0.001 0.001 0.001"/>
    <mesh name="left_shoulder2" class="/" file="left_shoulder2.stl" scale="0.001 0.001 0.001"/>
    <mesh name="left_shoulder3" class="/" file="left_shoulder3.stl" scale="0.001 0.001 0.001"/>
    <mesh name="left_forearm" class="/" file="left_forearm.stl" scale="0.001 0.001 0.001"/>
    <mesh name="left_shoulder11" class="/" content_type="model/stl" file="left_shoulder1.stl" scale="0.001 -0.001 0.001"/>
    <mesh name="left_shoulder21" class="/" content_type="model/stl" file="left_shoulder2.stl" scale="0.001 -0.001 0.001"/>
    <mesh name="left_shoulder31" class="/" content_type="model/stl" file="left_shoulder3.stl" scale="0.001 -0.001 0.001"/>
  </asset>

  <worldbody>
    <geom name="floor" class="/" size="100 100 0.125" type="plane" group="0" material="MatPlane"/>
    <light name="toplight_shadow" class="/" pos="0 0 5" dir="0.0990148 0.0990148 -0.990148" type="directional" ambient="0.04 0.04 0.04" diffuse="0.55 0.55 0.55" specular="0.12 0.12 0.12"/>
    <light name="toplight_fill" class="/" pos="0 0 5" dir="0.0990148 0.0990148 -0.990148" type="directional" castshadow="false" ambient="0.04 0.04 0.04" diffuse="0.3 0.3 0.3" specular="0.08 0.08 0.08"/>
    <body name="trunk" pos="0.000134777 -0.00071196 -0.00017066" quat="1 2.08404e-05 -3.03935e-06 -7.62487e-06">
      <inertial pos="0.00984112 0.000310298 0.141768" quat="1 1.35077e-05 5.79081e-05 -0.000124359" mass="7.5635" diaginertia="0.130507 0.143716 0.0654132"/>
      <joint name="//unnamed_joint_0" type="free"/>
      <geom name="//unnamed_geom_1" class="/" type="mesh" density="0" rgba="0.752941 0.752941 0.752941 1" mesh="torso"/>
      <geom name="//unnamed_geom_2" class="/" size="0.0738245 0.147649 0.172257" pos="0.021817 0 0.0747469" type="box" group="3" rgba="0.752941 0.752941 0.752941 1"/>
      <geom name="//unnamed_geom_3" class="reward_collision_sphere" size="0.142727" pos="0 0 0.14015"/>
      <site name="imu" class="/" pos="-0.000676128 0.00031023 0.136687" size="0.00984327"/>
      <camera name="track" class="/" pos="0 -2.14016 0" quat="0.707107 0.707107 0 0" mode="trackcom"/>
      <camera name="ego_camera" class="/" pos="0.0426855 0 0.280301" quat="-0.5 -0.5 0.5 0.5"/>
      <body name="left_hip_yaw" pos="0.00102766 0.0877991 0.000711803" quat="0.996189 -1.14917e-05 -0.0872251 1.6487e-05">
        <inertial pos="-0.0618545 0.00055712 -0.0605377" quat="0.949816 -0.00320002 -0.312774 0.00333489" mass="0.793597" diaginertia="0.0014501 0.00190249 0.000552917"/>
        <joint name="left_hip_yaw" class="/" pos="0 0 0" axis="-0.00193807 0.00199395 -0.999996" range="-2.98677 2.99476" armature="0.0100345" damping="0.0105763" frictionloss="0.0961839"/>
        <geom name="//unnamed_geom_4" class="/" type="mesh" density="0" rgba="0.2 0.2 0.2 1" mesh="left_hip_yaw"/>
        <body name="left_hip_abad" pos="-0.0604528 -0.000138786 -0.0689259" quat="0.976296 -1.73414e-08 0.216439 5.8364e-07">
          <inertial pos="0.0636034 -0.0137576 5.59148e-05" quat="0.580568 0.404786 0.409491 0.575679" mass="1.15984" diaginertia="0.00255214 0.00278454 0.0012251"/>
          <joint name="left_hip_abad" class="/" pos="0 0 0" axis="-0.999995 -0.00264561 0.00189116" range="-2.98299 3.01408" armature="0.0102484" damping="0.0120556" frictionloss="0.0942614"/>
          <geom name="//unnamed_geom_5" class="/" type="mesh" density="0" rgba="0.2 0.2 0.2 1" mesh="left_hip_abad"/>
          <body name="left_upper_leg" pos="0.0833596 -0.00358694 -0.0130533" quat="0.99141 0.000320858 -0.13079 -0.000173971">
            <inertial pos="-0.000753358 0.0281301 -0.0739038" quat="0.729943 0.0340991 -0.048371 0.680941" mass="2.55187" diaginertia="0.0205348 0.0343515 0.00251506"/>
            <joint name="left_hip_pitch" class="/" pos="0 0 0" axis="0.00164325 0.999997 0.0019343" stiffness="0.000713497" range="-3.0113 2.98976" armature="0.00990994" damping="0.00815981" frictionloss="0.0967874"/>
            <geom name="//unnamed_geom_6" class="/" type="mesh" density="0" rgba="0.752941 0.752941 0.752941 1" mesh="left_leg_upper"/>
            <geom name="//unnamed_geom_7" class="reward_collision_sphere" size="0.0689029" pos="-0.0142285 0.0160512 0.014015"/>
            <geom name="//unnamed_geom_8" class="reward_collision_sphere" size="0.0196865" pos="-0.0758853 -0.0321023 0.0747469"/>
            <body name="left_lower_leg" pos="-0.0124424 0.000349376 -0.232156" quat="1 -1.05328e-05 0.000108263 -0.000114237">
              <inertial pos="0.00510095 0.000506943 -0.12278" quat="0.998867 0.00494223 -0.0150266 0.0448905" mass="0.329738" diaginertia="0.0022724 0.0041811 0.000167257"/>
              <joint name="left_knee" class="/" pos="0 0 0" axis="0.00127984 0.999999 -0.00036998" range="-0.0109435 2.99962" armature="0.00946478" damping="0.00736454" frictionloss="0.0982308"/>
              <geom name="//unnamed_geom_9" class="/" type="mesh" density="0" rgba="0.752941 0.752941 0.752941 1" mesh="left_leg_lower"/>
              <geom name="//unnamed_geom_10" class="reward_collision_sphere" size="0.042326"/>
              <body name="left_foot" pos="0.000163425 0.000296561 -0.260327" quat="1 -4.9772e-06 3.43751e-05 -1.30883e-05">
                <inertial pos="0.0214196 -0.000641291 -0.013078" quat="0.51817 0.481841 0.479325 0.519207" mass="0.267877" diaginertia="0.0207024 0.0378894 0.0194513"/>
                <joint name="left_ankle" class="/" pos="0 0 0" axis="0.000561496 0.999999 -0.000866795" stiffness="0.00112112" range="-1.50926 1.48314" armature="0.0101691" damping="0.00910198" frictionloss="0.100822"/>
                <geom name="//unnamed_geom_11" class="/" type="mesh" density="0" rgba="0.2 0.2 0.2 1" mesh="left_foot"/>
                <geom name="left_foot" class="foot" size="0.10048 0.0174967 0.0209558" pos="0.0265599 0 -0.0233584" quat="0.707109 0.707105 0 0"/>
                <geom name="//unnamed_geom_13" class="reward_collision_sphere" size="0.0246082" pos="0.0265599 0 -0.0186867"/>
                <geom name="//unnamed_geom_14" class="reward_collision_sphere" size="0.0246082" pos="0.0948566 0 -0.0233584"/>
                <geom name="//unnamed_geom_15" class="reward_collision_sphere" size="0.0246082" pos="-0.0426855 0 -0.0233584"/>
                <site name="left_foot" class="foot" pos="0.0265599 0 -0.0233584" quat="0.707109 0.707105 0 0" size="0.00984327"/>
              </body>
            </body>
          </body>
        </body>
      </body>
      <body name="right_hip_yaw" pos="-0.000799264 -0.0876903 -3.67199e-05" quat="0.996197 -0.000229021 -0.0871252 0.000282674">
        <inertial pos="-0.061877 -0.000204853 -0.0605718" quat="0.950013 -0.00299925 0.312185 -0.00250386" mass="0.805349" diaginertia="0.00143777 0.00191666 0.000553317"/>
        <joint name="right_hip_yaw" class="/" pos="0 0 0" axis="-0.000708795 -0.000615379 -1" range="-2.99199 3.00131" armature="0.00957218" damping="0.0119772" frictionloss="0.096857"/>
        <geom name="//unnamed_geom_16" class="/" type="mesh" density="0" rgba="0.2 0.2 0.2 1" mesh="left_hip_yaw1"/>
        <body name="right_hip_abad" pos="-0.0603313 -0.000809457 -0.0710196" quat="0.976298 1.39689e-05 0.216433 -3.13316e-05">
          <inertial pos="0.063992 0.0139768 0.00015333" quat="0.411268 0.573936 0.57932 0.407239" mass="1.13709" diaginertia="0.00256766 0.002769 0.00122599"/>
          <joint name="right_hip_abad" class="/" pos="0 0 0" axis="-1 0.000733233 -7.58559e-06" range="-3.01488 3.00048" armature="0.00958314" damping="0.0110788" frictionloss="0.0952474"/>
          <geom name="//unnamed_geom_17" class="/" type="mesh" density="0" rgba="0.2 0.2 0.2 1" mesh="left_hip_abad1"/>
          <body name="right_upper_leg" pos="0.0831534 0.00333265 -0.0138657" quat="0.991468 3.205e-05 -0.130347 -6.30178e-05">
            <inertial pos="2.08911e-05 -0.0276727 -0.0730458" quat="0.679455 0.0485922 -0.0319351 0.73141" mass="2.49888" diaginertia="0.0202868 0.0341258 0.00249568"/>
            <joint name="right_hip_pitch" class="/" pos="0 0 0" axis="-3.13236e-05 -1 -3.32334e-05" stiffness="1.20758e-05" range="-2.98522 2.99826" armature="0.0098437" damping="0.0111886" frictionloss="0.101573"/>
            <geom name="//unnamed_geom_18" class="/" type="mesh" density="0" rgba="0.752941 0.752941 0.752941 1" mesh="left_leg_upper1"/>
            <geom name="//unnamed_geom_19" class="reward_collision_sphere" size="0.0689029" pos="-0.0142285 -0.0160512 0.014015"/>
            <geom name="//unnamed_geom_20" class="reward_collision_sphere" size="0.0196865" pos="-0.0758853 0.0321023 0.0747469"/>
            <body name="right_lower_leg" pos="-0.0113768 -0.000353476 -0.233374" quat="1 -0.000190476 7.52917e-05 -2.37039e-05">
              <inertial pos="0.00476701 -0.00058282 -0.12286" quat="0.998812 0.00571359 0.0177187 -0.0450374" mass="0.332957" diaginertia="0.00228115 0.00416475 0.000167181"/>
              <joint name="right_knee" class="/" pos="0 0 0" axis="-0.00288153 -0.999996 0.000322643" stiffness="0.00260217" range="-3.0168 -0.0185214" armature="0.0100367" damping="0.0145093" frictionloss="0.0986158"/>
              <geom name="//unnamed_geom_21" class="/" type="mesh" density="0" rgba="0.752941 0.752941 0.752941 1" mesh="left_leg_lower1"/>
              <geom name="//unnamed_geom_22" class="reward_collision_sphere" size="0.042326"/>
              <body name="right_foot" pos="0.00128202 -0.00118191 -0.259743" quat="1 0.000300719 0.000123383 -0.000317569">
                <inertial pos="0.0212911 0.00022799 -0.0138318" quat="0.480147 0.520031 0.519588 0.478597" mass="0.269277" diaginertia="0.0210509 0.0381723 0.0195264"/>
                <joint name="right_ankle" class="/" pos="0 0 0" axis="6.36571e-05 -1 -0.000130731" stiffness="0.000351993" range="-1.49942 1.50236" armature="0.00962942" damping="0.0102712" frictionloss="0.0981819"/>
                <geom name="//unnamed_geom_23" class="/" type="mesh" density="0" rgba="0.2 0.2 0.2 1" mesh="left_foot1"/>
                <geom name="right_foot" class="foot" size="0.100977 0.0161721 0.020026" pos="0.0265599 0 -0.0233584" quat="0.707109 0.707105 0 0"/>
                <geom name="//unnamed_geom_25" class="reward_collision_sphere" size="0.0246082" pos="0.0265599 0 -0.0186867"/>
                <geom name="//unnamed_geom_26" class="reward_collision_sphere" size="0.0246082" pos="0.0948566 0 -0.0233584"/>
                <geom name="//unnamed_geom_27" class="reward_collision_sphere" size="0.0246082" pos="-0.0426855 0 -0.0233584"/>
                <site name="right_foot" class="foot" pos="0.0265599 0 -0.0233584" quat="0.707109 0.707105 0 0" size="0.00984327"/>
              </body>
            </body>
          </body>
        </body>
      </body>
      <body name="left_shoulder" pos="0.0185902 0.188567 0.283909" quat="1 9.25909e-05 -9.87944e-05 -7.85976e-05">
        <inertial pos="0.00806104 0.0565816 0.000847161" quat="0.709892 0.704031 0.0156664 0.0121972" mass="0.752289" diaginertia="0.00104012 0.00120836 0.000540129"/>
        <joint name="left_shoulder_pitch" class="/" pos="0 0 0" axis="0.000169222 1 0.000205525" range="-3.00279 3.01695" armature="0.00992022" damping="0.00796623" frictionloss="0.102176"/>
        <geom name="//unnamed_geom_28" class="/" type="mesh" density="0" rgba="0.2 0.2 0.2 1" mesh="left_shoulder1"/>
        <body name="left_shoulder_2" pos="-0.000436497 0.0616831 -0.000787769" quat="1 0.000211865 -0.000139957 -6.20935e-05">
          <inertial pos="-0.000264347 0.00064814 -0.0779991" quat="0.0151158 0.756627 0.00133737 0.653671" mass="0.76194" diaginertia="0.000963472 0.00165809 0.00081192"/>
          <joint name="left_shoulder_abad" class="/" pos="0 0 0" axis="-1 0.000243556 -0.000614926" stiffness="0.00477604" range="-3.00274 2.9954" armature="0.0101003" damping="0.00826526" frictionloss="0.0986321"/>
          <geom name="//unnamed_geom_29" class="/" type="mesh" density="0" rgba="0.752941 0.752941 0.752941 1" mesh="left_shoulder2"/>
          <body name="left_upper_arm" pos="0.000676758 -1.50395e-05 -0.0959432" quat="1 -1.41612e-05 -4.46462e-07 9.81247e-05">
            <inertial pos="-6.29661e-05 -0.0176806 -0.0587092" quat="0.707426 -0.0204114 0.0179269 0.706265" mass="0.866617" diaginertia="0.00139709 0.0019068 0.000565805"/>
            <joint name="left_shoulder_yaw" class="/" pos="0 0 0" axis="0.00199095 -0.00224296 0.999996" stiffness="0.0047644" range="-3.00306 2.99797" armature="0.00982818" damping="0.0109408" frictionloss="0.100897"/>
            <geom name="//unnamed_geom_30" class="/" type="mesh" density="0" rgba="0.752941 0.752941 0.752941 1" mesh="left_shoulder3"/>
            <geom name="//unnamed_geom_31" class="reward_collision_sphere" size="0.0590596" pos="-0.00948566 -0.0107008 -0.0467168"/>
            <body name="left_lower_arm" pos="0.0002037 0.000274572 -0.148028" quat="1 -0.000100276 -0.000164794 -0.000132899">
              <inertial pos="-0.00716482 -0.00034715 -0.0947027" quat="0.707005 0.00675554 0.00415754 0.707164" mass="0.328017" diaginertia="0.0027908 0.00501783 5.47957e-05"/>
              <joint name="left_elbow" class="/" pos="0 0 0" axis="0.00021659 1 0.000351092" stiffness="0.00353" range="-3.01051 2.99756" armature="0.00977262" damping="0.00668341" frictionloss="0.0948154"/>
              <geom name="//unnamed_geom_32" class="/" type="mesh" density="0" rgba="0.752941 0.752941 0.752941 1" mesh="left_forearm"/>
              <geom name="//unnamed_geom_33" class="/" size="0.0246082 0.00738245" pos="0 0 -0.252271" quat="0.707109 0.707105 0 0" type="cylinder" group="3"/>
              <geom name="//unnamed_geom_34" class="reward_collision_sphere" size="0.0246082"/>
              <geom name="//unnamed_geom_35" class="reward_collision_sphere" size="0.0216552" pos="0 0 -0.261614"/>
            </body>
          </body>
        </body>
      </body>
      <body name="right_shoulder" pos="0.0182778 -0.187708 0.283336" quat="1 -0.000138793 7.58092e-05 -5.22901e-05">
        <inertial pos="0.00860642 -0.0568393 0.000529814" quat="0.711041 0.702865 -0.0149536 -0.0133362" mass="0.754211" diaginertia="0.00105276 0.00121543 0.000544411"/>
        <joint name="right_shoulder_pitch" class="/" pos="0 0 0" axis="0.00281023 -0.999996 0.000602787" stiffness="0.00523192" range="-3.0067 2.99241" armature="0.00988297" damping="0.00286813" frictionloss="0.0968999"/>
        <geom name="//unnamed_geom_36" class="/" type="mesh" density="0" rgba="0.2 0.2 0.2 1" mesh="left_shoulder11"/>
        <body name="right_shoulder_2" pos="0.000425072 -0.0608105 -9.56397e-05" quat="1 0.000194986 -2.19084e-05 -3.16643e-05">
          <inertial pos="-0.000381664 -0.000885364 -0.0772044" quat="-0.00377008 0.654772 0.0129121 0.755707" mass="0.754722" diaginertia="0.000957823 0.00165694 0.000807036"/>
          <joint name="right_shoulder_abad" class="/" pos="0 0 0" axis="-0.999999 0.000800612 -0.00126773" range="-3.01483 2.9852" armature="0.010065" damping="0.00763047" frictionloss="0.10205"/>
          <geom name="//unnamed_geom_37" class="/" type="mesh" density="0" rgba="0.752941 0.752941 0.752941 1" mesh="left_shoulder21"/>
          <body name="right_upper_arm" pos="-2.07687e-05 0.000184856 -0.0964969" quat="1 -0.000120984 -7.7955e-05 1.07723e-06">
            <inertial pos="-0.000520591 0.0174909 -0.059834" quat="0.704802 -0.0214879 0.0214698 0.708753" mass="0.864723" diaginertia="0.00139044 0.00192878 0.000567017"/>
            <joint name="right_shoulder_yaw" class="/" pos="0 0 0" axis="0.00248752 -0.00382982 0.99999" stiffness="0.00501303" range="-2.99425 3.00122" armature="0.00994133" damping="0.00941565" frictionloss="0.095835"/>
            <geom name="//unnamed_geom_38" class="/" type="mesh" density="0" rgba="0.752941 0.752941 0.752941 1" mesh="left_shoulder31"/>
            <geom name="//unnamed_geom_39" class="reward_collision_sphere" size="0.0590596" pos="-0.00948566 0.0107008 -0.0467168"/>
            <body name="right_lower_arm" pos="0.000239034 0.000726661 -0.146309" quat="1 -1.05307e-05 -1.39027e-05 1.88536e-05">
              <inertial pos="-0.00669634 -2.42358e-05 -0.0936518" quat="0.706888 0.00660483 0.00698611 0.70726" mass="0.333967" diaginertia="0.00278809 0.00505147 5.60484e-05"/>
              <joint name="right_elbow" class="/" pos="0 0 0" axis="-0.00107558 -0.999999 -0.000673363" range="-2.98578 3.01457" armature="0.00979603" damping="0.00847065" frictionloss="0.102587"/>
              <geom name="//unnamed_geom_40" class="/" type="mesh" density="0" rgba="0.752941 0.752941 0.752941 1" mesh="left_forearm"/>
              <geom name="//unnamed_geom_41" class="/" size="0.0246082 0.00738245" pos="0 0 -0.252271" quat="0.707109 0.707105 0 0" type="cylinder" group="3"/>
              <geom name="//unnamed_geom_42" class="reward_collision_sphere" size="0.0246082"/>
              <geom name="//unnamed_geom_43" class="reward_collision_sphere" size="0.0216552" pos="0 0 -0.261614"/>
            </body>
          </body>
        </body>
      </body>
    </body>
  </worldbody>

  <contact>
    <pair class="/" geom1="floor" geom2="left_foot" name="//unnamed_contact_0"/>
    <pair class="/" geom1="floor" geom2="right_foot" name="//unnamed_contact_1"/>
  </contact>

  <actuator>
    <general name="left_hip_yaw" class="/" joint="left_hip_yaw" forcerange="-34.3222 34.3222" gainprm="28.9188" biasprm="0 -28.9188 -0.477658"/>
    <general name="left_hip_abad" class="/" joint="left_hip_abad" forcerange="-33.3943 33.3943" gainprm="28.9188" biasprm="0 -28.9188 -0.477658"/>
    <general name="left_hip_pitch" class="/" joint="left_hip_pitch" forcerange="-68.8621 68.8621" gainprm="28.9188" biasprm="0 -28.9188 -0.477658"/>
    <general name="left_knee" class="/" joint="left_knee" forcerange="-141.054 141.054" gainprm="28.9188" biasprm="0 -28.9188 -0.477658"/>
    <general name="left_ankle" class="/" joint="left_ankle" forcerange="-66.7309 66.7309" gainprm="28.9188" biasprm="0 -28.9188 -0.477658"/>
    <general name="right_hip_yaw" class="/" joint="right_hip_yaw" forcerange="-33.4915 33.4915" gainprm="28.9188" biasprm="0 -28.9188 -0.477658"/>
    <general name="right_hip_abad" class="/" joint="right_hip_abad" forcerange="-32.5784 32.5784" gainprm="28.9188" biasprm="0 -28.9188 -0.477658"/>
    <general name="right_hip_pitch" class="/" joint="right_hip_pitch" forcerange="-71.7818 71.7818" gainprm="28.9188" biasprm="0 -28.9188 -0.477658"/>
    <general name="right_knee" class="/" joint="right_knee" forcerange="-139.595 139.595" gainprm="28.9188" biasprm="0 -28.9188 -0.477658"/>
    <general name="right_ankle" class="/" joint="right_ankle" forcerange="-66.4314 66.4314" gainprm="28.9188" biasprm="0 -28.9188 -0.477658"/>
    <general name="left_shoulder_pitch" class="/" joint="left_shoulder_pitch" forcerange="-33.6737 33.6737" gainprm="28.9188" biasprm="0 -28.9188 -0.477658"/>
    <general name="left_shoulder_abad" class="/" joint="left_shoulder_abad" forcerange="-33.5441 33.5441" gainprm="28.9188" biasprm="0 -28.9188 -0.477658"/>
    <general name="left_shoulder_yaw" class="/" joint="left_shoulder_yaw" forcerange="-33.4638 33.4638" gainprm="28.9188" biasprm="0 -28.9188 -0.477658"/>
    <general name="left_elbow" class="/" joint="left_elbow" forcerange="-54.1531 54.1531" gainprm="28.9188" biasprm="0 -28.9188 -0.477658"/>
    <general name="right_shoulder_pitch" class="/" joint="right_shoulder_pitch" forcerange="-33.5338 33.5338" gainprm="28.9188" biasprm="0 -28.9188 -0.477658"/>
    <general name="right_shoulder_abad" class="/" joint="right_shoulder_abad" forcerange="-34.1731 34.1731" gainprm="28.9188" biasprm="0 -28.9188 -0.477658"/>
    <general name="right_shoulder_yaw" class="/" joint="right_shoulder_yaw" forcerange="-34.1004 34.1004" gainprm="28.9188" biasprm="0 -28.9188 -0.477658"/>
    <general name="right_elbow" class="/" joint="right_elbow" forcerange="-53.9943 53.9943" gainprm="28.9188" biasprm="0 -28.9188 -0.477658"/>
  </actuator>

  <sensor>
    <gyro site="imu" name="imu_angular_velocity"/>
    <velocimeter site="imu" name="imu_linear_velocity"/>
    <framelinvel objtype="site" objname="left_foot" name="left_foot_global_linear_velocity"/>
    <framelinvel objtype="site" objname="right_foot" name="right_foot_global_linear_velocity"/>
  </sensor>

  <keyframe>
    <key name="home" qpos="0 0 0.656 1 0 0 0 0 0 -0.4 0.8 -0.4 0 0 0.4 -0.8 0.4 0 -0.05 0 -0.75 0 0.05 0 0.75"/>
  </keyframe>
</mujoco>
