<mujoco model="humanoid">
  <compiler angle="radian" assetdir="assets" balanceinertia="true" inertiafromgeom="false"/>

  <option timestep="0.005" density="1.2" viscosity="2e-05"/>

  <size nkey="1"/>

  <visual>
    <quality shadowsize="8192"/>
    <map shadowclip="0.5"/>
  </visual>

  <default>
    <default class="/">
      <joint armature="0.01" damping="0.01" frictionloss="0.1"/>
      <geom contype="0" conaffinity="0" group="1" solref="-1000 -80"/>
      <site size="0.01 0.005 0.005" group="5"/>
      <general forcelimited="true" biastype="affine" gainprm="30" biasprm="0 -30 -0.5"/>
      <default class="foot">
        <geom size="0.099 0.0178 0.021" type="box" condim="6" group="4" priority="1" solimp="0.015 1 0.021"/>
      </default>
      <default class="reward_collision_sphere">
        <geom group="5" rgba="1 0 0 1"/>
      </default>
    </default>
  </default>

  <asset>
    <texture type="skybox" colorspace="auto" name="//unnamed_texture_0" builtin="gradient" rgb1="0.95 0.95 0.95" rgb2="0.95 0.95 0.95" width="100" height="600"/>
    <texture type="2d" colorspace="auto" name="texplane" builtin="checker" rgb1="0.345 0.575 0.748" rgb2="0.345 0.575 0.748" markrgb="1 1 1" width="512" height="512"/>
    <material name="MatPlane" class="/" texture="texplane" texuniform="true" texrepeat="2 2" specular="0.9"/>
    <mesh name="torso" class="/" file="torso.stl" scale="0.001 0.001 0.001"/>
    <mesh name="left_hip_yaw" class="/" file="left_hip_yaw.stl" scale="0.001 0.001 0.001"/>
    <mesh name="left_hip_abad" class="/" file="left_hip_abad.stl" scale="0.001 0.001 0.001"/>
    <mesh name="left_leg_upper" class="/" file="left_leg_upper.stl" scale="0.001 0.001 0.001"/>
    <mesh name="left_leg_lower" class="/" file="left_leg_lower.stl" scale="0.001 0.001 0.001"/>
    <mesh name="left_foot" class="/" file="left_foot.stl" scale="0.001 0.001 0.001"/>
    <mesh name="left_hip_yaw1" class="/" content_type="model/stl" file="left_hip_yaw.stl" scale="0.001 -0.001 0.001"/>
    <mesh name="left_hip_abad1" class="/" content_type="model/stl" file="left_hip_abad.stl" scale="0.001 -0.001 0.001"/>
    <mesh name="left_leg_upper1" class="/" content_type="model/stl" file="left_leg_upper.stl" scale="0.001 -0.001 0.001"/>
    <mesh name="left_leg_lower1" class="/" content_type="model/stl" file="left_leg_lower.stl" scale="0.001 -0.001 0.001"/>
    <mesh name="left_foot1" class="/" content_type="model/stl" file="left_foot.stl" scale="0.001 -0.001 0.001"/>
    <mesh name="left_shoulder1" class="/" file="left_shoulder1.stl" scale="0.001 0.001 0.001"/>
    <mesh name="left_shoulder2" class="/" file="left_shoulder2.stl" scale="0.001 0.001 0.001"/>
    <mesh name="left_shoulder3" class="/" file="left_shoulder3.stl" scale="0.001 0.001 0.001"/>
    <mesh name="left_forearm" class="/" file="left_forearm.stl" scale="0.001 0.001 0.001"/>
    <mesh name="left_shoulder11" class="/" content_type="model/stl" file="left_shoulder1.stl" scale="0.001 -0.001 0.001"/>
    <mesh name="left_shoulder21" class="/" content_type="model/stl" file="left_shoulder2.stl" scale="0.001 -0.001 0.001"/>
    <mesh name="left_shoulder31" class="/" content_type="model/stl" file="left_shoulder3.stl" scale="0.001 -0.001 0.001"/>
  </asset>

  <worldbody>
    <geom name="floor" class="/" size="100 100 0.125" type="plane" group="0" material="MatPlane"/>
    <light name="toplight_shadow" class="/" pos="0 0 5" dir="0.0990148 0.0990148 -0.990148" type="directional" ambient="0.04 0.04 0.04" diffuse="0.55 0.55 0.55" specular="0.12 0.12 0.12"/>
    <light name="toplight_fill" class="/" pos="0 0 5" dir="0.0990148 0.0990148 -0.990148" type="directional" castshadow="false" ambient="0.04 0.04 0.04" diffuse="0.3 0.3 0.3" specular="0.08 0.08 0.08"/>
    <body name="trunk" pos="0.00218305 0.00222343 0.000675979" quat="1 -1.40479e-05 6.1339e-05 -5.89465e-05">
      <inertial pos="0.010986 0.00386451 0.124321" quat="0.99999 -0.00256902 0.00369302 0.000181113" mass="7.00001" diaginertia="0.128721 0.164402 0.0371333"/>
      <joint name="//unnamed_joint_0" type="free"/>
      <geom name="//unnamed_geom_1" class="/" type="mesh" density="0" rgba="0.752941 0.752941 0.752941 1" mesh="torso"/>
      <geom name="//unnamed_geom_2" class="/" size="0.0726424 0.145285 0.169499" pos="0.0218932 0 0.0669646" type="box" group="3" rgba="0.752941 0.752941 0.752941 1"/>
      <geom name="//unnamed_geom_3" class="reward_collision_sphere" size="0.140442" pos="0 0 0.125559"/>
      <site name="imu" class="/" pos="0.00248986 0.000893517 0.127282" size="0.00968566"/>
      <camera name="track" class="/" pos="0 -2.23352 0" quat="0.707107 0.707107 0 0" mode="trackcom"/>
      <camera name="ego_camera" class="/" pos="0.0428346 0 0.251117" quat="-0.5 -0.5 0.5 0.5"/>
      <body name="left_hip_yaw" pos="-0.0017234 0.0915546 0.00107012" quat="0.996193 -0.000214029 -0.0871802 0.000155277">
        <inertial pos="-0.0626191 -0.000639375 -0.0508546" quat="0.951163 -0.00543502 -0.308628 0.00299674" mass="0.752191" diaginertia="0.00142905 0.00224689 0.000314906"/>
        <joint name="left_hip_yaw" class="/" pos="0 0 0" axis="0.00428299 -0.00387319 -0.999983" stiffness="0.0136601" range="-3.04073 2.98408" armature="0.00998676" damping="0.00824829" frictionloss="0.092837"/>
        <geom name="//unnamed_geom_4" class="/" type="mesh" density="0" rgba="0.2 0.2 0.2 1" mesh="left_hip_yaw"/>
        <body name="left_hip_abad" pos="-0.0601453 -0.000243692 -0.0649737" quat="0.976298 -9.89006e-05 0.21643 0.000173977">
          <inertial pos="0.0666892 -0.0148823 -7.15846e-06" quat="0.577968 0.408652 0.401373 0.581255" mass="1.03834" diaginertia="0.002646 0.00339561 0.000696157"/>
          <joint name="left_hip_abad" class="/" pos="0 0 0" axis="-0.999905 0.00721033 0.0117265" stiffness="0.0125347" range="-3.05171 2.94198" armature="0.00847776" damping="0.0121805" frictionloss="0.110328"/>
          <geom name="//unnamed_geom_5" class="/" type="mesh" density="0" rgba="0.2 0.2 0.2 1" mesh="left_hip_abad"/>
          <body name="left_upper_leg" pos="0.0819708 -0.00271216 -0.00903016" quat="0.991531 -0.000142607 -0.129861 -0.00125908">
            <inertial pos="-0.00156474 0.0291827 -0.0669738" quat="0.729984 0.0349184 -0.0488785 0.680819" mass="2.27" diaginertia="0.0204406 0.0426302 0.00134349"/>
            <joint name="left_hip_pitch" class="/" pos="0 0 0" axis="-0.000856089 0.999992 0.00386586" stiffness="0.010601" range="-3.02077 2.99663" armature="0.00996561" damping="0.00939387" frictionloss="0.0949767"/>
            <geom name="//unnamed_geom_6" class="/" type="mesh" density="0" rgba="0.752941 0.752941 0.752941 1" mesh="left_leg_upper"/>
            <geom name="//unnamed_geom_7" class="reward_collision_sphere" size="0.0677996" pos="-0.0142782 0.0167514 0.0125559"/>
            <geom name="//unnamed_geom_8" class="reward_collision_sphere" size="0.0193713" pos="-0.0761504 -0.0335028 0.0669646"/>
            <body name="left_lower_leg" pos="-0.0123701 0.00163208 -0.211257" quat="0.999999 0.000231527 -0.000531908 -0.00111761">
              <inertial pos="0.004855 0.000359292 -0.11055" quat="0.999026 0.00404578 -0.0142503 0.0415546" mass="0.303554" diaginertia="0.00226003 0.00483624 9.79074e-05"/>
              <joint name="left_knee" class="/" pos="0 0 0" axis="0.00143717 0.999988 -0.00471033" range="0.0539 3.00732" armature="0.0111083" damping="0.00281292" frictionloss="0.101085"/>
              <geom name="//unnamed_geom_9" class="/" type="mesh" density="0" rgba="0.752941 0.752941 0.752941 1" mesh="left_leg_lower"/>
              <geom name="//unnamed_geom_10" class="reward_collision_sphere" size="0.0416483"/>
              <body name="left_foot" pos="-0.000583728 0.000130112 -0.233443" quat="1 -3.10631e-05 -4.51502e-05 4.42048e-05">
                <inertial pos="0.0212873 0.00052945 -0.0136695" quat="0.523449 0.478139 0.481069 0.51571" mass="0.253332" diaginertia="0.0206805 0.0477812 0.0110692"/>
                <joint name="left_ankle" class="/" pos="0 0 0" axis="-0.00196647 0.999954 0.00939958" range="-1.44798 1.55567" armature="0.00871527" damping="0.0104656" frictionloss="0.103616"/>
                <geom name="//unnamed_geom_11" class="/" type="mesh" density="0" rgba="0.2 0.2 0.2 1" mesh="left_foot"/>
                <geom name="left_foot" class="foot" size="0.099743 0.0176299 0.0215291" pos="0.0266526 0 -0.0209264" quat="0.707109 0.707105 0 0"/>
                <geom name="//unnamed_geom_13" class="reward_collision_sphere" size="0.0242141" pos="0.0266526 0 -0.0167412"/>
                <geom name="//unnamed_geom_14" class="reward_collision_sphere" size="0.0242141" pos="0.095188 0 -0.0209264"/>
                <geom name="//unnamed_geom_15" class="reward_collision_sphere" size="0.0242141" pos="-0.0428346 0 -0.0209264"/>
                <site name="left_foot" class="foot" pos="0.0266526 0 -0.0209264" quat="0.707109 0.707105 0 0" size="0.00968566"/>
              </body>
            </body>
          </body>
        </body>
      </body>
      <body name="right_hip_yaw" pos="0.00106865 -0.0941127 -0.00157677" quat="0.996187 -0.00109838 -0.0872361 -0.000162409">
        <inertial pos="-0.0623694 -0.00032292 -0.0512577" quat="0.950383 -0.00261884 0.311066 -0.00159707" mass="0.756486" diaginertia="0.00154204 0.00229813 0.000322314"/>
        <joint name="right_hip_yaw" class="/" pos="0 0 0" axis="-0.00891059 0.00900924 -0.99992" range="-2.96472 2.9962" armature="0.0105191" damping="0.015835" frictionloss="0.0949462"/>
        <geom name="//unnamed_geom_16" class="/" type="mesh" density="0" rgba="0.2 0.2 0.2 1" mesh="left_hip_yaw1"/>
        <body name="right_hip_abad" pos="-0.0629952 -0.000925626 -0.0605397" quat="0.97608 -0.000582729 0.217413 6.26354e-05">
          <inertial pos="0.0633072 0.014666 0.000580327" quat="0.414442 0.577384 0.574935 0.405358" mass="1.11216" diaginertia="0.00263849 0.00345662 0.000712188"/>
          <joint name="right_hip_abad" class="/" pos="0 0 0" axis="-0.999955 0.00833447 -0.00442898" stiffness="0.0125748" range="-2.94282 3.00496" armature="0.00974056" damping="0.0118897" frictionloss="0.107012"/>
          <geom name="//unnamed_geom_17" class="/" type="mesh" density="0" rgba="0.2 0.2 0.2 1" mesh="left_hip_abad1"/>
          <body name="right_upper_leg" pos="0.0859696 -0.000101779 -0.0119642" quat="0.991416 0.000405005 -0.130742 0.000201761">
            <inertial pos="-0.00371006 -0.028124 -0.0689103" quat="0.687751 0.0438967 -0.0310404 0.723954" mass="2.40082" diaginertia="0.020988 0.0423039 0.00145328"/>
            <joint name="right_hip_pitch" class="/" pos="0 0 0" axis="-0.00398979 -0.999991 -0.00161692" stiffness="0.00110001" range="-3.04301 3.00116" armature="0.0096882" damping="0.0248677" frictionloss="0.0832356"/>
            <geom name="//unnamed_geom_18" class="/" type="mesh" density="0" rgba="0.752941 0.752941 0.752941 1" mesh="left_leg_upper1"/>
            <geom name="//unnamed_geom_19" class="reward_collision_sphere" size="0.0677996" pos="-0.0142782 -0.0167514 0.0125559"/>
            <geom name="//unnamed_geom_20" class="reward_collision_sphere" size="0.0193713" pos="-0.0761504 0.0335028 0.0669646"/>
            <body name="right_lower_leg" pos="-0.0109961 -0.00259621 -0.20601" quat="1 0.000475168 -6.92963e-05 -0.000246938">
              <inertial pos="0.00423315 -0.000708675 -0.109663" quat="0.9991 0.00759223 0.00985881 -0.040539" mass="0.316898" diaginertia="0.00227035 0.00515306 9.90303e-05"/>
              <joint name="right_knee" class="/" pos="0 0 0" axis="-0.000384114 -1 0.000254268" range="-2.94702 0.0495148" armature="0.00895071" damping="0" frictionloss="0.0960019"/>
              <geom name="//unnamed_geom_21" class="/" type="mesh" density="0" rgba="0.752941 0.752941 0.752941 1" mesh="left_leg_lower1"/>
              <geom name="//unnamed_geom_22" class="reward_collision_sphere" size="0.0416483"/>
              <body name="right_foot" pos="-0.00231952 0.0024692 -0.232969" quat="0.999999 0.000715976 0.000314484 0.000901123">
                <inertial pos="0.0242675 -0.00232465 -0.00884955" quat="0.48093 0.518618 0.5194 0.479547" mass="0.245806" diaginertia="0.0198652 0.0456578 0.0103209"/>
                <joint name="right_ankle" class="/" pos="0 0 0" axis="-0.000331256 -0.999998 -0.00177736" range="-1.54723 1.49801" armature="0.00894234" damping="0.0113348" frictionloss="0.0946043"/>
                <geom name="//unnamed_geom_23" class="/" type="mesh" density="0" rgba="0.2 0.2 0.2 1" mesh="left_foot1"/>
                <geom name="right_foot" class="foot" size="0.11028 0.0188112 0.0211529" pos="0.0266526 0 -0.0209264" quat="0.707109 0.707105 0 0"/>
                <geom name="//unnamed_geom_25" class="reward_collision_sphere" size="0.0242141" pos="0.0266526 0 -0.0167412"/>
                <geom name="//unnamed_geom_26" class="reward_collision_sphere" size="0.0242141" pos="0.095188 0 -0.0209264"/>
                <geom name="//unnamed_geom_27" class="reward_collision_sphere" size="0.0242141" pos="-0.0428346 0 -0.0209264"/>
                <site name="right_foot" class="foot" pos="0.0266526 0 -0.0209264" quat="0.707109 0.707105 0 0" size="0.00968566"/>
              </body>
            </body>
          </body>
        </body>
      </body>
      <body name="left_shoulder" pos="0.0156176 0.195727 0.252981" quat="1 0.000496613 0.00028676 0.00042125">
        <inertial pos="0.0117473 0.0612525 -0.0023733" quat="0.708218 0.705729 0.0143279 0.0130066" mass="0.691644" diaginertia="0.00107802 0.00149908 0.000300681"/>
        <joint name="left_shoulder_pitch" class="/" pos="0 0 0" axis="0.00171907 0.999993 -0.00338538" range="-2.97352 2.94467" armature="0.0101796" damping="0.00300518" frictionloss="0.0831683"/>
        <geom name="//unnamed_geom_28" class="/" type="mesh" density="0" rgba="0.2 0.2 0.2 1" mesh="left_shoulder1"/>
        <body name="left_shoulder_2" pos="-0.000641895 0.0635113 0.00267705" quat="1 1.26809e-06 -2.99983e-05 -2.54342e-05">
          <inertial pos="5.40049e-06 0.000136317 -0.0664083" quat="0.00924751 0.766019 0.000624617 0.642752" mass="0.72797" diaginertia="0.000950409 0.00197464 0.000447171"/>
          <joint name="left_shoulder_abad" class="/" pos="0 0 0" axis="-0.999999 -0.000641411 -0.000929648" range="-3.01383 3.01189" armature="0.0102911" damping="0.0111989" frictionloss="0.0965869"/>
          <geom name="//unnamed_geom_29" class="/" type="mesh" density="0" rgba="0.752941 0.752941 0.752941 1" mesh="left_shoulder2"/>
          <body name="left_upper_arm" pos="-0.00263515 0.00140622 -0.0881023" quat="1 -0.000238743 7.30117e-05 0.000604326">
            <inertial pos="-0.000593836 -0.0172862 -0.0524515" quat="0.710164 -0.0198583 0.0305609 0.703092" mass="0.839937" diaginertia="0.00141498 0.00235525 0.000327833"/>
            <joint name="left_shoulder_yaw" class="/" pos="0 0 0" axis="-0.00850221 0.0116582 0.999896" range="-2.9771 3.04918" armature="0.00849493" damping="0" frictionloss="0.0834904"/>
            <geom name="//unnamed_geom_30" class="/" type="mesh" density="0" rgba="0.752941 0.752941 0.752941 1" mesh="left_shoulder3"/>
            <geom name="//unnamed_geom_31" class="reward_collision_sphere" size="0.0581139" pos="-0.0095188 -0.0111676 -0.0418529"/>
            <body name="left_lower_arm" pos="0.00110084 0.000815603 -0.129294" quat="1 -0.000280721 3.28741e-05 -0.000593684">
              <inertial pos="-0.00394801 -0.000442229 -0.0816119" quat="0.713429 0.00535375 0.00277872 0.700701" mass="0.32194" diaginertia="0.00278828 0.00618418 3.13201e-05"/>
              <joint name="left_elbow" class="/" pos="0 0 0" axis="0.000430513 1 -0.000583132" stiffness="0.0068979" range="-3.02331 2.95637" armature="0.0110056" damping="0" frictionloss="0.107862"/>
              <geom name="//unnamed_geom_32" class="/" type="mesh" density="0" rgba="0.752941 0.752941 0.752941 1" mesh="left_forearm"/>
              <geom name="//unnamed_geom_33" class="/" size="0.0242141 0.00726424" pos="0 0 -0.226006" quat="0.707109 0.707105 0 0" type="cylinder" group="3"/>
              <geom name="//unnamed_geom_34" class="reward_collision_sphere" size="0.0242141"/>
              <geom name="//unnamed_geom_35" class="reward_collision_sphere" size="0.0213084" pos="0 0 -0.234376"/>
            </body>
          </body>
        </body>
      </body>
      <body name="right_shoulder" pos="0.0176579 -0.195109 0.256755" quat="1 -0.000321346 0.000167204 0.0004941">
        <inertial pos="0.00801589 -0.0600498 -0.00179684" quat="0.708243 0.705679 -0.01488 -0.0137095" mass="0.721143" diaginertia="0.00104941 0.0015088 0.000317931"/>
        <joint name="right_shoulder_pitch" class="/" pos="0 0 0" axis="-0.00695439 -0.999968 0.00390948" range="-2.97038 2.99294" armature="0.0101251" damping="0.0194552" frictionloss="0.0921397"/>
        <geom name="//unnamed_geom_36" class="/" type="mesh" density="0" rgba="0.2 0.2 0.2 1" mesh="left_shoulder11"/>
        <body name="right_shoulder_2" pos="0.000740375 -0.0666256 -0.00188848" quat="1 0.000439186 -0.000100869 -0.000276983">
          <inertial pos="-0.00132334 0.00198476 -0.0694584" quat="0.00424928 0.644956 0.00732106 0.764173" mass="0.73042" diaginertia="0.00091387 0.00193772 0.000453561"/>
          <joint name="right_shoulder_abad" class="/" pos="0 0 0" axis="-0.99997 0.00710662 0.00291939" stiffness="0.0135204" range="-2.9521 3.007" armature="0.0101831" damping="0.0183454" frictionloss="0.085799"/>
          <geom name="//unnamed_geom_37" class="/" type="mesh" density="0" rgba="0.752941 0.752941 0.752941 1" mesh="left_shoulder21"/>
          <body name="right_upper_arm" pos="-0.000622442 -0.000481819 -0.0855028" quat="0.999999 -0.00110911 -5.82836e-05 0.000588192">
            <inertial pos="-0.00117946 0.0190472 -0.050531" quat="0.701005 -0.028277 0.0241629 0.712186" mass="0.867197" diaginertia="0.00140629 0.00231751 0.000332603"/>
            <joint name="right_shoulder_yaw" class="/" pos="0 0 0" axis="0.00394306 0.0133915 0.999903" stiffness="0.00447918" range="-2.98015 2.99628" armature="0.00955402" damping="0.0138381" frictionloss="0.110288"/>
            <geom name="//unnamed_geom_38" class="/" type="mesh" density="0" rgba="0.752941 0.752941 0.752941 1" mesh="left_shoulder31"/>
            <geom name="//unnamed_geom_39" class="reward_collision_sphere" size="0.0581139" pos="-0.0095188 0.0111676 -0.0418529"/>
            <body name="right_lower_arm" pos="9.92813e-05 0.0016707 -0.134597" quat="1 0.000203653 8.70894e-05 -0.000103766">
              <inertial pos="-0.00684455 0.000302945 -0.0842479" quat="0.708471 -0.00879055 0.000354064 0.705685" mass="0.302759" diaginertia="0.00283526 0.00588731 2.9697e-05"/>
              <joint name="right_elbow" class="/" pos="0 0 0" axis="0.00781812 -0.999925 -0.00942163" stiffness="0.0131177" range="-3.05731 2.94341" armature="0.0102434" damping="0.00879738" frictionloss="0.0844581"/>
              <geom name="//unnamed_geom_40" class="/" type="mesh" density="0" rgba="0.752941 0.752941 0.752941 1" mesh="left_forearm"/>
              <geom name="//unnamed_geom_41" class="/" size="0.0242141 0.00726424" pos="0 0 -0.226006" quat="0.707109 0.707105 0 0" type="cylinder" group="3"/>
              <geom name="//unnamed_geom_42" class="reward_collision_sphere" size="0.0242141"/>
              <geom name="//unnamed_geom_43" class="reward_collision_sphere" size="0.0213084" pos="0 0 -0.234376"/>
            </body>
          </body>
        </body>
      </body>
    </body>
  </worldbody>

  <contact>
    <pair class="/" geom1="floor" geom2="left_foot" name="//unnamed_contact_0"/>
    <pair class="/" geom1="floor" geom2="right_foot" name="//unnamed_contact_1"/>
  </contact>

  <actuator>
    <general name="left_hip_yaw" class="/" joint="left_hip_yaw" forcerange="-29.4503 29.4503" gainprm="31.3741" biasprm="0 -31.3741 -0.515036"/>
    <general name="left_hip_abad" class="/" joint="left_hip_abad" forcerange="-33.0994 33.0994" gainprm="31.3741" biasprm="0 -31.3741 -0.515036"/>
    <general name="left_hip_pitch" class="/" joint="left_hip_pitch" forcerange="-75.2774 75.2774" gainprm="31.3741" biasprm="0 -31.3741 -0.515036"/>
    <general name="left_knee" class="/" joint="left_knee" forcerange="-137.449 137.449" gainprm="31.3741" biasprm="0 -31.3741 -0.515036"/>
    <general name="left_ankle" class="/" joint="left_ankle" forcerange="-66.1496 66.1496" gainprm="31.3741" biasprm="0 -31.3741 -0.515036"/>
    <general name="right_hip_yaw" class="/" joint="right_hip_yaw" forcerange="-33.0673 33.0673" gainprm="31.3741" biasprm="0 -31.3741 -0.515036"/>
    <general name="right_hip_abad" class="/" joint="right_hip_abad" forcerange="-36.4976 36.4976" gainprm="31.3741" biasprm="0 -31.3741 -0.515036"/>
    <general name="right_hip_pitch" class="/" joint="right_hip_pitch" forcerange="-72.3175 72.3175" gainprm="31.3741" biasprm="0 -31.3741 -0.515036"/>
    <general name="right_knee" class="/" joint="right_knee" forcerange="-127.367 127.367" gainprm="31.3741" biasprm="0 -31.3741 -0.515036"/>
    <general name="right_ankle" class="/" joint="right_ankle" forcerange="-66.3776 66.3776" gainprm="31.3741" biasprm="0 -31.3741 -0.515036"/>
    <general name="left_shoulder_pitch" class="/" joint="left_shoulder_pitch" forcerange="-32.1188 32.1188" gainprm="31.3741" biasprm="0 -31.3741 -0.515036"/>
    <general name="left_shoulder_abad" class="/" joint="left_shoulder_abad" forcerange="-33.3926 33.3926" gainprm="31.3741" biasprm="0 -31.3741 -0.515036"/>
    <general name="left_shoulder_yaw" class="/" joint="left_shoulder_yaw" forcerange="-33.5365 33.5365" gainprm="31.3741" biasprm="0 -31.3741 -0.515036"/>
    <general name="left_elbow" class="/" joint="left_elbow" forcerange="-53.221 53.221" gainprm="31.3741" biasprm="0 -31.3741 -0.515036"/>
    <general name="right_shoulder_pitch" class="/" joint="right_shoulder_pitch" forcerange="-33.1528 33.1528" gainprm="31.3741" biasprm="0 -31.3741 -0.515036"/>
    <general name="right_shoulder_abad" class="/" joint="right_shoulder_abad" forcerange="-30.5188 30.5188" gainprm="31.3741" biasprm="0 -31.3741 -0.515036"/>
    <general name="right_shoulder_yaw" class="/" joint="right_shoulder_yaw" forcerange="-32.9047 32.9047" gainprm="31.3741" biasprm="0 -31.3741 -0.515036"/>
    <general name="right_elbow" class="/" joint="right_elbow" forcerange="-55.0304 55.0304" gainprm="31.3741" biasprm="0 -31.3741 -0.515036"/>
  </actuator>

  <sensor>
    <gyro site="imu" name="imu_angular_velocity"/>
    <velocimeter site="imu" name="imu_linear_velocity"/>
    <framelinvel objtype="site" objname="left_foot" name="left_foot_global_linear_velocity"/>
    <framelinvel objtype="site" objname="right_foot" name="right_foot_global_linear_velocity"/>
  </sensor>

  <keyframe>
    <key name="home" qpos="0 0 0.656 1 0 0 0 0 0 -0.4 0.8 -0.4 0 0 0.4 -0.8 0.4 0 -0.05 0 -0.75 0 0.05 0 0.75"/>
  </keyframe>
</mujoco>
