<mujoco model="anymal_c">
  <compiler angle="radian" assetdir="assets" balanceinertia="true" inertiafromgeom="false"/>

  <option timestep="0.005" density="1.2" viscosity="2e-05"/>

  <size nkey="1"/>

  <visual>
    <quality shadowsize="8192"/>
    <map shadowclip="0.5"/>
  </visual>

  <default>
    <default class="/">
      <material specular="0" shininess="0.25"/>
      <geom contype="0" conaffinity="0" group="1" solref="-1000 -80"/>
      <site size="0.01 0.005 0.005" group="5"/>
      <general forcelimited="true" forcerange="-80 80" biastype="affine" gainprm="80" biasprm="0 -80 -2"/>
      <default class="anymal_c">
        <joint armature="0.01" damping="0.01" frictionloss="0.1"/>
        <default class="visual">
          <geom type="mesh" group="2"/>
          <default class="visual_zflip"/>
        </default>
        <default class="collision">
          <geom type="cylinder" group="3"/>
          <default class="foot">
            <geom size="0.03 0 0" type="sphere" condim="6" priority="1" friction="0.8 0.02 0.01" solimp="0.015 1 0.03"/>
          </default>
        </default>
      </default>
      <default class="reward_collision_sphere">
        <geom group="5" rgba="1 0 0 1"/>
      </default>
    </default>
  </default>

  <asset>
    <texture type="skybox" colorspace="auto" name="//unnamed_texture_0" builtin="gradient" rgb1="0.95 0.95 0.95" rgb2="0.95 0.95 0.95" width="100" height="600"/>
    <texture type="2d" colorspace="auto" name="texplane" builtin="checker" rgb1="0.345 0.575 0.748" rgb2="0.345 0.575 0.748" markrgb="1 1 1" width="512" height="512"/>
    <texture type="2d" colorspace="linear" name="base" file="base.png"/>
    <texture type="2d" colorspace="linear" name="top_shell" file="top_shell.png"/>
    <texture type="2d" colorspace="linear" name="bottom_shell" file="bottom_shell.png"/>
    <texture type="2d" colorspace="linear" name="remote" file="remote.png"/>
    <texture type="2d" colorspace="linear" name="hatch" file="hatch.png"/>
    <texture type="2d" colorspace="linear" name="handle" file="handle.png"/>
    <texture type="2d" colorspace="linear" name="face" file="face.png"/>
    <texture type="2d" colorspace="linear" name="battery" file="battery.png"/>
    <texture type="2d" colorspace="linear" name="lidar_cage" file="lidar_cage.png"/>
    <texture type="2d" colorspace="linear" name="depth_camera" file="depth_camera.png"/>
    <texture type="2d" colorspace="linear" name="wide_angle_camera" file="wide_angle_camera.png"/>
    <texture type="2d" colorspace="linear" name="lidar" file="lidar.png"/>
    <texture type="2d" colorspace="linear" name="drive" file="drive.png"/>
    <texture type="2d" colorspace="linear" name="hip_l" file="hip_l.png"/>
    <texture type="2d" colorspace="linear" name="shank_l" file="shank_l.png"/>
    <texture type="2d" colorspace="linear" name="foot" file="foot.png"/>
    <texture type="2d" colorspace="linear" name="thigh" file="thigh.png"/>
    <texture type="2d" colorspace="linear" name="shank_r" file="shank_r.png"/>
    <texture type="2d" colorspace="linear" name="hip_r" file="hip_r.png"/>
    <material name="MatPlane" class="/" texture="texplane" texuniform="true" texrepeat="2 2" specular="0.9" shininess="0.5"/>
    <material name="black_plastic" class="/" rgba="0.007 0.007 0.007 1"/>
    <material name="green" class="/" rgba="0.052 0.178 0.033 1"/>
    <material name="red" class="/" rgba="0.178 0.006 0.005 1"/>
    <material name="yellow" class="/" rgba="0.178 0.119 0.006 1"/>
    <material name="lwl" class="/" rgba="0.8 0.8 0.8 1"/>
    <material name="base" class="/" texture="base"/>
    <material name="top_shell" class="/" texture="top_shell"/>
    <material name="bottom_shell" class="/" texture="bottom_shell"/>
    <material name="hip_l" class="/" texture="hip_l"/>
    <material name="thigh" class="/" texture="thigh"/>
    <material name="shank_l" class="/" texture="shank_l"/>
    <material name="foot" class="/" texture="foot"/>
    <material name="hip_r" class="/" texture="hip_r"/>
    <material name="shank" class="/" texture="shank_r"/>
    <material name="hatch" class="/" texture="hatch"/>
    <material name="remote" class="/" texture="remote"/>
    <material name="handle" class="/" texture="handle"/>
    <material name="face" class="/" texture="face"/>
    <material name="depth_camera" class="/" texture="depth_camera"/>
    <material name="wide_angle_camera" class="/" texture="wide_angle_camera"/>
    <material name="battery" class="/" texture="battery"/>
    <material name="lidar_cage" class="/" texture="lidar_cage"/>
    <material name="lidar" class="/" texture="lidar"/>
    <material name="drive" class="/" texture="drive"/>
    <mesh name="base_0" class="/" file="base_0.obj"/>
    <mesh name="base_1" class="/" file="base_1.obj"/>
    <mesh name="base_2" class="/" file="base_2.obj"/>
    <mesh name="base_3" class="/" file="base_3.obj"/>
    <mesh name="base_4" class="/" file="base_4.obj"/>
    <mesh name="base_5" class="/" file="base_5.obj"/>
    <mesh name="top_shell" class="/" file="top_shell.obj"/>
    <mesh name="bottom_shell" class="/" file="bottom_shell.obj"/>
    <mesh name="remote" class="/" file="remote.obj"/>
    <mesh name="handle" class="/" file="handle.obj"/>
    <mesh name="face" class="/" file="face.obj"/>
    <mesh name="wide_angle_camera" class="/" file="wide_angle_camera.obj"/>
    <mesh name="depth_camera" class="/" file="depth_camera.obj"/>
    <mesh name="battery" class="/" file="battery.obj"/>
    <mesh name="lidar_cage" class="/" file="lidar_cage.obj"/>
    <mesh name="lidar" class="/" file="lidar.obj"/>
    <mesh name="drive" class="/" file="drive.obj"/>
    <mesh name="hip_l" class="/" file="hip_l.obj"/>
    <mesh name="thigh" class="/" file="thigh.obj"/>
    <mesh name="shank_l" class="/" file="shank_l.obj"/>
    <mesh name="foot" class="/" file="foot.obj"/>
    <mesh name="hip_r" class="/" file="hip_r.obj"/>
    <mesh name="hatch" class="/" file="hatch.obj"/>
    <mesh name="shank_r" class="/" file="shank_r.obj"/>
  </asset>

  <worldbody>
    <geom name="floor" class="/" size="100 100 0.125" type="plane" group="0" material="MatPlane"/>
    <light name="toplight_shadow" class="/" pos="0 0 5" dir="0.0990148 0.0990148 -0.990148" type="directional" ambient="0.04 0.04 0.04" diffuse="0.55 0.55 0.55" specular="0.12 0.12 0.12"/>
    <light name="toplight_fill" class="/" pos="0 0 5" dir="0.0990148 0.0990148 -0.990148" type="directional" castshadow="false" ambient="0.04 0.04 0.04" diffuse="0.3 0.3 0.3" specular="0.08 0.08 0.08"/>
    <body name="trunk" childclass="anymal_c" pos="0.00182921 0.000590217 0.00891486" quat="0.999992 -0.00159725 0.00237832 -0.00273208">
      <inertial pos="0.0043104 -0.00619431 0.0277289" quat="0.51751 0.467987 0.508517 0.504561" mass="11.5242" diaginertia="0.994061 0.20706 0.020632"/>
      <joint name="//unnamed_joint_0" type="free" armature="0" damping="0" frictionloss="0"/>
      <geom name="//unnamed_geom_1" class="visual" material="green" mesh="base_0"/>
      <geom name="//unnamed_geom_2" class="visual" material="yellow" mesh="base_1"/>
      <geom name="//unnamed_geom_3" class="visual" material="red" mesh="base_2"/>
      <geom name="//unnamed_geom_4" class="visual" material="black_plastic" mesh="base_3"/>
      <geom name="//unnamed_geom_5" class="visual" material="lwl" mesh="base_4"/>
      <geom name="//unnamed_geom_6" class="visual" material="base" mesh="base_5"/>
      <geom name="trunk_1" class="collision" size="0.250269 0.0604097 0.0776696" type="box"/>
      <geom name="trunk_2" class="collision" size="0.0776696 0.0625672" pos="0.244947 0.0577644 0" quat="0.707107 0 0.707107 0"/>
      <geom name="trunk_3" class="collision" size="0.0776696 0.0625672" pos="-0.244947 0.0577644 0" quat="0.707107 0 0.707107 0"/>
      <geom name="trunk_4" class="collision" size="0.0776696 0.0625672" pos="0.244947 -0.0577644 0" quat="0.707107 0 0.707107 0"/>
      <geom name="trunk_5" class="collision" size="0.0776696 0.0625672" pos="-0.244947 -0.0577644 0" quat="0.707107 0 0.707107 0"/>
      <geom name="//unnamed_geom_12" class="visual" material="top_shell" mesh="top_shell"/>
      <geom name="//unnamed_geom_13" class="visual" material="bottom_shell" mesh="bottom_shell"/>
      <geom name="//unnamed_geom_14" class="visual" material="remote" mesh="remote"/>
      <geom name="//unnamed_geom_15" class="visual" material="handle" mesh="handle"/>
      <geom name="//unnamed_geom_16" class="visual" pos="0.466808 0 0" quat="1 0 0 0" material="face" mesh="face"/>
      <geom name="trunk_6" class="collision" size="0.0474647 0.0604097 0.0776696" pos="0.528749 0 0" type="box"/>
      <geom name="//unnamed_geom_18" class="collision" size="0.0776696 0.0474647" pos="0.528749 0.0577644 0" quat="0.707107 0 0.707107 0"/>
      <geom name="//unnamed_geom_19" class="collision" size="0.0776696 0.0474647" pos="0.528749 -0.0577644 0" quat="0.707107 0 0.707107 0"/>
      <geom name="//unnamed_geom_20" class="visual" pos="0.519888 0 -0.014904" quat="0.965926 0 0.258819 0" material="depth_camera" mesh="depth_camera"/>
      <geom name="//unnamed_geom_21" class="visual" pos="0.577738 0 0.00954465" material="wide_angle_camera" mesh="wide_angle_camera"/>
      <geom name="//unnamed_geom_22" class="visual_zflip" pos="-0.466808 0 0" quat="0 0 0 1" material="face" mesh="face"/>
      <geom name="trunk_7" class="collision" size="0.0474647 0.0604097 0.0776696" pos="-0.528749 0 0" quat="0 0 0 1" type="box"/>
      <geom name="//unnamed_geom_24" class="collision" size="0.0776696 0.0474647" pos="-0.528749 -0.0577644 0" quat="0 -0.707107 0 0.707107"/>
      <geom name="//unnamed_geom_25" class="collision" size="0.0776696 0.0474647" pos="-0.528749 0.0577644 0" quat="0 -0.707107 0 0.707107"/>
      <geom name="//unnamed_geom_26" class="visual" pos="-0.519888 0 -0.014904" quat="0 -0.258819 0 0.965926" material="depth_camera" mesh="depth_camera"/>
      <geom name="//unnamed_geom_27" class="visual_zflip" pos="-0.577738 0 0.00954465" quat="0 0 0 1" material="wide_angle_camera" mesh="wide_angle_camera"/>
      <geom name="//unnamed_geom_28" class="visual" material="battery" mesh="battery"/>
      <geom name="//unnamed_geom_29" class="visual" pos="0 0.0591253 0.0222353" quat="0.683013 -0.183013 0.183013 0.683013" material="depth_camera" mesh="depth_camera"/>
      <geom name="//unnamed_geom_30" class="visual" pos="0 -0.0591253 0.0222353" quat="0.683013 0.183013 0.183013 -0.683013" material="depth_camera" mesh="depth_camera"/>
      <geom name="//unnamed_geom_31" class="visual" pos="-0.409935 0 0.0468625" quat="1 0 0 0" material="lidar_cage" mesh="lidar_cage"/>
      <geom name="trunk_8" class="collision" size="0.0604097 0.0517797" pos="-0.409935 0 0.0851176"/>
      <geom name="//unnamed_geom_33" class="visual" pos="-0.409935 -0.000118251 0.0906646" quat="0.707107 0 0 -0.707107" material="lidar" mesh="lidar"/>
      <geom name="//unnamed_geom_34" class="visual" pos="0.337746 0.0857547 3.23647e-09" quat="0.258819 0.965926 0 0" material="drive" mesh="drive"/>
      <geom name="//unnamed_geom_35" class="visual" pos="0.337746 -0.0857547 -3.23647e-09" quat="0.258819 -0.965926 0 0" material="drive" mesh="drive"/>
      <geom name="//unnamed_geom_36" class="visual" pos="-0.337746 0.0857547 -3.23647e-09" quat="0 0 0.965926 -0.258819" material="drive" mesh="drive"/>
      <geom name="//unnamed_geom_37" class="visual" pos="-0.337746 -0.0857547 3.23647e-09" quat="0 0 -0.965926 -0.258819" material="drive" mesh="drive"/>
      <geom name="//unnamed_geom_38" class="visual" pos="0.130639 0 0.0465437" quat="1 0 0 0" material="hatch" mesh="hatch"/>
      <geom name="//unnamed_geom_39" class="reward_collision_sphere" size="0.103559"/>
      <geom name="//unnamed_geom_40" class="reward_collision_sphere" size="0.103559" pos="0.506788 0 0"/>
      <geom name="//unnamed_geom_41" class="reward_collision_sphere" size="0.103559" pos="-0.506788 0 0"/>
      <site name="imu" pos="0.286457 -0.00906357 0.0573849" size="0.00862995"/>
      <camera name="track" pos="0 -1.65041 0" quat="0.707107 0.707107 0 0" mode="trackcom"/>
      <camera name="ego_camera" pos="0.506788 0 -0.0255034" quat="-0.5 -0.5 0.5 0.5"/>
      <body name="LF_HIP" pos="0.339024 0.0857676 -0.00217829" quat="0.258547 0.965998 0.000538526 -6.88571e-05">
        <inertial pos="0.0712078 -0.0113384 0.0032226" quat="-0.134744 0.678652 -0.14038 0.708215" mass="1.86924" diaginertia="0.010327 0.00194928 0.000360872"/>
        <joint name="LF_HAA" pos="0 0 0" axis="0.999424 0.0158213 -0.0300384" stiffness="0.0226128" range="-0.743706 0.43697" armature="0.0085171" damping="0.0320789" frictionloss="0.0751772"/>
        <geom name="//unnamed_geom_42" class="visual" pos="0 0.000190387 -3.12709e-05" quat="0.258819 -0.965926 0 0" material="hip_l" mesh="hip_l"/>
        <geom name="//unnamed_geom_43" class="visual" pos="0.0674591 -0.0777114 -0.043479" quat="0.183013 -0.683013 0.683013 0.183013" material="drive" mesh="drive"/>
        <geom name="//unnamed_geom_44" class="collision" size="0.0431498 0.0604097" pos="0.0674591 -0.00986929 -0.00440253" quat="-0.353553 -0.612372 0.612372 -0.353553"/>
        <body name="LF_THIGH" pos="0.0733969 -0.0627332 -0.0338176" quat="0.183114 -0.683336 0.682855 0.182291">
          <inertial pos="0.0352286 0.0013869 -0.158494" quat="0.993164 -0.00488308 -0.0801351 0.0847287" mass="2.16427" diaginertia="0.060306 0.0124632 0.000514104"/>
          <joint name="LF_HFE" pos="0 0 0" axis="0.999991 0.000677057 -0.00422474" stiffness="0.00917651" range="-3.08412 3.14385" armature="0.0104939" damping="0" frictionloss="0.0853618"/>
          <geom name="//unnamed_geom_45" class="visual" pos="0.00598851 9.43649e-06 0" quat="0.707107 0 0 -0.707107" material="thigh" mesh="thigh"/>
          <geom name="//unnamed_geom_46" class="collision" size="0.0560947 0.0345198" pos="0.0450478 0 0" quat="0.5 0.5 -0.5 -0.5"/>
          <geom name="//unnamed_geom_47" class="collision" size="0.0323623 0.0258899 0.121953" pos="0.0337859 0 -0.0900997" quat="0.707107 0 0 -0.707107" type="box"/>
          <geom name="//unnamed_geom_48" class="visual" pos="0.112957 0 -0.181712" quat="1 0 0 0" material="drive" mesh="drive"/>
          <geom name="//unnamed_geom_49" class="collision" size="0.0431498 0.0604097" pos="0.0341237 0 -0.181712" quat="0.707107 0 0.707107 0"/>
          <geom name="//unnamed_geom_50" class="reward_collision_sphere" size="0.0690396" pos="0.0281549 0 0"/>
          <body name="LF_SHANK" pos="0.113899 -0.00131871 -0.179242" quat="1 -6.92227e-05 -4.72098e-05 0.000122872">
            <inertial pos="0.0162093 -0.0422961 -0.0516516" quat="0.992296 -0.119036 -0.00444145 -0.0340417" mass="0.373761" diaginertia="0.0197102 0.00353914 0.000114228"/>
            <joint name="LF_KFE" pos="0 0 0" axis="0.999972 0.00709602 -0.00217153" range="-2.94401 3.07628" armature="0.00868209" damping="0.00585177" frictionloss="0.0461509"/>
            <geom name="//unnamed_geom_51" class="visual" pos="0.00195272 0.010412 0" quat="0.707107 0 0 -0.707107" material="shank_l" mesh="shank_l"/>
            <geom name="LF_kfe_act" class="collision" size="0.0517797 0.0172599" pos="0.0225239 0 0" quat="0.5 0.5 -0.5 -0.5"/>
            <geom name="//unnamed_geom_53" class="collision" size="0.0496214 0.0291261 0.0163969" pos="0.0225239 -0.0474485 0" quat="0.5 0.5 -0.5 -0.5" type="box"/>
            <geom name="//unnamed_geom_54" class="visual" pos="0.0146964 -0.0692215 -0.215485" quat="0.382683 0 0 -0.92388" material="foot" mesh="foot"/>
            <geom name="LF_calf" class="collision" size="0.0151024 0.1219" pos="0.0146968 -0.0725768 -0.107742" quat="0.707107 0 0 -0.707107"/>
            <geom name="LF_foot" class="foot" size="0.0313291" pos="0.0146968 -0.0725768 -0.201139" quat="0.707107 0 0 -0.707107"/>
            <geom name="//unnamed_geom_57" class="reward_collision_sphere" size="0.0862995" pos="-0.0563098 0 0"/>
            <geom name="//unnamed_geom_58" class="reward_collision_sphere" size="0.0431498" pos="0.0146968 -0.0725768 -0.201139"/>
            <site name="LF_foot" class="foot" pos="0.0146968 -0.0725768 -0.201139" quat="0.707107 0 0 -0.707107" size="0.00862995"/>
          </body>
        </body>
      </body>
      <body name="RF_HIP" pos="0.34075 -0.0890484 -6.29435e-05" quat="0.256608 -0.966507 -9.71021e-06 -0.00408846">
        <inertial pos="0.0649558 0.0133615 -0.00554673" quat="0.158262 0.686702 0.0898088 0.703795" mass="1.58475" diaginertia="0.0108096 0.00184797 0.000354511"/>
        <joint name="RF_HAA" pos="0 0 0" axis="0.9999 -0.0126345 0.00636381" stiffness="0.0296418" range="-0.314374 0.773039" armature="0.00885984" damping="0.0269722" frictionloss="0.0693962"/>
        <geom name="//unnamed_geom_59" class="visual" pos="0 -0.000190386 -3.12708e-05" quat="0.258819 0.965926 0 0" material="hip_r" mesh="hip_r"/>
        <geom name="//unnamed_geom_60" class="visual" pos="0.0674591 0.0777114 -0.043479" quat="0.183013 0.683013 0.683013 -0.183013" material="drive" mesh="drive"/>
        <geom name="//unnamed_geom_61" class="collision" size="0.0431498 0.0604097" pos="0.0674591 0.00986929 -0.00440253" quat="-0.353553 0.612372 0.612372 0.353553"/>
        <body name="RF_THIGH" pos="0.0693669 0.0631475 -0.0288374" quat="0.183333 0.682362 0.683514 -0.183247">
          <inertial pos="0.0367548 0.000723589 -0.156178" quat="0.992704 -0.00606536 -0.0815031 0.0886535" mass="1.85327" diaginertia="0.0564844 0.0123783 0.000435306"/>
          <joint name="RF_HFE" pos="0 0 0" axis="0.999996 0.00268658 -0.000460678" range="-3.15247 3.20079" armature="0.00939772" damping="0.0552567" frictionloss="0.110908"/>
          <geom name="//unnamed_geom_62" class="visual" pos="0.00598851 9.43649e-06 0" quat="0.707107 0 0 -0.707107" material="thigh" mesh="thigh"/>
          <geom name="//unnamed_geom_63" class="collision" size="0.0560947 0.0345198" pos="0.0450478 0 0" quat="0.5 0.5 0.5 0.5"/>
          <geom name="//unnamed_geom_64" class="collision" size="0.0323623 0.0258899 0.121953" pos="0.0337859 0 -0.0900997" quat="0.707107 0 0 0.707107" type="box"/>
          <geom name="//unnamed_geom_65" class="visual" pos="0.112957 0 -0.181712" quat="1 0 0 0" material="drive" mesh="drive"/>
          <geom name="//unnamed_geom_66" class="collision" size="0.0431498 0.0604097" pos="0.0341237 0 -0.181712" quat="0.707107 0 0.707107 0"/>
          <geom name="//unnamed_geom_67" class="reward_collision_sphere" size="0.0690396" pos="0.0281549 0 0"/>
          <body name="RF_SHANK" pos="0.121498 -0.000281235 -0.179611" quat="1 -0.000398807 0.000136232 0.000292471">
            <inertial pos="0.00577584 0.0581516 -0.0571257" quat="0.991613 0.109081 -0.0323059 0.0613217" mass="0.406529" diaginertia="0.0196755 0.00353831 0.000135376"/>
            <joint name="RF_KFE" pos="0 0 0" axis="1 0.000114065 -0.000138797" range="-3.135 3.10182" armature="0.00867021" damping="0.0292369" frictionloss="0.0956001"/>
            <geom name="//unnamed_geom_68" class="visual" pos="0.00195271 -0.010412 0" quat="0.707107 0 0 0.707107" material="shank" mesh="shank_r"/>
            <geom name="RF_kfe_act" class="collision" size="0.0517797 0.0172599" pos="0.0225239 0 0" quat="0.5 0.5 0.5 0.5"/>
            <geom name="//unnamed_geom_70" class="collision" size="0.0496214 0.0291261 0.0163969" pos="0.0225239 0.0474485 0" quat="0.5 0.5 0.5 0.5" type="box"/>
            <geom name="//unnamed_geom_71" class="visual" pos="0.0146973 0.0692215 -0.215485" quat="0.382683 0 0 0.92388" material="foot" mesh="foot"/>
            <geom name="RF_calf" class="collision" size="0.0151024 0.1219" pos="0.0146968 0.0725768 -0.107742" quat="0.707107 0 0 0.707107"/>
            <geom name="RF_foot" class="foot" size="0.0330024" pos="0.0146968 0.0725768 -0.201139" quat="0.707107 0 0 0.707107"/>
            <geom name="//unnamed_geom_74" class="reward_collision_sphere" size="0.0862995" pos="-0.0563098 0 0"/>
            <geom name="//unnamed_geom_75" class="reward_collision_sphere" size="0.0431498" pos="0.0146968 0.0725768 -0.201139"/>
            <site name="RF_foot" class="foot" pos="0.0146968 0.0725768 -0.201139" quat="0.707107 0 0 0.707107" size="0.00862995"/>
          </body>
        </body>
      </body>
      <body name="LH_HIP" pos="-0.337125 0.0901326 -0.00441424" quat="-2.07457e-05 -3.6966e-05 0.965949 -0.258733">
        <inertial pos="0.0639899 0.0200038 0.00369325" quat="0.136454 0.675957 0.131336 0.712189" mass="1.81233" diaginertia="0.0113174 0.00192902 0.000384792"/>
        <joint name="LH_HAA" pos="0 0 0" axis="0.999433 0.0168156 0.029163" stiffness="0.00697995" range="-0.352946 0.566423" armature="0.0057285" damping="0.0255267" frictionloss="0.0865811"/>
        <geom name="//unnamed_geom_76" class="visual" pos="0 -0.000190386 -3.12708e-05" quat="-0.258819 -0.965926 0 0" material="hip_r" mesh="hip_r"/>
        <geom name="//unnamed_geom_77" class="visual" pos="0.0674591 0.0777114 -0.043479" quat="0.183013 0.683013 0.683013 -0.183013" material="drive" mesh="drive"/>
        <geom name="//unnamed_geom_78" class="collision" size="0.0431498 0.0604097" pos="0.0674591 0.00986929 -0.00440253" quat="-0.353553 0.612372 0.612372 0.353553"/>
        <body name="LH_THIGH" pos="0.0664893 0.0663552 -0.0361749" quat="0.184946 0.682913 0.682995 -0.181501">
          <inertial pos="0.0250414 0.00495574 -0.147122" quat="0.992631 -0.00483226 -0.0818167 0.0892518" mass="1.681" diaginertia="0.0431003 0.0102004 0.000363774"/>
          <joint name="LH_HFE" pos="0 0 0" axis="0.998888 -0.0451219 0.0136545" range="-3.06316 3.17595" armature="0.00898215" damping="0.0553522" frictionloss="0.0788286"/>
          <geom name="//unnamed_geom_79" class="visual" pos="0.00598851 9.43649e-06 0" quat="0.707107 0 0 -0.707107" material="thigh" mesh="thigh"/>
          <geom name="//unnamed_geom_80" class="collision" size="0.0560947 0.0345198" pos="0.0450478 0 0" quat="0.5 0.5 -0.5 -0.5"/>
          <geom name="//unnamed_geom_81" class="collision" size="0.0323623 0.0258899 0.121953" pos="0.0337859 0 -0.0900997" quat="0.707107 0 0 -0.707107" type="box"/>
          <geom name="//unnamed_geom_82" class="visual" pos="0.112957 0 -0.181712" quat="1 0 0 0" material="drive" mesh="drive"/>
          <geom name="//unnamed_geom_83" class="collision" size="0.0431498 0.0604097" pos="0.0341237 0 -0.181712" quat="0.707107 0 0.707107 0"/>
          <geom name="//unnamed_geom_84" class="reward_collision_sphere" size="0.0690396" pos="0.0281549 0 0"/>
          <body name="LH_SHANK" pos="0.116238 0.000513028 -0.176883" quat="0.999996 -0.000801177 -0.00254481 -0.00091583">
            <inertial pos="0.0147231 0.0460419 -0.0422537" quat="0.990652 0.136042 -0.0087255 -0.00499006" mass="0.410318" diaginertia="0.0194025 0.00385605 0.00012262"/>
            <joint name="LH_KFE" pos="0 0 0" axis="0.999952 0.00831127 -0.00522043" range="-3.11505 3.34025" armature="0.00542888" damping="0.0513232" frictionloss="0.0861779"/>
            <geom name="//unnamed_geom_85" class="visual" pos="0.00195271 -0.010412 0" quat="-0.707107 0 0 -0.707107" material="shank" mesh="shank_r"/>
            <geom name="LH_kfe_act" class="collision" size="0.0517797 0.0172599" pos="0.0225239 0 0" quat="0.5 0.5 -0.5 -0.5"/>
            <geom name="//unnamed_geom_87" class="collision" size="0.0496214 0.0291261 0.0163969" pos="0.0225239 0.0474485 0" quat="0.5 0.5 -0.5 -0.5" type="box"/>
            <geom name="//unnamed_geom_88" class="visual" pos="0.0146973 0.0692215 -0.215485" quat="-0.382683 0 0 -0.92388" material="foot" mesh="foot"/>
            <geom name="LH_calf" class="collision" size="0.0151024 0.1219" pos="0.0146968 0.0725768 -0.107742" quat="0.707107 0 0 -0.707107"/>
            <geom name="LH_foot" class="foot" size="0.0243907" pos="0.0146968 0.0725768 -0.201139" quat="0.707107 0 0 -0.707107"/>
            <geom name="//unnamed_geom_91" class="reward_collision_sphere" size="0.0862995" pos="-0.0563098 0 0"/>
            <geom name="//unnamed_geom_92" class="reward_collision_sphere" size="0.0431498" pos="0.0146968 0.0725768 -0.201139"/>
            <site name="LH_foot" class="foot" pos="0.0146968 0.0725768 -0.201139" quat="0.707107 0 0 -0.707107" size="0.00862995"/>
          </body>
        </body>
      </body>
      <body name="RH_HIP" pos="-0.347609 -0.084074 -0.00759493" quat="-0.000182588 0.000527956 -0.96583 -0.259174">
        <inertial pos="0.0697593 -0.00924453 -0.00549829" quat="-0.133047 0.682428 -0.136594 0.705643" mass="1.78912" diaginertia="0.00845968 0.00170527 0.000298005"/>
        <joint name="RH_HAA" pos="0 0 0" axis="0.998755 -0.0166176 0.0470258" stiffness="0.00585652" range="-0.683908 0.503231" armature="0.00853878" damping="0.0137208" frictionloss="0.044147"/>
        <geom name="//unnamed_geom_93" class="visual" pos="0 0.000190387 -3.12709e-05" quat="-0.258819 0.965926 0 0" material="hip_l" mesh="hip_l"/>
        <geom name="//unnamed_geom_94" class="visual" pos="0.0674591 -0.0777114 -0.043479" quat="-0.183013 0.683013 -0.683013 -0.183013" material="drive" mesh="drive"/>
        <geom name="//unnamed_geom_95" class="collision" size="0.0431498 0.0604097" pos="0.0674591 -0.00986929 -0.00440253" quat="0.353553 0.612372 -0.612372 0.353553"/>
        <body name="RH_THIGH" pos="0.0657481 -0.0612512 -0.0218466" quat="-0.182995 0.683346 -0.682437 -0.18393">
          <inertial pos="0.0333753 0.00260891 -0.149431" quat="0.990593 -0.00535951 -0.0924978 0.1007" mass="2.21028" diaginertia="0.0502626 0.0112985 0.000445716"/>
          <joint name="RH_HFE" pos="0 0 0" axis="0.999969 -0.00156165 -0.00774443" stiffness="0.00568883" range="-3.11203 3.25049" armature="0.00907787" damping="0.00812684" frictionloss="0.0843762"/>
          <geom name="//unnamed_geom_96" class="visual" pos="0.00598851 9.43649e-06 0" quat="0.707107 0 0 -0.707107" material="thigh" mesh="thigh"/>
          <geom name="//unnamed_geom_97" class="collision" size="0.0560947 0.0345198" pos="0.0450478 0 0" quat="0.5 0.5 0.5 0.5"/>
          <geom name="//unnamed_geom_98" class="collision" size="0.0323623 0.0258899 0.121953" pos="0.0337859 0 -0.0900997" quat="0.707107 0 0 0.707107" type="box"/>
          <geom name="//unnamed_geom_99" class="visual" pos="0.112957 0 -0.181712" quat="1 0 0 0" material="drive" mesh="drive"/>
          <geom name="//unnamed_geom_100" class="collision" size="0.0431498 0.0604097" pos="0.0341237 0 -0.181712" quat="0.707107 0 0.707107 0"/>
          <geom name="//unnamed_geom_101" class="reward_collision_sphere" size="0.0690396" pos="0.0281549 0 0"/>
          <body name="RH_SHANK" pos="0.121117 -0.00534704 -0.17681" quat="0.999987 -0.00182479 0.0042586 0.00194268">
            <inertial pos="0.00598345 -0.0493336 -0.0524674" quat="0.993843 -0.106812 0.0291794 -0.00399618" mass="0.356359" diaginertia="0.017281 0.00327392 0.000124092"/>
            <joint name="RH_KFE" pos="0 0 0" axis="0.998898 0.0381354 -0.0273667" stiffness="0.0388988" range="-3.27527 3.12898" armature="0.00903374" damping="0.0425326" frictionloss="0.0848663"/>
            <geom name="//unnamed_geom_102" class="visual" pos="0.00195272 0.010412 0" quat="0.707107 0 0 -0.707107" material="shank_l" mesh="shank_l"/>
            <geom name="RH_kfe_act" class="collision" size="0.0517797 0.0172599" pos="0.0225239 0 0" quat="0.5 0.5 0.5 0.5"/>
            <geom name="//unnamed_geom_104" class="collision" size="0.0496214 0.0291261 0.0163969" pos="0.0225239 -0.0474485 0" quat="0.5 0.5 0.5 0.5" type="box"/>
            <geom name="//unnamed_geom_105" class="visual" pos="0.0146964 -0.0692215 -0.215485" quat="0.382683 0 0 -0.92388" material="foot" mesh="foot"/>
            <geom name="RH_calf" class="collision" size="0.0151024 0.1219" pos="0.0146968 -0.0725768 -0.107742" quat="0.707107 0 0 0.707107"/>
            <geom name="RH_foot" class="foot" size="0.02505" pos="0.0146968 -0.0725768 -0.201139" quat="0.707107 0 0 0.707107"/>
            <geom name="//unnamed_geom_108" class="reward_collision_sphere" size="0.0862995" pos="-0.0563098 0 0"/>
            <geom name="//unnamed_geom_109" class="reward_collision_sphere" size="0.0431498" pos="0.0146968 -0.0725768 -0.201139"/>
            <site name="RH_foot" class="foot" pos="0.0146968 -0.0725768 -0.201139" quat="0.707107 0 0 0.707107" size="0.00862995"/>
          </body>
        </body>
      </body>
    </body>
  </worldbody>

  <contact>
    <pair class="/" geom1="floor" geom2="LF_foot" name="//unnamed_contact_0"/>
    <pair class="/" geom1="floor" geom2="RF_foot" name="//unnamed_contact_1"/>
    <pair class="/" geom1="floor" geom2="LH_foot" name="//unnamed_contact_2"/>
    <pair class="/" geom1="floor" geom2="RH_foot" name="//unnamed_contact_3"/>
  </contact>

  <actuator>
    <general name="LF_HAA" class="/" joint="LF_HAA" forcerange="-67.7679 67.7679" gainprm="70.4662" biasprm="0 -70.4662 -2.09859"/>
    <general name="LF_HFE" class="/" joint="LF_HFE" forcerange="-72.9662 72.9662" gainprm="70.4662" biasprm="0 -70.4662 -2.09859"/>
    <general name="LF_KFE" class="/" joint="LF_KFE" forcerange="-61.3005 61.3005" gainprm="70.4662" biasprm="0 -70.4662 -2.09859"/>
    <general name="RF_HAA" class="/" joint="RF_HAA" forcerange="-65.3875 65.3875" gainprm="70.4662" biasprm="0 -70.4662 -2.09859"/>
    <general name="RF_HFE" class="/" joint="RF_HFE" forcerange="-62.3185 62.3185" gainprm="70.4662" biasprm="0 -70.4662 -2.09859"/>
    <general name="RF_KFE" class="/" joint="RF_KFE" forcerange="-66.6915 66.6915" gainprm="70.4662" biasprm="0 -70.4662 -2.09859"/>
    <general name="LH_HAA" class="/" joint="LH_HAA" forcerange="-67.1821 67.1821" gainprm="70.4662" biasprm="0 -70.4662 -2.09859"/>
    <general name="LH_HFE" class="/" joint="LH_HFE" forcerange="-91.8023 91.8023" gainprm="70.4662" biasprm="0 -70.4662 -2.09859"/>
    <general name="LH_KFE" class="/" joint="LH_KFE" forcerange="-49.9 49.9" gainprm="70.4662" biasprm="0 -70.4662 -2.09859"/>
    <general name="RH_HAA" class="/" joint="RH_HAA" forcerange="-70.4842 70.4842" gainprm="70.4662" biasprm="0 -70.4662 -2.09859"/>
    <general name="RH_HFE" class="/" joint="RH_HFE" forcerange="-70.7603 70.7603" gainprm="70.4662" biasprm="0 -70.4662 -2.09859"/>
    <general name="RH_KFE" class="/" joint="RH_KFE" forcerange="-60.2936 60.2936" gainprm="70.4662" biasprm="0 -70.4662 -2.09859"/>
  </actuator>

  <sensor>
    <gyro site="imu" name="imu_angular_velocity"/>
    <velocimeter site="imu" name="imu_linear_velocity"/>
    <framelinvel objtype="site" objname="LF_foot" name="LF_foot_global_linear_velocity"/>
    <framelinvel objtype="site" objname="RF_foot" name="RF_foot_global_linear_velocity"/>
    <framelinvel objtype="site" objname="LH_foot" name="LH_foot_global_linear_velocity"/>
    <framelinvel objtype="site" objname="RH_foot" name="RH_foot_global_linear_velocity"/>
  </sensor>

  <keyframe>
    <key name="home" qpos="0 0 0.55 1 0 0 0 0 0.4 -0.8 0 -0.4 0.8 0 -0.4 0.8 0 0.4 -0.8"/>
  </keyframe>
</mujoco>
