<mujoco model="anymal_c">
  <compiler angle="radian" assetdir="assets" balanceinertia="true" inertiafromgeom="false"/>

  <option timestep="0.005" density="1.2" viscosity="2e-05"/>

  <size nkey="1"/>

  <visual>
    <quality shadowsize="8192"/>
    <map shadowclip="0.5"/>
  </visual>

  <default>
    <default class="/">
      <material specular="0" shininess="0.25"/>
      <geom contype="0" conaffinity="0" group="1" solref="-1000 -80"/>
      <site size="0.01 0.005 0.005" group="5"/>
      <general forcelimited="true" forcerange="-80 80" biastype="affine" gainprm="80" biasprm="0 -80 -2"/>
      <default class="anymal_c">
        <joint armature="0.01" damping="0.01" frictionloss="0.1"/>
        <default class="visual">
          <geom type="mesh" group="2"/>
          <default class="visual_zflip"/>
        </default>
        <default class="collision">
          <geom type="cylinder" group="3"/>
          <default class="foot">
            <geom size="0.03 0 0" type="sphere" condim="6" priority="1" friction="0.8 0.02 0.01" solimp="0.015 1 0.03"/>
          </default>
        </default>
      </default>
      <default class="reward_collision_sphere">
        <geom group="5" rgba="1 0 0 1"/>
      </default>
    </default>
  </default>

  <asset>
    <texture type="skybox" colorspace="auto" name="//unnamed_texture_0" builtin="gradient" rgb1="0.95 0.95 0.95" rgb2="0.95 0.95 0.95" width="100" height="600"/>
    <texture type="2d" colorspace="auto" name="texplane" builtin="checker" rgb1="0.345 0.575 0.748" rgb2="0.345 0.575 0.748" markrgb="1 1 1" width="512" height="512"/>
    <texture type="2d" colorspace="linear" name="base" file="base.png"/>
    <texture type="2d" colorspace="linear" name="top_shell" file="top_shell.png"/>
    <texture type="2d" colorspace="linear" name="bottom_shell" file="bottom_shell.png"/>
    <texture type="2d" colorspace="linear" name="remote" file="remote.png"/>
    <texture type="2d" colorspace="linear" name="hatch" file="hatch.png"/>
    <texture type="2d" colorspace="linear" name="handle" file="handle.png"/>
    <texture type="2d" colorspace="linear" name="face" file="face.png"/>
    <texture type="2d" colorspace="linear" name="battery" file="battery.png"/>
    <texture type="2d" colorspace="linear" name="lidar_cage" file="lidar_cage.png"/>
    <texture type="2d" colorspace="linear" name="depth_camera" file="depth_camera.png"/>
    <texture type="2d" colorspace="linear" name="wide_angle_camera" file="wide_angle_camera.png"/>
    <texture type="2d" colorspace="linear" name="lidar" file="lidar.png"/>
    <texture type="2d" colorspace="linear" name="drive" file="drive.png"/>
    <texture type="2d" colorspace="linear" name="hip_l" file="hip_l.png"/>
    <texture type="2d" colorspace="linear" name="shank_l" file="shank_l.png"/>
    <texture type="2d" colorspace="linear" name="foot" file="foot.png"/>
    <texture type="2d" colorspace="linear" name="thigh" file="thigh.png"/>
    <texture type="2d" colorspace="linear" name="shank_r" file="shank_r.png"/>
    <texture type="2d" colorspace="linear" name="hip_r" file="hip_r.png"/>
    <material name="MatPlane" class="/" texture="texplane" texuniform="true" texrepeat="2 2" specular="0.9" shininess="0.5"/>
    <material name="black_plastic" class="/" rgba="0.007 0.007 0.007 1"/>
    <material name="green" class="/" rgba="0.052 0.178 0.033 1"/>
    <material name="red" class="/" rgba="0.178 0.006 0.005 1"/>
    <material name="yellow" class="/" rgba="0.178 0.119 0.006 1"/>
    <material name="lwl" class="/" rgba="0.8 0.8 0.8 1"/>
    <material name="base" class="/" texture="base"/>
    <material name="top_shell" class="/" texture="top_shell"/>
    <material name="bottom_shell" class="/" texture="bottom_shell"/>
    <material name="hip_l" class="/" texture="hip_l"/>
    <material name="thigh" class="/" texture="thigh"/>
    <material name="shank_l" class="/" texture="shank_l"/>
    <material name="foot" class="/" texture="foot"/>
    <material name="hip_r" class="/" texture="hip_r"/>
    <material name="shank" class="/" texture="shank_r"/>
    <material name="hatch" class="/" texture="hatch"/>
    <material name="remote" class="/" texture="remote"/>
    <material name="handle" class="/" texture="handle"/>
    <material name="face" class="/" texture="face"/>
    <material name="depth_camera" class="/" texture="depth_camera"/>
    <material name="wide_angle_camera" class="/" texture="wide_angle_camera"/>
    <material name="battery" class="/" texture="battery"/>
    <material name="lidar_cage" class="/" texture="lidar_cage"/>
    <material name="lidar" class="/" texture="lidar"/>
    <material name="drive" class="/" texture="drive"/>
    <mesh name="base_0" class="/" file="base_0.obj"/>
    <mesh name="base_1" class="/" file="base_1.obj"/>
    <mesh name="base_2" class="/" file="base_2.obj"/>
    <mesh name="base_3" class="/" file="base_3.obj"/>
    <mesh name="base_4" class="/" file="base_4.obj"/>
    <mesh name="base_5" class="/" file="base_5.obj"/>
    <mesh name="top_shell" class="/" file="top_shell.obj"/>
    <mesh name="bottom_shell" class="/" file="bottom_shell.obj"/>
    <mesh name="remote" class="/" file="remote.obj"/>
    <mesh name="handle" class="/" file="handle.obj"/>
    <mesh name="face" class="/" file="face.obj"/>
    <mesh name="wide_angle_camera" class="/" file="wide_angle_camera.obj"/>
    <mesh name="depth_camera" class="/" file="depth_camera.obj"/>
    <mesh name="battery" class="/" file="battery.obj"/>
    <mesh name="lidar_cage" class="/" file="lidar_cage.obj"/>
    <mesh name="lidar" class="/" file="lidar.obj"/>
    <mesh name="drive" class="/" file="drive.obj"/>
    <mesh name="hip_l" class="/" file="hip_l.obj"/>
    <mesh name="thigh" class="/" file="thigh.obj"/>
    <mesh name="shank_l" class="/" file="shank_l.obj"/>
    <mesh name="foot" class="/" file="foot.obj"/>
    <mesh name="hip_r" class="/" file="hip_r.obj"/>
    <mesh name="hatch" class="/" file="hatch.obj"/>
    <mesh name="shank_r" class="/" file="shank_r.obj"/>
  </asset>

  <worldbody>
    <geom name="floor" class="/" size="100 100 0.125" type="plane" group="0" material="MatPlane"/>
    <light name="toplight_shadow" class="/" pos="0 0 5" dir="0.0990148 0.0990148 -0.990148" type="directional" ambient="0.04 0.04 0.04" diffuse="0.55 0.55 0.55" specular="0.12 0.12 0.12"/>
    <light name="toplight_fill" class="/" pos="0 0 5" dir="0.0990148 0.0990148 -0.990148" type="directional" castshadow="false" ambient="0.04 0.04 0.04" diffuse="0.3 0.3 0.3" specular="0.08 0.08 0.08"/>
    <body name="trunk" childclass="anymal_c" pos="-0.000133008 -0.00283969 -0.00118522" quat="0.999999 -0.000874946 0.00110835 0.000144434">
      <inertial pos="-0.000434393 -0.00124658 0.0520132" quat="0.507858 0.50499 0.494832 0.492145" mass="20.3299" diaginertia="0.703875 0.652701 0.228858"/>
      <joint name="//unnamed_joint_0" type="free" armature="0" damping="0" frictionloss="0"/>
      <geom name="//unnamed_geom_1" class="visual" material="green" mesh="base_0"/>
      <geom name="//unnamed_geom_2" class="visual" material="yellow" mesh="base_1"/>
      <geom name="//unnamed_geom_3" class="visual" material="red" mesh="base_2"/>
      <geom name="//unnamed_geom_4" class="visual" material="black_plastic" mesh="base_3"/>
      <geom name="//unnamed_geom_5" class="visual" material="lwl" mesh="base_4"/>
      <geom name="//unnamed_geom_6" class="visual" material="base" mesh="base_5"/>
      <geom name="trunk_1" class="collision" size="0.293787 0.0709141 0.0911753" type="box"/>
      <geom name="trunk_2" class="collision" size="0.0911753 0.0734467" pos="0.222955 0.0705188 0" quat="0.707107 0 0.707107 0"/>
      <geom name="trunk_3" class="collision" size="0.0911753 0.0734467" pos="-0.222955 0.0705188 0" quat="0.707107 0 0.707107 0"/>
      <geom name="trunk_4" class="collision" size="0.0911753 0.0734467" pos="0.222955 -0.0705188 0" quat="0.707107 0 0.707107 0"/>
      <geom name="trunk_5" class="collision" size="0.0911753 0.0734467" pos="-0.222955 -0.0705188 0" quat="0.707107 0 0.707107 0"/>
      <geom name="//unnamed_geom_12" class="visual" material="top_shell" mesh="top_shell"/>
      <geom name="//unnamed_geom_13" class="visual" material="bottom_shell" mesh="bottom_shell"/>
      <geom name="//unnamed_geom_14" class="visual" material="remote" mesh="remote"/>
      <geom name="//unnamed_geom_15" class="visual" material="handle" mesh="handle"/>
      <geom name="//unnamed_geom_16" class="visual" pos="0.424895 0 0" quat="1 0 0 0" material="face" mesh="face"/>
      <geom name="trunk_6" class="collision" size="0.0557182 0.0709141 0.0911753" pos="0.481275 0 0" type="box"/>
      <geom name="//unnamed_geom_18" class="collision" size="0.0911753 0.0557182" pos="0.481275 0.0705188 0" quat="0.707107 0 0.707107 0"/>
      <geom name="//unnamed_geom_19" class="collision" size="0.0911753 0.0557182" pos="0.481275 -0.0705188 0" quat="0.707107 0 0.707107 0"/>
      <geom name="//unnamed_geom_20" class="visual" pos="0.473227 0 -0.0292554" quat="0.965926 0 0.258819 0" material="depth_camera" mesh="depth_camera"/>
      <geom name="//unnamed_geom_21" class="visual" pos="0.525866 0 0.0150701" material="wide_angle_camera" mesh="wide_angle_camera"/>
      <geom name="//unnamed_geom_22" class="visual_zflip" pos="-0.424895 0 0" quat="0 0 0 1" material="face" mesh="face"/>
      <geom name="trunk_7" class="collision" size="0.0557182 0.0709141 0.0911753" pos="-0.481275 0 0" quat="0 0 0 1" type="box"/>
      <geom name="//unnamed_geom_24" class="collision" size="0.0911753 0.0557182" pos="-0.481275 -0.0705188 0" quat="0 -0.707107 0 0.707107"/>
      <geom name="//unnamed_geom_25" class="collision" size="0.0911753 0.0557182" pos="-0.481275 0.0705188 0" quat="0 -0.707107 0 0.707107"/>
      <geom name="//unnamed_geom_26" class="visual" pos="-0.473227 0 -0.0292554" quat="0 -0.258819 0 0.965926" material="depth_camera" mesh="depth_camera"/>
      <geom name="//unnamed_geom_27" class="visual_zflip" pos="-0.525866 0 0.0150701" quat="0 0 0 1" material="wide_angle_camera" mesh="wide_angle_camera"/>
      <geom name="//unnamed_geom_28" class="visual" material="battery" mesh="battery"/>
      <geom name="//unnamed_geom_29" class="visual" pos="0 0.0767941 0.029384" quat="0.683013 -0.183013 0.183013 0.683013" material="depth_camera" mesh="depth_camera"/>
      <geom name="//unnamed_geom_30" class="visual" pos="0 -0.0767941 0.029384" quat="0.683013 0.183013 0.183013 -0.683013" material="depth_camera" mesh="depth_camera"/>
      <geom name="//unnamed_geom_31" class="visual" pos="-0.373129 0 0.0739913" quat="1 0 0 0" material="lidar_cage" mesh="lidar_cage"/>
      <geom name="trunk_8" class="collision" size="0.0709141 0.0607835" pos="-0.373129 0 0.134392"/>
      <geom name="//unnamed_geom_33" class="visual" pos="-0.373129 -6.94117e-06 0.143151" quat="0.707107 0 0 -0.707107" material="lidar" mesh="lidar"/>
      <geom name="//unnamed_geom_34" class="visual" pos="0.307421 0.104771 1.25422e-11" quat="0.258819 0.965926 0 0" material="drive" mesh="drive"/>
      <geom name="//unnamed_geom_35" class="visual" pos="0.307421 -0.104771 -1.25422e-11" quat="0.258819 -0.965926 0 0" material="drive" mesh="drive"/>
      <geom name="//unnamed_geom_36" class="visual" pos="-0.307421 0.104771 -1.25422e-11" quat="0 0 0.965926 -0.258819" material="drive" mesh="drive"/>
      <geom name="//unnamed_geom_37" class="visual" pos="-0.307421 -0.104771 1.25422e-11" quat="0 0 -0.965926 -0.258819" material="drive" mesh="drive"/>
      <geom name="//unnamed_geom_38" class="visual" pos="0.118909 0 0.073488" quat="1 0 0 0" material="hatch" mesh="hatch"/>
      <geom name="//unnamed_geom_39" class="reward_collision_sphere" size="0.121567"/>
      <geom name="//unnamed_geom_40" class="reward_collision_sphere" size="0.121567" pos="0.461286 0 0"/>
      <geom name="//unnamed_geom_41" class="reward_collision_sphere" size="0.121567" pos="-0.461286 0 0"/>
      <site name="imu" pos="0.260164 0.00384673 0.0420706" size="0.0101306"/>
      <camera name="track" pos="0 -2.01482 0" quat="0.707107 0.707107 0 0" mode="trackcom"/>
      <camera name="ego_camera" pos="0.461286 0 -0.0402674" quat="-0.5 -0.5 0.5 0.5"/>
      <body name="LF_HIP" pos="0.306687 0.105375 0.00163782" quat="0.258815 0.965927 0.000603741 0.000227647">
        <inertial pos="0.0581222 -0.017726 -0.00776333" quat="-0.125439 0.70953 -0.136342 0.679884" mass="2.88169" diaginertia="0.00671033 0.00495367 0.00343539"/>
        <joint name="LF_HAA" pos="0 0 0" axis="0.999927 -0.000343053 -0.0120613" stiffness="0.00624407" range="-0.770661 0.495185" armature="0.0104774" damping="0.00591063" frictionloss="0.0991408"/>
        <geom name="//unnamed_geom_42" class="visual" pos="0 7.37804e-07 -1.21184e-07" quat="0.258819 -0.965926 0 0" material="hip_l" mesh="hip_l"/>
        <geom name="//unnamed_geom_43" class="visual" pos="0.0614023 -0.074169 -0.0428161" quat="0.183013 -0.683013 0.683013 0.183013" material="drive" mesh="drive"/>
        <geom name="//unnamed_geom_44" class="collision" size="0.0506529 0.0709141" pos="0.0614023 -0.0120484 -0.00695116" quat="-0.353553 -0.612372 0.612372 -0.353553"/>
        <body name="LF_THIGH" pos="0.0641698 -0.0706315 -0.0408878" quat="0.182837 -0.68291 0.683264 0.182632">
          <inertial pos="0.0315173 0.00109351 -0.246768" quat="0.993927 -0.00587167 -0.0709054 0.0839507" mass="3.3148" diaginertia="0.0334895 0.0317303 0.0043444"/>
          <joint name="LF_HFE" pos="0 0 0" axis="0.999897 0.0140676 -0.00278049" stiffness="0.0117455" range="-3.2006 3.10283" armature="0.0107069" damping="0.00401323" frictionloss="0.08769"/>
          <geom name="//unnamed_geom_45" class="visual" pos="0.000351518 5.5391e-07 0" quat="0.707107 0 0 -0.707107" material="thigh" mesh="thigh"/>
          <geom name="//unnamed_geom_46" class="collision" size="0.0658488 0.0405223" pos="0.0410032 0 0" quat="0.5 0.5 -0.5 -0.5"/>
          <geom name="//unnamed_geom_47" class="collision" size="0.0379897 0.0303918 0.143159" pos="0.0307524 0 -0.142259" quat="0.707107 0 0 -0.707107" type="box"/>
          <geom name="//unnamed_geom_48" class="visual" pos="0.102815 0 -0.286905" quat="1 0 0 0" material="drive" mesh="drive"/>
          <geom name="//unnamed_geom_49" class="collision" size="0.0506529 0.0709141" pos="0.0310599 0 -0.286905" quat="0.707107 0 0.707107 0"/>
          <geom name="//unnamed_geom_50" class="reward_collision_sphere" size="0.0810447" pos="0.025627 0 0"/>
          <body name="LF_SHANK" pos="0.102598 -0.000165017 -0.285446" quat="1 -0.000339981 0.000407 -0.000255398">
            <inertial pos="0.00344755 -0.0644628 -0.0838115" quat="0.993045 -0.116462 -0.000571659 -0.0172791" mass="0.601138" diaginertia="0.0110529 0.00945877 0.00113057"/>
            <joint name="LF_KFE" pos="0 0 0" axis="0.999991 0.00322973 -0.00290759" stiffness="0.00822879" range="-3.11916 3.19261" armature="0.00867668" damping="0" frictionloss="0.10816"/>
            <geom name="//unnamed_geom_51" class="visual" pos="0.000114622 0.000611173 0" quat="0.707107 0 0 -0.707107" material="shank_l" mesh="shank_l"/>
            <geom name="LF_kfe_act" class="collision" size="0.0607835 0.0202612" pos="0.0205016 0 0" quat="0.5 0.5 -0.5 -0.5"/>
            <geom name="//unnamed_geom_53" class="collision" size="0.0582499 0.0341907 0.0192481" pos="0.0205016 -0.0579252 0" quat="0.5 0.5 -0.5 -0.5" type="box"/>
            <geom name="//unnamed_geom_54" class="visual" pos="0.0133773 -0.0884049 -0.340229" quat="0.382683 0 0 -0.92388" material="foot" mesh="foot"/>
            <geom name="LF_calf" class="collision" size="0.0177285 0.143097" pos="0.0133773 -0.0886019 -0.170115" quat="0.707107 0 0 -0.707107"/>
            <geom name="LF_foot" class="foot" size="0.0283824" pos="0.0133773 -0.0886019 -0.317579" quat="0.707107 0 0 -0.707107"/>
            <geom name="//unnamed_geom_57" class="reward_collision_sphere" size="0.101306" pos="-0.051254 0 0"/>
            <geom name="//unnamed_geom_58" class="reward_collision_sphere" size="0.0506529" pos="0.0133773 -0.0886019 -0.317579"/>
            <site name="LF_foot" class="foot" pos="0.0133773 -0.0886019 -0.317579" quat="0.707107 0 0 -0.707107" size="0.0101306"/>
          </body>
        </body>
      </body>
      <body name="RF_HIP" pos="0.306474 -0.107738 0.000799337" quat="0.258615 -0.96598 0.00029577 0.000188198">
        <inertial pos="0.0590194 0.0179467 -0.0105523" quat="0.125906 0.67752 0.13032 0.712833" mass="2.82522" diaginertia="0.00639904 0.00511393 0.00346856"/>
        <joint name="RF_HAA" pos="0 0 0" axis="0.999879 0.00973224 0.0121345" range="-0.513037 0.768227" armature="0.008993" damping="0.00129442" frictionloss="0.10591"/>
        <geom name="//unnamed_geom_59" class="visual" pos="0 -7.37798e-07 -1.21183e-07" quat="0.258819 0.965926 0 0" material="hip_r" mesh="hip_r"/>
        <geom name="//unnamed_geom_60" class="visual" pos="0.0614023 0.074169 -0.0428161" quat="0.183013 0.683013 0.683013 -0.183013" material="drive" mesh="drive"/>
        <geom name="//unnamed_geom_61" class="collision" size="0.0506529 0.0709141" pos="0.0614023 0.0120484 -0.00695116" quat="-0.353553 0.612372 0.612372 0.353553"/>
        <body name="RF_THIGH" pos="0.059753 0.0720247 -0.0432885" quat="0.183134 0.683114 0.68287 -0.183045">
          <inertial pos="0.0342247 -0.00292934 -0.245442" quat="0.993207 -0.00101926 -0.0739108 0.0898627" mass="3.2335" diaginertia="0.0330432 0.0310317 0.0043276"/>
          <joint name="RF_HFE" pos="0 0 0" axis="0.999951 0.00833795 0.0053498" stiffness="0.00276305" range="-3.13824 3.17077" armature="0.0091593" damping="0.0214163" frictionloss="0.08705"/>
          <geom name="//unnamed_geom_62" class="visual" pos="0.000351518 5.5391e-07 0" quat="0.707107 0 0 -0.707107" material="thigh" mesh="thigh"/>
          <geom name="//unnamed_geom_63" class="collision" size="0.0658488 0.0405223" pos="0.0410032 0 0" quat="0.5 0.5 0.5 0.5"/>
          <geom name="//unnamed_geom_64" class="collision" size="0.0379897 0.0303918 0.143159" pos="0.0307524 0 -0.142259" quat="0.707107 0 0 0.707107" type="box"/>
          <geom name="//unnamed_geom_65" class="visual" pos="0.102815 0 -0.286905" quat="1 0 0 0" material="drive" mesh="drive"/>
          <geom name="//unnamed_geom_66" class="collision" size="0.0506529 0.0709141" pos="0.0310599 0 -0.286905" quat="0.707107 0 0.707107 0"/>
          <geom name="//unnamed_geom_67" class="reward_collision_sphere" size="0.0810447" pos="0.025627 0 0"/>
          <body name="RF_SHANK" pos="0.101411 0.00267376 -0.286081" quat="1 1.88436e-05 1.30876e-05 -1.99066e-05">
            <inertial pos="0.00294909 0.064551 -0.08182" quat="0.991947 0.122741 0.00460927 0.0309066" mass="0.61936" diaginertia="0.0113914 0.0100624 0.00113238"/>
            <joint name="RF_KFE" pos="0 0 0" axis="0.999995 0.00221203 0.00214038" range="-3.09602 3.151" armature="0.0104483" damping="0.00197235" frictionloss="0.0926139"/>
            <geom name="//unnamed_geom_68" class="visual" pos="0.000114622 -0.000611171 0" quat="0.707107 0 0 0.707107" material="shank" mesh="shank_r"/>
            <geom name="RF_kfe_act" class="collision" size="0.0607835 0.0202612" pos="0.0205016 0 0" quat="0.5 0.5 0.5 0.5"/>
            <geom name="//unnamed_geom_70" class="collision" size="0.0582499 0.0341907 0.0192481" pos="0.0205016 0.0579252 0" quat="0.5 0.5 0.5 0.5" type="box"/>
            <geom name="//unnamed_geom_71" class="visual" pos="0.0133773 0.0884049 -0.340229" quat="0.382683 0 0 0.92388" material="foot" mesh="foot"/>
            <geom name="RF_calf" class="collision" size="0.0177285 0.143097" pos="0.0133773 0.0886019 -0.170115" quat="0.707107 0 0 0.707107"/>
            <geom name="RF_foot" class="foot" size="0.0298731" pos="0.0133773 0.0886019 -0.317579" quat="0.707107 0 0 0.707107"/>
            <geom name="//unnamed_geom_74" class="reward_collision_sphere" size="0.101306" pos="-0.051254 0 0"/>
            <geom name="//unnamed_geom_75" class="reward_collision_sphere" size="0.0506529" pos="0.0133773 0.0886019 -0.317579"/>
            <site name="RF_foot" class="foot" pos="0.0133773 0.0886019 -0.317579" quat="0.707107 0 0 0.707107" size="0.0101306"/>
          </body>
        </body>
      </body>
      <body name="LH_HIP" pos="-0.307062 0.107844 0.00358796" quat="-0.000396141 1.40826e-05 0.966053 -0.258345">
        <inertial pos="0.0581244 0.0148825 -0.00567832" quat="0.134379 0.678199 0.128206 0.711022" mass="2.78953" diaginertia="0.00648517 0.00482835 0.0034343"/>
        <joint name="LH_HAA" pos="0 0 0" axis="0.999971 -0.000665075 0.00762528" stiffness="0.00751394" range="-0.444411 0.693145" armature="0.0100248" damping="0.0124634" frictionloss="0.115036"/>
        <geom name="//unnamed_geom_76" class="visual" pos="0 -7.37798e-07 -1.21183e-07" quat="-0.258819 -0.965926 0 0" material="hip_r" mesh="hip_r"/>
        <geom name="//unnamed_geom_77" class="visual" pos="0.0614023 0.074169 -0.0428161" quat="0.183013 0.683013 0.683013 -0.183013" material="drive" mesh="drive"/>
        <geom name="//unnamed_geom_78" class="collision" size="0.0506529 0.0709141" pos="0.0614023 0.0120484 -0.00695116" quat="-0.353553 0.612372 0.612372 0.353553"/>
        <body name="LH_THIGH" pos="0.0609229 0.0708005 -0.0421901" quat="0.182822 0.6836 0.68263 -0.182437">
          <inertial pos="0.0310038 0.000629174 -0.245552" quat="0.994213 -0.00833789 -0.070043 0.0810235" mass="3.15009" diaginertia="0.0332165 0.0321938 0.00445958"/>
          <joint name="LH_HFE" pos="0 0 0" axis="0.999991 0.00398276 0.00116518" range="-3.12566 3.1553" armature="0.0115476" damping="0.0235088" frictionloss="0.0876067"/>
          <geom name="//unnamed_geom_79" class="visual" pos="0.000351518 5.5391e-07 0" quat="0.707107 0 0 -0.707107" material="thigh" mesh="thigh"/>
          <geom name="//unnamed_geom_80" class="collision" size="0.0658488 0.0405223" pos="0.0410032 0 0" quat="0.5 0.5 -0.5 -0.5"/>
          <geom name="//unnamed_geom_81" class="collision" size="0.0379897 0.0303918 0.143159" pos="0.0307524 0 -0.142259" quat="0.707107 0 0 -0.707107" type="box"/>
          <geom name="//unnamed_geom_82" class="visual" pos="0.102815 0 -0.286905" quat="1 0 0 0" material="drive" mesh="drive"/>
          <geom name="//unnamed_geom_83" class="collision" size="0.0506529 0.0709141" pos="0.0310599 0 -0.286905" quat="0.707107 0 0.707107 0"/>
          <geom name="//unnamed_geom_84" class="reward_collision_sphere" size="0.0810447" pos="0.025627 0 0"/>
          <body name="LH_SHANK" pos="0.101036 0.00144526 -0.283981" quat="0.999999 -0.000245555 -0.000814629 -0.000776229">
            <inertial pos="0.00606275 0.0641437 -0.0800363" quat="0.99346 0.111154 -0.00206155 0.0260176" mass="0.599081" diaginertia="0.0110272 0.00919213 0.00111116"/>
            <joint name="LH_KFE" pos="0 0 0" axis="0.999996 -0.00283924 0.000666832" stiffness="0.00694337" range="-3.11573 3.1511" armature="0.0106557" damping="0.0214954" frictionloss="0.0869634"/>
            <geom name="//unnamed_geom_85" class="visual" pos="0.000114622 -0.000611171 0" quat="-0.707107 0 0 -0.707107" material="shank" mesh="shank_r"/>
            <geom name="LH_kfe_act" class="collision" size="0.0607835 0.0202612" pos="0.0205016 0 0" quat="0.5 0.5 -0.5 -0.5"/>
            <geom name="//unnamed_geom_87" class="collision" size="0.0582499 0.0341907 0.0192481" pos="0.0205016 0.0579252 0" quat="0.5 0.5 -0.5 -0.5" type="box"/>
            <geom name="//unnamed_geom_88" class="visual" pos="0.0133773 0.0884049 -0.340229" quat="-0.382683 0 0 -0.92388" material="foot" mesh="foot"/>
            <geom name="LH_calf" class="collision" size="0.0177285 0.143097" pos="0.0133773 0.0886019 -0.170115" quat="0.707107 0 0 -0.707107"/>
            <geom name="LH_foot" class="foot" size="0.030524" pos="0.0133773 0.0886019 -0.317579" quat="0.707107 0 0 -0.707107"/>
            <geom name="//unnamed_geom_91" class="reward_collision_sphere" size="0.101306" pos="-0.051254 0 0"/>
            <geom name="//unnamed_geom_92" class="reward_collision_sphere" size="0.0506529" pos="0.0133773 0.0886019 -0.317579"/>
            <site name="LH_foot" class="foot" pos="0.0133773 0.0886019 -0.317579" quat="0.707107 0 0 -0.707107" size="0.0101306"/>
          </body>
        </body>
      </body>
      <body name="RH_HIP" pos="-0.308535 -0.102805 0.000993358" quat="0.000360705 -5.28537e-05 -0.965847 -0.259112">
        <inertial pos="0.0572166 -0.0166409 -0.00782513" quat="-0.127973 0.71005 -0.137015 0.678733" mass="2.81071" diaginertia="0.00643078 0.00501494 0.00332131"/>
        <joint name="RH_HAA" pos="0 0 0" axis="0.999989 -0.00433185 0.00151288" stiffness="0.00836134" range="-0.724652 0.549113" armature="0.0111118" damping="0.0115962" frictionloss="0.115554"/>
        <geom name="//unnamed_geom_93" class="visual" pos="0 7.37804e-07 -1.21184e-07" quat="-0.258819 0.965926 0 0" material="hip_l" mesh="hip_l"/>
        <geom name="//unnamed_geom_94" class="visual" pos="0.0614023 -0.074169 -0.0428161" quat="-0.183013 0.683013 -0.683013 -0.183013" material="drive" mesh="drive"/>
        <geom name="//unnamed_geom_95" class="collision" size="0.0506529 0.0709141" pos="0.0614023 -0.0120484 -0.00695116" quat="0.353553 0.612372 -0.612372 0.353553"/>
        <body name="RH_THIGH" pos="0.0583927 -0.0699737 -0.0427849" quat="-0.182374 0.682689 -0.68352 -0.182967">
          <inertial pos="0.0323201 -0.00279135 -0.246178" quat="0.99325 -0.006051 -0.0779949 0.0856421" mass="3.24769" diaginertia="0.0347914 0.0307599 0.0041885"/>
          <joint name="RH_HFE" pos="0 0 0" axis="0.999986 0.00370796 -0.00386557" stiffness="0.00971584" range="-3.16119 3.15932" armature="0.00945181" damping="0.0204602" frictionloss="0.106491"/>
          <geom name="//unnamed_geom_96" class="visual" pos="0.000351518 5.5391e-07 0" quat="0.707107 0 0 -0.707107" material="thigh" mesh="thigh"/>
          <geom name="//unnamed_geom_97" class="collision" size="0.0658488 0.0405223" pos="0.0410032 0 0" quat="0.5 0.5 0.5 0.5"/>
          <geom name="//unnamed_geom_98" class="collision" size="0.0379897 0.0303918 0.143159" pos="0.0307524 0 -0.142259" quat="0.707107 0 0 0.707107" type="box"/>
          <geom name="//unnamed_geom_99" class="visual" pos="0.102815 0 -0.286905" quat="1 0 0 0" material="drive" mesh="drive"/>
          <geom name="//unnamed_geom_100" class="collision" size="0.0506529 0.0709141" pos="0.0310599 0 -0.286905" quat="0.707107 0 0.707107 0"/>
          <geom name="//unnamed_geom_101" class="reward_collision_sphere" size="0.0810447" pos="0.025627 0 0"/>
          <body name="RH_SHANK" pos="0.1051 0.00131989 -0.28543" quat="1 0.000108237 8.63306e-05 0.00019187">
            <inertial pos="0.00296032 -0.0620791 -0.0819045" quat="0.99293 -0.115827 8.16601e-05 -0.0259445" mass="0.632208" diaginertia="0.0116157 0.00986192 0.00116986"/>
            <joint name="RH_KFE" pos="0 0 0" axis="0.99996 0.00866707 -0.00227626" range="-3.09176 3.18313" armature="0.0105629" damping="0.0120365" frictionloss="0.114891"/>
            <geom name="//unnamed_geom_102" class="visual" pos="0.000114622 0.000611173 0" quat="0.707107 0 0 -0.707107" material="shank_l" mesh="shank_l"/>
            <geom name="RH_kfe_act" class="collision" size="0.0607835 0.0202612" pos="0.0205016 0 0" quat="0.5 0.5 0.5 0.5"/>
            <geom name="//unnamed_geom_104" class="collision" size="0.0582499 0.0341907 0.0192481" pos="0.0205016 -0.0579252 0" quat="0.5 0.5 0.5 0.5" type="box"/>
            <geom name="//unnamed_geom_105" class="visual" pos="0.0133773 -0.0884049 -0.340229" quat="0.382683 0 0 -0.92388" material="foot" mesh="foot"/>
            <geom name="RH_calf" class="collision" size="0.0177285 0.143097" pos="0.0133773 -0.0886019 -0.170115" quat="0.707107 0 0 0.707107"/>
            <geom name="RH_foot" class="foot" size="0.0306927" pos="0.0133773 -0.0886019 -0.317579" quat="0.707107 0 0 0.707107"/>
            <geom name="//unnamed_geom_108" class="reward_collision_sphere" size="0.101306" pos="-0.051254 0 0"/>
            <geom name="//unnamed_geom_109" class="reward_collision_sphere" size="0.0506529" pos="0.0133773 -0.0886019 -0.317579"/>
            <site name="RH_foot" class="foot" pos="0.0133773 -0.0886019 -0.317579" quat="0.707107 0 0 0.707107" size="0.0101306"/>
          </body>
        </body>
      </body>
    </body>
  </worldbody>

  <contact>
    <pair class="/" geom1="floor" geom2="LF_foot" name="//unnamed_contact_0"/>
    <pair class="/" geom1="floor" geom2="RF_foot" name="//unnamed_contact_1"/>
    <pair class="/" geom1="floor" geom2="LH_foot" name="//unnamed_contact_2"/>
    <pair class="/" geom1="floor" geom2="RH_foot" name="//unnamed_contact_3"/>
  </contact>

  <actuator>
    <general name="LF_HAA" class="/" joint="LF_HAA" forcerange="-89.7808 89.7808" gainprm="81.607" biasprm="0 -81.607 -2.1865"/>
    <general name="LF_HFE" class="/" joint="LF_HFE" forcerange="-80.6863 80.6863" gainprm="81.607" biasprm="0 -81.607 -2.1865"/>
    <general name="LF_KFE" class="/" joint="LF_KFE" forcerange="-77.7546 77.7546" gainprm="81.607" biasprm="0 -81.607 -2.1865"/>
    <general name="RF_HAA" class="/" joint="RF_HAA" forcerange="-73.8562 73.8562" gainprm="81.607" biasprm="0 -81.607 -2.1865"/>
    <general name="RF_HFE" class="/" joint="RF_HFE" forcerange="-80.9378 80.9378" gainprm="81.607" biasprm="0 -81.607 -2.1865"/>
    <general name="RF_KFE" class="/" joint="RF_KFE" forcerange="-72.8038 72.8038" gainprm="81.607" biasprm="0 -81.607 -2.1865"/>
    <general name="LH_HAA" class="/" joint="LH_HAA" forcerange="-78.8692 78.8692" gainprm="81.607" biasprm="0 -81.607 -2.1865"/>
    <general name="LH_HFE" class="/" joint="LH_HFE" forcerange="-80.8151 80.8151" gainprm="81.607" biasprm="0 -81.607 -2.1865"/>
    <general name="LH_KFE" class="/" joint="LH_KFE" forcerange="-86.3958 86.3958" gainprm="81.607" biasprm="0 -81.607 -2.1865"/>
    <general name="RH_HAA" class="/" joint="RH_HAA" forcerange="-74.6016 74.6016" gainprm="81.607" biasprm="0 -81.607 -2.1865"/>
    <general name="RH_HFE" class="/" joint="RH_HFE" forcerange="-87.1783 87.1783" gainprm="81.607" biasprm="0 -81.607 -2.1865"/>
    <general name="RH_KFE" class="/" joint="RH_KFE" forcerange="-87.5762 87.5762" gainprm="81.607" biasprm="0 -81.607 -2.1865"/>
  </actuator>

  <sensor>
    <gyro site="imu" name="imu_angular_velocity"/>
    <velocimeter site="imu" name="imu_linear_velocity"/>
    <framelinvel objtype="site" objname="LF_foot" name="LF_foot_global_linear_velocity"/>
    <framelinvel objtype="site" objname="RF_foot" name="RF_foot_global_linear_velocity"/>
    <framelinvel objtype="site" objname="LH_foot" name="LH_foot_global_linear_velocity"/>
    <framelinvel objtype="site" objname="RH_foot" name="RH_foot_global_linear_velocity"/>
  </sensor>

  <keyframe>
    <key name="home" qpos="0 0 0.55 1 0 0 0 0 0.4 -0.8 0 -0.4 0.8 0 -0.4 0.8 0 0.4 -0.8"/>
  </keyframe>
</mujoco>
