<mujoco model="anymal_c">
  <compiler angle="radian" assetdir="assets" balanceinertia="true" inertiafromgeom="false"/>

  <option timestep="0.005" density="1.2" viscosity="2e-05"/>

  <size nkey="1"/>

  <visual>
    <quality shadowsize="8192"/>
    <map shadowclip="0.5"/>
  </visual>

  <default>
    <default class="/">
      <material specular="0" shininess="0.25"/>
      <geom contype="0" conaffinity="0" group="1" solref="-1000 -80"/>
      <site size="0.01 0.005 0.005" group="5"/>
      <general forcelimited="true" forcerange="-80 80" biastype="affine" gainprm="80" biasprm="0 -80 -2"/>
      <default class="anymal_c">
        <joint armature="0.01" damping="0.01" frictionloss="0.1"/>
        <default class="visual">
          <geom type="mesh" group="2"/>
          <default class="visual_zflip"/>
        </default>
        <default class="collision">
          <geom type="cylinder" group="3"/>
          <default class="foot">
            <geom size="0.03 0 0" type="sphere" condim="6" priority="1" friction="0.8 0.02 0.01" solimp="0.015 1 0.03"/>
          </default>
        </default>
      </default>
      <default class="reward_collision_sphere">
        <geom group="5" rgba="1 0 0 1"/>
      </default>
    </default>
  </default>

  <asset>
    <texture type="skybox" colorspace="auto" name="//unnamed_texture_0" builtin="gradient" rgb1="0.95 0.95 0.95" rgb2="0.95 0.95 0.95" width="100" height="600"/>
    <texture type="2d" colorspace="auto" name="texplane" builtin="checker" rgb1="0.345 0.575 0.748" rgb2="0.345 0.575 0.748" markrgb="1 1 1" width="512" height="512"/>
    <texture type="2d" colorspace="linear" name="base" file="base.png"/>
    <texture type="2d" colorspace="linear" name="top_shell" file="top_shell.png"/>
    <texture type="2d" colorspace="linear" name="bottom_shell" file="bottom_shell.png"/>
    <texture type="2d" colorspace="linear" name="remote" file="remote.png"/>
    <texture type="2d" colorspace="linear" name="hatch" file="hatch.png"/>
    <texture type="2d" colorspace="linear" name="handle" file="handle.png"/>
    <texture type="2d" colorspace="linear" name="face" file="face.png"/>
    <texture type="2d" colorspace="linear" name="battery" file="battery.png"/>
    <texture type="2d" colorspace="linear" name="lidar_cage" file="lidar_cage.png"/>
    <texture type="2d" colorspace="linear" name="depth_camera" file="depth_camera.png"/>
    <texture type="2d" colorspace="linear" name="wide_angle_camera" file="wide_angle_camera.png"/>
    <texture type="2d" colorspace="linear" name="lidar" file="lidar.png"/>
    <texture type="2d" colorspace="linear" name="drive" file="drive.png"/>
    <texture type="2d" colorspace="linear" name="hip_l" file="hip_l.png"/>
    <texture type="2d" colorspace="linear" name="shank_l" file="shank_l.png"/>
    <texture type="2d" colorspace="linear" name="foot" file="foot.png"/>
    <texture type="2d" colorspace="linear" name="thigh" file="thigh.png"/>
    <texture type="2d" colorspace="linear" name="shank_r" file="shank_r.png"/>
    <texture type="2d" colorspace="linear" name="hip_r" file="hip_r.png"/>
    <material name="MatPlane" class="/" texture="texplane" texuniform="true" texrepeat="2 2" specular="0.9" shininess="0.5"/>
    <material name="black_plastic" class="/" rgba="0.007 0.007 0.007 1"/>
    <material name="green" class="/" rgba="0.052 0.178 0.033 1"/>
    <material name="red" class="/" rgba="0.178 0.006 0.005 1"/>
    <material name="yellow" class="/" rgba="0.178 0.119 0.006 1"/>
    <material name="lwl" class="/" rgba="0.8 0.8 0.8 1"/>
    <material name="base" class="/" texture="base"/>
    <material name="top_shell" class="/" texture="top_shell"/>
    <material name="bottom_shell" class="/" texture="bottom_shell"/>
    <material name="hip_l" class="/" texture="hip_l"/>
    <material name="thigh" class="/" texture="thigh"/>
    <material name="shank_l" class="/" texture="shank_l"/>
    <material name="foot" class="/" texture="foot"/>
    <material name="hip_r" class="/" texture="hip_r"/>
    <material name="shank" class="/" texture="shank_r"/>
    <material name="hatch" class="/" texture="hatch"/>
    <material name="remote" class="/" texture="remote"/>
    <material name="handle" class="/" texture="handle"/>
    <material name="face" class="/" texture="face"/>
    <material name="depth_camera" class="/" texture="depth_camera"/>
    <material name="wide_angle_camera" class="/" texture="wide_angle_camera"/>
    <material name="battery" class="/" texture="battery"/>
    <material name="lidar_cage" class="/" texture="lidar_cage"/>
    <material name="lidar" class="/" texture="lidar"/>
    <material name="drive" class="/" texture="drive"/>
    <mesh name="base_0" class="/" file="base_0.obj"/>
    <mesh name="base_1" class="/" file="base_1.obj"/>
    <mesh name="base_2" class="/" file="base_2.obj"/>
    <mesh name="base_3" class="/" file="base_3.obj"/>
    <mesh name="base_4" class="/" file="base_4.obj"/>
    <mesh name="base_5" class="/" file="base_5.obj"/>
    <mesh name="top_shell" class="/" file="top_shell.obj"/>
    <mesh name="bottom_shell" class="/" file="bottom_shell.obj"/>
    <mesh name="remote" class="/" file="remote.obj"/>
    <mesh name="handle" class="/" file="handle.obj"/>
    <mesh name="face" class="/" file="face.obj"/>
    <mesh name="wide_angle_camera" class="/" file="wide_angle_camera.obj"/>
    <mesh name="depth_camera" class="/" file="depth_camera.obj"/>
    <mesh name="battery" class="/" file="battery.obj"/>
    <mesh name="lidar_cage" class="/" file="lidar_cage.obj"/>
    <mesh name="lidar" class="/" file="lidar.obj"/>
    <mesh name="drive" class="/" file="drive.obj"/>
    <mesh name="hip_l" class="/" file="hip_l.obj"/>
    <mesh name="thigh" class="/" file="thigh.obj"/>
    <mesh name="shank_l" class="/" file="shank_l.obj"/>
    <mesh name="foot" class="/" file="foot.obj"/>
    <mesh name="hip_r" class="/" file="hip_r.obj"/>
    <mesh name="hatch" class="/" file="hatch.obj"/>
    <mesh name="shank_r" class="/" file="shank_r.obj"/>
  </asset>

  <worldbody>
    <geom name="floor" class="/" size="100 100 0.125" type="plane" group="0" material="MatPlane"/>
    <light name="toplight_shadow" class="/" pos="0 0 5" dir="0.0990148 0.0990148 -0.990148" type="directional" ambient="0.04 0.04 0.04" diffuse="0.55 0.55 0.55" specular="0.12 0.12 0.12"/>
    <light name="toplight_fill" class="/" pos="0 0 5" dir="0.0990148 0.0990148 -0.990148" type="directional" castshadow="false" ambient="0.04 0.04 0.04" diffuse="0.3 0.3 0.3" specular="0.08 0.08 0.08"/>
    <body name="trunk" childclass="anymal_c" pos="0.000196949 0.000369171 0.000592732" quat="1 0.000101715 -5.14738e-05 0.000129036">
      <inertial pos="0.00311599 -0.00184922 0.051207" quat="0.497374 0.500376 0.499401 0.502833" mass="18.004" diaginertia="0.652323 0.357185 0.27532"/>
      <joint name="//unnamed_joint_0" type="free" armature="0" damping="0" frictionloss="0"/>
      <geom name="//unnamed_geom_1" class="visual" material="green" mesh="base_0"/>
      <geom name="//unnamed_geom_2" class="visual" material="yellow" mesh="base_1"/>
      <geom name="//unnamed_geom_3" class="visual" material="red" mesh="base_2"/>
      <geom name="//unnamed_geom_4" class="visual" material="black_plastic" mesh="base_3"/>
      <geom name="//unnamed_geom_5" class="visual" material="lwl" mesh="base_4"/>
      <geom name="//unnamed_geom_6" class="visual" material="base" mesh="base_5"/>
      <geom name="trunk_1" class="collision" size="0.286818 0.069232 0.0890126" type="box"/>
      <geom name="trunk_2" class="collision" size="0.0890126 0.0717046" pos="0.220453 0.0630544 0" quat="0.707107 0 0.707107 0"/>
      <geom name="trunk_3" class="collision" size="0.0890126 0.0717046" pos="-0.220453 0.0630544 0" quat="0.707107 0 0.707107 0"/>
      <geom name="trunk_4" class="collision" size="0.0890126 0.0717046" pos="0.220453 -0.0630544 0" quat="0.707107 0 0.707107 0"/>
      <geom name="trunk_5" class="collision" size="0.0890126 0.0717046" pos="-0.220453 -0.0630544 0" quat="0.707107 0 0.707107 0"/>
      <geom name="//unnamed_geom_12" class="visual" material="top_shell" mesh="top_shell"/>
      <geom name="//unnamed_geom_13" class="visual" material="bottom_shell" mesh="bottom_shell"/>
      <geom name="//unnamed_geom_14" class="visual" material="remote" mesh="remote"/>
      <geom name="//unnamed_geom_15" class="visual" material="handle" mesh="handle"/>
      <geom name="//unnamed_geom_16" class="visual" pos="0.420128 0 0" quat="1 0 0 0" material="face" mesh="face"/>
      <geom name="trunk_6" class="collision" size="0.0543966 0.069232 0.0890126" pos="0.475874 0 0" type="box"/>
      <geom name="//unnamed_geom_18" class="collision" size="0.0890126 0.0543966" pos="0.475874 0.0630544 0" quat="0.707107 0 0.707107 0"/>
      <geom name="//unnamed_geom_19" class="collision" size="0.0890126 0.0543966" pos="0.475874 -0.0630544 0" quat="0.707107 0 0.707107 0"/>
      <geom name="//unnamed_geom_20" class="visual" pos="0.467919 0 -0.0310374" quat="0.965926 0 0.258819 0" material="depth_camera" mesh="depth_camera"/>
      <geom name="//unnamed_geom_21" class="visual" pos="0.519965 0 0.0157594" material="wide_angle_camera" mesh="wide_angle_camera"/>
      <geom name="//unnamed_geom_22" class="visual_zflip" pos="-0.420128 0 0" quat="0 0 0 1" material="face" mesh="face"/>
      <geom name="trunk_7" class="collision" size="0.0543966 0.069232 0.0890126" pos="-0.475874 0 0" quat="0 0 0 1" type="box"/>
      <geom name="//unnamed_geom_24" class="collision" size="0.0890126 0.0543966" pos="-0.475874 -0.0630544 0" quat="0 -0.707107 0 0.707107"/>
      <geom name="//unnamed_geom_25" class="collision" size="0.0890126 0.0543966" pos="-0.475874 0.0630544 0" quat="0 -0.707107 0 0.707107"/>
      <geom name="//unnamed_geom_26" class="visual" pos="-0.467919 0 -0.0310374" quat="0 -0.258819 0 0.965926" material="depth_camera" mesh="depth_camera"/>
      <geom name="//unnamed_geom_27" class="visual_zflip" pos="-0.519965 0 0.0157594" quat="0 0 0 1" material="wide_angle_camera" mesh="wide_angle_camera"/>
      <geom name="//unnamed_geom_28" class="visual" material="battery" mesh="battery"/>
      <geom name="//unnamed_geom_29" class="visual" pos="0 0.0673948 0.0302843" quat="0.683013 -0.183013 0.183013 0.683013" material="depth_camera" mesh="depth_camera"/>
      <geom name="//unnamed_geom_30" class="visual" pos="0 -0.0673948 0.0302843" quat="0.683013 0.183013 0.183013 -0.683013" material="depth_camera" mesh="depth_camera"/>
      <geom name="//unnamed_geom_31" class="visual" pos="-0.368942 0 0.0773758" quat="1 0 0 0" material="lidar_cage" mesh="lidar_cage"/>
      <geom name="trunk_8" class="collision" size="0.069232 0.0593417" pos="-0.368942 0 0.14054"/>
      <geom name="//unnamed_geom_33" class="visual" pos="-0.368942 -4.43162e-05 0.149699" quat="0.707107 0 0 -0.707107" material="lidar" mesh="lidar"/>
      <geom name="//unnamed_geom_34" class="visual" pos="0.303972 0.0937347 -2.62126e-09" quat="0.258819 0.965926 0 0" material="drive" mesh="drive"/>
      <geom name="//unnamed_geom_35" class="visual" pos="0.303972 -0.0937347 2.62126e-09" quat="0.258819 -0.965926 0 0" material="drive" mesh="drive"/>
      <geom name="//unnamed_geom_36" class="visual" pos="-0.303972 0.0937347 2.62126e-09" quat="0 0 0.965926 -0.258819" material="drive" mesh="drive"/>
      <geom name="//unnamed_geom_37" class="visual" pos="-0.303972 -0.0937347 -2.62126e-09" quat="0 0 -0.965926 -0.258819" material="drive" mesh="drive"/>
      <geom name="//unnamed_geom_38" class="visual" pos="0.117575 0 0.0768495" quat="1 0 0 0" material="hatch" mesh="hatch"/>
      <geom name="//unnamed_geom_39" class="reward_collision_sphere" size="0.118683"/>
      <geom name="//unnamed_geom_40" class="reward_collision_sphere" size="0.118683" pos="0.45611 0 0"/>
      <geom name="//unnamed_geom_41" class="reward_collision_sphere" size="0.118683" pos="-0.45611 0 0"/>
      <site name="imu" pos="0.249959 0.00745616 0.0485946" size="0.00989029"/>
      <camera name="track" pos="0 -1.80155 0" quat="0.707107 0.707107 0 0" mode="trackcom"/>
      <camera name="ego_camera" pos="0.45611 0 -0.0421093" quat="-0.5 -0.5 0.5 0.5"/>
      <body name="LF_HIP" pos="0.305002 0.0939655 -0.000351384" quat="0.258848 0.965918 -6.29352e-05 8.64909e-05">
        <inertial pos="0.0575623 -0.0139221 -0.00843362" quat="-0.124188 0.706357 -0.143809 0.681877" mass="2.68471" diaginertia="0.00627104 0.00295889 0.00427139"/>
        <joint name="LF_HAA" pos="0 0 0" axis="0.999996 0.000795174 -0.00285252" range="-0.700622 0.483469" armature="0.00987913" damping="0.0097864" frictionloss="0.0986794"/>
        <geom name="//unnamed_geom_42" class="visual" pos="0 -0.000154197 2.53267e-05" quat="0.258819 -0.965926 0 0" material="hip_l" mesh="hip_l"/>
        <geom name="//unnamed_geom_43" class="visual" pos="0.0607133 -0.0721358 -0.0427716" quat="0.183013 -0.683013 0.683013 0.183013" material="drive" mesh="drive"/>
        <geom name="//unnamed_geom_44" class="collision" size="0.0494514 0.069232" pos="0.0607132 -0.0107731 -0.00726912" quat="-0.353553 -0.612372 0.612372 -0.353553"/>
        <body name="LF_THIGH" pos="0.0616653 -0.0667905 -0.0453557" quat="0.183699 -0.683048 0.682665 0.18349">
          <inertial pos="0.0315427 0.0019512 -0.259032" quat="0.992855 -0.00204355 -0.0841618 0.084565" mass="2.93988" diaginertia="0.0319837 0.0181121 0.00541739"/>
          <joint name="LF_HFE" pos="0 0 0" axis="1 0.000297493 -0.000408558" range="-3.13988 3.11075" armature="0.0107863" damping="0.0120684" frictionloss="0.103042"/>
          <geom name="//unnamed_geom_45" class="visual" pos="0.00224428 3.53646e-06 0" quat="0.707107 0 0 -0.707107" material="thigh" mesh="thigh"/>
          <geom name="//unnamed_geom_46" class="collision" size="0.0642869 0.0395611" pos="0.0405431 0 0" quat="0.5 0.5 -0.5 -0.5"/>
          <geom name="//unnamed_geom_47" class="collision" size="0.0370886 0.0296709 0.139764" pos="0.0304073 0 -0.148766" quat="0.707107 0 0 -0.707107" type="box"/>
          <geom name="//unnamed_geom_48" class="visual" pos="0.101662 0 -0.300029" quat="1 0 0 0" material="drive" mesh="drive"/>
          <geom name="//unnamed_geom_49" class="collision" size="0.0494514 0.069232" pos="0.0307114 0 -0.300029" quat="0.707107 0 0.707107 0"/>
          <geom name="//unnamed_geom_50" class="reward_collision_sphere" size="0.0791223" pos="0.0253394 0 0"/>
          <body name="LF_SHANK" pos="0.102044 -8.22319e-05 -0.300522" quat="1 0.00028113 -1.77315e-05 7.91069e-06">
            <inertial pos="0.00447761 -0.0545567 -0.0854355" quat="0.992776 -0.116825 0.00255494 -0.0272159" mass="0.56772" diaginertia="0.0109421 0.00560803 0.00144904"/>
            <joint name="LF_KFE" pos="0 0 0" axis="1 0.000213205 0.000644583" range="-3.10331 3.14592" armature="0.0103486" damping="0.000960802" frictionloss="0.0954851"/>
            <geom name="//unnamed_geom_51" class="visual" pos="0.000731811 0.00390206 0" quat="0.707107 0 0 -0.707107" material="shank_l" mesh="shank_l"/>
            <geom name="LF_kfe_act" class="collision" size="0.0593417 0.0197806" pos="0.0202715 0 0" quat="0.5 0.5 -0.5 -0.5"/>
            <geom name="//unnamed_geom_53" class="collision" size="0.0568682 0.0333797 0.0187915" pos="0.0202715 -0.0517937 0" quat="0.5 0.5 -0.5 -0.5" type="box"/>
            <geom name="//unnamed_geom_54" class="visual" pos="0.013227 -0.0779658 -0.355792" quat="0.382683 0 0 -0.92388" material="foot" mesh="foot"/>
            <geom name="LF_calf" class="collision" size="0.017308 0.139702" pos="0.0132272 -0.0792233 -0.177896" quat="0.707107 0 0 -0.707107"/>
            <geom name="LF_foot" class="foot" size="0.0303142" pos="0.0132272 -0.0792233 -0.332106" quat="0.707107 0 0 -0.707107"/>
            <geom name="//unnamed_geom_57" class="reward_collision_sphere" size="0.0989029" pos="-0.0506788 0 0"/>
            <geom name="//unnamed_geom_58" class="reward_collision_sphere" size="0.0494514" pos="0.0132272 -0.0792233 -0.332106"/>
            <site name="LF_foot" class="foot" pos="0.0132272 -0.0792233 -0.332106" quat="0.707107 0 0 -0.707107" size="0.00989029"/>
          </body>
        </body>
      </body>
      <body name="RF_HIP" pos="0.302831 -0.0929829 -0.00203277" quat="0.259057 -0.965862 0.000243173 -0.00011797">
        <inertial pos="0.0570305 0.0131281 -0.00792329" quat="0.137561 0.674983 0.128762 0.713369" mass="2.71161" diaginertia="0.00625945 0.00291964 0.00419908"/>
        <joint name="RF_HAA" pos="0 0 0" axis="0.999997 0.000769988 -0.00213824" range="-0.487084 0.74068" armature="0.0104394" damping="0.0128961" frictionloss="0.0967869"/>
        <geom name="//unnamed_geom_59" class="visual" pos="0 0.000154196 2.53266e-05" quat="0.258819 0.965926 0 0" material="hip_r" mesh="hip_r"/>
        <geom name="//unnamed_geom_60" class="visual" pos="0.0607132 0.0721358 -0.0427716" quat="0.183013 0.683013 0.683013 -0.183013" material="drive" mesh="drive"/>
        <geom name="//unnamed_geom_61" class="collision" size="0.0494514 0.069232" pos="0.0607132 0.0107731 -0.00726912" quat="-0.353553 0.612372 0.612372 0.353553"/>
        <body name="RF_THIGH" pos="0.0619178 0.0669633 -0.0461146" quat="0.18306 0.68298 0.683039 -0.182989">
          <inertial pos="0.0304005 0.000380694 -0.256944" quat="0.992926 -0.00159039 -0.0787296 0.0888617" mass="2.95842" diaginertia="0.0325653 0.0177619 0.0054194"/>
          <joint name="RF_HFE" pos="0 0 0" axis="0.999982 -0.00506993 0.0033203" stiffness="0.0120507" range="-3.13587 3.12281" armature="0.00939425" damping="0.0142613" frictionloss="0.10186"/>
          <geom name="//unnamed_geom_62" class="visual" pos="0.00224428 3.53646e-06 0" quat="0.707107 0 0 -0.707107" material="thigh" mesh="thigh"/>
          <geom name="//unnamed_geom_63" class="collision" size="0.0642869 0.0395611" pos="0.0405431 0 0" quat="0.5 0.5 0.5 0.5"/>
          <geom name="//unnamed_geom_64" class="collision" size="0.0370886 0.0296709 0.139764" pos="0.0304073 0 -0.148766" quat="0.707107 0 0 0.707107" type="box"/>
          <geom name="//unnamed_geom_65" class="visual" pos="0.101662 0 -0.300029" quat="1 0 0 0" material="drive" mesh="drive"/>
          <geom name="//unnamed_geom_66" class="collision" size="0.0494514 0.069232" pos="0.0307114 0 -0.300029" quat="0.707107 0 0.707107 0"/>
          <geom name="//unnamed_geom_67" class="reward_collision_sphere" size="0.0791223" pos="0.0253394 0 0"/>
          <body name="RF_SHANK" pos="0.102449 -0.000779847 -0.298365" quat="1 -1.85997e-05 1.34861e-05 7.47536e-05">
            <inertial pos="0.00640149 0.0548204 -0.0849538" quat="0.993438 0.11123 -0.00152609 0.0265721" mass="0.581669" diaginertia="0.0112456 0.00559117 0.0014921"/>
            <joint name="RF_KFE" pos="0 0 0" axis="0.999997 0.00238813 -0.00102665" range="-3.15543 3.13073" armature="0.00965899" damping="0" frictionloss="0.103146"/>
            <geom name="//unnamed_geom_68" class="visual" pos="0.000731807 -0.00390205 0" quat="0.707107 0 0 0.707107" material="shank" mesh="shank_r"/>
            <geom name="RF_kfe_act" class="collision" size="0.0593417 0.0197806" pos="0.0202715 0 0" quat="0.5 0.5 0.5 0.5"/>
            <geom name="//unnamed_geom_70" class="collision" size="0.0568682 0.0333797 0.0187915" pos="0.0202715 0.0517937 0" quat="0.5 0.5 0.5 0.5" type="box"/>
            <geom name="//unnamed_geom_71" class="visual" pos="0.0132274 0.0779658 -0.355792" quat="0.382683 0 0 0.92388" material="foot" mesh="foot"/>
            <geom name="RF_calf" class="collision" size="0.017308 0.139702" pos="0.0132272 0.0792233 -0.177896" quat="0.707107 0 0 0.707107"/>
            <geom name="RF_foot" class="foot" size="0.0268282" pos="0.0132272 0.0792233 -0.332106" quat="0.707107 0 0 0.707107"/>
            <geom name="//unnamed_geom_74" class="reward_collision_sphere" size="0.0989029" pos="-0.0506788 0 0"/>
            <geom name="//unnamed_geom_75" class="reward_collision_sphere" size="0.0494514" pos="0.0132272 0.0792233 -0.332106"/>
            <site name="RF_foot" class="foot" pos="0.0132272 0.0792233 -0.332106" quat="0.707107 0 0 0.707107" size="0.00989029"/>
          </body>
        </body>
      </body>
      <body name="LH_HIP" pos="-0.30345 0.093023 0.000273547" quat="-4.74461e-05 -2.88933e-05 0.965968 -0.258662">
        <inertial pos="0.0577986 0.0136418 -0.00943342" quat="0.135282 0.679165 0.128103 0.709946" mass="2.65616" diaginertia="0.00631986 0.00298671 0.00426067"/>
        <joint name="LH_HAA" pos="0 0 0" axis="0.999985 -0.00273518 -0.00481163" range="-0.481249 0.737418" armature="0.00987469" damping="0.0109739" frictionloss="0.100027"/>
        <geom name="//unnamed_geom_76" class="visual" pos="0 0.000154196 2.53266e-05" quat="-0.258819 -0.965926 0 0" material="hip_r" mesh="hip_r"/>
        <geom name="//unnamed_geom_77" class="visual" pos="0.0607132 0.0721358 -0.0427716" quat="0.183013 0.683013 0.683013 -0.183013" material="drive" mesh="drive"/>
        <geom name="//unnamed_geom_78" class="collision" size="0.0494514 0.069232" pos="0.0607132 0.0107731 -0.00726912" quat="-0.353553 0.612372 0.612372 0.353553"/>
        <body name="LH_THIGH" pos="0.0601793 0.0666541 -0.0445147" quat="0.182591 0.683609 0.682468 -0.18324">
          <inertial pos="0.0310422 0.00191908 -0.259298" quat="0.992845 -0.00436798 -0.0802155 0.0883476" mass="2.90682" diaginertia="0.03269 0.017545 0.00547711"/>
          <joint name="LH_HFE" pos="0 0 0" axis="0.999959 0.00714947 0.0056144" range="-3.15296 3.14345" armature="0.00966793" damping="0.0094139" frictionloss="0.102946"/>
          <geom name="//unnamed_geom_79" class="visual" pos="0.00224428 3.53646e-06 0" quat="0.707107 0 0 -0.707107" material="thigh" mesh="thigh"/>
          <geom name="//unnamed_geom_80" class="collision" size="0.0642869 0.0395611" pos="0.0405431 0 0" quat="0.5 0.5 -0.5 -0.5"/>
          <geom name="//unnamed_geom_81" class="collision" size="0.0370886 0.0296709 0.139764" pos="0.0304073 0 -0.148766" quat="0.707107 0 0 -0.707107" type="box"/>
          <geom name="//unnamed_geom_82" class="visual" pos="0.101662 0 -0.300029" quat="1 0 0 0" material="drive" mesh="drive"/>
          <geom name="//unnamed_geom_83" class="collision" size="0.0494514 0.069232" pos="0.0307114 0 -0.300029" quat="0.707107 0 0.707107 0"/>
          <geom name="//unnamed_geom_84" class="reward_collision_sphere" size="0.0791223" pos="0.0253394 0 0"/>
          <body name="LH_SHANK" pos="0.102559 -0.00162754 -0.300965" quat="1 0.000535111 -0.000108867 -0.000272725">
            <inertial pos="0.00570252 0.0555808 -0.0853043" quat="0.992947 0.115774 -0.000579598 0.0255371" mass="0.576478" diaginertia="0.0109481 0.00550915 0.00145029"/>
            <joint name="LH_KFE" pos="0 0 0" axis="1 0.000293579 0.000797925" range="-3.1114 3.14492" armature="0.0108159" damping="0.00841675" frictionloss="0.101373"/>
            <geom name="//unnamed_geom_85" class="visual" pos="0.000731807 -0.00390205 0" quat="-0.707107 0 0 -0.707107" material="shank" mesh="shank_r"/>
            <geom name="LH_kfe_act" class="collision" size="0.0593417 0.0197806" pos="0.0202715 0 0" quat="0.5 0.5 -0.5 -0.5"/>
            <geom name="//unnamed_geom_87" class="collision" size="0.0568682 0.0333797 0.0187915" pos="0.0202715 0.0517937 0" quat="0.5 0.5 -0.5 -0.5" type="box"/>
            <geom name="//unnamed_geom_88" class="visual" pos="0.0132274 0.0779658 -0.355792" quat="-0.382683 0 0 -0.92388" material="foot" mesh="foot"/>
            <geom name="LH_calf" class="collision" size="0.017308 0.139702" pos="0.0132272 0.0792233 -0.177896" quat="0.707107 0 0 -0.707107"/>
            <geom name="LH_foot" class="foot" size="0.0310312" pos="0.0132272 0.0792233 -0.332106" quat="0.707107 0 0 -0.707107"/>
            <geom name="//unnamed_geom_91" class="reward_collision_sphere" size="0.0989029" pos="-0.0506788 0 0"/>
            <geom name="//unnamed_geom_92" class="reward_collision_sphere" size="0.0494514" pos="0.0132272 0.0792233 -0.332106"/>
            <site name="LH_foot" class="foot" pos="0.0132272 0.0792233 -0.332106" quat="0.707107 0 0 -0.707107" size="0.00989029"/>
          </body>
        </body>
      </body>
      <body name="RH_HIP" pos="-0.305678 -0.0941636 -0.000219435" quat="-0.000717709 -0.000107226 -0.965703 -0.259647">
        <inertial pos="0.0574008 -0.0133363 -0.00943332" quat="-0.128018 0.709764 -0.135298 0.679368" mass="2.72408" diaginertia="0.00633633 0.0029298 0.00441392"/>
        <joint name="RH_HAA" pos="0 0 0" axis="0.999996 0.000845309 -0.002575" range="-0.725371 0.4883" armature="0.010514" damping="0.00966596" frictionloss="0.0958239"/>
        <geom name="//unnamed_geom_93" class="visual" pos="0 -0.000154197 2.53267e-05" quat="-0.258819 0.965926 0 0" material="hip_l" mesh="hip_l"/>
        <geom name="//unnamed_geom_94" class="visual" pos="0.0607133 -0.0721358 -0.0427716" quat="-0.183013 0.683013 -0.683013 -0.183013" material="drive" mesh="drive"/>
        <geom name="//unnamed_geom_95" class="collision" size="0.0494514 0.069232" pos="0.0607132 -0.0107731 -0.00726912" quat="0.353553 0.612372 -0.612372 0.353553"/>
        <body name="RH_THIGH" pos="0.0609313 -0.0654515 -0.0442933" quat="-0.183354 0.68306 -0.682784 -0.183347">
          <inertial pos="0.0316049 -0.000206746 -0.258527" quat="0.993011 -0.00615986 -0.0828623 0.0838207" mass="2.94929" diaginertia="0.0321441 0.0178195 0.00543684"/>
          <joint name="RH_HFE" pos="0 0 0" axis="0.999998 -9.50857e-05 -0.00210068" range="-3.13766 3.18234" armature="0.00903713" damping="0.0110705" frictionloss="0.0980994"/>
          <geom name="//unnamed_geom_96" class="visual" pos="0.00224428 3.53646e-06 0" quat="0.707107 0 0 -0.707107" material="thigh" mesh="thigh"/>
          <geom name="//unnamed_geom_97" class="collision" size="0.0642869 0.0395611" pos="0.0405431 0 0" quat="0.5 0.5 0.5 0.5"/>
          <geom name="//unnamed_geom_98" class="collision" size="0.0370886 0.0296709 0.139764" pos="0.0304073 0 -0.148766" quat="0.707107 0 0 0.707107" type="box"/>
          <geom name="//unnamed_geom_99" class="visual" pos="0.101662 0 -0.300029" quat="1 0 0 0" material="drive" mesh="drive"/>
          <geom name="//unnamed_geom_100" class="collision" size="0.0494514 0.069232" pos="0.0307114 0 -0.300029" quat="0.707107 0 0.707107 0"/>
          <geom name="//unnamed_geom_101" class="reward_collision_sphere" size="0.0791223" pos="0.0253394 0 0"/>
          <body name="RH_SHANK" pos="0.100717 0.00075959 -0.300357" quat="1 -1.62251e-05 7.77359e-05 -1.55265e-05">
            <inertial pos="0.00644649 -0.0546866 -0.0851882" quat="0.993011 -0.115246 -0.00120719 -0.0254143" mass="0.565437" diaginertia="0.0107904 0.00540168 0.00143681"/>
            <joint name="RH_KFE" pos="0 0 0" axis="0.99999 0.000415052 -0.00447196" stiffness="0.000197404" range="-3.09962 3.11664" armature="0.00954916" damping="0.00754761" frictionloss="0.0947209"/>
            <geom name="//unnamed_geom_102" class="visual" pos="0.000731811 0.00390206 0" quat="0.707107 0 0 -0.707107" material="shank_l" mesh="shank_l"/>
            <geom name="RH_kfe_act" class="collision" size="0.0593417 0.0197806" pos="0.0202715 0 0" quat="0.5 0.5 0.5 0.5"/>
            <geom name="//unnamed_geom_104" class="collision" size="0.0568682 0.0333797 0.0187915" pos="0.0202715 -0.0517937 0" quat="0.5 0.5 0.5 0.5" type="box"/>
            <geom name="//unnamed_geom_105" class="visual" pos="0.013227 -0.0779658 -0.355792" quat="0.382683 0 0 -0.92388" material="foot" mesh="foot"/>
            <geom name="RH_calf" class="collision" size="0.017308 0.139702" pos="0.0132272 -0.0792233 -0.177896" quat="0.707107 0 0 0.707107"/>
            <geom name="RH_foot" class="foot" size="0.0291591" pos="0.0132272 -0.0792233 -0.332106" quat="0.707107 0 0 0.707107"/>
            <geom name="//unnamed_geom_108" class="reward_collision_sphere" size="0.0989029" pos="-0.0506788 0 0"/>
            <geom name="//unnamed_geom_109" class="reward_collision_sphere" size="0.0494514" pos="0.0132272 -0.0792233 -0.332106"/>
            <site name="RH_foot" class="foot" pos="0.0132272 -0.0792233 -0.332106" quat="0.707107 0 0 0.707107" size="0.00989029"/>
          </body>
        </body>
      </body>
    </body>
  </worldbody>

  <contact>
    <pair class="/" geom1="floor" geom2="LF_foot" name="//unnamed_contact_0"/>
    <pair class="/" geom1="floor" geom2="RF_foot" name="//unnamed_contact_1"/>
    <pair class="/" geom1="floor" geom2="LH_foot" name="//unnamed_contact_2"/>
    <pair class="/" geom1="floor" geom2="RH_foot" name="//unnamed_contact_3"/>
  </contact>

  <actuator>
    <general name="LF_HAA" class="/" joint="LF_HAA" forcerange="-77.1231 77.1231" gainprm="80.1816" biasprm="0 -80.1816 -1.87513"/>
    <general name="LF_HFE" class="/" joint="LF_HFE" forcerange="-79.229 79.229" gainprm="80.1816" biasprm="0 -80.1816 -1.87513"/>
    <general name="LF_KFE" class="/" joint="LF_KFE" forcerange="-80.5653 80.5653" gainprm="80.1816" biasprm="0 -80.1816 -1.87513"/>
    <general name="RF_HAA" class="/" joint="RF_HAA" forcerange="-82.7853 82.7853" gainprm="80.1816" biasprm="0 -80.1816 -1.87513"/>
    <general name="RF_HFE" class="/" joint="RF_HFE" forcerange="-79.6756 79.6756" gainprm="80.1816" biasprm="0 -80.1816 -1.87513"/>
    <general name="RF_KFE" class="/" joint="RF_KFE" forcerange="-79.3318 79.3318" gainprm="80.1816" biasprm="0 -80.1816 -1.87513"/>
    <general name="LH_HAA" class="/" joint="LH_HAA" forcerange="-80.5917 80.5917" gainprm="80.1816" biasprm="0 -80.1816 -1.87513"/>
    <general name="LH_HFE" class="/" joint="LH_HFE" forcerange="-79.4638 79.4638" gainprm="80.1816" biasprm="0 -80.1816 -1.87513"/>
    <general name="LH_KFE" class="/" joint="LH_KFE" forcerange="-77.3645 77.3645" gainprm="80.1816" biasprm="0 -80.1816 -1.87513"/>
    <general name="RH_HAA" class="/" joint="RH_HAA" forcerange="-82.4589 82.4589" gainprm="80.1816" biasprm="0 -80.1816 -1.87513"/>
    <general name="RH_HFE" class="/" joint="RH_HFE" forcerange="-76.739 76.739" gainprm="80.1816" biasprm="0 -80.1816 -1.87513"/>
    <general name="RH_KFE" class="/" joint="RH_KFE" forcerange="-82.712 82.712" gainprm="80.1816" biasprm="0 -80.1816 -1.87513"/>
  </actuator>

  <sensor>
    <gyro site="imu" name="imu_angular_velocity"/>
    <velocimeter site="imu" name="imu_linear_velocity"/>
    <framelinvel objtype="site" objname="LF_foot" name="LF_foot_global_linear_velocity"/>
    <framelinvel objtype="site" objname="RF_foot" name="RF_foot_global_linear_velocity"/>
    <framelinvel objtype="site" objname="LH_foot" name="LH_foot_global_linear_velocity"/>
    <framelinvel objtype="site" objname="RH_foot" name="RH_foot_global_linear_velocity"/>
  </sensor>

  <keyframe>
    <key name="home" qpos="0 0 0.55 1 0 0 0 0 0.4 -0.8 0 -0.4 0.8 0 -0.4 0.8 0 0.4 -0.8"/>
  </keyframe>
</mujoco>
