<mujoco model="anymal_c">
  <compiler angle="radian" assetdir="assets" balanceinertia="true" inertiafromgeom="false"/>

  <option timestep="0.005" density="1.2" viscosity="2e-05"/>

  <size nkey="1"/>

  <visual>
    <quality shadowsize="8192"/>
    <map shadowclip="0.5"/>
  </visual>

  <default>
    <default class="/">
      <material specular="0" shininess="0.25"/>
      <geom contype="0" conaffinity="0" group="1" solref="-1000 -80"/>
      <site size="0.01 0.005 0.005" group="5"/>
      <general forcelimited="true" forcerange="-80 80" biastype="affine" gainprm="80" biasprm="0 -80 -2"/>
      <default class="anymal_c">
        <joint armature="0.01" damping="0.01" frictionloss="0.1"/>
        <default class="visual">
          <geom type="mesh" group="2"/>
          <default class="visual_zflip"/>
        </default>
        <default class="collision">
          <geom type="cylinder" group="3"/>
          <default class="foot">
            <geom size="0.03 0 0" type="sphere" condim="6" priority="1" friction="0.8 0.02 0.01" solimp="0.015 1 0.03"/>
          </default>
        </default>
      </default>
      <default class="reward_collision_sphere">
        <geom group="5" rgba="1 0 0 1"/>
      </default>
    </default>
  </default>

  <asset>
    <texture type="skybox" colorspace="auto" name="//unnamed_texture_0" builtin="gradient" rgb1="0.95 0.95 0.95" rgb2="0.95 0.95 0.95" width="100" height="600"/>
    <texture type="2d" colorspace="auto" name="texplane" builtin="checker" rgb1="0.345 0.575 0.748" rgb2="0.345 0.575 0.748" markrgb="1 1 1" width="512" height="512"/>
    <texture type="2d" colorspace="linear" name="base" file="base.png"/>
    <texture type="2d" colorspace="linear" name="top_shell" file="top_shell.png"/>
    <texture type="2d" colorspace="linear" name="bottom_shell" file="bottom_shell.png"/>
    <texture type="2d" colorspace="linear" name="remote" file="remote.png"/>
    <texture type="2d" colorspace="linear" name="hatch" file="hatch.png"/>
    <texture type="2d" colorspace="linear" name="handle" file="handle.png"/>
    <texture type="2d" colorspace="linear" name="face" file="face.png"/>
    <texture type="2d" colorspace="linear" name="battery" file="battery.png"/>
    <texture type="2d" colorspace="linear" name="lidar_cage" file="lidar_cage.png"/>
    <texture type="2d" colorspace="linear" name="depth_camera" file="depth_camera.png"/>
    <texture type="2d" colorspace="linear" name="wide_angle_camera" file="wide_angle_camera.png"/>
    <texture type="2d" colorspace="linear" name="lidar" file="lidar.png"/>
    <texture type="2d" colorspace="linear" name="drive" file="drive.png"/>
    <texture type="2d" colorspace="linear" name="hip_l" file="hip_l.png"/>
    <texture type="2d" colorspace="linear" name="shank_l" file="shank_l.png"/>
    <texture type="2d" colorspace="linear" name="foot" file="foot.png"/>
    <texture type="2d" colorspace="linear" name="thigh" file="thigh.png"/>
    <texture type="2d" colorspace="linear" name="shank_r" file="shank_r.png"/>
    <texture type="2d" colorspace="linear" name="hip_r" file="hip_r.png"/>
    <material name="MatPlane" class="/" texture="texplane" texuniform="true" texrepeat="2 2" specular="0.9" shininess="0.5"/>
    <material name="black_plastic" class="/" rgba="0.007 0.007 0.007 1"/>
    <material name="green" class="/" rgba="0.052 0.178 0.033 1"/>
    <material name="red" class="/" rgba="0.178 0.006 0.005 1"/>
    <material name="yellow" class="/" rgba="0.178 0.119 0.006 1"/>
    <material name="lwl" class="/" rgba="0.8 0.8 0.8 1"/>
    <material name="base" class="/" texture="base"/>
    <material name="top_shell" class="/" texture="top_shell"/>
    <material name="bottom_shell" class="/" texture="bottom_shell"/>
    <material name="hip_l" class="/" texture="hip_l"/>
    <material name="thigh" class="/" texture="thigh"/>
    <material name="shank_l" class="/" texture="shank_l"/>
    <material name="foot" class="/" texture="foot"/>
    <material name="hip_r" class="/" texture="hip_r"/>
    <material name="shank" class="/" texture="shank_r"/>
    <material name="hatch" class="/" texture="hatch"/>
    <material name="remote" class="/" texture="remote"/>
    <material name="handle" class="/" texture="handle"/>
    <material name="face" class="/" texture="face"/>
    <material name="depth_camera" class="/" texture="depth_camera"/>
    <material name="wide_angle_camera" class="/" texture="wide_angle_camera"/>
    <material name="battery" class="/" texture="battery"/>
    <material name="lidar_cage" class="/" texture="lidar_cage"/>
    <material name="lidar" class="/" texture="lidar"/>
    <material name="drive" class="/" texture="drive"/>
    <mesh name="base_0" class="/" file="base_0.obj"/>
    <mesh name="base_1" class="/" file="base_1.obj"/>
    <mesh name="base_2" class="/" file="base_2.obj"/>
    <mesh name="base_3" class="/" file="base_3.obj"/>
    <mesh name="base_4" class="/" file="base_4.obj"/>
    <mesh name="base_5" class="/" file="base_5.obj"/>
    <mesh name="top_shell" class="/" file="top_shell.obj"/>
    <mesh name="bottom_shell" class="/" file="bottom_shell.obj"/>
    <mesh name="remote" class="/" file="remote.obj"/>
    <mesh name="handle" class="/" file="handle.obj"/>
    <mesh name="face" class="/" file="face.obj"/>
    <mesh name="wide_angle_camera" class="/" file="wide_angle_camera.obj"/>
    <mesh name="depth_camera" class="/" file="depth_camera.obj"/>
    <mesh name="battery" class="/" file="battery.obj"/>
    <mesh name="lidar_cage" class="/" file="lidar_cage.obj"/>
    <mesh name="lidar" class="/" file="lidar.obj"/>
    <mesh name="drive" class="/" file="drive.obj"/>
    <mesh name="hip_l" class="/" file="hip_l.obj"/>
    <mesh name="thigh" class="/" file="thigh.obj"/>
    <mesh name="shank_l" class="/" file="shank_l.obj"/>
    <mesh name="foot" class="/" file="foot.obj"/>
    <mesh name="hip_r" class="/" file="hip_r.obj"/>
    <mesh name="hatch" class="/" file="hatch.obj"/>
    <mesh name="shank_r" class="/" file="shank_r.obj"/>
  </asset>

  <worldbody>
    <geom name="floor" class="/" size="100 100 0.125" type="plane" group="0" material="MatPlane"/>
    <light name="toplight_shadow" class="/" pos="0 0 5" dir="0.0990148 0.0990148 -0.990148" type="directional" ambient="0.04 0.04 0.04" diffuse="0.55 0.55 0.55" specular="0.12 0.12 0.12"/>
    <light name="toplight_fill" class="/" pos="0 0 5" dir="0.0990148 0.0990148 -0.990148" type="directional" castshadow="false" ambient="0.04 0.04 0.04" diffuse="0.3 0.3 0.3" specular="0.08 0.08 0.08"/>
    <body name="trunk" childclass="anymal_c" pos="-0.000625703 0.00239494 -0.00123368" quat="0.999999 -0.00052812 -0.000694738 0.000859973">
      <inertial pos="0.00341585 0.00704869 0.0369337" quat="0.50067 0.504351 0.495926 0.499016" mass="20.6452" diaginertia="0.508437 2.21891 0.0894591"/>
      <joint name="//unnamed_joint_0" type="free" armature="0" damping="0" frictionloss="0"/>
      <geom name="//unnamed_geom_1" class="visual" material="green" mesh="base_0"/>
      <geom name="//unnamed_geom_2" class="visual" material="yellow" mesh="base_1"/>
      <geom name="//unnamed_geom_3" class="visual" material="red" mesh="base_2"/>
      <geom name="//unnamed_geom_4" class="visual" material="black_plastic" mesh="base_3"/>
      <geom name="//unnamed_geom_5" class="visual" material="lwl" mesh="base_4"/>
      <geom name="//unnamed_geom_6" class="visual" material="base" mesh="base_5"/>
      <geom name="trunk_1" class="collision" size="0.293385 0.0708172 0.0910506" type="box"/>
      <geom name="trunk_2" class="collision" size="0.0910506 0.0733463" pos="0.200906 0.0895144 0" quat="0.707107 0 0.707107 0"/>
      <geom name="trunk_3" class="collision" size="0.0910506 0.0733463" pos="-0.200906 0.0895144 0" quat="0.707107 0 0.707107 0"/>
      <geom name="trunk_4" class="collision" size="0.0910506 0.0733463" pos="0.200906 -0.0895144 0" quat="0.707107 0 0.707107 0"/>
      <geom name="trunk_5" class="collision" size="0.0910506 0.0733463" pos="-0.200906 -0.0895144 0" quat="0.707107 0 0.707107 0"/>
      <geom name="//unnamed_geom_12" class="visual" material="top_shell" mesh="top_shell"/>
      <geom name="//unnamed_geom_13" class="visual" material="bottom_shell" mesh="bottom_shell"/>
      <geom name="//unnamed_geom_14" class="visual" material="remote" mesh="remote"/>
      <geom name="//unnamed_geom_15" class="visual" material="handle" mesh="handle"/>
      <geom name="//unnamed_geom_16" class="visual" pos="0.382876 0 0" quat="1 0 0 0" material="face" mesh="face"/>
      <geom name="trunk_6" class="collision" size="0.0556421 0.0708172 0.0910506" pos="0.43368 0 0" type="box"/>
      <geom name="//unnamed_geom_18" class="collision" size="0.0910506 0.0556421" pos="0.43368 0.0895144 0" quat="0.707107 0 0.707107 0"/>
      <geom name="//unnamed_geom_19" class="collision" size="0.0910506 0.0556421" pos="0.43368 -0.0895144 0" quat="0.707107 0 0.707107 0"/>
      <geom name="//unnamed_geom_20" class="visual" pos="0.426425 0 -0.0236172" quat="0.965926 0 0.258819 0" material="depth_camera" mesh="depth_camera"/>
      <geom name="//unnamed_geom_21" class="visual" pos="0.473861 0 0.0124631" material="wide_angle_camera" mesh="wide_angle_camera"/>
      <geom name="//unnamed_geom_22" class="visual_zflip" pos="-0.382876 0 0" quat="0 0 0 1" material="face" mesh="face"/>
      <geom name="trunk_7" class="collision" size="0.0556421 0.0708172 0.0910506" pos="-0.43368 0 0" quat="0 0 0 1" type="box"/>
      <geom name="//unnamed_geom_24" class="collision" size="0.0910506 0.0556421" pos="-0.43368 -0.0895144 0" quat="0 -0.707107 0 0.707107"/>
      <geom name="//unnamed_geom_25" class="collision" size="0.0910506 0.0556421" pos="-0.43368 0.0895144 0" quat="0 -0.707107 0 0.707107"/>
      <geom name="//unnamed_geom_26" class="visual" pos="-0.426425 0 -0.0236172" quat="0 -0.258819 0 0.965926" material="depth_camera" mesh="depth_camera"/>
      <geom name="//unnamed_geom_27" class="visual_zflip" pos="-0.473861 0 0.0124631" quat="0 0 0 1" material="wide_angle_camera" mesh="wide_angle_camera"/>
      <geom name="//unnamed_geom_28" class="visual" material="battery" mesh="battery"/>
      <geom name="//unnamed_geom_29" class="visual" pos="0 0.102431 0.0248781" quat="0.683013 -0.183013 0.183013 0.683013" material="depth_camera" mesh="depth_camera"/>
      <geom name="//unnamed_geom_30" class="visual" pos="0 -0.102431 0.0248781" quat="0.683013 0.183013 0.183013 -0.683013" material="depth_camera" mesh="depth_camera"/>
      <geom name="//unnamed_geom_31" class="visual" pos="-0.336229 0 0.0611916" quat="1 0 0 0" material="lidar_cage" mesh="lidar_cage"/>
      <geom name="trunk_8" class="collision" size="0.0708172 0.0607004" pos="-0.336229 0 0.111144"/>
      <geom name="//unnamed_geom_33" class="visual" pos="-0.336229 0.000139498 0.118387" quat="0.707107 0 0 -0.707107" material="lidar" mesh="lidar"/>
      <geom name="//unnamed_geom_34" class="visual" pos="0.277019 0.132834 7.69768e-09" quat="0.258819 0.965926 0 0" material="drive" mesh="drive"/>
      <geom name="//unnamed_geom_35" class="visual" pos="0.277019 -0.132834 -7.69768e-09" quat="0.258819 -0.965926 0 0" material="drive" mesh="drive"/>
      <geom name="//unnamed_geom_36" class="visual" pos="-0.277019 0.132834 -7.69768e-09" quat="0 0 0.965926 -0.258819" material="drive" mesh="drive"/>
      <geom name="//unnamed_geom_37" class="visual" pos="-0.277019 -0.132834 7.69768e-09" quat="0 0 -0.965926 -0.258819" material="drive" mesh="drive"/>
      <geom name="//unnamed_geom_38" class="visual" pos="0.10715 0 0.0607753" quat="1 0 0 0" material="hatch" mesh="hatch"/>
      <geom name="//unnamed_geom_39" class="reward_collision_sphere" size="0.121401"/>
      <geom name="//unnamed_geom_40" class="reward_collision_sphere" size="0.121401" pos="0.415667 0 0"/>
      <geom name="//unnamed_geom_41" class="reward_collision_sphere" size="0.121401" pos="-0.415667 0 0"/>
      <site name="imu" pos="0.218861 0.0196925 0.0474795" size="0.0101167"/>
      <camera name="track" pos="0 -2.55755 0" quat="0.707107 0.707107 0 0" mode="trackcom"/>
      <camera name="ego_camera" pos="0.415667 0 -0.0333015" quat="-0.5 -0.5 0.5 0.5"/>
      <body name="LF_HIP" pos="0.279888 0.132196 -0.000836084" quat="0.257742 0.966214 -3.10989e-06 6.8192e-05">
        <inertial pos="0.05277 -0.0151238 -0.00682799" quat="-0.14645 0.682798 -0.129122 0.704036" mass="2.99069" diaginertia="0.00394136 0.0172922 0.00132162"/>
        <joint name="LF_HAA" pos="0 0 0" axis="0.999984 -0.00393235 0.0041552" range="-0.702106 0.441681" armature="0.00959583" damping="0.0191879" frictionloss="0.100111"/>
        <geom name="//unnamed_geom_42" class="visual" pos="0 0.000452819 -7.43752e-05" quat="0.258819 -0.965926 0 0" material="hip_l" mesh="hip_l"/>
        <geom name="//unnamed_geom_43" class="visual" pos="0.0553299 -0.0715606 -0.0380149" quat="0.183013 -0.683013 0.683013 0.183013" material="drive" mesh="drive"/>
        <geom name="//unnamed_geom_44" class="collision" size="0.0505837 0.0708172" pos="0.05533 -0.0152939 -0.00574868" quat="-0.353553 -0.612372 0.612372 -0.353553"/>
        <body name="LF_THIGH" pos="0.0511301 -0.0939016 -0.0327893" quat="0.184405 -0.683608 0.681255 0.18592">
          <inertial pos="0.0282365 -0.0074379 -0.206766" quat="0.993138 -0.00407518 -0.0819966 0.0832853" mass="3.14831" diaginertia="0.0217086 0.0935158 0.00167447"/>
          <joint name="LF_HFE" pos="0 0 0" axis="0.999913 0.00410672 0.0125227" range="-3.08907 3.26149" armature="0.00658938" damping="0.0233985" frictionloss="0.107204"/>
          <geom name="//unnamed_geom_45" class="visual" pos="-0.00706453 -1.11321e-05 0" quat="0.707107 0 0 -0.707107" material="thigh" mesh="thigh"/>
          <geom name="//unnamed_geom_46" class="collision" size="0.0657588 0.0404669" pos="0.0369482 0 0" quat="0.5 0.5 -0.5 -0.5"/>
          <geom name="//unnamed_geom_47" class="collision" size="0.0379378 0.0303502 0.142964" pos="0.0277112 0 -0.117649" quat="0.707107 0 0 -0.707107" type="box"/>
          <geom name="//unnamed_geom_48" class="visual" pos="0.0926477 0 -0.237273" quat="1 0 0 0" material="drive" mesh="drive"/>
          <geom name="//unnamed_geom_49" class="collision" size="0.0505837 0.0708172" pos="0.0279883 0 -0.237273" quat="0.707107 0 0.707107 0"/>
          <geom name="//unnamed_geom_50" class="reward_collision_sphere" size="0.0809339" pos="0.0230926 0 0"/>
          <body name="LF_SHANK" pos="0.0942329 0.000841221 -0.242496" quat="0.999999 0.000514367 -0.000887073 0.000767173">
            <inertial pos="0.0103791 -0.0763665 -0.0630871" quat="0.99257 -0.118853 -0.00360571 -0.0258009" mass="0.631555" diaginertia="0.00695125 0.0299243 0.000446117"/>
            <joint name="LF_KFE" pos="0 0 0" axis="0.999956 -0.00434463 0.00834381" range="-3.29104 3.06148" armature="0.0107378" damping="0.0305265" frictionloss="0.106557"/>
            <geom name="//unnamed_geom_51" class="visual" pos="-0.00230359 -0.0122829 0" quat="0.707107 0 0 -0.707107" material="shank_l" mesh="shank_l"/>
            <geom name="LF_kfe_act" class="collision" size="0.0607004 0.0202335" pos="0.0184741 0 0" quat="0.5 0.5 -0.5 -0.5"/>
            <geom name="//unnamed_geom_53" class="collision" size="0.0581702 0.034144 0.0192218" pos="0.0184741 -0.0735284 0" quat="0.5 0.5 -0.5 -0.5" type="box"/>
            <geom name="//unnamed_geom_54" class="visual" pos="0.0120549 -0.116427 -0.281373" quat="0.382683 0 0 -0.92388" material="foot" mesh="foot"/>
            <geom name="LF_calf" class="collision" size="0.0177043 0.142901" pos="0.0120544 -0.112468 -0.140686" quat="0.707107 0 0 -0.707107"/>
            <geom name="LF_foot" class="foot" size="0.0332987" pos="0.0120544 -0.112468 -0.262641" quat="0.707107 0 0 -0.707107"/>
            <geom name="//unnamed_geom_57" class="reward_collision_sphere" size="0.101167" pos="-0.0461853 0 0"/>
            <geom name="//unnamed_geom_58" class="reward_collision_sphere" size="0.0505837" pos="0.0120544 -0.112468 -0.262641"/>
            <site name="LF_foot" class="foot" pos="0.0120544 -0.112468 -0.262641" quat="0.707107 0 0 -0.707107" size="0.0101167"/>
          </body>
        </body>
      </body>
      <body name="RF_HIP" pos="0.284402 -0.132417 0.0106984" quat="0.258418 -0.966033 0.000807545 -0.000258258">
        <inertial pos="0.0502416 0.0202734 -0.00684075" quat="0.144237 0.695214 0.112996 0.695057" mass="2.885" diaginertia="0.00411909 0.0167868 0.00134294"/>
        <joint name="RF_HAA" pos="0 0 0" axis="0.999984 0.00331701 0.00449564" stiffness="0.0382277" range="-0.453044 0.62357" armature="0.0101149" damping="0.0265136" frictionloss="0.108611"/>
        <geom name="//unnamed_geom_59" class="visual" pos="0 -0.000452816 -7.4375e-05" quat="0.258819 0.965926 0 0" material="hip_r" mesh="hip_r"/>
        <geom name="//unnamed_geom_60" class="visual" pos="0.05533 0.0715606 -0.0380149" quat="0.183013 0.683013 0.683013 -0.183013" material="drive" mesh="drive"/>
        <geom name="//unnamed_geom_61" class="collision" size="0.0505837 0.0708172" pos="0.05533 0.0152939 -0.00574868" quat="-0.353553 0.612372 0.612372 0.353553"/>
        <body name="RF_THIGH" pos="0.0551133 0.0871264 -0.02935" quat="0.182886 0.682918 0.683403 -0.182033">
          <inertial pos="0.027866 0.00211153 -0.210551" quat="0.992555 -0.00472759 -0.0791845 0.0924277" mass="3.26449" diaginertia="0.0211421 0.103372 0.00169187"/>
          <joint name="RF_HFE" pos="0 0 0" axis="0.9999 0.0121418 -0.00721329" range="-3.16459 3.15701" armature="0.0126358" damping="0" frictionloss="0.110548"/>
          <geom name="//unnamed_geom_62" class="visual" pos="-0.00706453 -1.11321e-05 0" quat="0.707107 0 0 -0.707107" material="thigh" mesh="thigh"/>
          <geom name="//unnamed_geom_63" class="collision" size="0.0657588 0.0404669" pos="0.0369482 0 0" quat="0.5 0.5 0.5 0.5"/>
          <geom name="//unnamed_geom_64" class="collision" size="0.0379378 0.0303502 0.142964" pos="0.0277112 0 -0.117649" quat="0.707107 0 0 0.707107" type="box"/>
          <geom name="//unnamed_geom_65" class="visual" pos="0.0926477 0 -0.237273" quat="1 0 0 0" material="drive" mesh="drive"/>
          <geom name="//unnamed_geom_66" class="collision" size="0.0505837 0.0708172" pos="0.0279883 0 -0.237273" quat="0.707107 0 0.707107 0"/>
          <geom name="//unnamed_geom_67" class="reward_collision_sphere" size="0.0809339" pos="0.0230926 0 0"/>
          <body name="RF_SHANK" pos="0.0895639 -0.00340722 -0.242973" quat="1 0.000285047 -0.000871438 -0.000226936">
            <inertial pos="0.00695216 0.076075 -0.0653514" quat="0.992887 0.116388 -0.00178614 0.0250204" mass="0.553621" diaginertia="0.00616608 0.027661 0.000414963"/>
            <joint name="RF_KFE" pos="0 0 0" axis="0.999971 0.00469613 0.00607525" range="-3.11717 3.16974" armature="0.00907231" damping="0.0390965" frictionloss="0.0975869"/>
            <geom name="//unnamed_geom_68" class="visual" pos="-0.00230358 0.0122828 0" quat="0.707107 0 0 0.707107" material="shank" mesh="shank_r"/>
            <geom name="RF_kfe_act" class="collision" size="0.0607004 0.0202335" pos="0.0184741 0 0" quat="0.5 0.5 0.5 0.5"/>
            <geom name="//unnamed_geom_70" class="collision" size="0.0581702 0.034144 0.0192218" pos="0.0184741 0.0735284 0" quat="0.5 0.5 0.5 0.5" type="box"/>
            <geom name="//unnamed_geom_71" class="visual" pos="0.0120538 0.116427 -0.281373" quat="0.382683 0 0 0.92388" material="foot" mesh="foot"/>
            <geom name="RF_calf" class="collision" size="0.0177043 0.142901" pos="0.0120544 0.112468 -0.140686" quat="0.707107 0 0 0.707107"/>
            <geom name="RF_foot" class="foot" size="0.0387208" pos="0.0120544 0.112468 -0.262641" quat="0.707107 0 0 0.707107"/>
            <geom name="//unnamed_geom_74" class="reward_collision_sphere" size="0.101167" pos="-0.0461853 0 0"/>
            <geom name="//unnamed_geom_75" class="reward_collision_sphere" size="0.0505837" pos="0.0120544 0.112468 -0.262641"/>
            <site name="RF_foot" class="foot" pos="0.0120544 0.112468 -0.262641" quat="0.707107 0 0 0.707107" size="0.0101167"/>
          </body>
        </body>
      </body>
      <body name="LH_HIP" pos="-0.276559 0.132586 -0.00299521" quat="-0.000303521 0.00129509 0.966003 -0.258527">
        <inertial pos="0.0545377 0.0173368 -0.00870096" quat="0.130465 0.684876 0.130074 0.704986" mass="3.137" diaginertia="0.00381386 0.0168427 0.00128694"/>
        <joint name="LH_HAA" pos="0 0 0" axis="1 -0.000597298 -0.000341271" range="-0.584204 0.70438" armature="0.0091551" damping="0" frictionloss="0.0828862"/>
        <geom name="//unnamed_geom_76" class="visual" pos="0 -0.000452816 -7.4375e-05" quat="-0.258819 -0.965926 0 0" material="hip_r" mesh="hip_r"/>
        <geom name="//unnamed_geom_77" class="visual" pos="0.05533 0.0715606 -0.0380149" quat="0.183013 0.683013 0.683013 -0.183013" material="drive" mesh="drive"/>
        <geom name="//unnamed_geom_78" class="collision" size="0.0505837 0.0708172" pos="0.05533 0.0152939 -0.00574868" quat="-0.353553 0.612372 0.612372 0.353553"/>
        <body name="LH_THIGH" pos="0.0546697 0.0931249 -0.0347557" quat="0.180343 0.683771 0.682622 -0.184288">
          <inertial pos="0.0300108 -0.00815708 -0.203535" quat="0.993649 -0.0175683 -0.0680609 0.0878728" mass="3.47823" diaginertia="0.0207497 0.101194 0.00157248"/>
          <joint name="LH_HFE" pos="0 0 0" axis="0.999281 0.00443854 0.0376624" range="-3.1895 3.10672" armature="0.00899753" damping="0" frictionloss="0.107362"/>
          <geom name="//unnamed_geom_79" class="visual" pos="-0.00706453 -1.11321e-05 0" quat="0.707107 0 0 -0.707107" material="thigh" mesh="thigh"/>
          <geom name="//unnamed_geom_80" class="collision" size="0.0657588 0.0404669" pos="0.0369482 0 0" quat="0.5 0.5 -0.5 -0.5"/>
          <geom name="//unnamed_geom_81" class="collision" size="0.0379378 0.0303502 0.142964" pos="0.0277112 0 -0.117649" quat="0.707107 0 0 -0.707107" type="box"/>
          <geom name="//unnamed_geom_82" class="visual" pos="0.0926477 0 -0.237273" quat="1 0 0 0" material="drive" mesh="drive"/>
          <geom name="//unnamed_geom_83" class="collision" size="0.0505837 0.0708172" pos="0.0279883 0 -0.237273" quat="0.707107 0 0.707107 0"/>
          <geom name="//unnamed_geom_84" class="reward_collision_sphere" size="0.0809339" pos="0.0230926 0 0"/>
          <body name="LH_SHANK" pos="0.0929084 -0.00366365 -0.239934" quat="1 0.000102001 0.000272599 -0.000390576">
            <inertial pos="0.00510672 0.0739055 -0.0694121" quat="0.992783 0.117667 -0.00942186 0.0211655" mass="0.616032" diaginertia="0.00728238 0.0337508 0.000481492"/>
            <joint name="LH_KFE" pos="0 0 0" axis="0.999988 0.00255377 -0.00425486" range="-3.28253 3.13181" armature="0.00632219" damping="0" frictionloss="0.111764"/>
            <geom name="//unnamed_geom_85" class="visual" pos="-0.00230358 0.0122828 0" quat="-0.707107 0 0 -0.707107" material="shank" mesh="shank_r"/>
            <geom name="LH_kfe_act" class="collision" size="0.0607004 0.0202335" pos="0.0184741 0 0" quat="0.5 0.5 -0.5 -0.5"/>
            <geom name="//unnamed_geom_87" class="collision" size="0.0581702 0.034144 0.0192218" pos="0.0184741 0.0735284 0" quat="0.5 0.5 -0.5 -0.5" type="box"/>
            <geom name="//unnamed_geom_88" class="visual" pos="0.0120538 0.116427 -0.281373" quat="-0.382683 0 0 -0.92388" material="foot" mesh="foot"/>
            <geom name="LH_calf" class="collision" size="0.0177043 0.142901" pos="0.0120544 0.112468 -0.140686" quat="0.707107 0 0 -0.707107"/>
            <geom name="LH_foot" class="foot" size="0.035258" pos="0.0120544 0.112468 -0.262641" quat="0.707107 0 0 -0.707107"/>
            <geom name="//unnamed_geom_91" class="reward_collision_sphere" size="0.101167" pos="-0.0461853 0 0"/>
            <geom name="//unnamed_geom_92" class="reward_collision_sphere" size="0.0505837" pos="0.0120544 0.112468 -0.262641"/>
            <site name="LH_foot" class="foot" pos="0.0120544 0.112468 -0.262641" quat="0.707107 0 0 -0.707107" size="0.0101167"/>
          </body>
        </body>
      </body>
      <body name="RH_HIP" pos="-0.269891 -0.135398 -0.000143671" quat="-0.00327072 0.00099243 -0.966453 -0.256821">
        <inertial pos="0.0540825 -0.0208692 -0.00959237" quat="-0.128883 0.70978 -0.136321 0.678983" mass="2.92365" diaginertia="0.00397383 0.0172134 0.00119103"/>
        <joint name="RH_HAA" pos="0 0 0" axis="0.99992 0.0112352 0.00573965" range="-0.764895 0.439604" armature="0.00712845" damping="0.0124163" frictionloss="0.0922083"/>
        <geom name="//unnamed_geom_93" class="visual" pos="0 0.000452819 -7.43752e-05" quat="-0.258819 0.965926 0 0" material="hip_l" mesh="hip_l"/>
        <geom name="//unnamed_geom_94" class="visual" pos="0.0553299 -0.0715606 -0.0380149" quat="-0.183013 0.683013 -0.683013 -0.183013" material="drive" mesh="drive"/>
        <geom name="//unnamed_geom_95" class="collision" size="0.0505837 0.0708172" pos="0.05533 -0.0152939 -0.00574868" quat="0.353553 0.612372 -0.612372 0.353553"/>
        <body name="RH_THIGH" pos="0.0579087 -0.0968322 -0.0356169" quat="-0.183193 0.682952 -0.682997 -0.183118">
          <inertial pos="0.0286961 0.00342438 -0.206271" quat="0.993715 -0.0103464 -0.0708394 0.0860546" mass="3.30791" diaginertia="0.0202418 0.102812 0.00176119"/>
          <joint name="RH_HFE" pos="0 0 0" axis="0.999997 0.00208934 0.00145981" range="-3.10113 2.98675" armature="0.0136848" damping="0" frictionloss="0.0912054"/>
          <geom name="//unnamed_geom_96" class="visual" pos="-0.00706453 -1.11321e-05 0" quat="0.707107 0 0 -0.707107" material="thigh" mesh="thigh"/>
          <geom name="//unnamed_geom_97" class="collision" size="0.0657588 0.0404669" pos="0.0369482 0 0" quat="0.5 0.5 0.5 0.5"/>
          <geom name="//unnamed_geom_98" class="collision" size="0.0379378 0.0303502 0.142964" pos="0.0277112 0 -0.117649" quat="0.707107 0 0 0.707107" type="box"/>
          <geom name="//unnamed_geom_99" class="visual" pos="0.0926477 0 -0.237273" quat="1 0 0 0" material="drive" mesh="drive"/>
          <geom name="//unnamed_geom_100" class="collision" size="0.0505837 0.0708172" pos="0.0279883 0 -0.237273" quat="0.707107 0 0.707107 0"/>
          <geom name="//unnamed_geom_101" class="reward_collision_sphere" size="0.0809339" pos="0.0230926 0 0"/>
          <body name="RH_SHANK" pos="0.0914226 -0.000329144 -0.237695" quat="1 0.000389372 -0.000592509 0.000401239">
            <inertial pos="0.00640865 -0.0756102 -0.0669035" quat="0.992777 -0.117817 -0.00138213 -0.022612" mass="0.585745" diaginertia="0.00689431 0.0311097 0.000431571"/>
            <joint name="RH_KFE" pos="0 0 0" axis="0.99985 0.0087918 -0.0149148" stiffness="0.00573339" range="-3.24507 3.12849" armature="0.00932615" damping="0" frictionloss="0.0955222"/>
            <geom name="//unnamed_geom_102" class="visual" pos="-0.00230359 -0.0122829 0" quat="0.707107 0 0 -0.707107" material="shank_l" mesh="shank_l"/>
            <geom name="RH_kfe_act" class="collision" size="0.0607004 0.0202335" pos="0.0184741 0 0" quat="0.5 0.5 0.5 0.5"/>
            <geom name="//unnamed_geom_104" class="collision" size="0.0581702 0.034144 0.0192218" pos="0.0184741 -0.0735284 0" quat="0.5 0.5 0.5 0.5" type="box"/>
            <geom name="//unnamed_geom_105" class="visual" pos="0.0120549 -0.116427 -0.281373" quat="0.382683 0 0 -0.92388" material="foot" mesh="foot"/>
            <geom name="RH_calf" class="collision" size="0.0177043 0.142901" pos="0.0120544 -0.112468 -0.140686" quat="0.707107 0 0 0.707107"/>
            <geom name="RH_foot" class="foot" size="0.0213233" pos="0.0120544 -0.112468 -0.262641" quat="0.707107 0 0 0.707107"/>
            <geom name="//unnamed_geom_108" class="reward_collision_sphere" size="0.101167" pos="-0.0461853 0 0"/>
            <geom name="//unnamed_geom_109" class="reward_collision_sphere" size="0.0505837" pos="0.0120544 -0.112468 -0.262641"/>
            <site name="RH_foot" class="foot" pos="0.0120544 -0.112468 -0.262641" quat="0.707107 0 0 0.707107" size="0.0101167"/>
          </body>
        </body>
      </body>
    </body>
  </worldbody>

  <contact>
    <pair class="/" geom1="floor" geom2="LF_foot" name="//unnamed_contact_0"/>
    <pair class="/" geom1="floor" geom2="RF_foot" name="//unnamed_contact_1"/>
    <pair class="/" geom1="floor" geom2="LH_foot" name="//unnamed_contact_2"/>
    <pair class="/" geom1="floor" geom2="RH_foot" name="//unnamed_contact_3"/>
  </contact>

  <actuator>
    <general name="LF_HAA" class="/" joint="LF_HAA" forcerange="-80.3398 80.3398" gainprm="80.7174" biasprm="0 -80.7174 -2.27643"/>
    <general name="LF_HFE" class="/" joint="LF_HFE" forcerange="-79.8244 79.8244" gainprm="80.7174" biasprm="0 -80.7174 -2.27643"/>
    <general name="LF_KFE" class="/" joint="LF_KFE" forcerange="-88.039 88.039" gainprm="80.7174" biasprm="0 -80.7174 -2.27643"/>
    <general name="RF_HAA" class="/" joint="RF_HAA" forcerange="-83.0494 83.0494" gainprm="80.7174" biasprm="0 -80.7174 -2.27643"/>
    <general name="RF_HFE" class="/" joint="RF_HFE" forcerange="-84.0839 84.0839" gainprm="80.7174" biasprm="0 -80.7174 -2.27643"/>
    <general name="RF_KFE" class="/" joint="RF_KFE" forcerange="-90.6521 90.6521" gainprm="80.7174" biasprm="0 -80.7174 -2.27643"/>
    <general name="LH_HAA" class="/" joint="LH_HAA" forcerange="-78.09 78.09" gainprm="80.7174" biasprm="0 -80.7174 -2.27643"/>
    <general name="LH_HFE" class="/" joint="LH_HFE" forcerange="-82.301 82.301" gainprm="80.7174" biasprm="0 -80.7174 -2.27643"/>
    <general name="LH_KFE" class="/" joint="LH_KFE" forcerange="-86.3088 86.3088" gainprm="80.7174" biasprm="0 -80.7174 -2.27643"/>
    <general name="RH_HAA" class="/" joint="RH_HAA" forcerange="-82.3837 82.3837" gainprm="80.7174" biasprm="0 -80.7174 -2.27643"/>
    <general name="RH_HFE" class="/" joint="RH_HFE" forcerange="-83.2669 83.2669" gainprm="80.7174" biasprm="0 -80.7174 -2.27643"/>
    <general name="RH_KFE" class="/" joint="RH_KFE" forcerange="-64.1863 64.1863" gainprm="80.7174" biasprm="0 -80.7174 -2.27643"/>
  </actuator>

  <sensor>
    <gyro site="imu" name="imu_angular_velocity"/>
    <velocimeter site="imu" name="imu_linear_velocity"/>
    <framelinvel objtype="site" objname="LF_foot" name="LF_foot_global_linear_velocity"/>
    <framelinvel objtype="site" objname="RF_foot" name="RF_foot_global_linear_velocity"/>
    <framelinvel objtype="site" objname="LH_foot" name="LH_foot_global_linear_velocity"/>
    <framelinvel objtype="site" objname="RH_foot" name="RH_foot_global_linear_velocity"/>
  </sensor>

  <keyframe>
    <key name="home" qpos="0 0 0.55 1 0 0 0 0 0.4 -0.8 0 -0.4 0.8 0 -0.4 0.8 0 0.4 -0.8"/>
  </keyframe>
</mujoco>
