<mujoco model="anymal_c">
  <compiler angle="radian" assetdir="assets" balanceinertia="true" inertiafromgeom="false"/>

  <option timestep="0.005" density="1.2" viscosity="2e-05"/>

  <size nkey="1"/>

  <visual>
    <quality shadowsize="8192"/>
    <map shadowclip="0.5"/>
  </visual>

  <default>
    <default class="/">
      <material specular="0" shininess="0.25"/>
      <geom contype="0" conaffinity="0" group="1" solref="-1000 -80"/>
      <site size="0.01 0.005 0.005" group="5"/>
      <general forcelimited="true" forcerange="-80 80" biastype="affine" gainprm="80" biasprm="0 -80 -2"/>
      <default class="anymal_c">
        <joint armature="0.01" damping="0.01" frictionloss="0.1"/>
        <default class="visual">
          <geom type="mesh" group="2"/>
          <default class="visual_zflip"/>
        </default>
        <default class="collision">
          <geom type="cylinder" group="3"/>
          <default class="foot">
            <geom size="0.03 0 0" type="sphere" condim="6" priority="1" friction="0.8 0.02 0.01" solimp="0.015 1 0.03"/>
          </default>
        </default>
      </default>
      <default class="reward_collision_sphere">
        <geom group="5" rgba="1 0 0 1"/>
      </default>
    </default>
  </default>

  <asset>
    <texture type="skybox" colorspace="auto" name="//unnamed_texture_0" builtin="gradient" rgb1="0.95 0.95 0.95" rgb2="0.95 0.95 0.95" width="100" height="600"/>
    <texture type="2d" colorspace="auto" name="texplane" builtin="checker" rgb1="0.345 0.575 0.748" rgb2="0.345 0.575 0.748" markrgb="1 1 1" width="512" height="512"/>
    <texture type="2d" colorspace="linear" name="base" file="base.png"/>
    <texture type="2d" colorspace="linear" name="top_shell" file="top_shell.png"/>
    <texture type="2d" colorspace="linear" name="bottom_shell" file="bottom_shell.png"/>
    <texture type="2d" colorspace="linear" name="remote" file="remote.png"/>
    <texture type="2d" colorspace="linear" name="hatch" file="hatch.png"/>
    <texture type="2d" colorspace="linear" name="handle" file="handle.png"/>
    <texture type="2d" colorspace="linear" name="face" file="face.png"/>
    <texture type="2d" colorspace="linear" name="battery" file="battery.png"/>
    <texture type="2d" colorspace="linear" name="lidar_cage" file="lidar_cage.png"/>
    <texture type="2d" colorspace="linear" name="depth_camera" file="depth_camera.png"/>
    <texture type="2d" colorspace="linear" name="wide_angle_camera" file="wide_angle_camera.png"/>
    <texture type="2d" colorspace="linear" name="lidar" file="lidar.png"/>
    <texture type="2d" colorspace="linear" name="drive" file="drive.png"/>
    <texture type="2d" colorspace="linear" name="hip_l" file="hip_l.png"/>
    <texture type="2d" colorspace="linear" name="shank_l" file="shank_l.png"/>
    <texture type="2d" colorspace="linear" name="foot" file="foot.png"/>
    <texture type="2d" colorspace="linear" name="thigh" file="thigh.png"/>
    <texture type="2d" colorspace="linear" name="shank_r" file="shank_r.png"/>
    <texture type="2d" colorspace="linear" name="hip_r" file="hip_r.png"/>
    <material name="MatPlane" class="/" texture="texplane" texuniform="true" texrepeat="2 2" specular="0.9" shininess="0.5"/>
    <material name="black_plastic" class="/" rgba="0.007 0.007 0.007 1"/>
    <material name="green" class="/" rgba="0.052 0.178 0.033 1"/>
    <material name="red" class="/" rgba="0.178 0.006 0.005 1"/>
    <material name="yellow" class="/" rgba="0.178 0.119 0.006 1"/>
    <material name="lwl" class="/" rgba="0.8 0.8 0.8 1"/>
    <material name="base" class="/" texture="base"/>
    <material name="top_shell" class="/" texture="top_shell"/>
    <material name="bottom_shell" class="/" texture="bottom_shell"/>
    <material name="hip_l" class="/" texture="hip_l"/>
    <material name="thigh" class="/" texture="thigh"/>
    <material name="shank_l" class="/" texture="shank_l"/>
    <material name="foot" class="/" texture="foot"/>
    <material name="hip_r" class="/" texture="hip_r"/>
    <material name="shank" class="/" texture="shank_r"/>
    <material name="hatch" class="/" texture="hatch"/>
    <material name="remote" class="/" texture="remote"/>
    <material name="handle" class="/" texture="handle"/>
    <material name="face" class="/" texture="face"/>
    <material name="depth_camera" class="/" texture="depth_camera"/>
    <material name="wide_angle_camera" class="/" texture="wide_angle_camera"/>
    <material name="battery" class="/" texture="battery"/>
    <material name="lidar_cage" class="/" texture="lidar_cage"/>
    <material name="lidar" class="/" texture="lidar"/>
    <material name="drive" class="/" texture="drive"/>
    <mesh name="base_0" class="/" file="base_0.obj"/>
    <mesh name="base_1" class="/" file="base_1.obj"/>
    <mesh name="base_2" class="/" file="base_2.obj"/>
    <mesh name="base_3" class="/" file="base_3.obj"/>
    <mesh name="base_4" class="/" file="base_4.obj"/>
    <mesh name="base_5" class="/" file="base_5.obj"/>
    <mesh name="top_shell" class="/" file="top_shell.obj"/>
    <mesh name="bottom_shell" class="/" file="bottom_shell.obj"/>
    <mesh name="remote" class="/" file="remote.obj"/>
    <mesh name="handle" class="/" file="handle.obj"/>
    <mesh name="face" class="/" file="face.obj"/>
    <mesh name="wide_angle_camera" class="/" file="wide_angle_camera.obj"/>
    <mesh name="depth_camera" class="/" file="depth_camera.obj"/>
    <mesh name="battery" class="/" file="battery.obj"/>
    <mesh name="lidar_cage" class="/" file="lidar_cage.obj"/>
    <mesh name="lidar" class="/" file="lidar.obj"/>
    <mesh name="drive" class="/" file="drive.obj"/>
    <mesh name="hip_l" class="/" file="hip_l.obj"/>
    <mesh name="thigh" class="/" file="thigh.obj"/>
    <mesh name="shank_l" class="/" file="shank_l.obj"/>
    <mesh name="foot" class="/" file="foot.obj"/>
    <mesh name="hip_r" class="/" file="hip_r.obj"/>
    <mesh name="hatch" class="/" file="hatch.obj"/>
    <mesh name="shank_r" class="/" file="shank_r.obj"/>
  </asset>

  <worldbody>
    <geom name="floor" class="/" size="100 100 0.125" type="plane" group="0" material="MatPlane"/>
    <light name="toplight_shadow" class="/" pos="0 0 5" dir="0.0990148 0.0990148 -0.990148" type="directional" ambient="0.04 0.04 0.04" diffuse="0.55 0.55 0.55" specular="0.12 0.12 0.12"/>
    <light name="toplight_fill" class="/" pos="0 0 5" dir="0.0990148 0.0990148 -0.990148" type="directional" castshadow="false" ambient="0.04 0.04 0.04" diffuse="0.3 0.3 0.3" specular="0.08 0.08 0.08"/>
    <body name="trunk" childclass="anymal_c" pos="0.000426631 0.000275138 -0.0023627" quat="1 -0.000126648 -8.57521e-05 5.22404e-05">
      <inertial pos="0.00148454 0.00457384 0.0420757" quat="0.498623 0.502439 0.500707 0.498219" mass="20.4244" diaginertia="0.513125 1.57546 0.126031"/>
      <joint name="//unnamed_joint_0" type="free" armature="0" damping="0" frictionloss="0"/>
      <geom name="//unnamed_geom_1" class="visual" material="green" mesh="base_0"/>
      <geom name="//unnamed_geom_2" class="visual" material="yellow" mesh="base_1"/>
      <geom name="//unnamed_geom_3" class="visual" material="red" mesh="base_2"/>
      <geom name="//unnamed_geom_4" class="visual" material="black_plastic" mesh="base_3"/>
      <geom name="//unnamed_geom_5" class="visual" material="lwl" mesh="base_4"/>
      <geom name="//unnamed_geom_6" class="visual" material="base" mesh="base_5"/>
      <geom name="trunk_1" class="collision" size="0.292194 0.0705296 0.0906809" type="box"/>
      <geom name="trunk_2" class="collision" size="0.0906809 0.0730485" pos="0.203556 0.083694 0" quat="0.707107 0 0.707107 0"/>
      <geom name="trunk_3" class="collision" size="0.0906809 0.0730485" pos="-0.203556 0.083694 0" quat="0.707107 0 0.707107 0"/>
      <geom name="trunk_4" class="collision" size="0.0906809 0.0730485" pos="0.203556 -0.083694 0" quat="0.707107 0 0.707107 0"/>
      <geom name="trunk_5" class="collision" size="0.0906809 0.0730485" pos="-0.203556 -0.083694 0" quat="0.707107 0 0.707107 0"/>
      <geom name="//unnamed_geom_12" class="visual" material="top_shell" mesh="top_shell"/>
      <geom name="//unnamed_geom_13" class="visual" material="bottom_shell" mesh="bottom_shell"/>
      <geom name="//unnamed_geom_14" class="visual" material="remote" mesh="remote"/>
      <geom name="//unnamed_geom_15" class="visual" material="handle" mesh="handle"/>
      <geom name="//unnamed_geom_16" class="visual" pos="0.387927 0 0" quat="1 0 0 0" material="face" mesh="face"/>
      <geom name="trunk_6" class="collision" size="0.0554161 0.0705296 0.0906809" pos="0.439401 0 0" type="box"/>
      <geom name="//unnamed_geom_18" class="collision" size="0.0906809 0.0554161" pos="0.439401 0.083694 0" quat="0.707107 0 0.707107 0"/>
      <geom name="//unnamed_geom_19" class="collision" size="0.0906809 0.0554161" pos="0.439401 -0.083694 0" quat="0.707107 0 0.707107 0"/>
      <geom name="//unnamed_geom_20" class="visual" pos="0.432052 0 -0.0256826" quat="0.965926 0 0.258819 0" material="depth_camera" mesh="depth_camera"/>
      <geom name="//unnamed_geom_21" class="visual" pos="0.480112 0 0.0133409" material="wide_angle_camera" mesh="wide_angle_camera"/>
      <geom name="//unnamed_geom_22" class="visual_zflip" pos="-0.387927 0 0" quat="0 0 0 1" material="face" mesh="face"/>
      <geom name="trunk_7" class="collision" size="0.0554161 0.0705296 0.0906809" pos="-0.439401 0 0" quat="0 0 0 1" type="box"/>
      <geom name="//unnamed_geom_24" class="collision" size="0.0906809 0.0554161" pos="-0.439401 -0.083694 0" quat="0 -0.707107 0 0.707107"/>
      <geom name="//unnamed_geom_25" class="collision" size="0.0906809 0.0554161" pos="-0.439401 0.083694 0" quat="0 -0.707107 0 0.707107"/>
      <geom name="//unnamed_geom_26" class="visual" pos="-0.432052 0 -0.0256826" quat="0 -0.258819 0 0.965926" material="depth_camera" mesh="depth_camera"/>
      <geom name="//unnamed_geom_27" class="visual_zflip" pos="-0.480112 0 0.0133409" quat="0 0 0 1" material="wide_angle_camera" mesh="wide_angle_camera"/>
      <geom name="//unnamed_geom_28" class="visual" material="battery" mesh="battery"/>
      <geom name="//unnamed_geom_29" class="visual" pos="0 0.0948242 0.0262285" quat="0.683013 -0.183013 0.183013 0.683013" material="depth_camera" mesh="depth_camera"/>
      <geom name="//unnamed_geom_30" class="visual" pos="0 -0.0948242 0.0262285" quat="0.683013 0.183013 0.183013 -0.683013" material="depth_camera" mesh="depth_camera"/>
      <geom name="//unnamed_geom_31" class="visual" pos="-0.340664 0 0.0655015" quat="1 0 0 0" material="lidar_cage" mesh="lidar_cage"/>
      <geom name="trunk_8" class="collision" size="0.0705296 0.0604539" pos="-0.340664 0 0.118972"/>
      <geom name="//unnamed_geom_33" class="visual" pos="-0.340664 0.000102044 0.126725" quat="0.707107 0 0 -0.707107" material="lidar" mesh="lidar"/>
      <geom name="//unnamed_geom_34" class="visual" pos="0.280674 0.124237 5.25182e-09" quat="0.258819 0.965926 0 0" material="drive" mesh="drive"/>
      <geom name="//unnamed_geom_35" class="visual" pos="0.280674 -0.124237 -5.25182e-09" quat="0.258819 -0.965926 0 0" material="drive" mesh="drive"/>
      <geom name="//unnamed_geom_36" class="visual" pos="-0.280674 0.124237 -5.25182e-09" quat="0 0 0.965926 -0.258819" material="drive" mesh="drive"/>
      <geom name="//unnamed_geom_37" class="visual" pos="-0.280674 -0.124237 5.25182e-09" quat="0 0 -0.965926 -0.258819" material="drive" mesh="drive"/>
      <geom name="//unnamed_geom_38" class="visual" pos="0.108563 0 0.0650559" quat="1 0 0 0" material="hatch" mesh="hatch"/>
      <geom name="//unnamed_geom_39" class="reward_collision_sphere" size="0.120908"/>
      <geom name="//unnamed_geom_40" class="reward_collision_sphere" size="0.120908" pos="0.421151 0 0"/>
      <geom name="//unnamed_geom_41" class="reward_collision_sphere" size="0.120908" pos="-0.421151 0 0"/>
      <site name="imu" pos="0.22435 0.0145342 0.0456922" size="0.0100757"/>
      <camera name="track" pos="0 -2.39126 0" quat="0.707107 0.707107 0 0" mode="trackcom"/>
      <camera name="ego_camera" pos="0.421151 0 -0.0356471" quat="-0.5 -0.5 0.5 0.5"/>
      <body name="LF_HIP" pos="0.283109 0.123552 -0.000732582" quat="0.259024 0.965871 -0.000548376 -0.000114076">
        <inertial pos="0.0529677 -0.0161732 -0.00795474" quat="-0.146131 0.717191 -0.115865 0.67146" mass="2.93146" diaginertia="0.00427707 0.0121622 0.00189127"/>
        <joint name="LF_HAA" pos="0 0 0" axis="0.999917 0.011915 -0.00496992" range="-0.739375 0.437201" armature="0.00990622" damping="0.0131163" frictionloss="0.104302"/>
        <geom name="//unnamed_geom_42" class="visual" pos="0 0.000308941 -5.07433e-05" quat="0.258819 -0.965926 0 0" material="hip_l" mesh="hip_l"/>
        <geom name="//unnamed_geom_43" class="visual" pos="0.0560599 -0.0712401 -0.0388786" quat="0.183013 -0.683013 0.683013 0.183013" material="drive" mesh="drive"/>
        <geom name="//unnamed_geom_44" class="collision" size="0.0503783 0.0705296" pos="0.0560599 -0.0142995 -0.00615358" quat="-0.353553 -0.612372 0.612372 -0.353553"/>
        <body name="LF_THIGH" pos="0.0542096 -0.0860242 -0.0340197" quat="0.181008 -0.682611 0.683617 0.184245">
          <inertial pos="0.0296195 -0.00493474 -0.221304" quat="0.993198 -0.0145864 -0.0796947 0.0836255" mass="3.14938" diaginertia="0.0222884 0.0683548 0.00231851"/>
          <joint name="LF_HFE" pos="0 0 0" axis="0.999997 -0.00191536 0.0012069" stiffness="0.00624682" range="-3.13246 3.21251" armature="0.00780775" damping="0.0226167" frictionloss="0.0970727"/>
          <geom name="//unnamed_geom_45" class="visual" pos="-0.00516776 -8.14318e-06 0" quat="0.707107 0 0 -0.707107" material="thigh" mesh="thigh"/>
          <geom name="//unnamed_geom_46" class="collision" size="0.0654918 0.0403026" pos="0.0374356 0 0" quat="0.5 0.5 -0.5 -0.5"/>
          <geom name="//unnamed_geom_47" class="collision" size="0.0377837 0.030227 0.142383" pos="0.0280767 0 -0.125936" quat="0.707107 0 0 -0.707107" type="box"/>
          <geom name="//unnamed_geom_48" class="visual" pos="0.0938699 0 -0.253986" quat="1 0 0 0" material="drive" mesh="drive"/>
          <geom name="//unnamed_geom_49" class="collision" size="0.0503783 0.0705296" pos="0.0283575 0 -0.253986" quat="0.707107 0 0.707107 0"/>
          <geom name="//unnamed_geom_50" class="reward_collision_sphere" size="0.0806053" pos="0.0233973 0 0"/>
          <body name="LF_SHANK" pos="0.0956837 0.0010614 -0.258284" quat="1 0.000368795 -0.000405553 -0.000735163">
            <inertial pos="0.00805236 -0.0733213 -0.0701162" quat="0.991633 -0.126384 0.000414948 -0.0262982" mass="0.617857" diaginertia="0.00729459 0.0215317 0.00061511"/>
            <joint name="LF_KFE" pos="0 0 0" axis="0.99999 -0.00391844 0.0019976" range="-3.24054 3.10739" armature="0.00964625" damping="0.0187971" frictionloss="0.112251"/>
            <geom name="//unnamed_geom_51" class="visual" pos="-0.00168509 -0.00898501 0" quat="0.707107 0 0 -0.707107" material="shank_l" mesh="shank_l"/>
            <geom name="LF_kfe_act" class="collision" size="0.0604539 0.0201513" pos="0.0187178 0 0" quat="0.5 0.5 -0.5 -0.5"/>
            <geom name="//unnamed_geom_53" class="collision" size="0.057934 0.0340053 0.0191437" pos="0.0187178 -0.0687475 0" quat="0.5 0.5 -0.5 -0.5" type="box"/>
            <geom name="//unnamed_geom_54" class="visual" pos="0.0122138 -0.108051 -0.301191" quat="0.382683 0 0 -0.92388" material="foot" mesh="foot"/>
            <geom name="LF_calf" class="collision" size="0.0176324 0.142321" pos="0.0122134 -0.105156 -0.150596" quat="0.707107 0 0 -0.707107"/>
            <geom name="LF_foot" class="foot" size="0.0311053" pos="0.0122134 -0.105156 -0.28114" quat="0.707107 0 0 -0.707107"/>
            <geom name="//unnamed_geom_57" class="reward_collision_sphere" size="0.100757" pos="-0.0467945 0 0"/>
            <geom name="//unnamed_geom_58" class="reward_collision_sphere" size="0.0503783" pos="0.0122134 -0.105156 -0.28114"/>
            <site name="LF_foot" class="foot" pos="0.0122134 -0.105156 -0.28114" quat="0.707107 0 0 -0.707107" size="0.0100757"/>
          </body>
        </body>
      </body>
      <body name="RF_HIP" pos="0.285562 -0.125508 0.00848876" quat="0.259345 -0.965784 -0.000613266 -0.000924911">
        <inertial pos="0.0510718 0.0206164 -0.00892093" quat="0.131024 0.684344 0.140894 0.703317" mass="2.7613" diaginertia="0.00422598 0.0119999 0.00189271"/>
        <joint name="RF_HAA" pos="0 0 0" axis="0.99999 3.054e-05 -0.00439827" stiffness="0.0260727" range="-0.465044 0.670891" armature="0.00929681" damping="0.0191462" frictionloss="0.113129"/>
        <geom name="//unnamed_geom_59" class="visual" pos="0 -0.000308938 -5.07431e-05" quat="0.258819 0.965926 0 0" material="hip_r" mesh="hip_r"/>
        <geom name="//unnamed_geom_60" class="visual" pos="0.0560599 0.0712401 -0.0388786" quat="0.183013 0.683013 0.683013 -0.183013" material="drive" mesh="drive"/>
        <geom name="//unnamed_geom_61" class="collision" size="0.0503783 0.0705296" pos="0.0560599 0.0142995 -0.00615358" quat="-0.353553 0.612372 0.612372 0.353553"/>
        <body name="RF_THIGH" pos="0.0543686 0.0812049 -0.0338512" quat="0.182946 0.682688 0.683297 -0.18323">
          <inertial pos="0.0300521 1.2661e-05 -0.222527" quat="0.993039 -0.0118391 -0.0844883 0.0812047" mass="3.25254" diaginertia="0.0219062 0.0734923 0.0023669"/>
          <joint name="RF_HFE" pos="0 0 0" axis="0.999938 -0.00478885 -0.0100377" range="-3.14311 3.18305" armature="0.0114873" damping="0" frictionloss="0.0998152"/>
          <geom name="//unnamed_geom_62" class="visual" pos="-0.00516776 -8.14318e-06 0" quat="0.707107 0 0 -0.707107" material="thigh" mesh="thigh"/>
          <geom name="//unnamed_geom_63" class="collision" size="0.0654918 0.0403026" pos="0.0374356 0 0" quat="0.5 0.5 0.5 0.5"/>
          <geom name="//unnamed_geom_64" class="collision" size="0.0377837 0.030227 0.142383" pos="0.0280767 0 -0.125936" quat="0.707107 0 0 0.707107" type="box"/>
          <geom name="//unnamed_geom_65" class="visual" pos="0.0938699 0 -0.253986" quat="1 0 0 0" material="drive" mesh="drive"/>
          <geom name="//unnamed_geom_66" class="collision" size="0.0503783 0.0705296" pos="0.0283575 0 -0.253986" quat="0.707107 0 0.707107 0"/>
          <geom name="//unnamed_geom_67" class="reward_collision_sphere" size="0.0806053" pos="0.0233973 0 0"/>
          <body name="RF_SHANK" pos="0.0898474 -0.00112211 -0.257632" quat="0.999999 0.00111663 0.000407118 0.00031153">
            <inertial pos="0.00498722 0.0730715 -0.0709565" quat="0.992917 0.115695 0.00779126 0.0258797" mass="0.563615" diaginertia="0.00668511 0.021023 0.00058845"/>
            <joint name="RF_KFE" pos="0 0 0" axis="0.999987 0.00273472 0.00421369" range="-3.08983 3.18664" armature="0.00903496" damping="0.0269515" frictionloss="0.0901994"/>
            <geom name="//unnamed_geom_68" class="visual" pos="-0.00168508 0.00898499 0" quat="0.707107 0 0 0.707107" material="shank" mesh="shank_r"/>
            <geom name="RF_kfe_act" class="collision" size="0.0604539 0.0201513" pos="0.0187178 0 0" quat="0.5 0.5 0.5 0.5"/>
            <geom name="//unnamed_geom_70" class="collision" size="0.057934 0.0340053 0.0191437" pos="0.0187178 0.0687475 0" quat="0.5 0.5 0.5 0.5" type="box"/>
            <geom name="//unnamed_geom_71" class="visual" pos="0.012213 0.108051 -0.301191" quat="0.382683 0 0 0.92388" material="foot" mesh="foot"/>
            <geom name="RF_calf" class="collision" size="0.0176324 0.142321" pos="0.0122134 0.105156 -0.150596" quat="0.707107 0 0 0.707107"/>
            <geom name="RF_foot" class="foot" size="0.0359299" pos="0.0122134 0.105156 -0.28114" quat="0.707107 0 0 0.707107"/>
            <geom name="//unnamed_geom_74" class="reward_collision_sphere" size="0.100757" pos="-0.0467945 0 0"/>
            <geom name="//unnamed_geom_75" class="reward_collision_sphere" size="0.0503783" pos="0.0122134 0.105156 -0.28114"/>
            <site name="RF_foot" class="foot" pos="0.0122134 0.105156 -0.28114" quat="0.707107 0 0 0.707107" size="0.0100757"/>
          </body>
        </body>
      </body>
      <body name="LH_HIP" pos="-0.280256 0.125849 -0.000325648" quat="-0.000396485 8.71848e-05 0.965708 -0.25963">
        <inertial pos="0.0556296 0.015416 -0.00718629" quat="0.126867 0.67298 0.129267 0.717142" mass="2.95385" diaginertia="0.00397701 0.0115477 0.00181892"/>
        <joint name="LH_HAA" pos="0 0 0" axis="0.999968 0.00799951 0.000486836" range="-0.537316 0.678838" armature="0.00881279" damping="0.00525824" frictionloss="0.0939374"/>
        <geom name="//unnamed_geom_76" class="visual" pos="0 -0.000308938 -5.07431e-05" quat="-0.258819 -0.965926 0 0" material="hip_r" mesh="hip_r"/>
        <geom name="//unnamed_geom_77" class="visual" pos="0.0560599 0.0712401 -0.0388786" quat="0.183013 0.683013 0.683013 -0.183013" material="drive" mesh="drive"/>
        <geom name="//unnamed_geom_78" class="collision" size="0.0503783 0.0705296" pos="0.0560599 0.0142995 -0.00615358" quat="-0.353553 0.612372 0.612372 0.353553"/>
        <body name="LH_THIGH" pos="0.0554657 0.085011 -0.0373875" quat="0.183743 0.683544 0.682711 -0.181414">
          <inertial pos="0.0293421 -0.00561932 -0.216594" quat="0.992288 -0.00109427 -0.0856588 0.0895905" mass="3.31048" diaginertia="0.0214581 0.0734896 0.00226225"/>
          <joint name="LH_HFE" pos="0 0 0" axis="0.999662 0.018073 -0.0186924" range="-3.18542 3.12777" armature="0.010026" damping="0.000324341" frictionloss="0.0972005"/>
          <geom name="//unnamed_geom_79" class="visual" pos="-0.00516776 -8.14318e-06 0" quat="0.707107 0 0 -0.707107" material="thigh" mesh="thigh"/>
          <geom name="//unnamed_geom_80" class="collision" size="0.0654918 0.0403026" pos="0.0374356 0 0" quat="0.5 0.5 -0.5 -0.5"/>
          <geom name="//unnamed_geom_81" class="collision" size="0.0377837 0.030227 0.142383" pos="0.0280767 0 -0.125936" quat="0.707107 0 0 -0.707107" type="box"/>
          <geom name="//unnamed_geom_82" class="visual" pos="0.0938699 0 -0.253986" quat="1 0 0 0" material="drive" mesh="drive"/>
          <geom name="//unnamed_geom_83" class="collision" size="0.0503783 0.0705296" pos="0.0283575 0 -0.253986" quat="0.707107 0 0.707107 0"/>
          <geom name="//unnamed_geom_84" class="reward_collision_sphere" size="0.0806053" pos="0.0233973 0 0"/>
          <body name="LH_SHANK" pos="0.092673 -0.00365154 -0.254063" quat="1 5.68286e-05 0.000272802 0.000378149">
            <inertial pos="0.00443837 0.0711373 -0.073485" quat="0.993338 0.113201 -0.00334481 0.0212918" mass="0.600771" diaginertia="0.00757993 0.0235031 0.000659172"/>
            <joint name="LH_KFE" pos="0 0 0" axis="0.999996 0.00101242 -0.00259836" range="-3.23255 3.12286" armature="0.00754068" damping="0.00327446" frictionloss="0.100847"/>
            <geom name="//unnamed_geom_85" class="visual" pos="-0.00168508 0.00898499 0" quat="-0.707107 0 0 -0.707107" material="shank" mesh="shank_r"/>
            <geom name="LH_kfe_act" class="collision" size="0.0604539 0.0201513" pos="0.0187178 0 0" quat="0.5 0.5 -0.5 -0.5"/>
            <geom name="//unnamed_geom_87" class="collision" size="0.057934 0.0340053 0.0191437" pos="0.0187178 0.0687475 0" quat="0.5 0.5 -0.5 -0.5" type="box"/>
            <geom name="//unnamed_geom_88" class="visual" pos="0.012213 0.108051 -0.301191" quat="-0.382683 0 0 -0.92388" material="foot" mesh="foot"/>
            <geom name="LH_calf" class="collision" size="0.0176324 0.142321" pos="0.0122134 0.105156 -0.150596" quat="0.707107 0 0 -0.707107"/>
            <geom name="LH_foot" class="foot" size="0.0340407" pos="0.0122134 0.105156 -0.28114" quat="0.707107 0 0 -0.707107"/>
            <geom name="//unnamed_geom_91" class="reward_collision_sphere" size="0.100757" pos="-0.0467945 0 0"/>
            <geom name="//unnamed_geom_92" class="reward_collision_sphere" size="0.0503783" pos="0.0122134 0.105156 -0.28114"/>
            <site name="LH_foot" class="foot" pos="0.0122134 0.105156 -0.28114" quat="0.707107 0 0 -0.707107" size="0.0100757"/>
          </body>
        </body>
      </body>
      <body name="RH_HIP" pos="-0.276004 -0.125623 0.000320266" quat="0.00225357 0.00133135 -0.965734 -0.25952">
        <inertial pos="0.0539049 -0.0207207 -0.00999358" quat="-0.130114 0.71126 -0.135544 0.677353" mass="2.80145" diaginertia="0.00416313 0.0121898 0.00169428"/>
        <joint name="RH_HAA" pos="0 0 0" axis="0.999957 -0.00194751 -0.00903944" range="-0.775055 0.482564" armature="0.00828338" damping="0.00560016" frictionloss="0.102059"/>
        <geom name="//unnamed_geom_93" class="visual" pos="0 0.000308941 -5.07433e-05" quat="-0.258819 0.965926 0 0" material="hip_l" mesh="hip_l"/>
        <geom name="//unnamed_geom_94" class="visual" pos="0.0560599 -0.0712401 -0.0388786" quat="-0.183013 0.683013 -0.683013 -0.183013" material="drive" mesh="drive"/>
        <geom name="//unnamed_geom_95" class="collision" size="0.0503783 0.0705296" pos="0.0560599 -0.0142995 -0.00615358" quat="0.353553 0.612372 -0.612372 0.353553"/>
        <body name="RH_THIGH" pos="0.0564331 -0.0884914 -0.038994" quat="-0.183576 0.68238 -0.683466 -0.183116">
          <inertial pos="0.0282279 0.00117039 -0.219885" quat="0.992119 -0.00945669 -0.0909477 0.0856622" mass="3.33706" diaginertia="0.0218966 0.0730721 0.00243098"/>
          <joint name="RH_HFE" pos="0 0 0" axis="0.999994 -0.00349835 -0.000437249" range="-3.11919 3.03713" armature="0.0124166" damping="0" frictionloss="0.0947105"/>
          <geom name="//unnamed_geom_96" class="visual" pos="-0.00516776 -8.14318e-06 0" quat="0.707107 0 0 -0.707107" material="thigh" mesh="thigh"/>
          <geom name="//unnamed_geom_97" class="collision" size="0.0654918 0.0403026" pos="0.0374356 0 0" quat="0.5 0.5 0.5 0.5"/>
          <geom name="//unnamed_geom_98" class="collision" size="0.0377837 0.030227 0.142383" pos="0.0280767 0 -0.125936" quat="0.707107 0 0 0.707107" type="box"/>
          <geom name="//unnamed_geom_99" class="visual" pos="0.0938699 0 -0.253986" quat="1 0 0 0" material="drive" mesh="drive"/>
          <geom name="//unnamed_geom_100" class="collision" size="0.0503783 0.0705296" pos="0.0283575 0 -0.253986" quat="0.707107 0 0.707107 0"/>
          <geom name="//unnamed_geom_101" class="reward_collision_sphere" size="0.0806053" pos="0.0233973 0 0"/>
          <body name="RH_SHANK" pos="0.0945623 -0.000291331 -0.253001" quat="1 -0.00010114 0.000399108 -0.000405872">
            <inertial pos="0.00452379 -0.0704908 -0.0709653" quat="0.992905 -0.115991 -0.00116189 -0.0261478" mass="0.597732" diaginertia="0.00749334 0.0228504 0.000614096"/>
            <joint name="RH_KFE" pos="0 0 0" axis="0.99998 0.00621455 0.00115541" stiffness="0.0095384" range="-3.19707 3.16253" armature="0.00936216" damping="0" frictionloss="0.104766"/>
            <geom name="//unnamed_geom_102" class="visual" pos="-0.00168509 -0.00898501 0" quat="0.707107 0 0 -0.707107" material="shank_l" mesh="shank_l"/>
            <geom name="RH_kfe_act" class="collision" size="0.0604539 0.0201513" pos="0.0187178 0 0" quat="0.5 0.5 0.5 0.5"/>
            <geom name="//unnamed_geom_104" class="collision" size="0.057934 0.0340053 0.0191437" pos="0.0187178 -0.0687475 0" quat="0.5 0.5 0.5 0.5" type="box"/>
            <geom name="//unnamed_geom_105" class="visual" pos="0.0122138 -0.108051 -0.301191" quat="0.382683 0 0 -0.92388" material="foot" mesh="foot"/>
            <geom name="RH_calf" class="collision" size="0.0176324 0.142321" pos="0.0122134 -0.105156 -0.150596" quat="0.707107 0 0 0.707107"/>
            <geom name="RH_foot" class="foot" size="0.023976" pos="0.0122134 -0.105156 -0.28114" quat="0.707107 0 0 0.707107"/>
            <geom name="//unnamed_geom_108" class="reward_collision_sphere" size="0.100757" pos="-0.0467945 0 0"/>
            <geom name="//unnamed_geom_109" class="reward_collision_sphere" size="0.0503783" pos="0.0122134 -0.105156 -0.28114"/>
            <site name="RH_foot" class="foot" pos="0.0122134 -0.105156 -0.28114" quat="0.707107 0 0 0.707107" size="0.0100757"/>
          </body>
        </body>
      </body>
    </body>
  </worldbody>

  <contact>
    <pair class="/" geom1="floor" geom2="LF_foot" name="//unnamed_contact_0"/>
    <pair class="/" geom1="floor" geom2="RF_foot" name="//unnamed_contact_1"/>
    <pair class="/" geom1="floor" geom2="LH_foot" name="//unnamed_contact_2"/>
    <pair class="/" geom1="floor" geom2="RH_foot" name="//unnamed_contact_3"/>
  </contact>

  <actuator>
    <general name="LF_HAA" class="/" joint="LF_HAA" forcerange="-85.3318 85.3318" gainprm="81.7658" biasprm="0 -81.7658 -2.29989"/>
    <general name="LF_HFE" class="/" joint="LF_HFE" forcerange="-80.7603 80.7603" gainprm="81.7658" biasprm="0 -81.7658 -2.29989"/>
    <general name="LF_KFE" class="/" joint="LF_KFE" forcerange="-85.1362 85.1362" gainprm="81.7658" biasprm="0 -81.7658 -2.29989"/>
    <general name="RF_HAA" class="/" joint="RF_HAA" forcerange="-77.2052 77.2052" gainprm="81.7658" biasprm="0 -81.7658 -2.29989"/>
    <general name="RF_HFE" class="/" joint="RF_HFE" forcerange="-84.491 84.491" gainprm="81.7658" biasprm="0 -81.7658 -2.29989"/>
    <general name="RF_KFE" class="/" joint="RF_KFE" forcerange="-83.6441 83.6441" gainprm="81.7658" biasprm="0 -81.7658 -2.29989"/>
    <general name="LH_HAA" class="/" joint="LH_HAA" forcerange="-74.4509 74.4509" gainprm="81.7658" biasprm="0 -81.7658 -2.29989"/>
    <general name="LH_HFE" class="/" joint="LH_HFE" forcerange="-82.5795 82.5795" gainprm="81.7658" biasprm="0 -81.7658 -2.29989"/>
    <general name="LH_KFE" class="/" joint="LH_KFE" forcerange="-89.3176 89.3176" gainprm="81.7658" biasprm="0 -81.7658 -2.29989"/>
    <general name="RH_HAA" class="/" joint="RH_HAA" forcerange="-76.8464 76.8464" gainprm="81.7658" biasprm="0 -81.7658 -2.29989"/>
    <general name="RH_HFE" class="/" joint="RH_HFE" forcerange="-87.4007 87.4007" gainprm="81.7658" biasprm="0 -81.7658 -2.29989"/>
    <general name="RH_KFE" class="/" joint="RH_KFE" forcerange="-71.2703 71.2703" gainprm="81.7658" biasprm="0 -81.7658 -2.29989"/>
  </actuator>

  <sensor>
    <gyro site="imu" name="imu_angular_velocity"/>
    <velocimeter site="imu" name="imu_linear_velocity"/>
    <framelinvel objtype="site" objname="LF_foot" name="LF_foot_global_linear_velocity"/>
    <framelinvel objtype="site" objname="RF_foot" name="RF_foot_global_linear_velocity"/>
    <framelinvel objtype="site" objname="LH_foot" name="LH_foot_global_linear_velocity"/>
    <framelinvel objtype="site" objname="RH_foot" name="RH_foot_global_linear_velocity"/>
  </sensor>

  <keyframe>
    <key name="home" qpos="0 0 0.55 1 0 0 0 0 0.4 -0.8 0 -0.4 0.8 0 -0.4 0.8 0 0.4 -0.8"/>
  </keyframe>
</mujoco>
