<mujoco model="anymal_c">
  <compiler angle="radian" assetdir="assets" balanceinertia="true" inertiafromgeom="false"/>

  <option timestep="0.005" density="1.2" viscosity="2e-05"/>

  <size nkey="1"/>

  <visual>
    <quality shadowsize="8192"/>
    <map shadowclip="0.5"/>
  </visual>

  <default>
    <default class="/">
      <material specular="0" shininess="0.25"/>
      <geom contype="0" conaffinity="0" group="1" solref="-1000 -80"/>
      <site size="0.01 0.005 0.005" group="5"/>
      <general forcelimited="true" forcerange="-80 80" biastype="affine" gainprm="80" biasprm="0 -80 -2"/>
      <default class="anymal_c">
        <joint armature="0.01" damping="0.01" frictionloss="0.1"/>
        <default class="visual">
          <geom type="mesh" group="2"/>
          <default class="visual_zflip"/>
        </default>
        <default class="collision">
          <geom type="cylinder" group="3"/>
          <default class="foot">
            <geom size="0.03 0 0" type="sphere" condim="6" priority="1" friction="0.8 0.02 0.01" solimp="0.015 1 0.03"/>
          </default>
        </default>
      </default>
      <default class="reward_collision_sphere">
        <geom group="5" rgba="1 0 0 1"/>
      </default>
    </default>
  </default>

  <asset>
    <texture type="skybox" colorspace="auto" name="//unnamed_texture_0" builtin="gradient" rgb1="0.95 0.95 0.95" rgb2="0.95 0.95 0.95" width="100" height="600"/>
    <texture type="2d" colorspace="auto" name="texplane" builtin="checker" rgb1="0.345 0.575 0.748" rgb2="0.345 0.575 0.748" markrgb="1 1 1" width="512" height="512"/>
    <texture type="2d" colorspace="linear" name="base" file="base.png"/>
    <texture type="2d" colorspace="linear" name="top_shell" file="top_shell.png"/>
    <texture type="2d" colorspace="linear" name="bottom_shell" file="bottom_shell.png"/>
    <texture type="2d" colorspace="linear" name="remote" file="remote.png"/>
    <texture type="2d" colorspace="linear" name="hatch" file="hatch.png"/>
    <texture type="2d" colorspace="linear" name="handle" file="handle.png"/>
    <texture type="2d" colorspace="linear" name="face" file="face.png"/>
    <texture type="2d" colorspace="linear" name="battery" file="battery.png"/>
    <texture type="2d" colorspace="linear" name="lidar_cage" file="lidar_cage.png"/>
    <texture type="2d" colorspace="linear" name="depth_camera" file="depth_camera.png"/>
    <texture type="2d" colorspace="linear" name="wide_angle_camera" file="wide_angle_camera.png"/>
    <texture type="2d" colorspace="linear" name="lidar" file="lidar.png"/>
    <texture type="2d" colorspace="linear" name="drive" file="drive.png"/>
    <texture type="2d" colorspace="linear" name="hip_l" file="hip_l.png"/>
    <texture type="2d" colorspace="linear" name="shank_l" file="shank_l.png"/>
    <texture type="2d" colorspace="linear" name="foot" file="foot.png"/>
    <texture type="2d" colorspace="linear" name="thigh" file="thigh.png"/>
    <texture type="2d" colorspace="linear" name="shank_r" file="shank_r.png"/>
    <texture type="2d" colorspace="linear" name="hip_r" file="hip_r.png"/>
    <material name="MatPlane" class="/" texture="texplane" texuniform="true" texrepeat="2 2" specular="0.9" shininess="0.5"/>
    <material name="black_plastic" class="/" rgba="0.007 0.007 0.007 1"/>
    <material name="green" class="/" rgba="0.052 0.178 0.033 1"/>
    <material name="red" class="/" rgba="0.178 0.006 0.005 1"/>
    <material name="yellow" class="/" rgba="0.178 0.119 0.006 1"/>
    <material name="lwl" class="/" rgba="0.8 0.8 0.8 1"/>
    <material name="base" class="/" texture="base"/>
    <material name="top_shell" class="/" texture="top_shell"/>
    <material name="bottom_shell" class="/" texture="bottom_shell"/>
    <material name="hip_l" class="/" texture="hip_l"/>
    <material name="thigh" class="/" texture="thigh"/>
    <material name="shank_l" class="/" texture="shank_l"/>
    <material name="foot" class="/" texture="foot"/>
    <material name="hip_r" class="/" texture="hip_r"/>
    <material name="shank" class="/" texture="shank_r"/>
    <material name="hatch" class="/" texture="hatch"/>
    <material name="remote" class="/" texture="remote"/>
    <material name="handle" class="/" texture="handle"/>
    <material name="face" class="/" texture="face"/>
    <material name="depth_camera" class="/" texture="depth_camera"/>
    <material name="wide_angle_camera" class="/" texture="wide_angle_camera"/>
    <material name="battery" class="/" texture="battery"/>
    <material name="lidar_cage" class="/" texture="lidar_cage"/>
    <material name="lidar" class="/" texture="lidar"/>
    <material name="drive" class="/" texture="drive"/>
    <mesh name="base_0" class="/" file="base_0.obj"/>
    <mesh name="base_1" class="/" file="base_1.obj"/>
    <mesh name="base_2" class="/" file="base_2.obj"/>
    <mesh name="base_3" class="/" file="base_3.obj"/>
    <mesh name="base_4" class="/" file="base_4.obj"/>
    <mesh name="base_5" class="/" file="base_5.obj"/>
    <mesh name="top_shell" class="/" file="top_shell.obj"/>
    <mesh name="bottom_shell" class="/" file="bottom_shell.obj"/>
    <mesh name="remote" class="/" file="remote.obj"/>
    <mesh name="handle" class="/" file="handle.obj"/>
    <mesh name="face" class="/" file="face.obj"/>
    <mesh name="wide_angle_camera" class="/" file="wide_angle_camera.obj"/>
    <mesh name="depth_camera" class="/" file="depth_camera.obj"/>
    <mesh name="battery" class="/" file="battery.obj"/>
    <mesh name="lidar_cage" class="/" file="lidar_cage.obj"/>
    <mesh name="lidar" class="/" file="lidar.obj"/>
    <mesh name="drive" class="/" file="drive.obj"/>
    <mesh name="hip_l" class="/" file="hip_l.obj"/>
    <mesh name="thigh" class="/" file="thigh.obj"/>
    <mesh name="shank_l" class="/" file="shank_l.obj"/>
    <mesh name="foot" class="/" file="foot.obj"/>
    <mesh name="hip_r" class="/" file="hip_r.obj"/>
    <mesh name="hatch" class="/" file="hatch.obj"/>
    <mesh name="shank_r" class="/" file="shank_r.obj"/>
  </asset>

  <worldbody>
    <geom name="floor" class="/" size="100 100 0.125" type="plane" group="0" material="MatPlane"/>
    <light name="toplight_shadow" class="/" pos="0 0 5" dir="0.0990148 0.0990148 -0.990148" type="directional" ambient="0.04 0.04 0.04" diffuse="0.55 0.55 0.55" specular="0.12 0.12 0.12"/>
    <light name="toplight_fill" class="/" pos="0 0 5" dir="0.0990148 0.0990148 -0.990148" type="directional" castshadow="false" ambient="0.04 0.04 0.04" diffuse="0.3 0.3 0.3" specular="0.08 0.08 0.08"/>
    <body name="trunk" childclass="anymal_c" pos="0.000317284 1.33846e-05 0.000836756" quat="1 1.51486e-06 -6.89407e-06 -3.71602e-06">
      <inertial pos="0.00281288 -0.00217402 0.0514603" quat="0.497831 0.501688 0.500632 0.499842" mass="17.8162" diaginertia="0.59982 0.362527 0.276038"/>
      <joint name="//unnamed_joint_0" type="free" armature="0" damping="0" frictionloss="0"/>
      <geom name="//unnamed_geom_1" class="visual" material="green" mesh="base_0"/>
      <geom name="//unnamed_geom_2" class="visual" material="yellow" mesh="base_1"/>
      <geom name="//unnamed_geom_3" class="visual" material="red" mesh="base_2"/>
      <geom name="//unnamed_geom_4" class="visual" material="black_plastic" mesh="base_3"/>
      <geom name="//unnamed_geom_5" class="visual" material="lwl" mesh="base_4"/>
      <geom name="//unnamed_geom_6" class="visual" material="base" mesh="base_5"/>
      <geom name="trunk_1" class="collision" size="0.285674 0.0689557 0.0886574" type="box"/>
      <geom name="trunk_2" class="collision" size="0.0886574 0.0714184" pos="0.217109 0.0632938 0" quat="0.707107 0 0.707107 0"/>
      <geom name="trunk_3" class="collision" size="0.0886574 0.0714184" pos="-0.217109 0.0632938 0" quat="0.707107 0 0.707107 0"/>
      <geom name="trunk_4" class="collision" size="0.0886574 0.0714184" pos="0.217109 -0.0632938 0" quat="0.707107 0 0.707107 0"/>
      <geom name="trunk_5" class="collision" size="0.0886574 0.0714184" pos="-0.217109 -0.0632938 0" quat="0.707107 0 0.707107 0"/>
      <geom name="//unnamed_geom_12" class="visual" material="top_shell" mesh="top_shell"/>
      <geom name="//unnamed_geom_13" class="visual" material="bottom_shell" mesh="bottom_shell"/>
      <geom name="//unnamed_geom_14" class="visual" material="remote" mesh="remote"/>
      <geom name="//unnamed_geom_15" class="visual" material="handle" mesh="handle"/>
      <geom name="//unnamed_geom_16" class="visual" pos="0.413755 0 0" quat="1 0 0 0" material="face" mesh="face"/>
      <geom name="trunk_6" class="collision" size="0.0541795 0.0689557 0.0886574" pos="0.468656 0 0" type="box"/>
      <geom name="//unnamed_geom_18" class="collision" size="0.0886574 0.0541795" pos="0.468656 0.0632938 0" quat="0.707107 0 0.707107 0"/>
      <geom name="//unnamed_geom_19" class="collision" size="0.0886574 0.0541795" pos="0.468656 -0.0632938 0" quat="0.707107 0 0.707107 0"/>
      <geom name="//unnamed_geom_20" class="visual" pos="0.460823 0 -0.0311584" quat="0.965926 0 0.258819 0" material="depth_camera" mesh="depth_camera"/>
      <geom name="//unnamed_geom_21" class="visual" pos="0.512078 0 0.0157611" material="wide_angle_camera" mesh="wide_angle_camera"/>
      <geom name="//unnamed_geom_22" class="visual_zflip" pos="-0.413755 0 0" quat="0 0 0 1" material="face" mesh="face"/>
      <geom name="trunk_7" class="collision" size="0.0541795 0.0689557 0.0886574" pos="-0.468656 0 0" quat="0 0 0 1" type="box"/>
      <geom name="//unnamed_geom_24" class="collision" size="0.0886574 0.0541795" pos="-0.468656 -0.0632938 0" quat="0 -0.707107 0 0.707107"/>
      <geom name="//unnamed_geom_25" class="collision" size="0.0886574 0.0541795" pos="-0.468656 0.0632938 0" quat="0 -0.707107 0 0.707107"/>
      <geom name="//unnamed_geom_26" class="visual" pos="-0.460823 0 -0.0311584" quat="0 -0.258819 0 0.965926" material="depth_camera" mesh="depth_camera"/>
      <geom name="//unnamed_geom_27" class="visual_zflip" pos="-0.512078 0 0.0157611" quat="0 0 0 1" material="wide_angle_camera" mesh="wide_angle_camera"/>
      <geom name="//unnamed_geom_28" class="visual" material="battery" mesh="battery"/>
      <geom name="//unnamed_geom_29" class="visual" pos="0 0.0679036 0.0301699" quat="0.683013 -0.183013 0.183013 0.683013" material="depth_camera" mesh="depth_camera"/>
      <geom name="//unnamed_geom_30" class="visual" pos="0 -0.0679036 0.0301699" quat="0.683013 0.183013 0.183013 -0.683013" material="depth_camera" mesh="depth_camera"/>
      <geom name="//unnamed_geom_31" class="visual" pos="-0.363346 0 0.0773841" quat="1 0 0 0" material="lidar_cage" mesh="lidar_cage"/>
      <geom name="trunk_8" class="collision" size="0.0689557 0.0591049" pos="-0.363346 0 0.140555"/>
      <geom name="//unnamed_geom_33" class="visual" pos="-0.363346 -3.69322e-05 0.149715" quat="0.707107 0 0 -0.707107" material="lidar" mesh="lidar"/>
      <geom name="//unnamed_geom_34" class="visual" pos="0.299361 0.0940893 -2.5642e-09" quat="0.258819 0.965926 0 0" material="drive" mesh="drive"/>
      <geom name="//unnamed_geom_35" class="visual" pos="0.299361 -0.0940893 2.5642e-09" quat="0.258819 -0.965926 0 0" material="drive" mesh="drive"/>
      <geom name="//unnamed_geom_36" class="visual" pos="-0.299361 0.0940893 2.5642e-09" quat="0 0 0.965926 -0.258819" material="drive" mesh="drive"/>
      <geom name="//unnamed_geom_37" class="visual" pos="-0.299361 -0.0940893 -2.5642e-09" quat="0 0 -0.965926 -0.258819" material="drive" mesh="drive"/>
      <geom name="//unnamed_geom_38" class="visual" pos="0.115792 0 0.0768577" quat="1 0 0 0" material="hatch" mesh="hatch"/>
      <geom name="//unnamed_geom_39" class="reward_collision_sphere" size="0.11821"/>
      <geom name="//unnamed_geom_40" class="reward_collision_sphere" size="0.11821" pos="0.449191 0 0"/>
      <geom name="//unnamed_geom_41" class="reward_collision_sphere" size="0.11821" pos="-0.449191 0 0"/>
      <site name="imu" pos="0.245656 0.00865625 0.0497705" size="0.00985082"/>
      <camera name="track" pos="0 -1.80839 0" quat="0.707107 0.707107 0 0" mode="trackcom"/>
      <camera name="ego_camera" pos="0.449191 0 -0.0421138" quat="-0.5 -0.5 0.5 0.5"/>
      <body name="LF_HIP" pos="0.300406 0.0944775 -0.000496035" quat="0.25895 0.965891 -0.000147246 -5.93108e-05">
        <inertial pos="0.0566531 -0.0144107 -0.00839472" quat="-0.121228 0.705112 -0.141934 0.684088" mass="2.6445" diaginertia="0.00577245 0.00300273 0.00424679"/>
        <joint name="LF_HAA" pos="0 0 0" axis="0.999995 -0.00251464 -0.00200917" range="-0.703535 0.488936" armature="0.00970961" damping="0.0108782" frictionloss="0.0992165"/>
        <geom name="//unnamed_geom_42" class="visual" pos="0 -0.00015084 2.47753e-05" quat="0.258819 -0.965926 0 0" material="hip_l" mesh="hip_l"/>
        <geom name="//unnamed_geom_43" class="visual" pos="0.0597923 -0.0712662 -0.0422451" quat="0.183013 -0.683013 0.683013 0.183013" material="drive" mesh="drive"/>
        <geom name="//unnamed_geom_44" class="collision" size="0.0492541 0.0689557" pos="0.0597923 -0.010814 -0.0072699" quat="-0.353553 -0.612372 0.612372 -0.353553"/>
        <body name="LF_THIGH" pos="0.0611696 -0.0669689 -0.045582" quat="0.183768 -0.683417 0.682405 0.183017">
          <inertial pos="0.0312218 0.00226499 -0.258873" quat="0.992882 -0.00813678 -0.0796657 0.0881665" mass="2.90433" diaginertia="0.029404 0.0184961 0.00540015"/>
          <joint name="LF_HFE" pos="0 0 0" axis="0.999997 0.00227836 0.000130076" range="-3.1476 3.10294" armature="0.01091" damping="0.0110838" frictionloss="0.10157"/>
          <geom name="//unnamed_geom_45" class="visual" pos="0.00187034 2.94721e-06 0" quat="0.707107 0 0 -0.707107" material="thigh" mesh="thigh"/>
          <geom name="//unnamed_geom_46" class="collision" size="0.0640303 0.0394033" pos="0.0399281 0 0" quat="0.5 0.5 -0.5 -0.5"/>
          <geom name="//unnamed_geom_47" class="collision" size="0.0369406 0.0295525 0.139206" pos="0.0299461 0 -0.148782" quat="0.707107 0 0 -0.707107" type="box"/>
          <geom name="//unnamed_geom_48" class="visual" pos="0.10012 0 -0.300061" quat="1 0 0 0" material="drive" mesh="drive"/>
          <geom name="//unnamed_geom_49" class="collision" size="0.0492541 0.0689557" pos="0.0302455 0 -0.300061" quat="0.707107 0 0.707107 0"/>
          <geom name="//unnamed_geom_50" class="reward_collision_sphere" size="0.0788065" pos="0.0249551 0 0"/>
          <body name="LF_SHANK" pos="0.100528 -0.000155432 -0.300076" quat="1 1.7444e-05 -0.000159909 0.000310251">
            <inertial pos="0.00397467 -0.0550636 -0.0858744" quat="0.99335 -0.111761 -0.00257739 -0.0275588" mass="0.557416" diaginertia="0.0100834 0.0057207 0.00144236"/>
            <joint name="LF_KFE" pos="0 0 0" axis="1 -0.000803456 5.10377e-05" range="-3.09687 3.15457" armature="0.0102009" damping="0" frictionloss="0.0940451"/>
            <geom name="//unnamed_geom_51" class="visual" pos="0.000609876 0.00325189 0" quat="0.707107 0 0 -0.707107" material="shank_l" mesh="shank_l"/>
            <geom name="LF_kfe_act" class="collision" size="0.0591049 0.0197016" pos="0.0199641 0 0" quat="0.5 0.5 -0.5 -0.5"/>
            <geom name="//unnamed_geom_53" class="collision" size="0.0566412 0.0332465 0.0187166" pos="0.0199641 -0.0519904 0" quat="0.5 0.5 -0.5 -0.5" type="box"/>
            <geom name="//unnamed_geom_54" class="visual" pos="0.0130264 -0.0784762 -0.35583" quat="0.382683 0 0 -0.92388" material="foot" mesh="foot"/>
            <geom name="LF_calf" class="collision" size="0.0172389 0.139145" pos="0.0130265 -0.0795242 -0.177915" quat="0.707107 0 0 -0.707107"/>
            <geom name="LF_foot" class="foot" size="0.0304566" pos="0.0130265 -0.0795242 -0.332141" quat="0.707107 0 0 -0.707107"/>
            <geom name="//unnamed_geom_57" class="reward_collision_sphere" size="0.0985082" pos="-0.0499101 0 0"/>
            <geom name="//unnamed_geom_58" class="reward_collision_sphere" size="0.0492541" pos="0.0130265 -0.0795242 -0.332141"/>
            <site name="LF_foot" class="foot" pos="0.0130265 -0.0795242 -0.332141" quat="0.707107 0 0 -0.707107" size="0.00985082"/>
          </body>
        </body>
      </body>
      <body name="RF_HIP" pos="0.297853 -0.0933941 -0.00230516" quat="0.259206 -0.965822 0.000220284 6.1887e-05">
        <inertial pos="0.0562171 0.0131399 -0.00794974" quat="0.127844 0.678371 0.129938 0.711748" mass="2.68035" diaginertia="0.0057652 0.0029733 0.00418798"/>
        <joint name="RF_HAA" pos="0 0 0" axis="0.999999 0.000927606 -0.000401164" range="-0.483643 0.74921" armature="0.0103674" damping="0.0137192" frictionloss="0.0950239"/>
        <geom name="//unnamed_geom_59" class="visual" pos="0 0.000150839 2.47753e-05" quat="0.258819 0.965926 0 0" material="hip_r" mesh="hip_r"/>
        <geom name="//unnamed_geom_60" class="visual" pos="0.0597923 0.0712662 -0.0422451" quat="0.183013 0.683013 0.683013 -0.183013" material="drive" mesh="drive"/>
        <geom name="//unnamed_geom_61" class="collision" size="0.0492541 0.0689557" pos="0.0597923 0.010814 -0.0072699" quat="-0.353553 0.612372 0.612372 0.353553"/>
        <body name="RF_THIGH" pos="0.0610777 0.0674343 -0.0463461" quat="0.183027 0.68303 0.682995 -0.183003">
          <inertial pos="0.0300742 3.32764e-05 -0.256598" quat="0.992575 -0.00786542 -0.0844116 0.0872178" mass="2.90886" diaginertia="0.0299914 0.0180862 0.0054189"/>
          <joint name="RF_HFE" pos="0 0 0" axis="0.999979 -0.00365318 -0.0054214" stiffness="0.0134902" range="-3.13586 3.11953" armature="0.00916442" damping="0.016534" frictionloss="0.0999593"/>
          <geom name="//unnamed_geom_62" class="visual" pos="0.00187034 2.94721e-06 0" quat="0.707107 0 0 -0.707107" material="thigh" mesh="thigh"/>
          <geom name="//unnamed_geom_63" class="collision" size="0.0640303 0.0394033" pos="0.0399281 0 0" quat="0.5 0.5 0.5 0.5"/>
          <geom name="//unnamed_geom_64" class="collision" size="0.0369406 0.0295525 0.139206" pos="0.0299461 0 -0.148782" quat="0.707107 0 0 0.707107" type="box"/>
          <geom name="//unnamed_geom_65" class="visual" pos="0.10012 0 -0.300061" quat="1 0 0 0" material="drive" mesh="drive"/>
          <geom name="//unnamed_geom_66" class="collision" size="0.0492541 0.0689557" pos="0.0302455 0 -0.300061" quat="0.707107 0 0.707107 0"/>
          <geom name="//unnamed_geom_67" class="reward_collision_sphere" size="0.0788065" pos="0.0249551 0 0"/>
          <body name="RF_SHANK" pos="0.101171 -0.00086762 -0.298181" quat="1 -3.52148e-05 6.21482e-05 -6.96796e-06">
            <inertial pos="0.00602042 0.0553764 -0.0847458" quat="0.992395 0.120523 -0.00285267 0.0248492" mass="0.577457" diaginertia="0.0104723 0.00574869 0.00149359"/>
            <joint name="RF_KFE" pos="0 0 0" axis="0.999996 0.000504776 -0.00265373" range="-3.15661 3.12491" armature="0.00970263" damping="0" frictionloss="0.103415"/>
            <geom name="//unnamed_geom_68" class="visual" pos="0.000609873 -0.00325189 0" quat="0.707107 0 0 0.707107" material="shank" mesh="shank_r"/>
            <geom name="RF_kfe_act" class="collision" size="0.0591049 0.0197016" pos="0.0199641 0 0" quat="0.5 0.5 0.5 0.5"/>
            <geom name="//unnamed_geom_70" class="collision" size="0.0566412 0.0332465 0.0187166" pos="0.0199641 0.0519904 0" quat="0.5 0.5 0.5 0.5" type="box"/>
            <geom name="//unnamed_geom_71" class="visual" pos="0.0130267 0.0784762 -0.35583" quat="0.382683 0 0 0.92388" material="foot" mesh="foot"/>
            <geom name="RF_calf" class="collision" size="0.0172389 0.139145" pos="0.0130265 0.0795242 -0.177915" quat="0.707107 0 0 0.707107"/>
            <geom name="RF_foot" class="foot" size="0.0265834" pos="0.0130265 0.0795242 -0.332141" quat="0.707107 0 0 0.707107"/>
            <geom name="//unnamed_geom_74" class="reward_collision_sphere" size="0.0985082" pos="-0.0499101 0 0"/>
            <geom name="//unnamed_geom_75" class="reward_collision_sphere" size="0.0492541" pos="0.0130265 0.0795242 -0.332141"/>
            <site name="RF_foot" class="foot" pos="0.0130265 0.0795242 -0.332141" quat="0.707107 0 0 0.707107" size="0.00985082"/>
          </body>
        </body>
      </body>
      <body name="LH_HIP" pos="-0.298886 0.0935425 0.000617251" quat="7.30857e-05 -0.000288909 0.96592 -0.258839">
        <inertial pos="0.0566537 0.0140094 -0.00916262" quat="0.134636 0.680181 0.127121 0.709272" mass="2.6172" diaginertia="0.00588129 0.00304291 0.00428032"/>
        <joint name="LH_HAA" pos="0 0 0" axis="0.999981 0.0049511 0.00361116" range="-0.472553 0.741363" armature="0.00997756" damping="0.0107088" frictionloss="0.101712"/>
        <geom name="//unnamed_geom_76" class="visual" pos="0 0.000150839 2.47753e-05" quat="-0.258819 -0.965926 0 0" material="hip_r" mesh="hip_r"/>
        <geom name="//unnamed_geom_77" class="visual" pos="0.0597923 0.0712662 -0.0422451" quat="0.183013 0.683013 0.683013 -0.183013" material="drive" mesh="drive"/>
        <geom name="//unnamed_geom_78" class="collision" size="0.0492541 0.0689557" pos="0.0597923 0.010814 -0.0072699" quat="-0.353553 0.612372 0.612372 0.353553"/>
        <body name="LH_THIGH" pos="0.0591885 0.0669784 -0.0442575" quat="0.183521 0.683658 0.682252 -0.182933">
          <inertial pos="0.0307451 0.00220241 -0.259497" quat="0.992555 -0.00709214 -0.0829849 0.0888645" mass="2.86397" diaginertia="0.0302583 0.0179628 0.00551758"/>
          <joint name="LH_HFE" pos="0 0 0" axis="0.99994 -0.00496537 -0.00971727" range="-3.15118 3.1391" armature="0.00979246" damping="0.0116541" frictionloss="0.101436"/>
          <geom name="//unnamed_geom_79" class="visual" pos="0.00187034 2.94721e-06 0" quat="0.707107 0 0 -0.707107" material="thigh" mesh="thigh"/>
          <geom name="//unnamed_geom_80" class="collision" size="0.0640303 0.0394033" pos="0.0399281 0 0" quat="0.5 0.5 -0.5 -0.5"/>
          <geom name="//unnamed_geom_81" class="collision" size="0.0369406 0.0295525 0.139206" pos="0.0299461 0 -0.148782" quat="0.707107 0 0 -0.707107" type="box"/>
          <geom name="//unnamed_geom_82" class="visual" pos="0.10012 0 -0.300061" quat="1 0 0 0" material="drive" mesh="drive"/>
          <geom name="//unnamed_geom_83" class="collision" size="0.0492541 0.0689557" pos="0.0302455 0 -0.300061" quat="0.707107 0 0.707107 0"/>
          <geom name="//unnamed_geom_84" class="reward_collision_sphere" size="0.0788065" pos="0.0249551 0 0"/>
          <body name="LH_SHANK" pos="0.100996 -0.00181021 -0.300788" quat="1 -0.000234518 0.000517251 -5.84167e-05">
            <inertial pos="0.00547705 0.0562247 -0.0854536" quat="0.99275 0.117461 -0.000596072 0.0255086" mass="0.57007" diaginertia="0.0100695 0.00557324 0.00144002"/>
            <joint name="LH_KFE" pos="0 0 0" axis="1 1.83096e-05 -9.45182e-05" range="-3.10415 3.14376" armature="0.0109241" damping="0.0102018" frictionloss="0.099348"/>
            <geom name="//unnamed_geom_85" class="visual" pos="0.000609873 -0.00325189 0" quat="-0.707107 0 0 -0.707107" material="shank" mesh="shank_r"/>
            <geom name="LH_kfe_act" class="collision" size="0.0591049 0.0197016" pos="0.0199641 0 0" quat="0.5 0.5 -0.5 -0.5"/>
            <geom name="//unnamed_geom_87" class="collision" size="0.0566412 0.0332465 0.0187166" pos="0.0199641 0.0519904 0" quat="0.5 0.5 -0.5 -0.5" type="box"/>
            <geom name="//unnamed_geom_88" class="visual" pos="0.0130267 0.0784762 -0.35583" quat="-0.382683 0 0 -0.92388" material="foot" mesh="foot"/>
            <geom name="LH_calf" class="collision" size="0.0172389 0.139145" pos="0.0130265 0.0795242 -0.177915" quat="0.707107 0 0 -0.707107"/>
            <geom name="LH_foot" class="foot" size="0.0306694" pos="0.0130265 0.0795242 -0.332141" quat="0.707107 0 0 -0.707107"/>
            <geom name="//unnamed_geom_91" class="reward_collision_sphere" size="0.0985082" pos="-0.0499101 0 0"/>
            <geom name="//unnamed_geom_92" class="reward_collision_sphere" size="0.0492541" pos="0.0130265 0.0795242 -0.332141"/>
            <site name="LH_foot" class="foot" pos="0.0130265 0.0795242 -0.332141" quat="0.707107 0 0 -0.707107" size="0.00985082"/>
          </body>
        </body>
      </body>
      <body name="RH_HIP" pos="-0.30139 -0.0949501 -0.000197786" quat="0.000322235 0.0006203 -0.966199 -0.257795">
        <inertial pos="0.0567603 -0.0131407 -0.00927448" quat="-0.127985 0.710108 -0.136054 0.678864" mass="2.6906" diaginertia="0.0058695 0.00297198 0.00442411"/>
        <joint name="RH_HAA" pos="0 0 0" axis="0.999993 0.00166087 0.00323154" range="-0.71936 0.495918" armature="0.0106622" damping="0.00901086" frictionloss="0.096891"/>
        <geom name="//unnamed_geom_93" class="visual" pos="0 -0.00015084 2.47753e-05" quat="-0.258819 0.965926 0 0" material="hip_l" mesh="hip_l"/>
        <geom name="//unnamed_geom_94" class="visual" pos="0.0597923 -0.0712662 -0.0422451" quat="-0.183013 0.683013 -0.683013 -0.183013" material="drive" mesh="drive"/>
        <geom name="//unnamed_geom_95" class="collision" size="0.0492541 0.0689557" pos="0.0597923 -0.010814 -0.0072699" quat="0.353553 0.612372 -0.612372 0.353553"/>
        <body name="RH_THIGH" pos="0.0596452 -0.0651671 -0.0442132" quat="-0.182553 0.683218 -0.683 -0.182755">
          <inertial pos="0.0309655 -0.00062806 -0.258784" quat="0.99325 -0.00360267 -0.080364 0.0835664" mass="2.8935" diaginertia="0.0296458 0.0181525 0.00539585"/>
          <joint name="RH_HFE" pos="0 0 0" axis="1 0.000286576 -0.000723878" range="-3.13307 3.18806" armature="0.00884088" damping="0.0132063" frictionloss="0.0966504"/>
          <geom name="//unnamed_geom_96" class="visual" pos="0.00187034 2.94721e-06 0" quat="0.707107 0 0 -0.707107" material="thigh" mesh="thigh"/>
          <geom name="//unnamed_geom_97" class="collision" size="0.0640303 0.0394033" pos="0.0399281 0 0" quat="0.5 0.5 0.5 0.5"/>
          <geom name="//unnamed_geom_98" class="collision" size="0.0369406 0.0295525 0.139206" pos="0.0299461 0 -0.148782" quat="0.707107 0 0 0.707107" type="box"/>
          <geom name="//unnamed_geom_99" class="visual" pos="0.10012 0 -0.300061" quat="1 0 0 0" material="drive" mesh="drive"/>
          <geom name="//unnamed_geom_100" class="collision" size="0.0492541 0.0689557" pos="0.0302455 0 -0.300061" quat="0.707107 0 0.707107 0"/>
          <geom name="//unnamed_geom_101" class="reward_collision_sphere" size="0.0788065" pos="0.0249551 0 0"/>
          <body name="RH_SHANK" pos="0.0993896 0.000669147 -0.300416" quat="1 -0.00013823 4.57025e-05 -3.75875e-05">
            <inertial pos="0.00613823 -0.0551414 -0.0850787" quat="0.992965 -0.115663 -0.000348991 -0.0253513" mass="0.561617" diaginertia="0.00996953 0.00551655 0.00143657"/>
            <joint name="RH_KFE" pos="0 0 0" axis="0.999996 -0.00272251 -0.00114335" range="-3.09202 3.1183" armature="0.00947827" damping="0.00905869" frictionloss="0.0953575"/>
            <geom name="//unnamed_geom_102" class="visual" pos="0.000609876 0.00325189 0" quat="0.707107 0 0 -0.707107" material="shank_l" mesh="shank_l"/>
            <geom name="RH_kfe_act" class="collision" size="0.0591049 0.0197016" pos="0.0199641 0 0" quat="0.5 0.5 0.5 0.5"/>
            <geom name="//unnamed_geom_104" class="collision" size="0.0566412 0.0332465 0.0187166" pos="0.0199641 -0.0519904 0" quat="0.5 0.5 0.5 0.5" type="box"/>
            <geom name="//unnamed_geom_105" class="visual" pos="0.0130264 -0.0784762 -0.35583" quat="0.382683 0 0 -0.92388" material="foot" mesh="foot"/>
            <geom name="RH_calf" class="collision" size="0.0172389 0.139145" pos="0.0130265 -0.0795242 -0.177915" quat="0.707107 0 0 0.707107"/>
            <geom name="RH_foot" class="foot" size="0.0294943" pos="0.0130265 -0.0795242 -0.332141" quat="0.707107 0 0 0.707107"/>
            <geom name="//unnamed_geom_108" class="reward_collision_sphere" size="0.0985082" pos="-0.0499101 0 0"/>
            <geom name="//unnamed_geom_109" class="reward_collision_sphere" size="0.0492541" pos="0.0130265 -0.0795242 -0.332141"/>
            <site name="RH_foot" class="foot" pos="0.0130265 -0.0795242 -0.332141" quat="0.707107 0 0 0.707107" size="0.00985082"/>
          </body>
        </body>
      </body>
    </body>
  </worldbody>

  <contact>
    <pair class="/" geom1="floor" geom2="LF_foot" name="//unnamed_contact_0"/>
    <pair class="/" geom1="floor" geom2="RF_foot" name="//unnamed_contact_1"/>
    <pair class="/" geom1="floor" geom2="LH_foot" name="//unnamed_contact_2"/>
    <pair class="/" geom1="floor" geom2="RH_foot" name="//unnamed_contact_3"/>
  </contact>

  <actuator>
    <general name="LF_HAA" class="/" joint="LF_HAA" forcerange="-77.3333 77.3333" gainprm="79.9586" biasprm="0 -79.9586 -1.87904"/>
    <general name="LF_HFE" class="/" joint="LF_HFE" forcerange="-79.1821 79.1821" gainprm="79.9586" biasprm="0 -79.9586 -1.87904"/>
    <general name="LF_KFE" class="/" joint="LF_KFE" forcerange="-80.6633 80.6633" gainprm="79.9586" biasprm="0 -79.9586 -1.87904"/>
    <general name="RF_HAA" class="/" joint="RF_HAA" forcerange="-82.1387 82.1387" gainprm="79.9586" biasprm="0 -79.9586 -1.87904"/>
    <general name="RF_HFE" class="/" joint="RF_HFE" forcerange="-79.6825 79.6825" gainprm="79.9586" biasprm="0 -79.9586 -1.87904"/>
    <general name="RF_KFE" class="/" joint="RF_KFE" forcerange="-77.8193 77.8193" gainprm="79.9586" biasprm="0 -79.9586 -1.87904"/>
    <general name="LH_HAA" class="/" joint="LH_HAA" forcerange="-81.1312 81.1312" gainprm="79.9586" biasprm="0 -79.9586 -1.87904"/>
    <general name="LH_HFE" class="/" joint="LH_HFE" forcerange="-78.8009 78.8009" gainprm="79.9586" biasprm="0 -79.9586 -1.87904"/>
    <general name="LH_KFE" class="/" joint="LH_KFE" forcerange="-76.5533 76.5533" gainprm="79.9586" biasprm="0 -79.9586 -1.87904"/>
    <general name="RH_HAA" class="/" joint="RH_HAA" forcerange="-82.0753 82.0753" gainprm="79.9586" biasprm="0 -79.9586 -1.87904"/>
    <general name="RH_HFE" class="/" joint="RH_HFE" forcerange="-76.133 76.133" gainprm="79.9586" biasprm="0 -79.9586 -1.87904"/>
    <general name="RH_KFE" class="/" joint="RH_KFE" forcerange="-83.6218 83.6218" gainprm="79.9586" biasprm="0 -79.9586 -1.87904"/>
  </actuator>

  <sensor>
    <gyro site="imu" name="imu_angular_velocity"/>
    <velocimeter site="imu" name="imu_linear_velocity"/>
    <framelinvel objtype="site" objname="LF_foot" name="LF_foot_global_linear_velocity"/>
    <framelinvel objtype="site" objname="RF_foot" name="RF_foot_global_linear_velocity"/>
    <framelinvel objtype="site" objname="LH_foot" name="LH_foot_global_linear_velocity"/>
    <framelinvel objtype="site" objname="RH_foot" name="RH_foot_global_linear_velocity"/>
  </sensor>

  <keyframe>
    <key name="home" qpos="0 0 0.55 1 0 0 0 0 0.4 -0.8 0 -0.4 0.8 0 -0.4 0.8 0 0.4 -0.8"/>
  </keyframe>
</mujoco>
