<mujoco model="anymal_c">
  <compiler angle="radian" assetdir="assets" balanceinertia="true" inertiafromgeom="false"/>

  <option timestep="0.005" density="1.2" viscosity="2e-05"/>

  <size nkey="1"/>

  <visual>
    <quality shadowsize="8192"/>
    <map shadowclip="0.5"/>
  </visual>

  <default>
    <default class="/">
      <material specular="0" shininess="0.25"/>
      <geom contype="0" conaffinity="0" group="1" solref="-1000 -80"/>
      <site size="0.01 0.005 0.005" group="5"/>
      <general forcelimited="true" forcerange="-80 80" biastype="affine" gainprm="80" biasprm="0 -80 -2"/>
      <default class="anymal_c">
        <joint armature="0.01" damping="0.01" frictionloss="0.1"/>
        <default class="visual">
          <geom type="mesh" group="2"/>
          <default class="visual_zflip"/>
        </default>
        <default class="collision">
          <geom type="cylinder" group="3"/>
          <default class="foot">
            <geom size="0.03 0 0" type="sphere" condim="6" priority="1" friction="0.8 0.02 0.01" solimp="0.015 1 0.03"/>
          </default>
        </default>
      </default>
      <default class="reward_collision_sphere">
        <geom group="5" rgba="1 0 0 1"/>
      </default>
    </default>
  </default>

  <asset>
    <texture type="skybox" colorspace="auto" name="//unnamed_texture_0" builtin="gradient" rgb1="0.95 0.95 0.95" rgb2="0.95 0.95 0.95" width="100" height="600"/>
    <texture type="2d" colorspace="auto" name="texplane" builtin="checker" rgb1="0.345 0.575 0.748" rgb2="0.345 0.575 0.748" markrgb="1 1 1" width="512" height="512"/>
    <texture type="2d" colorspace="linear" name="base" file="base.png"/>
    <texture type="2d" colorspace="linear" name="top_shell" file="top_shell.png"/>
    <texture type="2d" colorspace="linear" name="bottom_shell" file="bottom_shell.png"/>
    <texture type="2d" colorspace="linear" name="remote" file="remote.png"/>
    <texture type="2d" colorspace="linear" name="hatch" file="hatch.png"/>
    <texture type="2d" colorspace="linear" name="handle" file="handle.png"/>
    <texture type="2d" colorspace="linear" name="face" file="face.png"/>
    <texture type="2d" colorspace="linear" name="battery" file="battery.png"/>
    <texture type="2d" colorspace="linear" name="lidar_cage" file="lidar_cage.png"/>
    <texture type="2d" colorspace="linear" name="depth_camera" file="depth_camera.png"/>
    <texture type="2d" colorspace="linear" name="wide_angle_camera" file="wide_angle_camera.png"/>
    <texture type="2d" colorspace="linear" name="lidar" file="lidar.png"/>
    <texture type="2d" colorspace="linear" name="drive" file="drive.png"/>
    <texture type="2d" colorspace="linear" name="hip_l" file="hip_l.png"/>
    <texture type="2d" colorspace="linear" name="shank_l" file="shank_l.png"/>
    <texture type="2d" colorspace="linear" name="foot" file="foot.png"/>
    <texture type="2d" colorspace="linear" name="thigh" file="thigh.png"/>
    <texture type="2d" colorspace="linear" name="shank_r" file="shank_r.png"/>
    <texture type="2d" colorspace="linear" name="hip_r" file="hip_r.png"/>
    <material name="MatPlane" class="/" texture="texplane" texuniform="true" texrepeat="2 2" specular="0.9" shininess="0.5"/>
    <material name="black_plastic" class="/" rgba="0.007 0.007 0.007 1"/>
    <material name="green" class="/" rgba="0.052 0.178 0.033 1"/>
    <material name="red" class="/" rgba="0.178 0.006 0.005 1"/>
    <material name="yellow" class="/" rgba="0.178 0.119 0.006 1"/>
    <material name="lwl" class="/" rgba="0.8 0.8 0.8 1"/>
    <material name="base" class="/" texture="base"/>
    <material name="top_shell" class="/" texture="top_shell"/>
    <material name="bottom_shell" class="/" texture="bottom_shell"/>
    <material name="hip_l" class="/" texture="hip_l"/>
    <material name="thigh" class="/" texture="thigh"/>
    <material name="shank_l" class="/" texture="shank_l"/>
    <material name="foot" class="/" texture="foot"/>
    <material name="hip_r" class="/" texture="hip_r"/>
    <material name="shank" class="/" texture="shank_r"/>
    <material name="hatch" class="/" texture="hatch"/>
    <material name="remote" class="/" texture="remote"/>
    <material name="handle" class="/" texture="handle"/>
    <material name="face" class="/" texture="face"/>
    <material name="depth_camera" class="/" texture="depth_camera"/>
    <material name="wide_angle_camera" class="/" texture="wide_angle_camera"/>
    <material name="battery" class="/" texture="battery"/>
    <material name="lidar_cage" class="/" texture="lidar_cage"/>
    <material name="lidar" class="/" texture="lidar"/>
    <material name="drive" class="/" texture="drive"/>
    <mesh name="base_0" class="/" file="base_0.obj"/>
    <mesh name="base_1" class="/" file="base_1.obj"/>
    <mesh name="base_2" class="/" file="base_2.obj"/>
    <mesh name="base_3" class="/" file="base_3.obj"/>
    <mesh name="base_4" class="/" file="base_4.obj"/>
    <mesh name="base_5" class="/" file="base_5.obj"/>
    <mesh name="top_shell" class="/" file="top_shell.obj"/>
    <mesh name="bottom_shell" class="/" file="bottom_shell.obj"/>
    <mesh name="remote" class="/" file="remote.obj"/>
    <mesh name="handle" class="/" file="handle.obj"/>
    <mesh name="face" class="/" file="face.obj"/>
    <mesh name="wide_angle_camera" class="/" file="wide_angle_camera.obj"/>
    <mesh name="depth_camera" class="/" file="depth_camera.obj"/>
    <mesh name="battery" class="/" file="battery.obj"/>
    <mesh name="lidar_cage" class="/" file="lidar_cage.obj"/>
    <mesh name="lidar" class="/" file="lidar.obj"/>
    <mesh name="drive" class="/" file="drive.obj"/>
    <mesh name="hip_l" class="/" file="hip_l.obj"/>
    <mesh name="thigh" class="/" file="thigh.obj"/>
    <mesh name="shank_l" class="/" file="shank_l.obj"/>
    <mesh name="foot" class="/" file="foot.obj"/>
    <mesh name="hip_r" class="/" file="hip_r.obj"/>
    <mesh name="hatch" class="/" file="hatch.obj"/>
    <mesh name="shank_r" class="/" file="shank_r.obj"/>
  </asset>

  <worldbody>
    <geom name="floor" class="/" size="100 100 0.125" type="plane" group="0" material="MatPlane"/>
    <light name="toplight_shadow" class="/" pos="0 0 5" dir="0.0990148 0.0990148 -0.990148" type="directional" ambient="0.04 0.04 0.04" diffuse="0.55 0.55 0.55" specular="0.12 0.12 0.12"/>
    <light name="toplight_fill" class="/" pos="0 0 5" dir="0.0990148 0.0990148 -0.990148" type="directional" castshadow="false" ambient="0.04 0.04 0.04" diffuse="0.3 0.3 0.3" specular="0.08 0.08 0.08"/>
    <body name="trunk" childclass="anymal_c" pos="-0.000132344 0.000803333 4.00808e-05" quat="1 0.00036866 1.78822e-05 -0.000142152">
      <inertial pos="0.00340106 -0.00112325 0.0509825" quat="0.496603 0.500306 0.503007 0.500063" mass="18.5151" diaginertia="0.769142 0.358387 0.271984"/>
      <joint name="//unnamed_joint_0" type="free" armature="0" damping="0" frictionloss="0"/>
      <geom name="//unnamed_geom_1" class="visual" material="green" mesh="base_0"/>
      <geom name="//unnamed_geom_2" class="visual" material="yellow" mesh="base_1"/>
      <geom name="//unnamed_geom_3" class="visual" material="red" mesh="base_2"/>
      <geom name="//unnamed_geom_4" class="visual" material="black_plastic" mesh="base_3"/>
      <geom name="//unnamed_geom_5" class="visual" material="lwl" mesh="base_4"/>
      <geom name="//unnamed_geom_6" class="visual" material="base" mesh="base_5"/>
      <geom name="trunk_1" class="collision" size="0.289355 0.0698443 0.0897998" type="box"/>
      <geom name="trunk_2" class="collision" size="0.0897998 0.0723387" pos="0.227061 0.0629288 0" quat="0.707107 0 0.707107 0"/>
      <geom name="trunk_3" class="collision" size="0.0897998 0.0723387" pos="-0.227061 0.0629288 0" quat="0.707107 0 0.707107 0"/>
      <geom name="trunk_4" class="collision" size="0.0897998 0.0723387" pos="0.227061 -0.0629288 0" quat="0.707107 0 0.707107 0"/>
      <geom name="trunk_5" class="collision" size="0.0897998 0.0723387" pos="-0.227061 -0.0629288 0" quat="0.707107 0 0.707107 0"/>
      <geom name="//unnamed_geom_12" class="visual" material="top_shell" mesh="top_shell"/>
      <geom name="//unnamed_geom_13" class="visual" material="bottom_shell" mesh="bottom_shell"/>
      <geom name="//unnamed_geom_14" class="visual" material="remote" mesh="remote"/>
      <geom name="//unnamed_geom_15" class="visual" material="handle" mesh="handle"/>
      <geom name="//unnamed_geom_16" class="visual" pos="0.432721 0 0" quat="1 0 0 0" material="face" mesh="face"/>
      <geom name="trunk_6" class="collision" size="0.0548777 0.0698443 0.0897998" pos="0.490139 0 0" type="box"/>
      <geom name="//unnamed_geom_18" class="collision" size="0.0897998 0.0548777" pos="0.490139 0.0629288 0" quat="0.707107 0 0.707107 0"/>
      <geom name="//unnamed_geom_19" class="collision" size="0.0897998 0.0548777" pos="0.490139 -0.0629288 0" quat="0.707107 0 0.707107 0"/>
      <geom name="//unnamed_geom_20" class="visual" pos="0.481944 0 -0.03072" quat="0.965926 0 0.258819 0" material="depth_camera" mesh="depth_camera"/>
      <geom name="//unnamed_geom_21" class="visual" pos="0.535551 0 0.0157242" material="wide_angle_camera" mesh="wide_angle_camera"/>
      <geom name="//unnamed_geom_22" class="visual_zflip" pos="-0.432721 0 0" quat="0 0 0 1" material="face" mesh="face"/>
      <geom name="trunk_7" class="collision" size="0.0548777 0.0698443 0.0897998" pos="-0.490139 0 0" quat="0 0 0 1" type="box"/>
      <geom name="//unnamed_geom_24" class="collision" size="0.0897998 0.0548777" pos="-0.490139 -0.0629288 0" quat="0 -0.707107 0 0.707107"/>
      <geom name="//unnamed_geom_25" class="collision" size="0.0897998 0.0548777" pos="-0.490139 0.0629288 0" quat="0 -0.707107 0 0.707107"/>
      <geom name="//unnamed_geom_26" class="visual" pos="-0.481944 0 -0.03072" quat="0 -0.258819 0 0.965926" material="depth_camera" mesh="depth_camera"/>
      <geom name="//unnamed_geom_27" class="visual_zflip" pos="-0.535551 0 0.0157242" quat="0 0 0 1" material="wide_angle_camera" mesh="wide_angle_camera"/>
      <geom name="//unnamed_geom_28" class="visual" material="battery" mesh="battery"/>
      <geom name="//unnamed_geom_29" class="visual" pos="0 0.0668341 0.0304648" quat="0.683013 -0.183013 0.183013 0.683013" material="depth_camera" mesh="depth_camera"/>
      <geom name="//unnamed_geom_30" class="visual" pos="0 -0.0668341 0.0304648" quat="0.683013 0.183013 0.183013 -0.683013" material="depth_camera" mesh="depth_camera"/>
      <geom name="//unnamed_geom_31" class="visual" pos="-0.380001 0 0.0772032" quat="1 0 0 0" material="lidar_cage" mesh="lidar_cage"/>
      <geom name="trunk_8" class="collision" size="0.0698443 0.0598665" pos="-0.380001 0 0.140226"/>
      <geom name="//unnamed_geom_33" class="visual" pos="-0.380001 -5.69573e-05 0.149365" quat="0.707107 0 0 -0.707107" material="lidar" mesh="lidar"/>
      <geom name="//unnamed_geom_34" class="visual" pos="0.313083 0.0935481 -2.61167e-09" quat="0.258819 0.965926 0 0" material="drive" mesh="drive"/>
      <geom name="//unnamed_geom_35" class="visual" pos="0.313083 -0.0935481 2.61167e-09" quat="0.258819 -0.965926 0 0" material="drive" mesh="drive"/>
      <geom name="//unnamed_geom_36" class="visual" pos="-0.313083 0.0935481 2.61167e-09" quat="0 0 0.965926 -0.258819" material="drive" mesh="drive"/>
      <geom name="//unnamed_geom_37" class="visual" pos="-0.313083 -0.0935481 -2.61167e-09" quat="0 0 -0.965926 -0.258819" material="drive" mesh="drive"/>
      <geom name="//unnamed_geom_38" class="visual" pos="0.121099 0 0.076678" quat="1 0 0 0" material="hatch" mesh="hatch"/>
      <geom name="//unnamed_geom_39" class="reward_collision_sphere" size="0.119733"/>
      <geom name="//unnamed_geom_40" class="reward_collision_sphere" size="0.119733" pos="0.469782 0 0"/>
      <geom name="//unnamed_geom_41" class="reward_collision_sphere" size="0.119733" pos="-0.469782 0 0"/>
      <site name="imu" pos="0.259472 0.00599219 0.0470826" size="0.00997776"/>
      <camera name="track" pos="0 -1.79797 0" quat="0.707107 0.707107 0 0" mode="trackcom"/>
      <camera name="ego_camera" pos="0.469782 0 -0.0420153" quat="-0.5 -0.5 0.5 0.5"/>
      <body name="LF_HIP" pos="0.313751 0.0937511 -0.000136773" quat="0.258822 0.965925 -1.81664e-05 -7.97808e-05">
        <inertial pos="0.0591471 -0.0131813 -0.00867929" quat="-0.130926 0.709813 -0.128982 0.679991" mass="2.77566" diaginertia="0.00733051 0.00293396 0.00424951"/>
        <joint name="LF_HAA" pos="0 0 0" axis="0.999999 0.00113419 -0.000253083" range="-0.7014 0.478683" armature="0.0101103" damping="0.00881292" frictionloss="0.0986905"/>
        <geom name="//unnamed_geom_42" class="visual" pos="0 -0.000153633 2.52341e-05" quat="0.258819 -0.965926 0 0" material="hip_l" mesh="hip_l"/>
        <geom name="//unnamed_geom_43" class="visual" pos="0.0625332 -0.0739172 -0.043796" quat="0.183013 -0.683013 0.683013 0.183013" material="drive" mesh="drive"/>
        <geom name="//unnamed_geom_44" class="collision" size="0.0498888 0.0698443" pos="0.0625332 -0.0107517 -0.0072529" quat="-0.353553 -0.612372 0.612372 -0.353553"/>
        <body name="LF_THIGH" pos="0.0627549 -0.0665119 -0.044572" quat="0.182681 -0.682729 0.683386 0.183009">
          <inertial pos="0.0321839 0.00123466 -0.258486" quat="0.993206 -0.00732912 -0.07917 0.0849736" mass="3.02271" diaginertia="0.0374966 0.017792 0.00536667"/>
          <joint name="LF_HFE" pos="0 0 0" axis="0.999998 0.00190665 0.00095365" range="-3.12945 3.12641" armature="0.0104956" damping="0.0117388" frictionloss="0.104465"/>
          <geom name="//unnamed_geom_45" class="visual" pos="0.00288446 4.54523e-06 0" quat="0.707107 0 0 -0.707107" material="thigh" mesh="thigh"/>
          <geom name="//unnamed_geom_46" class="collision" size="0.0648554 0.039911" pos="0.0417584 0 0" quat="0.5 0.5 -0.5 -0.5"/>
          <geom name="//unnamed_geom_47" class="collision" size="0.0374166 0.0299333 0.141" pos="0.0313188 0 -0.148434" quat="0.707107 0 0 -0.707107" type="box"/>
          <geom name="//unnamed_geom_48" class="visual" pos="0.104709 0 -0.299359" quat="1 0 0 0" material="drive" mesh="drive"/>
          <geom name="//unnamed_geom_49" class="collision" size="0.0498888 0.0698443" pos="0.031632 0 -0.299359" quat="0.707107 0 0.707107 0"/>
          <geom name="//unnamed_geom_50" class="reward_collision_sphere" size="0.079822" pos="0.026099 0 0"/>
          <body name="LF_SHANK" pos="0.104935 -0.000203712 -0.300528" quat="1 -4.19241e-05 2.65034e-05 2.7473e-05">
            <inertial pos="0.00542628 -0.0541591 -0.0845336" quat="0.992926 -0.115962 0.000618032 -0.0254919" mass="0.589159" diaginertia="0.0127594 0.00552128 0.00144594"/>
            <joint name="LF_KFE" pos="0 0 0" axis="1 3.62324e-06 -4.18231e-05" range="-3.11788 3.13212" armature="0.0104813" damping="0.00476652" frictionloss="0.0990186"/>
            <geom name="//unnamed_geom_51" class="visual" pos="0.000940558 0.0050151 0" quat="0.707107 0 0 -0.707107" material="shank_l" mesh="shank_l"/>
            <geom name="LF_kfe_act" class="collision" size="0.0598665 0.0199555" pos="0.0208792 0 0" quat="0.5 0.5 -0.5 -0.5"/>
            <geom name="//unnamed_geom_53" class="collision" size="0.0573711 0.0336749 0.0189577" pos="0.0208792 -0.0516906 0" quat="0.5 0.5 -0.5 -0.5" type="box"/>
            <geom name="//unnamed_geom_54" class="visual" pos="0.0136234 -0.0774494 -0.354998" quat="0.382683 0 0 -0.92388" material="foot" mesh="foot"/>
            <geom name="LF_calf" class="collision" size="0.0174611 0.140938" pos="0.0136237 -0.0790656 -0.177499" quat="0.707107 0 0 -0.707107"/>
            <geom name="LF_foot" class="foot" size="0.0300867" pos="0.0136237 -0.0790656 -0.331365" quat="0.707107 0 0 -0.707107"/>
            <geom name="//unnamed_geom_57" class="reward_collision_sphere" size="0.0997776" pos="-0.052198 0 0"/>
            <geom name="//unnamed_geom_58" class="reward_collision_sphere" size="0.0498888" pos="0.0136237 -0.0790656 -0.331365"/>
            <site name="LF_foot" class="foot" pos="0.0136237 -0.0790656 -0.331365" quat="0.707107 0 0 -0.707107" size="0.00997776"/>
          </body>
        </body>
      </body>
      <body name="RF_HIP" pos="0.312719 -0.0930651 -0.00130139" quat="0.258797 -0.965932 0.000140688 5.98924e-06">
        <inertial pos="0.0589629 0.0134584 -0.00812564" quat="0.133523 0.679706 0.127979 0.709783" mass="2.78033" diaginertia="0.00733352 0.00289186 0.00419617"/>
        <joint name="RF_HAA" pos="0 0 0" axis="0.999995 0.00181118 -0.00257136" range="-0.495282 0.72511" armature="0.0104344" damping="0.0101939" frictionloss="0.100385"/>
        <geom name="//unnamed_geom_59" class="visual" pos="0 0.000153632 2.5234e-05" quat="0.258819 0.965926 0 0" material="hip_r" mesh="hip_r"/>
        <geom name="//unnamed_geom_60" class="visual" pos="0.0625332 0.0739172 -0.043796" quat="0.183013 0.683013 0.683013 -0.183013" material="drive" mesh="drive"/>
        <geom name="//unnamed_geom_61" class="collision" size="0.0498888 0.0698443" pos="0.0625332 0.0107517 -0.0072529" quat="-0.353553 0.612372 0.612372 0.353553"/>
        <body name="RF_THIGH" pos="0.0633371 0.0662165 -0.0454624" quat="0.183018 0.682964 0.683042 -0.18308">
          <inertial pos="0.0313649 0.000789416 -0.257134" quat="0.992736 -0.00661043 -0.0810896 0.0886338" mass="3.05515" diaginertia="0.0379079 0.0175575 0.00535336"/>
          <joint name="RF_HFE" pos="0 0 0" axis="0.999996 -0.00177809 0.00232678" stiffness="0.00860455" range="-3.14146 3.13278" armature="0.00984788" damping="0.0102238" frictionloss="0.104257"/>
          <geom name="//unnamed_geom_62" class="visual" pos="0.00288446 4.54523e-06 0" quat="0.707107 0 0 -0.707107" material="thigh" mesh="thigh"/>
          <geom name="//unnamed_geom_63" class="collision" size="0.0648554 0.039911" pos="0.0417584 0 0" quat="0.5 0.5 0.5 0.5"/>
          <geom name="//unnamed_geom_64" class="collision" size="0.0374166 0.0299333 0.141" pos="0.0313188 0 -0.148434" quat="0.707107 0 0 0.707107" type="box"/>
          <geom name="//unnamed_geom_65" class="visual" pos="0.104709 0 -0.299359" quat="1 0 0 0" material="drive" mesh="drive"/>
          <geom name="//unnamed_geom_66" class="collision" size="0.0498888 0.0698443" pos="0.031632 0 -0.299359" quat="0.707107 0 0.707107 0"/>
          <geom name="//unnamed_geom_67" class="reward_collision_sphere" size="0.079822" pos="0.026099 0 0"/>
          <body name="RF_SHANK" pos="0.104856 -0.000232323 -0.298224" quat="1 -9.86899e-05 -0.000202876 8.65449e-05">
            <inertial pos="0.00684319 0.0542939 -0.084866" quat="0.993252 0.112914 -0.000986501 0.0264672" mass="0.592728" diaginertia="0.0128511 0.00544995 0.00146694"/>
            <joint name="RF_KFE" pos="0 0 0" axis="0.999997 0.0025836 0.00019552" range="-3.14812 3.14118" armature="0.00974812" damping="0.00120507" frictionloss="0.101705"/>
            <geom name="//unnamed_geom_68" class="visual" pos="0.000940553 -0.00501509 0" quat="0.707107 0 0 0.707107" material="shank" mesh="shank_r"/>
            <geom name="RF_kfe_act" class="collision" size="0.0598665 0.0199555" pos="0.0208792 0 0" quat="0.5 0.5 0.5 0.5"/>
            <geom name="//unnamed_geom_70" class="collision" size="0.0573711 0.0336749 0.0189577" pos="0.0208792 0.0516906 0" quat="0.5 0.5 0.5 0.5" type="box"/>
            <geom name="//unnamed_geom_71" class="visual" pos="0.0136239 0.0774494 -0.354998" quat="0.382683 0 0 0.92388" material="foot" mesh="foot"/>
            <geom name="RF_calf" class="collision" size="0.0174611 0.140938" pos="0.0136237 0.0790656 -0.177499" quat="0.707107 0 0 0.707107"/>
            <geom name="RF_foot" class="foot" size="0.0275262" pos="0.0136237 0.0790656 -0.331365" quat="0.707107 0 0 0.707107"/>
            <geom name="//unnamed_geom_74" class="reward_collision_sphere" size="0.0997776" pos="-0.052198 0 0"/>
            <geom name="//unnamed_geom_75" class="reward_collision_sphere" size="0.0498888" pos="0.0136237 0.0790656 -0.331365"/>
            <site name="RF_foot" class="foot" pos="0.0136237 0.0790656 -0.331365" quat="0.707107 0 0 0.707107" size="0.00997776"/>
          </body>
        </body>
      </body>
      <body name="LH_HIP" pos="-0.312586 0.0928014 -0.000141547" quat="1.53506e-05 -5.96263e-05 0.965929 -0.258807">
        <inertial pos="0.0597935 0.0131534 -0.00964647" quat="0.136368 0.677845 0.128699 0.710892" mass="2.73777" diaginertia="0.00726458 0.00293859 0.00418429"/>
        <joint name="LH_HAA" pos="0 0 0" axis="0.999995 -0.00297227 -0.00144186" range="-0.496126 0.72678" armature="0.00975854" damping="0.0101444" frictionloss="0.0976361"/>
        <geom name="//unnamed_geom_76" class="visual" pos="0 0.000153632 2.5234e-05" quat="-0.258819 -0.965926 0 0" material="hip_r" mesh="hip_r"/>
        <geom name="//unnamed_geom_77" class="visual" pos="0.0625332 0.0739172 -0.043796" quat="0.183013 0.683013 0.683013 -0.183013" material="drive" mesh="drive"/>
        <geom name="//unnamed_geom_78" class="collision" size="0.0498888 0.0698443" pos="0.0625332 0.0107517 -0.0072529" quat="-0.353553 0.612372 0.612372 0.353553"/>
        <body name="LH_THIGH" pos="0.0620129 0.0660093 -0.0448604" quat="0.182826 0.683365 0.682797 -0.18269">
          <inertial pos="0.0319576 0.00123711 -0.258207" quat="0.992974 -0.00502111 -0.0783958 0.0884991" mass="3.01085" diaginertia="0.0378958 0.0173252 0.00535926"/>
          <joint name="LH_HFE" pos="0 0 0" axis="0.999987 0.0033972 0.00374223" range="-3.14963 3.14625" armature="0.00956498" damping="0.00605303" frictionloss="0.104451"/>
          <geom name="//unnamed_geom_79" class="visual" pos="0.00288446 4.54523e-06 0" quat="0.707107 0 0 -0.707107" material="thigh" mesh="thigh"/>
          <geom name="//unnamed_geom_80" class="collision" size="0.0648554 0.039911" pos="0.0417584 0 0" quat="0.5 0.5 -0.5 -0.5"/>
          <geom name="//unnamed_geom_81" class="collision" size="0.0374166 0.0299333 0.141" pos="0.0313188 0 -0.148434" quat="0.707107 0 0 -0.707107" type="box"/>
          <geom name="//unnamed_geom_82" class="visual" pos="0.104709 0 -0.299359" quat="1 0 0 0" material="drive" mesh="drive"/>
          <geom name="//unnamed_geom_83" class="collision" size="0.0498888 0.0698443" pos="0.031632 0 -0.299359" quat="0.707107 0 0.707107 0"/>
          <geom name="//unnamed_geom_84" class="reward_collision_sphere" size="0.079822" pos="0.026099 0 0"/>
          <body name="LH_SHANK" pos="0.10534 -0.000803306 -0.300354" quat="1 -0.000469095 0.000155814 -0.000175406">
            <inertial pos="0.00584562 0.054751 -0.084675" quat="0.993028 0.115141 -2.78097e-05 0.0252432" mass="0.588026" diaginertia="0.0127816 0.00549655 0.00144672"/>
            <joint name="LH_KFE" pos="0 0 0" axis="0.999999 0.000793131 0.000982447" range="-3.1268 3.14109" armature="0.0105458" damping="0.0059646" frictionloss="0.104084"/>
            <geom name="//unnamed_geom_85" class="visual" pos="0.000940553 -0.00501509 0" quat="-0.707107 0 0 -0.707107" material="shank" mesh="shank_r"/>
            <geom name="LH_kfe_act" class="collision" size="0.0598665 0.0199555" pos="0.0208792 0 0" quat="0.5 0.5 -0.5 -0.5"/>
            <geom name="//unnamed_geom_87" class="collision" size="0.0573711 0.0336749 0.0189577" pos="0.0208792 0.0516906 0" quat="0.5 0.5 -0.5 -0.5" type="box"/>
            <geom name="//unnamed_geom_88" class="visual" pos="0.0136239 0.0774494 -0.354998" quat="-0.382683 0 0 -0.92388" material="foot" mesh="foot"/>
            <geom name="LH_calf" class="collision" size="0.0174611 0.140938" pos="0.0136237 0.0790656 -0.177499" quat="0.707107 0 0 -0.707107"/>
            <geom name="LH_foot" class="foot" size="0.0316296" pos="0.0136237 0.0790656 -0.331365" quat="0.707107 0 0 -0.707107"/>
            <geom name="//unnamed_geom_91" class="reward_collision_sphere" size="0.0997776" pos="-0.052198 0 0"/>
            <geom name="//unnamed_geom_92" class="reward_collision_sphere" size="0.0498888" pos="0.0136237 0.0790656 -0.331365"/>
            <site name="LH_foot" class="foot" pos="0.0136237 0.0790656 -0.331365" quat="0.707107 0 0 -0.707107" size="0.00997776"/>
          </body>
        </body>
      </body>
      <body name="RH_HIP" pos="-0.314072 -0.0932469 0.000221361" quat="0.000278126 -0.000698741 -0.965885 -0.25897">
        <inertial pos="0.0588544 -0.0138529 -0.00937058" quat="-0.128011 0.709036 -0.135358 0.680117" mass="2.78824" diaginertia="0.007339 0.00291831 0.00432547"/>
        <joint name="RH_HAA" pos="0 0 0" axis="1 -0.000327933 0.000121787" range="-0.73268 0.478093" armature="0.0102175" damping="0.0116551" frictionloss="0.0952847"/>
        <geom name="//unnamed_geom_93" class="visual" pos="0 -0.000153633 2.52341e-05" quat="-0.258819 0.965926 0 0" material="hip_l" mesh="hip_l"/>
        <geom name="//unnamed_geom_94" class="visual" pos="0.0625332 -0.0739172 -0.043796" quat="-0.183013 0.683013 -0.683013 -0.183013" material="drive" mesh="drive"/>
        <geom name="//unnamed_geom_95" class="collision" size="0.0498888 0.0698443" pos="0.0625332 -0.0107517 -0.0072529" quat="0.353553 0.612372 -0.612372 0.353553"/>
        <body name="RH_THIGH" pos="0.0631983 -0.066034 -0.0444375" quat="-0.183275 0.682876 -0.683114 -0.182882">
          <inertial pos="0.0325645 0.000439595 -0.257612" quat="0.993002 -0.00480585 -0.0803924 0.0863752" mass="3.06616" diaginertia="0.0376299 0.017618 0.00543285"/>
          <joint name="RH_HFE" pos="0 0 0" axis="0.999998 -5.6693e-05 -0.0019786" range="-3.14539 3.16876" armature="0.00948407" damping="0.00730388" frictionloss="0.100916"/>
          <geom name="//unnamed_geom_96" class="visual" pos="0.00288446 4.54523e-06 0" quat="0.707107 0 0 -0.707107" material="thigh" mesh="thigh"/>
          <geom name="//unnamed_geom_97" class="collision" size="0.0648554 0.039911" pos="0.0417584 0 0" quat="0.5 0.5 0.5 0.5"/>
          <geom name="//unnamed_geom_98" class="collision" size="0.0374166 0.0299333 0.141" pos="0.0313188 0 -0.148434" quat="0.707107 0 0 0.707107" type="box"/>
          <geom name="//unnamed_geom_99" class="visual" pos="0.104709 0 -0.299359" quat="1 0 0 0" material="drive" mesh="drive"/>
          <geom name="//unnamed_geom_100" class="collision" size="0.0498888 0.0698443" pos="0.031632 0 -0.299359" quat="0.707107 0 0.707107 0"/>
          <geom name="//unnamed_geom_101" class="reward_collision_sphere" size="0.079822" pos="0.026099 0 0"/>
          <body name="RH_SHANK" pos="0.103599 0.00052063 -0.299345" quat="1 2.4718e-05 -3.17012e-07 -3.01723e-05">
            <inertial pos="0.00673157 -0.0544237 -0.0848445" quat="0.992886 -0.116326 -0.000990551 -0.0254035" mass="0.578739" diaginertia="0.0126227 0.00536793 0.00143131"/>
            <joint name="RH_KFE" pos="0 0 0" axis="0.999979 -0.00232167 0.00601871" stiffness="0.000905314" range="-3.11505 3.11952" armature="0.00983721" damping="0.00580808" frictionloss="0.0951449"/>
            <geom name="//unnamed_geom_102" class="visual" pos="0.000940558 0.0050151 0" quat="0.707107 0 0 -0.707107" material="shank_l" mesh="shank_l"/>
            <geom name="RH_kfe_act" class="collision" size="0.0598665 0.0199555" pos="0.0208792 0 0" quat="0.5 0.5 0.5 0.5"/>
            <geom name="//unnamed_geom_104" class="collision" size="0.0573711 0.0336749 0.0189577" pos="0.0208792 -0.0516906 0" quat="0.5 0.5 0.5 0.5" type="box"/>
            <geom name="//unnamed_geom_105" class="visual" pos="0.0136234 -0.0774494 -0.354998" quat="0.382683 0 0 -0.92388" material="foot" mesh="foot"/>
            <geom name="RH_calf" class="collision" size="0.0174611 0.140938" pos="0.0136237 -0.0790656 -0.177499" quat="0.707107 0 0 0.707107"/>
            <geom name="RH_foot" class="foot" size="0.028575" pos="0.0136237 -0.0790656 -0.331365" quat="0.707107 0 0 0.707107"/>
            <geom name="//unnamed_geom_108" class="reward_collision_sphere" size="0.0997776" pos="-0.052198 0 0"/>
            <geom name="//unnamed_geom_109" class="reward_collision_sphere" size="0.0498888" pos="0.0136237 -0.0790656 -0.331365"/>
            <site name="RH_foot" class="foot" pos="0.0136237 -0.0790656 -0.331365" quat="0.707107 0 0 0.707107" size="0.00997776"/>
          </body>
        </body>
      </body>
    </body>
  </worldbody>

  <contact>
    <pair class="/" geom1="floor" geom2="LF_foot" name="//unnamed_contact_0"/>
    <pair class="/" geom1="floor" geom2="RF_foot" name="//unnamed_contact_1"/>
    <pair class="/" geom1="floor" geom2="LH_foot" name="//unnamed_contact_2"/>
    <pair class="/" geom1="floor" geom2="RH_foot" name="//unnamed_contact_3"/>
  </contact>

  <actuator>
    <general name="LF_HAA" class="/" joint="LF_HAA" forcerange="-77.7123 77.7123" gainprm="80.4704" biasprm="0 -80.4704 -1.88556"/>
    <general name="LF_HFE" class="/" joint="LF_HFE" forcerange="-79.7307 79.7307" gainprm="80.4704" biasprm="0 -80.4704 -1.88556"/>
    <general name="LF_KFE" class="/" joint="LF_KFE" forcerange="-79.9968 79.9968" gainprm="80.4704" biasprm="0 -80.4704 -1.88556"/>
    <general name="RF_HAA" class="/" joint="RF_HAA" forcerange="-83.1499 83.1499" gainprm="80.4704" biasprm="0 -80.4704 -1.88556"/>
    <general name="RF_HFE" class="/" joint="RF_HFE" forcerange="-80.7751 80.7751" gainprm="80.4704" biasprm="0 -80.4704 -1.88556"/>
    <general name="RF_KFE" class="/" joint="RF_KFE" forcerange="-81.7851 81.7851" gainprm="80.4704" biasprm="0 -80.4704 -1.88556"/>
    <general name="LH_HAA" class="/" joint="LH_HAA" forcerange="-79.6815 79.6815" gainprm="80.4704" biasprm="0 -80.4704 -1.88556"/>
    <general name="LH_HFE" class="/" joint="LH_HFE" forcerange="-80.5946 80.5946" gainprm="80.4704" biasprm="0 -80.4704 -1.88556"/>
    <general name="LH_KFE" class="/" joint="LH_KFE" forcerange="-79.5495 79.5495" gainprm="80.4704" biasprm="0 -80.4704 -1.88556"/>
    <general name="RH_HAA" class="/" joint="RH_HAA" forcerange="-82.3936 82.3936" gainprm="80.4704" biasprm="0 -80.4704 -1.88556"/>
    <general name="RH_HFE" class="/" joint="RH_HFE" forcerange="-78.689 78.689" gainprm="80.4704" biasprm="0 -80.4704 -1.88556"/>
    <general name="RH_KFE" class="/" joint="RH_KFE" forcerange="-81.0544 81.0544" gainprm="80.4704" biasprm="0 -80.4704 -1.88556"/>
  </actuator>

  <sensor>
    <gyro site="imu" name="imu_angular_velocity"/>
    <velocimeter site="imu" name="imu_linear_velocity"/>
    <framelinvel objtype="site" objname="LF_foot" name="LF_foot_global_linear_velocity"/>
    <framelinvel objtype="site" objname="RF_foot" name="RF_foot_global_linear_velocity"/>
    <framelinvel objtype="site" objname="LH_foot" name="LH_foot_global_linear_velocity"/>
    <framelinvel objtype="site" objname="RH_foot" name="RH_foot_global_linear_velocity"/>
  </sensor>

  <keyframe>
    <key name="home" qpos="0 0 0.55 1 0 0 0 0 0.4 -0.8 0 -0.4 0.8 0 -0.4 0.8 0 0.4 -0.8"/>
  </keyframe>
</mujoco>
