<mujoco model="anymal_c">
  <compiler angle="radian" assetdir="assets" balanceinertia="true" inertiafromgeom="false"/>

  <option timestep="0.005" density="1.2" viscosity="2e-05"/>

  <size nkey="1"/>

  <visual>
    <quality shadowsize="8192"/>
    <map shadowclip="0.5"/>
  </visual>

  <default>
    <default class="/">
      <material specular="0" shininess="0.25"/>
      <geom contype="0" conaffinity="0" group="1" solref="-1000 -80"/>
      <site size="0.01 0.005 0.005" group="5"/>
      <general forcelimited="true" forcerange="-80 80" biastype="affine" gainprm="80" biasprm="0 -80 -2"/>
      <default class="anymal_c">
        <joint armature="0.01" damping="0.01" frictionloss="0.1"/>
        <default class="visual">
          <geom type="mesh" group="2"/>
          <default class="visual_zflip"/>
        </default>
        <default class="collision">
          <geom type="cylinder" group="3"/>
          <default class="foot">
            <geom size="0.03 0 0" type="sphere" condim="6" priority="1" friction="0.8 0.02 0.01" solimp="0.015 1 0.03"/>
          </default>
        </default>
      </default>
      <default class="reward_collision_sphere">
        <geom group="5" rgba="1 0 0 1"/>
      </default>
    </default>
  </default>

  <asset>
    <texture type="skybox" colorspace="auto" name="//unnamed_texture_0" builtin="gradient" rgb1="0.95 0.95 0.95" rgb2="0.95 0.95 0.95" width="100" height="600"/>
    <texture type="2d" colorspace="auto" name="texplane" builtin="checker" rgb1="0.345 0.575 0.748" rgb2="0.345 0.575 0.748" markrgb="1 1 1" width="512" height="512"/>
    <texture type="2d" colorspace="linear" name="base" file="base.png"/>
    <texture type="2d" colorspace="linear" name="top_shell" file="top_shell.png"/>
    <texture type="2d" colorspace="linear" name="bottom_shell" file="bottom_shell.png"/>
    <texture type="2d" colorspace="linear" name="remote" file="remote.png"/>
    <texture type="2d" colorspace="linear" name="hatch" file="hatch.png"/>
    <texture type="2d" colorspace="linear" name="handle" file="handle.png"/>
    <texture type="2d" colorspace="linear" name="face" file="face.png"/>
    <texture type="2d" colorspace="linear" name="battery" file="battery.png"/>
    <texture type="2d" colorspace="linear" name="lidar_cage" file="lidar_cage.png"/>
    <texture type="2d" colorspace="linear" name="depth_camera" file="depth_camera.png"/>
    <texture type="2d" colorspace="linear" name="wide_angle_camera" file="wide_angle_camera.png"/>
    <texture type="2d" colorspace="linear" name="lidar" file="lidar.png"/>
    <texture type="2d" colorspace="linear" name="drive" file="drive.png"/>
    <texture type="2d" colorspace="linear" name="hip_l" file="hip_l.png"/>
    <texture type="2d" colorspace="linear" name="shank_l" file="shank_l.png"/>
    <texture type="2d" colorspace="linear" name="foot" file="foot.png"/>
    <texture type="2d" colorspace="linear" name="thigh" file="thigh.png"/>
    <texture type="2d" colorspace="linear" name="shank_r" file="shank_r.png"/>
    <texture type="2d" colorspace="linear" name="hip_r" file="hip_r.png"/>
    <material name="MatPlane" class="/" texture="texplane" texuniform="true" texrepeat="2 2" specular="0.9" shininess="0.5"/>
    <material name="black_plastic" class="/" rgba="0.007 0.007 0.007 1"/>
    <material name="green" class="/" rgba="0.052 0.178 0.033 1"/>
    <material name="red" class="/" rgba="0.178 0.006 0.005 1"/>
    <material name="yellow" class="/" rgba="0.178 0.119 0.006 1"/>
    <material name="lwl" class="/" rgba="0.8 0.8 0.8 1"/>
    <material name="base" class="/" texture="base"/>
    <material name="top_shell" class="/" texture="top_shell"/>
    <material name="bottom_shell" class="/" texture="bottom_shell"/>
    <material name="hip_l" class="/" texture="hip_l"/>
    <material name="thigh" class="/" texture="thigh"/>
    <material name="shank_l" class="/" texture="shank_l"/>
    <material name="foot" class="/" texture="foot"/>
    <material name="hip_r" class="/" texture="hip_r"/>
    <material name="shank" class="/" texture="shank_r"/>
    <material name="hatch" class="/" texture="hatch"/>
    <material name="remote" class="/" texture="remote"/>
    <material name="handle" class="/" texture="handle"/>
    <material name="face" class="/" texture="face"/>
    <material name="depth_camera" class="/" texture="depth_camera"/>
    <material name="wide_angle_camera" class="/" texture="wide_angle_camera"/>
    <material name="battery" class="/" texture="battery"/>
    <material name="lidar_cage" class="/" texture="lidar_cage"/>
    <material name="lidar" class="/" texture="lidar"/>
    <material name="drive" class="/" texture="drive"/>
    <mesh name="base_0" class="/" file="base_0.obj"/>
    <mesh name="base_1" class="/" file="base_1.obj"/>
    <mesh name="base_2" class="/" file="base_2.obj"/>
    <mesh name="base_3" class="/" file="base_3.obj"/>
    <mesh name="base_4" class="/" file="base_4.obj"/>
    <mesh name="base_5" class="/" file="base_5.obj"/>
    <mesh name="top_shell" class="/" file="top_shell.obj"/>
    <mesh name="bottom_shell" class="/" file="bottom_shell.obj"/>
    <mesh name="remote" class="/" file="remote.obj"/>
    <mesh name="handle" class="/" file="handle.obj"/>
    <mesh name="face" class="/" file="face.obj"/>
    <mesh name="wide_angle_camera" class="/" file="wide_angle_camera.obj"/>
    <mesh name="depth_camera" class="/" file="depth_camera.obj"/>
    <mesh name="battery" class="/" file="battery.obj"/>
    <mesh name="lidar_cage" class="/" file="lidar_cage.obj"/>
    <mesh name="lidar" class="/" file="lidar.obj"/>
    <mesh name="drive" class="/" file="drive.obj"/>
    <mesh name="hip_l" class="/" file="hip_l.obj"/>
    <mesh name="thigh" class="/" file="thigh.obj"/>
    <mesh name="shank_l" class="/" file="shank_l.obj"/>
    <mesh name="foot" class="/" file="foot.obj"/>
    <mesh name="hip_r" class="/" file="hip_r.obj"/>
    <mesh name="hatch" class="/" file="hatch.obj"/>
    <mesh name="shank_r" class="/" file="shank_r.obj"/>
  </asset>

  <worldbody>
    <geom name="floor" class="/" size="100 100 0.125" type="plane" group="0" material="MatPlane"/>
    <light name="toplight_shadow" class="/" pos="0 0 5" dir="0.0990148 0.0990148 -0.990148" type="directional" ambient="0.04 0.04 0.04" diffuse="0.55 0.55 0.55" specular="0.12 0.12 0.12"/>
    <light name="toplight_fill" class="/" pos="0 0 5" dir="0.0990148 0.0990148 -0.990148" type="directional" castshadow="false" ambient="0.04 0.04 0.04" diffuse="0.3 0.3 0.3" specular="0.08 0.08 0.08"/>
    <body name="trunk" childclass="anymal_c" pos="-0.00430888 0.00127749 -0.00161518" quat="0.999999 0.000828847 0.000349736 0.000669756">
      <inertial pos="0.00273914 -0.00292472 0.0527239" quat="0.500013 0.49995 0.499976 0.500061" mass="23.2751" diaginertia="0.715922 0.851301 0.280028"/>
      <joint name="//unnamed_joint_0" type="free" armature="0" damping="0" frictionloss="0"/>
      <geom name="//unnamed_geom_1" class="visual" material="green" mesh="base_0"/>
      <geom name="//unnamed_geom_2" class="visual" material="yellow" mesh="base_1"/>
      <geom name="//unnamed_geom_3" class="visual" material="red" mesh="base_2"/>
      <geom name="//unnamed_geom_4" class="visual" material="black_plastic" mesh="base_3"/>
      <geom name="//unnamed_geom_5" class="visual" material="lwl" mesh="base_4"/>
      <geom name="//unnamed_geom_6" class="visual" material="base" mesh="base_5"/>
      <geom name="trunk_1" class="collision" size="0.306827 0.0740616 0.0952221" type="box"/>
      <geom name="trunk_2" class="collision" size="0.0952221 0.0767067" pos="0.226917 0.0753262 0" quat="0.707107 0 0.707107 0"/>
      <geom name="trunk_3" class="collision" size="0.0952221 0.0767067" pos="-0.226917 0.0753262 0" quat="0.707107 0 0.707107 0"/>
      <geom name="trunk_4" class="collision" size="0.0952221 0.0767067" pos="0.226917 -0.0753262 0" quat="0.707107 0 0.707107 0"/>
      <geom name="trunk_5" class="collision" size="0.0952221 0.0767067" pos="-0.226917 -0.0753262 0" quat="0.707107 0 0.707107 0"/>
      <geom name="//unnamed_geom_12" class="visual" material="top_shell" mesh="top_shell"/>
      <geom name="//unnamed_geom_13" class="visual" material="bottom_shell" mesh="bottom_shell"/>
      <geom name="//unnamed_geom_14" class="visual" material="remote" mesh="remote"/>
      <geom name="//unnamed_geom_15" class="visual" material="handle" mesh="handle"/>
      <geom name="//unnamed_geom_16" class="visual" pos="0.432446 0 0" quat="1 0 0 0" material="face" mesh="face"/>
      <geom name="trunk_6" class="collision" size="0.0581913 0.0740616 0.0952221" pos="0.489827 0 0" type="box"/>
      <geom name="//unnamed_geom_18" class="collision" size="0.0952221 0.0581913" pos="0.489827 0.0753262 0" quat="0.707107 0 0.707107 0"/>
      <geom name="//unnamed_geom_19" class="collision" size="0.0952221 0.0581913" pos="0.489827 -0.0753262 0" quat="0.707107 0 0.707107 0"/>
      <geom name="//unnamed_geom_20" class="visual" pos="0.481638 0 -0.0308834" quat="0.965926 0 0.258819 0" material="depth_camera" mesh="depth_camera"/>
      <geom name="//unnamed_geom_21" class="visual" pos="0.535211 0 0.0157886" material="wide_angle_camera" mesh="wide_angle_camera"/>
      <geom name="//unnamed_geom_22" class="visual_zflip" pos="-0.432446 0 0" quat="0 0 0 1" material="face" mesh="face"/>
      <geom name="trunk_7" class="collision" size="0.0581913 0.0740616 0.0952221" pos="-0.489827 0 0" quat="0 0 0 1" type="box"/>
      <geom name="//unnamed_geom_24" class="collision" size="0.0952221 0.0581913" pos="-0.489827 -0.0753262 0" quat="0 -0.707107 0 0.707107"/>
      <geom name="//unnamed_geom_25" class="collision" size="0.0952221 0.0581913" pos="-0.489827 0.0753262 0" quat="0 -0.707107 0 0.707107"/>
      <geom name="//unnamed_geom_26" class="visual" pos="-0.481638 0 -0.0308834" quat="0 -0.258819 0 0.965926" material="depth_camera" mesh="depth_camera"/>
      <geom name="//unnamed_geom_27" class="visual_zflip" pos="-0.535211 0 0.0157886" quat="0 0 0 1" material="wide_angle_camera" mesh="wide_angle_camera"/>
      <geom name="//unnamed_geom_28" class="visual" material="battery" mesh="battery"/>
      <geom name="//unnamed_geom_29" class="visual" pos="0 0.0827085 0.0305521" quat="0.683013 -0.183013 0.183013 0.683013" material="depth_camera" mesh="depth_camera"/>
      <geom name="//unnamed_geom_30" class="visual" pos="0 -0.0827085 0.0305521" quat="0.683013 0.183013 0.183013 -0.683013" material="depth_camera" mesh="depth_camera"/>
      <geom name="//unnamed_geom_31" class="visual" pos="-0.37976 0 0.0775194" quat="1 0 0 0" material="lidar_cage" mesh="lidar_cage"/>
      <geom name="trunk_8" class="collision" size="0.0740616 0.0634814" pos="-0.37976 0 0.140801"/>
      <geom name="//unnamed_geom_33" class="visual" pos="-0.37976 1.28835e-05 0.149976" quat="0.707107 0 0 -0.707107" material="lidar" mesh="lidar"/>
      <geom name="//unnamed_geom_34" class="visual" pos="0.312884 0.111906 3.69207e-10" quat="0.258819 0.965926 0 0" material="drive" mesh="drive"/>
      <geom name="//unnamed_geom_35" class="visual" pos="0.312884 -0.111906 -3.69207e-10" quat="0.258819 -0.965926 0 0" material="drive" mesh="drive"/>
      <geom name="//unnamed_geom_36" class="visual" pos="-0.312884 0.111906 -3.69207e-10" quat="0 0 0.965926 -0.258819" material="drive" mesh="drive"/>
      <geom name="//unnamed_geom_37" class="visual" pos="-0.312884 -0.111906 3.69207e-10" quat="0 0 -0.965926 -0.258819" material="drive" mesh="drive"/>
      <geom name="//unnamed_geom_38" class="visual" pos="0.121022 0 0.0769921" quat="1 0 0 0" material="hatch" mesh="hatch"/>
      <geom name="//unnamed_geom_39" class="reward_collision_sphere" size="0.126963"/>
      <geom name="//unnamed_geom_40" class="reward_collision_sphere" size="0.126963" pos="0.469483 0 0"/>
      <geom name="//unnamed_geom_41" class="reward_collision_sphere" size="0.126963" pos="-0.469483 0 0"/>
      <site name="imu" pos="0.270059 -0.00226882 0.0774304" size="0.0105802"/>
      <camera name="track" pos="0 -2.15218 0" quat="0.707107 0.707107 0 0" mode="trackcom"/>
      <camera name="ego_camera" pos="0.469483 0 -0.0421874" quat="-0.5 -0.5 0.5 0.5"/>
      <body name="LF_HIP" pos="0.316079 0.112971 -0.000100018" quat="0.258304 0.966062 0.00140832 0.000988393">
        <inertial pos="0.0643003 -0.0174835 -0.00818532" quat="-0.124755 0.709944 -0.134665 0.679913" mass="3.16184" diaginertia="0.00694988 0.00719097 0.00413196"/>
        <joint name="LF_HAA" pos="0 0 0" axis="0.999388 0.0280378 -0.0209105" stiffness="0.021485" range="-0.754932 0.4837" armature="0.0135207" damping="0.0237605" frictionloss="0.107954"/>
        <geom name="//unnamed_geom_42" class="visual" pos="0 2.17188e-05 -3.56729e-06" quat="0.258819 -0.965926 0 0" material="hip_l" mesh="hip_l"/>
        <geom name="//unnamed_geom_43" class="visual" pos="0.0624934 -0.0761482 -0.0438059" quat="0.183013 -0.683013 0.683013 0.183013" material="drive" mesh="drive"/>
        <geom name="//unnamed_geom_44" class="collision" size="0.0529012 0.0740616" pos="0.0624934 -0.0128698 -0.0072826" quat="-0.353553 -0.612372 0.612372 -0.353553"/>
        <body name="LF_THIGH" pos="0.0635738 -0.0788697 -0.043343" quat="0.183341 -0.683029 0.682925 0.182951">
          <inertial pos="0.0313396 0.000319725 -0.252904" quat="0.993408 -0.00305624 -0.0794289 0.0825971" mass="3.61163" diaginertia="0.0368658 0.0422153 0.0053095"/>
          <joint name="LF_HFE" pos="0 0 0" axis="0.999998 -0.00164578 0.00112528" stiffness="0.00471826" range="-3.12249 3.13452" armature="0.00867524" damping="0.00972587" frictionloss="0.108009"/>
          <geom name="//unnamed_geom_45" class="visual" pos="-0.000652451 -1.02811e-06 0" quat="0.707107 0 0 -0.707107" material="thigh" mesh="thigh"/>
          <geom name="//unnamed_geom_46" class="collision" size="0.0687715 0.0423209" pos="0.0417318 0 0" quat="0.5 0.5 -0.5 -0.5"/>
          <geom name="//unnamed_geom_47" class="collision" size="0.0396759 0.0317407 0.149514" pos="0.0312989 0 -0.149042" quat="0.707107 0 0 -0.707107" type="box"/>
          <geom name="//unnamed_geom_48" class="visual" pos="0.104643 0 -0.300585" quat="1 0 0 0" material="drive" mesh="drive"/>
          <geom name="//unnamed_geom_49" class="collision" size="0.0529012 0.0740616" pos="0.0316119 0 -0.300585" quat="0.707107 0 0.707107 0"/>
          <geom name="//unnamed_geom_50" class="reward_collision_sphere" size="0.0846419" pos="0.0260824 0 0"/>
          <body name="LF_SHANK" pos="0.105947 0.00645413 -0.303179" quat="1 0.000954448 -0.000106105 -0.000183598">
            <inertial pos="0.00622457 -0.0681295 -0.0844321" quat="0.992521 -0.120662 -0.0174183 -0.00626235" mass="0.684468" diaginertia="0.0128295 0.0130979 0.00151133"/>
            <joint name="LF_KFE" pos="0 0 0" axis="0.999947 0.00851554 0.00585492" range="-3.14799 3.09178" armature="0.0102196" damping="0.0178163" frictionloss="0.115952"/>
            <geom name="//unnamed_geom_51" class="visual" pos="-0.00021275 -0.00113439 0" quat="0.707107 0 0 -0.707107" material="shank_l" mesh="shank_l"/>
            <geom name="LF_kfe_act" class="collision" size="0.0634814 0.0211605" pos="0.0208659 0 0" quat="0.5 0.5 -0.5 -0.5"/>
            <geom name="//unnamed_geom_53" class="collision" size="0.0608353 0.0357083 0.0201024" pos="0.0208659 -0.061874 0" quat="0.5 0.5 -0.5 -0.5" type="box"/>
            <geom name="//unnamed_geom_54" class="visual" pos="0.0136151 -0.0950076 -0.356452" quat="0.382683 0 0 -0.92388" material="foot" mesh="foot"/>
            <geom name="LF_calf" class="collision" size="0.0185154 0.149448" pos="0.013615 -0.094642 -0.178226" quat="0.707107 0 0 -0.707107"/>
            <geom name="LF_foot" class="foot" size="0.0301483" pos="0.013615 -0.094642 -0.332722" quat="0.707107 0 0 -0.707107"/>
            <geom name="//unnamed_geom_57" class="reward_collision_sphere" size="0.105802" pos="-0.0521648 0 0"/>
            <geom name="//unnamed_geom_58" class="reward_collision_sphere" size="0.0529012" pos="0.013615 -0.094642 -0.332722"/>
            <site name="LF_foot" class="foot" pos="0.013615 -0.094642 -0.332722" quat="0.707107 0 0 -0.707107" size="0.0105802"/>
          </body>
        </body>
      </body>
      <body name="RF_HIP" pos="0.319215 -0.118164 0.00308823" quat="0.258099 -0.966118 0.00103275 -0.000541011">
        <inertial pos="0.0532503 0.0189184 -0.00393365" quat="0.132697 0.677068 0.127846 0.712479" mass="3.15554" diaginertia="0.00663082 0.00672085 0.00399074"/>
        <joint name="RF_HAA" pos="0 0 0" axis="0.999797 0.0110392 0.016867" range="-0.390281 0.766392" armature="0.0102288" damping="0.0212359" frictionloss="0.123962"/>
        <geom name="//unnamed_geom_59" class="visual" pos="0 -2.17186e-05 -3.56728e-06" quat="0.258819 0.965926 0 0" material="hip_r" mesh="hip_r"/>
        <geom name="//unnamed_geom_60" class="visual" pos="0.0624934 0.0761482 -0.0438059" quat="0.183013 0.683013 0.683013 -0.183013" material="drive" mesh="drive"/>
        <geom name="//unnamed_geom_61" class="collision" size="0.0529012 0.0740616" pos="0.0624934 0.0128698 -0.0072826" quat="-0.353553 0.612372 0.612372 0.353553"/>
        <body name="RF_THIGH" pos="0.0631367 0.0769662 -0.0449141" quat="0.182828 0.682626 0.683566 -0.182572">
          <inertial pos="0.0319939 -0.00704527 -0.256966" quat="0.992919 -0.00528255 -0.0780999 0.0893556" mass="3.72625" diaginertia="0.0371291 0.0453521 0.00555304"/>
          <joint name="RF_HFE" pos="0 0 0" axis="0.999985 -0.00518567 -0.00181258" stiffness="0.00507412" range="-3.18768 3.14579" armature="0.00939622" damping="0.0206185" frictionloss="0.118213"/>
          <geom name="//unnamed_geom_62" class="visual" pos="-0.000652451 -1.02811e-06 0" quat="0.707107 0 0 -0.707107" material="thigh" mesh="thigh"/>
          <geom name="//unnamed_geom_63" class="collision" size="0.0687715 0.0423209" pos="0.0417318 0 0" quat="0.5 0.5 0.5 0.5"/>
          <geom name="//unnamed_geom_64" class="collision" size="0.0396759 0.0317407 0.149514" pos="0.0312989 0 -0.149042" quat="0.707107 0 0 0.707107" type="box"/>
          <geom name="//unnamed_geom_65" class="visual" pos="0.104643 0 -0.300585" quat="1 0 0 0" material="drive" mesh="drive"/>
          <geom name="//unnamed_geom_66" class="collision" size="0.0529012 0.0740616" pos="0.0316119 0 -0.300585" quat="0.707107 0 0.707107 0"/>
          <geom name="//unnamed_geom_67" class="reward_collision_sphere" size="0.0846419" pos="0.0260824 0 0"/>
          <body name="RF_SHANK" pos="0.102297 0.00233838 -0.304243" quat="0.999995 0.000784111 -0.00282478 0.000846108">
            <inertial pos="-0.00148838 0.0671342 -0.0884577" quat="0.992432 0.1215 -0.00641808 0.0165748" mass="0.706175" diaginertia="0.0122298 0.0123351 0.0013105"/>
            <joint name="RF_KFE" pos="0 0 0" axis="0.999967 -0.00385686 0.00718835" range="-3.0347 3.10535" armature="0.0118971" damping="0" frictionloss="0.0841439"/>
            <geom name="//unnamed_geom_68" class="visual" pos="-0.000212749 0.00113439 0" quat="0.707107 0 0 0.707107" material="shank" mesh="shank_r"/>
            <geom name="RF_kfe_act" class="collision" size="0.0634814 0.0211605" pos="0.0208659 0 0" quat="0.5 0.5 0.5 0.5"/>
            <geom name="//unnamed_geom_70" class="collision" size="0.0608353 0.0357083 0.0201024" pos="0.0208659 0.061874 0" quat="0.5 0.5 0.5 0.5" type="box"/>
            <geom name="//unnamed_geom_71" class="visual" pos="0.013615 0.0950076 -0.356452" quat="0.382683 0 0 0.92388" material="foot" mesh="foot"/>
            <geom name="RF_calf" class="collision" size="0.0185154 0.149448" pos="0.013615 0.094642 -0.178226" quat="0.707107 0 0 0.707107"/>
            <geom name="RF_foot" class="foot" size="0.0293664" pos="0.013615 0.094642 -0.332722" quat="0.707107 0 0 0.707107"/>
            <geom name="//unnamed_geom_74" class="reward_collision_sphere" size="0.105802" pos="-0.0521648 0 0"/>
            <geom name="//unnamed_geom_75" class="reward_collision_sphere" size="0.0529012" pos="0.013615 0.094642 -0.332722"/>
            <site name="RF_foot" class="foot" pos="0.013615 0.094642 -0.332722" quat="0.707107 0 0 0.707107" size="0.0105802"/>
          </body>
        </body>
      </body>
      <body name="LH_HIP" pos="-0.320205 0.116037 0.000435071" quat="0.000549519 0.000340205 0.965861 -0.259061">
        <inertial pos="0.0538391 0.0233137 -0.00962689" quat="0.149372 0.687221 0.128472 0.699221" mass="3.30251" diaginertia="0.0071075 0.00710989 0.00453087"/>
        <joint name="LH_HAA" pos="0 0 0" axis="0.99999 -0.000433535 -0.00438278" stiffness="0.000504026" range="-0.524427 0.747875" armature="0.0104847" damping="0.0072377" frictionloss="0.0972017"/>
        <geom name="//unnamed_geom_76" class="visual" pos="0 -2.17186e-05 -3.56728e-06" quat="-0.258819 -0.965926 0 0" material="hip_r" mesh="hip_r"/>
        <geom name="//unnamed_geom_77" class="visual" pos="0.0624934 0.0761482 -0.0438059" quat="0.183013 0.683013 0.683013 -0.183013" material="drive" mesh="drive"/>
        <geom name="//unnamed_geom_78" class="collision" size="0.0529012 0.0740616" pos="0.0624934 0.0128698 -0.0072826" quat="-0.353553 0.612372 0.612372 0.353553"/>
        <body name="LH_THIGH" pos="0.0619357 0.0791454 -0.0471573" quat="0.183685 0.682818 0.682898 -0.183492">
          <inertial pos="0.0345079 -0.00567861 -0.257443" quat="0.993356 -0.0158884 -0.0797015 0.0814832" mass="3.64856" diaginertia="0.0371331 0.0428037 0.00576063"/>
          <joint name="LH_HFE" pos="0 0 0" axis="0.999721 -0.0226952 0.00648569" stiffness="0.0101706" range="-3.17368 3.11936" armature="0.00790795" damping="0.0166177" frictionloss="0.0872038"/>
          <geom name="//unnamed_geom_79" class="visual" pos="-0.000652451 -1.02811e-06 0" quat="0.707107 0 0 -0.707107" material="thigh" mesh="thigh"/>
          <geom name="//unnamed_geom_80" class="collision" size="0.0687715 0.0423209" pos="0.0417318 0 0" quat="0.5 0.5 -0.5 -0.5"/>
          <geom name="//unnamed_geom_81" class="collision" size="0.0396759 0.0317407 0.149514" pos="0.0312989 0 -0.149042" quat="0.707107 0 0 -0.707107" type="box"/>
          <geom name="//unnamed_geom_82" class="visual" pos="0.104643 0 -0.300585" quat="1 0 0 0" material="drive" mesh="drive"/>
          <geom name="//unnamed_geom_83" class="collision" size="0.0529012 0.0740616" pos="0.0316119 0 -0.300585" quat="0.707107 0 0.707107 0"/>
          <geom name="//unnamed_geom_84" class="reward_collision_sphere" size="0.0846419" pos="0.0260824 0 0"/>
          <body name="LH_SHANK" pos="0.105672 -0.00353438 -0.294057" quat="0.999995 -0.00307382 0.000474479 0.000933937">
            <inertial pos="0.00771889 0.0659133 -0.0923587" quat="0.992977 0.115508 -0.00145692 0.0255261" mass="0.73266" diaginertia="0.0123973 0.0131182 0.00146023"/>
            <joint name="LH_KFE" pos="0 0 0" axis="0.999984 -0.00152936 -0.00548454" range="-3.1011 3.16102" armature="0.0117419" damping="0.00792339" frictionloss="0.120166"/>
            <geom name="//unnamed_geom_85" class="visual" pos="-0.000212749 0.00113439 0" quat="-0.707107 0 0 -0.707107" material="shank" mesh="shank_r"/>
            <geom name="LH_kfe_act" class="collision" size="0.0634814 0.0211605" pos="0.0208659 0 0" quat="0.5 0.5 -0.5 -0.5"/>
            <geom name="//unnamed_geom_87" class="collision" size="0.0608353 0.0357083 0.0201024" pos="0.0208659 0.061874 0" quat="0.5 0.5 -0.5 -0.5" type="box"/>
            <geom name="//unnamed_geom_88" class="visual" pos="0.013615 0.0950076 -0.356452" quat="-0.382683 0 0 -0.92388" material="foot" mesh="foot"/>
            <geom name="LH_calf" class="collision" size="0.0185154 0.149448" pos="0.013615 0.094642 -0.178226" quat="0.707107 0 0 -0.707107"/>
            <geom name="LH_foot" class="foot" size="0.0354646" pos="0.013615 0.094642 -0.332722" quat="0.707107 0 0 -0.707107"/>
            <geom name="//unnamed_geom_91" class="reward_collision_sphere" size="0.105802" pos="-0.0521648 0 0"/>
            <geom name="//unnamed_geom_92" class="reward_collision_sphere" size="0.0529012" pos="0.013615 0.094642 -0.332722"/>
            <site name="LH_foot" class="foot" pos="0.013615 0.094642 -0.332722" quat="0.707107 0 0 -0.707107" size="0.0105802"/>
          </body>
        </body>
      </body>
      <body name="RH_HIP" pos="-0.307403 -0.110367 -0.00099988" quat="0.000438014 -0.000404254 -0.965959 -0.258696">
        <inertial pos="0.0570312 -0.016481 -0.00974754" quat="-0.117384 0.711976 -0.110032 0.683524" mass="3.20631" diaginertia="0.00698736 0.00677995 0.00411912"/>
        <joint name="RH_HAA" pos="0 0 0" axis="0.999558 -0.00840218 0.0285102" range="-0.732965 0.527681" armature="0.00986982" damping="0.0113349" frictionloss="0.107479"/>
        <geom name="//unnamed_geom_93" class="visual" pos="0 2.17188e-05 -3.56729e-06" quat="-0.258819 0.965926 0 0" material="hip_l" mesh="hip_l"/>
        <geom name="//unnamed_geom_94" class="visual" pos="0.0624934 -0.0761482 -0.0438059" quat="-0.183013 0.683013 -0.683013 -0.183013" material="drive" mesh="drive"/>
        <geom name="//unnamed_geom_95" class="collision" size="0.0529012 0.0740616" pos="0.0624934 -0.0128698 -0.0072826" quat="0.353553 0.612372 -0.612372 0.353553"/>
        <body name="RH_THIGH" pos="0.0650785 -0.0793486 -0.0486797" quat="-0.182456 0.683436 -0.68263 -0.183417">
          <inertial pos="0.0345711 -0.0019037 -0.25711" quat="0.989776 0.0158626 -0.102033 0.0983955" mass="3.52551" diaginertia="0.0368238 0.041227 0.00498356"/>
          <joint name="RH_HFE" pos="0 0 0" axis="0.999921 0.00407547 -0.0118746" stiffness="0.0105166" range="-3.1409 3.17386" armature="0.00891059" damping="0.0288944" frictionloss="0.1042"/>
          <geom name="//unnamed_geom_96" class="visual" pos="-0.000652451 -1.02811e-06 0" quat="0.707107 0 0 -0.707107" material="thigh" mesh="thigh"/>
          <geom name="//unnamed_geom_97" class="collision" size="0.0687715 0.0423209" pos="0.0417318 0 0" quat="0.5 0.5 0.5 0.5"/>
          <geom name="//unnamed_geom_98" class="collision" size="0.0396759 0.0317407 0.149514" pos="0.0312989 0 -0.149042" quat="0.707107 0 0 0.707107" type="box"/>
          <geom name="//unnamed_geom_99" class="visual" pos="0.104643 0 -0.300585" quat="1 0 0 0" material="drive" mesh="drive"/>
          <geom name="//unnamed_geom_100" class="collision" size="0.0529012 0.0740616" pos="0.0316119 0 -0.300585" quat="0.707107 0 0.707107 0"/>
          <geom name="//unnamed_geom_101" class="reward_collision_sphere" size="0.0846419" pos="0.0260824 0 0"/>
          <body name="RH_SHANK" pos="0.103713 -0.000591602 -0.301531" quat="1 7.37528e-05 0.000270299 -0.0001984">
            <inertial pos="0.00987056 -0.0597963 -0.0903774" quat="0.993297 -0.113459 -0.00615294 -0.0212067" mass="0.649873" diaginertia="0.0124721 0.0123842 0.00141218"/>
            <joint name="RH_KFE" pos="0 0 0" axis="1 -8.7828e-05 5.47585e-07" range="-3.1615 3.03276" armature="0.0104522" damping="0.0164747" frictionloss="0.0763792"/>
            <geom name="//unnamed_geom_102" class="visual" pos="-0.00021275 -0.00113439 0" quat="0.707107 0 0 -0.707107" material="shank_l" mesh="shank_l"/>
            <geom name="RH_kfe_act" class="collision" size="0.0634814 0.0211605" pos="0.0208659 0 0" quat="0.5 0.5 0.5 0.5"/>
            <geom name="//unnamed_geom_104" class="collision" size="0.0608353 0.0357083 0.0201024" pos="0.0208659 -0.061874 0" quat="0.5 0.5 0.5 0.5" type="box"/>
            <geom name="//unnamed_geom_105" class="visual" pos="0.0136151 -0.0950076 -0.356452" quat="0.382683 0 0 -0.92388" material="foot" mesh="foot"/>
            <geom name="RH_calf" class="collision" size="0.0185154 0.149448" pos="0.013615 -0.094642 -0.178226" quat="0.707107 0 0 0.707107"/>
            <geom name="RH_foot" class="foot" size="0.0255169" pos="0.013615 -0.094642 -0.332722" quat="0.707107 0 0 0.707107"/>
            <geom name="//unnamed_geom_108" class="reward_collision_sphere" size="0.105802" pos="-0.0521648 0 0"/>
            <geom name="//unnamed_geom_109" class="reward_collision_sphere" size="0.0529012" pos="0.013615 -0.094642 -0.332722"/>
            <site name="RH_foot" class="foot" pos="0.013615 -0.094642 -0.332722" quat="0.707107 0 0 0.707107" size="0.0105802"/>
          </body>
        </body>
      </body>
    </body>
  </worldbody>

  <contact>
    <pair class="/" geom1="floor" geom2="LF_foot" name="//unnamed_contact_0"/>
    <pair class="/" geom1="floor" geom2="RF_foot" name="//unnamed_contact_1"/>
    <pair class="/" geom1="floor" geom2="LH_foot" name="//unnamed_contact_2"/>
    <pair class="/" geom1="floor" geom2="RH_foot" name="//unnamed_contact_3"/>
  </contact>

  <actuator>
    <general name="LF_HAA" class="/" joint="LF_HAA" forcerange="-83.9768 83.9768" gainprm="85.5448" biasprm="0 -85.5448 -2.24454"/>
    <general name="LF_HFE" class="/" joint="LF_HFE" forcerange="-95.6557 95.6557" gainprm="85.5448" biasprm="0 -85.5448 -2.24454"/>
    <general name="LF_KFE" class="/" joint="LF_KFE" forcerange="-87.7389 87.7389" gainprm="85.5448" biasprm="0 -85.5448 -2.24454"/>
    <general name="RF_HAA" class="/" joint="RF_HAA" forcerange="-82.8387 82.8387" gainprm="85.5448" biasprm="0 -85.5448 -2.24454"/>
    <general name="RF_HFE" class="/" joint="RF_HFE" forcerange="-95.1294 95.1294" gainprm="85.5448" biasprm="0 -85.5448 -2.24454"/>
    <general name="RF_KFE" class="/" joint="RF_KFE" forcerange="-82.7921 82.7921" gainprm="85.5448" biasprm="0 -85.5448 -2.24454"/>
    <general name="LH_HAA" class="/" joint="LH_HAA" forcerange="-83.427 83.427" gainprm="85.5448" biasprm="0 -85.5448 -2.24454"/>
    <general name="LH_HFE" class="/" joint="LH_HFE" forcerange="-81.8764 81.8764" gainprm="85.5448" biasprm="0 -85.5448 -2.24454"/>
    <general name="LH_KFE" class="/" joint="LH_KFE" forcerange="-85.7776 85.7776" gainprm="85.5448" biasprm="0 -85.5448 -2.24454"/>
    <general name="RH_HAA" class="/" joint="RH_HAA" forcerange="-82.4816 82.4816" gainprm="85.5448" biasprm="0 -85.5448 -2.24454"/>
    <general name="RH_HFE" class="/" joint="RH_HFE" forcerange="-91.5333 91.5333" gainprm="85.5448" biasprm="0 -85.5448 -2.24454"/>
    <general name="RH_KFE" class="/" joint="RH_KFE" forcerange="-105.426 105.426" gainprm="85.5448" biasprm="0 -85.5448 -2.24454"/>
  </actuator>

  <sensor>
    <gyro site="imu" name="imu_angular_velocity"/>
    <velocimeter site="imu" name="imu_linear_velocity"/>
    <framelinvel objtype="site" objname="LF_foot" name="LF_foot_global_linear_velocity"/>
    <framelinvel objtype="site" objname="RF_foot" name="RF_foot_global_linear_velocity"/>
    <framelinvel objtype="site" objname="LH_foot" name="LH_foot_global_linear_velocity"/>
    <framelinvel objtype="site" objname="RH_foot" name="RH_foot_global_linear_velocity"/>
  </sensor>

  <keyframe>
    <key name="home" qpos="0 0 0.55 1 0 0 0 0 0.4 -0.8 0 -0.4 0.8 0 -0.4 0.8 0 0.4 -0.8"/>
  </keyframe>
</mujoco>
