<mujoco model="anymal_c">
  <compiler angle="radian" assetdir="assets" balanceinertia="true" inertiafromgeom="false"/>

  <option timestep="0.005" density="1.2" viscosity="2e-05"/>

  <size nkey="1"/>

  <visual>
    <quality shadowsize="8192"/>
    <map shadowclip="0.5"/>
  </visual>

  <default>
    <default class="/">
      <material specular="0" shininess="0.25"/>
      <geom contype="0" conaffinity="0" group="1" solref="-1000 -80"/>
      <site size="0.01 0.005 0.005" group="5"/>
      <general forcelimited="true" forcerange="-80 80" biastype="affine" gainprm="80" biasprm="0 -80 -2"/>
      <default class="anymal_c">
        <joint armature="0.01" damping="0.01" frictionloss="0.1"/>
        <default class="visual">
          <geom type="mesh" group="2"/>
          <default class="visual_zflip"/>
        </default>
        <default class="collision">
          <geom type="cylinder" group="3"/>
          <default class="foot">
            <geom size="0.03 0 0" type="sphere" condim="6" priority="1" friction="0.8 0.02 0.01" solimp="0.015 1 0.03"/>
          </default>
        </default>
      </default>
      <default class="reward_collision_sphere">
        <geom group="5" rgba="1 0 0 1"/>
      </default>
    </default>
  </default>

  <asset>
    <texture type="skybox" colorspace="auto" name="//unnamed_texture_0" builtin="gradient" rgb1="0.95 0.95 0.95" rgb2="0.95 0.95 0.95" width="100" height="600"/>
    <texture type="2d" colorspace="auto" name="texplane" builtin="checker" rgb1="0.345 0.575 0.748" rgb2="0.345 0.575 0.748" markrgb="1 1 1" width="512" height="512"/>
    <texture type="2d" colorspace="linear" name="base" file="base.png"/>
    <texture type="2d" colorspace="linear" name="top_shell" file="top_shell.png"/>
    <texture type="2d" colorspace="linear" name="bottom_shell" file="bottom_shell.png"/>
    <texture type="2d" colorspace="linear" name="remote" file="remote.png"/>
    <texture type="2d" colorspace="linear" name="hatch" file="hatch.png"/>
    <texture type="2d" colorspace="linear" name="handle" file="handle.png"/>
    <texture type="2d" colorspace="linear" name="face" file="face.png"/>
    <texture type="2d" colorspace="linear" name="battery" file="battery.png"/>
    <texture type="2d" colorspace="linear" name="lidar_cage" file="lidar_cage.png"/>
    <texture type="2d" colorspace="linear" name="depth_camera" file="depth_camera.png"/>
    <texture type="2d" colorspace="linear" name="wide_angle_camera" file="wide_angle_camera.png"/>
    <texture type="2d" colorspace="linear" name="lidar" file="lidar.png"/>
    <texture type="2d" colorspace="linear" name="drive" file="drive.png"/>
    <texture type="2d" colorspace="linear" name="hip_l" file="hip_l.png"/>
    <texture type="2d" colorspace="linear" name="shank_l" file="shank_l.png"/>
    <texture type="2d" colorspace="linear" name="foot" file="foot.png"/>
    <texture type="2d" colorspace="linear" name="thigh" file="thigh.png"/>
    <texture type="2d" colorspace="linear" name="shank_r" file="shank_r.png"/>
    <texture type="2d" colorspace="linear" name="hip_r" file="hip_r.png"/>
    <material name="MatPlane" class="/" texture="texplane" texuniform="true" texrepeat="2 2" specular="0.9" shininess="0.5"/>
    <material name="black_plastic" class="/" rgba="0.007 0.007 0.007 1"/>
    <material name="green" class="/" rgba="0.052 0.178 0.033 1"/>
    <material name="red" class="/" rgba="0.178 0.006 0.005 1"/>
    <material name="yellow" class="/" rgba="0.178 0.119 0.006 1"/>
    <material name="lwl" class="/" rgba="0.8 0.8 0.8 1"/>
    <material name="base" class="/" texture="base"/>
    <material name="top_shell" class="/" texture="top_shell"/>
    <material name="bottom_shell" class="/" texture="bottom_shell"/>
    <material name="hip_l" class="/" texture="hip_l"/>
    <material name="thigh" class="/" texture="thigh"/>
    <material name="shank_l" class="/" texture="shank_l"/>
    <material name="foot" class="/" texture="foot"/>
    <material name="hip_r" class="/" texture="hip_r"/>
    <material name="shank" class="/" texture="shank_r"/>
    <material name="hatch" class="/" texture="hatch"/>
    <material name="remote" class="/" texture="remote"/>
    <material name="handle" class="/" texture="handle"/>
    <material name="face" class="/" texture="face"/>
    <material name="depth_camera" class="/" texture="depth_camera"/>
    <material name="wide_angle_camera" class="/" texture="wide_angle_camera"/>
    <material name="battery" class="/" texture="battery"/>
    <material name="lidar_cage" class="/" texture="lidar_cage"/>
    <material name="lidar" class="/" texture="lidar"/>
    <material name="drive" class="/" texture="drive"/>
    <mesh name="base_0" class="/" file="base_0.obj"/>
    <mesh name="base_1" class="/" file="base_1.obj"/>
    <mesh name="base_2" class="/" file="base_2.obj"/>
    <mesh name="base_3" class="/" file="base_3.obj"/>
    <mesh name="base_4" class="/" file="base_4.obj"/>
    <mesh name="base_5" class="/" file="base_5.obj"/>
    <mesh name="top_shell" class="/" file="top_shell.obj"/>
    <mesh name="bottom_shell" class="/" file="bottom_shell.obj"/>
    <mesh name="remote" class="/" file="remote.obj"/>
    <mesh name="handle" class="/" file="handle.obj"/>
    <mesh name="face" class="/" file="face.obj"/>
    <mesh name="wide_angle_camera" class="/" file="wide_angle_camera.obj"/>
    <mesh name="depth_camera" class="/" file="depth_camera.obj"/>
    <mesh name="battery" class="/" file="battery.obj"/>
    <mesh name="lidar_cage" class="/" file="lidar_cage.obj"/>
    <mesh name="lidar" class="/" file="lidar.obj"/>
    <mesh name="drive" class="/" file="drive.obj"/>
    <mesh name="hip_l" class="/" file="hip_l.obj"/>
    <mesh name="thigh" class="/" file="thigh.obj"/>
    <mesh name="shank_l" class="/" file="shank_l.obj"/>
    <mesh name="foot" class="/" file="foot.obj"/>
    <mesh name="hip_r" class="/" file="hip_r.obj"/>
    <mesh name="hatch" class="/" file="hatch.obj"/>
    <mesh name="shank_r" class="/" file="shank_r.obj"/>
  </asset>

  <worldbody>
    <geom name="floor" class="/" size="100 100 0.125" type="plane" group="0" material="MatPlane"/>
    <light name="toplight_shadow" class="/" pos="0 0 5" dir="0.0990148 0.0990148 -0.990148" type="directional" ambient="0.04 0.04 0.04" diffuse="0.55 0.55 0.55" specular="0.12 0.12 0.12"/>
    <light name="toplight_fill" class="/" pos="0 0 5" dir="0.0990148 0.0990148 -0.990148" type="directional" castshadow="false" ambient="0.04 0.04 0.04" diffuse="0.3 0.3 0.3" specular="0.08 0.08 0.08"/>
    <body name="trunk" childclass="anymal_c" pos="-0.0115934 -0.00488509 0.000128851" quat="0.999999 -0.000504479 6.15624e-05 -0.00132295">
      <inertial pos="0.00171591 -6.71268e-06 0.0621442" quat="0.512829 0.474077 0.495646 0.516327" mass="19.0971" diaginertia="0.168641 0.244368 0.799484"/>
      <joint name="//unnamed_joint_0" type="free" armature="0" damping="0" frictionloss="0"/>
      <geom name="//unnamed_geom_1" class="visual" material="green" mesh="base_0"/>
      <geom name="//unnamed_geom_2" class="visual" material="yellow" mesh="base_1"/>
      <geom name="//unnamed_geom_3" class="visual" material="red" mesh="base_2"/>
      <geom name="//unnamed_geom_4" class="visual" material="black_plastic" mesh="base_3"/>
      <geom name="//unnamed_geom_5" class="visual" material="lwl" mesh="base_4"/>
      <geom name="//unnamed_geom_6" class="visual" material="base" mesh="base_5"/>
      <geom name="trunk_1" class="collision" size="0.288971 0.0697516 0.0896807" type="box"/>
      <geom name="trunk_2" class="collision" size="0.0896807 0.0722428" pos="0.176872 0.0609415 0" quat="0.707107 0 0.707107 0"/>
      <geom name="trunk_3" class="collision" size="0.0896807 0.0722428" pos="-0.176872 0.0609415 0" quat="0.707107 0 0.707107 0"/>
      <geom name="trunk_4" class="collision" size="0.0896807 0.0722428" pos="0.176872 -0.0609415 0" quat="0.707107 0 0.707107 0"/>
      <geom name="trunk_5" class="collision" size="0.0896807 0.0722428" pos="-0.176872 -0.0609415 0" quat="0.707107 0 0.707107 0"/>
      <geom name="//unnamed_geom_12" class="visual" material="top_shell" mesh="top_shell"/>
      <geom name="//unnamed_geom_13" class="visual" material="bottom_shell" mesh="bottom_shell"/>
      <geom name="//unnamed_geom_14" class="visual" material="remote" mesh="remote"/>
      <geom name="//unnamed_geom_15" class="visual" material="handle" mesh="handle"/>
      <geom name="//unnamed_geom_16" class="visual" pos="0.337073 0 0" quat="1 0 0 0" material="face" mesh="face"/>
      <geom name="trunk_6" class="collision" size="0.0548048 0.0697516 0.0896807" pos="0.381799 0 0" type="box"/>
      <geom name="//unnamed_geom_18" class="collision" size="0.0896807 0.0548048" pos="0.381799 0.0609415 0" quat="0.707107 0 0.707107 0"/>
      <geom name="//unnamed_geom_19" class="collision" size="0.0896807 0.0548048" pos="0.381799 -0.0609415 0" quat="0.707107 0 0.707107 0"/>
      <geom name="//unnamed_geom_20" class="visual" pos="0.375436 0 -0.0418642" quat="0.965926 0 0.258819 0" material="depth_camera" mesh="depth_camera"/>
      <geom name="//unnamed_geom_21" class="visual" pos="0.417173 0 0.0195442" material="wide_angle_camera" mesh="wide_angle_camera"/>
      <geom name="//unnamed_geom_22" class="visual_zflip" pos="-0.337073 0 0" quat="0 0 0 1" material="face" mesh="face"/>
      <geom name="trunk_7" class="collision" size="0.0548048 0.0697516 0.0896807" pos="-0.381799 0 0" quat="0 0 0 1" type="box"/>
      <geom name="//unnamed_geom_24" class="collision" size="0.0896807 0.0548048" pos="-0.381799 -0.0609415 0" quat="0 -0.707107 0 0.707107"/>
      <geom name="//unnamed_geom_25" class="collision" size="0.0896807 0.0548048" pos="-0.381799 0.0609415 0" quat="0 -0.707107 0 0.707107"/>
      <geom name="//unnamed_geom_26" class="visual" pos="-0.375436 0 -0.0418642" quat="0 -0.258819 0 0.965926" material="depth_camera" mesh="depth_camera"/>
      <geom name="//unnamed_geom_27" class="visual_zflip" pos="-0.417173 0 0.0195442" quat="0 0 0 1" material="wide_angle_camera" mesh="wide_angle_camera"/>
      <geom name="//unnamed_geom_28" class="visual" material="battery" mesh="battery"/>
      <geom name="//unnamed_geom_29" class="visual" pos="0 0.0673391 0.0341846" quat="0.683013 -0.183013 0.183013 0.683013" material="depth_camera" mesh="depth_camera"/>
      <geom name="//unnamed_geom_30" class="visual" pos="0 -0.0673391 0.0341846" quat="0.683013 0.183013 0.183013 -0.683013" material="depth_camera" mesh="depth_camera"/>
      <geom name="//unnamed_geom_31" class="visual" pos="-0.296006 0 0.0959586" quat="1 0 0 0" material="lidar_cage" mesh="lidar_cage"/>
      <geom name="trunk_8" class="collision" size="0.0697516 0.0597871" pos="-0.296006 0 0.174292"/>
      <geom name="//unnamed_geom_33" class="visual" pos="-0.296006 2.25472e-05 0.18565" quat="0.707107 0 0 -0.707107" material="lidar" mesh="lidar"/>
      <geom name="//unnamed_geom_34" class="visual" pos="0.24388 0.0906962 -7.5032e-09" quat="0.258819 0.965926 0 0" material="drive" mesh="drive"/>
      <geom name="//unnamed_geom_35" class="visual" pos="0.24388 -0.0906962 7.5032e-09" quat="0.258819 -0.965926 0 0" material="drive" mesh="drive"/>
      <geom name="//unnamed_geom_36" class="visual" pos="-0.24388 0.0906962 7.5032e-09" quat="0 0 0.965926 -0.258819" material="drive" mesh="drive"/>
      <geom name="//unnamed_geom_37" class="visual" pos="-0.24388 -0.0906962 -7.5032e-09" quat="0 0 -0.965926 -0.258819" material="drive" mesh="drive"/>
      <geom name="//unnamed_geom_38" class="visual" pos="0.0943315 0 0.0953058" quat="1 0 0 0" material="hatch" mesh="hatch"/>
      <geom name="//unnamed_geom_39" class="reward_collision_sphere" size="0.119574"/>
      <geom name="//unnamed_geom_40" class="reward_collision_sphere" size="0.119574" pos="0.365941 0 0"/>
      <geom name="//unnamed_geom_41" class="reward_collision_sphere" size="0.119574" pos="-0.365941 0 0"/>
      <site name="imu" pos="0.185855 0.0134459 0.125933" size="0.00996452"/>
      <camera name="track" pos="0 -1.74119 0" quat="0.707107 0.707107 0 0" mode="trackcom"/>
      <camera name="ego_camera" pos="0.365941 0 -0.0522224" quat="-0.5 -0.5 0.5 0.5"/>
      <body name="LF_HIP" pos="0.2441 0.0930711 0.00724067" quat="0.255972 0.966674 -0.000762687 -0.00439665">
        <inertial pos="0.0586062 -0.00821301 -0.0119117" quat="-0.133244 0.707281 -0.137593 0.680491" mass="2.81621" diaginertia="0.00212877 0.00271817 0.0125479"/>
        <joint name="LF_HAA" pos="0 0 0" axis="0.997385 -0.0721871 -0.00357988" stiffness="0.0585171" range="-0.716103 0.482457" armature="0.0160848" damping="0" frictionloss="0.0690794"/>
        <geom name="//unnamed_geom_42" class="visual" pos="0 -0.00044138 7.24962e-05" quat="0.258819 -0.965926 0 0" material="hip_l" mesh="hip_l"/>
        <geom name="//unnamed_geom_43" class="visual" pos="0.0487109 -0.0599337 -0.03782" quat="0.183013 -0.683013 0.683013 0.183013" material="drive" mesh="drive"/>
        <geom name="//unnamed_geom_44" class="collision" size="0.0498226 0.0697516" pos="0.0487109 -0.0104121 -0.00901489" quat="-0.353553 -0.612372 0.612372 -0.353553"/>
        <body name="LF_THIGH" pos="0.0567253 -0.0640183 -0.0478909" quat="0.184213 -0.682709 0.682368 0.185332">
          <inertial pos="0.025147 0.000330915 -0.307148" quat="0.995789 -0.017412 -0.0636362 0.0636472" mass="3.21057" diaginertia="0.0114324 0.0158097 0.016557"/>
          <joint name="LF_HFE" pos="0 0 0" axis="0.999445 -0.0332575 -0.00172335" stiffness="0.0385083" range="-3.24684 3.14384" armature="0.00422318" damping="0.0399644" frictionloss="0.135447"/>
          <geom name="//unnamed_geom_45" class="visual" pos="-0.00114185 -1.79928e-06 0" quat="0.707107 0 0 -0.707107" material="thigh" mesh="thigh"/>
          <geom name="//unnamed_geom_46" class="collision" size="0.0647694 0.0398581" pos="0.0325281 0 0" quat="0.5 0.5 -0.5 -0.5"/>
          <geom name="//unnamed_geom_47" class="collision" size="0.0373669 0.0298936 0.140813" pos="0.0243961 0 -0.184494" quat="0.707107 0 0 -0.707107" type="box"/>
          <geom name="//unnamed_geom_48" class="visual" pos="0.0815643 0 -0.372084" quat="1 0 0 0" material="drive" mesh="drive"/>
          <geom name="//unnamed_geom_49" class="collision" size="0.0498226 0.0697516" pos="0.02464 0 -0.372084" quat="0.707107 0 0.707107 0"/>
          <geom name="//unnamed_geom_50" class="reward_collision_sphere" size="0.0797161" pos="0.0203301 0 0"/>
          <body name="LF_SHANK" pos="0.0826075 0.0139988 -0.369109" quat="0.99999 -0.00292939 -0.00139261 -0.0030667">
            <inertial pos="-0.00155913 -0.0506355 -0.10637" quat="0.986127 -0.164146 -0.0239543 0.00603939" mass="0.47743" diaginertia="0.0036638 0.00425159 0.00436099"/>
            <joint name="LF_KFE" pos="0 0 0" axis="0.99977 0.0202998 -0.00691134" range="-3.11823 3.17063" armature="0.0100734" damping="0.0487439" frictionloss="0.0969144"/>
            <geom name="//unnamed_geom_51" class="visual" pos="-0.000372331 -0.00198529 0" quat="0.707107 0 0 -0.707107" material="shank_l" mesh="shank_l"/>
            <geom name="LF_kfe_act" class="collision" size="0.0597871 0.019929" pos="0.0162641 0 0" quat="0.5 0.5 -0.5 -0.5"/>
            <geom name="//unnamed_geom_53" class="collision" size="0.057295 0.0336302 0.0189326" pos="0.0162641 -0.0500583 0" quat="0.5 0.5 -0.5 -0.5" type="box"/>
            <geom name="//unnamed_geom_54" class="visual" pos="0.0106124 -0.0772085 -0.44124" quat="0.382683 0 0 -0.92388" material="foot" mesh="foot"/>
            <geom name="LF_calf" class="collision" size="0.0174379 0.140751" pos="0.0106123 -0.0765687 -0.22062" quat="0.707107 0 0 -0.707107"/>
            <geom name="LF_foot" class="foot" size="0.0199682" pos="0.0106123 -0.0765687 -0.411865" quat="0.707107 0 0 -0.707107"/>
            <geom name="//unnamed_geom_57" class="reward_collision_sphere" size="0.0996452" pos="-0.0406601 0 0"/>
            <geom name="//unnamed_geom_58" class="reward_collision_sphere" size="0.0498226" pos="0.0106123 -0.0765687 -0.411865"/>
            <site name="LF_foot" class="foot" pos="0.0106123 -0.0765687 -0.411865" quat="0.707107 0 0 -0.707107" size="0.00996452"/>
          </body>
        </body>
      </body>
      <body name="RF_HIP" pos="0.257623 -0.103807 0.0103429" quat="0.258801 -0.965931 -0.000164204 0.000179218">
        <inertial pos="0.0328071 0.0100681 0.00129031" quat="0.134939 0.674427 0.0913105 0.72014" mass="2.27138" diaginertia="0.00174711 0.00227871 0.0104047"/>
        <joint name="RF_HAA" pos="0 0 0" axis="0.998387 -0.0209642 0.0527675" range="-0.243182 0.698726" armature="0.0109861" damping="0.00620386" frictionloss="0.152675"/>
        <geom name="//unnamed_geom_59" class="visual" pos="0 0.000441376 7.2496e-05" quat="0.258819 0.965926 0 0" material="hip_r" mesh="hip_r"/>
        <geom name="//unnamed_geom_60" class="visual" pos="0.0487109 0.0599337 -0.03782" quat="0.183013 0.683013 0.683013 -0.183013" material="drive" mesh="drive"/>
        <geom name="//unnamed_geom_61" class="collision" size="0.0498226 0.0697516" pos="0.0487109 0.0104121 -0.00901489" quat="-0.353553 0.612372 0.612372 0.353553"/>
        <body name="RF_THIGH" pos="0.048389 0.0668032 -0.0620454" quat="0.182207 0.682957 0.683581 -0.181898">
          <inertial pos="0.0315065 -0.0144774 -0.324016" quat="0.993313 -0.00362797 -0.0765498 0.0863463" mass="2.89619" diaginertia="0.0105676 0.0138997 0.0150636"/>
          <joint name="RF_HFE" pos="0 0 0" axis="0.999466 0.00308523 0.0325431" range="-3.12015 3.01385" armature="0.0118299" damping="0.050721" frictionloss="0.0892305"/>
          <geom name="//unnamed_geom_62" class="visual" pos="-0.00114185 -1.79928e-06 0" quat="0.707107 0 0 -0.707107" material="thigh" mesh="thigh"/>
          <geom name="//unnamed_geom_63" class="collision" size="0.0647694 0.0398581" pos="0.0325281 0 0" quat="0.5 0.5 0.5 0.5"/>
          <geom name="//unnamed_geom_64" class="collision" size="0.0373669 0.0298936 0.140813" pos="0.0243961 0 -0.184494" quat="0.707107 0 0 0.707107" type="box"/>
          <geom name="//unnamed_geom_65" class="visual" pos="0.0815643 0 -0.372084" quat="1 0 0 0" material="drive" mesh="drive"/>
          <geom name="//unnamed_geom_66" class="collision" size="0.0498226 0.0697516" pos="0.02464 0 -0.372084" quat="0.707107 0 0.707107 0"/>
          <geom name="//unnamed_geom_67" class="reward_collision_sphere" size="0.0797161" pos="0.0203301 0 0"/>
          <body name="RF_SHANK" pos="0.0786885 -0.00351421 -0.38291" quat="0.999977 -0.00646273 -0.000223941 -0.00185443">
            <inertial pos="-0.0101963 0.0614775 -0.115929" quat="0.993054 0.114791 -0.0103344 0.0236553" mass="0.67213" diaginertia="0.00338584 0.00405777 0.00359462"/>
            <joint name="RF_KFE" pos="0 0 0" axis="0.999834 -0.00165515 -0.0181453" range="-2.88735 3.1403" armature="0.0092715" damping="0" frictionloss="0.0430318"/>
            <geom name="//unnamed_geom_68" class="visual" pos="-0.000372329 0.00198528 0" quat="0.707107 0 0 0.707107" material="shank" mesh="shank_r"/>
            <geom name="RF_kfe_act" class="collision" size="0.0597871 0.019929" pos="0.0162641 0 0" quat="0.5 0.5 0.5 0.5"/>
            <geom name="//unnamed_geom_70" class="collision" size="0.057295 0.0336302 0.0189326" pos="0.0162641 0.0500583 0" quat="0.5 0.5 0.5 0.5" type="box"/>
            <geom name="//unnamed_geom_71" class="visual" pos="0.0106122 0.0772085 -0.44124" quat="0.382683 0 0 0.92388" material="foot" mesh="foot"/>
            <geom name="RF_calf" class="collision" size="0.0174379 0.140751" pos="0.0106123 0.0765687 -0.22062" quat="0.707107 0 0 0.707107"/>
            <geom name="RF_foot" class="foot" size="0.032101" pos="0.0106123 0.0765687 -0.411865" quat="0.707107 0 0 0.707107"/>
            <geom name="//unnamed_geom_74" class="reward_collision_sphere" size="0.0996452" pos="-0.0406601 0 0"/>
            <geom name="//unnamed_geom_75" class="reward_collision_sphere" size="0.0498226" pos="0.0106123 0.0765687 -0.411865"/>
            <site name="RF_foot" class="foot" pos="0.0106123 0.0765687 -0.411865" quat="0.707107 0 0 0.707107" size="0.00996452"/>
          </body>
        </body>
      </body>
      <body name="LH_HIP" pos="-0.25877 0.101843 0.00267719" quat="0.000653232 -0.000515615 0.965515 -0.260348">
        <inertial pos="0.033423 0.0276194 -0.00948239" quat="0.102653 0.652531 0.15549 0.734499" mass="2.91321" diaginertia="0.00213187 0.00245169 0.0139607"/>
        <joint name="LH_HAA" pos="0 0 0" axis="0.999612 0.0275924 -0.00380206" range="-0.664052 0.624057" armature="0.00973586" damping="0.00749865" frictionloss="0.121007"/>
        <geom name="//unnamed_geom_76" class="visual" pos="0 0.000441376 7.2496e-05" quat="-0.258819 -0.965926 0 0" material="hip_r" mesh="hip_r"/>
        <geom name="//unnamed_geom_77" class="visual" pos="0.0487109 0.0599337 -0.03782" quat="0.183013 0.683013 0.683013 -0.183013" material="drive" mesh="drive"/>
        <geom name="//unnamed_geom_78" class="collision" size="0.0498226 0.0697516" pos="0.0487109 0.0104121 -0.00901489" quat="-0.353553 0.612372 0.612372 0.353553"/>
        <body name="LH_THIGH" pos="0.0418151 0.0582699 -0.0552824" quat="0.182573 0.684301 0.682299 -0.181297">
          <inertial pos="0.0226585 -0.0130362 -0.320506" quat="0.990583 0.0128765 -0.119455 0.0656581" mass="2.61364" diaginertia="0.0105505 0.0132718 0.0165369"/>
          <joint name="LH_HFE" pos="0 0 0" axis="0.998201 -0.0588622 -0.0114071" stiffness="0.0452138" range="-3.31366 2.98216" armature="0.00408852" damping="0" frictionloss="0.0461607"/>
          <geom name="//unnamed_geom_79" class="visual" pos="-0.00114185 -1.79928e-06 0" quat="0.707107 0 0 -0.707107" material="thigh" mesh="thigh"/>
          <geom name="//unnamed_geom_80" class="collision" size="0.0647694 0.0398581" pos="0.0325281 0 0" quat="0.5 0.5 -0.5 -0.5"/>
          <geom name="//unnamed_geom_81" class="collision" size="0.0373669 0.0298936 0.140813" pos="0.0243961 0 -0.184494" quat="0.707107 0 0 -0.707107" type="box"/>
          <geom name="//unnamed_geom_82" class="visual" pos="0.0815643 0 -0.372084" quat="1 0 0 0" material="drive" mesh="drive"/>
          <geom name="//unnamed_geom_83" class="collision" size="0.0498226 0.0697516" pos="0.02464 0 -0.372084" quat="0.707107 0 0.707107 0"/>
          <geom name="//unnamed_geom_84" class="reward_collision_sphere" size="0.0797161" pos="0.0203301 0 0"/>
          <body name="LH_SHANK" pos="0.089333 -0.0104019 -0.35828" quat="0.999976 0.00562205 -0.00411014 -0.000295999">
            <inertial pos="0.00384435 0.0535269 -0.120063" quat="0.994361 0.101472 -0.0285686 0.0115578" mass="0.679989" diaginertia="0.00363494 0.00502718 0.00435271"/>
            <joint name="LH_KFE" pos="0 0 0" axis="0.9997 0.0147717 0.0195532" stiffness="0.0289508" range="-3.19733 3.29948" armature="0.00860518" damping="0.0186877" frictionloss="0.14873"/>
            <geom name="//unnamed_geom_85" class="visual" pos="-0.000372329 0.00198528 0" quat="-0.707107 0 0 -0.707107" material="shank" mesh="shank_r"/>
            <geom name="LH_kfe_act" class="collision" size="0.0597871 0.019929" pos="0.0162641 0 0" quat="0.5 0.5 -0.5 -0.5"/>
            <geom name="//unnamed_geom_87" class="collision" size="0.057295 0.0336302 0.0189326" pos="0.0162641 0.0500583 0" quat="0.5 0.5 -0.5 -0.5" type="box"/>
            <geom name="//unnamed_geom_88" class="visual" pos="0.0106122 0.0772085 -0.44124" quat="-0.382683 0 0 -0.92388" material="foot" mesh="foot"/>
            <geom name="LH_calf" class="collision" size="0.0174379 0.140751" pos="0.0106123 0.0765687 -0.22062" quat="0.707107 0 0 -0.707107"/>
            <geom name="LH_foot" class="foot" size="0.0414389" pos="0.0106123 0.0765687 -0.411865" quat="0.707107 0 0 -0.707107"/>
            <geom name="//unnamed_geom_91" class="reward_collision_sphere" size="0.0996452" pos="-0.0406601 0 0"/>
            <geom name="//unnamed_geom_92" class="reward_collision_sphere" size="0.0498226" pos="0.0106123 0.0765687 -0.411865"/>
            <site name="LH_foot" class="foot" pos="0.0106123 0.0765687 -0.411865" quat="0.707107 0 0 -0.707107" size="0.00996452"/>
          </body>
        </body>
      </body>
      <body name="RH_HIP" pos="-0.231089 -0.0959094 0.000756974" quat="-0.00103716 0.00121502 -0.965538 -0.260259">
        <inertial pos="0.0369454 -0.019985 -0.00993186" quat="-0.0807925 0.68327 -0.129102 0.714106" mass="2.82931" diaginertia="0.00194085 0.00226153 0.0115352"/>
        <joint name="RH_HAA" pos="0 0 0" axis="0.997775 0.0664433 -0.0054595" stiffness="0.00783861" range="-0.705292 0.409965" armature="0.0125872" damping="0" frictionloss="0.104058"/>
        <geom name="//unnamed_geom_93" class="visual" pos="0 -0.00044138 7.24962e-05" quat="-0.258819 0.965926 0 0" material="hip_l" mesh="hip_l"/>
        <geom name="//unnamed_geom_94" class="visual" pos="0.0487109 -0.0599337 -0.03782" quat="-0.183013 0.683013 -0.683013 -0.183013" material="drive" mesh="drive"/>
        <geom name="//unnamed_geom_95" class="collision" size="0.0498226 0.0697516" pos="0.0487109 -0.0104121 -0.00901489" quat="0.353553 0.612372 -0.612372 0.353553"/>
        <body name="RH_THIGH" pos="0.0479399 -0.0602379 -0.0662675" quat="-0.184354 0.684158 -0.681757 -0.182067">
          <inertial pos="0.0220476 -0.000137549 -0.324451" quat="0.994259 -0.0628281 -0.0409563 0.0763143" mass="3.19099" diaginertia="0.0108471 0.0131613 0.0132286"/>
          <joint name="RH_HFE" pos="0 0 0" axis="0.99987 0.00724163 0.0144156" stiffness="0.0446332" range="-3.11924 3.0523" armature="0.00517222" damping="0.0606694" frictionloss="0.130896"/>
          <geom name="//unnamed_geom_96" class="visual" pos="-0.00114185 -1.79928e-06 0" quat="0.707107 0 0 -0.707107" material="thigh" mesh="thigh"/>
          <geom name="//unnamed_geom_97" class="collision" size="0.0647694 0.0398581" pos="0.0325281 0 0" quat="0.5 0.5 0.5 0.5"/>
          <geom name="//unnamed_geom_98" class="collision" size="0.0373669 0.0298936 0.140813" pos="0.0243961 0 -0.184494" quat="0.707107 0 0 0.707107" type="box"/>
          <geom name="//unnamed_geom_99" class="visual" pos="0.0815643 0 -0.372084" quat="1 0 0 0" material="drive" mesh="drive"/>
          <geom name="//unnamed_geom_100" class="collision" size="0.0498226 0.0697516" pos="0.02464 0 -0.372084" quat="0.707107 0 0.707107 0"/>
          <geom name="//unnamed_geom_101" class="reward_collision_sphere" size="0.0797161" pos="0.0203301 0 0"/>
          <body name="RH_SHANK" pos="0.0845234 -0.00111343 -0.371863" quat="1 -4.03724e-05 0.000282621 -8.20179e-05">
            <inertial pos="0.0158664 -0.0398184 -0.117964" quat="0.992931 -0.115981 -0.000710016 -0.0252351" mass="0.50753" diaginertia="0.00402125 0.00400982 0.0043377"/>
            <joint name="RH_KFE" pos="0 0 0" axis="0.999825 -0.0116595 0.0146524" stiffness="0.00739764" range="-3.05068 2.88629" armature="0.0103393" damping="0" frictionloss="0.0352188"/>
            <geom name="//unnamed_geom_102" class="visual" pos="-0.000372331 -0.00198529 0" quat="0.707107 0 0 -0.707107" material="shank_l" mesh="shank_l"/>
            <geom name="RH_kfe_act" class="collision" size="0.0597871 0.019929" pos="0.0162641 0 0" quat="0.5 0.5 0.5 0.5"/>
            <geom name="//unnamed_geom_104" class="collision" size="0.057295 0.0336302 0.0189326" pos="0.0162641 -0.0500583 0" quat="0.5 0.5 0.5 0.5" type="box"/>
            <geom name="//unnamed_geom_105" class="visual" pos="0.0106124 -0.0772085 -0.44124" quat="0.382683 0 0 -0.92388" material="foot" mesh="foot"/>
            <geom name="RH_calf" class="collision" size="0.0174379 0.140751" pos="0.0106123 -0.0765687 -0.22062" quat="0.707107 0 0 0.707107"/>
            <geom name="RH_foot" class="foot" size="0.0159884" pos="0.0106123 -0.0765687 -0.411865" quat="0.707107 0 0 0.707107"/>
            <geom name="//unnamed_geom_108" class="reward_collision_sphere" size="0.0996452" pos="-0.0406601 0 0"/>
            <geom name="//unnamed_geom_109" class="reward_collision_sphere" size="0.0498226" pos="0.0106123 -0.0765687 -0.411865"/>
            <site name="RH_foot" class="foot" pos="0.0106123 -0.0765687 -0.411865" quat="0.707107 0 0 0.707107" size="0.00996452"/>
          </body>
        </body>
      </body>
    </body>
  </worldbody>

  <contact>
    <pair class="/" geom1="floor" geom2="LF_foot" name="//unnamed_contact_0"/>
    <pair class="/" geom1="floor" geom2="RF_foot" name="//unnamed_contact_1"/>
    <pair class="/" geom1="floor" geom2="LH_foot" name="//unnamed_contact_2"/>
    <pair class="/" geom1="floor" geom2="RH_foot" name="//unnamed_contact_3"/>
  </contact>

  <actuator>
    <general name="LF_HAA" class="/" joint="LF_HAA" forcerange="-83.7406 83.7406" gainprm="76.59" biasprm="0 -76.59 -1.80543"/>
    <general name="LF_HFE" class="/" joint="LF_HFE" forcerange="-111.711 111.711" gainprm="76.59" biasprm="0 -76.59 -1.80543"/>
    <general name="LF_KFE" class="/" joint="LF_KFE" forcerange="-63.7597 63.7597" gainprm="76.59" biasprm="0 -76.59 -1.80543"/>
    <general name="RF_HAA" class="/" joint="RF_HAA" forcerange="-86.2394 86.2394" gainprm="76.59" biasprm="0 -76.59 -1.80543"/>
    <general name="RF_HFE" class="/" joint="RF_HFE" forcerange="-76.9373 76.9373" gainprm="76.59" biasprm="0 -76.59 -1.80543"/>
    <general name="RF_KFE" class="/" joint="RF_KFE" forcerange="-57.4851 57.4851" gainprm="76.59" biasprm="0 -76.59 -1.80543"/>
    <general name="LH_HAA" class="/" joint="LH_HAA" forcerange="-84.4912 84.4912" gainprm="76.59" biasprm="0 -76.59 -1.80543"/>
    <general name="LH_HFE" class="/" joint="LH_HFE" forcerange="-56.4415 56.4415" gainprm="76.59" biasprm="0 -76.59 -1.80543"/>
    <general name="LH_KFE" class="/" joint="LH_KFE" forcerange="-100.733 100.733" gainprm="76.59" biasprm="0 -76.59 -1.80543"/>
    <general name="RH_HAA" class="/" joint="RH_HAA" forcerange="-79.7587 79.7587" gainprm="76.59" biasprm="0 -76.59 -1.80543"/>
    <general name="RH_HFE" class="/" joint="RH_HFE" forcerange="-68.4958 68.4958" gainprm="76.59" biasprm="0 -76.59 -1.80543"/>
    <general name="RH_KFE" class="/" joint="RH_KFE" forcerange="-121.44 121.44" gainprm="76.59" biasprm="0 -76.59 -1.80543"/>
  </actuator>

  <sensor>
    <gyro site="imu" name="imu_angular_velocity"/>
    <velocimeter site="imu" name="imu_linear_velocity"/>
    <framelinvel objtype="site" objname="LF_foot" name="LF_foot_global_linear_velocity"/>
    <framelinvel objtype="site" objname="RF_foot" name="RF_foot_global_linear_velocity"/>
    <framelinvel objtype="site" objname="LH_foot" name="LH_foot_global_linear_velocity"/>
    <framelinvel objtype="site" objname="RH_foot" name="RH_foot_global_linear_velocity"/>
  </sensor>

  <keyframe>
    <key name="home" qpos="0 0 0.55 1 0 0 0 0 0.4 -0.8 0 -0.4 0.8 0 -0.4 0.8 0 0.4 -0.8"/>
  </keyframe>
</mujoco>
