<mujoco model="anymal_c">
  <compiler angle="radian" assetdir="assets" balanceinertia="true" inertiafromgeom="false"/>

  <option timestep="0.005" density="1.2" viscosity="2e-05"/>

  <size nkey="1"/>

  <visual>
    <quality shadowsize="8192"/>
    <map shadowclip="0.5"/>
  </visual>

  <default>
    <default class="/">
      <material specular="0" shininess="0.25"/>
      <geom contype="0" conaffinity="0" group="1" solref="-1000 -80"/>
      <site size="0.01 0.005 0.005" group="5"/>
      <general forcelimited="true" forcerange="-80 80" biastype="affine" gainprm="80" biasprm="0 -80 -2"/>
      <default class="anymal_c">
        <joint armature="0.01" damping="0.01" frictionloss="0.1"/>
        <default class="visual">
          <geom type="mesh" group="2"/>
          <default class="visual_zflip"/>
        </default>
        <default class="collision">
          <geom type="cylinder" group="3"/>
          <default class="foot">
            <geom size="0.03 0 0" type="sphere" condim="6" priority="1" friction="0.8 0.02 0.01" solimp="0.015 1 0.03"/>
          </default>
        </default>
      </default>
      <default class="reward_collision_sphere">
        <geom group="5" rgba="1 0 0 1"/>
      </default>
    </default>
  </default>

  <asset>
    <texture type="skybox" colorspace="auto" name="//unnamed_texture_0" builtin="gradient" rgb1="0.95 0.95 0.95" rgb2="0.95 0.95 0.95" width="100" height="600"/>
    <texture type="2d" colorspace="auto" name="texplane" builtin="checker" rgb1="0.345 0.575 0.748" rgb2="0.345 0.575 0.748" markrgb="1 1 1" width="512" height="512"/>
    <texture type="2d" colorspace="linear" name="base" file="base.png"/>
    <texture type="2d" colorspace="linear" name="top_shell" file="top_shell.png"/>
    <texture type="2d" colorspace="linear" name="bottom_shell" file="bottom_shell.png"/>
    <texture type="2d" colorspace="linear" name="remote" file="remote.png"/>
    <texture type="2d" colorspace="linear" name="hatch" file="hatch.png"/>
    <texture type="2d" colorspace="linear" name="handle" file="handle.png"/>
    <texture type="2d" colorspace="linear" name="face" file="face.png"/>
    <texture type="2d" colorspace="linear" name="battery" file="battery.png"/>
    <texture type="2d" colorspace="linear" name="lidar_cage" file="lidar_cage.png"/>
    <texture type="2d" colorspace="linear" name="depth_camera" file="depth_camera.png"/>
    <texture type="2d" colorspace="linear" name="wide_angle_camera" file="wide_angle_camera.png"/>
    <texture type="2d" colorspace="linear" name="lidar" file="lidar.png"/>
    <texture type="2d" colorspace="linear" name="drive" file="drive.png"/>
    <texture type="2d" colorspace="linear" name="hip_l" file="hip_l.png"/>
    <texture type="2d" colorspace="linear" name="shank_l" file="shank_l.png"/>
    <texture type="2d" colorspace="linear" name="foot" file="foot.png"/>
    <texture type="2d" colorspace="linear" name="thigh" file="thigh.png"/>
    <texture type="2d" colorspace="linear" name="shank_r" file="shank_r.png"/>
    <texture type="2d" colorspace="linear" name="hip_r" file="hip_r.png"/>
    <material name="MatPlane" class="/" texture="texplane" texuniform="true" texrepeat="2 2" specular="0.9" shininess="0.5"/>
    <material name="black_plastic" class="/" rgba="0.007 0.007 0.007 1"/>
    <material name="green" class="/" rgba="0.052 0.178 0.033 1"/>
    <material name="red" class="/" rgba="0.178 0.006 0.005 1"/>
    <material name="yellow" class="/" rgba="0.178 0.119 0.006 1"/>
    <material name="lwl" class="/" rgba="0.8 0.8 0.8 1"/>
    <material name="base" class="/" texture="base"/>
    <material name="top_shell" class="/" texture="top_shell"/>
    <material name="bottom_shell" class="/" texture="bottom_shell"/>
    <material name="hip_l" class="/" texture="hip_l"/>
    <material name="thigh" class="/" texture="thigh"/>
    <material name="shank_l" class="/" texture="shank_l"/>
    <material name="foot" class="/" texture="foot"/>
    <material name="hip_r" class="/" texture="hip_r"/>
    <material name="shank" class="/" texture="shank_r"/>
    <material name="hatch" class="/" texture="hatch"/>
    <material name="remote" class="/" texture="remote"/>
    <material name="handle" class="/" texture="handle"/>
    <material name="face" class="/" texture="face"/>
    <material name="depth_camera" class="/" texture="depth_camera"/>
    <material name="wide_angle_camera" class="/" texture="wide_angle_camera"/>
    <material name="battery" class="/" texture="battery"/>
    <material name="lidar_cage" class="/" texture="lidar_cage"/>
    <material name="lidar" class="/" texture="lidar"/>
    <material name="drive" class="/" texture="drive"/>
    <mesh name="base_0" class="/" file="base_0.obj"/>
    <mesh name="base_1" class="/" file="base_1.obj"/>
    <mesh name="base_2" class="/" file="base_2.obj"/>
    <mesh name="base_3" class="/" file="base_3.obj"/>
    <mesh name="base_4" class="/" file="base_4.obj"/>
    <mesh name="base_5" class="/" file="base_5.obj"/>
    <mesh name="top_shell" class="/" file="top_shell.obj"/>
    <mesh name="bottom_shell" class="/" file="bottom_shell.obj"/>
    <mesh name="remote" class="/" file="remote.obj"/>
    <mesh name="handle" class="/" file="handle.obj"/>
    <mesh name="face" class="/" file="face.obj"/>
    <mesh name="wide_angle_camera" class="/" file="wide_angle_camera.obj"/>
    <mesh name="depth_camera" class="/" file="depth_camera.obj"/>
    <mesh name="battery" class="/" file="battery.obj"/>
    <mesh name="lidar_cage" class="/" file="lidar_cage.obj"/>
    <mesh name="lidar" class="/" file="lidar.obj"/>
    <mesh name="drive" class="/" file="drive.obj"/>
    <mesh name="hip_l" class="/" file="hip_l.obj"/>
    <mesh name="thigh" class="/" file="thigh.obj"/>
    <mesh name="shank_l" class="/" file="shank_l.obj"/>
    <mesh name="foot" class="/" file="foot.obj"/>
    <mesh name="hip_r" class="/" file="hip_r.obj"/>
    <mesh name="hatch" class="/" file="hatch.obj"/>
    <mesh name="shank_r" class="/" file="shank_r.obj"/>
  </asset>

  <worldbody>
    <geom name="floor" class="/" size="100 100 0.125" type="plane" group="0" material="MatPlane"/>
    <light name="toplight_shadow" class="/" pos="0 0 5" dir="0.0990148 0.0990148 -0.990148" type="directional" ambient="0.04 0.04 0.04" diffuse="0.55 0.55 0.55" specular="0.12 0.12 0.12"/>
    <light name="toplight_fill" class="/" pos="0 0 5" dir="0.0990148 0.0990148 -0.990148" type="directional" castshadow="false" ambient="0.04 0.04 0.04" diffuse="0.3 0.3 0.3" specular="0.08 0.08 0.08"/>
    <body name="trunk" childclass="anymal_c" pos="-0.00219819 -0.000468103 0.00103017" quat="1 0.000161311 0.000594138 9.20861e-05">
      <inertial pos="8.34475e-05 -0.00056878 0.0477586" quat="0.497407 0.499794 0.498667 0.504106" mass="19.3645" diaginertia="0.843227 0.59256 0.199593"/>
      <joint name="//unnamed_joint_0" type="free" armature="0" damping="0" frictionloss="0"/>
      <geom name="//unnamed_geom_1" class="visual" material="green" mesh="base_0"/>
      <geom name="//unnamed_geom_2" class="visual" material="yellow" mesh="base_1"/>
      <geom name="//unnamed_geom_3" class="visual" material="red" mesh="base_2"/>
      <geom name="//unnamed_geom_4" class="visual" material="black_plastic" mesh="base_3"/>
      <geom name="//unnamed_geom_5" class="visual" material="lwl" mesh="base_4"/>
      <geom name="//unnamed_geom_6" class="visual" material="base" mesh="base_5"/>
      <geom name="trunk_1" class="collision" size="0.292321 0.0705602 0.0907203" type="box"/>
      <geom name="trunk_2" class="collision" size="0.0907203 0.0730802" pos="0.229516 0.0692398 0" quat="0.707107 0 0.707107 0"/>
      <geom name="trunk_3" class="collision" size="0.0907203 0.0730802" pos="-0.229516 0.0692398 0" quat="0.707107 0 0.707107 0"/>
      <geom name="trunk_4" class="collision" size="0.0907203 0.0730802" pos="0.229516 -0.0692398 0" quat="0.707107 0 0.707107 0"/>
      <geom name="trunk_5" class="collision" size="0.0907203 0.0730802" pos="-0.229516 -0.0692398 0" quat="0.707107 0 0.707107 0"/>
      <geom name="//unnamed_geom_12" class="visual" material="top_shell" mesh="top_shell"/>
      <geom name="//unnamed_geom_13" class="visual" material="bottom_shell" mesh="bottom_shell"/>
      <geom name="//unnamed_geom_14" class="visual" material="remote" mesh="remote"/>
      <geom name="//unnamed_geom_15" class="visual" material="handle" mesh="handle"/>
      <geom name="//unnamed_geom_16" class="visual" pos="0.437399 0 0" quat="1 0 0 0" material="face" mesh="face"/>
      <geom name="trunk_6" class="collision" size="0.0554402 0.0705602 0.0907203" pos="0.495438 0 0" type="box"/>
      <geom name="//unnamed_geom_18" class="collision" size="0.0907203 0.0554402" pos="0.495438 0.0692398 0" quat="0.707107 0 0.707107 0"/>
      <geom name="//unnamed_geom_19" class="collision" size="0.0907203 0.0554402" pos="0.495438 -0.0692398 0" quat="0.707107 0 0.707107 0"/>
      <geom name="//unnamed_geom_20" class="visual" pos="0.487151 0 -0.0280303" quat="0.965926 0 0.258819 0" material="depth_camera" mesh="depth_camera"/>
      <geom name="//unnamed_geom_21" class="visual" pos="0.541341 0 0.014665" material="wide_angle_camera" mesh="wide_angle_camera"/>
      <geom name="//unnamed_geom_22" class="visual_zflip" pos="-0.437399 0 0" quat="0 0 0 1" material="face" mesh="face"/>
      <geom name="trunk_7" class="collision" size="0.0554402 0.0705602 0.0907203" pos="-0.495438 0 0" quat="0 0 0 1" type="box"/>
      <geom name="//unnamed_geom_24" class="collision" size="0.0907203 0.0554402" pos="-0.495438 -0.0692398 0" quat="0 -0.707107 0 0.707107"/>
      <geom name="//unnamed_geom_25" class="collision" size="0.0907203 0.0554402" pos="-0.495438 0.0692398 0" quat="0 -0.707107 0 0.707107"/>
      <geom name="//unnamed_geom_26" class="visual" pos="-0.487151 0 -0.0280303" quat="0 -0.258819 0 0.965926" material="depth_camera" mesh="depth_camera"/>
      <geom name="//unnamed_geom_27" class="visual_zflip" pos="-0.541341 0 0.014665" quat="0 0 0 1" material="wide_angle_camera" mesh="wide_angle_camera"/>
      <geom name="//unnamed_geom_28" class="visual" material="battery" mesh="battery"/>
      <geom name="//unnamed_geom_29" class="visual" pos="0 0.0747591 0.0290328" quat="0.683013 -0.183013 0.183013 0.683013" material="depth_camera" mesh="depth_camera"/>
      <geom name="//unnamed_geom_30" class="visual" pos="0 -0.0747591 0.0290328" quat="0.683013 0.183013 0.183013 -0.683013" material="depth_camera" mesh="depth_camera"/>
      <geom name="//unnamed_geom_31" class="visual" pos="-0.384109 0 0.0720023" quat="1 0 0 0" material="lidar_cage" mesh="lidar_cage"/>
      <geom name="trunk_8" class="collision" size="0.0705602 0.0604802" pos="-0.384109 0 0.13078"/>
      <geom name="//unnamed_geom_33" class="visual" pos="-0.384109 -2.59708e-05 0.139302" quat="0.707107 0 0 -0.707107" material="lidar" mesh="lidar"/>
      <geom name="//unnamed_geom_34" class="visual" pos="0.316468 0.102867 1.64169e-10" quat="0.258819 0.965926 0 0" material="drive" mesh="drive"/>
      <geom name="//unnamed_geom_35" class="visual" pos="0.316468 -0.102867 -1.64169e-10" quat="0.258819 -0.965926 0 0" material="drive" mesh="drive"/>
      <geom name="//unnamed_geom_36" class="visual" pos="-0.316468 0.102867 -1.64169e-10" quat="0 0 0.965926 -0.258819" material="drive" mesh="drive"/>
      <geom name="//unnamed_geom_37" class="visual" pos="-0.316468 -0.102867 1.64169e-10" quat="0 0 -0.965926 -0.258819" material="drive" mesh="drive"/>
      <geom name="//unnamed_geom_38" class="visual" pos="0.122408 0 0.0715125" quat="1 0 0 0" material="hatch" mesh="hatch"/>
      <geom name="//unnamed_geom_39" class="reward_collision_sphere" size="0.12096"/>
      <geom name="//unnamed_geom_40" class="reward_collision_sphere" size="0.12096" pos="0.47486 0 0"/>
      <geom name="//unnamed_geom_41" class="reward_collision_sphere" size="0.12096" pos="-0.47486 0 0"/>
      <site name="imu" pos="0.261675 0.00309547 0.049103" size="0.01008"/>
      <camera name="track" pos="0 -1.97828 0" quat="0.707107 0.707107 0 0" mode="trackcom"/>
      <camera name="ego_camera" pos="0.47486 0 -0.0391849" quat="-0.5 -0.5 0.5 0.5"/>
      <body name="LF_HIP" pos="0.317616 0.103577 -0.00103356" quat="0.258012 0.966142 0.000305991 -0.000588727">
        <inertial pos="0.0574828 -0.0141738 -0.00744052" quat="-0.12854 0.709898 -0.134054 0.679376" mass="2.89199" diaginertia="0.00780413 0.00463362 0.00301135"/>
        <joint name="LF_HAA" pos="0 0 0" axis="1 0.000113574 -4.40596e-05" range="-0.726731 0.456577" armature="0.0105654" damping="0.00893127" frictionloss="0.0957994"/>
        <geom name="//unnamed_geom_42" class="visual" pos="0 9.65734e-06 -1.58621e-06" quat="0.258819 -0.965926 0 0" material="hip_l" mesh="hip_l"/>
        <geom name="//unnamed_geom_43" class="visual" pos="0.0632092 -0.0757176 -0.0436452" quat="0.183013 -0.683013 0.683013 0.183013" material="drive" mesh="drive"/>
        <geom name="//unnamed_geom_44" class="collision" size="0.0504001 0.0705602" pos="0.0632092 -0.0118299 -0.0067643" quat="-0.353553 -0.612372 0.612372 -0.353553"/>
        <body name="LF_THIGH" pos="0.0634478 -0.072748 -0.04159" quat="0.182865 -0.683001 0.683049 0.183069">
          <inertial pos="0.0349386 0.000202729 -0.238789" quat="0.993031 -0.00439084 -0.0802161 0.0862242" mass="3.16854" diaginertia="0.0392999 0.0280432 0.00382301"/>
          <joint name="LF_HFE" pos="0 0 0" axis="0.999998 -0.00046499 -0.00216485" stiffness="0.013284" range="-3.17117 3.15545" armature="0.0104924" damping="0" frictionloss="0.097111"/>
          <geom name="//unnamed_geom_45" class="visual" pos="0.00131523 2.07249e-06 0" quat="0.707107 0 0 -0.707107" material="thigh" mesh="thigh"/>
          <geom name="//unnamed_geom_46" class="collision" size="0.0655202 0.0403201" pos="0.0422098 0 0" quat="0.5 0.5 -0.5 -0.5"/>
          <geom name="//unnamed_geom_47" class="collision" size="0.0378001 0.0302401 0.142445" pos="0.0316574 0 -0.138434" quat="0.707107 0 0 -0.707107" type="box"/>
          <geom name="//unnamed_geom_48" class="visual" pos="0.105841 0 -0.279193" quat="1 0 0 0" material="drive" mesh="drive"/>
          <geom name="//unnamed_geom_49" class="collision" size="0.0504001 0.0705602" pos="0.0319739 0 -0.279193" quat="0.707107 0 0.707107 0"/>
          <geom name="//unnamed_geom_50" class="reward_collision_sphere" size="0.0806402" pos="0.0263811 0 0"/>
          <body name="LF_SHANK" pos="0.105954 -0.00021152 -0.27994" quat="1 2.98182e-06 1.80347e-06 3.78124e-06">
            <inertial pos="0.00552874 -0.0611289 -0.0798652" quat="0.992855 -0.11765 0.00478529 -0.0193597" mass="0.595898" diaginertia="0.0134452 0.00866201 0.00100593"/>
            <joint name="LF_KFE" pos="0 0 0" axis="0.999981 -0.00590049 0.0018318" range="-3.15076 3.11002" armature="0.0103726" damping="0.00908839" frictionloss="0.0988734"/>
            <geom name="//unnamed_geom_51" class="visual" pos="0.000428867 0.00228674 0" quat="0.707107 0 0 -0.707107" material="shank_l" mesh="shank_l"/>
            <geom name="LF_kfe_act" class="collision" size="0.0604802 0.0201601" pos="0.0211049 0 0" quat="0.5 0.5 -0.5 -0.5"/>
            <geom name="//unnamed_geom_53" class="collision" size="0.0579592 0.0340201 0.0191521" pos="0.0211049 -0.0568746 0" quat="0.5 0.5 -0.5 -0.5" type="box"/>
            <geom name="//unnamed_geom_54" class="visual" pos="0.0137708 -0.086258 -0.331083" quat="0.382683 0 0 -0.92388" material="foot" mesh="foot"/>
            <geom name="LF_calf" class="collision" size="0.01764 0.142382" pos="0.0137709 -0.0869949 -0.165542" quat="0.707107 0 0 -0.707107"/>
            <geom name="LF_foot" class="foot" size="0.0298459" pos="0.0137709 -0.0869949 -0.309042" quat="0.707107 0 0 -0.707107"/>
            <geom name="//unnamed_geom_57" class="reward_collision_sphere" size="0.1008" pos="-0.0527623 0 0"/>
            <geom name="//unnamed_geom_58" class="reward_collision_sphere" size="0.0504001" pos="0.0137709 -0.0869949 -0.309042"/>
            <site name="LF_foot" class="foot" pos="0.0137709 -0.0869949 -0.309042" quat="0.707107 0 0 -0.707107" size="0.01008"/>
          </body>
        </body>
      </body>
      <body name="RF_HIP" pos="0.316712 -0.10169 0.00130781" quat="0.258824 -0.965924 8.4556e-05 0.000519245">
        <inertial pos="0.0611016 0.0145432 -0.00826364" quat="0.134705 0.679515 0.128114 0.709719" mass="2.95281" diaginertia="0.00768217 0.00470268 0.00298381"/>
        <joint name="RF_HAA" pos="0 0 0" axis="0.999997 0.00207431 -0.00150784" range="-0.501053 0.715391" armature="0.00890171" damping="0.00935728" frictionloss="0.112117"/>
        <geom name="//unnamed_geom_59" class="visual" pos="0 -9.65726e-06 -1.58621e-06" quat="0.258819 0.965926 0 0" material="hip_r" mesh="hip_r"/>
        <geom name="//unnamed_geom_60" class="visual" pos="0.0632092 0.0757176 -0.0436452" quat="0.183013 0.683013 0.683013 -0.183013" material="drive" mesh="drive"/>
        <geom name="//unnamed_geom_61" class="collision" size="0.0504001 0.0705602" pos="0.0632092 0.0118299 -0.0067643" quat="-0.353553 0.612372 0.612372 0.353553"/>
        <body name="RF_THIGH" pos="0.0637928 0.0716302 -0.0400358" quat="0.183138 0.68357 0.682345 -0.183297">
          <inertial pos="0.0320235 -0.00245005 -0.239547" quat="0.992709 -0.00417937 -0.0799148 0.0901348" mass="3.08958" diaginertia="0.0400061 0.0290098 0.0037666"/>
          <joint name="RF_HFE" pos="0 0 0" axis="0.999986 0.00273719 0.00450202" stiffness="0.00340399" range="-3.12332 3.15877" armature="0.0101798" damping="0.0108015" frictionloss="0.0958859"/>
          <geom name="//unnamed_geom_62" class="visual" pos="0.00131523 2.07249e-06 0" quat="0.707107 0 0 -0.707107" material="thigh" mesh="thigh"/>
          <geom name="//unnamed_geom_63" class="collision" size="0.0655202 0.0403201" pos="0.0422098 0 0" quat="0.5 0.5 0.5 0.5"/>
          <geom name="//unnamed_geom_64" class="collision" size="0.0378001 0.0302401 0.142445" pos="0.0316574 0 -0.138434" quat="0.707107 0 0 0.707107" type="box"/>
          <geom name="//unnamed_geom_65" class="visual" pos="0.105841 0 -0.279193" quat="1 0 0 0" material="drive" mesh="drive"/>
          <geom name="//unnamed_geom_66" class="collision" size="0.0504001 0.0705602" pos="0.0319739 0 -0.279193" quat="0.707107 0 0.707107 0"/>
          <geom name="//unnamed_geom_67" class="reward_collision_sphere" size="0.0806402" pos="0.0263811 0 0"/>
          <body name="RF_SHANK" pos="0.105367 -2.72329e-05 -0.278404" quat="1 8.36872e-05 0.000111207 5.98489e-05">
            <inertial pos="0.00541782 0.0606487 -0.0781095" quat="0.992786 0.117279 -0.0020689 0.0248323" mass="0.607263" diaginertia="0.0137808 0.00882415 0.00102839"/>
            <joint name="RF_KFE" pos="0 0 0" axis="0.999947 -0.00152199 -0.0101627" range="-3.14413 3.12671" armature="0.0102987" damping="0.0060098" frictionloss="0.0976794"/>
            <geom name="//unnamed_geom_68" class="visual" pos="0.000428865 -0.00228674 0" quat="0.707107 0 0 0.707107" material="shank" mesh="shank_r"/>
            <geom name="RF_kfe_act" class="collision" size="0.0604802 0.0201601" pos="0.0211049 0 0" quat="0.5 0.5 0.5 0.5"/>
            <geom name="//unnamed_geom_70" class="collision" size="0.0579592 0.0340201 0.0191521" pos="0.0211049 0.0568746 0" quat="0.5 0.5 0.5 0.5" type="box"/>
            <geom name="//unnamed_geom_71" class="visual" pos="0.0137711 0.086258 -0.331083" quat="0.382683 0 0 0.92388" material="foot" mesh="foot"/>
            <geom name="RF_calf" class="collision" size="0.01764 0.142382" pos="0.0137709 0.0869949 -0.165542" quat="0.707107 0 0 0.707107"/>
            <geom name="RF_foot" class="foot" size="0.0301498" pos="0.0137709 0.0869949 -0.309042" quat="0.707107 0 0 0.707107"/>
            <geom name="//unnamed_geom_74" class="reward_collision_sphere" size="0.1008" pos="-0.0527623 0 0"/>
            <geom name="//unnamed_geom_75" class="reward_collision_sphere" size="0.0504001" pos="0.0137709 0.0869949 -0.309042"/>
            <site name="RF_foot" class="foot" pos="0.0137709 0.0869949 -0.309042" quat="0.707107 0 0 0.707107" size="0.01008"/>
          </body>
        </body>
      </body>
      <body name="LH_HIP" pos="-0.31625 0.102099 0.000497395" quat="0.000167308 -1.28479e-05 0.966253 -0.257593">
        <inertial pos="0.0621652 0.0153514 -0.00764628" quat="0.135171 0.679373 0.127938 0.709798" mass="2.84051" diaginertia="0.00767584 0.00471144 0.00300037"/>
        <joint name="LH_HAA" pos="0 0 0" axis="0.999999 0.000525175 0.000854555" range="-0.491057 0.729232" armature="0.0100519" damping="0.00841486" frictionloss="0.095641"/>
        <geom name="//unnamed_geom_76" class="visual" pos="0 -9.65726e-06 -1.58621e-06" quat="-0.258819 -0.965926 0 0" material="hip_r" mesh="hip_r"/>
        <geom name="//unnamed_geom_77" class="visual" pos="0.0632092 0.0757176 -0.0436452" quat="0.183013 0.683013 0.683013 -0.183013" material="drive" mesh="drive"/>
        <geom name="//unnamed_geom_78" class="collision" size="0.0504001 0.0705602" pos="0.0632092 0.0118299 -0.0067643" quat="-0.353553 0.612372 0.612372 0.353553"/>
        <body name="LH_THIGH" pos="0.060355 0.0708324 -0.040773" quat="0.182492 0.683005 0.682992 -0.183637">
          <inertial pos="0.0328941 -0.000108551 -0.240609" quat="0.993164 0.00238607 -0.0799684 0.0849947" mass="3.08686" diaginertia="0.0391609 0.0279196 0.00372681"/>
          <joint name="LH_HFE" pos="0 0 0" axis="0.999993 -0.00266647 -0.0026864" range="-3.14666 3.14687" armature="0.00996138" damping="0" frictionloss="0.105976"/>
          <geom name="//unnamed_geom_79" class="visual" pos="0.00131523 2.07249e-06 0" quat="0.707107 0 0 -0.707107" material="thigh" mesh="thigh"/>
          <geom name="//unnamed_geom_80" class="collision" size="0.0655202 0.0403201" pos="0.0422098 0 0" quat="0.5 0.5 -0.5 -0.5"/>
          <geom name="//unnamed_geom_81" class="collision" size="0.0378001 0.0302401 0.142445" pos="0.0316574 0 -0.138434" quat="0.707107 0 0 -0.707107" type="box"/>
          <geom name="//unnamed_geom_82" class="visual" pos="0.105841 0 -0.279193" quat="1 0 0 0" material="drive" mesh="drive"/>
          <geom name="//unnamed_geom_83" class="collision" size="0.0504001 0.0705602" pos="0.0319739 0 -0.279193" quat="0.707107 0 0.707107 0"/>
          <geom name="//unnamed_geom_84" class="reward_collision_sphere" size="0.0806402" pos="0.0263811 0 0"/>
          <body name="LH_SHANK" pos="0.104508 -0.000424684 -0.279936" quat="1 -9.70689e-05 0.000119851 4.34167e-05">
            <inertial pos="0.00585843 0.0605516 -0.0793702" quat="0.992932 0.115877 -0.000864626 0.0256401" mass="0.604265" diaginertia="0.0132596 0.00873235 0.00100449"/>
            <joint name="LH_KFE" pos="0 0 0" axis="0.999978 0.00106517 -0.00655253" range="-3.12784 3.1402" armature="0.0104772" damping="0" frictionloss="0.101909"/>
            <geom name="//unnamed_geom_85" class="visual" pos="0.000428865 -0.00228674 0" quat="-0.707107 0 0 -0.707107" material="shank" mesh="shank_r"/>
            <geom name="LH_kfe_act" class="collision" size="0.0604802 0.0201601" pos="0.0211049 0 0" quat="0.5 0.5 -0.5 -0.5"/>
            <geom name="//unnamed_geom_87" class="collision" size="0.0579592 0.0340201 0.0191521" pos="0.0211049 0.0568746 0" quat="0.5 0.5 -0.5 -0.5" type="box"/>
            <geom name="//unnamed_geom_88" class="visual" pos="0.0137711 0.086258 -0.331083" quat="-0.382683 0 0 -0.92388" material="foot" mesh="foot"/>
            <geom name="LH_calf" class="collision" size="0.01764 0.142382" pos="0.0137709 0.0869949 -0.165542" quat="0.707107 0 0 -0.707107"/>
            <geom name="LH_foot" class="foot" size="0.0317554" pos="0.0137709 0.0869949 -0.309042" quat="0.707107 0 0 -0.707107"/>
            <geom name="//unnamed_geom_91" class="reward_collision_sphere" size="0.1008" pos="-0.0527623 0 0"/>
            <geom name="//unnamed_geom_92" class="reward_collision_sphere" size="0.0504001" pos="0.0137709 0.0869949 -0.309042"/>
            <site name="LH_foot" class="foot" pos="0.0137709 0.0869949 -0.309042" quat="0.707107 0 0 -0.707107" size="0.01008"/>
          </body>
        </body>
      </body>
      <body name="RH_HIP" pos="-0.317031 -0.105139 0.0014649" quat="0.000179653 0.000144247 -0.965952 -0.258723">
        <inertial pos="0.059878 -0.014146 -0.0084068" quat="-0.122969 0.713404 -0.141185 0.675278" mass="2.86311" diaginertia="0.00766309 0.00467547 0.00301835"/>
        <joint name="RH_HAA" pos="0 0 0" axis="1 0.000149964 -3.07591e-05" stiffness="0.0026061" range="-0.71912 0.485675" armature="0.0112395" damping="0.022507" frictionloss="0.0925817"/>
        <geom name="//unnamed_geom_93" class="visual" pos="0 9.65734e-06 -1.58621e-06" quat="-0.258819 0.965926 0 0" material="hip_l" mesh="hip_l"/>
        <geom name="//unnamed_geom_94" class="visual" pos="0.0632092 -0.0757176 -0.0436452" quat="-0.183013 0.683013 -0.683013 -0.183013" material="drive" mesh="drive"/>
        <geom name="//unnamed_geom_95" class="collision" size="0.0504001 0.0705602" pos="0.0632092 -0.0118299 -0.0067643" quat="0.353553 0.612372 -0.612372 0.353553"/>
        <body name="RH_THIGH" pos="0.0637974 -0.0719668 -0.0426758" quat="-0.182773 0.683034 -0.682933 -0.183469">
          <inertial pos="0.0329153 0.00060131 -0.24011" quat="0.993191 -0.00478464 -0.0806069 0.0839702" mass="3.21729" diaginertia="0.040593 0.0286837 0.00373369"/>
          <joint name="RH_HFE" pos="0 0 0" axis="0.999989 -0.00432471 -0.00158074" range="-3.17852 3.14427" armature="0.00980592" damping="0.00963492" frictionloss="0.104366"/>
          <geom name="//unnamed_geom_96" class="visual" pos="0.00131523 2.07249e-06 0" quat="0.707107 0 0 -0.707107" material="thigh" mesh="thigh"/>
          <geom name="//unnamed_geom_97" class="collision" size="0.0655202 0.0403201" pos="0.0422098 0 0" quat="0.5 0.5 0.5 0.5"/>
          <geom name="//unnamed_geom_98" class="collision" size="0.0378001 0.0302401 0.142445" pos="0.0316574 0 -0.138434" quat="0.707107 0 0 0.707107" type="box"/>
          <geom name="//unnamed_geom_99" class="visual" pos="0.105841 0 -0.279193" quat="1 0 0 0" material="drive" mesh="drive"/>
          <geom name="//unnamed_geom_100" class="collision" size="0.0504001 0.0705602" pos="0.0319739 0 -0.279193" quat="0.707107 0 0.707107 0"/>
          <geom name="//unnamed_geom_101" class="reward_collision_sphere" size="0.0806402" pos="0.0263811 0 0"/>
          <body name="RH_SHANK" pos="0.102991 0.00103768 -0.279309" quat="1 -3.85685e-05 -0.000112121 5.21689e-05">
            <inertial pos="0.00829783 -0.0604636 -0.0795179" quat="0.992509 -0.119949 0.00116281 -0.0231884" mass="0.602882" diaginertia="0.0128415 0.00842866 0.000983856"/>
            <joint name="RH_KFE" pos="0 0 0" axis="0.999997 -0.00129673 0.00195222" stiffness="0.000543006" range="-3.1062 3.18481" armature="0.00951352" damping="0.0087561" frictionloss="0.0968931"/>
            <geom name="//unnamed_geom_102" class="visual" pos="0.000428867 0.00228674 0" quat="0.707107 0 0 -0.707107" material="shank_l" mesh="shank_l"/>
            <geom name="RH_kfe_act" class="collision" size="0.0604802 0.0201601" pos="0.0211049 0 0" quat="0.5 0.5 0.5 0.5"/>
            <geom name="//unnamed_geom_104" class="collision" size="0.0579592 0.0340201 0.0191521" pos="0.0211049 -0.0568746 0" quat="0.5 0.5 0.5 0.5" type="box"/>
            <geom name="//unnamed_geom_105" class="visual" pos="0.0137708 -0.086258 -0.331083" quat="0.382683 0 0 -0.92388" material="foot" mesh="foot"/>
            <geom name="RH_calf" class="collision" size="0.01764 0.142382" pos="0.0137709 -0.0869949 -0.165542" quat="0.707107 0 0 0.707107"/>
            <geom name="RH_foot" class="foot" size="0.029931" pos="0.0137709 -0.0869949 -0.309042" quat="0.707107 0 0 0.707107"/>
            <geom name="//unnamed_geom_108" class="reward_collision_sphere" size="0.1008" pos="-0.0527623 0 0"/>
            <geom name="//unnamed_geom_109" class="reward_collision_sphere" size="0.0504001" pos="0.0137709 -0.0869949 -0.309042"/>
            <site name="RH_foot" class="foot" pos="0.0137709 -0.0869949 -0.309042" quat="0.707107 0 0 0.707107" size="0.01008"/>
          </body>
        </body>
      </body>
    </body>
  </worldbody>

  <contact>
    <pair class="/" geom1="floor" geom2="LF_foot" name="//unnamed_contact_0"/>
    <pair class="/" geom1="floor" geom2="RF_foot" name="//unnamed_contact_1"/>
    <pair class="/" geom1="floor" geom2="LH_foot" name="//unnamed_contact_2"/>
    <pair class="/" geom1="floor" geom2="RH_foot" name="//unnamed_contact_3"/>
  </contact>

  <actuator>
    <general name="LF_HAA" class="/" joint="LF_HAA" forcerange="-81.8873 81.8873" gainprm="81.3506" biasprm="0 -81.3506 -1.89305"/>
    <general name="LF_HFE" class="/" joint="LF_HFE" forcerange="-82.9052 82.9052" gainprm="81.3506" biasprm="0 -81.3506 -1.89305"/>
    <general name="LF_KFE" class="/" joint="LF_KFE" forcerange="-81.0196 81.0196" gainprm="81.3506" biasprm="0 -81.3506 -1.89305"/>
    <general name="RF_HAA" class="/" joint="RF_HAA" forcerange="-88.6998 88.6998" gainprm="81.3506" biasprm="0 -81.3506 -1.89305"/>
    <general name="RF_HFE" class="/" joint="RF_HFE" forcerange="-82.4608 82.4608" gainprm="81.3506" biasprm="0 -81.3506 -1.89305"/>
    <general name="RF_KFE" class="/" joint="RF_KFE" forcerange="-78.6245 78.6245" gainprm="81.3506" biasprm="0 -81.3506 -1.89305"/>
    <general name="LH_HAA" class="/" joint="LH_HAA" forcerange="-79.9057 79.9057" gainprm="81.3506" biasprm="0 -81.3506 -1.89305"/>
    <general name="LH_HFE" class="/" joint="LH_HFE" forcerange="-79.6278 79.6278" gainprm="81.3506" biasprm="0 -81.3506 -1.89305"/>
    <general name="LH_KFE" class="/" joint="LH_KFE" forcerange="-83.2163 83.2163" gainprm="81.3506" biasprm="0 -81.3506 -1.89305"/>
    <general name="RH_HAA" class="/" joint="RH_HAA" forcerange="-81.9078 81.9078" gainprm="81.3506" biasprm="0 -81.3506 -1.89305"/>
    <general name="RH_HFE" class="/" joint="RH_HFE" forcerange="-83.4118 83.4118" gainprm="81.3506" biasprm="0 -81.3506 -1.89305"/>
    <general name="RH_KFE" class="/" joint="RH_KFE" forcerange="-86.7002 86.7002" gainprm="81.3506" biasprm="0 -81.3506 -1.89305"/>
  </actuator>

  <sensor>
    <gyro site="imu" name="imu_angular_velocity"/>
    <velocimeter site="imu" name="imu_linear_velocity"/>
    <framelinvel objtype="site" objname="LF_foot" name="LF_foot_global_linear_velocity"/>
    <framelinvel objtype="site" objname="RF_foot" name="RF_foot_global_linear_velocity"/>
    <framelinvel objtype="site" objname="LH_foot" name="LH_foot_global_linear_velocity"/>
    <framelinvel objtype="site" objname="RH_foot" name="RH_foot_global_linear_velocity"/>
  </sensor>

  <keyframe>
    <key name="home" qpos="0 0 0.55 1 0 0 0 0 0.4 -0.8 0 -0.4 0.8 0 -0.4 0.8 0 0.4 -0.8"/>
  </keyframe>
</mujoco>
