<mujoco model="anymal_c">
  <compiler angle="radian" assetdir="assets" balanceinertia="true" inertiafromgeom="false"/>

  <option timestep="0.005" density="1.2" viscosity="2e-05"/>

  <size nkey="1"/>

  <visual>
    <quality shadowsize="8192"/>
    <map shadowclip="0.5"/>
  </visual>

  <default>
    <default class="/">
      <material specular="0" shininess="0.25"/>
      <geom contype="0" conaffinity="0" group="1" solref="-1000 -80"/>
      <site size="0.01 0.005 0.005" group="5"/>
      <general forcelimited="true" forcerange="-80 80" biastype="affine" gainprm="80" biasprm="0 -80 -2"/>
      <default class="anymal_c">
        <joint armature="0.01" damping="0.01" frictionloss="0.1"/>
        <default class="visual">
          <geom type="mesh" group="2"/>
          <default class="visual_zflip"/>
        </default>
        <default class="collision">
          <geom type="cylinder" group="3"/>
          <default class="foot">
            <geom size="0.03 0 0" type="sphere" condim="6" priority="1" friction="0.8 0.02 0.01" solimp="0.015 1 0.03"/>
          </default>
        </default>
      </default>
      <default class="reward_collision_sphere">
        <geom group="5" rgba="1 0 0 1"/>
      </default>
    </default>
  </default>

  <asset>
    <texture type="skybox" colorspace="auto" name="//unnamed_texture_0" builtin="gradient" rgb1="0.95 0.95 0.95" rgb2="0.95 0.95 0.95" width="100" height="600"/>
    <texture type="2d" colorspace="auto" name="texplane" builtin="checker" rgb1="0.345 0.575 0.748" rgb2="0.345 0.575 0.748" markrgb="1 1 1" width="512" height="512"/>
    <texture type="2d" colorspace="linear" name="base" file="base.png"/>
    <texture type="2d" colorspace="linear" name="top_shell" file="top_shell.png"/>
    <texture type="2d" colorspace="linear" name="bottom_shell" file="bottom_shell.png"/>
    <texture type="2d" colorspace="linear" name="remote" file="remote.png"/>
    <texture type="2d" colorspace="linear" name="hatch" file="hatch.png"/>
    <texture type="2d" colorspace="linear" name="handle" file="handle.png"/>
    <texture type="2d" colorspace="linear" name="face" file="face.png"/>
    <texture type="2d" colorspace="linear" name="battery" file="battery.png"/>
    <texture type="2d" colorspace="linear" name="lidar_cage" file="lidar_cage.png"/>
    <texture type="2d" colorspace="linear" name="depth_camera" file="depth_camera.png"/>
    <texture type="2d" colorspace="linear" name="wide_angle_camera" file="wide_angle_camera.png"/>
    <texture type="2d" colorspace="linear" name="lidar" file="lidar.png"/>
    <texture type="2d" colorspace="linear" name="drive" file="drive.png"/>
    <texture type="2d" colorspace="linear" name="hip_l" file="hip_l.png"/>
    <texture type="2d" colorspace="linear" name="shank_l" file="shank_l.png"/>
    <texture type="2d" colorspace="linear" name="foot" file="foot.png"/>
    <texture type="2d" colorspace="linear" name="thigh" file="thigh.png"/>
    <texture type="2d" colorspace="linear" name="shank_r" file="shank_r.png"/>
    <texture type="2d" colorspace="linear" name="hip_r" file="hip_r.png"/>
    <material name="MatPlane" class="/" texture="texplane" texuniform="true" texrepeat="2 2" specular="0.9" shininess="0.5"/>
    <material name="black_plastic" class="/" rgba="0.007 0.007 0.007 1"/>
    <material name="green" class="/" rgba="0.052 0.178 0.033 1"/>
    <material name="red" class="/" rgba="0.178 0.006 0.005 1"/>
    <material name="yellow" class="/" rgba="0.178 0.119 0.006 1"/>
    <material name="lwl" class="/" rgba="0.8 0.8 0.8 1"/>
    <material name="base" class="/" texture="base"/>
    <material name="top_shell" class="/" texture="top_shell"/>
    <material name="bottom_shell" class="/" texture="bottom_shell"/>
    <material name="hip_l" class="/" texture="hip_l"/>
    <material name="thigh" class="/" texture="thigh"/>
    <material name="shank_l" class="/" texture="shank_l"/>
    <material name="foot" class="/" texture="foot"/>
    <material name="hip_r" class="/" texture="hip_r"/>
    <material name="shank" class="/" texture="shank_r"/>
    <material name="hatch" class="/" texture="hatch"/>
    <material name="remote" class="/" texture="remote"/>
    <material name="handle" class="/" texture="handle"/>
    <material name="face" class="/" texture="face"/>
    <material name="depth_camera" class="/" texture="depth_camera"/>
    <material name="wide_angle_camera" class="/" texture="wide_angle_camera"/>
    <material name="battery" class="/" texture="battery"/>
    <material name="lidar_cage" class="/" texture="lidar_cage"/>
    <material name="lidar" class="/" texture="lidar"/>
    <material name="drive" class="/" texture="drive"/>
    <mesh name="base_0" class="/" file="base_0.obj"/>
    <mesh name="base_1" class="/" file="base_1.obj"/>
    <mesh name="base_2" class="/" file="base_2.obj"/>
    <mesh name="base_3" class="/" file="base_3.obj"/>
    <mesh name="base_4" class="/" file="base_4.obj"/>
    <mesh name="base_5" class="/" file="base_5.obj"/>
    <mesh name="top_shell" class="/" file="top_shell.obj"/>
    <mesh name="bottom_shell" class="/" file="bottom_shell.obj"/>
    <mesh name="remote" class="/" file="remote.obj"/>
    <mesh name="handle" class="/" file="handle.obj"/>
    <mesh name="face" class="/" file="face.obj"/>
    <mesh name="wide_angle_camera" class="/" file="wide_angle_camera.obj"/>
    <mesh name="depth_camera" class="/" file="depth_camera.obj"/>
    <mesh name="battery" class="/" file="battery.obj"/>
    <mesh name="lidar_cage" class="/" file="lidar_cage.obj"/>
    <mesh name="lidar" class="/" file="lidar.obj"/>
    <mesh name="drive" class="/" file="drive.obj"/>
    <mesh name="hip_l" class="/" file="hip_l.obj"/>
    <mesh name="thigh" class="/" file="thigh.obj"/>
    <mesh name="shank_l" class="/" file="shank_l.obj"/>
    <mesh name="foot" class="/" file="foot.obj"/>
    <mesh name="hip_r" class="/" file="hip_r.obj"/>
    <mesh name="hatch" class="/" file="hatch.obj"/>
    <mesh name="shank_r" class="/" file="shank_r.obj"/>
  </asset>

  <worldbody>
    <geom name="floor" class="/" size="100 100 0.125" type="plane" group="0" material="MatPlane"/>
    <light name="toplight_shadow" class="/" pos="0 0 5" dir="0.0990148 0.0990148 -0.990148" type="directional" ambient="0.04 0.04 0.04" diffuse="0.55 0.55 0.55" specular="0.12 0.12 0.12"/>
    <light name="toplight_fill" class="/" pos="0 0 5" dir="0.0990148 0.0990148 -0.990148" type="directional" castshadow="false" ambient="0.04 0.04 0.04" diffuse="0.3 0.3 0.3" specular="0.08 0.08 0.08"/>
    <body name="trunk" childclass="anymal_c" pos="0.0148928 0.0106948 0.00677671" quat="0.999981 0.000323584 -0.00403993 0.00459691">
      <inertial pos="0.0167228 0.0019758 0.0696639" quat="0.501903 0.476944 0.523715 0.496327" mass="10.5997" diaginertia="0.0136856 0.101894 0.851815"/>
      <joint name="//unnamed_joint_0" type="free" armature="0" damping="0" frictionloss="0"/>
      <geom name="//unnamed_geom_1" class="visual" material="green" mesh="base_0"/>
      <geom name="//unnamed_geom_2" class="visual" material="yellow" mesh="base_1"/>
      <geom name="//unnamed_geom_3" class="visual" material="red" mesh="base_2"/>
      <geom name="//unnamed_geom_4" class="visual" material="black_plastic" mesh="base_3"/>
      <geom name="//unnamed_geom_5" class="visual" material="lwl" mesh="base_4"/>
      <geom name="//unnamed_geom_6" class="visual" material="base" mesh="base_5"/>
      <geom name="trunk_1" class="collision" size="0.243422 0.0587569 0.0755446" type="box"/>
      <geom name="trunk_2" class="collision" size="0.0755446 0.0608554" pos="0.0994465 0.0489327 0" quat="0.707107 0 0.707107 0"/>
      <geom name="trunk_3" class="collision" size="0.0755446 0.0608554" pos="-0.0994465 0.0489327 0" quat="0.707107 0 0.707107 0"/>
      <geom name="trunk_4" class="collision" size="0.0755446 0.0608554" pos="0.0994465 -0.0489327 0" quat="0.707107 0 0.707107 0"/>
      <geom name="trunk_5" class="collision" size="0.0755446 0.0608554" pos="-0.0994465 -0.0489327 0" quat="0.707107 0 0.707107 0"/>
      <geom name="//unnamed_geom_12" class="visual" material="top_shell" mesh="top_shell"/>
      <geom name="//unnamed_geom_13" class="visual" material="bottom_shell" mesh="bottom_shell"/>
      <geom name="//unnamed_geom_14" class="visual" material="remote" mesh="remote"/>
      <geom name="//unnamed_geom_15" class="visual" material="handle" mesh="handle"/>
      <geom name="//unnamed_geom_16" class="visual" pos="0.18952 0 0" quat="1 0 0 0" material="face" mesh="face"/>
      <geom name="trunk_6" class="collision" size="0.0461661 0.0587569 0.0755446" pos="0.214667 0 0" type="box"/>
      <geom name="//unnamed_geom_18" class="collision" size="0.0755446 0.0461661" pos="0.214667 0.0489327 0" quat="0.707107 0 0.707107 0"/>
      <geom name="//unnamed_geom_19" class="collision" size="0.0755446 0.0461661" pos="0.214667 -0.0489327 0" quat="0.707107 0 0.707107 0"/>
      <geom name="//unnamed_geom_20" class="visual" pos="0.211116 0 -0.0466427" quat="0.965926 0 0.258819 0" material="depth_camera" mesh="depth_camera"/>
      <geom name="//unnamed_geom_21" class="visual" pos="0.234557 0 0.0203875" material="wide_angle_camera" mesh="wide_angle_camera"/>
      <geom name="//unnamed_geom_22" class="visual_zflip" pos="-0.18952 0 0" quat="0 0 0 1" material="face" mesh="face"/>
      <geom name="trunk_7" class="collision" size="0.0461661 0.0587569 0.0755446" pos="-0.214667 0 0" quat="0 0 0 1" type="box"/>
      <geom name="//unnamed_geom_24" class="collision" size="0.0755446 0.0461661" pos="-0.214667 -0.0489327 0" quat="0 -0.707107 0 0.707107"/>
      <geom name="//unnamed_geom_25" class="collision" size="0.0755446 0.0461661" pos="-0.214667 0.0489327 0" quat="0 -0.707107 0 0.707107"/>
      <geom name="//unnamed_geom_26" class="visual" pos="-0.211116 0 -0.0466427" quat="0 -0.258819 0 0.965926" material="depth_camera" mesh="depth_camera"/>
      <geom name="//unnamed_geom_27" class="visual_zflip" pos="-0.234557 0 0.0203875" quat="0 0 0 1" material="wide_angle_camera" mesh="wide_angle_camera"/>
      <geom name="//unnamed_geom_28" class="visual" material="battery" mesh="battery"/>
      <geom name="//unnamed_geom_29" class="visual" pos="0 0.0566591 0.0326875" quat="0.683013 -0.183013 0.183013 0.683013" material="depth_camera" mesh="depth_camera"/>
      <geom name="//unnamed_geom_30" class="visual" pos="0 -0.0566591 0.0326875" quat="0.683013 0.183013 0.183013 -0.683013" material="depth_camera" mesh="depth_camera"/>
      <geom name="//unnamed_geom_31" class="visual" pos="-0.16643 0 0.100099" quat="1 0 0 0" material="lidar_cage" mesh="lidar_cage"/>
      <geom name="trunk_8" class="collision" size="0.0587569 0.0503631" pos="-0.16643 0 0.181812"/>
      <geom name="//unnamed_geom_33" class="visual" pos="-0.16643 9.50017e-05 0.193661" quat="0.707107 0 0 -0.707107" material="lidar" mesh="lidar"/>
      <geom name="//unnamed_geom_34" class="visual" pos="0.137122 0.0729354 -1.14343e-08" quat="0.258819 0.965926 0 0" material="drive" mesh="drive"/>
      <geom name="//unnamed_geom_35" class="visual" pos="0.137122 -0.0729354 1.14343e-08" quat="0.258819 -0.965926 0 0" material="drive" mesh="drive"/>
      <geom name="//unnamed_geom_36" class="visual" pos="-0.137122 0.0729354 1.14343e-08" quat="0 0 0.965926 -0.258819" material="drive" mesh="drive"/>
      <geom name="//unnamed_geom_37" class="visual" pos="-0.137122 -0.0729354 -1.14343e-08" quat="0 0 -0.965926 -0.258819" material="drive" mesh="drive"/>
      <geom name="//unnamed_geom_38" class="visual" pos="0.0530381 0 0.099418" quat="1 0 0 0" material="hatch" mesh="hatch"/>
      <geom name="//unnamed_geom_39" class="reward_collision_sphere" size="0.100726"/>
      <geom name="//unnamed_geom_40" class="reward_collision_sphere" size="0.100726" pos="0.205751 0 0"/>
      <geom name="//unnamed_geom_41" class="reward_collision_sphere" size="0.100726" pos="-0.205751 0 0"/>
      <site name="imu" pos="0.109408 -0.0262191 0.0889139" size="0.00839385"/>
      <camera name="track" pos="0 -1.39808 0" quat="0.707107 0.707107 0 0" mode="trackcom"/>
      <camera name="ego_camera" pos="0.205751 0 -0.0544756" quat="-0.5 -0.5 0.5 0.5"/>
      <body name="LF_HIP" pos="0.146675 0.0825155 -0.00687403" quat="0.258123 0.966084 0.00740493 0.000187094">
        <inertial pos="0.0417362 -0.00219545 -0.00269044" quat="-0.130343 0.71395 -0.130998 0.675371" mass="1.42351" diaginertia="0.000101882 0.00080728 0.0114622"/>
        <joint name="LF_HAA" pos="0 0 0" axis="0.999855 -0.00247277 0.0168345" stiffness="0.0303939" range="-0.685955 0.75168" armature="0.00352445" damping="0.0584741" frictionloss="0.0538337"/>
        <geom name="//unnamed_geom_42" class="visual" pos="0 -0.000672627 0.000110478" quat="0.258819 -0.965926 0 0" material="hip_l" mesh="hip_l"/>
        <geom name="//unnamed_geom_43" class="visual" pos="0.0273878 -0.0366055 -0.026037" quat="0.183013 -0.683013 0.683013 0.183013" material="drive" mesh="drive"/>
        <geom name="//unnamed_geom_44" class="collision" size="0.0419692 0.0587569" pos="0.0273878 -0.00836035 -0.00940385" quat="-0.353553 -0.612372 0.612372 -0.353553"/>
        <body name="LF_THIGH" pos="0.0296024 -0.0540618 -0.06361" quat="0.182859 -0.682993 0.68313 0.182803">
          <inertial pos="-0.000753234 -0.0022682 -0.348224" quat="0.992686 0.000201848 -0.078863 0.0914042" mass="1.93043" diaginertia="0.00062264 0.00468092 0.021284"/>
          <joint name="LF_HFE" pos="0 0 0" axis="0.999247 0.0301077 0.024494" range="-2.89374 2.90754" armature="0.00376295" damping="0.0824803" frictionloss="0.0498738"/>
          <geom name="//unnamed_geom_45" class="visual" pos="-0.00481112 -7.5812e-06 0" quat="0.707107 0 0 -0.707107" material="thigh" mesh="thigh"/>
          <geom name="//unnamed_geom_46" class="collision" size="0.05456 0.0335754" pos="0.018289 0 0" quat="0.5 0.5 -0.5 -0.5"/>
          <geom name="//unnamed_geom_47" class="collision" size="0.0314769 0.0251815 0.118617" pos="0.0137168 0 -0.192454" quat="0.707107 0 0 -0.707107" type="box"/>
          <geom name="//unnamed_geom_48" class="visual" pos="0.0458597 0 -0.388139" quat="1 0 0 0" material="drive" mesh="drive"/>
          <geom name="//unnamed_geom_49" class="collision" size="0.0419692 0.0587569" pos="0.0138539 0 -0.388139" quat="0.707107 0 0.707107 0"/>
          <geom name="//unnamed_geom_50" class="reward_collision_sphere" size="0.0671508" pos="0.0114306 0 0"/>
          <body name="LF_SHANK" pos="0.0457742 -0.00435659 -0.386359" quat="0.999987 -0.00305184 0.00238728 -0.0032039">
            <inertial pos="-0.00677215 -0.0512765 -0.0984934" quat="0.985141 -0.171319 -0.0051364 0.0110261" mass="0.327278" diaginertia="0.000219695 0.00139293 0.00595633"/>
            <joint name="LF_KFE" pos="0 0 0" axis="0.999752 -0.0221857 0.00182122" stiffness="0.00300116" range="-3.09915 3.3942" armature="0.0124975" damping="0.0124525" frictionloss="0.0968264"/>
            <geom name="//unnamed_geom_51" class="visual" pos="-0.0015688 -0.00836493 0" quat="0.707107 0 0 -0.707107" material="shank_l" mesh="shank_l"/>
            <geom name="LF_kfe_act" class="collision" size="0.0503631 0.0167877" pos="0.0091445 0 0" quat="0.5 0.5 -0.5 -0.5"/>
            <geom name="//unnamed_geom_53" class="collision" size="0.0482638 0.0283292 0.0159483" pos="0.0091445 -0.040194 0" quat="0.5 0.5 -0.5 -0.5" type="box"/>
            <geom name="//unnamed_geom_54" class="visual" pos="0.00596717 -0.0641761 -0.460278" quat="0.382683 0 0 -0.92388" material="foot" mesh="foot"/>
            <geom name="LF_calf" class="collision" size="0.0146892 0.118565" pos="0.00596679 -0.0614804 -0.230139" quat="0.707107 0 0 -0.707107"/>
            <geom name="LF_foot" class="foot" size="0.0207764" pos="0.00596679 -0.0614804 -0.429636" quat="0.707107 0 0 -0.707107"/>
            <geom name="//unnamed_geom_57" class="reward_collision_sphere" size="0.0839385" pos="-0.0228613 0 0"/>
            <geom name="//unnamed_geom_58" class="reward_collision_sphere" size="0.0419692" pos="0.00596679 -0.0614804 -0.429636"/>
            <site name="LF_foot" class="foot" pos="0.00596679 -0.0614804 -0.429636" quat="0.707107 0 0 -0.707107" size="0.00839385"/>
          </body>
        </body>
      </body>
      <body name="RF_HIP" pos="0.139974 -0.0855296 -4.26136e-07" quat="0.257179 -0.966358 0.00235781 0.00255802">
        <inertial pos="0.0140152 0.00554649 -0.0120522" quat="0.132866 0.682115 0.122689 0.708529" mass="1.12419" diaginertia="0.000105777 0.000750902 0.0150102"/>
        <joint name="RF_HAA" pos="0 0 0" axis="0.999998 -0.00172176 -0.000781309" stiffness="0.0205282" range="-0.670023 0.709969" armature="0.0149713" damping="0.0138497" frictionloss="0.0205924"/>
        <geom name="//unnamed_geom_59" class="visual" pos="0 0.000672621 0.000110478" quat="0.258819 0.965926 0 0" material="hip_r" mesh="hip_r"/>
        <geom name="//unnamed_geom_60" class="visual" pos="0.0273878 0.0366055 -0.026037" quat="0.183013 0.683013 0.683013 -0.183013" material="drive" mesh="drive"/>
        <geom name="//unnamed_geom_61" class="collision" size="0.0419692 0.0587569" pos="0.0273878 0.00836035 -0.00940385" quat="-0.353553 0.612372 0.612372 0.353553"/>
        <body name="RF_THIGH" pos="0.0259509 0.0560172 -0.0705487" quat="0.180002 0.683936 0.681176 -0.189289">
          <inertial pos="0.0250778 0.0156499 -0.329265" quat="0.992741 -0.0109924 -0.0905356 0.0784078" mass="2.35246" diaginertia="0.000652819 0.00588495 0.024388"/>
          <joint name="RF_HFE" pos="0 0 0" axis="0.999842 0.0165783 0.00635413" stiffness="0.0118214" range="-3.02914 3.27087" armature="0.00843749" damping="0.00458638" frictionloss="0.0535671"/>
          <geom name="//unnamed_geom_62" class="visual" pos="-0.00481112 -7.5812e-06 0" quat="0.707107 0 0 -0.707107" material="thigh" mesh="thigh"/>
          <geom name="//unnamed_geom_63" class="collision" size="0.05456 0.0335754" pos="0.018289 0 0" quat="0.5 0.5 0.5 0.5"/>
          <geom name="//unnamed_geom_64" class="collision" size="0.0314769 0.0251815 0.118617" pos="0.0137168 0 -0.192454" quat="0.707107 0 0 0.707107" type="box"/>
          <geom name="//unnamed_geom_65" class="visual" pos="0.0458597 0 -0.388139" quat="1 0 0 0" material="drive" mesh="drive"/>
          <geom name="//unnamed_geom_66" class="collision" size="0.0419692 0.0587569" pos="0.0138539 0 -0.388139" quat="0.707107 0 0.707107 0"/>
          <geom name="//unnamed_geom_67" class="reward_collision_sphere" size="0.0671508" pos="0.0114306 0 0"/>
          <body name="RF_SHANK" pos="0.0355948 0.00263961 -0.389071" quat="1 4.49543e-05 0.000435276 -0.000392843">
            <inertial pos="-0.00596655 0.0419994 -0.104588" quat="0.991522 0.128681 0.00315679 0.0177347" mass="0.275108" diaginertia="0.000143778 0.00148086 0.00435452"/>
            <joint name="RF_KFE" pos="0 0 0" axis="0.998183 -0.060258 -0.000702425" stiffness="0.0462492" range="-3.12072 3.19173" armature="0.00763634" damping="0" frictionloss="0.0635132"/>
            <geom name="//unnamed_geom_68" class="visual" pos="-0.00156879 0.00836491 0" quat="0.707107 0 0 0.707107" material="shank" mesh="shank_r"/>
            <geom name="RF_kfe_act" class="collision" size="0.0503631 0.0167877" pos="0.0091445 0 0" quat="0.5 0.5 0.5 0.5"/>
            <geom name="//unnamed_geom_70" class="collision" size="0.0482638 0.0283292 0.0159483" pos="0.0091445 0.040194 0" quat="0.5 0.5 0.5 0.5" type="box"/>
            <geom name="//unnamed_geom_71" class="visual" pos="0.00596641 0.0641761 -0.460278" quat="0.382683 0 0 0.92388" material="foot" mesh="foot"/>
            <geom name="RF_calf" class="collision" size="0.0146892 0.118565" pos="0.00596679 0.0614804 -0.230139" quat="0.707107 0 0 0.707107"/>
            <geom name="RF_foot" class="foot" size="0.027812" pos="0.00596679 0.0614804 -0.429636" quat="0.707107 0 0 0.707107"/>
            <geom name="//unnamed_geom_74" class="reward_collision_sphere" size="0.0839385" pos="-0.0228613 0 0"/>
            <geom name="//unnamed_geom_75" class="reward_collision_sphere" size="0.0419692" pos="0.00596679 0.0614804 -0.429636"/>
            <site name="RF_foot" class="foot" pos="0.00596679 0.0614804 -0.429636" quat="0.707107 0 0 0.707107" size="0.00839385"/>
          </body>
        </body>
      </body>
      <body name="LH_HIP" pos="-0.133474 0.0690069 -0.00912998" quat="0.00577173 0.00494624 0.96677 -0.255536">
        <inertial pos="0.0110214 0.0149088 -0.0136139" quat="0.136377 0.680537 0.128343 0.708377" mass="1.52543" diaginertia="0.000115824 0.000694289 0.016083"/>
        <joint name="LH_HAA" pos="0 0 0" axis="0.999761 -0.0217804 0.00205602" range="-0.414384 0.661856" armature="0.00801669" damping="0.0183261" frictionloss="0.055914"/>
        <geom name="//unnamed_geom_76" class="visual" pos="0 0.000672621 0.000110478" quat="-0.258819 -0.965926 0 0" material="hip_r" mesh="hip_r"/>
        <geom name="//unnamed_geom_77" class="visual" pos="0.0273878 0.0366055 -0.026037" quat="0.183013 0.683013 0.683013 -0.183013" material="drive" mesh="drive"/>
        <geom name="//unnamed_geom_78" class="collision" size="0.0419692 0.0587569" pos="0.0273878 0.00836035 -0.00940385" quat="-0.353553 0.612372 0.612372 0.353553"/>
        <body name="LH_THIGH" pos="0.0416681 0.0434896 -0.0681975" quat="0.180589 0.68386 0.684538 -0.17644">
          <inertial pos="0.0147824 0.00384255 -0.330814" quat="0.99463 -0.0503342 -0.0810438 0.0401245" mass="2.09331" diaginertia="0.000561266 0.00570004 0.0180411"/>
          <joint name="LH_HFE" pos="0 0 0" axis="0.999985 0.00195829 0.00514165" range="-3.0777 3.1444" armature="0.0121909" damping="0.0828358" frictionloss="0.110141"/>
          <geom name="//unnamed_geom_79" class="visual" pos="-0.00481112 -7.5812e-06 0" quat="0.707107 0 0 -0.707107" material="thigh" mesh="thigh"/>
          <geom name="//unnamed_geom_80" class="collision" size="0.05456 0.0335754" pos="0.018289 0 0" quat="0.5 0.5 -0.5 -0.5"/>
          <geom name="//unnamed_geom_81" class="collision" size="0.0314769 0.0251815 0.118617" pos="0.0137168 0 -0.192454" quat="0.707107 0 0 -0.707107" type="box"/>
          <geom name="//unnamed_geom_82" class="visual" pos="0.0458597 0 -0.388139" quat="1 0 0 0" material="drive" mesh="drive"/>
          <geom name="//unnamed_geom_83" class="collision" size="0.0419692 0.0587569" pos="0.0138539 0 -0.388139" quat="0.707107 0 0.707107 0"/>
          <geom name="//unnamed_geom_84" class="reward_collision_sphere" size="0.0671508" pos="0.0114306 0 0"/>
          <body name="LH_SHANK" pos="0.0400497 -0.00343822 -0.396162" quat="1 -0.00011458 0.000235635 6.07423e-05">
            <inertial pos="0.00246188 0.0423988 -0.118936" quat="0.993189 0.113112 -0.00116889 0.0279156" mass="0.350498" diaginertia="0.000202443 0.00152238 0.00535154"/>
            <joint name="LH_KFE" pos="0 0 0" axis="0.999998 0.00206468 -2.03749e-05" stiffness="0.00775212" range="-3.04171 3.12317" armature="0.0121212" damping="0.0715391" frictionloss="0.0872333"/>
            <geom name="//unnamed_geom_85" class="visual" pos="-0.00156879 0.00836491 0" quat="-0.707107 0 0 -0.707107" material="shank" mesh="shank_r"/>
            <geom name="LH_kfe_act" class="collision" size="0.0503631 0.0167877" pos="0.0091445 0 0" quat="0.5 0.5 -0.5 -0.5"/>
            <geom name="//unnamed_geom_87" class="collision" size="0.0482638 0.0283292 0.0159483" pos="0.0091445 0.040194 0" quat="0.5 0.5 -0.5 -0.5" type="box"/>
            <geom name="//unnamed_geom_88" class="visual" pos="0.00596641 0.0641761 -0.460278" quat="-0.382683 0 0 -0.92388" material="foot" mesh="foot"/>
            <geom name="LH_calf" class="collision" size="0.0146892 0.118565" pos="0.00596679 0.0614804 -0.230139" quat="0.707107 0 0 -0.707107"/>
            <geom name="LH_foot" class="foot" size="0.0151708" pos="0.00596679 0.0614804 -0.429636" quat="0.707107 0 0 -0.707107"/>
            <geom name="//unnamed_geom_91" class="reward_collision_sphere" size="0.0839385" pos="-0.0228613 0 0"/>
            <geom name="//unnamed_geom_92" class="reward_collision_sphere" size="0.0419692" pos="0.00596679 0.0614804 -0.429636"/>
            <site name="LH_foot" class="foot" pos="0.00596679 0.0614804 -0.429636" quat="0.707107 0 0 -0.707107" size="0.00839385"/>
          </body>
        </body>
      </body>
      <body name="RH_HIP" pos="-0.13862 -0.0582196 -0.0119577" quat="-0.000381834 -0.00490685 -0.966521 -0.25654">
        <inertial pos="0.0258084 -0.0226842 -0.0111621" quat="-0.19311 0.709477 -0.150157 0.660912" mass="1.67349" diaginertia="0.0001044 0.000725574 0.0168646"/>
        <joint name="RH_HAA" pos="0 0 0" axis="0.99983 -0.0179651 0.00418564" range="-0.791555 0.49494" armature="0.001503" damping="0" frictionloss="0.139192"/>
        <geom name="//unnamed_geom_93" class="visual" pos="0 -0.000672627 0.000110478" quat="-0.258819 0.965926 0 0" material="hip_l" mesh="hip_l"/>
        <geom name="//unnamed_geom_94" class="visual" pos="0.0273878 -0.0366055 -0.026037" quat="-0.183013 0.683013 -0.683013 -0.183013" material="drive" mesh="drive"/>
        <geom name="//unnamed_geom_95" class="collision" size="0.0419692 0.0587569" pos="0.0273878 -0.00836035 -0.00940385" quat="0.353553 0.612372 -0.612372 0.353553"/>
        <body name="RH_THIGH" pos="0.026966 -0.0469766 -0.0446831" quat="-0.186263 0.681314 -0.683657 -0.183657">
          <inertial pos="0.0135208 0.00800619 -0.335913" quat="0.993252 -0.00536901 -0.0792627 0.0844926" mass="2.15955" diaginertia="0.00071188 0.00538704 0.024877"/>
          <joint name="RH_HFE" pos="0 0 0" axis="0.999795 0.0202306 -0.000622923" stiffness="0.0521085" range="-2.86187 2.94989" armature="0.00505461" damping="0.0264381" frictionloss="0.105173"/>
          <geom name="//unnamed_geom_96" class="visual" pos="-0.00481112 -7.5812e-06 0" quat="0.707107 0 0 -0.707107" material="thigh" mesh="thigh"/>
          <geom name="//unnamed_geom_97" class="collision" size="0.05456 0.0335754" pos="0.018289 0 0" quat="0.5 0.5 0.5 0.5"/>
          <geom name="//unnamed_geom_98" class="collision" size="0.0314769 0.0251815 0.118617" pos="0.0137168 0 -0.192454" quat="0.707107 0 0 0.707107" type="box"/>
          <geom name="//unnamed_geom_99" class="visual" pos="0.0458597 0 -0.388139" quat="1 0 0 0" material="drive" mesh="drive"/>
          <geom name="//unnamed_geom_100" class="collision" size="0.0419692 0.0587569" pos="0.0138539 0 -0.388139" quat="0.707107 0 0.707107 0"/>
          <geom name="//unnamed_geom_101" class="reward_collision_sphere" size="0.0671508" pos="0.0114306 0 0"/>
          <body name="RH_SHANK" pos="0.062862 -0.0112603 -0.383642" quat="0.999998 -0.00144849 -8.81542e-05 0.00121448">
            <inertial pos="-0.0137254 -0.0418254 -0.118654" quat="0.990518 -0.137145 0.00807858 -0.00081992" mass="0.332562" diaginertia="0.000215286 0.00208968 0.0054438"/>
            <joint name="RH_KFE" pos="0 0 0" axis="0.999817 0.0167469 0.00926522" range="-3.36147 2.80958" armature="0.0139233" damping="0" frictionloss="0.0619371"/>
            <geom name="//unnamed_geom_102" class="visual" pos="-0.0015688 -0.00836493 0" quat="0.707107 0 0 -0.707107" material="shank_l" mesh="shank_l"/>
            <geom name="RH_kfe_act" class="collision" size="0.0503631 0.0167877" pos="0.0091445 0 0" quat="0.5 0.5 0.5 0.5"/>
            <geom name="//unnamed_geom_104" class="collision" size="0.0482638 0.0283292 0.0159483" pos="0.0091445 -0.040194 0" quat="0.5 0.5 0.5 0.5" type="box"/>
            <geom name="//unnamed_geom_105" class="visual" pos="0.00596717 -0.0641761 -0.460278" quat="0.382683 0 0 -0.92388" material="foot" mesh="foot"/>
            <geom name="RH_calf" class="collision" size="0.0146892 0.118565" pos="0.00596679 -0.0614804 -0.230139" quat="0.707107 0 0 0.707107"/>
            <geom name="RH_foot" class="foot" size="0.0280792" pos="0.00596679 -0.0614804 -0.429636" quat="0.707107 0 0 0.707107"/>
            <geom name="//unnamed_geom_108" class="reward_collision_sphere" size="0.0839385" pos="-0.0228613 0 0"/>
            <geom name="//unnamed_geom_109" class="reward_collision_sphere" size="0.0419692" pos="0.00596679 -0.0614804 -0.429636"/>
            <site name="RH_foot" class="foot" pos="0.00596679 -0.0614804 -0.429636" quat="0.707107 0 0 0.707107" size="0.00839385"/>
          </body>
        </body>
      </body>
    </body>
  </worldbody>

  <contact>
    <pair class="/" geom1="floor" geom2="LF_foot" name="//unnamed_contact_0"/>
    <pair class="/" geom1="floor" geom2="RF_foot" name="//unnamed_contact_1"/>
    <pair class="/" geom1="floor" geom2="LH_foot" name="//unnamed_contact_2"/>
    <pair class="/" geom1="floor" geom2="RH_foot" name="//unnamed_contact_3"/>
  </contact>

  <actuator>
    <general name="LF_HAA" class="/" joint="LF_HAA" forcerange="-71.4441 71.4441" gainprm="65.5682" biasprm="0 -65.5682 -1.67894"/>
    <general name="LF_HFE" class="/" joint="LF_HFE" forcerange="-88.435 88.435" gainprm="65.5682" biasprm="0 -65.5682 -1.67894"/>
    <general name="LF_KFE" class="/" joint="LF_KFE" forcerange="-71.4026 71.4026" gainprm="65.5682" biasprm="0 -65.5682 -1.67894"/>
    <general name="RF_HAA" class="/" joint="RF_HAA" forcerange="-27.0495 27.0495" gainprm="65.5682" biasprm="0 -65.5682 -1.67894"/>
    <general name="RF_HFE" class="/" joint="RF_HFE" forcerange="-66.3329 66.3329" gainprm="65.5682" biasprm="0 -65.5682 -1.67894"/>
    <general name="RF_KFE" class="/" joint="RF_KFE" forcerange="-95.6554 95.6554" gainprm="65.5682" biasprm="0 -65.5682 -1.67894"/>
    <general name="LH_HAA" class="/" joint="LH_HAA" forcerange="-73.8562 73.8562" gainprm="65.5682" biasprm="0 -65.5682 -1.67894"/>
    <general name="LH_HFE" class="/" joint="LH_HFE" forcerange="-74.1827 74.1827" gainprm="65.5682" biasprm="0 -65.5682 -1.67894"/>
    <general name="LH_KFE" class="/" joint="LH_KFE" forcerange="-63.6278 63.6278" gainprm="65.5682" biasprm="0 -65.5682 -1.67894"/>
    <general name="RH_HAA" class="/" joint="RH_HAA" forcerange="-60.191 60.191" gainprm="65.5682" biasprm="0 -65.5682 -1.67894"/>
    <general name="RH_HFE" class="/" joint="RH_HFE" forcerange="-81.7094 81.7094" gainprm="65.5682" biasprm="0 -65.5682 -1.67894"/>
    <general name="RH_KFE" class="/" joint="RH_KFE" forcerange="-32.1587 32.1587" gainprm="65.5682" biasprm="0 -65.5682 -1.67894"/>
  </actuator>

  <sensor>
    <gyro site="imu" name="imu_angular_velocity"/>
    <velocimeter site="imu" name="imu_linear_velocity"/>
    <framelinvel objtype="site" objname="LF_foot" name="LF_foot_global_linear_velocity"/>
    <framelinvel objtype="site" objname="RF_foot" name="RF_foot_global_linear_velocity"/>
    <framelinvel objtype="site" objname="LH_foot" name="LH_foot_global_linear_velocity"/>
    <framelinvel objtype="site" objname="RH_foot" name="RH_foot_global_linear_velocity"/>
  </sensor>

  <keyframe>
    <key name="home" qpos="0 0 0.55 1 0 0 0 0 0.4 -0.8 0 -0.4 0.8 0 -0.4 0.8 0 0.4 -0.8"/>
  </keyframe>
</mujoco>
