<mujoco model="anymal_c">
  <compiler angle="radian" assetdir="assets" balanceinertia="true" inertiafromgeom="false"/>

  <option timestep="0.005" density="1.2" viscosity="2e-05"/>

  <size nkey="1"/>

  <visual>
    <quality shadowsize="8192"/>
    <map shadowclip="0.5"/>
  </visual>

  <default>
    <default class="/">
      <material specular="0" shininess="0.25"/>
      <geom contype="0" conaffinity="0" group="1" solref="-1000 -80"/>
      <site size="0.01 0.005 0.005" group="5"/>
      <general forcelimited="true" forcerange="-80 80" biastype="affine" gainprm="80" biasprm="0 -80 -2"/>
      <default class="anymal_c">
        <joint armature="0.01" damping="0.01" frictionloss="0.1"/>
        <default class="visual">
          <geom type="mesh" group="2"/>
          <default class="visual_zflip"/>
        </default>
        <default class="collision">
          <geom type="cylinder" group="3"/>
          <default class="foot">
            <geom size="0.03 0 0" type="sphere" condim="6" priority="1" friction="0.8 0.02 0.01" solimp="0.015 1 0.03"/>
          </default>
        </default>
      </default>
      <default class="reward_collision_sphere">
        <geom group="5" rgba="1 0 0 1"/>
      </default>
    </default>
  </default>

  <asset>
    <texture type="skybox" colorspace="auto" name="//unnamed_texture_0" builtin="gradient" rgb1="0.95 0.95 0.95" rgb2="0.95 0.95 0.95" width="100" height="600"/>
    <texture type="2d" colorspace="auto" name="texplane" builtin="checker" rgb1="0.345 0.575 0.748" rgb2="0.345 0.575 0.748" markrgb="1 1 1" width="512" height="512"/>
    <texture type="2d" colorspace="linear" name="base" file="base.png"/>
    <texture type="2d" colorspace="linear" name="top_shell" file="top_shell.png"/>
    <texture type="2d" colorspace="linear" name="bottom_shell" file="bottom_shell.png"/>
    <texture type="2d" colorspace="linear" name="remote" file="remote.png"/>
    <texture type="2d" colorspace="linear" name="hatch" file="hatch.png"/>
    <texture type="2d" colorspace="linear" name="handle" file="handle.png"/>
    <texture type="2d" colorspace="linear" name="face" file="face.png"/>
    <texture type="2d" colorspace="linear" name="battery" file="battery.png"/>
    <texture type="2d" colorspace="linear" name="lidar_cage" file="lidar_cage.png"/>
    <texture type="2d" colorspace="linear" name="depth_camera" file="depth_camera.png"/>
    <texture type="2d" colorspace="linear" name="wide_angle_camera" file="wide_angle_camera.png"/>
    <texture type="2d" colorspace="linear" name="lidar" file="lidar.png"/>
    <texture type="2d" colorspace="linear" name="drive" file="drive.png"/>
    <texture type="2d" colorspace="linear" name="hip_l" file="hip_l.png"/>
    <texture type="2d" colorspace="linear" name="shank_l" file="shank_l.png"/>
    <texture type="2d" colorspace="linear" name="foot" file="foot.png"/>
    <texture type="2d" colorspace="linear" name="thigh" file="thigh.png"/>
    <texture type="2d" colorspace="linear" name="shank_r" file="shank_r.png"/>
    <texture type="2d" colorspace="linear" name="hip_r" file="hip_r.png"/>
    <material name="MatPlane" class="/" texture="texplane" texuniform="true" texrepeat="2 2" specular="0.9" shininess="0.5"/>
    <material name="black_plastic" class="/" rgba="0.007 0.007 0.007 1"/>
    <material name="green" class="/" rgba="0.052 0.178 0.033 1"/>
    <material name="red" class="/" rgba="0.178 0.006 0.005 1"/>
    <material name="yellow" class="/" rgba="0.178 0.119 0.006 1"/>
    <material name="lwl" class="/" rgba="0.8 0.8 0.8 1"/>
    <material name="base" class="/" texture="base"/>
    <material name="top_shell" class="/" texture="top_shell"/>
    <material name="bottom_shell" class="/" texture="bottom_shell"/>
    <material name="hip_l" class="/" texture="hip_l"/>
    <material name="thigh" class="/" texture="thigh"/>
    <material name="shank_l" class="/" texture="shank_l"/>
    <material name="foot" class="/" texture="foot"/>
    <material name="hip_r" class="/" texture="hip_r"/>
    <material name="shank" class="/" texture="shank_r"/>
    <material name="hatch" class="/" texture="hatch"/>
    <material name="remote" class="/" texture="remote"/>
    <material name="handle" class="/" texture="handle"/>
    <material name="face" class="/" texture="face"/>
    <material name="depth_camera" class="/" texture="depth_camera"/>
    <material name="wide_angle_camera" class="/" texture="wide_angle_camera"/>
    <material name="battery" class="/" texture="battery"/>
    <material name="lidar_cage" class="/" texture="lidar_cage"/>
    <material name="lidar" class="/" texture="lidar"/>
    <material name="drive" class="/" texture="drive"/>
    <mesh name="base_0" class="/" file="base_0.obj"/>
    <mesh name="base_1" class="/" file="base_1.obj"/>
    <mesh name="base_2" class="/" file="base_2.obj"/>
    <mesh name="base_3" class="/" file="base_3.obj"/>
    <mesh name="base_4" class="/" file="base_4.obj"/>
    <mesh name="base_5" class="/" file="base_5.obj"/>
    <mesh name="top_shell" class="/" file="top_shell.obj"/>
    <mesh name="bottom_shell" class="/" file="bottom_shell.obj"/>
    <mesh name="remote" class="/" file="remote.obj"/>
    <mesh name="handle" class="/" file="handle.obj"/>
    <mesh name="face" class="/" file="face.obj"/>
    <mesh name="wide_angle_camera" class="/" file="wide_angle_camera.obj"/>
    <mesh name="depth_camera" class="/" file="depth_camera.obj"/>
    <mesh name="battery" class="/" file="battery.obj"/>
    <mesh name="lidar_cage" class="/" file="lidar_cage.obj"/>
    <mesh name="lidar" class="/" file="lidar.obj"/>
    <mesh name="drive" class="/" file="drive.obj"/>
    <mesh name="hip_l" class="/" file="hip_l.obj"/>
    <mesh name="thigh" class="/" file="thigh.obj"/>
    <mesh name="shank_l" class="/" file="shank_l.obj"/>
    <mesh name="foot" class="/" file="foot.obj"/>
    <mesh name="hip_r" class="/" file="hip_r.obj"/>
    <mesh name="hatch" class="/" file="hatch.obj"/>
    <mesh name="shank_r" class="/" file="shank_r.obj"/>
  </asset>

  <worldbody>
    <geom name="floor" class="/" size="100 100 0.125" type="plane" group="0" material="MatPlane"/>
    <light name="toplight_shadow" class="/" pos="0 0 5" dir="0.0990148 0.0990148 -0.990148" type="directional" ambient="0.04 0.04 0.04" diffuse="0.55 0.55 0.55" specular="0.12 0.12 0.12"/>
    <light name="toplight_fill" class="/" pos="0 0 5" dir="0.0990148 0.0990148 -0.990148" type="directional" castshadow="false" ambient="0.04 0.04 0.04" diffuse="0.3 0.3 0.3" specular="0.08 0.08 0.08"/>
    <body name="trunk" childclass="anymal_c" pos="-0.00155855 -0.00108261 0.00996614" quat="1 0.000250943 0.000606716 0.000736438">
      <inertial pos="0.0149509 0.0127273 0.073696" quat="0.498011 0.519667 0.501439 0.480094" mass="45.5081" diaginertia="4.35483 0.243921 1.96057"/>
      <joint name="//unnamed_joint_0" type="free" armature="0" damping="0" frictionloss="0"/>
      <geom name="//unnamed_geom_1" class="visual" material="green" mesh="base_0"/>
      <geom name="//unnamed_geom_2" class="visual" material="yellow" mesh="base_1"/>
      <geom name="//unnamed_geom_3" class="visual" material="red" mesh="base_2"/>
      <geom name="//unnamed_geom_4" class="visual" material="black_plastic" mesh="base_3"/>
      <geom name="//unnamed_geom_5" class="visual" material="lwl" mesh="base_4"/>
      <geom name="//unnamed_geom_6" class="visual" material="base" mesh="base_5"/>
      <geom name="trunk_1" class="collision" size="0.387857 0.0936207 0.12037" type="box"/>
      <geom name="trunk_2" class="collision" size="0.12037 0.0969643" pos="0.337003 0.0602562 0" quat="0.707107 0 0.707107 0"/>
      <geom name="trunk_3" class="collision" size="0.12037 0.0969643" pos="-0.337003 0.0602562 0" quat="0.707107 0 0.707107 0"/>
      <geom name="trunk_4" class="collision" size="0.12037 0.0969643" pos="0.337003 -0.0602562 0" quat="0.707107 0 0.707107 0"/>
      <geom name="trunk_5" class="collision" size="0.12037 0.0969643" pos="-0.337003 -0.0602562 0" quat="0.707107 0 0.707107 0"/>
      <geom name="//unnamed_geom_12" class="visual" material="top_shell" mesh="top_shell"/>
      <geom name="//unnamed_geom_13" class="visual" material="bottom_shell" mesh="bottom_shell"/>
      <geom name="//unnamed_geom_14" class="visual" material="remote" mesh="remote"/>
      <geom name="//unnamed_geom_15" class="visual" material="handle" mesh="handle"/>
      <geom name="//unnamed_geom_16" class="visual" pos="0.642243 0 0" quat="1 0 0 0" material="face" mesh="face"/>
      <geom name="trunk_6" class="collision" size="0.0735592 0.0936207 0.12037" pos="0.727462 0 0" type="box"/>
      <geom name="//unnamed_geom_18" class="collision" size="0.12037 0.0735592" pos="0.727462 0.0602562 0" quat="0.707107 0 0.707107 0"/>
      <geom name="//unnamed_geom_19" class="collision" size="0.12037 0.0735592" pos="0.727462 -0.0602562 0" quat="0.707107 0 0.707107 0"/>
      <geom name="//unnamed_geom_20" class="visual" pos="0.715301 0 -0.0471806" quat="0.965926 0 0.258819 0" material="depth_camera" mesh="depth_camera"/>
      <geom name="//unnamed_geom_21" class="visual" pos="0.794862 0 0.0239831" material="wide_angle_camera" mesh="wide_angle_camera"/>
      <geom name="//unnamed_geom_22" class="visual_zflip" pos="-0.642243 0 0" quat="0 0 0 1" material="face" mesh="face"/>
      <geom name="trunk_7" class="collision" size="0.0735592 0.0936207 0.12037" pos="-0.727462 0 0" quat="0 0 0 1" type="box"/>
      <geom name="//unnamed_geom_24" class="collision" size="0.12037 0.0735592" pos="-0.727462 -0.0602562 0" quat="0 -0.707107 0 0.707107"/>
      <geom name="//unnamed_geom_25" class="collision" size="0.12037 0.0735592" pos="-0.727462 0.0602562 0" quat="0 -0.707107 0 0.707107"/>
      <geom name="//unnamed_geom_26" class="visual" pos="-0.715301 0 -0.0471806" quat="0 -0.258819 0 0.965926" material="depth_camera" mesh="depth_camera"/>
      <geom name="//unnamed_geom_27" class="visual_zflip" pos="-0.794862 0 0.0239831" quat="0 0 0 1" material="wide_angle_camera" mesh="wide_angle_camera"/>
      <geom name="//unnamed_geom_28" class="visual" material="battery" mesh="battery"/>
      <geom name="//unnamed_geom_29" class="visual" pos="0 0.0567829 0.0461402" quat="0.683013 -0.183013 0.183013 0.683013" material="depth_camera" mesh="depth_camera"/>
      <geom name="//unnamed_geom_30" class="visual" pos="0 -0.0567829 0.0461402" quat="0.683013 0.183013 0.183013 -0.683013" material="depth_camera" mesh="depth_camera"/>
      <geom name="//unnamed_geom_31" class="visual" pos="-0.563996 0 0.117752" quat="1 0 0 0" material="lidar_cage" mesh="lidar_cage"/>
      <geom name="trunk_8" class="collision" size="0.0936207 0.0802463" pos="-0.563996 0 0.213877"/>
      <geom name="//unnamed_geom_33" class="visual" pos="-0.563996 -0.000270547 0.227815" quat="0.707107 0 0 -0.707107" material="lidar" mesh="lidar"/>
      <geom name="//unnamed_geom_34" class="visual" pos="0.464677 0.0897869 -1.2787e-08" quat="0.258819 0.965926 0 0" material="drive" mesh="drive"/>
      <geom name="//unnamed_geom_35" class="visual" pos="0.464677 -0.0897869 1.2787e-08" quat="0.258819 -0.965926 0 0" material="drive" mesh="drive"/>
      <geom name="//unnamed_geom_36" class="visual" pos="-0.464677 0.0897869 1.2787e-08" quat="0 0 0.965926 -0.258819" material="drive" mesh="drive"/>
      <geom name="//unnamed_geom_37" class="visual" pos="-0.464677 -0.0897869 -1.2787e-08" quat="0 0 -0.965926 -0.258819" material="drive" mesh="drive"/>
      <geom name="//unnamed_geom_38" class="visual" pos="0.179735 0 0.116951" quat="1 0 0 0" material="hatch" mesh="hatch"/>
      <geom name="//unnamed_geom_39" class="reward_collision_sphere" size="0.160493"/>
      <geom name="//unnamed_geom_40" class="reward_collision_sphere" size="0.160493" pos="0.697248 0 0"/>
      <geom name="//unnamed_geom_41" class="reward_collision_sphere" size="0.160493" pos="-0.697248 0 0"/>
      <site name="imu" pos="0.459596 0.0195396 0.0109746" size="0.0133744"/>
      <camera name="track" pos="0 -1.72161 0" quat="0.707107 0.707107 0 0" mode="trackcom"/>
      <camera name="ego_camera" pos="0.697248 0 -0.064083" quat="-0.5 -0.5 0.5 0.5"/>
      <body name="LF_HIP" pos="0.462267 0.0954719 9.0678e-06" quat="0.259154 0.965829 0.00265759 0.00256963">
        <inertial pos="0.0749241 -0.00561973 -0.0122993" quat="-0.0963476 0.730468 -0.11857 0.665639" mass="7.79302" diaginertia="0.0615359 0.00232593 0.0326005"/>
        <joint name="LF_HAA" pos="0 0 0" axis="0.998566 -0.0525498 -0.0102451" stiffness="0.0241487" range="-0.697 0.32488" armature="0.00409186" damping="0.0738975" frictionloss="0.155084"/>
        <geom name="//unnamed_geom_42" class="visual" pos="0 -0.000752202 0.000123549" quat="0.258819 -0.965926 0 0" material="hip_l" mesh="hip_l"/>
        <geom name="//unnamed_geom_43" class="visual" pos="0.0928114 -0.103657 -0.0653294" quat="0.183013 -0.683013 0.683013 0.183013" material="drive" mesh="drive"/>
        <geom name="//unnamed_geom_44" class="collision" size="0.066872 0.0936207" pos="0.0928114 -0.010295 -0.0110623" quat="-0.353553 -0.612372 0.612372 -0.353553"/>
        <body name="LF_THIGH" pos="0.0922758 -0.061133 -0.0670073" quat="0.182868 -0.682738 0.683406 0.182713">
          <inertial pos="0.0412109 -9.33742e-05 -0.406785" quat="0.990833 -0.0200899 -0.0884859 0.100087" mass="6.43977" diaginertia="0.310512 0.013858 0.0452587"/>
          <joint name="LF_HFE" pos="0 0 0" axis="0.997357 -0.0541835 -0.0483969" range="-3.05488 3.07469" armature="0.011549" damping="0.0321017" frictionloss="0.218227"/>
          <geom name="//unnamed_geom_45" class="visual" pos="0.0137012 2.15898e-05 0" quat="0.707107 0 0 -0.707107" material="thigh" mesh="thigh"/>
          <geom name="//unnamed_geom_46" class="collision" size="0.0869335 0.0534976" pos="0.0619776 0 0" quat="0.5 0.5 -0.5 -0.5"/>
          <geom name="//unnamed_geom_47" class="collision" size="0.050154 0.0401232 0.188999" pos="0.0464832 0 -0.226396" quat="0.707107 0 0 -0.707107" type="box"/>
          <geom name="//unnamed_geom_48" class="visual" pos="0.155409 0 -0.456591" quat="1 0 0 0" material="drive" mesh="drive"/>
          <geom name="//unnamed_geom_49" class="collision" size="0.066872 0.0936207" pos="0.046948 0 -0.456591" quat="0.707107 0 0.707107 0"/>
          <geom name="//unnamed_geom_50" class="reward_collision_sphere" size="0.106995" pos="0.038736 0 0"/>
          <body name="LF_SHANK" pos="0.143892 0.0118962 -0.44179" quat="0.999984 0.00447373 -0.00247951 -0.00260911">
            <inertial pos="0.0125219 -0.0531773 -0.12498" quat="0.994252 -0.100518 0.010997 -0.0351756" mass="1.56046" diaginertia="0.10046 0.00436671 0.0136213"/>
            <joint name="LF_KFE" pos="0 0 0" axis="0.999538 -0.0271899 -0.0135935" stiffness="0.00116318" range="-2.94927 3.01627" armature="0.00858687" damping="0.0653813" frictionloss="0.0724755"/>
            <geom name="//unnamed_geom_51" class="visual" pos="0.00446765 0.0238217 0" quat="0.707107 0 0 -0.707107" material="shank_l" mesh="shank_l"/>
            <geom name="LF_kfe_act" class="collision" size="0.0802463 0.0267488" pos="0.0309888 0 0" quat="0.5 0.5 -0.5 -0.5"/>
            <geom name="//unnamed_geom_53" class="collision" size="0.0769014 0.0451386 0.0254113" pos="0.0309888 -0.0494953 0" quat="0.5 0.5 -0.5 -0.5" type="box"/>
            <geom name="//unnamed_geom_54" class="visual" pos="0.0202191 -0.0680309 -0.541453" quat="0.382683 0 0 -0.92388" material="foot" mesh="foot"/>
            <geom name="LF_calf" class="collision" size="0.0234052 0.188916" pos="0.0202202 -0.0757076 -0.270727" quat="0.707107 0 0 -0.707107"/>
            <geom name="LF_foot" class="foot" size="0.0455185" pos="0.0202202 -0.0757076 -0.505407" quat="0.707107 0 0 -0.707107"/>
            <geom name="//unnamed_geom_57" class="reward_collision_sphere" size="0.133744" pos="-0.077472 0 0"/>
            <geom name="//unnamed_geom_58" class="reward_collision_sphere" size="0.066872" pos="0.0202202 -0.0757076 -0.505407"/>
            <site name="LF_foot" class="foot" pos="0.0202202 -0.0757076 -0.505407" quat="0.707107 0 0 -0.707107" size="0.0133744"/>
          </body>
        </body>
      </body>
      <body name="RF_HIP" pos="0.474037 -0.0916772 0.00185076" quat="0.258861 -0.965914 -5.993e-05 -1.27415e-05">
        <inertial pos="0.0754613 0.0150637 -0.0146111" quat="0.134976 0.679681 0.126542 0.70979" mass="6.21399" diaginertia="0.0503885 0.00184609 0.0311984"/>
        <joint name="RF_HAA" pos="0 0 0" axis="0.999568 0.02919 0.00339896" stiffness="0.0265764" range="-0.228442 0.66336" armature="0.0212316" damping="0.00656462" frictionloss="0.219101"/>
        <geom name="//unnamed_geom_59" class="visual" pos="0 0.000752196 0.000123548" quat="0.258819 0.965926 0 0" material="hip_r" mesh="hip_r"/>
        <geom name="//unnamed_geom_60" class="visual" pos="0.0928114 0.103657 -0.0653294" quat="0.183013 0.683013 0.683013 -0.183013" material="drive" mesh="drive"/>
        <geom name="//unnamed_geom_61" class="collision" size="0.066872 0.0936207" pos="0.0928114 0.010295 -0.0110623" quat="-0.353553 0.612372 0.612372 0.353553"/>
        <body name="RF_THIGH" pos="0.0996805 0.0489578 -0.059549" quat="0.184539 0.682966 0.682536 -0.183433">
          <inertial pos="0.0479374 -0.00261572 -0.392158" quat="0.994625 -0.0319004 -0.0256935 0.0951003" mass="9.77915" diaginertia="0.300657 0.0142058 0.0456703"/>
          <joint name="RF_HFE" pos="0 0 0" axis="0.998473 -0.0344647 0.0431771" stiffness="0.0127223" range="-3.43252 2.94896" armature="0.0122356" damping="0.0657695" frictionloss="0.0278393"/>
          <geom name="//unnamed_geom_62" class="visual" pos="0.0137012 2.15898e-05 0" quat="0.707107 0 0 -0.707107" material="thigh" mesh="thigh"/>
          <geom name="//unnamed_geom_63" class="collision" size="0.0869335 0.0534976" pos="0.0619776 0 0" quat="0.5 0.5 0.5 0.5"/>
          <geom name="//unnamed_geom_64" class="collision" size="0.050154 0.0401232 0.188999" pos="0.0464832 0 -0.226396" quat="0.707107 0 0 0.707107" type="box"/>
          <geom name="//unnamed_geom_65" class="visual" pos="0.155409 0 -0.456591" quat="1 0 0 0" material="drive" mesh="drive"/>
          <geom name="//unnamed_geom_66" class="collision" size="0.066872 0.0936207" pos="0.046948 0 -0.456591" quat="0.707107 0 0.707107 0"/>
          <geom name="//unnamed_geom_67" class="reward_collision_sphere" size="0.106995" pos="0.038736 0 0"/>
          <body name="RF_SHANK" pos="0.142796 0.0136078 -0.46295" quat="1 -0.000209577 -0.000320155 0.000509899">
            <inertial pos="0.00765356 0.0535587 -0.142704" quat="0.994889 0.0999892 -0.000532216 -0.0140717" mass="1.43571" diaginertia="0.105797 0.004921 0.0115297"/>
            <joint name="RF_KFE" pos="0 0 0" axis="0.999979 -0.00175715 0.00630883" range="-2.96653 2.9556" armature="0.0168826" damping="0.00208173" frictionloss="0.228648"/>
            <geom name="//unnamed_geom_68" class="visual" pos="0.00446762 -0.0238217 0" quat="0.707107 0 0 0.707107" material="shank" mesh="shank_r"/>
            <geom name="RF_kfe_act" class="collision" size="0.0802463 0.0267488" pos="0.0309888 0 0" quat="0.5 0.5 0.5 0.5"/>
            <geom name="//unnamed_geom_70" class="collision" size="0.0769014 0.0451386 0.0254113" pos="0.0309888 0.0494953 0" quat="0.5 0.5 0.5 0.5" type="box"/>
            <geom name="//unnamed_geom_71" class="visual" pos="0.0202213 0.0680309 -0.541453" quat="0.382683 0 0 0.92388" material="foot" mesh="foot"/>
            <geom name="RF_calf" class="collision" size="0.0234052 0.188916" pos="0.0202202 0.0757076 -0.270727" quat="0.707107 0 0 0.707107"/>
            <geom name="RF_foot" class="foot" size="0.064121" pos="0.0202202 0.0757076 -0.505407" quat="0.707107 0 0 0.707107"/>
            <geom name="//unnamed_geom_74" class="reward_collision_sphere" size="0.133744" pos="-0.077472 0 0"/>
            <geom name="//unnamed_geom_75" class="reward_collision_sphere" size="0.066872" pos="0.0202202 0.0757076 -0.505407"/>
            <site name="RF_foot" class="foot" pos="0.0202202 0.0757076 -0.505407" quat="0.707107 0 0 0.707107" size="0.0133744"/>
          </body>
        </body>
      </body>
      <body name="LH_HIP" pos="-0.450133 0.0827973 -0.00149026" quat="0.00229994 -0.000576846 0.965877 -0.258992">
        <inertial pos="0.0809232 2.22859e-05 -0.0141042" quat="0.154194 0.665764 0.0927484 0.724141" mass="6.63667" diaginertia="0.0644785 0.00219765 0.0462939"/>
        <joint name="LH_HAA" pos="0 0 0" axis="0.999589 -0.0243022 0.0152158" stiffness="0.0279317" range="-0.610276 1.03665" armature="0.0226644" damping="0.0536269" frictionloss="0.137352"/>
        <geom name="//unnamed_geom_76" class="visual" pos="0 0.000752196 0.000123548" quat="-0.258819 -0.965926 0 0" material="hip_r" mesh="hip_r"/>
        <geom name="//unnamed_geom_77" class="visual" pos="0.0928114 0.103657 -0.0653294" quat="0.183013 0.683013 0.683013 -0.183013" material="drive" mesh="drive"/>
        <geom name="//unnamed_geom_78" class="collision" size="0.066872 0.0936207" pos="0.0928114 0.010295 -0.0110623" quat="-0.353553 0.612372 0.612372 0.353553"/>
        <body name="LH_THIGH" pos="0.102091 0.0780079 -0.0628785" quat="0.182883 0.68302 0.682927 -0.183434">
          <inertial pos="0.0485169 -0.0114886 -0.390843" quat="0.992381 -0.00129774 -0.0794355 0.0941693" mass="7.26547" diaginertia="0.266752 0.0156909 0.0414018"/>
          <joint name="LH_HFE" pos="0 0 0" axis="0.998239 0.0182844 -0.0564294" range="-3.13455 3.17633" armature="0.0184771" damping="0.044967" frictionloss="0.0955078"/>
          <geom name="//unnamed_geom_79" class="visual" pos="0.0137012 2.15898e-05 0" quat="0.707107 0 0 -0.707107" material="thigh" mesh="thigh"/>
          <geom name="//unnamed_geom_80" class="collision" size="0.0869335 0.0534976" pos="0.0619776 0 0" quat="0.5 0.5 -0.5 -0.5"/>
          <geom name="//unnamed_geom_81" class="collision" size="0.050154 0.0401232 0.188999" pos="0.0464832 0 -0.226396" quat="0.707107 0 0 -0.707107" type="box"/>
          <geom name="//unnamed_geom_82" class="visual" pos="0.155409 0 -0.456591" quat="1 0 0 0" material="drive" mesh="drive"/>
          <geom name="//unnamed_geom_83" class="collision" size="0.066872 0.0936207" pos="0.046948 0 -0.456591" quat="0.707107 0 0.707107 0"/>
          <geom name="//unnamed_geom_84" class="reward_collision_sphere" size="0.106995" pos="0.038736 0 0"/>
          <body name="LH_SHANK" pos="0.164844 -0.000561312 -0.45053" quat="0.999995 -0.00021269 -0.00253904 0.00188027">
            <inertial pos="0.00891019 0.0520583 -0.12903" quat="0.985152 0.152503 -0.0686605 0.0387908" mass="1.41131" diaginertia="0.0903857 0.00428843 0.0141483"/>
            <joint name="LH_KFE" pos="0 0 0" axis="0.998576 0.039784 -0.0355425" range="-3.17607 3.15172" armature="0.0201252" damping="0.0177886" frictionloss="0.0705821"/>
            <geom name="//unnamed_geom_85" class="visual" pos="0.00446762 -0.0238217 0" quat="-0.707107 0 0 -0.707107" material="shank" mesh="shank_r"/>
            <geom name="LH_kfe_act" class="collision" size="0.0802463 0.0267488" pos="0.0309888 0 0" quat="0.5 0.5 -0.5 -0.5"/>
            <geom name="//unnamed_geom_87" class="collision" size="0.0769014 0.0451386 0.0254113" pos="0.0309888 0.0494953 0" quat="0.5 0.5 -0.5 -0.5" type="box"/>
            <geom name="//unnamed_geom_88" class="visual" pos="0.0202213 0.0680309 -0.541453" quat="-0.382683 0 0 -0.92388" material="foot" mesh="foot"/>
            <geom name="LH_calf" class="collision" size="0.0234052 0.188916" pos="0.0202202 0.0757076 -0.270727" quat="0.707107 0 0 -0.707107"/>
            <geom name="LH_foot" class="foot" size="0.0165915" pos="0.0202202 0.0757076 -0.505407" quat="0.707107 0 0 -0.707107"/>
            <geom name="//unnamed_geom_91" class="reward_collision_sphere" size="0.133744" pos="-0.077472 0 0"/>
            <geom name="//unnamed_geom_92" class="reward_collision_sphere" size="0.066872" pos="0.0202202 0.0757076 -0.505407"/>
            <site name="LH_foot" class="foot" pos="0.0202202 0.0757076 -0.505407" quat="0.707107 0 0 -0.707107" size="0.0133744"/>
          </body>
        </body>
      </body>
      <body name="RH_HIP" pos="-0.465535 -0.0763066 0.0069852" quat="-0.0043517 0.0031059 -0.96558 -0.260053">
        <inertial pos="0.101205 -0.0133577 -0.0255739" quat="-0.111394 0.703042 -0.14779 0.686645" mass="7.34234" diaginertia="0.0578018 0.00252141 0.0448017"/>
        <joint name="RH_HAA" pos="0 0 0" axis="1 0.000565387 -0.000367741" stiffness="0.0372735" range="-0.481727 0.198906" armature="0.0134849" damping="0.0543864" frictionloss="0.139866"/>
        <geom name="//unnamed_geom_93" class="visual" pos="0 -0.000752202 0.000123549" quat="-0.258819 0.965926 0 0" material="hip_l" mesh="hip_l"/>
        <geom name="//unnamed_geom_94" class="visual" pos="0.0928114 -0.103657 -0.0653294" quat="-0.183013 0.683013 -0.683013 -0.183013" material="drive" mesh="drive"/>
        <geom name="//unnamed_geom_95" class="collision" size="0.066872 0.0936207" pos="0.0928114 -0.010295 -0.0110623" quat="0.353553 0.612372 -0.612372 0.353553"/>
        <body name="RH_THIGH" pos="0.0918903 -0.0550605 -0.0804969" quat="-0.183636 0.682669 -0.683265 -0.18273">
          <inertial pos="0.0375816 0.00384896 -0.396783" quat="0.993212 -0.00285458 -0.0786344 0.0856622" mass="10.3317" diaginertia="0.370997 0.0167649 0.0501777"/>
          <joint name="RH_HFE" pos="0 0 0" axis="0.998318 -0.0215792 -0.0538108" stiffness="0.00728412" range="-3.15859 3.16988" armature="0.0176834" damping="0.0368257" frictionloss="0.139057"/>
          <geom name="//unnamed_geom_96" class="visual" pos="0.0137012 2.15898e-05 0" quat="0.707107 0 0 -0.707107" material="thigh" mesh="thigh"/>
          <geom name="//unnamed_geom_97" class="collision" size="0.0869335 0.0534976" pos="0.0619776 0 0" quat="0.5 0.5 0.5 0.5"/>
          <geom name="//unnamed_geom_98" class="collision" size="0.050154 0.0401232 0.188999" pos="0.0464832 0 -0.226396" quat="0.707107 0 0 0.707107" type="box"/>
          <geom name="//unnamed_geom_99" class="visual" pos="0.155409 0 -0.456591" quat="1 0 0 0" material="drive" mesh="drive"/>
          <geom name="//unnamed_geom_100" class="collision" size="0.066872 0.0936207" pos="0.046948 0 -0.456591" quat="0.707107 0 0.707107 0"/>
          <geom name="//unnamed_geom_101" class="reward_collision_sphere" size="0.106995" pos="0.038736 0 0"/>
          <body name="RH_SHANK" pos="0.168422 0.00376997 -0.459585" quat="0.999993 -0.00180291 0.000333063 -0.00325786">
            <inertial pos="0.0147153 -0.0526013 -0.130192" quat="0.992399 -0.0996546 -0.0540191 -0.0479037" mass="1.34802" diaginertia="0.0985291 0.00366456 0.0115456"/>
            <joint name="RH_KFE" pos="0 0 0" axis="0.999926 -0.00286521 -0.0117922" range="-3.07032 3.24353" armature="0.0229517" damping="0" frictionloss="0.13721"/>
            <geom name="//unnamed_geom_102" class="visual" pos="0.00446765 0.0238217 0" quat="0.707107 0 0 -0.707107" material="shank_l" mesh="shank_l"/>
            <geom name="RH_kfe_act" class="collision" size="0.0802463 0.0267488" pos="0.0309888 0 0" quat="0.5 0.5 0.5 0.5"/>
            <geom name="//unnamed_geom_104" class="collision" size="0.0769014 0.0451386 0.0254113" pos="0.0309888 -0.0494953 0" quat="0.5 0.5 0.5 0.5" type="box"/>
            <geom name="//unnamed_geom_105" class="visual" pos="0.0202191 -0.0680309 -0.541453" quat="0.382683 0 0 -0.92388" material="foot" mesh="foot"/>
            <geom name="RH_calf" class="collision" size="0.0234052 0.188916" pos="0.0202202 -0.0757076 -0.270727" quat="0.707107 0 0 0.707107"/>
            <geom name="RH_foot" class="foot" size="0.0546005" pos="0.0202202 -0.0757076 -0.505407" quat="0.707107 0 0 0.707107"/>
            <geom name="//unnamed_geom_108" class="reward_collision_sphere" size="0.133744" pos="-0.077472 0 0"/>
            <geom name="//unnamed_geom_109" class="reward_collision_sphere" size="0.066872" pos="0.0202202 -0.0757076 -0.505407"/>
            <site name="RH_foot" class="foot" pos="0.0202202 -0.0757076 -0.505407" quat="0.707107 0 0 0.707107" size="0.0133744"/>
          </body>
        </body>
      </body>
    </body>
  </worldbody>

  <contact>
    <pair class="/" geom1="floor" geom2="LF_foot" name="//unnamed_contact_0"/>
    <pair class="/" geom1="floor" geom2="RF_foot" name="//unnamed_contact_1"/>
    <pair class="/" geom1="floor" geom2="LH_foot" name="//unnamed_contact_2"/>
    <pair class="/" geom1="floor" geom2="RH_foot" name="//unnamed_contact_3"/>
  </contact>

  <actuator>
    <general name="LF_HAA" class="/" joint="LF_HAA" forcerange="-118.771 118.771" gainprm="78.613" biasprm="0 -78.613 -3.11144"/>
    <general name="LF_HFE" class="/" joint="LF_HFE" forcerange="-140.822 140.822" gainprm="78.613" biasprm="0 -78.613 -3.11144"/>
    <general name="LF_KFE" class="/" joint="LF_KFE" forcerange="-124.408 124.408" gainprm="78.613" biasprm="0 -78.613 -3.11144"/>
    <general name="RF_HAA" class="/" joint="RF_HAA" forcerange="-143.215 143.215" gainprm="78.613" biasprm="0 -78.613 -3.11144"/>
    <general name="RF_HFE" class="/" joint="RF_HFE" forcerange="-78.6609 78.6609" gainprm="78.613" biasprm="0 -78.613 -3.11144"/>
    <general name="RF_KFE" class="/" joint="RF_KFE" forcerange="-156.857 156.857" gainprm="78.613" biasprm="0 -78.613 -3.11144"/>
    <general name="LH_HAA" class="/" joint="LH_HAA" forcerange="-110.54 110.54" gainprm="78.613" biasprm="0 -78.613 -3.11144"/>
    <general name="LH_HFE" class="/" joint="LH_HFE" forcerange="-157.723 157.723" gainprm="78.613" biasprm="0 -78.613 -3.11144"/>
    <general name="LH_KFE" class="/" joint="LH_KFE" forcerange="-123.185 123.185" gainprm="78.613" biasprm="0 -78.613 -3.11144"/>
    <general name="RH_HAA" class="/" joint="RH_HAA" forcerange="-128.692 128.692" gainprm="78.613" biasprm="0 -78.613 -3.11144"/>
    <general name="RH_HFE" class="/" joint="RH_HFE" forcerange="-163.425 163.425" gainprm="78.613" biasprm="0 -78.613 -3.11144"/>
    <general name="RH_KFE" class="/" joint="RH_KFE" forcerange="-59.6964 59.6964" gainprm="78.613" biasprm="0 -78.613 -3.11144"/>
  </actuator>

  <sensor>
    <gyro site="imu" name="imu_angular_velocity"/>
    <velocimeter site="imu" name="imu_linear_velocity"/>
    <framelinvel objtype="site" objname="LF_foot" name="LF_foot_global_linear_velocity"/>
    <framelinvel objtype="site" objname="RF_foot" name="RF_foot_global_linear_velocity"/>
    <framelinvel objtype="site" objname="LH_foot" name="LH_foot_global_linear_velocity"/>
    <framelinvel objtype="site" objname="RH_foot" name="RH_foot_global_linear_velocity"/>
  </sensor>

  <keyframe>
    <key name="home" qpos="0 0 0.55 1 0 0 0 0 0.4 -0.8 0 -0.4 0.8 0 -0.4 0.8 0 0.4 -0.8"/>
  </keyframe>
</mujoco>
