<mujoco model="anymal_c">
  <compiler angle="radian" assetdir="assets" balanceinertia="true" inertiafromgeom="false"/>

  <option timestep="0.005" density="1.2" viscosity="2e-05"/>

  <size nkey="1"/>

  <visual>
    <quality shadowsize="8192"/>
    <map shadowclip="0.5"/>
  </visual>

  <default>
    <default class="/">
      <material specular="0" shininess="0.25"/>
      <geom contype="0" conaffinity="0" group="1" solref="-1000 -80"/>
      <site size="0.01 0.005 0.005" group="5"/>
      <general forcelimited="true" forcerange="-80 80" biastype="affine" gainprm="80" biasprm="0 -80 -2"/>
      <default class="anymal_c">
        <joint armature="0.01" damping="0.01" frictionloss="0.1"/>
        <default class="visual">
          <geom type="mesh" group="2"/>
          <default class="visual_zflip"/>
        </default>
        <default class="collision">
          <geom type="cylinder" group="3"/>
          <default class="foot">
            <geom size="0.03 0 0" type="sphere" condim="6" priority="1" friction="0.8 0.02 0.01" solimp="0.015 1 0.03"/>
          </default>
        </default>
      </default>
      <default class="reward_collision_sphere">
        <geom group="5" rgba="1 0 0 1"/>
      </default>
    </default>
  </default>

  <asset>
    <texture type="skybox" colorspace="auto" name="//unnamed_texture_0" builtin="gradient" rgb1="0.95 0.95 0.95" rgb2="0.95 0.95 0.95" width="100" height="600"/>
    <texture type="2d" colorspace="auto" name="texplane" builtin="checker" rgb1="0.345 0.575 0.748" rgb2="0.345 0.575 0.748" markrgb="1 1 1" width="512" height="512"/>
    <texture type="2d" colorspace="linear" name="base" file="base.png"/>
    <texture type="2d" colorspace="linear" name="top_shell" file="top_shell.png"/>
    <texture type="2d" colorspace="linear" name="bottom_shell" file="bottom_shell.png"/>
    <texture type="2d" colorspace="linear" name="remote" file="remote.png"/>
    <texture type="2d" colorspace="linear" name="hatch" file="hatch.png"/>
    <texture type="2d" colorspace="linear" name="handle" file="handle.png"/>
    <texture type="2d" colorspace="linear" name="face" file="face.png"/>
    <texture type="2d" colorspace="linear" name="battery" file="battery.png"/>
    <texture type="2d" colorspace="linear" name="lidar_cage" file="lidar_cage.png"/>
    <texture type="2d" colorspace="linear" name="depth_camera" file="depth_camera.png"/>
    <texture type="2d" colorspace="linear" name="wide_angle_camera" file="wide_angle_camera.png"/>
    <texture type="2d" colorspace="linear" name="lidar" file="lidar.png"/>
    <texture type="2d" colorspace="linear" name="drive" file="drive.png"/>
    <texture type="2d" colorspace="linear" name="hip_l" file="hip_l.png"/>
    <texture type="2d" colorspace="linear" name="shank_l" file="shank_l.png"/>
    <texture type="2d" colorspace="linear" name="foot" file="foot.png"/>
    <texture type="2d" colorspace="linear" name="thigh" file="thigh.png"/>
    <texture type="2d" colorspace="linear" name="shank_r" file="shank_r.png"/>
    <texture type="2d" colorspace="linear" name="hip_r" file="hip_r.png"/>
    <material name="MatPlane" class="/" texture="texplane" texuniform="true" texrepeat="2 2" specular="0.9" shininess="0.5"/>
    <material name="black_plastic" class="/" rgba="0.007 0.007 0.007 1"/>
    <material name="green" class="/" rgba="0.052 0.178 0.033 1"/>
    <material name="red" class="/" rgba="0.178 0.006 0.005 1"/>
    <material name="yellow" class="/" rgba="0.178 0.119 0.006 1"/>
    <material name="lwl" class="/" rgba="0.8 0.8 0.8 1"/>
    <material name="base" class="/" texture="base"/>
    <material name="top_shell" class="/" texture="top_shell"/>
    <material name="bottom_shell" class="/" texture="bottom_shell"/>
    <material name="hip_l" class="/" texture="hip_l"/>
    <material name="thigh" class="/" texture="thigh"/>
    <material name="shank_l" class="/" texture="shank_l"/>
    <material name="foot" class="/" texture="foot"/>
    <material name="hip_r" class="/" texture="hip_r"/>
    <material name="shank" class="/" texture="shank_r"/>
    <material name="hatch" class="/" texture="hatch"/>
    <material name="remote" class="/" texture="remote"/>
    <material name="handle" class="/" texture="handle"/>
    <material name="face" class="/" texture="face"/>
    <material name="depth_camera" class="/" texture="depth_camera"/>
    <material name="wide_angle_camera" class="/" texture="wide_angle_camera"/>
    <material name="battery" class="/" texture="battery"/>
    <material name="lidar_cage" class="/" texture="lidar_cage"/>
    <material name="lidar" class="/" texture="lidar"/>
    <material name="drive" class="/" texture="drive"/>
    <mesh name="base_0" class="/" file="base_0.obj"/>
    <mesh name="base_1" class="/" file="base_1.obj"/>
    <mesh name="base_2" class="/" file="base_2.obj"/>
    <mesh name="base_3" class="/" file="base_3.obj"/>
    <mesh name="base_4" class="/" file="base_4.obj"/>
    <mesh name="base_5" class="/" file="base_5.obj"/>
    <mesh name="top_shell" class="/" file="top_shell.obj"/>
    <mesh name="bottom_shell" class="/" file="bottom_shell.obj"/>
    <mesh name="remote" class="/" file="remote.obj"/>
    <mesh name="handle" class="/" file="handle.obj"/>
    <mesh name="face" class="/" file="face.obj"/>
    <mesh name="wide_angle_camera" class="/" file="wide_angle_camera.obj"/>
    <mesh name="depth_camera" class="/" file="depth_camera.obj"/>
    <mesh name="battery" class="/" file="battery.obj"/>
    <mesh name="lidar_cage" class="/" file="lidar_cage.obj"/>
    <mesh name="lidar" class="/" file="lidar.obj"/>
    <mesh name="drive" class="/" file="drive.obj"/>
    <mesh name="hip_l" class="/" file="hip_l.obj"/>
    <mesh name="thigh" class="/" file="thigh.obj"/>
    <mesh name="shank_l" class="/" file="shank_l.obj"/>
    <mesh name="foot" class="/" file="foot.obj"/>
    <mesh name="hip_r" class="/" file="hip_r.obj"/>
    <mesh name="hatch" class="/" file="hatch.obj"/>
    <mesh name="shank_r" class="/" file="shank_r.obj"/>
  </asset>

  <worldbody>
    <geom name="floor" class="/" size="100 100 0.125" type="plane" group="0" material="MatPlane"/>
    <light name="toplight_shadow" class="/" pos="0 0 5" dir="0.0990148 0.0990148 -0.990148" type="directional" ambient="0.04 0.04 0.04" diffuse="0.55 0.55 0.55" specular="0.12 0.12 0.12"/>
    <light name="toplight_fill" class="/" pos="0 0 5" dir="0.0990148 0.0990148 -0.990148" type="directional" castshadow="false" ambient="0.04 0.04 0.04" diffuse="0.3 0.3 0.3" specular="0.08 0.08 0.08"/>
    <body name="trunk" childclass="anymal_c" pos="0.00176493 -5.14504e-06 0.00524621" quat="1 0.000492396 -0.000145249 -0.000608214">
      <inertial pos="0.00968271 0.00792535 0.0680065" quat="0.502191 0.495878 0.498033 0.503858" mass="28.539" diaginertia="2.48064 0.0768429 1.02478"/>
      <joint name="//unnamed_joint_0" type="free" armature="0" damping="0" frictionloss="0"/>
      <geom name="//unnamed_geom_1" class="visual" material="green" mesh="base_0"/>
      <geom name="//unnamed_geom_2" class="visual" material="yellow" mesh="base_1"/>
      <geom name="//unnamed_geom_3" class="visual" material="red" mesh="base_2"/>
      <geom name="//unnamed_geom_4" class="visual" material="black_plastic" mesh="base_3"/>
      <geom name="//unnamed_geom_5" class="visual" material="lwl" mesh="base_4"/>
      <geom name="//unnamed_geom_6" class="visual" material="base" mesh="base_5"/>
      <geom name="trunk_1" class="collision" size="0.331683 0.0800614 0.102936" type="box"/>
      <geom name="trunk_2" class="collision" size="0.102936 0.0829207" pos="0.294196 0.0471327 0" quat="0.707107 0 0.707107 0"/>
      <geom name="trunk_3" class="collision" size="0.102936 0.0829207" pos="-0.294196 0.0471327 0" quat="0.707107 0 0.707107 0"/>
      <geom name="trunk_4" class="collision" size="0.102936 0.0829207" pos="0.294196 -0.0471327 0" quat="0.707107 0 0.707107 0"/>
      <geom name="trunk_5" class="collision" size="0.102936 0.0829207" pos="-0.294196 -0.0471327 0" quat="0.707107 0 0.707107 0"/>
      <geom name="//unnamed_geom_12" class="visual" material="top_shell" mesh="top_shell"/>
      <geom name="//unnamed_geom_13" class="visual" material="bottom_shell" mesh="bottom_shell"/>
      <geom name="//unnamed_geom_14" class="visual" material="remote" mesh="remote"/>
      <geom name="//unnamed_geom_15" class="visual" material="handle" mesh="handle"/>
      <geom name="//unnamed_geom_16" class="visual" pos="0.560663 0 0" quat="1 0 0 0" material="face" mesh="face"/>
      <geom name="trunk_6" class="collision" size="0.0629054 0.0800614 0.102936" pos="0.635057 0 0" type="box"/>
      <geom name="//unnamed_geom_18" class="collision" size="0.102936 0.0629054" pos="0.635057 0.0471327 0" quat="0.707107 0 0.707107 0"/>
      <geom name="//unnamed_geom_19" class="collision" size="0.102936 0.0629054" pos="0.635057 -0.0471327 0" quat="0.707107 0 0.707107 0"/>
      <geom name="//unnamed_geom_20" class="visual" pos="0.624441 0 -0.0414334" quat="0.965926 0 0.258819 0" material="depth_camera" mesh="depth_camera"/>
      <geom name="//unnamed_geom_21" class="visual" pos="0.693896 0 0.0210367" material="wide_angle_camera" mesh="wide_angle_camera"/>
      <geom name="//unnamed_geom_22" class="visual_zflip" pos="-0.560663 0 0" quat="0 0 0 1" material="face" mesh="face"/>
      <geom name="trunk_7" class="collision" size="0.0629054 0.0800614 0.102936" pos="-0.635057 0 0" quat="0 0 0 1" type="box"/>
      <geom name="//unnamed_geom_24" class="collision" size="0.102936 0.0629054" pos="-0.635057 -0.0471327 0" quat="0 -0.707107 0 0.707107"/>
      <geom name="//unnamed_geom_25" class="collision" size="0.102936 0.0629054" pos="-0.635057 0.0471327 0" quat="0 -0.707107 0 0.707107"/>
      <geom name="//unnamed_geom_26" class="visual" pos="-0.624441 0 -0.0414334" quat="0 -0.258819 0 0.965926" material="depth_camera" mesh="depth_camera"/>
      <geom name="//unnamed_geom_27" class="visual_zflip" pos="-0.693896 0 0.0210367" quat="0 0 0 1" material="wide_angle_camera" mesh="wide_angle_camera"/>
      <geom name="//unnamed_geom_28" class="visual" material="battery" mesh="battery"/>
      <geom name="//unnamed_geom_29" class="visual" pos="0 0.0425708 0.0404227" quat="0.683013 -0.183013 0.183013 0.683013" material="depth_camera" mesh="depth_camera"/>
      <geom name="//unnamed_geom_30" class="visual" pos="0 -0.0425708 0.0404227" quat="0.683013 0.183013 0.183013 -0.683013" material="depth_camera" mesh="depth_camera"/>
      <geom name="//unnamed_geom_31" class="visual" pos="-0.492355 0 0.103286" quat="1 0 0 0" material="lidar_cage" mesh="lidar_cage"/>
      <geom name="trunk_8" class="collision" size="0.0800614 0.0686241" pos="-0.492355 0 0.187602"/>
      <geom name="//unnamed_geom_33" class="visual" pos="-0.492355 -0.000266878 0.199827" quat="0.707107 0 0 -0.707107" material="lidar" mesh="lidar"/>
      <geom name="//unnamed_geom_34" class="visual" pos="0.405652 0.0702858 -1.26259e-08" quat="0.258819 0.965926 0 0" material="drive" mesh="drive"/>
      <geom name="//unnamed_geom_35" class="visual" pos="0.405652 -0.0702858 1.26259e-08" quat="0.258819 -0.965926 0 0" material="drive" mesh="drive"/>
      <geom name="//unnamed_geom_36" class="visual" pos="-0.405652 0.0702858 1.26259e-08" quat="0 0 0.965926 -0.258819" material="drive" mesh="drive"/>
      <geom name="//unnamed_geom_37" class="visual" pos="-0.405652 -0.0702858 -1.26259e-08" quat="0 0 -0.965926 -0.258819" material="drive" mesh="drive"/>
      <geom name="//unnamed_geom_38" class="visual" pos="0.156904 0 0.102584" quat="1 0 0 0" material="hatch" mesh="hatch"/>
      <geom name="//unnamed_geom_39" class="reward_collision_sphere" size="0.137248"/>
      <geom name="//unnamed_geom_40" class="reward_collision_sphere" size="0.137248" pos="0.608681 0 0"/>
      <geom name="//unnamed_geom_41" class="reward_collision_sphere" size="0.137248" pos="-0.608681 0 0"/>
      <site name="imu" pos="0.386515 -0.00098946 0.0258007" size="0.0114373"/>
      <camera name="track" pos="0 -1.34665 0" quat="0.707107 0.707107 0 0" mode="trackcom"/>
      <camera name="ego_camera" pos="0.608681 0 -0.0562102" quat="-0.5 -0.5 0.5 0.5"/>
      <body name="LF_HIP" pos="0.407271 0.071416 -0.00147791" quat="0.259686 0.965692 0.000792682 -0.000854971">
        <inertial pos="0.0685719 -0.00734333 -0.0137938" quat="-0.111551 0.708522 -0.125343 0.68545" mass="4.48179" diaginertia="0.0286953 0.000652045 0.017385"/>
        <joint name="LF_HAA" pos="0 0 0" axis="0.999566 0.00850775 0.0282099" range="-0.758435 0.416801" armature="0.00623595" damping="0.0518608" frictionloss="0.109461"/>
        <geom name="//unnamed_geom_42" class="visual" pos="0 -0.000742723 0.000121992" quat="0.258819 -0.965926 0 0" material="hip_l" mesh="hip_l"/>
        <geom name="//unnamed_geom_43" class="visual" pos="0.0810222 -0.0894916 -0.0570818" quat="0.183013 -0.683013 0.683013 0.183013" material="drive" mesh="drive"/>
        <geom name="//unnamed_geom_44" class="collision" size="0.0571867 0.0800614" pos="0.0810222 -0.00805283 -0.00970328" quat="-0.353553 -0.612372 0.612372 -0.353553"/>
        <body name="LF_THIGH" pos="0.0823201 -0.0504651 -0.0579289" quat="0.182187 -0.683791 0.682504 0.182828">
          <inertial pos="0.0397078 -0.000758585 -0.353635" quat="0.993313 -0.00596344 -0.0794076 0.083597" mass="4.44991" diaginertia="0.154806 0.00424864 0.0231854"/>
          <joint name="LF_HFE" pos="0 0 0" axis="0.998774 0.0378258 -0.0319372" range="-3.14327 3.15751" armature="0.0119693" damping="0.0104354" frictionloss="0.159255"/>
          <geom name="//unnamed_geom_45" class="visual" pos="0.0135154 2.12971e-05 0" quat="0.707107 0 0 -0.707107" material="thigh" mesh="thigh"/>
          <geom name="//unnamed_geom_46" class="collision" size="0.0743427 0.0457494" pos="0.0541049 0 0" quat="0.5 0.5 -0.5 -0.5"/>
          <geom name="//unnamed_geom_47" class="collision" size="0.04289 0.034312 0.161626" pos="0.0405787 0 -0.198582" quat="0.707107 0 0 -0.707107" type="box"/>
          <geom name="//unnamed_geom_48" class="visual" pos="0.135668 0 -0.400498" quat="1 0 0 0" material="drive" mesh="drive"/>
          <geom name="//unnamed_geom_49" class="collision" size="0.0571867 0.0800614" pos="0.0409845 0 -0.400498" quat="0.707107 0 0.707107 0"/>
          <geom name="//unnamed_geom_50" class="reward_collision_sphere" size="0.0914987" pos="0.0338156 0 0"/>
          <body name="LF_SHANK" pos="0.128815 0.00712128 -0.390541" quat="0.999994 6.3976e-05 0.00147971 0.00301492">
            <inertial pos="0.00728013 -0.0408245 -0.113301" quat="0.992914 -0.116128 -0.00125264 -0.0251839" mass="0.896638" diaginertia="0.0478032 0.00128799 0.00636559"/>
            <joint name="LF_KFE" pos="0 0 0" axis="0.999979 -0.00640552 0.000463247" stiffness="0.00297252" range="-3.04388 3.10527" armature="0.00986286" damping="0.0417204" frictionloss="0.0888333"/>
            <geom name="//unnamed_geom_51" class="visual" pos="0.00440707 0.0234987 0" quat="0.707107 0 0 -0.707107" material="shank_l" mesh="shank_l"/>
            <geom name="LF_kfe_act" class="collision" size="0.0686241 0.0228747" pos="0.0270525 0 0" quat="0.5 0.5 -0.5 -0.5"/>
            <geom name="//unnamed_geom_53" class="collision" size="0.0657636 0.038601 0.021731" pos="0.0270525 -0.0387155 0" quat="0.5 0.5 -0.5 -0.5" type="box"/>
            <geom name="//unnamed_geom_54" class="visual" pos="0.0176507 -0.0516462 -0.474934" quat="0.382683 0 0 -0.92388" material="foot" mesh="foot"/>
            <geom name="LF_calf" class="collision" size="0.0200154 0.161555" pos="0.0176517 -0.0592189 -0.237467" quat="0.707107 0 0 -0.707107"/>
            <geom name="LF_foot" class="foot" size="0.0330579" pos="0.0176517 -0.0592189 -0.443316" quat="0.707107 0 0 -0.707107"/>
            <geom name="//unnamed_geom_57" class="reward_collision_sphere" size="0.114373" pos="-0.0676312 0 0"/>
            <geom name="//unnamed_geom_58" class="reward_collision_sphere" size="0.0571867" pos="0.0176517 -0.0592189 -0.443316"/>
            <site name="LF_foot" class="foot" pos="0.0176517 -0.0592189 -0.443316" quat="0.707107 0 0 -0.707107" size="0.0114373"/>
          </body>
        </body>
      </body>
      <body name="RF_HIP" pos="0.410403 -0.0708682 0.0014885" quat="0.258833 -0.965922 -0.000588769 0.000245257">
        <inertial pos="0.0690885 0.00875807 -0.00986607" quat="0.136291 0.684276 0.126839 0.705056" mass="3.9321" diaginertia="0.0258013 0.000613758 0.0169522"/>
        <joint name="RF_HAA" pos="0 0 0" axis="0.999976 -0.00466338 0.00506426" stiffness="0.00197882" range="-0.324597 0.739193" armature="0.0156062" damping="0.0064695" frictionloss="0.159977"/>
        <geom name="//unnamed_geom_59" class="visual" pos="0 0.000742717 0.000121991" quat="0.258819 0.965926 0 0" material="hip_r" mesh="hip_r"/>
        <geom name="//unnamed_geom_60" class="visual" pos="0.0810221 0.0894916 -0.0570818" quat="0.183013 0.683013 0.683013 -0.183013" material="drive" mesh="drive"/>
        <geom name="//unnamed_geom_61" class="collision" size="0.0571867 0.0800614" pos="0.0810222 0.00805283 -0.00970328" quat="-0.353553 0.612372 0.612372 0.353553"/>
        <body name="RF_THIGH" pos="0.0833937 0.0402208 -0.0561454" quat="0.183028 0.68303 0.682983 -0.183045">
          <inertial pos="0.0409924 0.0013109 -0.347289" quat="0.992136 -0.0358978 -0.0634318 0.101751" mass="5.49903" diaginertia="0.150691 0.00420372 0.0238914"/>
          <joint name="RF_HFE" pos="0 0 0" axis="0.999536 -0.0188666 0.0239003" stiffness="0.00817485" range="-3.33677 3.04345" armature="0.0114587" damping="0.0365207" frictionloss="0.0514598"/>
          <geom name="//unnamed_geom_62" class="visual" pos="0.0135154 2.12971e-05 0" quat="0.707107 0 0 -0.707107" material="thigh" mesh="thigh"/>
          <geom name="//unnamed_geom_63" class="collision" size="0.0743427 0.0457494" pos="0.0541049 0 0" quat="0.5 0.5 0.5 0.5"/>
          <geom name="//unnamed_geom_64" class="collision" size="0.04289 0.034312 0.161626" pos="0.0405787 0 -0.198582" quat="0.707107 0 0 0.707107" type="box"/>
          <geom name="//unnamed_geom_65" class="visual" pos="0.135668 0 -0.400498" quat="1 0 0 0" material="drive" mesh="drive"/>
          <geom name="//unnamed_geom_66" class="collision" size="0.0571867 0.0800614" pos="0.0409845 0 -0.400498" quat="0.707107 0 0.707107 0"/>
          <geom name="//unnamed_geom_67" class="reward_collision_sphere" size="0.0914987" pos="0.0338156 0 0"/>
          <body name="RF_SHANK" pos="0.127951 0.00880059 -0.402156" quat="1 -0.000327833 -0.000909453 -0.000174864">
            <inertial pos="0.0065935 0.0393913 -0.122005" quat="0.993779 0.111096 -0.00368605 0.00693257" mass="0.870582" diaginertia="0.0517922 0.00138973 0.00630355"/>
            <joint name="RF_KFE" pos="0 0 0" axis="0.999991 0.00395335 -0.00175576" stiffness="0.00290758" range="-3.05928 3.0487" armature="0.0119033" damping="0.0164165" frictionloss="0.168008"/>
            <geom name="//unnamed_geom_68" class="visual" pos="0.00440705 -0.0234987 0" quat="0.707107 0 0 0.707107" material="shank" mesh="shank_r"/>
            <geom name="RF_kfe_act" class="collision" size="0.0686241 0.0228747" pos="0.0270525 0 0" quat="0.5 0.5 0.5 0.5"/>
            <geom name="//unnamed_geom_70" class="collision" size="0.0657636 0.038601 0.021731" pos="0.0270525 0.0387155 0" quat="0.5 0.5 0.5 0.5" type="box"/>
            <geom name="//unnamed_geom_71" class="visual" pos="0.0176528 0.0516462 -0.474934" quat="0.382683 0 0 0.92388" material="foot" mesh="foot"/>
            <geom name="RF_calf" class="collision" size="0.0200154 0.161555" pos="0.0176517 0.0592189 -0.237467" quat="0.707107 0 0 0.707107"/>
            <geom name="RF_foot" class="foot" size="0.0483555" pos="0.0176517 0.0592189 -0.443316" quat="0.707107 0 0 0.707107"/>
            <geom name="//unnamed_geom_74" class="reward_collision_sphere" size="0.114373" pos="-0.0676312 0 0"/>
            <geom name="//unnamed_geom_75" class="reward_collision_sphere" size="0.0571867" pos="0.0176517 0.0592189 -0.443316"/>
            <site name="RF_foot" class="foot" pos="0.0176517 0.0592189 -0.443316" quat="0.707107 0 0 0.707107" size="0.0114373"/>
          </body>
        </body>
      </body>
      <body name="LH_HIP" pos="-0.395897 0.0680616 0.00039867" quat="4.86138e-05 0.000104005 0.965925 -0.258821">
        <inertial pos="0.0743364 0.00194126 -0.00967928" quat="0.146516 0.669876 0.11543 0.718662" mass="4.20414" diaginertia="0.0293799 0.000654881 0.0216123"/>
        <joint name="LH_HAA" pos="0 0 0" axis="0.999982 0.00160244 -0.00577752" stiffness="0.00397079" range="-0.521772 0.940254" armature="0.0164862" damping="0.0245544" frictionloss="0.103592"/>
        <geom name="//unnamed_geom_76" class="visual" pos="0 0.000742717 0.000121991" quat="-0.258819 -0.965926 0 0" material="hip_r" mesh="hip_r"/>
        <geom name="//unnamed_geom_77" class="visual" pos="0.0810221 0.0894916 -0.0570818" quat="0.183013 0.683013 0.683013 -0.183013" material="drive" mesh="drive"/>
        <geom name="//unnamed_geom_78" class="collision" size="0.0571867 0.0800614" pos="0.0810222 0.00805283 -0.00970328" quat="-0.353553 0.612372 0.612372 0.353553"/>
        <body name="LH_THIGH" pos="0.0855383 0.0596298 -0.0591808" quat="0.182959 0.682974 0.683037 -0.183122">
          <inertial pos="0.0414224 -0.00674846 -0.346282" quat="0.993217 0.00331984 -0.0779879 0.0861771" mass="4.60612" diaginertia="0.137475 0.00433985 0.0226877"/>
          <joint name="LH_HFE" pos="0 0 0" axis="0.999389 -0.0307436 -0.01661" range="-3.13028 3.10458" armature="0.0131835" damping="0.020137" frictionloss="0.10725"/>
          <geom name="//unnamed_geom_79" class="visual" pos="0.0135154 2.12971e-05 0" quat="0.707107 0 0 -0.707107" material="thigh" mesh="thigh"/>
          <geom name="//unnamed_geom_80" class="collision" size="0.0743427 0.0457494" pos="0.0541049 0 0" quat="0.5 0.5 -0.5 -0.5"/>
          <geom name="//unnamed_geom_81" class="collision" size="0.04289 0.034312 0.161626" pos="0.0405787 0 -0.198582" quat="0.707107 0 0 -0.707107" type="box"/>
          <geom name="//unnamed_geom_82" class="visual" pos="0.135668 0 -0.400498" quat="1 0 0 0" material="drive" mesh="drive"/>
          <geom name="//unnamed_geom_83" class="collision" size="0.0571867 0.0800614" pos="0.0409845 0 -0.400498" quat="0.707107 0 0.707107 0"/>
          <geom name="//unnamed_geom_84" class="reward_collision_sphere" size="0.0914987" pos="0.0338156 0 0"/>
          <body name="LH_SHANK" pos="0.140524 0.00116477 -0.399019" quat="1 0.000316447 0.000828013 -0.000120845">
            <inertial pos="0.00762833 0.04188 -0.114214" quat="0.990137 0.115501 -0.01405 0.0780459" mass="0.894294" diaginertia="0.0476201 0.0013168 0.00698341"/>
            <joint name="LH_KFE" pos="0 0 0" axis="0.999552 -0.0112354 0.0277562" stiffness="0.00456316" range="-3.18052 3.12952" armature="0.0146724" damping="0.00174022" frictionloss="0.0872533"/>
            <geom name="//unnamed_geom_85" class="visual" pos="0.00440705 -0.0234987 0" quat="-0.707107 0 0 -0.707107" material="shank" mesh="shank_r"/>
            <geom name="LH_kfe_act" class="collision" size="0.0686241 0.0228747" pos="0.0270525 0 0" quat="0.5 0.5 -0.5 -0.5"/>
            <geom name="//unnamed_geom_87" class="collision" size="0.0657636 0.038601 0.021731" pos="0.0270525 0.0387155 0" quat="0.5 0.5 -0.5 -0.5" type="box"/>
            <geom name="//unnamed_geom_88" class="visual" pos="0.0176528 0.0516462 -0.474934" quat="-0.382683 0 0 -0.92388" material="foot" mesh="foot"/>
            <geom name="LH_calf" class="collision" size="0.0200154 0.161555" pos="0.0176517 0.0592189 -0.237467" quat="0.707107 0 0 -0.707107"/>
            <geom name="LH_foot" class="foot" size="0.0179008" pos="0.0176517 0.0592189 -0.443316" quat="0.707107 0 0 -0.707107"/>
            <geom name="//unnamed_geom_91" class="reward_collision_sphere" size="0.114373" pos="-0.0676312 0 0"/>
            <geom name="//unnamed_geom_92" class="reward_collision_sphere" size="0.0571867" pos="0.0176517 0.0592189 -0.443316"/>
            <site name="LH_foot" class="foot" pos="0.0176517 0.0592189 -0.443316" quat="0.707107 0 0 -0.707107" size="0.0114373"/>
          </body>
        </body>
      </body>
      <body name="RH_HIP" pos="-0.404564 -0.0615242 0.00234907" quat="0.000182932 -0.0027688 -0.96558 -0.26009">
        <inertial pos="0.0852514 -0.011894 -0.0191632" quat="-0.12748 0.710476 -0.134315 0.67892" mass="4.28655" diaginertia="0.0278437 0.000710532 0.0209096"/>
        <joint name="RH_HAA" pos="0 0 0" axis="0.999998 -0.00169312 -0.00120947" stiffness="0.0129055" range="-0.577571 0.295549" armature="0.0116223" damping="0.0323308" frictionloss="0.117866"/>
        <geom name="//unnamed_geom_93" class="visual" pos="0 -0.000742723 0.000121992" quat="-0.258819 0.965926 0 0" material="hip_l" mesh="hip_l"/>
        <geom name="//unnamed_geom_94" class="visual" pos="0.0810222 -0.0894916 -0.0570818" quat="-0.183013 0.683013 -0.683013 -0.183013" material="drive" mesh="drive"/>
        <geom name="//unnamed_geom_95" class="collision" size="0.0571867 0.0800614" pos="0.0810222 -0.00805283 -0.00970328" quat="0.353553 0.612372 -0.612372 0.353553"/>
        <body name="RH_THIGH" pos="0.0833352 -0.0459194 -0.0674066" quat="-0.18314 0.683128 -0.682899 -0.182879">
          <inertial pos="0.0362508 -0.000448387 -0.344418" quat="0.993325 -0.00358302 -0.0809217 0.0821198" mass="5.82107" diaginertia="0.169315 0.00479212 0.0260894"/>
          <joint name="RH_HFE" pos="0 0 0" axis="0.999434 -0.00564518 -0.0331491" stiffness="0.00732027" range="-3.10519 3.16919" armature="0.0124719" damping="0.00975628" frictionloss="0.118828"/>
          <geom name="//unnamed_geom_96" class="visual" pos="0.0135154 2.12971e-05 0" quat="0.707107 0 0 -0.707107" material="thigh" mesh="thigh"/>
          <geom name="//unnamed_geom_97" class="collision" size="0.0743427 0.0457494" pos="0.0541049 0 0" quat="0.5 0.5 0.5 0.5"/>
          <geom name="//unnamed_geom_98" class="collision" size="0.04289 0.034312 0.161626" pos="0.0405787 0 -0.198582" quat="0.707107 0 0 0.707107" type="box"/>
          <geom name="//unnamed_geom_99" class="visual" pos="0.135668 0 -0.400498" quat="1 0 0 0" material="drive" mesh="drive"/>
          <geom name="//unnamed_geom_100" class="collision" size="0.0571867 0.0800614" pos="0.0409845 0 -0.400498" quat="0.707107 0 0.707107 0"/>
          <geom name="//unnamed_geom_101" class="reward_collision_sphere" size="0.0914987" pos="0.0338156 0 0"/>
          <body name="RH_SHANK" pos="0.143811 -0.000496604 -0.399572" quat="0.999999 -0.000289478 0.00147008 -0.000197263">
            <inertial pos="0.00917558 -0.0416383 -0.111448" quat="0.989485 -0.137957 -0.0281381 -0.0331088" mass="0.917653" diaginertia="0.0492237 0.00119412 0.0064218"/>
            <joint name="RH_KFE" pos="0 0 0" axis="0.9995 -0.0313903 0.00366544" range="-3.14269 3.15469" armature="0.0168656" damping="0.00750387" frictionloss="0.112219"/>
            <geom name="//unnamed_geom_102" class="visual" pos="0.00440707 0.0234987 0" quat="0.707107 0 0 -0.707107" material="shank_l" mesh="shank_l"/>
            <geom name="RH_kfe_act" class="collision" size="0.0686241 0.0228747" pos="0.0270525 0 0" quat="0.5 0.5 0.5 0.5"/>
            <geom name="//unnamed_geom_104" class="collision" size="0.0657636 0.038601 0.021731" pos="0.0270525 -0.0387155 0" quat="0.5 0.5 0.5 0.5" type="box"/>
            <geom name="//unnamed_geom_105" class="visual" pos="0.0176507 -0.0516462 -0.474934" quat="0.382683 0 0 -0.92388" material="foot" mesh="foot"/>
            <geom name="RH_calf" class="collision" size="0.0200154 0.161555" pos="0.0176517 -0.0592189 -0.237467" quat="0.707107 0 0 0.707107"/>
            <geom name="RH_foot" class="foot" size="0.0403749" pos="0.0176517 -0.0592189 -0.443316" quat="0.707107 0 0 0.707107"/>
            <geom name="//unnamed_geom_108" class="reward_collision_sphere" size="0.114373" pos="-0.0676312 0 0"/>
            <geom name="//unnamed_geom_109" class="reward_collision_sphere" size="0.0571867" pos="0.0176517 -0.0592189 -0.443316"/>
            <site name="RH_foot" class="foot" pos="0.0176517 -0.0592189 -0.443316" quat="0.707107 0 0 0.707107" size="0.0114373"/>
          </body>
        </body>
      </body>
    </body>
  </worldbody>

  <contact>
    <pair class="/" geom1="floor" geom2="LF_foot" name="//unnamed_contact_0"/>
    <pair class="/" geom1="floor" geom2="RF_foot" name="//unnamed_contact_1"/>
    <pair class="/" geom1="floor" geom2="LH_foot" name="//unnamed_contact_2"/>
    <pair class="/" geom1="floor" geom2="RH_foot" name="//unnamed_contact_3"/>
  </contact>

  <actuator>
    <general name="LF_HAA" class="/" joint="LF_HAA" forcerange="-88.3784 88.3784" gainprm="61.474" biasprm="0 -61.474 -2.40623"/>
    <general name="LF_HFE" class="/" joint="LF_HFE" forcerange="-104.408 104.408" gainprm="61.474" biasprm="0 -61.474 -2.40623"/>
    <general name="LF_KFE" class="/" joint="LF_KFE" forcerange="-94.6706 94.6706" gainprm="61.474" biasprm="0 -61.474 -2.40623"/>
    <general name="RF_HAA" class="/" joint="RF_HAA" forcerange="-106.351 106.351" gainprm="61.474" biasprm="0 -61.474 -2.40623"/>
    <general name="RF_HFE" class="/" joint="RF_HFE" forcerange="-83.363 83.363" gainprm="61.474" biasprm="0 -61.474 -2.40623"/>
    <general name="RF_KFE" class="/" joint="RF_KFE" forcerange="-117.828 117.828" gainprm="61.474" biasprm="0 -61.474 -2.40623"/>
    <general name="LH_HAA" class="/" joint="LH_HAA" forcerange="-93.4986 93.4986" gainprm="61.474" biasprm="0 -61.474 -2.40623"/>
    <general name="LH_HFE" class="/" joint="LH_HFE" forcerange="-118.622 118.622" gainprm="61.474" biasprm="0 -61.474 -2.40623"/>
    <general name="LH_KFE" class="/" joint="LH_KFE" forcerange="-93.8438 93.8438" gainprm="61.474" biasprm="0 -61.474 -2.40623"/>
    <general name="RH_HAA" class="/" joint="RH_HAA" forcerange="-94.8066 94.8066" gainprm="61.474" biasprm="0 -61.474 -2.40623"/>
    <general name="RH_HFE" class="/" joint="RH_HFE" forcerange="-123.343 123.343" gainprm="61.474" biasprm="0 -61.474 -2.40623"/>
    <general name="RH_KFE" class="/" joint="RH_KFE" forcerange="-67.4316 67.4316" gainprm="61.474" biasprm="0 -61.474 -2.40623"/>
  </actuator>

  <sensor>
    <gyro site="imu" name="imu_angular_velocity"/>
    <velocimeter site="imu" name="imu_linear_velocity"/>
    <framelinvel objtype="site" objname="LF_foot" name="LF_foot_global_linear_velocity"/>
    <framelinvel objtype="site" objname="RF_foot" name="RF_foot_global_linear_velocity"/>
    <framelinvel objtype="site" objname="LH_foot" name="LH_foot_global_linear_velocity"/>
    <framelinvel objtype="site" objname="RH_foot" name="RH_foot_global_linear_velocity"/>
  </sensor>

  <keyframe>
    <key name="home" qpos="0 0 0.55 1 0 0 0 0 0.4 -0.8 0 -0.4 0.8 0 -0.4 0.8 0 0.4 -0.8"/>
  </keyframe>
</mujoco>
