<mujoco model="anymal_c">
  <compiler angle="radian" assetdir="assets" balanceinertia="true" inertiafromgeom="false"/>

  <option timestep="0.005" density="1.2" viscosity="2e-05"/>

  <size nkey="1"/>

  <visual>
    <quality shadowsize="8192"/>
    <map shadowclip="0.5"/>
  </visual>

  <default>
    <default class="/">
      <material specular="0" shininess="0.25"/>
      <geom contype="0" conaffinity="0" group="1" solref="-1000 -80"/>
      <site size="0.01 0.005 0.005" group="5"/>
      <general forcelimited="true" forcerange="-80 80" biastype="affine" gainprm="80" biasprm="0 -80 -2"/>
      <default class="anymal_c">
        <joint armature="0.01" damping="0.01" frictionloss="0.1"/>
        <default class="visual">
          <geom type="mesh" group="2"/>
          <default class="visual_zflip"/>
        </default>
        <default class="collision">
          <geom type="cylinder" group="3"/>
          <default class="foot">
            <geom size="0.03 0 0" type="sphere" condim="6" priority="1" friction="0.8 0.02 0.01" solimp="0.015 1 0.03"/>
          </default>
        </default>
      </default>
      <default class="reward_collision_sphere">
        <geom group="5" rgba="1 0 0 1"/>
      </default>
    </default>
  </default>

  <asset>
    <texture type="skybox" colorspace="auto" name="//unnamed_texture_0" builtin="gradient" rgb1="0.95 0.95 0.95" rgb2="0.95 0.95 0.95" width="100" height="600"/>
    <texture type="2d" colorspace="auto" name="texplane" builtin="checker" rgb1="0.345 0.575 0.748" rgb2="0.345 0.575 0.748" markrgb="1 1 1" width="512" height="512"/>
    <texture type="2d" colorspace="linear" name="base" file="base.png"/>
    <texture type="2d" colorspace="linear" name="top_shell" file="top_shell.png"/>
    <texture type="2d" colorspace="linear" name="bottom_shell" file="bottom_shell.png"/>
    <texture type="2d" colorspace="linear" name="remote" file="remote.png"/>
    <texture type="2d" colorspace="linear" name="hatch" file="hatch.png"/>
    <texture type="2d" colorspace="linear" name="handle" file="handle.png"/>
    <texture type="2d" colorspace="linear" name="face" file="face.png"/>
    <texture type="2d" colorspace="linear" name="battery" file="battery.png"/>
    <texture type="2d" colorspace="linear" name="lidar_cage" file="lidar_cage.png"/>
    <texture type="2d" colorspace="linear" name="depth_camera" file="depth_camera.png"/>
    <texture type="2d" colorspace="linear" name="wide_angle_camera" file="wide_angle_camera.png"/>
    <texture type="2d" colorspace="linear" name="lidar" file="lidar.png"/>
    <texture type="2d" colorspace="linear" name="drive" file="drive.png"/>
    <texture type="2d" colorspace="linear" name="hip_l" file="hip_l.png"/>
    <texture type="2d" colorspace="linear" name="shank_l" file="shank_l.png"/>
    <texture type="2d" colorspace="linear" name="foot" file="foot.png"/>
    <texture type="2d" colorspace="linear" name="thigh" file="thigh.png"/>
    <texture type="2d" colorspace="linear" name="shank_r" file="shank_r.png"/>
    <texture type="2d" colorspace="linear" name="hip_r" file="hip_r.png"/>
    <material name="MatPlane" class="/" texture="texplane" texuniform="true" texrepeat="2 2" specular="0.9" shininess="0.5"/>
    <material name="black_plastic" class="/" rgba="0.007 0.007 0.007 1"/>
    <material name="green" class="/" rgba="0.052 0.178 0.033 1"/>
    <material name="red" class="/" rgba="0.178 0.006 0.005 1"/>
    <material name="yellow" class="/" rgba="0.178 0.119 0.006 1"/>
    <material name="lwl" class="/" rgba="0.8 0.8 0.8 1"/>
    <material name="base" class="/" texture="base"/>
    <material name="top_shell" class="/" texture="top_shell"/>
    <material name="bottom_shell" class="/" texture="bottom_shell"/>
    <material name="hip_l" class="/" texture="hip_l"/>
    <material name="thigh" class="/" texture="thigh"/>
    <material name="shank_l" class="/" texture="shank_l"/>
    <material name="foot" class="/" texture="foot"/>
    <material name="hip_r" class="/" texture="hip_r"/>
    <material name="shank" class="/" texture="shank_r"/>
    <material name="hatch" class="/" texture="hatch"/>
    <material name="remote" class="/" texture="remote"/>
    <material name="handle" class="/" texture="handle"/>
    <material name="face" class="/" texture="face"/>
    <material name="depth_camera" class="/" texture="depth_camera"/>
    <material name="wide_angle_camera" class="/" texture="wide_angle_camera"/>
    <material name="battery" class="/" texture="battery"/>
    <material name="lidar_cage" class="/" texture="lidar_cage"/>
    <material name="lidar" class="/" texture="lidar"/>
    <material name="drive" class="/" texture="drive"/>
    <mesh name="base_0" class="/" file="base_0.obj"/>
    <mesh name="base_1" class="/" file="base_1.obj"/>
    <mesh name="base_2" class="/" file="base_2.obj"/>
    <mesh name="base_3" class="/" file="base_3.obj"/>
    <mesh name="base_4" class="/" file="base_4.obj"/>
    <mesh name="base_5" class="/" file="base_5.obj"/>
    <mesh name="top_shell" class="/" file="top_shell.obj"/>
    <mesh name="bottom_shell" class="/" file="bottom_shell.obj"/>
    <mesh name="remote" class="/" file="remote.obj"/>
    <mesh name="handle" class="/" file="handle.obj"/>
    <mesh name="face" class="/" file="face.obj"/>
    <mesh name="wide_angle_camera" class="/" file="wide_angle_camera.obj"/>
    <mesh name="depth_camera" class="/" file="depth_camera.obj"/>
    <mesh name="battery" class="/" file="battery.obj"/>
    <mesh name="lidar_cage" class="/" file="lidar_cage.obj"/>
    <mesh name="lidar" class="/" file="lidar.obj"/>
    <mesh name="drive" class="/" file="drive.obj"/>
    <mesh name="hip_l" class="/" file="hip_l.obj"/>
    <mesh name="thigh" class="/" file="thigh.obj"/>
    <mesh name="shank_l" class="/" file="shank_l.obj"/>
    <mesh name="foot" class="/" file="foot.obj"/>
    <mesh name="hip_r" class="/" file="hip_r.obj"/>
    <mesh name="hatch" class="/" file="hatch.obj"/>
    <mesh name="shank_r" class="/" file="shank_r.obj"/>
  </asset>

  <worldbody>
    <geom name="floor" class="/" size="100 100 0.125" type="plane" group="0" material="MatPlane"/>
    <light name="toplight_shadow" class="/" pos="0 0 5" dir="0.0990148 0.0990148 -0.990148" type="directional" ambient="0.04 0.04 0.04" diffuse="0.55 0.55 0.55" specular="0.12 0.12 0.12"/>
    <light name="toplight_fill" class="/" pos="0 0 5" dir="0.0990148 0.0990148 -0.990148" type="directional" castshadow="false" ambient="0.04 0.04 0.04" diffuse="0.3 0.3 0.3" specular="0.08 0.08 0.08"/>
    <body name="trunk" childclass="anymal_c" pos="-0.00014265 2.38863e-05 0.00079406" quat="1 1.78203e-05 1.9387e-05 -1.40583e-05">
      <inertial pos="0.00274754 -0.000166911 0.048097" quat="0.50068 0.499823 0.499603 0.499894" mass="17.7072" diaginertia="0.580206 0.589081 0.190132"/>
      <joint name="//unnamed_joint_0" type="free" armature="0" damping="0" frictionloss="0"/>
      <geom name="//unnamed_geom_1" class="visual" material="green" mesh="base_0"/>
      <geom name="//unnamed_geom_2" class="visual" material="yellow" mesh="base_1"/>
      <geom name="//unnamed_geom_3" class="visual" material="red" mesh="base_2"/>
      <geom name="//unnamed_geom_4" class="visual" material="black_plastic" mesh="base_3"/>
      <geom name="//unnamed_geom_5" class="visual" material="lwl" mesh="base_4"/>
      <geom name="//unnamed_geom_6" class="visual" material="base" mesh="base_5"/>
      <geom name="trunk_1" class="collision" size="0.285456 0.0689033 0.0885899" type="box"/>
      <geom name="trunk_2" class="collision" size="0.0885899 0.0713641" pos="0.213941 0.0694015 0" quat="0.707107 0 0.707107 0"/>
      <geom name="trunk_3" class="collision" size="0.0885899 0.0713641" pos="-0.213941 0.0694015 0" quat="0.707107 0 0.707107 0"/>
      <geom name="trunk_4" class="collision" size="0.0885899 0.0713641" pos="0.213941 -0.0694015 0" quat="0.707107 0 0.707107 0"/>
      <geom name="trunk_5" class="collision" size="0.0885899 0.0713641" pos="-0.213941 -0.0694015 0" quat="0.707107 0 0.707107 0"/>
      <geom name="//unnamed_geom_12" class="visual" material="top_shell" mesh="top_shell"/>
      <geom name="//unnamed_geom_13" class="visual" material="bottom_shell" mesh="bottom_shell"/>
      <geom name="//unnamed_geom_14" class="visual" material="remote" mesh="remote"/>
      <geom name="//unnamed_geom_15" class="visual" material="handle" mesh="handle"/>
      <geom name="//unnamed_geom_16" class="visual" pos="0.407718 0 0" quat="1 0 0 0" material="face" mesh="face"/>
      <geom name="trunk_6" class="collision" size="0.0541383 0.0689033 0.0885899" pos="0.461818 0 0" type="box"/>
      <geom name="//unnamed_geom_18" class="collision" size="0.0885899 0.0541383" pos="0.461818 0.0694015 0" quat="0.707107 0 0.707107 0"/>
      <geom name="//unnamed_geom_19" class="collision" size="0.0885899 0.0541383" pos="0.461818 -0.0694015 0" quat="0.707107 0 0.707107 0"/>
      <geom name="//unnamed_geom_20" class="visual" pos="0.454096 0 -0.0285115" quat="0.965926 0 0.258819 0" material="depth_camera" mesh="depth_camera"/>
      <geom name="//unnamed_geom_21" class="visual" pos="0.504606 0 0.0146393" material="wide_angle_camera" mesh="wide_angle_camera"/>
      <geom name="//unnamed_geom_22" class="visual_zflip" pos="-0.407718 0 0" quat="0 0 0 1" material="face" mesh="face"/>
      <geom name="trunk_7" class="collision" size="0.0541383 0.0689033 0.0885899" pos="-0.461818 0 0" quat="0 0 0 1" type="box"/>
      <geom name="//unnamed_geom_24" class="collision" size="0.0885899 0.0541383" pos="-0.461818 -0.0694015 0" quat="0 -0.707107 0 0.707107"/>
      <geom name="//unnamed_geom_25" class="collision" size="0.0885899 0.0541383" pos="-0.461818 0.0694015 0" quat="0 -0.707107 0 0.707107"/>
      <geom name="//unnamed_geom_26" class="visual" pos="-0.454096 0 -0.0285115" quat="0 -0.258819 0 0.965926" material="depth_camera" mesh="depth_camera"/>
      <geom name="//unnamed_geom_27" class="visual_zflip" pos="-0.504606 0 0.0146393" quat="0 0 0 1" material="wide_angle_camera" mesh="wide_angle_camera"/>
      <geom name="//unnamed_geom_28" class="visual" material="battery" mesh="battery"/>
      <geom name="//unnamed_geom_29" class="visual" pos="0 0.0759085 0.0284518" quat="0.683013 -0.183013 0.183013 0.683013" material="depth_camera" mesh="depth_camera"/>
      <geom name="//unnamed_geom_30" class="visual" pos="0 -0.0759085 0.0284518" quat="0.683013 0.183013 0.183013 -0.683013" material="depth_camera" mesh="depth_camera"/>
      <geom name="//unnamed_geom_31" class="visual" pos="-0.358044 0 0.0718765" quat="1 0 0 0" material="lidar_cage" mesh="lidar_cage"/>
      <geom name="trunk_8" class="collision" size="0.0689033 0.05906" pos="-0.358044 0 0.130551"/>
      <geom name="//unnamed_geom_33" class="visual" pos="-0.358044 3.06913e-06 0.139059" quat="0.707107 0 0 -0.707107" material="lidar" mesh="lidar"/>
      <geom name="//unnamed_geom_34" class="visual" pos="0.294993 0.103106 2.33533e-10" quat="0.258819 0.965926 0 0" material="drive" mesh="drive"/>
      <geom name="//unnamed_geom_35" class="visual" pos="0.294993 -0.103106 -2.33533e-10" quat="0.258819 -0.965926 0 0" material="drive" mesh="drive"/>
      <geom name="//unnamed_geom_36" class="visual" pos="-0.294993 0.103106 -2.33533e-10" quat="0 0 0.965926 -0.258819" material="drive" mesh="drive"/>
      <geom name="//unnamed_geom_37" class="visual" pos="-0.294993 -0.103106 2.33533e-10" quat="0 0 -0.965926 -0.258819" material="drive" mesh="drive"/>
      <geom name="//unnamed_geom_38" class="visual" pos="0.114102 0 0.0713875" quat="1 0 0 0" material="hatch" mesh="hatch"/>
      <geom name="//unnamed_geom_39" class="reward_collision_sphere" size="0.11812"/>
      <geom name="//unnamed_geom_40" class="reward_collision_sphere" size="0.11812" pos="0.442637 0 0"/>
      <geom name="//unnamed_geom_41" class="reward_collision_sphere" size="0.11812" pos="-0.442637 0 0"/>
      <site name="imu" pos="0.24044 0.00681707 0.0453642" size="0.00984333"/>
      <camera name="track" pos="0 -1.9829 0" quat="0.707107 0.707107 0 0" mode="trackcom"/>
      <camera name="ego_camera" pos="0.442637 0 -0.0391165" quat="-0.5 -0.5 0.5 0.5"/>
      <body name="LF_HIP" pos="0.295687 0.10298 -0.000103677" quat="0.258475 0.966018 0.000187013 0.000221273">
        <inertial pos="0.0559212 -0.0140951 -0.00771934" quat="-0.124165 0.709456 -0.137735 0.679915" mass="2.65274" diaginertia="0.0053855 0.00471517 0.00295231"/>
        <joint name="LF_HAA" pos="0 0 0" axis="1 -0.000604384 0.000377532" range="-0.713732 0.473" armature="0.0101141" damping="0.00481616" frictionloss="0.0959896"/>
        <geom name="//unnamed_geom_42" class="visual" pos="0 1.37377e-05 -2.2564e-06" quat="0.258819 -0.965926 0 0" material="hip_l" mesh="hip_l"/>
        <geom name="//unnamed_geom_43" class="visual" pos="0.0589199 -0.071492 -0.0411758" quat="0.183013 -0.683013 0.683013 0.183013" material="drive" mesh="drive"/>
        <geom name="//unnamed_geom_44" class="collision" size="0.0492166 0.0689033" pos="0.0589199 -0.0118575 -0.00675248" quat="-0.353553 -0.612372 0.612372 -0.353553"/>
        <body name="LF_THIGH" pos="0.0592289 -0.0729122 -0.0418589" quat="0.182997 -0.683083 0.682958 0.182969">
          <inertial pos="0.0297987 -4.67695e-05 -0.240008" quat="0.993036 -0.00458638 -0.0811742 0.0852623" mass="2.88362" diaginertia="0.0276589 0.0285246 0.00370547"/>
          <joint name="LF_HFE" pos="0 0 0" axis="0.999997 0.00226395 0.000750224" stiffness="0.000495137" range="-3.14825 3.14869" armature="0.010049" damping="0.00878616" frictionloss="0.0984033"/>
          <geom name="//unnamed_geom_45" class="visual" pos="-0.000155428 -2.44919e-07 0" quat="0.707107 0 0 -0.707107" material="thigh" mesh="thigh"/>
          <geom name="//unnamed_geom_46" class="collision" size="0.0639816 0.0393733" pos="0.0393455 0 0" quat="0.5 0.5 -0.5 -0.5"/>
          <geom name="//unnamed_geom_47" class="collision" size="0.0369125 0.02953 0.1391" pos="0.0295091 0 -0.138193" quat="0.707107 0 0 -0.707107" type="box"/>
          <geom name="//unnamed_geom_48" class="visual" pos="0.0986588 0 -0.278705" quat="1 0 0 0" material="drive" mesh="drive"/>
          <geom name="//unnamed_geom_49" class="collision" size="0.0492166 0.0689033" pos="0.0298042 0 -0.278705" quat="0.707107 0 0.707107 0"/>
          <geom name="//unnamed_geom_50" class="reward_collision_sphere" size="0.0787466" pos="0.0245909 0 0"/>
          <body name="LF_SHANK" pos="0.0980152 0.000161167 -0.279398" quat="1 -5.32913e-05 -0.000103515 8.32587e-05">
            <inertial pos="0.00488148 -0.0607548 -0.0793459" quat="0.99274 -0.117506 -0.00174393 -0.025636" mass="0.569138" diaginertia="0.00946941 0.00886338 0.00100592"/>
            <joint name="LF_KFE" pos="0 0 0" axis="1 -0.000245563 -0.000206948" range="-3.12373 3.13404" armature="0.00938467" damping="0.00793396" frictionloss="0.0939963"/>
            <geom name="//unnamed_geom_51" class="visual" pos="-5.06818e-05 -0.000270238 0" quat="0.707107 0 0 -0.707107" material="shank_l" mesh="shank_l"/>
            <geom name="LF_kfe_act" class="collision" size="0.05906 0.0196867" pos="0.0196727 0 0" quat="0.5 0.5 -0.5 -0.5"/>
            <geom name="//unnamed_geom_53" class="collision" size="0.0565981 0.0332212 0.0187023" pos="0.0196727 -0.0570073 0" quat="0.5 0.5 -0.5 -0.5" type="box"/>
            <geom name="//unnamed_geom_54" class="visual" pos="0.0128365 -0.0872851 -0.330505" quat="0.382683 0 0 -0.92388" material="foot" mesh="foot"/>
            <geom name="LF_calf" class="collision" size="0.0172258 0.139039" pos="0.0128365 -0.087198 -0.165252" quat="0.707107 0 0 -0.707107"/>
            <geom name="LF_foot" class="foot" size="0.0316534" pos="0.0128365 -0.087198 -0.308502" quat="0.707107 0 0 -0.707107"/>
            <geom name="//unnamed_geom_57" class="reward_collision_sphere" size="0.0984333" pos="-0.0491819 0 0"/>
            <geom name="//unnamed_geom_58" class="reward_collision_sphere" size="0.0492166" pos="0.0128365 -0.087198 -0.308502"/>
            <site name="LF_foot" class="foot" pos="0.0128365 -0.087198 -0.308502" quat="0.707107 0 0 -0.707107" size="0.00984333"/>
          </body>
        </body>
      </body>
      <body name="RF_HIP" pos="0.296358 -0.103786 0.000402868" quat="0.258835 -0.965921 2.9161e-05 1.08536e-06">
        <inertial pos="0.0558428 0.0155272 -0.00836282" quat="0.135656 0.679101 0.128857 0.7098" mass="2.60934" diaginertia="0.00537472 0.0046068 0.00291218"/>
        <joint name="RF_HAA" pos="0 0 0" axis="1 2.4824e-05 0.000390244" range="-0.498078 0.728953" armature="0.00989817" damping="0.00915727" frictionloss="0.098055"/>
        <geom name="//unnamed_geom_59" class="visual" pos="0 -1.37376e-05 -2.2564e-06" quat="0.258819 0.965926 0 0" material="hip_r" mesh="hip_r"/>
        <geom name="//unnamed_geom_60" class="visual" pos="0.0589199 0.071492 -0.0411758" quat="0.183013 0.683013 0.683013 -0.183013" material="drive" mesh="drive"/>
        <geom name="//unnamed_geom_61" class="collision" size="0.0492166 0.0689033" pos="0.0589199 0.0118575 -0.00675248" quat="-0.353553 0.612372 0.612372 0.353553"/>
        <body name="RF_THIGH" pos="0.0597087 0.0724476 -0.0407435" quat="0.182934 0.682966 0.683056 -0.183105">
          <inertial pos="0.0302688 0.000361699 -0.240015" quat="0.992779 -0.00538553 -0.0803044 0.0889475" mass="2.93169" diaginertia="0.0280124 0.0285105 0.00373456"/>
          <joint name="RF_HFE" pos="0 0 0" axis="1 -0.000194358 -0.000253573" stiffness="0.00600031" range="-3.12586 3.12165" armature="0.00989419" damping="0.00995687" frictionloss="0.104404"/>
          <geom name="//unnamed_geom_62" class="visual" pos="-0.000155428 -2.44919e-07 0" quat="0.707107 0 0 -0.707107" material="thigh" mesh="thigh"/>
          <geom name="//unnamed_geom_63" class="collision" size="0.0639816 0.0393733" pos="0.0393455 0 0" quat="0.5 0.5 0.5 0.5"/>
          <geom name="//unnamed_geom_64" class="collision" size="0.0369125 0.02953 0.1391" pos="0.0295091 0 -0.138193" quat="0.707107 0 0 0.707107" type="box"/>
          <geom name="//unnamed_geom_65" class="visual" pos="0.0986588 0 -0.278705" quat="1 0 0 0" material="drive" mesh="drive"/>
          <geom name="//unnamed_geom_66" class="collision" size="0.0492166 0.0689033" pos="0.0298042 0 -0.278705" quat="0.707107 0 0.707107 0"/>
          <geom name="//unnamed_geom_67" class="reward_collision_sphere" size="0.0787466" pos="0.0245909 0 0"/>
          <body name="RF_SHANK" pos="0.0987239 -0.00031595 -0.279114" quat="1 -7.38838e-05 2.34289e-05 -0.000111428">
            <inertial pos="0.00541759 0.0610645 -0.0782962" quat="0.992941 0.116068 -0.00532245 0.0238187" mass="0.557703" diaginertia="0.00925864 0.00888401 0.000995666"/>
            <joint name="RF_KFE" pos="0 0 0" axis="1 5.42944e-05 8.05642e-05" range="-3.11838 3.1189" armature="0.00983834" damping="0.0103666" frictionloss="0.0953449"/>
            <geom name="//unnamed_geom_68" class="visual" pos="-5.06815e-05 0.000270238 0" quat="0.707107 0 0 0.707107" material="shank" mesh="shank_r"/>
            <geom name="RF_kfe_act" class="collision" size="0.05906 0.0196867" pos="0.0196727 0 0" quat="0.5 0.5 0.5 0.5"/>
            <geom name="//unnamed_geom_70" class="collision" size="0.0565981 0.0332212 0.0187023" pos="0.0196727 0.0570073 0" quat="0.5 0.5 0.5 0.5" type="box"/>
            <geom name="//unnamed_geom_71" class="visual" pos="0.0128365 0.0872851 -0.330505" quat="0.382683 0 0 0.92388" material="foot" mesh="foot"/>
            <geom name="RF_calf" class="collision" size="0.0172258 0.139039" pos="0.0128365 0.087198 -0.165252" quat="0.707107 0 0 0.707107"/>
            <geom name="RF_foot" class="foot" size="0.0281872" pos="0.0128365 0.087198 -0.308502" quat="0.707107 0 0 0.707107"/>
            <geom name="//unnamed_geom_74" class="reward_collision_sphere" size="0.0984333" pos="-0.0491819 0 0"/>
            <geom name="//unnamed_geom_75" class="reward_collision_sphere" size="0.0492166" pos="0.0128365 0.087198 -0.308502"/>
            <site name="RF_foot" class="foot" pos="0.0128365 0.087198 -0.308502" quat="0.707107 0 0 0.707107" size="0.00984333"/>
          </body>
        </body>
      </body>
      <body name="LH_HIP" pos="-0.294951 0.10296 -8.99597e-05" quat="0.000152099 -4.72195e-05 0.965946 -0.258745">
        <inertial pos="0.0552096 0.0151647 -0.00848043" quat="0.136796 0.676052 0.12676 0.712862" mass="2.63607" diaginertia="0.00541525 0.00476304 0.00294809"/>
        <joint name="LH_HAA" pos="0 0 0" axis="1 -1.14502e-05 -0.000196832" range="-0.497928 0.69902" armature="0.00976531" damping="0.0125408" frictionloss="0.0997277"/>
        <geom name="//unnamed_geom_76" class="visual" pos="0 -1.37376e-05 -2.2564e-06" quat="-0.258819 -0.965926 0 0" material="hip_r" mesh="hip_r"/>
        <geom name="//unnamed_geom_77" class="visual" pos="0.0589199 0.071492 -0.0411758" quat="0.183013 0.683013 0.683013 -0.183013" material="drive" mesh="drive"/>
        <geom name="//unnamed_geom_78" class="collision" size="0.0492166 0.0689033" pos="0.0589199 0.0118575 -0.00675248" quat="-0.353553 0.612372 0.612372 0.353553"/>
        <body name="LH_THIGH" pos="0.0590982 0.0714107 -0.0410442" quat="0.183146 0.682955 0.683069 -0.182886">
          <inertial pos="0.0304024 -0.000491552 -0.2405" quat="0.992895 -0.00483874 -0.0798208 0.0881129" mass="2.9295" diaginertia="0.0278579 0.0289807 0.00375037"/>
          <joint name="LH_HFE" pos="0 0 0" axis="1 -0.000817107 -7.10454e-05" range="-3.14244 3.13902" armature="0.0102445" damping="0.0124047" frictionloss="0.0975867"/>
          <geom name="//unnamed_geom_79" class="visual" pos="-0.000155428 -2.44919e-07 0" quat="0.707107 0 0 -0.707107" material="thigh" mesh="thigh"/>
          <geom name="//unnamed_geom_80" class="collision" size="0.0639816 0.0393733" pos="0.0393455 0 0" quat="0.5 0.5 -0.5 -0.5"/>
          <geom name="//unnamed_geom_81" class="collision" size="0.0369125 0.02953 0.1391" pos="0.0295091 0 -0.138193" quat="0.707107 0 0 -0.707107" type="box"/>
          <geom name="//unnamed_geom_82" class="visual" pos="0.0986588 0 -0.278705" quat="1 0 0 0" material="drive" mesh="drive"/>
          <geom name="//unnamed_geom_83" class="collision" size="0.0492166 0.0689033" pos="0.0298042 0 -0.278705" quat="0.707107 0 0.707107 0"/>
          <geom name="//unnamed_geom_84" class="reward_collision_sphere" size="0.0787466" pos="0.0245909 0 0"/>
          <body name="LH_SHANK" pos="0.0999571 -0.000883053 -0.278782" quat="1 -0.000132659 -3.7859e-05 4.23354e-05">
            <inertial pos="0.00540862 0.0607414 -0.0789734" quat="0.992615 0.11731 0.000412369 0.030881" mass="0.561663" diaginertia="0.00932546 0.00886869 0.000989986"/>
            <joint name="LH_KFE" pos="0 0 0" axis="0.999999 -0.000993471 0.000411542" range="-3.14957 3.14257" armature="0.0101155" damping="0.00850461" frictionloss="0.0941439"/>
            <geom name="//unnamed_geom_85" class="visual" pos="-5.06815e-05 0.000270238 0" quat="-0.707107 0 0 -0.707107" material="shank" mesh="shank_r"/>
            <geom name="LH_kfe_act" class="collision" size="0.05906 0.0196867" pos="0.0196727 0 0" quat="0.5 0.5 -0.5 -0.5"/>
            <geom name="//unnamed_geom_87" class="collision" size="0.0565981 0.0332212 0.0187023" pos="0.0196727 0.0570073 0" quat="0.5 0.5 -0.5 -0.5" type="box"/>
            <geom name="//unnamed_geom_88" class="visual" pos="0.0128365 0.0872851 -0.330505" quat="-0.382683 0 0 -0.92388" material="foot" mesh="foot"/>
            <geom name="LH_calf" class="collision" size="0.0172258 0.139039" pos="0.0128365 0.087198 -0.165252" quat="0.707107 0 0 -0.707107"/>
            <geom name="LH_foot" class="foot" size="0.0311383" pos="0.0128365 0.087198 -0.308502" quat="0.707107 0 0 -0.707107"/>
            <geom name="//unnamed_geom_91" class="reward_collision_sphere" size="0.0984333" pos="-0.0491819 0 0"/>
            <geom name="//unnamed_geom_92" class="reward_collision_sphere" size="0.0492166" pos="0.0128365 0.087198 -0.308502"/>
            <site name="LH_foot" class="foot" pos="0.0128365 0.087198 -0.308502" quat="0.707107 0 0 -0.707107" size="0.00984333"/>
          </body>
        </body>
      </body>
      <body name="RH_HIP" pos="-0.294968 -0.103458 0.000421647" quat="-5.40546e-06 -2.05349e-06 -0.965926 -0.258819">
        <inertial pos="0.0554119 -0.0154631 -0.00842241" quat="-0.127785 0.70887 -0.135161 0.680372" mass="2.68141" diaginertia="0.00545252 0.00475709 0.00294876"/>
        <joint name="RH_HAA" pos="0 0 0" axis="0.999999 0.00111036 -0.000108401" stiffness="0.00201006" range="-0.719648 0.508481" armature="0.00984686" damping="0.013618" frictionloss="0.0978435"/>
        <geom name="//unnamed_geom_93" class="visual" pos="0 1.37377e-05 -2.2564e-06" quat="-0.258819 0.965926 0 0" material="hip_l" mesh="hip_l"/>
        <geom name="//unnamed_geom_94" class="visual" pos="0.0589199 -0.071492 -0.0411758" quat="-0.183013 0.683013 -0.683013 -0.183013" material="drive" mesh="drive"/>
        <geom name="//unnamed_geom_95" class="collision" size="0.0492166 0.0689033" pos="0.0589199 -0.0118575 -0.00675248" quat="0.353553 0.612372 -0.612372 0.353553"/>
        <body name="RH_THIGH" pos="0.058537 -0.0711847 -0.0405333" quat="-0.182995 0.682928 -0.683057 -0.183182">
          <inertial pos="0.0297326 -0.000453677 -0.239623" quat="0.993195 -0.00492269 -0.0803979 0.0841188" mass="2.86414" diaginertia="0.0275382 0.0281899 0.00371471"/>
          <joint name="RH_HFE" pos="0 0 0" axis="1 3.78046e-05 9.43206e-06" stiffness="0.000391233" range="-3.14611 3.14107" armature="0.0100694" damping="0.0093278" frictionloss="0.0982561"/>
          <geom name="//unnamed_geom_96" class="visual" pos="-0.000155428 -2.44919e-07 0" quat="0.707107 0 0 -0.707107" material="thigh" mesh="thigh"/>
          <geom name="//unnamed_geom_97" class="collision" size="0.0639816 0.0393733" pos="0.0393455 0 0" quat="0.5 0.5 0.5 0.5"/>
          <geom name="//unnamed_geom_98" class="collision" size="0.0369125 0.02953 0.1391" pos="0.0295091 0 -0.138193" quat="0.707107 0 0 0.707107" type="box"/>
          <geom name="//unnamed_geom_99" class="visual" pos="0.0986588 0 -0.278705" quat="1 0 0 0" material="drive" mesh="drive"/>
          <geom name="//unnamed_geom_100" class="collision" size="0.0492166 0.0689033" pos="0.0298042 0 -0.278705" quat="0.707107 0 0.707107 0"/>
          <geom name="//unnamed_geom_101" class="reward_collision_sphere" size="0.0787466" pos="0.0245909 0 0"/>
          <body name="RH_SHANK" pos="0.0979863 -0.000453713 -0.278962" quat="1 -7.18837e-05 -0.000377311 0.000173285">
            <inertial pos="0.00579266 -0.0606439 -0.0792295" quat="0.993025 -0.115146 -0.00187895 -0.0252907" mass="0.560339" diaginertia="0.00943674 0.00878985 0.000995204"/>
            <joint name="RH_KFE" pos="0 0 0" axis="0.999962 0.000595844 0.00871972" range="-3.13335 3.13524" armature="0.00951548" damping="0.00816449" frictionloss="0.0981638"/>
            <geom name="//unnamed_geom_102" class="visual" pos="-5.06818e-05 -0.000270238 0" quat="0.707107 0 0 -0.707107" material="shank_l" mesh="shank_l"/>
            <geom name="RH_kfe_act" class="collision" size="0.05906 0.0196867" pos="0.0196727 0 0" quat="0.5 0.5 0.5 0.5"/>
            <geom name="//unnamed_geom_104" class="collision" size="0.0565981 0.0332212 0.0187023" pos="0.0196727 -0.0570073 0" quat="0.5 0.5 0.5 0.5" type="box"/>
            <geom name="//unnamed_geom_105" class="visual" pos="0.0128365 -0.0872851 -0.330505" quat="0.382683 0 0 -0.92388" material="foot" mesh="foot"/>
            <geom name="RH_calf" class="collision" size="0.0172258 0.139039" pos="0.0128365 -0.087198 -0.165252" quat="0.707107 0 0 0.707107"/>
            <geom name="RH_foot" class="foot" size="0.0276466" pos="0.0128365 -0.087198 -0.308502" quat="0.707107 0 0 0.707107"/>
            <geom name="//unnamed_geom_108" class="reward_collision_sphere" size="0.0984333" pos="-0.0491819 0 0"/>
            <geom name="//unnamed_geom_109" class="reward_collision_sphere" size="0.0492166" pos="0.0128365 -0.087198 -0.308502"/>
            <site name="RH_foot" class="foot" pos="0.0128365 -0.087198 -0.308502" quat="0.707107 0 0 0.707107" size="0.00984333"/>
          </body>
        </body>
      </body>
    </body>
  </worldbody>

  <contact>
    <pair class="/" geom1="floor" geom2="LF_foot" name="//unnamed_contact_0"/>
    <pair class="/" geom1="floor" geom2="RF_foot" name="//unnamed_contact_1"/>
    <pair class="/" geom1="floor" geom2="LH_foot" name="//unnamed_contact_2"/>
    <pair class="/" geom1="floor" geom2="RH_foot" name="//unnamed_contact_3"/>
  </contact>

  <actuator>
    <general name="LF_HAA" class="/" joint="LF_HAA" forcerange="-78.2665 78.2665" gainprm="82.158" biasprm="0 -82.158 -1.96254"/>
    <general name="LF_HFE" class="/" joint="LF_HFE" forcerange="-81.4364 81.4364" gainprm="82.158" biasprm="0 -82.158 -1.96254"/>
    <general name="LF_KFE" class="/" joint="LF_KFE" forcerange="-77.9449 77.9449" gainprm="82.158" biasprm="0 -82.158 -1.96254"/>
    <general name="RF_HAA" class="/" joint="RF_HAA" forcerange="-81.9665 81.9665" gainprm="82.158" biasprm="0 -82.158 -1.96254"/>
    <general name="RF_HFE" class="/" joint="RF_HFE" forcerange="-77.1288 77.1288" gainprm="82.158" biasprm="0 -82.158 -1.96254"/>
    <general name="RF_KFE" class="/" joint="RF_KFE" forcerange="-79.5183 79.5183" gainprm="82.158" biasprm="0 -82.158 -1.96254"/>
    <general name="LH_HAA" class="/" joint="LH_HAA" forcerange="-79.1192 79.1192" gainprm="82.158" biasprm="0 -82.158 -1.96254"/>
    <general name="LH_HFE" class="/" joint="LH_HFE" forcerange="-79.841 79.841" gainprm="82.158" biasprm="0 -82.158 -1.96254"/>
    <general name="LH_KFE" class="/" joint="LH_KFE" forcerange="-78.8192 78.8192" gainprm="82.158" biasprm="0 -82.158 -1.96254"/>
    <general name="RH_HAA" class="/" joint="RH_HAA" forcerange="-78.6308 78.6308" gainprm="82.158" biasprm="0 -82.158 -1.96254"/>
    <general name="RH_HFE" class="/" joint="RH_HFE" forcerange="-77.4476 77.4476" gainprm="82.158" biasprm="0 -82.158 -1.96254"/>
    <general name="RH_KFE" class="/" joint="RH_KFE" forcerange="-77.9638 77.9638" gainprm="82.158" biasprm="0 -82.158 -1.96254"/>
  </actuator>

  <sensor>
    <gyro site="imu" name="imu_angular_velocity"/>
    <velocimeter site="imu" name="imu_linear_velocity"/>
    <framelinvel objtype="site" objname="LF_foot" name="LF_foot_global_linear_velocity"/>
    <framelinvel objtype="site" objname="RF_foot" name="RF_foot_global_linear_velocity"/>
    <framelinvel objtype="site" objname="LH_foot" name="LH_foot_global_linear_velocity"/>
    <framelinvel objtype="site" objname="RH_foot" name="RH_foot_global_linear_velocity"/>
  </sensor>

  <keyframe>
    <key name="home" qpos="0 0 0.55 1 0 0 0 0 0.4 -0.8 0 -0.4 0.8 0 -0.4 0.8 0 0.4 -0.8"/>
  </keyframe>
</mujoco>
