<mujoco model="anymal_c">
  <compiler angle="radian" assetdir="assets" balanceinertia="true" inertiafromgeom="false"/>

  <option timestep="0.005" density="1.2" viscosity="2e-05"/>

  <size nkey="1"/>

  <visual>
    <quality shadowsize="8192"/>
    <map shadowclip="0.5"/>
  </visual>

  <default>
    <default class="/">
      <material specular="0" shininess="0.25"/>
      <geom contype="0" conaffinity="0" group="1" solref="-1000 -80"/>
      <site size="0.01 0.005 0.005" group="5"/>
      <general forcelimited="true" forcerange="-80 80" biastype="affine" gainprm="80" biasprm="0 -80 -2"/>
      <default class="anymal_c">
        <joint armature="0.01" damping="0.01" frictionloss="0.1"/>
        <default class="visual">
          <geom type="mesh" group="2"/>
          <default class="visual_zflip"/>
        </default>
        <default class="collision">
          <geom type="cylinder" group="3"/>
          <default class="foot">
            <geom size="0.03 0 0" type="sphere" condim="6" priority="1" friction="0.8 0.02 0.01" solimp="0.015 1 0.03"/>
          </default>
        </default>
      </default>
      <default class="reward_collision_sphere">
        <geom group="5" rgba="1 0 0 1"/>
      </default>
    </default>
  </default>

  <asset>
    <texture type="skybox" colorspace="auto" name="//unnamed_texture_0" builtin="gradient" rgb1="0.95 0.95 0.95" rgb2="0.95 0.95 0.95" width="100" height="600"/>
    <texture type="2d" colorspace="auto" name="texplane" builtin="checker" rgb1="0.345 0.575 0.748" rgb2="0.345 0.575 0.748" markrgb="1 1 1" width="512" height="512"/>
    <texture type="2d" colorspace="linear" name="base" file="base.png"/>
    <texture type="2d" colorspace="linear" name="top_shell" file="top_shell.png"/>
    <texture type="2d" colorspace="linear" name="bottom_shell" file="bottom_shell.png"/>
    <texture type="2d" colorspace="linear" name="remote" file="remote.png"/>
    <texture type="2d" colorspace="linear" name="hatch" file="hatch.png"/>
    <texture type="2d" colorspace="linear" name="handle" file="handle.png"/>
    <texture type="2d" colorspace="linear" name="face" file="face.png"/>
    <texture type="2d" colorspace="linear" name="battery" file="battery.png"/>
    <texture type="2d" colorspace="linear" name="lidar_cage" file="lidar_cage.png"/>
    <texture type="2d" colorspace="linear" name="depth_camera" file="depth_camera.png"/>
    <texture type="2d" colorspace="linear" name="wide_angle_camera" file="wide_angle_camera.png"/>
    <texture type="2d" colorspace="linear" name="lidar" file="lidar.png"/>
    <texture type="2d" colorspace="linear" name="drive" file="drive.png"/>
    <texture type="2d" colorspace="linear" name="hip_l" file="hip_l.png"/>
    <texture type="2d" colorspace="linear" name="shank_l" file="shank_l.png"/>
    <texture type="2d" colorspace="linear" name="foot" file="foot.png"/>
    <texture type="2d" colorspace="linear" name="thigh" file="thigh.png"/>
    <texture type="2d" colorspace="linear" name="shank_r" file="shank_r.png"/>
    <texture type="2d" colorspace="linear" name="hip_r" file="hip_r.png"/>
    <material name="MatPlane" class="/" texture="texplane" texuniform="true" texrepeat="2 2" specular="0.9" shininess="0.5"/>
    <material name="black_plastic" class="/" rgba="0.007 0.007 0.007 1"/>
    <material name="green" class="/" rgba="0.052 0.178 0.033 1"/>
    <material name="red" class="/" rgba="0.178 0.006 0.005 1"/>
    <material name="yellow" class="/" rgba="0.178 0.119 0.006 1"/>
    <material name="lwl" class="/" rgba="0.8 0.8 0.8 1"/>
    <material name="base" class="/" texture="base"/>
    <material name="top_shell" class="/" texture="top_shell"/>
    <material name="bottom_shell" class="/" texture="bottom_shell"/>
    <material name="hip_l" class="/" texture="hip_l"/>
    <material name="thigh" class="/" texture="thigh"/>
    <material name="shank_l" class="/" texture="shank_l"/>
    <material name="foot" class="/" texture="foot"/>
    <material name="hip_r" class="/" texture="hip_r"/>
    <material name="shank" class="/" texture="shank_r"/>
    <material name="hatch" class="/" texture="hatch"/>
    <material name="remote" class="/" texture="remote"/>
    <material name="handle" class="/" texture="handle"/>
    <material name="face" class="/" texture="face"/>
    <material name="depth_camera" class="/" texture="depth_camera"/>
    <material name="wide_angle_camera" class="/" texture="wide_angle_camera"/>
    <material name="battery" class="/" texture="battery"/>
    <material name="lidar_cage" class="/" texture="lidar_cage"/>
    <material name="lidar" class="/" texture="lidar"/>
    <material name="drive" class="/" texture="drive"/>
    <mesh name="base_0" class="/" file="base_0.obj"/>
    <mesh name="base_1" class="/" file="base_1.obj"/>
    <mesh name="base_2" class="/" file="base_2.obj"/>
    <mesh name="base_3" class="/" file="base_3.obj"/>
    <mesh name="base_4" class="/" file="base_4.obj"/>
    <mesh name="base_5" class="/" file="base_5.obj"/>
    <mesh name="top_shell" class="/" file="top_shell.obj"/>
    <mesh name="bottom_shell" class="/" file="bottom_shell.obj"/>
    <mesh name="remote" class="/" file="remote.obj"/>
    <mesh name="handle" class="/" file="handle.obj"/>
    <mesh name="face" class="/" file="face.obj"/>
    <mesh name="wide_angle_camera" class="/" file="wide_angle_camera.obj"/>
    <mesh name="depth_camera" class="/" file="depth_camera.obj"/>
    <mesh name="battery" class="/" file="battery.obj"/>
    <mesh name="lidar_cage" class="/" file="lidar_cage.obj"/>
    <mesh name="lidar" class="/" file="lidar.obj"/>
    <mesh name="drive" class="/" file="drive.obj"/>
    <mesh name="hip_l" class="/" file="hip_l.obj"/>
    <mesh name="thigh" class="/" file="thigh.obj"/>
    <mesh name="shank_l" class="/" file="shank_l.obj"/>
    <mesh name="foot" class="/" file="foot.obj"/>
    <mesh name="hip_r" class="/" file="hip_r.obj"/>
    <mesh name="hatch" class="/" file="hatch.obj"/>
    <mesh name="shank_r" class="/" file="shank_r.obj"/>
  </asset>

  <worldbody>
    <geom name="floor" class="/" size="100 100 0.125" type="plane" group="0" material="MatPlane"/>
    <light name="toplight_shadow" class="/" pos="0 0 5" dir="0.0990148 0.0990148 -0.990148" type="directional" ambient="0.04 0.04 0.04" diffuse="0.55 0.55 0.55" specular="0.12 0.12 0.12"/>
    <light name="toplight_fill" class="/" pos="0 0 5" dir="0.0990148 0.0990148 -0.990148" type="directional" castshadow="false" ambient="0.04 0.04 0.04" diffuse="0.3 0.3 0.3" specular="0.08 0.08 0.08"/>
    <body name="trunk" childclass="anymal_c" pos="-0.00205676 0.000444808 -0.00277687" quat="0.999999 0.00117134 -0.000350755 -7.54204e-05">
      <inertial pos="-0.000779218 0.00249731 0.0486047" quat="0.496667 0.49734 0.501645 0.504309" mass="14.6232" diaginertia="0.349202 0.289692 0.196897"/>
      <joint name="//unnamed_joint_0" type="free" armature="0" damping="0" frictionloss="0"/>
      <geom name="//unnamed_geom_1" class="visual" material="green" mesh="base_0"/>
      <geom name="//unnamed_geom_2" class="visual" material="yellow" mesh="base_1"/>
      <geom name="//unnamed_geom_3" class="visual" material="red" mesh="base_2"/>
      <geom name="//unnamed_geom_4" class="visual" material="black_plastic" mesh="base_3"/>
      <geom name="//unnamed_geom_5" class="visual" material="lwl" mesh="base_4"/>
      <geom name="//unnamed_geom_6" class="visual" material="base" mesh="base_5"/>
      <geom name="trunk_1" class="collision" size="0.263332 0.0635629 0.0817237" type="box"/>
      <geom name="trunk_2" class="collision" size="0.0817237 0.065833" pos="0.192298 0.0601831 0" quat="0.707107 0 0.707107 0"/>
      <geom name="trunk_3" class="collision" size="0.0817237 0.065833" pos="-0.192298 0.0601831 0" quat="0.707107 0 0.707107 0"/>
      <geom name="trunk_4" class="collision" size="0.0817237 0.065833" pos="0.192298 -0.0601831 0" quat="0.707107 0 0.707107 0"/>
      <geom name="trunk_5" class="collision" size="0.0817237 0.065833" pos="-0.192298 -0.0601831 0" quat="0.707107 0 0.707107 0"/>
      <geom name="//unnamed_geom_12" class="visual" material="top_shell" mesh="top_shell"/>
      <geom name="//unnamed_geom_13" class="visual" material="bottom_shell" mesh="bottom_shell"/>
      <geom name="//unnamed_geom_14" class="visual" material="remote" mesh="remote"/>
      <geom name="//unnamed_geom_15" class="visual" material="handle" mesh="handle"/>
      <geom name="//unnamed_geom_16" class="visual" pos="0.366472 0 0" quat="1 0 0 0" material="face" mesh="face"/>
      <geom name="trunk_6" class="collision" size="0.0499423 0.0635629 0.0817237" pos="0.415099 0 0" type="box"/>
      <geom name="//unnamed_geom_18" class="collision" size="0.0817237 0.0499423" pos="0.415099 0.0601831 0" quat="0.707107 0 0.707107 0"/>
      <geom name="//unnamed_geom_19" class="collision" size="0.0817237 0.0499423" pos="0.415099 -0.0601831 0" quat="0.707107 0 0.707107 0"/>
      <geom name="//unnamed_geom_20" class="visual" pos="0.408163 0 -0.0293533" quat="0.965926 0 0.258819 0" material="depth_camera" mesh="depth_camera"/>
      <geom name="//unnamed_geom_21" class="visual" pos="0.453559 0 0.0146741" material="wide_angle_camera" mesh="wide_angle_camera"/>
      <geom name="//unnamed_geom_22" class="visual_zflip" pos="-0.366472 0 0" quat="0 0 0 1" material="face" mesh="face"/>
      <geom name="trunk_7" class="collision" size="0.0499423 0.0635629 0.0817237" pos="-0.415099 0 0" quat="0 0 0 1" type="box"/>
      <geom name="//unnamed_geom_24" class="collision" size="0.0817237 0.0499423" pos="-0.415099 -0.0601831 0" quat="0 -0.707107 0 0.707107"/>
      <geom name="//unnamed_geom_25" class="collision" size="0.0817237 0.0499423" pos="-0.415099 0.0601831 0" quat="0 -0.707107 0 0.707107"/>
      <geom name="//unnamed_geom_26" class="visual" pos="-0.408163 0 -0.0293533" quat="0 -0.258819 0 0.965926" material="depth_camera" mesh="depth_camera"/>
      <geom name="//unnamed_geom_27" class="visual_zflip" pos="-0.453559 0 0.0146741" quat="0 0 0 1" material="wide_angle_camera" mesh="wide_angle_camera"/>
      <geom name="//unnamed_geom_28" class="visual" material="battery" mesh="battery"/>
      <geom name="//unnamed_geom_29" class="visual" pos="0 0.0654213 0.0277454" quat="0.683013 -0.183013 0.183013 0.683013" material="depth_camera" mesh="depth_camera"/>
      <geom name="//unnamed_geom_30" class="visual" pos="0 -0.0654213 0.0277454" quat="0.683013 0.183013 0.183013 -0.683013" material="depth_camera" mesh="depth_camera"/>
      <geom name="//unnamed_geom_31" class="visual" pos="-0.321823 0 0.0720473" quat="1 0 0 0" material="lidar_cage" mesh="lidar_cage"/>
      <geom name="trunk_8" class="collision" size="0.0635629 0.0544825" pos="-0.321823 0 0.130861"/>
      <geom name="//unnamed_geom_33" class="visual" pos="-0.321823 -9.57505e-06 0.139389" quat="0.707107 0 0 -0.707107" material="lidar" mesh="lidar"/>
      <geom name="//unnamed_geom_34" class="visual" pos="0.265151 0.0894576 -2.07824e-09" quat="0.258819 0.965926 0 0" material="drive" mesh="drive"/>
      <geom name="//unnamed_geom_35" class="visual" pos="0.265151 -0.0894576 2.07824e-09" quat="0.258819 -0.965926 0 0" material="drive" mesh="drive"/>
      <geom name="//unnamed_geom_36" class="visual" pos="-0.265151 0.0894576 2.07824e-09" quat="0 0 0.965926 -0.258819" material="drive" mesh="drive"/>
      <geom name="//unnamed_geom_37" class="visual" pos="-0.265151 -0.0894576 -2.07824e-09" quat="0 0 -0.965926 -0.258819" material="drive" mesh="drive"/>
      <geom name="//unnamed_geom_38" class="visual" pos="0.102559 0 0.0715572" quat="1 0 0 0" material="hatch" mesh="hatch"/>
      <geom name="//unnamed_geom_39" class="reward_collision_sphere" size="0.108965"/>
      <geom name="//unnamed_geom_40" class="reward_collision_sphere" size="0.108965" pos="0.397858 0 0"/>
      <geom name="//unnamed_geom_41" class="reward_collision_sphere" size="0.108965" pos="-0.397858 0 0"/>
      <site name="imu" pos="0.233453 0.0136879 0.0324285" size="0.00908041"/>
      <camera name="track" pos="0 -1.71952 0" quat="0.707107 0.707107 0 0" mode="trackcom"/>
      <camera name="ego_camera" pos="0.397858 0 -0.0392094" quat="-0.5 -0.5 0.5 0.5"/>
      <body name="LF_HIP" pos="0.264885 0.088826 -0.00109806" quat="0.258548 0.965998 -0.000130206 -0.000233726">
        <inertial pos="0.0474239 -0.0135533 -0.00990617" quat="-0.132803 0.71168 -0.127101 0.678026" mass="2.0815" diaginertia="0.0031566 0.00231804 0.00308129"/>
        <joint name="LF_HAA" pos="0 0 0" axis="0.999883 -0.00928562 0.0121314" range="-0.715299 0.484147" armature="0.00994127" damping="0.00649364" frictionloss="0.0879745"/>
        <geom name="//unnamed_geom_42" class="visual" pos="0 -0.000122254 2.00801e-05" quat="0.258819 -0.965926 0 0" material="hip_l" mesh="hip_l"/>
        <geom name="//unnamed_geom_43" class="visual" pos="0.0529594 -0.0638935 -0.03778" quat="0.183013 -0.683013 0.683013 0.183013" material="drive" mesh="drive"/>
        <geom name="//unnamed_geom_44" class="collision" size="0.0454021 0.0635629" pos="0.0529594 -0.0102825 -0.00676852" quat="-0.353553 -0.612372 0.612372 -0.353553"/>
        <body name="LF_THIGH" pos="0.0533551 -0.0631558 -0.0451823" quat="0.182675 -0.683125 0.682968 0.183099">
          <inertial pos="0.0283999 -5.957e-05 -0.239476" quat="0.993705 0.0013333 -0.0720637 0.0857685" mass="2.24473" diaginertia="0.0163292 0.0134095 0.00379757"/>
          <joint name="LF_HFE" pos="0 0 0" axis="0.999983 -0.000267533 0.00588501" stiffness="0.0136215" range="-3.13725 3.12322" armature="0.00789153" damping="0.00982448" frictionloss="0.0904401"/>
          <geom name="//unnamed_geom_45" class="visual" pos="0.000484904 7.64096e-07 0" quat="0.707107 0 0 -0.707107" material="thigh" mesh="thigh"/>
          <geom name="//unnamed_geom_46" class="collision" size="0.0590227 0.0363216" pos="0.0353652 0 0" quat="0.5 0.5 -0.5 -0.5"/>
          <geom name="//unnamed_geom_47" class="collision" size="0.0340515 0.0272412 0.128319" pos="0.0265239 0 -0.138521" quat="0.707107 0 0 -0.707107" type="box"/>
          <geom name="//unnamed_geom_48" class="visual" pos="0.0886782 0 -0.279367" quat="1 0 0 0" material="drive" mesh="drive"/>
          <geom name="//unnamed_geom_49" class="collision" size="0.0454021 0.0635629" pos="0.0267891 0 -0.279367" quat="0.707107 0 0.707107 0"/>
          <geom name="//unnamed_geom_50" class="reward_collision_sphere" size="0.0726433" pos="0.0221032 0 0"/>
          <body name="LF_SHANK" pos="0.0871621 -0.000707233 -0.277292" quat="1 0.000102569 5.44109e-05 5.63232e-05">
            <inertial pos="0.00270838 -0.0552782 -0.0768838" quat="0.992886 -0.116514 -0.00317366 -0.0243187" mass="0.437141" diaginertia="0.00558363 0.00420869 0.00100883"/>
            <joint name="LF_KFE" pos="0 0 0" axis="0.999999 0.00148344 -0.000417315" stiffness="0.00172035" range="-3.09429 3.12568" armature="0.00902015" damping="0.008815" frictionloss="0.0901446"/>
            <geom name="//unnamed_geom_51" class="visual" pos="0.000158117 0.000843086 0" quat="0.707107 0 0 -0.707107" material="shank_l" mesh="shank_l"/>
            <geom name="LF_kfe_act" class="collision" size="0.0544825 0.0181608" pos="0.0176826 0 0" quat="0.5 0.5 -0.5 -0.5"/>
            <geom name="//unnamed_geom_53" class="collision" size="0.0522115 0.0306464 0.0172528" pos="0.0176826 -0.0494352 0" quat="0.5 0.5 -0.5 -0.5" type="box"/>
            <geom name="//unnamed_geom_54" class="visual" pos="0.0115379 -0.075344 -0.33129" quat="0.382683 0 0 -0.92388" material="foot" mesh="foot"/>
            <geom name="LF_calf" class="collision" size="0.0158907 0.128263" pos="0.0115379 -0.0756157 -0.165645" quat="0.707107 0 0 -0.707107"/>
            <geom name="LF_foot" class="foot" size="0.0279581" pos="0.0115379 -0.0756157 -0.309235" quat="0.707107 0 0 -0.707107"/>
            <geom name="//unnamed_geom_57" class="reward_collision_sphere" size="0.0908041" pos="-0.0442065 0 0"/>
            <geom name="//unnamed_geom_58" class="reward_collision_sphere" size="0.0454021" pos="0.0115379 -0.0756157 -0.309235"/>
            <site name="LF_foot" class="foot" pos="0.0115379 -0.0756157 -0.309235" quat="0.707107 0 0 -0.707107" size="0.00908041"/>
          </body>
        </body>
      </body>
      <body name="RF_HIP" pos="0.268477 -0.0868402 0.000226659" quat="0.258765 -0.96594 0.000117733 -0.000363434">
        <inertial pos="0.0483256 0.0112595 -0.00898745" quat="0.134777 0.679242 0.12796 0.709994" mass="2.06395" diaginertia="0.00304717 0.0023836 0.00300815"/>
        <joint name="RF_HAA" pos="0 0 0" axis="0.999999 -0.00164975 -0.000416268" range="-0.453773 0.706254" armature="0.00893287" damping="0.0107955" frictionloss="0.102042"/>
        <geom name="//unnamed_geom_59" class="visual" pos="0 0.000122253 2.008e-05" quat="0.258819 0.965926 0 0" material="hip_r" mesh="hip_r"/>
        <geom name="//unnamed_geom_60" class="visual" pos="0.0529594 0.0638935 -0.03778" quat="0.183013 0.683013 0.683013 -0.183013" material="drive" mesh="drive"/>
        <geom name="//unnamed_geom_61" class="collision" size="0.0454021 0.0635629" pos="0.0529594 0.0102825 -0.00676852" quat="-0.353553 0.612372 0.612372 0.353553"/>
        <body name="RF_THIGH" pos="0.0560358 0.0627805 -0.0430985" quat="0.182795 0.683432 0.682559 -0.183358">
          <inertial pos="0.0268312 0.000159039 -0.240377" quat="0.991929 -0.00489911 -0.0827937 0.0959021" mass="2.36147" diaginertia="0.0157535 0.0140226 0.00378009"/>
          <joint name="RF_HFE" pos="0 0 0" axis="0.999961 -0.000914686 -0.00879171" stiffness="0.00683469" range="-3.13913 3.16867" armature="0.00848459" damping="0.0095047" frictionloss="0.0978172"/>
          <geom name="//unnamed_geom_62" class="visual" pos="0.000484904 7.64096e-07 0" quat="0.707107 0 0 -0.707107" material="thigh" mesh="thigh"/>
          <geom name="//unnamed_geom_63" class="collision" size="0.0590227 0.0363216" pos="0.0353652 0 0" quat="0.5 0.5 0.5 0.5"/>
          <geom name="//unnamed_geom_64" class="collision" size="0.0340515 0.0272412 0.128319" pos="0.0265239 0 -0.138521" quat="0.707107 0 0 0.707107" type="box"/>
          <geom name="//unnamed_geom_65" class="visual" pos="0.0886782 0 -0.279367" quat="1 0 0 0" material="drive" mesh="drive"/>
          <geom name="//unnamed_geom_66" class="collision" size="0.0454021 0.0635629" pos="0.0267891 0 -0.279367" quat="0.707107 0 0.707107 0"/>
          <geom name="//unnamed_geom_67" class="reward_collision_sphere" size="0.0726433" pos="0.0221032 0 0"/>
          <body name="RF_SHANK" pos="0.088811 -0.00041657 -0.277853" quat="1 9.10658e-05 3.48841e-05 0.000246385">
            <inertial pos="0.00651314 0.0516199 -0.0805821" quat="0.991495 0.1253 -0.000338104 0.0351646" mass="0.439949" diaginertia="0.00579074 0.00436162 0.00102825"/>
            <joint name="RF_KFE" pos="0 0 0" axis="0.999993 0.00257819 0.00258051" stiffness="0.00100846" range="-3.15508 3.08225" armature="0.00992498" damping="0.00812608" frictionloss="0.0899835"/>
            <geom name="//unnamed_geom_68" class="visual" pos="0.000158116 -0.000843085 0" quat="0.707107 0 0 0.707107" material="shank" mesh="shank_r"/>
            <geom name="RF_kfe_act" class="collision" size="0.0544825 0.0181608" pos="0.0176826 0 0" quat="0.5 0.5 0.5 0.5"/>
            <geom name="//unnamed_geom_70" class="collision" size="0.0522115 0.0306464 0.0172528" pos="0.0176826 0.0494352 0" quat="0.5 0.5 0.5 0.5" type="box"/>
            <geom name="//unnamed_geom_71" class="visual" pos="0.0115379 0.075344 -0.33129" quat="0.382683 0 0 0.92388" material="foot" mesh="foot"/>
            <geom name="RF_calf" class="collision" size="0.0158907 0.128263" pos="0.0115379 0.0756157 -0.165645" quat="0.707107 0 0 0.707107"/>
            <geom name="RF_foot" class="foot" size="0.0294925" pos="0.0115379 0.0756157 -0.309235" quat="0.707107 0 0 0.707107"/>
            <geom name="//unnamed_geom_74" class="reward_collision_sphere" size="0.0908041" pos="-0.0442065 0 0"/>
            <geom name="//unnamed_geom_75" class="reward_collision_sphere" size="0.0454021" pos="0.0115379 0.0756157 -0.309235"/>
            <site name="RF_foot" class="foot" pos="0.0115379 0.0756157 -0.309235" quat="0.707107 0 0 0.707107" size="0.00908041"/>
          </body>
        </body>
      </body>
      <body name="LH_HIP" pos="-0.264875 0.0873588 0.000363" quat="-0.000346873 -0.000412109 0.965946 -0.258745">
        <inertial pos="0.0497305 0.0133868 -0.00850229" quat="0.136502 0.67855 0.128402 0.710247" mass="2.08697" diaginertia="0.00319496 0.0022425 0.00295269"/>
        <joint name="LH_HAA" pos="0 0 0" axis="0.999998 0.00157676 0.00136478" range="-0.510648 0.729107" armature="0.00911967" damping="0" frictionloss="0.0926647"/>
        <geom name="//unnamed_geom_76" class="visual" pos="0 0.000122253 2.008e-05" quat="-0.258819 -0.965926 0 0" material="hip_r" mesh="hip_r"/>
        <geom name="//unnamed_geom_77" class="visual" pos="0.0529594 0.0638935 -0.03778" quat="0.183013 0.683013 0.683013 -0.183013" material="drive" mesh="drive"/>
        <geom name="//unnamed_geom_78" class="collision" size="0.0454021 0.0635629" pos="0.0529594 0.0102825 -0.00676852" quat="-0.353553 0.612372 0.612372 0.353553"/>
        <body name="LH_THIGH" pos="0.0513075 0.061387 -0.0410438" quat="0.182924 0.683016 0.68302 -0.183064">
          <inertial pos="0.0266659 0.000419267 -0.239508" quat="0.993035 -0.00557254 -0.0799569 0.0863601" mass="2.34572" diaginertia="0.0169269 0.0143437 0.00390243"/>
          <joint name="LH_HFE" pos="0 0 0" axis="0.99999 0.000558395 0.00434695" range="-3.14925 3.11199" armature="0.0102265" damping="0.0194052" frictionloss="0.0942275"/>
          <geom name="//unnamed_geom_79" class="visual" pos="0.000484904 7.64096e-07 0" quat="0.707107 0 0 -0.707107" material="thigh" mesh="thigh"/>
          <geom name="//unnamed_geom_80" class="collision" size="0.0590227 0.0363216" pos="0.0353652 0 0" quat="0.5 0.5 -0.5 -0.5"/>
          <geom name="//unnamed_geom_81" class="collision" size="0.0340515 0.0272412 0.128319" pos="0.0265239 0 -0.138521" quat="0.707107 0 0 -0.707107" type="box"/>
          <geom name="//unnamed_geom_82" class="visual" pos="0.0886782 0 -0.279367" quat="1 0 0 0" material="drive" mesh="drive"/>
          <geom name="//unnamed_geom_83" class="collision" size="0.0454021 0.0635629" pos="0.0267891 0 -0.279367" quat="0.707107 0 0.707107 0"/>
          <geom name="//unnamed_geom_84" class="reward_collision_sphere" size="0.0726433" pos="0.0221032 0 0"/>
          <body name="LH_SHANK" pos="0.086604 0.0019593 -0.281095" quat="1 -0.000109094 -0.000180621 -0.000211996">
            <inertial pos="0.00751845 0.0499832 -0.0768188" quat="0.992912 0.116902 -0.00620438 0.0205417" mass="0.431677" diaginertia="0.00547637 0.0045005 0.000983935"/>
            <joint name="LH_KFE" pos="0 0 0" axis="0.999894 0.00407145 -0.0139468" stiffness="0.00642725" range="-3.09756 3.13986" armature="0.00918044" damping="0.0117763" frictionloss="0.102714"/>
            <geom name="//unnamed_geom_85" class="visual" pos="0.000158116 -0.000843085 0" quat="-0.707107 0 0 -0.707107" material="shank" mesh="shank_r"/>
            <geom name="LH_kfe_act" class="collision" size="0.0544825 0.0181608" pos="0.0176826 0 0" quat="0.5 0.5 -0.5 -0.5"/>
            <geom name="//unnamed_geom_87" class="collision" size="0.0522115 0.0306464 0.0172528" pos="0.0176826 0.0494352 0" quat="0.5 0.5 -0.5 -0.5" type="box"/>
            <geom name="//unnamed_geom_88" class="visual" pos="0.0115379 0.075344 -0.33129" quat="-0.382683 0 0 -0.92388" material="foot" mesh="foot"/>
            <geom name="LH_calf" class="collision" size="0.0158907 0.128263" pos="0.0115379 0.0756157 -0.165645" quat="0.707107 0 0 -0.707107"/>
            <geom name="LH_foot" class="foot" size="0.0313471" pos="0.0115379 0.0756157 -0.309235" quat="0.707107 0 0 -0.707107"/>
            <geom name="//unnamed_geom_91" class="reward_collision_sphere" size="0.0908041" pos="-0.0442065 0 0"/>
            <geom name="//unnamed_geom_92" class="reward_collision_sphere" size="0.0454021" pos="0.0115379 0.0756157 -0.309235"/>
            <site name="LH_foot" class="foot" pos="0.0115379 0.0756157 -0.309235" quat="0.707107 0 0 -0.707107" size="0.00908041"/>
          </body>
        </body>
      </body>
      <body name="RH_HIP" pos="-0.265114 -0.0924843 0.000806675" quat="-0.000839771 -9.57404e-05 -0.966089 -0.258209">
        <inertial pos="0.0492549 -0.0126571 -0.0103736" quat="-0.127873 0.709778 -0.135984 0.679244" mass="2.17613" diaginertia="0.00316224 0.00229962 0.00300564"/>
        <joint name="RH_HAA" pos="0 0 0" axis="0.999954 0.00756619 -0.00595775" range="-0.673857 0.464544" armature="0.00789842" damping="0.00422452" frictionloss="0.102524"/>
        <geom name="//unnamed_geom_93" class="visual" pos="0 -0.000122254 2.00801e-05" quat="-0.258819 0.965926 0 0" material="hip_l" mesh="hip_l"/>
        <geom name="//unnamed_geom_94" class="visual" pos="0.0529594 -0.0638935 -0.03778" quat="-0.183013 0.683013 -0.683013 -0.183013" material="drive" mesh="drive"/>
        <geom name="//unnamed_geom_95" class="collision" size="0.0454021 0.0635629" pos="0.0529594 -0.0102825 -0.00676852" quat="0.353553 0.612372 -0.612372 0.353553"/>
        <body name="RH_THIGH" pos="0.0542309 -0.0610398 -0.0408924" quat="-0.183125 0.682943 -0.683008 -0.183179">
          <inertial pos="0.0249531 0.00201114 -0.240414" quat="0.99336 -0.00479979 -0.0791575 0.0833485" mass="2.22592" diaginertia="0.0166462 0.0138776 0.0037909"/>
          <joint name="RH_HFE" pos="0 0 0" axis="0.999897 -0.0111621 0.00906402" stiffness="0.00394763" range="-3.13857 3.15042" armature="0.00876898" damping="0.00597772" frictionloss="0.0853687"/>
          <geom name="//unnamed_geom_96" class="visual" pos="0.000484904 7.64096e-07 0" quat="0.707107 0 0 -0.707107" material="thigh" mesh="thigh"/>
          <geom name="//unnamed_geom_97" class="collision" size="0.0590227 0.0363216" pos="0.0353652 0 0" quat="0.5 0.5 0.5 0.5"/>
          <geom name="//unnamed_geom_98" class="collision" size="0.0340515 0.0272412 0.128319" pos="0.0265239 0 -0.138521" quat="0.707107 0 0 0.707107" type="box"/>
          <geom name="//unnamed_geom_99" class="visual" pos="0.0886782 0 -0.279367" quat="1 0 0 0" material="drive" mesh="drive"/>
          <geom name="//unnamed_geom_100" class="collision" size="0.0454021 0.0635629" pos="0.0267891 0 -0.279367" quat="0.707107 0 0.707107 0"/>
          <geom name="//unnamed_geom_101" class="reward_collision_sphere" size="0.0726433" pos="0.0221032 0 0"/>
          <body name="RH_SHANK" pos="0.0881624 -0.000425484 -0.279775" quat="1 0.000177593 0.000376055 0.000107068">
            <inertial pos="0.00752226 -0.0525571 -0.0795389" quat="0.99319 -0.114148 -0.00185218 -0.023234" mass="0.418265" diaginertia="0.00523808 0.00424071 0.000974155"/>
            <joint name="RH_KFE" pos="0 0 0" axis="0.999954 0.00421084 -0.00866712" range="-3.12406 3.18827" armature="0.00793687" damping="0.0132898" frictionloss="0.0942486"/>
            <geom name="//unnamed_geom_102" class="visual" pos="0.000158117 0.000843086 0" quat="0.707107 0 0 -0.707107" material="shank_l" mesh="shank_l"/>
            <geom name="RH_kfe_act" class="collision" size="0.0544825 0.0181608" pos="0.0176826 0 0" quat="0.5 0.5 0.5 0.5"/>
            <geom name="//unnamed_geom_104" class="collision" size="0.0522115 0.0306464 0.0172528" pos="0.0176826 -0.0494352 0" quat="0.5 0.5 0.5 0.5" type="box"/>
            <geom name="//unnamed_geom_105" class="visual" pos="0.0115379 -0.075344 -0.33129" quat="0.382683 0 0 -0.92388" material="foot" mesh="foot"/>
            <geom name="RH_calf" class="collision" size="0.0158907 0.128263" pos="0.0115379 -0.0756157 -0.165645" quat="0.707107 0 0 0.707107"/>
            <geom name="RH_foot" class="foot" size="0.0217155" pos="0.0115379 -0.0756157 -0.309235" quat="0.707107 0 0 0.707107"/>
            <geom name="//unnamed_geom_108" class="reward_collision_sphere" size="0.0908041" pos="-0.0442065 0 0"/>
            <geom name="//unnamed_geom_109" class="reward_collision_sphere" size="0.0454021" pos="0.0115379 -0.0756157 -0.309235"/>
            <site name="RH_foot" class="foot" pos="0.0115379 -0.0756157 -0.309235" quat="0.707107 0 0 0.707107" size="0.00908041"/>
          </body>
        </body>
      </body>
    </body>
  </worldbody>

  <contact>
    <pair class="/" geom1="floor" geom2="LF_foot" name="//unnamed_contact_0"/>
    <pair class="/" geom1="floor" geom2="RF_foot" name="//unnamed_contact_1"/>
    <pair class="/" geom1="floor" geom2="LH_foot" name="//unnamed_contact_2"/>
    <pair class="/" geom1="floor" geom2="RH_foot" name="//unnamed_contact_3"/>
  </contact>

  <actuator>
    <general name="LF_HAA" class="/" joint="LF_HAA" forcerange="-78.5845 78.5845" gainprm="66.1555" biasprm="0 -66.1555 -1.81441"/>
    <general name="LF_HFE" class="/" joint="LF_HFE" forcerange="-75.0582 75.0582" gainprm="66.1555" biasprm="0 -66.1555 -1.81441"/>
    <general name="LF_KFE" class="/" joint="LF_KFE" forcerange="-70.8728 70.8728" gainprm="66.1555" biasprm="0 -66.1555 -1.81441"/>
    <general name="RF_HAA" class="/" joint="RF_HAA" forcerange="-73.2908 73.2908" gainprm="66.1555" biasprm="0 -66.1555 -1.81441"/>
    <general name="RF_HFE" class="/" joint="RF_HFE" forcerange="-80.9183 80.9183" gainprm="66.1555" biasprm="0 -66.1555 -1.81441"/>
    <general name="RF_KFE" class="/" joint="RF_KFE" forcerange="-68.0366 68.0366" gainprm="66.1555" biasprm="0 -66.1555 -1.81441"/>
    <general name="LH_HAA" class="/" joint="LH_HAA" forcerange="-72.9704 72.9704" gainprm="66.1555" biasprm="0 -66.1555 -1.81441"/>
    <general name="LH_HFE" class="/" joint="LH_HFE" forcerange="-80.962 80.962" gainprm="66.1555" biasprm="0 -66.1555 -1.81441"/>
    <general name="LH_KFE" class="/" joint="LH_KFE" forcerange="-71.9731 71.9731" gainprm="66.1555" biasprm="0 -66.1555 -1.81441"/>
    <general name="RH_HAA" class="/" joint="RH_HAA" forcerange="-71.7126 71.7126" gainprm="66.1555" biasprm="0 -66.1555 -1.81441"/>
    <general name="RH_HFE" class="/" joint="RH_HFE" forcerange="-75.4635 75.4635" gainprm="66.1555" biasprm="0 -66.1555 -1.81441"/>
    <general name="RH_KFE" class="/" joint="RH_KFE" forcerange="-69.0771 69.0771" gainprm="66.1555" biasprm="0 -66.1555 -1.81441"/>
  </actuator>

  <sensor>
    <gyro site="imu" name="imu_angular_velocity"/>
    <velocimeter site="imu" name="imu_linear_velocity"/>
    <framelinvel objtype="site" objname="LF_foot" name="LF_foot_global_linear_velocity"/>
    <framelinvel objtype="site" objname="RF_foot" name="RF_foot_global_linear_velocity"/>
    <framelinvel objtype="site" objname="LH_foot" name="LH_foot_global_linear_velocity"/>
    <framelinvel objtype="site" objname="RH_foot" name="RH_foot_global_linear_velocity"/>
  </sensor>

  <keyframe>
    <key name="home" qpos="0 0 0.55 1 0 0 0 0 0.4 -0.8 0 -0.4 0.8 0 -0.4 0.8 0 0.4 -0.8"/>
  </keyframe>
</mujoco>
