<mujoco model="anymal_c">
  <compiler angle="radian" assetdir="assets" balanceinertia="true" inertiafromgeom="false"/>

  <option timestep="0.005" density="1.2" viscosity="2e-05"/>

  <size nkey="1"/>

  <visual>
    <quality shadowsize="8192"/>
    <map shadowclip="0.5"/>
  </visual>

  <default>
    <default class="/">
      <material specular="0" shininess="0.25"/>
      <geom contype="0" conaffinity="0" group="1" solref="-1000 -80"/>
      <site size="0.01 0.005 0.005" group="5"/>
      <general forcelimited="true" forcerange="-80 80" biastype="affine" gainprm="80" biasprm="0 -80 -2"/>
      <default class="anymal_c">
        <joint armature="0.01" damping="0.01" frictionloss="0.1"/>
        <default class="visual">
          <geom type="mesh" group="2"/>
          <default class="visual_zflip"/>
        </default>
        <default class="collision">
          <geom type="cylinder" group="3"/>
          <default class="foot">
            <geom size="0.03 0 0" type="sphere" condim="6" priority="1" friction="0.8 0.02 0.01" solimp="0.015 1 0.03"/>
          </default>
        </default>
      </default>
      <default class="reward_collision_sphere">
        <geom group="5" rgba="1 0 0 1"/>
      </default>
    </default>
  </default>

  <asset>
    <texture type="skybox" colorspace="auto" name="//unnamed_texture_0" builtin="gradient" rgb1="0.95 0.95 0.95" rgb2="0.95 0.95 0.95" width="100" height="600"/>
    <texture type="2d" colorspace="auto" name="texplane" builtin="checker" rgb1="0.345 0.575 0.748" rgb2="0.345 0.575 0.748" markrgb="1 1 1" width="512" height="512"/>
    <texture type="2d" colorspace="linear" name="base" file="base.png"/>
    <texture type="2d" colorspace="linear" name="top_shell" file="top_shell.png"/>
    <texture type="2d" colorspace="linear" name="bottom_shell" file="bottom_shell.png"/>
    <texture type="2d" colorspace="linear" name="remote" file="remote.png"/>
    <texture type="2d" colorspace="linear" name="hatch" file="hatch.png"/>
    <texture type="2d" colorspace="linear" name="handle" file="handle.png"/>
    <texture type="2d" colorspace="linear" name="face" file="face.png"/>
    <texture type="2d" colorspace="linear" name="battery" file="battery.png"/>
    <texture type="2d" colorspace="linear" name="lidar_cage" file="lidar_cage.png"/>
    <texture type="2d" colorspace="linear" name="depth_camera" file="depth_camera.png"/>
    <texture type="2d" colorspace="linear" name="wide_angle_camera" file="wide_angle_camera.png"/>
    <texture type="2d" colorspace="linear" name="lidar" file="lidar.png"/>
    <texture type="2d" colorspace="linear" name="drive" file="drive.png"/>
    <texture type="2d" colorspace="linear" name="hip_l" file="hip_l.png"/>
    <texture type="2d" colorspace="linear" name="shank_l" file="shank_l.png"/>
    <texture type="2d" colorspace="linear" name="foot" file="foot.png"/>
    <texture type="2d" colorspace="linear" name="thigh" file="thigh.png"/>
    <texture type="2d" colorspace="linear" name="shank_r" file="shank_r.png"/>
    <texture type="2d" colorspace="linear" name="hip_r" file="hip_r.png"/>
    <material name="MatPlane" class="/" texture="texplane" texuniform="true" texrepeat="2 2" specular="0.9" shininess="0.5"/>
    <material name="black_plastic" class="/" rgba="0.007 0.007 0.007 1"/>
    <material name="green" class="/" rgba="0.052 0.178 0.033 1"/>
    <material name="red" class="/" rgba="0.178 0.006 0.005 1"/>
    <material name="yellow" class="/" rgba="0.178 0.119 0.006 1"/>
    <material name="lwl" class="/" rgba="0.8 0.8 0.8 1"/>
    <material name="base" class="/" texture="base"/>
    <material name="top_shell" class="/" texture="top_shell"/>
    <material name="bottom_shell" class="/" texture="bottom_shell"/>
    <material name="hip_l" class="/" texture="hip_l"/>
    <material name="thigh" class="/" texture="thigh"/>
    <material name="shank_l" class="/" texture="shank_l"/>
    <material name="foot" class="/" texture="foot"/>
    <material name="hip_r" class="/" texture="hip_r"/>
    <material name="shank" class="/" texture="shank_r"/>
    <material name="hatch" class="/" texture="hatch"/>
    <material name="remote" class="/" texture="remote"/>
    <material name="handle" class="/" texture="handle"/>
    <material name="face" class="/" texture="face"/>
    <material name="depth_camera" class="/" texture="depth_camera"/>
    <material name="wide_angle_camera" class="/" texture="wide_angle_camera"/>
    <material name="battery" class="/" texture="battery"/>
    <material name="lidar_cage" class="/" texture="lidar_cage"/>
    <material name="lidar" class="/" texture="lidar"/>
    <material name="drive" class="/" texture="drive"/>
    <mesh name="base_0" class="/" file="base_0.obj"/>
    <mesh name="base_1" class="/" file="base_1.obj"/>
    <mesh name="base_2" class="/" file="base_2.obj"/>
    <mesh name="base_3" class="/" file="base_3.obj"/>
    <mesh name="base_4" class="/" file="base_4.obj"/>
    <mesh name="base_5" class="/" file="base_5.obj"/>
    <mesh name="top_shell" class="/" file="top_shell.obj"/>
    <mesh name="bottom_shell" class="/" file="bottom_shell.obj"/>
    <mesh name="remote" class="/" file="remote.obj"/>
    <mesh name="handle" class="/" file="handle.obj"/>
    <mesh name="face" class="/" file="face.obj"/>
    <mesh name="wide_angle_camera" class="/" file="wide_angle_camera.obj"/>
    <mesh name="depth_camera" class="/" file="depth_camera.obj"/>
    <mesh name="battery" class="/" file="battery.obj"/>
    <mesh name="lidar_cage" class="/" file="lidar_cage.obj"/>
    <mesh name="lidar" class="/" file="lidar.obj"/>
    <mesh name="drive" class="/" file="drive.obj"/>
    <mesh name="hip_l" class="/" file="hip_l.obj"/>
    <mesh name="thigh" class="/" file="thigh.obj"/>
    <mesh name="shank_l" class="/" file="shank_l.obj"/>
    <mesh name="foot" class="/" file="foot.obj"/>
    <mesh name="hip_r" class="/" file="hip_r.obj"/>
    <mesh name="hatch" class="/" file="hatch.obj"/>
    <mesh name="shank_r" class="/" file="shank_r.obj"/>
  </asset>

  <worldbody>
    <geom name="floor" class="/" size="100 100 0.125" type="plane" group="0" material="MatPlane"/>
    <light name="toplight_shadow" class="/" pos="0 0 5" dir="0.0990148 0.0990148 -0.990148" type="directional" ambient="0.04 0.04 0.04" diffuse="0.55 0.55 0.55" specular="0.12 0.12 0.12"/>
    <light name="toplight_fill" class="/" pos="0 0 5" dir="0.0990148 0.0990148 -0.990148" type="directional" castshadow="false" ambient="0.04 0.04 0.04" diffuse="0.3 0.3 0.3" specular="0.08 0.08 0.08"/>
    <body name="trunk" childclass="anymal_c" pos="-0.00176556 -0.000528869 -0.00036757" quat="1 0.000228988 0.000369212 0.000461114">
      <inertial pos="0.00149888 0.000395664 0.0532701" quat="0.490098 0.504945 0.502763 0.50206" mass="15.9601" diaginertia="0.446633 0.250908 0.314884"/>
      <joint name="//unnamed_joint_0" type="free" armature="0" damping="0" frictionloss="0"/>
      <geom name="//unnamed_geom_1" class="visual" material="green" mesh="base_0"/>
      <geom name="//unnamed_geom_2" class="visual" material="yellow" mesh="base_1"/>
      <geom name="//unnamed_geom_3" class="visual" material="red" mesh="base_2"/>
      <geom name="//unnamed_geom_4" class="visual" material="black_plastic" mesh="base_3"/>
      <geom name="//unnamed_geom_5" class="visual" material="lwl" mesh="base_4"/>
      <geom name="//unnamed_geom_6" class="visual" material="base" mesh="base_5"/>
      <geom name="trunk_1" class="collision" size="0.273852 0.0661023 0.0849887" type="box"/>
      <geom name="trunk_2" class="collision" size="0.0849887 0.0684631" pos="0.201535 0.058358 0" quat="0.707107 0 0.707107 0"/>
      <geom name="trunk_3" class="collision" size="0.0849887 0.0684631" pos="-0.201535 0.058358 0" quat="0.707107 0 0.707107 0"/>
      <geom name="trunk_4" class="collision" size="0.0849887 0.0684631" pos="0.201535 -0.058358 0" quat="0.707107 0 0.707107 0"/>
      <geom name="trunk_5" class="collision" size="0.0849887 0.0684631" pos="-0.201535 -0.058358 0" quat="0.707107 0 0.707107 0"/>
      <geom name="//unnamed_geom_12" class="visual" material="top_shell" mesh="top_shell"/>
      <geom name="//unnamed_geom_13" class="visual" material="bottom_shell" mesh="bottom_shell"/>
      <geom name="//unnamed_geom_14" class="visual" material="remote" mesh="remote"/>
      <geom name="//unnamed_geom_15" class="visual" material="handle" mesh="handle"/>
      <geom name="//unnamed_geom_16" class="visual" pos="0.384074 0 0" quat="1 0 0 0" material="face" mesh="face"/>
      <geom name="trunk_6" class="collision" size="0.0519375 0.0661023 0.0849887" pos="0.435037 0 0" type="box"/>
      <geom name="//unnamed_geom_18" class="collision" size="0.0849887 0.0519375" pos="0.435037 0.058358 0" quat="0.707107 0 0.707107 0"/>
      <geom name="//unnamed_geom_19" class="collision" size="0.0849887 0.0519375" pos="0.435037 -0.058358 0" quat="0.707107 0 0.707107 0"/>
      <geom name="//unnamed_geom_20" class="visual" pos="0.42777 0 -0.0324322" quat="0.965926 0 0.258819 0" material="depth_camera" mesh="depth_camera"/>
      <geom name="//unnamed_geom_21" class="visual" pos="0.475344 0 0.0160579" material="wide_angle_camera" mesh="wide_angle_camera"/>
      <geom name="//unnamed_geom_22" class="visual_zflip" pos="-0.384074 0 0" quat="0 0 0 1" material="face" mesh="face"/>
      <geom name="trunk_7" class="collision" size="0.0519375 0.0661023 0.0849887" pos="-0.435037 0 0" quat="0 0 0 1" type="box"/>
      <geom name="//unnamed_geom_24" class="collision" size="0.0849887 0.0519375" pos="-0.435037 -0.058358 0" quat="0 -0.707107 0 0.707107"/>
      <geom name="//unnamed_geom_25" class="collision" size="0.0849887 0.0519375" pos="-0.435037 0.058358 0" quat="0 -0.707107 0 0.707107"/>
      <geom name="//unnamed_geom_26" class="visual" pos="-0.42777 0 -0.0324322" quat="0 -0.258819 0 0.965926" material="depth_camera" mesh="depth_camera"/>
      <geom name="//unnamed_geom_27" class="visual_zflip" pos="-0.475344 0 0.0160579" quat="0 0 0 1" material="wide_angle_camera" mesh="wide_angle_camera"/>
      <geom name="//unnamed_geom_28" class="visual" material="battery" mesh="battery"/>
      <geom name="//unnamed_geom_29" class="visual" pos="0 0.0625305 0.030051" quat="0.683013 -0.183013 0.183013 0.683013" material="depth_camera" mesh="depth_camera"/>
      <geom name="//unnamed_geom_30" class="visual" pos="0 -0.0625305 0.030051" quat="0.683013 0.183013 0.183013 -0.683013" material="depth_camera" mesh="depth_camera"/>
      <geom name="//unnamed_geom_31" class="visual" pos="-0.337281 0 0.0788415" quat="1 0 0 0" material="lidar_cage" mesh="lidar_cage"/>
      <geom name="trunk_8" class="collision" size="0.0661023 0.0566591" pos="-0.337281 0 0.143202"/>
      <geom name="//unnamed_geom_33" class="visual" pos="-0.337281 -3.65022e-05 0.152534" quat="0.707107 0 0 -0.707107" material="lidar" mesh="lidar"/>
      <geom name="//unnamed_geom_34" class="visual" pos="0.277886 0.0867882 -4.12256e-09" quat="0.258819 0.965926 0 0" material="drive" mesh="drive"/>
      <geom name="//unnamed_geom_35" class="visual" pos="0.277886 -0.0867882 4.12256e-09" quat="0.258819 -0.965926 0 0" material="drive" mesh="drive"/>
      <geom name="//unnamed_geom_36" class="visual" pos="-0.277886 0.0867882 4.12256e-09" quat="0 0 0.965926 -0.258819" material="drive" mesh="drive"/>
      <geom name="//unnamed_geom_37" class="visual" pos="-0.277886 -0.0867882 -4.12256e-09" quat="0 0 -0.965926 -0.258819" material="drive" mesh="drive"/>
      <geom name="//unnamed_geom_38" class="visual" pos="0.107485 0 0.0783051" quat="1 0 0 0" material="hatch" mesh="hatch"/>
      <geom name="//unnamed_geom_39" class="reward_collision_sphere" size="0.113318"/>
      <geom name="//unnamed_geom_40" class="reward_collision_sphere" size="0.113318" pos="0.416969 0 0"/>
      <geom name="//unnamed_geom_41" class="reward_collision_sphere" size="0.113318" pos="-0.416969 0 0"/>
      <site name="imu" pos="0.234167 -0.00609761 0.0529411" size="0.00944319"/>
      <camera name="track" pos="0 -1.66737 0" quat="0.707107 0.707107 0 0" mode="trackcom"/>
      <camera name="ego_camera" pos="0.416969 0 -0.0429069" quat="-0.5 -0.5 0.5 0.5"/>
      <body name="LF_HIP" pos="0.278636 0.0877298 -0.00105355" quat="0.2577 0.966224 -5.23008e-05 -0.000877494">
        <inertial pos="0.052157 -0.0120841 -0.00772965" quat="-0.121819 0.710013 -0.142239 0.67883" mass="2.41733" diaginertia="0.00413688 0.00203905 0.00485497"/>
        <joint name="LF_HAA" pos="0 0 0" axis="0.99997 -0.00714572 0.00289478" range="-0.666813 0.494836" armature="0.0104434" damping="0.0101675" frictionloss="0.0974746"/>
        <geom name="//unnamed_geom_42" class="visual" pos="0 -0.000242511 3.98323e-05" quat="0.258819 -0.965926 0 0" material="hip_l" mesh="hip_l"/>
        <geom name="//unnamed_geom_43" class="visual" pos="0.0555032 -0.0661155 -0.0399395" quat="0.183013 -0.683013 0.683013 0.183013" material="drive" mesh="drive"/>
        <geom name="//unnamed_geom_44" class="collision" size="0.0472159 0.0661023" pos="0.0555032 -0.00997072 -0.00740681" quat="-0.353553 -0.612372 0.612372 -0.353553"/>
        <body name="LF_THIGH" pos="0.0559863 -0.0609155 -0.0443988" quat="0.183012 -0.683151 0.682855 0.183084">
          <inertial pos="0.028304 -0.00255172 -0.2661" quat="0.992746 -0.0020368 -0.0841668 0.08583" mass="2.63061" diaginertia="0.020594 0.012018 0.00591313"/>
          <joint name="LF_HFE" pos="0 0 0" axis="0.999997 0.00189233 -0.00147345" range="-3.13833 3.19217" armature="0.00924885" damping="0" frictionloss="0.0946154"/>
          <geom name="//unnamed_geom_45" class="visual" pos="0.00184856 2.9129e-06 0" quat="0.707107 0 0 -0.707107" material="thigh" mesh="thigh"/>
          <geom name="//unnamed_geom_46" class="collision" size="0.0613807 0.0377727" pos="0.0370639 0 0" quat="0.5 0.5 -0.5 -0.5"/>
          <geom name="//unnamed_geom_47" class="collision" size="0.035412 0.0283296 0.133445" pos="0.0277979 0 -0.151584" quat="0.707107 0 0 -0.707107" type="box"/>
          <geom name="//unnamed_geom_48" class="visual" pos="0.0929377 0 -0.305712" quat="1 0 0 0" material="drive" mesh="drive"/>
          <geom name="//unnamed_geom_49" class="collision" size="0.0472159 0.0661023" pos="0.0280759 0 -0.305712" quat="0.707107 0 0.707107 0"/>
          <geom name="//unnamed_geom_50" class="reward_collision_sphere" size="0.0755455" pos="0.0231649 0 0"/>
          <body name="LF_SHANK" pos="0.0953836 0.0021366 -0.304039" quat="1 6.79176e-07 3.92038e-06 3.59645e-05">
            <inertial pos="0.00598506 -0.0517247 -0.085013" quat="0.992953 -0.115743 -0.00105518 -0.0254242" mass="0.513178" diaginertia="0.00710195 0.00377966 0.00159561"/>
            <joint name="LF_KFE" pos="0 0 0" axis="0.999999 0.00128347 0.000607903" range="-3.11151 3.08893" armature="0.00933015" damping="0.010046" frictionloss="0.0958505"/>
            <geom name="//unnamed_geom_51" class="visual" pos="0.000602776 0.00321403 0" quat="0.707107 0 0 -0.707107" material="shank_l" mesh="shank_l"/>
            <geom name="LF_kfe_act" class="collision" size="0.0566591 0.0188864" pos="0.0185319 0 0" quat="0.5 0.5 -0.5 -0.5"/>
            <geom name="//unnamed_geom_53" class="collision" size="0.0542974 0.0318708 0.0179421" pos="0.0185319 -0.0479361 0" quat="0.5 0.5 -0.5 -0.5" type="box"/>
            <geom name="//unnamed_geom_54" class="visual" pos="0.0120919 -0.0722869 -0.362531" quat="0.382683 0 0 -0.92388" material="foot" mesh="foot"/>
            <geom name="LF_calf" class="collision" size="0.0165256 0.133387" pos="0.0120921 -0.0733227 -0.181266" quat="0.707107 0 0 -0.707107"/>
            <geom name="LF_foot" class="foot" size="0.0269271" pos="0.0120921 -0.0733227 -0.338396" quat="0.707107 0 0 -0.707107"/>
            <geom name="//unnamed_geom_57" class="reward_collision_sphere" size="0.0944319" pos="-0.0463298 0 0"/>
            <geom name="//unnamed_geom_58" class="reward_collision_sphere" size="0.0472159" pos="0.0120921 -0.0733227 -0.338396"/>
            <site name="LF_foot" class="foot" pos="0.0120921 -0.0733227 -0.338396" quat="0.707107 0 0 -0.707107" size="0.00944319"/>
          </body>
        </body>
      </body>
      <body name="RF_HIP" pos="0.278972 -0.0868751 0.00285202" quat="0.2587 -0.965958 2.70485e-05 2.92356e-05">
        <inertial pos="0.0536589 0.011796 -0.00877398" quat="0.133624 0.684318 0.116252 0.707347" mass="2.42207" diaginertia="0.00411011 0.0020399 0.00477593"/>
        <joint name="RF_HAA" pos="0 0 0" axis="0.999998 0.000107144 0.00181665" range="-0.455925 0.731662" armature="0.00948195" damping="0.00806845" frictionloss="0.0906871"/>
        <geom name="//unnamed_geom_59" class="visual" pos="0 0.000242509 3.98322e-05" quat="0.258819 0.965926 0 0" material="hip_r" mesh="hip_r"/>
        <geom name="//unnamed_geom_60" class="visual" pos="0.0555032 0.0661155 -0.0399395" quat="0.183013 0.683013 0.683013 -0.183013" material="drive" mesh="drive"/>
        <geom name="//unnamed_geom_61" class="collision" size="0.0472159 0.0661023" pos="0.0555032 0.00997072 -0.00740681" quat="-0.353553 0.612372 0.612372 0.353553"/>
        <body name="RF_THIGH" pos="0.0560845 0.0616867 -0.0475472" quat="0.182995 0.683169 0.682787 -0.183289">
          <inertial pos="0.0284183 -4.8323e-05 -0.265986" quat="0.992818 0.00535281 -0.0747356 0.0932683" mass="2.64107" diaginertia="0.0212143 0.0124496 0.00614737"/>
          <joint name="RF_HFE" pos="0 0 0" axis="1 6.89686e-05 0.000597572" stiffness="0.00592588" range="-3.19596 3.18335" armature="0.00847741" damping="0.0101163" frictionloss="0.089526"/>
          <geom name="//unnamed_geom_62" class="visual" pos="0.00184856 2.9129e-06 0" quat="0.707107 0 0 -0.707107" material="thigh" mesh="thigh"/>
          <geom name="//unnamed_geom_63" class="collision" size="0.0613807 0.0377727" pos="0.0370639 0 0" quat="0.5 0.5 0.5 0.5"/>
          <geom name="//unnamed_geom_64" class="collision" size="0.035412 0.0283296 0.133445" pos="0.0277979 0 -0.151584" quat="0.707107 0 0 0.707107" type="box"/>
          <geom name="//unnamed_geom_65" class="visual" pos="0.0929377 0 -0.305712" quat="1 0 0 0" material="drive" mesh="drive"/>
          <geom name="//unnamed_geom_66" class="collision" size="0.0472159 0.0661023" pos="0.0280759 0 -0.305712" quat="0.707107 0 0.707107 0"/>
          <geom name="//unnamed_geom_67" class="reward_collision_sphere" size="0.0755455" pos="0.0231649 0 0"/>
          <body name="RF_SHANK" pos="0.0934209 0.00034398 -0.306522" quat="1 4.13055e-05 5.54999e-06 5.02022e-07">
            <inertial pos="0.00422818 0.0516519 -0.0838185" quat="0.992688 0.118389 -0.00129839 0.0235252" mass="0.467014" diaginertia="0.00669308 0.00371963 0.00148835"/>
            <joint name="RF_KFE" pos="0 0 0" axis="0.999998 -0.00195486 0.000176648" range="-3.12809 3.12508" armature="0.0103907" damping="0.00947328" frictionloss="0.0948261"/>
            <geom name="//unnamed_geom_68" class="visual" pos="0.000602773 -0.00321403 0" quat="0.707107 0 0 0.707107" material="shank" mesh="shank_r"/>
            <geom name="RF_kfe_act" class="collision" size="0.0566591 0.0188864" pos="0.0185319 0 0" quat="0.5 0.5 0.5 0.5"/>
            <geom name="//unnamed_geom_70" class="collision" size="0.0542974 0.0318708 0.0179421" pos="0.0185319 0.0479361 0" quat="0.5 0.5 0.5 0.5" type="box"/>
            <geom name="//unnamed_geom_71" class="visual" pos="0.0120922 0.0722869 -0.362531" quat="0.382683 0 0 0.92388" material="foot" mesh="foot"/>
            <geom name="RF_calf" class="collision" size="0.0165256 0.133387" pos="0.0120921 0.0733227 -0.181266" quat="0.707107 0 0 0.707107"/>
            <geom name="RF_foot" class="foot" size="0.0280985" pos="0.0120921 0.0733227 -0.338396" quat="0.707107 0 0 0.707107"/>
            <geom name="//unnamed_geom_74" class="reward_collision_sphere" size="0.0944319" pos="-0.0463298 0 0"/>
            <geom name="//unnamed_geom_75" class="reward_collision_sphere" size="0.0472159" pos="0.0120921 0.0733227 -0.338396"/>
            <site name="RF_foot" class="foot" pos="0.0120921 0.0733227 -0.338396" quat="0.707107 0 0 0.707107" size="0.00944319"/>
          </body>
        </body>
      </body>
      <body name="LH_HIP" pos="-0.276953 0.0871235 -0.00169764" quat="3.61817e-06 -1.80234e-05 0.965916 -0.258857">
        <inertial pos="0.0525265 0.0123605 -0.0115939" quat="0.137133 0.679372 0.127353 0.709527" mass="2.42655" diaginertia="0.00414056 0.0019509 0.0047057"/>
        <joint name="LH_HAA" pos="0 0 0" axis="1 -0.000351614 -0.000915041" range="-0.440147 0.775131" armature="0.00950697" damping="0.00343162" frictionloss="0.106767"/>
        <geom name="//unnamed_geom_76" class="visual" pos="0 0.000242509 3.98322e-05" quat="-0.258819 -0.965926 0 0" material="hip_r" mesh="hip_r"/>
        <geom name="//unnamed_geom_77" class="visual" pos="0.0555032 0.0661155 -0.0399395" quat="0.183013 0.683013 0.683013 -0.183013" material="drive" mesh="drive"/>
        <geom name="//unnamed_geom_78" class="collision" size="0.0472159 0.0661023" pos="0.0555032 0.00997072 -0.00740681" quat="-0.353553 0.612372 0.612372 0.353553"/>
        <body name="LH_THIGH" pos="0.0554529 0.0613657 -0.0467991" quat="0.183054 0.682934 0.683078 -0.183023">
          <inertial pos="0.0260741 -0.000600034 -0.265971" quat="0.992565 0.00513179 -0.0759778 0.0949537" mass="2.60403" diaginertia="0.0198944 0.01206 0.00572484"/>
          <joint name="LH_HFE" pos="0 0 0" axis="0.99989 0.00208732 0.014715" range="-3.1941 3.16035" armature="0.0091736" damping="0.00379307" frictionloss="0.0938311"/>
          <geom name="//unnamed_geom_79" class="visual" pos="0.00184856 2.9129e-06 0" quat="0.707107 0 0 -0.707107" material="thigh" mesh="thigh"/>
          <geom name="//unnamed_geom_80" class="collision" size="0.0613807 0.0377727" pos="0.0370639 0 0" quat="0.5 0.5 -0.5 -0.5"/>
          <geom name="//unnamed_geom_81" class="collision" size="0.035412 0.0283296 0.133445" pos="0.0277979 0 -0.151584" quat="0.707107 0 0 -0.707107" type="box"/>
          <geom name="//unnamed_geom_82" class="visual" pos="0.0929377 0 -0.305712" quat="1 0 0 0" material="drive" mesh="drive"/>
          <geom name="//unnamed_geom_83" class="collision" size="0.0472159 0.0661023" pos="0.0280759 0 -0.305712" quat="0.707107 0 0.707107 0"/>
          <geom name="//unnamed_geom_84" class="reward_collision_sphere" size="0.0755455" pos="0.0231649 0 0"/>
          <body name="LH_SHANK" pos="0.0922594 -0.00108135 -0.307781" quat="1 -0.000182806 -0.000202764 -0.000147623">
            <inertial pos="0.00586568 0.0498415 -0.0850995" quat="0.994096 0.105761 -0.00522398 0.0236817" mass="0.481562" diaginertia="0.00692628 0.00368808 0.00159838"/>
            <joint name="LH_KFE" pos="0 0 0" axis="0.99998 -0.000524343 0.00623713" range="-3.16234 3.14158" armature="0.00939447" damping="0.00471547" frictionloss="0.0987965"/>
            <geom name="//unnamed_geom_85" class="visual" pos="0.000602773 -0.00321403 0" quat="-0.707107 0 0 -0.707107" material="shank" mesh="shank_r"/>
            <geom name="LH_kfe_act" class="collision" size="0.0566591 0.0188864" pos="0.0185319 0 0" quat="0.5 0.5 -0.5 -0.5"/>
            <geom name="//unnamed_geom_87" class="collision" size="0.0542974 0.0318708 0.0179421" pos="0.0185319 0.0479361 0" quat="0.5 0.5 -0.5 -0.5" type="box"/>
            <geom name="//unnamed_geom_88" class="visual" pos="0.0120922 0.0722869 -0.362531" quat="-0.382683 0 0 -0.92388" material="foot" mesh="foot"/>
            <geom name="LH_calf" class="collision" size="0.0165256 0.133387" pos="0.0120921 0.0733227 -0.181266" quat="0.707107 0 0 -0.707107"/>
            <geom name="LH_foot" class="foot" size="0.0319288" pos="0.0120921 0.0733227 -0.338396" quat="0.707107 0 0 -0.707107"/>
            <geom name="//unnamed_geom_91" class="reward_collision_sphere" size="0.0944319" pos="-0.0463298 0 0"/>
            <geom name="//unnamed_geom_92" class="reward_collision_sphere" size="0.0472159" pos="0.0120921 0.0733227 -0.338396"/>
            <site name="LH_foot" class="foot" pos="0.0120921 0.0733227 -0.338396" quat="0.707107 0 0 -0.707107" size="0.00944319"/>
          </body>
        </body>
      </body>
      <body name="RH_HIP" pos="-0.277879 -0.0857372 0.000969642" quat="0.00015441 0.000360101 -0.965973 -0.258642">
        <inertial pos="0.0527778 -0.0102965 -0.0109372" quat="-0.127664 0.709941 -0.135324 0.679245" mass="2.25982" diaginertia="0.00390516 0.00193718 0.00451696"/>
        <joint name="RH_HAA" pos="0 0 0" axis="0.999986 -0.00284563 -0.00443713" range="-0.73667 0.447876" armature="0.00911395" damping="0" frictionloss="0.0912916"/>
        <geom name="//unnamed_geom_93" class="visual" pos="0 -0.000242511 3.98323e-05" quat="-0.258819 0.965926 0 0" material="hip_l" mesh="hip_l"/>
        <geom name="//unnamed_geom_94" class="visual" pos="0.0555032 -0.0661155 -0.0399395" quat="-0.183013 0.683013 -0.683013 -0.183013" material="drive" mesh="drive"/>
        <geom name="//unnamed_geom_95" class="collision" size="0.0472159 0.0661023" pos="0.0555032 -0.00997072 -0.00740681" quat="0.353553 0.612372 -0.612372 0.353553"/>
        <body name="RH_THIGH" pos="0.0543492 -0.0598991 -0.0423266" quat="-0.183212 0.68282 -0.68309 -0.183246">
          <inertial pos="0.0277666 0.00167554 -0.263331" quat="0.993271 -0.00479968 -0.080475 0.0831447" mass="2.4381" diaginertia="0.0200631 0.0116778 0.00593351"/>
          <joint name="RH_HFE" pos="0 0 0" axis="0.999996 0.00288753 0.000129497" stiffness="0.00610957" range="-3.19394 3.19563" armature="0.009714" damping="0.00747133" frictionloss="0.083369"/>
          <geom name="//unnamed_geom_96" class="visual" pos="0.00184856 2.9129e-06 0" quat="0.707107 0 0 -0.707107" material="thigh" mesh="thigh"/>
          <geom name="//unnamed_geom_97" class="collision" size="0.0613807 0.0377727" pos="0.0370639 0 0" quat="0.5 0.5 0.5 0.5"/>
          <geom name="//unnamed_geom_98" class="collision" size="0.035412 0.0283296 0.133445" pos="0.0277979 0 -0.151584" quat="0.707107 0 0 0.707107" type="box"/>
          <geom name="//unnamed_geom_99" class="visual" pos="0.0929377 0 -0.305712" quat="1 0 0 0" material="drive" mesh="drive"/>
          <geom name="//unnamed_geom_100" class="collision" size="0.0472159 0.0661023" pos="0.0280759 0 -0.305712" quat="0.707107 0 0.707107 0"/>
          <geom name="//unnamed_geom_101" class="reward_collision_sphere" size="0.0755455" pos="0.0231649 0 0"/>
          <body name="RH_SHANK" pos="0.0950175 0.000377263 -0.304466" quat="1 0.000265158 -0.000367602 -0.000391556">
            <inertial pos="0.00446659 -0.0509927 -0.0863359" quat="0.992599 -0.118651 -0.0024496 -0.0257387" mass="0.474115" diaginertia="0.00689877 0.00364161 0.00156869"/>
            <joint name="RH_KFE" pos="0 0 0" axis="0.999991 0.000688142 -0.00407479" range="-3.1316 3.15278" armature="0.00940421" damping="0" frictionloss="0.0937711"/>
            <geom name="//unnamed_geom_102" class="visual" pos="0.000602776 0.00321403 0" quat="0.707107 0 0 -0.707107" material="shank_l" mesh="shank_l"/>
            <geom name="RH_kfe_act" class="collision" size="0.0566591 0.0188864" pos="0.0185319 0 0" quat="0.5 0.5 0.5 0.5"/>
            <geom name="//unnamed_geom_104" class="collision" size="0.0542974 0.0318708 0.0179421" pos="0.0185319 -0.0479361 0" quat="0.5 0.5 0.5 0.5" type="box"/>
            <geom name="//unnamed_geom_105" class="visual" pos="0.0120919 -0.0722869 -0.362531" quat="0.382683 0 0 -0.92388" material="foot" mesh="foot"/>
            <geom name="RH_calf" class="collision" size="0.0165256 0.133387" pos="0.0120921 -0.0733227 -0.181266" quat="0.707107 0 0 0.707107"/>
            <geom name="RH_foot" class="foot" size="0.0292167" pos="0.0120921 -0.0733227 -0.338396" quat="0.707107 0 0 0.707107"/>
            <geom name="//unnamed_geom_108" class="reward_collision_sphere" size="0.0944319" pos="-0.0463298 0 0"/>
            <geom name="//unnamed_geom_109" class="reward_collision_sphere" size="0.0472159" pos="0.0120921 -0.0733227 -0.338396"/>
            <site name="RH_foot" class="foot" pos="0.0120921 -0.0733227 -0.338396" quat="0.707107 0 0 0.707107" size="0.00944319"/>
          </body>
        </body>
      </body>
    </body>
  </worldbody>

  <contact>
    <pair class="/" geom1="floor" geom2="LF_foot" name="//unnamed_contact_0"/>
    <pair class="/" geom1="floor" geom2="RF_foot" name="//unnamed_contact_1"/>
    <pair class="/" geom1="floor" geom2="LH_foot" name="//unnamed_contact_2"/>
    <pair class="/" geom1="floor" geom2="RH_foot" name="//unnamed_contact_3"/>
  </contact>

  <actuator>
    <general name="LF_HAA" class="/" joint="LF_HAA" forcerange="-72.6939 72.6939" gainprm="74.4981" biasprm="0 -74.4981 -1.99701"/>
    <general name="LF_HFE" class="/" joint="LF_HFE" forcerange="-82.5758 82.5758" gainprm="74.4981" biasprm="0 -74.4981 -1.99701"/>
    <general name="LF_KFE" class="/" joint="LF_KFE" forcerange="-68.2626 68.2626" gainprm="74.4981" biasprm="0 -74.4981 -1.99701"/>
    <general name="RF_HAA" class="/" joint="RF_HAA" forcerange="-75.4208 75.4208" gainprm="74.4981" biasprm="0 -74.4981 -1.99701"/>
    <general name="RF_HFE" class="/" joint="RF_HFE" forcerange="-81.0916 81.0916" gainprm="74.4981" biasprm="0 -74.4981 -1.99701"/>
    <general name="RF_KFE" class="/" joint="RF_KFE" forcerange="-82.6672 82.6672" gainprm="74.4981" biasprm="0 -74.4981 -1.99701"/>
    <general name="LH_HAA" class="/" joint="LH_HAA" forcerange="-83.3809 83.3809" gainprm="74.4981" biasprm="0 -74.4981 -1.99701"/>
    <general name="LH_HFE" class="/" joint="LH_HFE" forcerange="-77.6641 77.6641" gainprm="74.4981" biasprm="0 -74.4981 -1.99701"/>
    <general name="LH_KFE" class="/" joint="LH_KFE" forcerange="-75.1589 75.1589" gainprm="74.4981" biasprm="0 -74.4981 -1.99701"/>
    <general name="RH_HAA" class="/" joint="RH_HAA" forcerange="-76.2248 76.2248" gainprm="74.4981" biasprm="0 -74.4981 -1.99701"/>
    <general name="RH_HFE" class="/" joint="RH_HFE" forcerange="-68.2977 68.2977" gainprm="74.4981" biasprm="0 -74.4981 -1.99701"/>
    <general name="RH_KFE" class="/" joint="RH_KFE" forcerange="-69.3787 69.3787" gainprm="74.4981" biasprm="0 -74.4981 -1.99701"/>
  </actuator>

  <sensor>
    <gyro site="imu" name="imu_angular_velocity"/>
    <velocimeter site="imu" name="imu_linear_velocity"/>
    <framelinvel objtype="site" objname="LF_foot" name="LF_foot_global_linear_velocity"/>
    <framelinvel objtype="site" objname="RF_foot" name="RF_foot_global_linear_velocity"/>
    <framelinvel objtype="site" objname="LH_foot" name="LH_foot_global_linear_velocity"/>
    <framelinvel objtype="site" objname="RH_foot" name="RH_foot_global_linear_velocity"/>
  </sensor>

  <keyframe>
    <key name="home" qpos="0 0 0.55 1 0 0 0 0 0.4 -0.8 0 -0.4 0.8 0 -0.4 0.8 0 0.4 -0.8"/>
  </keyframe>
</mujoco>
