<mujoco model="anymal_c">
  <compiler angle="radian" assetdir="assets" balanceinertia="true" inertiafromgeom="false"/>

  <option timestep="0.005" density="1.2" viscosity="2e-05"/>

  <size nkey="1"/>

  <visual>
    <quality shadowsize="8192"/>
    <map shadowclip="0.5"/>
  </visual>

  <default>
    <default class="/">
      <material specular="0" shininess="0.25"/>
      <geom contype="0" conaffinity="0" group="1" solref="-1000 -80"/>
      <site size="0.01 0.005 0.005" group="5"/>
      <general forcelimited="true" forcerange="-80 80" biastype="affine" gainprm="80" biasprm="0 -80 -2"/>
      <default class="anymal_c">
        <joint armature="0.01" damping="0.01" frictionloss="0.1"/>
        <default class="visual">
          <geom type="mesh" group="2"/>
          <default class="visual_zflip"/>
        </default>
        <default class="collision">
          <geom type="cylinder" group="3"/>
          <default class="foot">
            <geom size="0.03 0 0" type="sphere" condim="6" priority="1" friction="0.8 0.02 0.01" solimp="0.015 1 0.03"/>
          </default>
        </default>
      </default>
      <default class="reward_collision_sphere">
        <geom group="5" rgba="1 0 0 1"/>
      </default>
    </default>
  </default>

  <asset>
    <texture type="skybox" colorspace="auto" name="//unnamed_texture_0" builtin="gradient" rgb1="0.95 0.95 0.95" rgb2="0.95 0.95 0.95" width="100" height="600"/>
    <texture type="2d" colorspace="auto" name="texplane" builtin="checker" rgb1="0.345 0.575 0.748" rgb2="0.345 0.575 0.748" markrgb="1 1 1" width="512" height="512"/>
    <texture type="2d" colorspace="linear" name="base" file="base.png"/>
    <texture type="2d" colorspace="linear" name="top_shell" file="top_shell.png"/>
    <texture type="2d" colorspace="linear" name="bottom_shell" file="bottom_shell.png"/>
    <texture type="2d" colorspace="linear" name="remote" file="remote.png"/>
    <texture type="2d" colorspace="linear" name="hatch" file="hatch.png"/>
    <texture type="2d" colorspace="linear" name="handle" file="handle.png"/>
    <texture type="2d" colorspace="linear" name="face" file="face.png"/>
    <texture type="2d" colorspace="linear" name="battery" file="battery.png"/>
    <texture type="2d" colorspace="linear" name="lidar_cage" file="lidar_cage.png"/>
    <texture type="2d" colorspace="linear" name="depth_camera" file="depth_camera.png"/>
    <texture type="2d" colorspace="linear" name="wide_angle_camera" file="wide_angle_camera.png"/>
    <texture type="2d" colorspace="linear" name="lidar" file="lidar.png"/>
    <texture type="2d" colorspace="linear" name="drive" file="drive.png"/>
    <texture type="2d" colorspace="linear" name="hip_l" file="hip_l.png"/>
    <texture type="2d" colorspace="linear" name="shank_l" file="shank_l.png"/>
    <texture type="2d" colorspace="linear" name="foot" file="foot.png"/>
    <texture type="2d" colorspace="linear" name="thigh" file="thigh.png"/>
    <texture type="2d" colorspace="linear" name="shank_r" file="shank_r.png"/>
    <texture type="2d" colorspace="linear" name="hip_r" file="hip_r.png"/>
    <material name="MatPlane" class="/" texture="texplane" texuniform="true" texrepeat="2 2" specular="0.9" shininess="0.5"/>
    <material name="black_plastic" class="/" rgba="0.007 0.007 0.007 1"/>
    <material name="green" class="/" rgba="0.052 0.178 0.033 1"/>
    <material name="red" class="/" rgba="0.178 0.006 0.005 1"/>
    <material name="yellow" class="/" rgba="0.178 0.119 0.006 1"/>
    <material name="lwl" class="/" rgba="0.8 0.8 0.8 1"/>
    <material name="base" class="/" texture="base"/>
    <material name="top_shell" class="/" texture="top_shell"/>
    <material name="bottom_shell" class="/" texture="bottom_shell"/>
    <material name="hip_l" class="/" texture="hip_l"/>
    <material name="thigh" class="/" texture="thigh"/>
    <material name="shank_l" class="/" texture="shank_l"/>
    <material name="foot" class="/" texture="foot"/>
    <material name="hip_r" class="/" texture="hip_r"/>
    <material name="shank" class="/" texture="shank_r"/>
    <material name="hatch" class="/" texture="hatch"/>
    <material name="remote" class="/" texture="remote"/>
    <material name="handle" class="/" texture="handle"/>
    <material name="face" class="/" texture="face"/>
    <material name="depth_camera" class="/" texture="depth_camera"/>
    <material name="wide_angle_camera" class="/" texture="wide_angle_camera"/>
    <material name="battery" class="/" texture="battery"/>
    <material name="lidar_cage" class="/" texture="lidar_cage"/>
    <material name="lidar" class="/" texture="lidar"/>
    <material name="drive" class="/" texture="drive"/>
    <mesh name="base_0" class="/" file="base_0.obj"/>
    <mesh name="base_1" class="/" file="base_1.obj"/>
    <mesh name="base_2" class="/" file="base_2.obj"/>
    <mesh name="base_3" class="/" file="base_3.obj"/>
    <mesh name="base_4" class="/" file="base_4.obj"/>
    <mesh name="base_5" class="/" file="base_5.obj"/>
    <mesh name="top_shell" class="/" file="top_shell.obj"/>
    <mesh name="bottom_shell" class="/" file="bottom_shell.obj"/>
    <mesh name="remote" class="/" file="remote.obj"/>
    <mesh name="handle" class="/" file="handle.obj"/>
    <mesh name="face" class="/" file="face.obj"/>
    <mesh name="wide_angle_camera" class="/" file="wide_angle_camera.obj"/>
    <mesh name="depth_camera" class="/" file="depth_camera.obj"/>
    <mesh name="battery" class="/" file="battery.obj"/>
    <mesh name="lidar_cage" class="/" file="lidar_cage.obj"/>
    <mesh name="lidar" class="/" file="lidar.obj"/>
    <mesh name="drive" class="/" file="drive.obj"/>
    <mesh name="hip_l" class="/" file="hip_l.obj"/>
    <mesh name="thigh" class="/" file="thigh.obj"/>
    <mesh name="shank_l" class="/" file="shank_l.obj"/>
    <mesh name="foot" class="/" file="foot.obj"/>
    <mesh name="hip_r" class="/" file="hip_r.obj"/>
    <mesh name="hatch" class="/" file="hatch.obj"/>
    <mesh name="shank_r" class="/" file="shank_r.obj"/>
  </asset>

  <worldbody>
    <geom name="floor" class="/" size="100 100 0.125" type="plane" group="0" material="MatPlane"/>
    <light name="toplight_shadow" class="/" pos="0 0 5" dir="0.0990148 0.0990148 -0.990148" type="directional" ambient="0.04 0.04 0.04" diffuse="0.55 0.55 0.55" specular="0.12 0.12 0.12"/>
    <light name="toplight_fill" class="/" pos="0 0 5" dir="0.0990148 0.0990148 -0.990148" type="directional" castshadow="false" ambient="0.04 0.04 0.04" diffuse="0.3 0.3 0.3" specular="0.08 0.08 0.08"/>
    <body name="trunk" childclass="anymal_c" pos="0.0113598 -0.00353903 0.0087588" quat="0.999987 0.00121282 0.00204309 0.00458948">
      <inertial pos="0.0123724 -0.00925328 0.0539385" quat="0.523025 0.537774 0.469397 0.465736" mass="35.5248" diaginertia="2.19337 2.91517 0.265574"/>
      <joint name="//unnamed_joint_0" type="free" armature="0" damping="0" frictionloss="0"/>
      <geom name="//unnamed_geom_1" class="visual" material="green" mesh="base_0"/>
      <geom name="//unnamed_geom_2" class="visual" material="yellow" mesh="base_1"/>
      <geom name="//unnamed_geom_3" class="visual" material="red" mesh="base_2"/>
      <geom name="//unnamed_geom_4" class="visual" material="black_plastic" mesh="base_3"/>
      <geom name="//unnamed_geom_5" class="visual" material="lwl" mesh="base_4"/>
      <geom name="//unnamed_geom_6" class="visual" material="base" mesh="base_5"/>
      <geom name="trunk_1" class="collision" size="0.372753 0.089975 0.115682" type="box"/>
      <geom name="trunk_2" class="collision" size="0.115682 0.0931884" pos="0.297541 0.0960946 0" quat="0.707107 0 0.707107 0"/>
      <geom name="trunk_3" class="collision" size="0.115682 0.0931884" pos="-0.297541 0.0960946 0" quat="0.707107 0 0.707107 0"/>
      <geom name="trunk_4" class="collision" size="0.115682 0.0931884" pos="0.297541 -0.0960946 0" quat="0.707107 0 0.707107 0"/>
      <geom name="trunk_5" class="collision" size="0.115682 0.0931884" pos="-0.297541 -0.0960946 0" quat="0.707107 0 0.707107 0"/>
      <geom name="//unnamed_geom_12" class="visual" material="top_shell" mesh="top_shell"/>
      <geom name="//unnamed_geom_13" class="visual" material="bottom_shell" mesh="bottom_shell"/>
      <geom name="//unnamed_geom_14" class="visual" material="remote" mesh="remote"/>
      <geom name="//unnamed_geom_15" class="visual" material="handle" mesh="handle"/>
      <geom name="//unnamed_geom_16" class="visual" pos="0.567038 0 0" quat="1 0 0 0" material="face" mesh="face"/>
      <geom name="trunk_6" class="collision" size="0.0706946 0.089975 0.115682" pos="0.642278 0 0" type="box"/>
      <geom name="//unnamed_geom_18" class="collision" size="0.115682 0.0706946" pos="0.642278 0.0960946 0" quat="0.707107 0 0.707107 0"/>
      <geom name="//unnamed_geom_19" class="collision" size="0.115682 0.0706946" pos="0.642278 -0.0960946 0" quat="0.707107 0 0.707107 0"/>
      <geom name="//unnamed_geom_20" class="visual" pos="0.631529 0 -0.0306456" quat="0.965926 0 0.258819 0" material="depth_camera" mesh="depth_camera"/>
      <geom name="//unnamed_geom_21" class="visual" pos="0.701787 0 0.0166958" material="wide_angle_camera" mesh="wide_angle_camera"/>
      <geom name="//unnamed_geom_22" class="visual_zflip" pos="-0.567038 0 0" quat="0 0 0 1" material="face" mesh="face"/>
      <geom name="trunk_7" class="collision" size="0.0706946 0.089975 0.115682" pos="-0.642278 0 0" quat="0 0 0 1" type="box"/>
      <geom name="//unnamed_geom_24" class="collision" size="0.115682 0.0706946" pos="-0.642278 -0.0960946 0" quat="0 -0.707107 0 0.707107"/>
      <geom name="//unnamed_geom_25" class="collision" size="0.115682 0.0706946" pos="-0.642278 0.0960946 0" quat="0 -0.707107 0 0.707107"/>
      <geom name="//unnamed_geom_26" class="visual" pos="-0.631529 0 -0.0306456" quat="0 -0.258819 0 0.965926" material="depth_camera" mesh="depth_camera"/>
      <geom name="//unnamed_geom_27" class="visual_zflip" pos="-0.701787 0 0.0166958" quat="0 0 0 1" material="wide_angle_camera" mesh="wide_angle_camera"/>
      <geom name="//unnamed_geom_28" class="visual" material="battery" mesh="battery"/>
      <geom name="//unnamed_geom_29" class="visual" pos="0 0.105015 0.0343197" quat="0.683013 -0.183013 0.183013 0.683013" material="depth_camera" mesh="depth_camera"/>
      <geom name="//unnamed_geom_30" class="visual" pos="0 -0.105015 0.0343197" quat="0.683013 0.183013 0.183013 -0.683013" material="depth_camera" mesh="depth_camera"/>
      <geom name="//unnamed_geom_31" class="visual" pos="-0.497954 0 0.0819734" quat="1 0 0 0" material="lidar_cage" mesh="lidar_cage"/>
      <geom name="trunk_8" class="collision" size="0.089975 0.0771214" pos="-0.497954 0 0.14889"/>
      <geom name="//unnamed_geom_33" class="visual" pos="-0.497954 1.87616e-06 0.158593" quat="0.707107 0 0 -0.707107" material="lidar" mesh="lidar"/>
      <geom name="//unnamed_geom_34" class="visual" pos="0.410265 0.142678 4.44184e-09" quat="0.258819 0.965926 0 0" material="drive" mesh="drive"/>
      <geom name="//unnamed_geom_35" class="visual" pos="0.410265 -0.142678 -4.44184e-09" quat="0.258819 -0.965926 0 0" material="drive" mesh="drive"/>
      <geom name="//unnamed_geom_36" class="visual" pos="-0.410265 0.142678 -4.44184e-09" quat="0 0 0.965926 -0.258819" material="drive" mesh="drive"/>
      <geom name="//unnamed_geom_37" class="visual" pos="-0.410265 -0.142678 4.44184e-09" quat="0 0 -0.965926 -0.258819" material="drive" mesh="drive"/>
      <geom name="//unnamed_geom_38" class="visual" pos="0.158689 0 0.0814158" quat="1 0 0 0" material="hatch" mesh="hatch"/>
      <geom name="//unnamed_geom_39" class="reward_collision_sphere" size="0.154243"/>
      <geom name="//unnamed_geom_40" class="reward_collision_sphere" size="0.154243" pos="0.615602 0 0"/>
      <geom name="//unnamed_geom_41" class="reward_collision_sphere" size="0.154243" pos="-0.615602 0 0"/>
      <site name="imu" pos="0.293523 0.0945682 0.0859883" size="0.0128536"/>
      <camera name="track" pos="0 -2.74556 0" quat="0.707107 0.707107 0 0" mode="trackcom"/>
      <camera name="ego_camera" pos="0.615602 0 -0.0446114" quat="-0.5 -0.5 0.5 0.5"/>
      <body name="LF_HIP" pos="0.409146 0.143707 0.00660794" quat="0.265715 0.964044 -0.00285894 0.00252316">
        <inertial pos="0.0864423 -0.0228235 -0.0037044" quat="-0.175787 0.720058 -0.152696 0.653681" mass="4.79234" diaginertia="0.0229708 0.0195958 0.00411096"/>
        <joint name="LF_HAA" pos="0 0 0" axis="0.998917 0.0327543 -0.0330504" stiffness="0.00194366" range="-1.01026 0.468026" armature="0.00467039" damping="0.000415479" frictionloss="0.152318"/>
        <geom name="//unnamed_geom_42" class="visual" pos="0 0.000261293 -4.29172e-05" quat="0.258819 -0.965926 0 0" material="hip_l" mesh="hip_l"/>
        <geom name="//unnamed_geom_43" class="visual" pos="0.0819435 -0.0992634 -0.0554052" quat="0.183013 -0.683013 0.683013 0.183013" material="drive" mesh="drive"/>
        <geom name="//unnamed_geom_44" class="collision" size="0.0642678 0.089975" pos="0.0819435 -0.0164182 -0.00770104" quat="-0.353553 -0.612372 0.612372 -0.353553"/>
        <body name="LF_THIGH" pos="0.0819088 -0.0949737 -0.0418368" quat="0.183063 -0.682911 0.683059 0.183172">
          <inertial pos="0.0437334 0.0147111 -0.257348" quat="0.994696 0.0191022 -0.0661524 0.0764121" mass="6.70765" diaginertia="0.134667 0.159114 0.00667961"/>
          <joint name="LF_HFE" pos="0 0 0" axis="0.999784 0.00896285 -0.0187576" range="-3.13518 2.81995" armature="0.0190622" damping="0.0915444" frictionloss="0.12811"/>
          <geom name="//unnamed_geom_45" class="visual" pos="-9.50132e-05 -1.49719e-07 0" quat="0.707107 0 0 -0.707107" material="thigh" mesh="thigh"/>
          <geom name="//unnamed_geom_46" class="collision" size="0.0835482 0.0514143" pos="0.0547202 0 0" quat="0.5 0.5 -0.5 -0.5"/>
          <geom name="//unnamed_geom_47" class="collision" size="0.0482009 0.0385607 0.181639" pos="0.0410402 0 -0.157605" quat="0.707107 0 0 -0.707107" type="box"/>
          <geom name="//unnamed_geom_48" class="visual" pos="0.137211 0 -0.317856" quat="1 0 0 0" material="drive" mesh="drive"/>
          <geom name="//unnamed_geom_49" class="collision" size="0.0642678 0.089975" pos="0.0414506 0 -0.317856" quat="0.707107 0 0.707107 0"/>
          <geom name="//unnamed_geom_50" class="reward_collision_sphere" size="0.102829" pos="0.0342001 0 0"/>
          <body name="LF_SHANK" pos="0.120435 -0.0154426 -0.3289" quat="1 0.00010743 0.000308436 6.37948e-05">
            <inertial pos="0.0134405 -0.0747209 -0.100854" quat="0.992711 -0.1175 -0.00329223 -0.0265908" mass="1.01232" diaginertia="0.0415771 0.047386 0.00192842"/>
            <joint name="LF_KFE" pos="0 0 0" axis="0.999915 -0.00693748 -0.0110105" stiffness="0.0799826" range="-3.35547 3.41512" armature="0.0140974" damping="0.0267895" frictionloss="0.149148"/>
            <geom name="//unnamed_geom_51" class="visual" pos="-3.09817e-05 -0.000165196 0" quat="0.707107 0 0 -0.707107" material="shank_l" mesh="shank_l"/>
            <geom name="LF_kfe_act" class="collision" size="0.0771214 0.0257071" pos="0.0273601 0 0" quat="0.5 0.5 -0.5 -0.5"/>
            <geom name="//unnamed_geom_53" class="collision" size="0.0739067 0.0433808 0.0244218" pos="0.0273601 -0.0789335 0" quat="0.5 0.5 -0.5 -0.5" type="box"/>
            <geom name="//unnamed_geom_54" class="visual" pos="0.0178525 -0.120789 -0.376933" quat="0.382683 0 0 -0.92388" material="foot" mesh="foot"/>
            <geom name="LF_calf" class="collision" size="0.0224937 0.181559" pos="0.0178525 -0.120736 -0.188466" quat="0.707107 0 0 -0.707107"/>
            <geom name="LF_foot" class="foot" size="0.0605525" pos="0.0178525 -0.120736 -0.351839" quat="0.707107 0 0 -0.707107"/>
            <geom name="//unnamed_geom_57" class="reward_collision_sphere" size="0.128536" pos="-0.0684003 0 0"/>
            <geom name="//unnamed_geom_58" class="reward_collision_sphere" size="0.0642678" pos="0.0178525 -0.120736 -0.351839"/>
            <site name="LF_foot" class="foot" pos="0.0178525 -0.120736 -0.351839" quat="0.707107 0 0 -0.707107" size="0.0128536"/>
          </body>
        </body>
      </body>
      <body name="RF_HIP" pos="0.401799 -0.15165 -0.0150477" quat="0.25903 -0.965869 -4.06445e-05 -0.000509605">
        <inertial pos="0.0831893 0.0319106 -0.0102894" quat="0.105259 0.709745 0.175674 0.674033" mass="4.75263" diaginertia="0.0252899 0.0175878 0.00435612"/>
        <joint name="RF_HAA" pos="0 0 0" axis="0.999995 -0.00296262 -0.000521746" range="-0.723301 0.677666" armature="0.0135662" damping="0.00899047" frictionloss="0.0863634"/>
        <geom name="//unnamed_geom_59" class="visual" pos="0 -0.000261291 -4.29171e-05" quat="0.258819 0.965926 0 0" material="hip_r" mesh="hip_r"/>
        <geom name="//unnamed_geom_60" class="visual" pos="0.0819435 0.0992634 -0.0554052" quat="0.183013 0.683013 0.683013 -0.183013" material="drive" mesh="drive"/>
        <geom name="//unnamed_geom_61" class="collision" size="0.0642678 0.089975" pos="0.0819435 0.0164182 -0.00770104" quat="-0.353553 0.612372 0.612372 0.353553"/>
        <body name="RF_THIGH" pos="0.0736191 0.100714 -0.0342833" quat="0.181694 0.68486 0.682012 -0.181145">
          <inertial pos="0.0416431 0.000428129 -0.258673" quat="0.982865 -0.00776306 -0.164319 0.0831626" mass="4.88648" diaginertia="0.130906 0.118692 0.00588341"/>
          <joint name="RF_HFE" pos="0 0 0" axis="0.999928 -0.00408491 0.0112638" stiffness="0.0130128" range="-2.83925 2.89052" armature="0.0202707" damping="0.0175114" frictionloss="0.0972406"/>
          <geom name="//unnamed_geom_62" class="visual" pos="-9.50132e-05 -1.49719e-07 0" quat="0.707107 0 0 -0.707107" material="thigh" mesh="thigh"/>
          <geom name="//unnamed_geom_63" class="collision" size="0.0835482 0.0514143" pos="0.0547202 0 0" quat="0.5 0.5 0.5 0.5"/>
          <geom name="//unnamed_geom_64" class="collision" size="0.0482009 0.0385607 0.181639" pos="0.0410402 0 -0.157605" quat="0.707107 0 0 0.707107" type="box"/>
          <geom name="//unnamed_geom_65" class="visual" pos="0.137211 0 -0.317856" quat="1 0 0 0" material="drive" mesh="drive"/>
          <geom name="//unnamed_geom_66" class="collision" size="0.0642678 0.089975" pos="0.0414506 0 -0.317856" quat="0.707107 0 0.707107 0"/>
          <geom name="//unnamed_geom_67" class="reward_collision_sphere" size="0.102829" pos="0.0342001 0 0"/>
          <body name="RF_SHANK" pos="0.1341 -0.00238346 -0.318501" quat="1 -0.000317377 -0.000257328 -0.000107405">
            <inertial pos="0.00313996 0.0831039 -0.106928" quat="0.988383 0.146388 0.0330923 0.0239653" mass="1.74557" diaginertia="0.0534441 0.043387 0.00276067"/>
            <joint name="RF_KFE" pos="0 0 0" axis="0.99954 -0.012591 -0.0275907" range="-3.15301 3.32114" armature="0.00544593" damping="0.0120812" frictionloss="0.126084"/>
            <geom name="//unnamed_geom_68" class="visual" pos="-3.09816e-05 0.000165196 0" quat="0.707107 0 0 0.707107" material="shank" mesh="shank_r"/>
            <geom name="RF_kfe_act" class="collision" size="0.0771214 0.0257071" pos="0.0273601 0 0" quat="0.5 0.5 0.5 0.5"/>
            <geom name="//unnamed_geom_70" class="collision" size="0.0739067 0.0433808 0.0244218" pos="0.0273601 0.0789335 0" quat="0.5 0.5 0.5 0.5" type="box"/>
            <geom name="//unnamed_geom_71" class="visual" pos="0.0178525 0.120789 -0.376933" quat="0.382683 0 0 0.92388" material="foot" mesh="foot"/>
            <geom name="RF_calf" class="collision" size="0.0224937 0.181559" pos="0.0178525 0.120736 -0.188466" quat="0.707107 0 0 0.707107"/>
            <geom name="RF_foot" class="foot" size="0.0290534" pos="0.0178525 0.120736 -0.351839" quat="0.707107 0 0 0.707107"/>
            <geom name="//unnamed_geom_74" class="reward_collision_sphere" size="0.128536" pos="-0.0684003 0 0"/>
            <geom name="//unnamed_geom_75" class="reward_collision_sphere" size="0.0642678" pos="0.0178525 0.120736 -0.351839"/>
            <site name="RF_foot" class="foot" pos="0.0178525 0.120736 -0.351839" quat="0.707107 0 0 0.707107" size="0.0128536"/>
          </body>
        </body>
      </body>
      <body name="LH_HIP" pos="-0.406017 0.151193 0.0146454" quat="2.13574e-05 -0.000154167 0.965913 -0.258865">
        <inertial pos="0.0773467 0.0232948 0.0051511" quat="0.119343 0.684179 0.127151 0.708159" mass="5.0291" diaginertia="0.0242207 0.0282949 0.00572849"/>
        <joint name="LH_HAA" pos="0 0 0" axis="0.999982 0.00570905 -0.00166064" range="-0.814869 0.434118" armature="0.0120513" damping="0.0577622" frictionloss="0.0368204"/>
        <geom name="//unnamed_geom_76" class="visual" pos="0 -0.000261291 -4.29171e-05" quat="-0.258819 -0.965926 0 0" material="hip_r" mesh="hip_r"/>
        <geom name="//unnamed_geom_77" class="visual" pos="0.0819435 0.0992634 -0.0554052" quat="0.183013 0.683013 0.683013 -0.183013" material="drive" mesh="drive"/>
        <geom name="//unnamed_geom_78" class="collision" size="0.0642678 0.089975" pos="0.0819435 0.0164182 -0.00770104" quat="-0.353553 0.612372 0.612372 0.353553"/>
        <body name="LH_THIGH" pos="0.0798999 0.104933 -0.0500968" quat="0.183049 0.683186 0.682855 -0.18292">
          <inertial pos="0.0561096 -0.0038732 -0.25746" quat="0.993179 0.0609909 -0.0568416 0.0815133" mass="6.20842" diaginertia="0.155767 0.130026 0.0077125"/>
          <joint name="LH_HFE" pos="0 0 0" axis="0.997584 -0.0660514 0.0215481" stiffness="0.0319513" range="-2.8559 3.22789" armature="0.00822811" damping="0" frictionloss="0.132484"/>
          <geom name="//unnamed_geom_79" class="visual" pos="-9.50132e-05 -1.49719e-07 0" quat="0.707107 0 0 -0.707107" material="thigh" mesh="thigh"/>
          <geom name="//unnamed_geom_80" class="collision" size="0.0835482 0.0514143" pos="0.0547202 0 0" quat="0.5 0.5 -0.5 -0.5"/>
          <geom name="//unnamed_geom_81" class="collision" size="0.0482009 0.0385607 0.181639" pos="0.0410402 0 -0.157605" quat="0.707107 0 0 -0.707107" type="box"/>
          <geom name="//unnamed_geom_82" class="visual" pos="0.137211 0 -0.317856" quat="1 0 0 0" material="drive" mesh="drive"/>
          <geom name="//unnamed_geom_83" class="collision" size="0.0642678 0.089975" pos="0.0414506 0 -0.317856" quat="0.707107 0 0.707107 0"/>
          <geom name="//unnamed_geom_84" class="reward_collision_sphere" size="0.102829" pos="0.0342001 0 0"/>
          <body name="LH_SHANK" pos="0.147181 -0.00778811 -0.306009" quat="1 0.000297082 -0.000358763 0.000681325">
            <inertial pos="-0.00203199 0.0940274 -0.100678" quat="0.987107 0.15785 0.0216681 -0.015258" mass="1.43782" diaginertia="0.0485135 0.0409755 0.00209794"/>
            <joint name="LH_KFE" pos="0 0 0" axis="0.998999 -0.001018 0.0447143" stiffness="0.08345" range="-3.27154 3.13752" armature="0.00993979" damping="0" frictionloss="0.0660874"/>
            <geom name="//unnamed_geom_85" class="visual" pos="-3.09816e-05 0.000165196 0" quat="-0.707107 0 0 -0.707107" material="shank" mesh="shank_r"/>
            <geom name="LH_kfe_act" class="collision" size="0.0771214 0.0257071" pos="0.0273601 0 0" quat="0.5 0.5 -0.5 -0.5"/>
            <geom name="//unnamed_geom_87" class="collision" size="0.0739067 0.0433808 0.0244218" pos="0.0273601 0.0789335 0" quat="0.5 0.5 -0.5 -0.5" type="box"/>
            <geom name="//unnamed_geom_88" class="visual" pos="0.0178525 0.120789 -0.376933" quat="-0.382683 0 0 -0.92388" material="foot" mesh="foot"/>
            <geom name="LH_calf" class="collision" size="0.0224937 0.181559" pos="0.0178525 0.120736 -0.188466" quat="0.707107 0 0 -0.707107"/>
            <geom name="LH_foot" class="foot" size="0.0282524" pos="0.0178525 0.120736 -0.351839" quat="0.707107 0 0 -0.707107"/>
            <geom name="//unnamed_geom_91" class="reward_collision_sphere" size="0.128536" pos="-0.0684003 0 0"/>
            <geom name="//unnamed_geom_92" class="reward_collision_sphere" size="0.0642678" pos="0.0178525 0.120736 -0.351839"/>
            <site name="LH_foot" class="foot" pos="0.0178525 0.120736 -0.351839" quat="0.707107 0 0 -0.707107" size="0.0128536"/>
          </body>
        </body>
      </body>
      <body name="RH_HIP" pos="-0.411643 -0.136744 -0.00152629" quat="-0.00288808 0.00179818 -0.966178 -0.257854">
        <inertial pos="0.0766302 -0.0350639 0.00207618" quat="-0.12936 0.71121 -0.135208 0.677618" mass="6.38341" diaginertia="0.0353513 0.0303485 0.00688773"/>
        <joint name="RH_HAA" pos="0 0 0" axis="0.999499 -0.0254174 0.0188593" stiffness="0.00809486" range="-0.861183 0.744131" armature="0.0183802" damping="0.0729227" frictionloss="0.084441"/>
        <geom name="//unnamed_geom_93" class="visual" pos="0 0.000261293 -4.29172e-05" quat="-0.258819 0.965926 0 0" material="hip_l" mesh="hip_l"/>
        <geom name="//unnamed_geom_94" class="visual" pos="0.0819435 -0.0992634 -0.0554052" quat="-0.183013 0.683013 -0.683013 -0.183013" material="drive" mesh="drive"/>
        <geom name="//unnamed_geom_95" class="collision" size="0.0642678 0.089975" pos="0.0819435 -0.0164182 -0.00770104" quat="0.353553 0.612372 -0.612372 0.353553"/>
        <body name="RH_THIGH" pos="0.0775679 -0.102428 -0.0617241" quat="-0.182988 0.682784 -0.683261 -0.182964">
          <inertial pos="0.0523181 -0.0113547 -0.274844" quat="0.993418 -0.00480954 -0.0814078 0.0804386" mass="8.78882" diaginertia="0.151207 0.17494 0.0070526"/>
          <joint name="RH_HFE" pos="0 0 0" axis="0.999394 -0.00268112 -0.034719" range="-2.84001 2.8567" armature="0.0115803" damping="0.000190783" frictionloss="0.212121"/>
          <geom name="//unnamed_geom_96" class="visual" pos="-9.50132e-05 -1.49719e-07 0" quat="0.707107 0 0 -0.707107" material="thigh" mesh="thigh"/>
          <geom name="//unnamed_geom_97" class="collision" size="0.0835482 0.0514143" pos="0.0547202 0 0" quat="0.5 0.5 0.5 0.5"/>
          <geom name="//unnamed_geom_98" class="collision" size="0.0482009 0.0385607 0.181639" pos="0.0410402 0 -0.157605" quat="0.707107 0 0 0.707107" type="box"/>
          <geom name="//unnamed_geom_99" class="visual" pos="0.137211 0 -0.317856" quat="1 0 0 0" material="drive" mesh="drive"/>
          <geom name="//unnamed_geom_100" class="collision" size="0.0642678 0.089975" pos="0.0414506 0 -0.317856" quat="0.707107 0 0.707107 0"/>
          <geom name="//unnamed_geom_101" class="reward_collision_sphere" size="0.102829" pos="0.0342001 0 0"/>
          <body name="RH_SHANK" pos="0.121925 -0.00148997 -0.318433" quat="0.999998 0.000649018 0.00157063 0.000977684">
            <inertial pos="0.000781629 -0.084 -0.0906053" quat="0.992767 -0.113012 -0.0145543 -0.0378257" mass="1.6288" diaginertia="0.0585121 0.0526793 0.0021371"/>
            <joint name="RH_KFE" pos="0 0 0" axis="0.998925 0.0444795 -0.0130689" stiffness="0.0466234" range="-3.09324 2.94702" armature="0.0177585" damping="0.0806233" frictionloss="0.132457"/>
            <geom name="//unnamed_geom_102" class="visual" pos="-3.09817e-05 -0.000165196 0" quat="0.707107 0 0 -0.707107" material="shank_l" mesh="shank_l"/>
            <geom name="RH_kfe_act" class="collision" size="0.0771214 0.0257071" pos="0.0273601 0 0" quat="0.5 0.5 0.5 0.5"/>
            <geom name="//unnamed_geom_104" class="collision" size="0.0739067 0.0433808 0.0244218" pos="0.0273601 -0.0789335 0" quat="0.5 0.5 0.5 0.5" type="box"/>
            <geom name="//unnamed_geom_105" class="visual" pos="0.0178525 -0.120789 -0.376933" quat="0.382683 0 0 -0.92388" material="foot" mesh="foot"/>
            <geom name="RH_calf" class="collision" size="0.0224937 0.181559" pos="0.0178525 -0.120736 -0.188466" quat="0.707107 0 0 0.707107"/>
            <geom name="RH_foot" class="foot" size="0.0451913" pos="0.0178525 -0.120736 -0.351839" quat="0.707107 0 0 0.707107"/>
            <geom name="//unnamed_geom_108" class="reward_collision_sphere" size="0.128536" pos="-0.0684003 0 0"/>
            <geom name="//unnamed_geom_109" class="reward_collision_sphere" size="0.0642678" pos="0.0178525 -0.120736 -0.351839"/>
            <site name="RH_foot" class="foot" pos="0.0178525 -0.120736 -0.351839" quat="0.707107 0 0 0.707107" size="0.0128536"/>
          </body>
        </body>
      </body>
    </body>
  </worldbody>

  <contact>
    <pair class="/" geom1="floor" geom2="LF_foot" name="//unnamed_contact_0"/>
    <pair class="/" geom1="floor" geom2="RF_foot" name="//unnamed_contact_1"/>
    <pair class="/" geom1="floor" geom2="LH_foot" name="//unnamed_contact_2"/>
    <pair class="/" geom1="floor" geom2="RH_foot" name="//unnamed_contact_3"/>
  </contact>

  <actuator>
    <general name="LF_HAA" class="/" joint="LF_HAA" forcerange="-87.1523 87.1523" gainprm="119.523" biasprm="0 -119.523 -1.67726"/>
    <general name="LF_HFE" class="/" joint="LF_HFE" forcerange="-51.5589 51.5589" gainprm="119.523" biasprm="0 -119.523 -1.67726"/>
    <general name="LF_KFE" class="/" joint="LF_KFE" forcerange="-158.445 158.445" gainprm="119.523" biasprm="0 -119.523 -1.67726"/>
    <general name="RF_HAA" class="/" joint="RF_HAA" forcerange="-93.4673 93.4673" gainprm="119.523" biasprm="0 -119.523 -1.67726"/>
    <general name="RF_HFE" class="/" joint="RF_HFE" forcerange="-64.3686 64.3686" gainprm="119.523" biasprm="0 -119.523 -1.67726"/>
    <general name="RF_KFE" class="/" joint="RF_KFE" forcerange="-37.2551 37.2551" gainprm="119.523" biasprm="0 -119.523 -1.67726"/>
    <general name="LH_HAA" class="/" joint="LH_HAA" forcerange="-46.5708 46.5708" gainprm="119.523" biasprm="0 -119.523 -1.67726"/>
    <general name="LH_HFE" class="/" joint="LH_HFE" forcerange="-70.3439 70.3439" gainprm="119.523" biasprm="0 -119.523 -1.67726"/>
    <general name="LH_KFE" class="/" joint="LH_KFE" forcerange="-101.57 101.57" gainprm="119.523" biasprm="0 -119.523 -1.67726"/>
    <general name="RH_HAA" class="/" joint="RH_HAA" forcerange="-107.655 107.655" gainprm="119.523" biasprm="0 -119.523 -1.67726"/>
    <general name="RH_HFE" class="/" joint="RH_HFE" forcerange="-165.486 165.486" gainprm="119.523" biasprm="0 -119.523 -1.67726"/>
    <general name="RH_KFE" class="/" joint="RH_KFE" forcerange="-151.524 151.524" gainprm="119.523" biasprm="0 -119.523 -1.67726"/>
  </actuator>

  <sensor>
    <gyro site="imu" name="imu_angular_velocity"/>
    <velocimeter site="imu" name="imu_linear_velocity"/>
    <framelinvel objtype="site" objname="LF_foot" name="LF_foot_global_linear_velocity"/>
    <framelinvel objtype="site" objname="RF_foot" name="RF_foot_global_linear_velocity"/>
    <framelinvel objtype="site" objname="LH_foot" name="LH_foot_global_linear_velocity"/>
    <framelinvel objtype="site" objname="RH_foot" name="RH_foot_global_linear_velocity"/>
  </sensor>

  <keyframe>
    <key name="home" qpos="0 0 0.55 1 0 0 0 0 0.4 -0.8 0 -0.4 0.8 0 -0.4 0.8 0 0.4 -0.8"/>
  </keyframe>
</mujoco>
