<mujoco model="anymal_c">
  <compiler angle="radian" assetdir="assets" balanceinertia="true" inertiafromgeom="false"/>

  <option timestep="0.005" density="1.2" viscosity="2e-05"/>

  <size nkey="1"/>

  <visual>
    <quality shadowsize="8192"/>
    <map shadowclip="0.5"/>
  </visual>

  <default>
    <default class="/">
      <material specular="0" shininess="0.25"/>
      <geom contype="0" conaffinity="0" group="1" solref="-1000 -80"/>
      <site size="0.01 0.005 0.005" group="5"/>
      <general forcelimited="true" forcerange="-80 80" biastype="affine" gainprm="80" biasprm="0 -80 -2"/>
      <default class="anymal_c">
        <joint armature="0.01" damping="0.01" frictionloss="0.1"/>
        <default class="visual">
          <geom type="mesh" group="2"/>
          <default class="visual_zflip"/>
        </default>
        <default class="collision">
          <geom type="cylinder" group="3"/>
          <default class="foot">
            <geom size="0.03 0 0" type="sphere" condim="6" priority="1" friction="0.8 0.02 0.01" solimp="0.015 1 0.03"/>
          </default>
        </default>
      </default>
      <default class="reward_collision_sphere">
        <geom group="5" rgba="1 0 0 1"/>
      </default>
    </default>
  </default>

  <asset>
    <texture type="skybox" colorspace="auto" name="//unnamed_texture_0" builtin="gradient" rgb1="0.95 0.95 0.95" rgb2="0.95 0.95 0.95" width="100" height="600"/>
    <texture type="2d" colorspace="auto" name="texplane" builtin="checker" rgb1="0.345 0.575 0.748" rgb2="0.345 0.575 0.748" markrgb="1 1 1" width="512" height="512"/>
    <texture type="2d" colorspace="linear" name="base" file="base.png"/>
    <texture type="2d" colorspace="linear" name="top_shell" file="top_shell.png"/>
    <texture type="2d" colorspace="linear" name="bottom_shell" file="bottom_shell.png"/>
    <texture type="2d" colorspace="linear" name="remote" file="remote.png"/>
    <texture type="2d" colorspace="linear" name="hatch" file="hatch.png"/>
    <texture type="2d" colorspace="linear" name="handle" file="handle.png"/>
    <texture type="2d" colorspace="linear" name="face" file="face.png"/>
    <texture type="2d" colorspace="linear" name="battery" file="battery.png"/>
    <texture type="2d" colorspace="linear" name="lidar_cage" file="lidar_cage.png"/>
    <texture type="2d" colorspace="linear" name="depth_camera" file="depth_camera.png"/>
    <texture type="2d" colorspace="linear" name="wide_angle_camera" file="wide_angle_camera.png"/>
    <texture type="2d" colorspace="linear" name="lidar" file="lidar.png"/>
    <texture type="2d" colorspace="linear" name="drive" file="drive.png"/>
    <texture type="2d" colorspace="linear" name="hip_l" file="hip_l.png"/>
    <texture type="2d" colorspace="linear" name="shank_l" file="shank_l.png"/>
    <texture type="2d" colorspace="linear" name="foot" file="foot.png"/>
    <texture type="2d" colorspace="linear" name="thigh" file="thigh.png"/>
    <texture type="2d" colorspace="linear" name="shank_r" file="shank_r.png"/>
    <texture type="2d" colorspace="linear" name="hip_r" file="hip_r.png"/>
    <material name="MatPlane" class="/" texture="texplane" texuniform="true" texrepeat="2 2" specular="0.9" shininess="0.5"/>
    <material name="black_plastic" class="/" rgba="0.007 0.007 0.007 1"/>
    <material name="green" class="/" rgba="0.052 0.178 0.033 1"/>
    <material name="red" class="/" rgba="0.178 0.006 0.005 1"/>
    <material name="yellow" class="/" rgba="0.178 0.119 0.006 1"/>
    <material name="lwl" class="/" rgba="0.8 0.8 0.8 1"/>
    <material name="base" class="/" texture="base"/>
    <material name="top_shell" class="/" texture="top_shell"/>
    <material name="bottom_shell" class="/" texture="bottom_shell"/>
    <material name="hip_l" class="/" texture="hip_l"/>
    <material name="thigh" class="/" texture="thigh"/>
    <material name="shank_l" class="/" texture="shank_l"/>
    <material name="foot" class="/" texture="foot"/>
    <material name="hip_r" class="/" texture="hip_r"/>
    <material name="shank" class="/" texture="shank_r"/>
    <material name="hatch" class="/" texture="hatch"/>
    <material name="remote" class="/" texture="remote"/>
    <material name="handle" class="/" texture="handle"/>
    <material name="face" class="/" texture="face"/>
    <material name="depth_camera" class="/" texture="depth_camera"/>
    <material name="wide_angle_camera" class="/" texture="wide_angle_camera"/>
    <material name="battery" class="/" texture="battery"/>
    <material name="lidar_cage" class="/" texture="lidar_cage"/>
    <material name="lidar" class="/" texture="lidar"/>
    <material name="drive" class="/" texture="drive"/>
    <mesh name="base_0" class="/" file="base_0.obj"/>
    <mesh name="base_1" class="/" file="base_1.obj"/>
    <mesh name="base_2" class="/" file="base_2.obj"/>
    <mesh name="base_3" class="/" file="base_3.obj"/>
    <mesh name="base_4" class="/" file="base_4.obj"/>
    <mesh name="base_5" class="/" file="base_5.obj"/>
    <mesh name="top_shell" class="/" file="top_shell.obj"/>
    <mesh name="bottom_shell" class="/" file="bottom_shell.obj"/>
    <mesh name="remote" class="/" file="remote.obj"/>
    <mesh name="handle" class="/" file="handle.obj"/>
    <mesh name="face" class="/" file="face.obj"/>
    <mesh name="wide_angle_camera" class="/" file="wide_angle_camera.obj"/>
    <mesh name="depth_camera" class="/" file="depth_camera.obj"/>
    <mesh name="battery" class="/" file="battery.obj"/>
    <mesh name="lidar_cage" class="/" file="lidar_cage.obj"/>
    <mesh name="lidar" class="/" file="lidar.obj"/>
    <mesh name="drive" class="/" file="drive.obj"/>
    <mesh name="hip_l" class="/" file="hip_l.obj"/>
    <mesh name="thigh" class="/" file="thigh.obj"/>
    <mesh name="shank_l" class="/" file="shank_l.obj"/>
    <mesh name="foot" class="/" file="foot.obj"/>
    <mesh name="hip_r" class="/" file="hip_r.obj"/>
    <mesh name="hatch" class="/" file="hatch.obj"/>
    <mesh name="shank_r" class="/" file="shank_r.obj"/>
  </asset>

  <worldbody>
    <geom name="floor" class="/" size="100 100 0.125" type="plane" group="0" material="MatPlane"/>
    <light name="toplight_shadow" class="/" pos="0 0 5" dir="0.0990148 0.0990148 -0.990148" type="directional" ambient="0.04 0.04 0.04" diffuse="0.55 0.55 0.55" specular="0.12 0.12 0.12"/>
    <light name="toplight_fill" class="/" pos="0 0 5" dir="0.0990148 0.0990148 -0.990148" type="directional" castshadow="false" ambient="0.04 0.04 0.04" diffuse="0.3 0.3 0.3" specular="0.08 0.08 0.08"/>
    <body name="trunk" childclass="anymal_c" pos="0.0103736 -0.00258757 0.00777722" quat="0.999989 0.00384757 -0.0011267 -0.00240601">
      <inertial pos="0.0112902 -0.0082739 0.0539452" quat="0.448727 0.512507 0.522854 0.512449" mass="33.5116" diaginertia="1.93381 2.50368 0.267666"/>
      <joint name="//unnamed_joint_0" type="free" armature="0" damping="0" frictionloss="0"/>
      <geom name="//unnamed_geom_1" class="visual" material="green" mesh="base_0"/>
      <geom name="//unnamed_geom_2" class="visual" material="yellow" mesh="base_1"/>
      <geom name="//unnamed_geom_3" class="visual" material="red" mesh="base_2"/>
      <geom name="//unnamed_geom_4" class="visual" material="black_plastic" mesh="base_3"/>
      <geom name="//unnamed_geom_5" class="visual" material="lwl" mesh="base_4"/>
      <geom name="//unnamed_geom_6" class="visual" material="base" mesh="base_5"/>
      <geom name="trunk_1" class="collision" size="0.364819 0.0880598 0.11322" type="box"/>
      <geom name="trunk_2" class="collision" size="0.11322 0.0912048" pos="0.28893 0.093326 0" quat="0.707107 0 0.707107 0"/>
      <geom name="trunk_3" class="collision" size="0.11322 0.0912048" pos="-0.28893 0.093326 0" quat="0.707107 0 0.707107 0"/>
      <geom name="trunk_4" class="collision" size="0.11322 0.0912048" pos="0.28893 -0.093326 0" quat="0.707107 0 0.707107 0"/>
      <geom name="trunk_5" class="collision" size="0.11322 0.0912048" pos="-0.28893 -0.093326 0" quat="0.707107 0 0.707107 0"/>
      <geom name="//unnamed_geom_12" class="visual" material="top_shell" mesh="top_shell"/>
      <geom name="//unnamed_geom_13" class="visual" material="bottom_shell" mesh="bottom_shell"/>
      <geom name="//unnamed_geom_14" class="visual" material="remote" mesh="remote"/>
      <geom name="//unnamed_geom_15" class="visual" material="handle" mesh="handle"/>
      <geom name="//unnamed_geom_16" class="visual" pos="0.550628 0 0" quat="1 0 0 0" material="face" mesh="face"/>
      <geom name="trunk_6" class="collision" size="0.0691898 0.0880598 0.11322" pos="0.623691 0 0" type="box"/>
      <geom name="//unnamed_geom_18" class="collision" size="0.11322 0.0691898" pos="0.623691 0.093326 0" quat="0.707107 0 0.707107 0"/>
      <geom name="//unnamed_geom_19" class="collision" size="0.11322 0.0691898" pos="0.623691 -0.093326 0" quat="0.707107 0 0.707107 0"/>
      <geom name="//unnamed_geom_20" class="visual" pos="0.613254 0 -0.0308384" quat="0.965926 0 0.258819 0" material="depth_camera" mesh="depth_camera"/>
      <geom name="//unnamed_geom_21" class="visual" pos="0.681477 0 0.0166518" material="wide_angle_camera" mesh="wide_angle_camera"/>
      <geom name="//unnamed_geom_22" class="visual_zflip" pos="-0.550628 0 0" quat="0 0 0 1" material="face" mesh="face"/>
      <geom name="trunk_7" class="collision" size="0.0691898 0.0880598 0.11322" pos="-0.623691 0 0" quat="0 0 0 1" type="box"/>
      <geom name="//unnamed_geom_24" class="collision" size="0.11322 0.0691898" pos="-0.623691 -0.093326 0" quat="0 -0.707107 0 0.707107"/>
      <geom name="//unnamed_geom_25" class="collision" size="0.11322 0.0691898" pos="-0.623691 0.093326 0" quat="0 -0.707107 0 0.707107"/>
      <geom name="//unnamed_geom_26" class="visual" pos="-0.613254 0 -0.0308384" quat="0 -0.258819 0 0.965926" material="depth_camera" mesh="depth_camera"/>
      <geom name="//unnamed_geom_27" class="visual_zflip" pos="-0.681477 0 0.0166518" quat="0 0 0 1" material="wide_angle_camera" mesh="wide_angle_camera"/>
      <geom name="//unnamed_geom_28" class="visual" material="battery" mesh="battery"/>
      <geom name="//unnamed_geom_29" class="visual" pos="0 0.101993 0.0339558" quat="0.683013 -0.183013 0.183013 0.683013" material="depth_camera" mesh="depth_camera"/>
      <geom name="//unnamed_geom_30" class="visual" pos="0 -0.101993 0.0339558" quat="0.683013 0.183013 0.183013 -0.683013" material="depth_camera" mesh="depth_camera"/>
      <geom name="//unnamed_geom_31" class="visual" pos="-0.483543 0 0.0817575" quat="1 0 0 0" material="lidar_cage" mesh="lidar_cage"/>
      <geom name="trunk_8" class="collision" size="0.0880598 0.0754798" pos="-0.483543 0 0.148498"/>
      <geom name="//unnamed_geom_33" class="visual" pos="-0.483543 1.89111e-06 0.158176" quat="0.707107 0 0 -0.707107" material="lidar" mesh="lidar"/>
      <geom name="//unnamed_geom_34" class="visual" pos="0.398392 0.138577 3.81023e-09" quat="0.258819 0.965926 0 0" material="drive" mesh="drive"/>
      <geom name="//unnamed_geom_35" class="visual" pos="0.398392 -0.138577 -3.81023e-09" quat="0.258819 -0.965926 0 0" material="drive" mesh="drive"/>
      <geom name="//unnamed_geom_36" class="visual" pos="-0.398392 0.138577 -3.81023e-09" quat="0 0 0.965926 -0.258819" material="drive" mesh="drive"/>
      <geom name="//unnamed_geom_37" class="visual" pos="-0.398392 -0.138577 3.81023e-09" quat="0 0 -0.965926 -0.258819" material="drive" mesh="drive"/>
      <geom name="//unnamed_geom_38" class="visual" pos="0.154096 0 0.0812014" quat="1 0 0 0" material="hatch" mesh="hatch"/>
      <geom name="//unnamed_geom_39" class="reward_collision_sphere" size="0.15096"/>
      <geom name="//unnamed_geom_40" class="reward_collision_sphere" size="0.15096" pos="0.597787 0 0"/>
      <geom name="//unnamed_geom_41" class="reward_collision_sphere" size="0.15096" pos="-0.597787 0 0"/>
      <site name="imu" pos="0.288588 0.0892832 0.0809728" size="0.01258"/>
      <camera name="track" pos="0 -2.66646 0" quat="0.707107 0.707107 0 0" mode="trackcom"/>
      <camera name="ego_camera" pos="0.597787 0 -0.0444939" quat="-0.5 -0.5 0.5 0.5"/>
      <body name="LF_HIP" pos="0.398141 0.138912 0.00577488" quat="0.265423 0.964126 -0.00288298 -0.00164654">
        <inertial pos="0.0832181 -0.0212946 -0.00464885" quat="-0.123846 0.741781 -0.152791 0.641154" mass="4.54756" diaginertia="0.0201952 0.017325 0.00417561"/>
        <joint name="LF_HAA" pos="0 0 0" axis="0.999134 -0.0021216 0.0415539" range="-0.990458 0.457088" armature="0.0052234" damping="0.0055656" frictionloss="0.143075"/>
        <geom name="//unnamed_geom_42" class="visual" pos="0 0.000224138 -3.68145e-05" quat="0.258819 -0.965926 0 0" material="hip_l" mesh="hip_l"/>
        <geom name="//unnamed_geom_43" class="visual" pos="0.0795721 -0.0964034 -0.0540248" quat="0.183013 -0.683013 0.683013 0.183013" material="drive" mesh="drive"/>
        <geom name="//unnamed_geom_44" class="collision" size="0.0628999 0.0880598" pos="0.0795721 -0.0159451 -0.00768076" quat="-0.353553 -0.612372 0.612372 -0.353553"/>
        <body name="LF_THIGH" pos="0.0797392 -0.0930504 -0.0427031" quat="0.183042 -0.68282 0.683225 0.182908">
          <inertial pos="0.0416427 0.0137197 -0.257617" quat="0.992333 0.0161533 -0.092205 0.0807026" mass="6.28841" diaginertia="0.1191 0.137531 0.0067529"/>
          <joint name="LF_HFE" pos="0 0 0" axis="0.99987 0.01246 -0.0102651" range="-3.12979 2.83976" armature="0.0180082" damping="0.0855928" frictionloss="0.123488"/>
          <geom name="//unnamed_geom_45" class="visual" pos="-9.57703e-05 -1.50912e-07 0" quat="0.707107 0 0 -0.707107" material="thigh" mesh="thigh"/>
          <geom name="//unnamed_geom_46" class="collision" size="0.0817698 0.0503199" pos="0.0531366 0 0" quat="0.5 0.5 -0.5 -0.5"/>
          <geom name="//unnamed_geom_47" class="collision" size="0.0471749 0.0377399 0.177773" pos="0.0398525 0 -0.15719" quat="0.707107 0 0 -0.707107" type="box"/>
          <geom name="//unnamed_geom_48" class="visual" pos="0.13324 0 -0.317019" quat="1 0 0 0" material="drive" mesh="drive"/>
          <geom name="//unnamed_geom_49" class="collision" size="0.0628999 0.0880598" pos="0.040251 0 -0.317019" quat="0.707107 0 0.707107 0"/>
          <geom name="//unnamed_geom_50" class="reward_collision_sphere" size="0.10064" pos="0.0332104 0 0"/>
          <body name="LF_SHANK" pos="0.117457 -0.0144503 -0.327072" quat="1 -0.00040196 2.97243e-05 0.000342401">
            <inertial pos="0.0122552 -0.0732808 -0.0996311" quat="0.993195 -0.112721 0.00091441 -0.0292712" mass="0.973635" diaginertia="0.0367993 0.0409065 0.00193398"/>
            <joint name="LF_KFE" pos="0 0 0" axis="0.9999 0.00392289 -0.0136025" stiffness="0.0749808" range="-3.33577 3.39534" armature="0.0136303" damping="0.0247038" frictionloss="0.14002"/>
            <geom name="//unnamed_geom_51" class="visual" pos="-3.12286e-05 -0.000166512 0" quat="0.707107 0 0 -0.707107" material="shank_l" mesh="shank_l"/>
            <geom name="LF_kfe_act" class="collision" size="0.0754798 0.0251599" pos="0.0265683 0 0" quat="0.5 0.5 -0.5 -0.5"/>
            <geom name="//unnamed_geom_53" class="collision" size="0.0723336 0.0424574 0.0239019" pos="0.0265683 -0.0766593 0" quat="0.5 0.5 -0.5 -0.5" type="box"/>
            <geom name="//unnamed_geom_54" class="visual" pos="0.0173358 -0.117311 -0.37594" quat="0.382683 0 0 -0.92388" material="foot" mesh="foot"/>
            <geom name="LF_calf" class="collision" size="0.0220149 0.177695" pos="0.0173358 -0.117257 -0.18797" quat="0.707107 0 0 -0.707107"/>
            <geom name="LF_foot" class="foot" size="0.0578394" pos="0.0173358 -0.117257 -0.350912" quat="0.707107 0 0 -0.707107"/>
            <geom name="//unnamed_geom_57" class="reward_collision_sphere" size="0.1258" pos="-0.0664208 0 0"/>
            <geom name="//unnamed_geom_58" class="reward_collision_sphere" size="0.0628999" pos="0.0173358 -0.117257 -0.350912"/>
            <site name="LF_foot" class="foot" pos="0.0173358 -0.117257 -0.350912" quat="0.707107 0 0 -0.707107" size="0.01258"/>
          </body>
        </body>
      </body>
      <body name="RF_HIP" pos="0.390909 -0.146551 -0.0140573" quat="0.258905 -0.965903 -0.000211927 2.01925e-05">
        <inertial pos="0.079974 0.030321 -0.00941495" quat="0.136173 0.67783 0.0601018 0.719994" mass="4.49336" diaginertia="0.0219251 0.0156366 0.00442002"/>
        <joint name="RF_HAA" pos="0 0 0" axis="0.99999 0.00373329 -0.00238769" range="-0.703574 0.696" armature="0.0130957" damping="0.0105581" frictionloss="0.0906551"/>
        <geom name="//unnamed_geom_59" class="visual" pos="0 -0.000224137 -3.68144e-05" quat="0.258819 0.965926 0 0" material="hip_r" mesh="hip_r"/>
        <geom name="//unnamed_geom_60" class="visual" pos="0.0795721 0.0964034 -0.0540248" quat="0.183013 0.683013 0.683013 -0.183013" material="drive" mesh="drive"/>
        <geom name="//unnamed_geom_61" class="collision" size="0.0628999 0.0880598" pos="0.0795721 0.0159451 -0.00768076" quat="-0.353553 0.612372 0.612372 0.353553"/>
        <body name="RF_THIGH" pos="0.0722294 0.0969082 -0.0351459" quat="0.180805 0.682378 0.684028 -0.18378">
          <inertial pos="0.0400451 5.06173e-05 -0.258941" quat="0.995679 -0.0303015 -0.0867213 0.0135653" mass="4.71214" diaginertia="0.113486 0.104432 0.00591185"/>
          <joint name="RF_HFE" pos="0 0 0" axis="0.999907 0.0126866 0.00492874" stiffness="0.0154702" range="-2.85906 2.91027" armature="0.0192576" damping="0.0142432" frictionloss="0.10124"/>
          <geom name="//unnamed_geom_62" class="visual" pos="-9.57703e-05 -1.50912e-07 0" quat="0.707107 0 0 -0.707107" material="thigh" mesh="thigh"/>
          <geom name="//unnamed_geom_63" class="collision" size="0.0817698 0.0503199" pos="0.0531366 0 0" quat="0.5 0.5 0.5 0.5"/>
          <geom name="//unnamed_geom_64" class="collision" size="0.0471749 0.0377399 0.177773" pos="0.0398525 0 -0.15719" quat="0.707107 0 0 0.707107" type="box"/>
          <geom name="//unnamed_geom_65" class="visual" pos="0.13324 0 -0.317019" quat="1 0 0 0" material="drive" mesh="drive"/>
          <geom name="//unnamed_geom_66" class="collision" size="0.0628999 0.0880598" pos="0.040251 0 -0.317019" quat="0.707107 0 0.707107 0"/>
          <geom name="//unnamed_geom_67" class="reward_collision_sphere" size="0.10064" pos="0.0332104 0 0"/>
          <body name="RF_SHANK" pos="0.130976 -0.00144595 -0.317183" quat="1 0.000289488 -2.30868e-05 0.000115368">
            <inertial pos="0.0038876 0.0815656 -0.105699" quat="0.987371 0.152276 -0.00416849 0.0435146" mass="1.60239" diaginertia="0.0462908 0.0376818 0.00266838"/>
            <joint name="RF_KFE" pos="0 0 0" axis="0.999672 -0.0176151 0.0186104" range="-3.13463 3.3015" armature="0.00590686" damping="0.00891001" frictionloss="0.125885"/>
            <geom name="//unnamed_geom_68" class="visual" pos="-3.12284e-05 0.000166512 0" quat="0.707107 0 0 0.707107" material="shank" mesh="shank_r"/>
            <geom name="RF_kfe_act" class="collision" size="0.0754798 0.0251599" pos="0.0265683 0 0" quat="0.5 0.5 0.5 0.5"/>
            <geom name="//unnamed_geom_70" class="collision" size="0.0723336 0.0424574 0.0239019" pos="0.0265683 0.0766593 0" quat="0.5 0.5 0.5 0.5" type="box"/>
            <geom name="//unnamed_geom_71" class="visual" pos="0.0173358 0.117311 -0.37594" quat="0.382683 0 0 0.92388" material="foot" mesh="foot"/>
            <geom name="RF_calf" class="collision" size="0.0220149 0.177695" pos="0.0173358 0.117257 -0.18797" quat="0.707107 0 0 0.707107"/>
            <geom name="RF_foot" class="foot" size="0.029823" pos="0.0173358 0.117257 -0.350912" quat="0.707107 0 0 0.707107"/>
            <geom name="//unnamed_geom_74" class="reward_collision_sphere" size="0.1258" pos="-0.0664208 0 0"/>
            <geom name="//unnamed_geom_75" class="reward_collision_sphere" size="0.0628999" pos="0.0173358 0.117257 -0.350912"/>
            <site name="RF_foot" class="foot" pos="0.0173358 0.117257 -0.350912" quat="0.707107 0 0 0.707107" size="0.01258"/>
          </body>
        </body>
      </body>
      <body name="LH_HIP" pos="-0.395093 0.146098 0.013655" quat="0.00016675 -0.000340936 0.966017 -0.258477">
        <inertial pos="0.0758925 0.0217569 0.00418572" quat="0.132865 0.671595 0.123907 0.718299" mass="4.73146" diaginertia="0.0209829 0.0239066 0.00565592"/>
        <joint name="LH_HAA" pos="0 0 0" axis="0.999989 0.0046113 -0.00109698" range="-0.795059 0.453916" armature="0.0120787" damping="0.0531472" frictionloss="0.0422591"/>
        <geom name="//unnamed_geom_76" class="visual" pos="0 -0.000224137 -3.68144e-05" quat="-0.258819 -0.965926 0 0" material="hip_r" mesh="hip_r"/>
        <geom name="//unnamed_geom_77" class="visual" pos="0.0795721 0.0964034 -0.0540248" quat="0.183013 0.683013 0.683013 -0.183013" material="drive" mesh="drive"/>
        <geom name="//unnamed_geom_78" class="collision" size="0.0628999 0.0880598" pos="0.0795721 0.0159451 -0.00768076" quat="-0.353553 0.612372 0.612372 0.353553"/>
        <body name="LH_THIGH" pos="0.0784093 0.101099 -0.049012" quat="0.183087 0.682938 0.683105 -0.182871">
          <inertial pos="0.0539009 -0.00292295 -0.257729" quat="0.992977 0.0443273 -0.0980882 0.0490873" mass="5.83179" diaginertia="0.134893 0.115123 0.00763359"/>
          <joint name="LH_HFE" pos="0 0 0" axis="0.997914 -0.0644017 -0.00444043" stiffness="0.027014" range="-2.87568 3.20866" armature="0.00871098" damping="0" frictionloss="0.124443"/>
          <geom name="//unnamed_geom_79" class="visual" pos="-9.57703e-05 -1.50912e-07 0" quat="0.707107 0 0 -0.707107" material="thigh" mesh="thigh"/>
          <geom name="//unnamed_geom_80" class="collision" size="0.0817698 0.0503199" pos="0.0531366 0 0" quat="0.5 0.5 -0.5 -0.5"/>
          <geom name="//unnamed_geom_81" class="collision" size="0.0471749 0.0377399 0.177773" pos="0.0398525 0 -0.15719" quat="0.707107 0 0 -0.707107" type="box"/>
          <geom name="//unnamed_geom_82" class="visual" pos="0.13324 0 -0.317019" quat="1 0 0 0" material="drive" mesh="drive"/>
          <geom name="//unnamed_geom_83" class="collision" size="0.0628999 0.0880598" pos="0.040251 0 -0.317019" quat="0.707107 0 0.707107 0"/>
          <geom name="//unnamed_geom_84" class="reward_collision_sphere" size="0.10064" pos="0.0332104 0 0"/>
          <body name="LH_SHANK" pos="0.142225 -0.0068089 -0.306162" quat="1 -6.49403e-05 8.46699e-05 0.000343873">
            <inertial pos="-0.00126445 0.0906203 -0.0994564" quat="0.992345 0.0968469 -0.0361391 0.0675663" mass="1.34423" diaginertia="0.0419385 0.0361697 0.0020637"/>
            <joint name="LH_KFE" pos="0 0 0" axis="0.999208 0.0124936 0.0377789" stiffness="0.0784489" range="-3.25208 3.13097" armature="0.010358" damping="0.00033187" frictionloss="0.0708678"/>
            <geom name="//unnamed_geom_85" class="visual" pos="-3.12284e-05 0.000166512 0" quat="-0.707107 0 0 -0.707107" material="shank" mesh="shank_r"/>
            <geom name="LH_kfe_act" class="collision" size="0.0754798 0.0251599" pos="0.0265683 0 0" quat="0.5 0.5 -0.5 -0.5"/>
            <geom name="//unnamed_geom_87" class="collision" size="0.0723336 0.0424574 0.0239019" pos="0.0265683 0.0766593 0" quat="0.5 0.5 -0.5 -0.5" type="box"/>
            <geom name="//unnamed_geom_88" class="visual" pos="0.0173358 0.117311 -0.37594" quat="-0.382683 0 0 -0.92388" material="foot" mesh="foot"/>
            <geom name="LH_calf" class="collision" size="0.0220149 0.177695" pos="0.0173358 0.117257 -0.18797" quat="0.707107 0 0 -0.707107"/>
            <geom name="LH_foot" class="foot" size="0.0290504" pos="0.0173358 0.117257 -0.350912" quat="0.707107 0 0 -0.707107"/>
            <geom name="//unnamed_geom_91" class="reward_collision_sphere" size="0.1258" pos="-0.0664208 0 0"/>
            <geom name="//unnamed_geom_92" class="reward_collision_sphere" size="0.0628999" pos="0.0173358 0.117257 -0.350912"/>
            <site name="LH_foot" class="foot" pos="0.0173358 0.117257 -0.350912" quat="0.707107 0 0 -0.707107" size="0.01258"/>
          </body>
        </body>
      </body>
      <body name="RH_HIP" pos="-0.399411 -0.133613 -0.00238195" quat="0.00189837 -0.00152334 -0.9664 -0.257031">
        <inertial pos="0.0752356 -0.0334698 0.00111354" quat="-0.128715 0.709694 -0.134897 0.679389" mass="6.00311" diaginertia="0.0298643 0.0256552 0.00673162"/>
        <joint name="RH_HAA" pos="0 0 0" axis="0.999641 -0.00804058 -0.0255773" stiffness="0.00756307" range="-0.84169 0.72439" armature="0.0174044" damping="0.0683417" frictionloss="0.0887808"/>
        <geom name="//unnamed_geom_93" class="visual" pos="0 0.000224138 -3.68145e-05" quat="-0.258819 0.965926 0 0" material="hip_l" mesh="hip_l"/>
        <geom name="//unnamed_geom_94" class="visual" pos="0.0795721 -0.0964034 -0.0540248" quat="-0.183013 0.683013 -0.683013 -0.183013" material="drive" mesh="drive"/>
        <geom name="//unnamed_geom_95" class="collision" size="0.0628999 0.0880598" pos="0.0795721 -0.0159451 -0.00768076" quat="0.353553 0.612372 -0.612372 0.353553"/>
        <body name="RH_THIGH" pos="0.0761619 -0.0998018 -0.06061" quat="-0.183239 0.683403 -0.682627 -0.18277">
          <inertial pos="0.0501147 -0.0103708 -0.273924" quat="0.993227 -0.00566613 -0.0839921 0.0800887" mass="8.06507" diaginertia="0.130931 0.147849 0.00698733"/>
          <joint name="RH_HFE" pos="0 0 0" axis="0.999553 0.0299057 0.000534627" range="-2.85981 2.87651" armature="0.0119191" damping="0" frictionloss="0.20139"/>
          <geom name="//unnamed_geom_96" class="visual" pos="-9.57703e-05 -1.50912e-07 0" quat="0.707107 0 0 -0.707107" material="thigh" mesh="thigh"/>
          <geom name="//unnamed_geom_97" class="collision" size="0.0817698 0.0503199" pos="0.0531366 0 0" quat="0.5 0.5 0.5 0.5"/>
          <geom name="//unnamed_geom_98" class="collision" size="0.0471749 0.0377399 0.177773" pos="0.0398525 0 -0.15719" quat="0.707107 0 0 0.707107" type="box"/>
          <geom name="//unnamed_geom_99" class="visual" pos="0.13324 0 -0.317019" quat="1 0 0 0" material="drive" mesh="drive"/>
          <geom name="//unnamed_geom_100" class="collision" size="0.0628999 0.0880598" pos="0.040251 0 -0.317019" quat="0.707107 0 0.707107 0"/>
          <geom name="//unnamed_geom_101" class="reward_collision_sphere" size="0.10064" pos="0.0332104 0 0"/>
          <body name="RH_SHANK" pos="0.118946 -0.00187236 -0.31753" quat="0.999999 -9.59174e-05 0.000994074 0.00109308">
            <inertial pos="0.00154128 -0.0818392 -0.0909362" quat="0.993185 -0.115948 -0.00180427 -0.0116861" mass="1.49419" diaginertia="0.0494045 0.0445127 0.00211075"/>
            <joint name="RH_KFE" pos="0 0 0" axis="0.999141 -0.0223581 0.0348997" stiffness="0.0416516" range="-3.10038 2.9667" armature="0.0168025" damping="0.0761869" frictionloss="0.124409"/>
            <geom name="//unnamed_geom_102" class="visual" pos="-3.12286e-05 -0.000166512 0" quat="0.707107 0 0 -0.707107" material="shank_l" mesh="shank_l"/>
            <geom name="RH_kfe_act" class="collision" size="0.0754798 0.0251599" pos="0.0265683 0 0" quat="0.5 0.5 0.5 0.5"/>
            <geom name="//unnamed_geom_104" class="collision" size="0.0723336 0.0424574 0.0239019" pos="0.0265683 -0.0766593 0" quat="0.5 0.5 0.5 0.5" type="box"/>
            <geom name="//unnamed_geom_105" class="visual" pos="0.0173358 -0.117311 -0.37594" quat="0.382683 0 0 -0.92388" material="foot" mesh="foot"/>
            <geom name="RH_calf" class="collision" size="0.0220149 0.177695" pos="0.0173358 -0.117257 -0.18797" quat="0.707107 0 0 0.707107"/>
            <geom name="RH_foot" class="foot" size="0.0428146" pos="0.0173358 -0.117257 -0.350912" quat="0.707107 0 0 0.707107"/>
            <geom name="//unnamed_geom_108" class="reward_collision_sphere" size="0.1258" pos="-0.0664208 0 0"/>
            <geom name="//unnamed_geom_109" class="reward_collision_sphere" size="0.0628999" pos="0.0173358 -0.117257 -0.350912"/>
            <site name="RH_foot" class="foot" pos="0.0173358 -0.117257 -0.350912" quat="0.707107 0 0 0.707107" size="0.01258"/>
          </body>
        </body>
      </body>
    </body>
  </worldbody>

  <contact>
    <pair class="/" geom1="floor" geom2="LF_foot" name="//unnamed_contact_0"/>
    <pair class="/" geom1="floor" geom2="RF_foot" name="//unnamed_contact_1"/>
    <pair class="/" geom1="floor" geom2="LH_foot" name="//unnamed_contact_2"/>
    <pair class="/" geom1="floor" geom2="RH_foot" name="//unnamed_contact_3"/>
  </contact>

  <actuator>
    <general name="LF_HAA" class="/" joint="LF_HAA" forcerange="-88.9565 88.9565" gainprm="114.506" biasprm="0 -114.506 -1.70428"/>
    <general name="LF_HFE" class="/" joint="LF_HFE" forcerange="-54.1946 54.1946" gainprm="114.506" biasprm="0 -114.506 -1.70428"/>
    <general name="LF_KFE" class="/" joint="LF_KFE" forcerange="-151.334 151.334" gainprm="114.506" biasprm="0 -114.506 -1.70428"/>
    <general name="RF_HAA" class="/" joint="RF_HAA" forcerange="-95.0546 95.0546" gainprm="114.506" biasprm="0 -114.506 -1.70428"/>
    <general name="RF_HFE" class="/" joint="RF_HFE" forcerange="-66.7271 66.7271" gainprm="114.506" biasprm="0 -114.506 -1.70428"/>
    <general name="RF_KFE" class="/" joint="RF_KFE" forcerange="-40.2046 40.2046" gainprm="114.506" biasprm="0 -114.506 -1.70428"/>
    <general name="LH_HAA" class="/" joint="LH_HAA" forcerange="-49.3169 49.3169" gainprm="114.506" biasprm="0 -114.506 -1.70428"/>
    <general name="LH_HFE" class="/" joint="LH_HFE" forcerange="-72.5573 72.5573" gainprm="114.506" biasprm="0 -114.506 -1.70428"/>
    <general name="LH_KFE" class="/" joint="LH_KFE" forcerange="-102.942 102.942" gainprm="114.506" biasprm="0 -114.506 -1.70428"/>
    <general name="RH_HAA" class="/" joint="RH_HAA" forcerange="-102.795 102.795" gainprm="114.506" biasprm="0 -114.506 -1.70428"/>
    <general name="RH_HFE" class="/" joint="RH_HFE" forcerange="-158.23 158.23" gainprm="114.506" biasprm="0 -114.506 -1.70428"/>
    <general name="RH_KFE" class="/" joint="RH_KFE" forcerange="-144.574 144.574" gainprm="114.506" biasprm="0 -114.506 -1.70428"/>
  </actuator>

  <sensor>
    <gyro site="imu" name="imu_angular_velocity"/>
    <velocimeter site="imu" name="imu_linear_velocity"/>
    <framelinvel objtype="site" objname="LF_foot" name="LF_foot_global_linear_velocity"/>
    <framelinvel objtype="site" objname="RF_foot" name="RF_foot_global_linear_velocity"/>
    <framelinvel objtype="site" objname="LH_foot" name="LH_foot_global_linear_velocity"/>
    <framelinvel objtype="site" objname="RH_foot" name="RH_foot_global_linear_velocity"/>
  </sensor>

  <keyframe>
    <key name="home" qpos="0 0 0.55 1 0 0 0 0 0.4 -0.8 0 -0.4 0.8 0 -0.4 0.8 0 0.4 -0.8"/>
  </keyframe>
</mujoco>
