<mujoco model="anymal_c">
  <compiler angle="radian" assetdir="assets" balanceinertia="true" inertiafromgeom="false"/>

  <option timestep="0.005" density="1.2" viscosity="2e-05"/>

  <size nkey="1"/>

  <visual>
    <quality shadowsize="8192"/>
    <map shadowclip="0.5"/>
  </visual>

  <default>
    <default class="/">
      <material specular="0" shininess="0.25"/>
      <geom contype="0" conaffinity="0" group="1" solref="-1000 -80"/>
      <site size="0.01 0.005 0.005" group="5"/>
      <general forcelimited="true" forcerange="-80 80" biastype="affine" gainprm="80" biasprm="0 -80 -2"/>
      <default class="anymal_c">
        <joint armature="0.01" damping="0.01" frictionloss="0.1"/>
        <default class="visual">
          <geom type="mesh" group="2"/>
          <default class="visual_zflip"/>
        </default>
        <default class="collision">
          <geom type="cylinder" group="3"/>
          <default class="foot">
            <geom size="0.03 0 0" type="sphere" condim="6" priority="1" friction="0.8 0.02 0.01" solimp="0.015 1 0.03"/>
          </default>
        </default>
      </default>
      <default class="reward_collision_sphere">
        <geom group="5" rgba="1 0 0 1"/>
      </default>
    </default>
  </default>

  <asset>
    <texture type="skybox" colorspace="auto" name="//unnamed_texture_0" builtin="gradient" rgb1="0.95 0.95 0.95" rgb2="0.95 0.95 0.95" width="100" height="600"/>
    <texture type="2d" colorspace="auto" name="texplane" builtin="checker" rgb1="0.345 0.575 0.748" rgb2="0.345 0.575 0.748" markrgb="1 1 1" width="512" height="512"/>
    <texture type="2d" colorspace="linear" name="base" file="base.png"/>
    <texture type="2d" colorspace="linear" name="top_shell" file="top_shell.png"/>
    <texture type="2d" colorspace="linear" name="bottom_shell" file="bottom_shell.png"/>
    <texture type="2d" colorspace="linear" name="remote" file="remote.png"/>
    <texture type="2d" colorspace="linear" name="hatch" file="hatch.png"/>
    <texture type="2d" colorspace="linear" name="handle" file="handle.png"/>
    <texture type="2d" colorspace="linear" name="face" file="face.png"/>
    <texture type="2d" colorspace="linear" name="battery" file="battery.png"/>
    <texture type="2d" colorspace="linear" name="lidar_cage" file="lidar_cage.png"/>
    <texture type="2d" colorspace="linear" name="depth_camera" file="depth_camera.png"/>
    <texture type="2d" colorspace="linear" name="wide_angle_camera" file="wide_angle_camera.png"/>
    <texture type="2d" colorspace="linear" name="lidar" file="lidar.png"/>
    <texture type="2d" colorspace="linear" name="drive" file="drive.png"/>
    <texture type="2d" colorspace="linear" name="hip_l" file="hip_l.png"/>
    <texture type="2d" colorspace="linear" name="shank_l" file="shank_l.png"/>
    <texture type="2d" colorspace="linear" name="foot" file="foot.png"/>
    <texture type="2d" colorspace="linear" name="thigh" file="thigh.png"/>
    <texture type="2d" colorspace="linear" name="shank_r" file="shank_r.png"/>
    <texture type="2d" colorspace="linear" name="hip_r" file="hip_r.png"/>
    <material name="MatPlane" class="/" texture="texplane" texuniform="true" texrepeat="2 2" specular="0.9" shininess="0.5"/>
    <material name="black_plastic" class="/" rgba="0.007 0.007 0.007 1"/>
    <material name="green" class="/" rgba="0.052 0.178 0.033 1"/>
    <material name="red" class="/" rgba="0.178 0.006 0.005 1"/>
    <material name="yellow" class="/" rgba="0.178 0.119 0.006 1"/>
    <material name="lwl" class="/" rgba="0.8 0.8 0.8 1"/>
    <material name="base" class="/" texture="base"/>
    <material name="top_shell" class="/" texture="top_shell"/>
    <material name="bottom_shell" class="/" texture="bottom_shell"/>
    <material name="hip_l" class="/" texture="hip_l"/>
    <material name="thigh" class="/" texture="thigh"/>
    <material name="shank_l" class="/" texture="shank_l"/>
    <material name="foot" class="/" texture="foot"/>
    <material name="hip_r" class="/" texture="hip_r"/>
    <material name="shank" class="/" texture="shank_r"/>
    <material name="hatch" class="/" texture="hatch"/>
    <material name="remote" class="/" texture="remote"/>
    <material name="handle" class="/" texture="handle"/>
    <material name="face" class="/" texture="face"/>
    <material name="depth_camera" class="/" texture="depth_camera"/>
    <material name="wide_angle_camera" class="/" texture="wide_angle_camera"/>
    <material name="battery" class="/" texture="battery"/>
    <material name="lidar_cage" class="/" texture="lidar_cage"/>
    <material name="lidar" class="/" texture="lidar"/>
    <material name="drive" class="/" texture="drive"/>
    <mesh name="base_0" class="/" file="base_0.obj"/>
    <mesh name="base_1" class="/" file="base_1.obj"/>
    <mesh name="base_2" class="/" file="base_2.obj"/>
    <mesh name="base_3" class="/" file="base_3.obj"/>
    <mesh name="base_4" class="/" file="base_4.obj"/>
    <mesh name="base_5" class="/" file="base_5.obj"/>
    <mesh name="top_shell" class="/" file="top_shell.obj"/>
    <mesh name="bottom_shell" class="/" file="bottom_shell.obj"/>
    <mesh name="remote" class="/" file="remote.obj"/>
    <mesh name="handle" class="/" file="handle.obj"/>
    <mesh name="face" class="/" file="face.obj"/>
    <mesh name="wide_angle_camera" class="/" file="wide_angle_camera.obj"/>
    <mesh name="depth_camera" class="/" file="depth_camera.obj"/>
    <mesh name="battery" class="/" file="battery.obj"/>
    <mesh name="lidar_cage" class="/" file="lidar_cage.obj"/>
    <mesh name="lidar" class="/" file="lidar.obj"/>
    <mesh name="drive" class="/" file="drive.obj"/>
    <mesh name="hip_l" class="/" file="hip_l.obj"/>
    <mesh name="thigh" class="/" file="thigh.obj"/>
    <mesh name="shank_l" class="/" file="shank_l.obj"/>
    <mesh name="foot" class="/" file="foot.obj"/>
    <mesh name="hip_r" class="/" file="hip_r.obj"/>
    <mesh name="hatch" class="/" file="hatch.obj"/>
    <mesh name="shank_r" class="/" file="shank_r.obj"/>
  </asset>

  <worldbody>
    <geom name="floor" class="/" size="100 100 0.125" type="plane" group="0" material="MatPlane"/>
    <light name="toplight_shadow" class="/" pos="0 0 5" dir="0.0990148 0.0990148 -0.990148" type="directional" ambient="0.04 0.04 0.04" diffuse="0.55 0.55 0.55" specular="0.12 0.12 0.12"/>
    <light name="toplight_fill" class="/" pos="0 0 5" dir="0.0990148 0.0990148 -0.990148" type="directional" castshadow="false" ambient="0.04 0.04 0.04" diffuse="0.3 0.3 0.3" specular="0.08 0.08 0.08"/>
    <body name="trunk" childclass="anymal_c" pos="-0.0019892 -0.000693392 -0.000629677" quat="1 -0.000463808 9.3832e-05 0.00059529">
      <inertial pos="0.00120626 0.00064757 0.0536655" quat="0.494935 0.49636 0.49808 0.510473" mass="15.8025" diaginertia="0.425 0.243578 0.323781"/>
      <joint name="//unnamed_joint_0" type="free" armature="0" damping="0" frictionloss="0"/>
      <geom name="//unnamed_geom_1" class="visual" material="green" mesh="base_0"/>
      <geom name="//unnamed_geom_2" class="visual" material="yellow" mesh="base_1"/>
      <geom name="//unnamed_geom_3" class="visual" material="red" mesh="base_2"/>
      <geom name="//unnamed_geom_4" class="visual" material="black_plastic" mesh="base_3"/>
      <geom name="//unnamed_geom_5" class="visual" material="lwl" mesh="base_4"/>
      <geom name="//unnamed_geom_6" class="visual" material="base" mesh="base_5"/>
      <geom name="trunk_1" class="collision" size="0.273215 0.0659484 0.0847908" type="box"/>
      <geom name="trunk_2" class="collision" size="0.0847908 0.0683037" pos="0.199617 0.0580551 0" quat="0.707107 0 0.707107 0"/>
      <geom name="trunk_3" class="collision" size="0.0847908 0.0683037" pos="-0.199617 0.0580551 0" quat="0.707107 0 0.707107 0"/>
      <geom name="trunk_4" class="collision" size="0.0847908 0.0683037" pos="0.199617 -0.0580551 0" quat="0.707107 0 0.707107 0"/>
      <geom name="trunk_5" class="collision" size="0.0847908 0.0683037" pos="-0.199617 -0.0580551 0" quat="0.707107 0 0.707107 0"/>
      <geom name="//unnamed_geom_12" class="visual" material="top_shell" mesh="top_shell"/>
      <geom name="//unnamed_geom_13" class="visual" material="bottom_shell" mesh="bottom_shell"/>
      <geom name="//unnamed_geom_14" class="visual" material="remote" mesh="remote"/>
      <geom name="//unnamed_geom_15" class="visual" material="handle" mesh="handle"/>
      <geom name="//unnamed_geom_16" class="visual" pos="0.38042 0 0" quat="1 0 0 0" material="face" mesh="face"/>
      <geom name="trunk_6" class="collision" size="0.0518166 0.0659484 0.0847908" pos="0.430897 0 0" type="box"/>
      <geom name="//unnamed_geom_18" class="collision" size="0.0847908 0.0518166" pos="0.430897 0.0580551 0" quat="0.707107 0 0.707107 0"/>
      <geom name="//unnamed_geom_19" class="collision" size="0.0847908 0.0518166" pos="0.430897 -0.0580551 0" quat="0.707107 0 0.707107 0"/>
      <geom name="//unnamed_geom_20" class="visual" pos="0.4237 0 -0.0327403" quat="0.965926 0 0.258819 0" material="depth_camera" mesh="depth_camera"/>
      <geom name="//unnamed_geom_21" class="visual" pos="0.470821 0 0.016156" material="wide_angle_camera" mesh="wide_angle_camera"/>
      <geom name="//unnamed_geom_22" class="visual_zflip" pos="-0.38042 0 0" quat="0 0 0 1" material="face" mesh="face"/>
      <geom name="trunk_7" class="collision" size="0.0518166 0.0659484 0.0847908" pos="-0.430897 0 0" quat="0 0 0 1" type="box"/>
      <geom name="//unnamed_geom_24" class="collision" size="0.0847908 0.0518166" pos="-0.430897 -0.0580551 0" quat="0 -0.707107 0 0.707107"/>
      <geom name="//unnamed_geom_25" class="collision" size="0.0847908 0.0518166" pos="-0.430897 0.0580551 0" quat="0 -0.707107 0 0.707107"/>
      <geom name="//unnamed_geom_26" class="visual" pos="-0.4237 0 -0.0327403" quat="0 -0.258819 0 0.965926" material="depth_camera" mesh="depth_camera"/>
      <geom name="//unnamed_geom_27" class="visual_zflip" pos="-0.470821 0 0.016156" quat="0 0 0 1" material="wide_angle_camera" mesh="wide_angle_camera"/>
      <geom name="//unnamed_geom_28" class="visual" material="battery" mesh="battery"/>
      <geom name="//unnamed_geom_29" class="visual" pos="0 0.0622592 0.0301244" quat="0.683013 -0.183013 0.183013 0.683013" material="depth_camera" mesh="depth_camera"/>
      <geom name="//unnamed_geom_30" class="visual" pos="0 -0.0622592 0.0301244" quat="0.683013 0.183013 0.183013 -0.683013" material="depth_camera" mesh="depth_camera"/>
      <geom name="//unnamed_geom_31" class="visual" pos="-0.334072 0 0.0793229" quat="1 0 0 0" material="lidar_cage" mesh="lidar_cage"/>
      <geom name="trunk_8" class="collision" size="0.0659484 0.0565272" pos="-0.334072 0 0.144076"/>
      <geom name="//unnamed_geom_33" class="visual" pos="-0.334072 -3.47382e-05 0.153465" quat="0.707107 0 0 -0.707107" material="lidar" mesh="lidar"/>
      <geom name="//unnamed_geom_34" class="visual" pos="0.275242 0.086342 -4.31019e-09" quat="0.258819 0.965926 0 0" material="drive" mesh="drive"/>
      <geom name="//unnamed_geom_35" class="visual" pos="0.275242 -0.086342 4.31019e-09" quat="0.258819 -0.965926 0 0" material="drive" mesh="drive"/>
      <geom name="//unnamed_geom_36" class="visual" pos="-0.275242 0.086342 4.31019e-09" quat="0 0 0.965926 -0.258819" material="drive" mesh="drive"/>
      <geom name="//unnamed_geom_37" class="visual" pos="-0.275242 -0.086342 -4.31019e-09" quat="0 0 -0.965926 -0.258819" material="drive" mesh="drive"/>
      <geom name="//unnamed_geom_38" class="visual" pos="0.106462 0 0.0787833" quat="1 0 0 0" material="hatch" mesh="hatch"/>
      <geom name="//unnamed_geom_39" class="reward_collision_sphere" size="0.113054"/>
      <geom name="//unnamed_geom_40" class="reward_collision_sphere" size="0.113054" pos="0.413001 0 0"/>
      <geom name="//unnamed_geom_41" class="reward_collision_sphere" size="0.113054" pos="-0.413001 0 0"/>
      <site name="imu" pos="0.233301 -0.00589204 0.0523397" size="0.0094212"/>
      <camera name="track" pos="0 -1.65872 0" quat="0.707107 0.707107 0 0" mode="trackcom"/>
      <camera name="ego_camera" pos="0.413001 0 -0.0431689" quat="-0.5 -0.5 0.5 0.5"/>
      <body name="LF_HIP" pos="0.276094 0.0873244 -0.00141205" quat="0.259872 0.965643 -0.000958189 0.000102449">
        <inertial pos="0.0513963 -0.0121621 -0.00783632" quat="-0.137878 0.706896 -0.136159 0.680256" mass="2.40076" diaginertia="0.0039424 0.00198689 0.0050245"/>
        <joint name="LF_HAA" pos="0 0 0" axis="0.99996 0.0030002 -0.00847713" range="-0.66552 0.496009" armature="0.0105206" damping="0.0091847" frictionloss="0.0979614"/>
        <geom name="//unnamed_geom_42" class="visual" pos="0 -0.000253549 4.16452e-05" quat="0.258819 -0.965926 0 0" material="hip_l" mesh="hip_l"/>
        <geom name="//unnamed_geom_43" class="visual" pos="0.054975 -0.0655385 -0.0396868" quat="0.183013 -0.683013 0.683013 0.183013" material="drive" mesh="drive"/>
        <geom name="//unnamed_geom_44" class="collision" size="0.047106 0.0659484" pos="0.054975 -0.00991896 -0.00745203" quat="-0.353553 -0.612372 0.612372 -0.353553"/>
        <body name="LF_THIGH" pos="0.0554656 -0.0605219 -0.0449515" quat="0.183099 -0.683012 0.68296 0.183125">
          <inertial pos="0.0279661 -0.00261112 -0.26766" quat="0.993499 -0.00158981 -0.0790253 0.0819262" mass="2.61459" diaginertia="0.0195917 0.0116641 0.00608595"/>
          <joint name="LF_HFE" pos="0 0 0" axis="0.999997 0.0014764 0.00181504" stiffness="0.000654583" range="-3.13828 3.19202" armature="0.00911076" damping="0" frictionloss="0.0940923"/>
          <geom name="//unnamed_geom_45" class="visual" pos="0.00175923 2.77213e-06 0" quat="0.707107 0 0 -0.707107" material="thigh" mesh="thigh"/>
          <geom name="//unnamed_geom_46" class="collision" size="0.0612378 0.0376848" pos="0.0367112 0 0" quat="0.5 0.5 -0.5 -0.5"/>
          <geom name="//unnamed_geom_47" class="collision" size="0.0353295 0.0282636 0.133135" pos="0.0275334 0 -0.152509" quat="0.707107 0 0 -0.707107" type="box"/>
          <geom name="//unnamed_geom_48" class="visual" pos="0.0920533 0 -0.307578" quat="1 0 0 0" material="drive" mesh="drive"/>
          <geom name="//unnamed_geom_49" class="collision" size="0.047106 0.0659484" pos="0.0278087 0 -0.307578" quat="0.707107 0 0.707107 0"/>
          <geom name="//unnamed_geom_50" class="reward_collision_sphere" size="0.0753696" pos="0.0229445 0 0"/>
          <body name="LF_SHANK" pos="0.0944226 0.00214145 -0.305711" quat="1 4.30448e-05 -1.59895e-05 -4.7355e-05">
            <inertial pos="0.00585654 -0.0517204 -0.0853071" quat="0.992908 -0.116054 -0.0009201 -0.0257804" mass="0.51082" diaginertia="0.00680065 0.00368919 0.00164535"/>
            <joint name="LF_KFE" pos="0 0 0" axis="0.999999 0.000811301 0.000812353" range="-3.10661 3.08684" armature="0.00926908" damping="0.0103397" frictionloss="0.0964783"/>
            <geom name="//unnamed_geom_51" class="visual" pos="0.000573646 0.00305871 0" quat="0.707107 0 0 -0.707107" material="shank_l" mesh="shank_l"/>
            <geom name="LF_kfe_act" class="collision" size="0.0565272 0.0188424" pos="0.0183556 0 0" quat="0.5 0.5 -0.5 -0.5"/>
            <geom name="//unnamed_geom_53" class="collision" size="0.054171 0.0317966 0.0179003" pos="0.0183556 -0.0476873 0" quat="0.5 0.5 -0.5 -0.5" type="box"/>
            <geom name="//unnamed_geom_54" class="visual" pos="0.0119769 -0.0719564 -0.364745" quat="0.382683 0 0 -0.92388" material="foot" mesh="foot"/>
            <geom name="LF_calf" class="collision" size="0.0164871 0.133076" pos="0.011977 -0.0729421 -0.182372" quat="0.707107 0 0 -0.707107"/>
            <geom name="LF_foot" class="foot" size="0.0268638" pos="0.011977 -0.0729421 -0.340462" quat="0.707107 0 0 -0.707107"/>
            <geom name="//unnamed_geom_57" class="reward_collision_sphere" size="0.094212" pos="-0.045889 0 0"/>
            <geom name="//unnamed_geom_58" class="reward_collision_sphere" size="0.047106" pos="0.011977 -0.0729421 -0.340462"/>
            <site name="LF_foot" class="foot" pos="0.011977 -0.0729421 -0.340462" quat="0.707107 0 0 -0.707107" size="0.0094212"/>
          </body>
        </body>
      </body>
      <body name="RF_HIP" pos="0.276588 -0.0861857 0.00290163" quat="0.258848 -0.965918 -4.63532e-05 1.50319e-05">
        <inertial pos="0.0531245 0.0114888 -0.00870665" quat="0.126591 0.67817 0.138334 0.71058" mass="2.40932" diaginertia="0.00390672 0.00199391 0.00491907"/>
        <joint name="RF_HAA" pos="0 0 0" axis="0.999997 -0.00225952 -0.000257808" range="-0.451652 0.730206" armature="0.00942943" damping="0.00781635" frictionloss="0.0912037"/>
        <geom name="//unnamed_geom_59" class="visual" pos="0 0.000253547 4.16451e-05" quat="0.258819 0.965926 0 0" material="hip_r" mesh="hip_r"/>
        <geom name="//unnamed_geom_60" class="visual" pos="0.054975 0.0655385 -0.0396868" quat="0.183013 0.683013 0.683013 -0.183013" material="drive" mesh="drive"/>
        <geom name="//unnamed_geom_61" class="collision" size="0.047106 0.0659484" pos="0.054975 0.00991896 -0.00745203" quat="-0.353553 0.612372 0.612372 0.353553"/>
        <body name="RF_THIGH" pos="0.0558076 0.06177 -0.0480337" quat="0.182914 0.683242 0.682863 -0.182814">
          <inertial pos="0.0282286 2.20617e-05 -0.267625" quat="0.994165 -0.00659719 -0.0739689 0.0782394" mass="2.62781" diaginertia="0.0201662 0.0121419 0.0063422"/>
          <joint name="RF_HFE" pos="0 0 0" axis="1 -0.000228667 8.60837e-05" stiffness="0.00600262" range="-3.19675 3.18672" armature="0.00838307" damping="0.00999281" frictionloss="0.0891783"/>
          <geom name="//unnamed_geom_62" class="visual" pos="0.00175923 2.77213e-06 0" quat="0.707107 0 0 -0.707107" material="thigh" mesh="thigh"/>
          <geom name="//unnamed_geom_63" class="collision" size="0.0612378 0.0376848" pos="0.0367112 0 0" quat="0.5 0.5 0.5 0.5"/>
          <geom name="//unnamed_geom_64" class="collision" size="0.0353295 0.0282636 0.133135" pos="0.0275334 0 -0.152509" quat="0.707107 0 0 0.707107" type="box"/>
          <geom name="//unnamed_geom_65" class="visual" pos="0.0920533 0 -0.307578" quat="1 0 0 0" material="drive" mesh="drive"/>
          <geom name="//unnamed_geom_66" class="collision" size="0.047106 0.0659484" pos="0.0278087 0 -0.307578" quat="0.707107 0 0.707107 0"/>
          <geom name="//unnamed_geom_67" class="reward_collision_sphere" size="0.0753696" pos="0.0229445 0 0"/>
          <body name="RF_SHANK" pos="0.0928202 0.000175542 -0.308456" quat="1 -1.78054e-05 -2.50467e-05 -7.76863e-05">
            <inertial pos="0.00413579 0.0514126 -0.0844222" quat="0.993393 0.112064 0.0011015 0.024726" mass="0.463036" diaginertia="0.00640419 0.00362559 0.00153411"/>
            <joint name="RF_KFE" pos="0 0 0" axis="0.999999 -0.000189657 0.00133082" range="-3.13171 3.11975" armature="0.0104735" damping="0.00951315" frictionloss="0.0943677"/>
            <geom name="//unnamed_geom_68" class="visual" pos="0.000573643 -0.00305871 0" quat="0.707107 0 0 0.707107" material="shank" mesh="shank_r"/>
            <geom name="RF_kfe_act" class="collision" size="0.0565272 0.0188424" pos="0.0183556 0 0" quat="0.5 0.5 0.5 0.5"/>
            <geom name="//unnamed_geom_70" class="collision" size="0.054171 0.0317966 0.0179003" pos="0.0183556 0.0476873 0" quat="0.5 0.5 0.5 0.5" type="box"/>
            <geom name="//unnamed_geom_71" class="visual" pos="0.0119772 0.0719564 -0.364745" quat="0.382683 0 0 0.92388" material="foot" mesh="foot"/>
            <geom name="RF_calf" class="collision" size="0.0164871 0.133076" pos="0.011977 0.0729421 -0.182372" quat="0.707107 0 0 0.707107"/>
            <geom name="RF_foot" class="foot" size="0.0281876" pos="0.011977 0.0729421 -0.340462" quat="0.707107 0 0 0.707107"/>
            <geom name="//unnamed_geom_74" class="reward_collision_sphere" size="0.094212" pos="-0.045889 0 0"/>
            <geom name="//unnamed_geom_75" class="reward_collision_sphere" size="0.047106" pos="0.011977 0.0729421 -0.340462"/>
            <site name="RF_foot" class="foot" pos="0.011977 0.0729421 -0.340462" quat="0.707107 0 0 0.707107" size="0.0094212"/>
          </body>
        </body>
      </body>
      <body name="LH_HIP" pos="-0.274147 0.0864965 -0.00171364" quat="3.1199e-05 -2.52659e-05 0.965915 -0.25886">
        <inertial pos="0.0521576 0.0124692 -0.0117253" quat="0.135102 0.679573 0.125072 0.71013" mass="2.41731" diaginertia="0.00396205 0.00189924 0.00485291"/>
        <joint name="LH_HAA" pos="0 0 0" axis="0.999999 0.00106131 0.000600572" range="-0.440418 0.776657" armature="0.00946732" damping="0.00219471" frictionloss="0.106909"/>
        <geom name="//unnamed_geom_76" class="visual" pos="0 0.000253547 4.16451e-05" quat="-0.258819 -0.965926 0 0" material="hip_r" mesh="hip_r"/>
        <geom name="//unnamed_geom_77" class="visual" pos="0.054975 0.0655385 -0.0396868" quat="0.183013 0.683013 0.683013 -0.183013" material="drive" mesh="drive"/>
        <geom name="//unnamed_geom_78" class="collision" size="0.047106 0.0659484" pos="0.054975 0.00991896 -0.00745203" quat="-0.353553 0.612372 0.612372 0.353553"/>
        <body name="LH_THIGH" pos="0.0549603 0.0610564 -0.0473313" quat="0.183027 0.683045 0.682976 -0.183016">
          <inertial pos="0.0256997 -0.000754285 -0.267543" quat="0.992601 0.00815889 -0.082002 0.0891799" mass="2.59646" diaginertia="0.0190096 0.0117933 0.0059129"/>
          <joint name="LH_HFE" pos="0 0 0" axis="0.99988 0.0130028 0.00846958" range="-3.19568 3.16144" armature="0.00923512" damping="0.0044805" frictionloss="0.0929709"/>
          <geom name="//unnamed_geom_79" class="visual" pos="0.00175923 2.77213e-06 0" quat="0.707107 0 0 -0.707107" material="thigh" mesh="thigh"/>
          <geom name="//unnamed_geom_80" class="collision" size="0.0612378 0.0376848" pos="0.0367112 0 0" quat="0.5 0.5 -0.5 -0.5"/>
          <geom name="//unnamed_geom_81" class="collision" size="0.0353295 0.0282636 0.133135" pos="0.0275334 0 -0.152509" quat="0.707107 0 0 -0.707107" type="box"/>
          <geom name="//unnamed_geom_82" class="visual" pos="0.0920533 0 -0.307578" quat="1 0 0 0" material="drive" mesh="drive"/>
          <geom name="//unnamed_geom_83" class="collision" size="0.047106 0.0659484" pos="0.0278087 0 -0.307578" quat="0.707107 0 0.707107 0"/>
          <geom name="//unnamed_geom_84" class="reward_collision_sphere" size="0.0753696" pos="0.0229445 0 0"/>
          <body name="LH_SHANK" pos="0.091176 -0.00091349 -0.309772" quat="1 -0.000113691 0.000144057 -8.78263e-05">
            <inertial pos="0.00608389 0.0493124 -0.0853887" quat="0.994124 0.105553 0.00463356 0.023552" mass="0.476721" diaginertia="0.00660828 0.00360138 0.00164363"/>
            <joint name="LH_KFE" pos="0 0 0" axis="0.999974 -0.00680749 -0.0024466" range="-3.15984 3.14024" armature="0.00928977" damping="0.00394383" frictionloss="0.0998077"/>
            <geom name="//unnamed_geom_85" class="visual" pos="0.000573643 -0.00305871 0" quat="-0.707107 0 0 -0.707107" material="shank" mesh="shank_r"/>
            <geom name="LH_kfe_act" class="collision" size="0.0565272 0.0188424" pos="0.0183556 0 0" quat="0.5 0.5 -0.5 -0.5"/>
            <geom name="//unnamed_geom_87" class="collision" size="0.054171 0.0317966 0.0179003" pos="0.0183556 0.0476873 0" quat="0.5 0.5 -0.5 -0.5" type="box"/>
            <geom name="//unnamed_geom_88" class="visual" pos="0.0119772 0.0719564 -0.364745" quat="-0.382683 0 0 -0.92388" material="foot" mesh="foot"/>
            <geom name="LH_calf" class="collision" size="0.0164871 0.133076" pos="0.011977 0.0729421 -0.182372" quat="0.707107 0 0 -0.707107"/>
            <geom name="LH_foot" class="foot" size="0.0320124" pos="0.011977 0.0729421 -0.340462" quat="0.707107 0 0 -0.707107"/>
            <geom name="//unnamed_geom_91" class="reward_collision_sphere" size="0.094212" pos="-0.045889 0 0"/>
            <geom name="//unnamed_geom_92" class="reward_collision_sphere" size="0.047106" pos="0.011977 0.0729421 -0.340462"/>
            <site name="LH_foot" class="foot" pos="0.011977 0.0729421 -0.340462" quat="0.707107 0 0 -0.707107" size="0.0094212"/>
          </body>
        </body>
      </body>
      <body name="RH_HIP" pos="-0.275254 -0.0854439 0.00112042" quat="0.00018524 -2.21097e-05 -0.966009 -0.258507">
        <inertial pos="0.0523951 -0.0101312 -0.0112146" quat="-0.128463 0.709946 -0.135342 0.679085" mass="2.25118" diaginertia="0.0037293 0.00188972 0.00466277"/>
        <joint name="RH_HAA" pos="0 0 0" axis="0.999989 -0.00347257 -0.00324502" range="-0.733321 0.444545" armature="0.00897311" damping="0" frictionloss="0.0919219"/>
        <geom name="//unnamed_geom_93" class="visual" pos="0 -0.000253549 4.16452e-05" quat="-0.258819 0.965926 0 0" material="hip_l" mesh="hip_l"/>
        <geom name="//unnamed_geom_94" class="visual" pos="0.054975 -0.0655385 -0.0396868" quat="-0.183013 0.683013 -0.683013 -0.183013" material="drive" mesh="drive"/>
        <geom name="//unnamed_geom_95" class="collision" size="0.047106 0.0659484" pos="0.054975 -0.00991896 -0.00745203" quat="0.353553 0.612372 -0.612372 0.353553"/>
        <body name="RH_THIGH" pos="0.0537688 -0.0594136 -0.0425018" quat="-0.182959 0.682864 -0.68326 -0.182698">
          <inertial pos="0.027235 0.00190128 -0.264867" quat="0.993177 -0.00531065 -0.0813074 0.083423" mass="2.41131" diaginertia="0.0191474 0.0113801 0.00611683"/>
          <joint name="RH_HFE" pos="0 0 0" axis="0.999998 0.00180161 -0.000727738" stiffness="0.00727132" range="-3.19482 3.1971" armature="0.0097405" damping="0.00780289" frictionloss="0.0824656"/>
          <geom name="//unnamed_geom_96" class="visual" pos="0.00175923 2.77213e-06 0" quat="0.707107 0 0 -0.707107" material="thigh" mesh="thigh"/>
          <geom name="//unnamed_geom_97" class="collision" size="0.0612378 0.0376848" pos="0.0367112 0 0" quat="0.5 0.5 0.5 0.5"/>
          <geom name="//unnamed_geom_98" class="collision" size="0.0353295 0.0282636 0.133135" pos="0.0275334 0 -0.152509" quat="0.707107 0 0 0.707107" type="box"/>
          <geom name="//unnamed_geom_99" class="visual" pos="0.0920533 0 -0.307578" quat="1 0 0 0" material="drive" mesh="drive"/>
          <geom name="//unnamed_geom_100" class="collision" size="0.047106 0.0659484" pos="0.0278087 0 -0.307578" quat="0.707107 0 0.707107 0"/>
          <geom name="//unnamed_geom_101" class="reward_collision_sphere" size="0.0753696" pos="0.0229445 0 0"/>
          <body name="RH_SHANK" pos="0.0941451 0.0006757 -0.306037" quat="1 0.000263526 0.000611595 9.97285e-05">
            <inertial pos="0.00459604 -0.0507936 -0.0867776" quat="0.993267 -0.113153 0.00158181 -0.0248003" mass="0.468141" diaginertia="0.0065603 0.0035444 0.00160998"/>
            <joint name="RH_KFE" pos="0 0 0" axis="0.999995 -0.00214246 -0.00229782" range="-3.13031 3.15794" armature="0.00927494" damping="0" frictionloss="0.0929117"/>
            <geom name="//unnamed_geom_102" class="visual" pos="0.000573646 0.00305871 0" quat="0.707107 0 0 -0.707107" material="shank_l" mesh="shank_l"/>
            <geom name="RH_kfe_act" class="collision" size="0.0565272 0.0188424" pos="0.0183556 0 0" quat="0.5 0.5 0.5 0.5"/>
            <geom name="//unnamed_geom_104" class="collision" size="0.054171 0.0317966 0.0179003" pos="0.0183556 -0.0476873 0" quat="0.5 0.5 0.5 0.5" type="box"/>
            <geom name="//unnamed_geom_105" class="visual" pos="0.0119769 -0.0719564 -0.364745" quat="0.382683 0 0 -0.92388" material="foot" mesh="foot"/>
            <geom name="RH_calf" class="collision" size="0.0164871 0.133076" pos="0.011977 -0.0729421 -0.182372" quat="0.707107 0 0 0.707107"/>
            <geom name="RH_foot" class="foot" size="0.028914" pos="0.011977 -0.0729421 -0.340462" quat="0.707107 0 0 0.707107"/>
            <geom name="//unnamed_geom_108" class="reward_collision_sphere" size="0.094212" pos="-0.045889 0 0"/>
            <geom name="//unnamed_geom_109" class="reward_collision_sphere" size="0.047106" pos="0.011977 -0.0729421 -0.340462"/>
            <site name="RH_foot" class="foot" pos="0.011977 -0.0729421 -0.340462" quat="0.707107 0 0 0.707107" size="0.0094212"/>
          </body>
        </body>
      </body>
    </body>
  </worldbody>

  <contact>
    <pair class="/" geom1="floor" geom2="LF_foot" name="//unnamed_contact_0"/>
    <pair class="/" geom1="floor" geom2="RF_foot" name="//unnamed_contact_1"/>
    <pair class="/" geom1="floor" geom2="LH_foot" name="//unnamed_contact_2"/>
    <pair class="/" geom1="floor" geom2="RH_foot" name="//unnamed_contact_3"/>
  </contact>

  <actuator>
    <general name="LF_HAA" class="/" joint="LF_HAA" forcerange="-72.5752 72.5752" gainprm="73.7599" biasprm="0 -73.7599 -1.99251"/>
    <general name="LF_HFE" class="/" joint="LF_HFE" forcerange="-82.6885 82.6885" gainprm="73.7599" biasprm="0 -73.7599 -1.99251"/>
    <general name="LF_KFE" class="/" joint="LF_KFE" forcerange="-67.7435 67.7435" gainprm="73.7599" biasprm="0 -73.7599 -1.99251"/>
    <general name="RF_HAA" class="/" joint="RF_HAA" forcerange="-74.6717 74.6717" gainprm="73.7599" biasprm="0 -73.7599 -1.99251"/>
    <general name="RF_HFE" class="/" joint="RF_HFE" forcerange="-81.6251 81.6251" gainprm="73.7599" biasprm="0 -73.7599 -1.99251"/>
    <general name="RF_KFE" class="/" joint="RF_KFE" forcerange="-82.2406 82.2406" gainprm="73.7599" biasprm="0 -73.7599 -1.99251"/>
    <general name="LH_HAA" class="/" joint="LH_HAA" forcerange="-83.2944 83.2944" gainprm="73.7599" biasprm="0 -73.7599 -1.99251"/>
    <general name="LH_HFE" class="/" joint="LH_HFE" forcerange="-78.2358 78.2358" gainprm="73.7599" biasprm="0 -73.7599 -1.99251"/>
    <general name="LH_KFE" class="/" joint="LH_KFE" forcerange="-74.2875 74.2875" gainprm="73.7599" biasprm="0 -73.7599 -1.99251"/>
    <general name="RH_HAA" class="/" joint="RH_HAA" forcerange="-76.3063 76.3063" gainprm="73.7599" biasprm="0 -73.7599 -1.99251"/>
    <general name="RH_HFE" class="/" joint="RH_HFE" forcerange="-68.1857 68.1857" gainprm="73.7599" biasprm="0 -73.7599 -1.99251"/>
    <general name="RH_KFE" class="/" joint="RH_KFE" forcerange="-68.7545 68.7545" gainprm="73.7599" biasprm="0 -73.7599 -1.99251"/>
  </actuator>

  <sensor>
    <gyro site="imu" name="imu_angular_velocity"/>
    <velocimeter site="imu" name="imu_linear_velocity"/>
    <framelinvel objtype="site" objname="LF_foot" name="LF_foot_global_linear_velocity"/>
    <framelinvel objtype="site" objname="RF_foot" name="RF_foot_global_linear_velocity"/>
    <framelinvel objtype="site" objname="LH_foot" name="LH_foot_global_linear_velocity"/>
    <framelinvel objtype="site" objname="RH_foot" name="RH_foot_global_linear_velocity"/>
  </sensor>

  <keyframe>
    <key name="home" qpos="0 0 0.55 1 0 0 0 0 0.4 -0.8 0 -0.4 0.8 0 -0.4 0.8 0 0.4 -0.8"/>
  </keyframe>
</mujoco>
