<mujoco model="anymal_c">
  <compiler angle="radian" assetdir="assets" balanceinertia="true" inertiafromgeom="false"/>

  <option timestep="0.005" density="1.2" viscosity="2e-05"/>

  <size nkey="1"/>

  <visual>
    <quality shadowsize="8192"/>
    <map shadowclip="0.5"/>
  </visual>

  <default>
    <default class="/">
      <material specular="0" shininess="0.25"/>
      <geom contype="0" conaffinity="0" group="1" solref="-1000 -80"/>
      <site size="0.01 0.005 0.005" group="5"/>
      <general forcelimited="true" forcerange="-80 80" biastype="affine" gainprm="80" biasprm="0 -80 -2"/>
      <default class="anymal_c">
        <joint armature="0.01" damping="0.01" frictionloss="0.1"/>
        <default class="visual">
          <geom type="mesh" group="2"/>
          <default class="visual_zflip"/>
        </default>
        <default class="collision">
          <geom type="cylinder" group="3"/>
          <default class="foot">
            <geom size="0.03 0 0" type="sphere" condim="6" priority="1" friction="0.8 0.02 0.01" solimp="0.015 1 0.03"/>
          </default>
        </default>
      </default>
      <default class="reward_collision_sphere">
        <geom group="5" rgba="1 0 0 1"/>
      </default>
    </default>
  </default>

  <asset>
    <texture type="skybox" colorspace="auto" name="//unnamed_texture_0" builtin="gradient" rgb1="0.95 0.95 0.95" rgb2="0.95 0.95 0.95" width="100" height="600"/>
    <texture type="2d" colorspace="auto" name="texplane" builtin="checker" rgb1="0.345 0.575 0.748" rgb2="0.345 0.575 0.748" markrgb="1 1 1" width="512" height="512"/>
    <texture type="2d" colorspace="linear" name="base" file="base.png"/>
    <texture type="2d" colorspace="linear" name="top_shell" file="top_shell.png"/>
    <texture type="2d" colorspace="linear" name="bottom_shell" file="bottom_shell.png"/>
    <texture type="2d" colorspace="linear" name="remote" file="remote.png"/>
    <texture type="2d" colorspace="linear" name="hatch" file="hatch.png"/>
    <texture type="2d" colorspace="linear" name="handle" file="handle.png"/>
    <texture type="2d" colorspace="linear" name="face" file="face.png"/>
    <texture type="2d" colorspace="linear" name="battery" file="battery.png"/>
    <texture type="2d" colorspace="linear" name="lidar_cage" file="lidar_cage.png"/>
    <texture type="2d" colorspace="linear" name="depth_camera" file="depth_camera.png"/>
    <texture type="2d" colorspace="linear" name="wide_angle_camera" file="wide_angle_camera.png"/>
    <texture type="2d" colorspace="linear" name="lidar" file="lidar.png"/>
    <texture type="2d" colorspace="linear" name="drive" file="drive.png"/>
    <texture type="2d" colorspace="linear" name="hip_l" file="hip_l.png"/>
    <texture type="2d" colorspace="linear" name="shank_l" file="shank_l.png"/>
    <texture type="2d" colorspace="linear" name="foot" file="foot.png"/>
    <texture type="2d" colorspace="linear" name="thigh" file="thigh.png"/>
    <texture type="2d" colorspace="linear" name="shank_r" file="shank_r.png"/>
    <texture type="2d" colorspace="linear" name="hip_r" file="hip_r.png"/>
    <material name="MatPlane" class="/" texture="texplane" texuniform="true" texrepeat="2 2" specular="0.9" shininess="0.5"/>
    <material name="black_plastic" class="/" rgba="0.007 0.007 0.007 1"/>
    <material name="green" class="/" rgba="0.052 0.178 0.033 1"/>
    <material name="red" class="/" rgba="0.178 0.006 0.005 1"/>
    <material name="yellow" class="/" rgba="0.178 0.119 0.006 1"/>
    <material name="lwl" class="/" rgba="0.8 0.8 0.8 1"/>
    <material name="base" class="/" texture="base"/>
    <material name="top_shell" class="/" texture="top_shell"/>
    <material name="bottom_shell" class="/" texture="bottom_shell"/>
    <material name="hip_l" class="/" texture="hip_l"/>
    <material name="thigh" class="/" texture="thigh"/>
    <material name="shank_l" class="/" texture="shank_l"/>
    <material name="foot" class="/" texture="foot"/>
    <material name="hip_r" class="/" texture="hip_r"/>
    <material name="shank" class="/" texture="shank_r"/>
    <material name="hatch" class="/" texture="hatch"/>
    <material name="remote" class="/" texture="remote"/>
    <material name="handle" class="/" texture="handle"/>
    <material name="face" class="/" texture="face"/>
    <material name="depth_camera" class="/" texture="depth_camera"/>
    <material name="wide_angle_camera" class="/" texture="wide_angle_camera"/>
    <material name="battery" class="/" texture="battery"/>
    <material name="lidar_cage" class="/" texture="lidar_cage"/>
    <material name="lidar" class="/" texture="lidar"/>
    <material name="drive" class="/" texture="drive"/>
    <mesh name="base_0" class="/" file="base_0.obj"/>
    <mesh name="base_1" class="/" file="base_1.obj"/>
    <mesh name="base_2" class="/" file="base_2.obj"/>
    <mesh name="base_3" class="/" file="base_3.obj"/>
    <mesh name="base_4" class="/" file="base_4.obj"/>
    <mesh name="base_5" class="/" file="base_5.obj"/>
    <mesh name="top_shell" class="/" file="top_shell.obj"/>
    <mesh name="bottom_shell" class="/" file="bottom_shell.obj"/>
    <mesh name="remote" class="/" file="remote.obj"/>
    <mesh name="handle" class="/" file="handle.obj"/>
    <mesh name="face" class="/" file="face.obj"/>
    <mesh name="wide_angle_camera" class="/" file="wide_angle_camera.obj"/>
    <mesh name="depth_camera" class="/" file="depth_camera.obj"/>
    <mesh name="battery" class="/" file="battery.obj"/>
    <mesh name="lidar_cage" class="/" file="lidar_cage.obj"/>
    <mesh name="lidar" class="/" file="lidar.obj"/>
    <mesh name="drive" class="/" file="drive.obj"/>
    <mesh name="hip_l" class="/" file="hip_l.obj"/>
    <mesh name="thigh" class="/" file="thigh.obj"/>
    <mesh name="shank_l" class="/" file="shank_l.obj"/>
    <mesh name="foot" class="/" file="foot.obj"/>
    <mesh name="hip_r" class="/" file="hip_r.obj"/>
    <mesh name="hatch" class="/" file="hatch.obj"/>
    <mesh name="shank_r" class="/" file="shank_r.obj"/>
  </asset>

  <worldbody>
    <geom name="floor" class="/" size="100 100 0.125" type="plane" group="0" material="MatPlane"/>
    <light name="toplight_shadow" class="/" pos="0 0 5" dir="0.0990148 0.0990148 -0.990148" type="directional" ambient="0.04 0.04 0.04" diffuse="0.55 0.55 0.55" specular="0.12 0.12 0.12"/>
    <light name="toplight_fill" class="/" pos="0 0 5" dir="0.0990148 0.0990148 -0.990148" type="directional" castshadow="false" ambient="0.04 0.04 0.04" diffuse="0.3 0.3 0.3" specular="0.08 0.08 0.08"/>
    <body name="trunk" childclass="anymal_c" pos="-0.000146313 0.000463769 0.000857068" quat="1 0.000100541 -0.000112017 -4.63588e-05">
      <inertial pos="0.00306091 -0.000814797 0.0498604" quat="0.500591 0.500797 0.502325 0.496266" mass="17.0209" diaginertia="0.628313 0.328241 0.239503"/>
      <joint name="//unnamed_joint_0" type="free" armature="0" damping="0" frictionloss="0"/>
      <geom name="//unnamed_geom_1" class="visual" material="green" mesh="base_0"/>
      <geom name="//unnamed_geom_2" class="visual" material="yellow" mesh="base_1"/>
      <geom name="//unnamed_geom_3" class="visual" material="red" mesh="base_2"/>
      <geom name="//unnamed_geom_4" class="visual" material="black_plastic" mesh="base_3"/>
      <geom name="//unnamed_geom_5" class="visual" material="lwl" mesh="base_4"/>
      <geom name="//unnamed_geom_6" class="visual" material="base" mesh="base_5"/>
      <geom name="trunk_1" class="collision" size="0.278426 0.0672062 0.0864079" type="box"/>
      <geom name="trunk_2" class="collision" size="0.0864079 0.0696064" pos="0.215449 0.0613623 0" quat="0.707107 0 0.707107 0"/>
      <geom name="trunk_3" class="collision" size="0.0864079 0.0696064" pos="-0.215449 0.0613623 0" quat="0.707107 0 0.707107 0"/>
      <geom name="trunk_4" class="collision" size="0.0864079 0.0696064" pos="0.215449 -0.0613623 0" quat="0.707107 0 0.707107 0"/>
      <geom name="trunk_5" class="collision" size="0.0864079 0.0696064" pos="-0.215449 -0.0613623 0" quat="0.707107 0 0.707107 0"/>
      <geom name="//unnamed_geom_12" class="visual" material="top_shell" mesh="top_shell"/>
      <geom name="//unnamed_geom_13" class="visual" material="bottom_shell" mesh="bottom_shell"/>
      <geom name="//unnamed_geom_14" class="visual" material="remote" mesh="remote"/>
      <geom name="//unnamed_geom_15" class="visual" material="handle" mesh="handle"/>
      <geom name="//unnamed_geom_16" class="visual" pos="0.41059 0 0" quat="1 0 0 0" material="face" mesh="face"/>
      <geom name="trunk_6" class="collision" size="0.0528048 0.0672062 0.0864079" pos="0.465072 0 0" type="box"/>
      <geom name="//unnamed_geom_18" class="collision" size="0.0864079 0.0528048" pos="0.465072 0.0613623 0" quat="0.707107 0 0.707107 0"/>
      <geom name="//unnamed_geom_19" class="collision" size="0.0864079 0.0528048" pos="0.465072 -0.0613623 0" quat="0.707107 0 0.707107 0"/>
      <geom name="//unnamed_geom_20" class="visual" pos="0.457297 0 -0.0297535" quat="0.965926 0 0.258819 0" material="depth_camera" mesh="depth_camera"/>
      <geom name="//unnamed_geom_21" class="visual" pos="0.508161 0 0.015166" material="wide_angle_camera" mesh="wide_angle_camera"/>
      <geom name="//unnamed_geom_22" class="visual_zflip" pos="-0.41059 0 0" quat="0 0 0 1" material="face" mesh="face"/>
      <geom name="trunk_7" class="collision" size="0.0528048 0.0672062 0.0864079" pos="-0.465072 0 0" quat="0 0 0 1" type="box"/>
      <geom name="//unnamed_geom_24" class="collision" size="0.0864079 0.0528048" pos="-0.465072 -0.0613623 0" quat="0 -0.707107 0 0.707107"/>
      <geom name="//unnamed_geom_25" class="collision" size="0.0864079 0.0528048" pos="-0.465072 0.0613623 0" quat="0 -0.707107 0 0.707107"/>
      <geom name="//unnamed_geom_26" class="visual" pos="-0.457297 0 -0.0297535" quat="0 -0.258819 0 0.965926" material="depth_camera" mesh="depth_camera"/>
      <geom name="//unnamed_geom_27" class="visual_zflip" pos="-0.508161 0 0.015166" quat="0 0 0 1" material="wide_angle_camera" mesh="wide_angle_camera"/>
      <geom name="//unnamed_geom_28" class="visual" material="battery" mesh="battery"/>
      <geom name="//unnamed_geom_29" class="visual" pos="0 0.0655307 0.0292591" quat="0.683013 -0.183013 0.183013 0.683013" material="depth_camera" mesh="depth_camera"/>
      <geom name="//unnamed_geom_30" class="visual" pos="0 -0.0655307 0.0292591" quat="0.683013 0.183013 0.183013 -0.683013" material="depth_camera" mesh="depth_camera"/>
      <geom name="//unnamed_geom_31" class="visual" pos="-0.360567 0 0.0744623" quat="1 0 0 0" material="lidar_cage" mesh="lidar_cage"/>
      <geom name="trunk_8" class="collision" size="0.0672062 0.0576053" pos="-0.360567 0 0.135248"/>
      <geom name="//unnamed_geom_33" class="visual" pos="-0.360567 -4.47731e-05 0.144062" quat="0.707107 0 0 -0.707107" material="lidar" mesh="lidar"/>
      <geom name="//unnamed_geom_34" class="visual" pos="0.297071 0.0912154 -2.35442e-09" quat="0.258819 0.965926 0 0" material="drive" mesh="drive"/>
      <geom name="//unnamed_geom_35" class="visual" pos="0.297071 -0.0912154 2.35442e-09" quat="0.258819 -0.965926 0 0" material="drive" mesh="drive"/>
      <geom name="//unnamed_geom_36" class="visual" pos="-0.297071 0.0912154 2.35442e-09" quat="0 0 0.965926 -0.258819" material="drive" mesh="drive"/>
      <geom name="//unnamed_geom_37" class="visual" pos="-0.297071 -0.0912154 -2.35442e-09" quat="0 0 -0.965926 -0.258819" material="drive" mesh="drive"/>
      <geom name="//unnamed_geom_38" class="visual" pos="0.114906 0 0.0739557" quat="1 0 0 0" material="hatch" mesh="hatch"/>
      <geom name="//unnamed_geom_39" class="reward_collision_sphere" size="0.115211"/>
      <geom name="//unnamed_geom_40" class="reward_collision_sphere" size="0.115211" pos="0.445756 0 0"/>
      <geom name="//unnamed_geom_41" class="reward_collision_sphere" size="0.115211" pos="-0.445756 0 0"/>
      <site name="imu" pos="0.243034 -0.00340596 0.0515866" size="0.00960088"/>
      <camera name="track" pos="0 -1.75321 0" quat="0.707107 0.707107 0 0" mode="trackcom"/>
      <camera name="ego_camera" pos="0.445756 0 -0.0405237" quat="-0.5 -0.5 0.5 0.5"/>
      <body name="LF_HIP" pos="0.297212 0.0910823 0.000747138" quat="0.259068 0.965858 0.000654265 0.000765438">
        <inertial pos="0.0570196 -0.0127846 -0.00774941" quat="-0.128192 0.709236 -0.13441 0.680062" mass="2.50963" diaginertia="0.00569484 0.00260569 0.0035472"/>
        <joint name="LF_HAA" pos="0 0 0" axis="1 1.98524e-06 -2.92898e-06" range="-0.688133 0.485003" armature="0.00981509" damping="0.0127695" frictionloss="0.0940473"/>
        <geom name="//unnamed_geom_42" class="visual" pos="0 -0.0001385 2.27485e-05" quat="0.258819 -0.965926 0 0" material="hip_l" mesh="hip_l"/>
        <geom name="//unnamed_geom_43" class="visual" pos="0.059335 -0.070445 -0.041681" quat="0.183013 -0.683013 0.683013 0.183013" material="drive" mesh="drive"/>
        <geom name="//unnamed_geom_44" class="collision" size="0.0480044 0.0672062" pos="0.059335 -0.010484 -0.0069954" quat="-0.353553 -0.612372 0.612372 -0.353553"/>
        <body name="LF_THIGH" pos="0.0597133 -0.0642805 -0.0408916" quat="0.183013 -0.683014 0.68301 0.183019">
          <inertial pos="0.0309897 -0.00151468 -0.251003" quat="0.993069 -0.00824914 -0.0814883 0.0842903" mass="2.70874" diaginertia="0.0289422 0.0156072 0.00447091"/>
          <joint name="LF_HFE" pos="0 0 0" axis="1 -0.000671576 -7.34116e-05" range="-3.14703 3.178" armature="0.0099388" damping="0" frictionloss="0.0958605"/>
          <geom name="//unnamed_geom_45" class="visual" pos="0.00226742 3.57293e-06 0" quat="0.707107 0 0 -0.707107" material="thigh" mesh="thigh"/>
          <geom name="//unnamed_geom_46" class="collision" size="0.0624057 0.0384035" pos="0.0396227 0 0" quat="0.5 0.5 -0.5 -0.5"/>
          <geom name="//unnamed_geom_47" class="collision" size="0.0360033 0.0288026 0.135674" pos="0.029717 0 -0.143164" quat="0.707107 0 0 -0.707107" type="box"/>
          <geom name="//unnamed_geom_48" class="visual" pos="0.099354 0 -0.288731" quat="1 0 0 0" material="drive" mesh="drive"/>
          <geom name="//unnamed_geom_49" class="collision" size="0.0480044 0.0672062" pos="0.0300142 0 -0.288731" quat="0.707107 0 0.707107 0"/>
          <geom name="//unnamed_geom_50" class="reward_collision_sphere" size="0.076807" pos="0.0247642 0 0"/>
          <body name="LF_SHANK" pos="0.101534 0.00146845 -0.288549" quat="1 -2.74023e-05 -1.85866e-05 8.92359e-06">
            <inertial pos="0.00595405 -0.0529841 -0.0818016" quat="0.992937 -0.115876 -0.00116401 -0.0254413" mass="0.528729" diaginertia="0.00965434 0.00477491 0.00118925"/>
            <joint name="LF_KFE" pos="0 0 0" axis="1 -0.000111456 -0.000668224" range="-3.14371 3.11382" armature="0.00948422" damping="0.00963531" frictionloss="0.0934499"/>
            <geom name="//unnamed_geom_51" class="visual" pos="0.000739357 0.00394229 0" quat="0.707107 0 0 -0.707107" material="shank_l" mesh="shank_l"/>
            <geom name="LF_kfe_act" class="collision" size="0.0576053 0.0192018" pos="0.0198114 0 0" quat="0.5 0.5 -0.5 -0.5"/>
            <geom name="//unnamed_geom_53" class="collision" size="0.0552041 0.032403 0.0182417" pos="0.0198114 -0.0504039 0" quat="0.5 0.5 -0.5 -0.5" type="box"/>
            <geom name="//unnamed_geom_54" class="visual" pos="0.0129267 -0.0758269 -0.342395" quat="0.382683 0 0 -0.92388" material="foot" mesh="foot"/>
            <geom name="LF_calf" class="collision" size="0.0168015 0.135614" pos="0.0129269 -0.0770974 -0.171197" quat="0.707107 0 0 -0.707107"/>
            <geom name="LF_foot" class="foot" size="0.027788" pos="0.0129269 -0.0770974 -0.3196" quat="0.707107 0 0 -0.707107"/>
            <geom name="//unnamed_geom_57" class="reward_collision_sphere" size="0.0960088" pos="-0.0495284 0 0"/>
            <geom name="//unnamed_geom_58" class="reward_collision_sphere" size="0.0480044" pos="0.0129269 -0.0770974 -0.3196"/>
            <site name="LF_foot" class="foot" pos="0.0129269 -0.0770974 -0.3196" quat="0.707107 0 0 -0.707107" size="0.00960088"/>
          </body>
        </body>
      </body>
      <body name="RF_HIP" pos="0.296851 -0.0926988 0.00181353" quat="0.258854 -0.965916 -9.40558e-06 2.07542e-05">
        <inertial pos="0.0566561 0.0140072 -0.00879997" quat="0.134099 0.674926 0.134047 0.713108" mass="2.51144" diaginertia="0.00576819 0.00257031 0.00359718"/>
        <joint name="RF_HAA" pos="0 0 0" axis="0.999998 -0.00174479 4.6159e-05" range="-0.487858 0.723158" armature="0.00956763" damping="0.0103236" frictionloss="0.0918402"/>
        <geom name="//unnamed_geom_59" class="visual" pos="0 0.000138499 2.27484e-05" quat="0.258819 0.965926 0 0" material="hip_r" mesh="hip_r"/>
        <geom name="//unnamed_geom_60" class="visual" pos="0.059335 0.070445 -0.041681" quat="0.183013 0.683013 0.683013 -0.183013" material="drive" mesh="drive"/>
        <geom name="//unnamed_geom_61" class="collision" size="0.0480044 0.0672062" pos="0.059335 0.010484 -0.0069954" quat="-0.353553 0.612372 0.612372 0.353553"/>
        <body name="RF_THIGH" pos="0.058792 0.0632295 -0.0433324" quat="0.182903 0.683113 0.682963 -0.182931">
          <inertial pos="0.0307399 2.75642e-05 -0.250453" quat="0.993299 -0.0142119 -0.074728 0.0870105" mass="2.75006" diaginertia="0.0297626 0.0158183 0.00456422"/>
          <joint name="RF_HFE" pos="0 0 0" axis="0.999998 -0.000969083 -0.00168612" stiffness="0.0047239" range="-3.1769 3.15373" armature="0.00929563" damping="0.00933611" frictionloss="0.0953247"/>
          <geom name="//unnamed_geom_62" class="visual" pos="0.00226742 3.57293e-06 0" quat="0.707107 0 0 -0.707107" material="thigh" mesh="thigh"/>
          <geom name="//unnamed_geom_63" class="collision" size="0.0624057 0.0384035" pos="0.0396227 0 0" quat="0.5 0.5 0.5 0.5"/>
          <geom name="//unnamed_geom_64" class="collision" size="0.0360033 0.0288026 0.135674" pos="0.029717 0 -0.143164" quat="0.707107 0 0 0.707107" type="box"/>
          <geom name="//unnamed_geom_65" class="visual" pos="0.099354 0 -0.288731" quat="1 0 0 0" material="drive" mesh="drive"/>
          <geom name="//unnamed_geom_66" class="collision" size="0.0480044 0.0672062" pos="0.0300142 0 -0.288731" quat="0.707107 0 0.707107 0"/>
          <geom name="//unnamed_geom_67" class="reward_collision_sphere" size="0.076807" pos="0.0247642 0 0"/>
          <body name="RF_SHANK" pos="0.098996 0.000832911 -0.288761" quat="1 9.46691e-06 4.95337e-06 4.70782e-06">
            <inertial pos="0.0055314 0.0535179 -0.0793109" quat="0.993035 0.115267 0.0023685 0.0242708" mass="0.502916" diaginertia="0.00930705 0.00477198 0.00114013"/>
            <joint name="RF_KFE" pos="0 0 0" axis="0.999999 -0.00150744 0.000442979" range="-3.12609 3.15212" armature="0.0097489" damping="0.00819802" frictionloss="0.095868"/>
            <geom name="//unnamed_geom_68" class="visual" pos="0.000739353 -0.00394228 0" quat="0.707107 0 0 0.707107" material="shank" mesh="shank_r"/>
            <geom name="RF_kfe_act" class="collision" size="0.0576053 0.0192018" pos="0.0198114 0 0" quat="0.5 0.5 0.5 0.5"/>
            <geom name="//unnamed_geom_70" class="collision" size="0.0552041 0.032403 0.0182417" pos="0.0198114 0.0504039 0" quat="0.5 0.5 0.5 0.5" type="box"/>
            <geom name="//unnamed_geom_71" class="visual" pos="0.0129271 0.0758269 -0.342395" quat="0.382683 0 0 0.92388" material="foot" mesh="foot"/>
            <geom name="RF_calf" class="collision" size="0.0168015 0.135614" pos="0.0129269 0.0770974 -0.171197" quat="0.707107 0 0 0.707107"/>
            <geom name="RF_foot" class="foot" size="0.0284266" pos="0.0129269 0.0770974 -0.3196" quat="0.707107 0 0 0.707107"/>
            <geom name="//unnamed_geom_74" class="reward_collision_sphere" size="0.0960088" pos="-0.0495284 0 0"/>
            <geom name="//unnamed_geom_75" class="reward_collision_sphere" size="0.0480044" pos="0.0129269 0.0770974 -0.3196"/>
            <site name="RF_foot" class="foot" pos="0.0129269 0.0770974 -0.3196" quat="0.707107 0 0 0.707107" size="0.00960088"/>
          </body>
        </body>
      </body>
      <body name="LH_HIP" pos="-0.297056 0.0922136 -0.000952342" quat="0.000244909 -2.9663e-05 0.965903 -0.258906">
        <inertial pos="0.0561168 0.0127432 -0.00995946" quat="0.134677 0.677382 0.128851 0.711628" mass="2.49003" diaginertia="0.00563076 0.00253314 0.00350472"/>
        <joint name="LH_HAA" pos="0 0 0" axis="0.999999 -0.000900307 -0.00111582" stiffness="0.000987707" range="-0.453614 0.752515" armature="0.00953634" damping="0.0106271" frictionloss="0.102991"/>
        <geom name="//unnamed_geom_76" class="visual" pos="0 0.000138499 2.27484e-05" quat="-0.258819 -0.965926 0 0" material="hip_r" mesh="hip_r"/>
        <geom name="//unnamed_geom_77" class="visual" pos="0.059335 0.070445 -0.041681" quat="0.183013 0.683013 0.683013 -0.183013" material="drive" mesh="drive"/>
        <geom name="//unnamed_geom_78" class="collision" size="0.0480044 0.0672062" pos="0.059335 0.010484 -0.0069954" quat="-0.353553 0.612372 0.612372 0.353553"/>
        <body name="LH_THIGH" pos="0.0585949 0.0637022 -0.0426251" quat="0.183052 0.683024 0.682975 -0.183073">
          <inertial pos="0.0292896 0.00035655 -0.250808" quat="0.993176 0.000975788 -0.0782576 0.0864685" mass="2.67703" diaginertia="0.0278731 0.0152233 0.00432573"/>
          <joint name="LH_HFE" pos="0 0 0" axis="0.99997 -0.0076911 -0.000778593" stiffness="0.00229389" range="-3.17132 3.14068" armature="0.00915145" damping="0.00413756" frictionloss="0.0974498"/>
          <geom name="//unnamed_geom_79" class="visual" pos="0.00226742 3.57293e-06 0" quat="0.707107 0 0 -0.707107" material="thigh" mesh="thigh"/>
          <geom name="//unnamed_geom_80" class="collision" size="0.0624057 0.0384035" pos="0.0396227 0 0" quat="0.5 0.5 -0.5 -0.5"/>
          <geom name="//unnamed_geom_81" class="collision" size="0.0360033 0.0288026 0.135674" pos="0.029717 0 -0.143164" quat="0.707107 0 0 -0.707107" type="box"/>
          <geom name="//unnamed_geom_82" class="visual" pos="0.099354 0 -0.288731" quat="1 0 0 0" material="drive" mesh="drive"/>
          <geom name="//unnamed_geom_83" class="collision" size="0.0480044 0.0672062" pos="0.0300142 0 -0.288731" quat="0.707107 0 0.707107 0"/>
          <geom name="//unnamed_geom_84" class="reward_collision_sphere" size="0.076807" pos="0.0247642 0 0"/>
          <body name="LH_SHANK" pos="0.0998164 -0.00154918 -0.289568" quat="1 0.000104751 0.000236816 0.000283623">
            <inertial pos="0.00476476 0.0540515 -0.0818582" quat="0.992628 0.118182 -0.00360082 0.0266548" mass="0.519777" diaginertia="0.00970302 0.00473527 0.00121121"/>
            <joint name="LH_KFE" pos="0 0 0" axis="1 0.0006725 0.000277574" range="-3.15942 3.14009" armature="0.00994856" damping="0.0107982" frictionloss="0.0933121"/>
            <geom name="//unnamed_geom_85" class="visual" pos="0.000739353 -0.00394228 0" quat="-0.707107 0 0 -0.707107" material="shank" mesh="shank_r"/>
            <geom name="LH_kfe_act" class="collision" size="0.0576053 0.0192018" pos="0.0198114 0 0" quat="0.5 0.5 -0.5 -0.5"/>
            <geom name="//unnamed_geom_87" class="collision" size="0.0552041 0.032403 0.0182417" pos="0.0198114 0.0504039 0" quat="0.5 0.5 -0.5 -0.5" type="box"/>
            <geom name="//unnamed_geom_88" class="visual" pos="0.0129271 0.0758269 -0.342395" quat="-0.382683 0 0 -0.92388" material="foot" mesh="foot"/>
            <geom name="LH_calf" class="collision" size="0.0168015 0.135614" pos="0.0129269 0.0770974 -0.171197" quat="0.707107 0 0 -0.707107"/>
            <geom name="LH_foot" class="foot" size="0.0312042" pos="0.0129269 0.0770974 -0.3196" quat="0.707107 0 0 -0.707107"/>
            <geom name="//unnamed_geom_91" class="reward_collision_sphere" size="0.0960088" pos="-0.0495284 0 0"/>
            <geom name="//unnamed_geom_92" class="reward_collision_sphere" size="0.0480044" pos="0.0129269 0.0770974 -0.3196"/>
            <site name="LH_foot" class="foot" pos="0.0129269 0.0770974 -0.3196" quat="0.707107 0 0 -0.707107" size="0.00960088"/>
          </body>
        </body>
      </body>
      <body name="RH_HIP" pos="-0.297016 -0.0898331 0.000123975" quat="-9.18151e-05 0.000494041 -0.965966 -0.258667">
        <inertial pos="0.0558111 -0.0121822 -0.008799" quat="-0.128024 0.70985 -0.135041 0.679328" mass="2.36968" diaginertia="0.00542646 0.00247908 0.00342636"/>
        <joint name="RH_HAA" pos="0 0 0" axis="0.999991 -0.000266279 -0.00423285" range="-0.740668 0.477511" armature="0.0099259" damping="0.00383801" frictionloss="0.0915492"/>
        <geom name="//unnamed_geom_93" class="visual" pos="0 -0.0001385 2.27485e-05" quat="-0.258819 0.965926 0 0" material="hip_l" mesh="hip_l"/>
        <geom name="//unnamed_geom_94" class="visual" pos="0.059335 -0.070445 -0.041681" quat="-0.183013 0.683013 -0.683013 -0.183013" material="drive" mesh="drive"/>
        <geom name="//unnamed_geom_95" class="collision" size="0.0480044 0.0672062" pos="0.059335 -0.010484 -0.0069954" quat="0.353553 0.612372 -0.612372 0.353553"/>
        <body name="RH_THIGH" pos="0.0591301 -0.0633717 -0.0410119" quat="-0.183029 0.683005 -0.683018 -0.183006">
          <inertial pos="0.0312525 5.95782e-05 -0.248677" quat="0.993139 -0.00531887 -0.0802735 0.0848726" mass="2.65971" diaginertia="0.0281898 0.0152106 0.00446043"/>
          <joint name="RH_HFE" pos="0 0 0" axis="0.999979 0.00383552 -0.00527916" range="-3.17447 3.17369" armature="0.00944669" damping="0.00713217" frictionloss="0.0916624"/>
          <geom name="//unnamed_geom_96" class="visual" pos="0.00226742 3.57293e-06 0" quat="0.707107 0 0 -0.707107" material="thigh" mesh="thigh"/>
          <geom name="//unnamed_geom_97" class="collision" size="0.0624057 0.0384035" pos="0.0396227 0 0" quat="0.5 0.5 0.5 0.5"/>
          <geom name="//unnamed_geom_98" class="collision" size="0.0360033 0.0288026 0.135674" pos="0.029717 0 -0.143164" quat="0.707107 0 0 0.707107" type="box"/>
          <geom name="//unnamed_geom_99" class="visual" pos="0.099354 0 -0.288731" quat="1 0 0 0" material="drive" mesh="drive"/>
          <geom name="//unnamed_geom_100" class="collision" size="0.0480044 0.0672062" pos="0.0300142 0 -0.288731" quat="0.707107 0 0.707107 0"/>
          <geom name="//unnamed_geom_101" class="reward_collision_sphere" size="0.076807" pos="0.0247642 0 0"/>
          <body name="RH_SHANK" pos="0.100575 0.000142022 -0.289193" quat="1 -3.17872e-06 -1.49907e-05 -3.58161e-06">
            <inertial pos="0.00456962 -0.0536725 -0.081956" quat="0.992727 -0.117636 -0.00217107 -0.0255006" mass="0.518863" diaginertia="0.00971488 0.00476294 0.00119938"/>
            <joint name="RH_KFE" pos="0 0 0" axis="0.999954 -0.00420338 0.00866005" range="-3.12809 3.12417" armature="0.010015" damping="0" frictionloss="0.0974442"/>
            <geom name="//unnamed_geom_102" class="visual" pos="0.000739357 0.00394229 0" quat="0.707107 0 0 -0.707107" material="shank_l" mesh="shank_l"/>
            <geom name="RH_kfe_act" class="collision" size="0.0576053 0.0192018" pos="0.0198114 0 0" quat="0.5 0.5 0.5 0.5"/>
            <geom name="//unnamed_geom_104" class="collision" size="0.0552041 0.032403 0.0182417" pos="0.0198114 -0.0504039 0" quat="0.5 0.5 0.5 0.5" type="box"/>
            <geom name="//unnamed_geom_105" class="visual" pos="0.0129267 -0.0758269 -0.342395" quat="0.382683 0 0 -0.92388" material="foot" mesh="foot"/>
            <geom name="RH_calf" class="collision" size="0.0168015 0.135614" pos="0.0129269 -0.0770974 -0.171197" quat="0.707107 0 0 0.707107"/>
            <geom name="RH_foot" class="foot" size="0.0294507" pos="0.0129269 -0.0770974 -0.3196" quat="0.707107 0 0 0.707107"/>
            <geom name="//unnamed_geom_108" class="reward_collision_sphere" size="0.0960088" pos="-0.0495284 0 0"/>
            <geom name="//unnamed_geom_109" class="reward_collision_sphere" size="0.0480044" pos="0.0129269 -0.0770974 -0.3196"/>
            <site name="RH_foot" class="foot" pos="0.0129269 -0.0770974 -0.3196" quat="0.707107 0 0 0.707107" size="0.00960088"/>
          </body>
        </body>
      </body>
    </body>
  </worldbody>

  <contact>
    <pair class="/" geom1="floor" geom2="LF_foot" name="//unnamed_contact_0"/>
    <pair class="/" geom1="floor" geom2="RF_foot" name="//unnamed_contact_1"/>
    <pair class="/" geom1="floor" geom2="LH_foot" name="//unnamed_contact_2"/>
    <pair class="/" geom1="floor" geom2="RH_foot" name="//unnamed_contact_3"/>
  </contact>

  <actuator>
    <general name="LF_HAA" class="/" joint="LF_HAA" forcerange="-76.1149 76.1149" gainprm="78.8875" biasprm="0 -78.8875 -2.00525"/>
    <general name="LF_HFE" class="/" joint="LF_HFE" forcerange="-80.4361 80.4361" gainprm="78.8875" biasprm="0 -78.8875 -2.00525"/>
    <general name="LF_KFE" class="/" joint="LF_KFE" forcerange="-73.5336 73.5336" gainprm="78.8875" biasprm="0 -78.8875 -2.00525"/>
    <general name="RF_HAA" class="/" joint="RF_HAA" forcerange="-79.1903 79.1903" gainprm="78.8875" biasprm="0 -78.8875 -2.00525"/>
    <general name="RF_HFE" class="/" joint="RF_HFE" forcerange="-77.6203 77.6203" gainprm="78.8875" biasprm="0 -78.8875 -2.00525"/>
    <general name="RF_KFE" class="/" joint="RF_KFE" forcerange="-83.3925 83.3925" gainprm="78.8875" biasprm="0 -78.8875 -2.00525"/>
    <general name="LH_HAA" class="/" joint="LH_HAA" forcerange="-82.1869 82.1869" gainprm="78.8875" biasprm="0 -78.8875 -2.00525"/>
    <general name="LH_HFE" class="/" joint="LH_HFE" forcerange="-75.0127 75.0127" gainprm="78.8875" biasprm="0 -78.8875 -2.00525"/>
    <general name="LH_KFE" class="/" joint="LH_KFE" forcerange="-79.5321 79.5321" gainprm="78.8875" biasprm="0 -78.8875 -2.00525"/>
    <general name="RH_HAA" class="/" joint="RH_HAA" forcerange="-76.7051 76.7051" gainprm="78.8875" biasprm="0 -78.8875 -2.00525"/>
    <general name="RH_HFE" class="/" joint="RH_HFE" forcerange="-71.3609 71.3609" gainprm="78.8875" biasprm="0 -78.8875 -2.00525"/>
    <general name="RH_KFE" class="/" joint="RH_KFE" forcerange="-74.7865 74.7865" gainprm="78.8875" biasprm="0 -78.8875 -2.00525"/>
  </actuator>

  <sensor>
    <gyro site="imu" name="imu_angular_velocity"/>
    <velocimeter site="imu" name="imu_linear_velocity"/>
    <framelinvel objtype="site" objname="LF_foot" name="LF_foot_global_linear_velocity"/>
    <framelinvel objtype="site" objname="RF_foot" name="RF_foot_global_linear_velocity"/>
    <framelinvel objtype="site" objname="LH_foot" name="LH_foot_global_linear_velocity"/>
    <framelinvel objtype="site" objname="RH_foot" name="RH_foot_global_linear_velocity"/>
  </sensor>

  <keyframe>
    <key name="home" qpos="0 0 0.55 1 0 0 0 0 0.4 -0.8 0 -0.4 0.8 0 -0.4 0.8 0 0.4 -0.8"/>
  </keyframe>
</mujoco>
