<mujoco model="anymal_c">
  <compiler angle="radian" assetdir="assets" balanceinertia="true" inertiafromgeom="false"/>

  <option timestep="0.005" density="1.2" viscosity="2e-05"/>

  <size nkey="1"/>

  <visual>
    <quality shadowsize="8192"/>
    <map shadowclip="0.5"/>
  </visual>

  <default>
    <default class="/">
      <material specular="0" shininess="0.25"/>
      <geom contype="0" conaffinity="0" group="1" solref="-1000 -80"/>
      <site size="0.01 0.005 0.005" group="5"/>
      <general forcelimited="true" forcerange="-80 80" biastype="affine" gainprm="80" biasprm="0 -80 -2"/>
      <default class="anymal_c">
        <joint armature="0.01" damping="0.01" frictionloss="0.1"/>
        <default class="visual">
          <geom type="mesh" group="2"/>
          <default class="visual_zflip"/>
        </default>
        <default class="collision">
          <geom type="cylinder" group="3"/>
          <default class="foot">
            <geom size="0.03 0 0" type="sphere" condim="6" priority="1" friction="0.8 0.02 0.01" solimp="0.015 1 0.03"/>
          </default>
        </default>
      </default>
      <default class="reward_collision_sphere">
        <geom group="5" rgba="1 0 0 1"/>
      </default>
    </default>
  </default>

  <asset>
    <texture type="skybox" colorspace="auto" name="//unnamed_texture_0" builtin="gradient" rgb1="0.95 0.95 0.95" rgb2="0.95 0.95 0.95" width="100" height="600"/>
    <texture type="2d" colorspace="auto" name="texplane" builtin="checker" rgb1="0.345 0.575 0.748" rgb2="0.345 0.575 0.748" markrgb="1 1 1" width="512" height="512"/>
    <texture type="2d" colorspace="linear" name="base" file="base.png"/>
    <texture type="2d" colorspace="linear" name="top_shell" file="top_shell.png"/>
    <texture type="2d" colorspace="linear" name="bottom_shell" file="bottom_shell.png"/>
    <texture type="2d" colorspace="linear" name="remote" file="remote.png"/>
    <texture type="2d" colorspace="linear" name="hatch" file="hatch.png"/>
    <texture type="2d" colorspace="linear" name="handle" file="handle.png"/>
    <texture type="2d" colorspace="linear" name="face" file="face.png"/>
    <texture type="2d" colorspace="linear" name="battery" file="battery.png"/>
    <texture type="2d" colorspace="linear" name="lidar_cage" file="lidar_cage.png"/>
    <texture type="2d" colorspace="linear" name="depth_camera" file="depth_camera.png"/>
    <texture type="2d" colorspace="linear" name="wide_angle_camera" file="wide_angle_camera.png"/>
    <texture type="2d" colorspace="linear" name="lidar" file="lidar.png"/>
    <texture type="2d" colorspace="linear" name="drive" file="drive.png"/>
    <texture type="2d" colorspace="linear" name="hip_l" file="hip_l.png"/>
    <texture type="2d" colorspace="linear" name="shank_l" file="shank_l.png"/>
    <texture type="2d" colorspace="linear" name="foot" file="foot.png"/>
    <texture type="2d" colorspace="linear" name="thigh" file="thigh.png"/>
    <texture type="2d" colorspace="linear" name="shank_r" file="shank_r.png"/>
    <texture type="2d" colorspace="linear" name="hip_r" file="hip_r.png"/>
    <material name="MatPlane" class="/" texture="texplane" texuniform="true" texrepeat="2 2" specular="0.9" shininess="0.5"/>
    <material name="black_plastic" class="/" rgba="0.007 0.007 0.007 1"/>
    <material name="green" class="/" rgba="0.052 0.178 0.033 1"/>
    <material name="red" class="/" rgba="0.178 0.006 0.005 1"/>
    <material name="yellow" class="/" rgba="0.178 0.119 0.006 1"/>
    <material name="lwl" class="/" rgba="0.8 0.8 0.8 1"/>
    <material name="base" class="/" texture="base"/>
    <material name="top_shell" class="/" texture="top_shell"/>
    <material name="bottom_shell" class="/" texture="bottom_shell"/>
    <material name="hip_l" class="/" texture="hip_l"/>
    <material name="thigh" class="/" texture="thigh"/>
    <material name="shank_l" class="/" texture="shank_l"/>
    <material name="foot" class="/" texture="foot"/>
    <material name="hip_r" class="/" texture="hip_r"/>
    <material name="shank" class="/" texture="shank_r"/>
    <material name="hatch" class="/" texture="hatch"/>
    <material name="remote" class="/" texture="remote"/>
    <material name="handle" class="/" texture="handle"/>
    <material name="face" class="/" texture="face"/>
    <material name="depth_camera" class="/" texture="depth_camera"/>
    <material name="wide_angle_camera" class="/" texture="wide_angle_camera"/>
    <material name="battery" class="/" texture="battery"/>
    <material name="lidar_cage" class="/" texture="lidar_cage"/>
    <material name="lidar" class="/" texture="lidar"/>
    <material name="drive" class="/" texture="drive"/>
    <mesh name="base_0" class="/" file="base_0.obj"/>
    <mesh name="base_1" class="/" file="base_1.obj"/>
    <mesh name="base_2" class="/" file="base_2.obj"/>
    <mesh name="base_3" class="/" file="base_3.obj"/>
    <mesh name="base_4" class="/" file="base_4.obj"/>
    <mesh name="base_5" class="/" file="base_5.obj"/>
    <mesh name="top_shell" class="/" file="top_shell.obj"/>
    <mesh name="bottom_shell" class="/" file="bottom_shell.obj"/>
    <mesh name="remote" class="/" file="remote.obj"/>
    <mesh name="handle" class="/" file="handle.obj"/>
    <mesh name="face" class="/" file="face.obj"/>
    <mesh name="wide_angle_camera" class="/" file="wide_angle_camera.obj"/>
    <mesh name="depth_camera" class="/" file="depth_camera.obj"/>
    <mesh name="battery" class="/" file="battery.obj"/>
    <mesh name="lidar_cage" class="/" file="lidar_cage.obj"/>
    <mesh name="lidar" class="/" file="lidar.obj"/>
    <mesh name="drive" class="/" file="drive.obj"/>
    <mesh name="hip_l" class="/" file="hip_l.obj"/>
    <mesh name="thigh" class="/" file="thigh.obj"/>
    <mesh name="shank_l" class="/" file="shank_l.obj"/>
    <mesh name="foot" class="/" file="foot.obj"/>
    <mesh name="hip_r" class="/" file="hip_r.obj"/>
    <mesh name="hatch" class="/" file="hatch.obj"/>
    <mesh name="shank_r" class="/" file="shank_r.obj"/>
  </asset>

  <worldbody>
    <geom name="floor" class="/" size="100 100 0.125" type="plane" group="0" material="MatPlane"/>
    <light name="toplight_shadow" class="/" pos="0 0 5" dir="0.0990148 0.0990148 -0.990148" type="directional" ambient="0.04 0.04 0.04" diffuse="0.55 0.55 0.55" specular="0.12 0.12 0.12"/>
    <light name="toplight_fill" class="/" pos="0 0 5" dir="0.0990148 0.0990148 -0.990148" type="directional" castshadow="false" ambient="0.04 0.04 0.04" diffuse="0.3 0.3 0.3" specular="0.08 0.08 0.08"/>
    <body name="trunk" childclass="anymal_c" pos="0.000265557 -0.000307117 0.000657952" quat="1 0.000587861 0.000250797 0.000397014">
      <inertial pos="0.000892434 -0.00273348 0.0499212" quat="0.501063 0.49854 0.498336 0.502052" mass="22.4963" diaginertia="1.00893 0.571067 0.280784"/>
      <joint name="//unnamed_joint_0" type="free" armature="0" damping="0" frictionloss="0"/>
      <geom name="//unnamed_geom_1" class="visual" material="green" mesh="base_0"/>
      <geom name="//unnamed_geom_2" class="visual" material="yellow" mesh="base_1"/>
      <geom name="//unnamed_geom_3" class="visual" material="red" mesh="base_2"/>
      <geom name="//unnamed_geom_4" class="visual" material="black_plastic" mesh="base_3"/>
      <geom name="//unnamed_geom_5" class="visual" material="lwl" mesh="base_4"/>
      <geom name="//unnamed_geom_6" class="visual" material="base" mesh="base_5"/>
      <geom name="trunk_1" class="collision" size="0.303017 0.0731421 0.0940398" type="box"/>
      <geom name="trunk_2" class="collision" size="0.0940398 0.0757543" pos="0.238347 0.0688682 0" quat="0.707107 0 0.707107 0"/>
      <geom name="trunk_3" class="collision" size="0.0940398 0.0757543" pos="-0.238347 0.0688682 0" quat="0.707107 0 0.707107 0"/>
      <geom name="trunk_4" class="collision" size="0.0940398 0.0757543" pos="0.238347 -0.0688682 0" quat="0.707107 0 0.707107 0"/>
      <geom name="trunk_5" class="collision" size="0.0940398 0.0757543" pos="-0.238347 -0.0688682 0" quat="0.707107 0 0.707107 0"/>
      <geom name="//unnamed_geom_12" class="visual" material="top_shell" mesh="top_shell"/>
      <geom name="//unnamed_geom_13" class="visual" material="bottom_shell" mesh="bottom_shell"/>
      <geom name="//unnamed_geom_14" class="visual" material="remote" mesh="remote"/>
      <geom name="//unnamed_geom_15" class="visual" material="handle" mesh="handle"/>
      <geom name="//unnamed_geom_16" class="visual" pos="0.454229 0 0" quat="1 0 0 0" material="face" mesh="face"/>
      <geom name="trunk_6" class="collision" size="0.0574688 0.0731421 0.0940398" pos="0.514501 0 0" type="box"/>
      <geom name="//unnamed_geom_18" class="collision" size="0.0940398 0.0574688" pos="0.514501 0.0688682 0" quat="0.707107 0 0.707107 0"/>
      <geom name="//unnamed_geom_19" class="collision" size="0.0940398 0.0574688" pos="0.514501 -0.0688682 0" quat="0.707107 0 0.707107 0"/>
      <geom name="//unnamed_geom_20" class="visual" pos="0.505896 0 -0.0304948" quat="0.965926 0 0.258819 0" material="depth_camera" mesh="depth_camera"/>
      <geom name="//unnamed_geom_21" class="visual" pos="0.56217 0 0.0157931" material="wide_angle_camera" mesh="wide_angle_camera"/>
      <geom name="//unnamed_geom_22" class="visual_zflip" pos="-0.454229 0 0" quat="0 0 0 1" material="face" mesh="face"/>
      <geom name="trunk_7" class="collision" size="0.0574688 0.0731421 0.0940398" pos="-0.514501 0 0" quat="0 0 0 1" type="box"/>
      <geom name="//unnamed_geom_24" class="collision" size="0.0940398 0.0574688" pos="-0.514501 -0.0688682 0" quat="0 -0.707107 0 0.707107"/>
      <geom name="//unnamed_geom_25" class="collision" size="0.0940398 0.0574688" pos="-0.514501 0.0688682 0" quat="0 -0.707107 0 0.707107"/>
      <geom name="//unnamed_geom_26" class="visual" pos="-0.505896 0 -0.0304948" quat="0 -0.258819 0 0.965926" material="depth_camera" mesh="depth_camera"/>
      <geom name="//unnamed_geom_27" class="visual_zflip" pos="-0.56217 0 0.0157931" quat="0 0 0 1" material="wide_angle_camera" mesh="wide_angle_camera"/>
      <geom name="//unnamed_geom_28" class="visual" material="battery" mesh="battery"/>
      <geom name="//unnamed_geom_29" class="visual" pos="0 0.0737522 0.0309578" quat="0.683013 -0.183013 0.183013 0.683013" material="depth_camera" mesh="depth_camera"/>
      <geom name="//unnamed_geom_30" class="visual" pos="0 -0.0737522 0.0309578" quat="0.683013 0.183013 0.183013 -0.683013" material="depth_camera" mesh="depth_camera"/>
      <geom name="//unnamed_geom_31" class="visual" pos="-0.398889 0 0.0775411" quat="1 0 0 0" material="lidar_cage" mesh="lidar_cage"/>
      <geom name="trunk_8" class="collision" size="0.0731421 0.0626932" pos="-0.398889 0 0.14084"/>
      <geom name="//unnamed_geom_33" class="visual" pos="-0.398889 -4.4008e-05 0.150018" quat="0.707107 0 0 -0.707107" material="lidar" mesh="lidar"/>
      <geom name="//unnamed_geom_34" class="visual" pos="0.328645 0.102344 -1.22732e-09" quat="0.258819 0.965926 0 0" material="drive" mesh="drive"/>
      <geom name="//unnamed_geom_35" class="visual" pos="0.328645 -0.102344 1.22732e-09" quat="0.258819 -0.965926 0 0" material="drive" mesh="drive"/>
      <geom name="//unnamed_geom_36" class="visual" pos="-0.328645 0.102344 1.22732e-09" quat="0 0 0.965926 -0.258819" material="drive" mesh="drive"/>
      <geom name="//unnamed_geom_37" class="visual" pos="-0.328645 -0.102344 -1.22732e-09" quat="0 0 -0.965926 -0.258819" material="drive" mesh="drive"/>
      <geom name="//unnamed_geom_38" class="visual" pos="0.127118 0 0.0770136" quat="1 0 0 0" material="hatch" mesh="hatch"/>
      <geom name="//unnamed_geom_39" class="reward_collision_sphere" size="0.125386"/>
      <geom name="//unnamed_geom_40" class="reward_collision_sphere" size="0.125386" pos="0.493132 0 0"/>
      <geom name="//unnamed_geom_41" class="reward_collision_sphere" size="0.125386" pos="-0.493132 0 0"/>
      <site name="imu" pos="0.285074 0.00765016 0.0363223" size="0.0104489"/>
      <camera name="track" pos="0 -1.96766 0" quat="0.707107 0.707107 0 0" mode="trackcom"/>
      <camera name="ego_camera" pos="0.493132 0 -0.0421992" quat="-0.5 -0.5 0.5 0.5"/>
      <body name="LF_HIP" pos="0.326298 0.0996996 -0.00134909" quat="0.258299 0.966065 -2.07857e-05 -3.12662e-05">
        <inertial pos="0.0619333 -0.0175407 -0.00779378" quat="-0.127962 0.709587 -0.135434 0.679536" mass="3.17702" diaginertia="0.0091119 0.00427663 0.00418858"/>
        <joint name="LF_HAA" pos="0 0 0" axis="0.999999 -0.00150043 0.000295443" range="-0.724187 0.514254" armature="0.0104611" damping="0.0226912" frictionloss="0.0906784"/>
        <geom name="//unnamed_geom_42" class="visual" pos="0 -7.21976e-05 1.18584e-05" quat="0.258819 -0.965926 0 0" material="hip_l" mesh="hip_l"/>
        <geom name="//unnamed_geom_43" class="visual" pos="0.0656413 -0.0780888 -0.0456108" quat="0.183013 -0.683013 0.683013 0.183013" material="drive" mesh="drive"/>
        <geom name="//unnamed_geom_44" class="collision" size="0.0522443 0.0731421" pos="0.0656413 -0.0117664 -0.00728464" quat="-0.353553 -0.612372 0.612372 -0.353553"/>
        <body name="LF_THIGH" pos="0.0638815 -0.0689678 -0.0429177" quat="0.183732 -0.682901 0.683226 0.181912">
          <inertial pos="0.0337325 0.000222718 -0.257027" quat="0.99287 0.0072187 -0.0776076 0.0901914" mass="3.41755" diaginertia="0.0483288 0.0271128 0.00553666"/>
          <joint name="LF_HFE" pos="0 0 0" axis="0.999996 0.00296763 0.000237169" stiffness="0.00358765" range="-3.08909 3.19011" armature="0.0106125" damping="0.0220951" frictionloss="0.0928655"/>
          <geom name="//unnamed_geom_45" class="visual" pos="0.00222868 3.51187e-06 0" quat="0.707107 0 0 -0.707107" material="thigh" mesh="thigh"/>
          <geom name="//unnamed_geom_46" class="collision" size="0.0679176 0.0417955" pos="0.0438339 0 0" quat="0.5 0.5 -0.5 -0.5"/>
          <geom name="//unnamed_geom_47" class="collision" size="0.0391833 0.0313466 0.147657" pos="0.0328754 0 -0.149084" quat="0.707107 0 0 -0.707107" type="box"/>
          <geom name="//unnamed_geom_48" class="visual" pos="0.109914 0 -0.300669" quat="1 0 0 0" material="drive" mesh="drive"/>
          <geom name="//unnamed_geom_49" class="collision" size="0.0522443 0.0731421" pos="0.0332042 0 -0.300669" quat="0.707107 0 0.707107 0"/>
          <geom name="//unnamed_geom_50" class="reward_collision_sphere" size="0.0835909" pos="0.0273962 0 0"/>
          <body name="LF_SHANK" pos="0.111201 0.00267338 -0.299582" quat="1 6.15346e-05 -0.00012255 3.88513e-05">
            <inertial pos="0.00569042 -0.0609325 -0.0868245" quat="0.993009 -0.115016 0.00110626 -0.0265326" mass="0.681468" diaginertia="0.0156854 0.00851928 0.00146665"/>
            <joint name="LF_KFE" pos="0 0 0" axis="0.999982 -0.00592794 0.000273334" range="-3.0888 3.14887" armature="0.0107314" damping="0.00500161" frictionloss="0.107335"/>
            <geom name="//unnamed_geom_51" class="visual" pos="0.000726722 0.00387492 0" quat="0.707107 0 0 -0.707107" material="shank_l" mesh="shank_l"/>
            <geom name="LF_kfe_act" class="collision" size="0.0626932 0.0208977" pos="0.021917 0 0" quat="0.5 0.5 -0.5 -0.5"/>
            <geom name="//unnamed_geom_53" class="collision" size="0.0600799 0.0352649 0.0198528" pos="0.021917 -0.0565694 0" quat="0.5 0.5 -0.5 -0.5" type="box"/>
            <geom name="//unnamed_geom_54" class="visual" pos="0.0143006 -0.0852793 -0.356552" quat="0.382683 0 0 -0.92388" material="foot" mesh="foot"/>
            <geom name="LF_calf" class="collision" size="0.0182855 0.147592" pos="0.0143008 -0.086528 -0.178276" quat="0.707107 0 0 -0.707107"/>
            <geom name="LF_foot" class="foot" size="0.0309676" pos="0.0143008 -0.086528 -0.332815" quat="0.707107 0 0 -0.707107"/>
            <geom name="//unnamed_geom_57" class="reward_collision_sphere" size="0.104489" pos="-0.0547924 0 0"/>
            <geom name="//unnamed_geom_58" class="reward_collision_sphere" size="0.0522443" pos="0.0143008 -0.086528 -0.332815"/>
            <site name="LF_foot" class="foot" pos="0.0143008 -0.086528 -0.332815" quat="0.707107 0 0 -0.707107" size="0.0104489"/>
          </body>
        </body>
      </body>
      <body name="RF_HIP" pos="0.326595 -0.102717 0.000508641" quat="0.258805 -0.96593 -3.3757e-05 6.45611e-05">
        <inertial pos="0.0597399 0.0135836 -0.011457" quat="0.133136 0.680148 0.117746 0.711203" mass="3.15856" diaginertia="0.00881998 0.00461932 0.00409712"/>
        <joint name="RF_HAA" pos="0 0 0" axis="0.999926 -0.0110169 0.0052489" range="-0.513411 0.728541" armature="0.010698" damping="0" frictionloss="0.10894"/>
        <geom name="//unnamed_geom_59" class="visual" pos="0 7.2197e-05 1.18584e-05" quat="0.258819 0.965926 0 0" material="hip_r" mesh="hip_r"/>
        <geom name="//unnamed_geom_60" class="visual" pos="0.0656413 0.0780888 -0.0456108" quat="0.183013 0.683013 0.683013 -0.183013" material="drive" mesh="drive"/>
        <geom name="//unnamed_geom_61" class="collision" size="0.0522443 0.0731421" pos="0.0656413 0.0117664 -0.00728464" quat="-0.353553 0.612372 0.612372 0.353553"/>
        <body name="RF_THIGH" pos="0.0680161 0.069918 -0.0467656" quat="0.182766 0.683668 0.682666 -0.182103">
          <inertial pos="0.0362766 -0.000328152 -0.261089" quat="0.994081 -0.00235632 -0.0722268 0.0811195" mass="3.66601" diaginertia="0.0468072 0.0268795 0.0056984"/>
          <joint name="RF_HFE" pos="0 0 0" axis="0.999999 -0.000248392 -0.0014363" range="-3.13097 3.15609" armature="0.00921822" damping="0.0102686" frictionloss="0.111216"/>
          <geom name="//unnamed_geom_62" class="visual" pos="0.00222868 3.51187e-06 0" quat="0.707107 0 0 -0.707107" material="thigh" mesh="thigh"/>
          <geom name="//unnamed_geom_63" class="collision" size="0.0679176 0.0417955" pos="0.0438339 0 0" quat="0.5 0.5 0.5 0.5"/>
          <geom name="//unnamed_geom_64" class="collision" size="0.0391833 0.0313466 0.147657" pos="0.0328754 0 -0.149084" quat="0.707107 0 0 0.707107" type="box"/>
          <geom name="//unnamed_geom_65" class="visual" pos="0.109914 0 -0.300669" quat="1 0 0 0" material="drive" mesh="drive"/>
          <geom name="//unnamed_geom_66" class="collision" size="0.0522443 0.0731421" pos="0.0332042 0 -0.300669" quat="0.707107 0 0.707107 0"/>
          <geom name="//unnamed_geom_67" class="reward_collision_sphere" size="0.0835909" pos="0.0273962 0 0"/>
          <body name="RF_SHANK" pos="0.107176 0.000493247 -0.301181" quat="0.999999 -0.000461372 -0.000848334 -0.000546576">
            <inertial pos="0.00339937 0.060367 -0.0850114" quat="0.991838 0.125771 -0.00102687 0.0209233" mass="0.715109" diaginertia="0.016883 0.00864188 0.00151601"/>
            <joint name="RF_KFE" pos="0 0 0" axis="1 -0.000795368 0.000599332" range="-3.18632 3.08847" armature="0.0120708" damping="0.0213993" frictionloss="0.112519"/>
            <geom name="//unnamed_geom_68" class="visual" pos="0.000726718 -0.00387491 0" quat="0.707107 0 0 0.707107" material="shank" mesh="shank_r"/>
            <geom name="RF_kfe_act" class="collision" size="0.0626932 0.0208977" pos="0.021917 0 0" quat="0.5 0.5 0.5 0.5"/>
            <geom name="//unnamed_geom_70" class="collision" size="0.0600799 0.0352649 0.0198528" pos="0.021917 0.0565694 0" quat="0.5 0.5 0.5 0.5" type="box"/>
            <geom name="//unnamed_geom_71" class="visual" pos="0.014301 0.0852793 -0.356552" quat="0.382683 0 0 0.92388" material="foot" mesh="foot"/>
            <geom name="RF_calf" class="collision" size="0.0182855 0.147592" pos="0.0143008 0.086528 -0.178276" quat="0.707107 0 0 0.707107"/>
            <geom name="RF_foot" class="foot" size="0.0279981" pos="0.0143008 0.086528 -0.332815" quat="0.707107 0 0 0.707107"/>
            <geom name="//unnamed_geom_74" class="reward_collision_sphere" size="0.104489" pos="-0.0547924 0 0"/>
            <geom name="//unnamed_geom_75" class="reward_collision_sphere" size="0.0522443" pos="0.0143008 0.086528 -0.332815"/>
            <site name="RF_foot" class="foot" pos="0.0143008 0.086528 -0.332815" quat="0.707107 0 0 0.707107" size="0.0104489"/>
          </body>
        </body>
      </body>
      <body name="LH_HIP" pos="-0.325468 0.10013 -0.0016936" quat="5.6616e-05 -5.5027e-05 0.965948 -0.258737">
        <inertial pos="0.0620262 0.0174788 -0.0110735" quat="0.124995 0.686719 0.129402 0.704307" mass="3.2634" diaginertia="0.0097307 0.00470644 0.00431182"/>
        <joint name="LH_HAA" pos="0 0 0" axis="0.999886 0.000404614 -0.0151162" range="-0.504267 0.739784" armature="0.011089" damping="0" frictionloss="0.104245"/>
        <geom name="//unnamed_geom_76" class="visual" pos="0 7.2197e-05 1.18584e-05" quat="-0.258819 -0.965926 0 0" material="hip_r" mesh="hip_r"/>
        <geom name="//unnamed_geom_77" class="visual" pos="0.0656413 0.0780888 -0.0456108" quat="0.183013 0.683013 0.683013 -0.183013" material="drive" mesh="drive"/>
        <geom name="//unnamed_geom_78" class="collision" size="0.0522443 0.0731421" pos="0.0656413 0.0117664 -0.00728464" quat="-0.353553 0.612372 0.612372 0.353553"/>
        <body name="LH_THIGH" pos="0.0646057 0.0700739 -0.0437569" quat="0.182963 0.682974 0.683071 -0.182992">
          <inertial pos="0.0320204 0.000366673 -0.261343" quat="0.992742 -0.00703346 -0.0795633 0.0899076" mass="3.33247" diaginertia="0.0450077 0.0275139 0.00533879"/>
          <joint name="LH_HFE" pos="0 0 0" axis="1 0.000898429 0.000285836" stiffness="0.0103594" range="-3.18188 3.08732" armature="0.0100385" damping="0" frictionloss="0.105862"/>
          <geom name="//unnamed_geom_79" class="visual" pos="0.00222868 3.51187e-06 0" quat="0.707107 0 0 -0.707107" material="thigh" mesh="thigh"/>
          <geom name="//unnamed_geom_80" class="collision" size="0.0679176 0.0417955" pos="0.0438339 0 0" quat="0.5 0.5 -0.5 -0.5"/>
          <geom name="//unnamed_geom_81" class="collision" size="0.0391833 0.0313466 0.147657" pos="0.0328754 0 -0.149084" quat="0.707107 0 0 -0.707107" type="box"/>
          <geom name="//unnamed_geom_82" class="visual" pos="0.109914 0 -0.300669" quat="1 0 0 0" material="drive" mesh="drive"/>
          <geom name="//unnamed_geom_83" class="collision" size="0.0522443 0.0731421" pos="0.0332042 0 -0.300669" quat="0.707107 0 0.707107 0"/>
          <geom name="//unnamed_geom_84" class="reward_collision_sphere" size="0.0835909" pos="0.0273962 0 0"/>
          <body name="LH_SHANK" pos="0.109141 -0.000253099 -0.30148" quat="1 2.98422e-05 3.92388e-05 -7.76319e-05">
            <inertial pos="0.00793232 0.0628931 -0.0854957" quat="0.994094 0.106789 0.00427424 0.0188466" mass="0.686497" diaginertia="0.0158618 0.0089956 0.00149856"/>
            <joint name="LH_KFE" pos="0 0 0" axis="0.999999 0.000565777 -0.000830926" range="-3.08882 3.08589" armature="0.0117806" damping="0.0222223" frictionloss="0.0898669"/>
            <geom name="//unnamed_geom_85" class="visual" pos="0.000726718 -0.00387491 0" quat="-0.707107 0 0 -0.707107" material="shank" mesh="shank_r"/>
            <geom name="LH_kfe_act" class="collision" size="0.0626932 0.0208977" pos="0.021917 0 0" quat="0.5 0.5 -0.5 -0.5"/>
            <geom name="//unnamed_geom_87" class="collision" size="0.0600799 0.0352649 0.0198528" pos="0.021917 0.0565694 0" quat="0.5 0.5 -0.5 -0.5" type="box"/>
            <geom name="//unnamed_geom_88" class="visual" pos="0.014301 0.0852793 -0.356552" quat="-0.382683 0 0 -0.92388" material="foot" mesh="foot"/>
            <geom name="LH_calf" class="collision" size="0.0182855 0.147592" pos="0.0143008 0.086528 -0.178276" quat="0.707107 0 0 -0.707107"/>
            <geom name="LH_foot" class="foot" size="0.0350384" pos="0.0143008 0.086528 -0.332815" quat="0.707107 0 0 -0.707107"/>
            <geom name="//unnamed_geom_91" class="reward_collision_sphere" size="0.104489" pos="-0.0547924 0 0"/>
            <geom name="//unnamed_geom_92" class="reward_collision_sphere" size="0.0522443" pos="0.0143008 0.086528 -0.332815"/>
            <site name="LH_foot" class="foot" pos="0.0143008 0.086528 -0.332815" quat="0.707107 0 0 -0.707107" size="0.0104489"/>
          </body>
        </body>
      </body>
      <body name="RH_HIP" pos="-0.32677 -0.103587 0.00182575" quat="-3.69756e-05 0.000163004 -0.965912 -0.258872">
        <inertial pos="0.0597242 -0.0131149 -0.0111718" quat="-0.125885 0.711055 -0.142646 0.676909" mass="3.20406" diaginertia="0.00899561 0.00445436 0.00420814"/>
        <joint name="RH_HAA" pos="0 0 0" axis="0.99991 0.00435924 0.0127169" range="-0.775467 0.5351" armature="0.00980465" damping="0.00108687" frictionloss="0.10398"/>
        <geom name="//unnamed_geom_93" class="visual" pos="0 -7.21976e-05 1.18584e-05" quat="-0.258819 0.965926 0 0" material="hip_l" mesh="hip_l"/>
        <geom name="//unnamed_geom_94" class="visual" pos="0.0656413 -0.0780888 -0.0456108" quat="-0.183013 0.683013 -0.683013 -0.183013" material="drive" mesh="drive"/>
        <geom name="//unnamed_geom_95" class="collision" size="0.0522443 0.0731421" pos="0.0656413 -0.0117664 -0.00728464" quat="0.353553 0.612372 -0.612372 0.353553"/>
        <body name="RH_THIGH" pos="0.0677198 -0.0701076 -0.0461999" quat="-0.183941 0.683522 -0.682398 -0.182472">
          <inertial pos="0.0338673 0.00219689 -0.259418" quat="0.99317 -0.00357826 -0.080989 0.083918" mass="3.27407" diaginertia="0.0446783 0.0269422 0.00536723"/>
          <joint name="RH_HFE" pos="0 0 0" axis="0.999992 0.00155574 0.00374339" stiffness="0.000418086" range="-3.09364 3.14388" armature="0.0109499" damping="0.0175005" frictionloss="0.104132"/>
          <geom name="//unnamed_geom_96" class="visual" pos="0.00222868 3.51187e-06 0" quat="0.707107 0 0 -0.707107" material="thigh" mesh="thigh"/>
          <geom name="//unnamed_geom_97" class="collision" size="0.0679176 0.0417955" pos="0.0438339 0 0" quat="0.5 0.5 0.5 0.5"/>
          <geom name="//unnamed_geom_98" class="collision" size="0.0391833 0.0313466 0.147657" pos="0.0328754 0 -0.149084" quat="0.707107 0 0 0.707107" type="box"/>
          <geom name="//unnamed_geom_99" class="visual" pos="0.109914 0 -0.300669" quat="1 0 0 0" material="drive" mesh="drive"/>
          <geom name="//unnamed_geom_100" class="collision" size="0.0522443 0.0731421" pos="0.0332042 0 -0.300669" quat="0.707107 0 0.707107 0"/>
          <geom name="//unnamed_geom_101" class="reward_collision_sphere" size="0.0835909" pos="0.0273962 0 0"/>
          <body name="RH_SHANK" pos="0.109196 0.00271761 -0.300194" quat="0.999999 1.15809e-05 -0.00111167 0.000554567">
            <inertial pos="0.00889665 -0.0615451 -0.0852448" quat="0.993188 -0.115044 0.00929834 -0.0159722" mass="0.678896" diaginertia="0.0156151 0.00851943 0.00142399"/>
            <joint name="RH_KFE" pos="0 0 0" axis="0.999998 -0.00199078 0.000728315" range="-3.12814 3.18795" armature="0.010351" damping="0.0218502" frictionloss="0.112237"/>
            <geom name="//unnamed_geom_102" class="visual" pos="0.000726722 0.00387492 0" quat="0.707107 0 0 -0.707107" material="shank_l" mesh="shank_l"/>
            <geom name="RH_kfe_act" class="collision" size="0.0626932 0.0208977" pos="0.021917 0 0" quat="0.5 0.5 0.5 0.5"/>
            <geom name="//unnamed_geom_104" class="collision" size="0.0600799 0.0352649 0.0198528" pos="0.021917 -0.0565694 0" quat="0.5 0.5 0.5 0.5" type="box"/>
            <geom name="//unnamed_geom_105" class="visual" pos="0.0143006 -0.0852793 -0.356552" quat="0.382683 0 0 -0.92388" material="foot" mesh="foot"/>
            <geom name="RH_calf" class="collision" size="0.0182855 0.147592" pos="0.0143008 -0.086528 -0.178276" quat="0.707107 0 0 0.707107"/>
            <geom name="RH_foot" class="foot" size="0.0270839" pos="0.0143008 -0.086528 -0.332815" quat="0.707107 0 0 0.707107"/>
            <geom name="//unnamed_geom_108" class="reward_collision_sphere" size="0.104489" pos="-0.0547924 0 0"/>
            <geom name="//unnamed_geom_109" class="reward_collision_sphere" size="0.0522443" pos="0.0143008 -0.086528 -0.332815"/>
            <site name="RH_foot" class="foot" pos="0.0143008 -0.086528 -0.332815" quat="0.707107 0 0 0.707107" size="0.0104489"/>
          </body>
        </body>
      </body>
    </body>
  </worldbody>

  <contact>
    <pair class="/" geom1="floor" geom2="LF_foot" name="//unnamed_contact_0"/>
    <pair class="/" geom1="floor" geom2="RF_foot" name="//unnamed_contact_1"/>
    <pair class="/" geom1="floor" geom2="LH_foot" name="//unnamed_contact_2"/>
    <pair class="/" geom1="floor" geom2="RH_foot" name="//unnamed_contact_3"/>
  </contact>

  <actuator>
    <general name="LF_HAA" class="/" joint="LF_HAA" forcerange="-75.5858 75.5858" gainprm="79.2401" biasprm="0 -79.2401 -2.08594"/>
    <general name="LF_HFE" class="/" joint="LF_HFE" forcerange="-76.1786 76.1786" gainprm="79.2401" biasprm="0 -79.2401 -2.08594"/>
    <general name="LF_KFE" class="/" joint="LF_KFE" forcerange="-82.8174 82.8174" gainprm="79.2401" biasprm="0 -79.2401 -2.08594"/>
    <general name="RF_HAA" class="/" joint="RF_HAA" forcerange="-83.6563 83.6563" gainprm="79.2401" biasprm="0 -79.2401 -2.08594"/>
    <general name="RF_HFE" class="/" joint="RF_HFE" forcerange="-93.9175 93.9175" gainprm="79.2401" biasprm="0 -79.2401 -2.08594"/>
    <general name="RF_KFE" class="/" joint="RF_KFE" forcerange="-86.3866 86.3866" gainprm="79.2401" biasprm="0 -79.2401 -2.08594"/>
    <general name="LH_HAA" class="/" joint="LH_HAA" forcerange="-85.0334 85.0334" gainprm="79.2401" biasprm="0 -79.2401 -2.08594"/>
    <general name="LH_HFE" class="/" joint="LH_HFE" forcerange="-75.4957 75.4957" gainprm="79.2401" biasprm="0 -79.2401 -2.08594"/>
    <general name="LH_KFE" class="/" joint="LH_KFE" forcerange="-88.3457 88.3457" gainprm="79.2401" biasprm="0 -79.2401 -2.08594"/>
    <general name="RH_HAA" class="/" joint="RH_HAA" forcerange="-86.4169 86.4169" gainprm="79.2401" biasprm="0 -79.2401 -2.08594"/>
    <general name="RH_HFE" class="/" joint="RH_HFE" forcerange="-92.6376 92.6376" gainprm="79.2401" biasprm="0 -79.2401 -2.08594"/>
    <general name="RH_KFE" class="/" joint="RH_KFE" forcerange="-81.8061 81.8061" gainprm="79.2401" biasprm="0 -79.2401 -2.08594"/>
  </actuator>

  <sensor>
    <gyro site="imu" name="imu_angular_velocity"/>
    <velocimeter site="imu" name="imu_linear_velocity"/>
    <framelinvel objtype="site" objname="LF_foot" name="LF_foot_global_linear_velocity"/>
    <framelinvel objtype="site" objname="RF_foot" name="RF_foot_global_linear_velocity"/>
    <framelinvel objtype="site" objname="LH_foot" name="LH_foot_global_linear_velocity"/>
    <framelinvel objtype="site" objname="RH_foot" name="RH_foot_global_linear_velocity"/>
  </sensor>

  <keyframe>
    <key name="home" qpos="0 0 0.55 1 0 0 0 0 0.4 -0.8 0 -0.4 0.8 0 -0.4 0.8 0 0.4 -0.8"/>
  </keyframe>
</mujoco>
