<mujoco model="anymal_c">
  <compiler angle="radian" assetdir="assets" balanceinertia="true" inertiafromgeom="false"/>

  <option timestep="0.005" density="1.2" viscosity="2e-05"/>

  <size nkey="1"/>

  <visual>
    <quality shadowsize="8192"/>
    <map shadowclip="0.5"/>
  </visual>

  <default>
    <default class="/">
      <material specular="0" shininess="0.25"/>
      <geom contype="0" conaffinity="0" group="1" solref="-1000 -80"/>
      <site size="0.01 0.005 0.005" group="5"/>
      <general forcelimited="true" forcerange="-80 80" biastype="affine" gainprm="80" biasprm="0 -80 -2"/>
      <default class="anymal_c">
        <joint armature="0.01" damping="0.01" frictionloss="0.1"/>
        <default class="visual">
          <geom type="mesh" group="2"/>
          <default class="visual_zflip"/>
        </default>
        <default class="collision">
          <geom type="cylinder" group="3"/>
          <default class="foot">
            <geom size="0.03 0 0" type="sphere" condim="6" priority="1" friction="0.8 0.02 0.01" solimp="0.015 1 0.03"/>
          </default>
        </default>
      </default>
      <default class="reward_collision_sphere">
        <geom group="5" rgba="1 0 0 1"/>
      </default>
    </default>
  </default>

  <asset>
    <texture type="skybox" colorspace="auto" name="//unnamed_texture_0" builtin="gradient" rgb1="0.95 0.95 0.95" rgb2="0.95 0.95 0.95" width="100" height="600"/>
    <texture type="2d" colorspace="auto" name="texplane" builtin="checker" rgb1="0.345 0.575 0.748" rgb2="0.345 0.575 0.748" markrgb="1 1 1" width="512" height="512"/>
    <texture type="2d" colorspace="linear" name="base" file="base.png"/>
    <texture type="2d" colorspace="linear" name="top_shell" file="top_shell.png"/>
    <texture type="2d" colorspace="linear" name="bottom_shell" file="bottom_shell.png"/>
    <texture type="2d" colorspace="linear" name="remote" file="remote.png"/>
    <texture type="2d" colorspace="linear" name="hatch" file="hatch.png"/>
    <texture type="2d" colorspace="linear" name="handle" file="handle.png"/>
    <texture type="2d" colorspace="linear" name="face" file="face.png"/>
    <texture type="2d" colorspace="linear" name="battery" file="battery.png"/>
    <texture type="2d" colorspace="linear" name="lidar_cage" file="lidar_cage.png"/>
    <texture type="2d" colorspace="linear" name="depth_camera" file="depth_camera.png"/>
    <texture type="2d" colorspace="linear" name="wide_angle_camera" file="wide_angle_camera.png"/>
    <texture type="2d" colorspace="linear" name="lidar" file="lidar.png"/>
    <texture type="2d" colorspace="linear" name="drive" file="drive.png"/>
    <texture type="2d" colorspace="linear" name="hip_l" file="hip_l.png"/>
    <texture type="2d" colorspace="linear" name="shank_l" file="shank_l.png"/>
    <texture type="2d" colorspace="linear" name="foot" file="foot.png"/>
    <texture type="2d" colorspace="linear" name="thigh" file="thigh.png"/>
    <texture type="2d" colorspace="linear" name="shank_r" file="shank_r.png"/>
    <texture type="2d" colorspace="linear" name="hip_r" file="hip_r.png"/>
    <material name="MatPlane" class="/" texture="texplane" texuniform="true" texrepeat="2 2" specular="0.9" shininess="0.5"/>
    <material name="black_plastic" class="/" rgba="0.007 0.007 0.007 1"/>
    <material name="green" class="/" rgba="0.052 0.178 0.033 1"/>
    <material name="red" class="/" rgba="0.178 0.006 0.005 1"/>
    <material name="yellow" class="/" rgba="0.178 0.119 0.006 1"/>
    <material name="lwl" class="/" rgba="0.8 0.8 0.8 1"/>
    <material name="base" class="/" texture="base"/>
    <material name="top_shell" class="/" texture="top_shell"/>
    <material name="bottom_shell" class="/" texture="bottom_shell"/>
    <material name="hip_l" class="/" texture="hip_l"/>
    <material name="thigh" class="/" texture="thigh"/>
    <material name="shank_l" class="/" texture="shank_l"/>
    <material name="foot" class="/" texture="foot"/>
    <material name="hip_r" class="/" texture="hip_r"/>
    <material name="shank" class="/" texture="shank_r"/>
    <material name="hatch" class="/" texture="hatch"/>
    <material name="remote" class="/" texture="remote"/>
    <material name="handle" class="/" texture="handle"/>
    <material name="face" class="/" texture="face"/>
    <material name="depth_camera" class="/" texture="depth_camera"/>
    <material name="wide_angle_camera" class="/" texture="wide_angle_camera"/>
    <material name="battery" class="/" texture="battery"/>
    <material name="lidar_cage" class="/" texture="lidar_cage"/>
    <material name="lidar" class="/" texture="lidar"/>
    <material name="drive" class="/" texture="drive"/>
    <mesh name="base_0" class="/" file="base_0.obj"/>
    <mesh name="base_1" class="/" file="base_1.obj"/>
    <mesh name="base_2" class="/" file="base_2.obj"/>
    <mesh name="base_3" class="/" file="base_3.obj"/>
    <mesh name="base_4" class="/" file="base_4.obj"/>
    <mesh name="base_5" class="/" file="base_5.obj"/>
    <mesh name="top_shell" class="/" file="top_shell.obj"/>
    <mesh name="bottom_shell" class="/" file="bottom_shell.obj"/>
    <mesh name="remote" class="/" file="remote.obj"/>
    <mesh name="handle" class="/" file="handle.obj"/>
    <mesh name="face" class="/" file="face.obj"/>
    <mesh name="wide_angle_camera" class="/" file="wide_angle_camera.obj"/>
    <mesh name="depth_camera" class="/" file="depth_camera.obj"/>
    <mesh name="battery" class="/" file="battery.obj"/>
    <mesh name="lidar_cage" class="/" file="lidar_cage.obj"/>
    <mesh name="lidar" class="/" file="lidar.obj"/>
    <mesh name="drive" class="/" file="drive.obj"/>
    <mesh name="hip_l" class="/" file="hip_l.obj"/>
    <mesh name="thigh" class="/" file="thigh.obj"/>
    <mesh name="shank_l" class="/" file="shank_l.obj"/>
    <mesh name="foot" class="/" file="foot.obj"/>
    <mesh name="hip_r" class="/" file="hip_r.obj"/>
    <mesh name="hatch" class="/" file="hatch.obj"/>
    <mesh name="shank_r" class="/" file="shank_r.obj"/>
  </asset>

  <worldbody>
    <geom name="floor" class="/" size="100 100 0.125" type="plane" group="0" material="MatPlane"/>
    <light name="toplight_shadow" class="/" pos="0 0 5" dir="0.0990148 0.0990148 -0.990148" type="directional" ambient="0.04 0.04 0.04" diffuse="0.55 0.55 0.55" specular="0.12 0.12 0.12"/>
    <light name="toplight_fill" class="/" pos="0 0 5" dir="0.0990148 0.0990148 -0.990148" type="directional" castshadow="false" ambient="0.04 0.04 0.04" diffuse="0.3 0.3 0.3" specular="0.08 0.08 0.08"/>
    <body name="trunk" childclass="anymal_c" pos="0.00038736 -3.0572e-05 -0.000890249" quat="1 0.000145977 -0.000411266 0.00023525">
      <inertial pos="0.000264358 -0.00126733 0.0486083" quat="0.499857 0.500132 0.499974 0.500037" mass="19.0297" diaginertia="0.759172 0.532032 0.190202"/>
      <joint name="//unnamed_joint_0" type="free" armature="0" damping="0" frictionloss="0"/>
      <geom name="//unnamed_geom_1" class="visual" material="green" mesh="base_0"/>
      <geom name="//unnamed_geom_2" class="visual" material="yellow" mesh="base_1"/>
      <geom name="//unnamed_geom_3" class="visual" material="red" mesh="base_2"/>
      <geom name="//unnamed_geom_4" class="visual" material="black_plastic" mesh="base_3"/>
      <geom name="//unnamed_geom_5" class="visual" material="lwl" mesh="base_4"/>
      <geom name="//unnamed_geom_6" class="visual" material="base" mesh="base_5"/>
      <geom name="trunk_1" class="collision" size="0.287931 0.0695006 0.0893579" type="box"/>
      <geom name="trunk_2" class="collision" size="0.0893579 0.0719827" pos="0.225226 0.0678223 0" quat="0.707107 0 0.707107 0"/>
      <geom name="trunk_3" class="collision" size="0.0893579 0.0719827" pos="-0.225226 0.0678223 0" quat="0.707107 0 0.707107 0"/>
      <geom name="trunk_4" class="collision" size="0.0893579 0.0719827" pos="0.225226 -0.0678223 0" quat="0.707107 0 0.707107 0"/>
      <geom name="trunk_5" class="collision" size="0.0893579 0.0719827" pos="-0.225226 -0.0678223 0" quat="0.707107 0 0.707107 0"/>
      <geom name="//unnamed_geom_12" class="visual" material="top_shell" mesh="top_shell"/>
      <geom name="//unnamed_geom_13" class="visual" material="bottom_shell" mesh="bottom_shell"/>
      <geom name="//unnamed_geom_14" class="visual" material="remote" mesh="remote"/>
      <geom name="//unnamed_geom_15" class="visual" material="handle" mesh="handle"/>
      <geom name="//unnamed_geom_16" class="visual" pos="0.429224 0 0" quat="1 0 0 0" material="face" mesh="face"/>
      <geom name="trunk_6" class="collision" size="0.0546076 0.0695006 0.0893579" pos="0.486178 0 0" type="box"/>
      <geom name="//unnamed_geom_18" class="collision" size="0.0893579 0.0546076" pos="0.486178 0.0678223 0" quat="0.707107 0 0.707107 0"/>
      <geom name="//unnamed_geom_19" class="collision" size="0.0893579 0.0546076" pos="0.486178 -0.0678223 0" quat="0.707107 0 0.707107 0"/>
      <geom name="//unnamed_geom_20" class="visual" pos="0.478046 0 -0.02798" quat="0.965926 0 0.258819 0" material="depth_camera" mesh="depth_camera"/>
      <geom name="//unnamed_geom_21" class="visual" pos="0.531223 0 0.0145835" material="wide_angle_camera" mesh="wide_angle_camera"/>
      <geom name="//unnamed_geom_22" class="visual_zflip" pos="-0.429224 0 0" quat="0 0 0 1" material="face" mesh="face"/>
      <geom name="trunk_7" class="collision" size="0.0546076 0.0695006 0.0893579" pos="-0.486178 0 0" quat="0 0 0 1" type="box"/>
      <geom name="//unnamed_geom_24" class="collision" size="0.0893579 0.0546076" pos="-0.486178 -0.0678223 0" quat="0 -0.707107 0 0.707107"/>
      <geom name="//unnamed_geom_25" class="collision" size="0.0893579 0.0546076" pos="-0.486178 0.0678223 0" quat="0 -0.707107 0 0.707107"/>
      <geom name="//unnamed_geom_26" class="visual" pos="-0.478046 0 -0.02798" quat="0 -0.258819 0 0.965926" material="depth_camera" mesh="depth_camera"/>
      <geom name="//unnamed_geom_27" class="visual_zflip" pos="-0.531223 0 0.0145835" quat="0 0 0 1" material="wide_angle_camera" mesh="wide_angle_camera"/>
      <geom name="//unnamed_geom_28" class="visual" material="battery" mesh="battery"/>
      <geom name="//unnamed_geom_29" class="visual" pos="0 0.0732044 0.0287662" quat="0.683013 -0.183013 0.183013 0.683013" material="depth_camera" mesh="depth_camera"/>
      <geom name="//unnamed_geom_30" class="visual" pos="0 -0.0732044 0.0287662" quat="0.683013 0.183013 0.183013 -0.683013" material="depth_camera" mesh="depth_camera"/>
      <geom name="//unnamed_geom_31" class="visual" pos="-0.37693 0 0.0716025" quat="1 0 0 0" material="lidar_cage" mesh="lidar_cage"/>
      <geom name="trunk_8" class="collision" size="0.0695006 0.0595719" pos="-0.37693 0 0.130054"/>
      <geom name="//unnamed_geom_33" class="visual" pos="-0.37693 -2.61781e-05 0.138529" quat="0.707107 0 0 -0.707107" material="lidar" mesh="lidar"/>
      <geom name="//unnamed_geom_34" class="visual" pos="0.310553 0.100766 -9.13154e-11" quat="0.258819 0.965926 0 0" material="drive" mesh="drive"/>
      <geom name="//unnamed_geom_35" class="visual" pos="0.310553 -0.100766 9.13154e-11" quat="0.258819 -0.965926 0 0" material="drive" mesh="drive"/>
      <geom name="//unnamed_geom_36" class="visual" pos="-0.310553 0.100766 9.13154e-11" quat="0 0 0.965926 -0.258819" material="drive" mesh="drive"/>
      <geom name="//unnamed_geom_37" class="visual" pos="-0.310553 -0.100766 -9.13154e-11" quat="0 0 -0.965926 -0.258819" material="drive" mesh="drive"/>
      <geom name="//unnamed_geom_38" class="visual" pos="0.120121 0 0.0711154" quat="1 0 0 0" material="hatch" mesh="hatch"/>
      <geom name="//unnamed_geom_39" class="reward_collision_sphere" size="0.119144"/>
      <geom name="//unnamed_geom_40" class="reward_collision_sphere" size="0.119144" pos="0.465985 0 0"/>
      <geom name="//unnamed_geom_41" class="reward_collision_sphere" size="0.119144" pos="-0.465985 0 0"/>
      <site name="imu" pos="0.265376 0.00828319 0.0374505" size="0.00992866"/>
      <camera name="track" pos="0 -1.93778 0" quat="0.707107 0.707107 0 0" mode="trackcom"/>
      <camera name="ego_camera" pos="0.465985 0 -0.0389674" quat="-0.5 -0.5 0.5 0.5"/>
      <body name="LF_HIP" pos="0.310758 0.100874 0.000339765" quat="0.258793 0.965933 -6.55176e-05 -0.000224145">
        <inertial pos="0.0586226 -0.0147614 -0.00839063" quat="-0.128174 0.709693 -0.135171 0.679438" mass="2.62047" diaginertia="0.00677382 0.00405342 0.00280512"/>
        <joint name="LF_HAA" pos="0 0 0" axis="0.999994 0.00270431 0.00222359" range="-0.720559 0.469348" armature="0.00985823" damping="0.00742221" frictionloss="0.100307"/>
        <geom name="//unnamed_geom_42" class="visual" pos="0 -5.37167e-06 8.82292e-07" quat="0.258819 -0.965926 0 0" material="hip_l" mesh="hip_l"/>
        <geom name="//unnamed_geom_43" class="visual" pos="0.0620278 -0.0742844 -0.0429273" quat="0.183013 -0.683013 0.683013 0.183013" material="drive" mesh="drive"/>
        <geom name="//unnamed_geom_44" class="collision" size="0.0496433 0.0695006" pos="0.0620278 -0.0115877 -0.00672674" quat="-0.353553 -0.612372 0.612372 -0.353553"/>
        <body name="LF_THIGH" pos="0.0631188 -0.0691431 -0.0414373" quat="0.182678 -0.682964 0.683001 0.183573">
          <inertial pos="0.0320657 0.000157685 -0.240071" quat="0.993316 -0.00559505 -0.0784578 0.0844791" mass="2.9899" diaginertia="0.0358551 0.0247697 0.00362106"/>
          <joint name="LF_HFE" pos="0 0 0" axis="1 0.000655061 -0.000523201" stiffness="0.00491739" range="-3.12316 3.13242" armature="0.0100951" damping="0.0106104" frictionloss="0.102794"/>
          <geom name="//unnamed_geom_45" class="visual" pos="0.00132572 2.08903e-06 0" quat="0.707107 0 0 -0.707107" material="thigh" mesh="thigh"/>
          <geom name="//unnamed_geom_46" class="collision" size="0.0645363 0.0397146" pos="0.0414209 0 0" quat="0.5 0.5 -0.5 -0.5"/>
          <geom name="//unnamed_geom_47" class="collision" size="0.0372325 0.029786 0.140306" pos="0.0310657 0 -0.137666" quat="0.707107 0 0 -0.707107" type="box"/>
          <geom name="//unnamed_geom_48" class="visual" pos="0.103863 0 -0.277642" quat="1 0 0 0" material="drive" mesh="drive"/>
          <geom name="//unnamed_geom_49" class="collision" size="0.0496433 0.0695006" pos="0.0313763 0 -0.277642" quat="0.707107 0 0.707107 0"/>
          <geom name="//unnamed_geom_50" class="reward_collision_sphere" size="0.0794292" pos="0.0258881 0 0"/>
          <body name="LF_SHANK" pos="0.103443 0.000767777 -0.278556" quat="1 -7.11025e-05 -1.75249e-05 -9.25787e-05">
            <inertial pos="0.00546181 -0.0593675 -0.0776642" quat="0.992824 -0.116975 -0.00168452 -0.0247982" mass="0.575164" diaginertia="0.0119334 0.00790531 0.000978763"/>
            <joint name="LF_KFE" pos="0 0 0" axis="0.999995 -0.00210027 -0.00249642" range="-3.14667 3.13915" armature="0.00953298" damping="0.0122566" frictionloss="0.0983312"/>
            <geom name="//unnamed_geom_51" class="visual" pos="0.000432289 0.00230499 0" quat="0.707107 0 0 -0.707107" material="shank_l" mesh="shank_l"/>
            <geom name="LF_kfe_act" class="collision" size="0.0595719 0.0198573" pos="0.0207105 0 0" quat="0.5 0.5 -0.5 -0.5"/>
            <geom name="//unnamed_geom_53" class="collision" size="0.0570888 0.0335092 0.0188644" pos="0.0207105 -0.0557102 0" quat="0.5 0.5 -0.5 -0.5" type="box"/>
            <geom name="//unnamed_geom_54" class="visual" pos="0.0135135 -0.0844711 -0.329245" quat="0.382683 0 0 -0.92388" material="foot" mesh="foot"/>
            <geom name="LF_calf" class="collision" size="0.0173751 0.140244" pos="0.0135136 -0.0852139 -0.164622" quat="0.707107 0 0 -0.707107"/>
            <geom name="LF_foot" class="foot" size="0.0296749" pos="0.0135136 -0.0852139 -0.307326" quat="0.707107 0 0 -0.707107"/>
            <geom name="//unnamed_geom_57" class="reward_collision_sphere" size="0.0992866" pos="-0.0517761 0 0"/>
            <geom name="//unnamed_geom_58" class="reward_collision_sphere" size="0.0496433" pos="0.0135136 -0.0852139 -0.307326"/>
            <site name="LF_foot" class="foot" pos="0.0135136 -0.0852139 -0.307326" quat="0.707107 0 0 -0.707107" size="0.00992866"/>
          </body>
        </body>
      </body>
      <body name="RF_HIP" pos="0.30955 -0.101006 0.000793181" quat="0.25878 -0.965936 7.03783e-05 3.9054e-05">
        <inertial pos="0.0592499 0.0130991 -0.00792801" quat="0.132521 0.681572 0.136153 0.706654" mass="2.72339" diaginertia="0.00695809 0.00429868 0.00288961"/>
        <joint name="RF_HAA" pos="0 0 0" axis="1 -0.000425295 -0.000763701" range="-0.484153 0.722702" armature="0.0101347" damping="0.0070625" frictionloss="0.0945998"/>
        <geom name="//unnamed_geom_59" class="visual" pos="0 5.37163e-06 8.8229e-07" quat="0.258819 0.965926 0 0" material="hip_r" mesh="hip_r"/>
        <geom name="//unnamed_geom_60" class="visual" pos="0.0620278 0.0742844 -0.0429273" quat="0.183013 0.683013 0.683013 -0.183013" material="drive" mesh="drive"/>
        <geom name="//unnamed_geom_61" class="collision" size="0.0496433 0.0695006" pos="0.0620278 0.0115877 -0.00672674" quat="-0.353553 0.612372 0.612372 0.353553"/>
        <body name="RF_THIGH" pos="0.0615635 0.0711469 -0.0421356" quat="0.18278 0.68303 0.683096 -0.182869">
          <inertial pos="0.0336055 0.00070193 -0.238303" quat="0.992968 -0.00263806 -0.079185 0.0879603" mass="3.01702" diaginertia="0.036115 0.0252012 0.00373459"/>
          <joint name="RF_HFE" pos="0 0 0" axis="1 0.000104398 0.000280037" stiffness="0.00496857" range="-3.15903 3.13424" armature="0.0100773" damping="0.0104946" frictionloss="0.0943148"/>
          <geom name="//unnamed_geom_62" class="visual" pos="0.00132572 2.08903e-06 0" quat="0.707107 0 0 -0.707107" material="thigh" mesh="thigh"/>
          <geom name="//unnamed_geom_63" class="collision" size="0.0645363 0.0397146" pos="0.0414209 0 0" quat="0.5 0.5 0.5 0.5"/>
          <geom name="//unnamed_geom_64" class="collision" size="0.0372325 0.029786 0.140306" pos="0.0310657 0 -0.137666" quat="0.707107 0 0 0.707107" type="box"/>
          <geom name="//unnamed_geom_65" class="visual" pos="0.103863 0 -0.277642" quat="1 0 0 0" material="drive" mesh="drive"/>
          <geom name="//unnamed_geom_66" class="collision" size="0.0496433 0.0695006" pos="0.0313763 0 -0.277642" quat="0.707107 0 0.707107 0"/>
          <geom name="//unnamed_geom_67" class="reward_collision_sphere" size="0.0794292" pos="0.0258881 0 0"/>
          <body name="RF_SHANK" pos="0.104254 0.000625186 -0.277305" quat="1 -0.0001399 -0.000277523 -8.29685e-05">
            <inertial pos="0.00556532 0.0593403 -0.0784757" quat="0.992479 0.117467 0.000730801 0.0344503" mass="0.574952" diaginertia="0.0120237 0.00803379 0.000990834"/>
            <joint name="RF_KFE" pos="0 0 0" axis="0.999995 0.00306227 0.00067026" range="-3.16514 3.14725" armature="0.0102625" damping="0.0162019" frictionloss="0.0943696"/>
            <geom name="//unnamed_geom_68" class="visual" pos="0.000432287 -0.00230498 0" quat="0.707107 0 0 0.707107" material="shank" mesh="shank_r"/>
            <geom name="RF_kfe_act" class="collision" size="0.0595719 0.0198573" pos="0.0207105 0 0" quat="0.5 0.5 0.5 0.5"/>
            <geom name="//unnamed_geom_70" class="collision" size="0.0570888 0.0335092 0.0188644" pos="0.0207105 0.0557102 0" quat="0.5 0.5 0.5 0.5" type="box"/>
            <geom name="//unnamed_geom_71" class="visual" pos="0.0135137 0.0844711 -0.329245" quat="0.382683 0 0 0.92388" material="foot" mesh="foot"/>
            <geom name="RF_calf" class="collision" size="0.0173751 0.140244" pos="0.0135136 0.0852139 -0.164622" quat="0.707107 0 0 0.707107"/>
            <geom name="RF_foot" class="foot" size="0.0281616" pos="0.0135136 0.0852139 -0.307326" quat="0.707107 0 0 0.707107"/>
            <geom name="//unnamed_geom_74" class="reward_collision_sphere" size="0.0992866" pos="-0.0517761 0 0"/>
            <geom name="//unnamed_geom_75" class="reward_collision_sphere" size="0.0496433" pos="0.0135136 0.0852139 -0.307326"/>
            <site name="RF_foot" class="foot" pos="0.0135136 0.0852139 -0.307326" quat="0.707107 0 0 0.707107" size="0.00992866"/>
          </body>
        </body>
      </body>
      <body name="LH_HIP" pos="-0.308599 0.101032 -0.000347206" quat="-6.44442e-05 -2.31893e-06 0.965919 -0.258844">
        <inertial pos="0.0587074 0.0144319 -0.00993038" quat="0.136413 0.680894 0.127785 0.708129" mass="2.7815" diaginertia="0.00731618 0.00429289 0.00297676"/>
        <joint name="LH_HAA" pos="0 0 0" axis="0.999986 -0.00299884 -0.00430765" range="-0.488259 0.70327" armature="0.00970654" damping="0.000471218" frictionloss="0.0997922"/>
        <geom name="//unnamed_geom_76" class="visual" pos="0 5.37163e-06 8.8229e-07" quat="-0.258819 -0.965926 0 0" material="hip_r" mesh="hip_r"/>
        <geom name="//unnamed_geom_77" class="visual" pos="0.0620278 0.0742844 -0.0429273" quat="0.183013 0.683013 0.683013 -0.183013" material="drive" mesh="drive"/>
        <geom name="//unnamed_geom_78" class="collision" size="0.0496433 0.0695006" pos="0.0620278 0.0115877 -0.00672674" quat="-0.353553 0.612372 0.612372 0.353553"/>
        <body name="LH_THIGH" pos="0.0615468 0.0713243 -0.0420841" quat="0.182909 0.683024 0.682888 -0.183537">
          <inertial pos="0.029872 -0.000888113 -0.240909" quat="0.992783 -0.0051063 -0.0807138 0.0885486" mass="3.04221" diaginertia="0.035118 0.0255109 0.00362733"/>
          <joint name="LH_HFE" pos="0 0 0" axis="1 -8.9448e-06 0.000136789" stiffness="0.000717452" range="-3.12485 3.14451" armature="0.00997676" damping="0.00689204" frictionloss="0.100092"/>
          <geom name="//unnamed_geom_79" class="visual" pos="0.00132572 2.08903e-06 0" quat="0.707107 0 0 -0.707107" material="thigh" mesh="thigh"/>
          <geom name="//unnamed_geom_80" class="collision" size="0.0645363 0.0397146" pos="0.0414209 0 0" quat="0.5 0.5 -0.5 -0.5"/>
          <geom name="//unnamed_geom_81" class="collision" size="0.0372325 0.029786 0.140306" pos="0.0310657 0 -0.137666" quat="0.707107 0 0 -0.707107" type="box"/>
          <geom name="//unnamed_geom_82" class="visual" pos="0.103863 0 -0.277642" quat="1 0 0 0" material="drive" mesh="drive"/>
          <geom name="//unnamed_geom_83" class="collision" size="0.0496433 0.0695006" pos="0.0313763 0 -0.277642" quat="0.707107 0 0.707107 0"/>
          <geom name="//unnamed_geom_84" class="reward_collision_sphere" size="0.0794292" pos="0.0258881 0 0"/>
          <body name="LH_SHANK" pos="0.104509 -0.00143525 -0.276619" quat="1 -1.83081e-05 -6.43608e-05 -6.49234e-05">
            <inertial pos="0.00479447 0.060396 -0.0777525" quat="0.992696 0.117967 -0.00148113 0.0252366" mass="0.59192" diaginertia="0.0124529 0.0082068 0.000999446"/>
            <joint name="LH_KFE" pos="0 0 0" axis="0.999988 0.00210882 -0.00446982" range="-3.12619 3.14205" armature="0.0106935" damping="0.0151603" frictionloss="0.0954074"/>
            <geom name="//unnamed_geom_85" class="visual" pos="0.000432287 -0.00230498 0" quat="-0.707107 0 0 -0.707107" material="shank" mesh="shank_r"/>
            <geom name="LH_kfe_act" class="collision" size="0.0595719 0.0198573" pos="0.0207105 0 0" quat="0.5 0.5 -0.5 -0.5"/>
            <geom name="//unnamed_geom_87" class="collision" size="0.0570888 0.0335092 0.0188644" pos="0.0207105 0.0557102 0" quat="0.5 0.5 -0.5 -0.5" type="box"/>
            <geom name="//unnamed_geom_88" class="visual" pos="0.0135137 0.0844711 -0.329245" quat="-0.382683 0 0 -0.92388" material="foot" mesh="foot"/>
            <geom name="LH_calf" class="collision" size="0.0173751 0.140244" pos="0.0135136 0.0852139 -0.164622" quat="0.707107 0 0 -0.707107"/>
            <geom name="LH_foot" class="foot" size="0.0295683" pos="0.0135136 0.0852139 -0.307326" quat="0.707107 0 0 -0.707107"/>
            <geom name="//unnamed_geom_91" class="reward_collision_sphere" size="0.0992866" pos="-0.0517761 0 0"/>
            <geom name="//unnamed_geom_92" class="reward_collision_sphere" size="0.0496433" pos="0.0135136 0.0852139 -0.307326"/>
            <site name="LH_foot" class="foot" pos="0.0135136 0.0852139 -0.307326" quat="0.707107 0 0 -0.707107" size="0.00992866"/>
          </body>
        </body>
      </body>
      <body name="RH_HIP" pos="-0.308383 -0.100591 -0.000317784" quat="-9.0111e-05 4.25551e-05 -0.965926 -0.258817">
        <inertial pos="0.0592503 -0.0157198 -0.0100917" quat="-0.134989 0.704741 -0.130561 0.684158" mass="2.67807" diaginertia="0.00678551 0.0040836 0.00281859"/>
        <joint name="RH_HAA" pos="0 0 0" axis="0.999962 0.0078145 -0.00392883" range="-0.750178 0.47659" armature="0.0103934" damping="0.0131026" frictionloss="0.0996829"/>
        <geom name="//unnamed_geom_93" class="visual" pos="0 -5.37167e-06 8.82292e-07" quat="-0.258819 0.965926 0 0" material="hip_l" mesh="hip_l"/>
        <geom name="//unnamed_geom_94" class="visual" pos="0.0620278 -0.0742844 -0.0429273" quat="-0.183013 0.683013 -0.683013 -0.183013" material="drive" mesh="drive"/>
        <geom name="//unnamed_geom_95" class="collision" size="0.0496433 0.0695006" pos="0.0620278 -0.0115877 -0.00672674" quat="0.353553 0.612372 -0.612372 0.353553"/>
        <body name="RH_THIGH" pos="0.063735 -0.0711195 -0.0424467" quat="-0.182708 0.68305 -0.683099 -0.182856">
          <inertial pos="0.0319964 -0.000675992 -0.239436" quat="0.993146 -0.00552473 -0.0808262 0.084248" mass="3.00971" diaginertia="0.0360531 0.0255366 0.00366596"/>
          <joint name="RH_HFE" pos="0 0 0" axis="1 -4.4505e-05 0.000250499" range="-3.15144 3.15319" armature="0.00978515" damping="0.00419343" frictionloss="0.0982202"/>
          <geom name="//unnamed_geom_96" class="visual" pos="0.00132572 2.08903e-06 0" quat="0.707107 0 0 -0.707107" material="thigh" mesh="thigh"/>
          <geom name="//unnamed_geom_97" class="collision" size="0.0645363 0.0397146" pos="0.0414209 0 0" quat="0.5 0.5 0.5 0.5"/>
          <geom name="//unnamed_geom_98" class="collision" size="0.0372325 0.029786 0.140306" pos="0.0310657 0 -0.137666" quat="0.707107 0 0 0.707107" type="box"/>
          <geom name="//unnamed_geom_99" class="visual" pos="0.103863 0 -0.277642" quat="1 0 0 0" material="drive" mesh="drive"/>
          <geom name="//unnamed_geom_100" class="collision" size="0.0496433 0.0695006" pos="0.0313763 0 -0.277642" quat="0.707107 0 0.707107 0"/>
          <geom name="//unnamed_geom_101" class="reward_collision_sphere" size="0.0794292" pos="0.0258881 0 0"/>
          <body name="RH_SHANK" pos="0.103864 0.00125776 -0.27724" quat="1 0.000657181 0.000253876 -7.19503e-05">
            <inertial pos="0.00647617 -0.0582478 -0.0790936" quat="0.992997 -0.11502 -0.00203861 -0.0268781" mass="0.583834" diaginertia="0.0122918 0.00788979 0.000992621"/>
            <joint name="RH_KFE" pos="0 0 0" axis="1 -0.000289954 0.000815508" stiffness="0.00106127" range="-3.12332 3.16149" armature="0.00996348" damping="0.0161235" frictionloss="0.0943457"/>
            <geom name="//unnamed_geom_102" class="visual" pos="0.000432289 0.00230499 0" quat="0.707107 0 0 -0.707107" material="shank_l" mesh="shank_l"/>
            <geom name="RH_kfe_act" class="collision" size="0.0595719 0.0198573" pos="0.0207105 0 0" quat="0.5 0.5 0.5 0.5"/>
            <geom name="//unnamed_geom_104" class="collision" size="0.0570888 0.0335092 0.0188644" pos="0.0207105 -0.0557102 0" quat="0.5 0.5 0.5 0.5" type="box"/>
            <geom name="//unnamed_geom_105" class="visual" pos="0.0135135 -0.0844711 -0.329245" quat="0.382683 0 0 -0.92388" material="foot" mesh="foot"/>
            <geom name="RH_calf" class="collision" size="0.0173751 0.140244" pos="0.0135136 -0.0852139 -0.164622" quat="0.707107 0 0 0.707107"/>
            <geom name="RH_foot" class="foot" size="0.0283931" pos="0.0135136 -0.0852139 -0.307326" quat="0.707107 0 0 0.707107"/>
            <geom name="//unnamed_geom_108" class="reward_collision_sphere" size="0.0992866" pos="-0.0517761 0 0"/>
            <geom name="//unnamed_geom_109" class="reward_collision_sphere" size="0.0496433" pos="0.0135136 -0.0852139 -0.307326"/>
            <site name="RH_foot" class="foot" pos="0.0135136 -0.0852139 -0.307326" quat="0.707107 0 0 0.707107" size="0.00992866"/>
          </body>
        </body>
      </body>
    </body>
  </worldbody>

  <contact>
    <pair class="/" geom1="floor" geom2="LF_foot" name="//unnamed_contact_0"/>
    <pair class="/" geom1="floor" geom2="RF_foot" name="//unnamed_contact_1"/>
    <pair class="/" geom1="floor" geom2="LH_foot" name="//unnamed_contact_2"/>
    <pair class="/" geom1="floor" geom2="RH_foot" name="//unnamed_contact_3"/>
  </contact>

  <actuator>
    <general name="LF_HAA" class="/" joint="LF_HAA" forcerange="-79.3335 79.3335" gainprm="81.4454" biasprm="0 -81.4454 -1.93266"/>
    <general name="LF_HFE" class="/" joint="LF_HFE" forcerange="-74.4863 74.4863" gainprm="81.4454" biasprm="0 -81.4454 -1.93266"/>
    <general name="LF_KFE" class="/" joint="LF_KFE" forcerange="-81.8962 81.8962" gainprm="81.4454" biasprm="0 -81.4454 -1.93266"/>
    <general name="RF_HAA" class="/" joint="RF_HAA" forcerange="-79.9691 79.9691" gainprm="81.4454" biasprm="0 -81.4454 -1.93266"/>
    <general name="RF_HFE" class="/" joint="RF_HFE" forcerange="-81.7547 81.7547" gainprm="81.4454" biasprm="0 -81.4454 -1.93266"/>
    <general name="RF_KFE" class="/" joint="RF_KFE" forcerange="-79.1579 79.1579" gainprm="81.4454" biasprm="0 -81.4454 -1.93266"/>
    <general name="LH_HAA" class="/" joint="LH_HAA" forcerange="-79.9573 79.9573" gainprm="81.4454" biasprm="0 -81.4454 -1.93266"/>
    <general name="LH_HFE" class="/" joint="LH_HFE" forcerange="-79.819 79.819" gainprm="81.4454" biasprm="0 -81.4454 -1.93266"/>
    <general name="LH_KFE" class="/" joint="LH_KFE" forcerange="-77.1302 77.1302" gainprm="81.4454" biasprm="0 -81.4454 -1.93266"/>
    <general name="RH_HAA" class="/" joint="RH_HAA" forcerange="-78.6869 78.6869" gainprm="81.4454" biasprm="0 -81.4454 -1.93266"/>
    <general name="RH_HFE" class="/" joint="RH_HFE" forcerange="-83.1889 83.1889" gainprm="81.4454" biasprm="0 -81.4454 -1.93266"/>
    <general name="RH_KFE" class="/" joint="RH_KFE" forcerange="-79.3207 79.3207" gainprm="81.4454" biasprm="0 -81.4454 -1.93266"/>
  </actuator>

  <sensor>
    <gyro site="imu" name="imu_angular_velocity"/>
    <velocimeter site="imu" name="imu_linear_velocity"/>
    <framelinvel objtype="site" objname="LF_foot" name="LF_foot_global_linear_velocity"/>
    <framelinvel objtype="site" objname="RF_foot" name="RF_foot_global_linear_velocity"/>
    <framelinvel objtype="site" objname="LH_foot" name="LH_foot_global_linear_velocity"/>
    <framelinvel objtype="site" objname="RH_foot" name="RH_foot_global_linear_velocity"/>
  </sensor>

  <keyframe>
    <key name="home" qpos="0 0 0.55 1 0 0 0 0 0.4 -0.8 0 -0.4 0.8 0 -0.4 0.8 0 0.4 -0.8"/>
  </keyframe>
</mujoco>
