<mujoco model="anymal_c">
  <compiler angle="radian" assetdir="assets" balanceinertia="true" inertiafromgeom="false"/>

  <option timestep="0.005" density="1.2" viscosity="2e-05"/>

  <size nkey="1"/>

  <visual>
    <quality shadowsize="8192"/>
    <map shadowclip="0.5"/>
  </visual>

  <default>
    <default class="/">
      <material specular="0" shininess="0.25"/>
      <geom contype="0" conaffinity="0" group="1" solref="-1000 -80"/>
      <site size="0.01 0.005 0.005" group="5"/>
      <general forcelimited="true" forcerange="-80 80" biastype="affine" gainprm="80" biasprm="0 -80 -2"/>
      <default class="anymal_c">
        <joint armature="0.01" damping="0.01" frictionloss="0.1"/>
        <default class="visual">
          <geom type="mesh" group="2"/>
          <default class="visual_zflip"/>
        </default>
        <default class="collision">
          <geom type="cylinder" group="3"/>
          <default class="foot">
            <geom size="0.03 0 0" type="sphere" condim="6" priority="1" friction="0.8 0.02 0.01" solimp="0.015 1 0.03"/>
          </default>
        </default>
      </default>
      <default class="reward_collision_sphere">
        <geom group="5" rgba="1 0 0 1"/>
      </default>
    </default>
  </default>

  <asset>
    <texture type="skybox" colorspace="auto" name="//unnamed_texture_0" builtin="gradient" rgb1="0.95 0.95 0.95" rgb2="0.95 0.95 0.95" width="100" height="600"/>
    <texture type="2d" colorspace="auto" name="texplane" builtin="checker" rgb1="0.345 0.575 0.748" rgb2="0.345 0.575 0.748" markrgb="1 1 1" width="512" height="512"/>
    <texture type="2d" colorspace="linear" name="base" file="base.png"/>
    <texture type="2d" colorspace="linear" name="top_shell" file="top_shell.png"/>
    <texture type="2d" colorspace="linear" name="bottom_shell" file="bottom_shell.png"/>
    <texture type="2d" colorspace="linear" name="remote" file="remote.png"/>
    <texture type="2d" colorspace="linear" name="hatch" file="hatch.png"/>
    <texture type="2d" colorspace="linear" name="handle" file="handle.png"/>
    <texture type="2d" colorspace="linear" name="face" file="face.png"/>
    <texture type="2d" colorspace="linear" name="battery" file="battery.png"/>
    <texture type="2d" colorspace="linear" name="lidar_cage" file="lidar_cage.png"/>
    <texture type="2d" colorspace="linear" name="depth_camera" file="depth_camera.png"/>
    <texture type="2d" colorspace="linear" name="wide_angle_camera" file="wide_angle_camera.png"/>
    <texture type="2d" colorspace="linear" name="lidar" file="lidar.png"/>
    <texture type="2d" colorspace="linear" name="drive" file="drive.png"/>
    <texture type="2d" colorspace="linear" name="hip_l" file="hip_l.png"/>
    <texture type="2d" colorspace="linear" name="shank_l" file="shank_l.png"/>
    <texture type="2d" colorspace="linear" name="foot" file="foot.png"/>
    <texture type="2d" colorspace="linear" name="thigh" file="thigh.png"/>
    <texture type="2d" colorspace="linear" name="shank_r" file="shank_r.png"/>
    <texture type="2d" colorspace="linear" name="hip_r" file="hip_r.png"/>
    <material name="MatPlane" class="/" texture="texplane" texuniform="true" texrepeat="2 2" specular="0.9" shininess="0.5"/>
    <material name="black_plastic" class="/" rgba="0.007 0.007 0.007 1"/>
    <material name="green" class="/" rgba="0.052 0.178 0.033 1"/>
    <material name="red" class="/" rgba="0.178 0.006 0.005 1"/>
    <material name="yellow" class="/" rgba="0.178 0.119 0.006 1"/>
    <material name="lwl" class="/" rgba="0.8 0.8 0.8 1"/>
    <material name="base" class="/" texture="base"/>
    <material name="top_shell" class="/" texture="top_shell"/>
    <material name="bottom_shell" class="/" texture="bottom_shell"/>
    <material name="hip_l" class="/" texture="hip_l"/>
    <material name="thigh" class="/" texture="thigh"/>
    <material name="shank_l" class="/" texture="shank_l"/>
    <material name="foot" class="/" texture="foot"/>
    <material name="hip_r" class="/" texture="hip_r"/>
    <material name="shank" class="/" texture="shank_r"/>
    <material name="hatch" class="/" texture="hatch"/>
    <material name="remote" class="/" texture="remote"/>
    <material name="handle" class="/" texture="handle"/>
    <material name="face" class="/" texture="face"/>
    <material name="depth_camera" class="/" texture="depth_camera"/>
    <material name="wide_angle_camera" class="/" texture="wide_angle_camera"/>
    <material name="battery" class="/" texture="battery"/>
    <material name="lidar_cage" class="/" texture="lidar_cage"/>
    <material name="lidar" class="/" texture="lidar"/>
    <material name="drive" class="/" texture="drive"/>
    <mesh name="base_0" class="/" file="base_0.obj"/>
    <mesh name="base_1" class="/" file="base_1.obj"/>
    <mesh name="base_2" class="/" file="base_2.obj"/>
    <mesh name="base_3" class="/" file="base_3.obj"/>
    <mesh name="base_4" class="/" file="base_4.obj"/>
    <mesh name="base_5" class="/" file="base_5.obj"/>
    <mesh name="top_shell" class="/" file="top_shell.obj"/>
    <mesh name="bottom_shell" class="/" file="bottom_shell.obj"/>
    <mesh name="remote" class="/" file="remote.obj"/>
    <mesh name="handle" class="/" file="handle.obj"/>
    <mesh name="face" class="/" file="face.obj"/>
    <mesh name="wide_angle_camera" class="/" file="wide_angle_camera.obj"/>
    <mesh name="depth_camera" class="/" file="depth_camera.obj"/>
    <mesh name="battery" class="/" file="battery.obj"/>
    <mesh name="lidar_cage" class="/" file="lidar_cage.obj"/>
    <mesh name="lidar" class="/" file="lidar.obj"/>
    <mesh name="drive" class="/" file="drive.obj"/>
    <mesh name="hip_l" class="/" file="hip_l.obj"/>
    <mesh name="thigh" class="/" file="thigh.obj"/>
    <mesh name="shank_l" class="/" file="shank_l.obj"/>
    <mesh name="foot" class="/" file="foot.obj"/>
    <mesh name="hip_r" class="/" file="hip_r.obj"/>
    <mesh name="hatch" class="/" file="hatch.obj"/>
    <mesh name="shank_r" class="/" file="shank_r.obj"/>
  </asset>

  <worldbody>
    <geom name="floor" class="/" size="100 100 0.125" type="plane" group="0" material="MatPlane"/>
    <light name="toplight_shadow" class="/" pos="0 0 5" dir="0.0990148 0.0990148 -0.990148" type="directional" ambient="0.04 0.04 0.04" diffuse="0.55 0.55 0.55" specular="0.12 0.12 0.12"/>
    <light name="toplight_fill" class="/" pos="0 0 5" dir="0.0990148 0.0990148 -0.990148" type="directional" castshadow="false" ambient="0.04 0.04 0.04" diffuse="0.3 0.3 0.3" specular="0.08 0.08 0.08"/>
    <body name="trunk" childclass="anymal_c" pos="-0.00258079 -0.0002914 0.00243966" quat="1 -0.00093611 -0.000145962 0.000274559">
      <inertial pos="0.00678479 0.00191997 0.0538845" quat="0.489714 0.504309 0.500431 0.505392" mass="16.1582" diaginertia="0.306507 0.347311 0.397485"/>
      <joint name="//unnamed_joint_0" type="free" armature="0" damping="0" frictionloss="0"/>
      <geom name="//unnamed_geom_1" class="visual" material="green" mesh="base_0"/>
      <geom name="//unnamed_geom_2" class="visual" material="yellow" mesh="base_1"/>
      <geom name="//unnamed_geom_3" class="visual" material="red" mesh="base_2"/>
      <geom name="//unnamed_geom_4" class="visual" material="black_plastic" mesh="base_3"/>
      <geom name="//unnamed_geom_5" class="visual" material="lwl" mesh="base_4"/>
      <geom name="//unnamed_geom_6" class="visual" material="base" mesh="base_5"/>
      <geom name="trunk_1" class="collision" size="0.27799 0.0671009 0.0862726" type="box"/>
      <geom name="trunk_2" class="collision" size="0.0862726 0.0694974" pos="0.188086 0.0621989 0" quat="0.707107 0 0.707107 0"/>
      <geom name="trunk_3" class="collision" size="0.0862726 0.0694974" pos="-0.188086 0.0621989 0" quat="0.707107 0 0.707107 0"/>
      <geom name="trunk_4" class="collision" size="0.0862726 0.0694974" pos="0.188086 -0.0621989 0" quat="0.707107 0 0.707107 0"/>
      <geom name="trunk_5" class="collision" size="0.0862726 0.0694974" pos="-0.188086 -0.0621989 0" quat="0.707107 0 0.707107 0"/>
      <geom name="//unnamed_geom_12" class="visual" material="top_shell" mesh="top_shell"/>
      <geom name="//unnamed_geom_13" class="visual" material="bottom_shell" mesh="bottom_shell"/>
      <geom name="//unnamed_geom_14" class="visual" material="remote" mesh="remote"/>
      <geom name="//unnamed_geom_15" class="visual" material="handle" mesh="handle"/>
      <geom name="//unnamed_geom_16" class="visual" pos="0.358444 0 0" quat="1 0 0 0" material="face" mesh="face"/>
      <geom name="trunk_6" class="collision" size="0.0527222 0.0671009 0.0862726" pos="0.406006 0 0" type="box"/>
      <geom name="//unnamed_geom_18" class="collision" size="0.0862726 0.0527222" pos="0.406006 0.0621989 0" quat="0.707107 0 0.707107 0"/>
      <geom name="//unnamed_geom_19" class="collision" size="0.0862726 0.0527222" pos="0.406006 -0.0621989 0" quat="0.707107 0 0.707107 0"/>
      <geom name="//unnamed_geom_20" class="visual" pos="0.399229 0 -0.0347334" quat="0.965926 0 0.258819 0" material="depth_camera" mesh="depth_camera"/>
      <geom name="//unnamed_geom_21" class="visual" pos="0.443624 0 0.0168029" material="wide_angle_camera" mesh="wide_angle_camera"/>
      <geom name="//unnamed_geom_22" class="visual_zflip" pos="-0.358444 0 0" quat="0 0 0 1" material="face" mesh="face"/>
      <geom name="trunk_7" class="collision" size="0.0527222 0.0671009 0.0862726" pos="-0.406006 0 0" quat="0 0 0 1" type="box"/>
      <geom name="//unnamed_geom_24" class="collision" size="0.0862726 0.0527222" pos="-0.406006 -0.0621989 0" quat="0 -0.707107 0 0.707107"/>
      <geom name="//unnamed_geom_25" class="collision" size="0.0862726 0.0527222" pos="-0.406006 0.0621989 0" quat="0 -0.707107 0 0.707107"/>
      <geom name="//unnamed_geom_26" class="visual" pos="-0.399229 0 -0.0347334" quat="0 -0.258819 0 0.965926" material="depth_camera" mesh="depth_camera"/>
      <geom name="//unnamed_geom_27" class="visual_zflip" pos="-0.443624 0 0.0168029" quat="0 0 0 1" material="wide_angle_camera" mesh="wide_angle_camera"/>
      <geom name="//unnamed_geom_28" class="visual" material="battery" mesh="battery"/>
      <geom name="//unnamed_geom_29" class="visual" pos="0 0.0682619 0.0306484" quat="0.683013 -0.183013 0.183013 0.683013" material="depth_camera" mesh="depth_camera"/>
      <geom name="//unnamed_geom_30" class="visual" pos="0 -0.0682619 0.0306484" quat="0.683013 0.183013 0.183013 -0.683013" material="depth_camera" mesh="depth_camera"/>
      <geom name="//unnamed_geom_31" class="visual" pos="-0.314774 0 0.082499" quat="1 0 0 0" material="lidar_cage" mesh="lidar_cage"/>
      <geom name="trunk_8" class="collision" size="0.0671009 0.0575151" pos="-0.314774 0 0.149845"/>
      <geom name="//unnamed_geom_33" class="visual" pos="-0.314774 9.34739e-06 0.15961" quat="0.707107 0 0 -0.707107" material="lidar" mesh="lidar"/>
      <geom name="//unnamed_geom_34" class="visual" pos="0.259342 0.0924929 -4.03445e-09" quat="0.258819 0.965926 0 0" material="drive" mesh="drive"/>
      <geom name="//unnamed_geom_35" class="visual" pos="0.259342 -0.0924929 4.03445e-09" quat="0.258819 -0.965926 0 0" material="drive" mesh="drive"/>
      <geom name="//unnamed_geom_36" class="visual" pos="-0.259342 0.0924929 4.03445e-09" quat="0 0 0.965926 -0.258819" material="drive" mesh="drive"/>
      <geom name="//unnamed_geom_37" class="visual" pos="-0.259342 -0.0924929 -4.03445e-09" quat="0 0 -0.965926 -0.258819" material="drive" mesh="drive"/>
      <geom name="//unnamed_geom_38" class="visual" pos="0.100313 0 0.0819378" quat="1 0 0 0" material="hatch" mesh="hatch"/>
      <geom name="//unnamed_geom_39" class="reward_collision_sphere" size="0.11503"/>
      <geom name="//unnamed_geom_40" class="reward_collision_sphere" size="0.11503" pos="0.389143 0 0"/>
      <geom name="//unnamed_geom_41" class="reward_collision_sphere" size="0.11503" pos="-0.389143 0 0"/>
      <site name="imu" pos="0.20072 0.00632714 0.066134" size="0.00958585"/>
      <camera name="track" pos="0 -1.77711 0" quat="0.707107 0.707107 0 0" mode="trackcom"/>
      <camera name="ego_camera" pos="0.389143 0 -0.0448974" quat="-0.5 -0.5 0.5 0.5"/>
      <body name="LF_HIP" pos="0.260084 0.0933271 -0.000640869" quat="0.258656 0.965969 0.000422939 0.000780404">
        <inertial pos="0.0486655 -0.0129623 -0.0101801" quat="-0.127237 0.710834 -0.135453 0.678364" mass="2.64147" diaginertia="0.00296723 0.00292304 0.00620256"/>
        <joint name="LF_HAA" pos="0 0 0" axis="0.99998 -0.00244711 -0.00587576" range="-0.726868 0.532063" armature="0.00964288" damping="0.012751" frictionloss="0.0942032"/>
        <geom name="//unnamed_geom_42" class="visual" pos="0 -0.000237328 3.8981e-05" quat="0.258819 -0.965926 0 0" material="hip_l" mesh="hip_l"/>
        <geom name="//unnamed_geom_43" class="visual" pos="0.0517993 -0.0631622 -0.0381966" quat="0.183013 -0.683013 0.683013 0.183013" material="drive" mesh="drive"/>
        <geom name="//unnamed_geom_44" class="collision" size="0.0479292 0.0671009" pos="0.0517993 -0.0106269 -0.00775042" quat="-0.353553 -0.612372 0.612372 -0.353553"/>
        <body name="LF_THIGH" pos="0.0507093 -0.0677006 -0.0461451" quat="0.183203 -0.683543 0.682691 0.182041">
          <inertial pos="0.027185 0.000142088 -0.274422" quat="0.99312 -0.00677286 -0.0832852 0.0820331" mass="2.6661" diaginertia="0.0143659 0.0171451 0.00758579"/>
          <joint name="LF_HFE" pos="0 0 0" axis="0.999953 -0.006089 0.00753328" stiffness="0.00155098" range="-3.18025 3.14791" armature="0.00836728" damping="0.00390951" frictionloss="0.0902367"/>
          <geom name="//unnamed_geom_45" class="visual" pos="-0.000473375 -7.45928e-07 0" quat="0.707107 0 0 -0.707107" material="thigh" mesh="thigh"/>
          <geom name="//unnamed_geom_46" class="collision" size="0.062308 0.0383434" pos="0.0345905 0 0" quat="0.5 0.5 -0.5 -0.5"/>
          <geom name="//unnamed_geom_47" class="collision" size="0.0359469 0.0287575 0.135461" pos="0.0259429 0 -0.158616" quat="0.707107 0 0 -0.707107" type="box"/>
          <geom name="//unnamed_geom_48" class="visual" pos="0.0867357 0 -0.319894" quat="1 0 0 0" material="drive" mesh="drive"/>
          <geom name="//unnamed_geom_49" class="collision" size="0.0479292 0.0671009" pos="0.0262023 0 -0.319894" quat="0.707107 0 0.707107 0"/>
          <geom name="//unnamed_geom_50" class="reward_collision_sphere" size="0.0766868" pos="0.0216191 0 0"/>
          <body name="LF_SHANK" pos="0.0866339 -0.00206219 -0.320605" quat="0.999999 -0.000406565 -0.00117061 -0.000502863">
            <inertial pos="0.00553749 -0.0518463 -0.0923446" quat="0.993236 -0.112974 -0.000520699 -0.0267952" mass="0.49838" diaginertia="0.00485948 0.00505214 0.00199711"/>
            <joint name="LF_KFE" pos="0 0 0" axis="0.999964 -0.0079037 0.00315801" stiffness="0.00862441" range="-3.13058 3.12331" armature="0.0106943" damping="0.0154278" frictionloss="0.0921218"/>
            <geom name="//unnamed_geom_51" class="visual" pos="-0.000154357 -0.000823041 0" quat="0.707107 0 0 -0.707107" material="shank_l" mesh="shank_l"/>
            <geom name="LF_kfe_act" class="collision" size="0.0575151 0.0191717" pos="0.0172953 0 0" quat="0.5 0.5 -0.5 -0.5"/>
            <geom name="//unnamed_geom_53" class="collision" size="0.0551177 0.0323522 0.0182131" pos="0.0172953 -0.0510911 0" quat="0.5 0.5 -0.5 -0.5" type="box"/>
            <geom name="//unnamed_geom_54" class="visual" pos="0.0112852 -0.0784137 -0.379349" quat="0.382683 0 0 -0.92388" material="foot" mesh="foot"/>
            <geom name="LF_calf" class="collision" size="0.0167752 0.135402" pos="0.0112852 -0.0781485 -0.189675" quat="0.707107 0 0 -0.707107"/>
            <geom name="LF_foot" class="foot" size="0.0298357" pos="0.0112852 -0.0781485 -0.354095" quat="0.707107 0 0 -0.707107"/>
            <geom name="//unnamed_geom_57" class="reward_collision_sphere" size="0.0958585" pos="-0.0432382 0 0"/>
            <geom name="//unnamed_geom_58" class="reward_collision_sphere" size="0.0479292" pos="0.0112852 -0.0781485 -0.354095"/>
            <site name="LF_foot" class="foot" pos="0.0112852 -0.0781485 -0.354095" quat="0.707107 0 0 -0.707107" size="0.00958585"/>
          </body>
        </body>
      </body>
      <body name="RF_HIP" pos="0.262572 -0.0925868 -0.00276178" quat="0.25872 -0.965952 -0.000540921 -2.55972e-05">
        <inertial pos="0.0484115 0.018486 -0.00977208" quat="0.129615 0.687482 0.141537 0.700382" mass="2.48693" diaginertia="0.00294462 0.00270285 0.00605739"/>
        <joint name="RF_HAA" pos="0 0 0" axis="0.999984 0.00184712 0.00533723" range="-0.452774 0.72677" armature="0.00895572" damping="0.011764" frictionloss="0.107146"/>
        <geom name="//unnamed_geom_59" class="visual" pos="0 0.000237326 3.89809e-05" quat="0.258819 0.965926 0 0" material="hip_r" mesh="hip_r"/>
        <geom name="//unnamed_geom_60" class="visual" pos="0.0517993 0.0631622 -0.0381966" quat="0.183013 0.683013 0.683013 -0.183013" material="drive" mesh="drive"/>
        <geom name="//unnamed_geom_61" class="collision" size="0.0479292 0.0671009" pos="0.0517993 0.0106269 -0.00775042" quat="-0.353553 0.612372 0.612372 0.353553"/>
        <body name="RF_THIGH" pos="0.0532958 0.0630397 -0.0453635" quat="0.182256 0.683346 0.68289 -0.182981">
          <inertial pos="0.0236892 -0.00263944 -0.276906" quat="0.992181 -0.00569796 -0.0847669 0.0914234" mass="2.59773" diaginertia="0.0140813 0.0163496 0.00696919"/>
          <joint name="RF_HFE" pos="0 0 0" axis="1 1.05449e-05 -2.31423e-05" stiffness="0.00380193" range="-3.09416 3.09522" armature="0.0093647" damping="0.00675691" frictionloss="0.106071"/>
          <geom name="//unnamed_geom_62" class="visual" pos="-0.000473375 -7.45928e-07 0" quat="0.707107 0 0 -0.707107" material="thigh" mesh="thigh"/>
          <geom name="//unnamed_geom_63" class="collision" size="0.062308 0.0383434" pos="0.0345905 0 0" quat="0.5 0.5 0.5 0.5"/>
          <geom name="//unnamed_geom_64" class="collision" size="0.0359469 0.0287575 0.135461" pos="0.0259429 0 -0.158616" quat="0.707107 0 0 0.707107" type="box"/>
          <geom name="//unnamed_geom_65" class="visual" pos="0.0867357 0 -0.319894" quat="1 0 0 0" material="drive" mesh="drive"/>
          <geom name="//unnamed_geom_66" class="collision" size="0.0479292 0.0671009" pos="0.0262023 0 -0.319894" quat="0.707107 0 0.707107 0"/>
          <geom name="//unnamed_geom_67" class="reward_collision_sphere" size="0.0766868" pos="0.0216191 0 0"/>
          <body name="RF_SHANK" pos="0.0854805 -0.000552752 -0.319805" quat="1 0.000230207 -0.000502435 0.000173468">
            <inertial pos="0.00542338 0.054523 -0.0903437" quat="0.99353 0.107103 0.0115847 0.0359709" mass="0.519656" diaginertia="0.0049966 0.0049433 0.00195512"/>
            <joint name="RF_KFE" pos="0 0 0" axis="0.999952 0.00559823 0.00799916" stiffness="0.0142896" range="-3.07761 3.12033" armature="0.00907085" damping="0" frictionloss="0.105212"/>
            <geom name="//unnamed_geom_68" class="visual" pos="-0.000154356 0.000823039 0" quat="0.707107 0 0 0.707107" material="shank" mesh="shank_r"/>
            <geom name="RF_kfe_act" class="collision" size="0.0575151 0.0191717" pos="0.0172953 0 0" quat="0.5 0.5 0.5 0.5"/>
            <geom name="//unnamed_geom_70" class="collision" size="0.0551177 0.0323522 0.0182131" pos="0.0172953 0.0510911 0" quat="0.5 0.5 0.5 0.5" type="box"/>
            <geom name="//unnamed_geom_71" class="visual" pos="0.0112851 0.0784137 -0.379349" quat="0.382683 0 0 0.92388" material="foot" mesh="foot"/>
            <geom name="RF_calf" class="collision" size="0.0167752 0.135402" pos="0.0112852 0.0781485 -0.189675" quat="0.707107 0 0 0.707107"/>
            <geom name="RF_foot" class="foot" size="0.0293646" pos="0.0112852 0.0781485 -0.354095" quat="0.707107 0 0 0.707107"/>
            <geom name="//unnamed_geom_74" class="reward_collision_sphere" size="0.0958585" pos="-0.0432382 0 0"/>
            <geom name="//unnamed_geom_75" class="reward_collision_sphere" size="0.0479292" pos="0.0112852 0.0781485 -0.354095"/>
            <site name="RF_foot" class="foot" pos="0.0112852 0.0781485 -0.354095" quat="0.707107 0 0 0.707107" size="0.00958585"/>
          </body>
        </body>
      </body>
      <body name="LH_HIP" pos="-0.261344 0.0926554 0.00174864" quat="-2.45456e-05 -1.79196e-05 0.965881 -0.258987">
        <inertial pos="0.0487316 0.0136795 -0.00580821" quat="0.133419 0.680181 0.1236 0.710124" mass="2.34292" diaginertia="0.00255299 0.00253379 0.00552876"/>
        <joint name="LH_HAA" pos="0 0 0" axis="0.999988 -0.00381072 -0.00322716" range="-0.480136 0.770999" armature="0.00883657" damping="0.0198387" frictionloss="0.0946845"/>
        <geom name="//unnamed_geom_76" class="visual" pos="0 0.000237326 3.89809e-05" quat="-0.258819 -0.965926 0 0" material="hip_r" mesh="hip_r"/>
        <geom name="//unnamed_geom_77" class="visual" pos="0.0517993 0.0631622 -0.0381966" quat="0.183013 0.683013 0.683013 -0.183013" material="drive" mesh="drive"/>
        <geom name="//unnamed_geom_78" class="collision" size="0.0479292 0.0671009" pos="0.0517993 0.0106269 -0.00775042" quat="-0.353553 0.612372 0.612372 0.353553"/>
        <body name="LH_THIGH" pos="0.0517893 0.06319 -0.0450748" quat="0.182159 0.682803 0.683392 -0.183231">
          <inertial pos="0.0312703 0.002399 -0.272212" quat="0.992492 -0.00763162 -0.084131 0.0884533" mass="2.62994" diaginertia="0.0153811 0.016562 0.00767259"/>
          <joint name="LH_HFE" pos="0 0 0" axis="0.999993 0.00328808 -0.00159855" range="-3.17257 3.13146" armature="0.0107502" damping="0.00762705" frictionloss="0.0953383"/>
          <geom name="//unnamed_geom_79" class="visual" pos="-0.000473375 -7.45928e-07 0" quat="0.707107 0 0 -0.707107" material="thigh" mesh="thigh"/>
          <geom name="//unnamed_geom_80" class="collision" size="0.062308 0.0383434" pos="0.0345905 0 0" quat="0.5 0.5 -0.5 -0.5"/>
          <geom name="//unnamed_geom_81" class="collision" size="0.0359469 0.0287575 0.135461" pos="0.0259429 0 -0.158616" quat="0.707107 0 0 -0.707107" type="box"/>
          <geom name="//unnamed_geom_82" class="visual" pos="0.0867357 0 -0.319894" quat="1 0 0 0" material="drive" mesh="drive"/>
          <geom name="//unnamed_geom_83" class="collision" size="0.0479292 0.0671009" pos="0.0262023 0 -0.319894" quat="0.707107 0 0.707107 0"/>
          <geom name="//unnamed_geom_84" class="reward_collision_sphere" size="0.0766868" pos="0.0216191 0 0"/>
          <body name="LH_SHANK" pos="0.0850382 0.00202016 -0.323268" quat="1 -0.000322731 0.000123683 7.75879e-05">
            <inertial pos="0.00631197 0.052334 -0.0929833" quat="0.992895 0.116919 -0.00123029 0.0221105" mass="0.48563" diaginertia="0.00460674 0.00470163 0.00193521"/>
            <joint name="LH_KFE" pos="0 0 0" axis="0.999942 -0.00588443 0.00906225" stiffness="0.00667584" range="-3.1759 3.13702" armature="0.00816706" damping="0" frictionloss="0.102234"/>
            <geom name="//unnamed_geom_85" class="visual" pos="-0.000154356 0.000823039 0" quat="-0.707107 0 0 -0.707107" material="shank" mesh="shank_r"/>
            <geom name="LH_kfe_act" class="collision" size="0.0575151 0.0191717" pos="0.0172953 0 0" quat="0.5 0.5 -0.5 -0.5"/>
            <geom name="//unnamed_geom_87" class="collision" size="0.0551177 0.0323522 0.0182131" pos="0.0172953 0.0510911 0" quat="0.5 0.5 -0.5 -0.5" type="box"/>
            <geom name="//unnamed_geom_88" class="visual" pos="0.0112851 0.0784137 -0.379349" quat="-0.382683 0 0 -0.92388" material="foot" mesh="foot"/>
            <geom name="LH_calf" class="collision" size="0.0167752 0.135402" pos="0.0112852 0.0781485 -0.189675" quat="0.707107 0 0 -0.707107"/>
            <geom name="LH_foot" class="foot" size="0.0324821" pos="0.0112852 0.0781485 -0.354095" quat="0.707107 0 0 -0.707107"/>
            <geom name="//unnamed_geom_91" class="reward_collision_sphere" size="0.0958585" pos="-0.0432382 0 0"/>
            <geom name="//unnamed_geom_92" class="reward_collision_sphere" size="0.0479292" pos="0.0112852 0.0781485 -0.354095"/>
            <site name="LH_foot" class="foot" pos="0.0112852 0.0781485 -0.354095" quat="0.707107 0 0 -0.707107" size="0.00958585"/>
          </body>
        </body>
      </body>
      <body name="RH_HIP" pos="-0.263952 -0.0909219 0.00206417" quat="0.00033039 -0.000104625 -0.966045 -0.258373">
        <inertial pos="0.048038 -0.0122741 -0.00591474" quat="-0.112618 0.709146 -0.154589 0.678624" mass="2.53842" diaginertia="0.00298079 0.00284312 0.00616594"/>
        <joint name="RH_HAA" pos="0 0 0" axis="0.999913 -0.0125723 -0.00408694" range="-0.675194 0.520242" armature="0.00846576" damping="0.00322766" frictionloss="0.0944778"/>
        <geom name="//unnamed_geom_93" class="visual" pos="0 -0.000237328 3.8981e-05" quat="-0.258819 0.965926 0 0" material="hip_l" mesh="hip_l"/>
        <geom name="//unnamed_geom_94" class="visual" pos="0.0517993 -0.0631622 -0.0381966" quat="-0.183013 0.683013 -0.683013 -0.183013" material="drive" mesh="drive"/>
        <geom name="//unnamed_geom_95" class="collision" size="0.0479292 0.0671009" pos="0.0517993 -0.0106269 -0.00775042" quat="0.353553 0.612372 -0.612372 0.353553"/>
        <body name="RH_THIGH" pos="0.0481144 -0.0622278 -0.0445061" quat="-0.183671 0.683119 -0.682706 -0.183102">
          <inertial pos="0.027075 0.00100586 -0.273083" quat="0.993205 -0.00430275 -0.0801229 0.0843006" mass="2.69776" diaginertia="0.014604 0.0162051 0.00722627"/>
          <joint name="RH_HFE" pos="0 0 0" axis="0.999926 -0.0108699 0.00555026" range="-3.12175 3.09525" armature="0.00849978" damping="0.0141214" frictionloss="0.0994495"/>
          <geom name="//unnamed_geom_96" class="visual" pos="-0.000473375 -7.45928e-07 0" quat="0.707107 0 0 -0.707107" material="thigh" mesh="thigh"/>
          <geom name="//unnamed_geom_97" class="collision" size="0.062308 0.0383434" pos="0.0345905 0 0" quat="0.5 0.5 0.5 0.5"/>
          <geom name="//unnamed_geom_98" class="collision" size="0.0359469 0.0287575 0.135461" pos="0.0259429 0 -0.158616" quat="0.707107 0 0 0.707107" type="box"/>
          <geom name="//unnamed_geom_99" class="visual" pos="0.0867357 0 -0.319894" quat="1 0 0 0" material="drive" mesh="drive"/>
          <geom name="//unnamed_geom_100" class="collision" size="0.0479292 0.0671009" pos="0.0262023 0 -0.319894" quat="0.707107 0 0.707107 0"/>
          <geom name="//unnamed_geom_101" class="reward_collision_sphere" size="0.0766868" pos="0.0216191 0 0"/>
          <body name="RH_SHANK" pos="0.0880423 -0.00119424 -0.321936" quat="0.999999 -0.000268765 0.000912533 0.00107065">
            <inertial pos="0.00359685 -0.0563547 -0.0880036" quat="0.992608 -0.118639 0.00065974 -0.0255537" mass="0.505318" diaginertia="0.00484041 0.00510925 0.00194561"/>
            <joint name="RH_KFE" pos="0 0 0" axis="0.999823 -0.00661185 0.0176373" stiffness="0.00686059" range="-3.14396 3.08981" armature="0.00967117" damping="0" frictionloss="0.105386"/>
            <geom name="//unnamed_geom_102" class="visual" pos="-0.000154357 -0.000823041 0" quat="0.707107 0 0 -0.707107" material="shank_l" mesh="shank_l"/>
            <geom name="RH_kfe_act" class="collision" size="0.0575151 0.0191717" pos="0.0172953 0 0" quat="0.5 0.5 0.5 0.5"/>
            <geom name="//unnamed_geom_104" class="collision" size="0.0551177 0.0323522 0.0182131" pos="0.0172953 -0.0510911 0" quat="0.5 0.5 0.5 0.5" type="box"/>
            <geom name="//unnamed_geom_105" class="visual" pos="0.0112852 -0.0784137 -0.379349" quat="0.382683 0 0 -0.92388" material="foot" mesh="foot"/>
            <geom name="RH_calf" class="collision" size="0.0167752 0.135402" pos="0.0112852 -0.0781485 -0.189675" quat="0.707107 0 0 0.707107"/>
            <geom name="RH_foot" class="foot" size="0.0278957" pos="0.0112852 -0.0781485 -0.354095" quat="0.707107 0 0 0.707107"/>
            <geom name="//unnamed_geom_108" class="reward_collision_sphere" size="0.0958585" pos="-0.0432382 0 0"/>
            <geom name="//unnamed_geom_109" class="reward_collision_sphere" size="0.0479292" pos="0.0112852 -0.0781485 -0.354095"/>
            <site name="RH_foot" class="foot" pos="0.0112852 -0.0781485 -0.354095" quat="0.707107 0 0 0.707107" size="0.00958585"/>
          </body>
        </body>
      </body>
    </body>
  </worldbody>

  <contact>
    <pair class="/" geom1="floor" geom2="LF_foot" name="//unnamed_contact_0"/>
    <pair class="/" geom1="floor" geom2="RF_foot" name="//unnamed_contact_1"/>
    <pair class="/" geom1="floor" geom2="LH_foot" name="//unnamed_contact_2"/>
    <pair class="/" geom1="floor" geom2="RH_foot" name="//unnamed_contact_3"/>
  </contact>

  <actuator>
    <general name="LF_HAA" class="/" joint="LF_HAA" forcerange="-78.9195 78.9195" gainprm="74.1799" biasprm="0 -74.1799 -1.8231"/>
    <general name="LF_HFE" class="/" joint="LF_HFE" forcerange="-86.3081 86.3081" gainprm="74.1799" biasprm="0 -74.1799 -1.8231"/>
    <general name="LF_KFE" class="/" joint="LF_KFE" forcerange="-69.8893 69.8893" gainprm="74.1799" biasprm="0 -74.1799 -1.8231"/>
    <general name="RF_HAA" class="/" joint="RF_HAA" forcerange="-77.9866 77.9866" gainprm="74.1799" biasprm="0 -74.1799 -1.8231"/>
    <general name="RF_HFE" class="/" joint="RF_HFE" forcerange="-77.0396 77.0396" gainprm="74.1799" biasprm="0 -74.1799 -1.8231"/>
    <general name="RF_KFE" class="/" joint="RF_KFE" forcerange="-70.2253 70.2253" gainprm="74.1799" biasprm="0 -74.1799 -1.8231"/>
    <general name="LH_HAA" class="/" joint="LH_HAA" forcerange="-77.9905 77.9905" gainprm="74.1799" biasprm="0 -74.1799 -1.8231"/>
    <general name="LH_HFE" class="/" joint="LH_HFE" forcerange="-77.7015 77.7015" gainprm="74.1799" biasprm="0 -74.1799 -1.8231"/>
    <general name="LH_KFE" class="/" joint="LH_KFE" forcerange="-84.4811 84.4811" gainprm="74.1799" biasprm="0 -74.1799 -1.8231"/>
    <general name="RH_HAA" class="/" joint="RH_HAA" forcerange="-73.678 73.678" gainprm="74.1799" biasprm="0 -74.1799 -1.8231"/>
    <general name="RH_HFE" class="/" joint="RH_HFE" forcerange="-71.6585 71.6585" gainprm="74.1799" biasprm="0 -74.1799 -1.8231"/>
    <general name="RH_KFE" class="/" joint="RH_KFE" forcerange="-84.346 84.346" gainprm="74.1799" biasprm="0 -74.1799 -1.8231"/>
  </actuator>

  <sensor>
    <gyro site="imu" name="imu_angular_velocity"/>
    <velocimeter site="imu" name="imu_linear_velocity"/>
    <framelinvel objtype="site" objname="LF_foot" name="LF_foot_global_linear_velocity"/>
    <framelinvel objtype="site" objname="RF_foot" name="RF_foot_global_linear_velocity"/>
    <framelinvel objtype="site" objname="LH_foot" name="LH_foot_global_linear_velocity"/>
    <framelinvel objtype="site" objname="RH_foot" name="RH_foot_global_linear_velocity"/>
  </sensor>

  <keyframe>
    <key name="home" qpos="0 0 0.55 1 0 0 0 0 0.4 -0.8 0 -0.4 0.8 0 -0.4 0.8 0 0.4 -0.8"/>
  </keyframe>
</mujoco>
