<mujoco model="anymal_c">
  <compiler angle="radian" assetdir="assets" balanceinertia="true" inertiafromgeom="false"/>

  <option timestep="0.005" density="1.2" viscosity="2e-05"/>

  <size nkey="1"/>

  <visual>
    <quality shadowsize="8192"/>
    <map shadowclip="0.5"/>
  </visual>

  <default>
    <default class="/">
      <material specular="0" shininess="0.25"/>
      <geom contype="0" conaffinity="0" group="1" solref="-1000 -80"/>
      <site size="0.01 0.005 0.005" group="5"/>
      <general forcelimited="true" forcerange="-80 80" biastype="affine" gainprm="80" biasprm="0 -80 -2"/>
      <default class="anymal_c">
        <joint armature="0.01" damping="0.01" frictionloss="0.1"/>
        <default class="visual">
          <geom type="mesh" group="2"/>
          <default class="visual_zflip"/>
        </default>
        <default class="collision">
          <geom type="cylinder" group="3"/>
          <default class="foot">
            <geom size="0.03 0 0" type="sphere" condim="6" priority="1" friction="0.8 0.02 0.01" solimp="0.015 1 0.03"/>
          </default>
        </default>
      </default>
      <default class="reward_collision_sphere">
        <geom group="5" rgba="1 0 0 1"/>
      </default>
    </default>
  </default>

  <asset>
    <texture type="skybox" colorspace="auto" name="//unnamed_texture_0" builtin="gradient" rgb1="0.95 0.95 0.95" rgb2="0.95 0.95 0.95" width="100" height="600"/>
    <texture type="2d" colorspace="auto" name="texplane" builtin="checker" rgb1="0.345 0.575 0.748" rgb2="0.345 0.575 0.748" markrgb="1 1 1" width="512" height="512"/>
    <texture type="2d" colorspace="linear" name="base" file="base.png"/>
    <texture type="2d" colorspace="linear" name="top_shell" file="top_shell.png"/>
    <texture type="2d" colorspace="linear" name="bottom_shell" file="bottom_shell.png"/>
    <texture type="2d" colorspace="linear" name="remote" file="remote.png"/>
    <texture type="2d" colorspace="linear" name="hatch" file="hatch.png"/>
    <texture type="2d" colorspace="linear" name="handle" file="handle.png"/>
    <texture type="2d" colorspace="linear" name="face" file="face.png"/>
    <texture type="2d" colorspace="linear" name="battery" file="battery.png"/>
    <texture type="2d" colorspace="linear" name="lidar_cage" file="lidar_cage.png"/>
    <texture type="2d" colorspace="linear" name="depth_camera" file="depth_camera.png"/>
    <texture type="2d" colorspace="linear" name="wide_angle_camera" file="wide_angle_camera.png"/>
    <texture type="2d" colorspace="linear" name="lidar" file="lidar.png"/>
    <texture type="2d" colorspace="linear" name="drive" file="drive.png"/>
    <texture type="2d" colorspace="linear" name="hip_l" file="hip_l.png"/>
    <texture type="2d" colorspace="linear" name="shank_l" file="shank_l.png"/>
    <texture type="2d" colorspace="linear" name="foot" file="foot.png"/>
    <texture type="2d" colorspace="linear" name="thigh" file="thigh.png"/>
    <texture type="2d" colorspace="linear" name="shank_r" file="shank_r.png"/>
    <texture type="2d" colorspace="linear" name="hip_r" file="hip_r.png"/>
    <material name="MatPlane" class="/" texture="texplane" texuniform="true" texrepeat="2 2" specular="0.9" shininess="0.5"/>
    <material name="black_plastic" class="/" rgba="0.007 0.007 0.007 1"/>
    <material name="green" class="/" rgba="0.052 0.178 0.033 1"/>
    <material name="red" class="/" rgba="0.178 0.006 0.005 1"/>
    <material name="yellow" class="/" rgba="0.178 0.119 0.006 1"/>
    <material name="lwl" class="/" rgba="0.8 0.8 0.8 1"/>
    <material name="base" class="/" texture="base"/>
    <material name="top_shell" class="/" texture="top_shell"/>
    <material name="bottom_shell" class="/" texture="bottom_shell"/>
    <material name="hip_l" class="/" texture="hip_l"/>
    <material name="thigh" class="/" texture="thigh"/>
    <material name="shank_l" class="/" texture="shank_l"/>
    <material name="foot" class="/" texture="foot"/>
    <material name="hip_r" class="/" texture="hip_r"/>
    <material name="shank" class="/" texture="shank_r"/>
    <material name="hatch" class="/" texture="hatch"/>
    <material name="remote" class="/" texture="remote"/>
    <material name="handle" class="/" texture="handle"/>
    <material name="face" class="/" texture="face"/>
    <material name="depth_camera" class="/" texture="depth_camera"/>
    <material name="wide_angle_camera" class="/" texture="wide_angle_camera"/>
    <material name="battery" class="/" texture="battery"/>
    <material name="lidar_cage" class="/" texture="lidar_cage"/>
    <material name="lidar" class="/" texture="lidar"/>
    <material name="drive" class="/" texture="drive"/>
    <mesh name="base_0" class="/" file="base_0.obj"/>
    <mesh name="base_1" class="/" file="base_1.obj"/>
    <mesh name="base_2" class="/" file="base_2.obj"/>
    <mesh name="base_3" class="/" file="base_3.obj"/>
    <mesh name="base_4" class="/" file="base_4.obj"/>
    <mesh name="base_5" class="/" file="base_5.obj"/>
    <mesh name="top_shell" class="/" file="top_shell.obj"/>
    <mesh name="bottom_shell" class="/" file="bottom_shell.obj"/>
    <mesh name="remote" class="/" file="remote.obj"/>
    <mesh name="handle" class="/" file="handle.obj"/>
    <mesh name="face" class="/" file="face.obj"/>
    <mesh name="wide_angle_camera" class="/" file="wide_angle_camera.obj"/>
    <mesh name="depth_camera" class="/" file="depth_camera.obj"/>
    <mesh name="battery" class="/" file="battery.obj"/>
    <mesh name="lidar_cage" class="/" file="lidar_cage.obj"/>
    <mesh name="lidar" class="/" file="lidar.obj"/>
    <mesh name="drive" class="/" file="drive.obj"/>
    <mesh name="hip_l" class="/" file="hip_l.obj"/>
    <mesh name="thigh" class="/" file="thigh.obj"/>
    <mesh name="shank_l" class="/" file="shank_l.obj"/>
    <mesh name="foot" class="/" file="foot.obj"/>
    <mesh name="hip_r" class="/" file="hip_r.obj"/>
    <mesh name="hatch" class="/" file="hatch.obj"/>
    <mesh name="shank_r" class="/" file="shank_r.obj"/>
  </asset>

  <worldbody>
    <geom name="floor" class="/" size="100 100 0.125" type="plane" group="0" material="MatPlane"/>
    <light name="toplight_shadow" class="/" pos="0 0 5" dir="0.0990148 0.0990148 -0.990148" type="directional" ambient="0.04 0.04 0.04" diffuse="0.55 0.55 0.55" specular="0.12 0.12 0.12"/>
    <light name="toplight_fill" class="/" pos="0 0 5" dir="0.0990148 0.0990148 -0.990148" type="directional" castshadow="false" ambient="0.04 0.04 0.04" diffuse="0.3 0.3 0.3" specular="0.08 0.08 0.08"/>
    <body name="trunk" childclass="anymal_c" pos="6.11847e-05 5.0348e-05 -0.00119129" quat="0.999999 0.000536608 -0.00103056 -0.000178754">
      <inertial pos="0.0129947 0.00761747 0.0561237" quat="0.501343 0.500379 0.499519 0.498756" mass="16.1678" diaginertia="0.440866 0.44884 0.320151"/>
      <joint name="//unnamed_joint_0" type="free" armature="0" damping="0" frictionloss="0"/>
      <geom name="//unnamed_geom_1" class="visual" material="green" mesh="base_0"/>
      <geom name="//unnamed_geom_2" class="visual" material="yellow" mesh="base_1"/>
      <geom name="//unnamed_geom_3" class="visual" material="red" mesh="base_2"/>
      <geom name="//unnamed_geom_4" class="visual" material="black_plastic" mesh="base_3"/>
      <geom name="//unnamed_geom_5" class="visual" material="lwl" mesh="base_4"/>
      <geom name="//unnamed_geom_6" class="visual" material="base" mesh="base_5"/>
      <geom name="trunk_1" class="collision" size="0.283976 0.068546 0.0881306" type="box"/>
      <geom name="trunk_2" class="collision" size="0.0881306 0.0709941" pos="0.201143 0.0656257 0" quat="0.707107 0 0.707107 0"/>
      <geom name="trunk_3" class="collision" size="0.0881306 0.0709941" pos="-0.201143 0.0656257 0" quat="0.707107 0 0.707107 0"/>
      <geom name="trunk_4" class="collision" size="0.0881306 0.0709941" pos="0.201143 -0.0656257 0" quat="0.707107 0 0.707107 0"/>
      <geom name="trunk_5" class="collision" size="0.0881306 0.0709941" pos="-0.201143 -0.0656257 0" quat="0.707107 0 0.707107 0"/>
      <geom name="//unnamed_geom_12" class="visual" material="top_shell" mesh="top_shell"/>
      <geom name="//unnamed_geom_13" class="visual" material="bottom_shell" mesh="bottom_shell"/>
      <geom name="//unnamed_geom_14" class="visual" material="remote" mesh="remote"/>
      <geom name="//unnamed_geom_15" class="visual" material="handle" mesh="handle"/>
      <geom name="//unnamed_geom_16" class="visual" pos="0.383328 0 0" quat="1 0 0 0" material="face" mesh="face"/>
      <geom name="trunk_6" class="collision" size="0.0538576 0.068546 0.0881306" pos="0.434192 0 0" type="box"/>
      <geom name="//unnamed_geom_18" class="collision" size="0.0881306 0.0538576" pos="0.434192 0.0656257 0" quat="0.707107 0 0.707107 0"/>
      <geom name="//unnamed_geom_19" class="collision" size="0.0881306 0.0538576" pos="0.434192 -0.0656257 0" quat="0.707107 0 0.707107 0"/>
      <geom name="//unnamed_geom_20" class="visual" pos="0.426938 0 -0.0325456" quat="0.965926 0 0.258819 0" material="depth_camera" mesh="depth_camera"/>
      <geom name="//unnamed_geom_21" class="visual" pos="0.47442 0 0.0160985" material="wide_angle_camera" mesh="wide_angle_camera"/>
      <geom name="//unnamed_geom_22" class="visual_zflip" pos="-0.383328 0 0" quat="0 0 0 1" material="face" mesh="face"/>
      <geom name="trunk_7" class="collision" size="0.0538576 0.068546 0.0881306" pos="-0.434192 0 0" quat="0 0 0 1" type="box"/>
      <geom name="//unnamed_geom_24" class="collision" size="0.0881306 0.0538576" pos="-0.434192 -0.0656257 0" quat="0 -0.707107 0 0.707107"/>
      <geom name="//unnamed_geom_25" class="collision" size="0.0881306 0.0538576" pos="-0.434192 0.0656257 0" quat="0 -0.707107 0 0.707107"/>
      <geom name="//unnamed_geom_26" class="visual" pos="-0.426938 0 -0.0325456" quat="0 -0.258819 0 0.965926" material="depth_camera" mesh="depth_camera"/>
      <geom name="//unnamed_geom_27" class="visual_zflip" pos="-0.47442 0 0.0160985" quat="0 0 0 1" material="wide_angle_camera" mesh="wide_angle_camera"/>
      <geom name="//unnamed_geom_28" class="visual" material="battery" mesh="battery"/>
      <geom name="//unnamed_geom_29" class="visual" pos="0 0.0718551 0.0300954" quat="0.683013 -0.183013 0.183013 0.683013" material="depth_camera" mesh="depth_camera"/>
      <geom name="//unnamed_geom_30" class="visual" pos="0 -0.0718551 0.0300954" quat="0.683013 0.183013 0.183013 -0.683013" material="depth_camera" mesh="depth_camera"/>
      <geom name="//unnamed_geom_31" class="visual" pos="-0.336626 0 0.0790406" quat="1 0 0 0" material="lidar_cage" mesh="lidar_cage"/>
      <geom name="trunk_8" class="collision" size="0.068546 0.0587538" pos="-0.336626 0 0.143563"/>
      <geom name="//unnamed_geom_33" class="visual" pos="-0.336626 4.99499e-06 0.152919" quat="0.707107 0 0 -0.707107" material="lidar" mesh="lidar"/>
      <geom name="//unnamed_geom_34" class="visual" pos="0.277346 0.09755 -2.37831e-09" quat="0.258819 0.965926 0 0" material="drive" mesh="drive"/>
      <geom name="//unnamed_geom_35" class="visual" pos="0.277346 -0.09755 2.37831e-09" quat="0.258819 -0.965926 0 0" material="drive" mesh="drive"/>
      <geom name="//unnamed_geom_36" class="visual" pos="-0.277346 0.09755 2.37831e-09" quat="0 0 0.965926 -0.258819" material="drive" mesh="drive"/>
      <geom name="//unnamed_geom_37" class="visual" pos="-0.277346 -0.09755 -2.37831e-09" quat="0 0 -0.965926 -0.258819" material="drive" mesh="drive"/>
      <geom name="//unnamed_geom_38" class="visual" pos="0.107276 0 0.0785029" quat="1 0 0 0" material="hatch" mesh="hatch"/>
      <geom name="//unnamed_geom_39" class="reward_collision_sphere" size="0.117508"/>
      <geom name="//unnamed_geom_40" class="reward_collision_sphere" size="0.117508" pos="0.416158 0 0"/>
      <geom name="//unnamed_geom_41" class="reward_collision_sphere" size="0.117508" pos="-0.416158 0 0"/>
      <site name="imu" pos="0.186298 0.0102582 0.0932838" size="0.00979229"/>
      <camera name="track" pos="0 -1.87502 0" quat="0.707107 0.707107 0 0" mode="trackcom"/>
      <camera name="ego_camera" pos="0.416158 0 -0.0430153" quat="-0.5 -0.5 0.5 0.5"/>
      <body name="LF_HIP" pos="0.283503 0.104082 0.00273896" quat="0.259091 0.965853 0.000768876 2.85287e-05">
        <inertial pos="0.053129 -0.00829789 -0.0106834" quat="-0.125978 0.71084 -0.135877 0.678508" mass="2.84488" diaginertia="0.00456999 0.00437795 0.00534949"/>
        <joint name="LF_HAA" pos="0 0 0" axis="0.999909 0.00207061 0.0133634" stiffness="0.0237288" range="-0.706381 0.449129" armature="0.0107227" damping="0" frictionloss="0.121809"/>
        <geom name="//unnamed_geom_42" class="visual" pos="0 -0.000139905 2.29793e-05" quat="0.258819 -0.965926 0 0" material="hip_l" mesh="hip_l"/>
        <geom name="//unnamed_geom_43" class="visual" pos="0.0553953 -0.0673395 -0.0398983" quat="0.183013 -0.683013 0.683013 0.183013" material="drive" mesh="drive"/>
        <geom name="//unnamed_geom_44" class="collision" size="0.0489615 0.068546" pos="0.0553953 -0.0112124 -0.00742551" quat="-0.353553 -0.612372 0.612372 -0.353553"/>
        <body name="LF_THIGH" pos="0.0590463 -0.0775163 -0.0476503" quat="0.184974 -0.684825 0.680289 0.184405">
          <inertial pos="0.0307531 0.000249563 -0.267659" quat="0.993961 0.0203708 -0.0848901 0.066492" mass="3.00437" diaginertia="0.0201181 0.0238047 0.00583562"/>
          <joint name="LF_HFE" pos="0 0 0" axis="0.999999 0.000853698 -0.00132748" stiffness="0.0100347" range="-3.2947 3.04449" armature="0.00988698" damping="0" frictionloss="0.11605"/>
          <geom name="//unnamed_geom_45" class="visual" pos="-0.000252959 -3.98604e-07 0" quat="0.707107 0 0 -0.707107" material="thigh" mesh="thigh"/>
          <geom name="//unnamed_geom_46" class="collision" size="0.0636499 0.0391692" pos="0.0369918 0 0" quat="0.5 0.5 -0.5 -0.5"/>
          <geom name="//unnamed_geom_47" class="collision" size="0.0367211 0.0293769 0.138379" pos="0.0277439 0 -0.151967" quat="0.707107 0 0 -0.707107" type="box"/>
          <geom name="//unnamed_geom_48" class="visual" pos="0.092757 0 -0.306484" quat="1 0 0 0" material="drive" mesh="drive"/>
          <geom name="//unnamed_geom_49" class="collision" size="0.0489615 0.068546" pos="0.0280213 0 -0.306484" quat="0.707107 0 0.707107 0"/>
          <geom name="//unnamed_geom_50" class="reward_collision_sphere" size="0.0783383" pos="0.0231199 0 0"/>
          <body name="LF_SHANK" pos="0.0923806 -0.00808047 -0.310017" quat="1 -0.000148709 -7.11383e-05 1.71538e-05">
            <inertial pos="0.00422004 -0.0567937 -0.0840487" quat="0.992978 -0.113654 -0.00277091 -0.0327032" mass="0.551689" diaginertia="0.00739141 0.00675481 0.00160164"/>
            <joint name="LF_KFE" pos="0 0 0" axis="0.999933 -0.0100814 0.00566683" stiffness="0.036953" range="-3.23413 3.16311" armature="0.00933527" damping="0.0201279" frictionloss="0.104869"/>
            <geom name="//unnamed_geom_51" class="visual" pos="-8.24843e-05 -0.000439811 0" quat="0.707107 0 0 -0.707107" material="shank_l" mesh="shank_l"/>
            <geom name="LF_kfe_act" class="collision" size="0.0587538 0.0195846" pos="0.0184959 0 0" quat="0.5 0.5 -0.5 -0.5"/>
            <geom name="//unnamed_geom_53" class="collision" size="0.0563047 0.033049 0.0186054" pos="0.0184959 -0.0539059 0" quat="0.5 0.5 -0.5 -0.5" type="box"/>
            <geom name="//unnamed_geom_54" class="visual" pos="0.0120686 -0.0825957 -0.363447" quat="0.382683 0 0 -0.92388" material="foot" mesh="foot"/>
            <geom name="LF_calf" class="collision" size="0.0171365 0.138318" pos="0.0120686 -0.082454 -0.181723" quat="0.707107 0 0 -0.707107"/>
            <geom name="LF_foot" class="foot" size="0.0323582" pos="0.0120686 -0.082454 -0.339251" quat="0.707107 0 0 -0.707107"/>
            <geom name="//unnamed_geom_57" class="reward_collision_sphere" size="0.0979229" pos="-0.0462398 0 0"/>
            <geom name="//unnamed_geom_58" class="reward_collision_sphere" size="0.0489615" pos="0.0120686 -0.082454 -0.339251"/>
            <site name="LF_foot" class="foot" pos="0.0120686 -0.082454 -0.339251" quat="0.707107 0 0 -0.707107" size="0.00979229"/>
          </body>
        </body>
      </body>
      <body name="RF_HIP" pos="0.286447 -0.0968216 -0.000560096" quat="0.258744 -0.965946 -5.9144e-05 0.000126373">
        <inertial pos="0.0569288 0.0252771 -0.0041918" quat="0.0917066 0.683771 0.105914 0.716121" mass="2.5839" diaginertia="0.00434302 0.00322273 0.00515167"/>
        <joint name="RF_HAA" pos="0 0 0" axis="0.999455 0.0327609 -0.00401187" range="-0.470133 0.721954" armature="0.00969603" damping="0.0351339" frictionloss="0.0908281"/>
        <geom name="//unnamed_geom_59" class="visual" pos="0 0.000139904 2.29793e-05" quat="0.258819 0.965926 0 0" material="hip_r" mesh="hip_r"/>
        <geom name="//unnamed_geom_60" class="visual" pos="0.0553953 0.0673395 -0.0398983" quat="0.183013 0.683013 0.683013 -0.183013" material="drive" mesh="drive"/>
        <geom name="//unnamed_geom_61" class="collision" size="0.0489615 0.068546" pos="0.0553953 0.0112124 -0.00742551" quat="-0.353553 0.612372 0.612372 0.353553"/>
        <body name="RF_THIGH" pos="0.0520854 0.0711541 -0.0378503" quat="0.184714 0.683731 0.682654 -0.179934">
          <inertial pos="0.0196555 0.000643197 -0.260512" quat="0.991327 0.00592277 -0.0788441 0.104968" mass="2.62735" diaginertia="0.021386 0.0233207 0.00530118"/>
          <joint name="RF_HFE" pos="0 0 0" axis="0.999942 -0.0100771 -0.00368228" stiffness="0.0187357" range="-3.16429 3.1268" armature="0.0118411" damping="0.00980661" frictionloss="0.0880078"/>
          <geom name="//unnamed_geom_62" class="visual" pos="-0.000252959 -3.98604e-07 0" quat="0.707107 0 0 -0.707107" material="thigh" mesh="thigh"/>
          <geom name="//unnamed_geom_63" class="collision" size="0.0636499 0.0391692" pos="0.0369918 0 0" quat="0.5 0.5 0.5 0.5"/>
          <geom name="//unnamed_geom_64" class="collision" size="0.0367211 0.0293769 0.138379" pos="0.0277439 0 -0.151967" quat="0.707107 0 0 0.707107" type="box"/>
          <geom name="//unnamed_geom_65" class="visual" pos="0.092757 0 -0.306484" quat="1 0 0 0" material="drive" mesh="drive"/>
          <geom name="//unnamed_geom_66" class="collision" size="0.0489615 0.068546" pos="0.0280213 0 -0.306484" quat="0.707107 0 0.707107 0"/>
          <geom name="//unnamed_geom_67" class="reward_collision_sphere" size="0.0783383" pos="0.0231199 0 0"/>
          <body name="RF_SHANK" pos="0.0965571 0.000954579 -0.305597" quat="0.999998 -0.000589552 0.00146102 0.000994396">
            <inertial pos="0.0112187 0.0577144 -0.0868674" quat="0.989613 0.142305 -0.0163693 -0.012105" mass="0.483806" diaginertia="0.00617568 0.00634891 0.00149392"/>
            <joint name="RF_KFE" pos="0 0 0" axis="0.999997 0.00139981 -0.00176154" stiffness="0.043132" range="-2.95901 3.22121" armature="0.00626339" damping="0" frictionloss="0.0861878"/>
            <geom name="//unnamed_geom_68" class="visual" pos="-8.24839e-05 0.00043981 0" quat="0.707107 0 0 0.707107" material="shank" mesh="shank_r"/>
            <geom name="RF_kfe_act" class="collision" size="0.0587538 0.0195846" pos="0.0184959 0 0" quat="0.5 0.5 0.5 0.5"/>
            <geom name="//unnamed_geom_70" class="collision" size="0.0563047 0.033049 0.0186054" pos="0.0184959 0.0539059 0" quat="0.5 0.5 0.5 0.5" type="box"/>
            <geom name="//unnamed_geom_71" class="visual" pos="0.0120686 0.0825957 -0.363447" quat="0.382683 0 0 0.92388" material="foot" mesh="foot"/>
            <geom name="RF_calf" class="collision" size="0.0171365 0.138318" pos="0.0120686 0.082454 -0.181723" quat="0.707107 0 0 0.707107"/>
            <geom name="RF_foot" class="foot" size="0.0359611" pos="0.0120686 0.082454 -0.339251" quat="0.707107 0 0 0.707107"/>
            <geom name="//unnamed_geom_74" class="reward_collision_sphere" size="0.0979229" pos="-0.0462398 0 0"/>
            <geom name="//unnamed_geom_75" class="reward_collision_sphere" size="0.0489615" pos="0.0120686 0.082454 -0.339251"/>
            <site name="RF_foot" class="foot" pos="0.0120686 0.082454 -0.339251" quat="0.707107 0 0 0.707107" size="0.00979229"/>
          </body>
        </body>
      </body>
      <body name="LH_HIP" pos="-0.285213 0.102865 0.0074178" quat="0.000212709 -0.000626903 0.965848 -0.259107">
        <inertial pos="0.0530923 0.00921169 0.000550207" quat="0.143981 0.695987 0.143723 0.688633" mass="2.32684" diaginertia="0.0030294 0.00314019 0.00436908"/>
        <joint name="LH_HAA" pos="0 0 0" axis="0.999461 0.027809 0.0174546" stiffness="0.00995535" range="-0.525924 0.695876" armature="0.00859922" damping="0.0472524" frictionloss="0.100379"/>
        <geom name="//unnamed_geom_76" class="visual" pos="0 0.000139904 2.29793e-05" quat="-0.258819 -0.965926 0 0" material="hip_r" mesh="hip_r"/>
        <geom name="//unnamed_geom_77" class="visual" pos="0.0553953 0.0673395 -0.0398983" quat="0.183013 0.683013 0.683013 -0.183013" material="drive" mesh="drive"/>
        <geom name="//unnamed_geom_78" class="collision" size="0.0489615 0.068546" pos="0.0553953 0.0112124 -0.00742551" quat="-0.353553 0.612372 0.612372 0.353553"/>
        <body name="LH_THIGH" pos="0.053255 0.0703669 -0.0474898" quat="0.183383 0.682713 0.683349 -0.182505">
          <inertial pos="0.0391633 -0.00105336 -0.254719" quat="0.993087 -0.00637785 -0.0826817 0.0830755" mass="3.14711" diaginertia="0.0245859 0.0215637 0.00629987"/>
          <joint name="LH_HFE" pos="0 0 0" axis="0.999983 0.00490035 0.00318928" range="-3.07903 3.23539" armature="0.0100949" damping="0.0355398" frictionloss="0.0995115"/>
          <geom name="//unnamed_geom_79" class="visual" pos="-0.000252959 -3.98604e-07 0" quat="0.707107 0 0 -0.707107" material="thigh" mesh="thigh"/>
          <geom name="//unnamed_geom_80" class="collision" size="0.0636499 0.0391692" pos="0.0369918 0 0" quat="0.5 0.5 -0.5 -0.5"/>
          <geom name="//unnamed_geom_81" class="collision" size="0.0367211 0.0293769 0.138379" pos="0.0277439 0 -0.151967" quat="0.707107 0 0 -0.707107" type="box"/>
          <geom name="//unnamed_geom_82" class="visual" pos="0.092757 0 -0.306484" quat="1 0 0 0" material="drive" mesh="drive"/>
          <geom name="//unnamed_geom_83" class="collision" size="0.0489615 0.068546" pos="0.0280213 0 -0.306484" quat="0.707107 0 0.707107 0"/>
          <geom name="//unnamed_geom_84" class="reward_collision_sphere" size="0.0783383" pos="0.0231199 0 0"/>
          <body name="LH_SHANK" pos="0.0947719 -0.00159935 -0.305801" quat="1 -1.43002e-05 1.70409e-05 -9.50671e-07">
            <inertial pos="0.00197681 0.0495809 -0.0858103" quat="0.995145 0.0970017 0.00459583 0.0160169" mass="0.480538" diaginertia="0.00631399 0.00523816 0.0013801"/>
            <joint name="LH_KFE" pos="0 0 0" axis="0.999948 -4.0352e-05 -0.0102313" range="-3.28961 3.24315" armature="0.00557838" damping="0" frictionloss="0.132019"/>
            <geom name="//unnamed_geom_85" class="visual" pos="-8.24839e-05 0.00043981 0" quat="-0.707107 0 0 -0.707107" material="shank" mesh="shank_r"/>
            <geom name="LH_kfe_act" class="collision" size="0.0587538 0.0195846" pos="0.0184959 0 0" quat="0.5 0.5 -0.5 -0.5"/>
            <geom name="//unnamed_geom_87" class="collision" size="0.0563047 0.033049 0.0186054" pos="0.0184959 0.0539059 0" quat="0.5 0.5 -0.5 -0.5" type="box"/>
            <geom name="//unnamed_geom_88" class="visual" pos="0.0120686 0.0825957 -0.363447" quat="-0.382683 0 0 -0.92388" material="foot" mesh="foot"/>
            <geom name="LH_calf" class="collision" size="0.0171365 0.138318" pos="0.0120686 0.082454 -0.181723" quat="0.707107 0 0 -0.707107"/>
            <geom name="LH_foot" class="foot" size="0.027746" pos="0.0120686 0.082454 -0.339251" quat="0.707107 0 0 -0.707107"/>
            <geom name="//unnamed_geom_91" class="reward_collision_sphere" size="0.0979229" pos="-0.0462398 0 0"/>
            <geom name="//unnamed_geom_92" class="reward_collision_sphere" size="0.0489615" pos="0.0120686 0.082454 -0.339251"/>
            <site name="LH_foot" class="foot" pos="0.0120686 0.082454 -0.339251" quat="0.707107 0 0 -0.707107" size="0.00979229"/>
          </body>
        </body>
      </body>
      <body name="RH_HIP" pos="-0.288048 -0.0959698 -0.00185451" quat="-0.000119522 0.00052858 -0.965993 -0.258566">
        <inertial pos="0.056413 -0.0177467 0.000426273" quat="-0.0794126 0.717607 -0.110755 0.682984" mass="2.69159" diaginertia="0.00446788 0.00409288 0.0053689"/>
        <joint name="RH_HAA" pos="0 0 0" axis="0.999094 0.000968924 0.0425512" stiffness="0.00616264" range="-0.559275 0.424329" armature="0.0107151" damping="0.0250828" frictionloss="0.100391"/>
        <geom name="//unnamed_geom_93" class="visual" pos="0 -0.000139905 2.29793e-05" quat="-0.258819 0.965926 0 0" material="hip_l" mesh="hip_l"/>
        <geom name="//unnamed_geom_94" class="visual" pos="0.0553953 -0.0673395 -0.0398983" quat="-0.183013 0.683013 -0.683013 -0.183013" material="drive" mesh="drive"/>
        <geom name="//unnamed_geom_95" class="collision" size="0.0489615 0.068546" pos="0.0553953 -0.0112124 -0.00742551" quat="0.353553 0.612372 -0.612372 0.353553"/>
        <body name="RH_THIGH" pos="0.0458038 -0.0694134 -0.0371395" quat="-0.185216 0.682249 -0.682479 -0.185617">
          <inertial pos="0.0307313 -0.00389214 -0.264001" quat="0.99315 -0.00520372 -0.0806749 0.0843678" mass="3.2683" diaginertia="0.0232185 0.0223251 0.00623546"/>
          <joint name="RH_HFE" pos="0 0 0" axis="0.999978 0.000460192 0.00666031" range="-3.22065 3.15525" armature="0.00933732" damping="0" frictionloss="0.0948813"/>
          <geom name="//unnamed_geom_96" class="visual" pos="-0.000252959 -3.98604e-07 0" quat="0.707107 0 0 -0.707107" material="thigh" mesh="thigh"/>
          <geom name="//unnamed_geom_97" class="collision" size="0.0636499 0.0391692" pos="0.0369918 0 0" quat="0.5 0.5 0.5 0.5"/>
          <geom name="//unnamed_geom_98" class="collision" size="0.0367211 0.0293769 0.138379" pos="0.0277439 0 -0.151967" quat="0.707107 0 0 0.707107" type="box"/>
          <geom name="//unnamed_geom_99" class="visual" pos="0.092757 0 -0.306484" quat="1 0 0 0" material="drive" mesh="drive"/>
          <geom name="//unnamed_geom_100" class="collision" size="0.0489615 0.068546" pos="0.0280213 0 -0.306484" quat="0.707107 0 0.707107 0"/>
          <geom name="//unnamed_geom_101" class="reward_collision_sphere" size="0.0783383" pos="0.0231199 0 0"/>
          <body name="RH_SHANK" pos="0.0930181 -0.00660282 -0.303789" quat="0.99999 0.00123346 0.00199736 -0.00368491">
            <inertial pos="-0.00169163 -0.0550846 -0.0870441" quat="0.989635 -0.140293 0.0173276 -0.025297" mass="0.531296" diaginertia="0.00696975 0.00666949 0.00166659"/>
            <joint name="RH_KFE" pos="0 0 0" axis="0.999964 0.000785575 0.00844256" range="-3.10969 2.97452" armature="0.00966439" damping="0" frictionloss="0.0865549"/>
            <geom name="//unnamed_geom_102" class="visual" pos="-8.24843e-05 -0.000439811 0" quat="0.707107 0 0 -0.707107" material="shank_l" mesh="shank_l"/>
            <geom name="RH_kfe_act" class="collision" size="0.0587538 0.0195846" pos="0.0184959 0 0" quat="0.5 0.5 0.5 0.5"/>
            <geom name="//unnamed_geom_104" class="collision" size="0.0563047 0.033049 0.0186054" pos="0.0184959 -0.0539059 0" quat="0.5 0.5 0.5 0.5" type="box"/>
            <geom name="//unnamed_geom_105" class="visual" pos="0.0120686 -0.0825957 -0.363447" quat="0.382683 0 0 -0.92388" material="foot" mesh="foot"/>
            <geom name="RH_calf" class="collision" size="0.0171365 0.138318" pos="0.0120686 -0.082454 -0.181723" quat="0.707107 0 0 0.707107"/>
            <geom name="RH_foot" class="foot" size="0.0346722" pos="0.0120686 -0.082454 -0.339251" quat="0.707107 0 0 0.707107"/>
            <geom name="//unnamed_geom_108" class="reward_collision_sphere" size="0.0979229" pos="-0.0462398 0 0"/>
            <geom name="//unnamed_geom_109" class="reward_collision_sphere" size="0.0489615" pos="0.0120686 -0.082454 -0.339251"/>
            <site name="RH_foot" class="foot" pos="0.0120686 -0.082454 -0.339251" quat="0.707107 0 0 0.707107" size="0.00979229"/>
          </body>
        </body>
      </body>
    </body>
  </worldbody>

  <contact>
    <pair class="/" geom1="floor" geom2="LF_foot" name="//unnamed_contact_0"/>
    <pair class="/" geom1="floor" geom2="RF_foot" name="//unnamed_contact_1"/>
    <pair class="/" geom1="floor" geom2="LH_foot" name="//unnamed_contact_2"/>
    <pair class="/" geom1="floor" geom2="RH_foot" name="//unnamed_contact_3"/>
  </contact>

  <actuator>
    <general name="LF_HAA" class="/" joint="LF_HAA" forcerange="-96.7972 96.7972" gainprm="85.526" biasprm="0 -85.526 -2.11746"/>
    <general name="LF_HFE" class="/" joint="LF_HFE" forcerange="-105.682 105.682" gainprm="85.526" biasprm="0 -85.526 -2.11746"/>
    <general name="LF_KFE" class="/" joint="LF_KFE" forcerange="-81.55 81.55" gainprm="85.526" biasprm="0 -85.526 -2.11746"/>
    <general name="RF_HAA" class="/" joint="RF_HAA" forcerange="-85.7389 85.7389" gainprm="85.526" biasprm="0 -85.526 -2.11746"/>
    <general name="RF_HFE" class="/" joint="RF_HFE" forcerange="-62.7272 62.7272" gainprm="85.526" biasprm="0 -85.526 -2.11746"/>
    <general name="RF_KFE" class="/" joint="RF_KFE" forcerange="-76.4257 76.4257" gainprm="85.526" biasprm="0 -85.526 -2.11746"/>
    <general name="LH_HAA" class="/" joint="LH_HAA" forcerange="-79.3564 79.3564" gainprm="85.526" biasprm="0 -85.526 -2.11746"/>
    <general name="LH_HFE" class="/" joint="LH_HFE" forcerange="-95.223 95.223" gainprm="85.526" biasprm="0 -85.526 -2.11746"/>
    <general name="LH_KFE" class="/" joint="LH_KFE" forcerange="-74.6752 74.6752" gainprm="85.526" biasprm="0 -85.526 -2.11746"/>
    <general name="RH_HAA" class="/" joint="RH_HAA" forcerange="-75.1855 75.1855" gainprm="85.526" biasprm="0 -85.526 -2.11746"/>
    <general name="RH_HFE" class="/" joint="RH_HFE" forcerange="-56.3456 56.3456" gainprm="85.526" biasprm="0 -85.526 -2.11746"/>
    <general name="RH_KFE" class="/" joint="RH_KFE" forcerange="-79.8838 79.8838" gainprm="85.526" biasprm="0 -85.526 -2.11746"/>
  </actuator>

  <sensor>
    <gyro site="imu" name="imu_angular_velocity"/>
    <velocimeter site="imu" name="imu_linear_velocity"/>
    <framelinvel objtype="site" objname="LF_foot" name="LF_foot_global_linear_velocity"/>
    <framelinvel objtype="site" objname="RF_foot" name="RF_foot_global_linear_velocity"/>
    <framelinvel objtype="site" objname="LH_foot" name="LH_foot_global_linear_velocity"/>
    <framelinvel objtype="site" objname="RH_foot" name="RH_foot_global_linear_velocity"/>
  </sensor>

  <keyframe>
    <key name="home" qpos="0 0 0.55 1 0 0 0 0 0.4 -0.8 0 -0.4 0.8 0 -0.4 0.8 0 0.4 -0.8"/>
  </keyframe>
</mujoco>
