<mujoco model="anymal_c">
  <compiler angle="radian" assetdir="assets" balanceinertia="true" inertiafromgeom="false"/>

  <option timestep="0.005" density="1.2" viscosity="2e-05"/>

  <size nkey="1"/>

  <visual>
    <quality shadowsize="8192"/>
    <map shadowclip="0.5"/>
  </visual>

  <default>
    <default class="/">
      <material specular="0" shininess="0.25"/>
      <geom contype="0" conaffinity="0" group="1" solref="-1000 -80"/>
      <site size="0.01 0.005 0.005" group="5"/>
      <general forcelimited="true" forcerange="-80 80" biastype="affine" gainprm="80" biasprm="0 -80 -2"/>
      <default class="anymal_c">
        <joint armature="0.01" damping="0.01" frictionloss="0.1"/>
        <default class="visual">
          <geom type="mesh" group="2"/>
          <default class="visual_zflip"/>
        </default>
        <default class="collision">
          <geom type="cylinder" group="3"/>
          <default class="foot">
            <geom size="0.03 0 0" type="sphere" condim="6" priority="1" friction="0.8 0.02 0.01" solimp="0.015 1 0.03"/>
          </default>
        </default>
      </default>
      <default class="reward_collision_sphere">
        <geom group="5" rgba="1 0 0 1"/>
      </default>
    </default>
  </default>

  <asset>
    <texture type="skybox" colorspace="auto" name="//unnamed_texture_0" builtin="gradient" rgb1="0.95 0.95 0.95" rgb2="0.95 0.95 0.95" width="100" height="600"/>
    <texture type="2d" colorspace="auto" name="texplane" builtin="checker" rgb1="0.345 0.575 0.748" rgb2="0.345 0.575 0.748" markrgb="1 1 1" width="512" height="512"/>
    <texture type="2d" colorspace="linear" name="base" file="base.png"/>
    <texture type="2d" colorspace="linear" name="top_shell" file="top_shell.png"/>
    <texture type="2d" colorspace="linear" name="bottom_shell" file="bottom_shell.png"/>
    <texture type="2d" colorspace="linear" name="remote" file="remote.png"/>
    <texture type="2d" colorspace="linear" name="hatch" file="hatch.png"/>
    <texture type="2d" colorspace="linear" name="handle" file="handle.png"/>
    <texture type="2d" colorspace="linear" name="face" file="face.png"/>
    <texture type="2d" colorspace="linear" name="battery" file="battery.png"/>
    <texture type="2d" colorspace="linear" name="lidar_cage" file="lidar_cage.png"/>
    <texture type="2d" colorspace="linear" name="depth_camera" file="depth_camera.png"/>
    <texture type="2d" colorspace="linear" name="wide_angle_camera" file="wide_angle_camera.png"/>
    <texture type="2d" colorspace="linear" name="lidar" file="lidar.png"/>
    <texture type="2d" colorspace="linear" name="drive" file="drive.png"/>
    <texture type="2d" colorspace="linear" name="hip_l" file="hip_l.png"/>
    <texture type="2d" colorspace="linear" name="shank_l" file="shank_l.png"/>
    <texture type="2d" colorspace="linear" name="foot" file="foot.png"/>
    <texture type="2d" colorspace="linear" name="thigh" file="thigh.png"/>
    <texture type="2d" colorspace="linear" name="shank_r" file="shank_r.png"/>
    <texture type="2d" colorspace="linear" name="hip_r" file="hip_r.png"/>
    <material name="MatPlane" class="/" texture="texplane" texuniform="true" texrepeat="2 2" specular="0.9" shininess="0.5"/>
    <material name="black_plastic" class="/" rgba="0.007 0.007 0.007 1"/>
    <material name="green" class="/" rgba="0.052 0.178 0.033 1"/>
    <material name="red" class="/" rgba="0.178 0.006 0.005 1"/>
    <material name="yellow" class="/" rgba="0.178 0.119 0.006 1"/>
    <material name="lwl" class="/" rgba="0.8 0.8 0.8 1"/>
    <material name="base" class="/" texture="base"/>
    <material name="top_shell" class="/" texture="top_shell"/>
    <material name="bottom_shell" class="/" texture="bottom_shell"/>
    <material name="hip_l" class="/" texture="hip_l"/>
    <material name="thigh" class="/" texture="thigh"/>
    <material name="shank_l" class="/" texture="shank_l"/>
    <material name="foot" class="/" texture="foot"/>
    <material name="hip_r" class="/" texture="hip_r"/>
    <material name="shank" class="/" texture="shank_r"/>
    <material name="hatch" class="/" texture="hatch"/>
    <material name="remote" class="/" texture="remote"/>
    <material name="handle" class="/" texture="handle"/>
    <material name="face" class="/" texture="face"/>
    <material name="depth_camera" class="/" texture="depth_camera"/>
    <material name="wide_angle_camera" class="/" texture="wide_angle_camera"/>
    <material name="battery" class="/" texture="battery"/>
    <material name="lidar_cage" class="/" texture="lidar_cage"/>
    <material name="lidar" class="/" texture="lidar"/>
    <material name="drive" class="/" texture="drive"/>
    <mesh name="base_0" class="/" file="base_0.obj"/>
    <mesh name="base_1" class="/" file="base_1.obj"/>
    <mesh name="base_2" class="/" file="base_2.obj"/>
    <mesh name="base_3" class="/" file="base_3.obj"/>
    <mesh name="base_4" class="/" file="base_4.obj"/>
    <mesh name="base_5" class="/" file="base_5.obj"/>
    <mesh name="top_shell" class="/" file="top_shell.obj"/>
    <mesh name="bottom_shell" class="/" file="bottom_shell.obj"/>
    <mesh name="remote" class="/" file="remote.obj"/>
    <mesh name="handle" class="/" file="handle.obj"/>
    <mesh name="face" class="/" file="face.obj"/>
    <mesh name="wide_angle_camera" class="/" file="wide_angle_camera.obj"/>
    <mesh name="depth_camera" class="/" file="depth_camera.obj"/>
    <mesh name="battery" class="/" file="battery.obj"/>
    <mesh name="lidar_cage" class="/" file="lidar_cage.obj"/>
    <mesh name="lidar" class="/" file="lidar.obj"/>
    <mesh name="drive" class="/" file="drive.obj"/>
    <mesh name="hip_l" class="/" file="hip_l.obj"/>
    <mesh name="thigh" class="/" file="thigh.obj"/>
    <mesh name="shank_l" class="/" file="shank_l.obj"/>
    <mesh name="foot" class="/" file="foot.obj"/>
    <mesh name="hip_r" class="/" file="hip_r.obj"/>
    <mesh name="hatch" class="/" file="hatch.obj"/>
    <mesh name="shank_r" class="/" file="shank_r.obj"/>
  </asset>

  <worldbody>
    <geom name="floor" class="/" size="100 100 0.125" type="plane" group="0" material="MatPlane"/>
    <light name="toplight_shadow" class="/" pos="0 0 5" dir="0.0990148 0.0990148 -0.990148" type="directional" ambient="0.04 0.04 0.04" diffuse="0.55 0.55 0.55" specular="0.12 0.12 0.12"/>
    <light name="toplight_fill" class="/" pos="0 0 5" dir="0.0990148 0.0990148 -0.990148" type="directional" castshadow="false" ambient="0.04 0.04 0.04" diffuse="0.3 0.3 0.3" specular="0.08 0.08 0.08"/>
    <body name="trunk" childclass="anymal_c" pos="-0.000613141 5.08841e-05 0.00156693" quat="0.999999 0.000904384 0.000559264 0.0003936">
      <inertial pos="0.00181855 -0.0022669 0.0506395" quat="0.499859 0.500353 0.500243 0.499545" mass="21.2384" diaginertia="0.826189 0.498348 0.316442"/>
      <joint name="//unnamed_joint_0" type="free" armature="0" damping="0" frictionloss="0"/>
      <geom name="//unnamed_geom_1" class="visual" material="green" mesh="base_0"/>
      <geom name="//unnamed_geom_2" class="visual" material="yellow" mesh="base_1"/>
      <geom name="//unnamed_geom_3" class="visual" material="red" mesh="base_2"/>
      <geom name="//unnamed_geom_4" class="visual" material="black_plastic" mesh="base_3"/>
      <geom name="//unnamed_geom_5" class="visual" material="lwl" mesh="base_4"/>
      <geom name="//unnamed_geom_6" class="visual" material="base" mesh="base_5"/>
      <geom name="trunk_1" class="collision" size="0.298778 0.0721188 0.0927242" type="box"/>
      <geom name="trunk_2" class="collision" size="0.0927242 0.0746945" pos="0.229064 0.0670231 0" quat="0.707107 0 0.707107 0"/>
      <geom name="trunk_3" class="collision" size="0.0927242 0.0746945" pos="-0.229064 0.0670231 0" quat="0.707107 0 0.707107 0"/>
      <geom name="trunk_4" class="collision" size="0.0927242 0.0746945" pos="0.229064 -0.0670231 0" quat="0.707107 0 0.707107 0"/>
      <geom name="trunk_5" class="collision" size="0.0927242 0.0746945" pos="-0.229064 -0.0670231 0" quat="0.707107 0 0.707107 0"/>
      <geom name="//unnamed_geom_12" class="visual" material="top_shell" mesh="top_shell"/>
      <geom name="//unnamed_geom_13" class="visual" material="bottom_shell" mesh="bottom_shell"/>
      <geom name="//unnamed_geom_14" class="visual" material="remote" mesh="remote"/>
      <geom name="//unnamed_geom_15" class="visual" material="handle" mesh="handle"/>
      <geom name="//unnamed_geom_16" class="visual" pos="0.436538 0 0" quat="1 0 0 0" material="face" mesh="face"/>
      <geom name="trunk_6" class="collision" size="0.0566648 0.0721188 0.0927242" pos="0.494462 0 0" type="box"/>
      <geom name="//unnamed_geom_18" class="collision" size="0.0927242 0.0566648" pos="0.494462 0.0670231 0" quat="0.707107 0 0.707107 0"/>
      <geom name="//unnamed_geom_19" class="collision" size="0.0927242 0.0566648" pos="0.494462 -0.0670231 0" quat="0.707107 0 0.707107 0"/>
      <geom name="//unnamed_geom_20" class="visual" pos="0.486196 0 -0.0317461" quat="0.965926 0 0.258819 0" material="depth_camera" mesh="depth_camera"/>
      <geom name="//unnamed_geom_21" class="visual" pos="0.540275 0 0.0161701" material="wide_angle_camera" mesh="wide_angle_camera"/>
      <geom name="//unnamed_geom_22" class="visual_zflip" pos="-0.436538 0 0" quat="0 0 0 1" material="face" mesh="face"/>
      <geom name="trunk_7" class="collision" size="0.0566648 0.0721188 0.0927242" pos="-0.494462 0 0" quat="0 0 0 1" type="box"/>
      <geom name="//unnamed_geom_24" class="collision" size="0.0927242 0.0566648" pos="-0.494462 -0.0670231 0" quat="0 -0.707107 0 0.707107"/>
      <geom name="//unnamed_geom_25" class="collision" size="0.0927242 0.0566648" pos="-0.494462 0.0670231 0" quat="0 -0.707107 0 0.707107"/>
      <geom name="//unnamed_geom_26" class="visual" pos="-0.486196 0 -0.0317461" quat="0 -0.258819 0 0.965926" material="depth_camera" mesh="depth_camera"/>
      <geom name="//unnamed_geom_27" class="visual_zflip" pos="-0.540275 0 0.0161701" quat="0 0 0 1" material="wide_angle_camera" mesh="wide_angle_camera"/>
      <geom name="//unnamed_geom_28" class="visual" material="battery" mesh="battery"/>
      <geom name="//unnamed_geom_29" class="visual" pos="0 0.0719538 0.0311736" quat="0.683013 -0.183013 0.183013 0.683013" material="depth_camera" mesh="depth_camera"/>
      <geom name="//unnamed_geom_30" class="visual" pos="0 -0.0719538 0.0311736" quat="0.683013 0.183013 0.183013 -0.683013" material="depth_camera" mesh="depth_camera"/>
      <geom name="//unnamed_geom_31" class="visual" pos="-0.383353 0 0.0793923" quat="1 0 0 0" material="lidar_cage" mesh="lidar_cage"/>
      <geom name="trunk_8" class="collision" size="0.0721188 0.0618161" pos="-0.383353 0 0.144202"/>
      <geom name="//unnamed_geom_33" class="visual" pos="-0.383353 -3.75954e-05 0.1536" quat="0.707107 0 0 -0.707107" material="lidar" mesh="lidar"/>
      <geom name="//unnamed_geom_34" class="visual" pos="0.315845 0.0996208 -2.11647e-09" quat="0.258819 0.965926 0 0" material="drive" mesh="drive"/>
      <geom name="//unnamed_geom_35" class="visual" pos="0.315845 -0.0996208 2.11647e-09" quat="0.258819 -0.965926 0 0" material="drive" mesh="drive"/>
      <geom name="//unnamed_geom_36" class="visual" pos="-0.315845 0.0996208 2.11647e-09" quat="0 0 0.965926 -0.258819" material="drive" mesh="drive"/>
      <geom name="//unnamed_geom_37" class="visual" pos="-0.315845 -0.0996208 -2.11647e-09" quat="0 0 -0.965926 -0.258819" material="drive" mesh="drive"/>
      <geom name="//unnamed_geom_38" class="visual" pos="0.122167 0 0.0788522" quat="1 0 0 0" material="hatch" mesh="hatch"/>
      <geom name="//unnamed_geom_39" class="reward_collision_sphere" size="0.123632"/>
      <geom name="//unnamed_geom_40" class="reward_collision_sphere" size="0.123632" pos="0.473925 0 0"/>
      <geom name="//unnamed_geom_41" class="reward_collision_sphere" size="0.123632" pos="-0.473925 0 0"/>
      <site name="imu" pos="0.271112 0.00708567 0.0407766" size="0.0103027"/>
      <camera name="track" pos="0 -1.91495 0" quat="0.707107 0.707107 0 0" mode="trackcom"/>
      <camera name="ego_camera" pos="0.473925 0 -0.0432067" quat="-0.5 -0.5 0.5 0.5"/>
      <body name="LF_HIP" pos="0.313504 0.0969816 -0.00150041" quat="0.258525 0.966004 -4.17248e-05 -0.000265187">
        <inertial pos="0.0597874 -0.0171247 -0.00773044" quat="-0.129395 0.709804 -0.134594 0.679205" mass="3.10812" diaginertia="0.00754277 0.00379351 0.00478045"/>
        <joint name="LF_HAA" pos="0 0 0" axis="0.999993 0.00157768 0.00338368" range="-0.720631 0.530701" armature="0.00997852" damping="0.0246487" frictionloss="0.0883608"/>
        <geom name="//unnamed_geom_42" class="visual" pos="0 -0.000124502 2.04494e-05" quat="0.258819 -0.965926 0 0" material="hip_l" mesh="hip_l"/>
        <geom name="//unnamed_geom_43" class="visual" pos="0.0630847 -0.0752242 -0.0443382" quat="0.183013 -0.683013 0.683013 0.183013" material="drive" mesh="drive"/>
        <geom name="//unnamed_geom_44" class="collision" size="0.0515135 0.0721188" pos="0.0630847 -0.0114512 -0.00745855" quat="-0.353553 -0.612372 0.612372 -0.353553"/>
        <body name="LF_THIGH" pos="0.0607717 -0.0676698 -0.0436672" quat="0.183973 -0.682782 0.682883 0.183395">
          <inertial pos="0.0318418 -8.01889e-05 -0.262678" quat="0.992779 0.0033829 -0.0898477 0.0794032" mass="3.2816" diaginertia="0.0398614 0.0240143 0.00632036"/>
          <joint name="LF_HFE" pos="0 0 0" axis="1 0.000302271 -0.000214419" stiffness="0.00445632" range="-3.09738 3.19508" armature="0.00998781" damping="0.0212089" frictionloss="0.0890545"/>
          <geom name="//unnamed_geom_45" class="visual" pos="0.00190393 3.00014e-06 0" quat="0.707107 0 0 -0.707107" material="thigh" mesh="thigh"/>
          <geom name="//unnamed_geom_46" class="collision" size="0.0669675 0.0412108" pos="0.0421267 0 0" quat="0.5 0.5 -0.5 -0.5"/>
          <geom name="//unnamed_geom_47" class="collision" size="0.0386351 0.0309081 0.145591" pos="0.031595 0 -0.152643" quat="0.707107 0 0 -0.707107" type="box"/>
          <geom name="//unnamed_geom_48" class="visual" pos="0.105633 0 -0.307848" quat="1 0 0 0" material="drive" mesh="drive"/>
          <geom name="//unnamed_geom_49" class="collision" size="0.0515135 0.0721188" pos="0.031911 0 -0.307848" quat="0.707107 0 0.707107 0"/>
          <geom name="//unnamed_geom_50" class="reward_collision_sphere" size="0.0824215" pos="0.0263292 0 0"/>
          <body name="LF_SHANK" pos="0.106395 0.0022866 -0.306254" quat="1 9.62545e-05 0.000252241 9.42601e-06">
            <inertial pos="0.00520976 -0.0585435 -0.0895619" quat="0.992898 -0.116283 -0.000918025 -0.0251091" mass="0.650896" diaginertia="0.0128216 0.0073732 0.00165398"/>
            <joint name="LF_KFE" pos="0 0 0" axis="0.999988 -0.00266107 -0.00405973" range="-3.08367 3.14781" armature="0.0110268" damping="0.00383063" frictionloss="0.104429"/>
            <geom name="//unnamed_geom_51" class="visual" pos="0.000620828 0.00331029 0" quat="0.707107 0 0 -0.707107" material="shank_l" mesh="shank_l"/>
            <geom name="LF_kfe_act" class="collision" size="0.0618161 0.0206054" pos="0.0210633 0 0" quat="0.5 0.5 -0.5 -0.5"/>
            <geom name="//unnamed_geom_53" class="collision" size="0.0592394 0.0347716 0.0195751" pos="0.0210633 -0.0550538 0" quat="0.5 0.5 -0.5 -0.5" type="box"/>
            <geom name="//unnamed_geom_54" class="visual" pos="0.0137437 -0.083143 -0.365064" quat="0.382683 0 0 -0.92388" material="foot" mesh="foot"/>
            <geom name="LF_calf" class="collision" size="0.0180297 0.145528" pos="0.0137438 -0.0842098 -0.182532" quat="0.707107 0 0 -0.707107"/>
            <geom name="LF_foot" class="foot" size="0.0306452" pos="0.0137438 -0.0842098 -0.34076" quat="0.707107 0 0 -0.707107"/>
            <geom name="//unnamed_geom_57" class="reward_collision_sphere" size="0.103027" pos="-0.0526584 0 0"/>
            <geom name="//unnamed_geom_58" class="reward_collision_sphere" size="0.0515135" pos="0.0137438 -0.0842098 -0.34076"/>
            <site name="LF_foot" class="foot" pos="0.0137438 -0.0842098 -0.34076" quat="0.707107 0 0 -0.707107" size="0.0103027"/>
          </body>
        </body>
      </body>
      <body name="RF_HIP" pos="0.314432 -0.100313 -0.000304695" quat="0.258944 -0.965892 7.34147e-05 0.000164308">
        <inertial pos="0.0569876 0.0141712 -0.0118799" quat="0.140898 0.677189 0.129603 0.710469" mass="3.05962" diaginertia="0.00729322 0.0040263 0.00464167"/>
        <joint name="RF_HAA" pos="0 0 0" axis="0.999934 0.000766703 0.01144" range="-0.505627 0.721438" armature="0.0106188" damping="0" frictionloss="0.111988"/>
        <geom name="//unnamed_geom_59" class="visual" pos="0 0.000124501 2.04494e-05" quat="0.258819 0.965926 0 0" material="hip_r" mesh="hip_r"/>
        <geom name="//unnamed_geom_60" class="visual" pos="0.0630847 0.0752242 -0.0443382" quat="0.183013 0.683013 0.683013 -0.183013" material="drive" mesh="drive"/>
        <geom name="//unnamed_geom_61" class="collision" size="0.0515135 0.0721188" pos="0.0630847 0.0114512 -0.00745855" quat="-0.353553 0.612372 0.612372 0.353553"/>
        <body name="RF_THIGH" pos="0.0659788 0.0673312 -0.0474757" quat="0.182695 0.683339 0.683026 -0.18206">
          <inertial pos="0.0342601 -0.00126565 -0.267838" quat="0.993791 0.00130356 -0.0808309 0.0764463" mass="3.48008" diaginertia="0.0379198 0.023374 0.00630873"/>
          <joint name="RF_HFE" pos="0 0 0" axis="0.999999 0.0010157 -0.000707301" range="-3.1131 3.14436" armature="0.00897247" damping="0.0110487" frictionloss="0.113863"/>
          <geom name="//unnamed_geom_62" class="visual" pos="0.00190393 3.00014e-06 0" quat="0.707107 0 0 -0.707107" material="thigh" mesh="thigh"/>
          <geom name="//unnamed_geom_63" class="collision" size="0.0669675 0.0412108" pos="0.0421267 0 0" quat="0.5 0.5 0.5 0.5"/>
          <geom name="//unnamed_geom_64" class="collision" size="0.0386351 0.0309081 0.145591" pos="0.031595 0 -0.152643" quat="0.707107 0 0 0.707107" type="box"/>
          <geom name="//unnamed_geom_65" class="visual" pos="0.105633 0 -0.307848" quat="1 0 0 0" material="drive" mesh="drive"/>
          <geom name="//unnamed_geom_66" class="collision" size="0.0515135 0.0721188" pos="0.031911 0 -0.307848" quat="0.707107 0 0.707107 0"/>
          <geom name="//unnamed_geom_67" class="reward_collision_sphere" size="0.0824215" pos="0.0263292 0 0"/>
          <body name="RF_SHANK" pos="0.1025 0.000817171 -0.308819" quat="0.999999 0.000588708 6.13408e-05 0.0012168">
            <inertial pos="0.0032175 0.0587126 -0.0868036" quat="0.993053 0.113426 0.0010094 0.0313013" mass="0.687919" diaginertia="0.0139575 0.00745963 0.00171091"/>
            <joint name="RF_KFE" pos="0 0 0" axis="0.999993 -0.00330974 0.00163356" range="-3.17302 3.08103" armature="0.0117935" damping="0.0175307" frictionloss="0.114836"/>
            <geom name="//unnamed_geom_68" class="visual" pos="0.000620825 -0.00331028 0" quat="0.707107 0 0 0.707107" material="shank" mesh="shank_r"/>
            <geom name="RF_kfe_act" class="collision" size="0.0618161 0.0206054" pos="0.0210633 0 0" quat="0.5 0.5 0.5 0.5"/>
            <geom name="//unnamed_geom_70" class="collision" size="0.0592394 0.0347716 0.0195751" pos="0.0210633 0.0550538 0" quat="0.5 0.5 0.5 0.5" type="box"/>
            <geom name="//unnamed_geom_71" class="visual" pos="0.013744 0.083143 -0.365064" quat="0.382683 0 0 0.92388" material="foot" mesh="foot"/>
            <geom name="RF_calf" class="collision" size="0.0180297 0.145528" pos="0.0137438 0.0842098 -0.182532" quat="0.707107 0 0 0.707107"/>
            <geom name="RF_foot" class="foot" size="0.0278826" pos="0.0137438 0.0842098 -0.34076" quat="0.707107 0 0 0.707107"/>
            <geom name="//unnamed_geom_74" class="reward_collision_sphere" size="0.103027" pos="-0.0526584 0 0"/>
            <geom name="//unnamed_geom_75" class="reward_collision_sphere" size="0.0515135" pos="0.0137438 0.0842098 -0.34076"/>
            <site name="RF_foot" class="foot" pos="0.0137438 0.0842098 -0.34076" quat="0.707107 0 0 0.707107" size="0.0103027"/>
          </body>
        </body>
      </body>
      <body name="LH_HIP" pos="-0.313265 0.0973115 -0.00161507" quat="0.000117402 -0.000430004 0.965885 -0.258972">
        <inertial pos="0.0598566 0.0172639 -0.0104741" quat="0.140941 0.678114 0.11634 0.711872" mass="3.09556" diaginertia="0.00780415 0.00403277 0.00477376"/>
        <joint name="LH_HAA" pos="0 0 0" axis="0.999906 -0.0129731 0.00452001" range="-0.496593 0.757658" armature="0.0109545" damping="0.00159484" frictionloss="0.102101"/>
        <geom name="//unnamed_geom_76" class="visual" pos="0 0.000124501 2.04494e-05" quat="-0.258819 -0.965926 0 0" material="hip_r" mesh="hip_r"/>
        <geom name="//unnamed_geom_77" class="visual" pos="0.0630847 0.0752242 -0.0443382" quat="0.183013 0.683013 0.683013 -0.183013" material="drive" mesh="drive"/>
        <geom name="//unnamed_geom_78" class="collision" size="0.0515135 0.0721188" pos="0.0630847 0.0114512 -0.00745855" quat="-0.353553 0.612372 0.612372 0.353553"/>
        <body name="LH_THIGH" pos="0.0621831 0.0678221 -0.0437669" quat="0.183422 0.683084 0.682912 -0.182711">
          <inertial pos="0.0317012 0.00128617 -0.266757" quat="0.992881 -0.00310843 -0.0803551 0.0878688" mass="3.15676" diaginertia="0.037288 0.0240219 0.0060655"/>
          <joint name="LH_HFE" pos="0 0 0" axis="0.999999 0.0010665 0.000647896" stiffness="0.00764149" range="-3.19396 3.08284" armature="0.0102306" damping="0" frictionloss="0.104408"/>
          <geom name="//unnamed_geom_79" class="visual" pos="0.00190393 3.00014e-06 0" quat="0.707107 0 0 -0.707107" material="thigh" mesh="thigh"/>
          <geom name="//unnamed_geom_80" class="collision" size="0.0669675 0.0412108" pos="0.0421267 0 0" quat="0.5 0.5 -0.5 -0.5"/>
          <geom name="//unnamed_geom_81" class="collision" size="0.0386351 0.0309081 0.145591" pos="0.031595 0 -0.152643" quat="0.707107 0 0 -0.707107" type="box"/>
          <geom name="//unnamed_geom_82" class="visual" pos="0.105633 0 -0.307848" quat="1 0 0 0" material="drive" mesh="drive"/>
          <geom name="//unnamed_geom_83" class="collision" size="0.0515135 0.0721188" pos="0.031911 0 -0.307848" quat="0.707107 0 0.707107 0"/>
          <geom name="//unnamed_geom_84" class="reward_collision_sphere" size="0.0824215" pos="0.0263292 0 0"/>
          <body name="LH_SHANK" pos="0.104235 0.000804153 -0.309943" quat="1 -1.66892e-05 -3.54071e-05 0.000104079">
            <inertial pos="0.00832568 0.060815 -0.0884338" quat="0.993689 0.108796 0.0111016 0.0249417" mass="0.651556" diaginertia="0.01281 0.0077147 0.00168409"/>
            <joint name="LH_KFE" pos="0 0 0" axis="0.999999 -0.000540267 0.00114367" stiffness="0.0012412" range="-3.09589 3.08303" armature="0.0112563" damping="0.0183837" frictionloss="0.0901037"/>
            <geom name="//unnamed_geom_85" class="visual" pos="0.000620825 -0.00331028 0" quat="-0.707107 0 0 -0.707107" material="shank" mesh="shank_r"/>
            <geom name="LH_kfe_act" class="collision" size="0.0618161 0.0206054" pos="0.0210633 0 0" quat="0.5 0.5 -0.5 -0.5"/>
            <geom name="//unnamed_geom_87" class="collision" size="0.0592394 0.0347716 0.0195751" pos="0.0210633 0.0550538 0" quat="0.5 0.5 -0.5 -0.5" type="box"/>
            <geom name="//unnamed_geom_88" class="visual" pos="0.013744 0.083143 -0.365064" quat="-0.382683 0 0 -0.92388" material="foot" mesh="foot"/>
            <geom name="LH_calf" class="collision" size="0.0180297 0.145528" pos="0.0137438 0.0842098 -0.182532" quat="0.707107 0 0 -0.707107"/>
            <geom name="LH_foot" class="foot" size="0.0356421" pos="0.0137438 0.0842098 -0.34076" quat="0.707107 0 0 -0.707107"/>
            <geom name="//unnamed_geom_91" class="reward_collision_sphere" size="0.103027" pos="-0.0526584 0 0"/>
            <geom name="//unnamed_geom_92" class="reward_collision_sphere" size="0.0515135" pos="0.0137438 0.0842098 -0.34076"/>
            <site name="LH_foot" class="foot" pos="0.0137438 0.0842098 -0.34076" quat="0.707107 0 0 -0.707107" size="0.0103027"/>
          </body>
        </body>
      </body>
      <body name="RH_HIP" pos="-0.314987 -0.100479 0.00242135" quat="-1.41415e-05 0.000145884 -0.965963 -0.258679">
        <inertial pos="0.0568969 -0.0121411 -0.010567" quat="-0.125872 0.710698 -0.13363 0.679123" mass="3.09804" diaginertia="0.0074869 0.00392425 0.00479694"/>
        <joint name="RH_HAA" pos="0 0 0" axis="0.999949 -0.00811939 0.00608528" range="-0.764256 0.546176" armature="0.00923787" damping="0" frictionloss="0.102185"/>
        <geom name="//unnamed_geom_93" class="visual" pos="0 -0.000124502 2.04494e-05" quat="-0.258819 0.965926 0 0" material="hip_l" mesh="hip_l"/>
        <geom name="//unnamed_geom_94" class="visual" pos="0.0630847 -0.0752242 -0.0443382" quat="-0.183013 0.683013 -0.683013 -0.183013" material="drive" mesh="drive"/>
        <geom name="//unnamed_geom_95" class="collision" size="0.0515135 0.0721188" pos="0.0630847 -0.0114512 -0.00745855" quat="0.353553 0.612372 -0.612372 0.353553"/>
        <body name="RH_THIGH" pos="0.0643524 -0.0674415 -0.0466965" quat="-0.183611 0.682319 -0.683649 -0.182626">
          <inertial pos="0.0319635 0.00264778 -0.264763" quat="0.993159 -0.00519527 -0.0807933 0.0841512" mass="3.12789" diaginertia="0.0365144 0.0235072 0.00600008"/>
          <joint name="RH_HFE" pos="0 0 0" axis="1 -0.000683268 -0.000709646" range="-3.08562 3.12637" armature="0.0104927" damping="0.0200045" frictionloss="0.100645"/>
          <geom name="//unnamed_geom_96" class="visual" pos="0.00190393 3.00014e-06 0" quat="0.707107 0 0 -0.707107" material="thigh" mesh="thigh"/>
          <geom name="//unnamed_geom_97" class="collision" size="0.0669675 0.0412108" pos="0.0421267 0 0" quat="0.5 0.5 0.5 0.5"/>
          <geom name="//unnamed_geom_98" class="collision" size="0.0386351 0.0309081 0.145591" pos="0.031595 0 -0.152643" quat="0.707107 0 0 0.707107" type="box"/>
          <geom name="//unnamed_geom_99" class="visual" pos="0.105633 0 -0.307848" quat="1 0 0 0" material="drive" mesh="drive"/>
          <geom name="//unnamed_geom_100" class="collision" size="0.0515135 0.0721188" pos="0.031911 0 -0.307848" quat="0.707107 0 0.707107 0"/>
          <geom name="//unnamed_geom_101" class="reward_collision_sphere" size="0.0824215" pos="0.0263292 0 0"/>
          <body name="RH_SHANK" pos="0.105165 0.00240776 -0.308242" quat="1 0.000510347 -0.000708723 0.000266253">
            <inertial pos="0.00840094 -0.060722 -0.0863846" quat="0.993845 -0.10844 0.00917671 -0.0206869" mass="0.645248" diaginertia="0.0127742 0.00743162 0.00159488"/>
            <joint name="RH_KFE" pos="0 0 0" axis="0.999974 0.00247384 0.00675272" range="-3.11961 3.17729" armature="0.0100183" damping="0.0179641" frictionloss="0.114627"/>
            <geom name="//unnamed_geom_102" class="visual" pos="0.000620828 0.00331029 0" quat="0.707107 0 0 -0.707107" material="shank_l" mesh="shank_l"/>
            <geom name="RH_kfe_act" class="collision" size="0.0618161 0.0206054" pos="0.0210633 0 0" quat="0.5 0.5 0.5 0.5"/>
            <geom name="//unnamed_geom_104" class="collision" size="0.0592394 0.0347716 0.0195751" pos="0.0210633 -0.0550538 0" quat="0.5 0.5 0.5 0.5" type="box"/>
            <geom name="//unnamed_geom_105" class="visual" pos="0.0137437 -0.083143 -0.365064" quat="0.382683 0 0 -0.92388" material="foot" mesh="foot"/>
            <geom name="RH_calf" class="collision" size="0.0180297 0.145528" pos="0.0137438 -0.0842098 -0.182532" quat="0.707107 0 0 0.707107"/>
            <geom name="RH_foot" class="foot" size="0.0265961" pos="0.0137438 -0.0842098 -0.34076" quat="0.707107 0 0 0.707107"/>
            <geom name="//unnamed_geom_108" class="reward_collision_sphere" size="0.103027" pos="-0.0526584 0 0"/>
            <geom name="//unnamed_geom_109" class="reward_collision_sphere" size="0.0515135" pos="0.0137438 -0.0842098 -0.34076"/>
            <site name="RH_foot" class="foot" pos="0.0137438 -0.0842098 -0.34076" quat="0.707107 0 0 0.707107" size="0.0103027"/>
          </body>
        </body>
      </body>
    </body>
  </worldbody>

  <contact>
    <pair class="/" geom1="floor" geom2="LF_foot" name="//unnamed_contact_0"/>
    <pair class="/" geom1="floor" geom2="RF_foot" name="//unnamed_contact_1"/>
    <pair class="/" geom1="floor" geom2="LH_foot" name="//unnamed_contact_2"/>
    <pair class="/" geom1="floor" geom2="RH_foot" name="//unnamed_contact_3"/>
  </contact>

  <actuator>
    <general name="LF_HAA" class="/" joint="LF_HAA" forcerange="-74.6905 74.6905" gainprm="76.9623" biasprm="0 -76.9623 -2.02144"/>
    <general name="LF_HFE" class="/" joint="LF_HFE" forcerange="-77.4669 77.4669" gainprm="76.9623" biasprm="0 -76.9623 -2.02144"/>
    <general name="LF_KFE" class="/" joint="LF_KFE" forcerange="-78.794 78.794" gainprm="76.9623" biasprm="0 -76.9623 -2.02144"/>
    <general name="RF_HAA" class="/" joint="RF_HAA" forcerange="-80.5193 80.5193" gainprm="76.9623" biasprm="0 -76.9623 -2.02144"/>
    <general name="RF_HFE" class="/" joint="RF_HFE" forcerange="-92.5035 92.5035" gainprm="76.9623" biasprm="0 -76.9623 -2.02144"/>
    <general name="RF_KFE" class="/" joint="RF_KFE" forcerange="-83.1991 83.1991" gainprm="76.9623" biasprm="0 -76.9623 -2.02144"/>
    <general name="LH_HAA" class="/" joint="LH_HAA" forcerange="-82.7398 82.7398" gainprm="76.9623" biasprm="0 -76.9623 -2.02144"/>
    <general name="LH_HFE" class="/" joint="LH_HFE" forcerange="-74.2666 74.2666" gainprm="76.9623" biasprm="0 -76.9623 -2.02144"/>
    <general name="LH_KFE" class="/" joint="LH_KFE" forcerange="-89.7647 89.7647" gainprm="76.9623" biasprm="0 -76.9623 -2.02144"/>
    <general name="RH_HAA" class="/" joint="RH_HAA" forcerange="-85.5571 85.5571" gainprm="76.9623" biasprm="0 -76.9623 -2.02144"/>
    <general name="RH_HFE" class="/" joint="RH_HFE" forcerange="-89.9708 89.9708" gainprm="76.9623" biasprm="0 -76.9623 -2.02144"/>
    <general name="RH_KFE" class="/" joint="RH_KFE" forcerange="-83.1775 83.1775" gainprm="76.9623" biasprm="0 -76.9623 -2.02144"/>
  </actuator>

  <sensor>
    <gyro site="imu" name="imu_angular_velocity"/>
    <velocimeter site="imu" name="imu_linear_velocity"/>
    <framelinvel objtype="site" objname="LF_foot" name="LF_foot_global_linear_velocity"/>
    <framelinvel objtype="site" objname="RF_foot" name="RF_foot_global_linear_velocity"/>
    <framelinvel objtype="site" objname="LH_foot" name="LH_foot_global_linear_velocity"/>
    <framelinvel objtype="site" objname="RH_foot" name="RH_foot_global_linear_velocity"/>
  </sensor>

  <keyframe>
    <key name="home" qpos="0 0 0.55 1 0 0 0 0 0.4 -0.8 0 -0.4 0.8 0 -0.4 0.8 0 0.4 -0.8"/>
  </keyframe>
</mujoco>
