<mujoco model="anymal_c">
  <compiler angle="radian" assetdir="assets" balanceinertia="true" inertiafromgeom="false"/>

  <option timestep="0.005" density="1.2" viscosity="2e-05"/>

  <size nkey="1"/>

  <visual>
    <quality shadowsize="8192"/>
    <map shadowclip="0.5"/>
  </visual>

  <default>
    <default class="/">
      <material specular="0" shininess="0.25"/>
      <geom contype="0" conaffinity="0" group="1" solref="-1000 -80"/>
      <site size="0.01 0.005 0.005" group="5"/>
      <general forcelimited="true" forcerange="-80 80" biastype="affine" gainprm="80" biasprm="0 -80 -2"/>
      <default class="anymal_c">
        <joint armature="0.01" damping="0.01" frictionloss="0.1"/>
        <default class="visual">
          <geom type="mesh" group="2"/>
          <default class="visual_zflip"/>
        </default>
        <default class="collision">
          <geom type="cylinder" group="3"/>
          <default class="foot">
            <geom size="0.03 0 0" type="sphere" condim="6" priority="1" friction="0.8 0.02 0.01" solimp="0.015 1 0.03"/>
          </default>
        </default>
      </default>
      <default class="reward_collision_sphere">
        <geom group="5" rgba="1 0 0 1"/>
      </default>
    </default>
  </default>

  <asset>
    <texture type="skybox" colorspace="auto" name="//unnamed_texture_0" builtin="gradient" rgb1="0.95 0.95 0.95" rgb2="0.95 0.95 0.95" width="100" height="600"/>
    <texture type="2d" colorspace="auto" name="texplane" builtin="checker" rgb1="0.345 0.575 0.748" rgb2="0.345 0.575 0.748" markrgb="1 1 1" width="512" height="512"/>
    <texture type="2d" colorspace="linear" name="base" file="base.png"/>
    <texture type="2d" colorspace="linear" name="top_shell" file="top_shell.png"/>
    <texture type="2d" colorspace="linear" name="bottom_shell" file="bottom_shell.png"/>
    <texture type="2d" colorspace="linear" name="remote" file="remote.png"/>
    <texture type="2d" colorspace="linear" name="hatch" file="hatch.png"/>
    <texture type="2d" colorspace="linear" name="handle" file="handle.png"/>
    <texture type="2d" colorspace="linear" name="face" file="face.png"/>
    <texture type="2d" colorspace="linear" name="battery" file="battery.png"/>
    <texture type="2d" colorspace="linear" name="lidar_cage" file="lidar_cage.png"/>
    <texture type="2d" colorspace="linear" name="depth_camera" file="depth_camera.png"/>
    <texture type="2d" colorspace="linear" name="wide_angle_camera" file="wide_angle_camera.png"/>
    <texture type="2d" colorspace="linear" name="lidar" file="lidar.png"/>
    <texture type="2d" colorspace="linear" name="drive" file="drive.png"/>
    <texture type="2d" colorspace="linear" name="hip_l" file="hip_l.png"/>
    <texture type="2d" colorspace="linear" name="shank_l" file="shank_l.png"/>
    <texture type="2d" colorspace="linear" name="foot" file="foot.png"/>
    <texture type="2d" colorspace="linear" name="thigh" file="thigh.png"/>
    <texture type="2d" colorspace="linear" name="shank_r" file="shank_r.png"/>
    <texture type="2d" colorspace="linear" name="hip_r" file="hip_r.png"/>
    <material name="MatPlane" class="/" texture="texplane" texuniform="true" texrepeat="2 2" specular="0.9" shininess="0.5"/>
    <material name="black_plastic" class="/" rgba="0.007 0.007 0.007 1"/>
    <material name="green" class="/" rgba="0.052 0.178 0.033 1"/>
    <material name="red" class="/" rgba="0.178 0.006 0.005 1"/>
    <material name="yellow" class="/" rgba="0.178 0.119 0.006 1"/>
    <material name="lwl" class="/" rgba="0.8 0.8 0.8 1"/>
    <material name="base" class="/" texture="base"/>
    <material name="top_shell" class="/" texture="top_shell"/>
    <material name="bottom_shell" class="/" texture="bottom_shell"/>
    <material name="hip_l" class="/" texture="hip_l"/>
    <material name="thigh" class="/" texture="thigh"/>
    <material name="shank_l" class="/" texture="shank_l"/>
    <material name="foot" class="/" texture="foot"/>
    <material name="hip_r" class="/" texture="hip_r"/>
    <material name="shank" class="/" texture="shank_r"/>
    <material name="hatch" class="/" texture="hatch"/>
    <material name="remote" class="/" texture="remote"/>
    <material name="handle" class="/" texture="handle"/>
    <material name="face" class="/" texture="face"/>
    <material name="depth_camera" class="/" texture="depth_camera"/>
    <material name="wide_angle_camera" class="/" texture="wide_angle_camera"/>
    <material name="battery" class="/" texture="battery"/>
    <material name="lidar_cage" class="/" texture="lidar_cage"/>
    <material name="lidar" class="/" texture="lidar"/>
    <material name="drive" class="/" texture="drive"/>
    <mesh name="base_0" class="/" file="base_0.obj"/>
    <mesh name="base_1" class="/" file="base_1.obj"/>
    <mesh name="base_2" class="/" file="base_2.obj"/>
    <mesh name="base_3" class="/" file="base_3.obj"/>
    <mesh name="base_4" class="/" file="base_4.obj"/>
    <mesh name="base_5" class="/" file="base_5.obj"/>
    <mesh name="top_shell" class="/" file="top_shell.obj"/>
    <mesh name="bottom_shell" class="/" file="bottom_shell.obj"/>
    <mesh name="remote" class="/" file="remote.obj"/>
    <mesh name="handle" class="/" file="handle.obj"/>
    <mesh name="face" class="/" file="face.obj"/>
    <mesh name="wide_angle_camera" class="/" file="wide_angle_camera.obj"/>
    <mesh name="depth_camera" class="/" file="depth_camera.obj"/>
    <mesh name="battery" class="/" file="battery.obj"/>
    <mesh name="lidar_cage" class="/" file="lidar_cage.obj"/>
    <mesh name="lidar" class="/" file="lidar.obj"/>
    <mesh name="drive" class="/" file="drive.obj"/>
    <mesh name="hip_l" class="/" file="hip_l.obj"/>
    <mesh name="thigh" class="/" file="thigh.obj"/>
    <mesh name="shank_l" class="/" file="shank_l.obj"/>
    <mesh name="foot" class="/" file="foot.obj"/>
    <mesh name="hip_r" class="/" file="hip_r.obj"/>
    <mesh name="hatch" class="/" file="hatch.obj"/>
    <mesh name="shank_r" class="/" file="shank_r.obj"/>
  </asset>

  <worldbody>
    <geom name="floor" class="/" size="100 100 0.125" type="plane" group="0" material="MatPlane"/>
    <light name="toplight_shadow" class="/" pos="0 0 5" dir="0.0990148 0.0990148 -0.990148" type="directional" ambient="0.04 0.04 0.04" diffuse="0.55 0.55 0.55" specular="0.12 0.12 0.12"/>
    <light name="toplight_fill" class="/" pos="0 0 5" dir="0.0990148 0.0990148 -0.990148" type="directional" castshadow="false" ambient="0.04 0.04 0.04" diffuse="0.3 0.3 0.3" specular="0.08 0.08 0.08"/>
    <body name="trunk" childclass="anymal_c" pos="0.000700605 -0.000303193 8.29175e-05" quat="1 -2.61548e-05 -9.41728e-05 -0.000454856">
      <inertial pos="0.000457821 -0.00281623 0.0495237" quat="0.497014 0.50346 0.498941 0.500563" mass="22.7339" diaginertia="1.06807 0.601575 0.258438"/>
      <joint name="//unnamed_joint_0" type="free" armature="0" damping="0" frictionloss="0"/>
      <geom name="//unnamed_geom_1" class="visual" material="green" mesh="base_0"/>
      <geom name="//unnamed_geom_2" class="visual" material="yellow" mesh="base_1"/>
      <geom name="//unnamed_geom_3" class="visual" material="red" mesh="base_2"/>
      <geom name="//unnamed_geom_4" class="visual" material="black_plastic" mesh="base_3"/>
      <geom name="//unnamed_geom_5" class="visual" material="lwl" mesh="base_4"/>
      <geom name="//unnamed_geom_6" class="visual" material="base" mesh="base_5"/>
      <geom name="trunk_1" class="collision" size="0.30346 0.0732489 0.0941771" type="box"/>
      <geom name="trunk_2" class="collision" size="0.0941771 0.0758649" pos="0.241017 0.0695564 0" quat="0.707107 0 0.707107 0"/>
      <geom name="trunk_3" class="collision" size="0.0941771 0.0758649" pos="-0.241017 0.0695564 0" quat="0.707107 0 0.707107 0"/>
      <geom name="trunk_4" class="collision" size="0.0941771 0.0758649" pos="0.241017 -0.0695564 0" quat="0.707107 0 0.707107 0"/>
      <geom name="trunk_5" class="collision" size="0.0941771 0.0758649" pos="-0.241017 -0.0695564 0" quat="0.707107 0 0.707107 0"/>
      <geom name="//unnamed_geom_12" class="visual" material="top_shell" mesh="top_shell"/>
      <geom name="//unnamed_geom_13" class="visual" material="bottom_shell" mesh="bottom_shell"/>
      <geom name="//unnamed_geom_14" class="visual" material="remote" mesh="remote"/>
      <geom name="//unnamed_geom_15" class="visual" material="handle" mesh="handle"/>
      <geom name="//unnamed_geom_16" class="visual" pos="0.459317 0 0" quat="1 0 0 0" material="face" mesh="face"/>
      <geom name="trunk_6" class="collision" size="0.0575527 0.0732489 0.0941771" pos="0.520264 0 0" type="box"/>
      <geom name="//unnamed_geom_18" class="collision" size="0.0941771 0.0575527" pos="0.520264 0.0695564 0" quat="0.707107 0 0.707107 0"/>
      <geom name="//unnamed_geom_19" class="collision" size="0.0941771 0.0575527" pos="0.520264 -0.0695564 0" quat="0.707107 0 0.707107 0"/>
      <geom name="//unnamed_geom_20" class="visual" pos="0.511563 0 -0.0297564" quat="0.965926 0 0.258819 0" material="depth_camera" mesh="depth_camera"/>
      <geom name="//unnamed_geom_21" class="visual" pos="0.568468 0 0.0155306" material="wide_angle_camera" mesh="wide_angle_camera"/>
      <geom name="//unnamed_geom_22" class="visual_zflip" pos="-0.459317 0 0" quat="0 0 0 1" material="face" mesh="face"/>
      <geom name="trunk_7" class="collision" size="0.0575527 0.0732489 0.0941771" pos="-0.520264 0 0" quat="0 0 0 1" type="box"/>
      <geom name="//unnamed_geom_24" class="collision" size="0.0941771 0.0575527" pos="-0.520264 -0.0695564 0" quat="0 -0.707107 0 0.707107"/>
      <geom name="//unnamed_geom_25" class="collision" size="0.0941771 0.0575527" pos="-0.520264 0.0695564 0" quat="0 -0.707107 0 0.707107"/>
      <geom name="//unnamed_geom_26" class="visual" pos="-0.511563 0 -0.0297564" quat="0 -0.258819 0 0.965926" material="depth_camera" mesh="depth_camera"/>
      <geom name="//unnamed_geom_27" class="visual_zflip" pos="-0.568468 0 0.0155306" quat="0 0 0 1" material="wide_angle_camera" mesh="wide_angle_camera"/>
      <geom name="//unnamed_geom_28" class="visual" material="battery" mesh="battery"/>
      <geom name="//unnamed_geom_29" class="visual" pos="0 0.0744706 0.030675" quat="0.683013 -0.183013 0.183013 0.683013" material="depth_camera" mesh="depth_camera"/>
      <geom name="//unnamed_geom_30" class="visual" pos="0 -0.0744706 0.030675" quat="0.683013 0.183013 0.183013 -0.683013" material="depth_camera" mesh="depth_camera"/>
      <geom name="//unnamed_geom_31" class="visual" pos="-0.403357 0 0.0762526" quat="1 0 0 0" material="lidar_cage" mesh="lidar_cage"/>
      <geom name="trunk_8" class="collision" size="0.0732489 0.0627847" pos="-0.403357 0 0.1385"/>
      <geom name="//unnamed_geom_33" class="visual" pos="-0.403357 -4.49687e-05 0.147525" quat="0.707107 0 0 -0.707107" material="lidar" mesh="lidar"/>
      <geom name="//unnamed_geom_34" class="visual" pos="0.332326 0.103357 -7.5533e-10" quat="0.258819 0.965926 0 0" material="drive" mesh="drive"/>
      <geom name="//unnamed_geom_35" class="visual" pos="0.332326 -0.103357 7.5533e-10" quat="0.258819 -0.965926 0 0" material="drive" mesh="drive"/>
      <geom name="//unnamed_geom_36" class="visual" pos="-0.332326 0.103357 7.5533e-10" quat="0 0 0.965926 -0.258819" material="drive" mesh="drive"/>
      <geom name="//unnamed_geom_37" class="visual" pos="-0.332326 -0.103357 -7.5533e-10" quat="0 0 -0.965926 -0.258819" material="drive" mesh="drive"/>
      <geom name="//unnamed_geom_38" class="visual" pos="0.128542 0 0.0757338" quat="1 0 0 0" material="hatch" mesh="hatch"/>
      <geom name="//unnamed_geom_39" class="reward_collision_sphere" size="0.125569"/>
      <geom name="//unnamed_geom_40" class="reward_collision_sphere" size="0.125569" pos="0.498656 0 0"/>
      <geom name="//unnamed_geom_41" class="reward_collision_sphere" size="0.125569" pos="-0.498656 0 0"/>
      <site name="imu" pos="0.289172 0.00870393 0.0345037" size="0.0104641"/>
      <camera name="track" pos="0 -1.98733 0" quat="0.707107 0.707107 0 0" mode="trackcom"/>
      <camera name="ego_camera" pos="0.498656 0 -0.041498" quat="-0.5 -0.5 0.5 0.5"/>
      <body name="LF_HIP" pos="0.330187 0.100934 -0.00116935" quat="0.259221 0.965818 9.02612e-05 0.000248684">
        <inertial pos="0.0626915 -0.0174875 -0.00801171" quat="-0.127256 0.709893 -0.135562 0.679324" mass="3.15237" diaginertia="0.00956709 0.00447302 0.00383841"/>
        <joint name="LF_HAA" pos="0 0 0" axis="1 -0.000440115 0.000466293" range="-0.721295 0.502527" armature="0.0106623" damping="0.020414" frictionloss="0.0925252"/>
        <geom name="//unnamed_geom_42" class="visual" pos="0 -4.44327e-05 7.29803e-06" quat="0.258819 -0.965926 0 0" material="hip_l" mesh="hip_l"/>
        <geom name="//unnamed_geom_43" class="visual" pos="0.0663766 -0.0789379 -0.0458987" quat="0.183013 -0.683013 0.683013 0.183013" material="drive" mesh="drive"/>
        <geom name="//unnamed_geom_44" class="collision" size="0.0523206 0.0732489" pos="0.0663766 -0.011884 -0.00716359" quat="-0.353553 -0.612372 0.612372 -0.353553"/>
        <body name="LF_THIGH" pos="0.0651112 -0.0695273 -0.0424557" quat="0.18226 -0.682818 0.683666 0.182051">
          <inertial pos="0.0345023 0.000238366 -0.253213" quat="0.994249 -0.0132151 -0.07168 0.0784635" mass="3.42984" diaginertia="0.0507375 0.0282393 0.00503666"/>
          <joint name="LF_HFE" pos="0 0 0" axis="0.999992 -0.00387117 0.000447749" stiffness="0.00270114" range="-3.08827 3.18308" armature="0.0108663" damping="0.0215304" frictionloss="0.0954617"/>
          <geom name="//unnamed_geom_45" class="visual" pos="0.00227732 3.58853e-06 0" quat="0.707107 0 0 -0.707107" material="thigh" mesh="thigh"/>
          <geom name="//unnamed_geom_46" class="collision" size="0.0680168 0.0418565" pos="0.044325 0 0" quat="0.5 0.5 -0.5 -0.5"/>
          <geom name="//unnamed_geom_47" class="collision" size="0.0392405 0.0313924 0.147873" pos="0.0332437 0 -0.146606" quat="0.707107 0 0 -0.707107" type="box"/>
          <geom name="//unnamed_geom_48" class="visual" pos="0.111145 0 -0.295673" quat="1 0 0 0" material="drive" mesh="drive"/>
          <geom name="//unnamed_geom_49" class="collision" size="0.0523206 0.0732489" pos="0.0335762 0 -0.295673" quat="0.707107 0 0.707107 0"/>
          <geom name="//unnamed_geom_50" class="reward_collision_sphere" size="0.083713" pos="0.0277031 0 0"/>
          <body name="LF_SHANK" pos="0.112088 0.00267954 -0.2951" quat="1 0.000134659 0.000307199 -4.84108e-06">
            <inertial pos="0.00605938 -0.0618366 -0.0848512" quat="0.993126 -0.114326 0.00105511 -0.0250905" mass="0.682929" diaginertia="0.0166143 0.00900121 0.00134621"/>
            <joint name="LF_KFE" pos="0 0 0" axis="0.999988 -0.00497729 4.62191e-05" range="-3.09592 3.14485" armature="0.0104645" damping="0.00676171" frictionloss="0.10703"/>
            <geom name="//unnamed_geom_51" class="visual" pos="0.000742586 0.0039595 0" quat="0.707107 0 0 -0.707107" material="shank_l" mesh="shank_l"/>
            <geom name="LF_kfe_act" class="collision" size="0.0627847 0.0209282" pos="0.0221625 0 0" quat="0.5 0.5 -0.5 -0.5"/>
            <geom name="//unnamed_geom_53" class="collision" size="0.0601677 0.0353164 0.0198818" pos="0.0221625 -0.0571346 0" quat="0.5 0.5 -0.5 -0.5" type="box"/>
            <geom name="//unnamed_geom_54" class="visual" pos="0.0144608 -0.0861167 -0.350627" quat="0.382683 0 0 -0.92388" material="foot" mesh="foot"/>
            <geom name="LF_calf" class="collision" size="0.0183122 0.147808" pos="0.014461 -0.0873927 -0.175313" quat="0.707107 0 0 -0.707107"/>
            <geom name="LF_foot" class="foot" size="0.0309497" pos="0.014461 -0.0873927 -0.327284" quat="0.707107 0 0 -0.707107"/>
            <geom name="//unnamed_geom_57" class="reward_collision_sphere" size="0.104641" pos="-0.0554062 0 0"/>
            <geom name="//unnamed_geom_58" class="reward_collision_sphere" size="0.0523206" pos="0.014461 -0.0873927 -0.327284"/>
            <site name="LF_foot" class="foot" pos="0.014461 -0.0873927 -0.327284" quat="0.707107 0 0 -0.707107" size="0.0104641"/>
          </body>
        </body>
      </body>
      <body name="RF_HIP" pos="0.330089 -0.103761 0.000839958" quat="0.258818 -0.965926 -1.37148e-06 -1.02293e-06">
        <inertial pos="0.0608313 0.0133004 -0.0109783" quat="0.137088 0.68699 0.131342 0.701428" mass="3.15499" diaginertia="0.00933001 0.0048619 0.00377371"/>
        <joint name="RF_HAA" pos="0 0 0" axis="0.999933 0.0100174 0.0058581" range="-0.513347 0.727974" armature="0.010583" damping="0" frictionloss="0.106044"/>
        <geom name="//unnamed_geom_59" class="visual" pos="0 4.44323e-05 7.29801e-06" quat="0.258819 0.965926 0 0" material="hip_r" mesh="hip_r"/>
        <geom name="//unnamed_geom_60" class="visual" pos="0.0663766 0.0789379 -0.0458987" quat="0.183013 0.683013 0.683013 -0.183013" material="drive" mesh="drive"/>
        <geom name="//unnamed_geom_61" class="collision" size="0.0523206 0.0732489" pos="0.0663766 0.011884 -0.00716359" quat="-0.353553 0.612372 0.612372 0.353553"/>
        <body name="RF_THIGH" pos="0.0682691 0.0712573 -0.0460713" quat="0.183103 0.683015 0.682678 -0.18416">
          <inertial pos="0.0368867 0.000217663 -0.256274" quat="0.992059 0.000458869 -0.0808063 0.0963772" mass="3.68503" diaginertia="0.0498466 0.028324 0.0052662"/>
          <joint name="RF_HFE" pos="0 0 0" axis="0.999999 -0.00100486 0.00113528" range="-3.14207 3.1592" armature="0.0094006" damping="0.0107895" frictionloss="0.108316"/>
          <geom name="//unnamed_geom_62" class="visual" pos="0.00227732 3.58853e-06 0" quat="0.707107 0 0 -0.707107" material="thigh" mesh="thigh"/>
          <geom name="//unnamed_geom_63" class="collision" size="0.0680168 0.0418565" pos="0.044325 0 0" quat="0.5 0.5 0.5 0.5"/>
          <geom name="//unnamed_geom_64" class="collision" size="0.0392405 0.0313924 0.147873" pos="0.0332437 0 -0.146606" quat="0.707107 0 0 0.707107" type="box"/>
          <geom name="//unnamed_geom_65" class="visual" pos="0.111145 0 -0.295673" quat="1 0 0 0" material="drive" mesh="drive"/>
          <geom name="//unnamed_geom_66" class="collision" size="0.0523206 0.0732489" pos="0.0335762 0 -0.295673" quat="0.707107 0 0.707107 0"/>
          <geom name="//unnamed_geom_67" class="reward_collision_sphere" size="0.083713" pos="0.0277031 0 0"/>
          <body name="RF_SHANK" pos="0.108921 0.000193327 -0.295841" quat="1 -0.000377222 -0.00074524 -0.000249761">
            <inertial pos="0.00364824 0.0608218 -0.083655" quat="0.992559 0.117067 0.009511 0.0321116" mass="0.713266" diaginertia="0.0176943 0.00913446 0.00138719"/>
            <joint name="RF_KFE" pos="0 0 0" axis="0.999999 0.00104035 5.37832e-05" range="-3.1903 3.09679" armature="0.0120328" damping="0.0225686" frictionloss="0.109687"/>
            <geom name="//unnamed_geom_68" class="visual" pos="0.000742582 -0.0039595 0" quat="0.707107 0 0 0.707107" material="shank" mesh="shank_r"/>
            <geom name="RF_kfe_act" class="collision" size="0.0627847 0.0209282" pos="0.0221625 0 0" quat="0.5 0.5 0.5 0.5"/>
            <geom name="//unnamed_geom_70" class="collision" size="0.0601677 0.0353164 0.0198818" pos="0.0221625 0.0571346 0" quat="0.5 0.5 0.5 0.5" type="box"/>
            <geom name="//unnamed_geom_71" class="visual" pos="0.0144612 0.0861167 -0.350627" quat="0.382683 0 0 0.92388" material="foot" mesh="foot"/>
            <geom name="RF_calf" class="collision" size="0.0183122 0.147808" pos="0.014461 0.0873927 -0.175313" quat="0.707107 0 0 0.707107"/>
            <geom name="RF_foot" class="foot" size="0.028039" pos="0.014461 0.0873927 -0.327284" quat="0.707107 0 0 0.707107"/>
            <geom name="//unnamed_geom_74" class="reward_collision_sphere" size="0.104641" pos="-0.0554062 0 0"/>
            <geom name="//unnamed_geom_75" class="reward_collision_sphere" size="0.0523206" pos="0.014461 0.0873927 -0.327284"/>
            <site name="RF_foot" class="foot" pos="0.014461 0.0873927 -0.327284" quat="0.707107 0 0 0.707107" size="0.0104641"/>
          </body>
        </body>
      </body>
      <body name="LH_HIP" pos="-0.328993 0.101397 -0.00153621" quat="2.31822e-06 -5.18886e-05 0.965936 -0.25878">
        <inertial pos="0.0628002 0.0173114 -0.0112308" quat="0.135724 0.684884 0.137694 0.702533" mass="3.29558" diaginertia="0.0103806 0.00498106 0.00400322"/>
        <joint name="LH_HAA" pos="0 0 0" axis="0.999889 0.000516068 -0.0149081" range="-0.504076 0.72803" armature="0.0109609" damping="0" frictionloss="0.105357"/>
        <geom name="//unnamed_geom_76" class="visual" pos="0 4.44323e-05 7.29801e-06" quat="-0.258819 -0.965926 0 0" material="hip_r" mesh="hip_r"/>
        <geom name="//unnamed_geom_77" class="visual" pos="0.0663766 0.0789379 -0.0458987" quat="0.183013 0.683013 0.683013 -0.183013" material="drive" mesh="drive"/>
        <geom name="//unnamed_geom_78" class="collision" size="0.0523206 0.0732489" pos="0.0663766 0.011884 -0.00716359" quat="-0.353553 0.612372 0.612372 0.353553"/>
        <body name="LH_THIGH" pos="0.0655009 0.0710704 -0.0437623" quat="0.183133 0.682924 0.683086 -0.182952">
          <inertial pos="0.0319614 -0.000190033 -0.257317" quat="0.992916 -0.0059572 -0.0796656 0.0879583" mass="3.38374" diaginertia="0.0475168 0.0289202 0.0048911"/>
          <joint name="LH_HFE" pos="0 0 0" axis="1 -0.000296026 -0.000385481" stiffness="0.0107201" range="-3.17145 3.09407" armature="0.00993846" damping="0" frictionloss="0.104882"/>
          <geom name="//unnamed_geom_79" class="visual" pos="0.00227732 3.58853e-06 0" quat="0.707107 0 0 -0.707107" material="thigh" mesh="thigh"/>
          <geom name="//unnamed_geom_80" class="collision" size="0.0680168 0.0418565" pos="0.044325 0 0" quat="0.5 0.5 -0.5 -0.5"/>
          <geom name="//unnamed_geom_81" class="collision" size="0.0392405 0.0313924 0.147873" pos="0.0332437 0 -0.146606" quat="0.707107 0 0 -0.707107" type="box"/>
          <geom name="//unnamed_geom_82" class="visual" pos="0.111145 0 -0.295673" quat="1 0 0 0" material="drive" mesh="drive"/>
          <geom name="//unnamed_geom_83" class="collision" size="0.0523206 0.0732489" pos="0.0335762 0 -0.295673" quat="0.707107 0 0.707107 0"/>
          <geom name="//unnamed_geom_84" class="reward_collision_sphere" size="0.083713" pos="0.0277031 0 0"/>
          <body name="LH_SHANK" pos="0.110806 -0.00091842 -0.295624" quat="1 -0.000155374 -7.71886e-05 2.85982e-05">
            <inertial pos="0.00746978 0.0635667 -0.0835348" quat="0.991627 0.126131 -0.00141376 0.0276718" mass="0.691423" diaginertia="0.0169341 0.00951287 0.0013767"/>
            <joint name="LH_KFE" pos="0 0 0" axis="1 -3.60623e-05 -3.25132e-05" range="-3.08879 3.09179" armature="0.0119037" damping="0.0233276" frictionloss="0.0901975"/>
            <geom name="//unnamed_geom_85" class="visual" pos="0.000742582 -0.0039595 0" quat="-0.707107 0 0 -0.707107" material="shank" mesh="shank_r"/>
            <geom name="LH_kfe_act" class="collision" size="0.0627847 0.0209282" pos="0.0221625 0 0" quat="0.5 0.5 -0.5 -0.5"/>
            <geom name="//unnamed_geom_87" class="collision" size="0.0601677 0.0353164 0.0198818" pos="0.0221625 0.0571346 0" quat="0.5 0.5 -0.5 -0.5" type="box"/>
            <geom name="//unnamed_geom_88" class="visual" pos="0.0144612 0.0861167 -0.350627" quat="-0.382683 0 0 -0.92388" material="foot" mesh="foot"/>
            <geom name="LH_calf" class="collision" size="0.0183122 0.147808" pos="0.014461 0.0873927 -0.175313" quat="0.707107 0 0 -0.707107"/>
            <geom name="LH_foot" class="foot" size="0.0341947" pos="0.014461 0.0873927 -0.327284" quat="0.707107 0 0 -0.707107"/>
            <geom name="//unnamed_geom_91" class="reward_collision_sphere" size="0.104641" pos="-0.0554062 0 0"/>
            <geom name="//unnamed_geom_92" class="reward_collision_sphere" size="0.0523206" pos="0.014461 0.0873927 -0.327284"/>
            <site name="LH_foot" class="foot" pos="0.014461 0.0873927 -0.327284" quat="0.707107 0 0 -0.707107" size="0.0104641"/>
          </body>
        </body>
      </body>
      <body name="RH_HIP" pos="-0.330004 -0.104474 0.00134712" quat="-4.49935e-06 -1.09231e-05 -0.965927 -0.258814">
        <inertial pos="0.0608526 -0.0137696 -0.0113356" quat="-0.127193 0.708749 -0.125279 0.682497" mass="3.19989" diaginertia="0.00947431 0.00465094 0.00383873"/>
        <joint name="RH_HAA" pos="0 0 0" axis="0.999895 0.000563445 -0.0144499" stiffness="0.00156229" range="-0.778217 0.525068" armature="0.0101202" damping="0.00311202" frictionloss="0.105168"/>
        <geom name="//unnamed_geom_93" class="visual" pos="0 -4.44327e-05 7.29803e-06" quat="-0.258819 0.965926 0 0" material="hip_l" mesh="hip_l"/>
        <geom name="//unnamed_geom_94" class="visual" pos="0.0663766 -0.0789379 -0.0458987" quat="-0.183013 0.683013 -0.683013 -0.183013" material="drive" mesh="drive"/>
        <geom name="//unnamed_geom_95" class="collision" size="0.0523206 0.0732489" pos="0.0663766 -0.011884 -0.00716359" quat="0.353553 0.612372 -0.612372 0.353553"/>
        <body name="RH_THIGH" pos="0.0687669 -0.0713005 -0.0456215" quat="-0.183878 0.682295 -0.683339 -0.183603">
          <inertial pos="0.0346082 0.00174781 -0.255505" quat="0.993077 -0.0062794 -0.0811547 0.0846875" mass="3.31267" diaginertia="0.0475787 0.0283307 0.0049525"/>
          <joint name="RH_HFE" pos="0 0 0" axis="0.999984 0.00103988 -0.00558613" stiffness="0.00231392" range="-3.10213 3.15326" armature="0.0110313" damping="0.0152308" frictionloss="0.105731"/>
          <geom name="//unnamed_geom_96" class="visual" pos="0.00227732 3.58853e-06 0" quat="0.707107 0 0 -0.707107" material="thigh" mesh="thigh"/>
          <geom name="//unnamed_geom_97" class="collision" size="0.0680168 0.0418565" pos="0.044325 0 0" quat="0.5 0.5 0.5 0.5"/>
          <geom name="//unnamed_geom_98" class="collision" size="0.0392405 0.0313924 0.147873" pos="0.0332437 0 -0.146606" quat="0.707107 0 0 0.707107" type="box"/>
          <geom name="//unnamed_geom_99" class="visual" pos="0.111145 0 -0.295673" quat="1 0 0 0" material="drive" mesh="drive"/>
          <geom name="//unnamed_geom_100" class="collision" size="0.0523206 0.0732489" pos="0.0335762 0 -0.295673" quat="0.707107 0 0.707107 0"/>
          <geom name="//unnamed_geom_101" class="reward_collision_sphere" size="0.083713" pos="0.0277031 0 0"/>
          <body name="RH_SHANK" pos="0.110226 0.0027175 -0.295061" quat="0.999999 0.000806909 -0.00102217 -0.000279128">
            <inertial pos="0.00890799 -0.0615675 -0.0842944" quat="0.994094 -0.107402 -0.00225623 -0.0153684" mass="0.684841" diaginertia="0.0165998 0.00895728 0.00131937"/>
            <joint name="RH_KFE" pos="0 0 0" axis="1 -0.000152274 1.59626e-07" range="-3.13392 3.19039" armature="0.0105001" damping="0.0230369" frictionloss="0.109387"/>
            <geom name="//unnamed_geom_102" class="visual" pos="0.000742586 0.0039595 0" quat="0.707107 0 0 -0.707107" material="shank_l" mesh="shank_l"/>
            <geom name="RH_kfe_act" class="collision" size="0.0627847 0.0209282" pos="0.0221625 0 0" quat="0.5 0.5 0.5 0.5"/>
            <geom name="//unnamed_geom_104" class="collision" size="0.0601677 0.0353164 0.0198818" pos="0.0221625 -0.0571346 0" quat="0.5 0.5 0.5 0.5" type="box"/>
            <geom name="//unnamed_geom_105" class="visual" pos="0.0144608 -0.0861167 -0.350627" quat="0.382683 0 0 -0.92388" material="foot" mesh="foot"/>
            <geom name="RH_calf" class="collision" size="0.0183122 0.147808" pos="0.014461 -0.0873927 -0.175313" quat="0.707107 0 0 0.707107"/>
            <geom name="RH_foot" class="foot" size="0.0274252" pos="0.014461 -0.0873927 -0.327284" quat="0.707107 0 0 0.707107"/>
            <geom name="//unnamed_geom_108" class="reward_collision_sphere" size="0.104641" pos="-0.0554062 0 0"/>
            <geom name="//unnamed_geom_109" class="reward_collision_sphere" size="0.0523206" pos="0.014461 -0.0873927 -0.327284"/>
            <site name="RH_foot" class="foot" pos="0.014461 -0.0873927 -0.327284" quat="0.707107 0 0 0.707107" size="0.0104641"/>
          </body>
        </body>
      </body>
    </body>
  </worldbody>

  <contact>
    <pair class="/" geom1="floor" geom2="LF_foot" name="//unnamed_contact_0"/>
    <pair class="/" geom1="floor" geom2="RF_foot" name="//unnamed_contact_1"/>
    <pair class="/" geom1="floor" geom2="LH_foot" name="//unnamed_contact_2"/>
    <pair class="/" geom1="floor" geom2="RH_foot" name="//unnamed_contact_3"/>
  </contact>

  <actuator>
    <general name="LF_HAA" class="/" joint="LF_HAA" forcerange="-76.2777 76.2777" gainprm="80.4247" biasprm="0 -80.4247 -2.09636"/>
    <general name="LF_HFE" class="/" joint="LF_HFE" forcerange="-75.4528 75.4528" gainprm="80.4247" biasprm="0 -80.4247 -2.09636"/>
    <general name="LF_KFE" class="/" joint="LF_KFE" forcerange="-84.6605 84.6605" gainprm="80.4247" biasprm="0 -80.4247 -2.09636"/>
    <general name="RF_HAA" class="/" joint="RF_HAA" forcerange="-85.0858 85.0858" gainprm="80.4247" biasprm="0 -80.4247 -2.09636"/>
    <general name="RF_HFE" class="/" joint="RF_HFE" forcerange="-93.4544 93.4544" gainprm="80.4247" biasprm="0 -80.4247 -2.09636"/>
    <general name="RF_KFE" class="/" joint="RF_KFE" forcerange="-87.1244 87.1244" gainprm="80.4247" biasprm="0 -80.4247 -2.09636"/>
    <general name="LH_HAA" class="/" joint="LH_HAA" forcerange="-85.1499 85.1499" gainprm="80.4247" biasprm="0 -80.4247 -2.09636"/>
    <general name="LH_HFE" class="/" joint="LH_HFE" forcerange="-76.391 76.391" gainprm="80.4247" biasprm="0 -80.4247 -2.09636"/>
    <general name="LH_KFE" class="/" joint="LH_KFE" forcerange="-86.5945 86.5945" gainprm="80.4247" biasprm="0 -80.4247 -2.09636"/>
    <general name="RH_HAA" class="/" joint="RH_HAA" forcerange="-85.7005 85.7005" gainprm="80.4247" biasprm="0 -80.4247 -2.09636"/>
    <general name="RH_HFE" class="/" joint="RH_HFE" forcerange="-92.962 92.962" gainprm="80.4247" biasprm="0 -80.4247 -2.09636"/>
    <general name="RH_KFE" class="/" joint="RH_KFE" forcerange="-80.8744 80.8744" gainprm="80.4247" biasprm="0 -80.4247 -2.09636"/>
  </actuator>

  <sensor>
    <gyro site="imu" name="imu_angular_velocity"/>
    <velocimeter site="imu" name="imu_linear_velocity"/>
    <framelinvel objtype="site" objname="LF_foot" name="LF_foot_global_linear_velocity"/>
    <framelinvel objtype="site" objname="RF_foot" name="RF_foot_global_linear_velocity"/>
    <framelinvel objtype="site" objname="LH_foot" name="LH_foot_global_linear_velocity"/>
    <framelinvel objtype="site" objname="RH_foot" name="RH_foot_global_linear_velocity"/>
  </sensor>

  <keyframe>
    <key name="home" qpos="0 0 0.55 1 0 0 0 0 0.4 -0.8 0 -0.4 0.8 0 -0.4 0.8 0 0.4 -0.8"/>
  </keyframe>
</mujoco>
