<mujoco model="anymal_c">
  <compiler angle="radian" assetdir="assets" balanceinertia="true" inertiafromgeom="false"/>

  <option timestep="0.005" density="1.2" viscosity="2e-05"/>

  <size nkey="1"/>

  <visual>
    <quality shadowsize="8192"/>
    <map shadowclip="0.5"/>
  </visual>

  <default>
    <default class="/">
      <material specular="0" shininess="0.25"/>
      <geom contype="0" conaffinity="0" group="1" solref="-1000 -80"/>
      <site size="0.01 0.005 0.005" group="5"/>
      <general forcelimited="true" forcerange="-80 80" biastype="affine" gainprm="80" biasprm="0 -80 -2"/>
      <default class="anymal_c">
        <joint armature="0.01" damping="0.01" frictionloss="0.1"/>
        <default class="visual">
          <geom type="mesh" group="2"/>
          <default class="visual_zflip"/>
        </default>
        <default class="collision">
          <geom type="cylinder" group="3"/>
          <default class="foot">
            <geom size="0.03 0 0" type="sphere" condim="6" priority="1" friction="0.8 0.02 0.01" solimp="0.015 1 0.03"/>
          </default>
        </default>
      </default>
      <default class="reward_collision_sphere">
        <geom group="5" rgba="1 0 0 1"/>
      </default>
    </default>
  </default>

  <asset>
    <texture type="skybox" colorspace="auto" name="//unnamed_texture_0" builtin="gradient" rgb1="0.95 0.95 0.95" rgb2="0.95 0.95 0.95" width="100" height="600"/>
    <texture type="2d" colorspace="auto" name="texplane" builtin="checker" rgb1="0.345 0.575 0.748" rgb2="0.345 0.575 0.748" markrgb="1 1 1" width="512" height="512"/>
    <texture type="2d" colorspace="linear" name="base" file="base.png"/>
    <texture type="2d" colorspace="linear" name="top_shell" file="top_shell.png"/>
    <texture type="2d" colorspace="linear" name="bottom_shell" file="bottom_shell.png"/>
    <texture type="2d" colorspace="linear" name="remote" file="remote.png"/>
    <texture type="2d" colorspace="linear" name="hatch" file="hatch.png"/>
    <texture type="2d" colorspace="linear" name="handle" file="handle.png"/>
    <texture type="2d" colorspace="linear" name="face" file="face.png"/>
    <texture type="2d" colorspace="linear" name="battery" file="battery.png"/>
    <texture type="2d" colorspace="linear" name="lidar_cage" file="lidar_cage.png"/>
    <texture type="2d" colorspace="linear" name="depth_camera" file="depth_camera.png"/>
    <texture type="2d" colorspace="linear" name="wide_angle_camera" file="wide_angle_camera.png"/>
    <texture type="2d" colorspace="linear" name="lidar" file="lidar.png"/>
    <texture type="2d" colorspace="linear" name="drive" file="drive.png"/>
    <texture type="2d" colorspace="linear" name="hip_l" file="hip_l.png"/>
    <texture type="2d" colorspace="linear" name="shank_l" file="shank_l.png"/>
    <texture type="2d" colorspace="linear" name="foot" file="foot.png"/>
    <texture type="2d" colorspace="linear" name="thigh" file="thigh.png"/>
    <texture type="2d" colorspace="linear" name="shank_r" file="shank_r.png"/>
    <texture type="2d" colorspace="linear" name="hip_r" file="hip_r.png"/>
    <material name="MatPlane" class="/" texture="texplane" texuniform="true" texrepeat="2 2" specular="0.9" shininess="0.5"/>
    <material name="black_plastic" class="/" rgba="0.007 0.007 0.007 1"/>
    <material name="green" class="/" rgba="0.052 0.178 0.033 1"/>
    <material name="red" class="/" rgba="0.178 0.006 0.005 1"/>
    <material name="yellow" class="/" rgba="0.178 0.119 0.006 1"/>
    <material name="lwl" class="/" rgba="0.8 0.8 0.8 1"/>
    <material name="base" class="/" texture="base"/>
    <material name="top_shell" class="/" texture="top_shell"/>
    <material name="bottom_shell" class="/" texture="bottom_shell"/>
    <material name="hip_l" class="/" texture="hip_l"/>
    <material name="thigh" class="/" texture="thigh"/>
    <material name="shank_l" class="/" texture="shank_l"/>
    <material name="foot" class="/" texture="foot"/>
    <material name="hip_r" class="/" texture="hip_r"/>
    <material name="shank" class="/" texture="shank_r"/>
    <material name="hatch" class="/" texture="hatch"/>
    <material name="remote" class="/" texture="remote"/>
    <material name="handle" class="/" texture="handle"/>
    <material name="face" class="/" texture="face"/>
    <material name="depth_camera" class="/" texture="depth_camera"/>
    <material name="wide_angle_camera" class="/" texture="wide_angle_camera"/>
    <material name="battery" class="/" texture="battery"/>
    <material name="lidar_cage" class="/" texture="lidar_cage"/>
    <material name="lidar" class="/" texture="lidar"/>
    <material name="drive" class="/" texture="drive"/>
    <mesh name="base_0" class="/" file="base_0.obj"/>
    <mesh name="base_1" class="/" file="base_1.obj"/>
    <mesh name="base_2" class="/" file="base_2.obj"/>
    <mesh name="base_3" class="/" file="base_3.obj"/>
    <mesh name="base_4" class="/" file="base_4.obj"/>
    <mesh name="base_5" class="/" file="base_5.obj"/>
    <mesh name="top_shell" class="/" file="top_shell.obj"/>
    <mesh name="bottom_shell" class="/" file="bottom_shell.obj"/>
    <mesh name="remote" class="/" file="remote.obj"/>
    <mesh name="handle" class="/" file="handle.obj"/>
    <mesh name="face" class="/" file="face.obj"/>
    <mesh name="wide_angle_camera" class="/" file="wide_angle_camera.obj"/>
    <mesh name="depth_camera" class="/" file="depth_camera.obj"/>
    <mesh name="battery" class="/" file="battery.obj"/>
    <mesh name="lidar_cage" class="/" file="lidar_cage.obj"/>
    <mesh name="lidar" class="/" file="lidar.obj"/>
    <mesh name="drive" class="/" file="drive.obj"/>
    <mesh name="hip_l" class="/" file="hip_l.obj"/>
    <mesh name="thigh" class="/" file="thigh.obj"/>
    <mesh name="shank_l" class="/" file="shank_l.obj"/>
    <mesh name="foot" class="/" file="foot.obj"/>
    <mesh name="hip_r" class="/" file="hip_r.obj"/>
    <mesh name="hatch" class="/" file="hatch.obj"/>
    <mesh name="shank_r" class="/" file="shank_r.obj"/>
  </asset>

  <worldbody>
    <geom name="floor" class="/" size="100 100 0.125" type="plane" group="0" material="MatPlane"/>
    <light name="toplight_shadow" class="/" pos="0 0 5" dir="0.0990148 0.0990148 -0.990148" type="directional" ambient="0.04 0.04 0.04" diffuse="0.55 0.55 0.55" specular="0.12 0.12 0.12"/>
    <light name="toplight_fill" class="/" pos="0 0 5" dir="0.0990148 0.0990148 -0.990148" type="directional" castshadow="false" ambient="0.04 0.04 0.04" diffuse="0.3 0.3 0.3" specular="0.08 0.08 0.08"/>
    <body name="trunk" childclass="anymal_c" pos="-0.00617065 -0.00157962 -0.000522934" quat="0.999997 0.00238929 -0.000162368 0.000222543">
      <inertial pos="0.00766075 0.000538947 0.0458854" quat="0.509336 0.500211 0.498149 0.492151" mass="21.3396" diaginertia="0.335545 1.25493 0.214379"/>
      <joint name="//unnamed_joint_0" type="free" armature="0" damping="0" frictionloss="0"/>
      <geom name="//unnamed_geom_1" class="visual" material="green" mesh="base_0"/>
      <geom name="//unnamed_geom_2" class="visual" material="yellow" mesh="base_1"/>
      <geom name="//unnamed_geom_3" class="visual" material="red" mesh="base_2"/>
      <geom name="//unnamed_geom_4" class="visual" material="black_plastic" mesh="base_3"/>
      <geom name="//unnamed_geom_5" class="visual" material="lwl" mesh="base_4"/>
      <geom name="//unnamed_geom_6" class="visual" material="base" mesh="base_5"/>
      <geom name="trunk_1" class="collision" size="0.291673 0.0704038 0.0905192" type="box"/>
      <geom name="trunk_2" class="collision" size="0.0905192 0.0729182" pos="0.190755 0.0804112 0" quat="0.707107 0 0.707107 0"/>
      <geom name="trunk_3" class="collision" size="0.0905192 0.0729182" pos="-0.190755 0.0804112 0" quat="0.707107 0 0.707107 0"/>
      <geom name="trunk_4" class="collision" size="0.0905192 0.0729182" pos="0.190755 -0.0804112 0" quat="0.707107 0 0.707107 0"/>
      <geom name="trunk_5" class="collision" size="0.0905192 0.0729182" pos="-0.190755 -0.0804112 0" quat="0.707107 0 0.707107 0"/>
      <geom name="//unnamed_geom_12" class="visual" material="top_shell" mesh="top_shell"/>
      <geom name="//unnamed_geom_13" class="visual" material="bottom_shell" mesh="bottom_shell"/>
      <geom name="//unnamed_geom_14" class="visual" material="remote" mesh="remote"/>
      <geom name="//unnamed_geom_15" class="visual" material="handle" mesh="handle"/>
      <geom name="//unnamed_geom_16" class="visual" pos="0.36353 0 0" quat="1 0 0 0" material="face" mesh="face"/>
      <geom name="trunk_6" class="collision" size="0.0553173 0.0704038 0.0905192" pos="0.411767 0 0" type="box"/>
      <geom name="//unnamed_geom_18" class="collision" size="0.0905192 0.0553173" pos="0.411767 0.0804112 0" quat="0.707107 0 0.707107 0"/>
      <geom name="//unnamed_geom_19" class="collision" size="0.0905192 0.0553173" pos="0.411767 -0.0804112 0" quat="0.707107 0 0.707107 0"/>
      <geom name="//unnamed_geom_20" class="visual" pos="0.404887 0 -0.0298233" quat="0.965926 0 0.258819 0" material="depth_camera" mesh="depth_camera"/>
      <geom name="//unnamed_geom_21" class="visual" pos="0.449918 0 0.0148434" material="wide_angle_camera" mesh="wide_angle_camera"/>
      <geom name="//unnamed_geom_22" class="visual_zflip" pos="-0.36353 0 0" quat="0 0 0 1" material="face" mesh="face"/>
      <geom name="trunk_7" class="collision" size="0.0553173 0.0704038 0.0905192" pos="-0.411767 0 0" quat="0 0 0 1" type="box"/>
      <geom name="//unnamed_geom_24" class="collision" size="0.0905192 0.0553173" pos="-0.411767 -0.0804112 0" quat="0 -0.707107 0 0.707107"/>
      <geom name="//unnamed_geom_25" class="collision" size="0.0905192 0.0553173" pos="-0.411767 0.0804112 0" quat="0 -0.707107 0 0.707107"/>
      <geom name="//unnamed_geom_26" class="visual" pos="-0.404887 0 -0.0298233" quat="0 -0.258819 0 0.965926" material="depth_camera" mesh="depth_camera"/>
      <geom name="//unnamed_geom_27" class="visual_zflip" pos="-0.449918 0 0.0148434" quat="0 0 0 1" material="wide_angle_camera" mesh="wide_angle_camera"/>
      <geom name="//unnamed_geom_28" class="visual" material="battery" mesh="battery"/>
      <geom name="//unnamed_geom_29" class="visual" pos="0 0.091402 0.027934" quat="0.683013 -0.183013 0.183013 0.683013" material="depth_camera" mesh="depth_camera"/>
      <geom name="//unnamed_geom_30" class="visual" pos="0 -0.091402 0.027934" quat="0.683013 0.183013 0.183013 -0.683013" material="depth_camera" mesh="depth_camera"/>
      <geom name="//unnamed_geom_31" class="visual" pos="-0.31924 0 0.0728784" quat="1 0 0 0" material="lidar_cage" mesh="lidar_cage"/>
      <geom name="trunk_8" class="collision" size="0.0704038 0.0603461" pos="-0.31924 0 0.132371"/>
      <geom name="//unnamed_geom_33" class="visual" pos="-0.31924 0.000106743 0.140997" quat="0.707107 0 0 -0.707107" material="lidar" mesh="lidar"/>
      <geom name="//unnamed_geom_34" class="visual" pos="0.263022 0.119412 2.71152e-09" quat="0.258819 0.965926 0 0" material="drive" mesh="drive"/>
      <geom name="//unnamed_geom_35" class="visual" pos="0.263022 -0.119412 -2.71152e-09" quat="0.258819 -0.965926 0 0" material="drive" mesh="drive"/>
      <geom name="//unnamed_geom_36" class="visual" pos="-0.263022 0.119412 -2.71152e-09" quat="0 0 0.965926 -0.258819" material="drive" mesh="drive"/>
      <geom name="//unnamed_geom_37" class="visual" pos="-0.263022 -0.119412 2.71152e-09" quat="0 0 -0.965926 -0.258819" material="drive" mesh="drive"/>
      <geom name="//unnamed_geom_38" class="visual" pos="0.101736 0 0.0723826" quat="1 0 0 0" material="hatch" mesh="hatch"/>
      <geom name="//unnamed_geom_39" class="reward_collision_sphere" size="0.120692"/>
      <geom name="//unnamed_geom_40" class="reward_collision_sphere" size="0.120692" pos="0.394665 0 0"/>
      <geom name="//unnamed_geom_41" class="reward_collision_sphere" size="0.120692" pos="-0.394665 0 0"/>
      <site name="imu" pos="0.209301 0.00872984 0.0238969" size="0.0100577"/>
      <camera name="track" pos="0 -2.29746 0" quat="0.707107 0.707107 0 0" mode="trackcom"/>
      <camera name="ego_camera" pos="0.394665 0 -0.0396617" quat="-0.5 -0.5 0.5 0.5"/>
      <body name="LF_HIP" pos="0.263811 0.117855 0.000655214" quat="0.259023 0.965871 0.000135067 -0.000238982">
        <inertial pos="0.05228 -0.0153846 -0.0104774" quat="-0.133426 0.70476 -0.141438 0.68228" mass="2.894" diaginertia="0.00288462 0.0101426 0.00314903"/>
        <joint name="LF_HAA" pos="0 0 0" axis="0.999568 0.0147226 0.0254421" range="-0.833725 0.442141" armature="0.0104307" damping="0.0111444" frictionloss="0.0968987"/>
        <geom name="//unnamed_geom_42" class="visual" pos="0 0.000159507 -2.61988e-05" quat="0.258819 -0.965926 0 0" material="hip_l" mesh="hip_l"/>
        <geom name="//unnamed_geom_43" class="visual" pos="0.0525343 -0.0671779 -0.0376225" quat="0.183013 -0.683013 0.683013 0.183013" material="drive" mesh="drive"/>
        <geom name="//unnamed_geom_44" class="collision" size="0.0502884 0.0704038" pos="0.0525343 -0.0137386 -0.0068466" quat="-0.353553 -0.612372 0.612372 -0.353553"/>
        <body name="LF_THIGH" pos="0.052958 -0.0837813 -0.0417091" quat="0.181674 -0.682371 0.683987 0.1831">
          <inertial pos="0.0251714 0.00118508 -0.238989" quat="0.993166 -0.00515502 -0.080656 0.0841939" mass="3.1465" diaginertia="0.0161719 0.062601 0.00377695"/>
          <joint name="LF_HFE" pos="0 0 0" axis="0.999971 0.00680311 -0.00338733" stiffness="0.0314804" range="-3.12907 3.1525" armature="0.00955792" damping="0.00551797" frictionloss="0.092461"/>
          <geom name="//unnamed_geom_45" class="visual" pos="-0.00540572 -8.51815e-06 0" quat="0.707107 0 0 -0.707107" material="thigh" mesh="thigh"/>
          <geom name="//unnamed_geom_46" class="collision" size="0.065375 0.0402308" pos="0.0350813 0 0" quat="0.5 0.5 -0.5 -0.5"/>
          <geom name="//unnamed_geom_47" class="collision" size="0.0377163 0.0301731 0.142129" pos="0.026311 0 -0.140119" quat="0.707107 0 0 -0.707107" type="box"/>
          <geom name="//unnamed_geom_48" class="visual" pos="0.0879664 0 -0.28259" quat="1 0 0 0" material="drive" mesh="drive"/>
          <geom name="//unnamed_geom_49" class="collision" size="0.0502884 0.0704038" pos="0.0265741 0 -0.28259" quat="0.707107 0 0.707107 0"/>
          <geom name="//unnamed_geom_50" class="reward_collision_sphere" size="0.0804615" pos="0.0219258 0 0"/>
          <body name="LF_SHANK" pos="0.0908434 0.00466782 -0.284678" quat="1 0.000131413 -0.000358848 0.000246908">
            <inertial pos="0.00794713 -0.0695598 -0.0814095" quat="0.992815 -0.116162 -0.00692944 -0.0278835" mass="0.593191" diaginertia="0.00488195 0.0167366 0.00100984"/>
            <joint name="LF_KFE" pos="0 0 0" axis="0.999963 0.00815125 0.00292385" range="-3.04706 3.16522" armature="0.0101375" damping="0.0218931" frictionloss="0.100736"/>
            <geom name="//unnamed_geom_51" class="visual" pos="-0.00176269 -0.00939874 0" quat="0.707107 0 0 -0.707107" material="shank_l" mesh="shank_l"/>
            <geom name="LF_kfe_act" class="collision" size="0.0603461 0.0201154" pos="0.0175407 0 0" quat="0.5 0.5 -0.5 -0.5"/>
            <geom name="//unnamed_geom_53" class="collision" size="0.0578307 0.0339447 0.0191096" pos="0.0175407 -0.0660509 0" quat="0.5 0.5 -0.5 -0.5" type="box"/>
            <geom name="//unnamed_geom_54" class="visual" pos="0.0114457 -0.10406 -0.335112" quat="0.382683 0 0 -0.92388" material="foot" mesh="foot"/>
            <geom name="LF_calf" class="collision" size="0.017601 0.142067" pos="0.0114453 -0.101031 -0.167556" quat="0.707107 0 0 -0.707107"/>
            <geom name="LF_foot" class="foot" size="0.0205429" pos="0.0114453 -0.101031 -0.312802" quat="0.707107 0 0 -0.707107"/>
            <geom name="//unnamed_geom_57" class="reward_collision_sphere" size="0.100577" pos="-0.0438517 0 0"/>
            <geom name="//unnamed_geom_58" class="reward_collision_sphere" size="0.0502884" pos="0.0114453 -0.101031 -0.312802"/>
            <site name="LF_foot" class="foot" pos="0.0114453 -0.101031 -0.312802" quat="0.707107 0 0 -0.707107" size="0.0100577"/>
          </body>
        </body>
      </body>
      <body name="RF_HIP" pos="0.266146 -0.11915 0.00489466" quat="0.258586 -0.965987 -0.00101307 -0.000790842">
        <inertial pos="0.0499016 0.021665 -0.0074504" quat="0.150235 0.68271 0.126612 0.703779" mass="2.86796" diaginertia="0.00314137 0.0099088 0.00321353"/>
        <joint name="RF_HAA" pos="0 0 0" axis="1 4.23484e-05 0.000756858" range="-0.458263 0.720259" armature="0.0110012" damping="0.0205287" frictionloss="0.118342"/>
        <geom name="//unnamed_geom_59" class="visual" pos="0 -0.000159505 -2.61988e-05" quat="0.258819 0.965926 0 0" material="hip_r" mesh="hip_r"/>
        <geom name="//unnamed_geom_60" class="visual" pos="0.0525343 0.0671779 -0.0376225" quat="0.183013 0.683013 0.683013 -0.183013" material="drive" mesh="drive"/>
        <geom name="//unnamed_geom_61" class="collision" size="0.0502884 0.0704038" pos="0.0525343 0.0137386 -0.0068466" quat="-0.353553 0.612372 0.612372 0.353553"/>
        <body name="RF_THIGH" pos="0.0520313 0.0895174 -0.0424206" quat="0.182444 0.682858 0.683369 -0.182826">
          <inertial pos="0.0267945 0.00248384 -0.245308" quat="0.992155 -0.00648856 -0.0814133 0.0946506" mass="3.0725" diaginertia="0.0152481 0.0581534 0.00382475"/>
          <joint name="RF_HFE" pos="0 0 0" axis="0.999991 0.00304372 -0.00300581" stiffness="0.00466507" range="-3.19163 3.08065" armature="0.00998932" damping="0.00127685" frictionloss="0.10466"/>
          <geom name="//unnamed_geom_62" class="visual" pos="-0.00540572 -8.51815e-06 0" quat="0.707107 0 0 -0.707107" material="thigh" mesh="thigh"/>
          <geom name="//unnamed_geom_63" class="collision" size="0.065375 0.0402308" pos="0.0350813 0 0" quat="0.5 0.5 0.5 0.5"/>
          <geom name="//unnamed_geom_64" class="collision" size="0.0377163 0.0301731 0.142129" pos="0.026311 0 -0.140119" quat="0.707107 0 0 0.707107" type="box"/>
          <geom name="//unnamed_geom_65" class="visual" pos="0.0879664 0 -0.28259" quat="1 0 0 0" material="drive" mesh="drive"/>
          <geom name="//unnamed_geom_66" class="collision" size="0.0502884 0.0704038" pos="0.0265741 0 -0.28259" quat="0.707107 0 0.707107 0"/>
          <geom name="//unnamed_geom_67" class="reward_collision_sphere" size="0.0804615" pos="0.0219258 0 0"/>
          <body name="RF_SHANK" pos="0.0889172 0.00294897 -0.284547" quat="1 -1.69258e-05 -5.75871e-05 7.74903e-06">
            <inertial pos="0.0057615 0.0717992 -0.0798322" quat="0.99306 0.11749 -0.00285932 0.00445475" mass="0.593173" diaginertia="0.00530642 0.0186022 0.00110353"/>
            <joint name="RF_KFE" pos="0 0 0" axis="0.999658 0.00902574 -0.0245473" stiffness="0.0167423" range="-3.08657 3.10322" armature="0.00913484" damping="0" frictionloss="0.094667"/>
            <geom name="//unnamed_geom_68" class="visual" pos="-0.00176268 0.00939872 0" quat="0.707107 0 0 0.707107" material="shank" mesh="shank_r"/>
            <geom name="RF_kfe_act" class="collision" size="0.0603461 0.0201154" pos="0.0175407 0 0" quat="0.5 0.5 0.5 0.5"/>
            <geom name="//unnamed_geom_70" class="collision" size="0.0578307 0.0339447 0.0191096" pos="0.0175407 0.0660509 0" quat="0.5 0.5 0.5 0.5" type="box"/>
            <geom name="//unnamed_geom_71" class="visual" pos="0.0114449 0.10406 -0.335112" quat="0.382683 0 0 0.92388" material="foot" mesh="foot"/>
            <geom name="RF_calf" class="collision" size="0.017601 0.142067" pos="0.0114453 0.101031 -0.167556" quat="0.707107 0 0 0.707107"/>
            <geom name="RF_foot" class="foot" size="0.0268857" pos="0.0114453 0.101031 -0.312802" quat="0.707107 0 0 0.707107"/>
            <geom name="//unnamed_geom_74" class="reward_collision_sphere" size="0.100577" pos="-0.0438517 0 0"/>
            <geom name="//unnamed_geom_75" class="reward_collision_sphere" size="0.0502884" pos="0.0114453 0.101031 -0.312802"/>
            <site name="RF_foot" class="foot" pos="0.0114453 0.101031 -0.312802" quat="0.707107 0 0 0.707107" size="0.0100577"/>
          </body>
        </body>
      </body>
      <body name="LH_HIP" pos="-0.26147 0.119651 0.00208444" quat="5.43197e-06 -2.18699e-05 0.965934 -0.258787">
        <inertial pos="0.0511955 0.0122427 -0.00606619" quat="0.163249 0.673308 0.143212 0.706751" mass="2.72986" diaginertia="0.00320486 0.0100873 0.00306585"/>
        <joint name="LH_HAA" pos="0 0 0" axis="0.999996 -0.00244757 -0.00141575" range="-0.542494 0.73387" armature="0.0115016" damping="0" frictionloss="0.0795277"/>
        <geom name="//unnamed_geom_76" class="visual" pos="0 -0.000159505 -2.61988e-05" quat="-0.258819 -0.965926 0 0" material="hip_r" mesh="hip_r"/>
        <geom name="//unnamed_geom_77" class="visual" pos="0.0525343 0.0671779 -0.0376225" quat="0.183013 0.683013 0.683013 -0.183013" material="drive" mesh="drive"/>
        <geom name="//unnamed_geom_78" class="collision" size="0.0502884 0.0704038" pos="0.0525343 0.0137386 -0.0068466" quat="-0.353553 0.612372 0.612372 0.353553"/>
        <body name="LH_THIGH" pos="0.0510291 0.087386 -0.0456159" quat="0.182105 0.682516 0.68392 -0.182382">
          <inertial pos="0.0272633 0.000389269 -0.241041" quat="0.993221 -0.00875745 -0.0737982 0.0893812" mass="2.99268" diaginertia="0.0163169 0.0632561 0.00405245"/>
          <joint name="LH_HFE" pos="0 0 0" axis="0.99999 -0.00139623 0.00414455" range="-3.11806 3.17178" armature="0.00892723" damping="0.00707334" frictionloss="0.1026"/>
          <geom name="//unnamed_geom_79" class="visual" pos="-0.00540572 -8.51815e-06 0" quat="0.707107 0 0 -0.707107" material="thigh" mesh="thigh"/>
          <geom name="//unnamed_geom_80" class="collision" size="0.065375 0.0402308" pos="0.0350813 0 0" quat="0.5 0.5 -0.5 -0.5"/>
          <geom name="//unnamed_geom_81" class="collision" size="0.0377163 0.0301731 0.142129" pos="0.026311 0 -0.140119" quat="0.707107 0 0 -0.707107" type="box"/>
          <geom name="//unnamed_geom_82" class="visual" pos="0.0879664 0 -0.28259" quat="1 0 0 0" material="drive" mesh="drive"/>
          <geom name="//unnamed_geom_83" class="collision" size="0.0502884 0.0704038" pos="0.0265741 0 -0.28259" quat="0.707107 0 0.707107 0"/>
          <geom name="//unnamed_geom_84" class="reward_collision_sphere" size="0.0804615" pos="0.0219258 0 0"/>
          <body name="LH_SHANK" pos="0.0880229 -0.000796811 -0.277921" quat="1 -0.000712431 -0.000331809 -0.000504967">
            <inertial pos="0.00317027 0.0645812 -0.0784958" quat="0.992933 0.115911 -0.00105664 0.0254427" mass="0.613189" diaginertia="0.00540008 0.0191869 0.00117688"/>
            <joint name="LH_KFE" pos="0 0 0" axis="0.999943 0.00673143 -0.00834008" stiffness="0.0297636" range="-3.1329 3.1549" armature="0.00991033" damping="0.0129962" frictionloss="0.0729911"/>
            <geom name="//unnamed_geom_85" class="visual" pos="-0.00176268 0.00939872 0" quat="-0.707107 0 0 -0.707107" material="shank" mesh="shank_r"/>
            <geom name="LH_kfe_act" class="collision" size="0.0603461 0.0201154" pos="0.0175407 0 0" quat="0.5 0.5 -0.5 -0.5"/>
            <geom name="//unnamed_geom_87" class="collision" size="0.0578307 0.0339447 0.0191096" pos="0.0175407 0.0660509 0" quat="0.5 0.5 -0.5 -0.5" type="box"/>
            <geom name="//unnamed_geom_88" class="visual" pos="0.0114449 0.10406 -0.335112" quat="-0.382683 0 0 -0.92388" material="foot" mesh="foot"/>
            <geom name="LH_calf" class="collision" size="0.017601 0.142067" pos="0.0114453 0.101031 -0.167556" quat="0.707107 0 0 -0.707107"/>
            <geom name="LH_foot" class="foot" size="0.0310362" pos="0.0114453 0.101031 -0.312802" quat="0.707107 0 0 -0.707107"/>
            <geom name="//unnamed_geom_91" class="reward_collision_sphere" size="0.100577" pos="-0.0438517 0 0"/>
            <geom name="//unnamed_geom_92" class="reward_collision_sphere" size="0.0502884" pos="0.0114453 0.101031 -0.312802"/>
            <site name="LH_foot" class="foot" pos="0.0114453 0.101031 -0.312802" quat="0.707107 0 0 -0.707107" size="0.0100577"/>
          </body>
        </body>
      </body>
      <body name="RH_HIP" pos="-0.26141 -0.119036 0.00193745" quat="-0.000337832 -0.00201806 -0.965499 -0.260397">
        <inertial pos="0.0441253 -0.0198006 -0.00279275" quat="-0.12755 0.712092 -0.142623 0.67551" mass="2.8122" diaginertia="0.00300985 0.00966348 0.00305241"/>
        <joint name="RH_HAA" pos="0 0 0" axis="0.999566 -0.00806559 -0.0283292" range="-0.690585 0.543269" armature="0.00977584" damping="0.00403919" frictionloss="0.112849"/>
        <geom name="//unnamed_geom_93" class="visual" pos="0 0.000159507 -2.61988e-05" quat="-0.258819 0.965926 0 0" material="hip_l" mesh="hip_l"/>
        <geom name="//unnamed_geom_94" class="visual" pos="0.0525343 -0.0671779 -0.0376225" quat="-0.183013 0.683013 -0.683013 -0.183013" material="drive" mesh="drive"/>
        <geom name="//unnamed_geom_95" class="collision" size="0.0502884 0.0704038" pos="0.0525343 -0.0137386 -0.0068466" quat="0.353553 0.612372 -0.612372 0.353553"/>
        <body name="RH_THIGH" pos="0.0502938 -0.0799755 -0.0361066" quat="-0.182962 0.682978 -0.683089 -0.182908">
          <inertial pos="0.0251763 -0.000890565 -0.243878" quat="0.993226 -0.00392234 -0.0795332 0.0846274" mass="3.27842" diaginertia="0.0152774 0.0590841 0.00398504"/>
          <joint name="RH_HFE" pos="0 0 0" axis="0.999936 -0.00568062 0.00978775" range="-3.14309 3.06735" armature="0.00899528" damping="0.00737796" frictionloss="0.112838"/>
          <geom name="//unnamed_geom_96" class="visual" pos="-0.00540572 -8.51815e-06 0" quat="0.707107 0 0 -0.707107" material="thigh" mesh="thigh"/>
          <geom name="//unnamed_geom_97" class="collision" size="0.065375 0.0402308" pos="0.0350813 0 0" quat="0.5 0.5 0.5 0.5"/>
          <geom name="//unnamed_geom_98" class="collision" size="0.0377163 0.0301731 0.142129" pos="0.026311 0 -0.140119" quat="0.707107 0 0 0.707107" type="box"/>
          <geom name="//unnamed_geom_99" class="visual" pos="0.0879664 0 -0.28259" quat="1 0 0 0" material="drive" mesh="drive"/>
          <geom name="//unnamed_geom_100" class="collision" size="0.0502884 0.0704038" pos="0.0265741 0 -0.28259" quat="0.707107 0 0.707107 0"/>
          <geom name="//unnamed_geom_101" class="reward_collision_sphere" size="0.0804615" pos="0.0219258 0 0"/>
          <body name="RH_SHANK" pos="0.0870671 0.00310607 -0.281469" quat="1 7.60883e-05 0.000121403 -8.93217e-05">
            <inertial pos="0.00687101 -0.067745 -0.0804925" quat="0.992959 -0.11555 -0.00111969 -0.0260758" mass="0.591903" diaginertia="0.00541433 0.0187344 0.0010401"/>
            <joint name="RH_KFE" pos="0 0 0" axis="0.999787 -0.000497023 0.0206381" range="-3.15824 3.1429" armature="0.00902597" damping="0" frictionloss="0.0895569"/>
            <geom name="//unnamed_geom_102" class="visual" pos="-0.00176269 -0.00939874 0" quat="0.707107 0 0 -0.707107" material="shank_l" mesh="shank_l"/>
            <geom name="RH_kfe_act" class="collision" size="0.0603461 0.0201154" pos="0.0175407 0 0" quat="0.5 0.5 0.5 0.5"/>
            <geom name="//unnamed_geom_104" class="collision" size="0.0578307 0.0339447 0.0191096" pos="0.0175407 -0.0660509 0" quat="0.5 0.5 0.5 0.5" type="box"/>
            <geom name="//unnamed_geom_105" class="visual" pos="0.0114457 -0.10406 -0.335112" quat="0.382683 0 0 -0.92388" material="foot" mesh="foot"/>
            <geom name="RH_calf" class="collision" size="0.017601 0.142067" pos="0.0114453 -0.101031 -0.167556" quat="0.707107 0 0 0.707107"/>
            <geom name="RH_foot" class="foot" size="0.0345512" pos="0.0114453 -0.101031 -0.312802" quat="0.707107 0 0 0.707107"/>
            <geom name="//unnamed_geom_108" class="reward_collision_sphere" size="0.100577" pos="-0.0438517 0 0"/>
            <geom name="//unnamed_geom_109" class="reward_collision_sphere" size="0.0502884" pos="0.0114453 -0.101031 -0.312802"/>
            <site name="RH_foot" class="foot" pos="0.0114453 -0.101031 -0.312802" quat="0.707107 0 0 0.707107" size="0.0100577"/>
          </body>
        </body>
      </body>
    </body>
  </worldbody>

  <contact>
    <pair class="/" geom1="floor" geom2="LF_foot" name="//unnamed_contact_0"/>
    <pair class="/" geom1="floor" geom2="RF_foot" name="//unnamed_contact_1"/>
    <pair class="/" geom1="floor" geom2="LH_foot" name="//unnamed_contact_2"/>
    <pair class="/" geom1="floor" geom2="RH_foot" name="//unnamed_contact_3"/>
  </contact>

  <actuator>
    <general name="LF_HAA" class="/" joint="LF_HAA" forcerange="-80.1686 80.1686" gainprm="80.2836" biasprm="0 -80.2836 -2.19183"/>
    <general name="LF_HFE" class="/" joint="LF_HFE" forcerange="-80.5325 80.5325" gainprm="80.2836" biasprm="0 -80.2836 -2.19183"/>
    <general name="LF_KFE" class="/" joint="LF_KFE" forcerange="-75.2968 75.2968" gainprm="80.2836" biasprm="0 -80.2836 -2.19183"/>
    <general name="RF_HAA" class="/" joint="RF_HAA" forcerange="-81.1944 81.1944" gainprm="80.2836" biasprm="0 -80.2836 -2.19183"/>
    <general name="RF_HFE" class="/" joint="RF_HFE" forcerange="-81.398 81.398" gainprm="80.2836" biasprm="0 -80.2836 -2.19183"/>
    <general name="RF_KFE" class="/" joint="RF_KFE" forcerange="-82.9308 82.9308" gainprm="80.2836" biasprm="0 -80.2836 -2.19183"/>
    <general name="LH_HAA" class="/" joint="LH_HAA" forcerange="-64.7364 64.7364" gainprm="80.2836" biasprm="0 -80.2836 -2.19183"/>
    <general name="LH_HFE" class="/" joint="LH_HFE" forcerange="-79.9447 79.9447" gainprm="80.2836" biasprm="0 -80.2836 -2.19183"/>
    <general name="LH_KFE" class="/" joint="LH_KFE" forcerange="-96.1643 96.1643" gainprm="80.2836" biasprm="0 -80.2836 -2.19183"/>
    <general name="RH_HAA" class="/" joint="RH_HAA" forcerange="-84.9251 84.9251" gainprm="80.2836" biasprm="0 -80.2836 -2.19183"/>
    <general name="RH_HFE" class="/" joint="RH_HFE" forcerange="-66.0525 66.0525" gainprm="80.2836" biasprm="0 -80.2836 -2.19183"/>
    <general name="RH_KFE" class="/" joint="RH_KFE" forcerange="-87.8397 87.8397" gainprm="80.2836" biasprm="0 -80.2836 -2.19183"/>
  </actuator>

  <sensor>
    <gyro site="imu" name="imu_angular_velocity"/>
    <velocimeter site="imu" name="imu_linear_velocity"/>
    <framelinvel objtype="site" objname="LF_foot" name="LF_foot_global_linear_velocity"/>
    <framelinvel objtype="site" objname="RF_foot" name="RF_foot_global_linear_velocity"/>
    <framelinvel objtype="site" objname="LH_foot" name="LH_foot_global_linear_velocity"/>
    <framelinvel objtype="site" objname="RH_foot" name="RH_foot_global_linear_velocity"/>
  </sensor>

  <keyframe>
    <key name="home" qpos="0 0 0.55 1 0 0 0 0 0.4 -0.8 0 -0.4 0.8 0 -0.4 0.8 0 0.4 -0.8"/>
  </keyframe>
</mujoco>
