<mujoco model="anymal_c">
  <compiler angle="radian" assetdir="assets" balanceinertia="true" inertiafromgeom="false"/>

  <option timestep="0.005" density="1.2" viscosity="2e-05"/>

  <size nkey="1"/>

  <visual>
    <quality shadowsize="8192"/>
    <map shadowclip="0.5"/>
  </visual>

  <default>
    <default class="/">
      <material specular="0" shininess="0.25"/>
      <geom contype="0" conaffinity="0" group="1" solref="-1000 -80"/>
      <site size="0.01 0.005 0.005" group="5"/>
      <general forcelimited="true" forcerange="-80 80" biastype="affine" gainprm="80" biasprm="0 -80 -2"/>
      <default class="anymal_c">
        <joint armature="0.01" damping="0.01" frictionloss="0.1"/>
        <default class="visual">
          <geom type="mesh" group="2"/>
          <default class="visual_zflip"/>
        </default>
        <default class="collision">
          <geom type="cylinder" group="3"/>
          <default class="foot">
            <geom size="0.03 0 0" type="sphere" condim="6" priority="1" friction="0.8 0.02 0.01" solimp="0.015 1 0.03"/>
          </default>
        </default>
      </default>
      <default class="reward_collision_sphere">
        <geom group="5" rgba="1 0 0 1"/>
      </default>
    </default>
  </default>

  <asset>
    <texture type="skybox" colorspace="auto" name="//unnamed_texture_0" builtin="gradient" rgb1="0.95 0.95 0.95" rgb2="0.95 0.95 0.95" width="100" height="600"/>
    <texture type="2d" colorspace="auto" name="texplane" builtin="checker" rgb1="0.345 0.575 0.748" rgb2="0.345 0.575 0.748" markrgb="1 1 1" width="512" height="512"/>
    <texture type="2d" colorspace="linear" name="base" file="base.png"/>
    <texture type="2d" colorspace="linear" name="top_shell" file="top_shell.png"/>
    <texture type="2d" colorspace="linear" name="bottom_shell" file="bottom_shell.png"/>
    <texture type="2d" colorspace="linear" name="remote" file="remote.png"/>
    <texture type="2d" colorspace="linear" name="hatch" file="hatch.png"/>
    <texture type="2d" colorspace="linear" name="handle" file="handle.png"/>
    <texture type="2d" colorspace="linear" name="face" file="face.png"/>
    <texture type="2d" colorspace="linear" name="battery" file="battery.png"/>
    <texture type="2d" colorspace="linear" name="lidar_cage" file="lidar_cage.png"/>
    <texture type="2d" colorspace="linear" name="depth_camera" file="depth_camera.png"/>
    <texture type="2d" colorspace="linear" name="wide_angle_camera" file="wide_angle_camera.png"/>
    <texture type="2d" colorspace="linear" name="lidar" file="lidar.png"/>
    <texture type="2d" colorspace="linear" name="drive" file="drive.png"/>
    <texture type="2d" colorspace="linear" name="hip_l" file="hip_l.png"/>
    <texture type="2d" colorspace="linear" name="shank_l" file="shank_l.png"/>
    <texture type="2d" colorspace="linear" name="foot" file="foot.png"/>
    <texture type="2d" colorspace="linear" name="thigh" file="thigh.png"/>
    <texture type="2d" colorspace="linear" name="shank_r" file="shank_r.png"/>
    <texture type="2d" colorspace="linear" name="hip_r" file="hip_r.png"/>
    <material name="MatPlane" class="/" texture="texplane" texuniform="true" texrepeat="2 2" specular="0.9" shininess="0.5"/>
    <material name="black_plastic" class="/" rgba="0.007 0.007 0.007 1"/>
    <material name="green" class="/" rgba="0.052 0.178 0.033 1"/>
    <material name="red" class="/" rgba="0.178 0.006 0.005 1"/>
    <material name="yellow" class="/" rgba="0.178 0.119 0.006 1"/>
    <material name="lwl" class="/" rgba="0.8 0.8 0.8 1"/>
    <material name="base" class="/" texture="base"/>
    <material name="top_shell" class="/" texture="top_shell"/>
    <material name="bottom_shell" class="/" texture="bottom_shell"/>
    <material name="hip_l" class="/" texture="hip_l"/>
    <material name="thigh" class="/" texture="thigh"/>
    <material name="shank_l" class="/" texture="shank_l"/>
    <material name="foot" class="/" texture="foot"/>
    <material name="hip_r" class="/" texture="hip_r"/>
    <material name="shank" class="/" texture="shank_r"/>
    <material name="hatch" class="/" texture="hatch"/>
    <material name="remote" class="/" texture="remote"/>
    <material name="handle" class="/" texture="handle"/>
    <material name="face" class="/" texture="face"/>
    <material name="depth_camera" class="/" texture="depth_camera"/>
    <material name="wide_angle_camera" class="/" texture="wide_angle_camera"/>
    <material name="battery" class="/" texture="battery"/>
    <material name="lidar_cage" class="/" texture="lidar_cage"/>
    <material name="lidar" class="/" texture="lidar"/>
    <material name="drive" class="/" texture="drive"/>
    <mesh name="base_0" class="/" file="base_0.obj"/>
    <mesh name="base_1" class="/" file="base_1.obj"/>
    <mesh name="base_2" class="/" file="base_2.obj"/>
    <mesh name="base_3" class="/" file="base_3.obj"/>
    <mesh name="base_4" class="/" file="base_4.obj"/>
    <mesh name="base_5" class="/" file="base_5.obj"/>
    <mesh name="top_shell" class="/" file="top_shell.obj"/>
    <mesh name="bottom_shell" class="/" file="bottom_shell.obj"/>
    <mesh name="remote" class="/" file="remote.obj"/>
    <mesh name="handle" class="/" file="handle.obj"/>
    <mesh name="face" class="/" file="face.obj"/>
    <mesh name="wide_angle_camera" class="/" file="wide_angle_camera.obj"/>
    <mesh name="depth_camera" class="/" file="depth_camera.obj"/>
    <mesh name="battery" class="/" file="battery.obj"/>
    <mesh name="lidar_cage" class="/" file="lidar_cage.obj"/>
    <mesh name="lidar" class="/" file="lidar.obj"/>
    <mesh name="drive" class="/" file="drive.obj"/>
    <mesh name="hip_l" class="/" file="hip_l.obj"/>
    <mesh name="thigh" class="/" file="thigh.obj"/>
    <mesh name="shank_l" class="/" file="shank_l.obj"/>
    <mesh name="foot" class="/" file="foot.obj"/>
    <mesh name="hip_r" class="/" file="hip_r.obj"/>
    <mesh name="hatch" class="/" file="hatch.obj"/>
    <mesh name="shank_r" class="/" file="shank_r.obj"/>
  </asset>

  <worldbody>
    <geom name="floor" class="/" size="100 100 0.125" type="plane" group="0" material="MatPlane"/>
    <light name="toplight_shadow" class="/" pos="0 0 5" dir="0.0990148 0.0990148 -0.990148" type="directional" ambient="0.04 0.04 0.04" diffuse="0.55 0.55 0.55" specular="0.12 0.12 0.12"/>
    <light name="toplight_fill" class="/" pos="0 0 5" dir="0.0990148 0.0990148 -0.990148" type="directional" castshadow="false" ambient="0.04 0.04 0.04" diffuse="0.3 0.3 0.3" specular="0.08 0.08 0.08"/>
    <body name="trunk" childclass="anymal_c" pos="-0.00115904 0.000673482 -0.00277885" quat="1 2.6662e-05 -3.09131e-05 -1.02463e-05">
      <inertial pos="0.00294364 0.00242075 0.0439215" quat="0.501316 0.498803 0.503941 0.495904" mass="18.4664" diaginertia="0.520723 0.720339 0.169905"/>
      <joint name="//unnamed_joint_0" type="free" armature="0" damping="0" frictionloss="0"/>
      <geom name="//unnamed_geom_1" class="visual" material="green" mesh="base_0"/>
      <geom name="//unnamed_geom_2" class="visual" material="yellow" mesh="base_1"/>
      <geom name="//unnamed_geom_3" class="visual" material="red" mesh="base_2"/>
      <geom name="//unnamed_geom_4" class="visual" material="black_plastic" mesh="base_3"/>
      <geom name="//unnamed_geom_5" class="visual" material="lwl" mesh="base_4"/>
      <geom name="//unnamed_geom_6" class="visual" material="base" mesh="base_5"/>
      <geom name="trunk_1" class="collision" size="0.2826 0.0682138 0.0877035" type="box"/>
      <geom name="trunk_2" class="collision" size="0.0877035 0.0706501" pos="0.208028 0.0717367 0" quat="0.707107 0 0.707107 0"/>
      <geom name="trunk_3" class="collision" size="0.0877035 0.0706501" pos="-0.208028 0.0717367 0" quat="0.707107 0 0.707107 0"/>
      <geom name="trunk_4" class="collision" size="0.0877035 0.0706501" pos="0.208028 -0.0717367 0" quat="0.707107 0 0.707107 0"/>
      <geom name="trunk_5" class="collision" size="0.0877035 0.0706501" pos="-0.208028 -0.0717367 0" quat="0.707107 0 0.707107 0"/>
      <geom name="//unnamed_geom_12" class="visual" material="top_shell" mesh="top_shell"/>
      <geom name="//unnamed_geom_13" class="visual" material="bottom_shell" mesh="bottom_shell"/>
      <geom name="//unnamed_geom_14" class="visual" material="remote" mesh="remote"/>
      <geom name="//unnamed_geom_15" class="visual" material="handle" mesh="handle"/>
      <geom name="//unnamed_geom_16" class="visual" pos="0.396448 0 0" quat="1 0 0 0" material="face" mesh="face"/>
      <geom name="trunk_6" class="collision" size="0.0535966 0.0682138 0.0877035" pos="0.449053 0 0" type="box"/>
      <geom name="//unnamed_geom_18" class="collision" size="0.0877035 0.0535966" pos="0.449053 0.0717367 0" quat="0.707107 0 0.707107 0"/>
      <geom name="//unnamed_geom_19" class="collision" size="0.0877035 0.0535966" pos="0.449053 -0.0717367 0" quat="0.707107 0 0.707107 0"/>
      <geom name="//unnamed_geom_20" class="visual" pos="0.441544 0 -0.0274036" quat="0.965926 0 0.258819 0" material="depth_camera" mesh="depth_camera"/>
      <geom name="//unnamed_geom_21" class="visual" pos="0.490659 0 0.0141046" material="wide_angle_camera" mesh="wide_angle_camera"/>
      <geom name="//unnamed_geom_22" class="visual_zflip" pos="-0.396448 0 0" quat="0 0 0 1" material="face" mesh="face"/>
      <geom name="trunk_7" class="collision" size="0.0535966 0.0682138 0.0877035" pos="-0.449053 0 0" quat="0 0 0 1" type="box"/>
      <geom name="//unnamed_geom_24" class="collision" size="0.0877035 0.0535966" pos="-0.449053 -0.0717367 0" quat="0 -0.707107 0 0.707107"/>
      <geom name="//unnamed_geom_25" class="collision" size="0.0877035 0.0535966" pos="-0.449053 0.0717367 0" quat="0 -0.707107 0 0.707107"/>
      <geom name="//unnamed_geom_26" class="visual" pos="-0.441544 0 -0.0274036" quat="0 -0.258819 0 0.965926" material="depth_camera" mesh="depth_camera"/>
      <geom name="//unnamed_geom_27" class="visual_zflip" pos="-0.490659 0 0.0141046" quat="0 0 0 1" material="wide_angle_camera" mesh="wide_angle_camera"/>
      <geom name="//unnamed_geom_28" class="visual" material="battery" mesh="battery"/>
      <geom name="//unnamed_geom_29" class="visual" pos="0 0.0792533 0.027479" quat="0.683013 -0.183013 0.183013 0.683013" material="depth_camera" mesh="depth_camera"/>
      <geom name="//unnamed_geom_30" class="visual" pos="0 -0.0792533 0.027479" quat="0.683013 0.183013 0.183013 -0.683013" material="depth_camera" mesh="depth_camera"/>
      <geom name="//unnamed_geom_31" class="visual" pos="-0.348148 0 0.0692511" quat="1 0 0 0" material="lidar_cage" mesh="lidar_cage"/>
      <geom name="trunk_8" class="collision" size="0.0682138 0.058469" pos="-0.348148 0 0.125783"/>
      <geom name="//unnamed_geom_33" class="visual" pos="-0.348148 2.68567e-05 0.13398" quat="0.707107 0 0 -0.707107" material="lidar" mesh="lidar"/>
      <geom name="//unnamed_geom_34" class="visual" pos="0.286839 0.106551 1.42517e-09" quat="0.258819 0.965926 0 0" material="drive" mesh="drive"/>
      <geom name="//unnamed_geom_35" class="visual" pos="0.286839 -0.106551 -1.42517e-09" quat="0.258819 -0.965926 0 0" material="drive" mesh="drive"/>
      <geom name="//unnamed_geom_36" class="visual" pos="-0.286839 0.106551 -1.42517e-09" quat="0 0 0.965926 -0.258819" material="drive" mesh="drive"/>
      <geom name="//unnamed_geom_37" class="visual" pos="-0.286839 -0.106551 1.42517e-09" quat="0 0 -0.965926 -0.258819" material="drive" mesh="drive"/>
      <geom name="//unnamed_geom_38" class="visual" pos="0.110948 0 0.06878" quat="1 0 0 0" material="hatch" mesh="hatch"/>
      <geom name="//unnamed_geom_39" class="reward_collision_sphere" size="0.116938"/>
      <geom name="//unnamed_geom_40" class="reward_collision_sphere" size="0.116938" pos="0.430402 0 0"/>
      <geom name="//unnamed_geom_41" class="reward_collision_sphere" size="0.116938" pos="-0.430402 0 0"/>
      <site name="imu" pos="0.240397 0.0217438 0.0447349" size="0.00974483"/>
      <camera name="track" pos="0 -2.04962 0" quat="0.707107 0.707107 0 0" mode="trackcom"/>
      <camera name="ego_camera" pos="0.430402 0 -0.0376877" quat="-0.5 -0.5 0.5 0.5"/>
      <body name="LF_HIP" pos="0.287037 0.105037 0.00179733" quat="0.257809 0.966195 0.000955001 0.000309959">
        <inertial pos="0.0561359 -0.0172189 -0.00810601" quat="-0.127561 0.709313 -0.135825 0.679819" mass="2.53439" diaginertia="0.00470983 0.0058649 0.00244874"/>
        <joint name="LF_HAA" pos="0 0 0" axis="0.999992 0.00396207 0.00109605" range="-0.735057 0.483788" armature="0.00973235" damping="0.0244609" frictionloss="0.0998135"/>
        <geom name="//unnamed_geom_42" class="visual" pos="0 8.38361e-05 -1.377e-05" quat="0.258819 -0.965926 0 0" material="hip_l" mesh="hip_l"/>
        <geom name="//unnamed_geom_43" class="visual" pos="0.0572913 -0.0702914 -0.0399716" quat="0.183013 -0.683013 0.683013 0.183013" material="drive" mesh="drive"/>
        <geom name="//unnamed_geom_44" class="collision" size="0.0487242 0.0682138" pos="0.0572913 -0.0122565 -0.00650583" quat="-0.353553 -0.612372 0.612372 -0.353553"/>
        <body name="LF_THIGH" pos="0.0604045 -0.0757462 -0.0363916" quat="0.183198 -0.683273 0.682684 0.183084">
          <inertial pos="0.0314962 -0.0022052 -0.231551" quat="0.99321 -0.00428907 -0.0804483 0.0839306" mass="2.80554" diaginertia="0.0244871 0.0327796 0.0029814"/>
          <joint name="LF_HFE" pos="0 0 0" axis="0.999953 -0.00922458 -0.00310006" stiffness="0.00749035" range="-3.09245 3.12814" armature="0.00844648" damping="0.00559344" frictionloss="0.0847386"/>
          <geom name="//unnamed_geom_45" class="visual" pos="-0.00136009 -2.14318e-06 0" quat="0.707107 0 0 -0.707107" material="thigh" mesh="thigh"/>
          <geom name="//unnamed_geom_46" class="collision" size="0.0633414 0.0389793" pos="0.038258 0 0" quat="0.5 0.5 -0.5 -0.5"/>
          <geom name="//unnamed_geom_47" class="collision" size="0.0365431 0.0292345 0.137708" pos="0.0286935 0 -0.133145" quat="0.707107 0 0 -0.707107" type="box"/>
          <geom name="//unnamed_geom_48" class="visual" pos="0.0959319 0 -0.268525" quat="1 0 0 0" material="drive" mesh="drive"/>
          <geom name="//unnamed_geom_49" class="collision" size="0.0487242 0.0682138" pos="0.0289804 0 -0.268525" quat="0.707107 0 0.707107 0"/>
          <geom name="//unnamed_geom_50" class="reward_collision_sphere" size="0.0779587" pos="0.0239112 0 0"/>
          <body name="LF_SHANK" pos="0.0965742 -0.000219212 -0.268421" quat="0.999999 -0.000229663 -0.00102375 -0.000635952">
            <inertial pos="0.00411829 -0.0626729 -0.073891" quat="0.992776 -0.114985 -0.0133136 -0.0315816" mass="0.54313" diaginertia="0.00774025 0.0105463 0.000840455"/>
            <joint name="LF_KFE" pos="0 0 0" axis="0.999914 0.00160099 0.0130056" stiffness="0.00820671" range="-3.14092 3.12238" armature="0.0109573" damping="0.00172389" frictionloss="0.110539"/>
            <geom name="//unnamed_geom_51" class="visual" pos="-0.000443495 -0.00236474 0" quat="0.707107 0 0 -0.707107" material="shank_l" mesh="shank_l"/>
            <geom name="LF_kfe_act" class="collision" size="0.058469 0.0194897" pos="0.019129 0 0" quat="0.5 0.5 -0.5 -0.5"/>
            <geom name="//unnamed_geom_53" class="collision" size="0.0560318 0.0328888 0.0185152" pos="0.019129 -0.0589255 0" quat="0.5 0.5 -0.5 -0.5" type="box"/>
            <geom name="//unnamed_geom_54" class="visual" pos="0.0124818 -0.090894 -0.318432" quat="0.382683 0 0 -0.92388" material="foot" mesh="foot"/>
            <geom name="LF_calf" class="collision" size="0.0170535 0.137648" pos="0.0124817 -0.090132 -0.159216" quat="0.707107 0 0 -0.707107"/>
            <geom name="LF_foot" class="foot" size="0.0247914" pos="0.0124817 -0.090132 -0.297233" quat="0.707107 0 0 -0.707107"/>
            <geom name="//unnamed_geom_57" class="reward_collision_sphere" size="0.0974483" pos="-0.0478225 0 0"/>
            <geom name="//unnamed_geom_58" class="reward_collision_sphere" size="0.0487242" pos="0.0124817 -0.090132 -0.297233"/>
            <site name="LF_foot" class="foot" pos="0.0124817 -0.090132 -0.297233" quat="0.707107 0 0 -0.707107" size="0.00974483"/>
          </body>
        </body>
      </body>
      <body name="RF_HIP" pos="0.288255 -0.105673 0.000230092" quat="0.258923 -0.965898 -0.000453563 0.000651344">
        <inertial pos="0.0570516 0.0153909 -0.00830355" quat="0.135775 0.676979 0.132232 0.711182" mass="2.57652" diaginertia="0.0044447 0.00538744 0.00229752"/>
        <joint name="RF_HAA" pos="0 0 0" axis="0.999929 -0.0117926 -0.00160997" range="-0.442752 0.723212" armature="0.0107988" damping="0.0074118" frictionloss="0.0933046"/>
        <geom name="//unnamed_geom_59" class="visual" pos="0 -8.38355e-05 -1.377e-05" quat="0.258819 0.965926 0 0" material="hip_r" mesh="hip_r"/>
        <geom name="//unnamed_geom_60" class="visual" pos="0.0572913 0.0702914 -0.0399716" quat="0.183013 0.683013 0.683013 -0.183013" material="drive" mesh="drive"/>
        <geom name="//unnamed_geom_61" class="collision" size="0.0487242 0.0682138" pos="0.0572913 0.0122565 -0.00650583" quat="-0.353553 0.612372 0.612372 0.353553"/>
        <body name="RF_THIGH" pos="0.0578025 0.075394 -0.0396035" quat="0.183278 0.683455 0.682647 -0.182459">
          <inertial pos="0.03219 -0.00156311 -0.230867" quat="0.992913 0.00163264 -0.0733158 0.0935225" mass="2.82449" diaginertia="0.0234783 0.0315899 0.00303683"/>
          <joint name="RF_HFE" pos="0 0 0" axis="0.999919 0.00412715 -0.0120191" range="-3.15298 3.16442" armature="0.00979385" damping="0.00467512" frictionloss="0.111071"/>
          <geom name="//unnamed_geom_62" class="visual" pos="-0.00136009 -2.14318e-06 0" quat="0.707107 0 0 -0.707107" material="thigh" mesh="thigh"/>
          <geom name="//unnamed_geom_63" class="collision" size="0.0633414 0.0389793" pos="0.038258 0 0" quat="0.5 0.5 0.5 0.5"/>
          <geom name="//unnamed_geom_64" class="collision" size="0.0365431 0.0292345 0.137708" pos="0.0286935 0 -0.133145" quat="0.707107 0 0 0.707107" type="box"/>
          <geom name="//unnamed_geom_65" class="visual" pos="0.0959319 0 -0.268525" quat="1 0 0 0" material="drive" mesh="drive"/>
          <geom name="//unnamed_geom_66" class="collision" size="0.0487242 0.0682138" pos="0.0289804 0 -0.268525" quat="0.707107 0 0.707107 0"/>
          <geom name="//unnamed_geom_67" class="reward_collision_sphere" size="0.0779587" pos="0.0239112 0 0"/>
          <body name="RF_SHANK" pos="0.0933553 -0.00117712 -0.271315" quat="1 6.26277e-05 -8.2594e-05 3.85632e-05">
            <inertial pos="0.00538028 0.0620035 -0.0764536" quat="0.992932 0.115533 -0.00134613 0.0271493" mass="0.549319" diaginertia="0.00808985 0.0104163 0.000809579"/>
            <joint name="RF_KFE" pos="0 0 0" axis="0.999993 0.00326946 0.00194002" range="-3.14019 3.17685" armature="0.0085118" damping="0.0160806" frictionloss="0.0839673"/>
            <geom name="//unnamed_geom_68" class="visual" pos="-0.000443492 0.00236473 0" quat="0.707107 0 0 0.707107" material="shank" mesh="shank_r"/>
            <geom name="RF_kfe_act" class="collision" size="0.058469 0.0194897" pos="0.019129 0 0" quat="0.5 0.5 0.5 0.5"/>
            <geom name="//unnamed_geom_70" class="collision" size="0.0560318 0.0328888 0.0185152" pos="0.019129 0.0589255 0" quat="0.5 0.5 0.5 0.5" type="box"/>
            <geom name="//unnamed_geom_71" class="visual" pos="0.0124816 0.090894 -0.318432" quat="0.382683 0 0 0.92388" material="foot" mesh="foot"/>
            <geom name="RF_calf" class="collision" size="0.0170535 0.137648" pos="0.0124817 0.090132 -0.159216" quat="0.707107 0 0 0.707107"/>
            <geom name="RF_foot" class="foot" size="0.0242824" pos="0.0124817 0.090132 -0.297233" quat="0.707107 0 0 0.707107"/>
            <geom name="//unnamed_geom_74" class="reward_collision_sphere" size="0.0974483" pos="-0.0478225 0 0"/>
            <geom name="//unnamed_geom_75" class="reward_collision_sphere" size="0.0487242" pos="0.0124817 0.090132 -0.297233"/>
            <site name="RF_foot" class="foot" pos="0.0124817 0.090132 -0.297233" quat="0.707107 0 0 0.707107" size="0.00974483"/>
          </body>
        </body>
      </body>
      <body name="LH_HIP" pos="-0.286015 0.106815 -0.00122139" quat="0.000672468 0.00033151 0.965978 -0.258621">
        <inertial pos="0.0570737 0.0151115 -0.00958802" quat="0.137091 0.680675 0.121251 0.709356" mass="2.61424" diaginertia="0.00475795 0.00573666 0.00249541"/>
        <joint name="LH_HAA" pos="0 0 0" axis="0.99999 0.00299365 -0.00341892" stiffness="0.00731268" range="-0.506705 0.673481" armature="0.00924866" damping="0" frictionloss="0.0993316"/>
        <geom name="//unnamed_geom_76" class="visual" pos="0 -8.38355e-05 -1.377e-05" quat="-0.258819 -0.965926 0 0" material="hip_r" mesh="hip_r"/>
        <geom name="//unnamed_geom_77" class="visual" pos="0.0572913 0.0702914 -0.0399716" quat="0.183013 0.683013 0.683013 -0.183013" material="drive" mesh="drive"/>
        <geom name="//unnamed_geom_78" class="collision" size="0.0487242 0.0682138" pos="0.0572913 0.0122565 -0.00650583" quat="-0.353553 0.612372 0.612372 0.353553"/>
        <body name="LH_THIGH" pos="0.0561492 0.0738516 -0.0394784" quat="0.183361 0.683002 0.682809 -0.183464">
          <inertial pos="0.0293873 -0.00053496 -0.230266" quat="0.9934 -0.0125427 -0.0831606 0.0779977" mass="2.89917" diaginertia="0.0245626 0.0351059 0.00327831"/>
          <joint name="LH_HFE" pos="0 0 0" axis="0.99995 0.00266919 0.00960438" stiffness="0.0047417" range="-3.16002 3.12574" armature="0.0104651" damping="0" frictionloss="0.0962317"/>
          <geom name="//unnamed_geom_79" class="visual" pos="-0.00136009 -2.14318e-06 0" quat="0.707107 0 0 -0.707107" material="thigh" mesh="thigh"/>
          <geom name="//unnamed_geom_80" class="collision" size="0.0633414 0.0389793" pos="0.038258 0 0" quat="0.5 0.5 -0.5 -0.5"/>
          <geom name="//unnamed_geom_81" class="collision" size="0.0365431 0.0292345 0.137708" pos="0.0286935 0 -0.133145" quat="0.707107 0 0 -0.707107" type="box"/>
          <geom name="//unnamed_geom_82" class="visual" pos="0.0959319 0 -0.268525" quat="1 0 0 0" material="drive" mesh="drive"/>
          <geom name="//unnamed_geom_83" class="collision" size="0.0487242 0.0682138" pos="0.0289804 0 -0.268525" quat="0.707107 0 0.707107 0"/>
          <geom name="//unnamed_geom_84" class="reward_collision_sphere" size="0.0779587" pos="0.0239112 0 0"/>
          <body name="LH_SHANK" pos="0.0958364 -0.00228808 -0.268371" quat="1 -0.000396873 -6.26666e-05 -0.000135761">
            <inertial pos="0.00256986 0.0618825 -0.0766962" quat="0.992855 0.118645 -0.00272507 0.0124055" mass="0.561114" diaginertia="0.00811871 0.010662 0.000867786"/>
            <joint name="LH_KFE" pos="0 0 0" axis="0.999999 0.00130844 -0.000120882" stiffness="0.00402434" range="-3.15351 3.19535" armature="0.0109082" damping="0" frictionloss="0.0944845"/>
            <geom name="//unnamed_geom_85" class="visual" pos="-0.000443492 0.00236473 0" quat="-0.707107 0 0 -0.707107" material="shank" mesh="shank_r"/>
            <geom name="LH_kfe_act" class="collision" size="0.058469 0.0194897" pos="0.019129 0 0" quat="0.5 0.5 -0.5 -0.5"/>
            <geom name="//unnamed_geom_87" class="collision" size="0.0560318 0.0328888 0.0185152" pos="0.019129 0.0589255 0" quat="0.5 0.5 -0.5 -0.5" type="box"/>
            <geom name="//unnamed_geom_88" class="visual" pos="0.0124816 0.090894 -0.318432" quat="-0.382683 0 0 -0.92388" material="foot" mesh="foot"/>
            <geom name="LH_calf" class="collision" size="0.0170535 0.137648" pos="0.0124817 0.090132 -0.159216" quat="0.707107 0 0 -0.707107"/>
            <geom name="LH_foot" class="foot" size="0.0288053" pos="0.0124817 0.090132 -0.297233" quat="0.707107 0 0 -0.707107"/>
            <geom name="//unnamed_geom_91" class="reward_collision_sphere" size="0.0974483" pos="-0.0478225 0 0"/>
            <geom name="//unnamed_geom_92" class="reward_collision_sphere" size="0.0487242" pos="0.0124817 0.090132 -0.297233"/>
            <site name="LH_foot" class="foot" pos="0.0124817 0.090132 -0.297233" quat="0.707107 0 0 -0.707107" size="0.00974483"/>
          </body>
        </body>
      </body>
      <body name="RH_HIP" pos="-0.28434 -0.108994 0.000809727" quat="-0.000112839 -0.000107344 -0.965884 -0.258976">
        <inertial pos="0.0535203 -0.0140377 -0.00731997" quat="-0.123035 0.710806 -0.126911 0.680816" mass="2.58133" diaginertia="0.00476326 0.00566269 0.00247048"/>
        <joint name="RH_HAA" pos="0 0 0" axis="0.99999 -0.00232704 0.00380326" stiffness="0.00677474" range="-0.671607 0.510913" armature="0.00828035" damping="0.0098291" frictionloss="0.103497"/>
        <geom name="//unnamed_geom_93" class="visual" pos="0 8.38361e-05 -1.377e-05" quat="-0.258819 0.965926 0 0" material="hip_l" mesh="hip_l"/>
        <geom name="//unnamed_geom_94" class="visual" pos="0.0572913 -0.0702914 -0.0399716" quat="-0.183013 0.683013 -0.683013 -0.183013" material="drive" mesh="drive"/>
        <geom name="//unnamed_geom_95" class="collision" size="0.0487242 0.0682138" pos="0.0572913 -0.0122565 -0.00650583" quat="0.353553 0.612372 -0.612372 0.353553"/>
        <body name="RH_THIGH" pos="0.0551919 -0.0742018 -0.038985" quat="-0.182877 0.683103 -0.682934 -0.183103">
          <inertial pos="0.0296778 8.6074e-05 -0.231084" quat="0.992912 -0.00411234 -0.0824231 0.0855242" mass="2.81186" diaginertia="0.0239148 0.0347013 0.00311919"/>
          <joint name="RH_HFE" pos="0 0 0" axis="0.999971 0.00675655 0.00356495" stiffness="0.010013" range="-3.13827 3.15715" armature="0.00985441" damping="0.00302982" frictionloss="0.103757"/>
          <geom name="//unnamed_geom_96" class="visual" pos="-0.00136009 -2.14318e-06 0" quat="0.707107 0 0 -0.707107" material="thigh" mesh="thigh"/>
          <geom name="//unnamed_geom_97" class="collision" size="0.0633414 0.0389793" pos="0.038258 0 0" quat="0.5 0.5 0.5 0.5"/>
          <geom name="//unnamed_geom_98" class="collision" size="0.0365431 0.0292345 0.137708" pos="0.0286935 0 -0.133145" quat="0.707107 0 0 0.707107" type="box"/>
          <geom name="//unnamed_geom_99" class="visual" pos="0.0959319 0 -0.268525" quat="1 0 0 0" material="drive" mesh="drive"/>
          <geom name="//unnamed_geom_100" class="collision" size="0.0487242 0.0682138" pos="0.0289804 0 -0.268525" quat="0.707107 0 0.707107 0"/>
          <geom name="//unnamed_geom_101" class="reward_collision_sphere" size="0.0779587" pos="0.0239112 0 0"/>
          <body name="RH_SHANK" pos="0.0957839 -0.00044515 -0.264674" quat="1 -0.000164053 -0.000237006 0.000103112">
            <inertial pos="0.00350708 -0.0621731 -0.075077" quat="0.991629 -0.127377 0.00347611 -0.0208575" mass="0.54554" diaginertia="0.00835982 0.0102562 0.000837522"/>
            <joint name="RH_KFE" pos="0 0 0" axis="0.999997 -0.00237419 -3.92686e-05" stiffness="0.0021098" range="-3.16544 3.14325" armature="0.00863098" damping="0.011441" frictionloss="0.0869429"/>
            <geom name="//unnamed_geom_102" class="visual" pos="-0.000443495 -0.00236474 0" quat="0.707107 0 0 -0.707107" material="shank_l" mesh="shank_l"/>
            <geom name="RH_kfe_act" class="collision" size="0.058469 0.0194897" pos="0.019129 0 0" quat="0.5 0.5 0.5 0.5"/>
            <geom name="//unnamed_geom_104" class="collision" size="0.0560318 0.0328888 0.0185152" pos="0.019129 -0.0589255 0" quat="0.5 0.5 0.5 0.5" type="box"/>
            <geom name="//unnamed_geom_105" class="visual" pos="0.0124818 -0.090894 -0.318432" quat="0.382683 0 0 -0.92388" material="foot" mesh="foot"/>
            <geom name="RH_calf" class="collision" size="0.0170535 0.137648" pos="0.0124817 -0.090132 -0.159216" quat="0.707107 0 0 0.707107"/>
            <geom name="RH_foot" class="foot" size="0.0291715" pos="0.0124817 -0.090132 -0.297233" quat="0.707107 0 0 0.707107"/>
            <geom name="//unnamed_geom_108" class="reward_collision_sphere" size="0.0974483" pos="-0.0478225 0 0"/>
            <geom name="//unnamed_geom_109" class="reward_collision_sphere" size="0.0487242" pos="0.0124817 -0.090132 -0.297233"/>
            <site name="RH_foot" class="foot" pos="0.0124817 -0.090132 -0.297233" quat="0.707107 0 0 0.707107" size="0.00974483"/>
          </body>
        </body>
      </body>
    </body>
  </worldbody>

  <contact>
    <pair class="/" geom1="floor" geom2="LF_foot" name="//unnamed_contact_0"/>
    <pair class="/" geom1="floor" geom2="RF_foot" name="//unnamed_contact_1"/>
    <pair class="/" geom1="floor" geom2="LH_foot" name="//unnamed_contact_2"/>
    <pair class="/" geom1="floor" geom2="RH_foot" name="//unnamed_contact_3"/>
  </contact>

  <actuator>
    <general name="LF_HAA" class="/" joint="LF_HAA" forcerange="-79.5646 79.5646" gainprm="83.2563" biasprm="0 -83.2563 -1.99236"/>
    <general name="LF_HFE" class="/" joint="LF_HFE" forcerange="-70.0683 70.0683" gainprm="83.2563" biasprm="0 -83.2563 -1.99236"/>
    <general name="LF_KFE" class="/" joint="LF_KFE" forcerange="-78.7337 78.7337" gainprm="83.2563" biasprm="0 -83.2563 -1.99236"/>
    <general name="RF_HAA" class="/" joint="RF_HAA" forcerange="-80.9409 80.9409" gainprm="83.2563" biasprm="0 -83.2563 -1.99236"/>
    <general name="RF_HFE" class="/" joint="RF_HFE" forcerange="-87.6318 87.6318" gainprm="83.2563" biasprm="0 -83.2563 -1.99236"/>
    <general name="RF_KFE" class="/" joint="RF_KFE" forcerange="-77.5355 77.5355" gainprm="83.2563" biasprm="0 -83.2563 -1.99236"/>
    <general name="LH_HAA" class="/" joint="LH_HAA" forcerange="-76.7935 76.7935" gainprm="83.2563" biasprm="0 -83.2563 -1.99236"/>
    <general name="LH_HFE" class="/" joint="LH_HFE" forcerange="-70.684 70.684" gainprm="83.2563" biasprm="0 -83.2563 -1.99236"/>
    <general name="LH_KFE" class="/" joint="LH_KFE" forcerange="-79.0857 79.0857" gainprm="83.2563" biasprm="0 -83.2563 -1.99236"/>
    <general name="RH_HAA" class="/" joint="RH_HAA" forcerange="-72.1872 72.1872" gainprm="83.2563" biasprm="0 -83.2563 -1.99236"/>
    <general name="RH_HFE" class="/" joint="RH_HFE" forcerange="-77.8455 77.8455" gainprm="83.2563" biasprm="0 -83.2563 -1.99236"/>
    <general name="RH_KFE" class="/" joint="RH_KFE" forcerange="-79.7422 79.7422" gainprm="83.2563" biasprm="0 -83.2563 -1.99236"/>
  </actuator>

  <sensor>
    <gyro site="imu" name="imu_angular_velocity"/>
    <velocimeter site="imu" name="imu_linear_velocity"/>
    <framelinvel objtype="site" objname="LF_foot" name="LF_foot_global_linear_velocity"/>
    <framelinvel objtype="site" objname="RF_foot" name="RF_foot_global_linear_velocity"/>
    <framelinvel objtype="site" objname="LH_foot" name="LH_foot_global_linear_velocity"/>
    <framelinvel objtype="site" objname="RH_foot" name="RH_foot_global_linear_velocity"/>
  </sensor>

  <keyframe>
    <key name="home" qpos="0 0 0.55 1 0 0 0 0 0.4 -0.8 0 -0.4 0.8 0 -0.4 0.8 0 0.4 -0.8"/>
  </keyframe>
</mujoco>
