<mujoco model="anymal_c">
  <compiler angle="radian" assetdir="assets" balanceinertia="true" inertiafromgeom="false"/>

  <option timestep="0.005" density="1.2" viscosity="2e-05"/>

  <size nkey="1"/>

  <visual>
    <quality shadowsize="8192"/>
    <map shadowclip="0.5"/>
  </visual>

  <default>
    <default class="/">
      <material specular="0" shininess="0.25"/>
      <geom contype="0" conaffinity="0" group="1" solref="-1000 -80"/>
      <site size="0.01 0.005 0.005" group="5"/>
      <general forcelimited="true" forcerange="-80 80" biastype="affine" gainprm="80" biasprm="0 -80 -2"/>
      <default class="anymal_c">
        <joint armature="0.01" damping="0.01" frictionloss="0.1"/>
        <default class="visual">
          <geom type="mesh" group="2"/>
          <default class="visual_zflip"/>
        </default>
        <default class="collision">
          <geom type="cylinder" group="3"/>
          <default class="foot">
            <geom size="0.03 0 0" type="sphere" condim="6" priority="1" friction="0.8 0.02 0.01" solimp="0.015 1 0.03"/>
          </default>
        </default>
      </default>
      <default class="reward_collision_sphere">
        <geom group="5" rgba="1 0 0 1"/>
      </default>
    </default>
  </default>

  <asset>
    <texture type="skybox" colorspace="auto" name="//unnamed_texture_0" builtin="gradient" rgb1="0.95 0.95 0.95" rgb2="0.95 0.95 0.95" width="100" height="600"/>
    <texture type="2d" colorspace="auto" name="texplane" builtin="checker" rgb1="0.345 0.575 0.748" rgb2="0.345 0.575 0.748" markrgb="1 1 1" width="512" height="512"/>
    <texture type="2d" colorspace="linear" name="base" file="base.png"/>
    <texture type="2d" colorspace="linear" name="top_shell" file="top_shell.png"/>
    <texture type="2d" colorspace="linear" name="bottom_shell" file="bottom_shell.png"/>
    <texture type="2d" colorspace="linear" name="remote" file="remote.png"/>
    <texture type="2d" colorspace="linear" name="hatch" file="hatch.png"/>
    <texture type="2d" colorspace="linear" name="handle" file="handle.png"/>
    <texture type="2d" colorspace="linear" name="face" file="face.png"/>
    <texture type="2d" colorspace="linear" name="battery" file="battery.png"/>
    <texture type="2d" colorspace="linear" name="lidar_cage" file="lidar_cage.png"/>
    <texture type="2d" colorspace="linear" name="depth_camera" file="depth_camera.png"/>
    <texture type="2d" colorspace="linear" name="wide_angle_camera" file="wide_angle_camera.png"/>
    <texture type="2d" colorspace="linear" name="lidar" file="lidar.png"/>
    <texture type="2d" colorspace="linear" name="drive" file="drive.png"/>
    <texture type="2d" colorspace="linear" name="hip_l" file="hip_l.png"/>
    <texture type="2d" colorspace="linear" name="shank_l" file="shank_l.png"/>
    <texture type="2d" colorspace="linear" name="foot" file="foot.png"/>
    <texture type="2d" colorspace="linear" name="thigh" file="thigh.png"/>
    <texture type="2d" colorspace="linear" name="shank_r" file="shank_r.png"/>
    <texture type="2d" colorspace="linear" name="hip_r" file="hip_r.png"/>
    <material name="MatPlane" class="/" texture="texplane" texuniform="true" texrepeat="2 2" specular="0.9" shininess="0.5"/>
    <material name="black_plastic" class="/" rgba="0.007 0.007 0.007 1"/>
    <material name="green" class="/" rgba="0.052 0.178 0.033 1"/>
    <material name="red" class="/" rgba="0.178 0.006 0.005 1"/>
    <material name="yellow" class="/" rgba="0.178 0.119 0.006 1"/>
    <material name="lwl" class="/" rgba="0.8 0.8 0.8 1"/>
    <material name="base" class="/" texture="base"/>
    <material name="top_shell" class="/" texture="top_shell"/>
    <material name="bottom_shell" class="/" texture="bottom_shell"/>
    <material name="hip_l" class="/" texture="hip_l"/>
    <material name="thigh" class="/" texture="thigh"/>
    <material name="shank_l" class="/" texture="shank_l"/>
    <material name="foot" class="/" texture="foot"/>
    <material name="hip_r" class="/" texture="hip_r"/>
    <material name="shank" class="/" texture="shank_r"/>
    <material name="hatch" class="/" texture="hatch"/>
    <material name="remote" class="/" texture="remote"/>
    <material name="handle" class="/" texture="handle"/>
    <material name="face" class="/" texture="face"/>
    <material name="depth_camera" class="/" texture="depth_camera"/>
    <material name="wide_angle_camera" class="/" texture="wide_angle_camera"/>
    <material name="battery" class="/" texture="battery"/>
    <material name="lidar_cage" class="/" texture="lidar_cage"/>
    <material name="lidar" class="/" texture="lidar"/>
    <material name="drive" class="/" texture="drive"/>
    <mesh name="base_0" class="/" file="base_0.obj"/>
    <mesh name="base_1" class="/" file="base_1.obj"/>
    <mesh name="base_2" class="/" file="base_2.obj"/>
    <mesh name="base_3" class="/" file="base_3.obj"/>
    <mesh name="base_4" class="/" file="base_4.obj"/>
    <mesh name="base_5" class="/" file="base_5.obj"/>
    <mesh name="top_shell" class="/" file="top_shell.obj"/>
    <mesh name="bottom_shell" class="/" file="bottom_shell.obj"/>
    <mesh name="remote" class="/" file="remote.obj"/>
    <mesh name="handle" class="/" file="handle.obj"/>
    <mesh name="face" class="/" file="face.obj"/>
    <mesh name="wide_angle_camera" class="/" file="wide_angle_camera.obj"/>
    <mesh name="depth_camera" class="/" file="depth_camera.obj"/>
    <mesh name="battery" class="/" file="battery.obj"/>
    <mesh name="lidar_cage" class="/" file="lidar_cage.obj"/>
    <mesh name="lidar" class="/" file="lidar.obj"/>
    <mesh name="drive" class="/" file="drive.obj"/>
    <mesh name="hip_l" class="/" file="hip_l.obj"/>
    <mesh name="thigh" class="/" file="thigh.obj"/>
    <mesh name="shank_l" class="/" file="shank_l.obj"/>
    <mesh name="foot" class="/" file="foot.obj"/>
    <mesh name="hip_r" class="/" file="hip_r.obj"/>
    <mesh name="hatch" class="/" file="hatch.obj"/>
    <mesh name="shank_r" class="/" file="shank_r.obj"/>
  </asset>

  <worldbody>
    <geom name="floor" class="/" size="100 100 0.125" type="plane" group="0" material="MatPlane"/>
    <light name="toplight_shadow" class="/" pos="0 0 5" dir="0.0990148 0.0990148 -0.990148" type="directional" ambient="0.04 0.04 0.04" diffuse="0.55 0.55 0.55" specular="0.12 0.12 0.12"/>
    <light name="toplight_fill" class="/" pos="0 0 5" dir="0.0990148 0.0990148 -0.990148" type="directional" castshadow="false" ambient="0.04 0.04 0.04" diffuse="0.3 0.3 0.3" specular="0.08 0.08 0.08"/>
    <body name="trunk" childclass="anymal_c" pos="2.17297e-05 1.31051e-05 0.000864011" quat="1 6.35488e-05 2.181e-06 -1.39408e-05">
      <inertial pos="0.00228137 -0.000157393 0.048255" quat="0.500227 0.499887 0.499894 0.499991" mass="18.9687" diaginertia="0.776398 0.477097 0.215078"/>
      <joint name="//unnamed_joint_0" type="free" armature="0" damping="0" frictionloss="0"/>
      <geom name="//unnamed_geom_1" class="visual" material="green" mesh="base_0"/>
      <geom name="//unnamed_geom_2" class="visual" material="yellow" mesh="base_1"/>
      <geom name="//unnamed_geom_3" class="visual" material="red" mesh="base_2"/>
      <geom name="//unnamed_geom_4" class="visual" material="black_plastic" mesh="base_3"/>
      <geom name="//unnamed_geom_5" class="visual" material="lwl" mesh="base_4"/>
      <geom name="//unnamed_geom_6" class="visual" material="base" mesh="base_5"/>
      <geom name="trunk_1" class="collision" size="0.2884 0.0696139 0.0895036" type="box"/>
      <geom name="trunk_2" class="collision" size="0.0895036 0.0721001" pos="0.2261 0.0663109 0" quat="0.707107 0 0.707107 0"/>
      <geom name="trunk_3" class="collision" size="0.0895036 0.0721001" pos="-0.2261 0.0663109 0" quat="0.707107 0 0.707107 0"/>
      <geom name="trunk_4" class="collision" size="0.0895036 0.0721001" pos="0.2261 -0.0663109 0" quat="0.707107 0 0.707107 0"/>
      <geom name="trunk_5" class="collision" size="0.0895036 0.0721001" pos="-0.2261 -0.0663109 0" quat="0.707107 0 0.707107 0"/>
      <geom name="//unnamed_geom_12" class="visual" material="top_shell" mesh="top_shell"/>
      <geom name="//unnamed_geom_13" class="visual" material="bottom_shell" mesh="bottom_shell"/>
      <geom name="//unnamed_geom_14" class="visual" material="remote" mesh="remote"/>
      <geom name="//unnamed_geom_15" class="visual" material="handle" mesh="handle"/>
      <geom name="//unnamed_geom_16" class="visual" pos="0.43089 0 0" quat="1 0 0 0" material="face" mesh="face"/>
      <geom name="trunk_6" class="collision" size="0.0546966 0.0696139 0.0895036" pos="0.488065 0 0" type="box"/>
      <geom name="//unnamed_geom_18" class="collision" size="0.0895036 0.0546966" pos="0.488065 0.0663109 0" quat="0.707107 0 0.707107 0"/>
      <geom name="//unnamed_geom_19" class="collision" size="0.0895036 0.0546966" pos="0.488065 -0.0663109 0" quat="0.707107 0 0.707107 0"/>
      <geom name="//unnamed_geom_20" class="visual" pos="0.479902 0 -0.0287748" quat="0.965926 0 0.258819 0" material="depth_camera" mesh="depth_camera"/>
      <geom name="//unnamed_geom_21" class="visual" pos="0.533285 0 0.0149193" material="wide_angle_camera" mesh="wide_angle_camera"/>
      <geom name="//unnamed_geom_22" class="visual_zflip" pos="-0.43089 0 0" quat="0 0 0 1" material="face" mesh="face"/>
      <geom name="trunk_7" class="collision" size="0.0546966 0.0696139 0.0895036" pos="-0.488065 0 0" quat="0 0 0 1" type="box"/>
      <geom name="//unnamed_geom_24" class="collision" size="0.0895036 0.0546966" pos="-0.488065 -0.0663109 0" quat="0 -0.707107 0 0.707107"/>
      <geom name="//unnamed_geom_25" class="collision" size="0.0895036 0.0546966" pos="-0.488065 0.0663109 0" quat="0 -0.707107 0 0.707107"/>
      <geom name="//unnamed_geom_26" class="visual" pos="-0.479902 0 -0.0287748" quat="0 -0.258819 0 0.965926" material="depth_camera" mesh="depth_camera"/>
      <geom name="//unnamed_geom_27" class="visual_zflip" pos="-0.533285 0 0.0149193" quat="0 0 0 1" material="wide_angle_camera" mesh="wide_angle_camera"/>
      <geom name="//unnamed_geom_28" class="visual" material="battery" mesh="battery"/>
      <geom name="//unnamed_geom_29" class="visual" pos="0 0.0712182 0.0292779" quat="0.683013 -0.183013 0.183013 0.683013" material="depth_camera" mesh="depth_camera"/>
      <geom name="//unnamed_geom_30" class="visual" pos="0 -0.0712182 0.0292779" quat="0.683013 0.183013 0.183013 -0.683013" material="depth_camera" mesh="depth_camera"/>
      <geom name="//unnamed_geom_31" class="visual" pos="-0.378393 0 0.0732511" quat="1 0 0 0" material="lidar_cage" mesh="lidar_cage"/>
      <geom name="trunk_8" class="collision" size="0.0696139 0.059669" pos="-0.378393 0 0.133048"/>
      <geom name="//unnamed_geom_33" class="visual" pos="-0.378393 -3.624e-05 0.141718" quat="0.707107 0 0 -0.707107" material="lidar" mesh="lidar"/>
      <geom name="//unnamed_geom_34" class="visual" pos="0.311758 0.0985365 -8.50693e-10" quat="0.258819 0.965926 0 0" material="drive" mesh="drive"/>
      <geom name="//unnamed_geom_35" class="visual" pos="0.311758 -0.0985365 8.50693e-10" quat="0.258819 -0.965926 0 0" material="drive" mesh="drive"/>
      <geom name="//unnamed_geom_36" class="visual" pos="-0.311758 0.0985365 8.50693e-10" quat="0 0 0.965926 -0.258819" material="drive" mesh="drive"/>
      <geom name="//unnamed_geom_37" class="visual" pos="-0.311758 -0.0985365 -8.50693e-10" quat="0 0 -0.965926 -0.258819" material="drive" mesh="drive"/>
      <geom name="//unnamed_geom_38" class="visual" pos="0.120587 0 0.0727528" quat="1 0 0 0" material="hatch" mesh="hatch"/>
      <geom name="//unnamed_geom_39" class="reward_collision_sphere" size="0.119338"/>
      <geom name="//unnamed_geom_40" class="reward_collision_sphere" size="0.119338" pos="0.467794 0 0"/>
      <geom name="//unnamed_geom_41" class="reward_collision_sphere" size="0.119338" pos="-0.467794 0 0"/>
      <site name="imu" pos="0.259946 0.0110369 0.0467971" size="0.00994484"/>
      <camera name="track" pos="0 -1.8946 0" quat="0.707107 0.707107 0 0" mode="trackcom"/>
      <camera name="ego_camera" pos="0.467794 0 -0.0398645" quat="-0.5 -0.5 0.5 0.5"/>
      <body name="LF_HIP" pos="0.311956 0.0991113 -9.52784e-05" quat="0.258978 0.965883 0.000146329 6.41727e-05">
        <inertial pos="0.0594918 -0.0144052 -0.00761538" quat="-0.127979 0.709765 -0.135288 0.679376" mass="2.70361" diaginertia="0.00706617 0.00375766 0.00318979"/>
        <joint name="LF_HAA" pos="0 0 0" axis="0.999998 3.16833e-05 -0.00174445" range="-0.716956 0.491295" armature="0.00959297" damping="0.00755634" frictionloss="0.102551"/>
        <geom name="//unnamed_geom_42" class="visual" pos="0 -5.00424e-05 8.21943e-06" quat="0.258819 -0.965926 0 0" material="hip_l" mesh="hip_l"/>
        <geom name="//unnamed_geom_43" class="visual" pos="0.0622685 -0.0742546 -0.0432357" quat="0.183013 -0.683013 0.683013 0.183013" material="drive" mesh="drive"/>
        <geom name="//unnamed_geom_44" class="collision" size="0.0497242 0.0696139" pos="0.0622685 -0.0113295 -0.00688161" quat="-0.353553 -0.612372 0.612372 -0.353553"/>
        <body name="LF_THIGH" pos="0.0626417 -0.0691837 -0.0421318" quat="0.183008 -0.683018 0.683006 0.183024">
          <inertial pos="0.0320487 0.000241006 -0.244192" quat="0.993163 -0.00515373 -0.0806746 0.0842122" mass="3.05208" diaginertia="0.036843 0.0226881 0.00412079"/>
          <joint name="LF_HFE" pos="0 0 0" axis="1 -1.38607e-05 5.42012e-05" stiffness="0.00577487" range="-3.12628 3.13546" armature="0.010163" damping="0.0079795" frictionloss="0.0980951"/>
          <geom name="//unnamed_geom_45" class="visual" pos="0.00183528 2.89198e-06 0" quat="0.707107 0 0 -0.707107" material="thigh" mesh="thigh"/>
          <geom name="//unnamed_geom_46" class="collision" size="0.0646415 0.0397794" pos="0.0415817 0 0" quat="0.5 0.5 -0.5 -0.5"/>
          <geom name="//unnamed_geom_47" class="collision" size="0.0372932 0.0298345 0.140535" pos="0.0311862 0 -0.140835" quat="0.707107 0 0 -0.707107" type="box"/>
          <geom name="//unnamed_geom_48" class="visual" pos="0.104266 0 -0.284035" quat="1 0 0 0" material="drive" mesh="drive"/>
          <geom name="//unnamed_geom_49" class="collision" size="0.0497242 0.0696139" pos="0.0314981 0 -0.284035" quat="0.707107 0 0.707107 0"/>
          <geom name="//unnamed_geom_50" class="reward_collision_sphere" size="0.0795587" pos="0.0259885 0 0"/>
          <body name="LF_SHANK" pos="0.10408 -0.00108586 -0.284955" quat="1 1.72481e-05 -2.05704e-05 -1.96282e-05">
            <inertial pos="0.00589349 -0.0579798 -0.0804797" quat="0.992959 -0.115711 -0.00113049 -0.025346" mass="0.583446" diaginertia="0.0123412 0.00709301 0.00110839"/>
            <joint name="LF_KFE" pos="0 0 0" axis="0.999994 0.00351828 0.000396187" range="-3.14301 3.13496" armature="0.00990667" damping="0.005726" frictionloss="0.103719"/>
            <geom name="//unnamed_geom_51" class="visual" pos="0.000598445 0.00319094 0" quat="0.707107 0 0 -0.707107" material="shank_l" mesh="shank_l"/>
            <geom name="LF_kfe_act" class="collision" size="0.059669 0.0198897" pos="0.0207908 0 0" quat="0.5 0.5 -0.5 -0.5"/>
            <geom name="//unnamed_geom_53" class="collision" size="0.0571818 0.0335638 0.0188952" pos="0.0207908 -0.0544687 0" quat="0.5 0.5 -0.5 -0.5" type="box"/>
            <geom name="//unnamed_geom_54" class="visual" pos="0.0135659 -0.0822865 -0.336825" quat="0.382683 0 0 -0.92388" material="foot" mesh="foot"/>
            <geom name="LF_calf" class="collision" size="0.0174035 0.140473" pos="0.013566 -0.0833148 -0.168413" quat="0.707107 0 0 -0.707107"/>
            <geom name="LF_foot" class="foot" size="0.0304566" pos="0.013566 -0.0833148 -0.314402" quat="0.707107 0 0 -0.707107"/>
            <geom name="//unnamed_geom_57" class="reward_collision_sphere" size="0.0994484" pos="-0.0519771 0 0"/>
            <geom name="//unnamed_geom_58" class="reward_collision_sphere" size="0.0497242" pos="0.013566 -0.0833148 -0.314402"/>
            <site name="LF_foot" class="foot" pos="0.013566 -0.0833148 -0.314402" quat="0.707107 0 0 -0.707107" size="0.00994484"/>
          </body>
        </body>
      </body>
      <body name="RF_HIP" pos="0.312356 -0.0983893 0.000642075" quat="0.259081 -0.965856 0.000162768 0.000276957">
        <inertial pos="0.0591709 0.0150262 -0.00855498" quat="0.134634 0.678956 0.127997 0.710288" mass="2.76094" diaginertia="0.00716645 0.00378975 0.00323631"/>
        <joint name="RF_HAA" pos="0 0 0" axis="0.999999 0.000415963 -0.001265" range="-0.508723 0.726548" armature="0.00988633" damping="0.0123936" frictionloss="0.103574"/>
        <geom name="//unnamed_geom_59" class="visual" pos="0 5.0042e-05 8.21941e-06" quat="0.258819 0.965926 0 0" material="hip_r" mesh="hip_r"/>
        <geom name="//unnamed_geom_60" class="visual" pos="0.0622685 0.0742546 -0.0432357" quat="0.183013 0.683013 0.683013 -0.183013" material="drive" mesh="drive"/>
        <geom name="//unnamed_geom_61" class="collision" size="0.0497242 0.0696139" pos="0.0622685 0.0113295 -0.00688161" quat="-0.353553 0.612372 0.612372 0.353553"/>
        <body name="RF_THIGH" pos="0.0629368 0.0682551 -0.0420177" quat="0.183046 0.683051 0.682978 -0.182966">
          <inertial pos="0.0322694 -2.00685e-05 -0.244677" quat="0.992853 -0.0053216 -0.0800573 0.088351" mass="3.05148" diaginertia="0.0369883 0.0229548 0.00415014"/>
          <joint name="RF_HFE" pos="0 0 0" axis="1 0.000509156 -0.000482111" stiffness="0.00560037" range="-3.13347 3.14322" armature="0.0100544" damping="0.0114745" frictionloss="0.0971937"/>
          <geom name="//unnamed_geom_62" class="visual" pos="0.00183528 2.89198e-06 0" quat="0.707107 0 0 -0.707107" material="thigh" mesh="thigh"/>
          <geom name="//unnamed_geom_63" class="collision" size="0.0646415 0.0397794" pos="0.0415817 0 0" quat="0.5 0.5 0.5 0.5"/>
          <geom name="//unnamed_geom_64" class="collision" size="0.0372932 0.0298345 0.140535" pos="0.0311862 0 -0.140835" quat="0.707107 0 0 0.707107" type="box"/>
          <geom name="//unnamed_geom_65" class="visual" pos="0.104266 0 -0.284035" quat="1 0 0 0" material="drive" mesh="drive"/>
          <geom name="//unnamed_geom_66" class="collision" size="0.0497242 0.0696139" pos="0.0314981 0 -0.284035" quat="0.707107 0 0.707107 0"/>
          <geom name="//unnamed_geom_67" class="reward_collision_sphere" size="0.0795587" pos="0.0259885 0 0"/>
          <body name="RF_SHANK" pos="0.103825 0.000613492 -0.28411" quat="1 -3.43236e-05 3.26569e-05 -7.07864e-05">
            <inertial pos="0.00568211 0.0576139 -0.0799289" quat="0.992965 0.115227 -0.0022645 0.0271807" mass="0.573521" diaginertia="0.0122046 0.00701984 0.001096"/>
            <joint name="RF_KFE" pos="0 0 0" axis="0.999983 0.00328979 0.00477297" stiffness="0.000678824" range="-3.12834 3.14915" armature="0.0100404" damping="0.00840282" frictionloss="0.0971292"/>
            <geom name="//unnamed_geom_68" class="visual" pos="0.000598442 -0.00319094 0" quat="0.707107 0 0 0.707107" material="shank" mesh="shank_r"/>
            <geom name="RF_kfe_act" class="collision" size="0.059669 0.0198897" pos="0.0207908 0 0" quat="0.5 0.5 0.5 0.5"/>
            <geom name="//unnamed_geom_70" class="collision" size="0.0571818 0.0335638 0.0188952" pos="0.0207908 0.0544687 0" quat="0.5 0.5 0.5 0.5" type="box"/>
            <geom name="//unnamed_geom_71" class="visual" pos="0.0135662 0.0822865 -0.336825" quat="0.382683 0 0 0.92388" material="foot" mesh="foot"/>
            <geom name="RF_calf" class="collision" size="0.0174035 0.140473" pos="0.013566 0.0833148 -0.168413" quat="0.707107 0 0 0.707107"/>
            <geom name="RF_foot" class="foot" size="0.0298652" pos="0.013566 0.0833148 -0.314402" quat="0.707107 0 0 0.707107"/>
            <geom name="//unnamed_geom_74" class="reward_collision_sphere" size="0.0994484" pos="-0.0519771 0 0"/>
            <geom name="//unnamed_geom_75" class="reward_collision_sphere" size="0.0497242" pos="0.013566 0.0833148 -0.314402"/>
            <site name="RF_foot" class="foot" pos="0.013566 0.0833148 -0.314402" quat="0.707107 0 0 0.707107" size="0.00994484"/>
          </body>
        </body>
      </body>
      <body name="LH_HIP" pos="-0.311587 0.0983425 0.000230358" quat="8.49645e-05 -5.07642e-05 0.965938 -0.258774">
        <inertial pos="0.059444 0.0148242 -0.0081996" quat="0.134396 0.678189 0.131124 0.710496" mass="2.71414" diaginertia="0.00713565 0.00371223 0.00324211"/>
        <joint name="LH_HAA" pos="0 0 0" axis="0.999984 -0.00561945 0.000232876" range="-0.48518 0.728616" armature="0.00998618" damping="0.0131719" frictionloss="0.0969477"/>
        <geom name="//unnamed_geom_76" class="visual" pos="0 5.0042e-05 8.21941e-06" quat="-0.258819 -0.965926 0 0" material="hip_r" mesh="hip_r"/>
        <geom name="//unnamed_geom_77" class="visual" pos="0.0622685 0.0742546 -0.0432357" quat="0.183013 0.683013 0.683013 -0.183013" material="drive" mesh="drive"/>
        <geom name="//unnamed_geom_78" class="collision" size="0.0497242 0.0696139" pos="0.0622685 0.0113295 -0.00688161" quat="-0.353553 0.612372 0.612372 0.353553"/>
        <body name="LH_THIGH" pos="0.0615825 0.069857 -0.0421505" quat="0.182834 0.682954 0.683111 -0.183043">
          <inertial pos="0.0317901 0.000785095 -0.244667" quat="0.992749 -0.00491971 -0.0808963 0.0887746" mass="3.04037" diaginertia="0.0365406 0.02294 0.00408479"/>
          <joint name="LH_HFE" pos="0 0 0" axis="1 0.000496486 -0.000170471" range="-3.14112 3.13719" armature="0.00997778" damping="0.0070425" frictionloss="0.0990742"/>
          <geom name="//unnamed_geom_79" class="visual" pos="0.00183528 2.89198e-06 0" quat="0.707107 0 0 -0.707107" material="thigh" mesh="thigh"/>
          <geom name="//unnamed_geom_80" class="collision" size="0.0646415 0.0397794" pos="0.0415817 0 0" quat="0.5 0.5 -0.5 -0.5"/>
          <geom name="//unnamed_geom_81" class="collision" size="0.0372932 0.0298345 0.140535" pos="0.0311862 0 -0.140835" quat="0.707107 0 0 -0.707107" type="box"/>
          <geom name="//unnamed_geom_82" class="visual" pos="0.104266 0 -0.284035" quat="1 0 0 0" material="drive" mesh="drive"/>
          <geom name="//unnamed_geom_83" class="collision" size="0.0497242 0.0696139" pos="0.0314981 0 -0.284035" quat="0.707107 0 0.707107 0"/>
          <geom name="//unnamed_geom_84" class="reward_collision_sphere" size="0.0795587" pos="0.0259885 0 0"/>
          <body name="LH_SHANK" pos="0.103889 -0.000439368 -0.284219" quat="1 -0.000279412 0.000212208 0.000317529">
            <inertial pos="0.00489746 0.0577083 -0.07947" quat="0.992935 0.115908 -0.00107154 0.0253985" mass="0.586628" diaginertia="0.0123825 0.00708328 0.00111885"/>
            <joint name="LH_KFE" pos="0 0 0" axis="0.999996 -0.00175919 0.00213941" range="-3.14643 3.12632" armature="0.0100005" damping="0.00506826" frictionloss="0.0975374"/>
            <geom name="//unnamed_geom_85" class="visual" pos="0.000598442 -0.00319094 0" quat="-0.707107 0 0 -0.707107" material="shank" mesh="shank_r"/>
            <geom name="LH_kfe_act" class="collision" size="0.059669 0.0198897" pos="0.0207908 0 0" quat="0.5 0.5 -0.5 -0.5"/>
            <geom name="//unnamed_geom_87" class="collision" size="0.0571818 0.0335638 0.0188952" pos="0.0207908 0.0544687 0" quat="0.5 0.5 -0.5 -0.5" type="box"/>
            <geom name="//unnamed_geom_88" class="visual" pos="0.0135662 0.0822865 -0.336825" quat="-0.382683 0 0 -0.92388" material="foot" mesh="foot"/>
            <geom name="LH_calf" class="collision" size="0.0174035 0.140473" pos="0.013566 0.0833148 -0.168413" quat="0.707107 0 0 -0.707107"/>
            <geom name="LH_foot" class="foot" size="0.0310335" pos="0.013566 0.0833148 -0.314402" quat="0.707107 0 0 -0.707107"/>
            <geom name="//unnamed_geom_91" class="reward_collision_sphere" size="0.0994484" pos="-0.0519771 0 0"/>
            <geom name="//unnamed_geom_92" class="reward_collision_sphere" size="0.0497242" pos="0.013566 0.0833148 -0.314402"/>
            <site name="LH_foot" class="foot" pos="0.013566 0.0833148 -0.314402" quat="0.707107 0 0 -0.707107" size="0.00994484"/>
          </body>
        </body>
      </body>
      <body name="RH_HIP" pos="-0.311668 -0.0993496 0.000639358" quat="0.000175607 -6.02014e-05 -0.96593 -0.258803">
        <inertial pos="0.059326 -0.0149662 -0.00818182" quat="-0.129637 0.710502 -0.135761 0.678196" mass="2.74751" diaginertia="0.00711334 0.00381199 0.00327203"/>
        <joint name="RH_HAA" pos="0 0 0" axis="0.999999 0.000470347 0.00139479" range="-0.712951 0.501696" armature="0.0101756" damping="0.0111156" frictionloss="0.0954478"/>
        <geom name="//unnamed_geom_93" class="visual" pos="0 -5.00424e-05 8.21943e-06" quat="-0.258819 0.965926 0 0" material="hip_l" mesh="hip_l"/>
        <geom name="//unnamed_geom_94" class="visual" pos="0.0622685 -0.0742546 -0.0432357" quat="-0.183013 0.683013 -0.683013 -0.183013" material="drive" mesh="drive"/>
        <geom name="//unnamed_geom_95" class="collision" size="0.0497242 0.0696139" pos="0.0622685 -0.0113295 -0.00688161" quat="0.353553 0.612372 -0.612372 0.353553"/>
        <body name="RH_THIGH" pos="0.0622049 -0.0689437 -0.0423476" quat="-0.183012 0.683011 -0.683013 -0.183019">
          <inertial pos="0.0322086 0.00047113 -0.24539" quat="0.992871 -0.00452194 -0.0803398 0.0879319" mass="2.99908" diaginertia="0.0365482 0.0225948 0.00410174"/>
          <joint name="RH_HFE" pos="0 0 0" axis="0.999986 -0.00480309 0.00226631" range="-3.14235 3.14856" armature="0.0101915" damping="0.00798756" frictionloss="0.101411"/>
          <geom name="//unnamed_geom_96" class="visual" pos="0.00183528 2.89198e-06 0" quat="0.707107 0 0 -0.707107" material="thigh" mesh="thigh"/>
          <geom name="//unnamed_geom_97" class="collision" size="0.0646415 0.0397794" pos="0.0415817 0 0" quat="0.5 0.5 0.5 0.5"/>
          <geom name="//unnamed_geom_98" class="collision" size="0.0372932 0.0298345 0.140535" pos="0.0311862 0 -0.140835" quat="0.707107 0 0 0.707107" type="box"/>
          <geom name="//unnamed_geom_99" class="visual" pos="0.104266 0 -0.284035" quat="1 0 0 0" material="drive" mesh="drive"/>
          <geom name="//unnamed_geom_100" class="collision" size="0.0497242 0.0696139" pos="0.0314981 0 -0.284035" quat="0.707107 0 0.707107 0"/>
          <geom name="//unnamed_geom_101" class="reward_collision_sphere" size="0.0795587" pos="0.0259885 0 0"/>
          <body name="RH_SHANK" pos="0.104398 0.00110067 -0.283946" quat="1 -0.000261116 7.19224e-05 -0.000237733">
            <inertial pos="0.00528683 -0.057927 -0.0804739" quat="0.992993 -0.115437 -0.00101539 -0.0252816" mass="0.58417" diaginertia="0.0124549 0.00705175 0.00111449"/>
            <joint name="RH_KFE" pos="0 0 0" axis="0.999982 -0.00575445 -0.00191388" range="-3.13997 3.12713" armature="0.00997762" damping="0.00855906" frictionloss="0.0995547"/>
            <geom name="//unnamed_geom_102" class="visual" pos="0.000598445 0.00319094 0" quat="0.707107 0 0 -0.707107" material="shank_l" mesh="shank_l"/>
            <geom name="RH_kfe_act" class="collision" size="0.059669 0.0198897" pos="0.0207908 0 0" quat="0.5 0.5 0.5 0.5"/>
            <geom name="//unnamed_geom_104" class="collision" size="0.0571818 0.0335638 0.0188952" pos="0.0207908 -0.0544687 0" quat="0.5 0.5 0.5 0.5" type="box"/>
            <geom name="//unnamed_geom_105" class="visual" pos="0.0135659 -0.0822865 -0.336825" quat="0.382683 0 0 -0.92388" material="foot" mesh="foot"/>
            <geom name="RH_calf" class="collision" size="0.0174035 0.140473" pos="0.013566 -0.0833148 -0.168413" quat="0.707107 0 0 0.707107"/>
            <geom name="RH_foot" class="foot" size="0.0269895" pos="0.013566 -0.0833148 -0.314402" quat="0.707107 0 0 0.707107"/>
            <geom name="//unnamed_geom_108" class="reward_collision_sphere" size="0.0994484" pos="-0.0519771 0 0"/>
            <geom name="//unnamed_geom_109" class="reward_collision_sphere" size="0.0497242" pos="0.013566 -0.0833148 -0.314402"/>
            <site name="RH_foot" class="foot" pos="0.013566 -0.0833148 -0.314402" quat="0.707107 0 0 0.707107" size="0.00994484"/>
          </body>
        </body>
      </body>
    </body>
  </worldbody>

  <contact>
    <pair class="/" geom1="floor" geom2="LF_foot" name="//unnamed_contact_0"/>
    <pair class="/" geom1="floor" geom2="RF_foot" name="//unnamed_contact_1"/>
    <pair class="/" geom1="floor" geom2="LH_foot" name="//unnamed_contact_2"/>
    <pair class="/" geom1="floor" geom2="RH_foot" name="//unnamed_contact_3"/>
  </contact>

  <actuator>
    <general name="LF_HAA" class="/" joint="LF_HAA" forcerange="-81.8385 81.8385" gainprm="79.61" biasprm="0 -79.61 -1.91301"/>
    <general name="LF_HFE" class="/" joint="LF_HFE" forcerange="-78.4064 78.4064" gainprm="79.61" biasprm="0 -79.61 -1.91301"/>
    <general name="LF_KFE" class="/" joint="LF_KFE" forcerange="-81.1297 81.1297" gainprm="79.61" biasprm="0 -79.61 -1.91301"/>
    <general name="RF_HAA" class="/" joint="RF_HAA" forcerange="-78.7901 78.7901" gainprm="79.61" biasprm="0 -79.61 -1.91301"/>
    <general name="RF_HFE" class="/" joint="RF_HFE" forcerange="-80.4684 80.4684" gainprm="79.61" biasprm="0 -79.61 -1.91301"/>
    <general name="RF_KFE" class="/" joint="RF_KFE" forcerange="-80.3034 80.3034" gainprm="79.61" biasprm="0 -79.61 -1.91301"/>
    <general name="LH_HAA" class="/" joint="LH_HAA" forcerange="-77.4145 77.4145" gainprm="79.61" biasprm="0 -79.61 -1.91301"/>
    <general name="LH_HFE" class="/" joint="LH_HFE" forcerange="-79.9126 79.9126" gainprm="79.61" biasprm="0 -79.61 -1.91301"/>
    <general name="LH_KFE" class="/" joint="LH_KFE" forcerange="-81.3196 81.3196" gainprm="79.61" biasprm="0 -79.61 -1.91301"/>
    <general name="RH_HAA" class="/" joint="RH_HAA" forcerange="-79.1455 79.1455" gainprm="79.61" biasprm="0 -79.61 -1.91301"/>
    <general name="RH_HFE" class="/" joint="RH_HFE" forcerange="-79.5401 79.5401" gainprm="79.61" biasprm="0 -79.61 -1.91301"/>
    <general name="RH_KFE" class="/" joint="RH_KFE" forcerange="-78.5415 78.5415" gainprm="79.61" biasprm="0 -79.61 -1.91301"/>
  </actuator>

  <sensor>
    <gyro site="imu" name="imu_angular_velocity"/>
    <velocimeter site="imu" name="imu_linear_velocity"/>
    <framelinvel objtype="site" objname="LF_foot" name="LF_foot_global_linear_velocity"/>
    <framelinvel objtype="site" objname="RF_foot" name="RF_foot_global_linear_velocity"/>
    <framelinvel objtype="site" objname="LH_foot" name="LH_foot_global_linear_velocity"/>
    <framelinvel objtype="site" objname="RH_foot" name="RH_foot_global_linear_velocity"/>
  </sensor>

  <keyframe>
    <key name="home" qpos="0 0 0.55 1 0 0 0 0 0.4 -0.8 0 -0.4 0.8 0 -0.4 0.8 0 0.4 -0.8"/>
  </keyframe>
</mujoco>
