<mujoco model="anymal_c">
  <compiler angle="radian" assetdir="assets" balanceinertia="true" inertiafromgeom="false"/>

  <option timestep="0.005" density="1.2" viscosity="2e-05"/>

  <size nkey="1"/>

  <visual>
    <quality shadowsize="8192"/>
    <map shadowclip="0.5"/>
  </visual>

  <default>
    <default class="/">
      <material specular="0" shininess="0.25"/>
      <geom contype="0" conaffinity="0" group="1" solref="-1000 -80"/>
      <site size="0.01 0.005 0.005" group="5"/>
      <general forcelimited="true" forcerange="-80 80" biastype="affine" gainprm="80" biasprm="0 -80 -2"/>
      <default class="anymal_c">
        <joint armature="0.01" damping="0.01" frictionloss="0.1"/>
        <default class="visual">
          <geom type="mesh" group="2"/>
          <default class="visual_zflip"/>
        </default>
        <default class="collision">
          <geom type="cylinder" group="3"/>
          <default class="foot">
            <geom size="0.03 0 0" type="sphere" condim="6" priority="1" friction="0.8 0.02 0.01" solimp="0.015 1 0.03"/>
          </default>
        </default>
      </default>
      <default class="reward_collision_sphere">
        <geom group="5" rgba="1 0 0 1"/>
      </default>
    </default>
  </default>

  <asset>
    <texture type="skybox" colorspace="auto" name="//unnamed_texture_0" builtin="gradient" rgb1="0.95 0.95 0.95" rgb2="0.95 0.95 0.95" width="100" height="600"/>
    <texture type="2d" colorspace="auto" name="texplane" builtin="checker" rgb1="0.345 0.575 0.748" rgb2="0.345 0.575 0.748" markrgb="1 1 1" width="512" height="512"/>
    <texture type="2d" colorspace="linear" name="base" file="base.png"/>
    <texture type="2d" colorspace="linear" name="top_shell" file="top_shell.png"/>
    <texture type="2d" colorspace="linear" name="bottom_shell" file="bottom_shell.png"/>
    <texture type="2d" colorspace="linear" name="remote" file="remote.png"/>
    <texture type="2d" colorspace="linear" name="hatch" file="hatch.png"/>
    <texture type="2d" colorspace="linear" name="handle" file="handle.png"/>
    <texture type="2d" colorspace="linear" name="face" file="face.png"/>
    <texture type="2d" colorspace="linear" name="battery" file="battery.png"/>
    <texture type="2d" colorspace="linear" name="lidar_cage" file="lidar_cage.png"/>
    <texture type="2d" colorspace="linear" name="depth_camera" file="depth_camera.png"/>
    <texture type="2d" colorspace="linear" name="wide_angle_camera" file="wide_angle_camera.png"/>
    <texture type="2d" colorspace="linear" name="lidar" file="lidar.png"/>
    <texture type="2d" colorspace="linear" name="drive" file="drive.png"/>
    <texture type="2d" colorspace="linear" name="hip_l" file="hip_l.png"/>
    <texture type="2d" colorspace="linear" name="shank_l" file="shank_l.png"/>
    <texture type="2d" colorspace="linear" name="foot" file="foot.png"/>
    <texture type="2d" colorspace="linear" name="thigh" file="thigh.png"/>
    <texture type="2d" colorspace="linear" name="shank_r" file="shank_r.png"/>
    <texture type="2d" colorspace="linear" name="hip_r" file="hip_r.png"/>
    <material name="MatPlane" class="/" texture="texplane" texuniform="true" texrepeat="2 2" specular="0.9" shininess="0.5"/>
    <material name="black_plastic" class="/" rgba="0.007 0.007 0.007 1"/>
    <material name="green" class="/" rgba="0.052 0.178 0.033 1"/>
    <material name="red" class="/" rgba="0.178 0.006 0.005 1"/>
    <material name="yellow" class="/" rgba="0.178 0.119 0.006 1"/>
    <material name="lwl" class="/" rgba="0.8 0.8 0.8 1"/>
    <material name="base" class="/" texture="base"/>
    <material name="top_shell" class="/" texture="top_shell"/>
    <material name="bottom_shell" class="/" texture="bottom_shell"/>
    <material name="hip_l" class="/" texture="hip_l"/>
    <material name="thigh" class="/" texture="thigh"/>
    <material name="shank_l" class="/" texture="shank_l"/>
    <material name="foot" class="/" texture="foot"/>
    <material name="hip_r" class="/" texture="hip_r"/>
    <material name="shank" class="/" texture="shank_r"/>
    <material name="hatch" class="/" texture="hatch"/>
    <material name="remote" class="/" texture="remote"/>
    <material name="handle" class="/" texture="handle"/>
    <material name="face" class="/" texture="face"/>
    <material name="depth_camera" class="/" texture="depth_camera"/>
    <material name="wide_angle_camera" class="/" texture="wide_angle_camera"/>
    <material name="battery" class="/" texture="battery"/>
    <material name="lidar_cage" class="/" texture="lidar_cage"/>
    <material name="lidar" class="/" texture="lidar"/>
    <material name="drive" class="/" texture="drive"/>
    <mesh name="base_0" class="/" file="base_0.obj"/>
    <mesh name="base_1" class="/" file="base_1.obj"/>
    <mesh name="base_2" class="/" file="base_2.obj"/>
    <mesh name="base_3" class="/" file="base_3.obj"/>
    <mesh name="base_4" class="/" file="base_4.obj"/>
    <mesh name="base_5" class="/" file="base_5.obj"/>
    <mesh name="top_shell" class="/" file="top_shell.obj"/>
    <mesh name="bottom_shell" class="/" file="bottom_shell.obj"/>
    <mesh name="remote" class="/" file="remote.obj"/>
    <mesh name="handle" class="/" file="handle.obj"/>
    <mesh name="face" class="/" file="face.obj"/>
    <mesh name="wide_angle_camera" class="/" file="wide_angle_camera.obj"/>
    <mesh name="depth_camera" class="/" file="depth_camera.obj"/>
    <mesh name="battery" class="/" file="battery.obj"/>
    <mesh name="lidar_cage" class="/" file="lidar_cage.obj"/>
    <mesh name="lidar" class="/" file="lidar.obj"/>
    <mesh name="drive" class="/" file="drive.obj"/>
    <mesh name="hip_l" class="/" file="hip_l.obj"/>
    <mesh name="thigh" class="/" file="thigh.obj"/>
    <mesh name="shank_l" class="/" file="shank_l.obj"/>
    <mesh name="foot" class="/" file="foot.obj"/>
    <mesh name="hip_r" class="/" file="hip_r.obj"/>
    <mesh name="hatch" class="/" file="hatch.obj"/>
    <mesh name="shank_r" class="/" file="shank_r.obj"/>
  </asset>

  <worldbody>
    <geom name="floor" class="/" size="100 100 0.125" type="plane" group="0" material="MatPlane"/>
    <light name="toplight_shadow" class="/" pos="0 0 5" dir="0.0990148 0.0990148 -0.990148" type="directional" ambient="0.04 0.04 0.04" diffuse="0.55 0.55 0.55" specular="0.12 0.12 0.12"/>
    <light name="toplight_fill" class="/" pos="0 0 5" dir="0.0990148 0.0990148 -0.990148" type="directional" castshadow="false" ambient="0.04 0.04 0.04" diffuse="0.3 0.3 0.3" specular="0.08 0.08 0.08"/>
    <body name="trunk" childclass="anymal_c" pos="0.000331895 -0.000239554 -4.66923e-05" quat="1 2.53095e-05 2.47283e-05 0.000104649">
      <inertial pos="0.00294885 -0.00307476 0.0453807" quat="0.500031 0.499743 0.500035 0.500191" mass="19.9729" diaginertia="0.756322 0.881438 0.142084"/>
      <joint name="//unnamed_joint_0" type="free" armature="0" damping="0" frictionloss="0"/>
      <geom name="//unnamed_geom_1" class="visual" material="green" mesh="base_0"/>
      <geom name="//unnamed_geom_2" class="visual" material="yellow" mesh="base_1"/>
      <geom name="//unnamed_geom_3" class="visual" material="red" mesh="base_2"/>
      <geom name="//unnamed_geom_4" class="visual" material="black_plastic" mesh="base_3"/>
      <geom name="//unnamed_geom_5" class="visual" material="lwl" mesh="base_4"/>
      <geom name="//unnamed_geom_6" class="visual" material="base" mesh="base_5"/>
      <geom name="trunk_1" class="collision" size="0.293942 0.0709514 0.0912232" type="box"/>
      <geom name="trunk_2" class="collision" size="0.0912232 0.0734854" pos="0.227001 0.0751876 0" quat="0.707107 0 0.707107 0"/>
      <geom name="trunk_3" class="collision" size="0.0912232 0.0734854" pos="-0.227001 0.0751876 0" quat="0.707107 0 0.707107 0"/>
      <geom name="trunk_4" class="collision" size="0.0912232 0.0734854" pos="0.227001 -0.0751876 0" quat="0.707107 0 0.707107 0"/>
      <geom name="trunk_5" class="collision" size="0.0912232 0.0734854" pos="-0.227001 -0.0751876 0" quat="0.707107 0 0.707107 0"/>
      <geom name="//unnamed_geom_12" class="visual" material="top_shell" mesh="top_shell"/>
      <geom name="//unnamed_geom_13" class="visual" material="bottom_shell" mesh="bottom_shell"/>
      <geom name="//unnamed_geom_14" class="visual" material="remote" mesh="remote"/>
      <geom name="//unnamed_geom_15" class="visual" material="handle" mesh="handle"/>
      <geom name="//unnamed_geom_16" class="visual" pos="0.432606 0 0" quat="1 0 0 0" material="face" mesh="face"/>
      <geom name="trunk_6" class="collision" size="0.0557475 0.0709514 0.0912232" pos="0.490009 0 0" type="box"/>
      <geom name="//unnamed_geom_18" class="collision" size="0.0912232 0.0557475" pos="0.490009 0.0751876 0" quat="0.707107 0 0.707107 0"/>
      <geom name="//unnamed_geom_19" class="collision" size="0.0912232 0.0557475" pos="0.490009 -0.0751876 0" quat="0.707107 0 0.707107 0"/>
      <geom name="//unnamed_geom_20" class="visual" pos="0.481811 0 -0.0260338" quat="0.965926 0 0.258819 0" material="depth_camera" mesh="depth_camera"/>
      <geom name="//unnamed_geom_21" class="visual" pos="0.535409 0 0.0138171" material="wide_angle_camera" mesh="wide_angle_camera"/>
      <geom name="//unnamed_geom_22" class="visual_zflip" pos="-0.432606 0 0" quat="0 0 0 1" material="face" mesh="face"/>
      <geom name="trunk_7" class="collision" size="0.0557475 0.0709514 0.0912232" pos="-0.490009 0 0" quat="0 0 0 1" type="box"/>
      <geom name="//unnamed_geom_24" class="collision" size="0.0912232 0.0557475" pos="-0.490009 -0.0751876 0" quat="0 -0.707107 0 0.707107"/>
      <geom name="//unnamed_geom_25" class="collision" size="0.0912232 0.0557475" pos="-0.490009 0.0751876 0" quat="0 -0.707107 0 0.707107"/>
      <geom name="//unnamed_geom_26" class="visual" pos="-0.481811 0 -0.0260338" quat="0 -0.258819 0 0.965926" material="depth_camera" mesh="depth_camera"/>
      <geom name="//unnamed_geom_27" class="visual_zflip" pos="-0.535409 0 0.0138171" quat="0 0 0 1" material="wide_angle_camera" mesh="wide_angle_camera"/>
      <geom name="//unnamed_geom_28" class="visual" material="battery" mesh="battery"/>
      <geom name="//unnamed_geom_29" class="visual" pos="0 0.0825206 0.02773" quat="0.683013 -0.183013 0.183013 0.683013" material="depth_camera" mesh="depth_camera"/>
      <geom name="//unnamed_geom_30" class="visual" pos="0 -0.0825206 0.02773" quat="0.683013 0.183013 0.183013 -0.683013" material="depth_camera" mesh="depth_camera"/>
      <geom name="//unnamed_geom_31" class="visual" pos="-0.3799 0 0.0678394" quat="1 0 0 0" material="lidar_cage" mesh="lidar_cage"/>
      <geom name="trunk_8" class="collision" size="0.0709514 0.0608155" pos="-0.3799 0 0.123218"/>
      <geom name="//unnamed_geom_33" class="visual" pos="-0.3799 1.19537e-05 0.131248" quat="0.707107 0 0 -0.707107" material="lidar" mesh="lidar"/>
      <geom name="//unnamed_geom_34" class="visual" pos="0.313 0.111654 2.60691e-09" quat="0.258819 0.965926 0 0" material="drive" mesh="drive"/>
      <geom name="//unnamed_geom_35" class="visual" pos="0.313 -0.111654 -2.60691e-09" quat="0.258819 -0.965926 0 0" material="drive" mesh="drive"/>
      <geom name="//unnamed_geom_36" class="visual" pos="-0.313 0.111654 -2.60691e-09" quat="0 0 0.965926 -0.258819" material="drive" mesh="drive"/>
      <geom name="//unnamed_geom_37" class="visual" pos="-0.313 -0.111654 2.60691e-09" quat="0 0 -0.965926 -0.258819" material="drive" mesh="drive"/>
      <geom name="//unnamed_geom_38" class="visual" pos="0.121067 0 0.0673779" quat="1 0 0 0" material="hatch" mesh="hatch"/>
      <geom name="//unnamed_geom_39" class="reward_collision_sphere" size="0.121631"/>
      <geom name="//unnamed_geom_40" class="reward_collision_sphere" size="0.121631" pos="0.469657 0 0"/>
      <geom name="//unnamed_geom_41" class="reward_collision_sphere" size="0.121631" pos="-0.469657 0 0"/>
      <site name="imu" pos="0.272128 0.00188237 0.0547156" size="0.0101359"/>
      <camera name="track" pos="0 -2.14822 0" quat="0.707107 0.707107 0 0" mode="trackcom"/>
      <camera name="ego_camera" pos="0.469657 0 -0.0369194" quat="-0.5 -0.5 0.5 0.5"/>
      <body name="LF_HIP" pos="0.313828 0.111085 0.00181423" quat="0.258619 0.965978 0.000175993 -0.0013614">
        <inertial pos="0.0608624 -0.0157505 -0.00918624" quat="-0.131194 0.703463 -0.139209 0.684507" mass="2.71158" diaginertia="0.00701277 0.00667288 0.00216649"/>
        <joint name="LF_HAA" pos="0 0 0" axis="0.999999 0.000901559 -0.0006619" range="-0.761838 0.489597" armature="0.0106544" damping="0.0156568" frictionloss="0.107989"/>
        <geom name="//unnamed_geom_42" class="visual" pos="0 0.000153352 -2.5188e-05" quat="0.258819 -0.965926 0 0" material="hip_l" mesh="hip_l"/>
        <geom name="//unnamed_geom_43" class="visual" pos="0.0625166 -0.076099 -0.042818" quat="0.183013 -0.683013 0.683013 0.183013" material="drive" mesh="drive"/>
        <geom name="//unnamed_geom_44" class="collision" size="0.0506796 0.0709514" pos="0.0625166 -0.0128461 -0.00637321" quat="-0.353553 -0.612372 0.612372 -0.353553"/>
        <body name="LF_THIGH" pos="0.0624439 -0.0805105 -0.0372143" quat="0.183259 -0.683001 0.682965 0.182987">
          <inertial pos="0.0326514 0.00095513 -0.228224" quat="0.99313 -0.0052165 -0.0806867 0.0845842" mass="3.38528" diaginertia="0.0370651 0.0434678 0.00301066"/>
          <joint name="LF_HFE" pos="0 0 0" axis="0.999961 -0.00537171 0.00694837" range="-3.15249 3.18189" armature="0.0113323" damping="0.00939289" frictionloss="0.107926"/>
          <geom name="//unnamed_geom_45" class="visual" pos="-0.000605364 -9.53912e-07 0" quat="0.707107 0 0 -0.707107" material="thigh" mesh="thigh"/>
          <geom name="//unnamed_geom_46" class="collision" size="0.0658835 0.0405437" pos="0.0417473 0 0" quat="0.5 0.5 -0.5 -0.5"/>
          <geom name="//unnamed_geom_47" class="collision" size="0.0380097 0.0304077 0.143235" pos="0.0313105 0 -0.130431" quat="0.707107 0 0 -0.707107" type="box"/>
          <geom name="//unnamed_geom_48" class="visual" pos="0.104681 0 -0.263051" quat="1 0 0 0" material="drive" mesh="drive"/>
          <geom name="//unnamed_geom_49" class="collision" size="0.0506796 0.0709514" pos="0.0316236 0 -0.263051" quat="0.707107 0 0.707107 0"/>
          <geom name="//unnamed_geom_50" class="reward_collision_sphere" size="0.0810873" pos="0.0260921 0 0"/>
          <body name="LF_SHANK" pos="0.102843 0.000235894 -0.263344" quat="0.999999 0.00107491 1.40756e-05 0.000780421">
            <inertial pos="0.00500223 -0.0658334 -0.0740568" quat="0.992845 -0.116864 -0.00216211 -0.0244214" mass="0.596267" diaginertia="0.0125526 0.0135786 0.000759148"/>
            <joint name="LF_KFE" pos="0 0 0" axis="0.999941 0.0108697 0.000743927" range="-3.10627 3.0957" armature="0.00913052" damping="0.000662463" frictionloss="0.101229"/>
            <geom name="//unnamed_geom_51" class="visual" pos="-0.000197396 -0.00105253 0" quat="0.707107 0 0 -0.707107" material="shank_l" mesh="shank_l"/>
            <geom name="LF_kfe_act" class="collision" size="0.0608155 0.0202718" pos="0.0208736 0 0" quat="0.5 0.5 -0.5 -0.5"/>
            <geom name="//unnamed_geom_53" class="collision" size="0.0582805 0.0342087 0.0192582" pos="0.0208736 -0.0617602 0" quat="0.5 0.5 -0.5 -0.5" type="box"/>
            <geom name="//unnamed_geom_54" class="visual" pos="0.0136201 -0.094807 -0.311941" quat="0.382683 0 0 -0.92388" material="foot" mesh="foot"/>
            <geom name="LF_calf" class="collision" size="0.0177379 0.143172" pos="0.0136201 -0.0944678 -0.155971" quat="0.707107 0 0 -0.707107"/>
            <geom name="LF_foot" class="foot" size="0.0290241" pos="0.0136201 -0.0944678 -0.291174" quat="0.707107 0 0 -0.707107"/>
            <geom name="//unnamed_geom_57" class="reward_collision_sphere" size="0.101359" pos="-0.0521841 0 0"/>
            <geom name="//unnamed_geom_58" class="reward_collision_sphere" size="0.0506796" pos="0.0136201 -0.0944678 -0.291174"/>
            <site name="LF_foot" class="foot" pos="0.0136201 -0.0944678 -0.291174" quat="0.707107 0 0 -0.707107" size="0.0101359"/>
          </body>
        </body>
      </body>
      <body name="RF_HIP" pos="0.315839 -0.112572 0.00033058" quat="0.258766 -0.96594 0.000293478 0.000470359">
        <inertial pos="0.0600673 0.0189653 -0.00995486" quat="0.133022 0.681352 0.129889 0.70795" mass="3.07016" diaginertia="0.00738626 0.0070659 0.00219952"/>
        <joint name="RF_HAA" pos="0 0 0" axis="0.999983 0.00493255 -0.00311066" stiffness="0.00576254" range="-0.5036 0.771524" armature="0.010458" damping="0.0225501" frictionloss="0.0977311"/>
        <geom name="//unnamed_geom_59" class="visual" pos="0 -0.000153351 -2.51879e-05" quat="0.258819 0.965926 0 0" material="hip_r" mesh="hip_r"/>
        <geom name="//unnamed_geom_60" class="visual" pos="0.0625166 0.076099 -0.042818" quat="0.183013 0.683013 0.683013 -0.183013" material="drive" mesh="drive"/>
        <geom name="//unnamed_geom_61" class="collision" size="0.0506796 0.0709514" pos="0.0625166 0.0128461 -0.00637321" quat="-0.353553 0.612372 0.612372 0.353553"/>
        <body name="RF_THIGH" pos="0.0587006 0.0790038 -0.0384581" quat="0.182372 0.682042 0.684198 -0.182845">
          <inertial pos="0.0319219 -0.00193645 -0.226624" quat="0.992936 -0.00489654 -0.0770121 0.0901247" mass="2.96609" diaginertia="0.0366996 0.0394526 0.00273617"/>
          <joint name="RF_HFE" pos="0 0 0" axis="0.999895 0.0106975 0.00977517" stiffness="0.00433517" range="-3.2266 3.19161" armature="0.00987473" damping="0.0138846" frictionloss="0.0886292"/>
          <geom name="//unnamed_geom_62" class="visual" pos="-0.000605364 -9.53912e-07 0" quat="0.707107 0 0 -0.707107" material="thigh" mesh="thigh"/>
          <geom name="//unnamed_geom_63" class="collision" size="0.0658835 0.0405437" pos="0.0417473 0 0" quat="0.5 0.5 0.5 0.5"/>
          <geom name="//unnamed_geom_64" class="collision" size="0.0380097 0.0304077 0.143235" pos="0.0313105 0 -0.130431" quat="0.707107 0 0 0.707107" type="box"/>
          <geom name="//unnamed_geom_65" class="visual" pos="0.104681 0 -0.263051" quat="1 0 0 0" material="drive" mesh="drive"/>
          <geom name="//unnamed_geom_66" class="collision" size="0.0506796 0.0709514" pos="0.0316236 0 -0.263051" quat="0.707107 0 0.707107 0"/>
          <geom name="//unnamed_geom_67" class="reward_collision_sphere" size="0.0810873" pos="0.0260921 0 0"/>
          <body name="RF_SHANK" pos="0.101672 0.00293348 -0.261598" quat="0.999999 -9.84352e-05 0.000515761 -0.000946132">
            <inertial pos="0.00347816 0.0633105 -0.0780998" quat="0.993107 0.116221 -0.0065328 0.0137389" mass="0.642244" diaginertia="0.0126429 0.0131472 0.000746699"/>
            <joint name="RF_KFE" pos="0 0 0" axis="0.999753 0.0211333 0.00687494" range="-3.08435 3.16481" armature="0.0100353" damping="0.0192105" frictionloss="0.123232"/>
            <geom name="//unnamed_geom_68" class="visual" pos="-0.000197395 0.00105252 0" quat="0.707107 0 0 0.707107" material="shank" mesh="shank_r"/>
            <geom name="RF_kfe_act" class="collision" size="0.0608155 0.0202718" pos="0.0208736 0 0" quat="0.5 0.5 0.5 0.5"/>
            <geom name="//unnamed_geom_70" class="collision" size="0.0582805 0.0342087 0.0192582" pos="0.0208736 0.0617602 0" quat="0.5 0.5 0.5 0.5" type="box"/>
            <geom name="//unnamed_geom_71" class="visual" pos="0.01362 0.094807 -0.311941" quat="0.382683 0 0 0.92388" material="foot" mesh="foot"/>
            <geom name="RF_calf" class="collision" size="0.0177379 0.143172" pos="0.0136201 0.0944678 -0.155971" quat="0.707107 0 0 0.707107"/>
            <geom name="RF_foot" class="foot" size="0.0308797" pos="0.0136201 0.0944678 -0.291174" quat="0.707107 0 0 0.707107"/>
            <geom name="//unnamed_geom_74" class="reward_collision_sphere" size="0.101359" pos="-0.0521841 0 0"/>
            <geom name="//unnamed_geom_75" class="reward_collision_sphere" size="0.0506796" pos="0.0136201 0.0944678 -0.291174"/>
            <site name="RF_foot" class="foot" pos="0.0136201 0.0944678 -0.291174" quat="0.707107 0 0 0.707107" size="0.0101359"/>
          </body>
        </body>
      </body>
      <body name="LH_HIP" pos="-0.314721 0.111487 0.00195225" quat="0.000552351 0.000112177 0.965944 -0.258749">
        <inertial pos="0.0574859 0.0178522 -0.00560649" quat="0.150381 0.691188 0.127105 0.695334" mass="3.05906" diaginertia="0.00747628 0.00707922 0.00214494"/>
        <joint name="LH_HAA" pos="0 0 0" axis="1 -0.000467112 8.70745e-05" stiffness="0.00228227" range="-0.444028 0.685427" armature="0.0101153" damping="0.00409353" frictionloss="0.109731"/>
        <geom name="//unnamed_geom_76" class="visual" pos="0 -0.000153351 -2.51879e-05" quat="-0.258819 -0.965926 0 0" material="hip_r" mesh="hip_r"/>
        <geom name="//unnamed_geom_77" class="visual" pos="0.0625166 0.076099 -0.042818" quat="0.183013 0.683013 0.683013 -0.183013" material="drive" mesh="drive"/>
        <geom name="//unnamed_geom_78" class="collision" size="0.0506796 0.0709514" pos="0.0625166 0.0128461 -0.00637321" quat="-0.353553 0.612372 0.612372 0.353553"/>
        <body name="LH_THIGH" pos="0.0624963 0.0793957 -0.0396993" quat="0.183386 0.683027 0.683098 -0.182266">
          <inertial pos="0.0297188 -0.000145839 -0.226661" quat="0.993446 0.00182201 -0.0821998 0.0794005" mass="3.12657" diaginertia="0.0351607 0.0405587 0.00276783"/>
          <joint name="LH_HFE" pos="0 0 0" axis="0.999999 -0.000555558 -0.0014026" stiffness="0.00607309" range="-3.14746 3.1244" armature="0.0101362" damping="0" frictionloss="0.103125"/>
          <geom name="//unnamed_geom_79" class="visual" pos="-0.000605364 -9.53912e-07 0" quat="0.707107 0 0 -0.707107" material="thigh" mesh="thigh"/>
          <geom name="//unnamed_geom_80" class="collision" size="0.0658835 0.0405437" pos="0.0417473 0 0" quat="0.5 0.5 -0.5 -0.5"/>
          <geom name="//unnamed_geom_81" class="collision" size="0.0380097 0.0304077 0.143235" pos="0.0313105 0 -0.130431" quat="0.707107 0 0 -0.707107" type="box"/>
          <geom name="//unnamed_geom_82" class="visual" pos="0.104681 0 -0.263051" quat="1 0 0 0" material="drive" mesh="drive"/>
          <geom name="//unnamed_geom_83" class="collision" size="0.0506796 0.0709514" pos="0.0316236 0 -0.263051" quat="0.707107 0 0.707107 0"/>
          <geom name="//unnamed_geom_84" class="reward_collision_sphere" size="0.0810873" pos="0.0260921 0 0"/>
          <body name="LH_SHANK" pos="0.104152 -0.00194644 -0.262298" quat="1 0.000369801 -7.87033e-05 0.000465575">
            <inertial pos="0.0050847 0.063181 -0.0747901" quat="0.992933 0.115975 -0.000960027 0.0251492" mass="0.589742" diaginertia="0.0114395 0.0120259 0.000661606"/>
            <joint name="LH_KFE" pos="0 0 0" axis="0.999996 0.00145715 0.00259063" range="-3.1422 3.23834" armature="0.0104913" damping="0.003862" frictionloss="0.110685"/>
            <geom name="//unnamed_geom_85" class="visual" pos="-0.000197395 0.00105252 0" quat="-0.707107 0 0 -0.707107" material="shank" mesh="shank_r"/>
            <geom name="LH_kfe_act" class="collision" size="0.0608155 0.0202718" pos="0.0208736 0 0" quat="0.5 0.5 -0.5 -0.5"/>
            <geom name="//unnamed_geom_87" class="collision" size="0.0582805 0.0342087 0.0192582" pos="0.0208736 0.0617602 0" quat="0.5 0.5 -0.5 -0.5" type="box"/>
            <geom name="//unnamed_geom_88" class="visual" pos="0.01362 0.094807 -0.311941" quat="-0.382683 0 0 -0.92388" material="foot" mesh="foot"/>
            <geom name="LH_calf" class="collision" size="0.0177379 0.143172" pos="0.0136201 0.0944678 -0.155971" quat="0.707107 0 0 -0.707107"/>
            <geom name="LH_foot" class="foot" size="0.034363" pos="0.0136201 0.0944678 -0.291174" quat="0.707107 0 0 -0.707107"/>
            <geom name="//unnamed_geom_91" class="reward_collision_sphere" size="0.101359" pos="-0.0521841 0 0"/>
            <geom name="//unnamed_geom_92" class="reward_collision_sphere" size="0.0506796" pos="0.0136201 0.0944678 -0.291174"/>
            <site name="LH_foot" class="foot" pos="0.0136201 0.0944678 -0.291174" quat="0.707107 0 0 -0.707107" size="0.0101359"/>
          </body>
        </body>
      </body>
      <body name="RH_HIP" pos="-0.311905 -0.112682 0.00265352" quat="0.000500201 0.000487198 -0.966044 -0.258378">
        <inertial pos="0.0616028 -0.0146755 -0.00984874" quat="-0.124367 0.700333 -0.152711 0.686109" mass="2.78175" diaginertia="0.00727777 0.00682571 0.0021804"/>
        <joint name="RH_HAA" pos="0 0 0" axis="0.999907 0.00943415 0.00982509" range="-0.689392 0.544783" armature="0.0111771" damping="0.00588384" frictionloss="0.10557"/>
        <geom name="//unnamed_geom_93" class="visual" pos="0 0.000153352 -2.5188e-05" quat="-0.258819 0.965926 0 0" material="hip_l" mesh="hip_l"/>
        <geom name="//unnamed_geom_94" class="visual" pos="0.0625166 -0.076099 -0.042818" quat="-0.183013 0.683013 -0.683013 -0.183013" material="drive" mesh="drive"/>
        <geom name="//unnamed_geom_95" class="collision" size="0.0506796 0.0709514" pos="0.0625166 -0.0128461 -0.00637321" quat="0.353553 0.612372 -0.612372 0.353553"/>
        <body name="RH_THIGH" pos="0.0604987 -0.0791637 -0.0352195" quat="-0.183184 0.683045 -0.682984 -0.182828">
          <inertial pos="0.0323319 -0.00449183 -0.22543" quat="0.993393 -0.00781215 -0.0780501 0.0837671" mass="3.39653" diaginertia="0.0393498 0.0454128 0.00291536"/>
          <joint name="RH_HFE" pos="0 0 0" axis="0.999995 0.00301715 0.00126601" range="-3.09617 3.19417" armature="0.0077414" damping="0.00398662" frictionloss="0.114386"/>
          <geom name="//unnamed_geom_96" class="visual" pos="-0.000605364 -9.53912e-07 0" quat="0.707107 0 0 -0.707107" material="thigh" mesh="thigh"/>
          <geom name="//unnamed_geom_97" class="collision" size="0.0658835 0.0405437" pos="0.0417473 0 0" quat="0.5 0.5 0.5 0.5"/>
          <geom name="//unnamed_geom_98" class="collision" size="0.0380097 0.0304077 0.143235" pos="0.0313105 0 -0.130431" quat="0.707107 0 0 0.707107" type="box"/>
          <geom name="//unnamed_geom_99" class="visual" pos="0.104681 0 -0.263051" quat="1 0 0 0" material="drive" mesh="drive"/>
          <geom name="//unnamed_geom_100" class="collision" size="0.0506796 0.0709514" pos="0.0316236 0 -0.263051" quat="0.707107 0 0.707107 0"/>
          <geom name="//unnamed_geom_101" class="reward_collision_sphere" size="0.0810873" pos="0.0260921 0 0"/>
          <body name="RH_SHANK" pos="0.107587 0.000604544 -0.259684" quat="1 7.90818e-05 -6.89542e-05 2.86991e-05">
            <inertial pos="0.00751062 -0.0648628 -0.0740431" quat="0.994272 -0.102186 -0.00985667 -0.0297413" mass="0.617152" diaginertia="0.0126694 0.0125071 0.000691806"/>
            <joint name="RH_KFE" pos="0 0 0" axis="0.999932 0.0039178 -0.0110064" range="-3.15581 3.09748" armature="0.0100311" damping="0.00895229" frictionloss="0.11129"/>
            <geom name="//unnamed_geom_102" class="visual" pos="-0.000197396 -0.00105253 0" quat="0.707107 0 0 -0.707107" material="shank_l" mesh="shank_l"/>
            <geom name="RH_kfe_act" class="collision" size="0.0608155 0.0202718" pos="0.0208736 0 0" quat="0.5 0.5 0.5 0.5"/>
            <geom name="//unnamed_geom_104" class="collision" size="0.0582805 0.0342087 0.0192582" pos="0.0208736 -0.0617602 0" quat="0.5 0.5 0.5 0.5" type="box"/>
            <geom name="//unnamed_geom_105" class="visual" pos="0.0136201 -0.094807 -0.311941" quat="0.382683 0 0 -0.92388" material="foot" mesh="foot"/>
            <geom name="RH_calf" class="collision" size="0.0177379 0.143172" pos="0.0136201 -0.0944678 -0.155971" quat="0.707107 0 0 0.707107"/>
            <geom name="RH_foot" class="foot" size="0.0354749" pos="0.0136201 -0.0944678 -0.291174" quat="0.707107 0 0 0.707107"/>
            <geom name="//unnamed_geom_108" class="reward_collision_sphere" size="0.101359" pos="-0.0521841 0 0"/>
            <geom name="//unnamed_geom_109" class="reward_collision_sphere" size="0.0506796" pos="0.0136201 -0.0944678 -0.291174"/>
            <site name="RH_foot" class="foot" pos="0.0136201 -0.0944678 -0.291174" quat="0.707107 0 0 0.707107" size="0.0101359"/>
          </body>
        </body>
      </body>
    </body>
  </worldbody>

  <contact>
    <pair class="/" geom1="floor" geom2="LF_foot" name="//unnamed_contact_0"/>
    <pair class="/" geom1="floor" geom2="RF_foot" name="//unnamed_contact_1"/>
    <pair class="/" geom1="floor" geom2="LH_foot" name="//unnamed_contact_2"/>
    <pair class="/" geom1="floor" geom2="RH_foot" name="//unnamed_contact_3"/>
  </contact>

  <actuator>
    <general name="LF_HAA" class="/" joint="LF_HAA" forcerange="-77.1949 77.1949" gainprm="75.749" biasprm="0 -75.749 -2.12276"/>
    <general name="LF_HFE" class="/" joint="LF_HFE" forcerange="-93.891 93.891" gainprm="75.749" biasprm="0 -75.749 -2.12276"/>
    <general name="LF_KFE" class="/" joint="LF_KFE" forcerange="-88.6507 88.6507" gainprm="75.749" biasprm="0 -75.749 -2.12276"/>
    <general name="RF_HAA" class="/" joint="RF_HAA" forcerange="-74.1262 74.1262" gainprm="75.749" biasprm="0 -75.749 -2.12276"/>
    <general name="RF_HFE" class="/" joint="RF_HFE" forcerange="-89.8174 89.8174" gainprm="75.749" biasprm="0 -75.749 -2.12276"/>
    <general name="RF_KFE" class="/" joint="RF_KFE" forcerange="-75.2344 75.2344" gainprm="75.749" biasprm="0 -75.749 -2.12276"/>
    <general name="LH_HAA" class="/" joint="LH_HAA" forcerange="-82.8068 82.8068" gainprm="75.749" biasprm="0 -75.749 -2.12276"/>
    <general name="LH_HFE" class="/" joint="LH_HFE" forcerange="-80.3807 80.3807" gainprm="75.749" biasprm="0 -75.749 -2.12276"/>
    <general name="LH_KFE" class="/" joint="LH_KFE" forcerange="-76.4356 76.4356" gainprm="75.749" biasprm="0 -75.749 -2.12276"/>
    <general name="RH_HAA" class="/" joint="RH_HAA" forcerange="-93.2438 93.2438" gainprm="75.749" biasprm="0 -75.749 -2.12276"/>
    <general name="RH_HFE" class="/" joint="RH_HFE" forcerange="-75.2376 75.2376" gainprm="75.749" biasprm="0 -75.749 -2.12276"/>
    <general name="RH_KFE" class="/" joint="RH_KFE" forcerange="-74.1086 74.1086" gainprm="75.749" biasprm="0 -75.749 -2.12276"/>
  </actuator>

  <sensor>
    <gyro site="imu" name="imu_angular_velocity"/>
    <velocimeter site="imu" name="imu_linear_velocity"/>
    <framelinvel objtype="site" objname="LF_foot" name="LF_foot_global_linear_velocity"/>
    <framelinvel objtype="site" objname="RF_foot" name="RF_foot_global_linear_velocity"/>
    <framelinvel objtype="site" objname="LH_foot" name="LH_foot_global_linear_velocity"/>
    <framelinvel objtype="site" objname="RH_foot" name="RH_foot_global_linear_velocity"/>
  </sensor>

  <keyframe>
    <key name="home" qpos="0 0 0.55 1 0 0 0 0 0.4 -0.8 0 -0.4 0.8 0 -0.4 0.8 0 0.4 -0.8"/>
  </keyframe>
</mujoco>
