<mujoco model="pi_12dof_release_v1">
  <compiler angle="radian" assetdir="assets" balanceinertia="true" inertiafromgeom="false"/>

  <option timestep="0.005" density="1.2" viscosity="2e-05"/>

  <size nkey="1"/>

  <visual>
    <quality shadowsize="8192"/>
    <map shadowclip="0.5"/>
  </visual>

  <default>
    <default class="/">
      <joint armature="0.01" damping="0.01" frictionloss="0.01"/>
      <geom contype="0" conaffinity="0" group="1" solref="-1000 -80"/>
      <site size="0.01 0.005 0.005" group="5"/>
      <general forcelimited="true" biastype="affine" gainprm="20" biasprm="0 -20 -0.5"/>
      <default class="foot">
        <geom size="0.0845 0.036 0.005" type="box" condim="6" group="4" priority="1" friction="0.9 0.2 0.2" solimp="0.015 1 0.005"/>
      </default>
      <default class="reward_collision_sphere">
        <geom group="5" rgba="1 0 0 1"/>
      </default>
    </default>
  </default>

  <asset>
    <texture type="skybox" colorspace="auto" name="//unnamed_texture_0" builtin="gradient" rgb1="0.95 0.95 0.95" rgb2="0.95 0.95 0.95" width="100" height="600"/>
    <texture type="2d" colorspace="auto" name="texplane" builtin="checker" rgb1="0.345 0.575 0.748" rgb2="0.345 0.575 0.748" markrgb="1 1 1" width="512" height="512"/>
    <material name="MatPlane" class="/" texture="texplane" texuniform="true" texrepeat="2 2" specular="0.9"/>
    <mesh name="baselink_1" class="/" file="baselink_1.STL"/>
    <mesh name="r_hip_pitch_link" class="/" file="r_hip_pitch_link.STL"/>
    <mesh name="r_hip_roll_link" class="/" file="r_hip_roll_link.STL"/>
    <mesh name="r_thigh_link" class="/" file="r_thigh_link.STL"/>
    <mesh name="r_calf_link" class="/" file="r_calf_link.STL"/>
    <mesh name="r_ankle_pitch_link" class="/" file="r_ankle_pitch_link.STL"/>
    <mesh name="r_ankle_roll_link" class="/" file="r_ankle_roll_link.STL"/>
    <mesh name="l_hip_pitch_link" class="/" file="l_hip_pitch_link.STL"/>
    <mesh name="l_hip_roll_link" class="/" file="l_hip_roll_link.STL"/>
    <mesh name="l_thigh_link" class="/" file="l_thigh_link.STL"/>
    <mesh name="l_calf_link" class="/" file="l_calf_link.STL"/>
    <mesh name="l_ankle_pitch_link" class="/" file="l_ankle_pitch_link.STL"/>
    <mesh name="l_ankle_roll_link" class="/" file="l_ankle_roll_link.STL"/>
  </asset>

  <worldbody>
    <geom name="floor" class="/" size="100 100 0.125" type="plane" group="0" material="MatPlane"/>
    <light name="toplight_shadow" class="/" pos="0 0 5" dir="0.0990148 0.0990148 -0.990148" type="directional" ambient="0.04 0.04 0.04" diffuse="0.55 0.55 0.55" specular="0.12 0.12 0.12"/>
    <light name="toplight_fill" class="/" pos="0 0 5" dir="0.0990148 0.0990148 -0.990148" type="directional" castshadow="false" ambient="0.04 0.04 0.04" diffuse="0.3 0.3 0.3" specular="0.08 0.08 0.08"/>
    <body name="trunk" pos="-0.000123249 0.0001905 3.90438e-05" quat="1 0.00029038 9.58334e-05 -9.72632e-05">
      <inertial pos="0.00238567 0.00103713 0.0385369" quat="0.695082 0.00784851 0.0134235 0.718762" mass="1.29564" diaginertia="0.00473149 0.00166038 0.00366841"/>
      <joint name="//unnamed_joint_0" type="free"/>
      <geom name="//unnamed_geom_1" class="/" type="mesh" density="0" rgba="1 1 1 1" mesh="baselink_1"/>
      <geom name="//unnamed_geom_2" class="/" size="0.042665 0.042665 0.042665" pos="0 0 0.0783091" type="box" rgba="1 1 1 1"/>
      <geom name="//unnamed_geom_3" class="reward_collision_sphere" size="0.0469314" pos="0 0 0.0685205"/>
      <site name="imu" class="/" pos="0.0042348 0.0137759 -0.00990514" size="0.00853299"/>
      <camera name="track" class="/" pos="0 -1.43142 0" quat="0.707107 0.707107 0 0" mode="trackcom"/>
      <camera name="ego_camera" class="/" pos="0.0648993 0 0.176195" quat="-0.5 -0.5 0.5 0.5"/>
      <body name="r_hip_pitch_link" pos="0.000185619 -0.0131724 -0.0310113" quat="0.992197 8.43155e-06 -0.124683 1.6925e-05">
        <inertial pos="-0.000237634 -0.0389861 -0.000374679" quat="-0.0189419 0.706099 -0.0290025 0.707266" mass="0.221778" diaginertia="5.22581e-05 1.73454e-05 7.21378e-05"/>
        <joint name="r_hip_pitch_joint" class="/" pos="0 0 0" axis="0.00563828 -0.999983 0.00117569" range="-1.72227 1.21333" armature="0.00858304" damping="0.00310841" frictionloss="0.00871753"/>
        <geom name="//unnamed_geom_4" class="/" type="mesh" density="0" rgba="0.75294 0.75294 0.75294 1" mesh="r_hip_pitch_link"/>
        <geom name="//unnamed_geom_5" class="/" size="0.00042665 0.00042665 0.00042665" type="box" rgba="0.75294 0.75294 0.75294 1"/>
        <body name="r_hip_roll_link" pos="-0.000282202 -0.0364533 0.0019511" quat="1 0.000221096 0.000147546 0.000538716">
          <inertial pos="-0.00308135 -0.000240016 -0.0619412" quat="0.702517 -0.0863811 -0.076037 0.702301" mass="0.241463" diaginertia="0.000161542 5.13444e-05 0.000110976"/>
          <joint name="r_hip_roll_joint" class="/" pos="0 0 0" axis="-0.999934 0.00539141 0.0101172" range="-0.108965 0.489119" armature="0.00865973" damping="0.00395657" frictionloss="0.00969008"/>
          <geom name="//unnamed_geom_6" class="/" type="mesh" density="0" rgba="0.75294 0.75294 0.75294 1" mesh="r_hip_roll_link"/>
          <geom name="//unnamed_geom_7" class="/" size="0.00042665 0.00042665 0.00042665" type="box" rgba="0.75294 0.75294 0.75294 1"/>
          <geom name="//unnamed_geom_8" class="reward_collision_sphere" size="0.034132"/>
          <body name="r_thigh_link" pos="-0.00109319 -8.3511e-05 -0.0665306" quat="1 -0.000212143 -0.0006288 -8.6834e-05">
            <inertial pos="0.00120848 0.00042897 -0.0453014" quat="0.737255 0.675595 0.00110814 0.00492151" mass="0.0707724" diaginertia="6.07542e-05 1.78739e-05 5.26163e-05"/>
            <joint name="r_thigh_joint" class="/" pos="0 0 0" axis="-0.00051022 -0.00110301 -0.999999" stiffness="0.00875678" range="-0.35896 0.621997" armature="0.00869179" damping="0.0160381" frictionloss="0.00830648"/>
            <geom name="//unnamed_geom_9" class="/" type="mesh" density="0" rgba="0.75294 0.75294 0.75294 1" mesh="r_thigh_link"/>
            <geom name="//unnamed_geom_10" class="/" size="0.00042665 0.00042665 0.00042665" type="box" rgba="0.75294 0.75294 0.75294 1"/>
            <body name="r_calf_link" pos="-0.00215309 -0.00352986 -0.0662843" quat="0.947662 -0.000158945 0.319274 3.89814e-06">
              <inertial pos="-0.00338638 -0.000664463 -0.0677348" quat="0.999986 -0.00344262 0.00074531 0.00405135" mass="0.490989" diaginertia="0.00167653 0.000645888 0.00015289"/>
              <joint name="r_calf_joint" class="/" pos="0 0 0" axis="-0.00973179 -0.999932 0.00639517" range="-1.65112 0.703793" armature="0.00853158" damping="0.00156765" frictionloss="0.00824607"/>
              <geom name="//unnamed_geom_11" class="/" type="mesh" density="0" rgba="0.75294 0.75294 0.75294 1" mesh="r_calf_link"/>
              <geom name="//unnamed_geom_12" class="/" size="0.00042665 0.00042665 0.00042665" type="box" rgba="0.75294 0.75294 0.75294 1"/>
              <geom name="//unnamed_geom_13" class="reward_collision_sphere" size="0.034132"/>
              <body name="r_ankle_pitch_link" pos="-0.000515745 -0.00169104 -0.141664" quat="0.979938 -0.00010852 -0.199296 0.00127525">
                <inertial pos="0.00127252 0.00274274 -0.00272474" quat="0.00155464 0.711992 -0.00848649 0.702134" mass="0.111891" diaginertia="0.000147114 4.06394e-05 0.000111124"/>
                <joint name="r_ankle_pitch_joint" class="/" pos="0 0 0" axis="0.0104571 -0.999921 -0.00701521" range="-1.35465 0.505153" armature="0.00745191" damping="0.00403364" frictionloss="0.00868882"/>
                <geom name="//unnamed_geom_14" class="/" type="mesh" density="0" rgba="0.75294 0.75294 0.75294 1" mesh="r_ankle_pitch_link"/>
                <geom name="//unnamed_geom_15" class="/" size="0.0332787 0.034132 0.0213325" type="box" rgba="0.75294 0.75294 0.75294 1"/>
                <body name="r_ankle_roll_link" pos="0.0658478 0.00501489 0.0007691" quat="1 4.59225e-05 0.00031197 0.000458675">
                  <inertial pos="-0.0231807 -0.000726064 -0.0125042" quat="0.560718 0.430629 0.431773 0.560113" mass="0.317582" diaginertia="0.000550112 0.000194759 0.000243766"/>
                  <joint name="r_ankle_roll_joint" class="/" pos="0 0 0" axis="-0.999985 0.00419184 -0.0034908" stiffness="0.00865986" range="-0.137231 0.207083" armature="0.00798064" damping="0" frictionloss="0.0082926"/>
                  <geom name="//unnamed_geom_16" class="/" type="mesh" density="0" rgba="0.75294 0.75294 0.75294 1" mesh="r_ankle_roll_link"/>
                  <geom name="//unnamed_geom_17" class="/" type="mesh" rgba="0.75294 0.75294 0.75294 1" mesh="r_ankle_roll_link"/>
                  <geom name="right_foot" class="foot" size="0.0647062 0.0299461 0.00421576" pos="-0.0441315 0 -0.04307"/>
                  <geom name="//unnamed_geom_19" class="reward_collision_sphere" size="0.034132" pos="-0.0432662 0 -0.0195773"/>
                  <geom name="//unnamed_geom_20" class="reward_collision_sphere" size="0.017066" pos="0.0129799 0.0143142 -0.0391546"/>
                  <geom name="//unnamed_geom_21" class="reward_collision_sphere" size="0.017066" pos="-0.103839 0.0143142 -0.0391546"/>
                  <site name="right_foot" class="foot" pos="-0.0441315 0 -0.04307" size="0.00853299"/>
                </body>
              </body>
            </body>
          </body>
        </body>
      </body>
      <body name="l_hip_pitch_link" pos="-0.000956676 0.0142812 -0.0307395" quat="0.992198 0.000860492 -0.124669 -0.000377291">
        <inertial pos="-0.00207525 0.037764 0.000271077" quat="-0.0259139 0.707632 0.0286561 0.705524" mass="0.234886" diaginertia="5.80103e-05 1.96807e-05 8.51524e-05"/>
        <joint name="l_hip_pitch_joint" class="/" pos="0 0 0" axis="-0.00563429 0.999971 0.00514137" range="-1.24812 1.69693" armature="0.00859595" damping="0" frictionloss="0.00973392"/>
        <geom name="//unnamed_geom_22" class="/" type="mesh" density="0" rgba="0.75294 0.75294 0.75294 1" mesh="l_hip_pitch_link"/>
        <geom name="//unnamed_geom_23" class="/" size="0.00042665 0.00042665 0.00042665" type="box" rgba="0.75294 0.75294 0.75294 1"/>
        <body name="l_hip_roll_link" pos="0.00142971 0.0387598 -0.000277105" quat="0.999999 -0.000673186 0.000686798 0.000388819">
          <inertial pos="-0.00201853 -0.00224529 -0.0592307" quat="0.699545 -0.074931 -0.0777193 0.706386" mass="0.241555" diaginertia="0.000161004 5.16174e-05 0.000117636"/>
          <joint name="l_hip_roll_joint" class="/" pos="0 0 0" axis="-0.999993 -0.00181961 -0.00324867" range="-0.499299 0.0580832" armature="0.00766043" damping="0.017024" frictionloss="0.00858737"/>
          <geom name="//unnamed_geom_24" class="/" type="mesh" density="0" rgba="0.75294 0.75294 0.75294 1" mesh="l_hip_roll_link"/>
          <geom name="//unnamed_geom_25" class="/" size="0.00042665 0.00042665 0.00042665" type="box" rgba="0.75294 0.75294 0.75294 1"/>
          <geom name="//unnamed_geom_26" class="reward_collision_sphere" size="0.034132"/>
          <body name="l_thigh_link" pos="-0.00285173 -0.00145227 -0.069044" quat="1 0.000413397 0.000824062 -0.000251053">
            <inertial pos="0.00020987 0.00111064 -0.0464353" quat="0.678398 0.734691 -0.00134257 0.00172579" mass="0.0671177" diaginertia="5.91519e-05 1.66477e-05 5.22295e-05"/>
            <joint name="l_thigh_joint" class="/" pos="0 0 0" axis="-0.00267688 0.000649511 -0.999996" range="-0.578802 0.293633" armature="0.00787826" damping="0" frictionloss="0.00839781"/>
            <geom name="//unnamed_geom_27" class="/" type="mesh" density="0" rgba="0.75294 0.75294 0.75294 1" mesh="l_thigh_link"/>
            <geom name="//unnamed_geom_28" class="/" size="0.00042665 0.00042665 0.00042665" type="box" rgba="0.75294 0.75294 0.75294 1"/>
            <body name="l_calf_link" pos="-0.00196962 0.000264933 -0.0682894" quat="0.947677 -5.44632e-06 0.319232 2.00227e-05">
              <inertial pos="-0.00178932 -0.000765608 -0.0664473" quat="0.99997 0.00647779 -0.00212601 0.00370935" mass="0.511178" diaginertia="0.00171691 0.000650308 0.00016228"/>
              <joint name="l_calf_joint" class="/" pos="0 0 0" axis="-0.0157332 0.999876 -0.000418209" range="-0.676104 1.66719" armature="0.00916034" damping="0" frictionloss="0.00964555"/>
              <geom name="//unnamed_geom_29" class="/" type="mesh" density="0" rgba="0.75294 0.75294 0.75294 1" mesh="l_calf_link"/>
              <geom name="//unnamed_geom_30" class="/" size="0.00042665 0.00042665 0.00042665" type="box" rgba="0.75294 0.75294 0.75294 1"/>
              <geom name="//unnamed_geom_31" class="reward_collision_sphere" size="0.034132"/>
              <body name="l_ankle_pitch_link" pos="-0.00147995 0.00317632 -0.140869" quat="0.980073 -0.000111823 -0.198637 -4.74508e-06">
                <inertial pos="0.00722776 -0.0037467 -0.00100476" quat="-0.00758737 0.707252 -0.00936793 0.706859" mass="0.107012" diaginertia="0.000147837 4.06796e-05 0.000106636"/>
                <joint name="l_ankle_pitch_joint" class="/" pos="0 0 0" axis="-0.00292981 0.999995 0.000848325" stiffness="0.00622749" range="-0.559364 1.28156" armature="0.00724492" damping="0.0123403" frictionloss="0.00771388"/>
                <geom name="//unnamed_geom_32" class="/" type="mesh" density="0" rgba="0.75294 0.75294 0.75294 1" mesh="l_ankle_pitch_link"/>
                <geom name="//unnamed_geom_33" class="/" size="0.0332787 0.034132 0.0213325" type="box" rgba="0.75294 0.75294 0.75294 1"/>
                <body name="l_ankle_roll_link" pos="0.0645919 0.00231409 -0.00158859" quat="1 -4.22058e-05 0.000203663 0.000395488">
                  <inertial pos="-0.0199545 -0.000911711 -0.0130359" quat="0.559872 0.42737 0.436495 0.559794" mass="0.329463" diaginertia="0.000564603 0.000207282 0.000261224"/>
                  <joint name="l_ankle_roll_joint" class="/" pos="0 0 0" axis="-1 -0.000130986 0.000134583" range="-0.147798 0.168083" armature="0.00838204" damping="0" frictionloss="0.00733441"/>
                  <geom name="//unnamed_geom_34" class="/" type="mesh" density="0" rgba="0.75294 0.75294 0.75294 1" mesh="l_ankle_roll_link"/>
                  <geom name="//unnamed_geom_35" class="/" type="mesh" rgba="0.75294 0.75294 0.75294 1" mesh="l_ankle_roll_link"/>
                  <geom name="left_foot" class="foot" size="0.0687804 0.0304175 0.00385897" pos="-0.0441315 0 -0.04307"/>
                  <geom name="//unnamed_geom_37" class="reward_collision_sphere" size="0.034132" pos="-0.0432662 0 -0.0195773"/>
                  <geom name="//unnamed_geom_38" class="reward_collision_sphere" size="0.017066" pos="0.0129799 -0.0143142 -0.0391546"/>
                  <geom name="//unnamed_geom_39" class="reward_collision_sphere" size="0.017066" pos="-0.103839 -0.0143142 -0.0391546"/>
                  <site name="left_foot" class="foot" pos="-0.0441315 0 -0.04307" size="0.00853299"/>
                </body>
              </body>
            </body>
          </body>
        </body>
      </body>
    </body>
  </worldbody>

  <contact>
    <pair class="/" geom1="floor" geom2="right_foot" name="//unnamed_contact_1"/>
    <pair class="/" geom1="floor" geom2="left_foot" name="//unnamed_contact_0"/>
  </contact>

  <actuator>
    <general name="r_hip_pitch_joint" class="/" joint="r_hip_pitch_joint" forcerange="-18.8515 18.8515" gainprm="17.4439" biasprm="0 -17.4439 -0.418589"/>
    <general name="r_hip_roll_joint" class="/" joint="r_hip_roll_joint" forcerange="-18.2565 18.2565" gainprm="17.4439" biasprm="0 -17.4439 -0.418589"/>
    <general name="r_thigh_joint" class="/" joint="r_thigh_joint" forcerange="-17.8128 17.8128" gainprm="17.4439" biasprm="0 -17.4439 -0.418589"/>
    <general name="r_calf_joint" class="/" joint="r_calf_joint" forcerange="-17.3578 17.3578" gainprm="17.4439" biasprm="0 -17.4439 -0.418589"/>
    <general name="r_ankle_pitch_joint" class="/" joint="r_ankle_pitch_joint" forcerange="-16.0381 16.0381" gainprm="17.4439" biasprm="0 -17.4439 -0.418589"/>
    <general name="r_ankle_roll_joint" class="/" joint="r_ankle_roll_joint" forcerange="-18.168 18.168" gainprm="17.4439" biasprm="0 -17.4439 -0.418589"/>
    <general name="l_hip_pitch_joint" class="/" joint="l_hip_pitch_joint" forcerange="-18.0283 18.0283" gainprm="17.4439" biasprm="0 -17.4439 -0.418589"/>
    <general name="l_hip_roll_joint" class="/" joint="l_hip_roll_joint" forcerange="-18.4138 18.4138" gainprm="17.4439" biasprm="0 -17.4439 -0.418589"/>
    <general name="l_thigh_joint" class="/" joint="l_thigh_joint" forcerange="-19.7774 19.7774" gainprm="17.4439" biasprm="0 -17.4439 -0.418589"/>
    <general name="l_calf_joint" class="/" joint="l_calf_joint" forcerange="-17.6351 17.6351" gainprm="17.4439" biasprm="0 -17.4439 -0.418589"/>
    <general name="l_ankle_pitch_joint" class="/" joint="l_ankle_pitch_joint" forcerange="-19.766 19.766" gainprm="17.4439" biasprm="0 -17.4439 -0.418589"/>
    <general name="l_ankle_roll_joint" class="/" joint="l_ankle_roll_joint" forcerange="-18.1111 18.1111" gainprm="17.4439" biasprm="0 -17.4439 -0.418589"/>
  </actuator>

  <sensor>
    <gyro site="imu" name="imu_angular_velocity"/>
    <velocimeter site="imu" name="imu_linear_velocity"/>
    <framelinvel objtype="site" objname="left_foot" name="left_foot_global_linear_velocity"/>
    <framelinvel objtype="site" objname="right_foot" name="right_foot_global_linear_velocity"/>
  </sensor>

  <keyframe>
    <key name="home" qpos="0 0 0.291 1 0 0 0 0.4 0 0 -0.8 0.4 0 -0.4 0 0 0.8 -0.4 0"/>
  </keyframe>
</mujoco>
