<mujoco model="pi_12dof_release_v1">
  <compiler angle="radian" assetdir="assets" balanceinertia="true" inertiafromgeom="false"/>

  <option timestep="0.005" density="1.2" viscosity="2e-05"/>

  <size nkey="1"/>

  <visual>
    <quality shadowsize="8192"/>
    <map shadowclip="0.5"/>
  </visual>

  <default>
    <default class="/">
      <joint armature="0.01" damping="0.01" frictionloss="0.01"/>
      <geom contype="0" conaffinity="0" group="1" solref="-1000 -80"/>
      <site size="0.01 0.005 0.005" group="5"/>
      <general forcelimited="true" biastype="affine" gainprm="20" biasprm="0 -20 -0.5"/>
      <default class="foot">
        <geom size="0.0845 0.036 0.005" type="box" condim="6" group="4" priority="1" friction="0.9 0.2 0.2" solimp="0.015 1 0.005"/>
      </default>
      <default class="reward_collision_sphere">
        <geom group="5" rgba="1 0 0 1"/>
      </default>
    </default>
  </default>

  <asset>
    <texture type="skybox" colorspace="auto" name="//unnamed_texture_0" builtin="gradient" rgb1="0.95 0.95 0.95" rgb2="0.95 0.95 0.95" width="100" height="600"/>
    <texture type="2d" colorspace="auto" name="texplane" builtin="checker" rgb1="0.345 0.575 0.748" rgb2="0.345 0.575 0.748" markrgb="1 1 1" width="512" height="512"/>
    <material name="MatPlane" class="/" texture="texplane" texuniform="true" texrepeat="2 2" specular="0.9"/>
    <mesh name="baselink_1" class="/" file="baselink_1.STL"/>
    <mesh name="r_hip_pitch_link" class="/" file="r_hip_pitch_link.STL"/>
    <mesh name="r_hip_roll_link" class="/" file="r_hip_roll_link.STL"/>
    <mesh name="r_thigh_link" class="/" file="r_thigh_link.STL"/>
    <mesh name="r_calf_link" class="/" file="r_calf_link.STL"/>
    <mesh name="r_ankle_pitch_link" class="/" file="r_ankle_pitch_link.STL"/>
    <mesh name="r_ankle_roll_link" class="/" file="r_ankle_roll_link.STL"/>
    <mesh name="l_hip_pitch_link" class="/" file="l_hip_pitch_link.STL"/>
    <mesh name="l_hip_roll_link" class="/" file="l_hip_roll_link.STL"/>
    <mesh name="l_thigh_link" class="/" file="l_thigh_link.STL"/>
    <mesh name="l_calf_link" class="/" file="l_calf_link.STL"/>
    <mesh name="l_ankle_pitch_link" class="/" file="l_ankle_pitch_link.STL"/>
    <mesh name="l_ankle_roll_link" class="/" file="l_ankle_roll_link.STL"/>
  </asset>

  <worldbody>
    <geom name="floor" class="/" size="100 100 0.125" type="plane" group="0" material="MatPlane"/>
    <light name="toplight_shadow" class="/" pos="0 0 5" dir="0.0990148 0.0990148 -0.990148" type="directional" ambient="0.04 0.04 0.04" diffuse="0.55 0.55 0.55" specular="0.12 0.12 0.12"/>
    <light name="toplight_fill" class="/" pos="0 0 5" dir="0.0990148 0.0990148 -0.990148" type="directional" castshadow="false" ambient="0.04 0.04 0.04" diffuse="0.3 0.3 0.3" specular="0.08 0.08 0.08"/>
    <body name="trunk" pos="-0.00231352 0.000766299 0.014659" quat="0.999977 0.0024682 0.00634967 0.000309648">
      <inertial pos="0.00151259 -0.011859 0.0188463" quat="0.727976 0.0522726 -0.00750255 0.683566" mass="1.05686" diaginertia="0.0221413 0.00231062 4.61455e-05"/>
      <joint name="//unnamed_joint_0" type="free"/>
      <geom name="//unnamed_geom_1" class="/" type="mesh" density="0" rgba="1 1 1 1" mesh="baselink_1"/>
      <geom name="//unnamed_geom_2" class="/" size="0.0405835 0.0405835 0.0405835" pos="0 0 0.0339803" type="box" rgba="1 1 1 1"/>
      <geom name="//unnamed_geom_3" class="reward_collision_sphere" size="0.0446418" pos="0 0 0.0297328"/>
      <site name="imu" class="/" pos="-0.0171327 -0.0435963 0.0561278" size="0.00811669"/>
      <camera name="track" class="/" pos="0 -1.57578 0" quat="0.707107 0.707107 0 0" mode="trackcom"/>
      <camera name="ego_camera" class="/" pos="0.0916774 0 0.0764557" quat="-0.5 -0.5 0.5 0.5"/>
      <body name="r_hip_pitch_link" pos="-0.00137045 -0.0240276 -0.0203761" quat="0.992166 -0.000172175 -0.124923 -0.000357789">
        <inertial pos="0.0142111 -0.0435288 0.0140939" quat="0.037229 0.685095 -0.0641348 0.724669" mass="0.21617" diaginertia="0.000284391 3.49782e-05 1.26324e-06"/>
        <joint name="r_hip_pitch_joint" class="/" pos="0 0 0" axis="0.00433501 -0.999527 -0.03043" stiffness="0.0060576" range="-1.81656 1.33966" armature="0.00774361" damping="0.0139507" frictionloss="0.0069178"/>
        <geom name="//unnamed_geom_4" class="/" type="mesh" density="0" rgba="0.75294 0.75294 0.75294 1" mesh="r_hip_pitch_link"/>
        <geom name="//unnamed_geom_5" class="/" size="0.000405835 0.000405835 0.000405835" type="box" rgba="0.75294 0.75294 0.75294 1"/>
        <body name="r_hip_roll_link" pos="0.0118872 -0.0517325 -0.0110196" quat="1 0.000209292 6.82771e-05 -0.000408609">
          <inertial pos="0.000464934 0.000325234 -0.0249873" quat="0.71396 -0.10194 -0.081165 0.687954" mass="0.228074" diaginertia="0.00100675 9.74406e-05 2.35173e-06"/>
          <joint name="r_hip_roll_joint" class="/" pos="0 0 0" axis="-0.998654 0.0517975 -0.00262993" stiffness="0.00206707" range="-0.0907022 0.501991" armature="0.0142608" damping="0.00333653" frictionloss="0.00445635"/>
          <geom name="//unnamed_geom_6" class="/" type="mesh" density="0" rgba="0.75294 0.75294 0.75294 1" mesh="r_hip_roll_link"/>
          <geom name="//unnamed_geom_7" class="/" size="0.000405835 0.000405835 0.000405835" type="box" rgba="0.75294 0.75294 0.75294 1"/>
          <geom name="//unnamed_geom_8" class="reward_collision_sphere" size="0.0324668"/>
          <body name="r_thigh_link" pos="-0.00478879 0.000974273 -0.0296926" quat="1 -0.000262833 0.000171418 0.000682406">
            <inertial pos="0.0158289 0.014894 -0.0207316" quat="0.737809 0.675 -0.00287302 -0.00209671" mass="0.0610224" diaginertia="0.000400253 2.82528e-05 7.97994e-07"/>
            <joint name="r_thigh_joint" class="/" pos="0 0 0" axis="0.0085413 -0.0116861 -0.999895" range="-0.147671 0.353671" armature="0.0135408" damping="0" frictionloss="0.00935888"/>
            <geom name="//unnamed_geom_9" class="/" type="mesh" density="0" rgba="0.75294 0.75294 0.75294 1" mesh="r_thigh_link"/>
            <geom name="//unnamed_geom_10" class="/" size="0.000405835 0.000405835 0.000405835" type="box" rgba="0.75294 0.75294 0.75294 1"/>
            <body name="r_calf_link" pos="0.00843924 0.00137867 -0.0343519" quat="0.94949 -0.00152238 0.313761 -0.00450938">
              <inertial pos="0.00600489 6.19519e-06 -0.0273324" quat="0.997111 -0.0420668 -0.0631722 0.00317878" mass="0.377313" diaginertia="0.00982844 0.00113195 2.48851e-06"/>
              <joint name="r_calf_joint" class="/" pos="0 0 0" axis="0.0229495 -0.999735 -0.00156485" stiffness="0.0254636" range="-1.65924 0.487198" armature="0.00838792" damping="0.0133259" frictionloss="0.0074615"/>
              <geom name="//unnamed_geom_11" class="/" type="mesh" density="0" rgba="0.75294 0.75294 0.75294 1" mesh="r_calf_link"/>
              <geom name="//unnamed_geom_12" class="/" size="0.000405835 0.000405835 0.000405835" type="box" rgba="0.75294 0.75294 0.75294 1"/>
              <geom name="//unnamed_geom_13" class="reward_collision_sphere" size="0.0324668"/>
              <body name="r_ankle_pitch_link" pos="-0.000548333 0.00878198 -0.0582678" quat="0.979987 -0.00336024 -0.199029 0.00100776">
                <inertial pos="0.0131746 0.00286991 0.00542123" quat="-0.00257445 0.691488 0.00676869 0.722352" mass="0.0799968" diaginertia="0.000823162 7.61033e-05 1.49236e-06"/>
                <joint name="r_ankle_pitch_joint" class="/" pos="0 0 0" axis="0.0128786 -0.998908 0.0449102" range="-1.13292 0.50631" armature="0.010659" damping="0" frictionloss="0.0069511"/>
                <geom name="//unnamed_geom_14" class="/" type="mesh" density="0" rgba="0.75294 0.75294 0.75294 1" mesh="r_ankle_pitch_link"/>
                <geom name="//unnamed_geom_15" class="/" size="0.0316551 0.0324668 0.0202917" type="box" rgba="0.75294 0.75294 0.75294 1"/>
                <body name="r_ankle_roll_link" pos="0.106354 0.000879027 -0.000283298" quat="0.999998 0.000166951 -0.000945032 -0.00159476">
                  <inertial pos="-0.0246517 0.0134557 -0.0175753" quat="0.58121 0.420096 0.481773 0.503596" mass="0.335622" diaginertia="0.0036543 0.000307803 5.10694e-06"/>
                  <joint name="r_ankle_roll_joint" class="/" pos="0 0 0" axis="-0.999999 0.00108945 0.00103576" range="0.161259 -0.0241539" armature="0.0132483" damping="0.0387925" frictionloss="0.0137052"/>
                  <geom name="//unnamed_geom_16" class="/" type="mesh" density="0" rgba="0.75294 0.75294 0.75294 1" mesh="r_ankle_roll_link"/>
                  <geom name="//unnamed_geom_17" class="/" type="mesh" rgba="0.75294 0.75294 0.75294 1" mesh="r_ankle_roll_link"/>
                  <geom name="right_foot" class="foot" size="0.0904063 0.032862 0.00624215" pos="-0.0623406 0 -0.0186892"/>
                  <geom name="//unnamed_geom_19" class="reward_collision_sphere" size="0.0324668" pos="-0.0611182 0 -0.00849507"/>
                  <geom name="//unnamed_geom_20" class="reward_collision_sphere" size="0.0162334" pos="0.0183355 0.0157578 -0.0169901"/>
                  <geom name="//unnamed_geom_21" class="reward_collision_sphere" size="0.0162334" pos="-0.146684 0.0157578 -0.0169901"/>
                  <site name="right_foot" class="foot" pos="-0.0623406 0 -0.0186892" size="0.00811669"/>
                </body>
              </body>
            </body>
          </body>
        </body>
      </body>
      <body name="l_hip_pitch_link" pos="-8.58452e-05 0.0283178 -0.0243177" quat="0.991888 -0.000504836 -0.127112 0.000780977">
        <inertial pos="0.00624158 0.0559859 0.0146115" quat="-0.00864081 0.712369 0.0350212 0.700878" mass="0.236663" diaginertia="0.000424644 3.25108e-05 1.75705e-06"/>
        <joint name="l_hip_pitch_joint" class="/" pos="0 0 0" axis="0.061659 0.99807 0.00739188" stiffness="0.0525572" range="-0.959201 1.91146" armature="0.00827594" damping="0.0615196" frictionloss="0.00484743"/>
        <geom name="//unnamed_geom_22" class="/" type="mesh" density="0" rgba="0.75294 0.75294 0.75294 1" mesh="l_hip_pitch_link"/>
        <geom name="//unnamed_geom_23" class="/" size="0.000405835 0.000405835 0.000405835" type="box" rgba="0.75294 0.75294 0.75294 1"/>
        <body name="l_hip_roll_link" pos="-0.000461379 0.0571704 -0.014319" quat="0.999986 0.00239719 0.0028258 -0.00375296">
          <inertial pos="-0.0179577 0.0107696 -0.010576" quat="0.699265 -0.0756554 -0.0767065 0.706697" mass="0.168042" diaginertia="0.000604005 6.53019e-05 1.24529e-06"/>
          <joint name="l_hip_roll_joint" class="/" pos="0 0 0" axis="-0.999995 0.000245354 -0.0032173" stiffness="0.0118856" range="-0.499808 0.291362" armature="0.0118523" damping="0" frictionloss="0.00823977"/>
          <geom name="//unnamed_geom_24" class="/" type="mesh" density="0" rgba="0.75294 0.75294 0.75294 1" mesh="l_hip_roll_link"/>
          <geom name="//unnamed_geom_25" class="/" size="0.000405835 0.000405835 0.000405835" type="box" rgba="0.75294 0.75294 0.75294 1"/>
          <geom name="//unnamed_geom_26" class="reward_collision_sphere" size="0.0324668"/>
          <body name="l_thigh_link" pos="0.00890515 0.00043339 -0.0202144" quat="0.999984 4.60645e-05 -0.000473819 0.00561756">
            <inertial pos="0.0143067 -0.0109972 -0.00528734" quat="0.698307 0.713528 -0.00269456 0.0569003" mass="0.0673619" diaginertia="0.000390262 3.56465e-05 8.27087e-07"/>
            <joint name="l_thigh_joint" class="/" pos="0 0 0" axis="0.00100313 0.00067301 -0.999999" stiffness="0.0131925" range="-0.594328 0.345607" armature="0.0104562" damping="0.0276235" frictionloss="0.0020001"/>
            <geom name="//unnamed_geom_27" class="/" type="mesh" density="0" rgba="0.75294 0.75294 0.75294 1" mesh="l_thigh_link"/>
            <geom name="//unnamed_geom_28" class="/" size="0.000405835 0.000405835 0.000405835" type="box" rgba="0.75294 0.75294 0.75294 1"/>
            <body name="l_calf_link" pos="-0.0156736 -0.00144713 -0.0427483" quat="0.947639 -0.000109761 0.319345 -9.27545e-05">
              <inertial pos="0.0119588 0.0119731 -0.0324869" quat="0.998102 -0.0364704 0.0241431 -0.0433505" mass="0.425962" diaginertia="0.00647995 0.000867208 1.77139e-06"/>
              <joint name="l_calf_joint" class="/" pos="0 0 0" axis="0.0411615 0.999146 0.00366041" stiffness="0.0597495" range="-0.398648 1.38188" armature="0.00654459" damping="0.0555627" frictionloss="0.0042619"/>
              <geom name="//unnamed_geom_29" class="/" type="mesh" density="0" rgba="0.75294 0.75294 0.75294 1" mesh="l_calf_link"/>
              <geom name="//unnamed_geom_30" class="/" size="0.000405835 0.000405835 0.000405835" type="box" rgba="0.75294 0.75294 0.75294 1"/>
              <geom name="//unnamed_geom_31" class="reward_collision_sphere" size="0.0324668"/>
              <body name="l_ankle_pitch_link" pos="0.00234986 -0.00508726 -0.0553537" quat="0.98015 -0.000173214 -0.198254 -0.00106366">
                <inertial pos="-0.00101283 0.0074769 0.0129476" quat="0.0305767 0.725827 0.0245999 0.686757" mass="0.119328" diaginertia="0.000755976 7.13296e-05 1.6741e-06"/>
                <joint name="l_ankle_pitch_joint" class="/" pos="0 0 0" axis="-0.000318186 0.999991 -0.00428864" range="-0.311605 1.28308" armature="0.0113016" damping="0.0815886" frictionloss="0.0127259"/>
                <geom name="//unnamed_geom_32" class="/" type="mesh" density="0" rgba="0.75294 0.75294 0.75294 1" mesh="l_ankle_pitch_link"/>
                <geom name="//unnamed_geom_33" class="/" size="0.0316551 0.0324668 0.0202917" type="box" rgba="0.75294 0.75294 0.75294 1"/>
                <body name="l_ankle_roll_link" pos="0.105738 -0.0109448 0.0105872" quat="0.999969 -0.00665167 -0.00384328 0.00185525">
                  <inertial pos="-0.0345571 -0.0012953 -0.00616834" quat="0.50996 0.450824 0.424299 0.597218" mass="0.256876" diaginertia="0.00284205 0.000249939 4.07112e-06"/>
                  <joint name="l_ankle_roll_joint" class="/" pos="0 0 0" axis="-0.999979 0.00491387 0.00431742" stiffness="0.0195159" range="-0.211025 0.465534" armature="0.00841173" damping="0.0562275" frictionloss="0.0112015"/>
                  <geom name="//unnamed_geom_34" class="/" type="mesh" density="0" rgba="0.75294 0.75294 0.75294 1" mesh="l_ankle_roll_link"/>
                  <geom name="//unnamed_geom_35" class="/" type="mesh" rgba="0.75294 0.75294 0.75294 1" mesh="l_ankle_roll_link"/>
                  <geom name="left_foot" class="foot" size="0.102147 0.0358437 0.00565002" pos="-0.0623406 0 -0.0186892"/>
                  <geom name="//unnamed_geom_37" class="reward_collision_sphere" size="0.0324668" pos="-0.0611182 0 -0.00849507"/>
                  <geom name="//unnamed_geom_38" class="reward_collision_sphere" size="0.0162334" pos="0.0183355 -0.0157578 -0.0169901"/>
                  <geom name="//unnamed_geom_39" class="reward_collision_sphere" size="0.0162334" pos="-0.146684 -0.0157578 -0.0169901"/>
                  <site name="left_foot" class="foot" pos="-0.0623406 0 -0.0186892" size="0.00811669"/>
                </body>
              </body>
            </body>
          </body>
        </body>
      </body>
    </body>
  </worldbody>

  <contact>
    <pair class="/" geom1="floor" geom2="right_foot" name="//unnamed_contact_1"/>
    <pair class="/" geom1="floor" geom2="left_foot" name="//unnamed_contact_0"/>
  </contact>

  <actuator>
    <general name="r_hip_pitch_joint" class="/" joint="r_hip_pitch_joint" forcerange="-9.07891 9.07891" gainprm="22.6036" biasprm="0 -22.6036 -0.537608"/>
    <general name="r_hip_roll_joint" class="/" joint="r_hip_roll_joint" forcerange="-26.8205 26.8205" gainprm="22.6036" biasprm="0 -22.6036 -0.537608"/>
    <general name="r_thigh_joint" class="/" joint="r_thigh_joint" forcerange="-16.5918 16.5918" gainprm="22.6036" biasprm="0 -22.6036 -0.537608"/>
    <general name="r_calf_joint" class="/" joint="r_calf_joint" forcerange="-6.97175 6.97175" gainprm="22.6036" biasprm="0 -22.6036 -0.537608"/>
    <general name="r_ankle_pitch_joint" class="/" joint="r_ankle_pitch_joint" forcerange="-21.4806 21.4806" gainprm="22.6036" biasprm="0 -22.6036 -0.537608"/>
    <general name="r_ankle_roll_joint" class="/" joint="r_ankle_roll_joint" forcerange="-26.7261 26.7261" gainprm="22.6036" biasprm="0 -22.6036 -0.537608"/>
    <general name="l_hip_pitch_joint" class="/" joint="l_hip_pitch_joint" forcerange="-16.9862 16.9862" gainprm="22.6036" biasprm="0 -22.6036 -0.537608"/>
    <general name="l_hip_roll_joint" class="/" joint="l_hip_roll_joint" forcerange="-14.9491 14.9491" gainprm="22.6036" biasprm="0 -22.6036 -0.537608"/>
    <general name="l_thigh_joint" class="/" joint="l_thigh_joint" forcerange="-11.5937 11.5937" gainprm="22.6036" biasprm="0 -22.6036 -0.537608"/>
    <general name="l_calf_joint" class="/" joint="l_calf_joint" forcerange="-18.9474 18.9474" gainprm="22.6036" biasprm="0 -22.6036 -0.537608"/>
    <general name="l_ankle_pitch_joint" class="/" joint="l_ankle_pitch_joint" forcerange="-11.787 11.787" gainprm="22.6036" biasprm="0 -22.6036 -0.537608"/>
    <general name="l_ankle_roll_joint" class="/" joint="l_ankle_roll_joint" forcerange="-16.6849 16.6849" gainprm="22.6036" biasprm="0 -22.6036 -0.537608"/>
  </actuator>

  <sensor>
    <gyro site="imu" name="imu_angular_velocity"/>
    <velocimeter site="imu" name="imu_linear_velocity"/>
    <framelinvel objtype="site" objname="left_foot" name="left_foot_global_linear_velocity"/>
    <framelinvel objtype="site" objname="right_foot" name="right_foot_global_linear_velocity"/>
  </sensor>

  <keyframe>
    <key name="home" qpos="0 0 0.291 1 0 0 0 0.4 0 0 -0.8 0.4 0 -0.4 0 0 0.8 -0.4 0"/>
  </keyframe>
</mujoco>
