<mujoco model="pi_12dof_release_v1">
  <compiler angle="radian" assetdir="assets" balanceinertia="true" inertiafromgeom="false"/>

  <option timestep="0.005" density="1.2" viscosity="2e-05"/>

  <size nkey="1"/>

  <visual>
    <quality shadowsize="8192"/>
    <map shadowclip="0.5"/>
  </visual>

  <default>
    <default class="/">
      <joint armature="0.01" damping="0.01" frictionloss="0.01"/>
      <geom contype="0" conaffinity="0" group="1" solref="-1000 -80"/>
      <site size="0.01 0.005 0.005" group="5"/>
      <general forcelimited="true" biastype="affine" gainprm="20" biasprm="0 -20 -0.5"/>
      <default class="foot">
        <geom size="0.0845 0.036 0.005" type="box" condim="6" group="4" priority="1" friction="0.9 0.2 0.2" solimp="0.015 1 0.005"/>
      </default>
      <default class="reward_collision_sphere">
        <geom group="5" rgba="1 0 0 1"/>
      </default>
    </default>
  </default>

  <asset>
    <texture type="skybox" colorspace="auto" name="//unnamed_texture_0" builtin="gradient" rgb1="0.95 0.95 0.95" rgb2="0.95 0.95 0.95" width="100" height="600"/>
    <texture type="2d" colorspace="auto" name="texplane" builtin="checker" rgb1="0.345 0.575 0.748" rgb2="0.345 0.575 0.748" markrgb="1 1 1" width="512" height="512"/>
    <material name="MatPlane" class="/" texture="texplane" texuniform="true" texrepeat="2 2" specular="0.9"/>
    <mesh name="baselink_1" class="/" file="baselink_1.STL"/>
    <mesh name="r_hip_pitch_link" class="/" file="r_hip_pitch_link.STL"/>
    <mesh name="r_hip_roll_link" class="/" file="r_hip_roll_link.STL"/>
    <mesh name="r_thigh_link" class="/" file="r_thigh_link.STL"/>
    <mesh name="r_calf_link" class="/" file="r_calf_link.STL"/>
    <mesh name="r_ankle_pitch_link" class="/" file="r_ankle_pitch_link.STL"/>
    <mesh name="r_ankle_roll_link" class="/" file="r_ankle_roll_link.STL"/>
    <mesh name="l_hip_pitch_link" class="/" file="l_hip_pitch_link.STL"/>
    <mesh name="l_hip_roll_link" class="/" file="l_hip_roll_link.STL"/>
    <mesh name="l_thigh_link" class="/" file="l_thigh_link.STL"/>
    <mesh name="l_calf_link" class="/" file="l_calf_link.STL"/>
    <mesh name="l_ankle_pitch_link" class="/" file="l_ankle_pitch_link.STL"/>
    <mesh name="l_ankle_roll_link" class="/" file="l_ankle_roll_link.STL"/>
  </asset>

  <worldbody>
    <geom name="floor" class="/" size="100 100 0.125" type="plane" group="0" material="MatPlane"/>
    <light name="toplight_shadow" class="/" pos="0 0 5" dir="0.0990148 0.0990148 -0.990148" type="directional" ambient="0.04 0.04 0.04" diffuse="0.55 0.55 0.55" specular="0.12 0.12 0.12"/>
    <light name="toplight_fill" class="/" pos="0 0 5" dir="0.0990148 0.0990148 -0.990148" type="directional" castshadow="false" ambient="0.04 0.04 0.04" diffuse="0.3 0.3 0.3" specular="0.08 0.08 0.08"/>
    <body name="trunk" pos="0.000334924 -0.000193981 0.000931752" quat="1 9.37677e-05 4.78545e-05 -3.95892e-05">
      <inertial pos="0.00300592 -0.00274003 0.0479907" quat="0.696138 0.00859532 0.0112415 0.717768" mass="2.09645" diaginertia="0.0142686 0.00175049 0.00911423"/>
      <joint name="//unnamed_joint_0" type="free"/>
      <geom name="//unnamed_geom_1" class="/" type="mesh" density="0" rgba="1 1 1 1" mesh="baselink_1"/>
      <geom name="//unnamed_geom_2" class="/" size="0.0497931 0.0497931 0.0497931" pos="0 0 0.0938224" type="box" rgba="1 1 1 1"/>
      <geom name="//unnamed_geom_3" class="reward_collision_sphere" size="0.0547725" pos="0 0 0.0820946"/>
      <site name="imu" class="/" pos="-0.00269836 0.00166312 0.00162326" size="0.00995863"/>
      <camera name="track" class="/" pos="0 -1.44896 0" quat="0.707107 0.707107 0 0" mode="trackcom"/>
      <camera name="ego_camera" class="/" pos="0.0817747 0 0.211101" quat="-0.5 -0.5 0.5 0.5"/>
      <body name="r_hip_pitch_link" pos="-0.00133188 -0.0170963 -0.038867" quat="0.992245 2.34442e-05 -0.124295 0.000189367">
        <inertial pos="0.00135865 -0.0422963 0.000823026" quat="-0.0260109 0.711132 -0.0345501 0.701728" mass="0.363116" diaginertia="0.000165782 1.97092e-05 0.000183183"/>
        <joint name="r_hip_pitch_joint" class="/" pos="0 0 0" axis="0.002562 -0.999967 0.00768139" range="-1.74817 1.24036" armature="0.00975341" damping="0.0230501" frictionloss="0.0109391"/>
        <geom name="//unnamed_geom_4" class="/" type="mesh" density="0" rgba="0.75294 0.75294 0.75294 1" mesh="r_hip_pitch_link"/>
        <geom name="//unnamed_geom_5" class="/" size="0.000497931 0.000497931 0.000497931" type="box" rgba="0.75294 0.75294 0.75294 1"/>
        <body name="r_hip_roll_link" pos="0.00109588 -0.0403651 -0.000538125" quat="0.999999 0.00083625 0.000564784 0.000438644">
          <inertial pos="-0.00112467 0.00185901 -0.0704926" quat="0.706361 -0.0743317 -0.0840308 0.698905" mass="0.379806" diaginertia="0.0005031 5.68647e-05 0.000283763"/>
          <joint name="r_hip_roll_joint" class="/" pos="0 0 0" axis="-0.999995 -0.00191127 0.00251949" range="-0.118007 0.505622" armature="0.0104646" damping="0.0148405" frictionloss="0.00968702"/>
          <geom name="//unnamed_geom_6" class="/" type="mesh" density="0" rgba="0.75294 0.75294 0.75294 1" mesh="r_hip_roll_link"/>
          <geom name="//unnamed_geom_7" class="/" size="0.000497931 0.000497931 0.000497931" type="box" rgba="0.75294 0.75294 0.75294 1"/>
          <geom name="//unnamed_geom_8" class="reward_collision_sphere" size="0.0398345"/>
          <body name="r_thigh_link" pos="-0.000303845 -0.000827786 -0.08019" quat="1 7.29302e-05 7.94963e-05 -0.00021649">
            <inertial pos="-0.00113626 0.000471347 -0.0569043" quat="0.735096 0.677951 0.0016474 0.00361391" mass="0.109975" diaginertia="0.00019227 1.93561e-05 0.000127702"/>
            <joint name="r_thigh_joint" class="/" pos="0 0 0" axis="-0.00450457 0.00161332 -0.999989" range="-0.344669 0.550059" armature="0.0106241" damping="0" frictionloss="0.0110053"/>
            <geom name="//unnamed_geom_9" class="/" type="mesh" density="0" rgba="0.75294 0.75294 0.75294 1" mesh="r_thigh_link"/>
            <geom name="//unnamed_geom_10" class="/" size="0.000497931 0.000497931 0.000497931" type="box" rgba="0.75294 0.75294 0.75294 1"/>
            <body name="r_calf_link" pos="-0.00245269 -0.00197992 -0.0816382" quat="0.947667 0.000120724 0.319261 0.000122613">
              <inertial pos="-8.6567e-05 -0.00184454 -0.0809658" quat="0.999937 0.000145141 -0.00710697 0.00869918" mass="0.810746" diaginertia="0.00537397 0.000698213 0.000380849"/>
              <joint name="r_calf_joint" class="/" pos="0 0 0" axis="-0.00801522 -0.99991 -0.0107745" stiffness="0.00250597" range="-1.63784 0.646404" armature="0.0100521" damping="0.0127767" frictionloss="0.0108748"/>
              <geom name="//unnamed_geom_11" class="/" type="mesh" density="0" rgba="0.75294 0.75294 0.75294 1" mesh="r_calf_link"/>
              <geom name="//unnamed_geom_12" class="/" size="0.000497931 0.000497931 0.000497931" type="box" rgba="0.75294 0.75294 0.75294 1"/>
              <geom name="//unnamed_geom_13" class="reward_collision_sphere" size="0.0398345"/>
              <body name="r_ankle_pitch_link" pos="0.00136032 -0.000840258 -0.166085" quat="0.980069 9.22882e-07 -0.198658 -2.90533e-06">
                <inertial pos="0.00454873 0.00272338 0.00170198" quat="-0.00144024 0.707551 0.00128088 0.706659" mass="0.171734" diaginertia="0.000472501 4.42548e-05 0.00026575"/>
                <joint name="r_ankle_pitch_joint" class="/" pos="0 0 0" axis="-0.00298042 -0.999992 0.00251185" range="-1.30298 0.462601" armature="0.0105804" damping="0.0123489" frictionloss="0.0107932"/>
                <geom name="//unnamed_geom_14" class="/" type="mesh" density="0" rgba="0.75294 0.75294 0.75294 1" mesh="r_ankle_pitch_link"/>
                <geom name="//unnamed_geom_15" class="/" size="0.0388386 0.0398345 0.0248966" type="box" rgba="0.75294 0.75294 0.75294 1"/>
                <body name="r_ankle_roll_link" pos="0.0844037 0.00121492 0.00189097" quat="1 3.89722e-05 -0.000122924 0.000111198">
                  <inertial pos="-0.0260011 0.000200393 -0.0165716" quat="0.555855 0.432067 0.435436 0.561016" mass="0.527162" diaginertia="0.00181634 0.000212869 0.000647964"/>
                  <joint name="r_ankle_roll_joint" class="/" pos="0 0 0" axis="-0.999937 0.0053542 -0.00982696" range="-0.10449 0.173272" armature="0.00967042" damping="0.00833653" frictionloss="0.00948688"/>
                  <geom name="//unnamed_geom_16" class="/" type="mesh" density="0" rgba="0.75294 0.75294 0.75294 1" mesh="r_ankle_roll_link"/>
                  <geom name="//unnamed_geom_17" class="/" type="mesh" rgba="0.75294 0.75294 0.75294 1" mesh="r_ankle_roll_link"/>
                  <geom name="right_foot" class="foot" size="0.0850818 0.038167 0.00498217" pos="-0.0556068 0 -0.0516023"/>
                  <geom name="//unnamed_geom_19" class="reward_collision_sphere" size="0.0398345" pos="-0.0545164 0 -0.0234556"/>
                  <geom name="//unnamed_geom_20" class="reward_collision_sphere" size="0.0199173" pos="0.0163549 0.0144896 -0.0469112"/>
                  <geom name="//unnamed_geom_21" class="reward_collision_sphere" size="0.0199173" pos="-0.130839 0.0144896 -0.0469112"/>
                  <site name="right_foot" class="foot" pos="-0.0556068 0 -0.0516023" size="0.00995863"/>
                </body>
              </body>
            </body>
          </body>
        </body>
      </body>
      <body name="l_hip_pitch_link" pos="0.00155503 0.0162125 -0.0368703" quat="0.99221 -6.90373e-05 -0.12458 0.000218366">
        <inertial pos="0.000713987 0.0396578 -0.00029839" quat="-0.0376807 0.704848 0.0275519 0.707821" mass="0.378377" diaginertia="0.00020073 2.14399e-05 0.000225159"/>
        <joint name="l_hip_pitch_joint" class="/" pos="0 0 0" axis="-0.00335001 0.999994 0.00128652" stiffness="0.00215093" range="-1.2364 1.78347" armature="0.00973244" damping="0.0153511" frictionloss="0.0100632"/>
        <geom name="//unnamed_geom_22" class="/" type="mesh" density="0" rgba="0.75294 0.75294 0.75294 1" mesh="l_hip_pitch_link"/>
        <geom name="//unnamed_geom_23" class="/" size="0.000497931 0.000497931 0.000497931" type="box" rgba="0.75294 0.75294 0.75294 1"/>
        <body name="l_hip_roll_link" pos="1.06921e-06 0.0414938 -0.00145285" quat="0.999999 -0.000438619 -0.000917267 -3.72421e-05">
          <inertial pos="-0.00220071 0.00231385 -0.0723267" quat="0.698104 -0.0717495 -0.0770238 0.708217" mass="0.373902" diaginertia="0.00051762 5.52254e-05 0.000291513"/>
          <joint name="l_hip_roll_joint" class="/" pos="0 0 0" axis="-1 -0.000142659 -4.89604e-05" range="-0.496471 0.100594" armature="0.0110789" damping="0.00627035" frictionloss="0.0101846"/>
          <geom name="//unnamed_geom_24" class="/" type="mesh" density="0" rgba="0.75294 0.75294 0.75294 1" mesh="l_hip_roll_link"/>
          <geom name="//unnamed_geom_25" class="/" size="0.000497931 0.000497931 0.000497931" type="box" rgba="0.75294 0.75294 0.75294 1"/>
          <geom name="//unnamed_geom_26" class="reward_collision_sphere" size="0.0398345"/>
          <body name="l_thigh_link" pos="0.00152215 -3.97317e-06 -0.0808825" quat="1 7.23926e-05 0.000257004 7.873e-05">
            <inertial pos="-5.81144e-05 -0.000296127 -0.0560303" quat="0.675824 0.73706 -0.00203671 -2.62588e-05" mass="0.112761" diaginertia="0.000191642 1.87734e-05 0.000127201"/>
            <joint name="l_thigh_joint" class="/" pos="0 0 0" axis="0.000620217 -0.00104652 -0.999999" range="-0.618449 0.288293" armature="0.0102068" damping="0" frictionloss="0.00947053"/>
            <geom name="//unnamed_geom_27" class="/" type="mesh" density="0" rgba="0.75294 0.75294 0.75294 1" mesh="l_thigh_link"/>
            <geom name="//unnamed_geom_28" class="/" size="0.000497931 0.000497931 0.000497931" type="box" rgba="0.75294 0.75294 0.75294 1"/>
            <body name="l_calf_link" pos="-0.00222666 0.00110469 -0.0837813" quat="0.947515 0.000387226 0.319708 0.00106287">
              <inertial pos="0.000925761 0.00342 -0.0808488" quat="0.999977 0.00382288 0.00072446 0.00550037" mass="0.812393" diaginertia="0.00548204 0.000696531 0.000402463"/>
              <joint name="l_calf_joint" class="/" pos="0 0 0" axis="0.000423548 0.999999 -0.00136669" range="-0.621512 1.67092" armature="0.0104357" damping="0.00554448" frictionloss="0.00954876"/>
              <geom name="//unnamed_geom_29" class="/" type="mesh" density="0" rgba="0.75294 0.75294 0.75294 1" mesh="l_calf_link"/>
              <geom name="//unnamed_geom_30" class="/" size="0.000497931 0.000497931 0.000497931" type="box" rgba="0.75294 0.75294 0.75294 1"/>
              <geom name="//unnamed_geom_31" class="reward_collision_sphere" size="0.0398345"/>
              <body name="l_ankle_pitch_link" pos="-1.15231e-05 0.00207769 -0.162833" quat="0.980141 -0.000165339 -0.198301 0.000297686">
                <inertial pos="0.00514417 -0.00149504 -0.000221255" quat="-0.00251772 0.707526 0.00126269 0.706682" mass="0.170777" diaginertia="0.00046821 4.44777e-05 0.000263854"/>
                <joint name="l_ankle_pitch_joint" class="/" pos="0 0 0" axis="0.00149012 0.999996 0.00251953" stiffness="0.00770904" range="-0.508639 1.30701" armature="0.0091598" damping="0.0148435" frictionloss="0.0100111"/>
                <geom name="//unnamed_geom_32" class="/" type="mesh" density="0" rgba="0.75294 0.75294 0.75294 1" mesh="l_ankle_pitch_link"/>
                <geom name="//unnamed_geom_33" class="/" size="0.0388386 0.0398345 0.0248966" type="box" rgba="0.75294 0.75294 0.75294 1"/>
                <body name="l_ankle_roll_link" pos="0.0824145 0.00129093 -0.000530196" quat="1 9.85381e-05 -2.925e-05 -0.000168842">
                  <inertial pos="-0.0263366 -1.91623e-05 -0.0168753" quat="0.559764 0.430837 0.43458 0.558735" mass="0.513196" diaginertia="0.00172465 0.00020376 0.000623855"/>
                  <joint name="l_ankle_roll_joint" class="/" pos="0 0 0" axis="-1 0.000185987 -0.000592992" range="-0.109772 0.148895" armature="0.00985277" damping="0" frictionloss="0.0104689"/>
                  <geom name="//unnamed_geom_34" class="/" type="mesh" density="0" rgba="0.75294 0.75294 0.75294 1" mesh="l_ankle_roll_link"/>
                  <geom name="//unnamed_geom_35" class="/" type="mesh" rgba="0.75294 0.75294 0.75294 1" mesh="l_ankle_roll_link"/>
                  <geom name="left_foot" class="foot" size="0.0804905 0.0362438 0.00512788" pos="-0.0556068 0 -0.0516023"/>
                  <geom name="//unnamed_geom_37" class="reward_collision_sphere" size="0.0398345" pos="-0.0545164 0 -0.0234556"/>
                  <geom name="//unnamed_geom_38" class="reward_collision_sphere" size="0.0199173" pos="0.0163549 -0.0144896 -0.0469112"/>
                  <geom name="//unnamed_geom_39" class="reward_collision_sphere" size="0.0199173" pos="-0.130839 -0.0144896 -0.0469112"/>
                  <site name="left_foot" class="foot" pos="-0.0556068 0 -0.0516023" size="0.00995863"/>
                </body>
              </body>
            </body>
          </body>
        </body>
      </body>
    </body>
  </worldbody>

  <contact>
    <pair class="/" geom1="floor" geom2="right_foot" name="//unnamed_contact_1"/>
    <pair class="/" geom1="floor" geom2="left_foot" name="//unnamed_contact_0"/>
  </contact>

  <actuator>
    <general name="r_hip_pitch_joint" class="/" joint="r_hip_pitch_joint" forcerange="-21.7029 21.7029" gainprm="20.3719" biasprm="0 -20.3719 -0.481586"/>
    <general name="r_hip_roll_joint" class="/" joint="r_hip_roll_joint" forcerange="-22.732 22.732" gainprm="20.3719" biasprm="0 -20.3719 -0.481586"/>
    <general name="r_thigh_joint" class="/" joint="r_thigh_joint" forcerange="-21.0273 21.0273" gainprm="20.3719" biasprm="0 -20.3719 -0.481586"/>
    <general name="r_calf_joint" class="/" joint="r_calf_joint" forcerange="-21.2111 21.2111" gainprm="20.3719" biasprm="0 -20.3719 -0.481586"/>
    <general name="r_ankle_pitch_joint" class="/" joint="r_ankle_pitch_joint" forcerange="-20.8821 20.8821" gainprm="20.3719" biasprm="0 -20.3719 -0.481586"/>
    <general name="r_ankle_roll_joint" class="/" joint="r_ankle_roll_joint" forcerange="-21.5224 21.5224" gainprm="20.3719" biasprm="0 -20.3719 -0.481586"/>
    <general name="l_hip_pitch_joint" class="/" joint="l_hip_pitch_joint" forcerange="-20.2793 20.2793" gainprm="20.3719" biasprm="0 -20.3719 -0.481586"/>
    <general name="l_hip_roll_joint" class="/" joint="l_hip_roll_joint" forcerange="-20.8015 20.8015" gainprm="20.3719" biasprm="0 -20.3719 -0.481586"/>
    <general name="l_thigh_joint" class="/" joint="l_thigh_joint" forcerange="-21.007 21.007" gainprm="20.3719" biasprm="0 -20.3719 -0.481586"/>
    <general name="l_calf_joint" class="/" joint="l_calf_joint" forcerange="-21.4504 21.4504" gainprm="20.3719" biasprm="0 -20.3719 -0.481586"/>
    <general name="l_ankle_pitch_joint" class="/" joint="l_ankle_pitch_joint" forcerange="-20.8953 20.8953" gainprm="20.3719" biasprm="0 -20.3719 -0.481586"/>
    <general name="l_ankle_roll_joint" class="/" joint="l_ankle_roll_joint" forcerange="-20.3893 20.3893" gainprm="20.3719" biasprm="0 -20.3719 -0.481586"/>
  </actuator>

  <sensor>
    <gyro site="imu" name="imu_angular_velocity"/>
    <velocimeter site="imu" name="imu_linear_velocity"/>
    <framelinvel objtype="site" objname="left_foot" name="left_foot_global_linear_velocity"/>
    <framelinvel objtype="site" objname="right_foot" name="right_foot_global_linear_velocity"/>
  </sensor>

  <keyframe>
    <key name="home" qpos="0 0 0.291 1 0 0 0 0.4 0 0 -0.8 0.4 0 -0.4 0 0 0.8 -0.4 0"/>
  </keyframe>
</mujoco>
