<mujoco model="pi_12dof_release_v1">
  <compiler angle="radian" assetdir="assets" balanceinertia="true" inertiafromgeom="false"/>

  <option timestep="0.005" density="1.2" viscosity="2e-05"/>

  <size nkey="1"/>

  <visual>
    <quality shadowsize="8192"/>
    <map shadowclip="0.5"/>
  </visual>

  <default>
    <default class="/">
      <joint armature="0.01" damping="0.01" frictionloss="0.01"/>
      <geom contype="0" conaffinity="0" group="1" solref="-1000 -80"/>
      <site size="0.01 0.005 0.005" group="5"/>
      <general forcelimited="true" biastype="affine" gainprm="20" biasprm="0 -20 -0.5"/>
      <default class="foot">
        <geom size="0.0845 0.036 0.005" type="box" condim="6" group="4" priority="1" friction="0.9 0.2 0.2" solimp="0.015 1 0.005"/>
      </default>
      <default class="reward_collision_sphere">
        <geom group="5" rgba="1 0 0 1"/>
      </default>
    </default>
  </default>

  <asset>
    <texture type="skybox" colorspace="auto" name="//unnamed_texture_0" builtin="gradient" rgb1="0.95 0.95 0.95" rgb2="0.95 0.95 0.95" width="100" height="600"/>
    <texture type="2d" colorspace="auto" name="texplane" builtin="checker" rgb1="0.345 0.575 0.748" rgb2="0.345 0.575 0.748" markrgb="1 1 1" width="512" height="512"/>
    <material name="MatPlane" class="/" texture="texplane" texuniform="true" texrepeat="2 2" specular="0.9"/>
    <mesh name="baselink_1" class="/" file="baselink_1.STL"/>
    <mesh name="r_hip_pitch_link" class="/" file="r_hip_pitch_link.STL"/>
    <mesh name="r_hip_roll_link" class="/" file="r_hip_roll_link.STL"/>
    <mesh name="r_thigh_link" class="/" file="r_thigh_link.STL"/>
    <mesh name="r_calf_link" class="/" file="r_calf_link.STL"/>
    <mesh name="r_ankle_pitch_link" class="/" file="r_ankle_pitch_link.STL"/>
    <mesh name="r_ankle_roll_link" class="/" file="r_ankle_roll_link.STL"/>
    <mesh name="l_hip_pitch_link" class="/" file="l_hip_pitch_link.STL"/>
    <mesh name="l_hip_roll_link" class="/" file="l_hip_roll_link.STL"/>
    <mesh name="l_thigh_link" class="/" file="l_thigh_link.STL"/>
    <mesh name="l_calf_link" class="/" file="l_calf_link.STL"/>
    <mesh name="l_ankle_pitch_link" class="/" file="l_ankle_pitch_link.STL"/>
    <mesh name="l_ankle_roll_link" class="/" file="l_ankle_roll_link.STL"/>
  </asset>

  <worldbody>
    <geom name="floor" class="/" size="100 100 0.125" type="plane" group="0" material="MatPlane"/>
    <light name="toplight_shadow" class="/" pos="0 0 5" dir="0.0990148 0.0990148 -0.990148" type="directional" ambient="0.04 0.04 0.04" diffuse="0.55 0.55 0.55" specular="0.12 0.12 0.12"/>
    <light name="toplight_fill" class="/" pos="0 0 5" dir="0.0990148 0.0990148 -0.990148" type="directional" castshadow="false" ambient="0.04 0.04 0.04" diffuse="0.3 0.3 0.3" specular="0.08 0.08 0.08"/>
    <body name="trunk" pos="-0.00153798 0.00490462 0.000702484" quat="0.999997 -0.000466279 0.00114936 0.00214988">
      <inertial pos="0.00619185 0.00952786 0.0262732" quat="0.698674 0.00557729 0.0258664 0.714951" mass="2.64087" diaginertia="0.0144653 0.046565 0.00123523"/>
      <joint name="//unnamed_joint_0" type="free"/>
      <geom name="//unnamed_geom_1" class="/" type="mesh" density="0" rgba="1 1 1 1" mesh="baselink_1"/>
      <geom name="//unnamed_geom_2" class="/" size="0.052903 0.052903 0.052903" pos="0 0 0.0624719" type="box" rgba="1 1 1 1"/>
      <geom name="//unnamed_geom_3" class="reward_collision_sphere" size="0.0581933" pos="0 0 0.0546629"/>
      <site name="imu" class="/" pos="-0.00841459 0.00952647 0.00953479" size="0.0105806"/>
      <camera name="track" class="/" pos="0 -2.71938 0" quat="0.707107 0.707107 0 0" mode="trackcom"/>
      <camera name="ego_camera" class="/" pos="0.0775193 0 0.140562" quat="-0.5 -0.5 0.5 0.5"/>
      <body name="r_hip_pitch_link" pos="-0.00328866 -0.0287965 -0.0244474" quat="0.992198 -8.23426e-05 -0.124674 5.13278e-06">
        <inertial pos="0.00250851 -0.0682468 0.003833" quat="-0.0465216 0.738157 -0.0316267 0.672279" mass="0.45103" diaginertia="0.000125883 0.000473256 2.37083e-05"/>
        <joint name="r_hip_pitch_joint" class="/" pos="0 0 0" axis="-0.0022741 -0.999979 0.00610945" range="-1.83577 1.1757" armature="0.00952433" damping="0" frictionloss="0.00588225"/>
        <geom name="//unnamed_geom_4" class="/" type="mesh" density="0" rgba="0.75294 0.75294 0.75294 1" mesh="r_hip_pitch_link"/>
        <geom name="//unnamed_geom_5" class="/" size="0.00052903 0.00052903 0.00052903" type="box" rgba="0.75294 0.75294 0.75294 1"/>
        <body name="r_hip_roll_link" pos="-0.00716373 -0.0802455 -0.000114045" quat="0.999987 0.00189459 -0.000539249 -0.00473169">
          <inertial pos="-4.32379e-06 -0.0103061 -0.0491899" quat="0.707266 -0.083833 -0.0751801 0.697922" mass="0.448222" diaginertia="0.000439931 0.00115467 3.81283e-05"/>
          <joint name="r_hip_roll_joint" class="/" pos="0 0 0" axis="-0.999881 0.0108469 -0.0110115" stiffness="0.0127206" range="-0.0991562 0.47252" armature="0.00684775" damping="0" frictionloss="0.00967712"/>
          <geom name="//unnamed_geom_6" class="/" type="mesh" density="0" rgba="0.75294 0.75294 0.75294 1" mesh="r_hip_roll_link"/>
          <geom name="//unnamed_geom_7" class="/" size="0.00052903 0.00052903 0.00052903" type="box" rgba="0.75294 0.75294 0.75294 1"/>
          <geom name="//unnamed_geom_8" class="reward_collision_sphere" size="0.0423224"/>
          <body name="r_thigh_link" pos="-0.00318228 0.00157659 -0.0508837" quat="0.999999 0.000656704 -0.00112261 -0.000648681">
            <inertial pos="0.00816535 0.00606349 -0.0305001" quat="0.735145 0.677886 0.00557163 0.000815596" mass="0.138988" diaginertia="0.000154727 0.000413725 1.73788e-05"/>
            <joint name="r_thigh_joint" class="/" pos="0 0 0" axis="-0.0126932 0.0355425 -0.999288" stiffness="0.0439078" range="-0.110148 0.785777" armature="0.00650648" damping="0.0573973" frictionloss="0.00564025"/>
            <geom name="//unnamed_geom_9" class="/" type="mesh" density="0" rgba="0.75294 0.75294 0.75294 1" mesh="r_thigh_link"/>
            <geom name="//unnamed_geom_10" class="/" size="0.00052903 0.00052903 0.00052903" type="box" rgba="0.75294 0.75294 0.75294 1"/>
            <body name="r_calf_link" pos="0.00986853 0.00130147 -0.0513913" quat="0.947643 -0.0001535 0.319331 -3.65328e-05">
              <inertial pos="-0.00204751 -0.0031919 -0.0519518" quat="0.998992 -0.00366072 0.0318733 0.0313821" mass="1.00281" diaginertia="0.00452579 0.0162492 5.09734e-05"/>
              <joint name="r_calf_joint" class="/" pos="0 0 0" axis="0.00551448 -0.998618 0.0522579" stiffness="0.0122942" range="-1.58494 0.62874" armature="0.00981915" damping="0.012344" frictionloss="0.00609077"/>
              <geom name="//unnamed_geom_11" class="/" type="mesh" density="0" rgba="0.75294 0.75294 0.75294 1" mesh="r_calf_link"/>
              <geom name="//unnamed_geom_12" class="/" size="0.00052903 0.00052903 0.00052903" type="box" rgba="0.75294 0.75294 0.75294 1"/>
              <geom name="//unnamed_geom_13" class="reward_collision_sphere" size="0.0423224"/>
              <body name="r_ankle_pitch_link" pos="0.00171062 0.00548696 -0.101623" quat="0.979945 6.82977e-05 -0.19927 -5.55093e-05">
                <inertial pos="0.00178495 0.00937492 -0.00873085" quat="0.00622834 0.710427 -0.00121926 0.703742" mass="0.207287" diaginertia="0.00038543 0.00102729 3.46766e-05"/>
                <joint name="r_ankle_pitch_joint" class="/" pos="0 0 0" axis="-0.00208568 -0.999998 -0.000275408" stiffness="0.00615614" range="-1.19792 0.67539" armature="0.00707029" damping="0.0113885" frictionloss="0.00633121"/>
                <geom name="//unnamed_geom_14" class="/" type="mesh" density="0" rgba="0.75294 0.75294 0.75294 1" mesh="r_ankle_pitch_link"/>
                <geom name="//unnamed_geom_15" class="/" size="0.0412643 0.0423224 0.0264515" type="box" rgba="0.75294 0.75294 0.75294 1"/>
                <body name="r_ankle_roll_link" pos="0.0765715 0.0124668 -0.0081224" quat="1 -3.65409e-05 -0.000114002 -6.95374e-05">
                  <inertial pos="-0.0203733 -0.0044499 -0.00951862" quat="0.556852 0.435945 0.42733 0.563256" mass="0.538572" diaginertia="0.00119059 0.00390656 7.55993e-05"/>
                  <joint name="r_ankle_roll_joint" class="/" pos="0 0 0" axis="-0.998443 -0.0202267 0.0519781" range="-0.355983 0.0197734" armature="0.00953159" damping="0" frictionloss="0.0101749"/>
                  <geom name="//unnamed_geom_16" class="/" type="mesh" density="0" rgba="0.75294 0.75294 0.75294 1" mesh="r_ankle_roll_link"/>
                  <geom name="//unnamed_geom_17" class="/" type="mesh" rgba="0.75294 0.75294 0.75294 1" mesh="r_ankle_roll_link"/>
                  <geom name="right_foot" class="foot" size="0.0645456 0.0233332 0.00476404" pos="-0.0527131 0 -0.0343596"/>
                  <geom name="//unnamed_geom_19" class="reward_collision_sphere" size="0.0423224" pos="-0.0516795 0 -0.015618"/>
                  <geom name="//unnamed_geom_20" class="reward_collision_sphere" size="0.0211612" pos="0.0155039 0.0271938 -0.031236"/>
                  <geom name="//unnamed_geom_21" class="reward_collision_sphere" size="0.0211612" pos="-0.124031 0.0271938 -0.031236"/>
                  <site name="right_foot" class="foot" pos="-0.0527131 0 -0.0343596" size="0.0105806"/>
                </body>
              </body>
            </body>
          </body>
        </body>
      </body>
      <body name="l_hip_pitch_link" pos="0.00571448 0.0289678 -0.0316194" quat="0.992297 -0.0007503 -0.123879 0.000551578">
        <inertial pos="0.00174991 0.0733531 -0.0043734" quat="-0.037377 0.705641 0.0293234 0.706976" mass="0.532524" diaginertia="0.000153201 0.00051671 2.84717e-05"/>
        <joint name="l_hip_pitch_joint" class="/" pos="0 0 0" axis="-0.00505021 0.999985 -0.00217028" range="-1.20708 1.60062" armature="0.0100399" damping="0.0277158" frictionloss="0.00994016"/>
        <geom name="//unnamed_geom_22" class="/" type="mesh" density="0" rgba="0.75294 0.75294 0.75294 1" mesh="l_hip_pitch_link"/>
        <geom name="//unnamed_geom_23" class="/" size="0.00052903 0.00052903 0.00052903" type="box" rgba="0.75294 0.75294 0.75294 1"/>
        <body name="l_hip_roll_link" pos="0.00667251 0.0800826 -7.09929e-05" quat="0.99999 0.000313545 0.00145655 0.00412755">
          <inertial pos="0.0024192 -0.0105764 -0.0487843" quat="0.689618 -0.102257 -0.0876076 0.711544" mass="0.519186" diaginertia="0.000412856 0.00123818 3.38212e-05"/>
          <joint name="l_hip_roll_joint" class="/" pos="0 0 0" axis="-0.999646 -0.00746156 0.0255521" range="-0.531303 0.091851" armature="0.00540866" damping="0.008282" frictionloss="0.0124831"/>
          <geom name="//unnamed_geom_24" class="/" type="mesh" density="0" rgba="0.75294 0.75294 0.75294 1" mesh="l_hip_roll_link"/>
          <geom name="//unnamed_geom_25" class="/" size="0.00052903 0.00052903 0.00052903" type="box" rgba="0.75294 0.75294 0.75294 1"/>
          <geom name="//unnamed_geom_26" class="reward_collision_sphere" size="0.0423224"/>
          <body name="l_thigh_link" pos="0.00291184 -0.000552117 -0.0596164" quat="0.999998 0.000990118 -0.000268508 0.00139827">
            <inertial pos="0.00251497 -0.00855789 -0.0400055" quat="0.671665 0.740812 0.00746461 -0.00286675" mass="0.136357" diaginertia="0.000159645 0.000477718 1.83894e-05"/>
            <joint name="l_thigh_joint" class="/" pos="0 0 0" axis="0.00017922 0.00278215 -0.999996" range="-0.622619 0.291497" armature="0.0126041" damping="0.0435082" frictionloss="0.0100919"/>
            <geom name="//unnamed_geom_27" class="/" type="mesh" density="0" rgba="0.75294 0.75294 0.75294 1" mesh="l_thigh_link"/>
            <geom name="//unnamed_geom_28" class="/" size="0.00052903 0.00052903 0.00052903" type="box" rgba="0.75294 0.75294 0.75294 1"/>
            <body name="l_calf_link" pos="0.00989135 0.00293158 -0.0553204" quat="0.947616 0.00530683 0.319369 0.000642766">
              <inertial pos="0.00260156 0.00570313 -0.056899" quat="0.999984 -0.00327714 0.0013622 0.00436201" mass="1.00432" diaginertia="0.00427825 0.016719 4.53977e-05"/>
              <joint name="l_calf_joint" class="/" pos="0 0 0" axis="-0.0133561 0.999828 0.0128553" stiffness="0.0512307" range="-0.79691 1.6761" armature="0.0116885" damping="0.0169867" frictionloss="0.0103837"/>
              <geom name="//unnamed_geom_29" class="/" type="mesh" density="0" rgba="0.75294 0.75294 0.75294 1" mesh="l_calf_link"/>
              <geom name="//unnamed_geom_30" class="/" size="0.00052903 0.00052903 0.00052903" type="box" rgba="0.75294 0.75294 0.75294 1"/>
              <geom name="//unnamed_geom_31" class="reward_collision_sphere" size="0.0423224"/>
              <body name="l_ankle_pitch_link" pos="0.0053305 -0.00622006 -0.107766" quat="0.980167 -0.000541735 -0.198172 0.000541965">
                <inertial pos="0.0052487 0.00484973 -0.00253045" quat="0.00228244 0.704352 0.00280898 0.709841" mass="0.207584" diaginertia="0.000356858 0.00104055 3.69844e-05"/>
                <joint name="l_ankle_pitch_joint" class="/" pos="0 0 0" axis="0.00859192 0.999961 -0.00205338" range="-0.542366 1.27737" armature="0.0144962" damping="0" frictionloss="0.0128667"/>
                <geom name="//unnamed_geom_32" class="/" type="mesh" density="0" rgba="0.75294 0.75294 0.75294 1" mesh="l_ankle_pitch_link"/>
                <geom name="//unnamed_geom_33" class="/" size="0.0412643 0.0423224 0.0264515" type="box" rgba="0.75294 0.75294 0.75294 1"/>
                <body name="l_ankle_roll_link" pos="0.0740618 0.00283074 -0.00277081" quat="1 -0.000116643 -0.000435447 -0.000249622">
                  <inertial pos="-0.0210236 0.000932769 -0.0148813" quat="0.56009 0.429885 0.433357 0.560089" mass="0.575294" diaginertia="0.00132454 0.00461199 8.02782e-05"/>
                  <joint name="l_ankle_roll_joint" class="/" pos="0 0 0" axis="-0.999983 -0.00573361 -0.000787617" stiffness="0.00475564" range="-0.347514 0.184196" armature="0.0099978" damping="0.0529155" frictionloss="0.0113142"/>
                  <geom name="//unnamed_geom_34" class="/" type="mesh" density="0" rgba="0.75294 0.75294 0.75294 1" mesh="l_ankle_roll_link"/>
                  <geom name="//unnamed_geom_35" class="/" type="mesh" rgba="0.75294 0.75294 0.75294 1" mesh="l_ankle_roll_link"/>
                  <geom name="left_foot" class="foot" size="0.12236 0.0377793 0.00559825" pos="-0.0527131 0 -0.0343596"/>
                  <geom name="//unnamed_geom_37" class="reward_collision_sphere" size="0.0423224" pos="-0.0516795 0 -0.015618"/>
                  <geom name="//unnamed_geom_38" class="reward_collision_sphere" size="0.0211612" pos="0.0155039 -0.0271938 -0.031236"/>
                  <geom name="//unnamed_geom_39" class="reward_collision_sphere" size="0.0211612" pos="-0.124031 -0.0271938 -0.031236"/>
                  <site name="left_foot" class="foot" pos="-0.0527131 0 -0.0343596" size="0.0105806"/>
                </body>
              </body>
            </body>
          </body>
        </body>
      </body>
    </body>
  </worldbody>

  <contact>
    <pair class="/" geom1="floor" geom2="right_foot" name="//unnamed_contact_1"/>
    <pair class="/" geom1="floor" geom2="left_foot" name="//unnamed_contact_0"/>
  </contact>

  <actuator>
    <general name="r_hip_pitch_joint" class="/" joint="r_hip_pitch_joint" forcerange="-23.8376 23.8376" gainprm="22.5494" biasprm="0 -22.5494 -0.529113"/>
    <general name="r_hip_roll_joint" class="/" joint="r_hip_roll_joint" forcerange="-13.7812 13.7812" gainprm="22.5494" biasprm="0 -22.5494 -0.529113"/>
    <general name="r_thigh_joint" class="/" joint="r_thigh_joint" forcerange="-22.5798 22.5798" gainprm="22.5494" biasprm="0 -22.5494 -0.529113"/>
    <general name="r_calf_joint" class="/" joint="r_calf_joint" forcerange="-23.6583 23.6583" gainprm="22.5494" biasprm="0 -22.5494 -0.529113"/>
    <general name="r_ankle_pitch_joint" class="/" joint="r_ankle_pitch_joint" forcerange="-21.7366 21.7366" gainprm="22.5494" biasprm="0 -22.5494 -0.529113"/>
    <general name="r_ankle_roll_joint" class="/" joint="r_ankle_roll_joint" forcerange="-17.0607 17.0607" gainprm="22.5494" biasprm="0 -22.5494 -0.529113"/>
    <general name="l_hip_pitch_joint" class="/" joint="l_hip_pitch_joint" forcerange="-20.1356 20.1356" gainprm="22.5494" biasprm="0 -22.5494 -0.529113"/>
    <general name="l_hip_roll_joint" class="/" joint="l_hip_roll_joint" forcerange="-21.6584 21.6584" gainprm="22.5494" biasprm="0 -22.5494 -0.529113"/>
    <general name="l_thigh_joint" class="/" joint="l_thigh_joint" forcerange="-23.7346 23.7346" gainprm="22.5494" biasprm="0 -22.5494 -0.529113"/>
    <general name="l_calf_joint" class="/" joint="l_calf_joint" forcerange="-24.7862 24.7862" gainprm="22.5494" biasprm="0 -22.5494 -0.529113"/>
    <general name="l_ankle_pitch_joint" class="/" joint="l_ankle_pitch_joint" forcerange="-20.5997 20.5997" gainprm="22.5494" biasprm="0 -22.5494 -0.529113"/>
    <general name="l_ankle_roll_joint" class="/" joint="l_ankle_roll_joint" forcerange="-26.9818 26.9818" gainprm="22.5494" biasprm="0 -22.5494 -0.529113"/>
  </actuator>

  <sensor>
    <gyro site="imu" name="imu_angular_velocity"/>
    <velocimeter site="imu" name="imu_linear_velocity"/>
    <framelinvel objtype="site" objname="left_foot" name="left_foot_global_linear_velocity"/>
    <framelinvel objtype="site" objname="right_foot" name="right_foot_global_linear_velocity"/>
  </sensor>

  <keyframe>
    <key name="home" qpos="0 0 0.291 1 0 0 0 0.4 0 0 -0.8 0.4 0 -0.4 0 0 0.8 -0.4 0"/>
  </keyframe>
</mujoco>
