<mujoco model="pi_12dof_release_v1">
  <compiler angle="radian" assetdir="assets" balanceinertia="true" inertiafromgeom="false"/>

  <option timestep="0.005" density="1.2" viscosity="2e-05"/>

  <size nkey="1"/>

  <visual>
    <quality shadowsize="8192"/>
    <map shadowclip="0.5"/>
  </visual>

  <default>
    <default class="/">
      <joint armature="0.01" damping="0.01" frictionloss="0.01"/>
      <geom contype="0" conaffinity="0" group="1" solref="-1000 -80"/>
      <site size="0.01 0.005 0.005" group="5"/>
      <general forcelimited="true" biastype="affine" gainprm="20" biasprm="0 -20 -0.5"/>
      <default class="foot">
        <geom size="0.0845 0.036 0.005" type="box" condim="6" group="4" priority="1" friction="0.9 0.2 0.2" solimp="0.015 1 0.005"/>
      </default>
      <default class="reward_collision_sphere">
        <geom group="5" rgba="1 0 0 1"/>
      </default>
    </default>
  </default>

  <asset>
    <texture type="skybox" colorspace="auto" name="//unnamed_texture_0" builtin="gradient" rgb1="0.95 0.95 0.95" rgb2="0.95 0.95 0.95" width="100" height="600"/>
    <texture type="2d" colorspace="auto" name="texplane" builtin="checker" rgb1="0.345 0.575 0.748" rgb2="0.345 0.575 0.748" markrgb="1 1 1" width="512" height="512"/>
    <material name="MatPlane" class="/" texture="texplane" texuniform="true" texrepeat="2 2" specular="0.9"/>
    <mesh name="baselink_1" class="/" file="baselink_1.STL"/>
    <mesh name="r_hip_pitch_link" class="/" file="r_hip_pitch_link.STL"/>
    <mesh name="r_hip_roll_link" class="/" file="r_hip_roll_link.STL"/>
    <mesh name="r_thigh_link" class="/" file="r_thigh_link.STL"/>
    <mesh name="r_calf_link" class="/" file="r_calf_link.STL"/>
    <mesh name="r_ankle_pitch_link" class="/" file="r_ankle_pitch_link.STL"/>
    <mesh name="r_ankle_roll_link" class="/" file="r_ankle_roll_link.STL"/>
    <mesh name="l_hip_pitch_link" class="/" file="l_hip_pitch_link.STL"/>
    <mesh name="l_hip_roll_link" class="/" file="l_hip_roll_link.STL"/>
    <mesh name="l_thigh_link" class="/" file="l_thigh_link.STL"/>
    <mesh name="l_calf_link" class="/" file="l_calf_link.STL"/>
    <mesh name="l_ankle_pitch_link" class="/" file="l_ankle_pitch_link.STL"/>
    <mesh name="l_ankle_roll_link" class="/" file="l_ankle_roll_link.STL"/>
  </asset>

  <worldbody>
    <geom name="floor" class="/" size="100 100 0.125" type="plane" group="0" material="MatPlane"/>
    <light name="toplight_shadow" class="/" pos="0 0 5" dir="0.0990148 0.0990148 -0.990148" type="directional" ambient="0.04 0.04 0.04" diffuse="0.55 0.55 0.55" specular="0.12 0.12 0.12"/>
    <light name="toplight_fill" class="/" pos="0 0 5" dir="0.0990148 0.0990148 -0.990148" type="directional" castshadow="false" ambient="0.04 0.04 0.04" diffuse="0.3 0.3 0.3" specular="0.08 0.08 0.08"/>
    <body name="trunk" pos="-0.000524241 -0.00264114 -0.000260968" quat="0.999999 -0.00114758 -0.000608107 -0.000274291">
      <inertial pos="0.000383893 -0.00248348 0.0512448" quat="0.701031 0.00259089 0.00747239 0.713087" mass="2.27886" diaginertia="0.0128492 0.00257444 0.0103433"/>
      <joint name="//unnamed_joint_0" type="free"/>
      <geom name="//unnamed_geom_1" class="/" type="mesh" density="0" rgba="1 1 1 1" mesh="baselink_1"/>
      <geom name="//unnamed_geom_2" class="/" size="0.0508319 0.0508319 0.0508319" pos="0 0 0.0958933" type="box" rgba="1 1 1 1"/>
      <geom name="//unnamed_geom_3" class="reward_collision_sphere" size="0.0559151" pos="0 0 0.0839066"/>
      <site name="imu" class="/" pos="0.0047659 -0.00207705 -0.00201621" size="0.0101664"/>
      <camera name="track" class="/" pos="0 -1.56638 0" quat="0.707107 0.707107 0 0" mode="trackcom"/>
      <camera name="ego_camera" class="/" pos="0.0801046 0 0.21576" quat="-0.5 -0.5 0.5 0.5"/>
      <body name="r_hip_pitch_link" pos="0.00177035 -0.0169926 -0.0396091" quat="0.992201 -2.41432e-05 -0.124647 -0.000461617">
        <inertial pos="0.00116708 -0.0467854 -0.00133602" quat="-0.0145276 0.703987 -0.022272 0.709714" mass="0.386763" diaginertia="0.00015054 2.8056e-05 0.000204238"/>
        <joint name="r_hip_pitch_joint" class="/" pos="0 0 0" axis="-0.00634181 -0.99997 0.00434214" range="-1.69759 1.29182" armature="0.0104955" damping="0.0244524" frictionloss="0.0114145"/>
        <geom name="//unnamed_geom_4" class="/" type="mesh" density="0" rgba="0.75294 0.75294 0.75294 1" mesh="r_hip_pitch_link"/>
        <geom name="//unnamed_geom_5" class="/" size="0.000508319 0.000508319 0.000508319" type="box" rgba="0.75294 0.75294 0.75294 1"/>
        <body name="r_hip_roll_link" pos="0.00316375 -0.0408366 0.000869074" quat="0.999999 -0.000790465 -0.00046843 0.000450798">
          <inertial pos="-0.00307547 0.00079613 -0.0729749" quat="0.702946 -0.0778033 -0.0797043 0.702468" mass="0.421263" diaginertia="0.000451806 8.47593e-05 0.000319103"/>
          <joint name="r_hip_roll_joint" class="/" pos="0 0 0" axis="-0.999954 0.00801458 -0.0052693" range="-0.124175 0.488495" armature="0.0117118" damping="0.0244682" frictionloss="0.0106415"/>
          <geom name="//unnamed_geom_6" class="/" type="mesh" density="0" rgba="0.75294 0.75294 0.75294 1" mesh="r_hip_roll_link"/>
          <geom name="//unnamed_geom_7" class="/" size="0.000508319 0.000508319 0.000508319" type="box" rgba="0.75294 0.75294 0.75294 1"/>
          <geom name="//unnamed_geom_8" class="reward_collision_sphere" size="0.0406655"/>
          <body name="r_thigh_link" pos="0.00118505 0.00345506 -0.0841779" quat="1 -0.000543249 -0.00033177 0.00050932">
            <inertial pos="-0.00213242 -0.00148109 -0.059818" quat="0.738879 0.673832 -0.00280029 -0.000197851" mass="0.115534" diaginertia="0.000167932 2.7858e-05 0.000140476"/>
            <joint name="r_thigh_joint" class="/" pos="0 0 0" axis="-0.00121902 0.0114647 -0.999934" range="-0.346023 0.549535" armature="0.0116894" damping="0" frictionloss="0.0113377"/>
            <geom name="//unnamed_geom_9" class="/" type="mesh" density="0" rgba="0.75294 0.75294 0.75294 1" mesh="r_thigh_link"/>
            <geom name="//unnamed_geom_10" class="/" size="0.000508319 0.000508319 0.000508319" type="box" rgba="0.75294 0.75294 0.75294 1"/>
            <body name="r_calf_link" pos="-0.00140747 -0.00339704 -0.0864561" quat="0.947567 8.20126e-06 0.319556 -8.40759e-05">
              <inertial pos="0.000738125 0.00051308 -0.0848237" quat="0.999839 -0.00387813 0.00473407 0.016864" mass="0.849852" diaginertia="0.00475373 0.00103172 0.000437906"/>
              <joint name="r_calf_joint" class="/" pos="0 0 0" axis="-0.0102123 -0.999946 -0.00172791" range="-1.691 0.668003" armature="0.0103874" damping="0" frictionloss="0.0114676"/>
              <geom name="//unnamed_geom_11" class="/" type="mesh" density="0" rgba="0.75294 0.75294 0.75294 1" mesh="r_calf_link"/>
              <geom name="//unnamed_geom_12" class="/" size="0.000508319 0.000508319 0.000508319" type="box" rgba="0.75294 0.75294 0.75294 1"/>
              <geom name="//unnamed_geom_13" class="reward_collision_sphere" size="0.0406655"/>
              <body name="r_ankle_pitch_link" pos="-0.00082169 -0.00108894 -0.170009" quat="0.980066 5.91984e-05 -0.198674 2.78745e-07">
                <inertial pos="0.00689482 0.00035415 0.00216263" quat="0.00358965 0.704849 -0.00145975 0.709347" mass="0.185762" diaginertia="0.00041518 6.55441e-05 0.000297347"/>
                <joint name="r_ankle_pitch_joint" class="/" pos="0 0 0" axis="-0.00302281 -0.999993 -0.0020048" stiffness="0.0019927" range="-1.3505 0.451433" armature="0.0114463" damping="0.00759118" frictionloss="0.011518"/>
                <geom name="//unnamed_geom_14" class="/" type="mesh" density="0" rgba="0.75294 0.75294 0.75294 1" mesh="r_ankle_pitch_link"/>
                <geom name="//unnamed_geom_15" class="/" size="0.0396489 0.0406655 0.025416" type="box" rgba="0.75294 0.75294 0.75294 1"/>
                <body name="r_ankle_roll_link" pos="0.0817832 -0.000221467 0.00243238" quat="1 -0.000195754 0.000199335 -9.5812e-05">
                  <inertial pos="-0.028048 0.00275683 -0.0180847" quat="0.555652 0.433952 0.432466 0.562059" mass="0.55956" diaginertia="0.00159255 0.000322273 0.000697101"/>
                  <joint name="r_ankle_roll_joint" class="/" pos="0 0 0" axis="-0.999974 -0.00246715 0.00671754" stiffness="0.0101574" range="-0.111398 0.208155" armature="0.0106185" damping="0.0222748" frictionloss="0.0103246"/>
                  <geom name="//unnamed_geom_16" class="/" type="mesh" density="0" rgba="0.75294 0.75294 0.75294 1" mesh="r_ankle_roll_link"/>
                  <geom name="//unnamed_geom_17" class="/" type="mesh" rgba="0.75294 0.75294 0.75294 1" mesh="r_ankle_roll_link"/>
                  <geom name="right_foot" class="foot" size="0.0917252 0.0379515 0.00494732" pos="-0.0544711 0 -0.0527413"/>
                  <geom name="//unnamed_geom_19" class="reward_collision_sphere" size="0.0406655" pos="-0.0534031 0 -0.0239733"/>
                  <geom name="//unnamed_geom_20" class="reward_collision_sphere" size="0.0203328" pos="0.0160209 0.0156638 -0.0479466"/>
                  <geom name="//unnamed_geom_21" class="reward_collision_sphere" size="0.0203328" pos="-0.128167 0.0156638 -0.0479466"/>
                  <site name="right_foot" class="foot" pos="-0.0544711 0 -0.0527413" size="0.0101664"/>
                </body>
              </body>
            </body>
          </body>
        </body>
      </body>
      <body name="l_hip_pitch_link" pos="-0.00236833 0.0203009 -0.0364225" quat="0.992217 4.85071e-05 -0.124521 -1.67806e-05">
        <inertial pos="3.08763e-05 0.0425649 0.00242007" quat="-0.0395748 0.706725 0.0278066 0.705834" mass="0.394632" diaginertia="0.000177902 2.98713e-05 0.000252939"/>
        <joint name="l_hip_pitch_joint" class="/" pos="0 0 0" axis="-0.000693961 1 -0.000221726" stiffness="0.0103469" range="-1.27458 1.80811" armature="0.010206" damping="0.00861661" frictionloss="0.00991206"/>
        <geom name="//unnamed_geom_22" class="/" type="mesh" density="0" rgba="0.75294 0.75294 0.75294 1" mesh="l_hip_pitch_link"/>
        <geom name="//unnamed_geom_23" class="/" size="0.000508319 0.000508319 0.000508319" type="box" rgba="0.75294 0.75294 0.75294 1"/>
        <body name="l_hip_roll_link" pos="-0.0021768 0.0419287 0.000998494" quat="0.999999 0.000178376 0.000606664 0.00098627">
          <inertial pos="-0.00353803 0.00173422 -0.0726859" quat="0.70324 -0.0872214 -0.0805268 0.700972" mass="0.397145" diaginertia="0.000450864 8.41178e-05 0.000328698"/>
          <joint name="l_hip_roll_joint" class="/" pos="0 0 0" axis="-0.999934 -0.0114755 -0.000632429" stiffness="0.00068502" range="-0.506753 0.125623" armature="0.0111711" damping="0.00725136" frictionloss="0.00905133"/>
          <geom name="//unnamed_geom_24" class="/" type="mesh" density="0" rgba="0.75294 0.75294 0.75294 1" mesh="l_hip_roll_link"/>
          <geom name="//unnamed_geom_25" class="/" size="0.000508319 0.000508319 0.000508319" type="box" rgba="0.75294 0.75294 0.75294 1"/>
          <geom name="//unnamed_geom_26" class="reward_collision_sphere" size="0.0406655"/>
          <body name="l_thigh_link" pos="-0.00151446 -0.00106292 -0.0802184" quat="0.999999 -0.000902724 0.000541123 -6.36228e-05">
            <inertial pos="0.000820426 0.00146363 -0.0552693" quat="0.674503 0.738268 0.000695629 0.00245229" mass="0.116632" diaginertia="0.000165615 2.65863e-05 0.000136536"/>
            <joint name="l_thigh_joint" class="/" pos="0 0 0" axis="-0.000677557 -0.000187786 -1" stiffness="0.00785939" range="-0.59323 0.294276" armature="0.00896197" damping="0" frictionloss="0.0103905"/>
            <geom name="//unnamed_geom_27" class="/" type="mesh" density="0" rgba="0.75294 0.75294 0.75294 1" mesh="l_thigh_link"/>
            <geom name="//unnamed_geom_28" class="/" size="0.000508319 0.000508319 0.000508319" type="box" rgba="0.75294 0.75294 0.75294 1"/>
            <body name="l_calf_link" pos="-0.00271893 -0.000818907 -0.0840788" quat="0.947607 -0.000484207 0.319437 0.000700357">
              <inertial pos="-0.000560635 0.001755 -0.0833436" quat="0.99998 0.00507776 0.00120408 0.00347248" mass="0.836628" diaginertia="0.00478935 0.00101005 0.000430667"/>
              <joint name="l_calf_joint" class="/" pos="0 0 0" axis="-0.00966026 0.999953 -0.00128313" range="-0.594977 1.64231" armature="0.00939002" damping="0.0115188" frictionloss="0.0101605"/>
              <geom name="//unnamed_geom_29" class="/" type="mesh" density="0" rgba="0.75294 0.75294 0.75294 1" mesh="l_calf_link"/>
              <geom name="//unnamed_geom_30" class="/" size="0.000508319 0.000508319 0.000508319" type="box" rgba="0.75294 0.75294 0.75294 1"/>
              <geom name="//unnamed_geom_31" class="reward_collision_sphere" size="0.0406655"/>
              <body name="l_ankle_pitch_link" pos="-0.00266553 0.0035875 -0.169184" quat="0.980086 -0.000437699 -0.198572 0.000157904">
                <inertial pos="0.00567349 -0.00363897 0.00128867" quat="0.000828333 0.707881 0.00632286 0.706302" mass="0.183996" diaginertia="0.000430127 6.4858e-05 0.000284904"/>
                <joint name="l_ankle_pitch_joint" class="/" pos="0 0 0" axis="0.00378511 0.999992 0.0011411" stiffness="0.00753822" range="-0.477078 1.29524" armature="0.00892271" damping="0.0229248" frictionloss="0.00890725"/>
                <geom name="//unnamed_geom_32" class="/" type="mesh" density="0" rgba="0.75294 0.75294 0.75294 1" mesh="l_ankle_pitch_link"/>
                <geom name="//unnamed_geom_33" class="/" size="0.0396489 0.0406655 0.025416" type="box" rgba="0.75294 0.75294 0.75294 1"/>
                <body name="l_ankle_roll_link" pos="0.0821594 -0.00105446 0.0012049" quat="1 -3.04737e-05 0.000202083 9.16046e-05">
                  <inertial pos="-0.0287266 -0.0011088 -0.0176537" quat="0.559013 0.431392 0.433844 0.559629" mass="0.560775" diaginertia="0.00156725 0.000309488 0.000706299"/>
                  <joint name="l_ankle_roll_joint" class="/" pos="0 0 0" axis="-0.999999 0.000866886 -0.000986111" stiffness="0.000411557" range="-0.10995 0.162243" armature="0.010682" damping="0" frictionloss="0.00975249"/>
                  <geom name="//unnamed_geom_34" class="/" type="mesh" density="0" rgba="0.75294 0.75294 0.75294 1" mesh="l_ankle_roll_link"/>
                  <geom name="//unnamed_geom_35" class="/" type="mesh" rgba="0.75294 0.75294 0.75294 1" mesh="l_ankle_roll_link"/>
                  <geom name="left_foot" class="foot" size="0.0795658 0.0397074 0.00480375" pos="-0.0544711 0 -0.0527413"/>
                  <geom name="//unnamed_geom_37" class="reward_collision_sphere" size="0.0406655" pos="-0.0534031 0 -0.0239733"/>
                  <geom name="//unnamed_geom_38" class="reward_collision_sphere" size="0.0203328" pos="0.0160209 -0.0156638 -0.0479466"/>
                  <geom name="//unnamed_geom_39" class="reward_collision_sphere" size="0.0203328" pos="-0.128167 -0.0156638 -0.0479466"/>
                  <site name="left_foot" class="foot" pos="-0.0544711 0 -0.0527413" size="0.0101664"/>
                </body>
              </body>
            </body>
          </body>
        </body>
      </body>
    </body>
  </worldbody>

  <contact>
    <pair class="/" geom1="floor" geom2="right_foot" name="//unnamed_contact_1"/>
    <pair class="/" geom1="floor" geom2="left_foot" name="//unnamed_contact_0"/>
  </contact>

  <actuator>
    <general name="r_hip_pitch_joint" class="/" joint="r_hip_pitch_joint" forcerange="-20.4396 20.4396" gainprm="19.5485" biasprm="0 -19.5485 -0.534714"/>
    <general name="r_hip_roll_joint" class="/" joint="r_hip_roll_joint" forcerange="-22.9835 22.9835" gainprm="19.5485" biasprm="0 -19.5485 -0.534714"/>
    <general name="r_thigh_joint" class="/" joint="r_thigh_joint" forcerange="-21.2143 21.2143" gainprm="19.5485" biasprm="0 -19.5485 -0.534714"/>
    <general name="r_calf_joint" class="/" joint="r_calf_joint" forcerange="-20.8786 20.8786" gainprm="19.5485" biasprm="0 -19.5485 -0.534714"/>
    <general name="r_ankle_pitch_joint" class="/" joint="r_ankle_pitch_joint" forcerange="-21.3113 21.3113" gainprm="19.5485" biasprm="0 -19.5485 -0.534714"/>
    <general name="r_ankle_roll_joint" class="/" joint="r_ankle_roll_joint" forcerange="-23.5592 23.5592" gainprm="19.5485" biasprm="0 -19.5485 -0.534714"/>
    <general name="l_hip_pitch_joint" class="/" joint="l_hip_pitch_joint" forcerange="-22.7697 22.7697" gainprm="19.5485" biasprm="0 -19.5485 -0.534714"/>
    <general name="l_hip_roll_joint" class="/" joint="l_hip_roll_joint" forcerange="-21.2887 21.2887" gainprm="19.5485" biasprm="0 -19.5485 -0.534714"/>
    <general name="l_thigh_joint" class="/" joint="l_thigh_joint" forcerange="-21.2558 21.2558" gainprm="19.5485" biasprm="0 -19.5485 -0.534714"/>
    <general name="l_calf_joint" class="/" joint="l_calf_joint" forcerange="-19.8151 19.8151" gainprm="19.5485" biasprm="0 -19.5485 -0.534714"/>
    <general name="l_ankle_pitch_joint" class="/" joint="l_ankle_pitch_joint" forcerange="-21.3194 21.3194" gainprm="19.5485" biasprm="0 -19.5485 -0.534714"/>
    <general name="l_ankle_roll_joint" class="/" joint="l_ankle_roll_joint" forcerange="-19.0901 19.0901" gainprm="19.5485" biasprm="0 -19.5485 -0.534714"/>
  </actuator>

  <sensor>
    <gyro site="imu" name="imu_angular_velocity"/>
    <velocimeter site="imu" name="imu_linear_velocity"/>
    <framelinvel objtype="site" objname="left_foot" name="left_foot_global_linear_velocity"/>
    <framelinvel objtype="site" objname="right_foot" name="right_foot_global_linear_velocity"/>
  </sensor>

  <keyframe>
    <key name="home" qpos="0 0 0.291 1 0 0 0 0.4 0 0 -0.8 0.4 0 -0.4 0 0 0.8 -0.4 0"/>
  </keyframe>
</mujoco>
