<mujoco model="pi_12dof_release_v1">
  <compiler angle="radian" assetdir="assets" balanceinertia="true" inertiafromgeom="false"/>

  <option timestep="0.005" density="1.2" viscosity="2e-05"/>

  <size nkey="1"/>

  <visual>
    <quality shadowsize="8192"/>
    <map shadowclip="0.5"/>
  </visual>

  <default>
    <default class="/">
      <joint armature="0.01" damping="0.01" frictionloss="0.01"/>
      <geom contype="0" conaffinity="0" group="1" solref="-1000 -80"/>
      <site size="0.01 0.005 0.005" group="5"/>
      <general forcelimited="true" biastype="affine" gainprm="20" biasprm="0 -20 -0.5"/>
      <default class="foot">
        <geom size="0.0845 0.036 0.005" type="box" condim="6" group="4" priority="1" friction="0.9 0.2 0.2" solimp="0.015 1 0.005"/>
      </default>
      <default class="reward_collision_sphere">
        <geom group="5" rgba="1 0 0 1"/>
      </default>
    </default>
  </default>

  <asset>
    <texture type="skybox" colorspace="auto" name="//unnamed_texture_0" builtin="gradient" rgb1="0.95 0.95 0.95" rgb2="0.95 0.95 0.95" width="100" height="600"/>
    <texture type="2d" colorspace="auto" name="texplane" builtin="checker" rgb1="0.345 0.575 0.748" rgb2="0.345 0.575 0.748" markrgb="1 1 1" width="512" height="512"/>
    <material name="MatPlane" class="/" texture="texplane" texuniform="true" texrepeat="2 2" specular="0.9"/>
    <mesh name="baselink_1" class="/" file="baselink_1.STL"/>
    <mesh name="r_hip_pitch_link" class="/" file="r_hip_pitch_link.STL"/>
    <mesh name="r_hip_roll_link" class="/" file="r_hip_roll_link.STL"/>
    <mesh name="r_thigh_link" class="/" file="r_thigh_link.STL"/>
    <mesh name="r_calf_link" class="/" file="r_calf_link.STL"/>
    <mesh name="r_ankle_pitch_link" class="/" file="r_ankle_pitch_link.STL"/>
    <mesh name="r_ankle_roll_link" class="/" file="r_ankle_roll_link.STL"/>
    <mesh name="l_hip_pitch_link" class="/" file="l_hip_pitch_link.STL"/>
    <mesh name="l_hip_roll_link" class="/" file="l_hip_roll_link.STL"/>
    <mesh name="l_thigh_link" class="/" file="l_thigh_link.STL"/>
    <mesh name="l_calf_link" class="/" file="l_calf_link.STL"/>
    <mesh name="l_ankle_pitch_link" class="/" file="l_ankle_pitch_link.STL"/>
    <mesh name="l_ankle_roll_link" class="/" file="l_ankle_roll_link.STL"/>
  </asset>

  <worldbody>
    <geom name="floor" class="/" size="100 100 0.125" type="plane" group="0" material="MatPlane"/>
    <light name="toplight_shadow" class="/" pos="0 0 5" dir="0.0990148 0.0990148 -0.990148" type="directional" ambient="0.04 0.04 0.04" diffuse="0.55 0.55 0.55" specular="0.12 0.12 0.12"/>
    <light name="toplight_fill" class="/" pos="0 0 5" dir="0.0990148 0.0990148 -0.990148" type="directional" castshadow="false" ambient="0.04 0.04 0.04" diffuse="0.3 0.3 0.3" specular="0.08 0.08 0.08"/>
    <body name="trunk" pos="0.00259581 0.00109327 0.000659056" quat="1 -9.45555e-05 -8.84679e-05 -0.000153908">
      <inertial pos="0.00218941 1.93113e-05 0.0394295" quat="0.692818 0.0184876 0.00416689 0.720864" mass="2.06064" diaginertia="0.013537 0.00604192 0.0037359"/>
      <joint name="//unnamed_joint_0" type="free"/>
      <geom name="//unnamed_geom_1" class="/" type="mesh" density="0" rgba="1 1 1 1" mesh="baselink_1"/>
      <geom name="//unnamed_geom_2" class="/" size="0.0490738 0.0490738 0.0490738" pos="0 0 0.078341" type="box" rgba="1 1 1 1"/>
      <geom name="//unnamed_geom_3" class="reward_collision_sphere" size="0.0539812" pos="0 0 0.0685483"/>
      <site name="imu" class="/" pos="-0.000394474 0.00533058 -0.0106117" size="0.00981477"/>
      <camera name="track" class="/" pos="0 -1.82408 0" quat="0.707107 0.707107 0 0" mode="trackcom"/>
      <camera name="ego_camera" class="/" pos="0.0789847 0 0.176267" quat="-0.5 -0.5 0.5 0.5"/>
      <body name="r_hip_pitch_link" pos="-0.00059301 -0.0200894 -0.0344205" quat="0.99213 0.000188144 -0.125207 0.00120645">
        <inertial pos="-0.00125294 -0.053245 0.000333893" quat="-0.0178675 0.705948 -0.02796 0.707486" mass="0.352452" diaginertia="0.000141798 5.96862e-05 7.57536e-05"/>
        <joint name="r_hip_pitch_joint" class="/" pos="0 0 0" axis="-0.0124855 -0.999922 -0.000375473" stiffness="0.00110019" range="-1.7037 1.30262" armature="0.00981907" damping="0.0223797" frictionloss="0.00991939"/>
        <geom name="//unnamed_geom_4" class="/" type="mesh" density="0" rgba="0.75294 0.75294 0.75294 1" mesh="r_hip_pitch_link"/>
        <geom name="//unnamed_geom_5" class="/" size="0.000490738 0.000490738 0.000490738" type="box" rgba="0.75294 0.75294 0.75294 1"/>
        <body name="r_hip_roll_link" pos="-0.00286029 -0.0514298 -0.00123402" quat="1 0.000848545 -0.000443449 -0.000209594">
          <inertial pos="-0.000953503 -0.000505163 -0.0615757" quat="0.710387 -0.0726777 -0.0823558 0.695188" mass="0.363284" diaginertia="0.000430967 0.000174329 0.000114393"/>
          <joint name="r_hip_roll_joint" class="/" pos="0 0 0" axis="-0.999894 -0.0096063 0.0109509" range="-0.143338 0.550936" armature="0.0103964" damping="0" frictionloss="0.00844031"/>
          <geom name="//unnamed_geom_6" class="/" type="mesh" density="0" rgba="0.75294 0.75294 0.75294 1" mesh="r_hip_roll_link"/>
          <geom name="//unnamed_geom_7" class="/" size="0.000490738 0.000490738 0.000490738" type="box" rgba="0.75294 0.75294 0.75294 1"/>
          <geom name="//unnamed_geom_8" class="reward_collision_sphere" size="0.0392591"/>
          <body name="r_thigh_link" pos="0.000225034 -0.00164355 -0.0668513" quat="0.999999 -0.00116187 0.000343925 -0.000366732">
            <inertial pos="0.00222995 0.000868124 -0.0463406" quat="0.740637 0.671822 -0.00318299 0.0101027" mass="0.113305" diaginertia="0.000161009 6.1742e-05 5.19276e-05"/>
            <joint name="r_thigh_joint" class="/" pos="0 0 0" axis="0.00497578 -0.0143166 -0.999885" range="-0.24642 0.639012" armature="0.00992744" damping="0.000370209" frictionloss="0.00897835"/>
            <geom name="//unnamed_geom_9" class="/" type="mesh" density="0" rgba="0.75294 0.75294 0.75294 1" mesh="r_thigh_link"/>
            <geom name="//unnamed_geom_10" class="/" size="0.000490738 0.000490738 0.000490738" type="box" rgba="0.75294 0.75294 0.75294 1"/>
            <body name="r_calf_link" pos="-0.00186701 -0.00119761 -0.0711272" quat="0.947797 0.000141502 0.318875 -2.94064e-05">
              <inertial pos="0.00182651 -0.000337821 -0.0706834" quat="0.999848 -0.002048 0.001389 0.0172548" mass="0.780279" diaginertia="0.00471428 0.00219392 0.000161211"/>
              <joint name="r_calf_joint" class="/" pos="0 0 0" axis="-0.0030054 -0.999988 0.00379767" range="-1.63333 0.645382" armature="0.0107428" damping="0.0107509" frictionloss="0.0103043"/>
              <geom name="//unnamed_geom_11" class="/" type="mesh" density="0" rgba="0.75294 0.75294 0.75294 1" mesh="r_calf_link"/>
              <geom name="//unnamed_geom_12" class="/" size="0.000490738 0.000490738 0.000490738" type="box" rgba="0.75294 0.75294 0.75294 1"/>
              <geom name="//unnamed_geom_13" class="reward_collision_sphere" size="0.0392591"/>
              <body name="r_ankle_pitch_link" pos="-0.000458116 -0.00199991 -0.134942" quat="0.980067 2.9876e-06 -0.198668 -3.1333e-05">
                <inertial pos="0.00298501 0.00472256 -0.000658821" quat="0.00329514 0.706337 -0.00239192 0.707864" mass="0.167152" diaginertia="0.000403183 0.000139093 0.000108589"/>
                <joint name="r_ankle_pitch_joint" class="/" pos="0 0 0" axis="-0.0132561 -0.999885 0.00740591" stiffness="0.00771204" range="-1.27071 0.502802" armature="0.00859948" damping="0.016354" frictionloss="0.0084444"/>
                <geom name="//unnamed_geom_14" class="/" type="mesh" density="0" rgba="0.75294 0.75294 0.75294 1" mesh="r_ankle_pitch_link"/>
                <geom name="//unnamed_geom_15" class="/" size="0.0382776 0.0392591 0.0245369" type="box" rgba="0.75294 0.75294 0.75294 1"/>
                <body name="r_ankle_roll_link" pos="0.0806296 0.0048022 0.00264029" quat="1 -0.000164944 0.000429125 -0.000881529">
                  <inertial pos="-0.0235909 -0.00238017 -0.011506" quat="0.563595 0.429961 0.433165 0.556653" mass="0.479599" diaginertia="0.0015226 0.00068164 0.000264761"/>
                  <joint name="r_ankle_roll_joint" class="/" pos="0 0 0" axis="-0.999958 0.00744321 0.00528988" range="-0.149032 0.172342" armature="0.0096824" damping="0.0181146" frictionloss="0.010319"/>
                  <geom name="//unnamed_geom_16" class="/" type="mesh" density="0" rgba="0.75294 0.75294 0.75294 1" mesh="r_ankle_roll_link"/>
                  <geom name="//unnamed_geom_17" class="/" type="mesh" rgba="0.75294 0.75294 0.75294 1" mesh="r_ankle_roll_link"/>
                  <geom name="right_foot" class="foot" size="0.0846773 0.0366537 0.00485421" pos="-0.0537096 0 -0.0430875"/>
                  <geom name="//unnamed_geom_19" class="reward_collision_sphere" size="0.0392591" pos="-0.0526565 0 -0.0195852"/>
                  <geom name="//unnamed_geom_20" class="reward_collision_sphere" size="0.0196295" pos="0.0157969 0.0182408 -0.0391705"/>
                  <geom name="//unnamed_geom_21" class="reward_collision_sphere" size="0.0196295" pos="-0.126376 0.0182408 -0.0391705"/>
                  <site name="right_foot" class="foot" pos="-0.0537096 0 -0.0430875" size="0.00981477"/>
                </body>
              </body>
            </body>
          </body>
        </body>
      </body>
      <body name="l_hip_pitch_link" pos="0.000921477 0.017807 -0.0320987" quat="0.992176 -0.000149445 -0.124848 -0.0002592">
        <inertial pos="0.00317971 0.0477421 -0.000247979" quat="-0.0294871 0.699699 0.034622 0.712989" mass="0.358881" diaginertia="0.000166114 6.58855e-05 8.73657e-05"/>
        <joint name="l_hip_pitch_joint" class="/" pos="0 0 0" axis="-0.00491249 0.999988 0.000202826" range="-1.2957 1.72989" armature="0.00880104" damping="0.00728866" frictionloss="0.0107376"/>
        <geom name="//unnamed_geom_22" class="/" type="mesh" density="0" rgba="0.75294 0.75294 0.75294 1" mesh="l_hip_pitch_link"/>
        <geom name="//unnamed_geom_23" class="/" size="0.000490738 0.000490738 0.000490738" type="box" rgba="0.75294 0.75294 0.75294 1"/>
        <body name="l_hip_roll_link" pos="0.00324943 0.052686 -0.000374554" quat="1 -0.000460251 0.000497948 0.000109855">
          <inertial pos="-0.000991961 0.00206834 -0.0600709" quat="0.698339 -0.073419 -0.0642149 0.70909" mass="0.377016" diaginertia="0.000431566 0.000180216 0.00011715"/>
          <joint name="l_hip_roll_joint" class="/" pos="0 0 0" axis="-0.999967 0.000486216 -0.00811641" range="-0.478028 0.147522" armature="0.0112928" damping="0" frictionloss="0.00865512"/>
          <geom name="//unnamed_geom_24" class="/" type="mesh" density="0" rgba="0.75294 0.75294 0.75294 1" mesh="l_hip_roll_link"/>
          <geom name="//unnamed_geom_25" class="/" size="0.000490738 0.000490738 0.000490738" type="box" rgba="0.75294 0.75294 0.75294 1"/>
          <geom name="//unnamed_geom_26" class="reward_collision_sphere" size="0.0392591"/>
          <body name="l_thigh_link" pos="-0.00177588 0.00208671 -0.0695752" quat="1 -0.000701473 0.000134205 0.0005435">
            <inertial pos="-0.00070937 -0.00134177 -0.0451074" quat="0.681535 0.731751 0.00640755 -0.00327466" mass="0.103747" diaginertia="0.000162062 5.88033e-05 5.2592e-05"/>
            <joint name="l_thigh_joint" class="/" pos="0 0 0" axis="1.3383e-05 -0.000290208 -1" range="-0.64647 0.322502" armature="0.0101484" damping="0" frictionloss="0.00936382"/>
            <geom name="//unnamed_geom_27" class="/" type="mesh" density="0" rgba="0.75294 0.75294 0.75294 1" mesh="l_thigh_link"/>
            <geom name="//unnamed_geom_28" class="/" size="0.000490738 0.000490738 0.000490738" type="box" rgba="0.75294 0.75294 0.75294 1"/>
            <body name="l_calf_link" pos="-0.00253384 0.00258571 -0.0689777" quat="0.947617 6.7019e-05 0.319409 -0.000229885">
              <inertial pos="0.00325092 0.00479265 -0.0696006" quat="0.999898 -0.000289701 0.00663673 0.0126351" mass="0.780093" diaginertia="0.00474961 0.00230765 0.000164061"/>
              <joint name="l_calf_joint" class="/" pos="0 0 0" axis="-0.0083126 0.999921 -0.00946186" range="-0.59444 1.67464" armature="0.00973548" damping="0.00299302" frictionloss="0.00845597"/>
              <geom name="//unnamed_geom_29" class="/" type="mesh" density="0" rgba="0.75294 0.75294 0.75294 1" mesh="l_calf_link"/>
              <geom name="//unnamed_geom_30" class="/" size="0.000490738 0.000490738 0.000490738" type="box" rgba="0.75294 0.75294 0.75294 1"/>
              <geom name="//unnamed_geom_31" class="reward_collision_sphere" size="0.0392591"/>
              <body name="l_ankle_pitch_link" pos="8.38754e-05 0.00131148 -0.135074" quat="0.980164 -6.22767e-05 -0.198188 0.000104707">
                <inertial pos="0.00533718 -0.000148169 -0.00020065" quat="-0.00301727 0.705708 -0.00601328 0.708471" mass="0.168245" diaginertia="0.000401736 0.000145813 0.000110839"/>
                <joint name="l_ankle_pitch_joint" class="/" pos="0 0 0" axis="0.00230997 0.999991 -0.00350982" range="-0.453476 1.35636" armature="0.009806" damping="0" frictionloss="0.00940642"/>
                <geom name="//unnamed_geom_32" class="/" type="mesh" density="0" rgba="0.75294 0.75294 0.75294 1" mesh="l_ankle_pitch_link"/>
                <geom name="//unnamed_geom_33" class="/" size="0.0382776 0.0392591 0.0245369" type="box" rgba="0.75294 0.75294 0.75294 1"/>
                <body name="l_ankle_roll_link" pos="0.078946 0.000570917 -0.000223069" quat="1 0.000240631 -8.92578e-05 3.03621e-05">
                  <inertial pos="-0.0281358 -0.00185671 -0.0119163" quat="0.560534 0.431493 0.432058 0.559411" mass="0.51321" diaginertia="0.00143299 0.000680699 0.000257163"/>
                  <joint name="l_ankle_roll_joint" class="/" pos="0 0 0" axis="-0.999999 -0.00116051 0.000676677" stiffness="0.0095264" range="-0.164532 0.101576" armature="0.00926854" damping="0.0196539" frictionloss="0.0111136"/>
                  <geom name="//unnamed_geom_34" class="/" type="mesh" density="0" rgba="0.75294 0.75294 0.75294 1" mesh="l_ankle_roll_link"/>
                  <geom name="//unnamed_geom_35" class="/" type="mesh" rgba="0.75294 0.75294 0.75294 1" mesh="l_ankle_roll_link"/>
                  <geom name="left_foot" class="foot" size="0.0824803 0.0329032 0.00463388" pos="-0.0537096 0 -0.0430875"/>
                  <geom name="//unnamed_geom_37" class="reward_collision_sphere" size="0.0392591" pos="-0.0526565 0 -0.0195852"/>
                  <geom name="//unnamed_geom_38" class="reward_collision_sphere" size="0.0196295" pos="0.0157969 -0.0182408 -0.0391705"/>
                  <geom name="//unnamed_geom_39" class="reward_collision_sphere" size="0.0196295" pos="-0.126376 -0.0182408 -0.0391705"/>
                  <site name="left_foot" class="foot" pos="-0.0537096 0 -0.0430875" size="0.00981477"/>
                </body>
              </body>
            </body>
          </body>
        </body>
      </body>
    </body>
  </worldbody>

  <contact>
    <pair class="/" geom1="floor" geom2="right_foot" name="//unnamed_contact_1"/>
    <pair class="/" geom1="floor" geom2="left_foot" name="//unnamed_contact_0"/>
  </contact>

  <actuator>
    <general name="r_hip_pitch_joint" class="/" joint="r_hip_pitch_joint" forcerange="-21.8921 21.8921" gainprm="19.2302" biasprm="0 -19.2302 -0.502836"/>
    <general name="r_hip_roll_joint" class="/" joint="r_hip_roll_joint" forcerange="-22.5496 22.5496" gainprm="19.2302" biasprm="0 -19.2302 -0.502836"/>
    <general name="r_thigh_joint" class="/" joint="r_thigh_joint" forcerange="-19.8763 19.8763" gainprm="19.2302" biasprm="0 -19.2302 -0.502836"/>
    <general name="r_calf_joint" class="/" joint="r_calf_joint" forcerange="-22.1697 22.1697" gainprm="19.2302" biasprm="0 -19.2302 -0.502836"/>
    <general name="r_ankle_pitch_joint" class="/" joint="r_ankle_pitch_joint" forcerange="-20.6991 20.6991" gainprm="19.2302" biasprm="0 -19.2302 -0.502836"/>
    <general name="r_ankle_roll_joint" class="/" joint="r_ankle_roll_joint" forcerange="-20.7216 20.7216" gainprm="19.2302" biasprm="0 -19.2302 -0.502836"/>
    <general name="l_hip_pitch_joint" class="/" joint="l_hip_pitch_joint" forcerange="-20.7903 20.7903" gainprm="19.2302" biasprm="0 -19.2302 -0.502836"/>
    <general name="l_hip_roll_joint" class="/" joint="l_hip_roll_joint" forcerange="-18.4924 18.4924" gainprm="19.2302" biasprm="0 -19.2302 -0.502836"/>
    <general name="l_thigh_joint" class="/" joint="l_thigh_joint" forcerange="-21.7075 21.7075" gainprm="19.2302" biasprm="0 -19.2302 -0.502836"/>
    <general name="l_calf_joint" class="/" joint="l_calf_joint" forcerange="-20.6732 20.6732" gainprm="19.2302" biasprm="0 -19.2302 -0.502836"/>
    <general name="l_ankle_pitch_joint" class="/" joint="l_ankle_pitch_joint" forcerange="-19.7989 19.7989" gainprm="19.2302" biasprm="0 -19.2302 -0.502836"/>
    <general name="l_ankle_roll_joint" class="/" joint="l_ankle_roll_joint" forcerange="-22.492 22.492" gainprm="19.2302" biasprm="0 -19.2302 -0.502836"/>
  </actuator>

  <sensor>
    <gyro site="imu" name="imu_angular_velocity"/>
    <velocimeter site="imu" name="imu_linear_velocity"/>
    <framelinvel objtype="site" objname="left_foot" name="left_foot_global_linear_velocity"/>
    <framelinvel objtype="site" objname="right_foot" name="right_foot_global_linear_velocity"/>
  </sensor>

  <keyframe>
    <key name="home" qpos="0 0 0.291 1 0 0 0 0.4 0 0 -0.8 0.4 0 -0.4 0 0 0.8 -0.4 0"/>
  </keyframe>
</mujoco>
