<mujoco model="pi_12dof_release_v1">
  <compiler angle="radian" assetdir="assets" balanceinertia="true" inertiafromgeom="false"/>

  <option timestep="0.005" density="1.2" viscosity="2e-05"/>

  <size nkey="1"/>

  <visual>
    <quality shadowsize="8192"/>
    <map shadowclip="0.5"/>
  </visual>

  <default>
    <default class="/">
      <joint armature="0.01" damping="0.01" frictionloss="0.01"/>
      <geom contype="0" conaffinity="0" group="1" solref="-1000 -80"/>
      <site size="0.01 0.005 0.005" group="5"/>
      <general forcelimited="true" biastype="affine" gainprm="20" biasprm="0 -20 -0.5"/>
      <default class="foot">
        <geom size="0.0845 0.036 0.005" type="box" condim="6" group="4" priority="1" friction="0.9 0.2 0.2" solimp="0.015 1 0.005"/>
      </default>
      <default class="reward_collision_sphere">
        <geom group="5" rgba="1 0 0 1"/>
      </default>
    </default>
  </default>

  <asset>
    <texture type="skybox" colorspace="auto" name="//unnamed_texture_0" builtin="gradient" rgb1="0.95 0.95 0.95" rgb2="0.95 0.95 0.95" width="100" height="600"/>
    <texture type="2d" colorspace="auto" name="texplane" builtin="checker" rgb1="0.345 0.575 0.748" rgb2="0.345 0.575 0.748" markrgb="1 1 1" width="512" height="512"/>
    <material name="MatPlane" class="/" texture="texplane" texuniform="true" texrepeat="2 2" specular="0.9"/>
    <mesh name="baselink_1" class="/" file="baselink_1.STL"/>
    <mesh name="r_hip_pitch_link" class="/" file="r_hip_pitch_link.STL"/>
    <mesh name="r_hip_roll_link" class="/" file="r_hip_roll_link.STL"/>
    <mesh name="r_thigh_link" class="/" file="r_thigh_link.STL"/>
    <mesh name="r_calf_link" class="/" file="r_calf_link.STL"/>
    <mesh name="r_ankle_pitch_link" class="/" file="r_ankle_pitch_link.STL"/>
    <mesh name="r_ankle_roll_link" class="/" file="r_ankle_roll_link.STL"/>
    <mesh name="l_hip_pitch_link" class="/" file="l_hip_pitch_link.STL"/>
    <mesh name="l_hip_roll_link" class="/" file="l_hip_roll_link.STL"/>
    <mesh name="l_thigh_link" class="/" file="l_thigh_link.STL"/>
    <mesh name="l_calf_link" class="/" file="l_calf_link.STL"/>
    <mesh name="l_ankle_pitch_link" class="/" file="l_ankle_pitch_link.STL"/>
    <mesh name="l_ankle_roll_link" class="/" file="l_ankle_roll_link.STL"/>
  </asset>

  <worldbody>
    <geom name="floor" class="/" size="100 100 0.125" type="plane" group="0" material="MatPlane"/>
    <light name="toplight_shadow" class="/" pos="0 0 5" dir="0.0990148 0.0990148 -0.990148" type="directional" ambient="0.04 0.04 0.04" diffuse="0.55 0.55 0.55" specular="0.12 0.12 0.12"/>
    <light name="toplight_fill" class="/" pos="0 0 5" dir="0.0990148 0.0990148 -0.990148" type="directional" castshadow="false" ambient="0.04 0.04 0.04" diffuse="0.3 0.3 0.3" specular="0.08 0.08 0.08"/>
    <body name="trunk" pos="-0.00871687 -0.00217856 -0.00163347" quat="1 2.98501e-05 -0.000143449 3.14049e-05">
      <inertial pos="0.00326446 -0.00253262 0.0556895" quat="0.698986 0.016897 0.0267803 0.714434" mass="2.78633" diaginertia="0.00511187 0.00584157 0.0206799"/>
      <joint name="//unnamed_joint_0" type="free"/>
      <geom name="//unnamed_geom_1" class="/" type="mesh" density="0" rgba="1 1 1 1" mesh="baselink_1"/>
      <geom name="//unnamed_geom_2" class="/" size="0.0541544 0.0541544 0.0541544" pos="0 0 0.110725" type="box" rgba="1 1 1 1"/>
      <geom name="//unnamed_geom_3" class="reward_collision_sphere" size="0.0595699" pos="0 0 0.0968844"/>
      <site name="imu" class="/" pos="-0.00353328 -0.00500311 0.0510545" size="0.0108309"/>
      <camera name="track" class="/" pos="0 -1.89579 0" quat="0.707107 0.707107 0 0" mode="trackcom"/>
      <camera name="ego_camera" class="/" pos="0.0687979 0 0.249131" quat="-0.5 -0.5 0.5 0.5"/>
      <body name="r_hip_pitch_link" pos="-0.00312456 -0.0199375 -0.0411032" quat="0.991996 -0.00214595 -0.12622 0.00285049">
        <inertial pos="0.0104872 -0.0502201 4.28852e-05" quat="-0.0152513 0.704672 -0.0309196 0.708695" mass="0.459563" diaginertia="6.88275e-05 7.90459e-05 0.00040657"/>
        <joint name="r_hip_pitch_joint" class="/" pos="0 0 0" axis="-0.0236979 -0.999309 -0.0286318" range="-1.94055 1.14051" armature="0.0110773" damping="0" frictionloss="0.0105309"/>
        <geom name="//unnamed_geom_4" class="/" type="mesh" density="0" rgba="0.75294 0.75294 0.75294 1" mesh="r_hip_pitch_link"/>
        <geom name="//unnamed_geom_5" class="/" size="0.000541544 0.000541544 0.000541544" type="box" rgba="0.75294 0.75294 0.75294 1"/>
        <body name="r_hip_roll_link" pos="0.00540605 -0.0521888 0.00427687" quat="0.999999 0.000464496 0.0011778 0.000288812">
          <inertial pos="-0.000452618 -0.000896009 -0.0734871" quat="0.714269 -0.0681608 -0.0835958 0.69151" mass="0.514349" diaginertia="0.000226127 0.000217237 0.000650705"/>
          <joint name="r_hip_roll_joint" class="/" pos="0 0 0" axis="-0.999257 -0.037484 -0.0089468" stiffness="0.000407156" range="-0.092998 0.326704" armature="0.00922861" damping="0.0230868" frictionloss="0.014199"/>
          <geom name="//unnamed_geom_6" class="/" type="mesh" density="0" rgba="0.75294 0.75294 0.75294 1" mesh="r_hip_roll_link"/>
          <geom name="//unnamed_geom_7" class="/" size="0.000541544 0.000541544 0.000541544" type="box" rgba="0.75294 0.75294 0.75294 1"/>
          <geom name="//unnamed_geom_8" class="reward_collision_sphere" size="0.0433235"/>
          <body name="r_thigh_link" pos="-0.00315788 0.0112869 -0.0950247" quat="0.999995 -0.00209746 0.00097582 -0.00199372">
            <inertial pos="-0.00322162 0.00113989 -0.0658247" quat="0.735419 0.675917 -0.00209278 -0.0478564" mass="0.126716" diaginertia="8.27358e-05 6.89468e-05 0.000303984"/>
            <joint name="r_thigh_joint" class="/" pos="0 0 0" axis="0.0124538 0.0178794 -0.999763" stiffness="0.0513681" range="-0.423724 0.392463" armature="0.0113958" damping="0.0112989" frictionloss="0.012498"/>
            <geom name="//unnamed_geom_9" class="/" type="mesh" density="0" rgba="0.75294 0.75294 0.75294 1" mesh="r_thigh_link"/>
            <geom name="//unnamed_geom_10" class="/" size="0.000541544 0.000541544 0.000541544" type="box" rgba="0.75294 0.75294 0.75294 1"/>
            <body name="r_calf_link" pos="0.0108149 -0.0129096 -0.0896442" quat="0.9475 0.000718992 0.319756 -0.000569834">
              <inertial pos="-0.0107249 -0.00165429 -0.0872416" quat="0.999759 -0.00310539 -0.0195755 -0.00944606" mass="0.915743" diaginertia="0.0019599 0.00250372 0.000780086"/>
              <joint name="r_calf_joint" class="/" pos="0 0 0" axis="-0.0476824 -0.998862 0.000386873" stiffness="0.0166256" range="-1.68406 0.649946" armature="0.00904485" damping="0.00453039" frictionloss="0.0104634"/>
              <geom name="//unnamed_geom_11" class="/" type="mesh" density="0" rgba="0.75294 0.75294 0.75294 1" mesh="r_calf_link"/>
              <geom name="//unnamed_geom_12" class="/" size="0.000541544 0.000541544 0.000541544" type="box" rgba="0.75294 0.75294 0.75294 1"/>
              <geom name="//unnamed_geom_13" class="reward_collision_sphere" size="0.0433235"/>
              <body name="r_ankle_pitch_link" pos="0.00116837 0.00659751 -0.198501" quat="0.980059 6.5856e-05 -0.198706 6.06444e-05">
                <inertial pos="0.00795753 -0.00829534 -0.000749134" quat="0.00222541 0.707102 -0.00222515 0.707105" mass="0.218791" diaginertia="0.000196938 0.000168167 0.000601023"/>
                <joint name="r_ankle_pitch_joint" class="/" pos="0 0 0" axis="0.0267146 -0.999637 -0.00348711" range="-1.35148 0.505463" armature="0.0147201" damping="0" frictionloss="0.0141351"/>
                <geom name="//unnamed_geom_14" class="/" type="mesh" density="0" rgba="0.75294 0.75294 0.75294 1" mesh="r_ankle_pitch_link"/>
                <geom name="//unnamed_geom_15" class="/" size="0.0422405 0.0433235 0.0270772" type="box" rgba="0.75294 0.75294 0.75294 1"/>
                <body name="r_ankle_roll_link" pos="0.0725139 0.00182562 -0.00799836" quat="0.999986 -0.00193286 -0.0039832 -0.00286724">
                  <inertial pos="-0.0335988 0.00556088 -0.0277773" quat="0.559522 0.432656 0.434396 0.557713" mass="0.716068" diaginertia="0.000694377 0.000701653 0.00123546"/>
                  <joint name="r_ankle_roll_joint" class="/" pos="0 0 0" axis="-0.998579 0.0532439 -0.00219142" stiffness="0.0234624" range="-0.135066 0.13631" armature="0.0105621" damping="0" frictionloss="0.0104081"/>
                  <geom name="//unnamed_geom_16" class="/" type="mesh" density="0" rgba="0.75294 0.75294 0.75294 1" mesh="r_ankle_roll_link"/>
                  <geom name="//unnamed_geom_17" class="/" type="mesh" rgba="0.75294 0.75294 0.75294 1" mesh="r_ankle_roll_link"/>
                  <geom name="right_foot" class="foot" size="0.0701353 0.0301289 0.00531027" pos="-0.0467826 0 -0.0608988"/>
                  <geom name="//unnamed_geom_19" class="reward_collision_sphere" size="0.0433235" pos="-0.0458653 0 -0.0276813"/>
                  <geom name="//unnamed_geom_20" class="reward_collision_sphere" size="0.0216618" pos="0.0137596 0.0189579 -0.0553625"/>
                  <geom name="//unnamed_geom_21" class="reward_collision_sphere" size="0.0216618" pos="-0.110077 0.0189579 -0.0553625"/>
                  <site name="right_foot" class="foot" pos="-0.0467826 0 -0.0608988" size="0.0108309"/>
                </body>
              </body>
            </body>
          </body>
        </body>
      </body>
      <body name="l_hip_pitch_link" pos="-0.0120414 0.0305024 -0.0449033" quat="0.992127 9.84595e-05 -0.125235 -0.000151226">
        <inertial pos="-0.00905314 0.0629754 0.000160615" quat="-0.0598033 0.714096 0.0619861 0.694729" mass="0.509481" diaginertia="8.29834e-05 7.94742e-05 0.000556414"/>
        <joint name="l_hip_pitch_joint" class="/" pos="0 0 0" axis="0.00828296 0.998327 0.0572217" stiffness="0.0442383" range="-1.06064 1.77652" armature="0.0160815" damping="0.0126003" frictionloss="0.00900561"/>
        <geom name="//unnamed_geom_22" class="/" type="mesh" density="0" rgba="0.75294 0.75294 0.75294 1" mesh="l_hip_pitch_link"/>
        <geom name="//unnamed_geom_23" class="/" size="0.000541544 0.000541544 0.000541544" type="box" rgba="0.75294 0.75294 0.75294 1"/>
        <body name="l_hip_roll_link" pos="-0.00407534 0.0515778 -7.75404e-05" quat="1 -0.000920572 -9.71852e-05 -0.00025856">
          <inertial pos="-0.00146877 -0.0099172 -0.0832145" quat="0.696615 -0.074292 -0.0442148 0.712217" mass="0.455714" diaginertia="0.000213678 0.000200123 0.000685448"/>
          <joint name="l_hip_roll_joint" class="/" pos="0 0 0" axis="-0.999806 -0.0104163 -0.0166993" stiffness="0.0242751" range="-0.526475 0.0472208" armature="0.00631743" damping="0.0273888" frictionloss="0.0132069"/>
          <geom name="//unnamed_geom_24" class="/" type="mesh" density="0" rgba="0.75294 0.75294 0.75294 1" mesh="l_hip_roll_link"/>
          <geom name="//unnamed_geom_25" class="/" size="0.000541544 0.000541544 0.000541544" type="box" rgba="0.75294 0.75294 0.75294 1"/>
          <geom name="//unnamed_geom_26" class="reward_collision_sphere" size="0.0433235"/>
          <body name="l_thigh_link" pos="0.0053111 -0.00756835 -0.0849944" quat="0.999985 -0.00207324 -0.0045537 0.00235622">
            <inertial pos="0.00187507 -0.00114873 -0.0776968" quat="0.663985 0.747631 -0.0130344 0.00130816" mass="0.161833" diaginertia="8.056e-05 7.62037e-05 0.000304858"/>
            <joint name="l_thigh_joint" class="/" pos="0 0 0" axis="-0.00771144 0.0012942 -0.999969" stiffness="0.00310315" range="-0.405364 0.255061" armature="0.0110767" damping="0.0364044" frictionloss="0.0116025"/>
            <geom name="//unnamed_geom_27" class="/" type="mesh" density="0" rgba="0.75294 0.75294 0.75294 1" mesh="l_thigh_link"/>
            <geom name="//unnamed_geom_28" class="/" size="0.000541544 0.000541544 0.000541544" type="box" rgba="0.75294 0.75294 0.75294 1"/>
            <body name="l_calf_link" pos="0.00995685 -0.0025173 -0.0988056" quat="0.947863 -0.000427064 0.318676 -0.000352906">
              <inertial pos="-0.00603922 -0.000249281 -0.098833" quat="0.998496 0.0171316 0.0266408 0.0447499" mass="1.02067" diaginertia="0.00214814 0.00248402 0.000826343"/>
              <joint name="l_calf_joint" class="/" pos="0 0 0" axis="0.00511987 0.999104 -0.0420035" stiffness="0.00720049" range="-0.767187 1.6079" armature="0.0115326" damping="0.0152161" frictionloss="0.0150426"/>
              <geom name="//unnamed_geom_29" class="/" type="mesh" density="0" rgba="0.75294 0.75294 0.75294 1" mesh="l_calf_link"/>
              <geom name="//unnamed_geom_30" class="/" size="0.000541544 0.000541544 0.000541544" type="box" rgba="0.75294 0.75294 0.75294 1"/>
              <geom name="//unnamed_geom_31" class="reward_collision_sphere" size="0.0433235"/>
              <body name="l_ankle_pitch_link" pos="0.00140995 0.00340818 -0.202531" quat="0.980108 -0.000447021 -0.198461 -0.000861355">
                <inertial pos="0.00396559 -0.00242336 -0.00112631" quat="-0.0312335 0.687616 0.042484 0.724157" mass="0.228561" diaginertia="0.00019898 0.00015626 0.000531854"/>
                <joint name="l_ankle_pitch_joint" class="/" pos="0 0 0" axis="0.00827407 0.999966 7.40162e-05" range="-0.618517 1.19905" armature="0.0113072" damping="0.0382033" frictionloss="0.0110087"/>
                <geom name="//unnamed_geom_32" class="/" type="mesh" density="0" rgba="0.75294 0.75294 0.75294 1" mesh="l_ankle_pitch_link"/>
                <geom name="//unnamed_geom_33" class="/" size="0.0422405 0.0433235 0.0270772" type="box" rgba="0.75294 0.75294 0.75294 1"/>
                <body name="l_ankle_roll_link" pos="0.0723673 0.00436071 -0.000103289" quat="1 -0.000766364 0.00017737 0.000511588">
                  <inertial pos="-0.0133705 0.0107862 -0.0297874" quat="0.556429 0.425748 0.436075 0.56477" mass="0.583516" diaginertia="0.000772022 0.000695836 0.00141902"/>
                  <joint name="l_ankle_roll_joint" class="/" pos="0 0 0" axis="-0.999987 0.00446531 -0.00243518" range="-0.158977 0.253593" armature="0.0113925" damping="0" frictionloss="0.0062336"/>
                  <geom name="//unnamed_geom_34" class="/" type="mesh" density="0" rgba="0.75294 0.75294 0.75294 1" mesh="l_ankle_roll_link"/>
                  <geom name="//unnamed_geom_35" class="/" type="mesh" rgba="0.75294 0.75294 0.75294 1" mesh="l_ankle_roll_link"/>
                  <geom name="left_foot" class="foot" size="0.0997342 0.0518679 0.00578437" pos="-0.0467826 0 -0.0608988"/>
                  <geom name="//unnamed_geom_37" class="reward_collision_sphere" size="0.0433235" pos="-0.0458653 0 -0.0276813"/>
                  <geom name="//unnamed_geom_38" class="reward_collision_sphere" size="0.0216618" pos="0.0137596 -0.0189579 -0.0553625"/>
                  <geom name="//unnamed_geom_39" class="reward_collision_sphere" size="0.0216618" pos="-0.110077 -0.0189579 -0.0553625"/>
                  <site name="left_foot" class="foot" pos="-0.0467826 0 -0.0608988" size="0.0108309"/>
                </body>
              </body>
            </body>
          </body>
        </body>
      </body>
    </body>
  </worldbody>

  <contact>
    <pair class="/" geom1="floor" geom2="right_foot" name="//unnamed_contact_1"/>
    <pair class="/" geom1="floor" geom2="left_foot" name="//unnamed_contact_0"/>
  </contact>

  <actuator>
    <general name="r_hip_pitch_joint" class="/" joint="r_hip_pitch_joint" forcerange="-20.3512 20.3512" gainprm="22.4338" biasprm="0 -22.4338 -0.574598"/>
    <general name="r_hip_roll_joint" class="/" joint="r_hip_roll_joint" forcerange="-14.9741 14.9741" gainprm="22.4338" biasprm="0 -22.4338 -0.574598"/>
    <general name="r_thigh_joint" class="/" joint="r_thigh_joint" forcerange="-24.6254 24.6254" gainprm="22.4338" biasprm="0 -22.4338 -0.574598"/>
    <general name="r_calf_joint" class="/" joint="r_calf_joint" forcerange="-13.8304 13.8304" gainprm="22.4338" biasprm="0 -22.4338 -0.574598"/>
    <general name="r_ankle_pitch_joint" class="/" joint="r_ankle_pitch_joint" forcerange="-23.1866 23.1866" gainprm="22.4338" biasprm="0 -22.4338 -0.574598"/>
    <general name="r_ankle_roll_joint" class="/" joint="r_ankle_roll_joint" forcerange="-21.7607 21.7607" gainprm="22.4338" biasprm="0 -22.4338 -0.574598"/>
    <general name="l_hip_pitch_joint" class="/" joint="l_hip_pitch_joint" forcerange="-22.4419 22.4419" gainprm="22.4338" biasprm="0 -22.4338 -0.574598"/>
    <general name="l_hip_roll_joint" class="/" joint="l_hip_roll_joint" forcerange="-29.4359 29.4359" gainprm="22.4338" biasprm="0 -22.4338 -0.574598"/>
    <general name="l_thigh_joint" class="/" joint="l_thigh_joint" forcerange="-20.5201 20.5201" gainprm="22.4338" biasprm="0 -22.4338 -0.574598"/>
    <general name="l_calf_joint" class="/" joint="l_calf_joint" forcerange="-22.4309 22.4309" gainprm="22.4338" biasprm="0 -22.4338 -0.574598"/>
    <general name="l_ankle_pitch_joint" class="/" joint="l_ankle_pitch_joint" forcerange="-23.6915 23.6915" gainprm="22.4338" biasprm="0 -22.4338 -0.574598"/>
    <general name="l_ankle_roll_joint" class="/" joint="l_ankle_roll_joint" forcerange="-18.7885 18.7885" gainprm="22.4338" biasprm="0 -22.4338 -0.574598"/>
  </actuator>

  <sensor>
    <gyro site="imu" name="imu_angular_velocity"/>
    <velocimeter site="imu" name="imu_linear_velocity"/>
    <framelinvel objtype="site" objname="left_foot" name="left_foot_global_linear_velocity"/>
    <framelinvel objtype="site" objname="right_foot" name="right_foot_global_linear_velocity"/>
  </sensor>

  <keyframe>
    <key name="home" qpos="0 0 0.291 1 0 0 0 0.4 0 0 -0.8 0.4 0 -0.4 0 0 0.8 -0.4 0"/>
  </keyframe>
</mujoco>
