<mujoco model="pi_12dof_release_v1">
  <compiler angle="radian" assetdir="assets" balanceinertia="true" inertiafromgeom="false"/>

  <option timestep="0.005" density="1.2" viscosity="2e-05"/>

  <size nkey="1"/>

  <visual>
    <quality shadowsize="8192"/>
    <map shadowclip="0.5"/>
  </visual>

  <default>
    <default class="/">
      <joint armature="0.01" damping="0.01" frictionloss="0.01"/>
      <geom contype="0" conaffinity="0" group="1" solref="-1000 -80"/>
      <site size="0.01 0.005 0.005" group="5"/>
      <general forcelimited="true" biastype="affine" gainprm="20" biasprm="0 -20 -0.5"/>
      <default class="foot">
        <geom size="0.0845 0.036 0.005" type="box" condim="6" group="4" priority="1" friction="0.9 0.2 0.2" solimp="0.015 1 0.005"/>
      </default>
      <default class="reward_collision_sphere">
        <geom group="5" rgba="1 0 0 1"/>
      </default>
    </default>
  </default>

  <asset>
    <texture type="skybox" colorspace="auto" name="//unnamed_texture_0" builtin="gradient" rgb1="0.95 0.95 0.95" rgb2="0.95 0.95 0.95" width="100" height="600"/>
    <texture type="2d" colorspace="auto" name="texplane" builtin="checker" rgb1="0.345 0.575 0.748" rgb2="0.345 0.575 0.748" markrgb="1 1 1" width="512" height="512"/>
    <material name="MatPlane" class="/" texture="texplane" texuniform="true" texrepeat="2 2" specular="0.9"/>
    <mesh name="baselink_1" class="/" file="baselink_1.STL"/>
    <mesh name="r_hip_pitch_link" class="/" file="r_hip_pitch_link.STL"/>
    <mesh name="r_hip_roll_link" class="/" file="r_hip_roll_link.STL"/>
    <mesh name="r_thigh_link" class="/" file="r_thigh_link.STL"/>
    <mesh name="r_calf_link" class="/" file="r_calf_link.STL"/>
    <mesh name="r_ankle_pitch_link" class="/" file="r_ankle_pitch_link.STL"/>
    <mesh name="r_ankle_roll_link" class="/" file="r_ankle_roll_link.STL"/>
    <mesh name="l_hip_pitch_link" class="/" file="l_hip_pitch_link.STL"/>
    <mesh name="l_hip_roll_link" class="/" file="l_hip_roll_link.STL"/>
    <mesh name="l_thigh_link" class="/" file="l_thigh_link.STL"/>
    <mesh name="l_calf_link" class="/" file="l_calf_link.STL"/>
    <mesh name="l_ankle_pitch_link" class="/" file="l_ankle_pitch_link.STL"/>
    <mesh name="l_ankle_roll_link" class="/" file="l_ankle_roll_link.STL"/>
  </asset>

  <worldbody>
    <geom name="floor" class="/" size="100 100 0.125" type="plane" group="0" material="MatPlane"/>
    <light name="toplight_shadow" class="/" pos="0 0 5" dir="0.0990148 0.0990148 -0.990148" type="directional" ambient="0.04 0.04 0.04" diffuse="0.55 0.55 0.55" specular="0.12 0.12 0.12"/>
    <light name="toplight_fill" class="/" pos="0 0 5" dir="0.0990148 0.0990148 -0.990148" type="directional" castshadow="false" ambient="0.04 0.04 0.04" diffuse="0.3 0.3 0.3" specular="0.08 0.08 0.08"/>
    <body name="trunk" pos="-0.00265958 -0.00145191 0.00070213" quat="0.999999 0.000195387 -0.00100718 -0.0002677">
      <inertial pos="-0.000252661 0.000628176 0.0383912" quat="0.697395 0.00829147 0.0113173 0.716549" mass="1.90349" diaginertia="0.0127916 0.00474917 0.00345226"/>
      <joint name="//unnamed_joint_0" type="free"/>
      <geom name="//unnamed_geom_1" class="/" type="mesh" density="0" rgba="1 1 1 1" mesh="baselink_1"/>
      <geom name="//unnamed_geom_2" class="/" size="0.0481454 0.0481454 0.0481454" pos="0 0 0.0766035" type="box" rgba="1 1 1 1"/>
      <geom name="//unnamed_geom_3" class="reward_collision_sphere" size="0.0529599" pos="0 0 0.0670281"/>
      <site name="imu" class="/" pos="0.00163094 -0.00420837 0.00533804" size="0.00962908"/>
      <camera name="track" class="/" pos="0 -1.75769 0" quat="0.707107 0.707107 0 0" mode="trackcom"/>
      <camera name="ego_camera" class="/" pos="0.0789251 0 0.172358" quat="-0.5 -0.5 0.5 0.5"/>
      <body name="r_hip_pitch_link" pos="-0.000897261 -0.0201035 -0.0318123" quat="0.992343 0.000218632 -0.123515 -0.000459128">
        <inertial pos="-0.00158843 -0.0502535 0.000361049" quat="-0.0185814 0.707834 -0.0274232 0.705602" mass="0.340949" diaginertia="0.000145162 5.12366e-05 6.91836e-05"/>
        <joint name="r_hip_pitch_joint" class="/" pos="0 0 0" axis="-0.00130371 -0.999999 0.000564041" range="-1.75162 1.22926" armature="0.00954182" damping="0.0139091" frictionloss="0.0103708"/>
        <geom name="//unnamed_geom_4" class="/" type="mesh" density="0" rgba="0.75294 0.75294 0.75294 1" mesh="r_hip_pitch_link"/>
        <geom name="//unnamed_geom_5" class="/" size="0.000481454 0.000481454 0.000481454" type="box" rgba="0.75294 0.75294 0.75294 1"/>
        <body name="r_hip_roll_link" pos="-0.00117655 -0.0500604 -0.000479114" quat="1 -3.65843e-05 2.00742e-07 9.01828e-05">
          <inertial pos="0.00117087 0.000313591 -0.056439" quat="0.707634 -0.0786826 -0.0831537 0.697244" mass="0.349917" diaginertia="0.000427734 0.000143282 0.000103913"/>
          <joint name="r_hip_roll_joint" class="/" pos="0 0 0" axis="-1 -0.000416673 -0.000155477" stiffness="0.00345302" range="-0.163871 0.496399" armature="0.00831671" damping="0" frictionloss="0.0098324"/>
          <geom name="//unnamed_geom_6" class="/" type="mesh" density="0" rgba="0.75294 0.75294 0.75294 1" mesh="r_hip_roll_link"/>
          <geom name="//unnamed_geom_7" class="/" size="0.000481454 0.000481454 0.000481454" type="box" rgba="0.75294 0.75294 0.75294 1"/>
          <geom name="//unnamed_geom_8" class="reward_collision_sphere" size="0.0385163"/>
          <body name="r_thigh_link" pos="-0.00133163 -0.000423772 -0.0656979" quat="1 -0.000319143 0.000311194 -0.000336072">
            <inertial pos="0.00106696 0.000694801 -0.0471524" quat="0.734309 0.678719 0.0107824 0.00381945" mass="0.099433" diaginertia="0.000163503 4.97487e-05 4.59959e-05"/>
            <joint name="r_thigh_joint" class="/" pos="0 0 0" axis="0.000919724 0.00736882 -0.999972" range="-0.304786 0.61487" armature="0.0084826" damping="0.000424735" frictionloss="0.00936189"/>
            <geom name="//unnamed_geom_9" class="/" type="mesh" density="0" rgba="0.75294 0.75294 0.75294 1" mesh="r_thigh_link"/>
            <geom name="//unnamed_geom_10" class="/" size="0.000481454 0.000481454 0.000481454" type="box" rgba="0.75294 0.75294 0.75294 1"/>
            <body name="r_calf_link" pos="-0.00134872 0.000447711 -0.0677035" quat="0.947686 3.51269e-05 0.319205 1.70644e-05">
              <inertial pos="0.00153089 -0.00186426 -0.0668136" quat="0.99997 -0.00547232 0.00124258 0.00542347" mass="0.763044" diaginertia="0.00464753 0.00188846 0.000141233"/>
              <joint name="r_calf_joint" class="/" pos="0 0 0" axis="0.000386664 -0.999997 -0.00260366" stiffness="0.0100451" range="-1.66136 0.600041" armature="0.0110438" damping="0" frictionloss="0.0109132"/>
              <geom name="//unnamed_geom_11" class="/" type="mesh" density="0" rgba="0.75294 0.75294 0.75294 1" mesh="r_calf_link"/>
              <geom name="//unnamed_geom_12" class="/" size="0.000481454 0.000481454 0.000481454" type="box" rgba="0.75294 0.75294 0.75294 1"/>
              <geom name="//unnamed_geom_13" class="reward_collision_sphere" size="0.0385163"/>
              <body name="r_ankle_pitch_link" pos="-0.000591766 0.00146012 -0.131712" quat="0.980164 -0.001155 -0.198186 -0.00055231">
                <inertial pos="0.00341035 0.000584066 0.000777373" quat="0.00252185 0.706339 -0.00235717 0.707866" mass="0.153441" diaginertia="0.00039965 0.000118138 9.49294e-05"/>
                <joint name="r_ankle_pitch_joint" class="/" pos="0 0 0" axis="-0.0070661 -0.999898 0.0124317" range="-1.3392 0.539895" armature="0.00989944" damping="0.0071624" frictionloss="0.0089941"/>
                <geom name="//unnamed_geom_14" class="/" type="mesh" density="0" rgba="0.75294 0.75294 0.75294 1" mesh="r_ankle_pitch_link"/>
                <geom name="//unnamed_geom_15" class="/" size="0.0375534 0.0385163 0.0240727" type="box" rgba="0.75294 0.75294 0.75294 1"/>
                <body name="r_ankle_roll_link" pos="0.0819394 0.00365719 -0.000342243" quat="1 -1.61802e-06 -1.76604e-05 -1.16658e-07">
                  <inertial pos="-0.0246347 0.000335004 -0.0129719" quat="0.560666 0.430803 0.433194 0.558932" mass="0.469439" diaginertia="0.00154411 0.000544389 0.000235836"/>
                  <joint name="r_ankle_roll_joint" class="/" pos="0 0 0" axis="-0.999913 0.0111853 -0.00697058" stiffness="0.000851943" range="-0.158434 0.106586" armature="0.00917463" damping="0" frictionloss="0.00962033"/>
                  <geom name="//unnamed_geom_16" class="/" type="mesh" density="0" rgba="0.75294 0.75294 0.75294 1" mesh="r_ankle_roll_link"/>
                  <geom name="//unnamed_geom_17" class="/" type="mesh" rgba="0.75294 0.75294 0.75294 1" mesh="r_ankle_roll_link"/>
                  <geom name="right_foot" class="foot" size="0.0807269 0.0329473 0.00473885" pos="-0.0536691 0 -0.0421319"/>
                  <geom name="//unnamed_geom_19" class="reward_collision_sphere" size="0.0385163" pos="-0.0526167 0 -0.0191509"/>
                  <geom name="//unnamed_geom_20" class="reward_collision_sphere" size="0.0192582" pos="0.015785 0.0175769 -0.0383017"/>
                  <geom name="//unnamed_geom_21" class="reward_collision_sphere" size="0.0192582" pos="-0.12628 0.0175769 -0.0383017"/>
                  <site name="right_foot" class="foot" pos="-0.0536691 0 -0.0421319" size="0.00962908"/>
                </body>
              </body>
            </body>
          </body>
        </body>
      </body>
      <body name="l_hip_pitch_link" pos="0.00161737 0.019368 -0.0301617" quat="0.992289 -0.000415461 -0.123944 0.000913374">
        <inertial pos="0.00352637 0.0484817 0.000445829" quat="-0.0385469 0.705503 0.0293089 0.707051" mass="0.346116" diaginertia="0.000166987 5.66446e-05 8.27093e-05"/>
        <joint name="l_hip_pitch_joint" class="/" pos="0 0 0" axis="-0.00429613 0.999988 -0.00222351" range="-1.23396 1.76204" armature="0.0105279" damping="0" frictionloss="0.00937929"/>
        <geom name="//unnamed_geom_22" class="/" type="mesh" density="0" rgba="0.75294 0.75294 0.75294 1" mesh="l_hip_pitch_link"/>
        <geom name="//unnamed_geom_23" class="/" size="0.000481454 0.000481454 0.000481454" type="box" rgba="0.75294 0.75294 0.75294 1"/>
        <body name="l_hip_roll_link" pos="-0.0023403 0.0492904 0.00189501" quat="0.999999 -0.000741202 0.000534216 -0.000923446">
          <inertial pos="-0.00166401 -8.49835e-05 -0.0576419" quat="0.691239 -0.0798228 -0.0759618 0.714176" mass="0.337385" diaginertia="0.000424685 0.000142078 0.00010229"/>
          <joint name="l_hip_roll_joint" class="/" pos="0 0 0" axis="-0.999992 0.00389651 -0.000540521" stiffness="0.0093722" range="-0.480152 0.12935" armature="0.0104899" damping="0" frictionloss="0.00962497"/>
          <geom name="//unnamed_geom_24" class="/" type="mesh" density="0" rgba="0.75294 0.75294 0.75294 1" mesh="l_hip_roll_link"/>
          <geom name="//unnamed_geom_25" class="/" size="0.000481454 0.000481454 0.000481454" type="box" rgba="0.75294 0.75294 0.75294 1"/>
          <geom name="//unnamed_geom_26" class="reward_collision_sphere" size="0.0385163"/>
          <body name="l_thigh_link" pos="-1.88351e-05 -0.00118773 -0.0660471" quat="1 9.66909e-05 -0.000267586 -0.000131495">
            <inertial pos="0.000566676 -0.00138313 -0.0450965" quat="0.675163 0.737668 -0.00075169 0.000687693" mass="0.100163" diaginertia="0.000161128 4.97011e-05 4.61045e-05"/>
            <joint name="l_thigh_joint" class="/" pos="0 0 0" axis="-0.00355339 0.00314656 -0.999989" range="-0.598076 0.307713" armature="0.00941901" damping="0.000400523" frictionloss="0.00973501"/>
            <geom name="//unnamed_geom_27" class="/" type="mesh" density="0" rgba="0.75294 0.75294 0.75294 1" mesh="l_thigh_link"/>
            <geom name="//unnamed_geom_28" class="/" size="0.000481454 0.000481454 0.000481454" type="box" rgba="0.75294 0.75294 0.75294 1"/>
            <body name="l_calf_link" pos="0.00105182 -0.00223327 -0.0653864" quat="0.947368 -0.000183718 0.320146 -9.0672e-05">
              <inertial pos="0.00022685 0.00444006 -0.0675626" quat="0.999853 0.00907121 0.00874059 0.0115994" mass="0.724415" diaginertia="0.00457282 0.00185492 0.000141493"/>
              <joint name="l_calf_joint" class="/" pos="0 0 0" axis="0.00220856 0.999997 0.00138374" stiffness="0.00265441" range="-0.636067 1.64732" armature="0.00834301" damping="0.0053526" frictionloss="0.0109142"/>
              <geom name="//unnamed_geom_29" class="/" type="mesh" density="0" rgba="0.75294 0.75294 0.75294 1" mesh="l_calf_link"/>
              <geom name="//unnamed_geom_30" class="/" size="0.000481454 0.000481454 0.000481454" type="box" rgba="0.75294 0.75294 0.75294 1"/>
              <geom name="//unnamed_geom_31" class="reward_collision_sphere" size="0.0385163"/>
              <body name="l_ankle_pitch_link" pos="0.000779347 0.00132258 -0.136352" quat="0.980073 0.000122474 -0.198638 -2.88503e-05">
                <inertial pos="0.0049496 -0.000925073 0.000209718" quat="-0.00170902 0.70772 0.00323451 0.706483" mass="0.158853" diaginertia="0.000403796 0.00011794 9.43191e-05"/>
                <joint name="l_ankle_pitch_joint" class="/" pos="0 0 0" axis="-0.000706035 0.999997 -0.00245336" range="-0.4862 1.30378" armature="0.0096411" damping="0.00348156" frictionloss="0.00939422"/>
                <geom name="//unnamed_geom_32" class="/" type="mesh" density="0" rgba="0.75294 0.75294 0.75294 1" mesh="l_ankle_pitch_link"/>
                <geom name="//unnamed_geom_33" class="/" size="0.0375534 0.0385163 0.0240727" type="box" rgba="0.75294 0.75294 0.75294 1"/>
                <body name="l_ankle_roll_link" pos="0.0769491 0.00285116 0.000298607" quat="1 -0.000437027 0.000188873 0.000176811">
                  <inertial pos="-0.0229385 -0.00104921 -0.0135942" quat="0.562762 0.430205 0.432807 0.557585" mass="0.462553" diaginertia="0.00141839 0.000512029 0.000223777"/>
                  <joint name="l_ankle_roll_joint" class="/" pos="0 0 0" axis="-0.999935 0.00807612 0.00810609" range="-0.131612 0.152641" armature="0.00987819" damping="0.00996889" frictionloss="0.00912671"/>
                  <geom name="//unnamed_geom_34" class="/" type="mesh" density="0" rgba="0.75294 0.75294 0.75294 1" mesh="l_ankle_roll_link"/>
                  <geom name="//unnamed_geom_35" class="/" type="mesh" rgba="0.75294 0.75294 0.75294 1" mesh="l_ankle_roll_link"/>
                  <geom name="left_foot" class="foot" size="0.0836025 0.0368135 0.00476421" pos="-0.0536691 0 -0.0421319"/>
                  <geom name="//unnamed_geom_37" class="reward_collision_sphere" size="0.0385163" pos="-0.0526167 0 -0.0191509"/>
                  <geom name="//unnamed_geom_38" class="reward_collision_sphere" size="0.0192582" pos="0.015785 -0.0175769 -0.0383017"/>
                  <geom name="//unnamed_geom_39" class="reward_collision_sphere" size="0.0192582" pos="-0.12628 -0.0175769 -0.0383017"/>
                  <site name="left_foot" class="foot" pos="-0.0536691 0 -0.0421319" size="0.00962908"/>
                </body>
              </body>
            </body>
          </body>
        </body>
      </body>
    </body>
  </worldbody>

  <contact>
    <pair class="/" geom1="floor" geom2="right_foot" name="//unnamed_contact_1"/>
    <pair class="/" geom1="floor" geom2="left_foot" name="//unnamed_contact_0"/>
  </contact>

  <actuator>
    <general name="r_hip_pitch_joint" class="/" joint="r_hip_pitch_joint" forcerange="-20.9319 20.9319" gainprm="19.1613" biasprm="0 -19.1613 -0.481347"/>
    <general name="r_hip_roll_joint" class="/" joint="r_hip_roll_joint" forcerange="-20.08 20.08" gainprm="19.1613" biasprm="0 -19.1613 -0.481347"/>
    <general name="r_thigh_joint" class="/" joint="r_thigh_joint" forcerange="-20.3263 20.3263" gainprm="19.1613" biasprm="0 -19.1613 -0.481347"/>
    <general name="r_calf_joint" class="/" joint="r_calf_joint" forcerange="-20.7094 20.7094" gainprm="19.1613" biasprm="0 -19.1613 -0.481347"/>
    <general name="r_ankle_pitch_joint" class="/" joint="r_ankle_pitch_joint" forcerange="-19.5806 19.5806" gainprm="19.1613" biasprm="0 -19.1613 -0.481347"/>
    <general name="r_ankle_roll_joint" class="/" joint="r_ankle_roll_joint" forcerange="-20.7926 20.7926" gainprm="19.1613" biasprm="0 -19.1613 -0.481347"/>
    <general name="l_hip_pitch_joint" class="/" joint="l_hip_pitch_joint" forcerange="-19.8827 19.8827" gainprm="19.1613" biasprm="0 -19.1613 -0.481347"/>
    <general name="l_hip_roll_joint" class="/" joint="l_hip_roll_joint" forcerange="-20.1329 20.1329" gainprm="19.1613" biasprm="0 -19.1613 -0.481347"/>
    <general name="l_thigh_joint" class="/" joint="l_thigh_joint" forcerange="-20.3008 20.3008" gainprm="19.1613" biasprm="0 -19.1613 -0.481347"/>
    <general name="l_calf_joint" class="/" joint="l_calf_joint" forcerange="-22.2296 22.2296" gainprm="19.1613" biasprm="0 -19.1613 -0.481347"/>
    <general name="l_ankle_pitch_joint" class="/" joint="l_ankle_pitch_joint" forcerange="-20.1433 20.1433" gainprm="19.1613" biasprm="0 -19.1613 -0.481347"/>
    <general name="l_ankle_roll_joint" class="/" joint="l_ankle_roll_joint" forcerange="-18.8795 18.8795" gainprm="19.1613" biasprm="0 -19.1613 -0.481347"/>
  </actuator>

  <sensor>
    <gyro site="imu" name="imu_angular_velocity"/>
    <velocimeter site="imu" name="imu_linear_velocity"/>
    <framelinvel objtype="site" objname="left_foot" name="left_foot_global_linear_velocity"/>
    <framelinvel objtype="site" objname="right_foot" name="right_foot_global_linear_velocity"/>
  </sensor>

  <keyframe>
    <key name="home" qpos="0 0 0.291 1 0 0 0 0.4 0 0 -0.8 0.4 0 -0.4 0 0 0.8 -0.4 0"/>
  </keyframe>
</mujoco>
