<mujoco model="pi_12dof_release_v1">
  <compiler angle="radian" assetdir="assets" balanceinertia="true" inertiafromgeom="false"/>

  <option timestep="0.005" density="1.2" viscosity="2e-05"/>

  <size nkey="1"/>

  <visual>
    <quality shadowsize="8192"/>
    <map shadowclip="0.5"/>
  </visual>

  <default>
    <default class="/">
      <joint armature="0.01" damping="0.01" frictionloss="0.01"/>
      <geom contype="0" conaffinity="0" group="1" solref="-1000 -80"/>
      <site size="0.01 0.005 0.005" group="5"/>
      <general forcelimited="true" biastype="affine" gainprm="20" biasprm="0 -20 -0.5"/>
      <default class="foot">
        <geom size="0.0845 0.036 0.005" type="box" condim="6" group="4" priority="1" friction="0.9 0.2 0.2" solimp="0.015 1 0.005"/>
      </default>
      <default class="reward_collision_sphere">
        <geom group="5" rgba="1 0 0 1"/>
      </default>
    </default>
  </default>

  <asset>
    <texture type="skybox" colorspace="auto" name="//unnamed_texture_0" builtin="gradient" rgb1="0.95 0.95 0.95" rgb2="0.95 0.95 0.95" width="100" height="600"/>
    <texture type="2d" colorspace="auto" name="texplane" builtin="checker" rgb1="0.345 0.575 0.748" rgb2="0.345 0.575 0.748" markrgb="1 1 1" width="512" height="512"/>
    <material name="MatPlane" class="/" texture="texplane" texuniform="true" texrepeat="2 2" specular="0.9"/>
    <mesh name="baselink_1" class="/" file="baselink_1.STL"/>
    <mesh name="r_hip_pitch_link" class="/" file="r_hip_pitch_link.STL"/>
    <mesh name="r_hip_roll_link" class="/" file="r_hip_roll_link.STL"/>
    <mesh name="r_thigh_link" class="/" file="r_thigh_link.STL"/>
    <mesh name="r_calf_link" class="/" file="r_calf_link.STL"/>
    <mesh name="r_ankle_pitch_link" class="/" file="r_ankle_pitch_link.STL"/>
    <mesh name="r_ankle_roll_link" class="/" file="r_ankle_roll_link.STL"/>
    <mesh name="l_hip_pitch_link" class="/" file="l_hip_pitch_link.STL"/>
    <mesh name="l_hip_roll_link" class="/" file="l_hip_roll_link.STL"/>
    <mesh name="l_thigh_link" class="/" file="l_thigh_link.STL"/>
    <mesh name="l_calf_link" class="/" file="l_calf_link.STL"/>
    <mesh name="l_ankle_pitch_link" class="/" file="l_ankle_pitch_link.STL"/>
    <mesh name="l_ankle_roll_link" class="/" file="l_ankle_roll_link.STL"/>
  </asset>

  <worldbody>
    <geom name="floor" class="/" size="100 100 0.125" type="plane" group="0" material="MatPlane"/>
    <light name="toplight_shadow" class="/" pos="0 0 5" dir="0.0990148 0.0990148 -0.990148" type="directional" ambient="0.04 0.04 0.04" diffuse="0.55 0.55 0.55" specular="0.12 0.12 0.12"/>
    <light name="toplight_fill" class="/" pos="0 0 5" dir="0.0990148 0.0990148 -0.990148" type="directional" castshadow="false" ambient="0.04 0.04 0.04" diffuse="0.3 0.3 0.3" specular="0.08 0.08 0.08"/>
    <body name="trunk" pos="-0.0025356 -0.00252208 -0.000462651" quat="0.999999 -0.000483006 0.000685496 -0.00111347">
      <inertial pos="8.40572e-05 2.3422e-05 0.04044" quat="0.69606 0.0111989 0.00883697 0.717841" mass="2.10381" diaginertia="0.0120954 0.00614343 0.00455543"/>
      <joint name="//unnamed_joint_0" type="free"/>
      <geom name="//unnamed_geom_1" class="/" type="mesh" density="0" rgba="1 1 1 1" mesh="baselink_1"/>
      <geom name="//unnamed_geom_2" class="/" size="0.049747 0.049747 0.049747" pos="0 0 0.08102" type="box" rgba="1 1 1 1"/>
      <geom name="//unnamed_geom_3" class="reward_collision_sphere" size="0.0547218" pos="0 0 0.0708925"/>
      <site name="imu" class="/" pos="0.00242494 0.00106068 0.0029216" size="0.00994941"/>
      <camera name="track" class="/" pos="0 -1.85711 0" quat="0.707107 0.707107 0 0" mode="trackcom"/>
      <camera name="ego_camera" class="/" pos="0.0782639 0 0.182295" quat="-0.5 -0.5 0.5 0.5"/>
      <body name="r_hip_pitch_link" pos="-0.00169048 -0.0228834 -0.0320609" quat="0.99207 -0.000627275 -0.125685 0.000454989">
        <inertial pos="-0.00122619 -0.0541446 -0.00112972" quat="-0.0189188 0.70584 -0.0283367 0.707552" mass="0.381639" diaginertia="0.000140846 6.77121e-05 9.35345e-05"/>
        <joint name="r_hip_pitch_joint" class="/" pos="0 0 0" axis="0.00807745 -0.999965 -0.00237074" range="-1.74459 1.24538" armature="0.0100404" damping="0.00747755" frictionloss="0.0112284"/>
        <geom name="//unnamed_geom_4" class="/" type="mesh" density="0" rgba="0.75294 0.75294 0.75294 1" mesh="r_hip_pitch_link"/>
        <geom name="//unnamed_geom_5" class="/" size="0.00049747 0.00049747 0.00049747" type="box" rgba="0.75294 0.75294 0.75294 1"/>
        <body name="r_hip_roll_link" pos="0.000171404 -0.052635 0.000528976" quat="1 -1.13846e-05 8.88922e-06 -1.21256e-06">
          <inertial pos="0.000790895 -0.000638003 -0.0591769" quat="0.70651 -0.0782512 -0.0824482 0.698514" mass="0.386644" diaginertia="0.000416912 0.000190706 0.00013631"/>
          <joint name="r_hip_roll_joint" class="/" pos="0 0 0" axis="-0.999999 -0.000607186 0.0010605" stiffness="0.00965281" range="-0.176066 0.524259" armature="0.00848188" damping="0" frictionloss="0.0101506"/>
          <geom name="//unnamed_geom_6" class="/" type="mesh" density="0" rgba="0.75294 0.75294 0.75294 1" mesh="r_hip_roll_link"/>
          <geom name="//unnamed_geom_7" class="/" size="0.00049747 0.00049747 0.00049747" type="box" rgba="0.75294 0.75294 0.75294 1"/>
          <geom name="//unnamed_geom_8" class="reward_collision_sphere" size="0.0397976"/>
          <body name="r_thigh_link" pos="-0.00110094 -5.38222e-05 -0.0693764" quat="0.999999 -0.000745105 0.000240083 0.000871476">
            <inertial pos="0.00224312 0.00194451 -0.0506704" quat="0.74026 0.672192 -0.000240393 0.0131376" mass="0.110097" diaginertia="0.000154595 6.63961e-05 5.97699e-05"/>
            <joint name="r_thigh_joint" class="/" pos="0 0 0" axis="0.00713389 0.0095155 -0.999929" range="-0.303068 0.640858" armature="0.00853476" damping="0.0084054" frictionloss="0.00996797"/>
            <geom name="//unnamed_geom_9" class="/" type="mesh" density="0" rgba="0.75294 0.75294 0.75294 1" mesh="r_thigh_link"/>
            <geom name="//unnamed_geom_10" class="/" size="0.00049747 0.00049747 0.00049747" type="box" rgba="0.75294 0.75294 0.75294 1"/>
            <body name="r_calf_link" pos="-0.000935305 0.000279504 -0.0720825" quat="0.947661 -0.000551236 0.319276 -2.47254e-05">
              <inertial pos="0.0023519 -0.00123798 -0.0708469" quat="0.999985 -0.0025934 0.000850547 0.00473196" mass="0.845567" diaginertia="0.00455211 0.00252102 0.000186443"/>
              <joint name="r_calf_joint" class="/" pos="0 0 0" axis="-0.00112132 -0.999999 -0.000468386" stiffness="0.0111869" range="-1.6514 0.591987" armature="0.0111597" damping="0.000809811" frictionloss="0.0110718"/>
              <geom name="//unnamed_geom_11" class="/" type="mesh" density="0" rgba="0.75294 0.75294 0.75294 1" mesh="r_calf_link"/>
              <geom name="//unnamed_geom_12" class="/" size="0.00049747 0.00049747 0.00049747" type="box" rgba="0.75294 0.75294 0.75294 1"/>
              <geom name="//unnamed_geom_13" class="reward_collision_sphere" size="0.0397976"/>
              <body name="r_ankle_pitch_link" pos="-0.000915637 0.00145325 -0.138974" quat="0.980254 -0.000732513 -0.197742 -0.000601477">
                <inertial pos="0.00236897 0.00116809 0.000145081" quat="-0.000217286 0.70681 -0.00652962 0.707374" mass="0.168014" diaginertia="0.000380991 0.000151068 0.000122895"/>
                <joint name="r_ankle_pitch_joint" class="/" pos="0 0 0" axis="-0.0021696 -0.999925 0.012018" range="-1.35288 0.555471" armature="0.0105586" damping="0.00917674" frictionloss="0.00873323"/>
                <geom name="//unnamed_geom_14" class="/" type="mesh" density="0" rgba="0.75294 0.75294 0.75294 1" mesh="r_ankle_pitch_link"/>
                <geom name="//unnamed_geom_15" class="/" size="0.0388027 0.0397976 0.0248735" type="box" rgba="0.75294 0.75294 0.75294 1"/>
                <body name="r_ankle_roll_link" pos="0.0820526 0.00338169 -0.000169085" quat="1 -3.74552e-05 7.16582e-05 -3.55735e-05">
                  <inertial pos="-0.0229342 -7.27902e-06 -0.0142601" quat="0.56275 0.426564 0.434437 0.559124" mass="0.524534" diaginertia="0.00150007 0.000712878 0.000313168"/>
                  <joint name="r_ankle_roll_joint" class="/" pos="0 0 0" axis="-0.999957 -0.00399133 0.00833524" range="-0.13956 0.0950151" armature="0.0092918" damping="0" frictionloss="0.0102167"/>
                  <geom name="//unnamed_geom_16" class="/" type="mesh" density="0" rgba="0.75294 0.75294 0.75294 1" mesh="r_ankle_roll_link"/>
                  <geom name="//unnamed_geom_17" class="/" type="mesh" rgba="0.75294 0.75294 0.75294 1" mesh="r_ankle_roll_link"/>
                  <geom name="right_foot" class="foot" size="0.0885904 0.0355418 0.00464562" pos="-0.0532194 0 -0.044561"/>
                  <geom name="//unnamed_geom_19" class="reward_collision_sphere" size="0.0397976" pos="-0.0521759 0 -0.020255"/>
                  <geom name="//unnamed_geom_20" class="reward_collision_sphere" size="0.0198988" pos="0.0156528 0.0185711 -0.04051"/>
                  <geom name="//unnamed_geom_21" class="reward_collision_sphere" size="0.0198988" pos="-0.125222 0.0185711 -0.04051"/>
                  <site name="right_foot" class="foot" pos="-0.0532194 0 -0.044561" size="0.00994941"/>
                </body>
              </body>
            </body>
          </body>
        </body>
      </body>
      <body name="l_hip_pitch_link" pos="0.000724422 0.0211982 -0.0311977" quat="0.992123 -0.000604761 -0.125266 1.06481e-05">
        <inertial pos="0.00339949 0.0508258 0.000110695" quat="-0.0384384 0.705549 0.0298989 0.706986" mass="0.380006" diaginertia="0.000158806 7.50654e-05 0.000108417"/>
        <joint name="l_hip_pitch_joint" class="/" pos="0 0 0" axis="-0.000976214 0.999993 -0.00348607" range="-1.20807 1.76106" armature="0.0113073" damping="0" frictionloss="0.0103161"/>
        <geom name="//unnamed_geom_22" class="/" type="mesh" density="0" rgba="0.75294 0.75294 0.75294 1" mesh="l_hip_pitch_link"/>
        <geom name="//unnamed_geom_23" class="/" size="0.00049747 0.00049747 0.00049747" type="box" rgba="0.75294 0.75294 0.75294 1"/>
        <body name="l_hip_roll_link" pos="-0.00280327 0.0532703 0.00266194" quat="0.999999 -0.00107715 0.00067742 -0.000411043">
          <inertial pos="-0.0011754 0.000674401 -0.060921" quat="0.690516 -0.08192 -0.082481 0.713915" mass="0.368901" diaginertia="0.000409402 0.000184861 0.000136665"/>
          <joint name="l_hip_roll_joint" class="/" pos="0 0 0" axis="-0.999997 0.00241654 -0.000670298" stiffness="0.00849049" range="-0.494874 0.105821" armature="0.0113212" damping="0" frictionloss="0.0106223"/>
          <geom name="//unnamed_geom_24" class="/" type="mesh" density="0" rgba="0.75294 0.75294 0.75294 1" mesh="l_hip_roll_link"/>
          <geom name="//unnamed_geom_25" class="/" size="0.00049747 0.00049747 0.00049747" type="box" rgba="0.75294 0.75294 0.75294 1"/>
          <geom name="//unnamed_geom_26" class="reward_collision_sphere" size="0.0397976"/>
          <body name="l_thigh_link" pos="-0.000379077 -0.000744322 -0.0686156" quat="1 -5.29161e-06 -4.12407e-05 5.06124e-05">
            <inertial pos="0.000396799 -0.00178581 -0.0462897" quat="0.675743 0.737137 -0.00106015 0.00058897" mass="0.110507" diaginertia="0.000155208 6.58004e-05 6.18587e-05"/>
            <joint name="l_thigh_joint" class="/" pos="0 0 0" axis="0.00363916 -0.00439909 -0.999984" stiffness="7.89401e-05" range="-0.60215 0.322164" armature="0.0089928" damping="0.00257778" frictionloss="0.0104429"/>
            <geom name="//unnamed_geom_27" class="/" type="mesh" density="0" rgba="0.75294 0.75294 0.75294 1" mesh="l_thigh_link"/>
            <geom name="//unnamed_geom_28" class="/" size="0.00049747 0.00049747 0.00049747" type="box" rgba="0.75294 0.75294 0.75294 1"/>
            <body name="l_calf_link" pos="-0.000368392 -0.00268667 -0.0686308" quat="0.947802 0.000813413 0.318857 -0.00100985">
              <inertial pos="0.000419774 0.00563799 -0.0712521" quat="0.999947 -0.00777257 -0.00670765 -0.000197899" mass="0.79694" diaginertia="0.00443083 0.00246545 0.000183425"/>
              <joint name="l_calf_joint" class="/" pos="0 0 0" axis="-0.00541271 0.999985 -0.000549212" range="-0.627985 1.63259" armature="0.00879504" damping="0.0104746" frictionloss="0.0111856"/>
              <geom name="//unnamed_geom_29" class="/" type="mesh" density="0" rgba="0.75294 0.75294 0.75294 1" mesh="l_calf_link"/>
              <geom name="//unnamed_geom_30" class="/" size="0.00049747 0.00049747 0.00049747" type="box" rgba="0.75294 0.75294 0.75294 1"/>
              <geom name="//unnamed_geom_31" class="reward_collision_sphere" size="0.0397976"/>
              <body name="l_ankle_pitch_link" pos="0.000928791 -0.000160869 -0.144865" quat="0.980087 0.000469024 -0.198567 -0.000204062">
                <inertial pos="0.0050745 -0.00230842 0.000388428" quat="-0.00229501 0.707059 0.00253002 0.707146" mass="0.169952" diaginertia="0.000376037 0.000152363 0.000122835"/>
                <joint name="l_ankle_pitch_joint" class="/" pos="0 0 0" axis="0.00247307 0.999988 0.00427153" stiffness="0.00374677" range="-0.48295 1.30623" armature="0.00997768" damping="0.0094975" frictionloss="0.0103369"/>
                <geom name="//unnamed_geom_32" class="/" type="mesh" density="0" rgba="0.75294 0.75294 0.75294 1" mesh="l_ankle_pitch_link"/>
                <geom name="//unnamed_geom_33" class="/" size="0.0388027 0.0397976 0.0248735" type="box" rgba="0.75294 0.75294 0.75294 1"/>
                <body name="l_ankle_roll_link" pos="0.0768509 0.00308593 0.000108348" quat="1 -0.000134744 0.000193361 -0.000516563">
                  <inertial pos="-0.0229888 -0.000850943 -0.012995" quat="0.559747 0.432157 0.432439 0.559393" mass="0.509385" diaginertia="0.00138703 0.000667677 0.000301311"/>
                  <joint name="l_ankle_roll_joint" class="/" pos="0 0 0" axis="-0.999894 0.0131411 0.00632753" range="-0.143015 0.15297" armature="0.00988922" damping="0.0174994" frictionloss="0.00957751"/>
                  <geom name="//unnamed_geom_34" class="/" type="mesh" density="0" rgba="0.75294 0.75294 0.75294 1" mesh="l_ankle_roll_link"/>
                  <geom name="//unnamed_geom_35" class="/" type="mesh" rgba="0.75294 0.75294 0.75294 1" mesh="l_ankle_roll_link"/>
                  <geom name="left_foot" class="foot" size="0.0823489 0.0372515 0.00484538" pos="-0.0532194 0 -0.044561"/>
                  <geom name="//unnamed_geom_37" class="reward_collision_sphere" size="0.0397976" pos="-0.0521759 0 -0.020255"/>
                  <geom name="//unnamed_geom_38" class="reward_collision_sphere" size="0.0198988" pos="0.0156528 -0.0185711 -0.04051"/>
                  <geom name="//unnamed_geom_39" class="reward_collision_sphere" size="0.0198988" pos="-0.125222 -0.0185711 -0.04051"/>
                  <site name="left_foot" class="foot" pos="-0.0532194 0 -0.044561" size="0.00994941"/>
                </body>
              </body>
            </body>
          </body>
        </body>
      </body>
    </body>
  </worldbody>

  <contact>
    <pair class="/" geom1="floor" geom2="right_foot" name="//unnamed_contact_1"/>
    <pair class="/" geom1="floor" geom2="left_foot" name="//unnamed_contact_0"/>
  </contact>

  <actuator>
    <general name="r_hip_pitch_joint" class="/" joint="r_hip_pitch_joint" forcerange="-21.6867 21.6867" gainprm="19.4411" biasprm="0 -19.4411 -0.477684"/>
    <general name="r_hip_roll_joint" class="/" joint="r_hip_roll_joint" forcerange="-21.018 21.018" gainprm="19.4411" biasprm="0 -19.4411 -0.477684"/>
    <general name="r_thigh_joint" class="/" joint="r_thigh_joint" forcerange="-21.1338 21.1338" gainprm="19.4411" biasprm="0 -19.4411 -0.477684"/>
    <general name="r_calf_joint" class="/" joint="r_calf_joint" forcerange="-21.7122 21.7122" gainprm="19.4411" biasprm="0 -19.4411 -0.477684"/>
    <general name="r_ankle_pitch_joint" class="/" joint="r_ankle_pitch_joint" forcerange="-20.0585 20.0585" gainprm="19.4411" biasprm="0 -19.4411 -0.477684"/>
    <general name="r_ankle_roll_joint" class="/" joint="r_ankle_roll_joint" forcerange="-21.7179 21.7179" gainprm="19.4411" biasprm="0 -19.4411 -0.477684"/>
    <general name="l_hip_pitch_joint" class="/" joint="l_hip_pitch_joint" forcerange="-20.7901 20.7901" gainprm="19.4411" biasprm="0 -19.4411 -0.477684"/>
    <general name="l_hip_roll_joint" class="/" joint="l_hip_roll_joint" forcerange="-19.7372 19.7372" gainprm="19.4411" biasprm="0 -19.4411 -0.477684"/>
    <general name="l_thigh_joint" class="/" joint="l_thigh_joint" forcerange="-20.7621 20.7621" gainprm="19.4411" biasprm="0 -19.4411 -0.477684"/>
    <general name="l_calf_joint" class="/" joint="l_calf_joint" forcerange="-22.629 22.629" gainprm="19.4411" biasprm="0 -19.4411 -0.477684"/>
    <general name="l_ankle_pitch_joint" class="/" joint="l_ankle_pitch_joint" forcerange="-20.7981 20.7981" gainprm="19.4411" biasprm="0 -19.4411 -0.477684"/>
    <general name="l_ankle_roll_joint" class="/" joint="l_ankle_roll_joint" forcerange="-18.7992 18.7992" gainprm="19.4411" biasprm="0 -19.4411 -0.477684"/>
  </actuator>

  <sensor>
    <gyro site="imu" name="imu_angular_velocity"/>
    <velocimeter site="imu" name="imu_linear_velocity"/>
    <framelinvel objtype="site" objname="left_foot" name="left_foot_global_linear_velocity"/>
    <framelinvel objtype="site" objname="right_foot" name="right_foot_global_linear_velocity"/>
  </sensor>

  <keyframe>
    <key name="home" qpos="0 0 0.291 1 0 0 0 0.4 0 0 -0.8 0.4 0 -0.4 0 0 0.8 -0.4 0"/>
  </keyframe>
</mujoco>
