<mujoco model="pi_12dof_release_v1">
  <compiler angle="radian" assetdir="assets" balanceinertia="true" inertiafromgeom="false"/>

  <option timestep="0.005" density="1.2" viscosity="2e-05"/>

  <size nkey="1"/>

  <visual>
    <quality shadowsize="8192"/>
    <map shadowclip="0.5"/>
  </visual>

  <default>
    <default class="/">
      <joint armature="0.01" damping="0.01" frictionloss="0.01"/>
      <geom contype="0" conaffinity="0" group="1" solref="-1000 -80"/>
      <site size="0.01 0.005 0.005" group="5"/>
      <general forcelimited="true" biastype="affine" gainprm="20" biasprm="0 -20 -0.5"/>
      <default class="foot">
        <geom size="0.0845 0.036 0.005" type="box" condim="6" group="4" priority="1" friction="0.9 0.2 0.2" solimp="0.015 1 0.005"/>
      </default>
      <default class="reward_collision_sphere">
        <geom group="5" rgba="1 0 0 1"/>
      </default>
    </default>
  </default>

  <asset>
    <texture type="skybox" colorspace="auto" name="//unnamed_texture_0" builtin="gradient" rgb1="0.95 0.95 0.95" rgb2="0.95 0.95 0.95" width="100" height="600"/>
    <texture type="2d" colorspace="auto" name="texplane" builtin="checker" rgb1="0.345 0.575 0.748" rgb2="0.345 0.575 0.748" markrgb="1 1 1" width="512" height="512"/>
    <material name="MatPlane" class="/" texture="texplane" texuniform="true" texrepeat="2 2" specular="0.9"/>
    <mesh name="baselink_1" class="/" file="baselink_1.STL"/>
    <mesh name="r_hip_pitch_link" class="/" file="r_hip_pitch_link.STL"/>
    <mesh name="r_hip_roll_link" class="/" file="r_hip_roll_link.STL"/>
    <mesh name="r_thigh_link" class="/" file="r_thigh_link.STL"/>
    <mesh name="r_calf_link" class="/" file="r_calf_link.STL"/>
    <mesh name="r_ankle_pitch_link" class="/" file="r_ankle_pitch_link.STL"/>
    <mesh name="r_ankle_roll_link" class="/" file="r_ankle_roll_link.STL"/>
    <mesh name="l_hip_pitch_link" class="/" file="l_hip_pitch_link.STL"/>
    <mesh name="l_hip_roll_link" class="/" file="l_hip_roll_link.STL"/>
    <mesh name="l_thigh_link" class="/" file="l_thigh_link.STL"/>
    <mesh name="l_calf_link" class="/" file="l_calf_link.STL"/>
    <mesh name="l_ankle_pitch_link" class="/" file="l_ankle_pitch_link.STL"/>
    <mesh name="l_ankle_roll_link" class="/" file="l_ankle_roll_link.STL"/>
  </asset>

  <worldbody>
    <geom name="floor" class="/" size="100 100 0.125" type="plane" group="0" material="MatPlane"/>
    <light name="toplight_shadow" class="/" pos="0 0 5" dir="0.0990148 0.0990148 -0.990148" type="directional" ambient="0.04 0.04 0.04" diffuse="0.55 0.55 0.55" specular="0.12 0.12 0.12"/>
    <light name="toplight_fill" class="/" pos="0 0 5" dir="0.0990148 0.0990148 -0.990148" type="directional" castshadow="false" ambient="0.04 0.04 0.04" diffuse="0.3 0.3 0.3" specular="0.08 0.08 0.08"/>
    <body name="trunk" pos="-0.000915858 -0.00270212 -0.00218126" quat="0.999999 0.0010496 -0.000369813 0.000136003">
      <inertial pos="0.00185027 -0.0017601 0.0478901" quat="0.692454 0.0165839 0.00235781 0.721267" mass="2.49759" diaginertia="0.00901548 0.00754184 0.00950518"/>
      <joint name="//unnamed_joint_0" type="free"/>
      <geom name="//unnamed_geom_1" class="/" type="mesh" density="0" rgba="1 1 1 1" mesh="baselink_1"/>
      <geom name="//unnamed_geom_2" class="/" size="0.0521261 0.0521261 0.0521261" pos="0 0 0.0939218" type="box" rgba="1 1 1 1"/>
      <geom name="//unnamed_geom_3" class="reward_collision_sphere" size="0.0573387" pos="0 0 0.0821816"/>
      <site name="imu" class="/" pos="-0.00299067 0.00993672 -0.00574618" size="0.0104252"/>
      <camera name="track" class="/" pos="0 -1.93411 0" quat="0.707107 0.707107 0 0" mode="trackcom"/>
      <camera name="ego_camera" class="/" pos="0.0739866 0 0.211324" quat="-0.5 -0.5 0.5 0.5"/>
      <body name="r_hip_pitch_link" pos="-0.00245439 -0.0249814 -0.0356584" quat="0.992163 0.000288748 -0.124952 -0.000305112">
        <inertial pos="0.000634152 -0.056919 -0.00270571" quat="-0.0169764 0.704149 -0.0319921 0.709128" mass="0.431979" diaginertia="0.00010405 8.34553e-05 0.000196072"/>
        <joint name="r_hip_pitch_joint" class="/" pos="0 0 0" axis="-0.00272468 -0.999926 -0.0118657" stiffness="0.00413573" range="-1.75198 1.28142" armature="0.0102919" damping="0.00537733" frictionloss="0.0118158"/>
        <geom name="//unnamed_geom_4" class="/" type="mesh" density="0" rgba="0.75294 0.75294 0.75294 1" mesh="r_hip_pitch_link"/>
        <geom name="//unnamed_geom_5" class="/" size="0.000521261 0.000521261 0.000521261" type="box" rgba="0.75294 0.75294 0.75294 1"/>
        <body name="r_hip_roll_link" pos="0.00086446 -0.05306 0.00239376" quat="1 -1.41009e-05 4.69032e-05 7.5616e-06">
          <inertial pos="-0.000921932 -0.00112371 -0.0698078" quat="0.709476 -0.0796803 -0.0817231 0.695425" mass="0.437598" diaginertia="0.000317724 0.000239734 0.000280348"/>
          <joint name="r_hip_roll_joint" class="/" pos="0 0 0" axis="-1 0.000345106 0.00075155" stiffness="0.0102904" range="-0.163397 0.550941" armature="0.00956256" damping="0" frictionloss="0.0100468"/>
          <geom name="//unnamed_geom_6" class="/" type="mesh" density="0" rgba="0.75294 0.75294 0.75294 1" mesh="r_hip_roll_link"/>
          <geom name="//unnamed_geom_7" class="/" size="0.000521261 0.000521261 0.000521261" type="box" rgba="0.75294 0.75294 0.75294 1"/>
          <geom name="//unnamed_geom_8" class="reward_collision_sphere" size="0.0417009"/>
          <body name="r_thigh_link" pos="-0.000315209 0.0015933 -0.0805545" quat="0.999999 -0.000994634 0.000220951 0.000922213">
            <inertial pos="0.0029509 0.00337521 -0.0582605" quat="0.742982 0.669309 -0.00203675 5.18458e-05" mass="0.130038" diaginertia="0.000114597 8.29852e-05 0.000125019"/>
            <joint name="r_thigh_joint" class="/" pos="0 0 0" axis="0.00197773 0.0106246 -0.999942" stiffness="0.00217943" range="-0.297988 0.652233" armature="0.00939482" damping="0.0178535" frictionloss="0.0109471"/>
            <geom name="//unnamed_geom_9" class="/" type="mesh" density="0" rgba="0.75294 0.75294 0.75294 1" mesh="r_thigh_link"/>
            <geom name="//unnamed_geom_10" class="/" size="0.000521261 0.000521261 0.000521261" type="box" rgba="0.75294 0.75294 0.75294 1"/>
            <body name="r_calf_link" pos="-2.19256e-05 -0.00107086 -0.0822326" quat="0.947383 5.0174e-05 0.320102 -0.00100694">
              <inertial pos="0.00202926 0.000536024 -0.0819497" quat="0.999955 -0.00758706 0.000514378 0.00560215" mass="0.948071" diaginertia="0.00341615 0.00304243 0.00038835"/>
              <joint name="r_calf_joint" class="/" pos="0 0 0" axis="0.00203837 -0.999986 0.00484055" stiffness="0.00368734" range="-1.63241 0.610763" armature="0.0105465" damping="0.00793619" frictionloss="0.0105843"/>
              <geom name="//unnamed_geom_11" class="/" type="mesh" density="0" rgba="0.75294 0.75294 0.75294 1" mesh="r_calf_link"/>
              <geom name="//unnamed_geom_12" class="/" size="0.000521261 0.000521261 0.000521261" type="box" rgba="0.75294 0.75294 0.75294 1"/>
              <geom name="//unnamed_geom_13" class="reward_collision_sphere" size="0.0417009"/>
              <body name="r_ankle_pitch_link" pos="-0.000150076 -0.000204952 -0.162637" quat="0.980076 -0.000541755 -0.198622 -0.000208055">
                <inertial pos="0.00205214 0.00317378 -0.00161102" quat="0.00439736 0.706515 -0.00355261 0.707676" mass="0.193796" diaginertia="0.000281392 0.000177363 0.000253166"/>
                <joint name="r_ankle_pitch_joint" class="/" pos="0 0 0" axis="-0.00217525 -0.999997 0.00133003" range="-1.34263 0.548944" armature="0.0106494" damping="0.0145404" frictionloss="0.00899245"/>
                <geom name="//unnamed_geom_14" class="/" type="mesh" density="0" rgba="0.75294 0.75294 0.75294 1" mesh="r_ankle_pitch_link"/>
                <geom name="//unnamed_geom_15" class="/" size="0.0406583 0.0417009 0.026063" type="box" rgba="0.75294 0.75294 0.75294 1"/>
                <body name="r_ankle_roll_link" pos="0.0773801 0.00177789 -0.000198592" quat="1 -6.11928e-05 -2.59863e-05 -1.83478e-05">
                  <inertial pos="-0.0204934 0.000225876 -0.0182736" quat="0.560887 0.430543 0.435516 0.557104" mass="0.611718" diaginertia="0.00111253 0.000866317 0.000641598"/>
                  <joint name="r_ankle_roll_joint" class="/" pos="0 0 0" axis="-0.999997 0.000234853 -0.00240851" range="-0.130187 0.109079" armature="0.0103732" damping="0" frictionloss="0.0103328"/>
                  <geom name="//unnamed_geom_16" class="/" type="mesh" density="0" rgba="0.75294 0.75294 0.75294 1" mesh="r_ankle_roll_link"/>
                  <geom name="//unnamed_geom_17" class="/" type="mesh" rgba="0.75294 0.75294 0.75294 1" mesh="r_ankle_roll_link"/>
                  <geom name="right_foot" class="foot" size="0.0979679 0.0404144 0.00460288" pos="-0.0503109 0 -0.051657"/>
                  <geom name="//unnamed_geom_19" class="reward_collision_sphere" size="0.0417009" pos="-0.0493244 0 -0.0234804"/>
                  <geom name="//unnamed_geom_20" class="reward_collision_sphere" size="0.0208504" pos="0.0147973 0.0193411 -0.0469609"/>
                  <geom name="//unnamed_geom_21" class="reward_collision_sphere" size="0.0208504" pos="-0.118379 0.0193411 -0.0469609"/>
                  <site name="right_foot" class="foot" pos="-0.0503109 0 -0.051657" size="0.0104252"/>
                </body>
              </body>
            </body>
          </body>
        </body>
      </body>
      <body name="l_hip_pitch_link" pos="-0.000872274 0.0237201 -0.036206" quat="0.992209 -0.000113825 -0.124585 -0.000245128">
        <inertial pos="0.00173569 0.0512087 -0.000942459" quat="-0.0389331 0.705965 0.0301502 0.706533" mass="0.439457" diaginertia="0.000118794 9.0704e-05 0.000219288"/>
        <joint name="l_hip_pitch_joint" class="/" pos="0 0 0" axis="-0.00278202 0.999996 0.000694125" range="-1.19078 1.73667" armature="0.0117084" damping="0" frictionloss="0.0116588"/>
        <geom name="//unnamed_geom_22" class="/" type="mesh" density="0" rgba="0.75294 0.75294 0.75294 1" mesh="l_hip_pitch_link"/>
        <geom name="//unnamed_geom_23" class="/" size="0.000521261 0.000521261 0.000521261" type="box" rgba="0.75294 0.75294 0.75294 1"/>
        <body name="l_hip_roll_link" pos="-0.00150709 0.0567018 0.00226652" quat="1 0.0003897 -0.000184171 -0.000445856">
          <inertial pos="-0.00117979 0.000478299 -0.072143" quat="0.702841 -0.0675758 -0.0788509 0.703726" mass="0.428692" diaginertia="0.000316164 0.000227703 0.000292759"/>
          <joint name="l_hip_roll_joint" class="/" pos="0 0 0" axis="-0.999943 -0.00465681 0.00959719" range="-0.530775 0.0716531" armature="0.011748" damping="0.00882496" frictionloss="0.011821"/>
          <geom name="//unnamed_geom_24" class="/" type="mesh" density="0" rgba="0.75294 0.75294 0.75294 1" mesh="l_hip_roll_link"/>
          <geom name="//unnamed_geom_25" class="/" size="0.000521261 0.000521261 0.000521261" type="box" rgba="0.75294 0.75294 0.75294 1"/>
          <geom name="//unnamed_geom_26" class="reward_collision_sphere" size="0.0417009"/>
          <body name="l_thigh_link" pos="0.000784738 0.000513269 -0.0789179" quat="1 0.000493711 0.000274551 0.000130342">
            <inertial pos="0.000222605 -0.00140347 -0.0529656" quat="0.675907 0.736987 -0.000187909 0.000208038" mass="0.128683" diaginertia="0.000116546 7.96623e-05 0.000131389"/>
            <joint name="l_thigh_joint" class="/" pos="0 0 0" axis="-0.000351135 0.000918372 -1" stiffness="0.00108688" range="-0.60291 0.307954" armature="0.00882106" damping="0.00833005" frictionloss="0.0107087"/>
            <geom name="//unnamed_geom_27" class="/" type="mesh" density="0" rgba="0.75294 0.75294 0.75294 1" mesh="l_thigh_link"/>
            <geom name="//unnamed_geom_28" class="/" size="0.000521261 0.000521261 0.000521261" type="box" rgba="0.75294 0.75294 0.75294 1"/>
            <body name="l_calf_link" pos="-0.00042376 -0.00161728 -0.0806231" quat="0.947519 -0.000503512 0.319697 -0.00119392">
              <inertial pos="0.000341994 0.00573297 -0.0817836" quat="0.999986 -0.00308092 0.00350319 0.00255895" mass="0.923873" diaginertia="0.00341879 0.00307585 0.000379882"/>
              <joint name="l_calf_joint" class="/" pos="0 0 0" axis="0.00222817 0.999996 -0.00180043" range="-0.649613 1.64269" armature="0.0101494" damping="0.0140799" frictionloss="0.0108393"/>
              <geom name="//unnamed_geom_29" class="/" type="mesh" density="0" rgba="0.75294 0.75294 0.75294 1" mesh="l_calf_link"/>
              <geom name="//unnamed_geom_30" class="/" size="0.000521261 0.000521261 0.000521261" type="box" rgba="0.75294 0.75294 0.75294 1"/>
              <geom name="//unnamed_geom_31" class="reward_collision_sphere" size="0.0417009"/>
              <body name="l_ankle_pitch_link" pos="0.00039582 -0.00146628 -0.166836" quat="0.98023 0.000968632 -0.197858 -0.000140334">
                <inertial pos="0.00514327 -0.00357308 -0.00064133" quat="-0.00105268 0.705941 0.000730583 0.70827" mass="0.187832" diaginertia="0.000271884 0.000181787 0.000255458"/>
                <joint name="l_ankle_pitch_joint" class="/" pos="0 0 0" axis="-0.000122983 1 0.000174087" range="-0.510321 1.29633" armature="0.0102336" damping="0.0153722" frictionloss="0.0116705"/>
                <geom name="//unnamed_geom_32" class="/" type="mesh" density="0" rgba="0.75294 0.75294 0.75294 1" mesh="l_ankle_pitch_link"/>
                <geom name="//unnamed_geom_33" class="/" size="0.0406583 0.0417009 0.026063" type="box" rgba="0.75294 0.75294 0.75294 1"/>
                <body name="l_ankle_roll_link" pos="0.0747595 0.00219266 0.000203999" quat="1 6.54823e-05 -9.90283e-05 -5.34597e-05">
                  <inertial pos="-0.023499 0.000755921 -0.0141958" quat="0.555917 0.440407 0.432129 0.557012" mass="0.585172" diaginertia="0.00108472 0.000836352 0.000648071"/>
                  <joint name="l_ankle_roll_joint" class="/" pos="0 0 0" axis="-0.999931 -0.0111779 0.00355631" range="-0.178926 0.151235" armature="0.00988817" damping="0.0238271" frictionloss="0.0108959"/>
                  <geom name="//unnamed_geom_34" class="/" type="mesh" density="0" rgba="0.75294 0.75294 0.75294 1" mesh="l_ankle_roll_link"/>
                  <geom name="//unnamed_geom_35" class="/" type="mesh" rgba="0.75294 0.75294 0.75294 1" mesh="l_ankle_roll_link"/>
                  <geom name="left_foot" class="foot" size="0.085125 0.0374432 0.00523117" pos="-0.0503109 0 -0.051657"/>
                  <geom name="//unnamed_geom_37" class="reward_collision_sphere" size="0.0417009" pos="-0.0493244 0 -0.0234804"/>
                  <geom name="//unnamed_geom_38" class="reward_collision_sphere" size="0.0208504" pos="0.0147973 -0.0193411 -0.0469609"/>
                  <geom name="//unnamed_geom_39" class="reward_collision_sphere" size="0.0208504" pos="-0.118379 -0.0193411 -0.0469609"/>
                  <site name="left_foot" class="foot" pos="-0.0503109 0 -0.051657" size="0.0104252"/>
                </body>
              </body>
            </body>
          </body>
        </body>
      </body>
    </body>
  </worldbody>

  <contact>
    <pair class="/" geom1="floor" geom2="right_foot" name="//unnamed_contact_1"/>
    <pair class="/" geom1="floor" geom2="left_foot" name="//unnamed_contact_0"/>
  </contact>

  <actuator>
    <general name="r_hip_pitch_joint" class="/" joint="r_hip_pitch_joint" forcerange="-21.5908 21.5908" gainprm="20.6863" biasprm="0 -20.6863 -0.483594"/>
    <general name="r_hip_roll_joint" class="/" joint="r_hip_roll_joint" forcerange="-21.9312 21.9312" gainprm="20.6863" biasprm="0 -20.6863 -0.483594"/>
    <general name="r_thigh_joint" class="/" joint="r_thigh_joint" forcerange="-21.5766 21.5766" gainprm="20.6863" biasprm="0 -20.6863 -0.483594"/>
    <general name="r_calf_joint" class="/" joint="r_calf_joint" forcerange="-21.8744 21.8744" gainprm="20.6863" biasprm="0 -20.6863 -0.483594"/>
    <general name="r_ankle_pitch_joint" class="/" joint="r_ankle_pitch_joint" forcerange="-22.0615 22.0615" gainprm="20.6863" biasprm="0 -20.6863 -0.483594"/>
    <general name="r_ankle_roll_joint" class="/" joint="r_ankle_roll_joint" forcerange="-21.7721 21.7721" gainprm="20.6863" biasprm="0 -20.6863 -0.483594"/>
    <general name="l_hip_pitch_joint" class="/" joint="l_hip_pitch_joint" forcerange="-22.6016 22.6016" gainprm="20.6863" biasprm="0 -20.6863 -0.483594"/>
    <general name="l_hip_roll_joint" class="/" joint="l_hip_roll_joint" forcerange="-19.6834 19.6834" gainprm="20.6863" biasprm="0 -20.6863 -0.483594"/>
    <general name="l_thigh_joint" class="/" joint="l_thigh_joint" forcerange="-22.0332 22.0332" gainprm="20.6863" biasprm="0 -20.6863 -0.483594"/>
    <general name="l_calf_joint" class="/" joint="l_calf_joint" forcerange="-22.0924 22.0924" gainprm="20.6863" biasprm="0 -20.6863 -0.483594"/>
    <general name="l_ankle_pitch_joint" class="/" joint="l_ankle_pitch_joint" forcerange="-22.0711 22.0711" gainprm="20.6863" biasprm="0 -20.6863 -0.483594"/>
    <general name="l_ankle_roll_joint" class="/" joint="l_ankle_roll_joint" forcerange="-19.8034 19.8034" gainprm="20.6863" biasprm="0 -20.6863 -0.483594"/>
  </actuator>

  <sensor>
    <gyro site="imu" name="imu_angular_velocity"/>
    <velocimeter site="imu" name="imu_linear_velocity"/>
    <framelinvel objtype="site" objname="left_foot" name="left_foot_global_linear_velocity"/>
    <framelinvel objtype="site" objname="right_foot" name="right_foot_global_linear_velocity"/>
  </sensor>

  <keyframe>
    <key name="home" qpos="0 0 0.291 1 0 0 0 0.4 0 0 -0.8 0.4 0 -0.4 0 0 0.8 -0.4 0"/>
  </keyframe>
</mujoco>
