<mujoco model="pi_12dof_release_v1">
  <compiler angle="radian" assetdir="assets" balanceinertia="true" inertiafromgeom="false"/>

  <option timestep="0.005" density="1.2" viscosity="2e-05"/>

  <size nkey="1"/>

  <visual>
    <quality shadowsize="8192"/>
    <map shadowclip="0.5"/>
  </visual>

  <default>
    <default class="/">
      <joint armature="0.01" damping="0.01" frictionloss="0.01"/>
      <geom contype="0" conaffinity="0" group="1" solref="-1000 -80"/>
      <site size="0.01 0.005 0.005" group="5"/>
      <general forcelimited="true" biastype="affine" gainprm="20" biasprm="0 -20 -0.5"/>
      <default class="foot">
        <geom size="0.0845 0.036 0.005" type="box" condim="6" group="4" priority="1" friction="0.9 0.2 0.2" solimp="0.015 1 0.005"/>
      </default>
      <default class="reward_collision_sphere">
        <geom group="5" rgba="1 0 0 1"/>
      </default>
    </default>
  </default>

  <asset>
    <texture type="skybox" colorspace="auto" name="//unnamed_texture_0" builtin="gradient" rgb1="0.95 0.95 0.95" rgb2="0.95 0.95 0.95" width="100" height="600"/>
    <texture type="2d" colorspace="auto" name="texplane" builtin="checker" rgb1="0.345 0.575 0.748" rgb2="0.345 0.575 0.748" markrgb="1 1 1" width="512" height="512"/>
    <material name="MatPlane" class="/" texture="texplane" texuniform="true" texrepeat="2 2" specular="0.9"/>
    <mesh name="baselink_1" class="/" file="baselink_1.STL"/>
    <mesh name="r_hip_pitch_link" class="/" file="r_hip_pitch_link.STL"/>
    <mesh name="r_hip_roll_link" class="/" file="r_hip_roll_link.STL"/>
    <mesh name="r_thigh_link" class="/" file="r_thigh_link.STL"/>
    <mesh name="r_calf_link" class="/" file="r_calf_link.STL"/>
    <mesh name="r_ankle_pitch_link" class="/" file="r_ankle_pitch_link.STL"/>
    <mesh name="r_ankle_roll_link" class="/" file="r_ankle_roll_link.STL"/>
    <mesh name="l_hip_pitch_link" class="/" file="l_hip_pitch_link.STL"/>
    <mesh name="l_hip_roll_link" class="/" file="l_hip_roll_link.STL"/>
    <mesh name="l_thigh_link" class="/" file="l_thigh_link.STL"/>
    <mesh name="l_calf_link" class="/" file="l_calf_link.STL"/>
    <mesh name="l_ankle_pitch_link" class="/" file="l_ankle_pitch_link.STL"/>
    <mesh name="l_ankle_roll_link" class="/" file="l_ankle_roll_link.STL"/>
  </asset>

  <worldbody>
    <geom name="floor" class="/" size="100 100 0.125" type="plane" group="0" material="MatPlane"/>
    <light name="toplight_shadow" class="/" pos="0 0 5" dir="0.0990148 0.0990148 -0.990148" type="directional" ambient="0.04 0.04 0.04" diffuse="0.55 0.55 0.55" specular="0.12 0.12 0.12"/>
    <light name="toplight_fill" class="/" pos="0 0 5" dir="0.0990148 0.0990148 -0.990148" type="directional" castshadow="false" ambient="0.04 0.04 0.04" diffuse="0.3 0.3 0.3" specular="0.08 0.08 0.08"/>
    <body name="trunk" pos="-0.000456574 -0.0004896 -0.00222823" quat="1 -3.60332e-05 3.29125e-05 -2.44608e-05">
      <inertial pos="0.000767565 -0.00106915 0.0514556" quat="0.701219 0.0164175 0.00299467 0.712751" mass="1.90818" diaginertia="0.0111749 0.000976333 0.0106485"/>
      <joint name="//unnamed_joint_0" type="free"/>
      <geom name="//unnamed_geom_1" class="/" type="mesh" density="0" rgba="1 1 1 1" mesh="baselink_1"/>
      <geom name="//unnamed_geom_2" class="/" size="0.0476947 0.0476947 0.0476947" pos="0 0 0.0962894" type="box" rgba="1 1 1 1"/>
      <geom name="//unnamed_geom_3" class="reward_collision_sphere" size="0.0524642" pos="0 0 0.0842533"/>
      <site name="imu" class="/" pos="0.00343319 -0.00167803 0.00412765" size="0.00953894"/>
      <camera name="track" class="/" pos="0 -1.27991 0" quat="0.707107 0.707107 0 0" mode="trackcom"/>
      <camera name="ego_camera" class="/" pos="0.0763579 0 0.216651" quat="-0.5 -0.5 0.5 0.5"/>
      <body name="r_hip_pitch_link" pos="0.00246284 -0.0161883 -0.0400164" quat="0.992056 0.000626279 -0.125796 -0.000404435">
        <inertial pos="0.00164385 -0.0389909 0.00074271" quat="-0.0250654 0.713851 -0.0252025 0.699395" mass="0.323222" diaginertia="0.000119911 1.07282e-05 0.000218765"/>
        <joint name="r_hip_pitch_joint" class="/" pos="0 0 0" axis="-0.00129845 -0.999991 0.00395715" range="-1.7521 1.24614" armature="0.00820513" damping="0.0127787" frictionloss="0.00834742"/>
        <geom name="//unnamed_geom_4" class="/" type="mesh" density="0" rgba="0.75294 0.75294 0.75294 1" mesh="r_hip_pitch_link"/>
        <geom name="//unnamed_geom_5" class="/" size="0.000476947 0.000476947 0.000476947" type="box" rgba="0.75294 0.75294 0.75294 1"/>
        <body name="r_hip_roll_link" pos="0.00118739 -0.0340117 -0.00207828" quat="1 1.54382e-05 5.38027e-05 1.52511e-05">
          <inertial pos="0.00172123 -9.08001e-05 -0.0728768" quat="0.706038 -0.0740833 -0.0737699 0.700414" mass="0.344641" diaginertia="0.000359926 2.95348e-05 0.000317621"/>
          <joint name="r_hip_roll_joint" class="/" pos="0 0 0" axis="-0.999993 -0.000246525 0.00361401" range="-0.133013 0.545545" armature="0.00807589" damping="0.00526632" frictionloss="0.010493"/>
          <geom name="//unnamed_geom_6" class="/" type="mesh" density="0" rgba="0.75294 0.75294 0.75294 1" mesh="r_hip_roll_link"/>
          <geom name="//unnamed_geom_7" class="/" size="0.000476947 0.000476947 0.000476947" type="box" rgba="0.75294 0.75294 0.75294 1"/>
          <geom name="//unnamed_geom_8" class="reward_collision_sphere" size="0.0381557"/>
          <body name="r_thigh_link" pos="0.00185037 -0.00141839 -0.0828549" quat="1 0.000456495 -5.63251e-06 -0.000422901">
            <inertial pos="-0.000680211 -0.000606647 -0.0591218" quat="0.733063 0.680125 -0.00172713 -0.00680844" mass="0.0956405" diaginertia="0.000131788 1.01552e-05 0.00013875"/>
            <joint name="r_thigh_joint" class="/" pos="0 0 0" axis="-0.0135959 0.00403768 -0.999899" stiffness="0.00891582" range="-0.251934 0.635652" armature="0.00985953" damping="0.00818503" frictionloss="0.00987336"/>
            <geom name="//unnamed_geom_9" class="/" type="mesh" density="0" rgba="0.75294 0.75294 0.75294 1" mesh="r_thigh_link"/>
            <geom name="//unnamed_geom_10" class="/" size="0.000476947 0.000476947 0.000476947" type="box" rgba="0.75294 0.75294 0.75294 1"/>
            <body name="r_calf_link" pos="-0.00184707 -0.00148816 -0.0867483" quat="0.94757 -0.000525608 0.319549 -0.000466979">
              <inertial pos="0.000513299 -8.85245e-05 -0.0847074" quat="0.999969 -0.00421365 0.00275562 0.0061327" mass="0.712368" diaginertia="0.00383631 0.000400619 0.000455731"/>
              <joint name="r_calf_joint" class="/" pos="0 0 0" axis="0.00739229 -0.999965 -0.0039269" range="-1.63638 0.702598" armature="0.00840012" damping="0.0195504" frictionloss="0.00820727"/>
              <geom name="//unnamed_geom_11" class="/" type="mesh" density="0" rgba="0.75294 0.75294 0.75294 1" mesh="r_calf_link"/>
              <geom name="//unnamed_geom_12" class="/" size="0.000476947 0.000476947 0.000476947" type="box" rgba="0.75294 0.75294 0.75294 1"/>
              <geom name="//unnamed_geom_13" class="reward_collision_sphere" size="0.0381557"/>
              <body name="r_ankle_pitch_link" pos="-0.00141637 -0.00037316 -0.171143" quat="0.98008 -9.37381e-05 -0.198602 7.78173e-05">
                <inertial pos="0.00494526 0.00296165 0.000259633" quat="0.00659013 0.706151 -0.00459637 0.708015" mass="0.149049" diaginertia="0.000327273 2.39935e-05 0.000306096"/>
                <joint name="r_ankle_pitch_joint" class="/" pos="0 0 0" axis="0.00676301 -0.99995 -0.00732293" range="-1.33575 0.525461" armature="0.00894652" damping="0.00295866" frictionloss="0.00940552"/>
                <geom name="//unnamed_geom_14" class="/" type="mesh" density="0" rgba="0.75294 0.75294 0.75294 1" mesh="r_ankle_pitch_link"/>
                <geom name="//unnamed_geom_15" class="/" size="0.0372019 0.0381557 0.0238473" type="box" rgba="0.75294 0.75294 0.75294 1"/>
                <body name="r_ankle_roll_link" pos="0.0783678 0.00278618 0.00197678" quat="1 7.72658e-05 0.000192774 3.47568e-05">
                  <inertial pos="-0.0242831 0.000717967 -0.0171276" quat="0.555146 0.422701 0.43587 0.568467" mass="0.445251" diaginertia="0.00123995 0.000108101 0.000704621"/>
                  <joint name="r_ankle_roll_joint" class="/" pos="0 0 0" axis="-0.999991 0.00421859 -0.000440782" range="-0.199712 0.207584" armature="0.0108019" damping="0.00197552" frictionloss="0.0100426"/>
                  <geom name="//unnamed_geom_16" class="/" type="mesh" density="0" rgba="0.75294 0.75294 0.75294 1" mesh="r_ankle_roll_link"/>
                  <geom name="//unnamed_geom_17" class="/" type="mesh" rgba="0.75294 0.75294 0.75294 1" mesh="r_ankle_roll_link"/>
                  <geom name="right_foot" class="foot" size="0.0663198 0.03284 0.00429545" pos="-0.0519234 0 -0.0529592"/>
                  <geom name="//unnamed_geom_19" class="reward_collision_sphere" size="0.0381557" pos="-0.0509053 0 -0.0240724"/>
                  <geom name="//unnamed_geom_20" class="reward_collision_sphere" size="0.0190779" pos="0.0152716 0.0127991 -0.0481447"/>
                  <geom name="//unnamed_geom_21" class="reward_collision_sphere" size="0.0190779" pos="-0.122173 0.0127991 -0.0481447"/>
                  <site name="right_foot" class="foot" pos="-0.0519234 0 -0.0529592" size="0.00953894"/>
                </body>
              </body>
            </body>
          </body>
        </body>
      </body>
      <body name="l_hip_pitch_link" pos="-7.51481e-05 0.0178451 -0.0385534" quat="0.992214 0.000797194 -0.124543 0.000213607">
        <inertial pos="0.00391881 0.0350177 -0.00105425" quat="-0.0386015 0.697697 0.0365024 0.714421" mass="0.341356" diaginertia="0.00013406 1.10739e-05 0.000248163"/>
        <joint name="l_hip_pitch_joint" class="/" pos="0 0 0" axis="0.0081294 0.999961 0.00349711" range="-1.2606 1.7784" armature="0.00952764" damping="0.0144658" frictionloss="0.0090738"/>
        <geom name="//unnamed_geom_22" class="/" type="mesh" density="0" rgba="0.75294 0.75294 0.75294 1" mesh="l_hip_pitch_link"/>
        <geom name="//unnamed_geom_23" class="/" size="0.000476947 0.000476947 0.000476947" type="box" rgba="0.75294 0.75294 0.75294 1"/>
        <body name="l_hip_roll_link" pos="-0.00305475 0.0374547 -0.000198431" quat="1 -0.000124933 -9.14655e-05 1.10045e-05">
          <inertial pos="-0.00116655 0.00155512 -0.0746936" quat="0.69736 -0.07511 -0.0767943 0.708626" mass="0.338111" diaginertia="0.000364364 2.88126e-05 0.000333494"/>
          <joint name="l_hip_roll_joint" class="/" pos="0 0 0" axis="-0.999998 0.000860682 -0.00152324" stiffness="0.0023052" range="-0.511445 0.164534" armature="0.00979139" damping="0" frictionloss="0.00914599"/>
          <geom name="//unnamed_geom_24" class="/" type="mesh" density="0" rgba="0.75294 0.75294 0.75294 1" mesh="l_hip_roll_link"/>
          <geom name="//unnamed_geom_25" class="/" size="0.000476947 0.000476947 0.000476947" type="box" rgba="0.75294 0.75294 0.75294 1"/>
          <geom name="//unnamed_geom_26" class="reward_collision_sphere" size="0.0381557"/>
          <body name="l_thigh_link" pos="-0.00304312 -0.000426486 -0.0845606" quat="0.999999 -5.96683e-05 -1.70446e-06 0.00126356">
            <inertial pos="0.000591206 -0.00138773 -0.0560256" quat="0.674724 0.73804 -0.00241745 -0.00621685" mass="0.097837" diaginertia="0.000135357 1.01685e-05 0.000147678"/>
            <joint name="l_thigh_joint" class="/" pos="0 0 0" axis="0.00671774 0.0115421 -0.999911" range="-0.655067 0.34751" armature="0.0108346" damping="0.00195931" frictionloss="0.0107365"/>
            <geom name="//unnamed_geom_27" class="/" type="mesh" density="0" rgba="0.75294 0.75294 0.75294 1" mesh="l_thigh_link"/>
            <geom name="//unnamed_geom_28" class="/" size="0.000476947 0.000476947 0.000476947" type="box" rgba="0.75294 0.75294 0.75294 1"/>
            <body name="l_calf_link" pos="-0.00186789 -0.000493682 -0.0862525" quat="0.947662 -0.000323291 0.319275 -0.00075098">
              <inertial pos="7.01166e-06 0.00239685 -0.0830229" quat="0.999927 -0.00359804 -0.00508256 0.0103692" mass="0.679299" diaginertia="0.00371457 0.000363835 0.000427005"/>
              <joint name="l_calf_joint" class="/" pos="0 0 0" axis="-0.00176598 0.999944 0.0103944" range="-0.599276 1.67972" armature="0.00916077" damping="0.00683731" frictionloss="0.00918623"/>
              <geom name="//unnamed_geom_29" class="/" type="mesh" density="0" rgba="0.75294 0.75294 0.75294 1" mesh="l_calf_link"/>
              <geom name="//unnamed_geom_30" class="/" size="0.000476947 0.000476947 0.000476947" type="box" rgba="0.75294 0.75294 0.75294 1"/>
              <geom name="//unnamed_geom_31" class="reward_collision_sphere" size="0.0381557"/>
              <body name="l_ankle_pitch_link" pos="-0.000838691 -0.00263624 -0.168565" quat="0.980153 5.03881e-05 -0.198244 0.000162885">
                <inertial pos="0.00708627 -0.00258268 0.000545572" quat="-0.00195718 0.707995 0.00198568 0.706212" mass="0.155495" diaginertia="0.000336421 2.38384e-05 0.000312386"/>
                <joint name="l_ankle_pitch_joint" class="/" pos="0 0 0" axis="-0.00862488 0.999955 -0.00403626" stiffness="0.000874128" range="-0.490534 1.31204" armature="0.00967186" damping="0" frictionloss="0.00883992"/>
                <geom name="//unnamed_geom_32" class="/" type="mesh" density="0" rgba="0.75294 0.75294 0.75294 1" mesh="l_ankle_pitch_link"/>
                <geom name="//unnamed_geom_33" class="/" size="0.0372019 0.0381557 0.0238473" type="box" rgba="0.75294 0.75294 0.75294 1"/>
                <body name="l_ankle_roll_link" pos="0.0756418 -0.00227566 0.0013343" quat="0.999999 -0.00112503 0.000673124 -2.21347e-05">
                  <inertial pos="-0.0277423 -0.000823458 -0.0182364" quat="0.560451 0.42938 0.439107 0.55562" mass="0.446631" diaginertia="0.00118659 0.000111715 0.000701152"/>
                  <joint name="l_ankle_roll_joint" class="/" pos="0 0 0" axis="-0.999996 -0.00297469 0.000194067" range="-0.160991 0.150357" armature="0.00843074" damping="0.00825431" frictionloss="0.00964914"/>
                  <geom name="//unnamed_geom_34" class="/" type="mesh" density="0" rgba="0.75294 0.75294 0.75294 1" mesh="l_ankle_roll_link"/>
                  <geom name="//unnamed_geom_35" class="/" type="mesh" rgba="0.75294 0.75294 0.75294 1" mesh="l_ankle_roll_link"/>
                  <geom name="left_foot" class="foot" size="0.0903027 0.0331246 0.00470815" pos="-0.0519234 0 -0.0529592"/>
                  <geom name="//unnamed_geom_37" class="reward_collision_sphere" size="0.0381557" pos="-0.0509053 0 -0.0240724"/>
                  <geom name="//unnamed_geom_38" class="reward_collision_sphere" size="0.0190779" pos="0.0152716 -0.0127991 -0.0481447"/>
                  <geom name="//unnamed_geom_39" class="reward_collision_sphere" size="0.0190779" pos="-0.122173 -0.0127991 -0.0481447"/>
                  <site name="left_foot" class="foot" pos="-0.0519234 0 -0.0529592" size="0.00953894"/>
                </body>
              </body>
            </body>
          </body>
        </body>
      </body>
    </body>
  </worldbody>

  <contact>
    <pair class="/" geom1="floor" geom2="right_foot" name="//unnamed_contact_1"/>
    <pair class="/" geom1="floor" geom2="left_foot" name="//unnamed_contact_0"/>
  </contact>

  <actuator>
    <general name="r_hip_pitch_joint" class="/" joint="r_hip_pitch_joint" forcerange="-22.0036 22.0036" gainprm="18.9648" biasprm="0 -18.9648 -0.486722"/>
    <general name="r_hip_roll_joint" class="/" joint="r_hip_roll_joint" forcerange="-19.0828 19.0828" gainprm="18.9648" biasprm="0 -18.9648 -0.486722"/>
    <general name="r_thigh_joint" class="/" joint="r_thigh_joint" forcerange="-21.4972 21.4972" gainprm="18.9648" biasprm="0 -18.9648 -0.486722"/>
    <general name="r_calf_joint" class="/" joint="r_calf_joint" forcerange="-20.7282 20.7282" gainprm="18.9648" biasprm="0 -18.9648 -0.486722"/>
    <general name="r_ankle_pitch_joint" class="/" joint="r_ankle_pitch_joint" forcerange="-18.9591 18.9591" gainprm="18.9648" biasprm="0 -18.9648 -0.486722"/>
    <general name="r_ankle_roll_joint" class="/" joint="r_ankle_roll_joint" forcerange="-19.6881 19.6881" gainprm="18.9648" biasprm="0 -18.9648 -0.486722"/>
    <general name="l_hip_pitch_joint" class="/" joint="l_hip_pitch_joint" forcerange="-19.6611 19.6611" gainprm="18.9648" biasprm="0 -18.9648 -0.486722"/>
    <general name="l_hip_roll_joint" class="/" joint="l_hip_roll_joint" forcerange="-18.0421 18.0421" gainprm="18.9648" biasprm="0 -18.9648 -0.486722"/>
    <general name="l_thigh_joint" class="/" joint="l_thigh_joint" forcerange="-18.6978 18.6978" gainprm="18.9648" biasprm="0 -18.9648 -0.486722"/>
    <general name="l_calf_joint" class="/" joint="l_calf_joint" forcerange="-18.1146 18.1146" gainprm="18.9648" biasprm="0 -18.9648 -0.486722"/>
    <general name="l_ankle_pitch_joint" class="/" joint="l_ankle_pitch_joint" forcerange="-22.0872 22.0872" gainprm="18.9648" biasprm="0 -18.9648 -0.486722"/>
    <general name="l_ankle_roll_joint" class="/" joint="l_ankle_roll_joint" forcerange="-19.3199 19.3199" gainprm="18.9648" biasprm="0 -18.9648 -0.486722"/>
  </actuator>

  <sensor>
    <gyro site="imu" name="imu_angular_velocity"/>
    <velocimeter site="imu" name="imu_linear_velocity"/>
    <framelinvel objtype="site" objname="left_foot" name="left_foot_global_linear_velocity"/>
    <framelinvel objtype="site" objname="right_foot" name="right_foot_global_linear_velocity"/>
  </sensor>

  <keyframe>
    <key name="home" qpos="0 0 0.291 1 0 0 0 0.4 0 0 -0.8 0.4 0 -0.4 0 0 0.8 -0.4 0"/>
  </keyframe>
</mujoco>
