<mujoco model="pi_12dof_release_v1">
  <compiler angle="radian" assetdir="assets" balanceinertia="true" inertiafromgeom="false"/>

  <option timestep="0.005" density="1.2" viscosity="2e-05"/>

  <size nkey="1"/>

  <visual>
    <quality shadowsize="8192"/>
    <map shadowclip="0.5"/>
  </visual>

  <default>
    <default class="/">
      <joint armature="0.01" damping="0.01" frictionloss="0.01"/>
      <geom contype="0" conaffinity="0" group="1" solref="-1000 -80"/>
      <site size="0.01 0.005 0.005" group="5"/>
      <general forcelimited="true" biastype="affine" gainprm="20" biasprm="0 -20 -0.5"/>
      <default class="foot">
        <geom size="0.0845 0.036 0.005" type="box" condim="6" group="4" priority="1" friction="0.9 0.2 0.2" solimp="0.015 1 0.005"/>
      </default>
      <default class="reward_collision_sphere">
        <geom group="5" rgba="1 0 0 1"/>
      </default>
    </default>
  </default>

  <asset>
    <texture type="skybox" colorspace="auto" name="//unnamed_texture_0" builtin="gradient" rgb1="0.95 0.95 0.95" rgb2="0.95 0.95 0.95" width="100" height="600"/>
    <texture type="2d" colorspace="auto" name="texplane" builtin="checker" rgb1="0.345 0.575 0.748" rgb2="0.345 0.575 0.748" markrgb="1 1 1" width="512" height="512"/>
    <material name="MatPlane" class="/" texture="texplane" texuniform="true" texrepeat="2 2" specular="0.9"/>
    <mesh name="baselink_1" class="/" file="baselink_1.STL"/>
    <mesh name="r_hip_pitch_link" class="/" file="r_hip_pitch_link.STL"/>
    <mesh name="r_hip_roll_link" class="/" file="r_hip_roll_link.STL"/>
    <mesh name="r_thigh_link" class="/" file="r_thigh_link.STL"/>
    <mesh name="r_calf_link" class="/" file="r_calf_link.STL"/>
    <mesh name="r_ankle_pitch_link" class="/" file="r_ankle_pitch_link.STL"/>
    <mesh name="r_ankle_roll_link" class="/" file="r_ankle_roll_link.STL"/>
    <mesh name="l_hip_pitch_link" class="/" file="l_hip_pitch_link.STL"/>
    <mesh name="l_hip_roll_link" class="/" file="l_hip_roll_link.STL"/>
    <mesh name="l_thigh_link" class="/" file="l_thigh_link.STL"/>
    <mesh name="l_calf_link" class="/" file="l_calf_link.STL"/>
    <mesh name="l_ankle_pitch_link" class="/" file="l_ankle_pitch_link.STL"/>
    <mesh name="l_ankle_roll_link" class="/" file="l_ankle_roll_link.STL"/>
  </asset>

  <worldbody>
    <geom name="floor" class="/" size="100 100 0.125" type="plane" group="0" material="MatPlane"/>
    <light name="toplight_shadow" class="/" pos="0 0 5" dir="0.0990148 0.0990148 -0.990148" type="directional" ambient="0.04 0.04 0.04" diffuse="0.55 0.55 0.55" specular="0.12 0.12 0.12"/>
    <light name="toplight_fill" class="/" pos="0 0 5" dir="0.0990148 0.0990148 -0.990148" type="directional" castshadow="false" ambient="0.04 0.04 0.04" diffuse="0.3 0.3 0.3" specular="0.08 0.08 0.08"/>
    <body name="trunk" pos="-0.000723017 0.000328201 -0.00258906" quat="1 0.000381715 -0.000154148 0.000223156">
      <inertial pos="-0.000560544 -0.00329353 0.0402387" quat="0.69455 0.0109882 0.00958371 0.719297" mass="1.56814" diaginertia="0.00838832 0.00244536 0.0036752"/>
      <joint name="//unnamed_joint_0" type="free"/>
      <geom name="//unnamed_geom_1" class="/" type="mesh" density="0" rgba="1 1 1 1" mesh="baselink_1"/>
      <geom name="//unnamed_geom_2" class="/" size="0.0448647 0.0448647 0.0448647" pos="0 0 0.0773503" type="box" rgba="1 1 1 1"/>
      <geom name="//unnamed_geom_3" class="reward_collision_sphere" size="0.0493512" pos="0 0 0.0676815"/>
      <site name="imu" class="/" pos="-0.0113713 0.00530553 0.0137886" size="0.00897294"/>
      <camera name="track" class="/" pos="0 -1.52983 0" quat="0.707107 0.707107 0 0" mode="trackcom"/>
      <camera name="ego_camera" class="/" pos="0.0720067 0 0.174038" quat="-0.5 -0.5 0.5 0.5"/>
      <body name="r_hip_pitch_link" pos="-0.00162475 -0.0168978 -0.0314193" quat="0.992216 0.000815352 -0.124527 -0.000562594">
        <inertial pos="0.00368917 -0.0450309 0.000225737" quat="-0.0164829 0.698736 -0.0259189 0.71472" mass="0.257823" diaginertia="8.54896e-05 2.54577e-05 7.01707e-05"/>
        <joint name="r_hip_pitch_joint" class="/" pos="0 0 0" axis="0.00294079 -0.999954 0.00917913" stiffness="0.00899385" range="-1.74431 1.19767" armature="0.00844901" damping="0.00165706" frictionloss="0.00881868"/>
        <geom name="//unnamed_geom_4" class="/" type="mesh" density="0" rgba="0.75294 0.75294 0.75294 1" mesh="r_hip_pitch_link"/>
        <geom name="//unnamed_geom_5" class="/" size="0.000448647 0.000448647 0.000448647" type="box" rgba="0.75294 0.75294 0.75294 1"/>
        <body name="r_hip_roll_link" pos="-0.00207382 -0.0412087 -0.00056437" quat="1 -2.59099e-05 0.000118897 -0.000230738">
          <inertial pos="0.000229598 -0.000498838 -0.0564766" quat="0.706795 -0.0792002 -0.0834173 0.698004" mass="0.287304" diaginertia="0.000262321 7.25574e-05 0.000109438"/>
          <joint name="r_hip_roll_joint" class="/" pos="0 0 0" axis="-0.999945 -0.00175316 -0.0103038" range="-0.174978 0.505105" armature="0.00846865" damping="0.0116828" frictionloss="0.0101841"/>
          <geom name="//unnamed_geom_6" class="/" type="mesh" density="0" rgba="0.75294 0.75294 0.75294 1" mesh="r_hip_roll_link"/>
          <geom name="//unnamed_geom_7" class="/" size="0.000448647 0.000448647 0.000448647" type="box" rgba="0.75294 0.75294 0.75294 1"/>
          <geom name="//unnamed_geom_8" class="reward_collision_sphere" size="0.0358918"/>
          <body name="r_thigh_link" pos="0.00273194 -0.00227018 -0.0691819" quat="0.999999 -0.000468248 -0.00119337 4.50281e-05">
            <inertial pos="0.000923819 0.00117662 -0.0454276" quat="0.73719 0.675681 -0.00210986 0.0012305" mass="0.0793794" diaginertia="9.93721e-05 2.46482e-05 4.8269e-05"/>
            <joint name="r_thigh_joint" class="/" pos="0 0 0" axis="0.0141501 0.00436316 -0.99989" stiffness="0.00441434" range="-0.293016 0.597148" armature="0.00894722" damping="0.0017112" frictionloss="0.00849656"/>
            <geom name="//unnamed_geom_9" class="/" type="mesh" density="0" rgba="0.75294 0.75294 0.75294 1" mesh="r_thigh_link"/>
            <geom name="//unnamed_geom_10" class="/" size="0.000448647 0.000448647 0.000448647" type="box" rgba="0.75294 0.75294 0.75294 1"/>
            <body name="r_calf_link" pos="-0.00250576 -0.00128508 -0.0670755" quat="0.947647 3.6053e-05 0.319321 -1.95169e-07">
              <inertial pos="0.00240094 -0.000734742 -0.0677086" quat="0.999981 -0.00397945 -0.00238923 0.00411312" mass="0.609034" diaginertia="0.00291167 0.000966737 0.000151768"/>
              <joint name="r_calf_joint" class="/" pos="0 0 0" axis="-0.00813513 -0.999963 0.00279628" stiffness="0.000468646" range="-1.63761 0.686732" armature="0.00786934" damping="0.0199881" frictionloss="0.00827209"/>
              <geom name="//unnamed_geom_11" class="/" type="mesh" density="0" rgba="0.75294 0.75294 0.75294 1" mesh="r_calf_link"/>
              <geom name="//unnamed_geom_12" class="/" size="0.000448647 0.000448647 0.000448647" type="box" rgba="0.75294 0.75294 0.75294 1"/>
              <geom name="//unnamed_geom_13" class="reward_collision_sphere" size="0.0358918"/>
              <body name="r_ankle_pitch_link" pos="-0.000479847 0.00233147 -0.137053" quat="0.980037 -2.80706e-05 -0.198813 -0.000185178">
                <inertial pos="0.00453623 0.00164596 0.00052385" quat="0.00551056 0.69771 0.000823675 0.716359" mass="0.11877" diaginertia="0.000240006 5.77335e-05 9.94354e-05"/>
                <joint name="r_ankle_pitch_joint" class="/" pos="0 0 0" axis="-0.00135349 -0.999996 0.00239649" range="-1.28565 0.481241" armature="0.00938839" damping="0" frictionloss="0.00899328"/>
                <geom name="//unnamed_geom_14" class="/" type="mesh" density="0" rgba="0.75294 0.75294 0.75294 1" mesh="r_ankle_pitch_link"/>
                <geom name="//unnamed_geom_15" class="/" size="0.0349945 0.0358918 0.0224323" type="box" rgba="0.75294 0.75294 0.75294 1"/>
                <body name="r_ankle_roll_link" pos="0.0765984 0.000296719 0.000992733" quat="1 0.000147722 -0.000130844 0.000141206">
                  <inertial pos="-0.0231307 -0.000244946 -0.0113715" quat="0.567654 0.424454 0.430933 0.558484" mass="0.380541" diaginertia="0.000897696 0.000261167 0.000239351"/>
                  <joint name="r_ankle_roll_joint" class="/" pos="0 0 0" axis="-0.999998 -0.00169869 0.00134783" range="-0.202112 0.169251" armature="0.00913586" damping="0" frictionloss="0.0102237"/>
                  <geom name="//unnamed_geom_16" class="/" type="mesh" density="0" rgba="0.75294 0.75294 0.75294 1" mesh="r_ankle_roll_link"/>
                  <geom name="//unnamed_geom_17" class="/" type="mesh" rgba="0.75294 0.75294 0.75294 1" mesh="r_ankle_roll_link"/>
                  <geom name="right_foot" class="foot" size="0.0757935 0.0336521 0.00449951" pos="-0.0489645 0 -0.0425427"/>
                  <geom name="//unnamed_geom_19" class="reward_collision_sphere" size="0.0358918" pos="-0.0480045 0 -0.0193376"/>
                  <geom name="//unnamed_geom_20" class="reward_collision_sphere" size="0.0179459" pos="0.0144013 0.0152983 -0.0386752"/>
                  <geom name="//unnamed_geom_21" class="reward_collision_sphere" size="0.0179459" pos="-0.115211 0.0152983 -0.0386752"/>
                  <site name="right_foot" class="foot" pos="-0.0489645 0 -0.0425427" size="0.00897294"/>
                </body>
              </body>
            </body>
          </body>
        </body>
      </body>
      <body name="l_hip_pitch_link" pos="-0.00253605 0.0188166 -0.0325534" quat="0.9922 -2.73061e-05 -0.124653 1.45236e-05">
        <inertial pos="0.0023571 0.0437577 1.72201e-05" quat="-0.0328896 0.71174 0.0339093 0.700852" mass="0.280946" diaginertia="0.000100611 2.73646e-05 7.93008e-05"/>
        <joint name="l_hip_pitch_joint" class="/" pos="0 0 0" axis="0.0065407 0.999917 0.0110759" range="-1.30248 1.72989" armature="0.0100973" damping="0.00326265" frictionloss="0.00942649"/>
        <geom name="//unnamed_geom_22" class="/" type="mesh" density="0" rgba="0.75294 0.75294 0.75294 1" mesh="l_hip_pitch_link"/>
        <geom name="//unnamed_geom_23" class="/" size="0.000448647 0.000448647 0.000448647" type="box" rgba="0.75294 0.75294 0.75294 1"/>
        <body name="l_hip_roll_link" pos="-0.00222282 0.0411044 -0.00028874" quat="1 -0.000234629 8.31608e-05 5.29918e-05">
          <inertial pos="-0.00161484 0.0026639 -0.0580014" quat="0.699275 -0.078121 -0.0785609 0.706215" mass="0.280207" diaginertia="0.000270823 7.05306e-05 0.000108265"/>
          <joint name="l_hip_roll_joint" class="/" pos="0 0 0" axis="-0.999916 0.00305375 -0.0125596" range="-0.453827 0.163044" armature="0.00853927" damping="0" frictionloss="0.00773721"/>
          <geom name="//unnamed_geom_24" class="/" type="mesh" density="0" rgba="0.75294 0.75294 0.75294 1" mesh="l_hip_roll_link"/>
          <geom name="//unnamed_geom_25" class="/" size="0.000448647 0.000448647 0.000448647" type="box" rgba="0.75294 0.75294 0.75294 1"/>
          <geom name="//unnamed_geom_26" class="reward_collision_sphere" size="0.0358918"/>
          <body name="l_thigh_link" pos="-0.002452 0.000718339 -0.0680192" quat="1 0.000217547 -0.000181866 0.000173512">
            <inertial pos="0.00051147 -0.00161332 -0.0456476" quat="0.681838 0.73149 -0.000126686 -0.00433227" mass="0.0817505" diaginertia="0.000101709 2.45353e-05 4.76812e-05"/>
            <joint name="l_thigh_joint" class="/" pos="0 0 0" axis="-0.000536517 0.00267263 -0.999996" stiffness="0.00212062" range="-0.646334 0.342148" armature="0.00970695" damping="0" frictionloss="0.010026"/>
            <geom name="//unnamed_geom_27" class="/" type="mesh" density="0" rgba="0.75294 0.75294 0.75294 1" mesh="l_thigh_link"/>
            <geom name="//unnamed_geom_28" class="/" size="0.000448647 0.000448647 0.000448647" type="box" rgba="0.75294 0.75294 0.75294 1"/>
            <body name="l_calf_link" pos="0.000836224 -0.00218683 -0.0694852" quat="0.948089 -0.000169212 0.318003 0.000355993">
              <inertial pos="-0.00229065 0.00171097 -0.064955" quat="0.999977 0.00353141 -0.00151587 0.00567398" mass="0.576146" diaginertia="0.00282238 0.000896662 0.000140083"/>
              <joint name="l_calf_joint" class="/" pos="0 0 0" axis="0.00297956 0.999994 -0.00183538" range="-0.63951 1.61356" armature="0.00777141" damping="0.00722185" frictionloss="0.00774381"/>
              <geom name="//unnamed_geom_29" class="/" type="mesh" density="0" rgba="0.75294 0.75294 0.75294 1" mesh="l_calf_link"/>
              <geom name="//unnamed_geom_30" class="/" size="0.000448647 0.000448647 0.000448647" type="box" rgba="0.75294 0.75294 0.75294 1"/>
              <geom name="//unnamed_geom_31" class="reward_collision_sphere" size="0.0358918"/>
              <body name="l_ankle_pitch_link" pos="-0.000507808 -0.000304958 -0.133056" quat="0.980072 -6.88467e-05 -0.198643 0.000196456">
                <inertial pos="0.00742444 -0.000129361 -0.00096493" quat="-0.00222175 0.707128 0.0022412 0.707078" mass="0.12006" diaginertia="0.00023592 5.67406e-05 9.76112e-05"/>
                <joint name="l_ankle_pitch_joint" class="/" pos="0 0 0" axis="0.00537469 0.99991 -0.0122817" range="-0.511334 1.31091" armature="0.00901974" damping="0" frictionloss="0.00982373"/>
                <geom name="//unnamed_geom_32" class="/" type="mesh" density="0" rgba="0.75294 0.75294 0.75294 1" mesh="l_ankle_pitch_link"/>
                <geom name="//unnamed_geom_33" class="/" size="0.0349945 0.0358918 0.0224323" type="box" rgba="0.75294 0.75294 0.75294 1"/>
                <body name="l_ankle_roll_link" pos="0.0692255 0.00172687 -0.000520325" quat="1 -0.000303919 -0.000714367 -7.64822e-05">
                  <inertial pos="-0.0246278 -0.000414914 -0.0138832" quat="0.563419 0.418411 0.439754 0.560454" mass="0.367529" diaginertia="0.000893833 0.000277555 0.000238143"/>
                  <joint name="l_ankle_roll_joint" class="/" pos="0 0 0" axis="-0.999995 -0.00318809 -0.000647761" range="-0.146328 0.155147" armature="0.00894189" damping="0.00524179" frictionloss="0.00786967"/>
                  <geom name="//unnamed_geom_34" class="/" type="mesh" density="0" rgba="0.75294 0.75294 0.75294 1" mesh="l_ankle_roll_link"/>
                  <geom name="//unnamed_geom_35" class="/" type="mesh" rgba="0.75294 0.75294 0.75294 1" mesh="l_ankle_roll_link"/>
                  <geom name="left_foot" class="foot" size="0.077889 0.0346184 0.00401901" pos="-0.0489645 0 -0.0425427"/>
                  <geom name="//unnamed_geom_37" class="reward_collision_sphere" size="0.0358918" pos="-0.0480045 0 -0.0193376"/>
                  <geom name="//unnamed_geom_38" class="reward_collision_sphere" size="0.0179459" pos="0.0144013 -0.0152983 -0.0386752"/>
                  <geom name="//unnamed_geom_39" class="reward_collision_sphere" size="0.0179459" pos="-0.115211 -0.0152983 -0.0386752"/>
                  <site name="left_foot" class="foot" pos="-0.0489645 0 -0.0425427" size="0.00897294"/>
                </body>
              </body>
            </body>
          </body>
        </body>
      </body>
    </body>
  </worldbody>

  <contact>
    <pair class="/" geom1="floor" geom2="right_foot" name="//unnamed_contact_1"/>
    <pair class="/" geom1="floor" geom2="left_foot" name="//unnamed_contact_0"/>
  </contact>

  <actuator>
    <general name="r_hip_pitch_joint" class="/" joint="r_hip_pitch_joint" forcerange="-19.1964 19.1964" gainprm="18.3885" biasprm="0 -18.3885 -0.478803"/>
    <general name="r_hip_roll_joint" class="/" joint="r_hip_roll_joint" forcerange="-16.882 16.882" gainprm="18.3885" biasprm="0 -18.3885 -0.478803"/>
    <general name="r_thigh_joint" class="/" joint="r_thigh_joint" forcerange="-20.8172 20.8172" gainprm="18.3885" biasprm="0 -18.3885 -0.478803"/>
    <general name="r_calf_joint" class="/" joint="r_calf_joint" forcerange="-18.45 18.45" gainprm="18.3885" biasprm="0 -18.3885 -0.478803"/>
    <general name="r_ankle_pitch_joint" class="/" joint="r_ankle_pitch_joint" forcerange="-16.8469 16.8469" gainprm="18.3885" biasprm="0 -18.3885 -0.478803"/>
    <general name="r_ankle_roll_joint" class="/" joint="r_ankle_roll_joint" forcerange="-19.0282 19.0282" gainprm="18.3885" biasprm="0 -18.3885 -0.478803"/>
    <general name="l_hip_pitch_joint" class="/" joint="l_hip_pitch_joint" forcerange="-19.5515 19.5515" gainprm="18.3885" biasprm="0 -18.3885 -0.478803"/>
    <general name="l_hip_roll_joint" class="/" joint="l_hip_roll_joint" forcerange="-17.4368 17.4368" gainprm="18.3885" biasprm="0 -18.3885 -0.478803"/>
    <general name="l_thigh_joint" class="/" joint="l_thigh_joint" forcerange="-19.2222 19.2222" gainprm="18.3885" biasprm="0 -18.3885 -0.478803"/>
    <general name="l_calf_joint" class="/" joint="l_calf_joint" forcerange="-17.2196 17.2196" gainprm="18.3885" biasprm="0 -18.3885 -0.478803"/>
    <general name="l_ankle_pitch_joint" class="/" joint="l_ankle_pitch_joint" forcerange="-19.7273 19.7273" gainprm="18.3885" biasprm="0 -18.3885 -0.478803"/>
    <general name="l_ankle_roll_joint" class="/" joint="l_ankle_roll_joint" forcerange="-16.8792 16.8792" gainprm="18.3885" biasprm="0 -18.3885 -0.478803"/>
  </actuator>

  <sensor>
    <gyro site="imu" name="imu_angular_velocity"/>
    <velocimeter site="imu" name="imu_linear_velocity"/>
    <framelinvel objtype="site" objname="left_foot" name="left_foot_global_linear_velocity"/>
    <framelinvel objtype="site" objname="right_foot" name="right_foot_global_linear_velocity"/>
  </sensor>

  <keyframe>
    <key name="home" qpos="0 0 0.291 1 0 0 0 0.4 0 0 -0.8 0.4 0 -0.4 0 0 0.8 -0.4 0"/>
  </keyframe>
</mujoco>
