<mujoco model="pi_12dof_release_v1">
  <compiler angle="radian" assetdir="assets" balanceinertia="true" inertiafromgeom="false"/>

  <option timestep="0.005" density="1.2" viscosity="2e-05"/>

  <size nkey="1"/>

  <visual>
    <quality shadowsize="8192"/>
    <map shadowclip="0.5"/>
  </visual>

  <default>
    <default class="/">
      <joint armature="0.01" damping="0.01" frictionloss="0.01"/>
      <geom contype="0" conaffinity="0" group="1" solref="-1000 -80"/>
      <site size="0.01 0.005 0.005" group="5"/>
      <general forcelimited="true" biastype="affine" gainprm="20" biasprm="0 -20 -0.5"/>
      <default class="foot">
        <geom size="0.0845 0.036 0.005" type="box" condim="6" group="4" priority="1" friction="0.9 0.2 0.2" solimp="0.015 1 0.005"/>
      </default>
      <default class="reward_collision_sphere">
        <geom group="5" rgba="1 0 0 1"/>
      </default>
    </default>
  </default>

  <asset>
    <texture type="skybox" colorspace="auto" name="//unnamed_texture_0" builtin="gradient" rgb1="0.95 0.95 0.95" rgb2="0.95 0.95 0.95" width="100" height="600"/>
    <texture type="2d" colorspace="auto" name="texplane" builtin="checker" rgb1="0.345 0.575 0.748" rgb2="0.345 0.575 0.748" markrgb="1 1 1" width="512" height="512"/>
    <material name="MatPlane" class="/" texture="texplane" texuniform="true" texrepeat="2 2" specular="0.9"/>
    <mesh name="baselink_1" class="/" file="baselink_1.STL"/>
    <mesh name="r_hip_pitch_link" class="/" file="r_hip_pitch_link.STL"/>
    <mesh name="r_hip_roll_link" class="/" file="r_hip_roll_link.STL"/>
    <mesh name="r_thigh_link" class="/" file="r_thigh_link.STL"/>
    <mesh name="r_calf_link" class="/" file="r_calf_link.STL"/>
    <mesh name="r_ankle_pitch_link" class="/" file="r_ankle_pitch_link.STL"/>
    <mesh name="r_ankle_roll_link" class="/" file="r_ankle_roll_link.STL"/>
    <mesh name="l_hip_pitch_link" class="/" file="l_hip_pitch_link.STL"/>
    <mesh name="l_hip_roll_link" class="/" file="l_hip_roll_link.STL"/>
    <mesh name="l_thigh_link" class="/" file="l_thigh_link.STL"/>
    <mesh name="l_calf_link" class="/" file="l_calf_link.STL"/>
    <mesh name="l_ankle_pitch_link" class="/" file="l_ankle_pitch_link.STL"/>
    <mesh name="l_ankle_roll_link" class="/" file="l_ankle_roll_link.STL"/>
  </asset>

  <worldbody>
    <geom name="floor" class="/" size="100 100 0.125" type="plane" group="0" material="MatPlane"/>
    <light name="toplight_shadow" class="/" pos="0 0 5" dir="0.0990148 0.0990148 -0.990148" type="directional" ambient="0.04 0.04 0.04" diffuse="0.55 0.55 0.55" specular="0.12 0.12 0.12"/>
    <light name="toplight_fill" class="/" pos="0 0 5" dir="0.0990148 0.0990148 -0.990148" type="directional" castshadow="false" ambient="0.04 0.04 0.04" diffuse="0.3 0.3 0.3" specular="0.08 0.08 0.08"/>
    <body name="trunk" pos="0.00050871 0.000475771 0.000942361" quat="1 0.000305679 -0.000175208 -0.000181283">
      <inertial pos="0.00328522 -0.00147755 0.0394641" quat="0.695327 0.00971759 0.00948887 0.718566" mass="1.67698" diaginertia="0.0104869 0.0024772 0.00377147"/>
      <joint name="//unnamed_joint_0" type="free"/>
      <geom name="//unnamed_geom_1" class="/" type="mesh" density="0" rgba="1 1 1 1" mesh="baselink_1"/>
      <geom name="//unnamed_geom_2" class="/" size="0.0459883 0.0459883 0.0459883" pos="0 0 0.0781136" type="box" rgba="1 1 1 1"/>
      <geom name="//unnamed_geom_3" class="reward_collision_sphere" size="0.0505871" pos="0 0 0.0683494"/>
      <site name="imu" class="/" pos="-0.00466676 -0.00748975 0.00259444" size="0.00919766"/>
      <camera name="track" class="/" pos="0 -1.5451 0" quat="0.707107 0.707107 0 0" mode="trackcom"/>
      <camera name="ego_camera" class="/" pos="0.0757747 0 0.175756" quat="-0.5 -0.5 0.5 0.5"/>
      <body name="r_hip_pitch_link" pos="2.66967e-05 -0.0175009 -0.0316961" quat="0.992247 0.000449807 -0.124281 8.05497e-05">
        <inertial pos="0.00201654 -0.043253 -0.000175193" quat="-0.0181909 0.705676 -0.0302922 0.707653" mass="0.291156" diaginertia="0.000115613 2.72836e-05 7.36424e-05"/>
        <joint name="r_hip_pitch_joint" class="/" pos="0 0 0" axis="0.00164145 -0.999995 0.00253946" range="-1.75325 1.25321" armature="0.00962556" damping="0.0158581" frictionloss="0.00918704"/>
        <geom name="//unnamed_geom_4" class="/" type="mesh" density="0" rgba="0.75294 0.75294 0.75294 1" mesh="r_hip_pitch_link"/>
        <geom name="//unnamed_geom_5" class="/" size="0.000459883 0.000459883 0.000459883" type="box" rgba="0.75294 0.75294 0.75294 1"/>
        <body name="r_hip_roll_link" pos="0.000508539 -0.0428346 0.000294848" quat="1 4.7792e-06 -5.34983e-06 -3.87226e-06">
          <inertial pos="-0.00140373 -0.00110749 -0.0616292" quat="0.706045 -0.0787684 -0.0826005 0.698909" mass="0.299276" diaginertia="0.000352803 7.71589e-05 0.000114258"/>
          <joint name="r_hip_roll_joint" class="/" pos="0 0 0" axis="-0.999998 -0.00145684 -0.00140383" range="-0.113813 0.510972" armature="0.00897809" damping="0.00655433" frictionloss="0.00934457"/>
          <geom name="//unnamed_geom_6" class="/" type="mesh" density="0" rgba="0.75294 0.75294 0.75294 1" mesh="r_hip_roll_link"/>
          <geom name="//unnamed_geom_7" class="/" size="0.000459883 0.000459883 0.000459883" type="box" rgba="0.75294 0.75294 0.75294 1"/>
          <geom name="//unnamed_geom_8" class="reward_collision_sphere" size="0.0367907"/>
          <body name="r_thigh_link" pos="0.00139882 0.00200938 -0.0676778" quat="1 7.38829e-05 -9.45862e-06 -0.000107036">
            <inertial pos="0.000218576 0.00172095 -0.0472235" quat="0.737086 0.675798 0.000708262 -9.87539e-05" mass="0.0884692" diaginertia="0.000130462 2.59297e-05 5.12801e-05"/>
            <joint name="r_thigh_joint" class="/" pos="0 0 0" axis="0.00165451 0.000600211 -0.999998" range="-0.30331 0.583449" armature="0.00943662" damping="0.00280465" frictionloss="0.00849691"/>
            <geom name="//unnamed_geom_9" class="/" type="mesh" density="0" rgba="0.75294 0.75294 0.75294 1" mesh="r_thigh_link"/>
            <geom name="//unnamed_geom_10" class="/" size="0.000459883 0.000459883 0.000459883" type="box" rgba="0.75294 0.75294 0.75294 1"/>
            <body name="r_calf_link" pos="-0.00132066 -0.00252987 -0.0676216" quat="0.947648 -1.34131e-05 0.319317 -4.95827e-05">
              <inertial pos="-6.32743e-05 0.000145195 -0.0680433" quat="0.999989 -7.96153e-05 0.00266137 0.00373857" mass="0.642227" diaginertia="0.00379761 0.000965823 0.000157829"/>
              <joint name="r_calf_joint" class="/" pos="0 0 0" axis="2.78417e-05 -1 -2.81904e-05" range="-1.63648 0.646091" armature="0.00929646" damping="0.0103103" frictionloss="0.00926629"/>
              <geom name="//unnamed_geom_11" class="/" type="mesh" density="0" rgba="0.75294 0.75294 0.75294 1" mesh="r_calf_link"/>
              <geom name="//unnamed_geom_12" class="/" size="0.000459883 0.000459883 0.000459883" type="box" rgba="0.75294 0.75294 0.75294 1"/>
              <geom name="//unnamed_geom_13" class="reward_collision_sphere" size="0.0367907"/>
              <body name="r_ankle_pitch_link" pos="-7.9462e-06 -6.042e-05 -0.136471" quat="0.980073 0.000109638 -0.198638 9.28678e-05">
                <inertial pos="0.00463167 0.00287356 -0.00135451" quat="-0.00071867 0.702693 0.00168398 0.711491" mass="0.138143" diaginertia="0.000331604 6.17251e-05 0.000107563"/>
                <joint name="r_ankle_pitch_joint" class="/" pos="0 0 0" axis="-0.0039597 -0.999992 0.000283121" range="-1.30045 0.527515" armature="0.00916479" damping="0.00813534" frictionloss="0.00937384"/>
                <geom name="//unnamed_geom_14" class="/" type="mesh" density="0" rgba="0.75294 0.75294 0.75294 1" mesh="r_ankle_pitch_link"/>
                <geom name="//unnamed_geom_15" class="/" size="0.0358709 0.0367907 0.0229942" type="box" rgba="0.75294 0.75294 0.75294 1"/>
                <body name="r_ankle_roll_link" pos="0.0772479 0.00266354 0.000321616" quat="1 -0.000105939 -1.39857e-05 -4.32894e-05">
                  <inertial pos="-0.0240321 -0.000271168 -0.0126818" quat="0.559692 0.434717 0.433337 0.556763" mass="0.396525" diaginertia="0.0011565 0.000283112 0.000244329"/>
                  <joint name="r_ankle_roll_joint" class="/" pos="0 0 0" axis="-0.999989 -0.00050056 -0.00468113" stiffness="0.00059728" range="-0.166841 0.143877" armature="0.00874609" damping="0.00596898" frictionloss="0.00962802"/>
                  <geom name="//unnamed_geom_16" class="/" type="mesh" density="0" rgba="0.75294 0.75294 0.75294 1" mesh="r_ankle_roll_link"/>
                  <geom name="//unnamed_geom_17" class="/" type="mesh" rgba="0.75294 0.75294 0.75294 1" mesh="r_ankle_roll_link"/>
                  <geom name="right_foot" class="foot" size="0.0714451 0.0312943 0.00438803" pos="-0.0515268 0 -0.0429625"/>
                  <geom name="//unnamed_geom_19" class="reward_collision_sphere" size="0.0367907" pos="-0.0505165 0 -0.0195284"/>
                  <geom name="//unnamed_geom_20" class="reward_collision_sphere" size="0.0183953" pos="0.0151549 0.015451 -0.0390568"/>
                  <geom name="//unnamed_geom_21" class="reward_collision_sphere" size="0.0183953" pos="-0.12124 0.015451 -0.0390568"/>
                  <site name="right_foot" class="foot" pos="-0.0515268 0 -0.0429625" size="0.00919766"/>
                </body>
              </body>
            </body>
          </body>
        </body>
      </body>
      <body name="l_hip_pitch_link" pos="0.000223343 0.0187133 -0.0327292" quat="0.992197 3.25429e-05 -0.124679 -1.59149e-05">
        <inertial pos="0.000857361 0.0412427 -0.000756263" quat="-0.0377393 0.704219 0.0296577 0.708358" mass="0.304503" diaginertia="0.000135092 2.90379e-05 8.89465e-05"/>
        <joint name="l_hip_pitch_joint" class="/" pos="0 0 0" axis="-0.00513597 0.999986 -0.00111324" range="-1.25383 1.75136" armature="0.00905387" damping="0.0140129" frictionloss="0.00896742"/>
        <geom name="//unnamed_geom_22" class="/" type="mesh" density="0" rgba="0.75294 0.75294 0.75294 1" mesh="l_hip_pitch_link"/>
        <geom name="//unnamed_geom_23" class="/" size="0.000459883 0.000459883 0.000459883" type="box" rgba="0.75294 0.75294 0.75294 1"/>
        <body name="l_hip_roll_link" pos="0.000756625 0.0430803 0.000333172" quat="1 -5.4208e-05 -6.90966e-05 0.00015623">
          <inertial pos="-0.00148109 0.000373749 -0.0613603" quat="0.699205 -0.0726521 -0.0767911 0.707063" mass="0.297524" diaginertia="0.00034331 7.5428e-05 0.00011195"/>
          <joint name="l_hip_roll_joint" class="/" pos="0 0 0" axis="-1 0.000379307 0.000297805" range="-0.52079 0.113027" armature="0.00953038" damping="0" frictionloss="0.00921369"/>
          <geom name="//unnamed_geom_24" class="/" type="mesh" density="0" rgba="0.75294 0.75294 0.75294 1" mesh="l_hip_roll_link"/>
          <geom name="//unnamed_geom_25" class="/" size="0.000459883 0.000459883 0.000459883" type="box" rgba="0.75294 0.75294 0.75294 1"/>
          <geom name="//unnamed_geom_26" class="reward_collision_sphere" size="0.0367907"/>
          <body name="l_thigh_link" pos="0.000737756 -0.00147591 -0.0674918" quat="1 8.11831e-05 0.000102439 -9.2129e-05">
            <inertial pos="-0.000459343 -0.000651315 -0.0472656" quat="0.675426 0.737428 0.000156972 -0.000197136" mass="0.0881544" diaginertia="0.000131896 2.58411e-05 5.17264e-05"/>
            <joint name="l_thigh_joint" class="/" pos="0 0 0" axis="-0.000670665 0.000496561 -1" range="-0.597711 0.315995" armature="0.00910805" damping="0.00382792" frictionloss="0.00901986"/>
            <geom name="//unnamed_geom_27" class="/" type="mesh" density="0" rgba="0.75294 0.75294 0.75294 1" mesh="l_thigh_link"/>
            <geom name="//unnamed_geom_28" class="/" size="0.000459883 0.000459883 0.000459883" type="box" rgba="0.75294 0.75294 0.75294 1"/>
            <body name="l_calf_link" pos="-0.000508764 0.000116256 -0.0693242" quat="0.947674 8.61391e-05 0.319239 8.63579e-05">
              <inertial pos="0.000440145 0.00258231 -0.0683297" quat="0.999984 0.00307915 -0.000169077 0.00473458" mass="0.616445" diaginertia="0.00362359 0.000941911 0.00015255"/>
              <joint name="l_calf_joint" class="/" pos="0 0 0" axis="-0.00105847 0.999999 0.000632231" range="-0.622505 1.66678" armature="0.00918981" damping="0.00739739" frictionloss="0.00901784"/>
              <geom name="//unnamed_geom_29" class="/" type="mesh" density="0" rgba="0.75294 0.75294 0.75294 1" mesh="l_calf_link"/>
              <geom name="//unnamed_geom_30" class="/" size="0.000459883 0.000459883 0.000459883" type="box" rgba="0.75294 0.75294 0.75294 1"/>
              <geom name="//unnamed_geom_31" class="reward_collision_sphere" size="0.0367907"/>
              <body name="l_ankle_pitch_link" pos="-3.033e-05 0.000846024 -0.13624" quat="0.980079 -3.45678e-05 -0.198609 -8.61038e-06">
                <inertial pos="0.00576751 -0.00136942 5.29463e-05" quat="-0.00222584 0.707073 0.00220839 0.707134" mass="0.136683" diaginertia="0.000320018 6.08645e-05 0.000106228"/>
                <joint name="l_ankle_pitch_joint" class="/" pos="0 0 0" axis="-0.000603185 1 0.000223073" range="-0.521462 1.29307" armature="0.00923335" damping="0.00256077" frictionloss="0.00935688"/>
                <geom name="//unnamed_geom_32" class="/" type="mesh" density="0" rgba="0.75294 0.75294 0.75294 1" mesh="l_ankle_pitch_link"/>
                <geom name="//unnamed_geom_33" class="/" size="0.0358709 0.0367907 0.0229942" type="box" rgba="0.75294 0.75294 0.75294 1"/>
                <body name="l_ankle_roll_link" pos="0.0767703 0.000454366 -0.000670761" quat="1 -0.000132112 2.40483e-05 7.47751e-05">
                  <inertial pos="-0.0247645 -0.000280254 -0.0142717" quat="0.561709 0.431084 0.432954 0.557854" mass="0.408658" diaginertia="0.00119559 0.000286124 0.000252916"/>
                  <joint name="l_ankle_roll_joint" class="/" pos="0 0 0" axis="-1 -0.000202172 9.07731e-05" range="-0.156559 0.151562" armature="0.0090119" damping="0.00959858" frictionloss="0.00919288"/>
                  <geom name="//unnamed_geom_34" class="/" type="mesh" density="0" rgba="0.75294 0.75294 0.75294 1" mesh="l_ankle_roll_link"/>
                  <geom name="//unnamed_geom_35" class="/" type="mesh" rgba="0.75294 0.75294 0.75294 1" mesh="l_ankle_roll_link"/>
                  <geom name="left_foot" class="foot" size="0.0772149 0.0373114 0.00476554" pos="-0.0515268 0 -0.0429625"/>
                  <geom name="//unnamed_geom_37" class="reward_collision_sphere" size="0.0367907" pos="-0.0505165 0 -0.0195284"/>
                  <geom name="//unnamed_geom_38" class="reward_collision_sphere" size="0.0183953" pos="0.0151549 -0.015451 -0.0390568"/>
                  <geom name="//unnamed_geom_39" class="reward_collision_sphere" size="0.0183953" pos="-0.12124 -0.015451 -0.0390568"/>
                  <site name="left_foot" class="foot" pos="-0.0515268 0 -0.0429625" size="0.00919766"/>
                </body>
              </body>
            </body>
          </body>
        </body>
      </body>
    </body>
  </worldbody>

  <contact>
    <pair class="/" geom1="floor" geom2="right_foot" name="//unnamed_contact_1"/>
    <pair class="/" geom1="floor" geom2="left_foot" name="//unnamed_contact_0"/>
  </contact>

  <actuator>
    <general name="r_hip_pitch_joint" class="/" joint="r_hip_pitch_joint" forcerange="-19.2884 19.2884" gainprm="18.4219" biasprm="0 -18.4219 -0.463818"/>
    <general name="r_hip_roll_joint" class="/" joint="r_hip_roll_joint" forcerange="-18.9742 18.9742" gainprm="18.4219" biasprm="0 -18.4219 -0.463818"/>
    <general name="r_thigh_joint" class="/" joint="r_thigh_joint" forcerange="-18.6527 18.6527" gainprm="18.4219" biasprm="0 -18.4219 -0.463818"/>
    <general name="r_calf_joint" class="/" joint="r_calf_joint" forcerange="-19.5456 19.5456" gainprm="18.4219" biasprm="0 -18.4219 -0.463818"/>
    <general name="r_ankle_pitch_joint" class="/" joint="r_ankle_pitch_joint" forcerange="-18.9111 18.9111" gainprm="18.4219" biasprm="0 -18.4219 -0.463818"/>
    <general name="r_ankle_roll_joint" class="/" joint="r_ankle_roll_joint" forcerange="-18.6159 18.6159" gainprm="18.4219" biasprm="0 -18.4219 -0.463818"/>
    <general name="l_hip_pitch_joint" class="/" joint="l_hip_pitch_joint" forcerange="-19.6874 19.6874" gainprm="18.4219" biasprm="0 -18.4219 -0.463818"/>
    <general name="l_hip_roll_joint" class="/" joint="l_hip_roll_joint" forcerange="-19.505 19.505" gainprm="18.4219" biasprm="0 -18.4219 -0.463818"/>
    <general name="l_thigh_joint" class="/" joint="l_thigh_joint" forcerange="-18.7926 18.7926" gainprm="18.4219" biasprm="0 -18.4219 -0.463818"/>
    <general name="l_calf_joint" class="/" joint="l_calf_joint" forcerange="-19.4076 19.4076" gainprm="18.4219" biasprm="0 -18.4219 -0.463818"/>
    <general name="l_ankle_pitch_joint" class="/" joint="l_ankle_pitch_joint" forcerange="-18.677 18.677" gainprm="18.4219" biasprm="0 -18.4219 -0.463818"/>
    <general name="l_ankle_roll_joint" class="/" joint="l_ankle_roll_joint" forcerange="-20.4689 20.4689" gainprm="18.4219" biasprm="0 -18.4219 -0.463818"/>
  </actuator>

  <sensor>
    <gyro site="imu" name="imu_angular_velocity"/>
    <velocimeter site="imu" name="imu_linear_velocity"/>
    <framelinvel objtype="site" objname="left_foot" name="left_foot_global_linear_velocity"/>
    <framelinvel objtype="site" objname="right_foot" name="right_foot_global_linear_velocity"/>
  </sensor>

  <keyframe>
    <key name="home" qpos="0 0 0.291 1 0 0 0 0.4 0 0 -0.8 0.4 0 -0.4 0 0 0.8 -0.4 0"/>
  </keyframe>
</mujoco>
