<mujoco model="pi_12dof_release_v1">
  <compiler angle="radian" assetdir="assets" balanceinertia="true" inertiafromgeom="false"/>

  <option timestep="0.005" density="1.2" viscosity="2e-05"/>

  <size nkey="1"/>

  <visual>
    <quality shadowsize="8192"/>
    <map shadowclip="0.5"/>
  </visual>

  <default>
    <default class="/">
      <joint armature="0.01" damping="0.01" frictionloss="0.01"/>
      <geom contype="0" conaffinity="0" group="1" solref="-1000 -80"/>
      <site size="0.01 0.005 0.005" group="5"/>
      <general forcelimited="true" biastype="affine" gainprm="20" biasprm="0 -20 -0.5"/>
      <default class="foot">
        <geom size="0.0845 0.036 0.005" type="box" condim="6" group="4" priority="1" friction="0.9 0.2 0.2" solimp="0.015 1 0.005"/>
      </default>
      <default class="reward_collision_sphere">
        <geom group="5" rgba="1 0 0 1"/>
      </default>
    </default>
  </default>

  <asset>
    <texture type="skybox" colorspace="auto" name="//unnamed_texture_0" builtin="gradient" rgb1="0.95 0.95 0.95" rgb2="0.95 0.95 0.95" width="100" height="600"/>
    <texture type="2d" colorspace="auto" name="texplane" builtin="checker" rgb1="0.345 0.575 0.748" rgb2="0.345 0.575 0.748" markrgb="1 1 1" width="512" height="512"/>
    <material name="MatPlane" class="/" texture="texplane" texuniform="true" texrepeat="2 2" specular="0.9"/>
    <mesh name="baselink_1" class="/" file="baselink_1.STL"/>
    <mesh name="r_hip_pitch_link" class="/" file="r_hip_pitch_link.STL"/>
    <mesh name="r_hip_roll_link" class="/" file="r_hip_roll_link.STL"/>
    <mesh name="r_thigh_link" class="/" file="r_thigh_link.STL"/>
    <mesh name="r_calf_link" class="/" file="r_calf_link.STL"/>
    <mesh name="r_ankle_pitch_link" class="/" file="r_ankle_pitch_link.STL"/>
    <mesh name="r_ankle_roll_link" class="/" file="r_ankle_roll_link.STL"/>
    <mesh name="l_hip_pitch_link" class="/" file="l_hip_pitch_link.STL"/>
    <mesh name="l_hip_roll_link" class="/" file="l_hip_roll_link.STL"/>
    <mesh name="l_thigh_link" class="/" file="l_thigh_link.STL"/>
    <mesh name="l_calf_link" class="/" file="l_calf_link.STL"/>
    <mesh name="l_ankle_pitch_link" class="/" file="l_ankle_pitch_link.STL"/>
    <mesh name="l_ankle_roll_link" class="/" file="l_ankle_roll_link.STL"/>
  </asset>

  <worldbody>
    <geom name="floor" class="/" size="100 100 0.125" type="plane" group="0" material="MatPlane"/>
    <light name="toplight_shadow" class="/" pos="0 0 5" dir="0.0990148 0.0990148 -0.990148" type="directional" ambient="0.04 0.04 0.04" diffuse="0.55 0.55 0.55" specular="0.12 0.12 0.12"/>
    <light name="toplight_fill" class="/" pos="0 0 5" dir="0.0990148 0.0990148 -0.990148" type="directional" castshadow="false" ambient="0.04 0.04 0.04" diffuse="0.3 0.3 0.3" specular="0.08 0.08 0.08"/>
    <body name="trunk" pos="0.000375553 0.000514506 0.000960653" quat="1 0.000203268 -0.000288914 3.69027e-05">
      <inertial pos="0.00330946 -0.00153018 0.0392818" quat="0.695191 0.0105884 0.00915231 0.718688" mass="1.66823" diaginertia="0.0109363 0.00242148 0.00362285"/>
      <joint name="//unnamed_joint_0" type="free"/>
      <geom name="//unnamed_geom_1" class="/" type="mesh" density="0" rgba="1 1 1 1" mesh="baselink_1"/>
      <geom name="//unnamed_geom_2" class="/" size="0.0459382 0.0459382 0.0459382" pos="0 0 0.0774812" type="box" rgba="1 1 1 1"/>
      <geom name="//unnamed_geom_3" class="reward_collision_sphere" size="0.050532" pos="0 0 0.0677961"/>
      <site name="imu" class="/" pos="-0.00455598 -0.00835576 0.00321844" size="0.00918763"/>
      <camera name="track" class="/" pos="0 -1.53811 0" quat="0.707107 0.707107 0 0" mode="trackcom"/>
      <camera name="ego_camera" class="/" pos="0.0764041 0 0.174333" quat="-0.5 -0.5 0.5 0.5"/>
      <body name="r_hip_pitch_link" pos="0.000155052 -0.0174497 -0.0314338" quat="0.992122 -0.000277783 -0.125275 -0.000218766">
        <inertial pos="0.00200823 -0.0431153 -0.000134628" quat="-0.0192899 0.705043 -0.0289369 0.708312" mass="0.29076" diaginertia="0.000120749 2.67606e-05 7.08712e-05"/>
        <joint name="r_hip_pitch_joint" class="/" pos="0 0 0" axis="0.00361417 -0.999993 0.000896399" range="-1.75488 1.25558" armature="0.00961416" damping="0.0153221" frictionloss="0.00911432"/>
        <geom name="//unnamed_geom_4" class="/" type="mesh" density="0" rgba="0.75294 0.75294 0.75294 1" mesh="r_hip_pitch_link"/>
        <geom name="//unnamed_geom_5" class="/" size="0.000459382 0.000459382 0.000459382" type="box" rgba="0.75294 0.75294 0.75294 1"/>
        <body name="r_hip_roll_link" pos="0.000617799 -0.0426652 0.000321401" quat="1 4.64268e-05 2.2515e-05 -1.62879e-05">
          <inertial pos="-0.00141225 -0.00130535 -0.0612979" quat="0.706069 -0.0797487 -0.081684 0.69888" mass="0.29857" diaginertia="0.000367855 7.54612e-05 0.000109705"/>
          <joint name="r_hip_roll_joint" class="/" pos="0 0 0" axis="-0.999999 -0.00043908 -0.00121683" range="-0.112162 0.514971" armature="0.00890104" damping="0.00719683" frictionloss="0.00939752"/>
          <geom name="//unnamed_geom_6" class="/" type="mesh" density="0" rgba="0.75294 0.75294 0.75294 1" mesh="r_hip_roll_link"/>
          <geom name="//unnamed_geom_7" class="/" size="0.000459382 0.000459382 0.000459382" type="box" rgba="0.75294 0.75294 0.75294 1"/>
          <geom name="//unnamed_geom_8" class="reward_collision_sphere" size="0.0367505"/>
          <body name="r_thigh_link" pos="0.00156496 0.00216961 -0.0669937" quat="1 6.00627e-05 1.94693e-05 0.000155677">
            <inertial pos="0.000327142 0.00167691 -0.0467387" quat="0.737635 0.675199 0.000418734 -0.00034117" mass="0.0882984" diaginertia="0.000136027 2.53534e-05 4.91754e-05"/>
            <joint name="r_thigh_joint" class="/" pos="0 0 0" axis="0.000948526 0.000719857 -0.999999" range="-0.30599 0.581146" armature="0.00940854" damping="0.0017973" frictionloss="0.00840877"/>
            <geom name="//unnamed_geom_9" class="/" type="mesh" density="0" rgba="0.75294 0.75294 0.75294 1" mesh="r_thigh_link"/>
            <geom name="//unnamed_geom_10" class="/" size="0.000459382 0.000459382 0.000459382" type="box" rgba="0.75294 0.75294 0.75294 1"/>
            <body name="r_calf_link" pos="-0.00121756 -0.0024169 -0.0668819" quat="0.947632 -2.21306e-05 0.319364 -3.36891e-05">
              <inertial pos="8.42339e-05 4.88598e-05 -0.0675081" quat="0.999954 -0.00564569 0.00409786 0.00655672" mass="0.641366" diaginertia="0.0039676 0.00094532 0.000151833"/>
              <joint name="r_calf_joint" class="/" pos="0 0 0" axis="0.000805626 -0.999999 0.000600483" range="-1.63253 0.645395" armature="0.00920587" damping="0.0107345" frictionloss="0.00929109"/>
              <geom name="//unnamed_geom_11" class="/" type="mesh" density="0" rgba="0.75294 0.75294 0.75294 1" mesh="r_calf_link"/>
              <geom name="//unnamed_geom_12" class="/" size="0.000459382 0.000459382 0.000459382" type="box" rgba="0.75294 0.75294 0.75294 1"/>
              <geom name="//unnamed_geom_13" class="reward_collision_sphere" size="0.0367505"/>
              <body name="r_ankle_pitch_link" pos="1.9356e-05 1.53706e-05 -0.135478" quat="0.980025 -7.08504e-05 -0.198876 1.50898e-05">
                <inertial pos="0.00469317 0.00286313 -0.00154104" quat="0.00292431 0.713238 -0.00190911 0.700914" mass="0.13778" diaginertia="0.00034644 6.05136e-05 0.000103584"/>
                <joint name="r_ankle_pitch_joint" class="/" pos="0 0 0" axis="-0.000924454 -0.99999 0.00441992" range="-1.29928 0.531156" armature="0.00913283" damping="0.0085657" frictionloss="0.00945185"/>
                <geom name="//unnamed_geom_14" class="/" type="mesh" density="0" rgba="0.75294 0.75294 0.75294 1" mesh="r_ankle_pitch_link"/>
                <geom name="//unnamed_geom_15" class="/" size="0.0358318 0.0367505 0.0229691" type="box" rgba="0.75294 0.75294 0.75294 1"/>
                <body name="r_ankle_roll_link" pos="0.0777703 0.0025227 0.0002418" quat="1 3.26476e-05 -5.38313e-05 -0.00010611">
                  <inertial pos="-0.0242357 -0.000244807 -0.0123939" quat="0.556878 0.429516 0.437077 0.560685" mass="0.393588" diaginertia="0.00120136 0.000276777 0.000233523"/>
                  <joint name="r_ankle_roll_joint" class="/" pos="0 0 0" axis="-0.999984 0.00403427 0.00400208" stiffness="0.000744431" range="-0.164908 0.13999" armature="0.00865097" damping="0.00701129" frictionloss="0.00960826"/>
                  <geom name="//unnamed_geom_16" class="/" type="mesh" density="0" rgba="0.75294 0.75294 0.75294 1" mesh="r_ankle_roll_link"/>
                  <geom name="//unnamed_geom_17" class="/" type="mesh" rgba="0.75294 0.75294 0.75294 1" mesh="r_ankle_roll_link"/>
                  <geom name="right_foot" class="foot" size="0.0711081 0.0312772 0.00437218" pos="-0.0519548 0 -0.0426147"/>
                  <geom name="//unnamed_geom_19" class="reward_collision_sphere" size="0.0367505" pos="-0.050936 0 -0.0193703"/>
                  <geom name="//unnamed_geom_20" class="reward_collision_sphere" size="0.0183753" pos="0.0152808 0.0153811 -0.0387406"/>
                  <geom name="//unnamed_geom_21" class="reward_collision_sphere" size="0.0183753" pos="-0.122246 0.0153811 -0.0387406"/>
                  <site name="right_foot" class="foot" pos="-0.0519548 0 -0.0426147" size="0.00918763"/>
                </body>
              </body>
            </body>
          </body>
        </body>
      </body>
      <body name="l_hip_pitch_link" pos="0.000302311 0.0186995 -0.0326748" quat="0.992199 1.25457e-05 -0.124661 -1.53282e-05">
        <inertial pos="0.000942129 0.040945 -0.000953461" quat="-0.0401414 0.704369 0.0287087 0.708116" mass="0.303945" diaginertia="0.000140992 2.8321e-05 8.54324e-05"/>
        <joint name="l_hip_pitch_joint" class="/" pos="0 0 0" axis="0.00544056 0.999985 0.000236728" range="-1.25078 1.7536" armature="0.00911578" damping="0.0143739" frictionloss="0.00894791"/>
        <geom name="//unnamed_geom_22" class="/" type="mesh" density="0" rgba="0.75294 0.75294 0.75294 1" mesh="l_hip_pitch_link"/>
        <geom name="//unnamed_geom_23" class="/" size="0.000459382 0.000459382 0.000459382" type="box" rgba="0.75294 0.75294 0.75294 1"/>
        <body name="l_hip_roll_link" pos="0.000780536 0.0430121 0.000305478" quat="1 9.07308e-06 -0.00018335 -0.000203293">
          <inertial pos="-0.00170127 0.000276047 -0.0610271" quat="0.696586 -0.0764183 -0.0788812 0.709018" mass="0.296344" diaginertia="0.000356521 7.36043e-05 0.000107104"/>
          <joint name="l_hip_roll_joint" class="/" pos="0 0 0" axis="-1 -0.000216547 -1.99217e-05" range="-0.524583 0.11643" armature="0.00953068" damping="0" frictionloss="0.00921185"/>
          <geom name="//unnamed_geom_24" class="/" type="mesh" density="0" rgba="0.75294 0.75294 0.75294 1" mesh="l_hip_roll_link"/>
          <geom name="//unnamed_geom_25" class="/" size="0.000459382 0.000459382 0.000459382" type="box" rgba="0.75294 0.75294 0.75294 1"/>
          <geom name="//unnamed_geom_26" class="reward_collision_sphere" size="0.0367505"/>
          <body name="l_thigh_link" pos="0.000583346 -0.00154829 -0.0671113" quat="1 -5.02964e-05 9.61274e-05 9.54319e-05">
            <inertial pos="-0.000445385 -0.000729857 -0.0467721" quat="0.675555 0.73731 0.000107894 0.000563452" mass="0.0877762" diaginertia="0.000137512 2.52508e-05 4.979e-05"/>
            <joint name="l_thigh_joint" class="/" pos="0 0 0" axis="0.000933354 -0.000361602 -0.999999" range="-0.598273 0.315935" armature="0.00908137" damping="0.00398708" frictionloss="0.00897678"/>
            <geom name="//unnamed_geom_27" class="/" type="mesh" density="0" rgba="0.75294 0.75294 0.75294 1" mesh="l_thigh_link"/>
            <geom name="//unnamed_geom_28" class="/" size="0.000459382 0.000459382 0.000459382" type="box" rgba="0.75294 0.75294 0.75294 1"/>
            <body name="l_calf_link" pos="-0.000652489 0.000246773 -0.0687739" quat="0.947692 -0.000135137 0.319186 -8.83851e-05">
              <inertial pos="0.000420367 0.00275329 -0.0679262" quat="0.999983 0.00313809 -2.49328e-05 0.00485165" mass="0.612421" diaginertia="0.00376835 0.000919264 0.000146201"/>
              <joint name="l_calf_joint" class="/" pos="0 0 0" axis="-0.000258617 0.999999 0.00169222" range="-0.618877 1.67071" armature="0.00915965" damping="0.00725139" frictionloss="0.00894626"/>
              <geom name="//unnamed_geom_29" class="/" type="mesh" density="0" rgba="0.75294 0.75294 0.75294 1" mesh="l_calf_link"/>
              <geom name="//unnamed_geom_30" class="/" size="0.000459382 0.000459382 0.000459382" type="box" rgba="0.75294 0.75294 0.75294 1"/>
              <geom name="//unnamed_geom_31" class="reward_collision_sphere" size="0.0367505"/>
              <body name="l_ankle_pitch_link" pos="-0.000172039 0.000762501 -0.134939" quat="0.980052 -4.2705e-06 -0.198742 5.49521e-05">
                <inertial pos="0.00572019 -0.001242 8.52226e-05" quat="-0.00237861 0.707112 0.00200009 0.707095" mass="0.135621" diaginertia="0.000332524 5.9286e-05 0.000101991"/>
                <joint name="l_ankle_pitch_joint" class="/" pos="0 0 0" axis="6.11175e-05 1 -0.000471603" range="-0.525329 1.29291" armature="0.00914748" damping="0.0029052" frictionloss="0.00930272"/>
                <geom name="//unnamed_geom_32" class="/" type="mesh" density="0" rgba="0.75294 0.75294 0.75294 1" mesh="l_ankle_pitch_link"/>
                <geom name="//unnamed_geom_33" class="/" size="0.0358318 0.0367505 0.0229691" type="box" rgba="0.75294 0.75294 0.75294 1"/>
                <body name="l_ankle_roll_link" pos="0.0776122 0.00036956 -0.000632479" quat="1 0.000126946 3.9208e-06 -1.04484e-05">
                  <inertial pos="-0.0250718 -0.000188482 -0.0142248" quat="0.559412 0.429047 0.436129 0.559256" mass="0.406008" diaginertia="0.00124574 0.000278963 0.000242776"/>
                  <joint name="l_ankle_roll_joint" class="/" pos="0 0 0" axis="-1 -0.000291848 -0.000231713" range="-0.159123 0.151451" armature="0.00906762" damping="0.00953451" frictionloss="0.00920133"/>
                  <geom name="//unnamed_geom_34" class="/" type="mesh" density="0" rgba="0.75294 0.75294 0.75294 1" mesh="l_ankle_roll_link"/>
                  <geom name="//unnamed_geom_35" class="/" type="mesh" rgba="0.75294 0.75294 0.75294 1" mesh="l_ankle_roll_link"/>
                  <geom name="left_foot" class="foot" size="0.077345 0.0374382 0.00479448" pos="-0.0519548 0 -0.0426147"/>
                  <geom name="//unnamed_geom_37" class="reward_collision_sphere" size="0.0367505" pos="-0.050936 0 -0.0193703"/>
                  <geom name="//unnamed_geom_38" class="reward_collision_sphere" size="0.0183753" pos="0.0152808 -0.0153811 -0.0387406"/>
                  <geom name="//unnamed_geom_39" class="reward_collision_sphere" size="0.0183753" pos="-0.122246 -0.0153811 -0.0387406"/>
                  <site name="left_foot" class="foot" pos="-0.0519548 0 -0.0426147" size="0.00918763"/>
                </body>
              </body>
            </body>
          </body>
        </body>
      </body>
    </body>
  </worldbody>

  <contact>
    <pair class="/" geom1="floor" geom2="right_foot" name="//unnamed_contact_1"/>
    <pair class="/" geom1="floor" geom2="left_foot" name="//unnamed_contact_0"/>
  </contact>

  <actuator>
    <general name="r_hip_pitch_joint" class="/" joint="r_hip_pitch_joint" forcerange="-19.2661 19.2661" gainprm="18.4382" biasprm="0 -18.4382 -0.465724"/>
    <general name="r_hip_roll_joint" class="/" joint="r_hip_roll_joint" forcerange="-18.8132 18.8132" gainprm="18.4382" biasprm="0 -18.4382 -0.465724"/>
    <general name="r_thigh_joint" class="/" joint="r_thigh_joint" forcerange="-18.6349 18.6349" gainprm="18.4382" biasprm="0 -18.4382 -0.465724"/>
    <general name="r_calf_joint" class="/" joint="r_calf_joint" forcerange="-19.6223 19.6223" gainprm="18.4382" biasprm="0 -18.4382 -0.465724"/>
    <general name="r_ankle_pitch_joint" class="/" joint="r_ankle_pitch_joint" forcerange="-18.8003 18.8003" gainprm="18.4382" biasprm="0 -18.4382 -0.465724"/>
    <general name="r_ankle_roll_joint" class="/" joint="r_ankle_roll_joint" forcerange="-18.6004 18.6004" gainprm="18.4382" biasprm="0 -18.4382 -0.465724"/>
    <general name="l_hip_pitch_joint" class="/" joint="l_hip_pitch_joint" forcerange="-19.6169 19.6169" gainprm="18.4382" biasprm="0 -18.4382 -0.465724"/>
    <general name="l_hip_roll_joint" class="/" joint="l_hip_roll_joint" forcerange="-19.6208 19.6208" gainprm="18.4382" biasprm="0 -18.4382 -0.465724"/>
    <general name="l_thigh_joint" class="/" joint="l_thigh_joint" forcerange="-18.6309 18.6309" gainprm="18.4382" biasprm="0 -18.4382 -0.465724"/>
    <general name="l_calf_joint" class="/" joint="l_calf_joint" forcerange="-19.4654 19.4654" gainprm="18.4382" biasprm="0 -18.4382 -0.465724"/>
    <general name="l_ankle_pitch_joint" class="/" joint="l_ankle_pitch_joint" forcerange="-18.6991 18.6991" gainprm="18.4382" biasprm="0 -18.4382 -0.465724"/>
    <general name="l_ankle_roll_joint" class="/" joint="l_ankle_roll_joint" forcerange="-20.567 20.567" gainprm="18.4382" biasprm="0 -18.4382 -0.465724"/>
  </actuator>

  <sensor>
    <gyro site="imu" name="imu_angular_velocity"/>
    <velocimeter site="imu" name="imu_linear_velocity"/>
    <framelinvel objtype="site" objname="left_foot" name="left_foot_global_linear_velocity"/>
    <framelinvel objtype="site" objname="right_foot" name="right_foot_global_linear_velocity"/>
  </sensor>

  <keyframe>
    <key name="home" qpos="0 0 0.291 1 0 0 0 0.4 0 0 -0.8 0.4 0 -0.4 0 0 0.8 -0.4 0"/>
  </keyframe>
</mujoco>
