<mujoco model="pi_12dof_release_v1">
  <compiler angle="radian" assetdir="assets" balanceinertia="true" inertiafromgeom="false"/>

  <option timestep="0.005" density="1.2" viscosity="2e-05"/>

  <size nkey="1"/>

  <visual>
    <quality shadowsize="8192"/>
    <map shadowclip="0.5"/>
  </visual>

  <default>
    <default class="/">
      <joint armature="0.01" damping="0.01" frictionloss="0.01"/>
      <geom contype="0" conaffinity="0" group="1" solref="-1000 -80"/>
      <site size="0.01 0.005 0.005" group="5"/>
      <general forcelimited="true" biastype="affine" gainprm="20" biasprm="0 -20 -0.5"/>
      <default class="foot">
        <geom size="0.0845 0.036 0.005" type="box" condim="6" group="4" priority="1" friction="0.9 0.2 0.2" solimp="0.015 1 0.005"/>
      </default>
      <default class="reward_collision_sphere">
        <geom group="5" rgba="1 0 0 1"/>
      </default>
    </default>
  </default>

  <asset>
    <texture type="skybox" colorspace="auto" name="//unnamed_texture_0" builtin="gradient" rgb1="0.95 0.95 0.95" rgb2="0.95 0.95 0.95" width="100" height="600"/>
    <texture type="2d" colorspace="auto" name="texplane" builtin="checker" rgb1="0.345 0.575 0.748" rgb2="0.345 0.575 0.748" markrgb="1 1 1" width="512" height="512"/>
    <material name="MatPlane" class="/" texture="texplane" texuniform="true" texrepeat="2 2" specular="0.9"/>
    <mesh name="baselink_1" class="/" file="baselink_1.STL"/>
    <mesh name="r_hip_pitch_link" class="/" file="r_hip_pitch_link.STL"/>
    <mesh name="r_hip_roll_link" class="/" file="r_hip_roll_link.STL"/>
    <mesh name="r_thigh_link" class="/" file="r_thigh_link.STL"/>
    <mesh name="r_calf_link" class="/" file="r_calf_link.STL"/>
    <mesh name="r_ankle_pitch_link" class="/" file="r_ankle_pitch_link.STL"/>
    <mesh name="r_ankle_roll_link" class="/" file="r_ankle_roll_link.STL"/>
    <mesh name="l_hip_pitch_link" class="/" file="l_hip_pitch_link.STL"/>
    <mesh name="l_hip_roll_link" class="/" file="l_hip_roll_link.STL"/>
    <mesh name="l_thigh_link" class="/" file="l_thigh_link.STL"/>
    <mesh name="l_calf_link" class="/" file="l_calf_link.STL"/>
    <mesh name="l_ankle_pitch_link" class="/" file="l_ankle_pitch_link.STL"/>
    <mesh name="l_ankle_roll_link" class="/" file="l_ankle_roll_link.STL"/>
  </asset>

  <worldbody>
    <geom name="floor" class="/" size="100 100 0.125" type="plane" group="0" material="MatPlane"/>
    <light name="toplight_shadow" class="/" pos="0 0 5" dir="0.0990148 0.0990148 -0.990148" type="directional" ambient="0.04 0.04 0.04" diffuse="0.55 0.55 0.55" specular="0.12 0.12 0.12"/>
    <light name="toplight_fill" class="/" pos="0 0 5" dir="0.0990148 0.0990148 -0.990148" type="directional" castshadow="false" ambient="0.04 0.04 0.04" diffuse="0.3 0.3 0.3" specular="0.08 0.08 0.08"/>
    <body name="trunk" pos="-0.000476471 9.69586e-05 0.000186789" quat="1 0.00012896 5.27474e-05 3.95059e-05">
      <inertial pos="0.00177286 -0.000649279 0.0405734" quat="0.69468 0.0112042 0.0108705 0.71915" mass="1.92955" diaginertia="0.012046 0.00375412 0.00432911"/>
      <joint name="//unnamed_joint_0" type="free"/>
      <geom name="//unnamed_geom_1" class="/" type="mesh" density="0" rgba="1 1 1 1" mesh="baselink_1"/>
      <geom name="//unnamed_geom_2" class="/" size="0.0481918 0.0481918 0.0481918" pos="0 0 0.0806197" type="box" rgba="1 1 1 1"/>
      <geom name="//unnamed_geom_3" class="reward_collision_sphere" size="0.0530109" pos="0 0 0.0705422"/>
      <site name="imu" class="/" pos="-0.000465282 -0.000138792 0.000550245" size="0.00963835"/>
      <camera name="track" class="/" pos="0 -1.6806 0" quat="0.707107 0.707107 0 0" mode="trackcom"/>
      <camera name="ego_camera" class="/" pos="0.0782597 0 0.181394" quat="-0.5 -0.5 0.5 0.5"/>
      <body name="r_hip_pitch_link" pos="0.000845395 -0.01799 -0.0323924" quat="0.992192 -7.02936e-05 -0.124722 -1.20364e-05">
        <inertial pos="0.000997867 -0.0463319 -1.7029e-06" quat="-0.0187676 0.705812 -0.0281565 0.707591" mass="0.326554" diaginertia="0.000133488 4.11243e-05 8.57881e-05"/>
        <joint name="r_hip_pitch_joint" class="/" pos="0 0 0" axis="-4.30655e-05 -1 6.59054e-05" range="-1.75443 1.24656" armature="0.00987509" damping="0.0137462" frictionloss="0.00971898"/>
        <geom name="//unnamed_geom_4" class="/" type="mesh" density="0" rgba="0.75294 0.75294 0.75294 1" mesh="r_hip_pitch_link"/>
        <geom name="//unnamed_geom_5" class="/" size="0.000481918 0.000481918 0.000481918" type="box" rgba="0.75294 0.75294 0.75294 1"/>
        <body name="r_hip_roll_link" pos="0.00149018 -0.0460724 -0.000741264" quat="1 -6.43441e-05 0.000160879 0.000152778">
          <inertial pos="-0.00156142 -0.000166479 -0.0619761" quat="0.707064 -0.0824357 -0.0825099 0.697465" mass="0.352948" diaginertia="0.000415373 0.000116456 0.000134631"/>
          <joint name="r_hip_roll_joint" class="/" pos="0 0 0" axis="-0.999993 -0.00276648 -0.00246371" range="-0.122591 0.498837" armature="0.0100459" damping="0.00275771" frictionloss="0.00966398"/>
          <geom name="//unnamed_geom_6" class="/" type="mesh" density="0" rgba="0.75294 0.75294 0.75294 1" mesh="r_hip_roll_link"/>
          <geom name="//unnamed_geom_7" class="/" size="0.000481918 0.000481918 0.000481918" type="box" rgba="0.75294 0.75294 0.75294 1"/>
          <geom name="//unnamed_geom_8" class="reward_collision_sphere" size="0.0385534"/>
          <body name="r_thigh_link" pos="-0.000738001 0.000663637 -0.0689605" quat="1 0.000227691 -3.63087e-05 -0.000178651">
            <inertial pos="0.000597798 0.00151321 -0.0473021" quat="0.736957 0.675939 -0.000611385 -0.000534202" mass="0.100419" diaginertia="0.000155261 3.93937e-05 6.03196e-05"/>
            <joint name="r_thigh_joint" class="/" pos="0 0 0" axis="0.00192475 -0.000414134 -0.999998" range="-0.285124 0.582429" armature="0.00961631" damping="0.00861998" frictionloss="0.00938621"/>
            <geom name="//unnamed_geom_9" class="/" type="mesh" density="0" rgba="0.75294 0.75294 0.75294 1" mesh="r_thigh_link"/>
            <geom name="//unnamed_geom_10" class="/" size="0.000481918 0.000481918 0.000481918" type="box" rgba="0.75294 0.75294 0.75294 1"/>
            <body name="r_calf_link" pos="-0.000252349 -0.00194964 -0.0707489" quat="0.94767 -3.85483e-05 0.319251 -3.27131e-05">
              <inertial pos="0.00053632 -0.00128414 -0.0695049" quat="0.999988 -0.00350469 -0.000126448 0.00328232" mass="0.732888" diaginertia="0.00440506 0.00146678 0.000183669"/>
              <joint name="r_calf_joint" class="/" pos="0 0 0" axis="-0.000666653 -0.99999 0.00446514" range="-1.65229 0.645253" armature="0.00988055" damping="0.00573532" frictionloss="0.00949635"/>
              <geom name="//unnamed_geom_11" class="/" type="mesh" density="0" rgba="0.75294 0.75294 0.75294 1" mesh="r_calf_link"/>
              <geom name="//unnamed_geom_12" class="/" size="0.000481918 0.000481918 0.000481918" type="box" rgba="0.75294 0.75294 0.75294 1"/>
              <geom name="//unnamed_geom_13" class="reward_collision_sphere" size="0.0385534"/>
              <body name="r_ankle_pitch_link" pos="-0.000323034 0.000251371 -0.140833" quat="0.980081 -1.4652e-05 -0.198598 0.000196868">
                <inertial pos="0.00477852 0.0026248 0.000514044" quat="0.00110185 0.709411 -0.000503207 0.704794" mass="0.155409" diaginertia="0.000382991 9.32416e-05 0.000123897"/>
                <joint name="r_ankle_pitch_joint" class="/" pos="0 0 0" axis="-0.00467663 -0.999985 0.00296278" range="-1.3064 0.483622" armature="0.00924362" damping="0.00922904" frictionloss="0.0097737"/>
                <geom name="//unnamed_geom_14" class="/" type="mesh" density="0" rgba="0.75294 0.75294 0.75294 1" mesh="r_ankle_pitch_link"/>
                <geom name="//unnamed_geom_15" class="/" size="0.0375896 0.0385534 0.0240959" type="box" rgba="0.75294 0.75294 0.75294 1"/>
                <body name="r_ankle_roll_link" pos="0.0805391 0.0026023 0.000188742" quat="1 -7.79975e-05 -0.000280797 6.88071e-05">
                  <inertial pos="-0.0242305 0.000144937 -0.0145141" quat="0.559857 0.430318 0.433445 0.559922" mass="0.455689" diaginertia="0.00138469 0.000429799 0.000291163"/>
                  <joint name="r_ankle_roll_joint" class="/" pos="0 0 0" axis="-0.999996 0.0022308 -0.00167618" range="-0.166869 0.156147" armature="0.00966291" damping="0.00719275" frictionloss="0.00986469"/>
                  <geom name="//unnamed_geom_16" class="/" type="mesh" density="0" rgba="0.75294 0.75294 0.75294 1" mesh="r_ankle_roll_link"/>
                  <geom name="//unnamed_geom_17" class="/" type="mesh" rgba="0.75294 0.75294 0.75294 1" mesh="r_ankle_roll_link"/>
                  <geom name="right_foot" class="foot" size="0.0787661 0.0338013 0.00470385" pos="-0.0532166 0 -0.0443408"/>
                  <geom name="//unnamed_geom_19" class="reward_collision_sphere" size="0.0385534" pos="-0.0521731 0 -0.0201549"/>
                  <geom name="//unnamed_geom_20" class="reward_collision_sphere" size="0.0192767" pos="0.0156519 0.016806 -0.0403098"/>
                  <geom name="//unnamed_geom_21" class="reward_collision_sphere" size="0.0192767" pos="-0.125215 0.016806 -0.0403098"/>
                  <site name="right_foot" class="foot" pos="-0.0532166 0 -0.0443408" size="0.00963835"/>
                </body>
              </body>
            </body>
          </body>
        </body>
      </body>
      <body name="l_hip_pitch_link" pos="-0.000311079 0.0200383 -0.0327002" quat="0.992201 -7.95751e-06 -0.124652 1.29493e-05">
        <inertial pos="0.000917603 0.0444696 -0.000315372" quat="-0.037623 0.70356 0.0314571 0.708941" mass="0.349293" diaginertia="0.000160202 4.38089e-05 0.000105567"/>
        <joint name="l_hip_pitch_joint" class="/" pos="0 0 0" axis="-0.000260713 1 0.000674444" range="-1.23996 1.75079" armature="0.00965376" damping="0.00842167" frictionloss="0.0100552"/>
        <geom name="//unnamed_geom_22" class="/" type="mesh" density="0" rgba="0.75294 0.75294 0.75294 1" mesh="l_hip_pitch_link"/>
        <geom name="//unnamed_geom_23" class="/" size="0.000481918 0.000481918 0.000481918" type="box" rgba="0.75294 0.75294 0.75294 1"/>
        <body name="l_hip_roll_link" pos="0.000829127 0.0473964 -0.000503354" quat="1 -5.97639e-06 -9.99622e-05 4.70888e-05">
          <inertial pos="-0.00166095 0.000104124 -0.0619817" quat="0.699245 -0.0752383 -0.077992 0.706621" mass="0.352047" diaginertia="0.000414593 0.000116283 0.000135133"/>
          <joint name="l_hip_roll_joint" class="/" pos="0 0 0" axis="-0.999997 0.00204268 -0.00146319" range="-0.496603 0.105735" armature="0.00938983" damping="0.000841424" frictionloss="0.00998456"/>
          <geom name="//unnamed_geom_24" class="/" type="mesh" density="0" rgba="0.75294 0.75294 0.75294 1" mesh="l_hip_roll_link"/>
          <geom name="//unnamed_geom_25" class="/" size="0.000481918 0.000481918 0.000481918" type="box" rgba="0.75294 0.75294 0.75294 1"/>
          <geom name="//unnamed_geom_26" class="reward_collision_sphere" size="0.0385534"/>
          <body name="l_thigh_link" pos="-0.000160931 -0.000459787 -0.0695965" quat="1 4.41209e-05 0.000175412 9.10938e-05">
            <inertial pos="-8.307e-05 -0.00199762 -0.0480984" quat="0.673096 0.73955 -0.00272017 -0.000529033" mass="0.101802" diaginertia="0.000157511 3.97406e-05 6.09495e-05"/>
            <joint name="l_thigh_joint" class="/" pos="0 0 0" axis="-0.000194353 2.86939e-05 -1" range="-0.602473 0.315019" armature="0.00975978" damping="0.00300753" frictionloss="0.00969617"/>
            <geom name="//unnamed_geom_27" class="/" type="mesh" density="0" rgba="0.75294 0.75294 0.75294 1" mesh="l_thigh_link"/>
            <geom name="//unnamed_geom_28" class="/" size="0.000481918 0.000481918 0.000481918" type="box" rgba="0.75294 0.75294 0.75294 1"/>
            <body name="l_calf_link" pos="0.000274251 0.000117574 -0.0713259" quat="0.94765 4.86207e-05 0.31931 4.54454e-05">
              <inertial pos="0.00111883 0.0023187 -0.0710626" quat="0.99996 0.00379882 0.00020634 0.00815626" mass="0.718649" diaginertia="0.00433621 0.00145958 0.000180339"/>
              <joint name="l_calf_joint" class="/" pos="0 0 0" axis="-0.00401421 0.999989 -0.00245917" stiffness="0.00282197" range="-0.647275 1.65502" armature="0.00961778" damping="0.00678339" frictionloss="0.00967935"/>
              <geom name="//unnamed_geom_29" class="/" type="mesh" density="0" rgba="0.75294 0.75294 0.75294 1" mesh="l_calf_link"/>
              <geom name="//unnamed_geom_30" class="/" size="0.000481918 0.000481918 0.000481918" type="box" rgba="0.75294 0.75294 0.75294 1"/>
              <geom name="//unnamed_geom_31" class="reward_collision_sphere" size="0.0385534"/>
              <body name="l_ankle_pitch_link" pos="0.0010372 0.000623104 -0.14086" quat="0.980113 9.76148e-05 -0.198439 0.000212241">
                <inertial pos="0.00525216 -0.00139996 0.000245595" quat="-0.0022326 0.707154 0.0027659 0.707051" mass="0.160779" diaginertia="0.000388405 9.42437e-05 0.000125956"/>
                <joint name="l_ankle_pitch_joint" class="/" pos="0 0 0" axis="9.07665e-05 0.999999 0.00136927" stiffness="0.000400179" range="-0.489942 1.31932" armature="0.0100215" damping="0.00538996" frictionloss="0.0095625"/>
                <geom name="//unnamed_geom_32" class="/" type="mesh" density="0" rgba="0.75294 0.75294 0.75294 1" mesh="l_ankle_pitch_link"/>
                <geom name="//unnamed_geom_33" class="/" size="0.0375896 0.0385534 0.0240959" type="box" rgba="0.75294 0.75294 0.75294 1"/>
                <body name="l_ankle_roll_link" pos="0.0788752 3.94473e-05 -0.000326824" quat="1 9.44525e-07 6.04853e-06 1.04526e-05">
                  <inertial pos="-0.0262738 0.000309589 -0.0142412" quat="0.558616 0.428886 0.437396 0.559186" mass="0.462263" diaginertia="0.0014046 0.000431796 0.000296545"/>
                  <joint name="l_ankle_roll_joint" class="/" pos="0 0 0" axis="-1 0.000118513 -0.000138261" range="-0.16457 0.169768" armature="0.00926653" damping="0.00770928" frictionloss="0.00949"/>
                  <geom name="//unnamed_geom_34" class="/" type="mesh" density="0" rgba="0.75294 0.75294 0.75294 1" mesh="l_ankle_roll_link"/>
                  <geom name="//unnamed_geom_35" class="/" type="mesh" rgba="0.75294 0.75294 0.75294 1" mesh="l_ankle_roll_link"/>
                  <geom name="left_foot" class="foot" size="0.0847048 0.0358438 0.00476125" pos="-0.0532166 0 -0.0443408"/>
                  <geom name="//unnamed_geom_37" class="reward_collision_sphere" size="0.0385534" pos="-0.0521731 0 -0.0201549"/>
                  <geom name="//unnamed_geom_38" class="reward_collision_sphere" size="0.0192767" pos="0.0156519 -0.016806 -0.0403098"/>
                  <geom name="//unnamed_geom_39" class="reward_collision_sphere" size="0.0192767" pos="-0.125215 -0.016806 -0.0403098"/>
                  <site name="left_foot" class="foot" pos="-0.0532166 0 -0.0443408" size="0.00963835"/>
                </body>
              </body>
            </body>
          </body>
        </body>
      </body>
    </body>
  </worldbody>

  <contact>
    <pair class="/" geom1="floor" geom2="right_foot" name="//unnamed_contact_1"/>
    <pair class="/" geom1="floor" geom2="left_foot" name="//unnamed_contact_0"/>
  </contact>

  <actuator>
    <general name="r_hip_pitch_joint" class="/" joint="r_hip_pitch_joint" forcerange="-19.7354 19.7354" gainprm="19.0184" biasprm="0 -19.0184 -0.475704"/>
    <general name="r_hip_roll_joint" class="/" joint="r_hip_roll_joint" forcerange="-20.3313 20.3313" gainprm="19.0184" biasprm="0 -19.0184 -0.475704"/>
    <general name="r_thigh_joint" class="/" joint="r_thigh_joint" forcerange="-20.0459 20.0459" gainprm="19.0184" biasprm="0 -19.0184 -0.475704"/>
    <general name="r_calf_joint" class="/" joint="r_calf_joint" forcerange="-20.0674 20.0674" gainprm="19.0184" biasprm="0 -19.0184 -0.475704"/>
    <general name="r_ankle_pitch_joint" class="/" joint="r_ankle_pitch_joint" forcerange="-20.3292 20.3292" gainprm="19.0184" biasprm="0 -19.0184 -0.475704"/>
    <general name="r_ankle_roll_joint" class="/" joint="r_ankle_roll_joint" forcerange="-20.383 20.383" gainprm="19.0184" biasprm="0 -19.0184 -0.475704"/>
    <general name="l_hip_pitch_joint" class="/" joint="l_hip_pitch_joint" forcerange="-20.8658 20.8658" gainprm="19.0184" biasprm="0 -19.0184 -0.475704"/>
    <general name="l_hip_roll_joint" class="/" joint="l_hip_roll_joint" forcerange="-20.1859 20.1859" gainprm="19.0184" biasprm="0 -19.0184 -0.475704"/>
    <general name="l_thigh_joint" class="/" joint="l_thigh_joint" forcerange="-20.0546 20.0546" gainprm="19.0184" biasprm="0 -19.0184 -0.475704"/>
    <general name="l_calf_joint" class="/" joint="l_calf_joint" forcerange="-20.3856 20.3856" gainprm="19.0184" biasprm="0 -19.0184 -0.475704"/>
    <general name="l_ankle_pitch_joint" class="/" joint="l_ankle_pitch_joint" forcerange="-19.5724 19.5724" gainprm="19.0184" biasprm="0 -19.0184 -0.475704"/>
    <general name="l_ankle_roll_joint" class="/" joint="l_ankle_roll_joint" forcerange="-19.9023 19.9023" gainprm="19.0184" biasprm="0 -19.0184 -0.475704"/>
  </actuator>

  <sensor>
    <gyro site="imu" name="imu_angular_velocity"/>
    <velocimeter site="imu" name="imu_linear_velocity"/>
    <framelinvel objtype="site" objname="left_foot" name="left_foot_global_linear_velocity"/>
    <framelinvel objtype="site" objname="right_foot" name="right_foot_global_linear_velocity"/>
  </sensor>

  <keyframe>
    <key name="home" qpos="0 0 0.291 1 0 0 0 0.4 0 0 -0.8 0.4 0 -0.4 0 0 0.8 -0.4 0"/>
  </keyframe>
</mujoco>
