<mujoco model="pi_12dof_release_v1">
  <compiler angle="radian" assetdir="assets" balanceinertia="true" inertiafromgeom="false"/>

  <option timestep="0.005" density="1.2" viscosity="2e-05"/>

  <size nkey="1"/>

  <visual>
    <quality shadowsize="8192"/>
    <map shadowclip="0.5"/>
  </visual>

  <default>
    <default class="/">
      <joint armature="0.01" damping="0.01" frictionloss="0.01"/>
      <geom contype="0" conaffinity="0" group="1" solref="-1000 -80"/>
      <site size="0.01 0.005 0.005" group="5"/>
      <general forcelimited="true" biastype="affine" gainprm="20" biasprm="0 -20 -0.5"/>
      <default class="foot">
        <geom size="0.0845 0.036 0.005" type="box" condim="6" group="4" priority="1" friction="0.9 0.2 0.2" solimp="0.015 1 0.005"/>
      </default>
      <default class="reward_collision_sphere">
        <geom group="5" rgba="1 0 0 1"/>
      </default>
    </default>
  </default>

  <asset>
    <texture type="skybox" colorspace="auto" name="//unnamed_texture_0" builtin="gradient" rgb1="0.95 0.95 0.95" rgb2="0.95 0.95 0.95" width="100" height="600"/>
    <texture type="2d" colorspace="auto" name="texplane" builtin="checker" rgb1="0.345 0.575 0.748" rgb2="0.345 0.575 0.748" markrgb="1 1 1" width="512" height="512"/>
    <material name="MatPlane" class="/" texture="texplane" texuniform="true" texrepeat="2 2" specular="0.9"/>
    <mesh name="baselink_1" class="/" file="baselink_1.STL"/>
    <mesh name="r_hip_pitch_link" class="/" file="r_hip_pitch_link.STL"/>
    <mesh name="r_hip_roll_link" class="/" file="r_hip_roll_link.STL"/>
    <mesh name="r_thigh_link" class="/" file="r_thigh_link.STL"/>
    <mesh name="r_calf_link" class="/" file="r_calf_link.STL"/>
    <mesh name="r_ankle_pitch_link" class="/" file="r_ankle_pitch_link.STL"/>
    <mesh name="r_ankle_roll_link" class="/" file="r_ankle_roll_link.STL"/>
    <mesh name="l_hip_pitch_link" class="/" file="l_hip_pitch_link.STL"/>
    <mesh name="l_hip_roll_link" class="/" file="l_hip_roll_link.STL"/>
    <mesh name="l_thigh_link" class="/" file="l_thigh_link.STL"/>
    <mesh name="l_calf_link" class="/" file="l_calf_link.STL"/>
    <mesh name="l_ankle_pitch_link" class="/" file="l_ankle_pitch_link.STL"/>
    <mesh name="l_ankle_roll_link" class="/" file="l_ankle_roll_link.STL"/>
  </asset>

  <worldbody>
    <geom name="floor" class="/" size="100 100 0.125" type="plane" group="0" material="MatPlane"/>
    <light name="toplight_shadow" class="/" pos="0 0 5" dir="0.0990148 0.0990148 -0.990148" type="directional" ambient="0.04 0.04 0.04" diffuse="0.55 0.55 0.55" specular="0.12 0.12 0.12"/>
    <light name="toplight_fill" class="/" pos="0 0 5" dir="0.0990148 0.0990148 -0.990148" type="directional" castshadow="false" ambient="0.04 0.04 0.04" diffuse="0.3 0.3 0.3" specular="0.08 0.08 0.08"/>
    <body name="trunk" pos="-3.85234e-06 -0.000228128 0.000962568" quat="1 7.14486e-06 -0.00073869 -0.000496119">
      <inertial pos="0.000856003 -0.00266888 0.0509146" quat="0.694682 0.00814365 0.00865392 0.719219" mass="2.24604" diaginertia="0.00945478 0.00185 0.0149792"/>
      <joint name="//unnamed_joint_0" type="free"/>
      <geom name="//unnamed_geom_1" class="/" type="mesh" density="0" rgba="1 1 1 1" mesh="baselink_1"/>
      <geom name="//unnamed_geom_2" class="/" size="0.050368 0.050368 0.050368" pos="0 0 0.103728" type="box" rgba="1 1 1 1"/>
      <geom name="//unnamed_geom_3" class="reward_collision_sphere" size="0.0554048" pos="0 0 0.0907617"/>
      <site name="imu" class="/" pos="0.0115572 -0.000910352 -0.0116468" size="0.0100736"/>
      <camera name="track" class="/" pos="0 -1.46146 0" quat="0.707107 0.707107 0 0" mode="trackcom"/>
      <camera name="ego_camera" class="/" pos="0.0746066 0 0.233387" quat="-0.5 -0.5 0.5 0.5"/>
      <body name="r_hip_pitch_link" pos="-0.0023202 -0.0195134 -0.0444256" quat="0.992197 -8.04384e-06 -0.124683 1.73656e-05">
        <inertial pos="0.000718601 -0.0440352 -0.000356156" quat="-0.0191682 0.706311 -0.0275666 0.707105" mass="0.381331" diaginertia="0.000104428 1.93506e-05 0.000297507"/>
        <joint name="r_hip_pitch_joint" class="/" pos="0 0 0" axis="-0.00425412 -0.99999 0.00122008" stiffness="0.0118593" range="-1.77345 1.20842" armature="0.00878517" damping="0.0135295" frictionloss="0.00927372"/>
        <geom name="//unnamed_geom_4" class="/" type="mesh" density="0" rgba="0.75294 0.75294 0.75294 1" mesh="r_hip_pitch_link"/>
        <geom name="//unnamed_geom_5" class="/" size="0.00050368 0.00050368 0.00050368" type="box" rgba="0.75294 0.75294 0.75294 1"/>
        <body name="r_hip_roll_link" pos="-0.00221991 -0.0391692 0.0025245" quat="0.999999 -0.00115176 -4.70166e-05 -0.000592561">
          <inertial pos="-0.00304698 -0.000490911 -0.0774422" quat="0.712456 -0.0800445 -0.0921427 0.69102" mass="0.387716" diaginertia="0.000330095 5.72966e-05 0.000479069"/>
          <joint name="r_hip_roll_joint" class="/" pos="0 0 0" axis="-0.999898 -0.00145878 -0.0142386" stiffness="0.000239102" range="-0.14273 0.500531" armature="0.00870102" damping="0.00255752" frictionloss="0.0111608"/>
          <geom name="//unnamed_geom_6" class="/" type="mesh" density="0" rgba="0.75294 0.75294 0.75294 1" mesh="r_hip_roll_link"/>
          <geom name="//unnamed_geom_7" class="/" size="0.00050368 0.00050368 0.00050368" type="box" rgba="0.75294 0.75294 0.75294 1"/>
          <geom name="//unnamed_geom_8" class="reward_collision_sphere" size="0.0402944"/>
          <body name="r_thigh_link" pos="0.00246698 0.00260886 -0.0909663" quat="1 4.7526e-05 3.34431e-06 1.20323e-06">
            <inertial pos="0.0002488 0.000333375 -0.0637279" quat="0.738426 0.674333 0.001131 -0.000625097" mass="0.116968" diaginertia="0.000118747 1.9674e-05 0.000213023"/>
            <joint name="r_thigh_joint" class="/" pos="0 0 0" axis="-0.00371049 -0.0034954 -0.999987" stiffness="0.00610296" range="-0.35789 0.607371" armature="0.0113133" damping="0" frictionloss="0.0111468"/>
            <geom name="//unnamed_geom_9" class="/" type="mesh" density="0" rgba="0.75294 0.75294 0.75294 1" mesh="r_thigh_link"/>
            <geom name="//unnamed_geom_10" class="/" size="0.00050368 0.00050368 0.00050368" type="box" rgba="0.75294 0.75294 0.75294 1"/>
            <body name="r_calf_link" pos="-0.00149361 -0.000976355 -0.091757" quat="0.947653 -8.65393e-06 0.319303 7.67096e-05">
              <inertial pos="-0.00315687 -0.00233366 -0.0932946" quat="0.999964 -0.00537084 -0.00645307 -0.00152648" mass="0.831038" diaginertia="0.0032725 0.000742276 0.000610114"/>
              <joint name="r_calf_joint" class="/" pos="0 0 0" axis="0.0111831 -0.999912 0.00715898" range="-1.65383 0.678279" armature="0.00896188" damping="0.00765181" frictionloss="0.00964509"/>
              <geom name="//unnamed_geom_11" class="/" type="mesh" density="0" rgba="0.75294 0.75294 0.75294 1" mesh="r_calf_link"/>
              <geom name="//unnamed_geom_12" class="/" size="0.00050368 0.00050368 0.00050368" type="box" rgba="0.75294 0.75294 0.75294 1"/>
              <geom name="//unnamed_geom_13" class="reward_collision_sphere" size="0.0402944"/>
              <body name="r_ankle_pitch_link" pos="0.00253551 -0.00138325 -0.183772" quat="0.980012 -0.00136618 -0.198934 -1.91746e-05">
                <inertial pos="0.00718071 0.00250158 -0.0026909" quat="-0.00885281 0.702803 -0.00134023 0.711329" mass="0.187816" diaginertia="0.000292272 4.50201e-05 0.000455602"/>
                <joint name="r_ankle_pitch_joint" class="/" pos="0 0 0" axis="0.00666552 -0.99992 -0.0107596" range="-1.24573 0.555692" armature="0.0113979" damping="0" frictionloss="0.0105793"/>
                <geom name="//unnamed_geom_14" class="/" type="mesh" density="0" rgba="0.75294 0.75294 0.75294 1" mesh="r_ankle_pitch_link"/>
                <geom name="//unnamed_geom_15" class="/" size="0.039287 0.0402944 0.025184" type="box" rgba="0.75294 0.75294 0.75294 1"/>
                <body name="r_ankle_roll_link" pos="0.0729147 -2.6365e-05 0.000731514" quat="0.999999 1.80877e-05 0.00116853 0.000308246">
                  <inertial pos="-0.0265835 7.02769e-05 -0.0193871" quat="0.567662 0.426145 0.430878 0.557229" mass="0.566113" diaginertia="0.00116278 0.000217314 0.00107795"/>
                  <joint name="r_ankle_roll_joint" class="/" pos="0 0 0" axis="-0.999916 0.0124448 -0.00349104" stiffness="0.00263615" range="-0.097241 0.157807" armature="0.0111497" damping="0.0139451" frictionloss="0.0101089"/>
                  <geom name="//unnamed_geom_16" class="/" type="mesh" density="0" rgba="0.75294 0.75294 0.75294 1" mesh="r_ankle_roll_link"/>
                  <geom name="//unnamed_geom_17" class="/" type="mesh" rgba="0.75294 0.75294 0.75294 1" mesh="r_ankle_roll_link"/>
                  <geom name="right_foot" class="foot" size="0.0828271 0.0358298 0.00525313" pos="-0.0507325 0 -0.0570502"/>
                  <geom name="//unnamed_geom_19" class="reward_collision_sphere" size="0.0402944" pos="-0.0497377 0 -0.0259319"/>
                  <geom name="//unnamed_geom_20" class="reward_collision_sphere" size="0.0201472" pos="0.0149213 0.0146146 -0.0518638"/>
                  <geom name="//unnamed_geom_21" class="reward_collision_sphere" size="0.0201472" pos="-0.119371 0.0146146 -0.0518638"/>
                  <site name="right_foot" class="foot" pos="-0.0507325 0 -0.0570502" size="0.0100736"/>
                </body>
              </body>
            </body>
          </body>
        </body>
      </body>
      <body name="l_hip_pitch_link" pos="0.00181549 0.0144185 -0.0451408" quat="0.992197 -9.45659e-05 -0.124683 -4.45104e-05">
        <inertial pos="0.000981532 0.0418791 -0.00228068" quat="-0.0428829 0.711037 0.0400359 0.700703" mass="0.408501" diaginertia="0.000130573 2.26083e-05 0.000368174"/>
        <joint name="l_hip_pitch_joint" class="/" pos="0 0 0" axis="-0.000512751 1 -4.39841e-05" range="-1.26444 1.75901" armature="0.00999408" damping="0.0246134" frictionloss="0.00868991"/>
        <geom name="//unnamed_geom_22" class="/" type="mesh" density="0" rgba="0.75294 0.75294 0.75294 1" mesh="l_hip_pitch_link"/>
        <geom name="//unnamed_geom_23" class="/" size="0.00050368 0.00050368 0.00050368" type="box" rgba="0.75294 0.75294 0.75294 1"/>
        <body name="l_hip_roll_link" pos="-0.00250686 0.0392926 0.00221166" quat="1 0.000242128 0.000346689 0.000394356">
          <inertial pos="-0.0035417 0.000850012 -0.0808547" quat="0.700912 -0.0749659 -0.0791793 0.704864" mass="0.376187" diaginertia="0.000306325 5.77619e-05 0.000461102"/>
          <joint name="l_hip_roll_joint" class="/" pos="0 0 0" axis="-0.999991 0.00123573 -0.00398657" range="-0.482208 0.124883" armature="0.0100463" damping="0.0198993" frictionloss="0.00884571"/>
          <geom name="//unnamed_geom_24" class="/" type="mesh" density="0" rgba="0.75294 0.75294 0.75294 1" mesh="l_hip_roll_link"/>
          <geom name="//unnamed_geom_25" class="/" size="0.00050368 0.00050368 0.00050368" type="box" rgba="0.75294 0.75294 0.75294 1"/>
          <geom name="//unnamed_geom_26" class="reward_collision_sphere" size="0.0402944"/>
          <body name="l_thigh_link" pos="-0.00226072 0.000835177 -0.0909523" quat="1 -0.000182726 0.00024277 4.58739e-05">
            <inertial pos="0.00238703 0.00132756 -0.0626354" quat="0.668577 0.743581 0.00847505 -0.00444006" mass="0.11757" diaginertia="0.000119611 2.07365e-05 0.000217463"/>
            <joint name="l_thigh_joint" class="/" pos="0 0 0" axis="0.000228332 -0.00155388 -0.999999" range="-0.644039 0.245314" armature="0.0104522" damping="0.00942316" frictionloss="0.0103341"/>
            <geom name="//unnamed_geom_27" class="/" type="mesh" density="0" rgba="0.75294 0.75294 0.75294 1" mesh="l_thigh_link"/>
            <geom name="//unnamed_geom_28" class="/" size="0.00050368 0.00050368 0.00050368" type="box" rgba="0.75294 0.75294 0.75294 1"/>
            <body name="l_calf_link" pos="0.000672701 -0.00126376 -0.0894105" quat="0.947876 -7.17656e-05 0.31864 -0.00027329">
              <inertial pos="-0.00221025 0.00407644 -0.0924644" quat="0.999965 0.00535332 -0.00588677 0.00241777" mass="0.842582" diaginertia="0.00334586 0.000718636 0.000628702"/>
              <joint name="l_calf_joint" class="/" pos="0 0 0" axis="-0.0137195 0.999901 -0.0032267" range="-0.657754 1.67432" armature="0.010369" damping="0" frictionloss="0.0106587"/>
              <geom name="//unnamed_geom_29" class="/" type="mesh" density="0" rgba="0.75294 0.75294 0.75294 1" mesh="l_calf_link"/>
              <geom name="//unnamed_geom_30" class="/" size="0.00050368 0.00050368 0.00050368" type="box" rgba="0.75294 0.75294 0.75294 1"/>
              <geom name="//unnamed_geom_31" class="reward_collision_sphere" size="0.0402944"/>
              <body name="l_ankle_pitch_link" pos="0.00177904 0.00219928 -0.184387" quat="0.979803 0.000239576 -0.199963 0.000176802">
                <inertial pos="0.00504204 0.00168784 -0.00064608" quat="-0.00337951 0.707389 0.00282041 0.706811" mass="0.16772" diaginertia="0.000279485 4.51804e-05 0.000430081"/>
                <joint name="l_ankle_pitch_joint" class="/" pos="0 0 0" axis="-0.000196596 1 0.000213135" range="-0.553623 1.24943" armature="0.00882342" damping="0.00667396" frictionloss="0.010865"/>
                <geom name="//unnamed_geom_32" class="/" type="mesh" density="0" rgba="0.75294 0.75294 0.75294 1" mesh="l_ankle_pitch_link"/>
                <geom name="//unnamed_geom_33" class="/" size="0.039287 0.0402944 0.025184" type="box" rgba="0.75294 0.75294 0.75294 1"/>
                <body name="l_ankle_roll_link" pos="0.0754132 0.00271353 -0.000546896" quat="0.999999 -0.000679837 0.000616095 -0.000513167">
                  <inertial pos="-0.0214656 -0.00273192 -0.0189762" quat="0.566156 0.418524 0.433401 0.562556" mass="0.534871" diaginertia="0.00107005 0.000214927 0.00100815"/>
                  <joint name="l_ankle_roll_joint" class="/" pos="0 0 0" axis="-1 0.000153635 -0.000973076" range="-0.0988155 0.0975806" armature="0.0116214" damping="0.0201433" frictionloss="0.010984"/>
                  <geom name="//unnamed_geom_34" class="/" type="mesh" density="0" rgba="0.75294 0.75294 0.75294 1" mesh="l_ankle_roll_link"/>
                  <geom name="//unnamed_geom_35" class="/" type="mesh" rgba="0.75294 0.75294 0.75294 1" mesh="l_ankle_roll_link"/>
                  <geom name="left_foot" class="foot" size="0.075301 0.0406807 0.00521231" pos="-0.0507325 0 -0.0570502"/>
                  <geom name="//unnamed_geom_37" class="reward_collision_sphere" size="0.0402944" pos="-0.0497377 0 -0.0259319"/>
                  <geom name="//unnamed_geom_38" class="reward_collision_sphere" size="0.0201472" pos="0.0149213 -0.0146146 -0.0518638"/>
                  <geom name="//unnamed_geom_39" class="reward_collision_sphere" size="0.0201472" pos="-0.119371 -0.0146146 -0.0518638"/>
                  <site name="left_foot" class="foot" pos="-0.0507325 0 -0.0570502" size="0.0100736"/>
                </body>
              </body>
            </body>
          </body>
        </body>
      </body>
    </body>
  </worldbody>

  <contact>
    <pair class="/" geom1="floor" geom2="right_foot" name="//unnamed_contact_1"/>
    <pair class="/" geom1="floor" geom2="left_foot" name="//unnamed_contact_0"/>
  </contact>

  <actuator>
    <general name="r_hip_pitch_joint" class="/" joint="r_hip_pitch_joint" forcerange="-23.4093 23.4093" gainprm="19.5107" biasprm="0 -19.5107 -0.486613"/>
    <general name="r_hip_roll_joint" class="/" joint="r_hip_roll_joint" forcerange="-21.0078 21.0078" gainprm="19.5107" biasprm="0 -19.5107 -0.486613"/>
    <general name="r_thigh_joint" class="/" joint="r_thigh_joint" forcerange="-20.494 20.494" gainprm="19.5107" biasprm="0 -19.5107 -0.486613"/>
    <general name="r_calf_joint" class="/" joint="r_calf_joint" forcerange="-23.0438 23.0438" gainprm="19.5107" biasprm="0 -19.5107 -0.486613"/>
    <general name="r_ankle_pitch_joint" class="/" joint="r_ankle_pitch_joint" forcerange="-20.4656 20.4656" gainprm="19.5107" biasprm="0 -19.5107 -0.486613"/>
    <general name="r_ankle_roll_joint" class="/" joint="r_ankle_roll_joint" forcerange="-22.0025 22.0025" gainprm="19.5107" biasprm="0 -19.5107 -0.486613"/>
    <general name="l_hip_pitch_joint" class="/" joint="l_hip_pitch_joint" forcerange="-18.9333 18.9333" gainprm="19.5107" biasprm="0 -19.5107 -0.486613"/>
    <general name="l_hip_roll_joint" class="/" joint="l_hip_roll_joint" forcerange="-19.4971 19.4971" gainprm="19.5107" biasprm="0 -19.5107 -0.486613"/>
    <general name="l_thigh_joint" class="/" joint="l_thigh_joint" forcerange="-20.4763 20.4763" gainprm="19.5107" biasprm="0 -19.5107 -0.486613"/>
    <general name="l_calf_joint" class="/" joint="l_calf_joint" forcerange="-21.3704 21.3704" gainprm="19.5107" biasprm="0 -19.5107 -0.486613"/>
    <general name="l_ankle_pitch_joint" class="/" joint="l_ankle_pitch_joint" forcerange="-23.3574 23.3574" gainprm="19.5107" biasprm="0 -19.5107 -0.486613"/>
    <general name="l_ankle_roll_joint" class="/" joint="l_ankle_roll_joint" forcerange="-21.6185 21.6185" gainprm="19.5107" biasprm="0 -19.5107 -0.486613"/>
  </actuator>

  <sensor>
    <gyro site="imu" name="imu_angular_velocity"/>
    <velocimeter site="imu" name="imu_linear_velocity"/>
    <framelinvel objtype="site" objname="left_foot" name="left_foot_global_linear_velocity"/>
    <framelinvel objtype="site" objname="right_foot" name="right_foot_global_linear_velocity"/>
  </sensor>

  <keyframe>
    <key name="home" qpos="0 0 0.291 1 0 0 0 0.4 0 0 -0.8 0.4 0 -0.4 0 0 0.8 -0.4 0"/>
  </keyframe>
</mujoco>
