<mujoco model="pi_12dof_release_v1">
  <compiler angle="radian" assetdir="assets" balanceinertia="true" inertiafromgeom="false"/>

  <option timestep="0.005" density="1.2" viscosity="2e-05"/>

  <size nkey="1"/>

  <visual>
    <quality shadowsize="8192"/>
    <map shadowclip="0.5"/>
  </visual>

  <default>
    <default class="/">
      <joint armature="0.01" damping="0.01" frictionloss="0.01"/>
      <geom contype="0" conaffinity="0" group="1" solref="-1000 -80"/>
      <site size="0.01 0.005 0.005" group="5"/>
      <general forcelimited="true" biastype="affine" gainprm="20" biasprm="0 -20 -0.5"/>
      <default class="foot">
        <geom size="0.0845 0.036 0.005" type="box" condim="6" group="4" priority="1" friction="0.9 0.2 0.2" solimp="0.015 1 0.005"/>
      </default>
      <default class="reward_collision_sphere">
        <geom group="5" rgba="1 0 0 1"/>
      </default>
    </default>
  </default>

  <asset>
    <texture type="skybox" colorspace="auto" name="//unnamed_texture_0" builtin="gradient" rgb1="0.95 0.95 0.95" rgb2="0.95 0.95 0.95" width="100" height="600"/>
    <texture type="2d" colorspace="auto" name="texplane" builtin="checker" rgb1="0.345 0.575 0.748" rgb2="0.345 0.575 0.748" markrgb="1 1 1" width="512" height="512"/>
    <material name="MatPlane" class="/" texture="texplane" texuniform="true" texrepeat="2 2" specular="0.9"/>
    <mesh name="baselink_1" class="/" file="baselink_1.STL"/>
    <mesh name="r_hip_pitch_link" class="/" file="r_hip_pitch_link.STL"/>
    <mesh name="r_hip_roll_link" class="/" file="r_hip_roll_link.STL"/>
    <mesh name="r_thigh_link" class="/" file="r_thigh_link.STL"/>
    <mesh name="r_calf_link" class="/" file="r_calf_link.STL"/>
    <mesh name="r_ankle_pitch_link" class="/" file="r_ankle_pitch_link.STL"/>
    <mesh name="r_ankle_roll_link" class="/" file="r_ankle_roll_link.STL"/>
    <mesh name="l_hip_pitch_link" class="/" file="l_hip_pitch_link.STL"/>
    <mesh name="l_hip_roll_link" class="/" file="l_hip_roll_link.STL"/>
    <mesh name="l_thigh_link" class="/" file="l_thigh_link.STL"/>
    <mesh name="l_calf_link" class="/" file="l_calf_link.STL"/>
    <mesh name="l_ankle_pitch_link" class="/" file="l_ankle_pitch_link.STL"/>
    <mesh name="l_ankle_roll_link" class="/" file="l_ankle_roll_link.STL"/>
  </asset>

  <worldbody>
    <geom name="floor" class="/" size="100 100 0.125" type="plane" group="0" material="MatPlane"/>
    <light name="toplight_shadow" class="/" pos="0 0 5" dir="0.0990148 0.0990148 -0.990148" type="directional" ambient="0.04 0.04 0.04" diffuse="0.55 0.55 0.55" specular="0.12 0.12 0.12"/>
    <light name="toplight_fill" class="/" pos="0 0 5" dir="0.0990148 0.0990148 -0.990148" type="directional" castshadow="false" ambient="0.04 0.04 0.04" diffuse="0.3 0.3 0.3" specular="0.08 0.08 0.08"/>
    <body name="trunk" pos="-0.00156966 0.000455543 0.00232991" quat="0.999999 -0.000983571 -0.000942204 7.64956e-05">
      <inertial pos="0.00319342 -0.0013248 0.0512969" quat="0.697999 0.013838 0.00840203 0.715915" mass="2.22401" diaginertia="0.0127908 0.00100868 0.0175451"/>
      <joint name="//unnamed_joint_0" type="free"/>
      <geom name="//unnamed_geom_1" class="/" type="mesh" density="0" rgba="1 1 1 1" mesh="baselink_1"/>
      <geom name="//unnamed_geom_2" class="/" size="0.0506066 0.0506066 0.0506066" pos="0 0 0.106728" type="box" rgba="1 1 1 1"/>
      <geom name="//unnamed_geom_3" class="reward_collision_sphere" size="0.0556673" pos="0 0 0.0933867"/>
      <site name="imu" class="/" pos="0.00345613 0.000760611 -0.00362628" size="0.0101213"/>
      <camera name="track" class="/" pos="0 -1.29199 0" quat="0.707107 0.707107 0 0" mode="trackcom"/>
      <camera name="ego_camera" class="/" pos="0.0792227 0 0.240137" quat="-0.5 -0.5 0.5 0.5"/>
      <body name="r_hip_pitch_link" pos="-0.00156439 -0.0167957 -0.0465581" quat="0.992195 0.000143525 -0.124694 2.69501e-05">
        <inertial pos="0.00120949 -0.0385266 -4.04552e-05" quat="-0.0193698 0.705853 -0.0283277 0.707527" mass="0.400337" diaginertia="0.000143312 1.08631e-05 0.000355071"/>
        <joint name="r_hip_pitch_joint" class="/" pos="0 0 0" axis="-0.00225517 -0.999974 0.00680369" stiffness="0.00694086" range="-1.76468 1.24438" armature="0.00942163" damping="0.0138553" frictionloss="0.00877638"/>
        <geom name="//unnamed_geom_4" class="/" type="mesh" density="0" rgba="0.75294 0.75294 0.75294 1" mesh="r_hip_pitch_link"/>
        <geom name="//unnamed_geom_5" class="/" size="0.000506066 0.000506066 0.000506066" type="box" rgba="0.75294 0.75294 0.75294 1"/>
        <body name="r_hip_roll_link" pos="-0.00254232 -0.0362604 0.00248242" quat="1 -8.97382e-05 -0.000297691 0.00045779">
          <inertial pos="-0.00254472 -0.000127881 -0.0790741" quat="0.707222 -0.0859147 -0.0749406 0.697739" mass="0.394262" diaginertia="0.000444147 3.16578e-05 0.000561717"/>
          <joint name="r_hip_roll_joint" class="/" pos="0 0 0" axis="-0.999928 -0.0086747 0.00825109" stiffness="0.000501071" range="-0.126031 0.492229" armature="0.00877527" damping="0.0102147" frictionloss="0.0103298"/>
          <geom name="//unnamed_geom_6" class="/" type="mesh" density="0" rgba="0.75294 0.75294 0.75294 1" mesh="r_hip_roll_link"/>
          <geom name="//unnamed_geom_7" class="/" size="0.000506066 0.000506066 0.000506066" type="box" rgba="0.75294 0.75294 0.75294 1"/>
          <geom name="//unnamed_geom_8" class="reward_collision_sphere" size="0.0404853"/>
          <body name="r_thigh_link" pos="0.000534857 0.00120416 -0.0933671" quat="1 0.000295582 0.000396702 0.000461465">
            <inertial pos="-0.000841952 0.00226845 -0.0662934" quat="0.736407 0.676534 0.00223537 -0.000700288" mass="0.11651" diaginertia="0.000159809 1.04951e-05 0.000246159"/>
            <joint name="r_thigh_joint" class="/" pos="0 0 0" axis="-0.00148584 -0.000329008 -0.999999" stiffness="0.00916831" range="-0.349372 0.570298" armature="0.0104324" damping="0" frictionloss="0.0115412"/>
            <geom name="//unnamed_geom_9" class="/" type="mesh" density="0" rgba="0.75294 0.75294 0.75294 1" mesh="r_thigh_link"/>
            <geom name="//unnamed_geom_10" class="/" size="0.000506066 0.000506066 0.000506066" type="box" rgba="0.75294 0.75294 0.75294 1"/>
            <body name="r_calf_link" pos="1.67982e-05 0.00151836 -0.0956782" quat="0.947648 -1.62565e-05 0.319317 -2.05689e-07">
              <inertial pos="-0.00310868 1.44359e-05 -0.0957667" quat="0.999985 -0.00300682 0.000395467 0.00453385" mass="0.856785" diaginertia="0.0045375 0.000399397 0.000720503"/>
              <joint name="r_calf_joint" class="/" pos="0 0 0" axis="0.0110008 -0.999936 0.0028131" stiffness="0.000111245" range="-1.64538 0.700463" armature="0.00857904" damping="0" frictionloss="0.00968711"/>
              <geom name="//unnamed_geom_11" class="/" type="mesh" density="0" rgba="0.75294 0.75294 0.75294 1" mesh="r_calf_link"/>
              <geom name="//unnamed_geom_12" class="/" size="0.000506066 0.000506066 0.000506066" type="box" rgba="0.75294 0.75294 0.75294 1"/>
              <geom name="//unnamed_geom_13" class="reward_collision_sphere" size="0.0404853"/>
              <body name="r_ankle_pitch_link" pos="0.00275302 -0.00200589 -0.188166" quat="0.980186 0.000335604 -0.19808 0.000452676">
                <inertial pos="0.00578784 0.000812508 -0.00300865" quat="-0.00182453 0.697685 -0.00241601 0.716399" mass="0.185374" diaginertia="0.000387571 2.42068e-05 0.000505925"/>
                <joint name="r_ankle_pitch_joint" class="/" pos="0 0 0" axis="-0.0044671 -0.999925 -0.0114068" range="-1.27207 0.552862" armature="0.0114852" damping="0.000719989" frictionloss="0.010448"/>
                <geom name="//unnamed_geom_14" class="/" type="mesh" density="0" rgba="0.75294 0.75294 0.75294 1" mesh="r_ankle_pitch_link"/>
                <geom name="//unnamed_geom_15" class="/" size="0.0394731 0.0404853 0.0253033" type="box" rgba="0.75294 0.75294 0.75294 1"/>
                <body name="r_ankle_roll_link" pos="0.0772201 0.000434633 1.3229e-05" quat="0.999999 -0.000469189 0.000728049 -0.00102263">
                  <inertial pos="-0.0273318 -0.000225381 -0.0194647" quat="0.560135 0.43057 0.43409 0.558949" mass="0.570606" diaginertia="0.00157624 0.00011489 0.00123388"/>
                  <joint name="r_ankle_roll_joint" class="/" pos="0 0 0" axis="-0.999888 0.0148543 0.00155901" range="-0.0996174 0.133725" armature="0.010321" damping="0.0100576" frictionloss="0.0109483"/>
                  <geom name="//unnamed_geom_16" class="/" type="mesh" density="0" rgba="0.75294 0.75294 0.75294 1" mesh="r_ankle_roll_link"/>
                  <geom name="//unnamed_geom_17" class="/" type="mesh" rgba="0.75294 0.75294 0.75294 1" mesh="r_ankle_roll_link"/>
                  <geom name="right_foot" class="foot" size="0.0849582 0.0341383 0.00551654" pos="-0.0538715 0 -0.0587002"/>
                  <geom name="//unnamed_geom_19" class="reward_collision_sphere" size="0.0404853" pos="-0.0528152 0 -0.0266819"/>
                  <geom name="//unnamed_geom_20" class="reward_collision_sphere" size="0.0202426" pos="0.0158445 0.0129199 -0.0533638"/>
                  <geom name="//unnamed_geom_21" class="reward_collision_sphere" size="0.0202426" pos="-0.126756 0.0129199 -0.0533638"/>
                  <site name="right_foot" class="foot" pos="-0.0538715 0 -0.0587002" size="0.0101213"/>
                </body>
              </body>
            </body>
          </body>
        </body>
      </body>
      <body name="l_hip_pitch_link" pos="0.0005001 0.0127286 -0.0446482" quat="0.992199 -4.53172e-05 -0.124667 1.40923e-05">
        <inertial pos="0.00037131 0.0372092 -0.000454962" quat="-0.0310313 0.701612 0.028065 0.71133" mass="0.406895" diaginertia="0.000167883 1.1723e-05 0.00041294"/>
        <joint name="l_hip_pitch_joint" class="/" pos="0 0 0" axis="0.00265398 0.999983 -0.0052361" range="-1.23438 1.74765" armature="0.00960323" damping="0.0253483" frictionloss="0.00881655"/>
        <geom name="//unnamed_geom_22" class="/" type="mesh" density="0" rgba="0.75294 0.75294 0.75294 1" mesh="l_hip_pitch_link"/>
        <geom name="//unnamed_geom_23" class="/" size="0.000506066 0.000506066 0.000506066" type="box" rgba="0.75294 0.75294 0.75294 1"/>
        <body name="l_hip_roll_link" pos="-0.000172204 0.0335436 0.00313789" quat="0.999999 0.000103636 0.000425036 0.00120015">
          <inertial pos="-0.00155541 0.00225998 -0.081328" quat="0.699193 -0.0755412 -0.0776518 0.706678" mass="0.377769" diaginertia="0.000426113 3.1204e-05 0.000542624"/>
          <joint name="l_hip_roll_joint" class="/" pos="0 0 0" axis="-0.999921 0.00982098 0.00781057" range="-0.455144 0.0911966" armature="0.00925896" damping="0.0169993" frictionloss="0.00870617"/>
          <geom name="//unnamed_geom_24" class="/" type="mesh" density="0" rgba="0.75294 0.75294 0.75294 1" mesh="l_hip_roll_link"/>
          <geom name="//unnamed_geom_25" class="/" size="0.000506066 0.000506066 0.000506066" type="box" rgba="0.75294 0.75294 0.75294 1"/>
          <geom name="//unnamed_geom_26" class="reward_collision_sphere" size="0.0404853"/>
          <body name="l_thigh_link" pos="-0.00220076 0.00205241 -0.0939671" quat="1 0.000275557 -7.66671e-05 -0.000405059">
            <inertial pos="0.0029987 0.000272965 -0.0658817" quat="0.668695 0.743469 -0.00987887 0.00176537" mass="0.115812" diaginertia="0.000157593 1.07354e-05 0.000248613"/>
            <joint name="l_thigh_joint" class="/" pos="0 0 0" axis="0.00050947 -0.00322909 -0.999995" range="-0.609773 0.24281" armature="0.0111675" damping="0.00678089" frictionloss="0.00995148"/>
            <geom name="//unnamed_geom_27" class="/" type="mesh" density="0" rgba="0.75294 0.75294 0.75294 1" mesh="l_thigh_link"/>
            <geom name="//unnamed_geom_28" class="/" size="0.000506066 0.000506066 0.000506066" type="box" rgba="0.75294 0.75294 0.75294 1"/>
            <body name="l_calf_link" pos="-0.00120673 -0.000688787 -0.0908593" quat="0.947731 -0.000197726 0.31907 0.000139431">
              <inertial pos="-0.0025203 0.00442927 -0.0932473" quat="0.99996 0.00705825 -0.00227902 0.00492748" mass="0.866245" diaginertia="0.00467477 0.000394095 0.000740268"/>
              <joint name="l_calf_joint" class="/" pos="0 0 0" axis="-0.0038104 0.999954 -0.00878826" stiffness="0.00658338" range="-0.653387 1.70107" armature="0.010217" damping="0" frictionloss="0.0113616"/>
              <geom name="//unnamed_geom_29" class="/" type="mesh" density="0" rgba="0.75294 0.75294 0.75294 1" mesh="l_calf_link"/>
              <geom name="//unnamed_geom_30" class="/" size="0.000506066 0.000506066 0.000506066" type="box" rgba="0.75294 0.75294 0.75294 1"/>
              <geom name="//unnamed_geom_31" class="reward_collision_sphere" size="0.0404853"/>
              <body name="l_ankle_pitch_link" pos="-0.000350505 0.00360266 -0.187803" quat="0.980081 0.000488309 -0.198594 0.00064004">
                <inertial pos="0.00435533 0.00213886 0.00081713" quat="-0.00329365 0.706831 0.00394458 0.707364" mass="0.171384" diaginertia="0.000380339 2.43557e-05 0.00049037"/>
                <joint name="l_ankle_pitch_joint" class="/" pos="0 0 0" axis="-0.00293047 0.999991 0.00307942" stiffness="0.00155224" range="-0.564325 1.25051" armature="0.00890128" damping="0.00960124" frictionloss="0.0114618"/>
                <geom name="//unnamed_geom_32" class="/" type="mesh" density="0" rgba="0.75294 0.75294 0.75294 1" mesh="l_ankle_pitch_link"/>
                <geom name="//unnamed_geom_33" class="/" size="0.0394731 0.0404853 0.0253033" type="box" rgba="0.75294 0.75294 0.75294 1"/>
                <body name="l_ankle_roll_link" pos="0.0816462 0.00191656 -0.000456725" quat="1 -0.000127336 -0.000186745 -7.74223e-05">
                  <inertial pos="-0.0237628 -0.00340495 -0.0180687" quat="0.56832 0.430216 0.430638 0.553604" mass="0.53396" diaginertia="0.00144877 0.000115897 0.00116147"/>
                  <joint name="l_ankle_roll_joint" class="/" pos="0 0 0" axis="-0.999994 -0.00273936 -0.00212823" range="-0.122396 0.102809" armature="0.011201" damping="0.0111262" frictionloss="0.0115073"/>
                  <geom name="//unnamed_geom_34" class="/" type="mesh" density="0" rgba="0.75294 0.75294 0.75294 1" mesh="l_ankle_roll_link"/>
                  <geom name="//unnamed_geom_35" class="/" type="mesh" rgba="0.75294 0.75294 0.75294 1" mesh="l_ankle_roll_link"/>
                  <geom name="left_foot" class="foot" size="0.0774574 0.0405422 0.00545484" pos="-0.0538715 0 -0.0587002"/>
                  <geom name="//unnamed_geom_37" class="reward_collision_sphere" size="0.0404853" pos="-0.0528152 0 -0.0266819"/>
                  <geom name="//unnamed_geom_38" class="reward_collision_sphere" size="0.0202426" pos="0.0158445 -0.0129199 -0.0533638"/>
                  <geom name="//unnamed_geom_39" class="reward_collision_sphere" size="0.0202426" pos="-0.126756 -0.0129199 -0.0533638"/>
                  <site name="left_foot" class="foot" pos="-0.0538715 0 -0.0587002" size="0.0101213"/>
                </body>
              </body>
            </body>
          </body>
        </body>
      </body>
    </body>
  </worldbody>

  <contact>
    <pair class="/" geom1="floor" geom2="right_foot" name="//unnamed_contact_1"/>
    <pair class="/" geom1="floor" geom2="left_foot" name="//unnamed_contact_0"/>
  </contact>

  <actuator>
    <general name="r_hip_pitch_joint" class="/" joint="r_hip_pitch_joint" forcerange="-22.8234 22.8234" gainprm="20.6997" biasprm="0 -20.6997 -0.477646"/>
    <general name="r_hip_roll_joint" class="/" joint="r_hip_roll_joint" forcerange="-21.6263 21.6263" gainprm="20.6997" biasprm="0 -20.6997 -0.477646"/>
    <general name="r_thigh_joint" class="/" joint="r_thigh_joint" forcerange="-20.5712 20.5712" gainprm="20.6997" biasprm="0 -20.6997 -0.477646"/>
    <general name="r_calf_joint" class="/" joint="r_calf_joint" forcerange="-21.9253 21.9253" gainprm="20.6997" biasprm="0 -20.6997 -0.477646"/>
    <general name="r_ankle_pitch_joint" class="/" joint="r_ankle_pitch_joint" forcerange="-21.5322 21.5322" gainprm="20.6997" biasprm="0 -20.6997 -0.477646"/>
    <general name="r_ankle_roll_joint" class="/" joint="r_ankle_roll_joint" forcerange="-21.6075 21.6075" gainprm="20.6997" biasprm="0 -20.6997 -0.477646"/>
    <general name="l_hip_pitch_joint" class="/" joint="l_hip_pitch_joint" forcerange="-19.6061 19.6061" gainprm="20.6997" biasprm="0 -20.6997 -0.477646"/>
    <general name="l_hip_roll_joint" class="/" joint="l_hip_roll_joint" forcerange="-21.0038 21.0038" gainprm="20.6997" biasprm="0 -20.6997 -0.477646"/>
    <general name="l_thigh_joint" class="/" joint="l_thigh_joint" forcerange="-19.4388 19.4388" gainprm="20.6997" biasprm="0 -20.6997 -0.477646"/>
    <general name="l_calf_joint" class="/" joint="l_calf_joint" forcerange="-20.6678 20.6678" gainprm="20.6997" biasprm="0 -20.6997 -0.477646"/>
    <general name="l_ankle_pitch_joint" class="/" joint="l_ankle_pitch_joint" forcerange="-23.1789 23.1789" gainprm="20.6997" biasprm="0 -20.6997 -0.477646"/>
    <general name="l_ankle_roll_joint" class="/" joint="l_ankle_roll_joint" forcerange="-20.4993 20.4993" gainprm="20.6997" biasprm="0 -20.6997 -0.477646"/>
  </actuator>

  <sensor>
    <gyro site="imu" name="imu_angular_velocity"/>
    <velocimeter site="imu" name="imu_linear_velocity"/>
    <framelinvel objtype="site" objname="left_foot" name="left_foot_global_linear_velocity"/>
    <framelinvel objtype="site" objname="right_foot" name="right_foot_global_linear_velocity"/>
  </sensor>

  <keyframe>
    <key name="home" qpos="0 0 0.291 1 0 0 0 0.4 0 0 -0.8 0.4 0 -0.4 0 0 0.8 -0.4 0"/>
  </keyframe>
</mujoco>
