<mujoco model="pi_12dof_release_v1">
  <compiler angle="radian" assetdir="assets" balanceinertia="true" inertiafromgeom="false"/>

  <option timestep="0.005" density="1.2" viscosity="2e-05"/>

  <size nkey="1"/>

  <visual>
    <quality shadowsize="8192"/>
    <map shadowclip="0.5"/>
  </visual>

  <default>
    <default class="/">
      <joint armature="0.01" damping="0.01" frictionloss="0.01"/>
      <geom contype="0" conaffinity="0" group="1" solref="-1000 -80"/>
      <site size="0.01 0.005 0.005" group="5"/>
      <general forcelimited="true" biastype="affine" gainprm="20" biasprm="0 -20 -0.5"/>
      <default class="foot">
        <geom size="0.0845 0.036 0.005" type="box" condim="6" group="4" priority="1" friction="0.9 0.2 0.2" solimp="0.015 1 0.005"/>
      </default>
      <default class="reward_collision_sphere">
        <geom group="5" rgba="1 0 0 1"/>
      </default>
    </default>
  </default>

  <asset>
    <texture type="skybox" colorspace="auto" name="//unnamed_texture_0" builtin="gradient" rgb1="0.95 0.95 0.95" rgb2="0.95 0.95 0.95" width="100" height="600"/>
    <texture type="2d" colorspace="auto" name="texplane" builtin="checker" rgb1="0.345 0.575 0.748" rgb2="0.345 0.575 0.748" markrgb="1 1 1" width="512" height="512"/>
    <material name="MatPlane" class="/" texture="texplane" texuniform="true" texrepeat="2 2" specular="0.9"/>
    <mesh name="baselink_1" class="/" file="baselink_1.STL"/>
    <mesh name="r_hip_pitch_link" class="/" file="r_hip_pitch_link.STL"/>
    <mesh name="r_hip_roll_link" class="/" file="r_hip_roll_link.STL"/>
    <mesh name="r_thigh_link" class="/" file="r_thigh_link.STL"/>
    <mesh name="r_calf_link" class="/" file="r_calf_link.STL"/>
    <mesh name="r_ankle_pitch_link" class="/" file="r_ankle_pitch_link.STL"/>
    <mesh name="r_ankle_roll_link" class="/" file="r_ankle_roll_link.STL"/>
    <mesh name="l_hip_pitch_link" class="/" file="l_hip_pitch_link.STL"/>
    <mesh name="l_hip_roll_link" class="/" file="l_hip_roll_link.STL"/>
    <mesh name="l_thigh_link" class="/" file="l_thigh_link.STL"/>
    <mesh name="l_calf_link" class="/" file="l_calf_link.STL"/>
    <mesh name="l_ankle_pitch_link" class="/" file="l_ankle_pitch_link.STL"/>
    <mesh name="l_ankle_roll_link" class="/" file="l_ankle_roll_link.STL"/>
  </asset>

  <worldbody>
    <geom name="floor" class="/" size="100 100 0.125" type="plane" group="0" material="MatPlane"/>
    <light name="toplight_shadow" class="/" pos="0 0 5" dir="0.0990148 0.0990148 -0.990148" type="directional" ambient="0.04 0.04 0.04" diffuse="0.55 0.55 0.55" specular="0.12 0.12 0.12"/>
    <light name="toplight_fill" class="/" pos="0 0 5" dir="0.0990148 0.0990148 -0.990148" type="directional" castshadow="false" ambient="0.04 0.04 0.04" diffuse="0.3 0.3 0.3" specular="0.08 0.08 0.08"/>
    <body name="trunk" pos="0.0012604 0.000194821 0.00089873" quat="1 -0.000182125 0.000249431 -0.000193063">
      <inertial pos="0.00114986 -0.0013752 0.037202" quat="0.696151 0.00750078 0.00896113 0.7178" mass="1.44459" diaginertia="0.00825043 0.00208497 0.0028656"/>
      <joint name="//unnamed_joint_0" type="free"/>
      <geom name="//unnamed_geom_1" class="/" type="mesh" density="0" rgba="1 1 1 1" mesh="baselink_1"/>
      <geom name="//unnamed_geom_2" class="/" size="0.0441178 0.0441178 0.0441178" pos="0 0 0.0744747" type="box" rgba="1 1 1 1"/>
      <geom name="//unnamed_geom_3" class="reward_collision_sphere" size="0.0485296" pos="0 0 0.0651654"/>
      <site name="imu" class="/" pos="0.000385821 -0.00461787 0.00276295" size="0.00882357"/>
      <camera name="track" class="/" pos="0 -1.49542 0" quat="0.707107 0.707107 0 0" mode="trackcom"/>
      <camera name="ego_camera" class="/" pos="0.072632 0 0.167568" quat="-0.5 -0.5 0.5 0.5"/>
      <body name="r_hip_pitch_link" pos="0.00012328 -0.0170144 -0.0313482" quat="0.992231 -0.000434008 -0.124407 8.74828e-05">
        <inertial pos="0.00137766 -0.0418206 0.000159484" quat="-0.0191963 0.705582 -0.0283299 0.707802" mass="0.258237" diaginertia="9.43973e-05 2.27558e-05 5.80216e-05"/>
        <joint name="r_hip_pitch_joint" class="/" pos="0 0 0" axis="-0.000823356 -1 -0.000204261" stiffness="0.00348374" range="-1.72958 1.25883" armature="0.00885622" damping="0.0135743" frictionloss="0.00864932"/>
        <geom name="//unnamed_geom_4" class="/" type="mesh" density="0" rgba="0.75294 0.75294 0.75294 1" mesh="r_hip_pitch_link"/>
        <geom name="//unnamed_geom_5" class="/" size="0.000441178 0.000441178 0.000441178" type="box" rgba="0.75294 0.75294 0.75294 1"/>
        <body name="r_hip_roll_link" pos="-0.000842246 -0.0407256 -0.000306218" quat="1 -3.17633e-05 -1.49687e-05 1.64842e-05">
          <inertial pos="-0.00140492 0.000433736 -0.0581525" quat="0.705925 -0.0788555 -0.0826375 0.699015" mass="0.269276" diaginertia="0.000282934 6.52246e-05 9.18715e-05"/>
          <joint name="r_hip_roll_joint" class="/" pos="0 0 0" axis="-0.999998 0.000712448 -0.00161715" range="-0.12362 0.506604" armature="0.00914909" damping="0" frictionloss="0.00885614"/>
          <geom name="//unnamed_geom_6" class="/" type="mesh" density="0" rgba="0.75294 0.75294 0.75294 1" mesh="r_hip_roll_link"/>
          <geom name="//unnamed_geom_7" class="/" size="0.000441178 0.000441178 0.000441178" type="box" rgba="0.75294 0.75294 0.75294 1"/>
          <geom name="//unnamed_geom_8" class="reward_collision_sphere" size="0.0352943"/>
          <body name="r_thigh_link" pos="-1.89871e-05 0.000382111 -0.0637902" quat="1 -0.000313696 3.30125e-05 -0.000206147">
            <inertial pos="0.000509113 0.000472871 -0.0449128" quat="0.736529 0.676399 -0.00138556 0.00279872" mass="0.0774761" diaginertia="0.000109448 2.22909e-05 4.11199e-05"/>
            <joint name="r_thigh_joint" class="/" pos="0 0 0" axis="-3.49016e-06 -0.000150011 -1" range="-0.29865 0.576518" armature="0.00916662" damping="0.0045225" frictionloss="0.00825513"/>
            <geom name="//unnamed_geom_9" class="/" type="mesh" density="0" rgba="0.75294 0.75294 0.75294 1" mesh="r_thigh_link"/>
            <geom name="//unnamed_geom_10" class="/" size="0.000441178 0.000441178 0.000441178" type="box" rgba="0.75294 0.75294 0.75294 1"/>
            <body name="r_calf_link" pos="-2.49754e-05 -0.00186588 -0.0661374" quat="0.94762 1.86583e-05 0.319399 3.57703e-05">
              <inertial pos="-0.00119767 -0.000924035 -0.0653281" quat="0.999986 -0.00316794 0.000249128 0.00429477" mass="0.559344" diaginertia="0.00304646 0.000827082 0.00012457"/>
              <joint name="r_calf_joint" class="/" pos="0 0 0" axis="-0.00202303 -0.999996 -0.00207867" range="-1.62914 0.644112" armature="0.00865945" damping="0.010415" frictionloss="0.00869009"/>
              <geom name="//unnamed_geom_11" class="/" type="mesh" density="0" rgba="0.75294 0.75294 0.75294 1" mesh="r_calf_link"/>
              <geom name="//unnamed_geom_12" class="/" size="0.000441178 0.000441178 0.000441178" type="box" rgba="0.75294 0.75294 0.75294 1"/>
              <geom name="//unnamed_geom_13" class="reward_collision_sphere" size="0.0352943"/>
              <body name="r_ankle_pitch_link" pos="0.000202197 0.000117929 -0.130016" quat="0.98006 3.73232e-05 -0.1987 1.95597e-05">
                <inertial pos="0.0038035 0.00299738 -0.000421163" quat="-0.000747463 0.70681 -0.00423984 0.70739" mass="0.121008" diaginertia="0.000265002 5.26295e-05 8.48085e-05"/>
                <joint name="r_ankle_pitch_joint" class="/" pos="0 0 0" axis="-0.000470838 -0.999996 0.0026665" range="-1.31534 0.503329" armature="0.00873129" damping="0.00806444" frictionloss="0.00842595"/>
                <geom name="//unnamed_geom_14" class="/" type="mesh" density="0" rgba="0.75294 0.75294 0.75294 1" mesh="r_ankle_pitch_link"/>
                <geom name="//unnamed_geom_15" class="/" size="0.0344119 0.0352943 0.0220589" type="box" rgba="0.75294 0.75294 0.75294 1"/>
                <body name="r_ankle_roll_link" pos="0.0745261 0.00356802 0.000466545" quat="1 3.59014e-05 3.94969e-05 -3.90696e-05">
                  <inertial pos="-0.0233395 -5.92322e-05 -0.0133802" quat="0.561024 0.429595 0.432604 0.559959" mass="0.357315" diaginertia="0.000961496 0.000240617 0.000198995"/>
                  <joint name="r_ankle_roll_joint" class="/" pos="0 0 0" axis="-0.99998 0.00603948 -0.00211722" range="-0.165478 0.146149" armature="0.00904682" damping="0.00355895" frictionloss="0.00873539"/>
                  <geom name="//unnamed_geom_16" class="/" type="mesh" density="0" rgba="0.75294 0.75294 0.75294 1" mesh="r_ankle_roll_link"/>
                  <geom name="//unnamed_geom_17" class="/" type="mesh" rgba="0.75294 0.75294 0.75294 1" mesh="r_ankle_roll_link"/>
                  <geom name="right_foot" class="foot" size="0.0739253 0.0315826 0.00447246" pos="-0.0493897 0 -0.0409611"/>
                  <geom name="//unnamed_geom_19" class="reward_collision_sphere" size="0.0352943" pos="-0.0484213 0 -0.0186187"/>
                  <geom name="//unnamed_geom_20" class="reward_collision_sphere" size="0.0176471" pos="0.0145264 0.0149542 -0.0372374"/>
                  <geom name="//unnamed_geom_21" class="reward_collision_sphere" size="0.0176471" pos="-0.116211 0.0149542 -0.0372374"/>
                  <site name="right_foot" class="foot" pos="-0.0493897 0 -0.0409611" size="0.00882357"/>
                </body>
              </body>
            </body>
          </body>
        </body>
      </body>
      <body name="l_hip_pitch_link" pos="0.000113719 0.0173565 -0.0302589" quat="0.9922 -0.00013558 -0.124654 -8.21758e-05">
        <inertial pos="0.000266149 0.0409782 0.000365509" quat="-0.0436581 0.703053 0.0328726 0.709034" mass="0.271867" diaginertia="0.000109878 2.4728e-05 7.13082e-05"/>
        <joint name="l_hip_pitch_joint" class="/" pos="0 0 0" axis="-0.00262187 0.999991 0.00333655" range="-1.25807 1.74948" armature="0.00878467" damping="0.00684611" frictionloss="0.00876075"/>
        <geom name="//unnamed_geom_22" class="/" type="mesh" density="0" rgba="0.75294 0.75294 0.75294 1" mesh="l_hip_pitch_link"/>
        <geom name="//unnamed_geom_23" class="/" size="0.000441178 0.000441178 0.000441178" type="box" rgba="0.75294 0.75294 0.75294 1"/>
        <body name="l_hip_roll_link" pos="0.000121583 0.041551 0.000433906" quat="1 -6.32077e-05 0.000152257 7.7042e-05">
          <inertial pos="-0.00119 -0.000263484 -0.0565762" quat="0.698865 -0.0729307 -0.0784679 0.707185" mass="0.27025" diaginertia="0.000282885 6.53254e-05 8.91021e-05"/>
          <joint name="l_hip_roll_joint" class="/" pos="0 0 0" axis="-0.999999 -0.00094572 -0.00138338" range="-0.507167 0.112978" armature="0.00902759" damping="0.00556425" frictionloss="0.00902276"/>
          <geom name="//unnamed_geom_24" class="/" type="mesh" density="0" rgba="0.75294 0.75294 0.75294 1" mesh="l_hip_roll_link"/>
          <geom name="//unnamed_geom_25" class="/" size="0.000441178 0.000441178 0.000441178" type="box" rgba="0.75294 0.75294 0.75294 1"/>
          <geom name="//unnamed_geom_26" class="reward_collision_sphere" size="0.0352943"/>
          <body name="l_thigh_link" pos="0.000130628 -0.000774286 -0.0655852" quat="1 0.000207533 -6.36884e-05 -0.00012025">
            <inertial pos="0.000768364 -0.000382498 -0.0444293" quat="0.674739 0.738042 0.00456769 -0.000246176" mass="0.0770263" diaginertia="0.000107184 2.19415e-05 3.97232e-05"/>
            <joint name="l_thigh_joint" class="/" pos="0 0 0" axis="-0.00100329 0.00289377 -0.999995" range="-0.606142 0.285546" armature="0.00844731" damping="0" frictionloss="0.00841155"/>
            <geom name="//unnamed_geom_27" class="/" type="mesh" density="0" rgba="0.75294 0.75294 0.75294 1" mesh="l_thigh_link"/>
            <geom name="//unnamed_geom_28" class="/" size="0.000441178 0.000441178 0.000441178" type="box" rgba="0.75294 0.75294 0.75294 1"/>
            <body name="l_calf_link" pos="-0.000370692 0.00130693 -0.0658872" quat="0.947548 -0.000380923 0.319613 8.99921e-05">
              <inertial pos="0.00131296 0.00169897 -0.0665718" quat="0.999987 0.000709369 -0.00161814 0.00487025" mass="0.55751" diaginertia="0.00299152 0.000818922 0.000121848"/>
              <joint name="l_calf_joint" class="/" pos="0 0 0" axis="-0.0023185 0.999991 -0.00342399" stiffness="0.00367321" range="-0.658516 1.67024" armature="0.00879016" damping="0.00555795" frictionloss="0.00874734"/>
              <geom name="//unnamed_geom_29" class="/" type="mesh" density="0" rgba="0.75294 0.75294 0.75294 1" mesh="l_calf_link"/>
              <geom name="//unnamed_geom_30" class="/" size="0.000441178 0.000441178 0.000441178" type="box" rgba="0.75294 0.75294 0.75294 1"/>
              <geom name="//unnamed_geom_31" class="reward_collision_sphere" size="0.0352943"/>
              <body name="l_ankle_pitch_link" pos="0.000751826 0.000935286 -0.131594" quat="0.980066 -3.656e-07 -0.198674 6.75303e-06">
                <inertial pos="0.0042864 -0.000741905 -0.000117587" quat="-0.00187472 0.707255 0.00128226 0.706955" mass="0.120548" diaginertia="0.00026045 5.13775e-05 8.3653e-05"/>
                <joint name="l_ankle_pitch_joint" class="/" pos="0 0 0" axis="-0.0015716 0.999999 0.000414913" range="-0.502831 1.30695" armature="0.00882666" damping="0.00912954" frictionloss="0.00845375"/>
                <geom name="//unnamed_geom_32" class="/" type="mesh" density="0" rgba="0.75294 0.75294 0.75294 1" mesh="l_ankle_pitch_link"/>
                <geom name="//unnamed_geom_33" class="/" size="0.0344119 0.0352943 0.0220589" type="box" rgba="0.75294 0.75294 0.75294 1"/>
                <body name="l_ankle_roll_link" pos="0.0737307 3.98399e-05 -0.00096273" quat="1 1.25671e-05 -2.3818e-05 8.09893e-06">
                  <inertial pos="-0.0236604 -0.000514018 -0.0131969" quat="0.561416 0.426532 0.434624 0.560343" mass="0.357754" diaginertia="0.000958424 0.000241121 0.000198406"/>
                  <joint name="l_ankle_roll_joint" class="/" pos="0 0 0" axis="-0.999993 -0.00170489 0.00338444" range="-0.151454 0.134381" armature="0.00900539" damping="0.0055602" frictionloss="0.00913599"/>
                  <geom name="//unnamed_geom_34" class="/" type="mesh" density="0" rgba="0.75294 0.75294 0.75294 1" mesh="l_ankle_roll_link"/>
                  <geom name="//unnamed_geom_35" class="/" type="mesh" rgba="0.75294 0.75294 0.75294 1" mesh="l_ankle_roll_link"/>
                  <geom name="left_foot" class="foot" size="0.0780392 0.0342384 0.00430972" pos="-0.0493897 0 -0.0409611"/>
                  <geom name="//unnamed_geom_37" class="reward_collision_sphere" size="0.0352943" pos="-0.0484213 0 -0.0186187"/>
                  <geom name="//unnamed_geom_38" class="reward_collision_sphere" size="0.0176471" pos="0.0145264 -0.0149542 -0.0372374"/>
                  <geom name="//unnamed_geom_39" class="reward_collision_sphere" size="0.0176471" pos="-0.116211 -0.0149542 -0.0372374"/>
                  <site name="left_foot" class="foot" pos="-0.0493897 0 -0.0409611" size="0.00882357"/>
                </body>
              </body>
            </body>
          </body>
        </body>
      </body>
    </body>
  </worldbody>

  <contact>
    <pair class="/" geom1="floor" geom2="right_foot" name="//unnamed_contact_1"/>
    <pair class="/" geom1="floor" geom2="left_foot" name="//unnamed_contact_0"/>
  </contact>

  <actuator>
    <general name="r_hip_pitch_joint" class="/" joint="r_hip_pitch_joint" forcerange="-18.5616 18.5616" gainprm="17.5564" biasprm="0 -17.5564 -0.430491"/>
    <general name="r_hip_roll_joint" class="/" joint="r_hip_roll_joint" forcerange="-17.9522 17.9522" gainprm="17.5564" biasprm="0 -17.5564 -0.430491"/>
    <general name="r_thigh_joint" class="/" joint="r_thigh_joint" forcerange="-18.2232 18.2232" gainprm="17.5564" biasprm="0 -17.5564 -0.430491"/>
    <general name="r_calf_joint" class="/" joint="r_calf_joint" forcerange="-19.2979 19.2979" gainprm="17.5564" biasprm="0 -17.5564 -0.430491"/>
    <general name="r_ankle_pitch_joint" class="/" joint="r_ankle_pitch_joint" forcerange="-18.847 18.847" gainprm="17.5564" biasprm="0 -17.5564 -0.430491"/>
    <general name="r_ankle_roll_joint" class="/" joint="r_ankle_roll_joint" forcerange="-18.1012 18.1012" gainprm="17.5564" biasprm="0 -17.5564 -0.430491"/>
    <general name="l_hip_pitch_joint" class="/" joint="l_hip_pitch_joint" forcerange="-18.5122 18.5122" gainprm="17.5564" biasprm="0 -17.5564 -0.430491"/>
    <general name="l_hip_roll_joint" class="/" joint="l_hip_roll_joint" forcerange="-19.1756 19.1756" gainprm="17.5564" biasprm="0 -17.5564 -0.430491"/>
    <general name="l_thigh_joint" class="/" joint="l_thigh_joint" forcerange="-18.2971 18.2971" gainprm="17.5564" biasprm="0 -17.5564 -0.430491"/>
    <general name="l_calf_joint" class="/" joint="l_calf_joint" forcerange="-18.6903 18.6903" gainprm="17.5564" biasprm="0 -17.5564 -0.430491"/>
    <general name="l_ankle_pitch_joint" class="/" joint="l_ankle_pitch_joint" forcerange="-17.8722 17.8722" gainprm="17.5564" biasprm="0 -17.5564 -0.430491"/>
    <general name="l_ankle_roll_joint" class="/" joint="l_ankle_roll_joint" forcerange="-18.3653 18.3653" gainprm="17.5564" biasprm="0 -17.5564 -0.430491"/>
  </actuator>

  <sensor>
    <gyro site="imu" name="imu_angular_velocity"/>
    <velocimeter site="imu" name="imu_linear_velocity"/>
    <framelinvel objtype="site" objname="left_foot" name="left_foot_global_linear_velocity"/>
    <framelinvel objtype="site" objname="right_foot" name="right_foot_global_linear_velocity"/>
  </sensor>

  <keyframe>
    <key name="home" qpos="0 0 0.291 1 0 0 0 0.4 0 0 -0.8 0.4 0 -0.4 0 0 0.8 -0.4 0"/>
  </keyframe>
</mujoco>
