<mujoco model="pi_12dof_release_v1">
  <compiler angle="radian" assetdir="assets" balanceinertia="true" inertiafromgeom="false"/>

  <option timestep="0.005" density="1.2" viscosity="2e-05"/>

  <size nkey="1"/>

  <visual>
    <quality shadowsize="8192"/>
    <map shadowclip="0.5"/>
  </visual>

  <default>
    <default class="/">
      <joint armature="0.01" damping="0.01" frictionloss="0.01"/>
      <geom contype="0" conaffinity="0" group="1" solref="-1000 -80"/>
      <site size="0.01 0.005 0.005" group="5"/>
      <general forcelimited="true" biastype="affine" gainprm="20" biasprm="0 -20 -0.5"/>
      <default class="foot">
        <geom size="0.0845 0.036 0.005" type="box" condim="6" group="4" priority="1" friction="0.9 0.2 0.2" solimp="0.015 1 0.005"/>
      </default>
      <default class="reward_collision_sphere">
        <geom group="5" rgba="1 0 0 1"/>
      </default>
    </default>
  </default>

  <asset>
    <texture type="skybox" colorspace="auto" name="//unnamed_texture_0" builtin="gradient" rgb1="0.95 0.95 0.95" rgb2="0.95 0.95 0.95" width="100" height="600"/>
    <texture type="2d" colorspace="auto" name="texplane" builtin="checker" rgb1="0.345 0.575 0.748" rgb2="0.345 0.575 0.748" markrgb="1 1 1" width="512" height="512"/>
    <material name="MatPlane" class="/" texture="texplane" texuniform="true" texrepeat="2 2" specular="0.9"/>
    <mesh name="baselink_1" class="/" file="baselink_1.STL"/>
    <mesh name="r_hip_pitch_link" class="/" file="r_hip_pitch_link.STL"/>
    <mesh name="r_hip_roll_link" class="/" file="r_hip_roll_link.STL"/>
    <mesh name="r_thigh_link" class="/" file="r_thigh_link.STL"/>
    <mesh name="r_calf_link" class="/" file="r_calf_link.STL"/>
    <mesh name="r_ankle_pitch_link" class="/" file="r_ankle_pitch_link.STL"/>
    <mesh name="r_ankle_roll_link" class="/" file="r_ankle_roll_link.STL"/>
    <mesh name="l_hip_pitch_link" class="/" file="l_hip_pitch_link.STL"/>
    <mesh name="l_hip_roll_link" class="/" file="l_hip_roll_link.STL"/>
    <mesh name="l_thigh_link" class="/" file="l_thigh_link.STL"/>
    <mesh name="l_calf_link" class="/" file="l_calf_link.STL"/>
    <mesh name="l_ankle_pitch_link" class="/" file="l_ankle_pitch_link.STL"/>
    <mesh name="l_ankle_roll_link" class="/" file="l_ankle_roll_link.STL"/>
  </asset>

  <worldbody>
    <geom name="floor" class="/" size="100 100 0.125" type="plane" group="0" material="MatPlane"/>
    <light name="toplight_shadow" class="/" pos="0 0 5" dir="0.0990148 0.0990148 -0.990148" type="directional" ambient="0.04 0.04 0.04" diffuse="0.55 0.55 0.55" specular="0.12 0.12 0.12"/>
    <light name="toplight_fill" class="/" pos="0 0 5" dir="0.0990148 0.0990148 -0.990148" type="directional" castshadow="false" ambient="0.04 0.04 0.04" diffuse="0.3 0.3 0.3" specular="0.08 0.08 0.08"/>
    <body name="trunk" pos="-0.00176257 0.000425982 -0.00267797" quat="1 -1.86129e-05 0.000310401 -5.31307e-05">
      <inertial pos="0.00366661 0.00234752 0.0548793" quat="0.690939 0.00874466 0.00527571 0.722841" mass="3.2015" diaginertia="0.0116162 0.00700706 0.0223641"/>
      <joint name="//unnamed_joint_0" type="free"/>
      <geom name="//unnamed_geom_1" class="/" type="mesh" density="0" rgba="1 1 1 1" mesh="baselink_1"/>
      <geom name="//unnamed_geom_2" class="/" size="0.0558964 0.0558964 0.0558964" pos="0 0 0.110499" type="box" rgba="1 1 1 1"/>
      <geom name="//unnamed_geom_3" class="reward_collision_sphere" size="0.061486" pos="0 0 0.0966867"/>
      <site name="imu" class="/" pos="0.00101925 0.0122275 -0.00150618" size="0.0111793"/>
      <camera name="track" class="/" pos="0 -1.88805 0" quat="0.707107 0.707107 0 0" mode="trackcom"/>
      <camera name="ego_camera" class="/" pos="0.0771388 0 0.248623" quat="-0.5 -0.5 0.5 0.5"/>
      <body name="r_hip_pitch_link" pos="0.000968324 -0.0233948 -0.0430369" quat="0.992166 -1.1816e-05 -0.124918 -0.00135411">
        <inertial pos="0.0031388 -0.0538199 -0.000410168" quat="-0.0192063 0.706107 -0.0277292 0.707301" mass="0.511701" diaginertia="0.000125008 7.76924e-05 0.000418461"/>
        <joint name="r_hip_pitch_joint" class="/" pos="0 0 0" axis="-0.00935261 -0.999907 0.00989694" range="-1.80192 1.26811" armature="0.0097371" damping="0.0143707" frictionloss="0.0119213"/>
        <geom name="//unnamed_geom_4" class="/" type="mesh" density="0" rgba="0.75294 0.75294 0.75294 1" mesh="r_hip_pitch_link"/>
        <geom name="//unnamed_geom_5" class="/" size="0.000558964 0.000558964 0.000558964" type="box" rgba="0.75294 0.75294 0.75294 1"/>
        <body name="r_hip_roll_link" pos="0.00284968 -0.0520291 0.00176921" quat="1 -0.000141138 0.000142357 0.000126909">
          <inertial pos="-0.000147338 -0.00173794 -0.0835364" quat="0.705768 -0.078973 -0.0826867 0.699155" mass="0.537405" diaginertia="0.000390354 0.00020397 0.000617773"/>
          <joint name="r_hip_roll_joint" class="/" pos="0 0 0" axis="-0.999981 0.002875 0.00543274" range="-0.165296 0.467687" armature="0.00968358" damping="0.0140544" frictionloss="0.0114796"/>
          <geom name="//unnamed_geom_6" class="/" type="mesh" density="0" rgba="0.75294 0.75294 0.75294 1" mesh="r_hip_roll_link"/>
          <geom name="//unnamed_geom_7" class="/" size="0.000558964 0.000558964 0.000558964" type="box" rgba="0.75294 0.75294 0.75294 1"/>
          <geom name="//unnamed_geom_8" class="reward_collision_sphere" size="0.0447171"/>
          <body name="r_thigh_link" pos="0.00180906 0.000568893 -0.0968754" quat="0.999999 0.000519694 -0.000593577 -0.000652851">
            <inertial pos="-0.000587196 0.00162771 -0.0638302" quat="0.745786 0.666163 -0.00549097 -7.94789e-05" mass="0.157009" diaginertia="0.000136198 7.08615e-05 0.000292749"/>
            <joint name="r_thigh_joint" class="/" pos="0 0 0" axis="0.0024985 0.00203484 -0.999995" range="-0.319735 0.638757" armature="0.0100053" damping="0.0145847" frictionloss="0.0122025"/>
            <geom name="//unnamed_geom_9" class="/" type="mesh" density="0" rgba="0.75294 0.75294 0.75294 1" mesh="r_thigh_link"/>
            <geom name="//unnamed_geom_10" class="/" size="0.000558964 0.000558964 0.000558964" type="box" rgba="0.75294 0.75294 0.75294 1"/>
            <body name="r_calf_link" pos="0.00208649 0.000318094 -0.0965854" quat="0.94765 0.00045922 0.31931 -0.000133996">
              <inertial pos="0.00207598 -0.00107079 -0.0955313" quat="0.999983 -0.00151443 -0.00174501 0.00542208" mass="1.1406" diaginertia="0.00387116 0.00254493 0.000830667"/>
              <joint name="r_calf_joint" class="/" pos="0 0 0" axis="-0.0030491 -0.999993 0.00215624" stiffness="0.000656524" range="-1.67727 0.641658" armature="0.0104351" damping="0.017221" frictionloss="0.0118347"/>
              <geom name="//unnamed_geom_11" class="/" type="mesh" density="0" rgba="0.75294 0.75294 0.75294 1" mesh="r_calf_link"/>
              <geom name="//unnamed_geom_12" class="/" size="0.000558964 0.000558964 0.000558964" type="box" rgba="0.75294 0.75294 0.75294 1"/>
              <geom name="//unnamed_geom_13" class="reward_collision_sphere" size="0.0447171"/>
              <body name="r_ankle_pitch_link" pos="0.00131112 0.00122746 -0.194009" quat="0.980126 1.71438e-05 -0.198374 -0.000316764">
                <inertial pos="0.00727784 0.00219488 -0.000295856" quat="-0.00244064 0.712773 7.33356e-05 0.70139" mass="0.24385" diaginertia="0.000342579 0.000155468 0.000586239"/>
                <joint name="r_ankle_pitch_joint" class="/" pos="0 0 0" axis="-0.00411957 -0.999991 -0.000566446" range="-1.24292 0.49446" armature="0.0109378" damping="0" frictionloss="0.0124931"/>
                <geom name="//unnamed_geom_14" class="/" type="mesh" density="0" rgba="0.75294 0.75294 0.75294 1" mesh="r_ankle_pitch_link"/>
                <geom name="//unnamed_geom_15" class="/" size="0.0435992 0.0447171 0.0279482" type="box" rgba="0.75294 0.75294 0.75294 1"/>
                <body name="r_ankle_roll_link" pos="0.079036 0.00131133 -0.00302964" quat="1 -7.29379e-05 8.71092e-05 4.89754e-05">
                  <inertial pos="-0.023848 -0.000405391 -0.0205327" quat="0.560132 0.431253 0.433885 0.558584" mass="0.730992" diaginertia="0.00129466 0.000771239 0.00139589"/>
                  <joint name="r_ankle_roll_joint" class="/" pos="0 0 0" axis="-0.999982 -0.00353793 -0.00482537" stiffness="0.00744532" range="-0.139502 0.14024" armature="0.0109324" damping="0.00049671" frictionloss="0.0114455"/>
                  <geom name="//unnamed_geom_16" class="/" type="mesh" density="0" rgba="0.75294 0.75294 0.75294 1" mesh="r_ankle_roll_link"/>
                  <geom name="//unnamed_geom_17" class="/" type="mesh" rgba="0.75294 0.75294 0.75294 1" mesh="r_ankle_roll_link"/>
                  <geom name="right_foot" class="foot" size="0.0864912 0.0386356 0.00502672" pos="-0.0524544 0 -0.0607745"/>
                  <geom name="//unnamed_geom_19" class="reward_collision_sphere" size="0.0447171" pos="-0.0514258 0 -0.0276248"/>
                  <geom name="//unnamed_geom_20" class="reward_collision_sphere" size="0.0223585" pos="0.0154278 0.0188805 -0.0552495"/>
                  <geom name="//unnamed_geom_21" class="reward_collision_sphere" size="0.0223585" pos="-0.123422 0.0188805 -0.0552495"/>
                  <site name="right_foot" class="foot" pos="-0.0524544 0 -0.0607745" size="0.0111793"/>
                </body>
              </body>
            </body>
          </body>
        </body>
      </body>
      <body name="l_hip_pitch_link" pos="-0.000282554 0.0207573 -0.0462499" quat="0.992264 -0.00018019 -0.124143 0.00022664">
        <inertial pos="0.00364852 0.0501725 -0.00166701" quat="-0.0329967 0.711642 0.0272223 0.701238" mass="0.551291" diaginertia="0.000151001 8.16174e-05 0.000515682"/>
        <joint name="l_hip_pitch_joint" class="/" pos="0 0 0" axis="0.0032493 0.999974 -0.00641246" range="-1.1915 1.76166" armature="0.0112182" damping="0.026145" frictionloss="0.0114083"/>
        <geom name="//unnamed_geom_22" class="/" type="mesh" density="0" rgba="0.75294 0.75294 0.75294 1" mesh="l_hip_pitch_link"/>
        <geom name="//unnamed_geom_23" class="/" size="0.000558964 0.000558964 0.000558964" type="box" rgba="0.75294 0.75294 0.75294 1"/>
        <body name="l_hip_roll_link" pos="0.000471051 0.0532359 0.00025361" quat="1 1.62354e-05 0.000234321 8.28319e-05">
          <inertial pos="-0.00121966 -0.000348942 -0.0827738" quat="0.703582 -0.0850001 -0.0839039 0.700505" mass="0.551407" diaginertia="0.000390795 0.000217755 0.000681124"/>
          <joint name="l_hip_roll_joint" class="/" pos="0 0 0" axis="-0.999879 0.0144561 -0.00582601" stiffness="0.0146246" range="-0.513168 0.135428" armature="0.00965005" damping="0.00980518" frictionloss="0.00966276"/>
          <geom name="//unnamed_geom_24" class="/" type="mesh" density="0" rgba="0.75294 0.75294 0.75294 1" mesh="l_hip_roll_link"/>
          <geom name="//unnamed_geom_25" class="/" size="0.000558964 0.000558964 0.000558964" type="box" rgba="0.75294 0.75294 0.75294 1"/>
          <geom name="//unnamed_geom_26" class="reward_collision_sphere" size="0.0447171"/>
          <body name="l_thigh_link" pos="0.000571154 0.000289809 -0.0944049" quat="1 0.000479529 0.00041359 0.000665276">
            <inertial pos="-0.00231602 -0.00270766 -0.0660071" quat="0.680673 0.732515 -0.0100655 -0.00205388" mass="0.162376" diaginertia="0.000144108 7.27465e-05 0.000306707"/>
            <joint name="l_thigh_joint" class="/" pos="0 0 0" axis="0.0135935 -0.00578703 -0.999891" stiffness="0.00866231" range="-0.615622 0.330995" armature="0.0124752" damping="0.00534916" frictionloss="0.0125916"/>
            <geom name="//unnamed_geom_27" class="/" type="mesh" density="0" rgba="0.75294 0.75294 0.75294 1" mesh="l_thigh_link"/>
            <geom name="//unnamed_geom_28" class="/" size="0.000558964 0.000558964 0.000558964" type="box" rgba="0.75294 0.75294 0.75294 1"/>
            <body name="l_calf_link" pos="0.00201302 -0.0024379 -0.0986188" quat="0.947544 -0.000341742 0.319625 0.000144922">
              <inertial pos="-0.000866672 0.00455216 -0.0950311" quat="0.999952 -0.0017184 -0.00601583 0.00754752" mass="1.14148" diaginertia="0.00411876 0.00266789 0.000883019"/>
              <joint name="l_calf_joint" class="/" pos="0 0 0" axis="-0.00572481 0.999943 0.00898512" range="-0.665874 1.60693" armature="0.0124931" damping="0.00536278" frictionloss="0.0109722"/>
              <geom name="//unnamed_geom_29" class="/" type="mesh" density="0" rgba="0.75294 0.75294 0.75294 1" mesh="l_calf_link"/>
              <geom name="//unnamed_geom_30" class="/" size="0.000558964 0.000558964 0.000558964" type="box" rgba="0.75294 0.75294 0.75294 1"/>
              <geom name="//unnamed_geom_31" class="reward_collision_sphere" size="0.0447171"/>
              <body name="l_ankle_pitch_link" pos="-0.00229309 0.00183697 -0.19176" quat="0.980085 0.000241269 -0.198577 6.39681e-05">
                <inertial pos="0.00409662 -0.000832487 -0.000221353" quat="-0.00116272 0.709274 0.00345406 0.704923" mass="0.244227" diaginertia="0.000347583 0.000169803 0.000602246"/>
                <joint name="l_ankle_pitch_joint" class="/" pos="0 0 0" axis="0.00523817 0.999981 -0.0033075" range="-0.505688 1.30535" armature="0.0111111" damping="0" frictionloss="0.0127087"/>
                <geom name="//unnamed_geom_32" class="/" type="mesh" density="0" rgba="0.75294 0.75294 0.75294 1" mesh="l_ankle_pitch_link"/>
                <geom name="//unnamed_geom_33" class="/" size="0.0435992 0.0447171 0.0279482" type="box" rgba="0.75294 0.75294 0.75294 1"/>
                <body name="l_ankle_roll_link" pos="0.07852 -5.28535e-06 0.00278004" quat="1 -5.92386e-05 0.000105627 -4.65995e-05">
                  <inertial pos="-0.0261331 -0.000414075 -0.0188449" quat="0.56731 0.421357 0.431625 0.56064" mass="0.724534" diaginertia="0.00134044 0.000759901 0.00142857"/>
                  <joint name="l_ankle_roll_joint" class="/" pos="0 0 0" axis="-0.999987 -0.00505977 0.00109694" stiffness="0.00051351" range="-0.161583 0.208378" armature="0.0096703" damping="0.0153184" frictionloss="0.0096328"/>
                  <geom name="//unnamed_geom_34" class="/" type="mesh" density="0" rgba="0.75294 0.75294 0.75294 1" mesh="l_ankle_roll_link"/>
                  <geom name="//unnamed_geom_35" class="/" type="mesh" rgba="0.75294 0.75294 0.75294 1" mesh="l_ankle_roll_link"/>
                  <geom name="left_foot" class="foot" size="0.092449 0.0426744 0.00548641" pos="-0.0524544 0 -0.0607745"/>
                  <geom name="//unnamed_geom_37" class="reward_collision_sphere" size="0.0447171" pos="-0.0514258 0 -0.0276248"/>
                  <geom name="//unnamed_geom_38" class="reward_collision_sphere" size="0.0223585" pos="0.0154278 -0.0188805 -0.0552495"/>
                  <geom name="//unnamed_geom_39" class="reward_collision_sphere" size="0.0223585" pos="-0.123422 -0.0188805 -0.0552495"/>
                  <site name="left_foot" class="foot" pos="-0.0524544 0 -0.0607745" size="0.0111793"/>
                </body>
              </body>
            </body>
          </body>
        </body>
      </body>
    </body>
  </worldbody>

  <contact>
    <pair class="/" geom1="floor" geom2="right_foot" name="//unnamed_contact_1"/>
    <pair class="/" geom1="floor" geom2="left_foot" name="//unnamed_contact_0"/>
  </contact>

  <actuator>
    <general name="r_hip_pitch_joint" class="/" joint="r_hip_pitch_joint" forcerange="-24.3534 24.3534" gainprm="21.8254" biasprm="0 -21.8254 -0.601328"/>
    <general name="r_hip_roll_joint" class="/" joint="r_hip_roll_joint" forcerange="-25.4321 25.4321" gainprm="21.8254" biasprm="0 -21.8254 -0.601328"/>
    <general name="r_thigh_joint" class="/" joint="r_thigh_joint" forcerange="-22.5406 22.5406" gainprm="21.8254" biasprm="0 -21.8254 -0.601328"/>
    <general name="r_calf_joint" class="/" joint="r_calf_joint" forcerange="-22.133 22.133" gainprm="21.8254" biasprm="0 -21.8254 -0.601328"/>
    <general name="r_ankle_pitch_joint" class="/" joint="r_ankle_pitch_joint" forcerange="-24.865 24.865" gainprm="21.8254" biasprm="0 -21.8254 -0.601328"/>
    <general name="r_ankle_roll_joint" class="/" joint="r_ankle_roll_joint" forcerange="-23.7586 23.7586" gainprm="21.8254" biasprm="0 -21.8254 -0.601328"/>
    <general name="l_hip_pitch_joint" class="/" joint="l_hip_pitch_joint" forcerange="-23.6584 23.6584" gainprm="21.8254" biasprm="0 -21.8254 -0.601328"/>
    <general name="l_hip_roll_joint" class="/" joint="l_hip_roll_joint" forcerange="-21.3223 21.3223" gainprm="21.8254" biasprm="0 -21.8254 -0.601328"/>
    <general name="l_thigh_joint" class="/" joint="l_thigh_joint" forcerange="-22.9597 22.9597" gainprm="21.8254" biasprm="0 -21.8254 -0.601328"/>
    <general name="l_calf_joint" class="/" joint="l_calf_joint" forcerange="-24.2273 24.2273" gainprm="21.8254" biasprm="0 -21.8254 -0.601328"/>
    <general name="l_ankle_pitch_joint" class="/" joint="l_ankle_pitch_joint" forcerange="-25.679 25.679" gainprm="21.8254" biasprm="0 -21.8254 -0.601328"/>
    <general name="l_ankle_roll_joint" class="/" joint="l_ankle_roll_joint" forcerange="-24.1123 24.1123" gainprm="21.8254" biasprm="0 -21.8254 -0.601328"/>
  </actuator>

  <sensor>
    <gyro site="imu" name="imu_angular_velocity"/>
    <velocimeter site="imu" name="imu_linear_velocity"/>
    <framelinvel objtype="site" objname="left_foot" name="left_foot_global_linear_velocity"/>
    <framelinvel objtype="site" objname="right_foot" name="right_foot_global_linear_velocity"/>
  </sensor>

  <keyframe>
    <key name="home" qpos="0 0 0.291 1 0 0 0 0.4 0 0 -0.8 0.4 0 -0.4 0 0 0.8 -0.4 0"/>
  </keyframe>
</mujoco>
