<mujoco model="pi_12dof_release_v1">
  <compiler angle="radian" assetdir="assets" balanceinertia="true" inertiafromgeom="false"/>

  <option timestep="0.005" density="1.2" viscosity="2e-05"/>

  <size nkey="1"/>

  <visual>
    <quality shadowsize="8192"/>
    <map shadowclip="0.5"/>
  </visual>

  <default>
    <default class="/">
      <joint armature="0.01" damping="0.01" frictionloss="0.01"/>
      <geom contype="0" conaffinity="0" group="1" solref="-1000 -80"/>
      <site size="0.01 0.005 0.005" group="5"/>
      <general forcelimited="true" biastype="affine" gainprm="20" biasprm="0 -20 -0.5"/>
      <default class="foot">
        <geom size="0.0845 0.036 0.005" type="box" condim="6" group="4" priority="1" friction="0.9 0.2 0.2" solimp="0.015 1 0.005"/>
      </default>
      <default class="reward_collision_sphere">
        <geom group="5" rgba="1 0 0 1"/>
      </default>
    </default>
  </default>

  <asset>
    <texture type="skybox" colorspace="auto" name="//unnamed_texture_0" builtin="gradient" rgb1="0.95 0.95 0.95" rgb2="0.95 0.95 0.95" width="100" height="600"/>
    <texture type="2d" colorspace="auto" name="texplane" builtin="checker" rgb1="0.345 0.575 0.748" rgb2="0.345 0.575 0.748" markrgb="1 1 1" width="512" height="512"/>
    <material name="MatPlane" class="/" texture="texplane" texuniform="true" texrepeat="2 2" specular="0.9"/>
    <mesh name="baselink_1" class="/" file="baselink_1.STL"/>
    <mesh name="r_hip_pitch_link" class="/" file="r_hip_pitch_link.STL"/>
    <mesh name="r_hip_roll_link" class="/" file="r_hip_roll_link.STL"/>
    <mesh name="r_thigh_link" class="/" file="r_thigh_link.STL"/>
    <mesh name="r_calf_link" class="/" file="r_calf_link.STL"/>
    <mesh name="r_ankle_pitch_link" class="/" file="r_ankle_pitch_link.STL"/>
    <mesh name="r_ankle_roll_link" class="/" file="r_ankle_roll_link.STL"/>
    <mesh name="l_hip_pitch_link" class="/" file="l_hip_pitch_link.STL"/>
    <mesh name="l_hip_roll_link" class="/" file="l_hip_roll_link.STL"/>
    <mesh name="l_thigh_link" class="/" file="l_thigh_link.STL"/>
    <mesh name="l_calf_link" class="/" file="l_calf_link.STL"/>
    <mesh name="l_ankle_pitch_link" class="/" file="l_ankle_pitch_link.STL"/>
    <mesh name="l_ankle_roll_link" class="/" file="l_ankle_roll_link.STL"/>
  </asset>

  <worldbody>
    <geom name="floor" class="/" size="100 100 0.125" type="plane" group="0" material="MatPlane"/>
    <light name="toplight_shadow" class="/" pos="0 0 5" dir="0.0990148 0.0990148 -0.990148" type="directional" ambient="0.04 0.04 0.04" diffuse="0.55 0.55 0.55" specular="0.12 0.12 0.12"/>
    <light name="toplight_fill" class="/" pos="0 0 5" dir="0.0990148 0.0990148 -0.990148" type="directional" castshadow="false" ambient="0.04 0.04 0.04" diffuse="0.3 0.3 0.3" specular="0.08 0.08 0.08"/>
    <body name="trunk" pos="-0.00617065 -0.00157962 -0.000522934" quat="0.999997 -0.00126306 -0.00112171 -0.00171202">
      <inertial pos="0.00765872 0.000464625 0.0595448" quat="0.697331 -0.00174821 0.0127273 0.716634" mass="3.8145" diaginertia="0.00546566 0.0147281 0.0358765"/>
      <joint name="//unnamed_joint_0" type="free"/>
      <geom name="//unnamed_geom_1" class="/" type="mesh" density="0" rgba="1 1 1 1" mesh="baselink_1"/>
      <geom name="//unnamed_geom_2" class="/" size="0.0586279 0.0586279 0.0586279" pos="0 0 0.122303" type="box" rgba="1 1 1 1"/>
      <geom name="//unnamed_geom_3" class="reward_collision_sphere" size="0.0644907" pos="0 0 0.107015"/>
      <site name="imu" class="/" pos="-0.00889249 -0.000863156 -0.0219931" size="0.0117256"/>
      <camera name="track" class="/" pos="0 -2.20295 0" quat="0.707107 0.707107 0 0" mode="trackcom"/>
      <camera name="ego_camera" class="/" pos="0.0665558 0 0.275182" quat="-0.5 -0.5 0.5 0.5"/>
      <body name="r_hip_pitch_link" pos="0.00169095 -0.0270353 -0.0493535" quat="0.992186 -0.000101343 -0.124766 0.0002577">
        <inertial pos="0.00345818 -0.0589452 -0.00164952" quat="-0.0278166 0.709112 -0.0297279 0.703919" mass="0.610235" diaginertia="5.67063e-05 0.000163922 0.000692722"/>
        <joint name="r_hip_pitch_joint" class="/" pos="0 0 0" axis="0.00152448 -0.999998 0.00137361" range="-1.75444 1.29287" armature="0.0106436" damping="0" frictionloss="0.0104413"/>
        <geom name="//unnamed_geom_4" class="/" type="mesh" density="0" rgba="0.75294 0.75294 0.75294 1" mesh="r_hip_pitch_link"/>
        <geom name="//unnamed_geom_5" class="/" size="0.000586279 0.000586279 0.000586279" type="box" rgba="0.75294 0.75294 0.75294 1"/>
        <body name="r_hip_roll_link" pos="0.000473011 -0.0590972 -0.000481185" quat="0.999998 0.000482916 0.00152405 -0.000798673">
          <inertial pos="-0.00334523 0.00142975 -0.0884018" quat="0.70596 -0.0791991 -0.0827757 0.698925" mass="0.631605" diaginertia="0.000189504 0.000472185 0.00101016"/>
          <joint name="r_hip_roll_joint" class="/" pos="0 0 0" axis="-0.999939 -0.00147839 0.0109605" stiffness="0.00975365" range="-0.160908 0.536174" armature="0.0110298" damping="0.0306043" frictionloss="0.00978652"/>
          <geom name="//unnamed_geom_6" class="/" type="mesh" density="0" rgba="0.75294 0.75294 0.75294 1" mesh="r_hip_roll_link"/>
          <geom name="//unnamed_geom_7" class="/" size="0.000586279 0.000586279 0.000586279" type="box" rgba="0.75294 0.75294 0.75294 1"/>
          <geom name="//unnamed_geom_8" class="reward_collision_sphere" size="0.0469023"/>
          <body name="r_thigh_link" pos="0.00307338 0.00483537 -0.104864" quat="1 0.000298178 -0.00035474 -4.81271e-05">
            <inertial pos="0.00318576 0.00196959 -0.0741193" quat="0.735263 0.677758 -0.00461639 0.00323427" mass="0.180045" diaginertia="6.36593e-05 0.000139004 0.000455345"/>
            <joint name="r_thigh_joint" class="/" pos="0 0 0" axis="-0.0032115 -0.00274687 -0.999991" stiffness="0.0017971" range="-0.245281 0.57982" armature="0.011996" damping="0.0151403" frictionloss="0.0153879"/>
            <geom name="//unnamed_geom_9" class="/" type="mesh" density="0" rgba="0.75294 0.75294 0.75294 1" mesh="r_thigh_link"/>
            <geom name="//unnamed_geom_10" class="/" size="0.000586279 0.000586279 0.000586279" type="box" rgba="0.75294 0.75294 0.75294 1"/>
            <body name="r_calf_link" pos="0.00321673 -0.000663713 -0.102483" quat="0.94774 0.00122791 0.319041 -0.00034902">
              <inertial pos="-0.000331107 0.00276877 -0.10599" quat="0.999796 -0.0184049 0.0068756 0.00459619" mass="1.32972" diaginertia="0.00200221 0.00571257 0.00148525"/>
              <joint name="r_calf_joint" class="/" pos="0 0 0" axis="-0.0168257 -0.999838 -0.00642901" stiffness="0.0184236" range="-1.76398 0.607085" armature="0.0103464" damping="0.0210104" frictionloss="0.0103086"/>
              <geom name="//unnamed_geom_11" class="/" type="mesh" density="0" rgba="0.75294 0.75294 0.75294 1" mesh="r_calf_link"/>
              <geom name="//unnamed_geom_12" class="/" size="0.000586279 0.000586279 0.000586279" type="box" rgba="0.75294 0.75294 0.75294 1"/>
              <geom name="//unnamed_geom_13" class="reward_collision_sphere" size="0.0469023"/>
              <body name="r_ankle_pitch_link" pos="-0.000853348 0.00603247 -0.213555" quat="0.980095 -0.000375185 -0.198527 -0.000240264">
                <inertial pos="0.00387427 0.00630234 -0.00221323" quat="-0.000489006 0.706572 -0.00773937 0.707599" mass="0.278886" diaginertia="0.000164458 0.000349712 0.000954134"/>
                <joint name="r_ankle_pitch_joint" class="/" pos="0 0 0" axis="-0.0233697 -0.999689 0.00874905" range="-1.284 0.515474" armature="0.0125454" damping="0.0138727" frictionloss="0.0114949"/>
                <geom name="//unnamed_geom_14" class="/" type="mesh" density="0" rgba="0.75294 0.75294 0.75294 1" mesh="r_ankle_pitch_link"/>
                <geom name="//unnamed_geom_15" class="/" size="0.0457298 0.0469023 0.029314" type="box" rgba="0.75294 0.75294 0.75294 1"/>
                <body name="r_ankle_roll_link" pos="0.0682694 0.00601536 -0.00119856" quat="1 -0.000253418 -0.000140903 5.98671e-05">
                  <inertial pos="-0.0201588 0.00186205 -0.0224016" quat="0.559204 0.422873 0.452204 0.551345" mass="0.82871" diaginertia="0.000626707 0.00168327 0.00243366"/>
                  <joint name="r_ankle_roll_joint" class="/" pos="0 0 0" axis="-0.999618 -0.0216556 0.0171635" range="-0.0574663 0.184967" armature="0.00908982" damping="0" frictionloss="0.0120452"/>
                  <geom name="//unnamed_geom_16" class="/" type="mesh" density="0" rgba="0.75294 0.75294 0.75294 1" mesh="r_ankle_roll_link"/>
                  <geom name="//unnamed_geom_17" class="/" type="mesh" rgba="0.75294 0.75294 0.75294 1" mesh="r_ankle_roll_link"/>
                  <geom name="right_foot" class="foot" size="0.0852964 0.0411235 0.00585538" pos="-0.045258 0 -0.0672667"/>
                  <geom name="//unnamed_geom_19" class="reward_collision_sphere" size="0.0469023" pos="-0.0443706 0 -0.0305758"/>
                  <geom name="//unnamed_geom_20" class="reward_collision_sphere" size="0.0234512" pos="0.0133112 0.0220295 -0.0611515"/>
                  <geom name="//unnamed_geom_21" class="reward_collision_sphere" size="0.0234512" pos="-0.106489 0.0220295 -0.0611515"/>
                  <site name="right_foot" class="foot" pos="-0.045258 0 -0.0672667" size="0.0117256"/>
                </body>
              </body>
            </body>
          </body>
        </body>
      </body>
      <body name="l_hip_pitch_link" pos="-0.00176567 0.0248541 -0.0480586" quat="0.992186 0.000131565 -0.124763 0.000293604">
        <inertial pos="0.00212549 0.054566 0.0018121" quat="-0.0469416 0.720271 0.00599151 0.692077" mass="0.606202" diaginertia="7.44631e-05 0.000174668 0.000817742"/>
        <joint name="l_hip_pitch_joint" class="/" pos="0 0 0" axis="-0.025615 0.999554 0.0153714" range="-1.21312 1.7371" armature="0.0120824" damping="0.0132501" frictionloss="0.0112939"/>
        <geom name="//unnamed_geom_22" class="/" type="mesh" density="0" rgba="0.75294 0.75294 0.75294 1" mesh="l_hip_pitch_link"/>
        <geom name="//unnamed_geom_23" class="/" size="0.000586279 0.000586279 0.000586279" type="box" rgba="0.75294 0.75294 0.75294 1"/>
        <body name="l_hip_roll_link" pos="-0.000120152 0.0662643 -0.00409449" quat="0.999999 -0.000522444 -0.000829194 -0.000519567">
          <inertial pos="-0.00215263 1.57373e-05 -0.0905807" quat="0.704777 -0.0743803 -0.0783488 0.701155" mass="0.600072" diaginertia="0.000190676 0.000476243 0.00108464"/>
          <joint name="l_hip_roll_joint" class="/" pos="0 0 0" axis="-0.999954 -0.00415922 0.00868618" stiffness="0.0330185" range="-0.547084 0.060372" armature="0.0110846" damping="0.00511999" frictionloss="0.0107723"/>
          <geom name="//unnamed_geom_24" class="/" type="mesh" density="0" rgba="0.75294 0.75294 0.75294 1" mesh="l_hip_roll_link"/>
          <geom name="//unnamed_geom_25" class="/" size="0.000586279 0.000586279 0.000586279" type="box" rgba="0.75294 0.75294 0.75294 1"/>
          <geom name="//unnamed_geom_26" class="reward_collision_sphere" size="0.0469023"/>
          <body name="l_thigh_link" pos="-0.00087606 0.000463462 -0.100828" quat="0.999999 0.00114633 0.000208721 -1.281e-05">
            <inertial pos="-0.00137013 -0.00708389 -0.0721061" quat="0.675391 0.73746 -1.89872e-06 1.64172e-06" mass="0.186141" diaginertia="7.04248e-05 0.000159381 0.000530656"/>
            <joint name="l_thigh_joint" class="/" pos="0 0 0" axis="0.0026344 0.00802065 -0.999964" range="-0.582972 0.262784" armature="0.0117917" damping="0.0232742" frictionloss="0.0117484"/>
            <geom name="//unnamed_geom_27" class="/" type="mesh" density="0" rgba="0.75294 0.75294 0.75294 1" mesh="l_thigh_link"/>
            <geom name="//unnamed_geom_28" class="/" size="0.000586279 0.000586279 0.000586279" type="box" rgba="0.75294 0.75294 0.75294 1"/>
            <body name="l_calf_link" pos="0.000563012 -0.000217549 -0.110262" quat="0.94736 -0.00245746 0.320159 1.55648e-05">
              <inertial pos="-0.00528383 0.001849 -0.101104" quat="0.999991 0.00153168 0.00192521 -0.00349735" mass="1.30347" diaginertia="0.00191898 0.00557225 0.00141068"/>
              <joint name="l_calf_joint" class="/" pos="0 0 0" axis="-0.000784677 0.999999 -0.000716213" range="-0.69636 1.66313" armature="0.0128336" damping="0.0114034" frictionloss="0.0137982"/>
              <geom name="//unnamed_geom_29" class="/" type="mesh" density="0" rgba="0.75294 0.75294 0.75294 1" mesh="l_calf_link"/>
              <geom name="//unnamed_geom_30" class="/" size="0.000586279 0.000586279 0.000586279" type="box" rgba="0.75294 0.75294 0.75294 1"/>
              <geom name="//unnamed_geom_31" class="reward_collision_sphere" size="0.0469023"/>
              <body name="l_ankle_pitch_link" pos="-0.00121346 -0.000357361 -0.208317" quat="0.98006 -6.27075e-06 -0.198702 0.000325138">
                <inertial pos="0.00177158 -0.0017382 4.65103e-05" quat="-0.00374909 0.707023 0.00283982 0.707175" mass="0.297703" diaginertia="0.000164848 0.000355441 0.00099447"/>
                <joint name="l_ankle_pitch_joint" class="/" pos="0 0 0" axis="0.000334067 0.999995 -0.00306821" stiffness="0.000366874" range="-0.509682 1.35031" armature="0.0116919" damping="0" frictionloss="0.0122032"/>
                <geom name="//unnamed_geom_32" class="/" type="mesh" density="0" rgba="0.75294 0.75294 0.75294 1" mesh="l_ankle_pitch_link"/>
                <geom name="//unnamed_geom_33" class="/" size="0.0457298 0.0469023 0.029314" type="box" rgba="0.75294 0.75294 0.75294 1"/>
                <body name="l_ankle_roll_link" pos="0.0684648 0.00173154 -0.000448471" quat="0.999999 0.000485783 0.000691406 -0.000688217">
                  <inertial pos="-0.0192842 0.00126427 -0.0227208" quat="0.560459 0.430559 0.43414 0.558594" mass="0.826944" diaginertia="0.000639448 0.00169527 0.00229384"/>
                  <joint name="l_ankle_roll_joint" class="/" pos="0 0 0" axis="-0.99965 0.0260504 0.00457569" stiffness="0.0185511" range="-0.138458 0.167461" armature="0.0106509" damping="0" frictionloss="0.0110365"/>
                  <geom name="//unnamed_geom_34" class="/" type="mesh" density="0" rgba="0.75294 0.75294 0.75294 1" mesh="l_ankle_roll_link"/>
                  <geom name="//unnamed_geom_35" class="/" type="mesh" rgba="0.75294 0.75294 0.75294 1" mesh="l_ankle_roll_link"/>
                  <geom name="left_foot" class="foot" size="0.0983794 0.0385497 0.0066328" pos="-0.045258 0 -0.0672667"/>
                  <geom name="//unnamed_geom_37" class="reward_collision_sphere" size="0.0469023" pos="-0.0443706 0 -0.0305758"/>
                  <geom name="//unnamed_geom_38" class="reward_collision_sphere" size="0.0234512" pos="0.0133112 -0.0220295 -0.0611515"/>
                  <geom name="//unnamed_geom_39" class="reward_collision_sphere" size="0.0234512" pos="-0.106489 -0.0220295 -0.0611515"/>
                  <site name="left_foot" class="foot" pos="-0.045258 0 -0.0672667" size="0.0117256"/>
                </body>
              </body>
            </body>
          </body>
        </body>
      </body>
    </body>
  </worldbody>

  <contact>
    <pair class="/" geom1="floor" geom2="right_foot" name="//unnamed_contact_1"/>
    <pair class="/" geom1="floor" geom2="left_foot" name="//unnamed_contact_0"/>
  </contact>

  <actuator>
    <general name="r_hip_pitch_joint" class="/" joint="r_hip_pitch_joint" forcerange="-24.6611 24.6611" gainprm="24.0238" biasprm="0 -24.0238 -0.6051"/>
    <general name="r_hip_roll_joint" class="/" joint="r_hip_roll_joint" forcerange="-23.9588 23.9588" gainprm="24.0238" biasprm="0 -24.0238 -0.6051"/>
    <general name="r_thigh_joint" class="/" joint="r_thigh_joint" forcerange="-22.5754 22.5754" gainprm="24.0238" biasprm="0 -24.0238 -0.6051"/>
    <general name="r_calf_joint" class="/" joint="r_calf_joint" forcerange="-19.169 19.169" gainprm="24.0238" biasprm="0 -24.0238 -0.6051"/>
    <general name="r_ankle_pitch_joint" class="/" joint="r_ankle_pitch_joint" forcerange="-26.8219 26.8219" gainprm="24.0238" biasprm="0 -24.0238 -0.6051"/>
    <general name="r_ankle_roll_joint" class="/" joint="r_ankle_roll_joint" forcerange="-28.6942 28.6942" gainprm="24.0238" biasprm="0 -24.0238 -0.6051"/>
    <general name="l_hip_pitch_joint" class="/" joint="l_hip_pitch_joint" forcerange="-24.1088 24.1088" gainprm="24.0238" biasprm="0 -24.0238 -0.6051"/>
    <general name="l_hip_roll_joint" class="/" joint="l_hip_roll_joint" forcerange="-24.6812 24.6812" gainprm="24.0238" biasprm="0 -24.0238 -0.6051"/>
    <general name="l_thigh_joint" class="/" joint="l_thigh_joint" forcerange="-22.5644 22.5644" gainprm="24.0238" biasprm="0 -24.0238 -0.6051"/>
    <general name="l_calf_joint" class="/" joint="l_calf_joint" forcerange="-23.9227 23.9227" gainprm="24.0238" biasprm="0 -24.0238 -0.6051"/>
    <general name="l_ankle_pitch_joint" class="/" joint="l_ankle_pitch_joint" forcerange="-24.6548 24.6548" gainprm="24.0238" biasprm="0 -24.0238 -0.6051"/>
    <general name="l_ankle_roll_joint" class="/" joint="l_ankle_roll_joint" forcerange="-25.028 25.028" gainprm="24.0238" biasprm="0 -24.0238 -0.6051"/>
  </actuator>

  <sensor>
    <gyro site="imu" name="imu_angular_velocity"/>
    <velocimeter site="imu" name="imu_linear_velocity"/>
    <framelinvel objtype="site" objname="left_foot" name="left_foot_global_linear_velocity"/>
    <framelinvel objtype="site" objname="right_foot" name="right_foot_global_linear_velocity"/>
  </sensor>

  <keyframe>
    <key name="home" qpos="0 0 0.291 1 0 0 0 0.4 0 0 -0.8 0.4 0 -0.4 0 0 0.8 -0.4 0"/>
  </keyframe>
</mujoco>
