<mujoco model="pi_12dof_release_v1">
  <compiler angle="radian" assetdir="assets" balanceinertia="true" inertiafromgeom="false"/>

  <option timestep="0.005" density="1.2" viscosity="2e-05"/>

  <size nkey="1"/>

  <visual>
    <quality shadowsize="8192"/>
    <map shadowclip="0.5"/>
  </visual>

  <default>
    <default class="/">
      <joint armature="0.01" damping="0.01" frictionloss="0.01"/>
      <geom contype="0" conaffinity="0" group="1" solref="-1000 -80"/>
      <site size="0.01 0.005 0.005" group="5"/>
      <general forcelimited="true" biastype="affine" gainprm="20" biasprm="0 -20 -0.5"/>
      <default class="foot">
        <geom size="0.0845 0.036 0.005" type="box" condim="6" group="4" priority="1" friction="0.9 0.2 0.2" solimp="0.015 1 0.005"/>
      </default>
      <default class="reward_collision_sphere">
        <geom group="5" rgba="1 0 0 1"/>
      </default>
    </default>
  </default>

  <asset>
    <texture type="skybox" colorspace="auto" name="//unnamed_texture_0" builtin="gradient" rgb1="0.95 0.95 0.95" rgb2="0.95 0.95 0.95" width="100" height="600"/>
    <texture type="2d" colorspace="auto" name="texplane" builtin="checker" rgb1="0.345 0.575 0.748" rgb2="0.345 0.575 0.748" markrgb="1 1 1" width="512" height="512"/>
    <material name="MatPlane" class="/" texture="texplane" texuniform="true" texrepeat="2 2" specular="0.9"/>
    <mesh name="baselink_1" class="/" file="baselink_1.STL"/>
    <mesh name="r_hip_pitch_link" class="/" file="r_hip_pitch_link.STL"/>
    <mesh name="r_hip_roll_link" class="/" file="r_hip_roll_link.STL"/>
    <mesh name="r_thigh_link" class="/" file="r_thigh_link.STL"/>
    <mesh name="r_calf_link" class="/" file="r_calf_link.STL"/>
    <mesh name="r_ankle_pitch_link" class="/" file="r_ankle_pitch_link.STL"/>
    <mesh name="r_ankle_roll_link" class="/" file="r_ankle_roll_link.STL"/>
    <mesh name="l_hip_pitch_link" class="/" file="l_hip_pitch_link.STL"/>
    <mesh name="l_hip_roll_link" class="/" file="l_hip_roll_link.STL"/>
    <mesh name="l_thigh_link" class="/" file="l_thigh_link.STL"/>
    <mesh name="l_calf_link" class="/" file="l_calf_link.STL"/>
    <mesh name="l_ankle_pitch_link" class="/" file="l_ankle_pitch_link.STL"/>
    <mesh name="l_ankle_roll_link" class="/" file="l_ankle_roll_link.STL"/>
  </asset>

  <worldbody>
    <geom name="floor" class="/" size="100 100 0.125" type="plane" group="0" material="MatPlane"/>
    <light name="toplight_shadow" class="/" pos="0 0 5" dir="0.0990148 0.0990148 -0.990148" type="directional" ambient="0.04 0.04 0.04" diffuse="0.55 0.55 0.55" specular="0.12 0.12 0.12"/>
    <light name="toplight_fill" class="/" pos="0 0 5" dir="0.0990148 0.0990148 -0.990148" type="directional" castshadow="false" ambient="0.04 0.04 0.04" diffuse="0.3 0.3 0.3" specular="0.08 0.08 0.08"/>
    <body name="trunk" pos="-0.00113727 0.00802512 0.000965333" quat="1 -1.0673e-05 -6.84156e-05 4.60826e-06">
      <inertial pos="-3.99897e-05 0.00863945 0.0396053" quat="0.72934 0.0487845 0.0125592 0.682294" mass="2.84162" diaginertia="0.00303118 0.0707705 0.00390624"/>
      <joint name="//unnamed_joint_0" type="free"/>
      <geom name="//unnamed_geom_1" class="/" type="mesh" density="0" rgba="1 1 1 1" mesh="baselink_1"/>
      <geom name="//unnamed_geom_2" class="/" size="0.0544348 0.0544348 0.0544348" pos="0 0 0.0789534" type="box" rgba="1 1 1 1"/>
      <geom name="//unnamed_geom_3" class="reward_collision_sphere" size="0.0598782" pos="0 0 0.0690842"/>
      <site name="imu" class="/" pos="-0.0384597 -0.0267221 0.0400482" size="0.010887"/>
      <camera name="track" class="/" pos="0 -2.99657 0" quat="0.707107 0.707107 0 0" mode="trackcom"/>
      <camera name="ego_camera" class="/" pos="0.0585662 0 0.177645" quat="-0.5 -0.5 0.5 0.5"/>
      <body name="r_hip_pitch_link" pos="-0.00672715 -0.0470907 -0.0426187" quat="0.991751 0.00225393 -0.128159 0.00077047">
        <inertial pos="0.00110978 -0.0852914 -0.00473159" quat="-0.0195607 0.707422 -0.0313711 0.705824" mass="0.514138" diaginertia="3.12745e-05 0.000810611 7.55748e-05"/>
        <joint name="r_hip_pitch_joint" class="/" pos="0 0 0" axis="-0.0025306 -0.999878 0.0154316" stiffness="0.00358208" range="-1.72541 1.35207" armature="0.0117657" damping="0.0228812" frictionloss="0.0115872"/>
        <geom name="//unnamed_geom_4" class="/" type="mesh" density="0" rgba="0.75294 0.75294 0.75294 1" mesh="r_hip_pitch_link"/>
        <geom name="//unnamed_geom_5" class="/" size="0.000544348 0.000544348 0.000544348" type="box" rgba="0.75294 0.75294 0.75294 1"/>
        <body name="r_hip_roll_link" pos="0.00016776 -0.0973628 0.00573447" quat="0.999994 -0.0022467 -0.00273846 -0.000213879">
          <inertial pos="-0.00842315 -0.00539639 -0.0641527" quat="0.691064 -0.0444567 -0.062327 0.718728" mass="0.500672" diaginertia="9.98324e-05 0.00214271 0.000125551"/>
          <joint name="r_hip_roll_joint" class="/" pos="0 0 0" axis="-0.999485 0.0300227 0.0113355" stiffness="0.01393" range="-0.149728 0.322343" armature="0.0147366" damping="0.0813909" frictionloss="0.0101909"/>
          <geom name="//unnamed_geom_6" class="/" type="mesh" density="0" rgba="0.75294 0.75294 0.75294 1" mesh="r_hip_roll_link"/>
          <geom name="//unnamed_geom_7" class="/" size="0.000544348 0.000544348 0.000544348" type="box" rgba="0.75294 0.75294 0.75294 1"/>
          <geom name="//unnamed_geom_8" class="reward_collision_sphere" size="0.0435478"/>
          <body name="r_thigh_link" pos="0.00203641 0.0105265 -0.0627556" quat="0.999997 -0.0024209 0.000148166 -0.000172437">
            <inertial pos="-0.0062877 0.00215795 -0.0351582" quat="0.73711 0.675751 -0.00379117 0.00391369" mass="0.146746" diaginertia="4.04266e-05 0.000625577 6.28519e-05"/>
            <joint name="r_thigh_joint" class="/" pos="0 0 0" axis="0.00834158 -0.0133736 -0.999876" stiffness="0.0272162" range="-0.161992 0.586169" armature="0.0129372" damping="0.00854041" frictionloss="0.0117047"/>
            <geom name="//unnamed_geom_9" class="/" type="mesh" density="0" rgba="0.75294 0.75294 0.75294 1" mesh="r_thigh_link"/>
            <geom name="//unnamed_geom_10" class="/" size="0.000544348 0.000544348 0.000544348" type="box" rgba="0.75294 0.75294 0.75294 1"/>
            <body name="r_calf_link" pos="-0.00343067 0.00032316 -0.064343" quat="0.947705 -0.000275253 0.319147 0.000683851">
              <inertial pos="0.00255615 -0.00264499 -0.0699349" quat="0.999953 0.000986845 -0.00278022 0.00920107" mass="1.19078" diaginertia="0.00106281 0.0309937 0.000148228"/>
              <joint name="r_calf_joint" class="/" pos="0 0 0" axis="-0.00119712 -0.999652 -0.0263683" stiffness="0.0220329" range="-1.90049 0.551676" armature="0.011676" damping="0.0108068" frictionloss="0.00842495"/>
              <geom name="//unnamed_geom_11" class="/" type="mesh" density="0" rgba="0.75294 0.75294 0.75294 1" mesh="r_calf_link"/>
              <geom name="//unnamed_geom_12" class="/" size="0.000544348 0.000544348 0.000544348" type="box" rgba="0.75294 0.75294 0.75294 1"/>
              <geom name="//unnamed_geom_13" class="reward_collision_sphere" size="0.0435478"/>
              <body name="r_ankle_pitch_link" pos="-0.0109689 -0.012012 -0.143979" quat="0.980001 -0.000391789 -0.198978 0.00220202">
                <inertial pos="0.00810944 0.0172758 -0.00159947" quat="-0.00947328 0.710056 -0.028158 0.703518" mass="0.183941" diaginertia="8.0554e-05 0.00148768 0.000103682"/>
                <joint name="r_ankle_pitch_joint" class="/" pos="0 0 0" axis="0.0543108 -0.998524 0.000786045" range="-1.38476 0.287265" armature="0.0115651" damping="0" frictionloss="0.0124681"/>
                <geom name="//unnamed_geom_14" class="/" type="mesh" density="0" rgba="0.75294 0.75294 0.75294 1" mesh="r_ankle_pitch_link"/>
                <geom name="//unnamed_geom_15" class="/" size="0.0424591 0.0435478 0.0272174" type="box" rgba="0.75294 0.75294 0.75294 1"/>
                <body name="r_ankle_roll_link" pos="0.0698387 0.00580826 0.00649542" quat="0.999989 -0.00102552 0.00438872 -0.00124152">
                  <inertial pos="-0.0215632 0.00214345 -0.0211157" quat="0.549821 0.42784 0.460399 0.550166" mass="0.673572" diaginertia="0.000322712 0.00780995 0.000256224"/>
                  <joint name="r_ankle_roll_joint" class="/" pos="0 0 0" axis="-0.99998 0.00455497 -0.00428758" range="0.0807353 0.18309" armature="0.0116329" damping="0.00845672" frictionloss="0.0134497"/>
                  <geom name="//unnamed_geom_16" class="/" type="mesh" density="0" rgba="0.75294 0.75294 0.75294 1" mesh="r_ankle_roll_link"/>
                  <geom name="//unnamed_geom_17" class="/" type="mesh" rgba="0.75294 0.75294 0.75294 1" mesh="r_ankle_roll_link"/>
                  <geom name="right_foot" class="foot" size="0.0810485 0.0522379 0.00718937" pos="-0.039825 0 -0.0434244"/>
                  <geom name="//unnamed_geom_19" class="reward_collision_sphere" size="0.0435478" pos="-0.0390441 0 -0.0197383"/>
                  <geom name="//unnamed_geom_20" class="reward_collision_sphere" size="0.0217739" pos="0.0117132 0.0299657 -0.0394767"/>
                  <geom name="//unnamed_geom_21" class="reward_collision_sphere" size="0.0217739" pos="-0.0937059 0.0299657 -0.0394767"/>
                  <site name="right_foot" class="foot" pos="-0.039825 0 -0.0434244" size="0.010887"/>
                </body>
              </body>
            </body>
          </body>
        </body>
      </body>
      <body name="l_hip_pitch_link" pos="0.000691389 0.0349821 -0.0333217" quat="0.992267 -0.00080175 -0.124113 0.000834805">
        <inertial pos="0.0023962 0.0902455 -0.00533819" quat="-0.0295176 0.706851 0.0275757 0.706208" mass="0.46889" diaginertia="3.59449e-05 0.000757207 8.86289e-05"/>
        <joint name="l_hip_pitch_joint" class="/" pos="0 0 0" axis="0.00355556 0.99996 0.0082354" range="-1.22184 1.73457" armature="0.0104861" damping="0.0462706" frictionloss="0.00727802"/>
        <geom name="//unnamed_geom_22" class="/" type="mesh" density="0" rgba="0.75294 0.75294 0.75294 1" mesh="l_hip_pitch_link"/>
        <geom name="//unnamed_geom_23" class="/" size="0.000544348 0.000544348 0.000544348" type="box" rgba="0.75294 0.75294 0.75294 1"/>
        <body name="l_hip_roll_link" pos="0.00599704 0.085016 0.011035" quat="1 6.87903e-05 -0.000174599 0.000508796">
          <inertial pos="0.0025423 -0.000563077 -0.0490348" quat="0.7083 -0.0506309 -0.0724509 0.700356" mass="0.407864" diaginertia="9.49199e-05 0.00192885 0.00011448"/>
          <joint name="l_hip_roll_joint" class="/" pos="0 0 0" axis="-0.999132 -0.0272847 0.0314788" stiffness="0.0101439" range="-0.283333 0.0888888" armature="0.00616654" damping="0.00672861" frictionloss="0.00926779"/>
          <geom name="//unnamed_geom_24" class="/" type="mesh" density="0" rgba="0.75294 0.75294 0.75294 1" mesh="l_hip_roll_link"/>
          <geom name="//unnamed_geom_25" class="/" size="0.000544348 0.000544348 0.000544348" type="box" rgba="0.75294 0.75294 0.75294 1"/>
          <geom name="//unnamed_geom_26" class="reward_collision_sphere" size="0.0435478"/>
          <body name="l_thigh_link" pos="0.00561907 0.012312 -0.0732679" quat="1 0.000425358 0.000445822 -0.00019953">
            <inertial pos="-0.000131886 -0.00297869 -0.0474652" quat="0.672983 0.739631 0.00616885 -0.0011525" mass="0.125001" diaginertia="2.96689e-05 0.000651598 5.04756e-05"/>
            <joint name="l_thigh_joint" class="/" pos="0 0 0" axis="0.00296289 0.00280143 -0.999992" range="-0.599187 0.305875" armature="0.0140934" damping="0" frictionloss="0.0106489"/>
            <geom name="//unnamed_geom_27" class="/" type="mesh" density="0" rgba="0.75294 0.75294 0.75294 1" mesh="l_thigh_link"/>
            <geom name="//unnamed_geom_28" class="/" size="0.000544348 0.000544348 0.000544348" type="box" rgba="0.75294 0.75294 0.75294 1"/>
            <body name="l_calf_link" pos="-0.0027361 0.00175032 -0.0674416" quat="0.946851 0.00326068 0.321648 0.00225068">
              <inertial pos="-0.00133735 -0.00338391 -0.0624013" quat="0.999938 0.00696763 0.00382317 0.00779567" mass="0.997129" diaginertia="0.000861065 0.0237185 0.000132362"/>
              <joint name="l_calf_joint" class="/" pos="0 0 0" axis="0.0310729 0.999486 0.00789926" stiffness="0.0124359" range="-0.670803 1.71945" armature="0.00999569" damping="0" frictionloss="0.00943464"/>
              <geom name="//unnamed_geom_29" class="/" type="mesh" density="0" rgba="0.75294 0.75294 0.75294 1" mesh="l_calf_link"/>
              <geom name="//unnamed_geom_30" class="/" size="0.000544348 0.000544348 0.000544348" type="box" rgba="0.75294 0.75294 0.75294 1"/>
              <geom name="//unnamed_geom_31" class="reward_collision_sphere" size="0.0435478"/>
              <body name="l_ankle_pitch_link" pos="0.00222562 -0.00698739 -0.142114" quat="0.979764 0.000366044 -0.2001 -0.0047624">
                <inertial pos="0.00301108 0.00899199 -0.00565539" quat="-0.00594886 0.705766 0.00112248 0.708419" mass="0.247697" diaginertia="9.69445e-05 0.00182993 0.000120258"/>
                <joint name="l_ankle_pitch_joint" class="/" pos="0 0 0" axis="0.0197294 0.999802 -0.00252326" stiffness="0.0133227" range="-0.341835 1.18046" armature="0.0112958" damping="0" frictionloss="0.0109259"/>
                <geom name="//unnamed_geom_32" class="/" type="mesh" density="0" rgba="0.75294 0.75294 0.75294 1" mesh="l_ankle_pitch_link"/>
                <geom name="//unnamed_geom_33" class="/" size="0.0424591 0.0435478 0.0272174" type="box" rgba="0.75294 0.75294 0.75294 1"/>
                <body name="l_ankle_roll_link" pos="0.0717361 -0.000840777 -0.00641648" quat="0.999998 -0.00171738 -0.000734431 0.000864893">
                  <inertial pos="-0.0312678 -0.000685306 -0.0124672" quat="0.547527 0.437303 0.435083 0.565406" mass="0.671247" diaginertia="0.000291783 0.00812895 0.000268097"/>
                  <joint name="l_ankle_roll_joint" class="/" pos="0 0 0" axis="-0.998232 -0.0582357 0.0119179" stiffness="0.0170641" range="-0.388487 0.306476" armature="0.00554443" damping="0" frictionloss="0.0159076"/>
                  <geom name="//unnamed_geom_34" class="/" type="mesh" density="0" rgba="0.75294 0.75294 0.75294 1" mesh="l_ankle_roll_link"/>
                  <geom name="//unnamed_geom_35" class="/" type="mesh" rgba="0.75294 0.75294 0.75294 1" mesh="l_ankle_roll_link"/>
                  <geom name="left_foot" class="foot" size="0.101127 0.0251438 0.00506812" pos="-0.039825 0 -0.0434244"/>
                  <geom name="//unnamed_geom_37" class="reward_collision_sphere" size="0.0435478" pos="-0.0390441 0 -0.0197383"/>
                  <geom name="//unnamed_geom_38" class="reward_collision_sphere" size="0.0217739" pos="0.0117132 -0.0299657 -0.0394767"/>
                  <geom name="//unnamed_geom_39" class="reward_collision_sphere" size="0.0217739" pos="-0.0937059 -0.0299657 -0.0394767"/>
                  <site name="left_foot" class="foot" pos="-0.039825 0 -0.0434244" size="0.010887"/>
                </body>
              </body>
            </body>
          </body>
        </body>
      </body>
    </body>
  </worldbody>

  <contact>
    <pair class="/" geom1="floor" geom2="right_foot" name="//unnamed_contact_1"/>
    <pair class="/" geom1="floor" geom2="left_foot" name="//unnamed_contact_0"/>
  </contact>

  <actuator>
    <general name="r_hip_pitch_joint" class="/" joint="r_hip_pitch_joint" forcerange="-24.228 24.228" gainprm="24.8584" biasprm="0 -24.8584 -0.58556"/>
    <general name="r_hip_roll_joint" class="/" joint="r_hip_roll_joint" forcerange="-23.3155 23.3155" gainprm="24.8584" biasprm="0 -24.8584 -0.58556"/>
    <general name="r_thigh_joint" class="/" joint="r_thigh_joint" forcerange="-17.1551 17.1551" gainprm="24.8584" biasprm="0 -24.8584 -0.58556"/>
    <general name="r_calf_joint" class="/" joint="r_calf_joint" forcerange="-31.1597 31.1597" gainprm="24.8584" biasprm="0 -24.8584 -0.58556"/>
    <general name="r_ankle_pitch_joint" class="/" joint="r_ankle_pitch_joint" forcerange="-13.6744 13.6744" gainprm="24.8584" biasprm="0 -24.8584 -0.58556"/>
    <general name="r_ankle_roll_joint" class="/" joint="r_ankle_roll_joint" forcerange="-13.5964 13.5964" gainprm="24.8584" biasprm="0 -24.8584 -0.58556"/>
    <general name="l_hip_pitch_joint" class="/" joint="l_hip_pitch_joint" forcerange="-12.236 12.236" gainprm="24.8584" biasprm="0 -24.8584 -0.58556"/>
    <general name="l_hip_roll_joint" class="/" joint="l_hip_roll_joint" forcerange="-28.5921 28.5921" gainprm="24.8584" biasprm="0 -24.8584 -0.58556"/>
    <general name="l_thigh_joint" class="/" joint="l_thigh_joint" forcerange="-24.6382 24.6382" gainprm="24.8584" biasprm="0 -24.8584 -0.58556"/>
    <general name="l_calf_joint" class="/" joint="l_calf_joint" forcerange="-13.6602 13.6602" gainprm="24.8584" biasprm="0 -24.8584 -0.58556"/>
    <general name="l_ankle_pitch_joint" class="/" joint="l_ankle_pitch_joint" forcerange="-13.6281 13.6281" gainprm="24.8584" biasprm="0 -24.8584 -0.58556"/>
    <general name="l_ankle_roll_joint" class="/" joint="l_ankle_roll_joint" forcerange="-17.2986 17.2986" gainprm="24.8584" biasprm="0 -24.8584 -0.58556"/>
  </actuator>

  <sensor>
    <gyro site="imu" name="imu_angular_velocity"/>
    <velocimeter site="imu" name="imu_linear_velocity"/>
    <framelinvel objtype="site" objname="left_foot" name="left_foot_global_linear_velocity"/>
    <framelinvel objtype="site" objname="right_foot" name="right_foot_global_linear_velocity"/>
  </sensor>

  <keyframe>
    <key name="home" qpos="0 0 0.291 1 0 0 0 0.4 0 0 -0.8 0.4 0 -0.4 0 0 0.8 -0.4 0"/>
  </keyframe>
</mujoco>
