<mujoco model="pi_12dof_release_v1">
  <compiler angle="radian" assetdir="assets" balanceinertia="true" inertiafromgeom="false"/>

  <option timestep="0.005" density="1.2" viscosity="2e-05"/>

  <size nkey="1"/>

  <visual>
    <quality shadowsize="8192"/>
    <map shadowclip="0.5"/>
  </visual>

  <default>
    <default class="/">
      <joint armature="0.01" damping="0.01" frictionloss="0.01"/>
      <geom contype="0" conaffinity="0" group="1" solref="-1000 -80"/>
      <site size="0.01 0.005 0.005" group="5"/>
      <general forcelimited="true" biastype="affine" gainprm="20" biasprm="0 -20 -0.5"/>
      <default class="foot">
        <geom size="0.0845 0.036 0.005" type="box" condim="6" group="4" priority="1" friction="0.9 0.2 0.2" solimp="0.015 1 0.005"/>
      </default>
      <default class="reward_collision_sphere">
        <geom group="5" rgba="1 0 0 1"/>
      </default>
    </default>
  </default>

  <asset>
    <texture type="skybox" colorspace="auto" name="//unnamed_texture_0" builtin="gradient" rgb1="0.95 0.95 0.95" rgb2="0.95 0.95 0.95" width="100" height="600"/>
    <texture type="2d" colorspace="auto" name="texplane" builtin="checker" rgb1="0.345 0.575 0.748" rgb2="0.345 0.575 0.748" markrgb="1 1 1" width="512" height="512"/>
    <material name="MatPlane" class="/" texture="texplane" texuniform="true" texrepeat="2 2" specular="0.9"/>
    <mesh name="baselink_1" class="/" file="baselink_1.STL"/>
    <mesh name="r_hip_pitch_link" class="/" file="r_hip_pitch_link.STL"/>
    <mesh name="r_hip_roll_link" class="/" file="r_hip_roll_link.STL"/>
    <mesh name="r_thigh_link" class="/" file="r_thigh_link.STL"/>
    <mesh name="r_calf_link" class="/" file="r_calf_link.STL"/>
    <mesh name="r_ankle_pitch_link" class="/" file="r_ankle_pitch_link.STL"/>
    <mesh name="r_ankle_roll_link" class="/" file="r_ankle_roll_link.STL"/>
    <mesh name="l_hip_pitch_link" class="/" file="l_hip_pitch_link.STL"/>
    <mesh name="l_hip_roll_link" class="/" file="l_hip_roll_link.STL"/>
    <mesh name="l_thigh_link" class="/" file="l_thigh_link.STL"/>
    <mesh name="l_calf_link" class="/" file="l_calf_link.STL"/>
    <mesh name="l_ankle_pitch_link" class="/" file="l_ankle_pitch_link.STL"/>
    <mesh name="l_ankle_roll_link" class="/" file="l_ankle_roll_link.STL"/>
  </asset>

  <worldbody>
    <geom name="floor" class="/" size="100 100 0.125" type="plane" group="0" material="MatPlane"/>
    <light name="toplight_shadow" class="/" pos="0 0 5" dir="0.0990148 0.0990148 -0.990148" type="directional" ambient="0.04 0.04 0.04" diffuse="0.55 0.55 0.55" specular="0.12 0.12 0.12"/>
    <light name="toplight_fill" class="/" pos="0 0 5" dir="0.0990148 0.0990148 -0.990148" type="directional" castshadow="false" ambient="0.04 0.04 0.04" diffuse="0.3 0.3 0.3" specular="0.08 0.08 0.08"/>
    <body name="trunk" pos="-0.000215598 -0.000849057 0.000507942" quat="1 -3.22883e-07 -1.76315e-06 8.1844e-06">
      <inertial pos="0.00139961 -0.00194172 0.0455202" quat="0.699255 0.0170716 0.0169085 0.714468" mass="2.06567" diaginertia="0.0128619 0.00252288 0.00769795"/>
      <joint name="//unnamed_joint_0" type="free"/>
      <geom name="//unnamed_geom_1" class="/" type="mesh" density="0" rgba="1 1 1 1" mesh="baselink_1"/>
      <geom name="//unnamed_geom_2" class="/" size="0.0493291 0.0493291 0.0493291" pos="0 0 0.0905118" type="box" rgba="1 1 1 1"/>
      <geom name="//unnamed_geom_3" class="reward_collision_sphere" size="0.054262" pos="0 0 0.0791978"/>
      <site name="imu" class="/" pos="0.00341244 -0.00235912 -0.00419183" size="0.00986582"/>
      <camera name="track" class="/" pos="0 -1.54779 0" quat="0.707107 0.707107 0 0" mode="trackcom"/>
      <camera name="ego_camera" class="/" pos="0.0790842 0 0.203652" quat="-0.5 -0.5 0.5 0.5"/>
      <body name="r_hip_pitch_link" pos="2.47431e-05 -0.0152066 -0.0352518" quat="0.99222 0.000256928 -0.124493 0.000329376">
        <inertial pos="0.000698059 -0.0435841 -0.000417292" quat="-0.0195792 0.707526 -0.0267583 0.705909" mass="0.353128" diaginertia="0.000141354 2.69852e-05 0.000155165"/>
        <joint name="r_hip_pitch_joint" class="/" pos="0 0 0" axis="0.0056801 -0.999979 -0.0031986" stiffness="0.000431998" range="-1.74458 1.2596" armature="0.00969644" damping="0.0144324" frictionloss="0.0101159"/>
        <geom name="//unnamed_geom_4" class="/" type="mesh" density="0" rgba="0.75294 0.75294 0.75294 1" mesh="r_hip_pitch_link"/>
        <geom name="//unnamed_geom_5" class="/" size="0.000493291 0.000493291 0.000493291" type="box" rgba="0.75294 0.75294 0.75294 1"/>
        <body name="r_hip_roll_link" pos="0.00120114 -0.0406821 -0.000165591" quat="1 -5.19766e-05 -0.000232906 0.00013939">
          <inertial pos="-0.00032499 -0.000499382 -0.0687603" quat="0.710157 -0.078927 -0.0864079 0.694249" mass="0.373617" diaginertia="0.000439027 7.7131e-05 0.000240881"/>
          <joint name="r_hip_roll_joint" class="/" pos="0 0 0" axis="-1 0.00045827 -0.000392242" stiffness="0.00224267" range="-0.11471 0.519836" armature="0.0097705" damping="0.00550469" frictionloss="0.00971985"/>
          <geom name="//unnamed_geom_6" class="/" type="mesh" density="0" rgba="0.75294 0.75294 0.75294 1" mesh="r_hip_roll_link"/>
          <geom name="//unnamed_geom_7" class="/" size="0.000493291 0.000493291 0.000493291" type="box" rgba="0.75294 0.75294 0.75294 1"/>
          <geom name="//unnamed_geom_8" class="reward_collision_sphere" size="0.0394633"/>
          <body name="r_thigh_link" pos="0.000537543 -0.00116099 -0.0782049" quat="1 3.5389e-05 -4.63824e-05 -0.000175259">
            <inertial pos="0.00082368 0.000669152 -0.0559362" quat="0.737703 0.675125 0.000108995 0.000920973" mass="0.107791" diaginertia="0.000161759 2.70102e-05 0.00010476"/>
            <joint name="r_thigh_joint" class="/" pos="0 0 0" axis="0.00105439 0.00170578 -0.999998" range="-0.308292 0.595422" armature="0.0103387" damping="0.0067465" frictionloss="0.00979103"/>
            <geom name="//unnamed_geom_9" class="/" type="mesh" density="0" rgba="0.75294 0.75294 0.75294 1" mesh="r_thigh_link"/>
            <geom name="//unnamed_geom_10" class="/" size="0.000493291 0.000493291 0.000493291" type="box" rgba="0.75294 0.75294 0.75294 1"/>
            <body name="r_calf_link" pos="-0.000236252 -0.000818699 -0.0794454" quat="0.947688 6.76854e-05 0.3192 -7.2215e-05">
              <inertial pos="0.000675967 -0.00124304 -0.079419" quat="0.999979 -0.00411639 -0.000112451 0.00497693" mass="0.770821" diaginertia="0.00466713 0.000948027 0.000329626"/>
              <joint name="r_calf_joint" class="/" pos="0 0 0" axis="0.00114103 -0.999999 5.4497e-05" range="-1.60332 0.634619" armature="0.01013" damping="0.00919026" frictionloss="0.00947944"/>
              <geom name="//unnamed_geom_11" class="/" type="mesh" density="0" rgba="0.75294 0.75294 0.75294 1" mesh="r_calf_link"/>
              <geom name="//unnamed_geom_12" class="/" size="0.000493291 0.000493291 0.000493291" type="box" rgba="0.75294 0.75294 0.75294 1"/>
              <geom name="//unnamed_geom_13" class="reward_collision_sphere" size="0.0394633"/>
              <body name="r_ankle_pitch_link" pos="0.00240718 0.00275686 -0.159257" quat="0.9801 -0.00024071 -0.198505 -0.00043905">
                <inertial pos="0.00571082 0.000543019 -0.00064682" quat="0.00341407 0.707287 -0.00152034 0.706916" mass="0.172392" diaginertia="0.000409502 6.25216e-05 0.000228417"/>
                <joint name="r_ankle_pitch_joint" class="/" pos="0 0 0" axis="-0.00910375 -0.999935 -0.00686064" stiffness="0.000375674" range="-1.3153 0.540295" armature="0.00990635" damping="0.00976177" frictionloss="0.0103682"/>
                <geom name="//unnamed_geom_14" class="/" type="mesh" density="0" rgba="0.75294 0.75294 0.75294 1" mesh="r_ankle_pitch_link"/>
                <geom name="//unnamed_geom_15" class="/" size="0.0384767 0.0394633 0.0246646" type="box" rgba="0.75294 0.75294 0.75294 1"/>
                <body name="r_ankle_roll_link" pos="0.0783578 0.00220402 -0.000311819" quat="1 -0.00014749 -0.000741283 0.000176924">
                  <inertial pos="-0.0262249 -5.79621e-05 -0.0161816" quat="0.560405 0.429816 0.434441 0.558986" mass="0.500561" diaginertia="0.00146789 0.000286258 0.000518592"/>
                  <joint name="r_ankle_roll_joint" class="/" pos="0 0 0" axis="-1 0.000359296 5.13162e-05" range="-0.19396 0.147196" armature="0.00979426" damping="0.0135784" frictionloss="0.0102217"/>
                  <geom name="//unnamed_geom_16" class="/" type="mesh" density="0" rgba="0.75294 0.75294 0.75294 1" mesh="r_ankle_roll_link"/>
                  <geom name="//unnamed_geom_17" class="/" type="mesh" rgba="0.75294 0.75294 0.75294 1" mesh="r_ankle_roll_link"/>
                  <geom name="right_foot" class="foot" size="0.0799992 0.0340522 0.00459185" pos="-0.0537773 0 -0.0497815"/>
                  <geom name="//unnamed_geom_19" class="reward_collision_sphere" size="0.0394633" pos="-0.0527228 0 -0.0226279"/>
                  <geom name="//unnamed_geom_20" class="reward_collision_sphere" size="0.0197316" pos="0.0158168 0.0154779 -0.0452559"/>
                  <geom name="//unnamed_geom_21" class="reward_collision_sphere" size="0.0197316" pos="-0.126535 0.0154779 -0.0452559"/>
                  <site name="right_foot" class="foot" pos="-0.0537773 0 -0.0497815" size="0.00986582"/>
                </body>
              </body>
            </body>
          </body>
        </body>
      </body>
      <body name="l_hip_pitch_link" pos="-0.000887633 0.0176634 -0.0366318" quat="0.99218 0.000455451 -0.124814 0.000137084">
        <inertial pos="0.000625293 0.0402417 -0.00114491" quat="-0.0365783 0.704686 0.0265076 0.70808" mass="0.365827" diaginertia="0.000165444 2.88303e-05 0.000184111"/>
        <joint name="l_hip_pitch_joint" class="/" pos="0 0 0" axis="0.0014927 0.999998 -0.00139855" stiffness="0.000834633" range="-1.24565 1.75371" armature="0.00978294" damping="0" frictionloss="0.00993579"/>
        <geom name="//unnamed_geom_22" class="/" type="mesh" density="0" rgba="0.75294 0.75294 0.75294 1" mesh="l_hip_pitch_link"/>
        <geom name="//unnamed_geom_23" class="/" size="0.000493291 0.000493291 0.000493291" type="box" rgba="0.75294 0.75294 0.75294 1"/>
        <body name="l_hip_roll_link" pos="0.000491894 0.0434305 -0.00195307" quat="1 -8.18663e-06 -2.4476e-05 -0.000112374">
          <inertial pos="-0.000928336 -0.000564445 -0.0711902" quat="0.698422 -0.0740911 -0.0770426 0.70766" mass="0.379157" diaginertia="0.000432158 7.51205e-05 0.000233691"/>
          <joint name="l_hip_roll_joint" class="/" pos="0 0 0" axis="-0.999998 -0.00191386 -5.8969e-05" range="-0.54048 0.111661" armature="0.0104053" damping="0.00646843" frictionloss="0.00936218"/>
          <geom name="//unnamed_geom_24" class="/" type="mesh" density="0" rgba="0.75294 0.75294 0.75294 1" mesh="l_hip_roll_link"/>
          <geom name="//unnamed_geom_25" class="/" size="0.000493291 0.000493291 0.000493291" type="box" rgba="0.75294 0.75294 0.75294 1"/>
          <geom name="//unnamed_geom_26" class="reward_collision_sphere" size="0.0394633"/>
          <body name="l_thigh_link" pos="0.000100101 -0.00265749 -0.0781723" quat="1 -0.000160651 8.28783e-06 0.000156376">
            <inertial pos="0.000469304 -0.00151696 -0.0532312" quat="0.675691 0.737185 0.000367502 -0.000237263" mass="0.107557" diaginertia="0.000165422 2.61392e-05 0.00010678"/>
            <joint name="l_thigh_joint" class="/" pos="0 0 0" axis="4.48909e-05 1.44127e-05 -1" range="-0.592089 0.29715" armature="0.00995286" damping="0.00212053" frictionloss="0.00991789"/>
            <geom name="//unnamed_geom_27" class="/" type="mesh" density="0" rgba="0.75294 0.75294 0.75294 1" mesh="l_thigh_link"/>
            <geom name="//unnamed_geom_28" class="/" size="0.000493291 0.000493291 0.000493291" type="box" rgba="0.75294 0.75294 0.75294 1"/>
            <body name="l_calf_link" pos="-0.000842631 8.55324e-05 -0.0786789" quat="0.94783 -0.000270872 0.318777 0.000219645">
              <inertial pos="-0.000461883 0.00355581 -0.0798666" quat="0.999968 0.00431709 0.000739009 0.00669879" mass="0.776821" diaginertia="0.00460465 0.00095364 0.000329361"/>
              <joint name="l_calf_joint" class="/" pos="0 0 0" axis="0.000239317 1 0.000452683" range="-0.656311 1.67273" armature="0.00943" damping="0.00476558" frictionloss="0.00937577"/>
              <geom name="//unnamed_geom_29" class="/" type="mesh" density="0" rgba="0.75294 0.75294 0.75294 1" mesh="l_calf_link"/>
              <geom name="//unnamed_geom_30" class="/" size="0.000493291 0.000493291 0.000493291" type="box" rgba="0.75294 0.75294 0.75294 1"/>
              <geom name="//unnamed_geom_31" class="reward_collision_sphere" size="0.0394633"/>
              <body name="l_ankle_pitch_link" pos="-0.000215226 0.0020213 -0.158893" quat="0.980044 -0.000304914 -0.198781 -0.00087333">
                <inertial pos="0.00528709 -0.0023108 -0.000658978" quat="-0.00136463 0.706981 0.00129365 0.70723" mass="0.169637" diaginertia="0.000405019 6.16254e-05 0.000222807"/>
                <joint name="l_ankle_pitch_joint" class="/" pos="0 0 0" axis="-0.00222814 0.999996 0.00168083" stiffness="0.00231668" range="-0.530084 1.30497" armature="0.0101281" damping="0.00511197" frictionloss="0.00983936"/>
                <geom name="//unnamed_geom_32" class="/" type="mesh" density="0" rgba="0.75294 0.75294 0.75294 1" mesh="l_ankle_pitch_link"/>
                <geom name="//unnamed_geom_33" class="/" size="0.0384767 0.0394633 0.0246646" type="box" rgba="0.75294 0.75294 0.75294 1"/>
                <body name="l_ankle_roll_link" pos="0.0769909 -0.00139996 0.000352592" quat="1 9.45248e-05 0.000166287 -0.000422777">
                  <inertial pos="-0.0234551 -0.000199468 -0.0154331" quat="0.556871 0.429821 0.433709 0.563067" mass="0.494931" diaginertia="0.00150464 0.000288373 0.000522863"/>
                  <joint name="l_ankle_roll_joint" class="/" pos="0 0 0" axis="-0.999928 -0.0101076 0.00641953" range="-0.109238 0.140047" armature="0.010783" damping="0.0188785" frictionloss="0.00917379"/>
                  <geom name="//unnamed_geom_34" class="/" type="mesh" density="0" rgba="0.75294 0.75294 0.75294 1" mesh="l_ankle_roll_link"/>
                  <geom name="//unnamed_geom_35" class="/" type="mesh" rgba="0.75294 0.75294 0.75294 1" mesh="l_ankle_roll_link"/>
                  <geom name="left_foot" class="foot" size="0.0866434 0.0400684 0.00490665" pos="-0.0537773 0 -0.0497815"/>
                  <geom name="//unnamed_geom_37" class="reward_collision_sphere" size="0.0394633" pos="-0.0527228 0 -0.0226279"/>
                  <geom name="//unnamed_geom_38" class="reward_collision_sphere" size="0.0197316" pos="0.0158168 -0.0154779 -0.0452559"/>
                  <geom name="//unnamed_geom_39" class="reward_collision_sphere" size="0.0197316" pos="-0.126535 -0.0154779 -0.0452559"/>
                  <site name="left_foot" class="foot" pos="-0.0537773 0 -0.0497815" size="0.00986582"/>
                </body>
              </body>
            </body>
          </body>
        </body>
      </body>
    </body>
  </worldbody>

  <contact>
    <pair class="/" geom1="floor" geom2="right_foot" name="//unnamed_contact_1"/>
    <pair class="/" geom1="floor" geom2="left_foot" name="//unnamed_contact_0"/>
  </contact>

  <actuator>
    <general name="r_hip_pitch_joint" class="/" joint="r_hip_pitch_joint" forcerange="-21.2354 21.2354" gainprm="19.9583" biasprm="0 -19.9583 -0.490336"/>
    <general name="r_hip_roll_joint" class="/" joint="r_hip_roll_joint" forcerange="-20.6376 20.6376" gainprm="19.9583" biasprm="0 -19.9583 -0.490336"/>
    <general name="r_thigh_joint" class="/" joint="r_thigh_joint" forcerange="-20.9512 20.9512" gainprm="19.9583" biasprm="0 -19.9583 -0.490336"/>
    <general name="r_calf_joint" class="/" joint="r_calf_joint" forcerange="-19.444 19.444" gainprm="19.9583" biasprm="0 -19.9583 -0.490336"/>
    <general name="r_ankle_pitch_joint" class="/" joint="r_ankle_pitch_joint" forcerange="-22.2059 22.2059" gainprm="19.9583" biasprm="0 -19.9583 -0.490336"/>
    <general name="r_ankle_roll_joint" class="/" joint="r_ankle_roll_joint" forcerange="-22.2203 22.2203" gainprm="19.9583" biasprm="0 -19.9583 -0.490336"/>
    <general name="l_hip_pitch_joint" class="/" joint="l_hip_pitch_joint" forcerange="-22.5681 22.5681" gainprm="19.9583" biasprm="0 -19.9583 -0.490336"/>
    <general name="l_hip_roll_joint" class="/" joint="l_hip_roll_joint" forcerange="-20.6093 20.6093" gainprm="19.9583" biasprm="0 -19.9583 -0.490336"/>
    <general name="l_thigh_joint" class="/" joint="l_thigh_joint" forcerange="-21.4141 21.4141" gainprm="19.9583" biasprm="0 -19.9583 -0.490336"/>
    <general name="l_calf_joint" class="/" joint="l_calf_joint" forcerange="-22.2399 22.2399" gainprm="19.9583" biasprm="0 -19.9583 -0.490336"/>
    <general name="l_ankle_pitch_joint" class="/" joint="l_ankle_pitch_joint" forcerange="-22.2265 22.2265" gainprm="19.9583" biasprm="0 -19.9583 -0.490336"/>
    <general name="l_ankle_roll_joint" class="/" joint="l_ankle_roll_joint" forcerange="-20.7588 20.7588" gainprm="19.9583" biasprm="0 -19.9583 -0.490336"/>
  </actuator>

  <sensor>
    <gyro site="imu" name="imu_angular_velocity"/>
    <velocimeter site="imu" name="imu_linear_velocity"/>
    <framelinvel objtype="site" objname="left_foot" name="left_foot_global_linear_velocity"/>
    <framelinvel objtype="site" objname="right_foot" name="right_foot_global_linear_velocity"/>
  </sensor>

  <keyframe>
    <key name="home" qpos="0 0 0.291 1 0 0 0 0.4 0 0 -0.8 0.4 0 -0.4 0 0 0.8 -0.4 0"/>
  </keyframe>
</mujoco>
