<mujoco model="pi_12dof_release_v1">
  <compiler angle="radian" assetdir="assets" balanceinertia="true" inertiafromgeom="false"/>

  <option timestep="0.005" density="1.2" viscosity="2e-05"/>

  <size nkey="1"/>

  <visual>
    <quality shadowsize="8192"/>
    <map shadowclip="0.5"/>
  </visual>

  <default>
    <default class="/">
      <joint armature="0.01" damping="0.01" frictionloss="0.01"/>
      <geom contype="0" conaffinity="0" group="1" solref="-1000 -80"/>
      <site size="0.01 0.005 0.005" group="5"/>
      <general forcelimited="true" biastype="affine" gainprm="20" biasprm="0 -20 -0.5"/>
      <default class="foot">
        <geom size="0.0845 0.036 0.005" type="box" condim="6" group="4" priority="1" friction="0.9 0.2 0.2" solimp="0.015 1 0.005"/>
      </default>
      <default class="reward_collision_sphere">
        <geom group="5" rgba="1 0 0 1"/>
      </default>
    </default>
  </default>

  <asset>
    <texture type="skybox" colorspace="auto" name="//unnamed_texture_0" builtin="gradient" rgb1="0.95 0.95 0.95" rgb2="0.95 0.95 0.95" width="100" height="600"/>
    <texture type="2d" colorspace="auto" name="texplane" builtin="checker" rgb1="0.345 0.575 0.748" rgb2="0.345 0.575 0.748" markrgb="1 1 1" width="512" height="512"/>
    <material name="MatPlane" class="/" texture="texplane" texuniform="true" texrepeat="2 2" specular="0.9"/>
    <mesh name="baselink_1" class="/" file="baselink_1.STL"/>
    <mesh name="r_hip_pitch_link" class="/" file="r_hip_pitch_link.STL"/>
    <mesh name="r_hip_roll_link" class="/" file="r_hip_roll_link.STL"/>
    <mesh name="r_thigh_link" class="/" file="r_thigh_link.STL"/>
    <mesh name="r_calf_link" class="/" file="r_calf_link.STL"/>
    <mesh name="r_ankle_pitch_link" class="/" file="r_ankle_pitch_link.STL"/>
    <mesh name="r_ankle_roll_link" class="/" file="r_ankle_roll_link.STL"/>
    <mesh name="l_hip_pitch_link" class="/" file="l_hip_pitch_link.STL"/>
    <mesh name="l_hip_roll_link" class="/" file="l_hip_roll_link.STL"/>
    <mesh name="l_thigh_link" class="/" file="l_thigh_link.STL"/>
    <mesh name="l_calf_link" class="/" file="l_calf_link.STL"/>
    <mesh name="l_ankle_pitch_link" class="/" file="l_ankle_pitch_link.STL"/>
    <mesh name="l_ankle_roll_link" class="/" file="l_ankle_roll_link.STL"/>
  </asset>

  <worldbody>
    <geom name="floor" class="/" size="100 100 0.125" type="plane" group="0" material="MatPlane"/>
    <light name="toplight_shadow" class="/" pos="0 0 5" dir="0.0990148 0.0990148 -0.990148" type="directional" ambient="0.04 0.04 0.04" diffuse="0.55 0.55 0.55" specular="0.12 0.12 0.12"/>
    <light name="toplight_fill" class="/" pos="0 0 5" dir="0.0990148 0.0990148 -0.990148" type="directional" castshadow="false" ambient="0.04 0.04 0.04" diffuse="0.3 0.3 0.3" specular="0.08 0.08 0.08"/>
    <body name="trunk" pos="1.15051e-05 -0.000984615 -6.5574e-05" quat="1 7.76031e-05 -3.25857e-05 -4.03783e-05">
      <inertial pos="0.00495749 -0.000552592 0.0501831" quat="0.698541 0.0166425 0.0189379 0.715126" mass="2.79015" diaginertia="0.00658967 0.0138673 0.0123345"/>
      <joint name="//unnamed_joint_0" type="free"/>
      <geom name="//unnamed_geom_1" class="/" type="mesh" density="0" rgba="1 1 1 1" mesh="baselink_1"/>
      <geom name="//unnamed_geom_2" class="/" size="0.0544479 0.0544479 0.0544479" pos="0 0 0.0994194" type="box" rgba="1 1 1 1"/>
      <geom name="//unnamed_geom_3" class="reward_collision_sphere" size="0.0598927" pos="0 0 0.086992"/>
      <site name="imu" class="/" pos="0.00597053 0.0118107 -0.00497695" size="0.0108896"/>
      <camera name="track" class="/" pos="0 -2.1901 0" quat="0.707107 0.707107 0 0" mode="trackcom"/>
      <camera name="ego_camera" class="/" pos="0.0696812 0 0.223694" quat="-0.5 -0.5 0.5 0.5"/>
      <body name="r_hip_pitch_link" pos="0.00257918 -0.0276021 -0.042077" quat="0.99218 -0.000295355 -0.124811 -9.34149e-05">
        <inertial pos="0.000753021 -0.0608428 0.00251971" quat="-0.0192574 0.706551 -0.0289874 0.706806" mass="0.477099" diaginertia="7.52191e-05 0.000155036 0.000243423"/>
        <joint name="r_hip_pitch_joint" class="/" pos="0 0 0" axis="0.00888582 -0.999942 -0.00610326" range="-1.74727 1.20054" armature="0.0104104" damping="0.0165285" frictionloss="0.00972299"/>
        <geom name="//unnamed_geom_4" class="/" type="mesh" density="0" rgba="0.75294 0.75294 0.75294 1" mesh="r_hip_pitch_link"/>
        <geom name="//unnamed_geom_5" class="/" size="0.000544479 0.000544479 0.000544479" type="box" rgba="0.75294 0.75294 0.75294 1"/>
        <body name="r_hip_roll_link" pos="0.00162589 -0.0643145 -0.000748874" quat="1 -0.000645905 0.000343182 -0.000173422">
          <inertial pos="2.17017e-05 0.00247163 -0.0745113" quat="0.705863 -0.0791747 -0.0824819 0.699061" mass="0.502252" diaginertia="0.000229461 0.000436105 0.000365398"/>
          <joint name="r_hip_roll_joint" class="/" pos="0 0 0" axis="-0.999951 -0.00991515 -5.76918e-05" range="-0.104079 0.507523" armature="0.00981912" damping="0.035337" frictionloss="0.0111657"/>
          <geom name="//unnamed_geom_6" class="/" type="mesh" density="0" rgba="0.75294 0.75294 0.75294 1" mesh="r_hip_roll_link"/>
          <geom name="//unnamed_geom_7" class="/" size="0.000544479 0.000544479 0.000544479" type="box" rgba="0.75294 0.75294 0.75294 1"/>
          <geom name="//unnamed_geom_8" class="reward_collision_sphere" size="0.0435583"/>
          <body name="r_thigh_link" pos="-0.00195864 0.000862036 -0.0873307" quat="0.999999 4.63921e-05 0.00049069 -0.00110596">
            <inertial pos="0.00206467 0.00130808 -0.0572286" quat="0.737285 0.675581 0.000247495 -2.53752e-05" mass="0.144304" diaginertia="8.51653e-05 0.000146615 0.000174518"/>
            <joint name="r_thigh_joint" class="/" pos="0 0 0" axis="-0.00304913 0.0035535 -0.999989" range="-0.333613 0.602132" armature="0.00934852" damping="0.00308435" frictionloss="0.0105425"/>
            <geom name="//unnamed_geom_9" class="/" type="mesh" density="0" rgba="0.75294 0.75294 0.75294 1" mesh="r_thigh_link"/>
            <geom name="//unnamed_geom_10" class="/" size="0.000544479 0.000544479 0.000544479" type="box" rgba="0.75294 0.75294 0.75294 1"/>
            <body name="r_calf_link" pos="0.00242278 -0.00517661 -0.0892989" quat="0.947652 -0.000116591 0.319305 -3.01118e-07">
              <inertial pos="-0.00328187 0.00100773 -0.0847909" quat="0.99998 -0.000505083 0.000412146 0.00627134" mass="1.04939" diaginertia="0.00235555 0.00567044 0.000521152"/>
              <joint name="r_calf_joint" class="/" pos="0 0 0" axis="-0.0077912 -0.999942 -0.00744093" range="-1.69902 0.698304" armature="0.00971972" damping="0.0131455" frictionloss="0.0123073"/>
              <geom name="//unnamed_geom_11" class="/" type="mesh" density="0" rgba="0.75294 0.75294 0.75294 1" mesh="r_calf_link"/>
              <geom name="//unnamed_geom_12" class="/" size="0.000544479 0.000544479 0.000544479" type="box" rgba="0.75294 0.75294 0.75294 1"/>
              <geom name="//unnamed_geom_13" class="reward_collision_sphere" size="0.0435583"/>
              <body name="r_ankle_pitch_link" pos="-0.000637726 -0.00204854 -0.171333" quat="0.979869 -0.000544362 -0.199638 0.000549619">
                <inertial pos="0.0018567 0.00591051 2.60762e-05" quat="-0.00246611 0.713025 0.00309633 0.701128" mass="0.23279" diaginertia="0.000213489 0.000350254 0.000344933"/>
                <joint name="r_ankle_pitch_joint" class="/" pos="0 0 0" axis="-0.00507711 -0.999985 -0.00206108" stiffness="0.00226132" range="-1.24375 0.482085" armature="0.0105364" damping="0.0177185" frictionloss="0.00941795"/>
                <geom name="//unnamed_geom_14" class="/" type="mesh" density="0" rgba="0.75294 0.75294 0.75294 1" mesh="r_ankle_pitch_link"/>
                <geom name="//unnamed_geom_15" class="/" size="0.0424694 0.0435583 0.0272239" type="box" rgba="0.75294 0.75294 0.75294 1"/>
                <body name="r_ankle_roll_link" pos="0.0722569 0.00471744 -0.00150184" quat="1 1.12861e-05 -2.99963e-06 3.03381e-06">
                  <inertial pos="-0.0191159 -0.000449046 -0.0163548" quat="0.552954 0.42745 0.438051 0.565367" mass="0.66712" diaginertia="0.000800309 0.0016278 0.000864463"/>
                  <joint name="r_ankle_roll_joint" class="/" pos="0 0 0" axis="-0.999996 -0.000111055 -0.00298697" stiffness="0.00938809" range="-0.117633 0.138037" armature="0.0109638" damping="0" frictionloss="0.00949523"/>
                  <geom name="//unnamed_geom_16" class="/" type="mesh" density="0" rgba="0.75294 0.75294 0.75294 1" mesh="r_ankle_roll_link"/>
                  <geom name="//unnamed_geom_17" class="/" type="mesh" rgba="0.75294 0.75294 0.75294 1" mesh="r_ankle_roll_link"/>
                  <geom name="right_foot" class="foot" size="0.086663 0.0373888 0.00530901" pos="-0.0473832 0 -0.0546807"/>
                  <geom name="//unnamed_geom_19" class="reward_collision_sphere" size="0.0435583" pos="-0.0464541 0 -0.0248549"/>
                  <geom name="//unnamed_geom_20" class="reward_collision_sphere" size="0.0217792" pos="0.0139362 0.021901 -0.0497097"/>
                  <geom name="//unnamed_geom_21" class="reward_collision_sphere" size="0.0217792" pos="-0.11149 0.021901 -0.0497097"/>
                  <site name="right_foot" class="foot" pos="-0.0473832 0 -0.0546807" size="0.0108896"/>
                </body>
              </body>
            </body>
          </body>
        </body>
      </body>
      <body name="l_hip_pitch_link" pos="0.000387037 0.0255146 -0.0401168" quat="0.992317 -0.000825756 -0.123714 0.000432121">
        <inertial pos="4.94095e-05 0.0590294 0.0024077" quat="-0.0321288 0.712903 0.0271776 0.699999" mass="0.53633" diaginertia="9.23013e-05 0.000170858 0.000309748"/>
        <joint name="l_hip_pitch_joint" class="/" pos="0 0 0" axis="-0.000398896 1 0.00014692" range="-1.24517 1.7622" armature="0.0111816" damping="0.00744713" frictionloss="0.0118694"/>
        <geom name="//unnamed_geom_22" class="/" type="mesh" density="0" rgba="0.75294 0.75294 0.75294 1" mesh="l_hip_pitch_link"/>
        <geom name="//unnamed_geom_23" class="/" size="0.000544479 0.000544479 0.000544479" type="box" rgba="0.75294 0.75294 0.75294 1"/>
        <body name="l_hip_roll_link" pos="-0.00282508 0.0616005 0.00201953" quat="1 0.000527109 -9.26296e-05 0.000252414">
          <inertial pos="-0.00136081 -1.83407e-05 -0.074387" quat="0.702489 -0.076434 -0.0880066 0.702083" mass="0.503631" diaginertia="0.000231733 0.000467333 0.000394092"/>
          <joint name="l_hip_roll_joint" class="/" pos="0 0 0" axis="-0.999993 -0.00378534 0.000288703" range="-0.479888 0.116196" armature="0.0112068" damping="0.00854689" frictionloss="0.0123661"/>
          <geom name="//unnamed_geom_24" class="/" type="mesh" density="0" rgba="0.75294 0.75294 0.75294 1" mesh="l_hip_roll_link"/>
          <geom name="//unnamed_geom_25" class="/" size="0.000544479 0.000544479 0.000544479" type="box" rgba="0.75294 0.75294 0.75294 1"/>
          <geom name="//unnamed_geom_26" class="reward_collision_sphere" size="0.0435583"/>
          <body name="l_thigh_link" pos="-0.00292464 0.00210427 -0.0848736" quat="1 -0.000223709 0.000767714 -0.000245489">
            <inertial pos="0.000915671 -0.00160056 -0.0612363" quat="0.67306 0.739586 0.000563802 -0.00146595" mass="0.15355" diaginertia="8.8856e-05 0.000154457 0.000177352"/>
            <joint name="l_thigh_joint" class="/" pos="0 0 0" axis="-0.00129939 -0.000701327 -0.999999" stiffness="0.00122772" range="-0.585741 0.305608" armature="0.00978701" damping="0.00648716" frictionloss="0.0106307"/>
            <geom name="//unnamed_geom_27" class="/" type="mesh" density="0" rgba="0.75294 0.75294 0.75294 1" mesh="l_thigh_link"/>
            <geom name="//unnamed_geom_28" class="/" size="0.000544479 0.000544479 0.000544479" type="box" rgba="0.75294 0.75294 0.75294 1"/>
            <body name="l_calf_link" pos="0.000149366 0.000463876 -0.0893271" quat="0.947645 -4.92895e-05 0.319327 -1.43423e-05">
              <inertial pos="0.00278998 0.00425034 -0.088569" quat="0.99995 -0.00626356 -0.00501983 0.0059378" mass="1.07038" diaginertia="0.00254541 0.00586353 0.000527298"/>
              <joint name="l_calf_joint" class="/" pos="0 0 0" axis="-0.00212088 0.999929 -0.0117271" range="-0.610506 1.59874" armature="0.0122036" damping="0.0193707" frictionloss="0.0123429"/>
              <geom name="//unnamed_geom_29" class="/" type="mesh" density="0" rgba="0.75294 0.75294 0.75294 1" mesh="l_calf_link"/>
              <geom name="//unnamed_geom_30" class="/" size="0.000544479 0.000544479 0.000544479" type="box" rgba="0.75294 0.75294 0.75294 1"/>
              <geom name="//unnamed_geom_31" class="reward_collision_sphere" size="0.0435583"/>
              <body name="l_ankle_pitch_link" pos="0.000877787 0.00203109 -0.172748" quat="0.980089 0.000197693 -0.19856 -3.74157e-05">
                <inertial pos="0.00418129 -0.00061836 0.00237677" quat="0.00413394 0.711911 0.00203681 0.702255" mass="0.218698" diaginertia="0.000206666 0.000335559 0.000345884"/>
                <joint name="l_ankle_pitch_joint" class="/" pos="0 0 0" axis="0.00638127 0.999973 0.00356157" range="-0.521374 1.34372" armature="0.0109951" damping="0.0184043" frictionloss="0.0109662"/>
                <geom name="//unnamed_geom_32" class="/" type="mesh" density="0" rgba="0.75294 0.75294 0.75294 1" mesh="l_ankle_pitch_link"/>
                <geom name="//unnamed_geom_33" class="/" size="0.0424694 0.0435583 0.0272239" type="box" rgba="0.75294 0.75294 0.75294 1"/>
                <body name="l_ankle_roll_link" pos="0.0726695 0.00462522 0.00016123" quat="0.999999 0.000440922 0.00123307 0.000163612">
                  <inertial pos="-0.0245434 -0.000807941 -0.0206124" quat="0.569687 0.427457 0.42529 0.558449" mass="0.668038" diaginertia="0.00077019 0.00155969 0.000849869"/>
                  <joint name="l_ankle_roll_joint" class="/" pos="0 0 0" axis="-0.999953 -0.00838082 -0.00496914" range="-0.188261 0.128931" armature="0.0104134" damping="0.00371672" frictionloss="0.010796"/>
                  <geom name="//unnamed_geom_34" class="/" type="mesh" density="0" rgba="0.75294 0.75294 0.75294 1" mesh="l_ankle_roll_link"/>
                  <geom name="//unnamed_geom_35" class="/" type="mesh" rgba="0.75294 0.75294 0.75294 1" mesh="l_ankle_roll_link"/>
                  <geom name="left_foot" class="foot" size="0.0825796 0.0390416 0.00553658" pos="-0.0473832 0 -0.0546807"/>
                  <geom name="//unnamed_geom_37" class="reward_collision_sphere" size="0.0435583" pos="-0.0464541 0 -0.0248549"/>
                  <geom name="//unnamed_geom_38" class="reward_collision_sphere" size="0.0217792" pos="0.0139362 -0.021901 -0.0497097"/>
                  <geom name="//unnamed_geom_39" class="reward_collision_sphere" size="0.0217792" pos="-0.11149 -0.021901 -0.0497097"/>
                  <site name="left_foot" class="foot" pos="-0.0473832 0 -0.0546807" size="0.0108896"/>
                </body>
              </body>
            </body>
          </body>
        </body>
      </body>
    </body>
  </worldbody>

  <contact>
    <pair class="/" geom1="floor" geom2="right_foot" name="//unnamed_contact_1"/>
    <pair class="/" geom1="floor" geom2="left_foot" name="//unnamed_contact_0"/>
  </contact>

  <actuator>
    <general name="r_hip_pitch_joint" class="/" joint="r_hip_pitch_joint" forcerange="-20.983 20.983" gainprm="20.5904" biasprm="0 -20.5904 -0.51991"/>
    <general name="r_hip_roll_joint" class="/" joint="r_hip_roll_joint" forcerange="-23.2751 23.2751" gainprm="20.5904" biasprm="0 -20.5904 -0.51991"/>
    <general name="r_thigh_joint" class="/" joint="r_thigh_joint" forcerange="-24.4137 24.4137" gainprm="20.5904" biasprm="0 -20.5904 -0.51991"/>
    <general name="r_calf_joint" class="/" joint="r_calf_joint" forcerange="-23.0047 23.0047" gainprm="20.5904" biasprm="0 -20.5904 -0.51991"/>
    <general name="r_ankle_pitch_joint" class="/" joint="r_ankle_pitch_joint" forcerange="-22.0627 22.0627" gainprm="20.5904" biasprm="0 -20.5904 -0.51991"/>
    <general name="r_ankle_roll_joint" class="/" joint="r_ankle_roll_joint" forcerange="-22.0175 22.0175" gainprm="20.5904" biasprm="0 -20.5904 -0.51991"/>
    <general name="l_hip_pitch_joint" class="/" joint="l_hip_pitch_joint" forcerange="-20.8617 20.8617" gainprm="20.5904" biasprm="0 -20.5904 -0.51991"/>
    <general name="l_hip_roll_joint" class="/" joint="l_hip_roll_joint" forcerange="-21.3738 21.3738" gainprm="20.5904" biasprm="0 -20.5904 -0.51991"/>
    <general name="l_thigh_joint" class="/" joint="l_thigh_joint" forcerange="-20.6621 20.6621" gainprm="20.5904" biasprm="0 -20.5904 -0.51991"/>
    <general name="l_calf_joint" class="/" joint="l_calf_joint" forcerange="-22.0206 22.0206" gainprm="20.5904" biasprm="0 -20.5904 -0.51991"/>
    <general name="l_ankle_pitch_joint" class="/" joint="l_ankle_pitch_joint" forcerange="-22.0099 22.0099" gainprm="20.5904" biasprm="0 -20.5904 -0.51991"/>
    <general name="l_ankle_roll_joint" class="/" joint="l_ankle_roll_joint" forcerange="-24.4654 24.4654" gainprm="20.5904" biasprm="0 -20.5904 -0.51991"/>
  </actuator>

  <sensor>
    <gyro site="imu" name="imu_angular_velocity"/>
    <velocimeter site="imu" name="imu_linear_velocity"/>
    <framelinvel objtype="site" objname="left_foot" name="left_foot_global_linear_velocity"/>
    <framelinvel objtype="site" objname="right_foot" name="right_foot_global_linear_velocity"/>
  </sensor>

  <keyframe>
    <key name="home" qpos="0 0 0.291 1 0 0 0 0.4 0 0 -0.8 0.4 0 -0.4 0 0 0.8 -0.4 0"/>
  </keyframe>
</mujoco>
