<mujoco model="pi_12dof_release_v1">
  <compiler angle="radian" assetdir="assets" balanceinertia="true" inertiafromgeom="false"/>

  <option timestep="0.005" density="1.2" viscosity="2e-05"/>

  <size nkey="1"/>

  <visual>
    <quality shadowsize="8192"/>
    <map shadowclip="0.5"/>
  </visual>

  <default>
    <default class="/">
      <joint armature="0.01" damping="0.01" frictionloss="0.01"/>
      <geom contype="0" conaffinity="0" group="1" solref="-1000 -80"/>
      <site size="0.01 0.005 0.005" group="5"/>
      <general forcelimited="true" biastype="affine" gainprm="20" biasprm="0 -20 -0.5"/>
      <default class="foot">
        <geom size="0.0845 0.036 0.005" type="box" condim="6" group="4" priority="1" friction="0.9 0.2 0.2" solimp="0.015 1 0.005"/>
      </default>
      <default class="reward_collision_sphere">
        <geom group="5" rgba="1 0 0 1"/>
      </default>
    </default>
  </default>

  <asset>
    <texture type="skybox" colorspace="auto" name="//unnamed_texture_0" builtin="gradient" rgb1="0.95 0.95 0.95" rgb2="0.95 0.95 0.95" width="100" height="600"/>
    <texture type="2d" colorspace="auto" name="texplane" builtin="checker" rgb1="0.345 0.575 0.748" rgb2="0.345 0.575 0.748" markrgb="1 1 1" width="512" height="512"/>
    <material name="MatPlane" class="/" texture="texplane" texuniform="true" texrepeat="2 2" specular="0.9"/>
    <mesh name="baselink_1" class="/" file="baselink_1.STL"/>
    <mesh name="r_hip_pitch_link" class="/" file="r_hip_pitch_link.STL"/>
    <mesh name="r_hip_roll_link" class="/" file="r_hip_roll_link.STL"/>
    <mesh name="r_thigh_link" class="/" file="r_thigh_link.STL"/>
    <mesh name="r_calf_link" class="/" file="r_calf_link.STL"/>
    <mesh name="r_ankle_pitch_link" class="/" file="r_ankle_pitch_link.STL"/>
    <mesh name="r_ankle_roll_link" class="/" file="r_ankle_roll_link.STL"/>
    <mesh name="l_hip_pitch_link" class="/" file="l_hip_pitch_link.STL"/>
    <mesh name="l_hip_roll_link" class="/" file="l_hip_roll_link.STL"/>
    <mesh name="l_thigh_link" class="/" file="l_thigh_link.STL"/>
    <mesh name="l_calf_link" class="/" file="l_calf_link.STL"/>
    <mesh name="l_ankle_pitch_link" class="/" file="l_ankle_pitch_link.STL"/>
    <mesh name="l_ankle_roll_link" class="/" file="l_ankle_roll_link.STL"/>
  </asset>

  <worldbody>
    <geom name="floor" class="/" size="100 100 0.125" type="plane" group="0" material="MatPlane"/>
    <light name="toplight_shadow" class="/" pos="0 0 5" dir="0.0990148 0.0990148 -0.990148" type="directional" ambient="0.04 0.04 0.04" diffuse="0.55 0.55 0.55" specular="0.12 0.12 0.12"/>
    <light name="toplight_fill" class="/" pos="0 0 5" dir="0.0990148 0.0990148 -0.990148" type="directional" castshadow="false" ambient="0.04 0.04 0.04" diffuse="0.3 0.3 0.3" specular="0.08 0.08 0.08"/>
    <body name="trunk" pos="0.000314721 -0.000430604 0.00804841" quat="1 -0.000546759 -6.06784e-05 -0.000159387">
      <inertial pos="0.00386184 -0.0118905 0.0465175" quat="0.695642 0.00803667 0.0107671 0.718263" mass="3.82601" diaginertia="0.0422446 0.00398615 0.0218377"/>
      <joint name="//unnamed_joint_0" type="free"/>
      <geom name="//unnamed_geom_1" class="/" type="mesh" density="0" rgba="1 1 1 1" mesh="baselink_1"/>
      <geom name="//unnamed_geom_2" class="/" size="0.0596321 0.0596321 0.0596321" pos="0 0 0.110328" type="box" rgba="1 1 1 1"/>
      <geom name="//unnamed_geom_3" class="reward_collision_sphere" size="0.0655953" pos="0 0 0.0965371"/>
      <site name="imu" class="/" pos="-0.0177247 0.0302154 -0.0195586" size="0.0119264"/>
      <camera name="track" class="/" pos="0 -1.67623 0" quat="0.707107 0.707107 0 0" mode="trackcom"/>
      <camera name="ego_camera" class="/" pos="0.102053 0 0.248238" quat="-0.5 -0.5 0.5 0.5"/>
      <body name="r_hip_pitch_link" pos="0.00262995 -0.0125091 -0.0458694" quat="0.992131 0.000124001 -0.125198 -0.00105705">
        <inertial pos="0.0114513 -0.0478081 0.00536424" quat="-0.0205993 0.703873 -0.0290843 0.709432" mass="0.669431" diaginertia="0.00052177 4.50386e-05 0.000395237"/>
        <joint name="r_hip_pitch_joint" class="/" pos="0 0 0" axis="0.0346737 -0.998263 -0.0476389" range="-1.72607 1.40175" armature="0.0156939" damping="0.0375915" frictionloss="0.0170606"/>
        <geom name="//unnamed_geom_4" class="/" type="mesh" density="0" rgba="0.75294 0.75294 0.75294 1" mesh="r_hip_pitch_link"/>
        <geom name="//unnamed_geom_5" class="/" size="0.000596321 0.000596321 0.000596321" type="box" rgba="0.75294 0.75294 0.75294 1"/>
        <body name="r_hip_roll_link" pos="0.00447249 -0.0468089 -0.00495316" quat="1 0.000159256 -0.000114767 0.000363615">
          <inertial pos="-0.00229592 -0.00201209 -0.0779409" quat="0.702896 -0.0810825 -0.0812608 0.701968" mass="0.726163" diaginertia="0.00151155 0.000115685 0.000840396"/>
          <joint name="r_hip_roll_joint" class="/" pos="0 0 0" axis="-0.999062 -0.0430877 0.00422521" stiffness="0.0228749" range="-0.132679 0.490447" armature="0.0124008" damping="0.0738434" frictionloss="0.00818761"/>
          <geom name="//unnamed_geom_6" class="/" type="mesh" density="0" rgba="0.75294 0.75294 0.75294 1" mesh="r_hip_roll_link"/>
          <geom name="//unnamed_geom_7" class="/" size="0.000596321 0.000596321 0.000596321" type="box" rgba="0.75294 0.75294 0.75294 1"/>
          <geom name="//unnamed_geom_8" class="reward_collision_sphere" size="0.0477057"/>
          <body name="r_thigh_link" pos="0.00480939 -0.00780828 -0.104409" quat="0.999984 -0.0027155 0.00496405 -0.000118083">
            <inertial pos="-0.000371511 0.0010419 -0.0678122" quat="0.736429 0.676513 0.00107547 0.000400412" mass="0.221505" diaginertia="0.000574144 4.05536e-05 0.000321782"/>
            <joint name="r_thigh_joint" class="/" pos="0 0 0" axis="-0.0105088 -0.000213311 -0.999945" range="-0.285424 0.75221" armature="0.00608767" damping="0" frictionloss="0.0127611"/>
            <geom name="//unnamed_geom_9" class="/" type="mesh" density="0" rgba="0.75294 0.75294 0.75294 1" mesh="r_thigh_link"/>
            <geom name="//unnamed_geom_10" class="/" size="0.000596321 0.000596321 0.000596321" type="box" rgba="0.75294 0.75294 0.75294 1"/>
            <body name="r_calf_link" pos="-0.00359224 0.004263 -0.0970222" quat="0.948042 -0.00292981 0.318112 -0.00352589">
              <inertial pos="-0.00255092 -0.00163519 -0.0951688" quat="0.999984 0.0031632 0.00325431 0.00331073" mass="1.50821" diaginertia="0.0185201 0.00175339 0.000853381"/>
              <joint name="r_calf_joint" class="/" pos="0 0 0" axis="-0.0280322 -0.997829 0.0595997" range="-1.55698 0.666453" armature="0.012884" damping="0.00921322" frictionloss="0.0135543"/>
              <geom name="//unnamed_geom_11" class="/" type="mesh" density="0" rgba="0.75294 0.75294 0.75294 1" mesh="r_calf_link"/>
              <geom name="//unnamed_geom_12" class="/" size="0.000596321 0.000596321 0.000596321" type="box" rgba="0.75294 0.75294 0.75294 1"/>
              <geom name="//unnamed_geom_13" class="reward_collision_sphere" size="0.0477057"/>
              <body name="r_ankle_pitch_link" pos="-0.0127229 -0.00616334 -0.191557" quat="0.980321 -0.000384398 -0.197408 -0.000460733">
                <inertial pos="0.00738864 0.00347067 -0.000409736" quat="0.00451787 0.707756 0.00427692 0.706429" mass="0.26691" diaginertia="0.00137207 8.12839e-05 0.000491737"/>
                <joint name="r_ankle_pitch_joint" class="/" pos="0 0 0" axis="0.0247471 -0.999663 0.00789448" stiffness="0.0233472" range="-1.1543 0.407365" armature="0.0114861" damping="0" frictionloss="0.00598284"/>
                <geom name="//unnamed_geom_14" class="/" type="mesh" density="0" rgba="0.75294 0.75294 0.75294 1" mesh="r_ankle_pitch_link"/>
                <geom name="//unnamed_geom_15" class="/" size="0.046513 0.0477057 0.029816" type="box" rgba="0.75294 0.75294 0.75294 1"/>
                <body name="r_ankle_roll_link" pos="0.0907514 0.000722698 -0.00595535" quat="1 0.00017491 0.000158243 -0.00063578">
                  <inertial pos="-0.0283399 0.00210682 -0.0324268" quat="0.569577 0.432305 0.425006 0.555035" mass="1.04655" diaginertia="0.0049306 0.000427053 0.00141457"/>
                  <joint name="r_ankle_roll_joint" class="/" pos="0 0 0" axis="-0.999966 -0.00760673 -0.00312719" range="-0.157481 0.173567" armature="0.0116278" damping="0.00207197" frictionloss="0.00423777"/>
                  <geom name="//unnamed_geom_16" class="/" type="mesh" density="0" rgba="0.75294 0.75294 0.75294 1" mesh="r_ankle_roll_link"/>
                  <geom name="//unnamed_geom_17" class="/" type="mesh" rgba="0.75294 0.75294 0.75294 1" mesh="r_ankle_roll_link"/>
                  <geom name="right_foot" class="foot" size="0.0637584 0.0401157 0.00832757" pos="-0.0693962 0 -0.0606804"/>
                  <geom name="//unnamed_geom_19" class="reward_collision_sphere" size="0.0477057" pos="-0.0680355 0 -0.027582"/>
                  <geom name="//unnamed_geom_20" class="reward_collision_sphere" size="0.0238528" pos="0.0204106 0.0167623 -0.055164"/>
                  <geom name="//unnamed_geom_21" class="reward_collision_sphere" size="0.0238528" pos="-0.163285 0.0167623 -0.055164"/>
                  <site name="right_foot" class="foot" pos="-0.0693962 0 -0.0606804" size="0.0119264"/>
                </body>
              </body>
            </body>
          </body>
        </body>
      </body>
      <body name="l_hip_pitch_link" pos="0.00190489 0.011161 -0.0472786" quat="0.992187 6.00167e-05 -0.124758 8.89445e-05">
        <inertial pos="0.00655085 0.0555385 -0.00136828" quat="0.0279855 0.712991 0.0445389 0.699197" mass="0.768906" diaginertia="0.000570011 3.92997e-05 0.000529938"/>
        <joint name="l_hip_pitch_joint" class="/" pos="0 0 0" axis="0.0056273 0.999923 0.0110715" range="-1.42904 1.9745" armature="0.00761148" damping="0" frictionloss="0.0177415"/>
        <geom name="//unnamed_geom_22" class="/" type="mesh" density="0" rgba="0.75294 0.75294 0.75294 1" mesh="l_hip_pitch_link"/>
        <geom name="//unnamed_geom_23" class="/" size="0.000596321 0.000596321 0.000596321" type="box" rgba="0.75294 0.75294 0.75294 1"/>
        <body name="l_hip_roll_link" pos="-0.00347099 0.0577132 0.000535046" quat="0.999996 0.00034672 -0.000472655 0.00282433">
          <inertial pos="0.000620676 0.00808505 -0.0862157" quat="0.693682 -0.0877275 -0.0930932 0.708832" mass="0.630975" diaginertia="0.00135142 0.000105876 0.000512641"/>
          <joint name="l_hip_roll_joint" class="/" pos="0 0 0" axis="-0.999698 -0.0141844 0.0200718" stiffness="0.0146997" range="-0.763674 0.345802" armature="0.0101565" damping="0" frictionloss="0.0119661"/>
          <geom name="//unnamed_geom_24" class="/" type="mesh" density="0" rgba="0.75294 0.75294 0.75294 1" mesh="l_hip_roll_link"/>
          <geom name="//unnamed_geom_25" class="/" size="0.000596321 0.000596321 0.000596321" type="box" rgba="0.75294 0.75294 0.75294 1"/>
          <geom name="//unnamed_geom_26" class="reward_collision_sphere" size="0.0477057"/>
          <body name="l_thigh_link" pos="-0.00891586 -0.00466148 -0.0959715" quat="0.999989 0.00439723 0.00122365 0.00146683">
            <inertial pos="-0.00892361 0.00240873 -0.0579106" quat="0.675097 0.737729 -0.000620526 -0.000107082" mass="0.179067" diaginertia="0.000500884 2.7896e-05 0.000197887"/>
            <joint name="l_thigh_joint" class="/" pos="0 0 0" axis="0.0117652 0.00103596 -0.99993" stiffness="0.00329891" range="-0.65282 0.494916" armature="0.0149678" damping="0" frictionloss="0.0167481"/>
            <geom name="//unnamed_geom_27" class="/" type="mesh" density="0" rgba="0.75294 0.75294 0.75294 1" mesh="l_thigh_link"/>
            <geom name="//unnamed_geom_28" class="/" size="0.000596321 0.000596321 0.000596321" type="box" rgba="0.75294 0.75294 0.75294 1"/>
            <body name="l_calf_link" pos="-0.00218545 -0.00900402 -0.0963258" quat="0.949076 0.00114826 0.315038 -0.00221054">
              <inertial pos="-0.00138777 -0.00217415 -0.0913238" quat="0.997762 0.0112889 -0.0648601 0.0117317" mass="1.55421" diaginertia="0.0163773 0.00168618 0.000943462"/>
              <joint name="l_calf_joint" class="/" pos="0 0 0" axis="-0.00557486 0.999958 0.00729573" range="-0.689244 1.75736" armature="0.0111024" damping="0" frictionloss="0.0161746"/>
              <geom name="//unnamed_geom_29" class="/" type="mesh" density="0" rgba="0.75294 0.75294 0.75294 1" mesh="l_calf_link"/>
              <geom name="//unnamed_geom_30" class="/" size="0.000596321 0.000596321 0.000596321" type="box" rgba="0.75294 0.75294 0.75294 1"/>
              <geom name="//unnamed_geom_31" class="reward_collision_sphere" size="0.0477057"/>
              <body name="l_ankle_pitch_link" pos="0.000920414 -0.00370105 -0.181026" quat="0.980083 2.63736e-05 -0.198589 3.0737e-05">
                <inertial pos="0.00641474 -0.0141059 -0.00625661" quat="-0.0050119 0.677204 0.0209341 0.73548" mass="0.343273" diaginertia="0.00166014 0.000105335 0.000696594"/>
                <joint name="l_ankle_pitch_joint" class="/" pos="0 0 0" axis="-0.0268655 0.998323 0.0512748" range="-0.558028 1.33881" armature="0.0127027" damping="0.0506412" frictionloss="0.0130952"/>
                <geom name="//unnamed_geom_32" class="/" type="mesh" density="0" rgba="0.75294 0.75294 0.75294 1" mesh="l_ankle_pitch_link"/>
                <geom name="//unnamed_geom_33" class="/" size="0.046513 0.0477057 0.029816" type="box" rgba="0.75294 0.75294 0.75294 1"/>
                <body name="l_ankle_roll_link" pos="0.0952109 0.00915527 -0.00286191" quat="0.999991 0.00212661 -0.00357309 -0.000455518">
                  <inertial pos="-0.037822 -0.00168886 -0.021064" quat="0.514901 0.437255 0.42972 0.599187" mass="1.06963" diaginertia="0.00554711 0.00047291 0.00125606"/>
                  <joint name="l_ankle_roll_joint" class="/" pos="0 0 0" axis="-0.997778 -0.0659854 -0.00922239" stiffness="0.0191256" range="-0.182307 0.427123" armature="0.0128047" damping="0.00451159" frictionloss="0.0197975"/>
                  <geom name="//unnamed_geom_34" class="/" type="mesh" density="0" rgba="0.75294 0.75294 0.75294 1" mesh="l_ankle_roll_link"/>
                  <geom name="//unnamed_geom_35" class="/" type="mesh" rgba="0.75294 0.75294 0.75294 1" mesh="l_ankle_roll_link"/>
                  <geom name="left_foot" class="foot" size="0.0922553 0.0368683 0.0060205" pos="-0.0693962 0 -0.0606804"/>
                  <geom name="//unnamed_geom_37" class="reward_collision_sphere" size="0.0477057" pos="-0.0680355 0 -0.027582"/>
                  <geom name="//unnamed_geom_38" class="reward_collision_sphere" size="0.0238528" pos="0.0204106 -0.0167623 -0.055164"/>
                  <geom name="//unnamed_geom_39" class="reward_collision_sphere" size="0.0238528" pos="-0.163285 -0.0167623 -0.055164"/>
                  <site name="left_foot" class="foot" pos="-0.0693962 0 -0.0606804" size="0.0119264"/>
                </body>
              </body>
            </body>
          </body>
        </body>
      </body>
    </body>
  </worldbody>

  <contact>
    <pair class="/" geom1="floor" geom2="right_foot" name="//unnamed_contact_1"/>
    <pair class="/" geom1="floor" geom2="left_foot" name="//unnamed_contact_0"/>
  </contact>

  <actuator>
    <general name="r_hip_pitch_joint" class="/" joint="r_hip_pitch_joint" forcerange="-32.6849 32.6849" gainprm="26.4785" biasprm="0 -26.4785 -0.579767"/>
    <general name="r_hip_roll_joint" class="/" joint="r_hip_roll_joint" forcerange="-25.7978 25.7978" gainprm="26.4785" biasprm="0 -26.4785 -0.579767"/>
    <general name="r_thigh_joint" class="/" joint="r_thigh_joint" forcerange="-31.4998 31.4998" gainprm="26.4785" biasprm="0 -26.4785 -0.579767"/>
    <general name="r_calf_joint" class="/" joint="r_calf_joint" forcerange="-21.7709 21.7709" gainprm="26.4785" biasprm="0 -26.4785 -0.579767"/>
    <general name="r_ankle_pitch_joint" class="/" joint="r_ankle_pitch_joint" forcerange="-18.3071 18.3071" gainprm="26.4785" biasprm="0 -26.4785 -0.579767"/>
    <general name="r_ankle_roll_joint" class="/" joint="r_ankle_roll_joint" forcerange="-14.6838 14.6838" gainprm="26.4785" biasprm="0 -26.4785 -0.579767"/>
    <general name="l_hip_pitch_joint" class="/" joint="l_hip_pitch_joint" forcerange="-30.8412 30.8412" gainprm="26.4785" biasprm="0 -26.4785 -0.579767"/>
    <general name="l_hip_roll_joint" class="/" joint="l_hip_roll_joint" forcerange="-37.3429 37.3429" gainprm="26.4785" biasprm="0 -26.4785 -0.579767"/>
    <general name="l_thigh_joint" class="/" joint="l_thigh_joint" forcerange="-22.8739 22.8739" gainprm="26.4785" biasprm="0 -26.4785 -0.579767"/>
    <general name="l_calf_joint" class="/" joint="l_calf_joint" forcerange="-27.8222 27.8222" gainprm="26.4785" biasprm="0 -26.4785 -0.579767"/>
    <general name="l_ankle_pitch_joint" class="/" joint="l_ankle_pitch_joint" forcerange="-21.6507 21.6507" gainprm="26.4785" biasprm="0 -26.4785 -0.579767"/>
    <general name="l_ankle_roll_joint" class="/" joint="l_ankle_roll_joint" forcerange="-29.7642 29.7642" gainprm="26.4785" biasprm="0 -26.4785 -0.579767"/>
  </actuator>

  <sensor>
    <gyro site="imu" name="imu_angular_velocity"/>
    <velocimeter site="imu" name="imu_linear_velocity"/>
    <framelinvel objtype="site" objname="left_foot" name="left_foot_global_linear_velocity"/>
    <framelinvel objtype="site" objname="right_foot" name="right_foot_global_linear_velocity"/>
  </sensor>

  <keyframe>
    <key name="home" qpos="0 0 0.291 1 0 0 0 0.4 0 0 -0.8 0.4 0 -0.4 0 0 0.8 -0.4 0"/>
  </keyframe>
</mujoco>
