<mujoco model="pi_12dof_release_v1">
  <compiler angle="radian" assetdir="assets" balanceinertia="true" inertiafromgeom="false"/>

  <option timestep="0.005" density="1.2" viscosity="2e-05"/>

  <size nkey="1"/>

  <visual>
    <quality shadowsize="8192"/>
    <map shadowclip="0.5"/>
  </visual>

  <default>
    <default class="/">
      <joint armature="0.01" damping="0.01" frictionloss="0.01"/>
      <geom contype="0" conaffinity="0" group="1" solref="-1000 -80"/>
      <site size="0.01 0.005 0.005" group="5"/>
      <general forcelimited="true" biastype="affine" gainprm="20" biasprm="0 -20 -0.5"/>
      <default class="foot">
        <geom size="0.0845 0.036 0.005" type="box" condim="6" group="4" priority="1" friction="0.9 0.2 0.2" solimp="0.015 1 0.005"/>
      </default>
      <default class="reward_collision_sphere">
        <geom group="5" rgba="1 0 0 1"/>
      </default>
    </default>
  </default>

  <asset>
    <texture type="skybox" colorspace="auto" name="//unnamed_texture_0" builtin="gradient" rgb1="0.95 0.95 0.95" rgb2="0.95 0.95 0.95" width="100" height="600"/>
    <texture type="2d" colorspace="auto" name="texplane" builtin="checker" rgb1="0.345 0.575 0.748" rgb2="0.345 0.575 0.748" markrgb="1 1 1" width="512" height="512"/>
    <material name="MatPlane" class="/" texture="texplane" texuniform="true" texrepeat="2 2" specular="0.9"/>
    <mesh name="baselink_1" class="/" file="baselink_1.STL"/>
    <mesh name="r_hip_pitch_link" class="/" file="r_hip_pitch_link.STL"/>
    <mesh name="r_hip_roll_link" class="/" file="r_hip_roll_link.STL"/>
    <mesh name="r_thigh_link" class="/" file="r_thigh_link.STL"/>
    <mesh name="r_calf_link" class="/" file="r_calf_link.STL"/>
    <mesh name="r_ankle_pitch_link" class="/" file="r_ankle_pitch_link.STL"/>
    <mesh name="r_ankle_roll_link" class="/" file="r_ankle_roll_link.STL"/>
    <mesh name="l_hip_pitch_link" class="/" file="l_hip_pitch_link.STL"/>
    <mesh name="l_hip_roll_link" class="/" file="l_hip_roll_link.STL"/>
    <mesh name="l_thigh_link" class="/" file="l_thigh_link.STL"/>
    <mesh name="l_calf_link" class="/" file="l_calf_link.STL"/>
    <mesh name="l_ankle_pitch_link" class="/" file="l_ankle_pitch_link.STL"/>
    <mesh name="l_ankle_roll_link" class="/" file="l_ankle_roll_link.STL"/>
  </asset>

  <worldbody>
    <geom name="floor" class="/" size="100 100 0.125" type="plane" group="0" material="MatPlane"/>
    <light name="toplight_shadow" class="/" pos="0 0 5" dir="0.0990148 0.0990148 -0.990148" type="directional" ambient="0.04 0.04 0.04" diffuse="0.55 0.55 0.55" specular="0.12 0.12 0.12"/>
    <light name="toplight_fill" class="/" pos="0 0 5" dir="0.0990148 0.0990148 -0.990148" type="directional" castshadow="false" ambient="0.04 0.04 0.04" diffuse="0.3 0.3 0.3" specular="0.08 0.08 0.08"/>
    <body name="trunk" pos="-0.000252188 0.000184117 -0.00191277" quat="1 -0.000166295 0.000190364 0.000415229">
      <inertial pos="0.00194891 -0.000328746 0.0551904" quat="0.695487 0.00983456 0.00857808 0.71842" mass="2.62263" diaginertia="0.0116116 0.00361443 0.0174614"/>
      <joint name="//unnamed_joint_0" type="free"/>
      <geom name="//unnamed_geom_1" class="/" type="mesh" density="0" rgba="1 1 1 1" mesh="baselink_1"/>
      <geom name="//unnamed_geom_2" class="/" size="0.0536535 0.0536535 0.0536535" pos="0 0 0.107081" type="box" rgba="1 1 1 1"/>
      <geom name="//unnamed_geom_3" class="reward_collision_sphere" size="0.0590189" pos="0 0 0.0936962"/>
      <site name="imu" class="/" pos="0.0128739 -0.0131723 0.0133324" size="0.0107307"/>
      <camera name="track" class="/" pos="0 -1.67943 0" quat="0.707107 0.707107 0 0" mode="trackcom"/>
      <camera name="ego_camera" class="/" pos="0.0780736 0 0.240933" quat="-0.5 -0.5 0.5 0.5"/>
      <body name="r_hip_pitch_link" pos="-0.00112611 -0.0213501 -0.0422614" quat="0.992127 0.000501596 -0.125235 -0.000958435">
        <inertial pos="0.000233482 -0.0471275 -0.00297431" quat="-0.0165912 0.704749 -0.0296881 0.708641" mass="0.432621" diaginertia="0.00012864 3.84346e-05 0.000357842"/>
        <joint name="r_hip_pitch_joint" class="/" pos="0 0 0" axis="0.0003689 -0.999986 0.00519207" stiffness="0.00525842" range="-1.75936 1.20674" armature="0.00936659" damping="0.00289518" frictionloss="0.00986135"/>
        <geom name="//unnamed_geom_4" class="/" type="mesh" density="0" rgba="0.75294 0.75294 0.75294 1" mesh="r_hip_pitch_link"/>
        <geom name="//unnamed_geom_5" class="/" size="0.000536535 0.000536535 0.000536535" type="box" rgba="0.75294 0.75294 0.75294 1"/>
        <body name="r_hip_roll_link" pos="-0.00160643 -0.0468817 0.00290947" quat="1 -9.07363e-05 0.000126538 9.64195e-05">
          <inertial pos="-0.00165908 0.00108985 -0.0840916" quat="0.703893 -0.0824483 -0.084488 0.700427" mass="0.489699" diaginertia="0.000405326 0.000117651 0.000556648"/>
          <joint name="r_hip_roll_joint" class="/" pos="0 0 0" axis="-0.999981 0.00613708 0.000429456" range="-0.120936 0.50202" armature="0.0102646" damping="0.030549" frictionloss="0.0121159"/>
          <geom name="//unnamed_geom_6" class="/" type="mesh" density="0" rgba="0.75294 0.75294 0.75294 1" mesh="r_hip_roll_link"/>
          <geom name="//unnamed_geom_7" class="/" size="0.000536535 0.000536535 0.000536535" type="box" rgba="0.75294 0.75294 0.75294 1"/>
          <geom name="//unnamed_geom_8" class="reward_collision_sphere" size="0.0429228"/>
          <body name="r_thigh_link" pos="-0.00297585 0.00228324 -0.091345" quat="1 6.91954e-08 -1.23306e-05 -1.74805e-05">
            <inertial pos="0.000983748 0.000686668 -0.0623507" quat="0.737313 0.675551 -0.000625627 -0.00100039" mass="0.131833" diaginertia="0.000152411 4.00239e-05 0.000241816"/>
            <joint name="r_thigh_joint" class="/" pos="0 0 0" axis="0.000444318 -0.00309144 -0.999995" stiffness="0.000941452" range="-0.293141 0.56055" armature="0.0112553" damping="0.00878898" frictionloss="0.0103136"/>
            <geom name="//unnamed_geom_9" class="/" type="mesh" density="0" rgba="0.75294 0.75294 0.75294 1" mesh="r_thigh_link"/>
            <geom name="//unnamed_geom_10" class="/" size="0.000536535 0.000536535 0.000536535" type="box" rgba="0.75294 0.75294 0.75294 1"/>
            <body name="r_calf_link" pos="0.00242354 -0.00469183 -0.0937668" quat="0.947829 3.01745e-07 0.31878 -7.3146e-05">
              <inertial pos="0.000797778 0.000731817 -0.0947323" quat="0.999987 -0.00212343 0.000462695 0.00462878" mass="1.03168" diaginertia="0.00432109 0.00140634 0.000749137"/>
              <joint name="r_calf_joint" class="/" pos="0 0 0" axis="-0.00272647 -0.999992 0.00288305" stiffness="0.00254182" range="-1.70572 0.657298" armature="0.0109198" damping="0.00695756" frictionloss="0.00952704"/>
              <geom name="//unnamed_geom_11" class="/" type="mesh" density="0" rgba="0.75294 0.75294 0.75294 1" mesh="r_calf_link"/>
              <geom name="//unnamed_geom_12" class="/" size="0.000536535 0.000536535 0.000536535" type="box" rgba="0.75294 0.75294 0.75294 1"/>
              <geom name="//unnamed_geom_13" class="reward_collision_sphere" size="0.0429228"/>
              <body name="r_ankle_pitch_link" pos="-0.00113193 0.00271718 -0.187605" quat="0.980169 -0.000939519 -0.198161 0.00026184">
                <inertial pos="0.00465667 0.00235394 -0.000191334" quat="0.00225495 0.707015 -0.00213852 0.707192" mass="0.206336" diaginertia="0.000370104 8.78678e-05 0.00051442"/>
                <joint name="r_ankle_pitch_joint" class="/" pos="0 0 0" axis="0.00826369 -0.999919 -0.00973018" range="-1.34237 0.555712" armature="0.0107144" damping="0.00911161" frictionloss="0.0111724"/>
                <geom name="//unnamed_geom_14" class="/" type="mesh" density="0" rgba="0.75294 0.75294 0.75294 1" mesh="r_ankle_pitch_link"/>
                <geom name="//unnamed_geom_15" class="/" size="0.0418498 0.0429228 0.0268268" type="box" rgba="0.75294 0.75294 0.75294 1"/>
                <body name="r_ankle_roll_link" pos="0.0778722 0.00501561 0.00230978" quat="1 -0.000273416 0.000418305 0.000122696">
                  <inertial pos="-0.0273913 -0.00164481 -0.0203188" quat="0.55242 0.429935 0.433418 0.567571" mass="0.656133" diaginertia="0.00142812 0.000436176 0.0012328"/>
                  <joint name="r_ankle_roll_joint" class="/" pos="0 0 0" axis="-0.999993 -0.00130869 0.00357066" stiffness="0.00625149" range="-0.144812 0.131761" armature="0.0107664" damping="0.00897347" frictionloss="0.0100367"/>
                  <geom name="//unnamed_geom_16" class="/" type="mesh" density="0" rgba="0.75294 0.75294 0.75294 1" mesh="r_ankle_roll_link"/>
                  <geom name="//unnamed_geom_17" class="/" type="mesh" rgba="0.75294 0.75294 0.75294 1" mesh="r_ankle_roll_link"/>
                  <geom name="right_foot" class="foot" size="0.0812748 0.0338131 0.0052707" pos="-0.0530901 0 -0.0588948"/>
                  <geom name="//unnamed_geom_19" class="reward_collision_sphere" size="0.0429228" pos="-0.0520491 0 -0.0267703"/>
                  <geom name="//unnamed_geom_20" class="reward_collision_sphere" size="0.0214614" pos="0.0156147 0.0167943 -0.0535407"/>
                  <geom name="//unnamed_geom_21" class="reward_collision_sphere" size="0.0214614" pos="-0.124918 0.0167943 -0.0535407"/>
                  <site name="right_foot" class="foot" pos="-0.0530901 0 -0.0588948" size="0.0107307"/>
                </body>
              </body>
            </body>
          </body>
        </body>
      </body>
      <body name="l_hip_pitch_link" pos="-0.00205261 0.0206961 -0.0428689" quat="0.992227 -0.000270883 -0.124442 -0.000318888">
        <inertial pos="-0.00185876 0.0446572 0.00122309" quat="-0.0382296 0.71271 0.0306941 0.699744" mass="0.493332" diaginertia="0.000162255 4.52121e-05 0.000418726"/>
        <joint name="l_hip_pitch_joint" class="/" pos="0 0 0" axis="0.00199948 0.999997 -0.00110752" stiffness="0.00136532" range="-1.22298 1.75023" armature="0.012124" damping="0.0245841" frictionloss="0.0102205"/>
        <geom name="//unnamed_geom_22" class="/" type="mesh" density="0" rgba="0.75294 0.75294 0.75294 1" mesh="l_hip_pitch_link"/>
        <geom name="//unnamed_geom_23" class="/" size="0.000536535 0.000536535 0.000536535" type="box" rgba="0.75294 0.75294 0.75294 1"/>
        <body name="l_hip_roll_link" pos="0.00183314 0.0468562 -5.1567e-06" quat="0.999999 0.000400826 0.00124763 0.000581641">
          <inertial pos="-0.00328588 -0.00211019 -0.0814905" quat="0.702304 -0.0858091 -0.0841104 0.701663" mass="0.471769" diaginertia="0.000400511 0.000111814 0.000569632"/>
          <joint name="l_hip_roll_joint" class="/" pos="0 0 0" axis="-0.999919 -0.00133529 -0.0126397" range="-0.530983 0.124052" armature="0.0117085" damping="0.0131249" frictionloss="0.0106672"/>
          <geom name="//unnamed_geom_24" class="/" type="mesh" density="0" rgba="0.75294 0.75294 0.75294 1" mesh="l_hip_roll_link"/>
          <geom name="//unnamed_geom_25" class="/" size="0.000536535 0.000536535 0.000536535" type="box" rgba="0.75294 0.75294 0.75294 1"/>
          <geom name="//unnamed_geom_26" class="reward_collision_sphere" size="0.0429228"/>
          <body name="l_thigh_link" pos="0.0019635 0.00138292 -0.0922782" quat="1 -0.00026521 0.000481071 -6.41474e-05">
            <inertial pos="0.00141361 -0.00420712 -0.065412" quat="0.675321 0.737524 7.54334e-05 6.13784e-05" mass="0.135012" diaginertia="0.000144374 3.85446e-05 0.000236476"/>
            <joint name="l_thigh_joint" class="/" pos="0 0 0" axis="0.00231457 0.00875788 -0.999959" range="-0.559174 0.28424" armature="0.00930524" damping="0.013402" frictionloss="0.00971163"/>
            <geom name="//unnamed_geom_27" class="/" type="mesh" density="0" rgba="0.75294 0.75294 0.75294 1" mesh="l_thigh_link"/>
            <geom name="//unnamed_geom_28" class="/" size="0.000536535 0.000536535 0.000536535" type="box" rgba="0.75294 0.75294 0.75294 1"/>
            <body name="l_calf_link" pos="-0.00095705 0.00205406 -0.0945437" quat="0.947625 -0.0002302 0.319385 -0.000316143">
              <inertial pos="0.00150231 0.00538272 -0.0962921" quat="0.999962 0.000497412 0.00678516 0.00548686" mass="0.951199" diaginertia="0.00430871 0.00137156 0.000726273"/>
              <joint name="l_calf_joint" class="/" pos="0 0 0" axis="3.01202e-05 1 -0.000549213" stiffness="0.0123283" range="-0.614538 1.59731" armature="0.0111941" damping="0.0176282" frictionloss="0.00949015"/>
              <geom name="//unnamed_geom_29" class="/" type="mesh" density="0" rgba="0.75294 0.75294 0.75294 1" mesh="l_calf_link"/>
              <geom name="//unnamed_geom_30" class="/" size="0.000536535 0.000536535 0.000536535" type="box" rgba="0.75294 0.75294 0.75294 1"/>
              <geom name="//unnamed_geom_31" class="reward_collision_sphere" size="0.0429228"/>
              <body name="l_ankle_pitch_link" pos="-0.00100606 0.00327784 -0.185904" quat="0.980097 5.95636e-05 -0.198517 0.000219232">
                <inertial pos="0.00492604 -0.00248208 0.0026249" quat="-0.00858696 0.705703 0.00377663 0.708445" mass="0.220873" diaginertia="0.000387616 9.56588e-05 0.000526777"/>
                <joint name="l_ankle_pitch_joint" class="/" pos="0 0 0" axis="-0.000110315 1 0.000957777" stiffness="0.00218956" range="-0.48323 1.2878" armature="0.0102518" damping="0.0102216" frictionloss="0.00977874"/>
                <geom name="//unnamed_geom_32" class="/" type="mesh" density="0" rgba="0.75294 0.75294 0.75294 1" mesh="l_ankle_pitch_link"/>
                <geom name="//unnamed_geom_33" class="/" size="0.0418498 0.0429228 0.0268268" type="box" rgba="0.75294 0.75294 0.75294 1"/>
                <body name="l_ankle_roll_link" pos="0.0804689 -0.000199891 0.00144343" quat="1 0.000387483 -7.17653e-05 0.000741331">
                  <inertial pos="-0.0224891 0.000596602 -0.0197307" quat="0.561278 0.431433 0.435513 0.556022" mass="0.618084" diaginertia="0.00135762 0.000403571 0.00114988"/>
                  <joint name="l_ankle_roll_joint" class="/" pos="0 0 0" axis="-0.999964 -0.00266846 0.008095" range="-0.160434 0.190963" armature="0.0108659" damping="0.0130654" frictionloss="0.0115586"/>
                  <geom name="//unnamed_geom_34" class="/" type="mesh" density="0" rgba="0.75294 0.75294 0.75294 1" mesh="l_ankle_roll_link"/>
                  <geom name="//unnamed_geom_35" class="/" type="mesh" rgba="0.75294 0.75294 0.75294 1" mesh="l_ankle_roll_link"/>
                  <geom name="left_foot" class="foot" size="0.0998142 0.0410766 0.00515182" pos="-0.0530901 0 -0.0588948"/>
                  <geom name="//unnamed_geom_37" class="reward_collision_sphere" size="0.0429228" pos="-0.0520491 0 -0.0267703"/>
                  <geom name="//unnamed_geom_38" class="reward_collision_sphere" size="0.0214614" pos="0.0156147 -0.0167943 -0.0535407"/>
                  <geom name="//unnamed_geom_39" class="reward_collision_sphere" size="0.0214614" pos="-0.124918 -0.0167943 -0.0535407"/>
                  <site name="left_foot" class="foot" pos="-0.0530901 0 -0.0588948" size="0.0107307"/>
                </body>
              </body>
            </body>
          </body>
        </body>
      </body>
    </body>
  </worldbody>

  <contact>
    <pair class="/" geom1="floor" geom2="right_foot" name="//unnamed_contact_1"/>
    <pair class="/" geom1="floor" geom2="left_foot" name="//unnamed_contact_0"/>
  </contact>

  <actuator>
    <general name="r_hip_pitch_joint" class="/" joint="r_hip_pitch_joint" forcerange="-20.9724 20.9724" gainprm="20.0483" biasprm="0 -20.0483 -0.566014"/>
    <general name="r_hip_roll_joint" class="/" joint="r_hip_roll_joint" forcerange="-22.9126 22.9126" gainprm="20.0483" biasprm="0 -20.0483 -0.566014"/>
    <general name="r_thigh_joint" class="/" joint="r_thigh_joint" forcerange="-20.5342 20.5342" gainprm="20.0483" biasprm="0 -20.0483 -0.566014"/>
    <general name="r_calf_joint" class="/" joint="r_calf_joint" forcerange="-24.6561 24.6561" gainprm="20.0483" biasprm="0 -20.0483 -0.566014"/>
    <general name="r_ankle_pitch_joint" class="/" joint="r_ankle_pitch_joint" forcerange="-24.4831 24.4831" gainprm="20.0483" biasprm="0 -20.0483 -0.566014"/>
    <general name="r_ankle_roll_joint" class="/" joint="r_ankle_roll_joint" forcerange="-22.6505 22.6505" gainprm="20.0483" biasprm="0 -20.0483 -0.566014"/>
    <general name="l_hip_pitch_joint" class="/" joint="l_hip_pitch_joint" forcerange="-20.3275 20.3275" gainprm="20.0483" biasprm="0 -20.0483 -0.566014"/>
    <general name="l_hip_roll_joint" class="/" joint="l_hip_roll_joint" forcerange="-23.7539 23.7539" gainprm="20.0483" biasprm="0 -20.0483 -0.566014"/>
    <general name="l_thigh_joint" class="/" joint="l_thigh_joint" forcerange="-24.2312 24.2312" gainprm="20.0483" biasprm="0 -20.0483 -0.566014"/>
    <general name="l_calf_joint" class="/" joint="l_calf_joint" forcerange="-20.5561 20.5561" gainprm="20.0483" biasprm="0 -20.0483 -0.566014"/>
    <general name="l_ankle_pitch_joint" class="/" joint="l_ankle_pitch_joint" forcerange="-24.673 24.673" gainprm="20.0483" biasprm="0 -20.0483 -0.566014"/>
    <general name="l_ankle_roll_joint" class="/" joint="l_ankle_roll_joint" forcerange="-20.2136 20.2136" gainprm="20.0483" biasprm="0 -20.0483 -0.566014"/>
  </actuator>

  <sensor>
    <gyro site="imu" name="imu_angular_velocity"/>
    <velocimeter site="imu" name="imu_linear_velocity"/>
    <framelinvel objtype="site" objname="left_foot" name="left_foot_global_linear_velocity"/>
    <framelinvel objtype="site" objname="right_foot" name="right_foot_global_linear_velocity"/>
  </sensor>

  <keyframe>
    <key name="home" qpos="0 0 0.291 1 0 0 0 0.4 0 0 -0.8 0.4 0 -0.4 0 0 0.8 -0.4 0"/>
  </keyframe>
</mujoco>
