<mujoco model="go2">
  <compiler angle="radian" assetdir="assets" balanceinertia="true" inertiafromgeom="false"/>

  <option timestep="0.005" density="1.2" viscosity="2e-05"/>

  <size nkey="1"/>

  <visual>
    <quality shadowsize="8192"/>
    <map shadowclip="0.5"/>
  </visual>

  <default>
    <default class="/">
      <geom contype="0" conaffinity="0" group="1" solref="-1000 -80"/>
      <site size="0.01 0.005 0.005" group="5"/>
      <general forcelimited="true" biastype="affine" gainprm="20" biasprm="0 -20 -0.5"/>
      <default class="go2">
        <joint armature="0.01" damping="0.01" frictionloss="0.2"/>
        <geom condim="1" margin="0.001"/>
        <default class="visual">
          <geom type="mesh" group="2"/>
        </default>
        <default class="collision">
          <geom group="3"/>
          <default class="foot">
            <geom size="0.022 0 0" condim="6" priority="1" friction="0.8 0.02 0.01" solimp="0.015 1 0.022"/>
          </default>
        </default>
        <default class="reward_collision_sphere">
          <geom group="5" rgba="1 0 0 1"/>
        </default>
      </default>
    </default>
  </default>

  <asset>
    <texture type="skybox" colorspace="auto" name="//unnamed_texture_0" builtin="gradient" rgb1="0.95 0.95 0.95" rgb2="0.95 0.95 0.95" width="100" height="600"/>
    <texture type="2d" colorspace="auto" name="texplane" builtin="checker" rgb1="0.345 0.575 0.748" rgb2="0.345 0.575 0.748" markrgb="1 1 1" width="512" height="512"/>
    <material name="MatPlane" class="/" texture="texplane" texuniform="true" texrepeat="2 2" specular="0.9"/>
    <material name="metal" class="/" rgba="0.9 0.95 0.95 1"/>
    <material name="black" class="/" rgba="0 0 0 1"/>
    <material name="white" class="/"/>
    <material name="gray" class="/" rgba="0.671705 0.692426 0.77427 1"/>
    <mesh name="base_0" class="/" file="base_0.obj"/>
    <mesh name="base_1" class="/" file="base_1.obj"/>
    <mesh name="base_2" class="/" file="base_2.obj"/>
    <mesh name="base_3" class="/" file="base_3.obj"/>
    <mesh name="base_4" class="/" file="base_4.obj"/>
    <mesh name="hip_0" class="/" file="hip_0.obj"/>
    <mesh name="hip_1" class="/" file="hip_1.obj"/>
    <mesh name="thigh_0" class="/" file="thigh_0.obj"/>
    <mesh name="thigh_1" class="/" file="thigh_1.obj"/>
    <mesh name="thigh_mirror_0" class="/" file="thigh_mirror_0.obj"/>
    <mesh name="thigh_mirror_1" class="/" file="thigh_mirror_1.obj"/>
    <mesh name="calf_0" class="/" file="calf_0.obj"/>
    <mesh name="calf_1" class="/" file="calf_1.obj"/>
    <mesh name="calf_mirror_0" class="/" file="calf_mirror_0.obj"/>
    <mesh name="calf_mirror_1" class="/" file="calf_mirror_1.obj"/>
    <mesh name="foot" class="/" file="foot.obj"/>
  </asset>

  <worldbody>
    <geom name="floor" class="/" size="100 100 0.125" type="plane" group="0" material="MatPlane"/>
    <light name="toplight_shadow" class="/" pos="0 0 5" dir="0.0990148 0.0990148 -0.990148" type="directional" ambient="0.04 0.04 0.04" diffuse="0.55 0.55 0.55" specular="0.12 0.12 0.12"/>
    <light name="toplight_fill" class="/" pos="0 0 5" dir="0.0990148 0.0990148 -0.990148" type="directional" castshadow="false" ambient="0.04 0.04 0.04" diffuse="0.3 0.3 0.3" specular="0.08 0.08 0.08"/>
    <body name="trunk" childclass="go2" pos="2.95256e-05 -8.15354e-05 -0.000448879" quat="1 -1.49391e-06 -3.58393e-05 1.68111e-05">
      <inertial pos="0.0225636 -0.000209102 -0.00494696" quat="-0.000757714 0.713324 -0.00171485 0.700832" mass="6.3867" diaginertia="0.14458 0.0753241 0.0141516"/>
      <joint name="//unnamed_joint_0" type="free" armature="0" damping="0" frictionloss="0"/>
      <geom name="//unnamed_geom_1" class="visual" material="black" mesh="base_0"/>
      <geom name="//unnamed_geom_2" class="visual" material="black" mesh="base_1"/>
      <geom name="//unnamed_geom_3" class="visual" material="black" mesh="base_2"/>
      <geom name="//unnamed_geom_4" class="visual" material="white" mesh="base_3"/>
      <geom name="//unnamed_geom_5" class="visual" material="gray" mesh="base_4"/>
      <geom name="trunk_1" class="collision" size="0.182056 0.0452477 0.0551684" type="box"/>
      <geom name="trunk_2" class="collision" size="0.0483933 0.043554" pos="0.302153 0 0.0089526" type="cylinder"/>
      <geom name="trunk_3" class="collision" size="0.0454897" pos="0.310635 0 -0.0537156"/>
      <geom name="//unnamed_geom_9" class="reward_collision_sphere" size="0.0967866"/>
      <geom name="//unnamed_geom_10" class="reward_collision_sphere" size="0.058072" pos="0.296852 0 -0.0402867"/>
      <site name="imu" pos="-0.024926 -0.00422955 0.0412097" size="0.00967866"/>
      <camera name="track" pos="0 -1.8963 0" quat="0.707107 0.707107 0 0" mode="trackcom"/>
      <camera name="ego_camera" pos="0.330778 0 0.0402867" quat="-0.5 -0.5 0.5 0.5"/>
      <body name="FL_hip" pos="0.204805 0.043328 0.0011469" quat="1 2.05854e-07 0.000155025 -0.000134106">
        <inertial pos="-0.00535638 0.0022767 -0.00109659" quat="0.495533 0.499469 0.505854 0.499088" mass="0.620909" diaginertia="0.0011846 0.000459452 0.000278772"/>
        <joint name="FL_hip_joint" pos="0 0 0" axis="1 1.05384e-05 -1.31212e-08" stiffness="0.00256597" range="-1.0462 1.03456" armature="0.00965472" damping="0.00783357" frictionloss="0.186474"/>
        <geom name="//unnamed_geom_11" class="visual" material="metal" mesh="hip_0"/>
        <geom name="//unnamed_geom_12" class="visual" material="gray" mesh="hip_1"/>
        <geom name="//unnamed_geom_13" class="collision" size="0.0445218 0.0193573" pos="0 0.0758521 0" quat="0.707107 0.707107 0 0" type="cylinder"/>
        <geom name="//unnamed_geom_14" class="reward_collision_sphere" size="0.058072" pos="0 0.0663706 0"/>
        <body name="FL_thigh" pos="-0.000167351 0.089711 0.00173705" quat="1 -9.43068e-05 -0.000111298 6.25425e-05">
          <inertial pos="-0.00376459 -0.0210119 -0.0289206" quat="0.829371 0.0838427 -0.0203356 0.551997" mass="1.05478" diaginertia="0.00804619 0.00449102 0.000510925"/>
          <joint name="FL_thigh_joint" pos="0 0 0" axis="0.00438258 0.999987 -0.00270731" stiffness="0.00335367" range="-1.55431 3.49128" armature="0.0100251" damping="0.00282701" frictionloss="0.193527"/>
          <geom name="//unnamed_geom_15" class="visual" material="metal" mesh="thigh_0"/>
          <geom name="//unnamed_geom_16" class="visual" material="gray" mesh="thigh_1"/>
          <geom name="//unnamed_geom_17" class="collision" size="0.103078 0.0118564 0.0164537" pos="0 0 -0.0953452" quat="0.707107 0 0.707107 0" type="box"/>
          <body name="FL_calf" pos="-0.000908677 4.09989e-05 -0.190424" quat="1 3.52314e-07 -6.24519e-06 -5.04927e-05">
            <inertial pos="0.00586077 -0.00057016 -0.12641" quat="0.710059 0.00127829 -0.00493137 0.704124" mass="0.219225" diaginertia="0.00199769 0.00111963 3.06008e-05"/>
            <joint name="FL_calf_joint" pos="0 0 0" axis="-0.00431305 0.99999 -0.000841037" stiffness="0.0044627" range="-2.74222 -0.855071" armature="0.00944629" damping="0.00731388" frictionloss="0.199452"/>
            <geom name="//unnamed_geom_18" class="visual" material="gray" mesh="calf_0"/>
            <geom name="//unnamed_geom_19" class="visual" material="black" mesh="calf_1"/>
            <geom name="FL_calf0" class="collision" size="0.0116144 0.058072" pos="0.00848149 0 -0.0537156" quat="0.994493 0 -0.104807 0" type="cylinder"/>
            <geom name="//unnamed_geom_21" class="collision" size="0.0106465 0.0314556" pos="0.0212037 0 -0.132498" quat="0.999688 0 0.0249974 0" type="cylinder"/>
            <geom name="//unnamed_geom_22" class="visual" pos="0 0 -0.19069" quat="1 0 0 0" material="black" mesh="foot"/>
            <geom name="FL_foot" class="foot" size="0.0175691" pos="-0.00212037 0 -0.19069"/>
            <geom name="//unnamed_geom_24" class="reward_collision_sphere" size="0.0241967"/>
            <geom name="//unnamed_geom_25" class="reward_collision_sphere" size="0.0241967" pos="-0.00212037 0 -0.19069"/>
            <site name="FL_foot" class="foot" pos="-0.00212037 0 -0.19069" size="0.00967866"/>
          </body>
        </body>
      </body>
      <body name="FR_hip" pos="0.205417 -0.0432617 -0.000130228" quat="1 -0.000217869 0.000239994 0.000175518">
        <inertial pos="-0.00572077 -0.00158932 -0.000549842" quat="0.500111 0.505891 0.498641 0.495298" mass="0.616914" diaginertia="0.0011861 0.000454382 0.000275689"/>
        <joint name="FR_hip_joint" pos="0 0 0" axis="0.999999 0.000556472 -0.00156702" range="-1.05618 1.06538" armature="0.00988185" damping="0.0152804" frictionloss="0.18507"/>
        <geom name="//unnamed_geom_26" class="visual" pos="0 4.60773e-10 1.97635e-08" quat="4.63268e-05 1 0 0" material="metal" mesh="hip_0"/>
        <geom name="//unnamed_geom_27" class="visual" pos="0 7.46968e-10 -4.88827e-08" quat="4.63268e-05 1 0 0" material="gray" mesh="hip_1"/>
        <geom name="//unnamed_geom_28" class="collision" size="0.0445218 0.0193573" pos="0 -0.0758521 0" quat="0.707107 0.707107 0 0" type="cylinder"/>
        <geom name="//unnamed_geom_29" class="reward_collision_sphere" size="0.058072" pos="0 -0.0663706 0"/>
        <body name="FR_thigh" pos="0.000199569 -0.0895505 0.00155238" quat="1 3.57218e-05 -0.000196006 -0.000220361">
          <inertial pos="-0.00417395 0.021274 -0.0290384" quat="0.550371 -0.0198895 0.0858782 0.830253" mass="1.03434" diaginertia="0.00795224 0.00450361 0.000502286"/>
          <joint name="FR_thigh_joint" pos="0 0 0" axis="-0.00501796 -0.999982 -0.00322598" range="-3.49269 1.58693" armature="0.00989193" damping="0.00846301" frictionloss="0.199878"/>
          <geom name="//unnamed_geom_30" class="visual" material="metal" mesh="thigh_mirror_0"/>
          <geom name="//unnamed_geom_31" class="visual" material="gray" mesh="thigh_mirror_1"/>
          <geom name="//unnamed_geom_32" class="collision" size="0.103078 0.0118564 0.0164537" pos="0 0 -0.0953452" quat="0.707107 0 0.707107 0" type="box"/>
          <body name="FR_calf" pos="-0.00028747 0.000376712 -0.190882" quat="1 -0.000123567 -0.00019148 -3.56666e-05">
            <inertial pos="0.00609436 0.000780469 -0.127315" quat="0.705841 -0.00382976 0.00263309 0.708355" mass="0.218046" diaginertia="0.00200314 0.00111785 3.08977e-05"/>
            <joint name="FR_calf_joint" pos="0 0 0" axis="-0.00259906 -0.999991 -0.00349178" range="0.83282 2.72659" armature="0.00973345" damping="0.00678487" frictionloss="0.199775"/>
            <geom name="//unnamed_geom_33" class="visual" material="gray" mesh="calf_mirror_0"/>
            <geom name="//unnamed_geom_34" class="visual" material="black" mesh="calf_mirror_1"/>
            <geom name="FR_calf0" class="collision" size="0.0125823 0.058072" pos="0.0106019 0 -0.0537156" quat="0.995004 0 -0.0998334 0" type="cylinder"/>
            <geom name="//unnamed_geom_36" class="collision" size="0.0106465 0.0314556" pos="0.0212037 0 -0.132498" quat="0.999688 0 0.0249974 0" type="cylinder"/>
            <geom name="//unnamed_geom_37" class="visual" pos="0 0 -0.19069" quat="1 0 0 0" material="black" mesh="foot"/>
            <geom name="FR_foot" class="foot" size="0.0212785" pos="-0.00212037 0 -0.19069"/>
            <geom name="//unnamed_geom_39" class="reward_collision_sphere" size="0.0241967"/>
            <geom name="//unnamed_geom_40" class="reward_collision_sphere" size="0.0241967" pos="-0.00212037 0 -0.19069"/>
            <site name="FR_foot" class="foot" pos="-0.00212037 0 -0.19069" size="0.00967866"/>
          </body>
        </body>
      </body>
      <body name="RL_hip" pos="-0.205341 0.0448284 0.000543586" quat="1 -2.47618e-06 1.28325e-05 -1.53865e-06">
        <inertial pos="0.00542731 0.00248625 -0.00045498" quat="0.506 0.498645 0.496479 0.498824" mass="0.62209" diaginertia="0.00120551 0.000460153 0.000281356"/>
        <joint name="RL_hip_joint" pos="0 0 0" axis="-0.999798 0.010035 0.0174227" stiffness="0.00306601" range="-1.04292 1.04574" armature="0.00947871" damping="0.0122731" frictionloss="0.194409"/>
        <geom name="//unnamed_geom_41" class="visual" pos="-1.43678e-09 0 -2.81641e-07" quat="4.63268e-05 0 1 0" material="metal" mesh="hip_0"/>
        <geom name="//unnamed_geom_42" class="visual" pos="-2.32919e-09 0 -2.49776e-07" quat="4.63268e-05 0 1 0" material="gray" mesh="hip_1"/>
        <geom name="//unnamed_geom_43" class="collision" size="0.0445218 0.0193573" pos="0 0.0758521 0" quat="0.707107 0.707107 0 0" type="cylinder"/>
        <geom name="//unnamed_geom_44" class="reward_collision_sphere" size="0.058072" pos="0 0.0663706 0"/>
        <body name="RL_thigh" pos="-2.7492e-05 0.0899257 0.000773841" quat="1 0.000125374 -0.00019042 -0.000308027">
          <inertial pos="-0.00313377 -0.0201358 -0.0298901" quat="0.82959 0.0847042 -0.0202136 0.55154" mass="1.05891" diaginertia="0.00806669 0.00453576 0.000505513"/>
          <joint name="RL_thigh_joint" pos="0 0 0" axis="-0.00282967 0.99998 0.00561298" range="-0.505582 4.53708" armature="0.00965406" damping="0.00133592" frictionloss="0.188816"/>
          <geom name="//unnamed_geom_45" class="visual" material="metal" mesh="thigh_0"/>
          <geom name="//unnamed_geom_46" class="visual" material="gray" mesh="thigh_1"/>
          <geom name="//unnamed_geom_47" class="collision" size="0.103078 0.0118564 0.0164537" pos="0 0 -0.0953452" quat="0.707107 0 0.707107 0" type="box"/>
          <body name="RL_calf" pos="0.000388429 -0.000859707 -0.190075" quat="1 -0.000173288 -8.3804e-05 0.000396297">
            <inertial pos="0.00628797 -0.00123807 -0.127329" quat="0.710739 0.00160554 -0.00410652 0.703442" mass="0.220452" diaginertia="0.00201884 0.00114299 3.07348e-05"/>
            <joint name="RL_calf_joint" pos="0 0 0" axis="0.00743453 0.999941 0.00792582" range="-2.71771 -0.854457" armature="0.00960176" damping="0" frictionloss="0.193915"/>
            <geom name="//unnamed_geom_48" class="visual" material="gray" mesh="calf_0"/>
            <geom name="//unnamed_geom_49" class="visual" material="black" mesh="calf_1"/>
            <geom name="RL_calf0" class="collision" size="0.0125823 0.058072" pos="0.0106019 0 -0.0537156" quat="0.995004 0 -0.0998334 0" type="cylinder"/>
            <geom name="//unnamed_geom_51" class="collision" size="0.0106465 0.0314556" pos="0.0212037 0 -0.132498" quat="0.999688 0 0.0249974 0" type="cylinder"/>
            <geom name="//unnamed_geom_52" class="visual" pos="0 0 -0.19069" quat="1 0 0 0" material="black" mesh="foot"/>
            <geom name="RL_foot" class="foot" size="0.0188419" pos="-0.00212037 0 -0.19069"/>
            <geom name="//unnamed_geom_54" class="reward_collision_sphere" size="0.0241967"/>
            <geom name="//unnamed_geom_55" class="reward_collision_sphere" size="0.0241967" pos="-0.00212037 0 -0.19069"/>
            <site name="RL_foot" class="foot" pos="-0.00212037 0 -0.19069" size="0.00967866"/>
          </body>
        </body>
      </body>
      <body name="RR_hip" pos="-0.20458 -0.045318 0.000923891" quat="1 -4.58299e-07 2.61499e-05 7.5378e-06">
        <inertial pos="0.00631927 -0.00102148 -0.000248477" quat="0.499195 0.497003 0.49829 0.505468" mass="0.611339" diaginertia="0.00119356 0.000460157 0.000275008"/>
        <joint name="RR_hip_joint" pos="0 0 0" axis="-0.999992 -0.00318626 -0.00227784" range="-1.03757 1.04735" armature="0.00966263" damping="0.00250604" frictionloss="0.200833"/>
        <geom name="//unnamed_geom_56" class="visual" pos="1.4329e-09 4.60773e-10 -3.01405e-07" quat="2.14617e-09 4.63268e-05 4.63268e-05 -1" material="metal" mesh="hip_0"/>
        <geom name="//unnamed_geom_57" class="visual" pos="2.33878e-09 7.46968e-10 -2.00893e-07" quat="2.14617e-09 4.63268e-05 4.63268e-05 -1" material="gray" mesh="hip_1"/>
        <geom name="//unnamed_geom_58" class="collision" size="0.0445218 0.0193573" pos="0 -0.0758521 0" quat="0.707107 0.707107 0 0" type="cylinder"/>
        <geom name="//unnamed_geom_59" class="reward_collision_sphere" size="0.058072" pos="0 -0.0663706 0"/>
        <body name="RR_thigh" pos="-0.000360406 -0.0914706 -0.00134313" quat="1 -0.000177463 -0.000341648 -0.000299397">
          <inertial pos="-0.00377435 0.0216179 -0.030394" quat="0.549115 -0.0200498 0.0881242 0.830846" mass="1.03273" diaginertia="0.00791074 0.00445474 0.000506916"/>
          <joint name="RR_thigh_joint" pos="0 0 0" axis="-0.000151787 -1 -6.21498e-05" range="-4.54067 0.539148" armature="0.00970308" damping="0.0202724" frictionloss="0.18945"/>
          <geom name="//unnamed_geom_60" class="visual" material="metal" mesh="thigh_mirror_0"/>
          <geom name="//unnamed_geom_61" class="visual" material="gray" mesh="thigh_mirror_1"/>
          <geom name="//unnamed_geom_62" class="collision" size="0.103078 0.0118564 0.0164537" pos="0 0 -0.0953452" quat="0.707107 0 0.707107 0" type="box"/>
          <body name="RR_calf" pos="0.00108919 -0.000903588 -0.191602" quat="1 8.6449e-05 5.98523e-05 -0.000302498">
            <inertial pos="0.00677177 0.000776211 -0.126997" quat="0.703495 -0.00461526 0.00152505 0.710684" mass="0.215233" diaginertia="0.00196666 0.00109908 3.01899e-05"/>
            <joint name="RR_calf_joint" pos="0 0 0" axis="0.00456917 -0.999978 0.00482283" range="0.832884 2.71667" armature="0.00969321" damping="0.0075566" frictionloss="0.189855"/>
            <geom name="//unnamed_geom_63" class="visual" material="gray" mesh="calf_mirror_0"/>
            <geom name="//unnamed_geom_64" class="visual" material="black" mesh="calf_mirror_1"/>
            <geom name="RR_calf0" class="collision" size="0.0125823 0.058072" pos="0.0106019 0 -0.0537156" quat="0.995004 0 -0.0998334 0" type="cylinder"/>
            <geom name="//unnamed_geom_66" class="collision" size="0.0106465 0.0314556" pos="0.0212037 0 -0.132498" quat="0.999688 0 0.0249974 0" type="cylinder"/>
            <geom name="//unnamed_geom_67" class="visual" pos="0 0 -0.19069" quat="1 0 0 0" material="black" mesh="foot"/>
            <geom name="RR_foot" class="foot" size="0.0221602" pos="-0.00212037 0 -0.19069"/>
            <geom name="//unnamed_geom_69" class="reward_collision_sphere" size="0.0241967"/>
            <geom name="//unnamed_geom_70" class="reward_collision_sphere" size="0.0241967" pos="-0.00212037 0 -0.19069"/>
            <site name="RR_foot" class="foot" pos="-0.00212037 0 -0.19069" size="0.00967866"/>
          </body>
        </body>
      </body>
    </body>
  </worldbody>

  <contact>
    <pair class="/" geom1="floor" geom2="FL_foot" name="//unnamed_contact_0"/>
    <pair class="/" geom1="floor" geom2="FR_foot" name="//unnamed_contact_1"/>
    <pair class="/" geom1="floor" geom2="RL_foot" name="//unnamed_contact_2"/>
    <pair class="/" geom1="floor" geom2="RR_foot" name="//unnamed_contact_3"/>
  </contact>

  <actuator>
    <general name="FL_hip" class="/" joint="FL_hip_joint" forcerange="-22.8218 22.8218" gainprm="19.681" biasprm="0 -19.681 -0.48214"/>
    <general name="FL_thigh" class="/" joint="FL_thigh_joint" forcerange="-23.2456 23.2456" gainprm="19.681" biasprm="0 -19.681 -0.48214"/>
    <general name="FL_calf" class="/" joint="FL_calf_joint" forcerange="-42.3867 42.3867" gainprm="19.681" biasprm="0 -19.681 -0.48214"/>
    <general name="FR_hip" class="/" joint="FR_hip_joint" forcerange="-22.5899 22.5899" gainprm="19.681" biasprm="0 -19.681 -0.48214"/>
    <general name="FR_thigh" class="/" joint="FR_thigh_joint" forcerange="-22.1799 22.1799" gainprm="19.681" biasprm="0 -19.681 -0.48214"/>
    <general name="FR_calf" class="/" joint="FR_calf_joint" forcerange="-43.6148 43.6148" gainprm="19.681" biasprm="0 -19.681 -0.48214"/>
    <general name="RL_hip" class="/" joint="RL_hip_joint" forcerange="-22.7966 22.7966" gainprm="19.681" biasprm="0 -19.681 -0.48214"/>
    <general name="RL_thigh" class="/" joint="RL_thigh_joint" forcerange="-22.6635 22.6635" gainprm="19.681" biasprm="0 -19.681 -0.48214"/>
    <general name="RL_calf" class="/" joint="RL_calf_joint" forcerange="-43.6493 43.6493" gainprm="19.681" biasprm="0 -19.681 -0.48214"/>
    <general name="RR_hip" class="/" joint="RR_hip_joint" forcerange="-22.936 22.936" gainprm="19.681" biasprm="0 -19.681 -0.48214"/>
    <general name="RR_thigh" class="/" joint="RR_thigh_joint" forcerange="-22.9397 22.9397" gainprm="19.681" biasprm="0 -19.681 -0.48214"/>
    <general name="RR_calf" class="/" joint="RR_calf_joint" forcerange="-42.6503 42.6503" gainprm="19.681" biasprm="0 -19.681 -0.48214"/>
  </actuator>

  <sensor>
    <gyro site="imu" name="imu_angular_velocity"/>
    <velocimeter site="imu" name="imu_linear_velocity"/>
    <framelinvel objtype="site" objname="FL_foot" name="FL_foot_global_linear_velocity"/>
    <framelinvel objtype="site" objname="FR_foot" name="FR_foot_global_linear_velocity"/>
    <framelinvel objtype="site" objname="RL_foot" name="RL_foot_global_linear_velocity"/>
    <framelinvel objtype="site" objname="RR_foot" name="RR_foot_global_linear_velocity"/>
  </sensor>

  <keyframe>
    <key name="home" qpos="0 0 0.325 1 0 0 0 0.1 0.8 -1.5 -0.1 -0.8 1.5 -0.1 0.8 -1.5 0.1 -0.8 1.5"/>
  </keyframe>
</mujoco>
