<mujoco model="go2">
  <compiler angle="radian" assetdir="assets" balanceinertia="true" inertiafromgeom="false"/>

  <option timestep="0.005" density="1.2" viscosity="2e-05"/>

  <size nkey="1"/>

  <visual>
    <quality shadowsize="8192"/>
    <map shadowclip="0.5"/>
  </visual>

  <default>
    <default class="/">
      <geom contype="0" conaffinity="0" group="1" solref="-1000 -80"/>
      <site size="0.01 0.005 0.005" group="5"/>
      <general forcelimited="true" biastype="affine" gainprm="20" biasprm="0 -20 -0.5"/>
      <default class="go2">
        <joint armature="0.01" damping="0.01" frictionloss="0.2"/>
        <geom condim="1" margin="0.001"/>
        <default class="visual">
          <geom type="mesh" group="2"/>
        </default>
        <default class="collision">
          <geom group="3"/>
          <default class="foot">
            <geom size="0.022 0 0" condim="6" priority="1" friction="0.8 0.02 0.01" solimp="0.015 1 0.022"/>
          </default>
        </default>
        <default class="reward_collision_sphere">
          <geom group="5" rgba="1 0 0 1"/>
        </default>
      </default>
    </default>
  </default>

  <asset>
    <texture type="skybox" colorspace="auto" name="//unnamed_texture_0" builtin="gradient" rgb1="0.95 0.95 0.95" rgb2="0.95 0.95 0.95" width="100" height="600"/>
    <texture type="2d" colorspace="auto" name="texplane" builtin="checker" rgb1="0.345 0.575 0.748" rgb2="0.345 0.575 0.748" markrgb="1 1 1" width="512" height="512"/>
    <material name="MatPlane" class="/" texture="texplane" texuniform="true" texrepeat="2 2" specular="0.9"/>
    <material name="metal" class="/" rgba="0.9 0.95 0.95 1"/>
    <material name="black" class="/" rgba="0 0 0 1"/>
    <material name="white" class="/"/>
    <material name="gray" class="/" rgba="0.671705 0.692426 0.77427 1"/>
    <mesh name="base_0" class="/" file="base_0.obj"/>
    <mesh name="base_1" class="/" file="base_1.obj"/>
    <mesh name="base_2" class="/" file="base_2.obj"/>
    <mesh name="base_3" class="/" file="base_3.obj"/>
    <mesh name="base_4" class="/" file="base_4.obj"/>
    <mesh name="hip_0" class="/" file="hip_0.obj"/>
    <mesh name="hip_1" class="/" file="hip_1.obj"/>
    <mesh name="thigh_0" class="/" file="thigh_0.obj"/>
    <mesh name="thigh_1" class="/" file="thigh_1.obj"/>
    <mesh name="thigh_mirror_0" class="/" file="thigh_mirror_0.obj"/>
    <mesh name="thigh_mirror_1" class="/" file="thigh_mirror_1.obj"/>
    <mesh name="calf_0" class="/" file="calf_0.obj"/>
    <mesh name="calf_1" class="/" file="calf_1.obj"/>
    <mesh name="calf_mirror_0" class="/" file="calf_mirror_0.obj"/>
    <mesh name="calf_mirror_1" class="/" file="calf_mirror_1.obj"/>
    <mesh name="foot" class="/" file="foot.obj"/>
  </asset>

  <worldbody>
    <geom name="floor" class="/" size="100 100 0.125" type="plane" group="0" material="MatPlane"/>
    <light name="toplight_shadow" class="/" pos="0 0 5" dir="0.0990148 0.0990148 -0.990148" type="directional" ambient="0.04 0.04 0.04" diffuse="0.55 0.55 0.55" specular="0.12 0.12 0.12"/>
    <light name="toplight_fill" class="/" pos="0 0 5" dir="0.0990148 0.0990148 -0.990148" type="directional" castshadow="false" ambient="0.04 0.04 0.04" diffuse="0.3 0.3 0.3" specular="0.08 0.08 0.08"/>
    <body name="trunk" childclass="go2" pos="0.000478156 7.44089e-05 -0.0020711" quat="1 0.00045245 0.000458482 0.00060649">
      <inertial pos="0.0222923 0.00138476 -0.00483798" quat="-7.06061e-05 0.713369 0.00643513 0.700759" mass="6.45851" diaginertia="0.132623 0.0906532 0.0142562"/>
      <joint name="//unnamed_joint_0" type="free" armature="0" damping="0" frictionloss="0"/>
      <geom name="//unnamed_geom_1" class="visual" material="black" mesh="base_0"/>
      <geom name="//unnamed_geom_2" class="visual" material="black" mesh="base_1"/>
      <geom name="//unnamed_geom_3" class="visual" material="black" mesh="base_2"/>
      <geom name="//unnamed_geom_4" class="visual" material="white" mesh="base_3"/>
      <geom name="//unnamed_geom_5" class="visual" material="gray" mesh="base_4"/>
      <geom name="trunk_1" class="collision" size="0.18252 0.0453633 0.0553092" type="box"/>
      <geom name="trunk_2" class="collision" size="0.0485169 0.0436652" pos="0.296255 0 0.00892797" type="cylinder"/>
      <geom name="trunk_3" class="collision" size="0.0456058" pos="0.304571 0 -0.0535678"/>
      <geom name="//unnamed_geom_9" class="reward_collision_sphere" size="0.0970337"/>
      <geom name="//unnamed_geom_10" class="reward_collision_sphere" size="0.0582202" pos="0.291058 0 -0.0401759"/>
      <site name="imu" pos="-0.0267671 -0.00208522 0.0339443" size="0.00970337"/>
      <camera name="track" pos="0 -1.95744 0" quat="0.707107 0.707107 0 0" mode="trackcom"/>
      <camera name="ego_camera" pos="0.324322 0 0.0401759" quat="-0.5 -0.5 0.5 0.5"/>
      <body name="FL_hip" pos="0.200153 0.0449497 0.000798589" quat="1 -2.51257e-05 -1.72532e-05 4.96393e-05">
        <inertial pos="-0.00692098 0.00170814 -0.00230109" quat="0.491779 0.494954 0.512457 0.500561" mass="0.624398" diaginertia="0.00108583 0.000543657 0.000274022"/>
        <joint name="FL_hip_joint" pos="0 0 0" axis="0.999984 0.000662785 0.00563551" range="-1.05192 1.03656" armature="0.00967764" damping="0.00126057" frictionloss="0.187613"/>
        <geom name="//unnamed_geom_11" class="visual" material="metal" mesh="hip_0"/>
        <geom name="//unnamed_geom_12" class="visual" material="gray" mesh="hip_1"/>
        <geom name="//unnamed_geom_13" class="collision" size="0.0446355 0.0194067" pos="0 0.0782977 0" quat="0.707107 0.707107 0 0" type="cylinder"/>
        <geom name="//unnamed_geom_14" class="reward_collision_sphere" size="0.0582202" pos="0 0.0685105 0"/>
        <body name="FL_thigh" pos="-0.00190762 0.0923898 0.00227726" quat="1 1.27113e-05 -1.9334e-05 1.94934e-05">
          <inertial pos="-0.00489242 -0.0217431 -0.0291687" quat="0.83032 0.086948 -0.0235283 0.54996" mass="1.02964" diaginertia="0.00708427 0.00515523 0.000484265"/>
          <joint name="FL_thigh_joint" pos="0 0 0" axis="0.00217501 0.999978 0.00619434" stiffness="0.00288198" range="-1.55791 3.49459" armature="0.0095179" damping="0.00977899" frictionloss="0.194475"/>
          <geom name="//unnamed_geom_15" class="visual" material="metal" mesh="thigh_0"/>
          <geom name="//unnamed_geom_16" class="visual" material="gray" mesh="thigh_1"/>
          <geom name="//unnamed_geom_17" class="collision" size="0.103341 0.0118866 0.0164957" pos="0 0 -0.0950829" quat="0.707107 0 0.707107 0" type="box"/>
          <body name="FL_calf" pos="-0.000726101 -0.000766618 -0.190095" quat="1 8.82045e-06 -5.71718e-05 6.23483e-05">
            <inertial pos="0.0042663 -0.00232148 -0.125218" quat="0.710534 0.00201209 -0.00464015 0.703644" mass="0.220357" diaginertia="0.00177257 0.00132474 3.01691e-05"/>
            <joint name="FL_calf_joint" pos="0 0 0" axis="-0.000820099 0.999998 -0.0017077" stiffness="0.00607764" range="-2.77058 -0.843474" armature="0.00983032" damping="0.0110825" frictionloss="0.215237"/>
            <geom name="//unnamed_geom_18" class="visual" material="gray" mesh="calf_0"/>
            <geom name="//unnamed_geom_19" class="visual" material="black" mesh="calf_1"/>
            <geom name="FL_calf0" class="collision" size="0.011644 0.0582202" pos="0.00831594 0 -0.0535678" quat="0.994493 0 -0.104807 0" type="cylinder"/>
            <geom name="//unnamed_geom_21" class="collision" size="0.0106737 0.031536" pos="0.0207898 0 -0.132134" quat="0.999688 0 0.0249974 0" type="cylinder"/>
            <geom name="//unnamed_geom_22" class="visual" pos="0 0 -0.190166" quat="1 0 0 0" material="black" mesh="foot"/>
            <geom name="FL_foot" class="foot" size="0.0170338" pos="-0.00207898 0 -0.190166"/>
            <geom name="//unnamed_geom_24" class="reward_collision_sphere" size="0.0242584"/>
            <geom name="//unnamed_geom_25" class="reward_collision_sphere" size="0.0242584" pos="-0.00207898 0 -0.190166"/>
            <site name="FL_foot" class="foot" pos="-0.00207898 0 -0.190166" size="0.00970337"/>
          </body>
        </body>
      </body>
      <body name="FR_hip" pos="0.20179 -0.0460311 -0.000191888" quat="0.999999 0.000928756 -2.95711e-05 -0.00079001">
        <inertial pos="-0.00458908 -0.0019761 -0.000465879" quat="0.490137 0.511164 0.502834 0.495616" mass="0.642845" diaginertia="0.0010859 0.000543206 0.000276586"/>
        <joint name="FR_hip_joint" pos="0 0 0" axis="1 0.000679808 -0.000263655" range="-1.09023 1.06196" armature="0.00945224" damping="0.00825292" frictionloss="0.193529"/>
        <geom name="//unnamed_geom_26" class="visual" pos="0 7.48533e-10 3.21061e-08" quat="4.63268e-05 1 0 0" material="metal" mesh="hip_0"/>
        <geom name="//unnamed_geom_27" class="visual" pos="0 1.21346e-09 -7.94107e-08" quat="4.63268e-05 1 0 0" material="gray" mesh="hip_1"/>
        <geom name="//unnamed_geom_28" class="collision" size="0.0446355 0.0194067" pos="0 -0.0782977 0" quat="0.707107 0.707107 0 0" type="cylinder"/>
        <geom name="//unnamed_geom_29" class="reward_collision_sphere" size="0.0582202" pos="0 -0.0685105 0"/>
        <body name="FR_thigh" pos="0.000145476 -0.0933954 0.0024052" quat="1 -0.000178071 -5.58217e-06 -0.000261181">
          <inertial pos="-0.0031015 0.0216949 -0.0279508" quat="0.548753 -0.0188143 0.0846127 0.831479" mass="1.06358" diaginertia="0.00723071 0.00519318 0.000493458"/>
          <joint name="FR_thigh_joint" pos="0 0 0" axis="0.00068499 -1 -8.12279e-05" stiffness="0.00585035" range="-3.49312 1.57766" armature="0.0102002" damping="0.00446513" frictionloss="0.186258"/>
          <geom name="//unnamed_geom_30" class="visual" material="metal" mesh="thigh_mirror_0"/>
          <geom name="//unnamed_geom_31" class="visual" material="gray" mesh="thigh_mirror_1"/>
          <geom name="//unnamed_geom_32" class="collision" size="0.103341 0.0118866 0.0164957" pos="0 0 -0.0950829" quat="0.707107 0 0.707107 0" type="box"/>
          <body name="FR_calf" pos="-0.00219837 -7.64302e-05 -0.189035" quat="1 1.98846e-05 -2.81899e-05 1.65466e-05">
            <inertial pos="0.00699401 -0.000880585 -0.125455" quat="0.696296 -0.00166956 0.00536407 0.717733" mass="0.215173" diaginertia="0.00176324 0.00130909 2.95581e-05"/>
            <joint name="FR_calf_joint" pos="0 0 0" axis="0.000870823 -0.999999 -0.000603948" stiffness="0.00239708" range="0.841939 2.71262" armature="0.00963901" damping="0.00207306" frictionloss="0.202096"/>
            <geom name="//unnamed_geom_33" class="visual" material="gray" mesh="calf_mirror_0"/>
            <geom name="//unnamed_geom_34" class="visual" material="black" mesh="calf_mirror_1"/>
            <geom name="FR_calf0" class="collision" size="0.0126144 0.0582202" pos="0.0103949 0 -0.0535678" quat="0.995004 0 -0.0998334 0" type="cylinder"/>
            <geom name="//unnamed_geom_36" class="collision" size="0.0106737 0.031536" pos="0.0207898 0 -0.132134" quat="0.999688 0 0.0249974 0" type="cylinder"/>
            <geom name="//unnamed_geom_37" class="visual" pos="0 0 -0.190166" quat="1 0 0 0" material="black" mesh="foot"/>
            <geom name="FR_foot" class="foot" size="0.0213279" pos="-0.00207898 0 -0.190166"/>
            <geom name="//unnamed_geom_39" class="reward_collision_sphere" size="0.0242584"/>
            <geom name="//unnamed_geom_40" class="reward_collision_sphere" size="0.0242584" pos="-0.00207898 0 -0.190166"/>
            <site name="FR_foot" class="foot" pos="-0.00207898 0 -0.190166" size="0.00970337"/>
          </body>
        </body>
      </body>
      <body name="RL_hip" pos="-0.200954 0.0454405 0.00126397" quat="1 -2.23572e-05 5.99059e-05 7.37143e-05">
        <inertial pos="0.00627961 0.000927982 -0.00195566" quat="0.501619 0.498579 0.497259 0.502524" mass="0.618665" diaginertia="0.00109017 0.000531386 0.000271364"/>
        <joint name="RL_hip_joint" pos="0 0 0" axis="-0.999856 0.00554126 0.0160435" stiffness="0.00147488" range="-1.07726 1.07821" armature="0.0103132" damping="0.0126713" frictionloss="0.192029"/>
        <geom name="//unnamed_geom_41" class="visual" pos="-1.27795e-09 0 -2.50507e-07" quat="4.63268e-05 0 1 0" material="metal" mesh="hip_0"/>
        <geom name="//unnamed_geom_42" class="visual" pos="-2.0717e-09 0 -2.22164e-07" quat="4.63268e-05 0 1 0" material="gray" mesh="hip_1"/>
        <geom name="//unnamed_geom_43" class="collision" size="0.0446355 0.0194067" pos="0 0.0782977 0" quat="0.707107 0.707107 0 0" type="cylinder"/>
        <geom name="//unnamed_geom_44" class="reward_collision_sphere" size="0.0582202" pos="0 0.0685105 0"/>
        <body name="RL_thigh" pos="0.000973457 0.0917075 0.00101268" quat="1 -0.000219222 8.21429e-05 2.32269e-05">
          <inertial pos="-0.00159324 -0.0220398 -0.0314082" quat="0.829567 0.0848974 -0.0198051 0.55156" mass="1.0812" diaginertia="0.00759605 0.00542283 0.000514091"/>
          <joint name="RL_thigh_joint" pos="0 0 0" axis="-0.0136487 0.999842 -0.0114121" range="-0.522393 4.53991" armature="0.00977483" damping="0.00149627" frictionloss="0.1852"/>
          <geom name="//unnamed_geom_45" class="visual" material="metal" mesh="thigh_0"/>
          <geom name="//unnamed_geom_46" class="visual" material="gray" mesh="thigh_1"/>
          <geom name="//unnamed_geom_47" class="collision" size="0.103341 0.0118866 0.0164957" pos="0 0 -0.0950829" quat="0.707107 0 0.707107 0" type="box"/>
          <body name="RL_calf" pos="-0.000595054 -0.00156883 -0.191153" quat="1 8.59229e-05 0.000121644 0.000253727">
            <inertial pos="0.00451624 1.11286e-05 -0.128393" quat="0.713489 -0.00133788 0.00184971 0.700663" mass="0.220021" diaginertia="0.00180082 0.00132089 2.9651e-05"/>
            <joint name="RL_calf_joint" pos="0 0 0" axis="0.000369231 0.999951 -0.00984554" stiffness="0.00133846" range="-2.71556 -0.882908" armature="0.0104963" damping="0" frictionloss="0.192816"/>
            <geom name="//unnamed_geom_48" class="visual" material="gray" mesh="calf_0"/>
            <geom name="//unnamed_geom_49" class="visual" material="black" mesh="calf_1"/>
            <geom name="RL_calf0" class="collision" size="0.0126144 0.0582202" pos="0.0103949 0 -0.0535678" quat="0.995004 0 -0.0998334 0" type="cylinder"/>
            <geom name="//unnamed_geom_51" class="collision" size="0.0106737 0.031536" pos="0.0207898 0 -0.132134" quat="0.999688 0 0.0249974 0" type="cylinder"/>
            <geom name="//unnamed_geom_52" class="visual" pos="0 0 -0.190166" quat="1 0 0 0" material="black" mesh="foot"/>
            <geom name="RL_foot" class="foot" size="0.0190307" pos="-0.00207898 0 -0.190166"/>
            <geom name="//unnamed_geom_54" class="reward_collision_sphere" size="0.0242584"/>
            <geom name="//unnamed_geom_55" class="reward_collision_sphere" size="0.0242584" pos="-0.00207898 0 -0.190166"/>
            <site name="RL_foot" class="foot" pos="-0.00207898 0 -0.190166" size="0.00970337"/>
          </body>
        </body>
      </body>
      <body name="RR_hip" pos="-0.198895 -0.0461214 0.000480236" quat="1 0.000221616 2.58266e-05 3.55747e-05">
        <inertial pos="0.00471459 -0.00161626 0.000639262" quat="0.50583 0.491984 0.49786 0.504206" mass="0.617051" diaginertia="0.00112643 0.000547025 0.000277004"/>
        <joint name="RR_hip_joint" pos="0 0 0" axis="-0.999932 0.00812052 -0.00841898" range="-1.02962 1.04695" armature="0.00965336" damping="0.0045551" frictionloss="0.215968"/>
        <geom name="//unnamed_geom_56" class="visual" pos="1.27584e-09 7.48533e-10 -2.82613e-07" quat="2.14617e-09 4.63268e-05 4.63268e-05 -1" material="metal" mesh="hip_0"/>
        <geom name="//unnamed_geom_57" class="visual" pos="2.07691e-09 1.21346e-09 -1.42753e-07" quat="2.14617e-09 4.63268e-05 4.63268e-05 -1" material="gray" mesh="hip_1"/>
        <geom name="//unnamed_geom_58" class="collision" size="0.0446355 0.0194067" pos="0 -0.0782977 0" quat="0.707107 0.707107 0 0" type="cylinder"/>
        <geom name="//unnamed_geom_59" class="reward_collision_sphere" size="0.0582202" pos="0 -0.0685105 0"/>
        <body name="RR_thigh" pos="0.000555114 -0.0939429 -0.00177015" quat="1 7.57063e-06 -3.53908e-05 9.58273e-06">
          <inertial pos="-0.00272161 0.0229237 -0.0311042" quat="0.551643 -0.019979 0.0847471 0.829523" mass="1.03466" diaginertia="0.00741805 0.00531785 0.00050132"/>
          <joint name="RR_thigh_joint" pos="0 0 0" axis="0.00120318 -0.999999 -0.000110518" stiffness="0.00188179" range="-4.53518 0.51078" armature="0.00972443" damping="0.020287" frictionloss="0.200259"/>
          <geom name="//unnamed_geom_60" class="visual" material="metal" mesh="thigh_mirror_0"/>
          <geom name="//unnamed_geom_61" class="visual" material="gray" mesh="thigh_mirror_1"/>
          <geom name="//unnamed_geom_62" class="collision" size="0.103341 0.0118866 0.0164957" pos="0 0 -0.0950829" quat="0.707107 0 0.707107 0" type="box"/>
          <body name="RR_calf" pos="-0.000943516 0.000640336 -0.192076" quat="0.999999 -0.000332924 0.000305787 -0.000990122">
            <inertial pos="0.00557955 0.000400565 -0.125933" quat="0.705707 0.000589932 -0.00430294 0.708491" mass="0.219886" diaginertia="0.00179688 0.00129842 2.93593e-05"/>
            <joint name="RR_calf_joint" pos="0 0 0" axis="-0.013478 -0.999907 0.00188002" range="0.86509 2.73732" armature="0.00966885" damping="0.00480052" frictionloss="0.2011"/>
            <geom name="//unnamed_geom_63" class="visual" material="gray" mesh="calf_mirror_0"/>
            <geom name="//unnamed_geom_64" class="visual" material="black" mesh="calf_mirror_1"/>
            <geom name="RR_calf0" class="collision" size="0.0126144 0.0582202" pos="0.0103949 0 -0.0535678" quat="0.995004 0 -0.0998334 0" type="cylinder"/>
            <geom name="//unnamed_geom_66" class="collision" size="0.0106737 0.031536" pos="0.0207898 0 -0.132134" quat="0.999688 0 0.0249974 0" type="cylinder"/>
            <geom name="//unnamed_geom_67" class="visual" pos="0 0 -0.190166" quat="1 0 0 0" material="black" mesh="foot"/>
            <geom name="RR_foot" class="foot" size="0.0236596" pos="-0.00207898 0 -0.190166"/>
            <geom name="//unnamed_geom_69" class="reward_collision_sphere" size="0.0242584"/>
            <geom name="//unnamed_geom_70" class="reward_collision_sphere" size="0.0242584" pos="-0.00207898 0 -0.190166"/>
            <site name="RR_foot" class="foot" pos="-0.00207898 0 -0.190166" size="0.00970337"/>
          </body>
        </body>
      </body>
    </body>
  </worldbody>

  <contact>
    <pair class="/" geom1="floor" geom2="FL_foot" name="//unnamed_contact_0"/>
    <pair class="/" geom1="floor" geom2="FR_foot" name="//unnamed_contact_1"/>
    <pair class="/" geom1="floor" geom2="RL_foot" name="//unnamed_contact_2"/>
    <pair class="/" geom1="floor" geom2="RR_foot" name="//unnamed_contact_3"/>
  </contact>

  <actuator>
    <general name="FL_hip" class="/" joint="FL_hip_joint" forcerange="-23.1889 23.1889" gainprm="19.3721" biasprm="0 -19.3721 -0.497476"/>
    <general name="FL_thigh" class="/" joint="FL_thigh_joint" forcerange="-23.1408 23.1408" gainprm="19.3721" biasprm="0 -19.3721 -0.497476"/>
    <general name="FL_calf" class="/" joint="FL_calf_joint" forcerange="-43.2104 43.2104" gainprm="19.3721" biasprm="0 -19.3721 -0.497476"/>
    <general name="FR_hip" class="/" joint="FR_hip_joint" forcerange="-22.7828 22.7828" gainprm="19.3721" biasprm="0 -19.3721 -0.497476"/>
    <general name="FR_thigh" class="/" joint="FR_thigh_joint" forcerange="-22.4775 22.4775" gainprm="19.3721" biasprm="0 -19.3721 -0.497476"/>
    <general name="FR_calf" class="/" joint="FR_calf_joint" forcerange="-44.2307 44.2307" gainprm="19.3721" biasprm="0 -19.3721 -0.497476"/>
    <general name="RL_hip" class="/" joint="RL_hip_joint" forcerange="-23.1772 23.1772" gainprm="19.3721" biasprm="0 -19.3721 -0.497476"/>
    <general name="RL_thigh" class="/" joint="RL_thigh_joint" forcerange="-21.3076 21.3076" gainprm="19.3721" biasprm="0 -19.3721 -0.497476"/>
    <general name="RL_calf" class="/" joint="RL_calf_joint" forcerange="-46.6689 46.6689" gainprm="19.3721" biasprm="0 -19.3721 -0.497476"/>
    <general name="RR_hip" class="/" joint="RR_hip_joint" forcerange="-23.1239 23.1239" gainprm="19.3721" biasprm="0 -19.3721 -0.497476"/>
    <general name="RR_thigh" class="/" joint="RR_thigh_joint" forcerange="-23.8293 23.8293" gainprm="19.3721" biasprm="0 -19.3721 -0.497476"/>
    <general name="RR_calf" class="/" joint="RR_calf_joint" forcerange="-43.8947 43.8947" gainprm="19.3721" biasprm="0 -19.3721 -0.497476"/>
  </actuator>

  <sensor>
    <gyro site="imu" name="imu_angular_velocity"/>
    <velocimeter site="imu" name="imu_linear_velocity"/>
    <framelinvel objtype="site" objname="FL_foot" name="FL_foot_global_linear_velocity"/>
    <framelinvel objtype="site" objname="FR_foot" name="FR_foot_global_linear_velocity"/>
    <framelinvel objtype="site" objname="RL_foot" name="RL_foot_global_linear_velocity"/>
    <framelinvel objtype="site" objname="RR_foot" name="RR_foot_global_linear_velocity"/>
  </sensor>

  <keyframe>
    <key name="home" qpos="0 0 0.325 1 0 0 0 0.1 0.8 -1.5 -0.1 -0.8 1.5 -0.1 0.8 -1.5 0.1 -0.8 1.5"/>
  </keyframe>
</mujoco>
