<mujoco model="go2">
  <compiler angle="radian" assetdir="assets" balanceinertia="true" inertiafromgeom="false"/>

  <option timestep="0.005" density="1.2" viscosity="2e-05"/>

  <size nkey="1"/>

  <visual>
    <quality shadowsize="8192"/>
    <map shadowclip="0.5"/>
  </visual>

  <default>
    <default class="/">
      <geom contype="0" conaffinity="0" group="1" solref="-1000 -80"/>
      <site size="0.01 0.005 0.005" group="5"/>
      <general forcelimited="true" biastype="affine" gainprm="20" biasprm="0 -20 -0.5"/>
      <default class="go2">
        <joint armature="0.01" damping="0.01" frictionloss="0.2"/>
        <geom condim="1" margin="0.001"/>
        <default class="visual">
          <geom type="mesh" group="2"/>
        </default>
        <default class="collision">
          <geom group="3"/>
          <default class="foot">
            <geom size="0.022 0 0" condim="6" priority="1" friction="0.8 0.02 0.01" solimp="0.015 1 0.022"/>
          </default>
        </default>
        <default class="reward_collision_sphere">
          <geom group="5" rgba="1 0 0 1"/>
        </default>
      </default>
    </default>
  </default>

  <asset>
    <texture type="skybox" colorspace="auto" name="//unnamed_texture_0" builtin="gradient" rgb1="0.95 0.95 0.95" rgb2="0.95 0.95 0.95" width="100" height="600"/>
    <texture type="2d" colorspace="auto" name="texplane" builtin="checker" rgb1="0.345 0.575 0.748" rgb2="0.345 0.575 0.748" markrgb="1 1 1" width="512" height="512"/>
    <material name="MatPlane" class="/" texture="texplane" texuniform="true" texrepeat="2 2" specular="0.9"/>
    <material name="metal" class="/" rgba="0.9 0.95 0.95 1"/>
    <material name="black" class="/" rgba="0 0 0 1"/>
    <material name="white" class="/"/>
    <material name="gray" class="/" rgba="0.671705 0.692426 0.77427 1"/>
    <mesh name="base_0" class="/" file="base_0.obj"/>
    <mesh name="base_1" class="/" file="base_1.obj"/>
    <mesh name="base_2" class="/" file="base_2.obj"/>
    <mesh name="base_3" class="/" file="base_3.obj"/>
    <mesh name="base_4" class="/" file="base_4.obj"/>
    <mesh name="hip_0" class="/" file="hip_0.obj"/>
    <mesh name="hip_1" class="/" file="hip_1.obj"/>
    <mesh name="thigh_0" class="/" file="thigh_0.obj"/>
    <mesh name="thigh_1" class="/" file="thigh_1.obj"/>
    <mesh name="thigh_mirror_0" class="/" file="thigh_mirror_0.obj"/>
    <mesh name="thigh_mirror_1" class="/" file="thigh_mirror_1.obj"/>
    <mesh name="calf_0" class="/" file="calf_0.obj"/>
    <mesh name="calf_1" class="/" file="calf_1.obj"/>
    <mesh name="calf_mirror_0" class="/" file="calf_mirror_0.obj"/>
    <mesh name="calf_mirror_1" class="/" file="calf_mirror_1.obj"/>
    <mesh name="foot" class="/" file="foot.obj"/>
  </asset>

  <worldbody>
    <geom name="floor" class="/" size="100 100 0.125" type="plane" group="0" material="MatPlane"/>
    <light name="toplight_shadow" class="/" pos="0 0 5" dir="0.0990148 0.0990148 -0.990148" type="directional" ambient="0.04 0.04 0.04" diffuse="0.55 0.55 0.55" specular="0.12 0.12 0.12"/>
    <light name="toplight_fill" class="/" pos="0 0 5" dir="0.0990148 0.0990148 -0.990148" type="directional" castshadow="false" ambient="0.04 0.04 0.04" diffuse="0.3 0.3 0.3" specular="0.08 0.08 0.08"/>
    <body name="trunk" childclass="go2" pos="-0.000309613 -0.00281909 -0.000871543" quat="0.999999 -5.65043e-05 0.00135826 0.000380551">
      <inertial pos="0.017644 -0.00159431 -0.00206176" quat="0.00578742 0.712673 0.00926234 0.701411" mass="5.76025" diaginertia="0.0846223 0.0753863 0.0142583"/>
      <joint name="//unnamed_joint_0" type="free" armature="0" damping="0" frictionloss="0"/>
      <geom name="//unnamed_geom_1" class="visual" material="black" mesh="base_0"/>
      <geom name="//unnamed_geom_2" class="visual" material="black" mesh="base_1"/>
      <geom name="//unnamed_geom_3" class="visual" material="black" mesh="base_2"/>
      <geom name="//unnamed_geom_4" class="visual" material="white" mesh="base_3"/>
      <geom name="//unnamed_geom_5" class="visual" material="gray" mesh="base_4"/>
      <geom name="trunk_1" class="collision" size="0.176299 0.0438171 0.053424" type="box"/>
      <geom name="trunk_2" class="collision" size="0.0468632 0.0421769" pos="0.274268 0 0.00895997" type="cylinder"/>
      <geom name="trunk_3" class="collision" size="0.0440514" pos="0.281966 0 -0.0537598"/>
      <geom name="//unnamed_geom_9" class="reward_collision_sphere" size="0.0937264"/>
      <geom name="//unnamed_geom_10" class="reward_collision_sphere" size="0.0562358" pos="0.269456 0 -0.0403199"/>
      <site name="imu" pos="-0.0193143 -0.00389656 0.0340851" size="0.00937264"/>
      <camera name="track" pos="0 -1.9069 0" quat="0.707107 0.707107 0 0" mode="trackcom"/>
      <camera name="ego_camera" pos="0.300251 0 0.0403199" quat="-0.5 -0.5 0.5 0.5"/>
      <body name="FL_hip" pos="0.18501 0.0446834 -0.000415173" quat="1 0.0001175 -0.000157194 -0.000167453">
        <inertial pos="-0.00560689 -0.000624982 -0.00123091" quat="0.492876 0.500408 0.506472 0.500152" mass="0.555975" diaginertia="0.000735133 0.000455579 0.000278343"/>
        <joint name="FL_hip_joint" pos="0 0 0" axis="0.999897 0.0130953 -0.00594843" stiffness="0.00999685" range="-1.09906 1.06161" armature="0.00961051" damping="0.00109561" frictionloss="0.1827"/>
        <geom name="//unnamed_geom_11" class="visual" material="metal" mesh="hip_0"/>
        <geom name="//unnamed_geom_12" class="visual" material="gray" mesh="hip_1"/>
        <geom name="//unnamed_geom_13" class="collision" size="0.0431141 0.0187453" pos="0 0.0762761 0" quat="0.707107 0.707107 0 0" type="cylinder"/>
        <geom name="//unnamed_geom_14" class="reward_collision_sphere" size="0.0562358" pos="0 0.0667416 0"/>
        <body name="FL_thigh" pos="0.00203445 0.0933304 -0.000363149" quat="1 -0.000572393 -0.000102499 -0.000496761">
          <inertial pos="-0.00325078 -0.0199078 -0.0281286" quat="0.830086 0.0863425 -0.0118094 0.550784" mass="0.983968" diaginertia="0.00479479 0.00473181 0.000509577"/>
          <joint name="FL_thigh_joint" pos="0 0 0" axis="0.0160704 0.999871 0.000767718" stiffness="0.0142738" range="-1.62657 3.4478" armature="0.0100514" damping="0.00150569" frictionloss="0.163243"/>
          <geom name="//unnamed_geom_15" class="visual" material="metal" mesh="thigh_0"/>
          <geom name="//unnamed_geom_16" class="visual" material="gray" mesh="thigh_1"/>
          <geom name="//unnamed_geom_17" class="collision" size="0.0998186 0.0114815 0.0159335" pos="0 0 -0.0954237" quat="0.707107 0 0.707107 0" type="box"/>
          <body name="FL_calf" pos="0.000291203 -0.00138461 -0.190464" quat="1 0.000251928 0.000371569 0.000113342">
            <inertial pos="0.00369188 -0.00324279 -0.128956" quat="0.706338 0.00293732 -0.00687816 0.707835" mass="0.194708" diaginertia="0.00118282 0.00114262 3.00179e-05"/>
            <joint name="FL_calf_joint" pos="0 0 0" axis="0.000945233 0.999952 0.00977882" stiffness="0.0140818" range="-2.6965 -0.783706" armature="0.00807454" damping="0" frictionloss="0.197529"/>
            <geom name="//unnamed_geom_18" class="visual" material="gray" mesh="calf_0"/>
            <geom name="//unnamed_geom_19" class="visual" material="black" mesh="calf_1"/>
            <geom name="FL_calf0" class="collision" size="0.0112472 0.0562358" pos="0.00769874 0 -0.0537598" quat="0.994493 0 -0.104807 0" type="cylinder"/>
            <geom name="//unnamed_geom_21" class="collision" size="0.0103099 0.0304611" pos="0.0192469 0 -0.132608" quat="0.999688 0 0.0249974 0" type="cylinder"/>
            <geom name="//unnamed_geom_22" class="visual" pos="0 0 -0.190847" quat="1 0 0 0" material="black" mesh="foot"/>
            <geom name="FL_foot" class="foot" size="0.0157925" pos="-0.00192469 0 -0.190847"/>
            <geom name="//unnamed_geom_24" class="reward_collision_sphere" size="0.0234316"/>
            <geom name="//unnamed_geom_25" class="reward_collision_sphere" size="0.0234316" pos="-0.00192469 0 -0.190847"/>
            <site name="FL_foot" class="foot" pos="-0.00192469 0 -0.190847" size="0.00937264"/>
          </body>
        </body>
      </body>
      <body name="FR_hip" pos="0.184681 -0.0463001 -0.00144201" quat="1 0.000524973 6.96186e-05 -9.15775e-05">
        <inertial pos="-0.00391271 -0.000244832 -0.00136578" quat="0.498818 0.514346 0.493361 0.493178" mass="0.548742" diaginertia="0.000705325 0.00047009 0.000282138"/>
        <joint name="FR_hip_joint" pos="0 0 0" axis="0.999913 0.0111499 -0.00698878" range="-1.06914 1.10114" armature="0.0084068" damping="0.00628408" frictionloss="0.193096"/>
        <geom name="//unnamed_geom_26" class="visual" pos="0 5.00516e-10 2.14682e-08" quat="4.63268e-05 1 0 0" material="metal" mesh="hip_0"/>
        <geom name="//unnamed_geom_27" class="visual" pos="0 8.11396e-10 -5.3099e-08" quat="4.63268e-05 1 0 0" material="gray" mesh="hip_1"/>
        <geom name="//unnamed_geom_28" class="collision" size="0.0431141 0.0187453" pos="0 -0.0762761 0" quat="0.707107 0.707107 0 0" type="cylinder"/>
        <geom name="//unnamed_geom_29" class="reward_collision_sphere" size="0.0562358" pos="0 -0.0667416 0"/>
        <body name="FR_thigh" pos="-0.0002799 -0.0907782 0.00142687" quat="1 -0.000213339 -7.56835e-05 -0.000101441">
          <inertial pos="-0.000930713 0.0186591 -0.0272418" quat="0.550629 -0.0192762 0.0912314 0.829526" mass="0.958503" diaginertia="0.0047481 0.00460711 0.000507988"/>
          <joint name="FR_thigh_joint" pos="0 0 0" axis="-0.000297161 -0.999999 -0.00113209" stiffness="0.0045895" range="-3.48441 1.5896" armature="0.00837751" damping="0.0237972" frictionloss="0.161898"/>
          <geom name="//unnamed_geom_30" class="visual" material="metal" mesh="thigh_mirror_0"/>
          <geom name="//unnamed_geom_31" class="visual" material="gray" mesh="thigh_mirror_1"/>
          <geom name="//unnamed_geom_32" class="collision" size="0.0998186 0.0114815 0.0159335" pos="0 0 -0.0954237" quat="0.707107 0 0.707107 0" type="box"/>
          <body name="FR_calf" pos="-0.00230243 -0.000164747 -0.187615" quat="1 8.25705e-05 -1.3122e-06 3.30761e-05">
            <inertial pos="0.00333444 0.0034714 -0.126374" quat="0.706541 0.00364649 0.0015666 0.707661" mass="0.202307" diaginertia="0.0012275 0.0012161 3.01939e-05"/>
            <joint name="FR_calf_joint" pos="0 0 0" axis="0.00401552 -0.999984 0.00389423" range="0.853359 2.73016" armature="0.00974558" damping="0" frictionloss="0.173985"/>
            <geom name="//unnamed_geom_33" class="visual" material="gray" mesh="calf_mirror_0"/>
            <geom name="//unnamed_geom_34" class="visual" material="black" mesh="calf_mirror_1"/>
            <geom name="FR_calf0" class="collision" size="0.0121844 0.0562358" pos="0.00962343 0 -0.0537598" quat="0.995004 0 -0.0998334 0" type="cylinder"/>
            <geom name="//unnamed_geom_36" class="collision" size="0.0103099 0.0304611" pos="0.0192469 0 -0.132608" quat="0.999688 0 0.0249974 0" type="cylinder"/>
            <geom name="//unnamed_geom_37" class="visual" pos="0 0 -0.190847" quat="1 0 0 0" material="black" mesh="foot"/>
            <geom name="FR_foot" class="foot" size="0.020102" pos="-0.00192469 0 -0.190847"/>
            <geom name="//unnamed_geom_39" class="reward_collision_sphere" size="0.0234316"/>
            <geom name="//unnamed_geom_40" class="reward_collision_sphere" size="0.0234316" pos="-0.00192469 0 -0.190847"/>
            <site name="FR_foot" class="foot" pos="-0.00192469 0 -0.190847" size="0.00937264"/>
          </body>
        </body>
      </body>
      <body name="RL_hip" pos="-0.185351 0.0465467 0.000986038" quat="1 -1.24275e-07 -0.000397649 -0.000209572">
        <inertial pos="0.00491101 0.002589 0.00287021" quat="0.505428 0.498231 0.497042 0.499257" mass="0.538082" diaginertia="0.000718565 0.00044685 0.000280414"/>
        <joint name="RL_hip_joint" pos="0 0 0" axis="-0.99992 0.00895318 0.00895666" stiffness="0.0098918" range="-0.998307 1.01411" armature="0.00944403" damping="0.0116585" frictionloss="0.213546"/>
        <geom name="//unnamed_geom_41" class="visual" pos="-5.77975e-10 0 -1.13296e-07" quat="4.63268e-05 0 1 0" material="metal" mesh="hip_0"/>
        <geom name="//unnamed_geom_42" class="visual" pos="-9.36967e-10 0 -1.00478e-07" quat="4.63268e-05 0 1 0" material="gray" mesh="hip_1"/>
        <geom name="//unnamed_geom_43" class="collision" size="0.0431141 0.0187453" pos="0 0.0762761 0" quat="0.707107 0.707107 0 0" type="cylinder"/>
        <geom name="//unnamed_geom_44" class="reward_collision_sphere" size="0.0562358" pos="0 0.0667416 0"/>
        <body name="RL_thigh" pos="-0.000446975 0.0882935 0.00269242" quat="0.999999 -9.84869e-05 0.00095136 -0.00052561">
          <inertial pos="-0.00297042 -0.0202076 -0.0277778" quat="0.822032 0.086432 -0.0161052 0.562613" mass="0.931461" diaginertia="0.00477028 0.0047677 0.000524237"/>
          <joint name="RL_thigh_joint" pos="0 0 0" axis="0.00311225 0.999987 -0.00409263" stiffness="0.00200523" range="-0.502552 4.54743" armature="0.010678" damping="0.0234245" frictionloss="0.163405"/>
          <geom name="//unnamed_geom_45" class="visual" material="metal" mesh="thigh_0"/>
          <geom name="//unnamed_geom_46" class="visual" material="gray" mesh="thigh_1"/>
          <geom name="//unnamed_geom_47" class="collision" size="0.0998186 0.0114815 0.0159335" pos="0 0 -0.0954237" quat="0.707107 0 0.707107 0" type="box"/>
          <body name="RL_calf" pos="-0.00225284 2.94257e-05 -0.188699" quat="0.999999 0.00125938 -0.000159607 -0.000381279">
            <inertial pos="0.00589599 0.00208211 -0.125613" quat="0.711141 -0.00205278 -0.0069718 0.703012" mass="0.194892" diaginertia="0.00117553 0.00110235 2.93554e-05"/>
            <joint name="RL_calf_joint" pos="0 0 0" axis="-0.00670681 0.999971 0.00371284" stiffness="0.00893303" range="-2.69041 -0.824539" armature="0.0100208" damping="0.0140534" frictionloss="0.161484"/>
            <geom name="//unnamed_geom_48" class="visual" material="gray" mesh="calf_0"/>
            <geom name="//unnamed_geom_49" class="visual" material="black" mesh="calf_1"/>
            <geom name="RL_calf0" class="collision" size="0.0121844 0.0562358" pos="0.00962343 0 -0.0537598" quat="0.995004 0 -0.0998334 0" type="cylinder"/>
            <geom name="//unnamed_geom_51" class="collision" size="0.0103099 0.0304611" pos="0.0192469 0 -0.132608" quat="0.999688 0 0.0249974 0" type="cylinder"/>
            <geom name="//unnamed_geom_52" class="visual" pos="0 0 -0.190847" quat="1 0 0 0" material="black" mesh="foot"/>
            <geom name="RL_foot" class="foot" size="0.0173988" pos="-0.00192469 0 -0.190847"/>
            <geom name="//unnamed_geom_54" class="reward_collision_sphere" size="0.0234316"/>
            <geom name="//unnamed_geom_55" class="reward_collision_sphere" size="0.0234316" pos="-0.00192469 0 -0.190847"/>
            <site name="RL_foot" class="foot" pos="-0.00192469 0 -0.190847" size="0.00937264"/>
          </body>
        </body>
      </body>
      <body name="RR_hip" pos="-0.187817 -0.0457698 -0.000912109" quat="1 0.00048643 1.06743e-05 0.000129334">
        <inertial pos="0.00427026 -0.00253645 0.000853259" quat="0.498303 0.49685 0.497284 0.507487" mass="0.544091" diaginertia="0.000710164 0.000460796 0.000272568"/>
        <joint name="RR_hip_joint" pos="0 0 0" axis="-0.999995 -0.00304456 -0.00111974" stiffness="0.00983964" range="-1.03777 1.10372" armature="0.0104097" damping="0.00588341" frictionloss="0.212957"/>
        <geom name="//unnamed_geom_56" class="visual" pos="5.77667e-10 5.00516e-10 -1.34765e-07" quat="2.14617e-09 4.63268e-05 4.63268e-05 -1" material="metal" mesh="hip_0"/>
        <geom name="//unnamed_geom_57" class="visual" pos="9.37728e-10 8.11396e-10 -4.73789e-08" quat="2.14617e-09 4.63268e-05 4.63268e-05 -1" material="gray" mesh="hip_1"/>
        <geom name="//unnamed_geom_58" class="collision" size="0.0431141 0.0187453" pos="0 -0.0762761 0" quat="0.707107 0.707107 0 0" type="cylinder"/>
        <geom name="//unnamed_geom_59" class="reward_collision_sphere" size="0.0562358" pos="0 -0.0667416 0"/>
        <body name="RR_thigh" pos="-0.00257915 -0.0888678 -0.00332314" quat="1 2.29386e-06 -0.000121222 -0.000684472">
          <inertial pos="-0.00311043 0.0185748 -0.029096" quat="0.552521 -0.0239399 0.0837777 0.828932" mass="0.95745" diaginertia="0.00497412 0.00456281 0.000489568"/>
          <joint name="RR_thigh_joint" pos="0 0 0" axis="-0.00101663 -0.999986 0.00526771" stiffness="0.0107107" range="-4.55203 0.55044" armature="0.00858112" damping="0.0240531" frictionloss="0.196189"/>
          <geom name="//unnamed_geom_60" class="visual" material="metal" mesh="thigh_mirror_0"/>
          <geom name="//unnamed_geom_61" class="visual" material="gray" mesh="thigh_mirror_1"/>
          <geom name="//unnamed_geom_62" class="collision" size="0.0998186 0.0114815 0.0159335" pos="0 0 -0.0954237" quat="0.707107 0 0.707107 0" type="box"/>
          <body name="RR_calf" pos="0.00360372 -0.000215531 -0.190677" quat="1 0.000434043 -2.99817e-05 7.77277e-05">
            <inertial pos="0.00334071 -0.000454127 -0.12676" quat="0.704107 -0.00327496 0.00099623 0.710086" mass="0.205014" diaginertia="0.00123521 0.00118189 3.09852e-05"/>
            <joint name="RR_calf_joint" pos="0 0 0" axis="-0.00490107 -0.999955 -0.00807299" range="0.883051 2.77003" armature="0.0097892" damping="0.0151243" frictionloss="0.211208"/>
            <geom name="//unnamed_geom_63" class="visual" material="gray" mesh="calf_mirror_0"/>
            <geom name="//unnamed_geom_64" class="visual" material="black" mesh="calf_mirror_1"/>
            <geom name="RR_calf0" class="collision" size="0.0121844 0.0562358" pos="0.00962343 0 -0.0537598" quat="0.995004 0 -0.0998334 0" type="cylinder"/>
            <geom name="//unnamed_geom_66" class="collision" size="0.0103099 0.0304611" pos="0.0192469 0 -0.132608" quat="0.999688 0 0.0249974 0" type="cylinder"/>
            <geom name="//unnamed_geom_67" class="visual" pos="0 0 -0.190847" quat="1 0 0 0" material="black" mesh="foot"/>
            <geom name="RR_foot" class="foot" size="0.0218218" pos="-0.00192469 0 -0.190847"/>
            <geom name="//unnamed_geom_69" class="reward_collision_sphere" size="0.0234316"/>
            <geom name="//unnamed_geom_70" class="reward_collision_sphere" size="0.0234316" pos="-0.00192469 0 -0.190847"/>
            <site name="RR_foot" class="foot" pos="-0.00192469 0 -0.190847" size="0.00937264"/>
          </body>
        </body>
      </body>
    </body>
  </worldbody>

  <contact>
    <pair class="/" geom1="floor" geom2="FL_foot" name="//unnamed_contact_0"/>
    <pair class="/" geom1="floor" geom2="FR_foot" name="//unnamed_contact_1"/>
    <pair class="/" geom1="floor" geom2="RL_foot" name="//unnamed_contact_2"/>
    <pair class="/" geom1="floor" geom2="RR_foot" name="//unnamed_contact_3"/>
  </contact>

  <actuator>
    <general name="FL_hip" class="/" joint="FL_hip_joint" forcerange="-23.9798 23.9798" gainprm="18.7004" biasprm="0 -18.7004 -0.461435"/>
    <general name="FL_thigh" class="/" joint="FL_thigh_joint" forcerange="-21.7189 21.7189" gainprm="18.7004" biasprm="0 -18.7004 -0.461435"/>
    <general name="FL_calf" class="/" joint="FL_calf_joint" forcerange="-41.3727 41.3727" gainprm="18.7004" biasprm="0 -18.7004 -0.461435"/>
    <general name="FR_hip" class="/" joint="FR_hip_joint" forcerange="-20.1986 20.1986" gainprm="18.7004" biasprm="0 -18.7004 -0.461435"/>
    <general name="FR_thigh" class="/" joint="FR_thigh_joint" forcerange="-22.512 22.512" gainprm="18.7004" biasprm="0 -18.7004 -0.461435"/>
    <general name="FR_calf" class="/" joint="FR_calf_joint" forcerange="-37.7864 37.7864" gainprm="18.7004" biasprm="0 -18.7004 -0.461435"/>
    <general name="RL_hip" class="/" joint="RL_hip_joint" forcerange="-21.3047 21.3047" gainprm="18.7004" biasprm="0 -18.7004 -0.461435"/>
    <general name="RL_thigh" class="/" joint="RL_thigh_joint" forcerange="-22.2281 22.2281" gainprm="18.7004" biasprm="0 -18.7004 -0.461435"/>
    <general name="RL_calf" class="/" joint="RL_calf_joint" forcerange="-43.9852 43.9852" gainprm="18.7004" biasprm="0 -18.7004 -0.461435"/>
    <general name="RR_hip" class="/" joint="RR_hip_joint" forcerange="-20.3407 20.3407" gainprm="18.7004" biasprm="0 -18.7004 -0.461435"/>
    <general name="RR_thigh" class="/" joint="RR_thigh_joint" forcerange="-23.3979 23.3979" gainprm="18.7004" biasprm="0 -18.7004 -0.461435"/>
    <general name="RR_calf" class="/" joint="RR_calf_joint" forcerange="-46.1343 46.1343" gainprm="18.7004" biasprm="0 -18.7004 -0.461435"/>
  </actuator>

  <sensor>
    <gyro site="imu" name="imu_angular_velocity"/>
    <velocimeter site="imu" name="imu_linear_velocity"/>
    <framelinvel objtype="site" objname="FL_foot" name="FL_foot_global_linear_velocity"/>
    <framelinvel objtype="site" objname="FR_foot" name="FR_foot_global_linear_velocity"/>
    <framelinvel objtype="site" objname="RL_foot" name="RL_foot_global_linear_velocity"/>
    <framelinvel objtype="site" objname="RR_foot" name="RR_foot_global_linear_velocity"/>
  </sensor>

  <keyframe>
    <key name="home" qpos="0 0 0.325 1 0 0 0 0.1 0.8 -1.5 -0.1 -0.8 1.5 -0.1 0.8 -1.5 0.1 -0.8 1.5"/>
  </keyframe>
</mujoco>
