<mujoco model="go2">
  <compiler angle="radian" assetdir="assets" balanceinertia="true" inertiafromgeom="false"/>

  <option timestep="0.005" density="1.2" viscosity="2e-05"/>

  <size nkey="1"/>

  <visual>
    <quality shadowsize="8192"/>
    <map shadowclip="0.5"/>
  </visual>

  <default>
    <default class="/">
      <geom contype="0" conaffinity="0" group="1" solref="-1000 -80"/>
      <site size="0.01 0.005 0.005" group="5"/>
      <general forcelimited="true" biastype="affine" gainprm="20" biasprm="0 -20 -0.5"/>
      <default class="go2">
        <joint armature="0.01" damping="0.01" frictionloss="0.2"/>
        <geom condim="1" margin="0.001"/>
        <default class="visual">
          <geom type="mesh" group="2"/>
        </default>
        <default class="collision">
          <geom group="3"/>
          <default class="foot">
            <geom size="0.022 0 0" condim="6" priority="1" friction="0.8 0.02 0.01" solimp="0.015 1 0.022"/>
          </default>
        </default>
        <default class="reward_collision_sphere">
          <geom group="5" rgba="1 0 0 1"/>
        </default>
      </default>
    </default>
  </default>

  <asset>
    <texture type="skybox" colorspace="auto" name="//unnamed_texture_0" builtin="gradient" rgb1="0.95 0.95 0.95" rgb2="0.95 0.95 0.95" width="100" height="600"/>
    <texture type="2d" colorspace="auto" name="texplane" builtin="checker" rgb1="0.345 0.575 0.748" rgb2="0.345 0.575 0.748" markrgb="1 1 1" width="512" height="512"/>
    <material name="MatPlane" class="/" texture="texplane" texuniform="true" texrepeat="2 2" specular="0.9"/>
    <material name="metal" class="/" rgba="0.9 0.95 0.95 1"/>
    <material name="black" class="/" rgba="0 0 0 1"/>
    <material name="white" class="/"/>
    <material name="gray" class="/" rgba="0.671705 0.692426 0.77427 1"/>
    <mesh name="base_0" class="/" file="base_0.obj"/>
    <mesh name="base_1" class="/" file="base_1.obj"/>
    <mesh name="base_2" class="/" file="base_2.obj"/>
    <mesh name="base_3" class="/" file="base_3.obj"/>
    <mesh name="base_4" class="/" file="base_4.obj"/>
    <mesh name="hip_0" class="/" file="hip_0.obj"/>
    <mesh name="hip_1" class="/" file="hip_1.obj"/>
    <mesh name="thigh_0" class="/" file="thigh_0.obj"/>
    <mesh name="thigh_1" class="/" file="thigh_1.obj"/>
    <mesh name="thigh_mirror_0" class="/" file="thigh_mirror_0.obj"/>
    <mesh name="thigh_mirror_1" class="/" file="thigh_mirror_1.obj"/>
    <mesh name="calf_0" class="/" file="calf_0.obj"/>
    <mesh name="calf_1" class="/" file="calf_1.obj"/>
    <mesh name="calf_mirror_0" class="/" file="calf_mirror_0.obj"/>
    <mesh name="calf_mirror_1" class="/" file="calf_mirror_1.obj"/>
    <mesh name="foot" class="/" file="foot.obj"/>
  </asset>

  <worldbody>
    <geom name="floor" class="/" size="100 100 0.125" type="plane" group="0" material="MatPlane"/>
    <light name="toplight_shadow" class="/" pos="0 0 5" dir="0.0990148 0.0990148 -0.990148" type="directional" ambient="0.04 0.04 0.04" diffuse="0.55 0.55 0.55" specular="0.12 0.12 0.12"/>
    <light name="toplight_fill" class="/" pos="0 0 5" dir="0.0990148 0.0990148 -0.990148" type="directional" castshadow="false" ambient="0.04 0.04 0.04" diffuse="0.3 0.3 0.3" specular="0.08 0.08 0.08"/>
    <body name="trunk" childclass="go2" pos="0.000696274 -0.00236153 -0.0022806" quat="0.999999 -1.94834e-05 0.000934014 -0.00070387">
      <inertial pos="0.0154785 0.000560243 -0.00262166" quat="-0.0121514 0.716962 -0.00681485 0.696973" mass="5.46938" diaginertia="0.0543198 0.104624 0.012159"/>
      <joint name="//unnamed_joint_0" type="free" armature="0" damping="0" frictionloss="0"/>
      <geom name="//unnamed_geom_1" class="visual" material="black" mesh="base_0"/>
      <geom name="//unnamed_geom_2" class="visual" material="black" mesh="base_1"/>
      <geom name="//unnamed_geom_3" class="visual" material="black" mesh="base_2"/>
      <geom name="//unnamed_geom_4" class="visual" material="white" mesh="base_3"/>
      <geom name="//unnamed_geom_5" class="visual" material="gray" mesh="base_4"/>
      <geom name="trunk_1" class="collision" size="0.172431 0.0428558 0.052252" type="box"/>
      <geom name="trunk_2" class="collision" size="0.0458351 0.0412516" pos="0.248354 0 0.00865998" type="cylinder"/>
      <geom name="trunk_3" class="collision" size="0.043085" pos="0.255325 0 -0.0519599"/>
      <geom name="//unnamed_geom_9" class="reward_collision_sphere" size="0.0916701"/>
      <geom name="//unnamed_geom_10" class="reward_collision_sphere" size="0.0550021" pos="0.243997 0 -0.0389699"/>
      <site name="imu" pos="-0.0208302 -0.00437817 0.0322283" size="0.00916701"/>
      <camera name="track" pos="0 -2.02537 0" quat="0.707107 0.707107 0 0" mode="trackcom"/>
      <camera name="ego_camera" pos="0.271882 0 0.0389699" quat="-0.5 -0.5 0.5 0.5"/>
      <body name="FL_hip" pos="0.16649 0.0457618 -0.00017856" quat="1 3.11306e-05 -1.23593e-05 3.08125e-05">
        <inertial pos="-0.00427049 0.000716085 -0.00123839" quat="0.495157 0.502282 0.509356 0.49304" mass="0.52465" diaginertia="0.000455939 0.00062266 0.000240437"/>
        <joint name="FL_hip_joint" pos="0 0 0" axis="0.99991 -0.00855488 -0.0103372" range="-1.10592 1.03183" armature="0.00958589" damping="0.0141187" frictionloss="0.18614"/>
        <geom name="//unnamed_geom_11" class="visual" material="metal" mesh="hip_0"/>
        <geom name="//unnamed_geom_12" class="visual" material="gray" mesh="hip_1"/>
        <geom name="//unnamed_geom_13" class="collision" size="0.0421683 0.018334" pos="0 0.081015 0" quat="0.707107 0.707107 0 0" type="cylinder"/>
        <geom name="//unnamed_geom_14" class="reward_collision_sphere" size="0.0550021" pos="0 0.0708881 0"/>
        <body name="FL_thigh" pos="0.00130975 0.0992705 0.000422663" quat="1 -0.000312865 0.000143102 0.000186306">
          <inertial pos="-0.00250856 -0.0235395 -0.0282291" quat="0.830226 0.0796711 -0.0324691 0.550748" mass="0.914507" diaginertia="0.00294912 0.00616606 0.000427919"/>
          <joint name="FL_thigh_joint" pos="0 0 0" axis="-0.00556095 0.99993 -0.0104748" stiffness="0.0162811" range="-1.61679 3.48504" armature="0.00888008" damping="0.0114798" frictionloss="0.158298"/>
          <geom name="//unnamed_geom_15" class="visual" material="metal" mesh="thigh_0"/>
          <geom name="//unnamed_geom_16" class="visual" material="gray" mesh="thigh_1"/>
          <geom name="//unnamed_geom_17" class="collision" size="0.0976287 0.0112296 0.0155839" pos="0 0 -0.0922288" quat="0.707107 0 0.707107 0" type="box"/>
          <body name="FL_calf" pos="0.00173142 0.000233449 -0.185443" quat="1 -0.000418614 -0.000140452 -6.69243e-05">
            <inertial pos="0.00473104 -0.00315592 -0.123717" quat="0.714117 0.0118924 -0.0099508 0.699854" mass="0.185634" diaginertia="0.00072677 0.00151427 2.51611e-05"/>
            <joint name="FL_calf_joint" pos="0 0 0" axis="-0.00139448 0.999998 0.00110792" stiffness="0.00997833" range="-2.74161 -0.807494" armature="0.00779177" damping="0.000466499" frictionloss="0.205438"/>
            <geom name="//unnamed_geom_18" class="visual" material="gray" mesh="calf_0"/>
            <geom name="//unnamed_geom_19" class="visual" material="black" mesh="calf_1"/>
            <geom name="FL_calf0" class="collision" size="0.0110004 0.0550021" pos="0.00697134 0 -0.0519599" quat="0.994493 0 -0.104807 0" type="cylinder"/>
            <geom name="//unnamed_geom_21" class="collision" size="0.0100837 0.0297928" pos="0.0174284 0 -0.128168" quat="0.999688 0 0.0249974 0" type="cylinder"/>
            <geom name="//unnamed_geom_22" class="visual" pos="0 0 -0.184458" quat="1 0 0 0" material="black" mesh="foot"/>
            <geom name="FL_foot" class="foot" size="0.0157152" pos="-0.00174284 0 -0.184458"/>
            <geom name="//unnamed_geom_24" class="reward_collision_sphere" size="0.0229175"/>
            <geom name="//unnamed_geom_25" class="reward_collision_sphere" size="0.0229175" pos="-0.00174284 0 -0.184458"/>
            <site name="FL_foot" class="foot" pos="-0.00174284 0 -0.184458" size="0.00916701"/>
          </body>
        </body>
      </body>
      <body name="FR_hip" pos="0.169138 -0.0494868 -0.00079052" quat="1 -0.000170487 -0.000259274 -9.83887e-05">
        <inertial pos="-0.00440077 0.000796597 -0.00287079" quat="0.49694 0.507306 0.498014 0.497668" mass="0.500013" diaginertia="0.000427845 0.00063513 0.000238648"/>
        <joint name="FR_hip_joint" pos="0 0 0" axis="0.999914 0.0129622 0.00219075" stiffness="0.00951487" range="-1.04835 1.07144" armature="0.00790566" damping="0.0148791" frictionloss="0.202541"/>
        <geom name="//unnamed_geom_26" class="visual" pos="0 1.27789e-09 5.48115e-08" quat="4.63268e-05 1 0 0" material="metal" mesh="hip_0"/>
        <geom name="//unnamed_geom_27" class="visual" pos="0 2.07162e-09 -1.3557e-07" quat="4.63268e-05 1 0 0" material="gray" mesh="hip_1"/>
        <geom name="//unnamed_geom_28" class="collision" size="0.0421683 0.018334" pos="0 -0.081015 0" quat="0.707107 0.707107 0 0" type="cylinder"/>
        <geom name="//unnamed_geom_29" class="reward_collision_sphere" size="0.0550021" pos="0 -0.0708881 0"/>
        <body name="FR_thigh" pos="-0.00180562 -0.0967652 0.00286835" quat="1 6.38501e-05 0.000210635 -9.33403e-06">
          <inertial pos="-0.000353836 0.0202507 -0.0281668" quat="0.545161 -0.0106719 0.0885379 0.833575" mass="0.905736" diaginertia="0.00288414 0.00619126 0.000425876"/>
          <joint name="FR_thigh_joint" pos="0 0 0" axis="-0.00079683 -0.999996 0.0026426" range="-3.47143 1.61475" armature="0.00890882" damping="0.013257" frictionloss="0.16002"/>
          <geom name="//unnamed_geom_30" class="visual" material="metal" mesh="thigh_mirror_0"/>
          <geom name="//unnamed_geom_31" class="visual" material="gray" mesh="thigh_mirror_1"/>
          <geom name="//unnamed_geom_32" class="collision" size="0.0976287 0.0112296 0.0155839" pos="0 0 -0.0922288" quat="0.707107 0 0.707107 0" type="box"/>
          <body name="FR_calf" pos="-0.00347261 9.63616e-06 -0.182953" quat="1 0.000445753 0.000133287 -0.000567693">
            <inertial pos="0.0029768 0.00303789 -0.122835" quat="0.696129 -0.0107974 -0.00494167 0.717819" mass="0.184342" diaginertia="0.000717058 0.00158596 2.48034e-05"/>
            <joint name="FR_calf_joint" pos="0 0 0" axis="-0.00345807 -0.999993 0.00155136" range="0.882462 2.75944" armature="0.00894346" damping="0.00482815" frictionloss="0.159649"/>
            <geom name="//unnamed_geom_33" class="visual" material="gray" mesh="calf_mirror_0"/>
            <geom name="//unnamed_geom_34" class="visual" material="black" mesh="calf_mirror_1"/>
            <geom name="FR_calf0" class="collision" size="0.0119171 0.0550021" pos="0.00871418 0 -0.0519599" quat="0.995004 0 -0.0998334 0" type="cylinder"/>
            <geom name="//unnamed_geom_36" class="collision" size="0.0100837 0.0297928" pos="0.0174284 0 -0.128168" quat="0.999688 0 0.0249974 0" type="cylinder"/>
            <geom name="//unnamed_geom_37" class="visual" pos="0 0 -0.184458" quat="1 0 0 0" material="black" mesh="foot"/>
            <geom name="FR_foot" class="foot" size="0.0210845" pos="-0.00174284 0 -0.184458"/>
            <geom name="//unnamed_geom_39" class="reward_collision_sphere" size="0.0229175"/>
            <geom name="//unnamed_geom_40" class="reward_collision_sphere" size="0.0229175" pos="-0.00174284 0 -0.184458"/>
            <site name="FR_foot" class="foot" pos="-0.00174284 0 -0.184458" size="0.00916701"/>
          </body>
        </body>
      </body>
      <body name="RL_hip" pos="-0.168791 0.0497977 -0.000422644" quat="1 1.48746e-05 -6.42159e-07 -2.34952e-05">
        <inertial pos="0.0058756 0.0011619 0.00255795" quat="0.505088 0.491832 0.500669 0.502313" mass="0.511263" diaginertia="0.000423248 0.000592233 0.000233618"/>
        <joint name="RL_hip_joint" pos="0 0 0" axis="-0.999774 0.0141388 -0.0158889" stiffness="0.000657143" range="-1.02737 0.991457" armature="0.00847283" damping="0.0141546" frictionloss="0.199644"/>
        <geom name="//unnamed_geom_41" class="visual" pos="-4.72113e-11 0 -9.25449e-09" quat="4.63268e-05 0 1 0" material="metal" mesh="hip_0"/>
        <geom name="//unnamed_geom_42" class="visual" pos="-7.65351e-11 0 -8.20742e-09" quat="4.63268e-05 0 1 0" material="gray" mesh="hip_1"/>
        <geom name="//unnamed_geom_43" class="collision" size="0.0421683 0.018334" pos="0 0.081015 0" quat="0.707107 0.707107 0 0" type="cylinder"/>
        <geom name="//unnamed_geom_44" class="reward_collision_sphere" size="0.0550021" pos="0 0.0708881 0"/>
        <body name="RL_thigh" pos="-0.000196583 0.0932839 0.00278526" quat="1 -9.93662e-05 -4.59224e-05 -8.72168e-05">
          <inertial pos="-0.00321883 -0.0240149 -0.0257449" quat="0.831142 0.0888615 -0.0126215 0.548768" mass="0.891685" diaginertia="0.00288535 0.00642688 0.000431719"/>
          <joint name="RL_thigh_joint" pos="0 0 0" axis="0.00419777 0.999983 0.00416673" range="-0.525495 4.55835" armature="0.0102481" damping="0.0173542" frictionloss="0.158529"/>
          <geom name="//unnamed_geom_45" class="visual" material="metal" mesh="thigh_0"/>
          <geom name="//unnamed_geom_46" class="visual" material="gray" mesh="thigh_1"/>
          <geom name="//unnamed_geom_47" class="collision" size="0.0976287 0.0112296 0.0155839" pos="0 0 -0.0922288" quat="0.707107 0 0.707107 0" type="box"/>
          <body name="RL_calf" pos="-0.00206061 -0.000376149 -0.183355" quat="0.999999 -0.00130331 0.000563569 -0.000310344">
            <inertial pos="0.00443721 0.000661821 -0.12212" quat="0.710002 0.00531602 -0.00400098 0.704169" mass="0.182299" diaginertia="0.00073541 0.00153307 2.55515e-05"/>
            <joint name="RL_calf_joint" pos="0 0 0" axis="0.000252232 0.999999 0.00128498" range="-2.73407 -0.844161" armature="0.00878646" damping="0.0136262" frictionloss="0.160726"/>
            <geom name="//unnamed_geom_48" class="visual" material="gray" mesh="calf_0"/>
            <geom name="//unnamed_geom_49" class="visual" material="black" mesh="calf_1"/>
            <geom name="RL_calf0" class="collision" size="0.0119171 0.0550021" pos="0.00871418 0 -0.0519599" quat="0.995004 0 -0.0998334 0" type="cylinder"/>
            <geom name="//unnamed_geom_51" class="collision" size="0.0100837 0.0297928" pos="0.0174284 0 -0.128168" quat="0.999688 0 0.0249974 0" type="cylinder"/>
            <geom name="//unnamed_geom_52" class="visual" pos="0 0 -0.184458" quat="1 0 0 0" material="black" mesh="foot"/>
            <geom name="RL_foot" class="foot" size="0.0179946" pos="-0.00174284 0 -0.184458"/>
            <geom name="//unnamed_geom_54" class="reward_collision_sphere" size="0.0229175"/>
            <geom name="//unnamed_geom_55" class="reward_collision_sphere" size="0.0229175" pos="-0.00174284 0 -0.184458"/>
            <site name="RL_foot" class="foot" pos="-0.00174284 0 -0.184458" size="0.00916701"/>
          </body>
        </body>
      </body>
      <body name="RR_hip" pos="-0.168124 -0.048316 0.000713317" quat="1 1.95695e-05 0.000259378 -0.000632072">
        <inertial pos="0.00386053 -0.00404261 0.000516405" quat="0.499096 0.498013 0.499093 0.503778" mass="0.502763" diaginertia="0.000427177 0.00063003 0.000221727"/>
        <joint name="RR_hip_joint" pos="0 0 0" axis="-0.999998 -0.00212308 7.98274e-05" stiffness="0.00201556" range="-1.06922 1.09394" armature="0.00930374" damping="0.00620426" frictionloss="0.206941"/>
        <geom name="//unnamed_geom_56" class="visual" pos="5.2102e-11 1.27789e-09 -6.4066e-08" quat="2.14617e-09 4.63268e-05 4.63268e-05 -1" material="metal" mesh="hip_0"/>
        <geom name="//unnamed_geom_57" class="visual" pos="6.4438e-11 2.07162e-09 1.27362e-07" quat="2.14617e-09 4.63268e-05 4.63268e-05 -1" material="gray" mesh="hip_1"/>
        <geom name="//unnamed_geom_58" class="collision" size="0.0421683 0.018334" pos="0 -0.081015 0" quat="0.707107 0.707107 0 0" type="cylinder"/>
        <geom name="//unnamed_geom_59" class="reward_collision_sphere" size="0.0550021" pos="0 -0.0708881 0"/>
        <body name="RR_thigh" pos="-0.00222149 -0.0955009 -0.0039293" quat="0.999999 -0.00115945 -0.000219665 0.000408717">
          <inertial pos="-0.00258763 0.0207961 -0.0274306" quat="0.550319 -0.0184015 0.0861343 0.830296" mass="0.929962" diaginertia="0.00305421 0.00617346 0.000423244"/>
          <joint name="RR_thigh_joint" pos="0 0 0" axis="-0.00453622 -0.999987 0.00229211" stiffness="0.00347947" range="-4.55667 0.504258" armature="0.00941933" damping="0.0159042" frictionloss="0.189861"/>
          <geom name="//unnamed_geom_60" class="visual" material="metal" mesh="thigh_mirror_0"/>
          <geom name="//unnamed_geom_61" class="visual" material="gray" mesh="thigh_mirror_1"/>
          <geom name="//unnamed_geom_62" class="collision" size="0.0976287 0.0112296 0.0155839" pos="0 0 -0.0922288" quat="0.707107 0 0.707107 0" type="box"/>
          <body name="RR_calf" pos="0.00294465 -0.000906297 -0.182909" quat="1 -9.53831e-05 0.000104466 2.94478e-05">
            <inertial pos="0.00261224 0.000696642 -0.123492" quat="0.703258 -0.00611218 0.00173458 0.710907" mass="0.192419" diaginertia="0.000772521 0.00162163 2.61343e-05"/>
            <joint name="RR_calf_joint" pos="0 0 0" axis="0.0035102 -0.999982 0.00494663" stiffness="0.00351359" range="0.850699 2.78005" armature="0.00927392" damping="0.0108132" frictionloss="0.208344"/>
            <geom name="//unnamed_geom_63" class="visual" material="gray" mesh="calf_mirror_0"/>
            <geom name="//unnamed_geom_64" class="visual" material="black" mesh="calf_mirror_1"/>
            <geom name="RR_calf0" class="collision" size="0.0119171 0.0550021" pos="0.00871418 0 -0.0519599" quat="0.995004 0 -0.0998334 0" type="cylinder"/>
            <geom name="//unnamed_geom_66" class="collision" size="0.0100837 0.0297928" pos="0.0174284 0 -0.128168" quat="0.999688 0 0.0249974 0" type="cylinder"/>
            <geom name="//unnamed_geom_67" class="visual" pos="0 0 -0.184458" quat="1 0 0 0" material="black" mesh="foot"/>
            <geom name="RR_foot" class="foot" size="0.0191944" pos="-0.00174284 0 -0.184458"/>
            <geom name="//unnamed_geom_69" class="reward_collision_sphere" size="0.0229175"/>
            <geom name="//unnamed_geom_70" class="reward_collision_sphere" size="0.0229175" pos="-0.00174284 0 -0.184458"/>
            <site name="RR_foot" class="foot" pos="-0.00174284 0 -0.184458" size="0.00916701"/>
          </body>
        </body>
      </body>
    </body>
  </worldbody>

  <contact>
    <pair class="/" geom1="floor" geom2="FL_foot" name="//unnamed_contact_0"/>
    <pair class="/" geom1="floor" geom2="FR_foot" name="//unnamed_contact_1"/>
    <pair class="/" geom1="floor" geom2="RL_foot" name="//unnamed_contact_2"/>
    <pair class="/" geom1="floor" geom2="RR_foot" name="//unnamed_contact_3"/>
  </contact>

  <actuator>
    <general name="FL_hip" class="/" joint="FL_hip_joint" forcerange="-23.9659 23.9659" gainprm="18.6414" biasprm="0 -18.6414 -0.449373"/>
    <general name="FL_thigh" class="/" joint="FL_thigh_joint" forcerange="-21.6397 21.6397" gainprm="18.6414" biasprm="0 -18.6414 -0.449373"/>
    <general name="FL_calf" class="/" joint="FL_calf_joint" forcerange="-39.9168 39.9168" gainprm="18.6414" biasprm="0 -18.6414 -0.449373"/>
    <general name="FR_hip" class="/" joint="FR_hip_joint" forcerange="-19.4243 19.4243" gainprm="18.6414" biasprm="0 -18.6414 -0.449373"/>
    <general name="FR_thigh" class="/" joint="FR_thigh_joint" forcerange="-22.4684 22.4684" gainprm="18.6414" biasprm="0 -18.6414 -0.449373"/>
    <general name="FR_calf" class="/" joint="FR_calf_joint" forcerange="-38.2792 38.2792" gainprm="18.6414" biasprm="0 -18.6414 -0.449373"/>
    <general name="RL_hip" class="/" joint="RL_hip_joint" forcerange="-19.7975 19.7975" gainprm="18.6414" biasprm="0 -18.6414 -0.449373"/>
    <general name="RL_thigh" class="/" joint="RL_thigh_joint" forcerange="-22.4782 22.4782" gainprm="18.6414" biasprm="0 -18.6414 -0.449373"/>
    <general name="RL_calf" class="/" joint="RL_calf_joint" forcerange="-45.4127 45.4127" gainprm="18.6414" biasprm="0 -18.6414 -0.449373"/>
    <general name="RR_hip" class="/" joint="RR_hip_joint" forcerange="-19.4747 19.4747" gainprm="18.6414" biasprm="0 -18.6414 -0.449373"/>
    <general name="RR_thigh" class="/" joint="RR_thigh_joint" forcerange="-23.8053 23.8053" gainprm="18.6414" biasprm="0 -18.6414 -0.449373"/>
    <general name="RR_calf" class="/" joint="RR_calf_joint" forcerange="-42.3704 42.3704" gainprm="18.6414" biasprm="0 -18.6414 -0.449373"/>
  </actuator>

  <sensor>
    <gyro site="imu" name="imu_angular_velocity"/>
    <velocimeter site="imu" name="imu_linear_velocity"/>
    <framelinvel objtype="site" objname="FL_foot" name="FL_foot_global_linear_velocity"/>
    <framelinvel objtype="site" objname="FR_foot" name="FR_foot_global_linear_velocity"/>
    <framelinvel objtype="site" objname="RL_foot" name="RL_foot_global_linear_velocity"/>
    <framelinvel objtype="site" objname="RR_foot" name="RR_foot_global_linear_velocity"/>
  </sensor>

  <keyframe>
    <key name="home" qpos="0 0 0.325 1 0 0 0 0.1 0.8 -1.5 -0.1 -0.8 1.5 -0.1 0.8 -1.5 0.1 -0.8 1.5"/>
  </keyframe>
</mujoco>
