<mujoco model="go2">
  <compiler angle="radian" assetdir="assets" balanceinertia="true" inertiafromgeom="false"/>

  <option timestep="0.005" density="1.2" viscosity="2e-05"/>

  <size nkey="1"/>

  <visual>
    <quality shadowsize="8192"/>
    <map shadowclip="0.5"/>
  </visual>

  <default>
    <default class="/">
      <geom contype="0" conaffinity="0" group="1" solref="-1000 -80"/>
      <site size="0.01 0.005 0.005" group="5"/>
      <general forcelimited="true" biastype="affine" gainprm="20" biasprm="0 -20 -0.5"/>
      <default class="go2">
        <joint armature="0.01" damping="0.01" frictionloss="0.2"/>
        <geom condim="1" margin="0.001"/>
        <default class="visual">
          <geom type="mesh" group="2"/>
        </default>
        <default class="collision">
          <geom group="3"/>
          <default class="foot">
            <geom size="0.022 0 0" condim="6" priority="1" friction="0.8 0.02 0.01" solimp="0.015 1 0.022"/>
          </default>
        </default>
        <default class="reward_collision_sphere">
          <geom group="5" rgba="1 0 0 1"/>
        </default>
      </default>
    </default>
  </default>

  <asset>
    <texture type="skybox" colorspace="auto" name="//unnamed_texture_0" builtin="gradient" rgb1="0.95 0.95 0.95" rgb2="0.95 0.95 0.95" width="100" height="600"/>
    <texture type="2d" colorspace="auto" name="texplane" builtin="checker" rgb1="0.345 0.575 0.748" rgb2="0.345 0.575 0.748" markrgb="1 1 1" width="512" height="512"/>
    <material name="MatPlane" class="/" texture="texplane" texuniform="true" texrepeat="2 2" specular="0.9"/>
    <material name="metal" class="/" rgba="0.9 0.95 0.95 1"/>
    <material name="black" class="/" rgba="0 0 0 1"/>
    <material name="white" class="/"/>
    <material name="gray" class="/" rgba="0.671705 0.692426 0.77427 1"/>
    <mesh name="base_0" class="/" file="base_0.obj"/>
    <mesh name="base_1" class="/" file="base_1.obj"/>
    <mesh name="base_2" class="/" file="base_2.obj"/>
    <mesh name="base_3" class="/" file="base_3.obj"/>
    <mesh name="base_4" class="/" file="base_4.obj"/>
    <mesh name="hip_0" class="/" file="hip_0.obj"/>
    <mesh name="hip_1" class="/" file="hip_1.obj"/>
    <mesh name="thigh_0" class="/" file="thigh_0.obj"/>
    <mesh name="thigh_1" class="/" file="thigh_1.obj"/>
    <mesh name="thigh_mirror_0" class="/" file="thigh_mirror_0.obj"/>
    <mesh name="thigh_mirror_1" class="/" file="thigh_mirror_1.obj"/>
    <mesh name="calf_0" class="/" file="calf_0.obj"/>
    <mesh name="calf_1" class="/" file="calf_1.obj"/>
    <mesh name="calf_mirror_0" class="/" file="calf_mirror_0.obj"/>
    <mesh name="calf_mirror_1" class="/" file="calf_mirror_1.obj"/>
    <mesh name="foot" class="/" file="foot.obj"/>
  </asset>

  <worldbody>
    <geom name="floor" class="/" size="100 100 0.125" type="plane" group="0" material="MatPlane"/>
    <light name="toplight_shadow" class="/" pos="0 0 5" dir="0.0990148 0.0990148 -0.990148" type="directional" ambient="0.04 0.04 0.04" diffuse="0.55 0.55 0.55" specular="0.12 0.12 0.12"/>
    <light name="toplight_fill" class="/" pos="0 0 5" dir="0.0990148 0.0990148 -0.990148" type="directional" castshadow="false" ambient="0.04 0.04 0.04" diffuse="0.3 0.3 0.3" specular="0.08 0.08 0.08"/>
    <body name="trunk" childclass="go2" pos="0.000111055 0.000513795 0.000454668" quat="1 0.000215387 -0.000117734 1.44404e-05">
      <inertial pos="0.0230767 -0.00152931 -0.00515105" quat="0.00240876 0.712948 0.00163183 0.701211" mass="6.20774" diaginertia="0.132225 0.0718668 0.0157037"/>
      <joint name="//unnamed_joint_0" type="free" armature="0" damping="0" frictionloss="0"/>
      <geom name="//unnamed_geom_1" class="visual" material="black" mesh="base_0"/>
      <geom name="//unnamed_geom_2" class="visual" material="black" mesh="base_1"/>
      <geom name="//unnamed_geom_3" class="visual" material="black" mesh="base_2"/>
      <geom name="//unnamed_geom_4" class="visual" material="white" mesh="base_3"/>
      <geom name="//unnamed_geom_5" class="visual" material="gray" mesh="base_4"/>
      <geom name="trunk_1" class="collision" size="0.182575 0.0453769 0.0553259" type="box"/>
      <geom name="trunk_2" class="collision" size="0.0485315 0.0436783" pos="0.299536 0 0.00917889" type="cylinder"/>
      <geom name="trunk_3" class="collision" size="0.0456196" pos="0.307944 0 -0.0550733"/>
      <geom name="//unnamed_geom_9" class="reward_collision_sphere" size="0.097063"/>
      <geom name="//unnamed_geom_10" class="reward_collision_sphere" size="0.0582378" pos="0.294281 0 -0.041305"/>
      <site name="imu" pos="-0.0286789 -0.000586108 0.0382054" size="0.0097063"/>
      <camera name="track" pos="0 -1.88599 0" quat="0.707107 0.707107 0 0" mode="trackcom"/>
      <camera name="ego_camera" pos="0.327914 0 0.041305" quat="-0.5 -0.5 0.5 0.5"/>
      <body name="FL_hip" pos="0.202416 0.0440997 0.000500366" quat="1 -8.55101e-09 -4.62211e-05 -3.32424e-06">
        <inertial pos="-0.00584203 0.00183338 8.13472e-05" quat="0.493804 0.505187 0.508512 0.4923" mass="0.619804" diaginertia="0.00113786 0.000451372 0.000314708"/>
        <joint name="FL_hip_joint" pos="0 0 0" axis="1 -0.000597289 0.000525473" stiffness="0.0113878" range="-1.02869 1.04036" armature="0.00972611" damping="0.0106328" frictionloss="0.192781"/>
        <geom name="//unnamed_geom_11" class="visual" material="metal" mesh="hip_0"/>
        <geom name="//unnamed_geom_12" class="visual" material="gray" mesh="hip_1"/>
        <geom name="//unnamed_geom_13" class="collision" size="0.044649 0.0194126" pos="0 0.0754396 0" quat="0.707107 0.707107 0 0" type="cylinder"/>
        <geom name="//unnamed_geom_14" class="reward_collision_sphere" size="0.0582378" pos="0 0.0660096 0"/>
        <body name="FL_thigh" pos="-0.000771068 0.0889429 0.000291759" quat="1 -0.000398425 -5.10256e-05 0.000719969">
          <inertial pos="-0.00396864 -0.0191221 -0.0303617" quat="0.829286 0.0882754 -0.0175236 0.55153" mass="1.04291" diaginertia="0.00756765 0.00444376 0.000574116"/>
          <joint name="FL_thigh_joint" pos="0 0 0" axis="0.00468892 0.999985 -0.00272305" stiffness="0.00230157" range="-1.55853 3.47096" armature="0.0104914" damping="0.00850826" frictionloss="0.202723"/>
          <geom name="//unnamed_geom_15" class="visual" material="metal" mesh="thigh_0"/>
          <geom name="//unnamed_geom_16" class="visual" material="gray" mesh="thigh_1"/>
          <geom name="//unnamed_geom_17" class="collision" size="0.103372 0.0118902 0.0165007" pos="0 0 -0.0977551" quat="0.707107 0 0.707107 0" type="box"/>
          <body name="FL_calf" pos="-0.000991576 0.000243173 -0.195779" quat="1 2.65988e-05 -1.31083e-06 5.77018e-05">
            <inertial pos="0.00591953 0.000215748 -0.129516" quat="0.710432 0.00386944 -0.00179769 0.703753" mass="0.22078" diaginertia="0.00192764 0.00111605 3.47578e-05"/>
            <joint name="FL_calf_joint" pos="0 0 0" axis="0.000439911 1 -3.52884e-05" stiffness="0.00142379" range="-2.69107 -0.831417" armature="0.0101762" damping="0.00064012" frictionloss="0.188765"/>
            <geom name="//unnamed_geom_18" class="visual" material="gray" mesh="calf_0"/>
            <geom name="//unnamed_geom_19" class="visual" material="black" mesh="calf_1"/>
            <geom name="FL_calf0" class="collision" size="0.0116476 0.0582378" pos="0.00840804 0 -0.0550733" quat="0.994493 0 -0.104807 0" type="cylinder"/>
            <geom name="//unnamed_geom_21" class="collision" size="0.0106769 0.0315455" pos="0.0210201 0 -0.135848" quat="0.999688 0 0.0249974 0" type="cylinder"/>
            <geom name="//unnamed_geom_22" class="visual" pos="0 0 -0.19551" quat="1 0 0 0" material="black" mesh="foot"/>
            <geom name="FL_foot" class="foot" size="0.0167518" pos="-0.00210201 0 -0.19551"/>
            <geom name="//unnamed_geom_24" class="reward_collision_sphere" size="0.0242657"/>
            <geom name="//unnamed_geom_25" class="reward_collision_sphere" size="0.0242657" pos="-0.00210201 0 -0.19551"/>
            <site name="FL_foot" class="foot" pos="-0.00210201 0 -0.19551" size="0.0097063"/>
          </body>
        </body>
      </body>
      <body name="FR_hip" pos="0.202203 -0.0421111 -0.00064855" quat="1 0.000209006 2.2327e-05 -5.58107e-05">
        <inertial pos="-0.00603696 -0.00249452 -1.86478e-05" quat="0.494479 0.5062 0.499388 0.499863" mass="0.62464" diaginertia="0.00113531 0.000444661 0.000309307"/>
        <joint name="FR_hip_joint" pos="0 0 0" axis="0.999975 0.00673527 0.00222536" range="-1.03985 1.06045" armature="0.0102355" damping="0.0185632" frictionloss="0.191438"/>
        <geom name="//unnamed_geom_26" class="visual" pos="0 2.18716e-10 9.38117e-09" quat="4.63268e-05 1 0 0" material="metal" mesh="hip_0"/>
        <geom name="//unnamed_geom_27" class="visual" pos="0 3.54564e-10 -2.32032e-08" quat="4.63268e-05 1 0 0" material="gray" mesh="hip_1"/>
        <geom name="//unnamed_geom_28" class="collision" size="0.044649 0.0194126" pos="0 -0.0754396 0" quat="0.707107 0.707107 0 0" type="cylinder"/>
        <geom name="//unnamed_geom_29" class="reward_collision_sphere" size="0.0582378" pos="0 -0.0660096 0"/>
        <body name="FR_thigh" pos="-0.000114789 -0.0896309 -0.000348986" quat="1 -8.41519e-06 -0.000121134 -3.7306e-05">
          <inertial pos="-0.00498854 0.0217794 -0.0287036" quat="0.551916 -0.0234889 0.0840317 0.829322" mass="1.05125" diaginertia="0.00769391 0.0043626 0.000573417"/>
          <joint name="FR_thigh_joint" pos="0 0 0" axis="0.000114425 -1 -2.50455e-05" stiffness="0.00791984" range="-3.48536 1.55963" armature="0.00931228" damping="0.0142226" frictionloss="0.201211"/>
          <geom name="//unnamed_geom_30" class="visual" material="metal" mesh="thigh_mirror_0"/>
          <geom name="//unnamed_geom_31" class="visual" material="gray" mesh="thigh_mirror_1"/>
          <geom name="//unnamed_geom_32" class="collision" size="0.103372 0.0118902 0.0165007" pos="0 0 -0.0977551" quat="0.707107 0 0.707107 0" type="box"/>
          <body name="FR_calf" pos="0.000221817 0.000275101 -0.194241" quat="1 -7.20262e-05 -0.00010606 -3.20151e-05">
            <inertial pos="0.00727663 0.000213464 -0.129771" quat="0.705824 -0.00247713 -0.000965134 0.708382" mass="0.225106" diaginertia="0.00197011 0.00110899 3.56655e-05"/>
            <joint name="FR_calf_joint" pos="0 0 0" axis="0.000520917 -1 -0.000795843" range="0.828717 2.71793" armature="0.0094567" damping="0.00514625" frictionloss="0.201654"/>
            <geom name="//unnamed_geom_33" class="visual" material="gray" mesh="calf_mirror_0"/>
            <geom name="//unnamed_geom_34" class="visual" material="black" mesh="calf_mirror_1"/>
            <geom name="FR_calf0" class="collision" size="0.0126182 0.0582378" pos="0.0105101 0 -0.0550733" quat="0.995004 0 -0.0998334 0" type="cylinder"/>
            <geom name="//unnamed_geom_36" class="collision" size="0.0106769 0.0315455" pos="0.0210201 0 -0.135848" quat="0.999688 0 0.0249974 0" type="cylinder"/>
            <geom name="//unnamed_geom_37" class="visual" pos="0 0 -0.19551" quat="1 0 0 0" material="black" mesh="foot"/>
            <geom name="FR_foot" class="foot" size="0.0207532" pos="-0.00210201 0 -0.19551"/>
            <geom name="//unnamed_geom_39" class="reward_collision_sphere" size="0.0242657"/>
            <geom name="//unnamed_geom_40" class="reward_collision_sphere" size="0.0242657" pos="-0.00210201 0 -0.19551"/>
            <site name="FR_foot" class="foot" pos="-0.00210201 0 -0.19551" size="0.0097063"/>
          </body>
        </body>
      </body>
      <body name="RL_hip" pos="-0.203117 0.0428067 0.00181718" quat="1 -0.00031016 -0.000164557 -0.000472104">
        <inertial pos="0.00591848 0.00169768 -0.000644317" quat="0.505323 0.498656 0.496967 0.499014" mass="0.61294" diaginertia="0.00114053 0.000454536 0.000312576"/>
        <joint name="RL_hip_joint" pos="0 0 0" axis="-0.999824 0.0171336 -0.0076661" stiffness="0.00577861" range="-1.03554 1.06469" armature="0.00961902" damping="0.0153292" frictionloss="0.194319"/>
        <geom name="//unnamed_geom_41" class="visual" pos="-1.15966e-09 0 -2.27319e-07" quat="4.63268e-05 0 1 0" material="metal" mesh="hip_0"/>
        <geom name="//unnamed_geom_42" class="visual" pos="-1.87994e-09 0 -2.016e-07" quat="4.63268e-05 0 1 0" material="gray" mesh="hip_1"/>
        <geom name="//unnamed_geom_43" class="collision" size="0.044649 0.0194126" pos="0 0.0754396 0" quat="0.707107 0.707107 0 0" type="cylinder"/>
        <geom name="//unnamed_geom_44" class="reward_collision_sphere" size="0.0582378" pos="0 0.0660096 0"/>
        <body name="RL_thigh" pos="-0.000392598 0.0910877 0.000489413" quat="1 -9.64034e-05 0.000363649 -0.000418253">
          <inertial pos="-0.0036167 -0.0188499 -0.0309122" quat="0.82954 0.084719 -0.0200636 0.551619" mass="1.03267" diaginertia="0.00770802 0.00430387 0.000577754"/>
          <joint name="RL_thigh_joint" pos="0 0 0" axis="0.00567935 0.999982 0.00168504" stiffness="0.00167706" range="-0.533239 4.5443" armature="0.00943208" damping="0.00876891" frictionloss="0.20281"/>
          <geom name="//unnamed_geom_45" class="visual" material="metal" mesh="thigh_0"/>
          <geom name="//unnamed_geom_46" class="visual" material="gray" mesh="thigh_1"/>
          <geom name="//unnamed_geom_47" class="collision" size="0.103372 0.0118902 0.0165007" pos="0 0 -0.0977551" quat="0.707107 0 0.707107 0" type="box"/>
          <body name="RL_calf" pos="0.000128643 -0.000924613 -0.195314" quat="1 -0.000211298 0.000253178 -0.000126239">
            <inertial pos="0.00624185 3.43818e-05 -0.129948" quat="0.710696 0.00151461 -0.00445226 0.703484" mass="0.223253" diaginertia="0.00192945 0.00110057 3.4803e-05"/>
            <joint name="RL_calf_joint" pos="0 0 0" axis="-0.0043343 0.999979 -0.00475638" stiffness="0.00488299" range="-2.69118 -0.834615" armature="0.0105256" damping="0" frictionloss="0.200469"/>
            <geom name="//unnamed_geom_48" class="visual" material="gray" mesh="calf_0"/>
            <geom name="//unnamed_geom_49" class="visual" material="black" mesh="calf_1"/>
            <geom name="RL_calf0" class="collision" size="0.0126182 0.0582378" pos="0.0105101 0 -0.0550733" quat="0.995004 0 -0.0998334 0" type="cylinder"/>
            <geom name="//unnamed_geom_51" class="collision" size="0.0106769 0.0315455" pos="0.0210201 0 -0.135848" quat="0.999688 0 0.0249974 0" type="cylinder"/>
            <geom name="//unnamed_geom_52" class="visual" pos="0 0 -0.19551" quat="1 0 0 0" material="black" mesh="foot"/>
            <geom name="RL_foot" class="foot" size="0.0192532" pos="-0.00210201 0 -0.19551"/>
            <geom name="//unnamed_geom_54" class="reward_collision_sphere" size="0.0242657"/>
            <geom name="//unnamed_geom_55" class="reward_collision_sphere" size="0.0242657" pos="-0.00210201 0 -0.19551"/>
            <site name="RL_foot" class="foot" pos="-0.00210201 0 -0.19551" size="0.0097063"/>
          </body>
        </body>
      </body>
      <body name="RR_hip" pos="-0.20437 -0.0449219 -0.00115593" quat="1 -0.00027741 0.000644075 0.000596817">
        <inertial pos="0.00556187 -0.00152293 1.0588e-05" quat="0.498995 0.496915 0.498532 0.505516" mass="0.627469" diaginertia="0.00114624 0.000447304 0.000323897"/>
        <joint name="RR_hip_joint" pos="0 0 0" axis="-1 -0.000379772 -3.5025e-05" range="-1.05419 1.03728" armature="0.0102374" damping="0.00538922" frictionloss="0.186941"/>
        <geom name="//unnamed_geom_56" class="visual" pos="1.15592e-09 2.18716e-10 -2.367e-07" quat="2.14617e-09 4.63268e-05 4.63268e-05 -1" material="metal" mesh="hip_0"/>
        <geom name="//unnamed_geom_57" class="visual" pos="1.88919e-09 3.54564e-10 -1.78397e-07" quat="2.14617e-09 4.63268e-05 4.63268e-05 -1" material="gray" mesh="hip_1"/>
        <geom name="//unnamed_geom_58" class="collision" size="0.044649 0.0194126" pos="0 -0.0754396 0" quat="0.707107 0.707107 0 0" type="cylinder"/>
        <geom name="//unnamed_geom_59" class="reward_collision_sphere" size="0.0582378" pos="0 -0.0660096 0"/>
        <body name="RR_thigh" pos="0.00113999 -0.0905765 -6.81664e-06" quat="1 -0.000507228 -0.000309934 -9.34083e-05">
          <inertial pos="-0.00360817 0.0211818 -0.0297803" quat="0.550631 -0.0223591 0.0843682 0.830173" mass="1.04979" diaginertia="0.00760067 0.00438036 0.00057751"/>
          <joint name="RR_thigh_joint" pos="0 0 0" axis="-0.0086571 -0.999961 -0.00156708" range="-4.54211 0.559326" armature="0.00895847" damping="0.0131894" frictionloss="0.193559"/>
          <geom name="//unnamed_geom_60" class="visual" material="metal" mesh="thigh_mirror_0"/>
          <geom name="//unnamed_geom_61" class="visual" material="gray" mesh="thigh_mirror_1"/>
          <geom name="//unnamed_geom_62" class="collision" size="0.103372 0.0118902 0.0165007" pos="0 0 -0.0977551" quat="0.707107 0 0.707107 0" type="box"/>
          <body name="RR_calf" pos="0.000693122 -0.000768109 -0.195885" quat="1 0.000158305 -0.000229653 -0.00020113">
            <inertial pos="0.00739015 0.00112267 -0.129926" quat="0.703575 -0.00486053 0.00170497 0.710602" mass="0.218898" diaginertia="0.00190049 0.00107618 3.44243e-05"/>
            <joint name="RR_calf_joint" pos="0 0 0" axis="-0.000136407 -0.999986 0.00530619" stiffness="0.000796813" range="0.854661 2.7073" armature="0.0094271" damping="0.00956371" frictionloss="0.185223"/>
            <geom name="//unnamed_geom_63" class="visual" material="gray" mesh="calf_mirror_0"/>
            <geom name="//unnamed_geom_64" class="visual" material="black" mesh="calf_mirror_1"/>
            <geom name="RR_calf0" class="collision" size="0.0126182 0.0582378" pos="0.0105101 0 -0.0550733" quat="0.995004 0 -0.0998334 0" type="cylinder"/>
            <geom name="//unnamed_geom_66" class="collision" size="0.0106769 0.0315455" pos="0.0210201 0 -0.135848" quat="0.999688 0 0.0249974 0" type="cylinder"/>
            <geom name="//unnamed_geom_67" class="visual" pos="0 0 -0.19551" quat="1 0 0 0" material="black" mesh="foot"/>
            <geom name="RR_foot" class="foot" size="0.0248456" pos="-0.00210201 0 -0.19551"/>
            <geom name="//unnamed_geom_69" class="reward_collision_sphere" size="0.0242657"/>
            <geom name="//unnamed_geom_70" class="reward_collision_sphere" size="0.0242657" pos="-0.00210201 0 -0.19551"/>
            <site name="RR_foot" class="foot" pos="-0.00210201 0 -0.19551" size="0.0097063"/>
          </body>
        </body>
      </body>
    </body>
  </worldbody>

  <contact>
    <pair class="/" geom1="floor" geom2="FL_foot" name="//unnamed_contact_0"/>
    <pair class="/" geom1="floor" geom2="FR_foot" name="//unnamed_contact_1"/>
    <pair class="/" geom1="floor" geom2="RL_foot" name="//unnamed_contact_2"/>
    <pair class="/" geom1="floor" geom2="RR_foot" name="//unnamed_contact_3"/>
  </contact>

  <actuator>
    <general name="FL_hip" class="/" joint="FL_hip_joint" forcerange="-22.0808 22.0808" gainprm="19.4145" biasprm="0 -19.4145 -0.483408"/>
    <general name="FL_thigh" class="/" joint="FL_thigh_joint" forcerange="-22.8013 22.8013" gainprm="19.4145" biasprm="0 -19.4145 -0.483408"/>
    <general name="FL_calf" class="/" joint="FL_calf_joint" forcerange="-43.605 43.605" gainprm="19.4145" biasprm="0 -19.4145 -0.483408"/>
    <general name="FR_hip" class="/" joint="FR_hip_joint" forcerange="-23.7708 23.7708" gainprm="19.4145" biasprm="0 -19.4145 -0.483408"/>
    <general name="FR_thigh" class="/" joint="FR_thigh_joint" forcerange="-23.2108 23.2108" gainprm="19.4145" biasprm="0 -19.4145 -0.483408"/>
    <general name="FR_calf" class="/" joint="FR_calf_joint" forcerange="-44.1048 44.1048" gainprm="19.4145" biasprm="0 -19.4145 -0.483408"/>
    <general name="RL_hip" class="/" joint="RL_hip_joint" forcerange="-23.5401 23.5401" gainprm="19.4145" biasprm="0 -19.4145 -0.483408"/>
    <general name="RL_thigh" class="/" joint="RL_thigh_joint" forcerange="-23.2952 23.2952" gainprm="19.4145" biasprm="0 -19.4145 -0.483408"/>
    <general name="RL_calf" class="/" joint="RL_calf_joint" forcerange="-43.1299 43.1299" gainprm="19.4145" biasprm="0 -19.4145 -0.483408"/>
    <general name="RR_hip" class="/" joint="RR_hip_joint" forcerange="-23.8663 23.8663" gainprm="19.4145" biasprm="0 -19.4145 -0.483408"/>
    <general name="RR_thigh" class="/" joint="RR_thigh_joint" forcerange="-22.3522 22.3522" gainprm="19.4145" biasprm="0 -19.4145 -0.483408"/>
    <general name="RR_calf" class="/" joint="RR_calf_joint" forcerange="-45.9097 45.9097" gainprm="19.4145" biasprm="0 -19.4145 -0.483408"/>
  </actuator>

  <sensor>
    <gyro site="imu" name="imu_angular_velocity"/>
    <velocimeter site="imu" name="imu_linear_velocity"/>
    <framelinvel objtype="site" objname="FL_foot" name="FL_foot_global_linear_velocity"/>
    <framelinvel objtype="site" objname="FR_foot" name="FR_foot_global_linear_velocity"/>
    <framelinvel objtype="site" objname="RL_foot" name="RL_foot_global_linear_velocity"/>
    <framelinvel objtype="site" objname="RR_foot" name="RR_foot_global_linear_velocity"/>
  </sensor>

  <keyframe>
    <key name="home" qpos="0 0 0.325 1 0 0 0 0.1 0.8 -1.5 -0.1 -0.8 1.5 -0.1 0.8 -1.5 0.1 -0.8 1.5"/>
  </keyframe>
</mujoco>
