<mujoco model="go2">
  <compiler angle="radian" assetdir="assets" balanceinertia="true" inertiafromgeom="false"/>

  <option timestep="0.005" density="1.2" viscosity="2e-05"/>

  <size nkey="1"/>

  <visual>
    <quality shadowsize="8192"/>
    <map shadowclip="0.5"/>
  </visual>

  <default>
    <default class="/">
      <geom contype="0" conaffinity="0" group="1" solref="-1000 -80"/>
      <site size="0.01 0.005 0.005" group="5"/>
      <general forcelimited="true" biastype="affine" gainprm="20" biasprm="0 -20 -0.5"/>
      <default class="go2">
        <joint armature="0.01" damping="0.01" frictionloss="0.2"/>
        <geom condim="1" margin="0.001"/>
        <default class="visual">
          <geom type="mesh" group="2"/>
        </default>
        <default class="collision">
          <geom group="3"/>
          <default class="foot">
            <geom size="0.022 0 0" condim="6" priority="1" friction="0.8 0.02 0.01" solimp="0.015 1 0.022"/>
          </default>
        </default>
        <default class="reward_collision_sphere">
          <geom group="5" rgba="1 0 0 1"/>
        </default>
      </default>
    </default>
  </default>

  <asset>
    <texture type="skybox" colorspace="auto" name="//unnamed_texture_0" builtin="gradient" rgb1="0.95 0.95 0.95" rgb2="0.95 0.95 0.95" width="100" height="600"/>
    <texture type="2d" colorspace="auto" name="texplane" builtin="checker" rgb1="0.345 0.575 0.748" rgb2="0.345 0.575 0.748" markrgb="1 1 1" width="512" height="512"/>
    <material name="MatPlane" class="/" texture="texplane" texuniform="true" texrepeat="2 2" specular="0.9"/>
    <material name="metal" class="/" rgba="0.9 0.95 0.95 1"/>
    <material name="black" class="/" rgba="0 0 0 1"/>
    <material name="white" class="/"/>
    <material name="gray" class="/" rgba="0.671705 0.692426 0.77427 1"/>
    <mesh name="base_0" class="/" file="base_0.obj"/>
    <mesh name="base_1" class="/" file="base_1.obj"/>
    <mesh name="base_2" class="/" file="base_2.obj"/>
    <mesh name="base_3" class="/" file="base_3.obj"/>
    <mesh name="base_4" class="/" file="base_4.obj"/>
    <mesh name="hip_0" class="/" file="hip_0.obj"/>
    <mesh name="hip_1" class="/" file="hip_1.obj"/>
    <mesh name="thigh_0" class="/" file="thigh_0.obj"/>
    <mesh name="thigh_1" class="/" file="thigh_1.obj"/>
    <mesh name="thigh_mirror_0" class="/" file="thigh_mirror_0.obj"/>
    <mesh name="thigh_mirror_1" class="/" file="thigh_mirror_1.obj"/>
    <mesh name="calf_0" class="/" file="calf_0.obj"/>
    <mesh name="calf_1" class="/" file="calf_1.obj"/>
    <mesh name="calf_mirror_0" class="/" file="calf_mirror_0.obj"/>
    <mesh name="calf_mirror_1" class="/" file="calf_mirror_1.obj"/>
    <mesh name="foot" class="/" file="foot.obj"/>
  </asset>

  <worldbody>
    <geom name="floor" class="/" size="100 100 0.125" type="plane" group="0" material="MatPlane"/>
    <light name="toplight_shadow" class="/" pos="0 0 5" dir="0.0990148 0.0990148 -0.990148" type="directional" ambient="0.04 0.04 0.04" diffuse="0.55 0.55 0.55" specular="0.12 0.12 0.12"/>
    <light name="toplight_fill" class="/" pos="0 0 5" dir="0.0990148 0.0990148 -0.990148" type="directional" castshadow="false" ambient="0.04 0.04 0.04" diffuse="0.3 0.3 0.3" specular="0.08 0.08 0.08"/>
    <body name="trunk" childclass="go2" pos="-0.00138108 0.00767565 0.00322703" quat="0.999993 0.000156103 0.00374624 -0.000951715">
      <inertial pos="0.023322 0.0126067 -0.0115359" quat="0.00973 0.73352 0.00289673 0.679592" mass="6.62903" diaginertia="0.0490394 0.815076 0.00270434"/>
      <joint name="//unnamed_joint_0" type="free" armature="0" damping="0" frictionloss="0"/>
      <geom name="//unnamed_geom_1" class="visual" material="black" mesh="base_0"/>
      <geom name="//unnamed_geom_2" class="visual" material="black" mesh="base_1"/>
      <geom name="//unnamed_geom_3" class="visual" material="black" mesh="base_2"/>
      <geom name="//unnamed_geom_4" class="visual" material="white" mesh="base_3"/>
      <geom name="//unnamed_geom_5" class="visual" material="gray" mesh="base_4"/>
      <geom name="trunk_1" class="collision" size="0.183903 0.0457069 0.0557283" type="box"/>
      <geom name="trunk_2" class="collision" size="0.0488844 0.043996" pos="0.230125 0 0.0064195" type="cylinder"/>
      <geom name="trunk_3" class="collision" size="0.0459514" pos="0.236584 0 -0.038517"/>
      <geom name="//unnamed_geom_9" class="reward_collision_sphere" size="0.0977689"/>
      <geom name="//unnamed_geom_10" class="reward_collision_sphere" size="0.0586613" pos="0.226087 0 -0.0288877"/>
      <site name="imu" pos="-0.020314 0.0032784 0.030521" size="0.00977689"/>
      <camera name="track" pos="0 -2.96732 0" quat="0.707107 0.707107 0 0" mode="trackcom"/>
      <camera name="ego_camera" pos="0.251926 0 0.0288877" quat="-0.5 -0.5 0.5 0.5"/>
      <body name="FL_hip" pos="0.156521 0.0717704 -0.000107641" quat="1 -0.000187764 0.000196015 0.000426274">
        <inertial pos="-0.00358606 0.0127348 0.00188212" quat="0.444282 0.50153 0.505753 0.54341" mass="0.629101" diaginertia="0.000294824 0.00446224 5.06455e-05"/>
        <joint name="FL_hip_joint" pos="0 0 0" axis="0.999474 -0.00586131 -0.0318924" range="-0.928044 1.07013" armature="0.0100174" damping="0.0155087" frictionloss="0.181518"/>
        <geom name="//unnamed_geom_11" class="visual" material="metal" mesh="hip_0"/>
        <geom name="//unnamed_geom_12" class="visual" material="gray" mesh="hip_1"/>
        <geom name="//unnamed_geom_13" class="collision" size="0.0449737 0.0195538" pos="0 0.118693 0" quat="0.707107 0.707107 0 0" type="cylinder"/>
        <geom name="//unnamed_geom_14" class="reward_collision_sphere" size="0.0586613" pos="0 0.103856 0"/>
        <body name="FL_thigh" pos="-0.00962185 0.135726 -0.00273447" quat="0.999979 0.000292051 0.00559726 -0.00334425">
          <inertial pos="-0.00435551 -0.0461748 -0.0198717" quat="0.840794 0.0790116 -0.0268236 0.534886" mass="1.01425" diaginertia="0.00235861 0.0360873 9.76133e-05"/>
          <joint name="FL_thigh_joint" pos="0 0 0" axis="-0.0190692 0.99919 -0.0354359" range="-1.41314 3.72296" armature="0.00351376" damping="0.00632335" frictionloss="0.257341"/>
          <geom name="//unnamed_geom_15" class="visual" material="metal" mesh="thigh_0"/>
          <geom name="//unnamed_geom_16" class="visual" material="gray" mesh="thigh_1"/>
          <geom name="//unnamed_geom_17" class="collision" size="0.104124 0.0119767 0.0166207" pos="0 0 -0.0683676" quat="0.707107 0 0.707107 0" type="box"/>
          <body name="FL_calf" pos="-0.00178174 -0.00162232 -0.138908" quat="1 5.65573e-05 -8.0233e-05 -0.000193372">
            <inertial pos="0.0159061 0.0062324 -0.0812688" quat="0.705188 0.018115 -0.0110981 0.708702" mass="0.234604" diaginertia="0.000561777 0.00981047 6.31951e-06"/>
            <joint name="FL_calf_joint" pos="0 0 0" axis="-0.0133782 0.999712 -0.0199409" range="-2.9858 -1.02485" armature="0.0131224" damping="0.0594512" frictionloss="0.161588"/>
            <geom name="//unnamed_geom_18" class="visual" material="gray" mesh="calf_0"/>
            <geom name="//unnamed_geom_19" class="visual" material="black" mesh="calf_1"/>
            <geom name="FL_calf0" class="collision" size="0.0117323 0.0586613" pos="0.00645964 0 -0.038517" quat="0.994493 0 -0.104807 0" type="cylinder"/>
            <geom name="//unnamed_geom_21" class="collision" size="0.0107546 0.0317749" pos="0.0161491 0 -0.0950085" quat="0.999688 0 0.0249974 0" type="cylinder"/>
            <geom name="//unnamed_geom_22" class="visual" pos="0 0 -0.136735" quat="1 0 0 0" material="black" mesh="foot"/>
            <geom name="FL_foot" class="foot" size="0.0249696" pos="-0.00161491 0 -0.136735"/>
            <geom name="//unnamed_geom_24" class="reward_collision_sphere" size="0.0244422"/>
            <geom name="//unnamed_geom_25" class="reward_collision_sphere" size="0.0244422" pos="-0.00161491 0 -0.136735"/>
            <site name="FL_foot" class="foot" pos="-0.00161491 0 -0.136735" size="0.00977689"/>
          </body>
        </body>
      </body>
      <body name="FR_hip" pos="0.169058 -0.0637437 0.00601001" quat="1 6.61316e-05 -0.000733832 -0.000484121">
        <inertial pos="-0.00357397 -0.0071483 0.00465355" quat="0.481454 0.541644 0.512577 0.460531" mass="0.677576" diaginertia="0.000340023 0.00428552 5.06989e-05"/>
        <joint name="FR_hip_joint" pos="0 0 0" axis="0.999484 -0.0153388 0.0282341" stiffness="0.0678521" range="-1.04883 0.841165" armature="0.0119349" damping="0.020349" frictionloss="0.167622"/>
        <geom name="//unnamed_geom_26" class="visual" pos="0 7.33265e-09 3.14512e-07" quat="4.63268e-05 1 0 0" material="metal" mesh="hip_0"/>
        <geom name="//unnamed_geom_27" class="visual" pos="0 1.18871e-08 -7.77909e-07" quat="4.63268e-05 1 0 0" material="gray" mesh="hip_1"/>
        <geom name="//unnamed_geom_28" class="collision" size="0.0449737 0.0195538" pos="0 -0.118693 0" quat="0.707107 0.707107 0 0" type="cylinder"/>
        <geom name="//unnamed_geom_29" class="reward_collision_sphere" size="0.0586613" pos="0 -0.103856 0"/>
        <body name="FR_thigh" pos="0.00442783 -0.141873 0.0110496" quat="0.999999 0.000702876 0.000421036 -0.000818808">
          <inertial pos="-0.00871378 0.0404314 -0.0325551" quat="0.539885 -0.0287945 0.0954796 0.83581" mass="1.02373" diaginertia="0.00221016 0.0415402 9.48326e-05"/>
          <joint name="FR_thigh_joint" pos="0 0 0" axis="0.0130346 -0.999865 0.0100023" range="-3.51382 1.49573" armature="0.0146245" damping="0" frictionloss="0.264689"/>
          <geom name="//unnamed_geom_30" class="visual" material="metal" mesh="thigh_mirror_0"/>
          <geom name="//unnamed_geom_31" class="visual" material="gray" mesh="thigh_mirror_1"/>
          <geom name="//unnamed_geom_32" class="collision" size="0.104124 0.0119767 0.0166207" pos="0 0 -0.0683676" quat="0.707107 0 0.707107 0" type="box"/>
          <body name="FR_calf" pos="0.00542652 -0.000758804 -0.14766" quat="1 -0.000752516 -0.000469135 -0.000229873">
            <inertial pos="0.0122007 -0.00659586 -0.0913046" quat="0.709256 -0.0240999 0.0108237 0.704456" mass="0.188188" diaginertia="0.000451475 0.00791787 5.27293e-06"/>
            <joint name="FR_calf_joint" pos="0 0 0" axis="0.00162545 -0.999999 0.00047173" stiffness="0.000902596" range="0.766701 2.66923" armature="0.0101591" damping="0.0693321" frictionloss="0.234509"/>
            <geom name="//unnamed_geom_33" class="visual" material="gray" mesh="calf_mirror_0"/>
            <geom name="//unnamed_geom_34" class="visual" material="black" mesh="calf_mirror_1"/>
            <geom name="FR_calf0" class="collision" size="0.01271 0.0586613" pos="0.00807455 0 -0.038517" quat="0.995004 0 -0.0998334 0" type="cylinder"/>
            <geom name="//unnamed_geom_36" class="collision" size="0.0107546 0.0317749" pos="0.0161491 0 -0.0950085" quat="0.999688 0 0.0249974 0" type="cylinder"/>
            <geom name="//unnamed_geom_37" class="visual" pos="0 0 -0.136735" quat="1 0 0 0" material="black" mesh="foot"/>
            <geom name="FR_foot" class="foot" size="0.0319022" pos="-0.00161491 0 -0.136735"/>
            <geom name="//unnamed_geom_39" class="reward_collision_sphere" size="0.0244422"/>
            <geom name="//unnamed_geom_40" class="reward_collision_sphere" size="0.0244422" pos="-0.00161491 0 -0.136735"/>
            <site name="FR_foot" class="foot" pos="-0.00161491 0 -0.136735" size="0.00977689"/>
          </body>
        </body>
      </body>
      <body name="RL_hip" pos="-0.156688 0.0633275 -0.00899527" quat="1 5.97824e-05 -0.000394683 1.25055e-05">
        <inertial pos="0.00274116 0.0047697 -0.00704786" quat="0.51081 0.490509 0.494739 0.503694" mass="0.778358" diaginertia="0.000325962 0.00482979 5.06892e-05"/>
        <joint name="RL_hip_joint" pos="0 0 0" axis="-0.999744 -0.0224321 -0.00290995" range="-1.25067 1.12309" armature="0.0106705" damping="0.00503984" frictionloss="0.107494"/>
        <geom name="//unnamed_geom_41" class="visual" pos="-1.44182e-09 0 -2.8263e-07" quat="4.63268e-05 0 1 0" material="metal" mesh="hip_0"/>
        <geom name="//unnamed_geom_42" class="visual" pos="-2.33736e-09 0 -2.50652e-07" quat="4.63268e-05 0 1 0" material="gray" mesh="hip_1"/>
        <geom name="//unnamed_geom_43" class="collision" size="0.0449737 0.0195538" pos="0 0.118693 0" quat="0.707107 0.707107 0 0" type="cylinder"/>
        <geom name="//unnamed_geom_44" class="reward_collision_sphere" size="0.0586613" pos="0 0.103856 0"/>
        <body name="RL_thigh" pos="-0.00202173 0.147109 -0.00260128" quat="0.999983 -0.00449714 -0.000593179 0.00368246">
          <inertial pos="-0.00242058 -0.0469099 -0.0246973" quat="0.816711 0.0507071 -0.00847201 0.574753" mass="1.2373" diaginertia="0.00218658 0.0383669 8.23461e-05"/>
          <joint name="RL_thigh_joint" pos="0 0 0" axis="-0.0286953 0.997861 0.0587413" stiffness="0.00102942" range="-0.517059 4.51794" armature="0.0060282" damping="0" frictionloss="0.257682"/>
          <geom name="//unnamed_geom_45" class="visual" material="metal" mesh="thigh_0"/>
          <geom name="//unnamed_geom_46" class="visual" material="gray" mesh="thigh_1"/>
          <geom name="//unnamed_geom_47" class="collision" size="0.104124 0.0119767 0.0166207" pos="0 0 -0.0683676" quat="0.707107 0 0.707107 0" type="box"/>
          <body name="RL_calf" pos="0.00507819 0.000985593 -0.144979" quat="0.999995 -0.000435772 0.00225152 0.00197126">
            <inertial pos="0.00676943 -0.0107618 -0.090933" quat="0.711612 -0.000642028 -0.00436858 0.702558" mass="0.231269" diaginertia="0.00055676 0.0114848 6.36684e-06"/>
            <joint name="RL_calf_joint" pos="0 0 0" axis="-0.00828662 0.999956 0.00428136" range="-2.97671 -0.802971" armature="0.00335738" damping="0" frictionloss="0.267319"/>
            <geom name="//unnamed_geom_48" class="visual" material="gray" mesh="calf_0"/>
            <geom name="//unnamed_geom_49" class="visual" material="black" mesh="calf_1"/>
            <geom name="RL_calf0" class="collision" size="0.01271 0.0586613" pos="0.00807455 0 -0.038517" quat="0.995004 0 -0.0998334 0" type="cylinder"/>
            <geom name="//unnamed_geom_51" class="collision" size="0.0107546 0.0317749" pos="0.0161491 0 -0.0950085" quat="0.999688 0 0.0249974 0" type="cylinder"/>
            <geom name="//unnamed_geom_52" class="visual" pos="0 0 -0.136735" quat="1 0 0 0" material="black" mesh="foot"/>
            <geom name="RL_foot" class="foot" size="0.0232339" pos="-0.00161491 0 -0.136735"/>
            <geom name="//unnamed_geom_54" class="reward_collision_sphere" size="0.0244422"/>
            <geom name="//unnamed_geom_55" class="reward_collision_sphere" size="0.0244422" pos="-0.00161491 0 -0.136735"/>
            <site name="RL_foot" class="foot" pos="-0.00161491 0 -0.136735" size="0.00977689"/>
          </body>
        </body>
      </body>
      <body name="RR_hip" pos="-0.143534 -0.0680595 -0.00236518" quat="0.999977 -0.00409648 0.00358796 -0.00409333">
        <inertial pos="0.00494369 0.000310682 0.00036947" quat="0.500569 0.501929 0.496993 0.500495" mass="0.672863" diaginertia="0.000324486 0.00440346 4.63797e-05"/>
        <joint name="RR_hip_joint" pos="0 0 0" axis="-0.999999 -0.00166435 0.000122744" range="-1.01435 0.890703" armature="0.00425726" damping="0.0128492" frictionloss="0.127272"/>
        <geom name="//unnamed_geom_56" class="visual" pos="1.46523e-09 7.33265e-09 -5.97142e-07" quat="2.14617e-09 4.63268e-05 4.63268e-05 -1" material="metal" mesh="hip_0"/>
        <geom name="//unnamed_geom_57" class="visual" pos="2.27946e-09 1.18871e-08 5.27257e-07" quat="2.14617e-09 4.63268e-05 4.63268e-05 -1" material="gray" mesh="hip_1"/>
        <geom name="//unnamed_geom_58" class="collision" size="0.0449737 0.0195538" pos="0 -0.118693 0" quat="0.707107 0.707107 0 0" type="cylinder"/>
        <geom name="//unnamed_geom_59" class="reward_collision_sphere" size="0.0586613" pos="0 -0.103856 0"/>
        <body name="RR_thigh" pos="0.0079363 -0.150869 0.00362758" quat="0.999997 0.000176997 -0.00055069 -0.00217976">
          <inertial pos="-0.00209054 0.0418601 -0.0212161" quat="0.553176 -0.0159725 0.08426 0.828639" mass="1.00793" diaginertia="0.00199413 0.0424192 0.000102067"/>
          <joint name="RR_thigh_joint" pos="0 0 0" axis="0.00569655 -0.999984 0.0002715" range="-4.52248 0.258395" armature="0.0158808" damping="0" frictionloss="0.191488"/>
          <geom name="//unnamed_geom_60" class="visual" material="metal" mesh="thigh_mirror_0"/>
          <geom name="//unnamed_geom_61" class="visual" material="gray" mesh="thigh_mirror_1"/>
          <geom name="//unnamed_geom_62" class="collision" size="0.104124 0.0119767 0.0166207" pos="0 0 -0.0683676" quat="0.707107 0 0.707107 0" type="box"/>
          <body name="RR_calf" pos="-0.00670895 0.000144858 -0.14148" quat="1 3.11301e-07 -5.27919e-06 -1.73227e-05">
            <inertial pos="0.0115796 0.00028281 -0.0914159" quat="0.704903 -0.00113241 0.00171322 0.709301" mass="0.206215" diaginertia="0.000498357 0.00990611 5.85699e-06"/>
            <joint name="RR_calf_joint" pos="0 0 0" axis="-3.26723e-05 -0.998961 -0.0455764" range="0.621927 2.61344" armature="0.0105193" damping="0.00640614" frictionloss="0.134577"/>
            <geom name="//unnamed_geom_63" class="visual" material="gray" mesh="calf_mirror_0"/>
            <geom name="//unnamed_geom_64" class="visual" material="black" mesh="calf_mirror_1"/>
            <geom name="RR_calf0" class="collision" size="0.01271 0.0586613" pos="0.00807455 0 -0.038517" quat="0.995004 0 -0.0998334 0" type="cylinder"/>
            <geom name="//unnamed_geom_66" class="collision" size="0.0107546 0.0317749" pos="0.0161491 0 -0.0950085" quat="0.999688 0 0.0249974 0" type="cylinder"/>
            <geom name="//unnamed_geom_67" class="visual" pos="0 0 -0.136735" quat="1 0 0 0" material="black" mesh="foot"/>
            <geom name="RR_foot" class="foot" size="0.0106464" pos="-0.00161491 0 -0.136735"/>
            <geom name="//unnamed_geom_69" class="reward_collision_sphere" size="0.0244422"/>
            <geom name="//unnamed_geom_70" class="reward_collision_sphere" size="0.0244422" pos="-0.00161491 0 -0.136735"/>
            <site name="RR_foot" class="foot" pos="-0.00161491 0 -0.136735" size="0.00977689"/>
          </body>
        </body>
      </body>
    </body>
  </worldbody>

  <contact>
    <pair class="/" geom1="floor" geom2="FL_foot" name="//unnamed_contact_0"/>
    <pair class="/" geom1="floor" geom2="FR_foot" name="//unnamed_contact_1"/>
    <pair class="/" geom1="floor" geom2="RL_foot" name="//unnamed_contact_2"/>
    <pair class="/" geom1="floor" geom2="RR_foot" name="//unnamed_contact_3"/>
  </contact>

  <actuator>
    <general name="FL_hip" class="/" joint="FL_hip_joint" forcerange="-18.6204 18.6204" gainprm="20.2005" biasprm="0 -20.2005 -0.495632"/>
    <general name="FL_thigh" class="/" joint="FL_thigh_joint" forcerange="-21.9219 21.9219" gainprm="20.2005" biasprm="0 -20.2005 -0.495632"/>
    <general name="FL_calf" class="/" joint="FL_calf_joint" forcerange="-45.8076 45.8076" gainprm="20.2005" biasprm="0 -20.2005 -0.495632"/>
    <general name="FR_hip" class="/" joint="FR_hip_joint" forcerange="-28.1794 28.1794" gainprm="20.2005" biasprm="0 -20.2005 -0.495632"/>
    <general name="FR_thigh" class="/" joint="FR_thigh_joint" forcerange="-22.2871 22.2871" gainprm="20.2005" biasprm="0 -20.2005 -0.495632"/>
    <general name="FR_calf" class="/" joint="FR_calf_joint" forcerange="-58.6032 58.6032" gainprm="20.2005" biasprm="0 -20.2005 -0.495632"/>
    <general name="RL_hip" class="/" joint="RL_hip_joint" forcerange="-26.1925 26.1925" gainprm="20.2005" biasprm="0 -20.2005 -0.495632"/>
    <general name="RL_thigh" class="/" joint="RL_thigh_joint" forcerange="-22.2822 22.2822" gainprm="20.2005" biasprm="0 -20.2005 -0.495632"/>
    <general name="RL_calf" class="/" joint="RL_calf_joint" forcerange="-39.9753 39.9753" gainprm="20.2005" biasprm="0 -20.2005 -0.495632"/>
    <general name="RR_hip" class="/" joint="RR_hip_joint" forcerange="-27.8996 27.8996" gainprm="20.2005" biasprm="0 -20.2005 -0.495632"/>
    <general name="RR_thigh" class="/" joint="RR_thigh_joint" forcerange="-19.6126 19.6126" gainprm="20.2005" biasprm="0 -20.2005 -0.495632"/>
    <general name="RR_calf" class="/" joint="RR_calf_joint" forcerange="-25.9459 25.9459" gainprm="20.2005" biasprm="0 -20.2005 -0.495632"/>
  </actuator>

  <sensor>
    <gyro site="imu" name="imu_angular_velocity"/>
    <velocimeter site="imu" name="imu_linear_velocity"/>
    <framelinvel objtype="site" objname="FL_foot" name="FL_foot_global_linear_velocity"/>
    <framelinvel objtype="site" objname="FR_foot" name="FR_foot_global_linear_velocity"/>
    <framelinvel objtype="site" objname="RL_foot" name="RL_foot_global_linear_velocity"/>
    <framelinvel objtype="site" objname="RR_foot" name="RR_foot_global_linear_velocity"/>
  </sensor>

  <keyframe>
    <key name="home" qpos="0 0 0.325 1 0 0 0 0.1 0.8 -1.5 -0.1 -0.8 1.5 -0.1 0.8 -1.5 0.1 -0.8 1.5"/>
  </keyframe>
</mujoco>
