<mujoco model="go2">
  <compiler angle="radian" assetdir="assets" balanceinertia="true" inertiafromgeom="false"/>

  <option timestep="0.005" density="1.2" viscosity="2e-05"/>

  <size nkey="1"/>

  <visual>
    <quality shadowsize="8192"/>
    <map shadowclip="0.5"/>
  </visual>

  <default>
    <default class="/">
      <geom contype="0" conaffinity="0" group="1" solref="-1000 -80"/>
      <site size="0.01 0.005 0.005" group="5"/>
      <general forcelimited="true" biastype="affine" gainprm="20" biasprm="0 -20 -0.5"/>
      <default class="go2">
        <joint armature="0.01" damping="0.01" frictionloss="0.2"/>
        <geom condim="1" margin="0.001"/>
        <default class="visual">
          <geom type="mesh" group="2"/>
        </default>
        <default class="collision">
          <geom group="3"/>
          <default class="foot">
            <geom size="0.022 0 0" condim="6" priority="1" friction="0.8 0.02 0.01" solimp="0.015 1 0.022"/>
          </default>
        </default>
        <default class="reward_collision_sphere">
          <geom group="5" rgba="1 0 0 1"/>
        </default>
      </default>
    </default>
  </default>

  <asset>
    <texture type="skybox" colorspace="auto" name="//unnamed_texture_0" builtin="gradient" rgb1="0.95 0.95 0.95" rgb2="0.95 0.95 0.95" width="100" height="600"/>
    <texture type="2d" colorspace="auto" name="texplane" builtin="checker" rgb1="0.345 0.575 0.748" rgb2="0.345 0.575 0.748" markrgb="1 1 1" width="512" height="512"/>
    <material name="MatPlane" class="/" texture="texplane" texuniform="true" texrepeat="2 2" specular="0.9"/>
    <material name="metal" class="/" rgba="0.9 0.95 0.95 1"/>
    <material name="black" class="/" rgba="0 0 0 1"/>
    <material name="white" class="/"/>
    <material name="gray" class="/" rgba="0.671705 0.692426 0.77427 1"/>
    <mesh name="base_0" class="/" file="base_0.obj"/>
    <mesh name="base_1" class="/" file="base_1.obj"/>
    <mesh name="base_2" class="/" file="base_2.obj"/>
    <mesh name="base_3" class="/" file="base_3.obj"/>
    <mesh name="base_4" class="/" file="base_4.obj"/>
    <mesh name="hip_0" class="/" file="hip_0.obj"/>
    <mesh name="hip_1" class="/" file="hip_1.obj"/>
    <mesh name="thigh_0" class="/" file="thigh_0.obj"/>
    <mesh name="thigh_1" class="/" file="thigh_1.obj"/>
    <mesh name="thigh_mirror_0" class="/" file="thigh_mirror_0.obj"/>
    <mesh name="thigh_mirror_1" class="/" file="thigh_mirror_1.obj"/>
    <mesh name="calf_0" class="/" file="calf_0.obj"/>
    <mesh name="calf_1" class="/" file="calf_1.obj"/>
    <mesh name="calf_mirror_0" class="/" file="calf_mirror_0.obj"/>
    <mesh name="calf_mirror_1" class="/" file="calf_mirror_1.obj"/>
    <mesh name="foot" class="/" file="foot.obj"/>
  </asset>

  <worldbody>
    <geom name="floor" class="/" size="100 100 0.125" type="plane" group="0" material="MatPlane"/>
    <light name="toplight_shadow" class="/" pos="0 0 5" dir="0.0990148 0.0990148 -0.990148" type="directional" ambient="0.04 0.04 0.04" diffuse="0.55 0.55 0.55" specular="0.12 0.12 0.12"/>
    <light name="toplight_fill" class="/" pos="0 0 5" dir="0.0990148 0.0990148 -0.990148" type="directional" castshadow="false" ambient="0.04 0.04 0.04" diffuse="0.3 0.3 0.3" specular="0.08 0.08 0.08"/>
    <body name="trunk" childclass="go2" pos="0.00246074 0.0125874 0.00805895" quat="0.99998 -0.00547547 -0.00302138 -0.000943452">
      <inertial pos="0.0318691 0.0175468 -0.0155045" quat="0.0525928 0.708603 -0.0176148 0.703425" mass="7.90379" diaginertia="0.142526 1.58697 0.000561475"/>
      <joint name="//unnamed_joint_0" type="free" armature="0" damping="0" frictionloss="0"/>
      <geom name="//unnamed_geom_1" class="visual" material="black" mesh="base_0"/>
      <geom name="//unnamed_geom_2" class="visual" material="black" mesh="base_1"/>
      <geom name="//unnamed_geom_3" class="visual" material="black" mesh="base_2"/>
      <geom name="//unnamed_geom_4" class="visual" material="white" mesh="base_3"/>
      <geom name="//unnamed_geom_5" class="visual" material="gray" mesh="base_4"/>
      <geom name="trunk_1" class="collision" size="0.196271 0.0487807 0.0594759" type="box"/>
      <geom name="trunk_2" class="collision" size="0.0521719 0.0469547" pos="0.278991 0 0.00470655" type="cylinder"/>
      <geom name="trunk_3" class="collision" size="0.0490416" pos="0.286822 0 -0.0282393"/>
      <geom name="//unnamed_geom_9" class="reward_collision_sphere" size="0.104344"/>
      <geom name="//unnamed_geom_10" class="reward_collision_sphere" size="0.0626062" pos="0.274096 0 -0.0211795"/>
      <site name="imu" pos="-0.0017281 -0.0188037 0.00121668" size="0.0104344"/>
      <camera name="track" pos="0 -3.36148 0" quat="0.707107 0.707107 0 0" mode="trackcom"/>
      <camera name="ego_camera" pos="0.305421 0 0.0211795" quat="-0.5 -0.5 0.5 0.5"/>
      <body name="FL_hip" pos="0.184922 0.0770904 -0.00429202" quat="0.999999 0.00159697 -0.000376643 0.00043906">
        <inertial pos="-0.00499765 0.0180493 -0.00214075" quat="0.540634 0.439459 0.549945 0.460599" mass="0.681978" diaginertia="0.000765787 0.00826553 1.06283e-05"/>
        <joint name="FL_hip_joint" pos="0 0 0" axis="0.998618 -0.0522577 0.00550032" range="-0.829963 1.16447" armature="0.0131853" damping="0" frictionloss="0.230118"/>
        <geom name="//unnamed_geom_11" class="visual" material="metal" mesh="hip_0"/>
        <geom name="//unnamed_geom_12" class="visual" material="gray" mesh="hip_1"/>
        <geom name="//unnamed_geom_13" class="collision" size="0.0479981 0.0208687" pos="0 0.134459 0" quat="0.707107 0.707107 0 0" type="cylinder"/>
        <geom name="//unnamed_geom_14" class="reward_collision_sphere" size="0.0626062" pos="0 0.117652 0"/>
        <body name="FL_thigh" pos="-0.0146106 0.149641 -0.00764775" quat="0.99996 -0.00615054 0.00535098 0.00379804">
          <inertial pos="-0.00108105 -0.0555009 -0.00945202" quat="0.812407 0.0652784 -0.0485549 0.577388" mass="1.10182" diaginertia="0.00623216 0.0597079 1.98065e-05"/>
          <joint name="FL_thigh_joint" pos="0 0 0" axis="0.0647624 0.997901 -0.000394153" range="-1.31478 3.8217" armature="0.000939981" damping="0" frictionloss="0.32574"/>
          <geom name="//unnamed_geom_15" class="visual" material="metal" mesh="thigh_0"/>
          <geom name="//unnamed_geom_16" class="visual" material="gray" mesh="thigh_1"/>
          <geom name="//unnamed_geom_17" class="collision" size="0.111126 0.0127821 0.0177384" pos="0 0 -0.0501248" quat="0.707107 0 0.707107 0" type="box"/>
          <body name="FL_calf" pos="-0.00643465 -0.00647809 -0.0981815" quat="0.999998 8.43942e-05 0.000470443 0.00194744">
            <inertial pos="0.0219268 0.0110274 -0.0521378" quat="0.698898 0.0199268 0.0317088 0.71424" mass="0.282117" diaginertia="0.00153015 0.0179377 1.49518e-06"/>
            <joint name="FL_calf_joint" pos="0 0 0" axis="-0.0255007 0.999658 -0.00571656" range="-3.08461 -1.12328" armature="0.0167886" damping="0.0878254" frictionloss="0.121953"/>
            <geom name="//unnamed_geom_18" class="visual" material="gray" mesh="calf_0"/>
            <geom name="//unnamed_geom_19" class="visual" material="black" mesh="calf_1"/>
            <geom name="FL_calf0" class="collision" size="0.0125212 0.0626062" pos="0.00783132 0 -0.0282393" quat="0.994493 0 -0.104807 0" type="cylinder"/>
            <geom name="//unnamed_geom_21" class="collision" size="0.0114778 0.0339117" pos="0.0195783 0 -0.069657" quat="0.999688 0 0.0249974 0" type="cylinder"/>
            <geom name="//unnamed_geom_22" class="visual" pos="0 0 -0.10025" quat="1 0 0 0" material="black" mesh="foot"/>
            <geom name="FL_foot" class="foot" size="0.0239474" pos="-0.00195783 0 -0.10025"/>
            <geom name="//unnamed_geom_24" class="reward_collision_sphere" size="0.0260859"/>
            <geom name="//unnamed_geom_25" class="reward_collision_sphere" size="0.0260859" pos="-0.00195783 0 -0.10025"/>
            <site name="FL_foot" class="foot" pos="-0.00195783 0 -0.10025" size="0.0104344"/>
          </body>
        </body>
      </body>
      <body name="FR_hip" pos="0.20719 -0.0681679 0.0106454" quat="0.999994 0.000543061 0.00331184 0.000332022">
        <inertial pos="0.000128082 -0.0124386 0.00969127" quat="0.562706 0.462831 0.478409 0.490178" mass="0.828841" diaginertia="0.000894432 0.00799343 9.56816e-06"/>
        <joint name="FR_hip_joint" pos="0 0 0" axis="0.998421 -0.0451374 -0.0334445" stiffness="0.09175" range="-1.13899 0.742069" armature="0.0150785" damping="0" frictionloss="0.128623"/>
        <geom name="//unnamed_geom_26" class="visual" pos="0 1.05418e-08 4.52159e-07" quat="4.63268e-05 1 0 0" material="metal" mesh="hip_0"/>
        <geom name="//unnamed_geom_27" class="visual" pos="0 1.70895e-08 -1.11836e-06" quat="4.63268e-05 1 0 0" material="gray" mesh="hip_1"/>
        <geom name="//unnamed_geom_28" class="collision" size="0.0479981 0.0208687" pos="0 -0.134459 0" quat="0.707107 0.707107 0 0" type="cylinder"/>
        <geom name="//unnamed_geom_29" class="reward_collision_sphere" size="0.0626062" pos="0 -0.117652 0"/>
        <body name="FR_thigh" pos="0.00937075 -0.157631 0.0157077" quat="1 -3.00909e-05 1.12551e-05 -6.16222e-05">
          <inertial pos="-0.0141942 0.0497316 -0.0318817" quat="0.559598 -0.0374994 0.0458956 0.826643" mass="1.19593" diaginertia="0.00626655 0.0786968 2.04e-05"/>
          <joint name="FR_thigh_joint" pos="0 0 0" axis="-0.0170564 -0.999778 0.0123567" range="-3.43108 1.39909" armature="0.017962" damping="0" frictionloss="0.333684"/>
          <geom name="//unnamed_geom_30" class="visual" material="metal" mesh="thigh_mirror_0"/>
          <geom name="//unnamed_geom_31" class="visual" material="gray" mesh="thigh_mirror_1"/>
          <geom name="//unnamed_geom_32" class="collision" size="0.111126 0.0127821 0.0177384" pos="0 0 -0.0501248" quat="0.707107 0 0.707107 0" type="box"/>
          <body name="FR_calf" pos="0.0085852 -0.000985736 -0.116166" quat="0.999994 0.00164117 0.00262776 0.00119501">
            <inertial pos="0.0181827 -0.0113741 -0.0705528" quat="0.726939 0.0155531 -0.0251266 0.686066" mass="0.213932" diaginertia="0.00115838 0.0127462 1.09303e-06"/>
            <joint name="FR_calf_joint" pos="0 0 0" axis="-0.00568434 -0.999748 -0.0217275" range="0.669232 2.57336" armature="0.013071" damping="0.0970816" frictionloss="0.300901"/>
            <geom name="//unnamed_geom_33" class="visual" material="gray" mesh="calf_mirror_0"/>
            <geom name="//unnamed_geom_34" class="visual" material="black" mesh="calf_mirror_1"/>
            <geom name="FR_calf0" class="collision" size="0.0135647 0.0626062" pos="0.00978915 0 -0.0282393" quat="0.995004 0 -0.0998334 0" type="cylinder"/>
            <geom name="//unnamed_geom_36" class="collision" size="0.0114778 0.0339117" pos="0.0195783 0 -0.069657" quat="0.999688 0 0.0249974 0" type="cylinder"/>
            <geom name="//unnamed_geom_37" class="visual" pos="0 0 -0.10025" quat="1 0 0 0" material="black" mesh="foot"/>
            <geom name="FR_foot" class="foot" size="0.0383335" pos="-0.00195783 0 -0.10025"/>
            <geom name="//unnamed_geom_39" class="reward_collision_sphere" size="0.0260859"/>
            <geom name="//unnamed_geom_40" class="reward_collision_sphere" size="0.0260859" pos="-0.00195783 0 -0.10025"/>
            <site name="FR_foot" class="foot" pos="-0.00195783 0 -0.10025" size="0.0104344"/>
          </body>
        </body>
      </body>
      <body name="RL_hip" pos="-0.190784 0.0676677 -0.0136922" quat="0.999999 -0.000298873 -0.000989575 -0.00120662">
        <inertial pos="-0.00104434 0.00991413 -0.0119066" quat="0.517714 0.482756 0.477842 0.520179" mass="1.05382" diaginertia="0.000955556 0.0100744 1.06012e-05"/>
        <joint name="RL_hip_joint" pos="0 0 0" axis="-0.998888 -0.000178023 0.04714" range="-1.34903 1.21996" armature="0.0139881" damping="0.0212751" frictionloss="0.0633687"/>
        <geom name="//unnamed_geom_41" class="visual" pos="-4.42775e-09 0 -8.67941e-07" quat="4.63268e-05 0 1 0" material="metal" mesh="hip_0"/>
        <geom name="//unnamed_geom_42" class="visual" pos="-7.17791e-09 0 -7.6974e-07" quat="4.63268e-05 0 1 0" material="gray" mesh="hip_1"/>
        <geom name="//unnamed_geom_43" class="collision" size="0.0479981 0.0208687" pos="0 0.134459 0" quat="0.707107 0.707107 0 0" type="cylinder"/>
        <geom name="//unnamed_geom_44" class="reward_collision_sphere" size="0.0626062" pos="0 0.117652 0"/>
        <body name="RL_thigh" pos="-0.000757396 0.170914 -0.00719975" quat="0.999965 -0.00343297 -0.000941926 0.00751841">
          <inertial pos="-0.0068109 -0.0562476 -0.0238906" quat="0.854267 0.0608242 -0.0653384 0.512113" mass="1.60495" diaginertia="0.00613012 0.0676773 1.64099e-05"/>
          <joint name="RL_thigh_joint" pos="0 0 0" axis="0.0751716 0.995979 0.0487271" stiffness="0.0230021" range="-0.423062 4.60311" armature="0.00400362" damping="0" frictionloss="0.326112"/>
          <geom name="//unnamed_geom_45" class="visual" material="metal" mesh="thigh_0"/>
          <geom name="//unnamed_geom_46" class="visual" material="gray" mesh="thigh_1"/>
          <geom name="//unnamed_geom_47" class="collision" size="0.111126 0.0127821 0.0177384" pos="0 0 -0.0501248" quat="0.707107 0 0.707107 0" type="box"/>
          <body name="RL_calf" pos="0.00975088 0.00202517 -0.113288" quat="0.999985 -0.00118966 -0.00379754 -0.00376152">
            <inertial pos="0.00401074 -0.0158088 -0.0622322" quat="0.706537 -0.0142978 -0.0148552 0.707376" mass="0.279674" diaginertia="0.0014473 0.0212649 1.33815e-06"/>
            <joint name="RL_calf_joint" pos="0 0 0" axis="-0.00185941 0.999984 -0.00532194" range="-3.07546 -0.874189" armature="0.00106822" damping="0" frictionloss="0.336517"/>
            <geom name="//unnamed_geom_48" class="visual" material="gray" mesh="calf_0"/>
            <geom name="//unnamed_geom_49" class="visual" material="black" mesh="calf_1"/>
            <geom name="RL_calf0" class="collision" size="0.0135647 0.0626062" pos="0.00978915 0 -0.0282393" quat="0.995004 0 -0.0998334 0" type="cylinder"/>
            <geom name="//unnamed_geom_51" class="collision" size="0.0114778 0.0339117" pos="0.0195783 0 -0.069657" quat="0.999688 0 0.0249974 0" type="cylinder"/>
            <geom name="//unnamed_geom_52" class="visual" pos="0 0 -0.10025" quat="1 0 0 0" material="black" mesh="foot"/>
            <geom name="RL_foot" class="foot" size="0.0218465" pos="-0.00195783 0 -0.10025"/>
            <geom name="//unnamed_geom_54" class="reward_collision_sphere" size="0.0260859"/>
            <geom name="//unnamed_geom_55" class="reward_collision_sphere" size="0.0260859" pos="-0.00195783 0 -0.10025"/>
            <site name="RL_foot" class="foot" pos="-0.00195783 0 -0.10025" size="0.0104344"/>
          </body>
        </body>
      </body>
      <body name="RR_hip" pos="-0.171723 -0.0810891 -0.00719064" quat="0.999957 -0.00553716 0.00589442 0.00451907">
        <inertial pos="0.0015031 0.00475112 0.00510523" quat="0.48992 0.499132 0.501194 0.509558" mass="0.87877" diaginertia="0.00089796 0.00813774 9.60986e-06"/>
        <joint name="RR_hip_joint" pos="0 0 0" axis="-0.999787 -0.0115595 -0.0170845" range="-0.919037 0.792277" armature="0.00178886" damping="0.0133867" frictionloss="0.0846541"/>
        <geom name="//unnamed_geom_56" class="visual" pos="4.45205e-09 1.05418e-08 -1.3201e-06" quat="2.14617e-09 4.63268e-05 4.63268e-05 -1" material="metal" mesh="hip_0"/>
        <geom name="//unnamed_geom_57" class="visual" pos="7.11781e-09 1.70895e-08 3.48621e-07" quat="2.14617e-09 4.63268e-05 4.63268e-05 -1" material="gray" mesh="hip_1"/>
        <geom name="//unnamed_geom_58" class="collision" size="0.0479981 0.0208687" pos="0 -0.134459 0" quat="0.707107 0.707107 0 0" type="cylinder"/>
        <geom name="//unnamed_geom_59" class="reward_collision_sphere" size="0.0626062" pos="0 -0.117652 0"/>
        <body name="RR_thigh" pos="0.0128799 -0.174532 0.00834363" quat="0.999989 -0.00222999 -0.00388135 0.00131711">
          <inertial pos="-0.00541208 0.0511734 -0.011105" quat="0.528218 -0.0236905 0.0861377 0.844396" mass="1.07781" diaginertia="0.00518403 0.0785974 2.14328e-05"/>
          <joint name="RR_thigh_joint" pos="0 0 0" axis="-0.000261195 -1 0.000322194" range="-4.60937 0.159467" armature="0.0197068" damping="0" frictionloss="0.251235"/>
          <geom name="//unnamed_geom_60" class="visual" material="metal" mesh="thigh_mirror_0"/>
          <geom name="//unnamed_geom_61" class="visual" material="gray" mesh="thigh_mirror_1"/>
          <geom name="//unnamed_geom_62" class="collision" size="0.111126 0.0127821 0.0177384" pos="0 0 -0.0501248" quat="0.707107 0 0.707107 0" type="box"/>
          <body name="RR_calf" pos="-0.011487 -0.00330034 -0.109974" quat="0.999997 -0.00222818 0.000532926 0.000246674">
            <inertial pos="0.0175742 -0.00428259 -0.0658119" quat="0.704206 -0.00803824 0.00255169 0.709946" mass="0.228609" diaginertia="0.00119714 0.0168964 1.28346e-06"/>
            <joint name="RR_calf_joint" pos="0 0 0" axis="0.0346554 -0.997588 -0.060151" range="0.523246 2.51586" armature="0.013837" damping="0.0246306" frictionloss="0.0925441"/>
            <geom name="//unnamed_geom_63" class="visual" material="gray" mesh="calf_mirror_0"/>
            <geom name="//unnamed_geom_64" class="visual" material="black" mesh="calf_mirror_1"/>
            <geom name="RR_calf0" class="collision" size="0.0135647 0.0626062" pos="0.00978915 0 -0.0282393" quat="0.995004 0 -0.0998334 0" type="cylinder"/>
            <geom name="//unnamed_geom_66" class="collision" size="0.0114778 0.0339117" pos="0.0195783 0 -0.069657" quat="0.999688 0 0.0249974 0" type="cylinder"/>
            <geom name="//unnamed_geom_67" class="visual" pos="0 0 -0.10025" quat="1 0 0 0" material="black" mesh="foot"/>
            <geom name="RR_foot" class="foot" size="0.00717916" pos="-0.00195783 0 -0.10025"/>
            <geom name="//unnamed_geom_69" class="reward_collision_sphere" size="0.0260859"/>
            <geom name="//unnamed_geom_70" class="reward_collision_sphere" size="0.0260859" pos="-0.00195783 0 -0.10025"/>
            <site name="RR_foot" class="foot" pos="-0.00195783 0 -0.10025" size="0.0104344"/>
          </body>
        </body>
      </body>
    </body>
  </worldbody>

  <contact>
    <pair class="/" geom1="floor" geom2="FL_foot" name="//unnamed_contact_0"/>
    <pair class="/" geom1="floor" geom2="FR_foot" name="//unnamed_contact_1"/>
    <pair class="/" geom1="floor" geom2="RL_foot" name="//unnamed_contact_2"/>
    <pair class="/" geom1="floor" geom2="RR_foot" name="//unnamed_contact_3"/>
  </contact>

  <actuator>
    <general name="FL_hip" class="/" joint="FL_hip_joint" forcerange="-15.3634 15.3634" gainprm="21.0817" biasprm="0 -21.0817 -0.470224"/>
    <general name="FL_thigh" class="/" joint="FL_thigh_joint" forcerange="-26.1039 26.1039" gainprm="21.0817" biasprm="0 -21.0817 -0.470224"/>
    <general name="FL_calf" class="/" joint="FL_calf_joint" forcerange="-41.2008 41.2008" gainprm="21.0817" biasprm="0 -21.0817 -0.470224"/>
    <general name="FR_hip" class="/" joint="FR_hip_joint" forcerange="-34.6209 34.6209" gainprm="21.0817" biasprm="0 -21.0817 -0.470224"/>
    <general name="FR_thigh" class="/" joint="FR_thigh_joint" forcerange="-27.7021 27.7021" gainprm="21.0817" biasprm="0 -21.0817 -0.470224"/>
    <general name="FR_calf" class="/" joint="FR_calf_joint" forcerange="-71.3136 71.3136" gainprm="21.0817" biasprm="0 -21.0817 -0.470224"/>
    <general name="RL_hip" class="/" joint="RL_hip_joint" forcerange="-32.4214 32.4214" gainprm="21.0817" biasprm="0 -21.0817 -0.470224"/>
    <general name="RL_thigh" class="/" joint="RL_thigh_joint" forcerange="-27.5792 27.5792" gainprm="21.0817" biasprm="0 -21.0817 -0.470224"/>
    <general name="RL_calf" class="/" joint="RL_calf_joint" forcerange="-34.0794 34.0794" gainprm="21.0817" biasprm="0 -21.0817 -0.470224"/>
    <general name="RR_hip" class="/" joint="RR_hip_joint" forcerange="-34.2909 34.2909" gainprm="21.0817" biasprm="0 -21.0817 -0.470224"/>
    <general name="RR_thigh" class="/" joint="RR_thigh_joint" forcerange="-16.4303 16.4303" gainprm="21.0817" biasprm="0 -21.0817 -0.470224"/>
    <general name="RR_calf" class="/" joint="RR_calf_joint" forcerange="-18.9763 18.9763" gainprm="21.0817" biasprm="0 -21.0817 -0.470224"/>
  </actuator>

  <sensor>
    <gyro site="imu" name="imu_angular_velocity"/>
    <velocimeter site="imu" name="imu_linear_velocity"/>
    <framelinvel objtype="site" objname="FL_foot" name="FL_foot_global_linear_velocity"/>
    <framelinvel objtype="site" objname="FR_foot" name="FR_foot_global_linear_velocity"/>
    <framelinvel objtype="site" objname="RL_foot" name="RL_foot_global_linear_velocity"/>
    <framelinvel objtype="site" objname="RR_foot" name="RR_foot_global_linear_velocity"/>
  </sensor>

  <keyframe>
    <key name="home" qpos="0 0 0.325 1 0 0 0 0.1 0.8 -1.5 -0.1 -0.8 1.5 -0.1 0.8 -1.5 0.1 -0.8 1.5"/>
  </keyframe>
</mujoco>
