<mujoco model="go2">
  <compiler angle="radian" assetdir="assets" balanceinertia="true" inertiafromgeom="false"/>

  <option timestep="0.005" density="1.2" viscosity="2e-05"/>

  <size nkey="1"/>

  <visual>
    <quality shadowsize="8192"/>
    <map shadowclip="0.5"/>
  </visual>

  <default>
    <default class="/">
      <geom contype="0" conaffinity="0" group="1" solref="-1000 -80"/>
      <site size="0.01 0.005 0.005" group="5"/>
      <general forcelimited="true" biastype="affine" gainprm="20" biasprm="0 -20 -0.5"/>
      <default class="go2">
        <joint armature="0.01" damping="0.01" frictionloss="0.2"/>
        <geom condim="1" margin="0.001"/>
        <default class="visual">
          <geom type="mesh" group="2"/>
        </default>
        <default class="collision">
          <geom group="3"/>
          <default class="foot">
            <geom size="0.022 0 0" condim="6" priority="1" friction="0.8 0.02 0.01" solimp="0.015 1 0.022"/>
          </default>
        </default>
        <default class="reward_collision_sphere">
          <geom group="5" rgba="1 0 0 1"/>
        </default>
      </default>
    </default>
  </default>

  <asset>
    <texture type="skybox" colorspace="auto" name="//unnamed_texture_0" builtin="gradient" rgb1="0.95 0.95 0.95" rgb2="0.95 0.95 0.95" width="100" height="600"/>
    <texture type="2d" colorspace="auto" name="texplane" builtin="checker" rgb1="0.345 0.575 0.748" rgb2="0.345 0.575 0.748" markrgb="1 1 1" width="512" height="512"/>
    <material name="MatPlane" class="/" texture="texplane" texuniform="true" texrepeat="2 2" specular="0.9"/>
    <material name="metal" class="/" rgba="0.9 0.95 0.95 1"/>
    <material name="black" class="/" rgba="0 0 0 1"/>
    <material name="white" class="/"/>
    <material name="gray" class="/" rgba="0.671705 0.692426 0.77427 1"/>
    <mesh name="base_0" class="/" file="base_0.obj"/>
    <mesh name="base_1" class="/" file="base_1.obj"/>
    <mesh name="base_2" class="/" file="base_2.obj"/>
    <mesh name="base_3" class="/" file="base_3.obj"/>
    <mesh name="base_4" class="/" file="base_4.obj"/>
    <mesh name="hip_0" class="/" file="hip_0.obj"/>
    <mesh name="hip_1" class="/" file="hip_1.obj"/>
    <mesh name="thigh_0" class="/" file="thigh_0.obj"/>
    <mesh name="thigh_1" class="/" file="thigh_1.obj"/>
    <mesh name="thigh_mirror_0" class="/" file="thigh_mirror_0.obj"/>
    <mesh name="thigh_mirror_1" class="/" file="thigh_mirror_1.obj"/>
    <mesh name="calf_0" class="/" file="calf_0.obj"/>
    <mesh name="calf_1" class="/" file="calf_1.obj"/>
    <mesh name="calf_mirror_0" class="/" file="calf_mirror_0.obj"/>
    <mesh name="calf_mirror_1" class="/" file="calf_mirror_1.obj"/>
    <mesh name="foot" class="/" file="foot.obj"/>
  </asset>

  <worldbody>
    <geom name="floor" class="/" size="100 100 0.125" type="plane" group="0" material="MatPlane"/>
    <light name="toplight_shadow" class="/" pos="0 0 5" dir="0.0990148 0.0990148 -0.990148" type="directional" ambient="0.04 0.04 0.04" diffuse="0.55 0.55 0.55" specular="0.12 0.12 0.12"/>
    <light name="toplight_fill" class="/" pos="0 0 5" dir="0.0990148 0.0990148 -0.990148" type="directional" castshadow="false" ambient="0.04 0.04 0.04" diffuse="0.3 0.3 0.3" specular="0.08 0.08 0.08"/>
    <body name="trunk" childclass="go2" pos="0.00276349 0.000492137 0.000272212" quat="1 0.000272216 -1.28749e-05 -0.000297537">
      <inertial pos="0.0241921 0.000157131 -0.00409761" quat="-0.00104854 0.717312 -0.00788748 0.696706" mass="6.47656" diaginertia="0.213755 0.127507 0.00598335"/>
      <joint name="//unnamed_joint_0" type="free" armature="0" damping="0" frictionloss="0"/>
      <geom name="//unnamed_geom_1" class="visual" material="black" mesh="base_0"/>
      <geom name="//unnamed_geom_2" class="visual" material="black" mesh="base_1"/>
      <geom name="//unnamed_geom_3" class="visual" material="black" mesh="base_2"/>
      <geom name="//unnamed_geom_4" class="visual" material="white" mesh="base_3"/>
      <geom name="//unnamed_geom_5" class="visual" material="gray" mesh="base_4"/>
      <geom name="trunk_1" class="collision" size="0.183686 0.0456531 0.0556626" type="box"/>
      <geom name="trunk_2" class="collision" size="0.0488268 0.0439441" pos="0.32283 0 0.00754826" type="cylinder"/>
      <geom name="trunk_3" class="collision" size="0.0458972" pos="0.331892 0 -0.0452895"/>
      <geom name="//unnamed_geom_9" class="reward_collision_sphere" size="0.0976536"/>
      <geom name="//unnamed_geom_10" class="reward_collision_sphere" size="0.0585922" pos="0.317166 0 -0.0339672"/>
      <site name="imu" pos="-0.0318086 0.0049651 0.0194947" size="0.00976536"/>
      <camera name="track" pos="0 -2.08409 0" quat="0.707107 0.707107 0 0" mode="trackcom"/>
      <camera name="ego_camera" pos="0.353414 0 0.0339672" quat="-0.5 -0.5 0.5 0.5"/>
      <body name="FL_hip" pos="0.218502 0.0488048 -0.00138362" quat="0.999999 0.00114176 -0.000486998 4.66471e-05">
        <inertial pos="-0.00876084 0.00165405 -0.000750564" quat="0.496896 0.499078 0.50568 0.4983" mass="0.635939" diaginertia="0.00166126 0.000705225 0.000118371"/>
        <joint name="FL_hip_joint" pos="0 0 0" axis="0.999957 0.00585971 0.00723977" range="-1.04358 1.04888" armature="0.00856561" damping="0.00780207" frictionloss="0.20849"/>
        <geom name="//unnamed_geom_11" class="visual" material="metal" mesh="hip_0"/>
        <geom name="//unnamed_geom_12" class="visual" material="gray" mesh="hip_1"/>
        <geom name="//unnamed_geom_13" class="collision" size="0.0449207 0.0195307" pos="0 0.0833637 0" quat="0.707107 0.707107 0 0" type="cylinder"/>
        <geom name="//unnamed_geom_14" class="reward_collision_sphere" size="0.0585922" pos="0 0.0729433 0"/>
        <body name="FL_thigh" pos="-0.00289497 0.0989575 -0.000968642" quat="1 -0.000700904 9.96241e-05 8.96103e-05">
          <inertial pos="-0.00402935 -0.0233601 -0.026935" quat="0.828407 0.0812566 -0.0161061 0.553968" mass="1.0742" diaginertia="0.0111596 0.00716612 0.000213875"/>
          <joint name="FL_thigh_joint" pos="0 0 0" axis="0.0127478 0.999848 0.0118623" range="-1.55554 3.49202" armature="0.011251" damping="0" frictionloss="0.17658"/>
          <geom name="//unnamed_geom_15" class="visual" material="metal" mesh="thigh_0"/>
          <geom name="//unnamed_geom_16" class="visual" material="gray" mesh="thigh_1"/>
          <geom name="//unnamed_geom_17" class="collision" size="0.104001 0.0119626 0.0166011" pos="0 0 -0.0803889" quat="0.707107 0 0.707107 0" type="box"/>
          <body name="FL_calf" pos="-0.000622651 -0.00256058 -0.160012" quat="0.999999 0.000242119 0.000507676 -0.00114746">
            <inertial pos="0.00859191 0.000390349 -0.106331" quat="0.712763 0.0129806 -0.0102291 0.70121" mass="0.236668" diaginertia="0.00275506 0.00184265 1.28926e-05"/>
            <joint name="FL_calf_joint" pos="0 0 0" axis="-0.00367129 0.999992 0.00161308" stiffness="0.0016221" range="-2.73181 -0.81831" armature="0.00999003" damping="0" frictionloss="0.189252"/>
            <geom name="//unnamed_geom_18" class="visual" material="gray" mesh="calf_0"/>
            <geom name="//unnamed_geom_19" class="visual" material="black" mesh="calf_1"/>
            <geom name="FL_calf0" class="collision" size="0.0117184 0.0585922" pos="0.00906189 0 -0.0452895" quat="0.994493 0 -0.104807 0" type="cylinder"/>
            <geom name="//unnamed_geom_21" class="collision" size="0.0107419 0.0317374" pos="0.0226547 0 -0.111714" quat="0.999688 0 0.0249974 0" type="cylinder"/>
            <geom name="//unnamed_geom_22" class="visual" pos="0 0 -0.160778" quat="1 0 0 0" material="black" mesh="foot"/>
            <geom name="FL_foot" class="foot" size="0.020763" pos="-0.00226547 0 -0.160778"/>
            <geom name="//unnamed_geom_24" class="reward_collision_sphere" size="0.0244134"/>
            <geom name="//unnamed_geom_25" class="reward_collision_sphere" size="0.0244134" pos="-0.00226547 0 -0.160778"/>
            <site name="FL_foot" class="foot" pos="-0.00226547 0 -0.160778" size="0.00976536"/>
          </body>
        </body>
      </body>
      <body name="FR_hip" pos="0.217054 -0.0460297 -0.0019768" quat="1 0.000314737 -0.000106325 -3.01559e-05">
        <inertial pos="-0.00367245 -0.00233892 -0.00226738" quat="0.496119 0.508244 0.491708 0.503763" mass="0.643225" diaginertia="0.00170209 0.000733394 0.000121398"/>
        <joint name="FR_hip_joint" pos="0 0 0" axis="0.999916 0.0122905 -0.00423282" range="-1.10261 1.03394" armature="0.00954821" damping="0.0191317" frictionloss="0.167963"/>
        <geom name="//unnamed_geom_26" class="visual" pos="0 2.50215e-09 1.07322e-07" quat="4.63268e-05 1 0 0" material="metal" mesh="hip_0"/>
        <geom name="//unnamed_geom_27" class="visual" pos="0 4.05628e-09 -2.65449e-07" quat="4.63268e-05 1 0 0" material="gray" mesh="hip_1"/>
        <geom name="//unnamed_geom_28" class="collision" size="0.0449207 0.0195307" pos="0 -0.0833637 0" quat="0.707107 0.707107 0 0" type="cylinder"/>
        <geom name="//unnamed_geom_29" class="reward_collision_sphere" size="0.0585922" pos="0 -0.0729433 0"/>
        <body name="FR_thigh" pos="0.000216572 -0.0980653 0.00272602" quat="1 2.53143e-05 -3.88492e-05 9.25086e-06">
          <inertial pos="-0.00532506 0.0253811 -0.0250273" quat="0.551723 -0.0194416 0.0849769 0.82946" mass="1.07196" diaginertia="0.0112002 0.00707659 0.000215596"/>
          <joint name="FR_thigh_joint" pos="0 0 0" axis="-0.0105577 -0.999936 -0.00405691" stiffness="0.000392934" range="-3.47402 1.59714" armature="0.0100434" damping="0.00532587" frictionloss="0.185311"/>
          <geom name="//unnamed_geom_30" class="visual" material="metal" mesh="thigh_mirror_0"/>
          <geom name="//unnamed_geom_31" class="visual" material="gray" mesh="thigh_mirror_1"/>
          <geom name="//unnamed_geom_32" class="collision" size="0.104001 0.0119626 0.0166011" pos="0 0 -0.0803889" quat="0.707107 0 0.707107 0" type="box"/>
          <body name="FR_calf" pos="-0.000288137 0.000712474 -0.157604" quat="0.999999 -0.000808278 0.000821794 0.000181479">
            <inertial pos="0.00906199 -0.0015037 -0.104171" quat="0.704079 -0.00901869 -0.00119121 0.710063" mass="0.219734" diaginertia="0.00286809 0.00188563 1.35852e-05"/>
            <joint name="FR_calf_joint" pos="0 0 0" axis="-0.00411372 -0.999931 -0.0109949" stiffness="0.010269" range="0.785122 2.72315" armature="0.00926099" damping="0.0217724" frictionloss="0.222661"/>
            <geom name="//unnamed_geom_33" class="visual" material="gray" mesh="calf_mirror_0"/>
            <geom name="//unnamed_geom_34" class="visual" material="black" mesh="calf_mirror_1"/>
            <geom name="FR_calf0" class="collision" size="0.012695 0.0585922" pos="0.0113274 0 -0.0452895" quat="0.995004 0 -0.0998334 0" type="cylinder"/>
            <geom name="//unnamed_geom_36" class="collision" size="0.0107419 0.0317374" pos="0.0226547 0 -0.111714" quat="0.999688 0 0.0249974 0" type="cylinder"/>
            <geom name="//unnamed_geom_37" class="visual" pos="0 0 -0.160778" quat="1 0 0 0" material="black" mesh="foot"/>
            <geom name="FR_foot" class="foot" size="0.0213188" pos="-0.00226547 0 -0.160778"/>
            <geom name="//unnamed_geom_39" class="reward_collision_sphere" size="0.0244134"/>
            <geom name="//unnamed_geom_40" class="reward_collision_sphere" size="0.0244134" pos="-0.00226547 0 -0.160778"/>
            <site name="FR_foot" class="foot" pos="-0.00226547 0 -0.160778" size="0.00976536"/>
          </body>
        </body>
      </body>
      <body name="RL_hip" pos="-0.217495 0.0456424 0.000345094" quat="1 2.77398e-05 -0.000142399 -0.000404995">
        <inertial pos="0.00870695 -2.07454e-05 0.000191462" quat="0.513514 0.492573 0.488771 0.504755" mass="0.621745" diaginertia="0.00166322 0.000731703 0.000113608"/>
        <joint name="RL_hip_joint" pos="0 0 0" axis="-0.999978 0.000639747 0.00656311" range="-0.998117 1.05064" armature="0.0098398" damping="0.0167673" frictionloss="0.194659"/>
        <geom name="//unnamed_geom_41" class="visual" pos="-3.2922e-09 0 -6.45348e-07" quat="4.63268e-05 0 1 0" material="metal" mesh="hip_0"/>
        <geom name="//unnamed_geom_42" class="visual" pos="-5.33706e-09 0 -5.72332e-07" quat="4.63268e-05 0 1 0" material="gray" mesh="hip_1"/>
        <geom name="//unnamed_geom_43" class="collision" size="0.0449207 0.0195307" pos="0 0.0833637 0" quat="0.707107 0.707107 0 0" type="cylinder"/>
        <geom name="//unnamed_geom_44" class="reward_collision_sphere" size="0.0585922" pos="0 0.0729433 0"/>
        <body name="RL_thigh" pos="0.00201473 0.100202 -0.00069984" quat="1 -0.000204241 6.53104e-05 1.00472e-05">
          <inertial pos="-0.00506549 -0.020672 -0.0246219" quat="0.829193 0.0719808 -0.0243268 0.553774" mass="1.09419" diaginertia="0.0111067 0.00740339 0.000216148"/>
          <joint name="RL_thigh_joint" pos="0 0 0" axis="-0.00382498 0.999946 -0.00966776" range="-0.474358 4.58076" armature="0.0110734" damping="0.00304064" frictionloss="0.222713"/>
          <geom name="//unnamed_geom_45" class="visual" material="metal" mesh="thigh_0"/>
          <geom name="//unnamed_geom_46" class="visual" material="gray" mesh="thigh_1"/>
          <geom name="//unnamed_geom_47" class="collision" size="0.104001 0.0119626 0.0166011" pos="0 0 -0.0803889" quat="0.707107 0 0.707107 0" type="box"/>
          <body name="RL_calf" pos="-0.00244789 0.00243027 -0.163386" quat="0.999999 -0.000520119 -0.00052769 0.000739328">
            <inertial pos="0.00663073 -0.000489165 -0.104783" quat="0.716553 0.00162118 -0.0064144 0.697501" mass="0.217419" diaginertia="0.00276432 0.00177682 1.31216e-05"/>
            <joint name="RL_calf_joint" pos="0 0 0" axis="-0.0028796 0.999856 0.0167231" range="-2.73992 -0.88196" armature="0.00932235" damping="0.00783243" frictionloss="0.168607"/>
            <geom name="//unnamed_geom_48" class="visual" material="gray" mesh="calf_0"/>
            <geom name="//unnamed_geom_49" class="visual" material="black" mesh="calf_1"/>
            <geom name="RL_calf0" class="collision" size="0.012695 0.0585922" pos="0.0113274 0 -0.0452895" quat="0.995004 0 -0.0998334 0" type="cylinder"/>
            <geom name="//unnamed_geom_51" class="collision" size="0.0107419 0.0317374" pos="0.0226547 0 -0.111714" quat="0.999688 0 0.0249974 0" type="cylinder"/>
            <geom name="//unnamed_geom_52" class="visual" pos="0 0 -0.160778" quat="1 0 0 0" material="black" mesh="foot"/>
            <geom name="RL_foot" class="foot" size="0.0170881" pos="-0.00226547 0 -0.160778"/>
            <geom name="//unnamed_geom_54" class="reward_collision_sphere" size="0.0244134"/>
            <geom name="//unnamed_geom_55" class="reward_collision_sphere" size="0.0244134" pos="-0.00226547 0 -0.160778"/>
            <site name="RL_foot" class="foot" pos="-0.00226547 0 -0.160778" size="0.00976536"/>
          </body>
        </body>
      </body>
      <body name="RR_hip" pos="-0.221053 -0.0496943 -0.000618108" quat="1 1.7882e-05 -7.91803e-05 2.34479e-05">
        <inertial pos="0.00863389 -0.000432656 0.000527619" quat="0.506575 0.50175 0.494539 0.497051" mass="0.640837" diaginertia="0.00171092 0.000763819 0.000122458"/>
        <joint name="RR_hip_joint" pos="0 0 0" axis="-0.999927 0.011441 0.00383386" range="-1.04662 1.04335" armature="0.00965319" damping="0.0107875" frictionloss="0.200451"/>
        <geom name="//unnamed_geom_56" class="visual" pos="3.28906e-09 2.50215e-09 -7.5267e-07" quat="2.14617e-09 4.63268e-05 4.63268e-05 -1" material="metal" mesh="hip_0"/>
        <geom name="//unnamed_geom_57" class="visual" pos="5.34482e-09 4.05628e-09 -3.06882e-07" quat="2.14617e-09 4.63268e-05 4.63268e-05 -1" material="gray" mesh="hip_1"/>
        <geom name="//unnamed_geom_58" class="collision" size="0.0449207 0.0195307" pos="0 -0.0833637 0" quat="0.707107 0.707107 0 0" type="cylinder"/>
        <geom name="//unnamed_geom_59" class="reward_collision_sphere" size="0.0585922" pos="0 -0.0729433 0"/>
        <body name="RR_thigh" pos="0.000250161 -0.0998172 0.00143378" quat="1 -0.000280602 0.000352619 -9.94619e-05">
          <inertial pos="-0.00495281 0.0235517 -0.0250632" quat="0.553985 -0.0131184 0.0925428 0.827263" mass="1.08931" diaginertia="0.0111177 0.00746906 0.000222298"/>
          <joint name="RR_thigh_joint" pos="0 0 0" axis="0.00962902 -0.999954 -0.0001775" range="-4.53757 0.5282" armature="0.0109958" damping="0.00161208" frictionloss="0.181444"/>
          <geom name="//unnamed_geom_60" class="visual" material="metal" mesh="thigh_mirror_0"/>
          <geom name="//unnamed_geom_61" class="visual" material="gray" mesh="thigh_mirror_1"/>
          <geom name="//unnamed_geom_62" class="collision" size="0.104001 0.0119626 0.0166011" pos="0 0 -0.0803889" quat="0.707107 0 0.707107 0" type="box"/>
          <body name="RR_calf" pos="0.000580675 0.000473362 -0.160533" quat="1 -0.000179407 4.54707e-05 -0.000258253">
            <inertial pos="0.00424822 -0.00168637 -0.104334" quat="0.703528 -0.00462789 0.00185525 0.71065" mass="0.234519" diaginertia="0.00271688 0.00187621 1.30747e-05"/>
            <joint name="RR_calf_joint" pos="0 0 0" axis="0.000709686 -0.999999 -0.00116826" stiffness="0.000582868" range="0.83337 2.77631" armature="0.00983315" damping="0.0101269" frictionloss="0.220112"/>
            <geom name="//unnamed_geom_63" class="visual" material="gray" mesh="calf_mirror_0"/>
            <geom name="//unnamed_geom_64" class="visual" material="black" mesh="calf_mirror_1"/>
            <geom name="RR_calf0" class="collision" size="0.012695 0.0585922" pos="0.0113274 0 -0.0452895" quat="0.995004 0 -0.0998334 0" type="cylinder"/>
            <geom name="//unnamed_geom_66" class="collision" size="0.0107419 0.0317374" pos="0.0226547 0 -0.111714" quat="0.999688 0 0.0249974 0" type="cylinder"/>
            <geom name="//unnamed_geom_67" class="visual" pos="0 0 -0.160778" quat="1 0 0 0" material="black" mesh="foot"/>
            <geom name="RR_foot" class="foot" size="0.0230231" pos="-0.00226547 0 -0.160778"/>
            <geom name="//unnamed_geom_69" class="reward_collision_sphere" size="0.0244134"/>
            <geom name="//unnamed_geom_70" class="reward_collision_sphere" size="0.0244134" pos="-0.00226547 0 -0.160778"/>
            <site name="RR_foot" class="foot" pos="-0.00226547 0 -0.160778" size="0.00976536"/>
          </body>
        </body>
      </body>
    </body>
  </worldbody>

  <contact>
    <pair class="/" geom1="floor" geom2="FL_foot" name="//unnamed_contact_0"/>
    <pair class="/" geom1="floor" geom2="FR_foot" name="//unnamed_contact_1"/>
    <pair class="/" geom1="floor" geom2="RL_foot" name="//unnamed_contact_2"/>
    <pair class="/" geom1="floor" geom2="RR_foot" name="//unnamed_contact_3"/>
  </contact>

  <actuator>
    <general name="FL_hip" class="/" joint="FL_hip_joint" forcerange="-23.2687 23.2687" gainprm="19.4774" biasprm="0 -19.4774 -0.482867"/>
    <general name="FL_thigh" class="/" joint="FL_thigh_joint" forcerange="-20.7471 20.7471" gainprm="19.4774" biasprm="0 -19.4774 -0.482867"/>
    <general name="FL_calf" class="/" joint="FL_calf_joint" forcerange="-46.4758 46.4758" gainprm="19.4774" biasprm="0 -19.4774 -0.482867"/>
    <general name="FR_hip" class="/" joint="FR_hip_joint" forcerange="-23.1875 23.1875" gainprm="19.4774" biasprm="0 -19.4774 -0.482867"/>
    <general name="FR_thigh" class="/" joint="FR_thigh_joint" forcerange="-22.4365 22.4365" gainprm="19.4774" biasprm="0 -19.4774 -0.482867"/>
    <general name="FR_calf" class="/" joint="FR_calf_joint" forcerange="-47.9816 47.9816" gainprm="19.4774" biasprm="0 -19.4774 -0.482867"/>
    <general name="RL_hip" class="/" joint="RL_hip_joint" forcerange="-23.1172 23.1172" gainprm="19.4774" biasprm="0 -19.4774 -0.482867"/>
    <general name="RL_thigh" class="/" joint="RL_thigh_joint" forcerange="-25.1365 25.1365" gainprm="19.4774" biasprm="0 -19.4774 -0.482867"/>
    <general name="RL_calf" class="/" joint="RL_calf_joint" forcerange="-41.9876 41.9876" gainprm="19.4774" biasprm="0 -19.4774 -0.482867"/>
    <general name="RR_hip" class="/" joint="RR_hip_joint" forcerange="-23.1803 23.1803" gainprm="19.4774" biasprm="0 -19.4774 -0.482867"/>
    <general name="RR_thigh" class="/" joint="RR_thigh_joint" forcerange="-22.8262 22.8262" gainprm="19.4774" biasprm="0 -19.4774 -0.482867"/>
    <general name="RR_calf" class="/" joint="RR_calf_joint" forcerange="-40.8492 40.8492" gainprm="19.4774" biasprm="0 -19.4774 -0.482867"/>
  </actuator>

  <sensor>
    <gyro site="imu" name="imu_angular_velocity"/>
    <velocimeter site="imu" name="imu_linear_velocity"/>
    <framelinvel objtype="site" objname="FL_foot" name="FL_foot_global_linear_velocity"/>
    <framelinvel objtype="site" objname="FR_foot" name="FR_foot_global_linear_velocity"/>
    <framelinvel objtype="site" objname="RL_foot" name="RL_foot_global_linear_velocity"/>
    <framelinvel objtype="site" objname="RR_foot" name="RR_foot_global_linear_velocity"/>
  </sensor>

  <keyframe>
    <key name="home" qpos="0 0 0.325 1 0 0 0 0.1 0.8 -1.5 -0.1 -0.8 1.5 -0.1 0.8 -1.5 0.1 -0.8 1.5"/>
  </keyframe>
</mujoco>
