<mujoco model="go2">
  <compiler angle="radian" assetdir="assets" balanceinertia="true" inertiafromgeom="false"/>

  <option timestep="0.005" density="1.2" viscosity="2e-05"/>

  <size nkey="1"/>

  <visual>
    <quality shadowsize="8192"/>
    <map shadowclip="0.5"/>
  </visual>

  <default>
    <default class="/">
      <geom contype="0" conaffinity="0" group="1" solref="-1000 -80"/>
      <site size="0.01 0.005 0.005" group="5"/>
      <general forcelimited="true" biastype="affine" gainprm="20" biasprm="0 -20 -0.5"/>
      <default class="go2">
        <joint armature="0.01" damping="0.01" frictionloss="0.2"/>
        <geom condim="1" margin="0.001"/>
        <default class="visual">
          <geom type="mesh" group="2"/>
        </default>
        <default class="collision">
          <geom group="3"/>
          <default class="foot">
            <geom size="0.022 0 0" condim="6" priority="1" friction="0.8 0.02 0.01" solimp="0.015 1 0.022"/>
          </default>
        </default>
        <default class="reward_collision_sphere">
          <geom group="5" rgba="1 0 0 1"/>
        </default>
      </default>
    </default>
  </default>

  <asset>
    <texture type="skybox" colorspace="auto" name="//unnamed_texture_0" builtin="gradient" rgb1="0.95 0.95 0.95" rgb2="0.95 0.95 0.95" width="100" height="600"/>
    <texture type="2d" colorspace="auto" name="texplane" builtin="checker" rgb1="0.345 0.575 0.748" rgb2="0.345 0.575 0.748" markrgb="1 1 1" width="512" height="512"/>
    <material name="MatPlane" class="/" texture="texplane" texuniform="true" texrepeat="2 2" specular="0.9"/>
    <material name="metal" class="/" rgba="0.9 0.95 0.95 1"/>
    <material name="black" class="/" rgba="0 0 0 1"/>
    <material name="white" class="/"/>
    <material name="gray" class="/" rgba="0.671705 0.692426 0.77427 1"/>
    <mesh name="base_0" class="/" file="base_0.obj"/>
    <mesh name="base_1" class="/" file="base_1.obj"/>
    <mesh name="base_2" class="/" file="base_2.obj"/>
    <mesh name="base_3" class="/" file="base_3.obj"/>
    <mesh name="base_4" class="/" file="base_4.obj"/>
    <mesh name="hip_0" class="/" file="hip_0.obj"/>
    <mesh name="hip_1" class="/" file="hip_1.obj"/>
    <mesh name="thigh_0" class="/" file="thigh_0.obj"/>
    <mesh name="thigh_1" class="/" file="thigh_1.obj"/>
    <mesh name="thigh_mirror_0" class="/" file="thigh_mirror_0.obj"/>
    <mesh name="thigh_mirror_1" class="/" file="thigh_mirror_1.obj"/>
    <mesh name="calf_0" class="/" file="calf_0.obj"/>
    <mesh name="calf_1" class="/" file="calf_1.obj"/>
    <mesh name="calf_mirror_0" class="/" file="calf_mirror_0.obj"/>
    <mesh name="calf_mirror_1" class="/" file="calf_mirror_1.obj"/>
    <mesh name="foot" class="/" file="foot.obj"/>
  </asset>

  <worldbody>
    <geom name="floor" class="/" size="100 100 0.125" type="plane" group="0" material="MatPlane"/>
    <light name="toplight_shadow" class="/" pos="0 0 5" dir="0.0990148 0.0990148 -0.990148" type="directional" ambient="0.04 0.04 0.04" diffuse="0.55 0.55 0.55" specular="0.12 0.12 0.12"/>
    <light name="toplight_fill" class="/" pos="0 0 5" dir="0.0990148 0.0990148 -0.990148" type="directional" castshadow="false" ambient="0.04 0.04 0.04" diffuse="0.3 0.3 0.3" specular="0.08 0.08 0.08"/>
    <body name="trunk" childclass="go2" pos="0.00198551 -0.000996201 -0.000523379" quat="1 0.000296784 -9.57427e-06 0.000183229">
      <inertial pos="0.0229829 -0.00061561 -0.00463979" quat="-0.000403309 0.713268 -0.00353692 0.700883" mass="6.17059" diaginertia="0.176793 0.0849424 0.00981519"/>
      <joint name="//unnamed_joint_0" type="free" armature="0" damping="0" frictionloss="0"/>
      <geom name="//unnamed_geom_1" class="visual" material="black" mesh="base_0"/>
      <geom name="//unnamed_geom_2" class="visual" material="black" mesh="base_1"/>
      <geom name="//unnamed_geom_3" class="visual" material="black" mesh="base_2"/>
      <geom name="//unnamed_geom_4" class="visual" material="white" mesh="base_3"/>
      <geom name="//unnamed_geom_5" class="visual" material="gray" mesh="base_4"/>
      <geom name="trunk_1" class="collision" size="0.1816 0.0451345 0.0550303" type="box"/>
      <geom name="trunk_2" class="collision" size="0.0482722 0.043445" pos="0.312342 0 0.00832584" type="cylinder"/>
      <geom name="trunk_3" class="collision" size="0.0453759" pos="0.321109 0 -0.049955"/>
      <geom name="//unnamed_geom_9" class="reward_collision_sphere" size="0.0965445"/>
      <geom name="//unnamed_geom_10" class="reward_collision_sphere" size="0.0579267" pos="0.306862 0 -0.0374663"/>
      <site name="imu" pos="-0.0324339 -0.00131457 0.0233192" size="0.00965445"/>
      <camera name="track" pos="0 -1.93563 0" quat="0.707107 0.707107 0 0" mode="trackcom"/>
      <camera name="ego_camera" pos="0.341932 0 0.0374663" quat="-0.5 -0.5 0.5 0.5"/>
      <body name="FL_hip" pos="0.212329 0.0456643 0.000508229" quat="1 -0.000459398 0.000585717 3.52124e-05">
        <inertial pos="-0.00799927 0.00297366 0.000117563" quat="0.497013 0.499219 0.505484 0.498241" mass="0.613204" diaginertia="0.00140344 0.000500069 0.000190853"/>
        <joint name="FL_hip_joint" pos="0 0 0" axis="0.999897 0.0135715 -0.00475406" range="-1.06061 1.04967" armature="0.00848796" damping="0.00671382" frictionloss="0.187298"/>
        <geom name="//unnamed_geom_11" class="visual" material="metal" mesh="hip_0"/>
        <geom name="//unnamed_geom_12" class="visual" material="gray" mesh="hip_1"/>
        <geom name="//unnamed_geom_13" class="collision" size="0.0444104 0.0193089" pos="0 0.0774251 0" quat="0.707107 0.707107 0 0" type="cylinder"/>
        <geom name="//unnamed_geom_14" class="reward_collision_sphere" size="0.0579267" pos="0 0.067747 0"/>
        <body name="FL_thigh" pos="-0.000998495 0.0929188 0.000836047" quat="1 0.00023389 -0.000236406 6.92669e-05">
          <inertial pos="-0.00479356 -0.0213737 -0.029522" quat="0.831136 0.0823252 -0.0200701 0.549575" mass="1.05421" diaginertia="0.00951738 0.00502548 0.000356603"/>
          <joint name="FL_thigh_joint" pos="0 0 0" axis="0.00106771 0.999966 -0.00822295" range="-1.58898 3.49127" armature="0.0104737" damping="0.00287735" frictionloss="0.194197"/>
          <geom name="//unnamed_geom_15" class="visual" material="metal" mesh="thigh_0"/>
          <geom name="//unnamed_geom_16" class="visual" material="gray" mesh="thigh_1"/>
          <geom name="//unnamed_geom_17" class="collision" size="0.10282 0.0118267 0.0164126" pos="0 0 -0.0886701" quat="0.707107 0 0.707107 0" type="box"/>
          <body name="FL_calf" pos="-0.000408877 -0.00292524 -0.177435" quat="1 0.000365925 -0.000161224 -2.18286e-05">
            <inertial pos="0.00652357 -0.000167131 -0.117817" quat="0.706498 0.0101495 -0.000341576 0.707642" mass="0.217569" diaginertia="0.0023248 0.00124423 2.08343e-05"/>
            <joint name="FL_calf_joint" pos="0 0 0" axis="-0.0120667 0.999926 -0.00136835" stiffness="0.00275836" range="-2.72065 -0.839272" armature="0.00962886" damping="0.000132799" frictionloss="0.198384"/>
            <geom name="//unnamed_geom_18" class="visual" material="gray" mesh="calf_0"/>
            <geom name="//unnamed_geom_19" class="visual" material="black" mesh="calf_1"/>
            <geom name="FL_calf0" class="collision" size="0.0115853 0.0579267" pos="0.00876749 0 -0.049955" quat="0.994493 0 -0.104807 0" type="cylinder"/>
            <geom name="//unnamed_geom_21" class="collision" size="0.0106199 0.0313769" pos="0.0219187 0 -0.123222" quat="0.999688 0 0.0249974 0" type="cylinder"/>
            <geom name="//unnamed_geom_22" class="visual" pos="0 0 -0.17734" quat="1 0 0 0" material="black" mesh="foot"/>
            <geom name="FL_foot" class="foot" size="0.0188501" pos="-0.00219187 0 -0.17734"/>
            <geom name="//unnamed_geom_24" class="reward_collision_sphere" size="0.0241361"/>
            <geom name="//unnamed_geom_25" class="reward_collision_sphere" size="0.0241361" pos="-0.00219187 0 -0.17734"/>
            <site name="FL_foot" class="foot" pos="-0.00219187 0 -0.17734" size="0.00965445"/>
          </body>
        </body>
      </body>
      <body name="FR_hip" pos="0.210205 -0.042183 -0.00156523" quat="1 4.60171e-05 -2.27575e-05 -6.64874e-05">
        <inertial pos="-0.00328837 -0.00275263 -0.00261351" quat="0.498779 0.505321 0.498926 0.496934" mass="0.629414" diaginertia="0.00143058 0.000517967 0.000197313"/>
        <joint name="FR_hip_joint" pos="0 0 0" axis="0.99997 -0.00327973 0.00705478" stiffness="0.0026075" range="-1.09417 1.06018" armature="0.00971803" damping="0.0148184" frictionloss="0.177492"/>
        <geom name="//unnamed_geom_26" class="visual" pos="0 1.17807e-09 5.05298e-08" quat="4.63268e-05 1 0 0" material="metal" mesh="hip_0"/>
        <geom name="//unnamed_geom_27" class="visual" pos="0 1.90979e-09 -1.2498e-07" quat="4.63268e-05 1 0 0" material="gray" mesh="hip_1"/>
        <geom name="//unnamed_geom_28" class="collision" size="0.0444104 0.0193089" pos="0 -0.0774251 0" quat="0.707107 0.707107 0 0" type="cylinder"/>
        <geom name="//unnamed_geom_29" class="reward_collision_sphere" size="0.0579267" pos="0 -0.067747 0"/>
        <body name="FR_thigh" pos="0.00070438 -0.0928554 0.000458879" quat="1 7.65177e-06 5.51587e-06 5.1374e-07">
          <inertial pos="-0.00307695 0.0242832 -0.0280449" quat="0.551631 -0.0200079 0.084764 0.829529" mass="1.02279" diaginertia="0.00936463 0.00489766 0.00034684"/>
          <joint name="FR_thigh_joint" pos="0 0 0" axis="-0.00137764 -0.999999 0.000962995" range="-3.49949 1.55697" armature="0.0101331" damping="0.00944081" frictionloss="0.190303"/>
          <geom name="//unnamed_geom_30" class="visual" material="metal" mesh="thigh_mirror_0"/>
          <geom name="//unnamed_geom_31" class="visual" material="gray" mesh="thigh_mirror_1"/>
          <geom name="//unnamed_geom_32" class="collision" size="0.10282 0.0118267 0.0164126" pos="0 0 -0.0886701" quat="0.707107 0 0.707107 0" type="box"/>
          <body name="FR_calf" pos="-0.000331143 -0.000779734 -0.175557" quat="0.999999 0.00111935 -2.53021e-06 -0.000450423">
            <inertial pos="0.00947117 0.000419113 -0.11645" quat="0.70345 -0.00391081 0.001021 0.710733" mass="0.212406" diaginertia="0.00233777 0.00126843 2.18787e-05"/>
            <joint name="FR_calf_joint" pos="0 0 0" axis="0.00263044 -0.999991 -0.00339307" stiffness="0.00437228" range="0.789057 2.71386" armature="0.00979673" damping="0.0195411" frictionloss="0.211518"/>
            <geom name="//unnamed_geom_33" class="visual" material="gray" mesh="calf_mirror_0"/>
            <geom name="//unnamed_geom_34" class="visual" material="black" mesh="calf_mirror_1"/>
            <geom name="FR_calf0" class="collision" size="0.0125508 0.0579267" pos="0.0109594 0 -0.049955" quat="0.995004 0 -0.0998334 0" type="cylinder"/>
            <geom name="//unnamed_geom_36" class="collision" size="0.0106199 0.0313769" pos="0.0219187 0 -0.123222" quat="0.999688 0 0.0249974 0" type="cylinder"/>
            <geom name="//unnamed_geom_37" class="visual" pos="0 0 -0.17734" quat="1 0 0 0" material="black" mesh="foot"/>
            <geom name="FR_foot" class="foot" size="0.0218128" pos="-0.00219187 0 -0.17734"/>
            <geom name="//unnamed_geom_39" class="reward_collision_sphere" size="0.0241361"/>
            <geom name="//unnamed_geom_40" class="reward_collision_sphere" size="0.0241361" pos="-0.00219187 0 -0.17734"/>
            <site name="FR_foot" class="foot" pos="-0.00219187 0 -0.17734" size="0.00965445"/>
          </body>
        </body>
      </body>
      <body name="RL_hip" pos="-0.209646 0.0439015 0.00118319" quat="1 -3.6058e-05 -4.00561e-05 1.37906e-05">
        <inertial pos="0.00818348 -0.000354892 -0.000295858" quat="0.505811 0.505485 0.494205 0.494371" mass="0.614873" diaginertia="0.00141222 0.000506134 0.000187791"/>
        <joint name="RL_hip_joint" pos="0 0 0" axis="-0.999947 0.00947417 -0.00410955" stiffness="0.000787473" range="-1.0351 1.02422" armature="0.00969949" damping="0.00735118" frictionloss="0.203203"/>
        <geom name="//unnamed_geom_41" class="visual" pos="-2.29422e-09 0 -4.4972e-07" quat="4.63268e-05 0 1 0" material="metal" mesh="hip_0"/>
        <geom name="//unnamed_geom_42" class="visual" pos="-3.71921e-09 0 -3.98838e-07" quat="4.63268e-05 0 1 0" material="gray" mesh="hip_1"/>
        <geom name="//unnamed_geom_43" class="collision" size="0.0444104 0.0193089" pos="0 0.0774251 0" quat="0.707107 0.707107 0 0" type="cylinder"/>
        <geom name="//unnamed_geom_44" class="reward_collision_sphere" size="0.0579267" pos="0 0.067747 0"/>
        <body name="RL_thigh" pos="-2.07121e-05 0.0915699 0.000461892" quat="1 -0.000426356 -0.000192346 0.000151882">
          <inertial pos="-0.00447471 -0.0190423 -0.0268076" quat="0.831671 0.0873947 -0.0164946 0.548099" mass="1.04168" diaginertia="0.00944167 0.00504174 0.000344214"/>
          <joint name="RL_thigh_joint" pos="0 0 0" axis="-0.00341151 0.999969 -0.00709528" range="-0.511758 4.53729" armature="0.0107547" damping="0.00264823" frictionloss="0.209322"/>
          <geom name="//unnamed_geom_45" class="visual" material="metal" mesh="thigh_0"/>
          <geom name="//unnamed_geom_46" class="visual" material="gray" mesh="thigh_1"/>
          <geom name="//unnamed_geom_47" class="collision" size="0.10282 0.0118267 0.0164126" pos="0 0 -0.0886701" quat="0.707107 0 0.707107 0" type="box"/>
          <body name="RL_calf" pos="-0.000600881 0.00134465 -0.179822" quat="0.999999 -0.000212256 0.000697223 0.000926847">
            <inertial pos="0.00749574 -0.000335639 -0.115113" quat="0.711176 0.000171321 -0.00435567 0.703001" mass="0.211064" diaginertia="0.0023556 0.00125261 2.1191e-05"/>
            <joint name="RL_calf_joint" pos="0 0 0" axis="0.00207376 0.999997 0.00137689" stiffness="0.000604183" range="-2.73356 -0.844965" armature="0.00934936" damping="0.00867837" frictionloss="0.180975"/>
            <geom name="//unnamed_geom_48" class="visual" material="gray" mesh="calf_0"/>
            <geom name="//unnamed_geom_49" class="visual" material="black" mesh="calf_1"/>
            <geom name="RL_calf0" class="collision" size="0.0125508 0.0579267" pos="0.0109594 0 -0.049955" quat="0.995004 0 -0.0998334 0" type="cylinder"/>
            <geom name="//unnamed_geom_51" class="collision" size="0.0106199 0.0313769" pos="0.0219187 0 -0.123222" quat="0.999688 0 0.0249974 0" type="cylinder"/>
            <geom name="//unnamed_geom_52" class="visual" pos="0 0 -0.17734" quat="1 0 0 0" material="black" mesh="foot"/>
            <geom name="RL_foot" class="foot" size="0.0176315" pos="-0.00219187 0 -0.17734"/>
            <geom name="//unnamed_geom_54" class="reward_collision_sphere" size="0.0241361"/>
            <geom name="//unnamed_geom_55" class="reward_collision_sphere" size="0.0241361" pos="-0.00219187 0 -0.17734"/>
            <site name="RL_foot" class="foot" pos="-0.00219187 0 -0.17734" size="0.00965445"/>
          </body>
        </body>
      </body>
      <body name="RR_hip" pos="-0.214151 -0.0465099 -0.000245748" quat="1 0.000107845 0.000182033 -0.000444751">
        <inertial pos="0.0065587 -0.00221803 -0.00031264" quat="0.489418 0.500087 0.503768 0.506558" mass="0.61189" diaginertia="0.00139879 0.000509763 0.000192938"/>
        <joint name="RR_hip_joint" pos="0 0 0" axis="-0.999917 0.00260594 0.0126099" stiffness="0.00383479" range="-1.04735 1.02722" armature="0.0100554" damping="0.000850601" frictionloss="0.190359"/>
        <geom name="//unnamed_geom_56" class="visual" pos="2.28979e-09 1.17807e-09 -5.0025e-07" quat="2.14617e-09 4.63268e-05 4.63268e-05 -1" material="metal" mesh="hip_0"/>
        <geom name="//unnamed_geom_57" class="visual" pos="3.73018e-09 1.90979e-09 -2.73858e-07" quat="2.14617e-09 4.63268e-05 4.63268e-05 -1" material="gray" mesh="hip_1"/>
        <geom name="//unnamed_geom_58" class="collision" size="0.0444104 0.0193089" pos="0 -0.0774251 0" quat="0.707107 0.707107 0 0" type="cylinder"/>
        <geom name="//unnamed_geom_59" class="reward_collision_sphere" size="0.0579267" pos="0 -0.067747 0"/>
        <body name="RR_thigh" pos="0.000411293 -0.0918607 0.000707144" quat="1 0.000231276 -6.74473e-05 0.000110202">
          <inertial pos="-0.00452578 0.0212154 -0.0282002" quat="0.549161 -0.0252181 0.096017 0.829799" mass="1.04154" diaginertia="0.00934391 0.00503695 0.000361213"/>
          <joint name="RR_thigh_joint" pos="0 0 0" axis="0.00136589 -0.999999 4.69687e-05" range="-4.53955 0.504052" armature="0.0103697" damping="0.00834663" frictionloss="0.198417"/>
          <geom name="//unnamed_geom_60" class="visual" material="metal" mesh="thigh_mirror_0"/>
          <geom name="//unnamed_geom_61" class="visual" material="gray" mesh="thigh_mirror_1"/>
          <geom name="//unnamed_geom_62" class="collision" size="0.10282 0.0118267 0.0164126" pos="0 0 -0.0886701" quat="0.707107 0 0.707107 0" type="box"/>
          <body name="RR_calf" pos="0.000552812 -0.00144122 -0.177976" quat="1 -6.43561e-05 -2.19082e-05 -0.000118709">
            <inertial pos="0.00482452 -0.00179951 -0.115615" quat="0.702213 -0.00334663 0.00101625 0.711959" mass="0.220248" diaginertia="0.00232517 0.00126213 2.11711e-05"/>
            <joint name="RR_calf_joint" pos="0 0 0" axis="0.00535086 -0.999973 0.00499594" stiffness="0.00192528" range="0.859293 2.7716" armature="0.00957673" damping="0.0104358" frictionloss="0.215657"/>
            <geom name="//unnamed_geom_63" class="visual" material="gray" mesh="calf_mirror_0"/>
            <geom name="//unnamed_geom_64" class="visual" material="black" mesh="calf_mirror_1"/>
            <geom name="RR_calf0" class="collision" size="0.0125508 0.0579267" pos="0.0109594 0 -0.049955" quat="0.995004 0 -0.0998334 0" type="cylinder"/>
            <geom name="//unnamed_geom_66" class="collision" size="0.0106199 0.0313769" pos="0.0219187 0 -0.123222" quat="0.999688 0 0.0249974 0" type="cylinder"/>
            <geom name="//unnamed_geom_67" class="visual" pos="0 0 -0.17734" quat="1 0 0 0" material="black" mesh="foot"/>
            <geom name="RR_foot" class="foot" size="0.0229656" pos="-0.00219187 0 -0.17734"/>
            <geom name="//unnamed_geom_69" class="reward_collision_sphere" size="0.0241361"/>
            <geom name="//unnamed_geom_70" class="reward_collision_sphere" size="0.0241361" pos="-0.00219187 0 -0.17734"/>
            <site name="RR_foot" class="foot" pos="-0.00219187 0 -0.17734" size="0.00965445"/>
          </body>
        </body>
      </body>
    </body>
  </worldbody>

  <contact>
    <pair class="/" geom1="floor" geom2="FL_foot" name="//unnamed_contact_0"/>
    <pair class="/" geom1="floor" geom2="FR_foot" name="//unnamed_contact_1"/>
    <pair class="/" geom1="floor" geom2="RL_foot" name="//unnamed_contact_2"/>
    <pair class="/" geom1="floor" geom2="RR_foot" name="//unnamed_contact_3"/>
  </contact>

  <actuator>
    <general name="FL_hip" class="/" joint="FL_hip_joint" forcerange="-22.9039 22.9039" gainprm="19.4921" biasprm="0 -19.4921 -0.472078"/>
    <general name="FL_thigh" class="/" joint="FL_thigh_joint" forcerange="-21.4878 21.4878" gainprm="19.4921" biasprm="0 -19.4921 -0.472078"/>
    <general name="FL_calf" class="/" joint="FL_calf_joint" forcerange="-42.8148 42.8148" gainprm="19.4921" biasprm="0 -19.4921 -0.472078"/>
    <general name="FR_hip" class="/" joint="FR_hip_joint" forcerange="-22.88 22.88" gainprm="19.4921" biasprm="0 -19.4921 -0.472078"/>
    <general name="FR_thigh" class="/" joint="FR_thigh_joint" forcerange="-23.2497 23.2497" gainprm="19.4921" biasprm="0 -19.4921 -0.472078"/>
    <general name="FR_calf" class="/" joint="FR_calf_joint" forcerange="-44.6065 44.6065" gainprm="19.4921" biasprm="0 -19.4921 -0.472078"/>
    <general name="RL_hip" class="/" joint="RL_hip_joint" forcerange="-23.0093 23.0093" gainprm="19.4921" biasprm="0 -19.4921 -0.472078"/>
    <general name="RL_thigh" class="/" joint="RL_thigh_joint" forcerange="-23.2091 23.2091" gainprm="19.4921" biasprm="0 -19.4921 -0.472078"/>
    <general name="RL_calf" class="/" joint="RL_calf_joint" forcerange="-44.8389 44.8389" gainprm="19.4921" biasprm="0 -19.4921 -0.472078"/>
    <general name="RR_hip" class="/" joint="RR_hip_joint" forcerange="-22.5177 22.5177" gainprm="19.4921" biasprm="0 -19.4921 -0.472078"/>
    <general name="RR_thigh" class="/" joint="RR_thigh_joint" forcerange="-21.9931 21.9931" gainprm="19.4921" biasprm="0 -19.4921 -0.472078"/>
    <general name="RR_calf" class="/" joint="RR_calf_joint" forcerange="-39.8673 39.8673" gainprm="19.4921" biasprm="0 -19.4921 -0.472078"/>
  </actuator>

  <sensor>
    <gyro site="imu" name="imu_angular_velocity"/>
    <velocimeter site="imu" name="imu_linear_velocity"/>
    <framelinvel objtype="site" objname="FL_foot" name="FL_foot_global_linear_velocity"/>
    <framelinvel objtype="site" objname="FR_foot" name="FR_foot_global_linear_velocity"/>
    <framelinvel objtype="site" objname="RL_foot" name="RL_foot_global_linear_velocity"/>
    <framelinvel objtype="site" objname="RR_foot" name="RR_foot_global_linear_velocity"/>
  </sensor>

  <keyframe>
    <key name="home" qpos="0 0 0.325 1 0 0 0 0.1 0.8 -1.5 -0.1 -0.8 1.5 -0.1 0.8 -1.5 0.1 -0.8 1.5"/>
  </keyframe>
</mujoco>
