<mujoco model="go2">
  <compiler angle="radian" assetdir="assets" balanceinertia="true" inertiafromgeom="false"/>

  <option timestep="0.005" density="1.2" viscosity="2e-05"/>

  <size nkey="1"/>

  <visual>
    <quality shadowsize="8192"/>
    <map shadowclip="0.5"/>
  </visual>

  <default>
    <default class="/">
      <geom contype="0" conaffinity="0" group="1" solref="-1000 -80"/>
      <site size="0.01 0.005 0.005" group="5"/>
      <general forcelimited="true" biastype="affine" gainprm="20" biasprm="0 -20 -0.5"/>
      <default class="go2">
        <joint armature="0.01" damping="0.01" frictionloss="0.2"/>
        <geom condim="1" margin="0.001"/>
        <default class="visual">
          <geom type="mesh" group="2"/>
        </default>
        <default class="collision">
          <geom group="3"/>
          <default class="foot">
            <geom size="0.022 0 0" condim="6" priority="1" friction="0.8 0.02 0.01" solimp="0.015 1 0.022"/>
          </default>
        </default>
        <default class="reward_collision_sphere">
          <geom group="5" rgba="1 0 0 1"/>
        </default>
      </default>
    </default>
  </default>

  <asset>
    <texture type="skybox" colorspace="auto" name="//unnamed_texture_0" builtin="gradient" rgb1="0.95 0.95 0.95" rgb2="0.95 0.95 0.95" width="100" height="600"/>
    <texture type="2d" colorspace="auto" name="texplane" builtin="checker" rgb1="0.345 0.575 0.748" rgb2="0.345 0.575 0.748" markrgb="1 1 1" width="512" height="512"/>
    <material name="MatPlane" class="/" texture="texplane" texuniform="true" texrepeat="2 2" specular="0.9"/>
    <material name="metal" class="/" rgba="0.9 0.95 0.95 1"/>
    <material name="black" class="/" rgba="0 0 0 1"/>
    <material name="white" class="/"/>
    <material name="gray" class="/" rgba="0.671705 0.692426 0.77427 1"/>
    <mesh name="base_0" class="/" file="base_0.obj"/>
    <mesh name="base_1" class="/" file="base_1.obj"/>
    <mesh name="base_2" class="/" file="base_2.obj"/>
    <mesh name="base_3" class="/" file="base_3.obj"/>
    <mesh name="base_4" class="/" file="base_4.obj"/>
    <mesh name="hip_0" class="/" file="hip_0.obj"/>
    <mesh name="hip_1" class="/" file="hip_1.obj"/>
    <mesh name="thigh_0" class="/" file="thigh_0.obj"/>
    <mesh name="thigh_1" class="/" file="thigh_1.obj"/>
    <mesh name="thigh_mirror_0" class="/" file="thigh_mirror_0.obj"/>
    <mesh name="thigh_mirror_1" class="/" file="thigh_mirror_1.obj"/>
    <mesh name="calf_0" class="/" file="calf_0.obj"/>
    <mesh name="calf_1" class="/" file="calf_1.obj"/>
    <mesh name="calf_mirror_0" class="/" file="calf_mirror_0.obj"/>
    <mesh name="calf_mirror_1" class="/" file="calf_mirror_1.obj"/>
    <mesh name="foot" class="/" file="foot.obj"/>
  </asset>

  <worldbody>
    <geom name="floor" class="/" size="100 100 0.125" type="plane" group="0" material="MatPlane"/>
    <light name="toplight_shadow" class="/" pos="0 0 5" dir="0.0990148 0.0990148 -0.990148" type="directional" ambient="0.04 0.04 0.04" diffuse="0.55 0.55 0.55" specular="0.12 0.12 0.12"/>
    <light name="toplight_fill" class="/" pos="0 0 5" dir="0.0990148 0.0990148 -0.990148" type="directional" castshadow="false" ambient="0.04 0.04 0.04" diffuse="0.3 0.3 0.3" specular="0.08 0.08 0.08"/>
    <body name="trunk" childclass="go2" pos="0.0178856 0.0136846 0.00976025" quat="0.999971 -0.00206042 -0.000549801 0.00731962">
      <inertial pos="0.0256899 0.00494771 -0.00367727" quat="-0.0322562 0.709834 -0.0378696 0.70261" mass="3.28275" diaginertia="0.000534739 0.00622091 0.144783"/>
      <joint name="//unnamed_joint_0" type="free" armature="0" damping="0" frictionloss="0"/>
      <geom name="//unnamed_geom_1" class="visual" material="black" mesh="base_0"/>
      <geom name="//unnamed_geom_2" class="visual" material="black" mesh="base_1"/>
      <geom name="//unnamed_geom_3" class="visual" material="black" mesh="base_2"/>
      <geom name="//unnamed_geom_4" class="visual" material="white" mesh="base_3"/>
      <geom name="//unnamed_geom_5" class="visual" material="gray" mesh="base_4"/>
      <geom name="trunk_1" class="collision" size="0.150353 0.0373684 0.0455615" type="box"/>
      <geom name="trunk_2" class="collision" size="0.0399662 0.0359696" pos="0.096056 0 0.0148204" type="cylinder"/>
      <geom name="trunk_3" class="collision" size="0.0375683" pos="0.0987523 0 -0.0889223"/>
      <geom name="//unnamed_geom_9" class="reward_collision_sphere" size="0.0799325"/>
      <geom name="//unnamed_geom_10" class="reward_collision_sphere" size="0.0479595" pos="0.0943708 0 -0.0666918"/>
      <site name="imu" pos="-0.0275565 -0.046969 0.103498" size="0.00799325"/>
      <camera name="track" pos="0 -1.15779 0" quat="0.707107 0.707107 0 0" mode="trackcom"/>
      <camera name="ego_camera" pos="0.105156 0 0.0666918" quat="-0.5 -0.5 0.5 0.5"/>
      <body name="FL_hip" pos="0.0777098 0.0397243 -0.00984979" quat="0.99996 0.003651 -0.00815701 -0.000210382">
        <inertial pos="0.0170023 0.0126044 0.0114411" quat="0.494762 0.482506 0.510217 0.511935" mass="0.296489" diaginertia="3.31042e-06 3.75479e-05 0.00233483"/>
        <joint name="FL_hip_joint" pos="0 0 0" axis="0.99949 -0.0102272 0.0302386" stiffness="0.0454173" range="-0.954307 1.36873" armature="0.00215934" damping="0.074039" frictionloss="0.0786752"/>
        <geom name="//unnamed_geom_11" class="visual" material="metal" mesh="hip_0"/>
        <geom name="//unnamed_geom_12" class="visual" material="gray" mesh="hip_1"/>
        <geom name="//unnamed_geom_13" class="collision" size="0.0367689 0.0159865" pos="0 0.0463117 0" quat="0.707107 0.707107 0 0" type="cylinder"/>
        <geom name="//unnamed_geom_14" class="reward_collision_sphere" size="0.0479595" pos="0 0.0405228 0"/>
        <body name="FL_thigh" pos="-0.000721478 0.0489933 -0.00953067" quat="0.999998 0.000975674 -0.00080164 0.00123438">
          <inertial pos="-0.0190968 -0.0181379 -0.0650669" quat="0.836947 0.0903473 -0.0377235 0.538455" mass="0.62445" diaginertia="2.66375e-05 0.000330034 0.00680724"/>
          <joint name="FL_thigh_joint" pos="0 0 0" axis="-0.0535246 0.998553 0.00527673" range="-1.26469 3.19844" armature="0.00254461" damping="0.0979551" frictionloss="0.0711204"/>
          <geom name="//unnamed_geom_15" class="visual" material="metal" mesh="thigh_0"/>
          <geom name="//unnamed_geom_16" class="visual" material="gray" mesh="thigh_1"/>
          <geom name="//unnamed_geom_17" class="collision" size="0.0851281 0.00979173 0.0135885" pos="0 0 -0.157837" quat="0.707107 0 0.707107 0" type="box"/>
          <body name="FL_calf" pos="0.00286206 -0.00728456 -0.310928" quat="0.999979 -0.00121441 -0.00631768 -0.0010701">
            <inertial pos="-0.0101369 -0.0118055 -0.19524" quat="0.738293 0.0678206 -0.0259678 0.670559" mass="0.109328" diaginertia="7.12504e-06 8.09128e-05 0.000437975"/>
            <joint name="FL_calf_joint" pos="0 0 0" axis="-0.0366918 0.999307 -0.00625744" range="-2.6228 -0.523718" armature="0.0132637" damping="0.00354297" frictionloss="0.208113"/>
            <geom name="//unnamed_geom_18" class="visual" material="gray" mesh="calf_0"/>
            <geom name="//unnamed_geom_19" class="visual" material="black" mesh="calf_1"/>
            <geom name="FL_calf0" class="collision" size="0.0095919 0.0479595" pos="0.00269631 0 -0.0889223" quat="0.994493 0 -0.104807 0" type="cylinder"/>
            <geom name="//unnamed_geom_21" class="collision" size="0.00879257 0.0259781" pos="0.00674077 0 -0.219342" quat="0.999688 0 0.0249974 0" type="cylinder"/>
            <geom name="//unnamed_geom_22" class="visual" pos="0 0 -0.315674" quat="1 0 0 0" material="black" mesh="foot"/>
            <geom name="FL_foot" class="foot" size="0.0125274" pos="-0.000674077 0 -0.315674"/>
            <geom name="//unnamed_geom_24" class="reward_collision_sphere" size="0.0199831"/>
            <geom name="//unnamed_geom_25" class="reward_collision_sphere" size="0.0199831" pos="-0.000674077 0 -0.315674"/>
            <site name="FL_foot" class="foot" pos="-0.000674077 0 -0.315674" size="0.00799325"/>
          </body>
        </body>
      </body>
      <body name="FR_hip" pos="0.0684799 -0.0427427 -0.00230329" quat="0.999986 -0.0039324 0.00264126 0.00250058">
        <inertial pos="-0.0167498 -0.00925275 -0.000441735" quat="0.515169 0.492769 0.497288 0.494454" mass="0.215726" diaginertia="3.44213e-06 3.50952e-05 0.00330363"/>
        <joint name="FR_hip_joint" pos="0 0 0" axis="0.999926 -0.00409606 0.011487" stiffness="0.0355526" range="-1.28698 0.978993" armature="0.0156069" damping="0.0261748" frictionloss="0.0152974"/>
        <geom name="//unnamed_geom_26" class="visual" pos="0 -7.8678e-09 -3.37466e-07" quat="4.63268e-05 1 0 0" material="metal" mesh="hip_0"/>
        <geom name="//unnamed_geom_27" class="visual" pos="0 -1.27546e-08 8.34683e-07" quat="4.63268e-05 1 0 0" material="gray" mesh="hip_1"/>
        <geom name="//unnamed_geom_28" class="collision" size="0.0367689 0.0159865" pos="0 -0.0463117 0" quat="0.707107 0.707107 0 0" type="cylinder"/>
        <geom name="//unnamed_geom_29" class="reward_collision_sphere" size="0.0479595" pos="0 -0.0405228 0"/>
        <body name="FR_thigh" pos="-0.00440581 -0.0470185 -0.0164747" quat="0.999962 -0.000830794 -0.00699961 -0.0051886">
          <inertial pos="0.0127179 0.0315187 -0.0401369" quat="0.534787 -0.0363807 0.101843 0.838038" mass="0.812948" diaginertia="2.78784e-05 0.000479208 0.00834866"/>
          <joint name="FR_thigh_joint" pos="0 0 0" axis="-0.0251763 -0.999464 0.0209343" stiffness="0.025665" range="-3.32018 1.76128" armature="0.00878462" damping="0.0153774" frictionloss="0.078164"/>
          <geom name="//unnamed_geom_30" class="visual" material="metal" mesh="thigh_mirror_0"/>
          <geom name="//unnamed_geom_31" class="visual" material="gray" mesh="thigh_mirror_1"/>
          <geom name="//unnamed_geom_32" class="collision" size="0.0851281 0.00979173 0.0135885" pos="0 0 -0.157837" quat="0.707107 0 0.707107 0" type="box"/>
          <body name="FR_calf" pos="-0.0132417 0.000503898 -0.319491" quat="1 -0.000113177 0.000118765 0.000747984">
            <inertial pos="-0.00933053 0.00215945 -0.201347" quat="0.720099 -0.0232875 0.00123224 0.69348" mass="0.0894258" diaginertia="4.18908e-06 9.01979e-05 0.000290293"/>
            <joint name="FR_calf_joint" pos="0 0 0" axis="0.0751567 -0.997167 0.0029635" stiffness="0.0612738" range="0.798702 2.83359" armature="0.00622243" damping="0" frictionloss="0.0971674"/>
            <geom name="//unnamed_geom_33" class="visual" material="gray" mesh="calf_mirror_0"/>
            <geom name="//unnamed_geom_34" class="visual" material="black" mesh="calf_mirror_1"/>
            <geom name="FR_calf0" class="collision" size="0.0103912 0.0479595" pos="0.00337039 0 -0.0889223" quat="0.995004 0 -0.0998334 0" type="cylinder"/>
            <geom name="//unnamed_geom_36" class="collision" size="0.00879257 0.0259781" pos="0.00674077 0 -0.219342" quat="0.999688 0 0.0249974 0" type="cylinder"/>
            <geom name="//unnamed_geom_37" class="visual" pos="0 0 -0.315674" quat="1 0 0 0" material="black" mesh="foot"/>
            <geom name="FR_foot" class="foot" size="0.0174585" pos="-0.000674077 0 -0.315674"/>
            <geom name="//unnamed_geom_39" class="reward_collision_sphere" size="0.0199831"/>
            <geom name="//unnamed_geom_40" class="reward_collision_sphere" size="0.0199831" pos="-0.000674077 0 -0.315674"/>
            <site name="FR_foot" class="foot" pos="-0.000674077 0 -0.315674" size="0.00799325"/>
          </body>
        </body>
      </body>
      <body name="RL_hip" pos="-0.0585694 0.020233 -0.0121112" quat="0.999952 -0.00179915 -0.00963943 -0.000535707">
        <inertial pos="-0.0161047 0.00831843 -0.00542434" quat="0.508448 0.498558 0.495092 0.4978" mass="0.296973" diaginertia="3.5987e-06 3.01617e-05 0.00356702"/>
        <joint name="RL_hip_joint" pos="0 0 0" axis="-0.999326 0.0354692 0.00943252" range="-0.912065 0.929698" armature="0.00760996" damping="0.00805952" frictionloss="0.0826445"/>
        <geom name="//unnamed_geom_41" class="visual" pos="9.97477e-09 0 1.95528e-06" quat="4.63268e-05 0 1 0" material="metal" mesh="hip_0"/>
        <geom name="//unnamed_geom_42" class="visual" pos="1.61703e-08 0 1.73406e-06" quat="4.63268e-05 0 1 0" material="gray" mesh="hip_1"/>
        <geom name="//unnamed_geom_43" class="collision" size="0.0367689 0.0159865" pos="0 0.0463117 0" quat="0.707107 0.707107 0 0" type="cylinder"/>
        <geom name="//unnamed_geom_44" class="reward_collision_sphere" size="0.0479595" pos="0 0.0405228 0"/>
        <body name="RL_thigh" pos="0.0172738 0.0450405 -0.0141174" quat="0.999962 0.00300469 0.00422064 0.00700766">
          <inertial pos="0.00232749 -0.00612807 -0.0416976" quat="0.870582 0.0635208 0.000347039 0.487905" mass="0.709449" diaginertia="2.33786e-05 0.000454021 0.00562422"/>
          <joint name="RL_thigh_joint" pos="0 0 0" axis="-0.00397553 0.999955 0.00856819" range="-0.401941 4.59984" armature="0.0126317" damping="0.098442" frictionloss="0.233603"/>
          <geom name="//unnamed_geom_45" class="visual" material="metal" mesh="thigh_0"/>
          <geom name="//unnamed_geom_46" class="visual" material="gray" mesh="thigh_1"/>
          <geom name="//unnamed_geom_47" class="collision" size="0.0851281 0.00979173 0.0135885" pos="0 0 -0.157837" quat="0.707107 0 0.707107 0" type="box"/>
          <body name="RL_calf" pos="-0.00880423 -0.00641102 -0.32667" quat="0.999999 -0.000741851 -0.0011817 0.000946417">
            <inertial pos="0.00304397 0.00182935 -0.22166" quat="0.708578 0.00843468 0.00108502 0.705582" mass="0.124051" diaginertia="6.44913e-06 8.72429e-05 0.000387469"/>
            <joint name="RL_calf_joint" pos="0 0 0" axis="-0.00024164 0.999922 -0.012491" stiffness="0.0227381" range="-2.56479 -0.828444" armature="0.0129249" damping="0.0851321" frictionloss="0.189429"/>
            <geom name="//unnamed_geom_48" class="visual" material="gray" mesh="calf_0"/>
            <geom name="//unnamed_geom_49" class="visual" material="black" mesh="calf_1"/>
            <geom name="RL_calf0" class="collision" size="0.0103912 0.0479595" pos="0.00337039 0 -0.0889223" quat="0.995004 0 -0.0998334 0" type="cylinder"/>
            <geom name="//unnamed_geom_51" class="collision" size="0.00879257 0.0259781" pos="0.00674077 0 -0.219342" quat="0.999688 0 0.0249974 0" type="cylinder"/>
            <geom name="//unnamed_geom_52" class="visual" pos="0 0 -0.315674" quat="1 0 0 0" material="black" mesh="foot"/>
            <geom name="RL_foot" class="foot" size="0.00861597" pos="-0.000674077 0 -0.315674"/>
            <geom name="//unnamed_geom_54" class="reward_collision_sphere" size="0.0199831"/>
            <geom name="//unnamed_geom_55" class="reward_collision_sphere" size="0.0199831" pos="-0.000674077 0 -0.315674"/>
            <site name="RL_foot" class="foot" pos="-0.000674077 0 -0.315674" size="0.00799325"/>
          </body>
        </body>
      </body>
      <body name="RR_hip" pos="-0.0637306 -0.00944135 -0.0149592" quat="0.999976 -0.00546632 -0.003109 0.00294969">
        <inertial pos="0.0016275 -0.0161067 -0.000925734" quat="0.555276 0.499881 0.495839 0.442641" mass="0.356103" diaginertia="3.40311e-06 3.39671e-05 0.0040226"/>
        <joint name="RR_hip_joint" pos="0 0 0" axis="-0.999446 -0.0204819 0.0262171" range="-1.17806 0.994722" armature="4.60576e-05" damping="0" frictionloss="0.289016"/>
        <geom name="//unnamed_geom_56" class="visual" pos="-9.9664e-09 -7.8678e-09 2.29275e-06" quat="2.14617e-09 4.63268e-05 4.63268e-05 -1" material="metal" mesh="hip_0"/>
        <geom name="//unnamed_geom_57" class="visual" pos="-1.6191e-08 -1.27546e-08 8.99376e-07" quat="2.14617e-09 4.63268e-05 4.63268e-05 -1" material="gray" mesh="hip_1"/>
        <geom name="//unnamed_geom_58" class="collision" size="0.0367689 0.0159865" pos="0 -0.0463117 0" quat="0.707107 0.707107 0 0" type="cylinder"/>
        <geom name="//unnamed_geom_59" class="reward_collision_sphere" size="0.0479595" pos="0 -0.0405228 0"/>
        <body name="RR_thigh" pos="-0.00339342 -0.0485583 0.0153886" quat="0.999986 0.000152467 0.00302001 -0.0043096">
          <inertial pos="0.000189272 0.0238736 -0.0527161" quat="0.554047 -0.012323 0.0940629 0.827063" mass="0.748244" diaginertia="3.26044e-05 0.000439171 0.00851059"/>
          <joint name="RR_thigh_joint" pos="0 0 0" axis="-0.00394688 -0.99938 -0.0349884" stiffness="0.0671318" range="-4.19993 0.273644" armature="0.00377944" damping="0.0400881" frictionloss="0.224115"/>
          <geom name="//unnamed_geom_60" class="visual" material="metal" mesh="thigh_mirror_0"/>
          <geom name="//unnamed_geom_61" class="visual" material="gray" mesh="thigh_mirror_1"/>
          <geom name="//unnamed_geom_62" class="collision" size="0.0851281 0.00979173 0.0135885" pos="0 0 -0.157837" quat="0.707107 0 0.707107 0" type="box"/>
          <body name="RR_calf" pos="0.0199921 -0.0142545 -0.314182" quat="0.999994 -0.00112076 -0.00314924 -0.000518788">
            <inertial pos="-0.017094 0.00147014 -0.221376" quat="0.687122 -0.0461971 -0.0113958 0.724982" mass="0.115831" diaginertia="6.78815e-06 0.000137362 0.000389391"/>
            <joint name="RR_calf_joint" pos="0 0 0" axis="-0.0332615 -0.999426 0.00644704" range="0.556402 2.33242" armature="0.0146329" damping="0" frictionloss="0.0941515"/>
            <geom name="//unnamed_geom_63" class="visual" material="gray" mesh="calf_mirror_0"/>
            <geom name="//unnamed_geom_64" class="visual" material="black" mesh="calf_mirror_1"/>
            <geom name="RR_calf0" class="collision" size="0.0103912 0.0479595" pos="0.00337039 0 -0.0889223" quat="0.995004 0 -0.0998334 0" type="cylinder"/>
            <geom name="//unnamed_geom_66" class="collision" size="0.00879257 0.0259781" pos="0.00674077 0 -0.219342" quat="0.999688 0 0.0249974 0" type="cylinder"/>
            <geom name="//unnamed_geom_67" class="visual" pos="0 0 -0.315674" quat="1 0 0 0" material="black" mesh="foot"/>
            <geom name="RR_foot" class="foot" size="0.0192975" pos="-0.000674077 0 -0.315674"/>
            <geom name="//unnamed_geom_69" class="reward_collision_sphere" size="0.0199831"/>
            <geom name="//unnamed_geom_70" class="reward_collision_sphere" size="0.0199831" pos="-0.000674077 0 -0.315674"/>
            <site name="RR_foot" class="foot" pos="-0.000674077 0 -0.315674" size="0.00799325"/>
          </body>
        </body>
      </body>
    </body>
  </worldbody>

  <contact>
    <pair class="/" geom1="floor" geom2="FL_foot" name="//unnamed_contact_0"/>
    <pair class="/" geom1="floor" geom2="FR_foot" name="//unnamed_contact_1"/>
    <pair class="/" geom1="floor" geom2="RL_foot" name="//unnamed_contact_2"/>
    <pair class="/" geom1="floor" geom2="RR_foot" name="//unnamed_contact_3"/>
  </contact>

  <actuator>
    <general name="FL_hip" class="/" joint="FL_hip_joint" forcerange="-22.2121 22.2121" gainprm="15.9175" biasprm="0 -15.9175 -0.369693"/>
    <general name="FL_thigh" class="/" joint="FL_thigh_joint" forcerange="-27.0684 27.0684" gainprm="15.9175" biasprm="0 -15.9175 -0.369693"/>
    <general name="FL_calf" class="/" joint="FL_calf_joint" forcerange="-35.2362 35.2362" gainprm="15.9175" biasprm="0 -15.9175 -0.369693"/>
    <general name="FR_hip" class="/" joint="FR_hip_joint" forcerange="-5.50348 5.50348" gainprm="15.9175" biasprm="0 -15.9175 -0.369693"/>
    <general name="FR_thigh" class="/" joint="FR_thigh_joint" forcerange="-19.9932 19.9932" gainprm="15.9175" biasprm="0 -15.9175 -0.369693"/>
    <general name="FR_calf" class="/" joint="FR_calf_joint" forcerange="-55.7966 55.7966" gainprm="15.9175" biasprm="0 -15.9175 -0.369693"/>
    <general name="RL_hip" class="/" joint="RL_hip_joint" forcerange="-22.9228 22.9228" gainprm="15.9175" biasprm="0 -15.9175 -0.369693"/>
    <general name="RL_thigh" class="/" joint="RL_thigh_joint" forcerange="-23.0209 23.0209" gainprm="15.9175" biasprm="0 -15.9175 -0.369693"/>
    <general name="RL_calf" class="/" joint="RL_calf_joint" forcerange="-30.3733 30.3733" gainprm="15.9175" biasprm="0 -15.9175 -0.369693"/>
    <general name="RR_hip" class="/" joint="RR_hip_joint" forcerange="-14.8683 14.8683" gainprm="15.9175" biasprm="0 -15.9175 -0.369693"/>
    <general name="RR_thigh" class="/" joint="RR_thigh_joint" forcerange="-25.1645 25.1645" gainprm="15.9175" biasprm="0 -15.9175 -0.369693"/>
    <general name="RR_calf" class="/" joint="RR_calf_joint" forcerange="-13.3149 13.3149" gainprm="15.9175" biasprm="0 -15.9175 -0.369693"/>
  </actuator>

  <sensor>
    <gyro site="imu" name="imu_angular_velocity"/>
    <velocimeter site="imu" name="imu_linear_velocity"/>
    <framelinvel objtype="site" objname="FL_foot" name="FL_foot_global_linear_velocity"/>
    <framelinvel objtype="site" objname="FR_foot" name="FR_foot_global_linear_velocity"/>
    <framelinvel objtype="site" objname="RL_foot" name="RL_foot_global_linear_velocity"/>
    <framelinvel objtype="site" objname="RR_foot" name="RR_foot_global_linear_velocity"/>
  </sensor>

  <keyframe>
    <key name="home" qpos="0 0 0.325 1 0 0 0 0.1 0.8 -1.5 -0.1 -0.8 1.5 -0.1 0.8 -1.5 0.1 -0.8 1.5"/>
  </keyframe>
</mujoco>
