<mujoco model="go2">
  <compiler angle="radian" assetdir="assets" balanceinertia="true" inertiafromgeom="false"/>

  <option timestep="0.005" density="1.2" viscosity="2e-05"/>

  <size nkey="1"/>

  <visual>
    <quality shadowsize="8192"/>
    <map shadowclip="0.5"/>
  </visual>

  <default>
    <default class="/">
      <geom contype="0" conaffinity="0" group="1" solref="-1000 -80"/>
      <site size="0.01 0.005 0.005" group="5"/>
      <general forcelimited="true" biastype="affine" gainprm="20" biasprm="0 -20 -0.5"/>
      <default class="go2">
        <joint armature="0.01" damping="0.01" frictionloss="0.2"/>
        <geom condim="1" margin="0.001"/>
        <default class="visual">
          <geom type="mesh" group="2"/>
        </default>
        <default class="collision">
          <geom group="3"/>
          <default class="foot">
            <geom size="0.022 0 0" condim="6" priority="1" friction="0.8 0.02 0.01" solimp="0.015 1 0.022"/>
          </default>
        </default>
        <default class="reward_collision_sphere">
          <geom group="5" rgba="1 0 0 1"/>
        </default>
      </default>
    </default>
  </default>

  <asset>
    <texture type="skybox" colorspace="auto" name="//unnamed_texture_0" builtin="gradient" rgb1="0.95 0.95 0.95" rgb2="0.95 0.95 0.95" width="100" height="600"/>
    <texture type="2d" colorspace="auto" name="texplane" builtin="checker" rgb1="0.345 0.575 0.748" rgb2="0.345 0.575 0.748" markrgb="1 1 1" width="512" height="512"/>
    <material name="MatPlane" class="/" texture="texplane" texuniform="true" texrepeat="2 2" specular="0.9"/>
    <material name="metal" class="/" rgba="0.9 0.95 0.95 1"/>
    <material name="black" class="/" rgba="0 0 0 1"/>
    <material name="white" class="/"/>
    <material name="gray" class="/" rgba="0.671705 0.692426 0.77427 1"/>
    <mesh name="base_0" class="/" file="base_0.obj"/>
    <mesh name="base_1" class="/" file="base_1.obj"/>
    <mesh name="base_2" class="/" file="base_2.obj"/>
    <mesh name="base_3" class="/" file="base_3.obj"/>
    <mesh name="base_4" class="/" file="base_4.obj"/>
    <mesh name="hip_0" class="/" file="hip_0.obj"/>
    <mesh name="hip_1" class="/" file="hip_1.obj"/>
    <mesh name="thigh_0" class="/" file="thigh_0.obj"/>
    <mesh name="thigh_1" class="/" file="thigh_1.obj"/>
    <mesh name="thigh_mirror_0" class="/" file="thigh_mirror_0.obj"/>
    <mesh name="thigh_mirror_1" class="/" file="thigh_mirror_1.obj"/>
    <mesh name="calf_0" class="/" file="calf_0.obj"/>
    <mesh name="calf_1" class="/" file="calf_1.obj"/>
    <mesh name="calf_mirror_0" class="/" file="calf_mirror_0.obj"/>
    <mesh name="calf_mirror_1" class="/" file="calf_mirror_1.obj"/>
    <mesh name="foot" class="/" file="foot.obj"/>
  </asset>

  <worldbody>
    <geom name="floor" class="/" size="100 100 0.125" type="plane" group="0" material="MatPlane"/>
    <light name="toplight_shadow" class="/" pos="0 0 5" dir="0.0990148 0.0990148 -0.990148" type="directional" ambient="0.04 0.04 0.04" diffuse="0.55 0.55 0.55" specular="0.12 0.12 0.12"/>
    <light name="toplight_fill" class="/" pos="0 0 5" dir="0.0990148 0.0990148 -0.990148" type="directional" castshadow="false" ambient="0.04 0.04 0.04" diffuse="0.3 0.3 0.3" specular="0.08 0.08 0.08"/>
    <body name="trunk" childclass="go2" pos="-0.00108007 0.000604597 0.000608614" quat="1 -7.54693e-06 6.37233e-07 -6.58199e-06">
      <inertial pos="0.0197496 3.23099e-05 -0.00451506" quat="-0.00210647 0.712115 -0.00314002 0.702053" mass="6.21654" diaginertia="0.113361 0.126785 0.00971519"/>
      <joint name="//unnamed_joint_0" type="free" armature="0" damping="0" frictionloss="0"/>
      <geom name="//unnamed_geom_1" class="visual" material="black" mesh="base_0"/>
      <geom name="//unnamed_geom_2" class="visual" material="black" mesh="base_1"/>
      <geom name="//unnamed_geom_3" class="visual" material="black" mesh="base_2"/>
      <geom name="//unnamed_geom_4" class="visual" material="white" mesh="base_3"/>
      <geom name="//unnamed_geom_5" class="visual" material="gray" mesh="base_4"/>
      <geom name="trunk_1" class="collision" size="0.181498 0.0451091 0.0549993" type="box"/>
      <geom name="trunk_2" class="collision" size="0.048245 0.0434205" pos="0.288298 0 0.00830386" type="cylinder"/>
      <geom name="trunk_3" class="collision" size="0.0453503" pos="0.29639 0 -0.0498232"/>
      <geom name="//unnamed_geom_9" class="reward_collision_sphere" size="0.0964901"/>
      <geom name="//unnamed_geom_10" class="reward_collision_sphere" size="0.057894" pos="0.28324 0 -0.0373674"/>
      <site name="imu" pos="-0.026915 -0.00231092 0.0345676" size="0.00964901"/>
      <camera name="track" pos="0 -2.10549 0" quat="0.707107 0.707107 0 0" mode="trackcom"/>
      <camera name="ego_camera" pos="0.31561 0 0.0373674" quat="-0.5 -0.5 0.5 0.5"/>
      <body name="FL_hip" pos="0.196053 0.0502566 0.00069084" quat="1 0.000488227 0.00016612 0.0001559">
        <inertial pos="-0.0067208 0.00311381 0.000853836" quat="0.49734 0.500312 0.504563 0.497752" mass="0.609184" diaginertia="0.000935099 0.000766462 0.000188156"/>
        <joint name="FL_hip_joint" pos="0 0 0" axis="0.999998 0.000731254 0.00159273" stiffness="0.0001397" range="-1.0432 1.03961" armature="0.00951273" damping="0.00603709" frictionloss="0.18589"/>
        <geom name="//unnamed_geom_11" class="visual" material="metal" mesh="hip_0"/>
        <geom name="//unnamed_geom_12" class="visual" material="gray" mesh="hip_1"/>
        <geom name="//unnamed_geom_13" class="collision" size="0.0443854 0.019298" pos="0 0.0842195 0" quat="0.707107 0.707107 0 0" type="cylinder"/>
        <geom name="//unnamed_geom_14" class="reward_collision_sphere" size="0.057894" pos="0 0.0736921 0"/>
        <body name="FL_thigh" pos="-0.000797899 0.101023 0.000581648" quat="1 5.16694e-05 5.33543e-05 -0.000105252">
          <inertial pos="-0.00288658 -0.0229797 -0.0264831" quat="0.829548 0.0840594 -0.0207318 0.551683" mass="1.03387" diaginertia="0.00631348 0.00758348 0.000350186"/>
          <joint name="FL_thigh_joint" pos="0 0 0" axis="5.19598e-05 1 1.38619e-05" stiffness="0.0120128" range="-1.56852 3.49196" armature="0.00945718" damping="0" frictionloss="0.183948"/>
          <geom name="//unnamed_geom_15" class="visual" material="metal" mesh="thigh_0"/>
          <geom name="//unnamed_geom_16" class="visual" material="gray" mesh="thigh_1"/>
          <geom name="//unnamed_geom_17" class="collision" size="0.102762 0.01182 0.0164033" pos="0 0 -0.0884361" quat="0.707107 0 0.707107 0" type="box"/>
          <body name="FL_calf" pos="-0.000919834 -0.000235661 -0.176765" quat="1 -0.000353745 -0.00021834 -3.29994e-05">
            <inertial pos="0.00554389 -0.0015406 -0.116652" quat="0.712245 0.00101192 -0.00446875 0.701916" mass="0.217155" diaginertia="0.00158431 0.00187167 2.11947e-05"/>
            <joint name="FL_calf_joint" pos="0 0 0" axis="0.00294202 0.999966 -0.0077612" stiffness="0.00179148" range="-2.73023 -0.837599" armature="0.0101582" damping="0.00591442" frictionloss="0.188922"/>
            <geom name="//unnamed_geom_18" class="visual" material="gray" mesh="calf_0"/>
            <geom name="//unnamed_geom_19" class="visual" material="black" mesh="calf_1"/>
            <geom name="FL_calf0" class="collision" size="0.0115788 0.057894" pos="0.00809257 0 -0.0498232" quat="0.994493 0 -0.104807 0" type="cylinder"/>
            <geom name="//unnamed_geom_21" class="collision" size="0.0106139 0.0313593" pos="0.0202314 0 -0.122897" quat="0.999688 0 0.0249974 0" type="cylinder"/>
            <geom name="//unnamed_geom_22" class="visual" pos="0 0 -0.176872" quat="1 0 0 0" material="black" mesh="foot"/>
            <geom name="FL_foot" class="foot" size="0.0153634" pos="-0.00202314 0 -0.176872"/>
            <geom name="//unnamed_geom_24" class="reward_collision_sphere" size="0.0241225"/>
            <geom name="//unnamed_geom_25" class="reward_collision_sphere" size="0.0241225" pos="-0.00202314 0 -0.176872"/>
            <site name="FL_foot" class="foot" pos="-0.00202314 0 -0.176872" size="0.00964901"/>
          </body>
        </body>
      </body>
      <body name="FR_hip" pos="0.195862 -0.0477421 0.00141479" quat="1 -0.00013632 -2.71084e-05 -1.44862e-05">
        <inertial pos="-0.00509738 -0.00174184 -0.000397601" quat="0.498966 0.505868 0.497882 0.497236" mass="0.617628" diaginertia="0.000923382 0.000760463 0.000189979"/>
        <joint name="FR_hip_joint" pos="0 0 0" axis="0.999995 0.00319419 -0.000539116" stiffness="0.0035264" range="-1.06867 1.0482" armature="0.00903746" damping="0.0194537" frictionloss="0.204234"/>
        <geom name="//unnamed_geom_26" class="visual" pos="0 1.93709e-09 8.30858e-08" quat="4.63268e-05 1 0 0" material="metal" mesh="hip_0"/>
        <geom name="//unnamed_geom_27" class="visual" pos="0 3.14025e-09 -2.05503e-07" quat="4.63268e-05 1 0 0" material="gray" mesh="hip_1"/>
        <geom name="//unnamed_geom_28" class="collision" size="0.0443854 0.019298" pos="0 -0.0842195 0" quat="0.707107 0.707107 0 0" type="cylinder"/>
        <geom name="//unnamed_geom_29" class="reward_collision_sphere" size="0.057894" pos="0 -0.0736921 0"/>
        <body name="FR_thigh" pos="3.51473e-05 -0.100797 0.00152162" quat="1 -0.000127536 -0.00021103 -0.00020519">
          <inertial pos="-0.00312112 0.0222496 -0.0269927" quat="0.55276 -0.0205888 0.0861753 0.828617" mass="1.02184" diaginertia="0.00635529 0.00767209 0.000349233"/>
          <joint name="FR_thigh_joint" pos="0 0 0" axis="-0.00401776 -0.999992 -0.00078173" range="-3.49071 1.58296" armature="0.00965751" damping="0.0100238" frictionloss="0.185735"/>
          <geom name="//unnamed_geom_30" class="visual" material="metal" mesh="thigh_mirror_0"/>
          <geom name="//unnamed_geom_31" class="visual" material="gray" mesh="thigh_mirror_1"/>
          <geom name="//unnamed_geom_32" class="collision" size="0.102762 0.01182 0.0164033" pos="0 0 -0.0884361" quat="0.707107 0 0.707107 0" type="box"/>
          <body name="FR_calf" pos="-0.00131446 0.000876121 -0.176043" quat="1 8.10564e-05 1.26742e-05 4.49303e-05">
            <inertial pos="0.00543735 0.000903967 -0.117566" quat="0.704375 -0.00550482 8.77638e-05 0.709807" mass="0.217423" diaginertia="0.00158473 0.00190594 2.09131e-05"/>
            <joint name="FR_calf_joint" pos="0 0 0" axis="-0.00340954 -0.99998 0.00534136" stiffness="0.00225458" range="0.834425 2.72407" armature="0.0095382" damping="0.00421752" frictionloss="0.195694"/>
            <geom name="//unnamed_geom_33" class="visual" material="gray" mesh="calf_mirror_0"/>
            <geom name="//unnamed_geom_34" class="visual" material="black" mesh="calf_mirror_1"/>
            <geom name="FR_calf0" class="collision" size="0.0125437 0.057894" pos="0.0101157 0 -0.0498232" quat="0.995004 0 -0.0998334 0" type="cylinder"/>
            <geom name="//unnamed_geom_36" class="collision" size="0.0106139 0.0313593" pos="0.0202314 0 -0.122897" quat="0.999688 0 0.0249974 0" type="cylinder"/>
            <geom name="//unnamed_geom_37" class="visual" pos="0 0 -0.176872" quat="1 0 0 0" material="black" mesh="foot"/>
            <geom name="FR_foot" class="foot" size="0.0218267" pos="-0.00202314 0 -0.176872"/>
            <geom name="//unnamed_geom_39" class="reward_collision_sphere" size="0.0241225"/>
            <geom name="//unnamed_geom_40" class="reward_collision_sphere" size="0.0241225" pos="-0.00202314 0 -0.176872"/>
            <site name="FR_foot" class="foot" pos="-0.00202314 0 -0.176872" size="0.00964901"/>
          </body>
        </body>
      </body>
      <body name="RL_hip" pos="-0.194843 0.0480581 -0.00142688" quat="1 0.000148323 0.000757173 0.000570039">
        <inertial pos="0.00623615 0.00196471 0.000486182" quat="0.50549 0.498159 0.497048 0.49926" mass="0.609682" diaginertia="0.000933337 0.000763289 0.00018825"/>
        <joint name="RL_hip_joint" pos="0 0 0" axis="-0.999827 -0.018243 -0.00357011" range="-1.06086 1.05523" armature="0.00958781" damping="0.0177237" frictionloss="0.187561"/>
        <geom name="//unnamed_geom_41" class="visual" pos="-1.57841e-09 0 -3.09404e-07" quat="4.63268e-05 0 1 0" material="metal" mesh="hip_0"/>
        <geom name="//unnamed_geom_42" class="visual" pos="-2.55879e-09 0 -2.74398e-07" quat="4.63268e-05 0 1 0" material="gray" mesh="hip_1"/>
        <geom name="//unnamed_geom_43" class="collision" size="0.0443854 0.019298" pos="0 0.0842195 0" quat="0.707107 0.707107 0 0" type="cylinder"/>
        <geom name="//unnamed_geom_44" class="reward_collision_sphere" size="0.057894" pos="0 0.0736921 0"/>
        <body name="RL_thigh" pos="-0.00117788 0.0989928 -0.000858046" quat="1 -2.05599e-05 -2.95783e-05 -0.000506158">
          <inertial pos="-0.00381893 -0.0238481 -0.0276939" quat="0.828982 0.0863175 -0.0211814 0.552168" mass="1.03357" diaginertia="0.00630959 0.0075762 0.000346006"/>
          <joint name="RL_thigh_joint" pos="0 0 0" axis="0.00410653 0.999967 -0.00706417" range="-0.530261 4.5437" armature="0.00996126" damping="0" frictionloss="0.196812"/>
          <geom name="//unnamed_geom_45" class="visual" material="metal" mesh="thigh_0"/>
          <geom name="//unnamed_geom_46" class="visual" material="gray" mesh="thigh_1"/>
          <geom name="//unnamed_geom_47" class="collision" size="0.102762 0.01182 0.0164033" pos="0 0 -0.0884361" quat="0.707107 0 0.707107 0" type="box"/>
          <body name="RL_calf" pos="0.000206758 -0.000318325 -0.178598" quat="1 -9.5322e-05 -0.000161789 9.55222e-05">
            <inertial pos="0.00639508 -0.000469466 -0.118177" quat="0.710982 0.00151927 -0.00430919 0.703195" mass="0.217343" diaginertia="0.0015813 0.00189032 2.11098e-05"/>
            <joint name="RL_calf_joint" pos="0 0 0" axis="-0.00558404 0.999939 0.0095471" range="-2.72355 -0.838047" armature="0.00988402" damping="0" frictionloss="0.194903"/>
            <geom name="//unnamed_geom_48" class="visual" material="gray" mesh="calf_0"/>
            <geom name="//unnamed_geom_49" class="visual" material="black" mesh="calf_1"/>
            <geom name="RL_calf0" class="collision" size="0.0125437 0.057894" pos="0.0101157 0 -0.0498232" quat="0.995004 0 -0.0998334 0" type="cylinder"/>
            <geom name="//unnamed_geom_51" class="collision" size="0.0106139 0.0313593" pos="0.0202314 0 -0.122897" quat="0.999688 0 0.0249974 0" type="cylinder"/>
            <geom name="//unnamed_geom_52" class="visual" pos="0 0 -0.176872" quat="1 0 0 0" material="black" mesh="foot"/>
            <geom name="RL_foot" class="foot" size="0.0190102" pos="-0.00202314 0 -0.176872"/>
            <geom name="//unnamed_geom_54" class="reward_collision_sphere" size="0.0241225"/>
            <geom name="//unnamed_geom_55" class="reward_collision_sphere" size="0.0241225" pos="-0.00202314 0 -0.176872"/>
            <site name="RL_foot" class="foot" pos="-0.00202314 0 -0.176872" size="0.00964901"/>
          </body>
        </body>
      </body>
      <body name="RR_hip" pos="-0.19572 -0.0513054 -0.00234765" quat="1 0.000208572 -0.000281532 0.000181856">
        <inertial pos="0.0054337 -0.00204822 -2.66269e-05" quat="0.501368 0.49484 0.499197 0.504545" mass="0.608627" diaginertia="0.000925776 0.000762886 0.000191118"/>
        <joint name="RR_hip_joint" pos="0 0 0" axis="-0.999997 0.00225934 2.39681e-05" range="-1.03639 1.04706" armature="0.0101626" damping="0.0146358" frictionloss="0.189182"/>
        <geom name="//unnamed_geom_56" class="visual" pos="1.57983e-09 1.93709e-09 -3.9249e-07" quat="2.14617e-09 4.63268e-05 4.63268e-05 -1" material="metal" mesh="hip_0"/>
        <geom name="//unnamed_geom_57" class="visual" pos="2.55526e-09 3.14025e-09 -6.88947e-08" quat="2.14617e-09 4.63268e-05 4.63268e-05 -1" material="gray" mesh="hip_1"/>
        <geom name="//unnamed_geom_58" class="collision" size="0.0443854 0.019298" pos="0 -0.0842195 0" quat="0.707107 0.707107 0 0" type="cylinder"/>
        <geom name="//unnamed_geom_59" class="reward_collision_sphere" size="0.057894" pos="0 -0.0736921 0"/>
        <body name="RR_thigh" pos="0.00099549 -0.100893 -0.00192952" quat="1 1.79681e-05 2.71124e-05 -8.06102e-05">
          <inertial pos="-0.00353631 0.0243163 -0.027523" quat="0.551668 -0.0198134 0.0850855 0.829476" mass="1.05339" diaginertia="0.00639942 0.00758505 0.00034631"/>
          <joint name="RR_thigh_joint" pos="0 0 0" axis="-0.00271762 -0.999985 0.00466463" stiffness="0.000779836" range="-4.5525 0.506924" armature="0.00917121" damping="0.0164042" frictionloss="0.191542"/>
          <geom name="//unnamed_geom_60" class="visual" material="metal" mesh="thigh_mirror_0"/>
          <geom name="//unnamed_geom_61" class="visual" material="gray" mesh="thigh_mirror_1"/>
          <geom name="//unnamed_geom_62" class="collision" size="0.102762 0.01182 0.0164033" pos="0 0 -0.0884361" quat="0.707107 0 0.707107 0" type="box"/>
          <body name="RR_calf" pos="-0.000948329 -0.00153229 -0.17796" quat="1 -8.81466e-06 0.000160478 -6.76017e-05">
            <inertial pos="0.00768299 0.000501198 -0.118537" quat="0.702125 -0.00654372 0.00269002 0.712018" mass="0.217277" diaginertia="0.00153564 0.00187501 2.04718e-05"/>
            <joint name="RR_calf_joint" pos="0 0 0" axis="-0.00349034 -0.999994 0.000347649" stiffness="3.62124e-05" range="0.828511 2.75885" armature="0.00976735" damping="0.01085" frictionloss="0.194138"/>
            <geom name="//unnamed_geom_63" class="visual" material="gray" mesh="calf_mirror_0"/>
            <geom name="//unnamed_geom_64" class="visual" material="black" mesh="calf_mirror_1"/>
            <geom name="RR_calf0" class="collision" size="0.0125437 0.057894" pos="0.0101157 0 -0.0498232" quat="0.995004 0 -0.0998334 0" type="cylinder"/>
            <geom name="//unnamed_geom_66" class="collision" size="0.0106139 0.0313593" pos="0.0202314 0 -0.122897" quat="0.999688 0 0.0249974 0" type="cylinder"/>
            <geom name="//unnamed_geom_67" class="visual" pos="0 0 -0.176872" quat="1 0 0 0" material="black" mesh="foot"/>
            <geom name="RR_foot" class="foot" size="0.0231088" pos="-0.00202314 0 -0.176872"/>
            <geom name="//unnamed_geom_69" class="reward_collision_sphere" size="0.0241225"/>
            <geom name="//unnamed_geom_70" class="reward_collision_sphere" size="0.0241225" pos="-0.00202314 0 -0.176872"/>
            <site name="RR_foot" class="foot" pos="-0.00202314 0 -0.176872" size="0.00964901"/>
          </body>
        </body>
      </body>
    </body>
  </worldbody>

  <contact>
    <pair class="/" geom1="floor" geom2="FL_foot" name="//unnamed_contact_0"/>
    <pair class="/" geom1="floor" geom2="FR_foot" name="//unnamed_contact_1"/>
    <pair class="/" geom1="floor" geom2="RL_foot" name="//unnamed_contact_2"/>
    <pair class="/" geom1="floor" geom2="RR_foot" name="//unnamed_contact_3"/>
  </contact>

  <actuator>
    <general name="FL_hip" class="/" joint="FL_hip_joint" forcerange="-22.9374 22.9374" gainprm="19.3497" biasprm="0 -19.3497 -0.483471"/>
    <general name="FL_thigh" class="/" joint="FL_thigh_joint" forcerange="-23.7359 23.7359" gainprm="19.3497" biasprm="0 -19.3497 -0.483471"/>
    <general name="FL_calf" class="/" joint="FL_calf_joint" forcerange="-43.3749 43.3749" gainprm="19.3497" biasprm="0 -19.3497 -0.483471"/>
    <general name="FR_hip" class="/" joint="FR_hip_joint" forcerange="-24.0631 24.0631" gainprm="19.3497" biasprm="0 -19.3497 -0.483471"/>
    <general name="FR_thigh" class="/" joint="FR_thigh_joint" forcerange="-22.8478 22.8478" gainprm="19.3497" biasprm="0 -19.3497 -0.483471"/>
    <general name="FR_calf" class="/" joint="FR_calf_joint" forcerange="-44.1493 44.1493" gainprm="19.3497" biasprm="0 -19.3497 -0.483471"/>
    <general name="RL_hip" class="/" joint="RL_hip_joint" forcerange="-22.6684 22.6684" gainprm="19.3497" biasprm="0 -19.3497 -0.483471"/>
    <general name="RL_thigh" class="/" joint="RL_thigh_joint" forcerange="-22.8383 22.8383" gainprm="19.3497" biasprm="0 -19.3497 -0.483471"/>
    <general name="RL_calf" class="/" joint="RL_calf_joint" forcerange="-44.3806 44.3806" gainprm="19.3497" biasprm="0 -19.3497 -0.483471"/>
    <general name="RR_hip" class="/" joint="RR_hip_joint" forcerange="-23.236 23.236" gainprm="19.3497" biasprm="0 -19.3497 -0.483471"/>
    <general name="RR_thigh" class="/" joint="RR_thigh_joint" forcerange="-22.9563 22.9563" gainprm="19.3497" biasprm="0 -19.3497 -0.483471"/>
    <general name="RR_calf" class="/" joint="RR_calf_joint" forcerange="-45.3604 45.3604" gainprm="19.3497" biasprm="0 -19.3497 -0.483471"/>
  </actuator>

  <sensor>
    <gyro site="imu" name="imu_angular_velocity"/>
    <velocimeter site="imu" name="imu_linear_velocity"/>
    <framelinvel objtype="site" objname="FL_foot" name="FL_foot_global_linear_velocity"/>
    <framelinvel objtype="site" objname="FR_foot" name="FR_foot_global_linear_velocity"/>
    <framelinvel objtype="site" objname="RL_foot" name="RL_foot_global_linear_velocity"/>
    <framelinvel objtype="site" objname="RR_foot" name="RR_foot_global_linear_velocity"/>
  </sensor>

  <keyframe>
    <key name="home" qpos="0 0 0.325 1 0 0 0 0.1 0.8 -1.5 -0.1 -0.8 1.5 -0.1 0.8 -1.5 0.1 -0.8 1.5"/>
  </keyframe>
</mujoco>
