<mujoco model="go2">
  <compiler angle="radian" assetdir="assets" balanceinertia="true" inertiafromgeom="false"/>

  <option timestep="0.005" density="1.2" viscosity="2e-05"/>

  <size nkey="1"/>

  <visual>
    <quality shadowsize="8192"/>
    <map shadowclip="0.5"/>
  </visual>

  <default>
    <default class="/">
      <geom contype="0" conaffinity="0" group="1" solref="-1000 -80"/>
      <site size="0.01 0.005 0.005" group="5"/>
      <general forcelimited="true" biastype="affine" gainprm="20" biasprm="0 -20 -0.5"/>
      <default class="go2">
        <joint armature="0.01" damping="0.01" frictionloss="0.2"/>
        <geom condim="1" margin="0.001"/>
        <default class="visual">
          <geom type="mesh" group="2"/>
        </default>
        <default class="collision">
          <geom group="3"/>
          <default class="foot">
            <geom size="0.022 0 0" condim="6" priority="1" friction="0.8 0.02 0.01" solimp="0.015 1 0.022"/>
          </default>
        </default>
        <default class="reward_collision_sphere">
          <geom group="5" rgba="1 0 0 1"/>
        </default>
      </default>
    </default>
  </default>

  <asset>
    <texture type="skybox" colorspace="auto" name="//unnamed_texture_0" builtin="gradient" rgb1="0.95 0.95 0.95" rgb2="0.95 0.95 0.95" width="100" height="600"/>
    <texture type="2d" colorspace="auto" name="texplane" builtin="checker" rgb1="0.345 0.575 0.748" rgb2="0.345 0.575 0.748" markrgb="1 1 1" width="512" height="512"/>
    <material name="MatPlane" class="/" texture="texplane" texuniform="true" texrepeat="2 2" specular="0.9"/>
    <material name="metal" class="/" rgba="0.9 0.95 0.95 1"/>
    <material name="black" class="/" rgba="0 0 0 1"/>
    <material name="white" class="/"/>
    <material name="gray" class="/" rgba="0.671705 0.692426 0.77427 1"/>
    <mesh name="base_0" class="/" file="base_0.obj"/>
    <mesh name="base_1" class="/" file="base_1.obj"/>
    <mesh name="base_2" class="/" file="base_2.obj"/>
    <mesh name="base_3" class="/" file="base_3.obj"/>
    <mesh name="base_4" class="/" file="base_4.obj"/>
    <mesh name="hip_0" class="/" file="hip_0.obj"/>
    <mesh name="hip_1" class="/" file="hip_1.obj"/>
    <mesh name="thigh_0" class="/" file="thigh_0.obj"/>
    <mesh name="thigh_1" class="/" file="thigh_1.obj"/>
    <mesh name="thigh_mirror_0" class="/" file="thigh_mirror_0.obj"/>
    <mesh name="thigh_mirror_1" class="/" file="thigh_mirror_1.obj"/>
    <mesh name="calf_0" class="/" file="calf_0.obj"/>
    <mesh name="calf_1" class="/" file="calf_1.obj"/>
    <mesh name="calf_mirror_0" class="/" file="calf_mirror_0.obj"/>
    <mesh name="calf_mirror_1" class="/" file="calf_mirror_1.obj"/>
    <mesh name="foot" class="/" file="foot.obj"/>
  </asset>

  <worldbody>
    <geom name="floor" class="/" size="100 100 0.125" type="plane" group="0" material="MatPlane"/>
    <light name="toplight_shadow" class="/" pos="0 0 5" dir="0.0990148 0.0990148 -0.990148" type="directional" ambient="0.04 0.04 0.04" diffuse="0.55 0.55 0.55" specular="0.12 0.12 0.12"/>
    <light name="toplight_fill" class="/" pos="0 0 5" dir="0.0990148 0.0990148 -0.990148" type="directional" castshadow="false" ambient="0.04 0.04 0.04" diffuse="0.3 0.3 0.3" specular="0.08 0.08 0.08"/>
    <body name="trunk" childclass="go2" pos="-0.000979276 0.000254018 -0.00279588" quat="1 0.000522988 -8.63049e-05 3.45269e-05">
      <inertial pos="0.0177025 -0.00277405 -0.00350226" quat="-0.0043074 0.71143 -0.00150926 0.702742" mass="6.90737" diaginertia="0.102668 0.128201 0.0206586"/>
      <joint name="//unnamed_joint_0" type="free" armature="0" damping="0" frictionloss="0"/>
      <geom name="//unnamed_geom_1" class="visual" material="black" mesh="base_0"/>
      <geom name="//unnamed_geom_2" class="visual" material="black" mesh="base_1"/>
      <geom name="//unnamed_geom_3" class="visual" material="black" mesh="base_2"/>
      <geom name="//unnamed_geom_4" class="visual" material="white" mesh="base_3"/>
      <geom name="//unnamed_geom_5" class="visual" material="gray" mesh="base_4"/>
      <geom name="trunk_1" class="collision" size="0.187256 0.0465403 0.0567443" type="box"/>
      <geom name="trunk_2" class="collision" size="0.0497757 0.0447981" pos="0.279522 0 0.00957882" type="cylinder"/>
      <geom name="trunk_3" class="collision" size="0.0467891" pos="0.287368 0 -0.0574729"/>
      <geom name="//unnamed_geom_9" class="reward_collision_sphere" size="0.0995514"/>
      <geom name="//unnamed_geom_10" class="reward_collision_sphere" size="0.0597308" pos="0.274618 0 -0.0431047"/>
      <site name="imu" pos="-0.0341724 0.00510559 0.0534456" size="0.00995514"/>
      <camera name="track" pos="0 -2.09576 0" quat="0.707107 0.707107 0 0" mode="trackcom"/>
      <camera name="ego_camera" pos="0.306003 0 0.0431047" quat="-0.5 -0.5 0.5 0.5"/>
      <body name="FL_hip" pos="0.187991 0.0484866 0.00294231" quat="1 -0.000311719 0.000666455 0.000538239">
        <inertial pos="-0.00278619 0.000423049 0.000748648" quat="0.498087 0.501336 0.495155 0.505365" mass="0.650447" diaginertia="0.000781398 0.000750319 0.000391698"/>
        <joint name="FL_hip_joint" pos="0 0 0" axis="0.999908 -0.0125921 -0.00512959" stiffness="0.00324937" range="-1.02931 1.09802" armature="0.0110445" damping="0.00871042" frictionloss="0.206782"/>
        <geom name="//unnamed_geom_11" class="visual" material="metal" mesh="hip_0"/>
        <geom name="//unnamed_geom_12" class="visual" material="gray" mesh="hip_1"/>
        <geom name="//unnamed_geom_13" class="collision" size="0.0457936 0.0199103" pos="0 0.0838306 0" quat="0.707107 0.707107 0 0" type="cylinder"/>
        <geom name="//unnamed_geom_14" class="reward_collision_sphere" size="0.0597308" pos="0 0.0733518 0"/>
        <body name="FL_thigh" pos="-0.00110775 0.101304 0.000596313" quat="1 -1.19591e-05 -0.000651642 -3.74904e-06">
          <inertial pos="-0.00217827 -0.0229925 -0.0288052" quat="0.829869 0.0855958 -0.0203316 0.550979" mass="1.16288" diaginertia="0.00518785 0.00732474 0.000709136"/>
          <joint name="FL_thigh_joint" pos="0 0 0" axis="0.000102868 1 -0.000115323" range="-1.56859 3.48738" armature="0.00955893" damping="0.00638156" frictionloss="0.173482"/>
          <geom name="//unnamed_geom_15" class="visual" material="metal" mesh="thigh_0"/>
          <geom name="//unnamed_geom_16" class="visual" material="gray" mesh="thigh_1"/>
          <geom name="//unnamed_geom_17" class="collision" size="0.106022 0.012195 0.0169237" pos="0 0 -0.102014" quat="0.707107 0 0.707107 0" type="box"/>
          <body name="FL_calf" pos="0.00264216 -0.00227959 -0.206208" quat="0.999999 0.00102486 -0.000594918 -0.000921367">
            <inertial pos="0.00633147 -0.00109357 -0.135095" quat="0.710692 0.00149376 -0.00442094 0.703488" mass="0.231953" diaginertia="0.00131371 0.00184002 4.1809e-05"/>
            <joint name="FL_calf_joint" pos="0 0 0" axis="-0.010188 0.999839 0.0147832" range="-2.77959 -0.809885" armature="0.0110401" damping="0" frictionloss="0.225848"/>
            <geom name="//unnamed_geom_18" class="visual" material="gray" mesh="calf_0"/>
            <geom name="//unnamed_geom_19" class="visual" material="black" mesh="calf_1"/>
            <geom name="FL_calf0" class="collision" size="0.0119462 0.0597308" pos="0.00784622 0 -0.0574729" quat="0.994493 0 -0.104807 0" type="cylinder"/>
            <geom name="//unnamed_geom_21" class="collision" size="0.0109507 0.0323542" pos="0.0196155 0 -0.141767" quat="0.999688 0 0.0249974 0" type="cylinder"/>
            <geom name="//unnamed_geom_22" class="visual" pos="0 0 -0.204029" quat="1 0 0 0" material="black" mesh="foot"/>
            <geom name="FL_foot" class="foot" size="0.0162082" pos="-0.00196155 0 -0.204029"/>
            <geom name="//unnamed_geom_24" class="reward_collision_sphere" size="0.0248878"/>
            <geom name="//unnamed_geom_25" class="reward_collision_sphere" size="0.0248878" pos="-0.00196155 0 -0.204029"/>
            <site name="FL_foot" class="foot" pos="-0.00196155 0 -0.204029" size="0.00995514"/>
          </body>
        </body>
      </body>
      <body name="FR_hip" pos="0.187567 -0.048759 0.000222832" quat="1 9.71092e-05 2.9631e-05 9.93472e-05">
        <inertial pos="-0.00257265 -0.000975175 -0.00125217" quat="0.498762 0.506364 0.499854 0.494952" mass="0.691596" diaginertia="0.000810693 0.000801712 0.000398723"/>
        <joint name="FR_hip_joint" pos="0 0 0" axis="0.999979 -0.00344503 -0.0054405" stiffness="0.00194426" range="-1.09965 1.03041" armature="0.00869896" damping="0.00701076" frictionloss="0.173776"/>
        <geom name="//unnamed_geom_26" class="visual" pos="0 7.84045e-10 3.36293e-08" quat="4.63268e-05 1 0 0" material="metal" mesh="hip_0"/>
        <geom name="//unnamed_geom_27" class="visual" pos="0 1.27103e-09 -8.31782e-08" quat="4.63268e-05 1 0 0" material="gray" mesh="hip_1"/>
        <geom name="//unnamed_geom_28" class="collision" size="0.0457936 0.0199103" pos="0 -0.0838306 0" quat="0.707107 0.707107 0 0" type="cylinder"/>
        <geom name="//unnamed_geom_29" class="reward_collision_sphere" size="0.0597308" pos="0 -0.0733518 0"/>
        <body name="FR_thigh" pos="-0.0014368 -0.0975449 -0.00186472" quat="1 0.000232591 -0.000154708 -0.000114093">
          <inertial pos="-0.00356099 0.0225141 -0.0302028" quat="0.550726 -0.0272443 0.0737235 0.830978" mass="1.06553" diaginertia="0.00514353 0.00735787 0.000700036"/>
          <joint name="FR_thigh_joint" pos="0 0 0" axis="0.00711525 -0.999938 -0.00861278" range="-3.45318 1.62402" armature="0.0100878" damping="0" frictionloss="0.212349"/>
          <geom name="//unnamed_geom_30" class="visual" material="metal" mesh="thigh_mirror_0"/>
          <geom name="//unnamed_geom_31" class="visual" material="gray" mesh="thigh_mirror_1"/>
          <geom name="//unnamed_geom_32" class="collision" size="0.106022 0.012195 0.0169237" pos="0 0 -0.102014" quat="0.707107 0 0.707107 0" type="box"/>
          <body name="FR_calf" pos="0.00230292 -0.00213826 -0.202343" quat="1 0.000111361 -2.83917e-05 -0.000234702">
            <inertial pos="0.00565545 0.00120877 -0.133188" quat="0.695904 0.000713599 0.00544678 0.718113" mass="0.241921" diaginertia="0.00132455 0.00179161 4.27156e-05"/>
            <joint name="FR_calf_joint" pos="0 0 0" axis="-0.00480413 -0.999962 0.00731904" range="0.786165 2.7765" armature="0.00962516" damping="0.00450671" frictionloss="0.178514"/>
            <geom name="//unnamed_geom_33" class="visual" material="gray" mesh="calf_mirror_0"/>
            <geom name="//unnamed_geom_34" class="visual" material="black" mesh="calf_mirror_1"/>
            <geom name="FR_calf0" class="collision" size="0.0129417 0.0597308" pos="0.00980777 0 -0.0574729" quat="0.995004 0 -0.0998334 0" type="cylinder"/>
            <geom name="//unnamed_geom_36" class="collision" size="0.0109507 0.0323542" pos="0.0196155 0 -0.141767" quat="0.999688 0 0.0249974 0" type="cylinder"/>
            <geom name="//unnamed_geom_37" class="visual" pos="0 0 -0.204029" quat="1 0 0 0" material="black" mesh="foot"/>
            <geom name="FR_foot" class="foot" size="0.021527" pos="-0.00196155 0 -0.204029"/>
            <geom name="//unnamed_geom_39" class="reward_collision_sphere" size="0.0248878"/>
            <geom name="//unnamed_geom_40" class="reward_collision_sphere" size="0.0248878" pos="-0.00196155 0 -0.204029"/>
            <site name="FR_foot" class="foot" pos="-0.00196155 0 -0.204029" size="0.00995514"/>
          </body>
        </body>
      </body>
      <body name="RL_hip" pos="-0.191536 0.0508417 2.66932e-05" quat="1 0.000464972 0.000136688 7.78881e-05">
        <inertial pos="0.00699362 0.00471435 -0.00102705" quat="0.514619 0.490594 0.499666 0.494791" mass="0.669254" diaginertia="0.000766172 0.00074607 0.000361935"/>
        <joint name="RL_hip_joint" pos="0 0 0" axis="-0.999998 0.00152652 0.00106136" range="-1.02525 1.0195" armature="0.00858073" damping="0" frictionloss="0.201713"/>
        <geom name="//unnamed_geom_41" class="visual" pos="-1.99455e-10 0 -3.90977e-08" quat="4.63268e-05 0 1 0" material="metal" mesh="hip_0"/>
        <geom name="//unnamed_geom_42" class="visual" pos="-3.2334e-10 0 -3.46741e-08" quat="4.63268e-05 0 1 0" material="gray" mesh="hip_1"/>
        <geom name="//unnamed_geom_43" class="collision" size="0.0457936 0.0199103" pos="0 0.0838306 0" quat="0.707107 0.707107 0 0" type="cylinder"/>
        <geom name="//unnamed_geom_44" class="reward_collision_sphere" size="0.0597308" pos="0 0.0733518 0"/>
        <body name="RL_thigh" pos="-0.00264708 0.0979754 -0.000722192" quat="1 -1.33231e-06 7.5795e-07 -1.27739e-06">
          <inertial pos="-0.00395545 -0.0203319 -0.0304173" quat="0.830763 0.0883229 -0.0205201 0.549191" mass="1.13397" diaginertia="0.00540593 0.00714192 0.000713015"/>
          <joint name="RL_thigh_joint" pos="0 0 0" axis="-0.00750483 0.999972 -0.000102829" stiffness="0.0143811" range="-0.516407 4.56212" armature="0.00888091" damping="0" frictionloss="0.209479"/>
          <geom name="//unnamed_geom_45" class="visual" material="metal" mesh="thigh_0"/>
          <geom name="//unnamed_geom_46" class="visual" material="gray" mesh="thigh_1"/>
          <geom name="//unnamed_geom_47" class="collision" size="0.106022 0.012195 0.0169237" pos="0 0 -0.102014" quat="0.707107 0 0.707107 0" type="box"/>
          <body name="RL_calf" pos="-0.00245934 -0.00256035 -0.205618" quat="1 5.87577e-05 -0.000535915 0.000129629">
            <inertial pos="0.00619132 -0.000632252 -0.134801" quat="0.706157 -0.00127393 -0.00527653 0.708034" mass="0.239689" diaginertia="0.00134715 0.00183464 4.21322e-05"/>
            <joint name="RL_calf_joint" pos="0 0 0" axis="0.00353331 0.999988 -0.00330622" range="-2.72218 -0.838814" armature="0.00866168" damping="0.00537486" frictionloss="0.226454"/>
            <geom name="//unnamed_geom_48" class="visual" material="gray" mesh="calf_0"/>
            <geom name="//unnamed_geom_49" class="visual" material="black" mesh="calf_1"/>
            <geom name="RL_calf0" class="collision" size="0.0129417 0.0597308" pos="0.00980777 0 -0.0574729" quat="0.995004 0 -0.0998334 0" type="cylinder"/>
            <geom name="//unnamed_geom_51" class="collision" size="0.0109507 0.0323542" pos="0.0196155 0 -0.141767" quat="0.999688 0 0.0249974 0" type="cylinder"/>
            <geom name="//unnamed_geom_52" class="visual" pos="0 0 -0.204029" quat="1 0 0 0" material="black" mesh="foot"/>
            <geom name="RL_foot" class="foot" size="0.0185243" pos="-0.00196155 0 -0.204029"/>
            <geom name="//unnamed_geom_54" class="reward_collision_sphere" size="0.0248878"/>
            <geom name="//unnamed_geom_55" class="reward_collision_sphere" size="0.0248878" pos="-0.00196155 0 -0.204029"/>
            <site name="RL_foot" class="foot" pos="-0.00196155 0 -0.204029" size="0.00995514"/>
          </body>
        </body>
      </body>
      <body name="RR_hip" pos="-0.190919 -0.0517538 -0.00186501" quat="0.999999 -0.000929593 -0.00101056 0.000317868">
        <inertial pos="0.00292634 -0.0024028 0.00254482" quat="0.498831 0.496655 0.498225 0.506234" mass="0.652905" diaginertia="0.000785556 0.000731056 0.000367088"/>
        <joint name="RR_hip_joint" pos="0 0 0" axis="-1 -1.76926e-05 -0.000649749" range="-1.09973 1.08365" armature="0.00981585" damping="0" frictionloss="0.201081"/>
        <geom name="//unnamed_geom_56" class="visual" pos="2.01778e-10 7.84045e-10 -7.2727e-08" quat="2.14617e-09 4.63268e-05 4.63268e-05 -1" material="metal" mesh="hip_0"/>
        <geom name="//unnamed_geom_57" class="visual" pos="3.17593e-10 1.27103e-09 4.85041e-08" quat="2.14617e-09 4.63268e-05 4.63268e-05 -1" material="gray" mesh="hip_1"/>
        <geom name="//unnamed_geom_58" class="collision" size="0.0457936 0.0199103" pos="0 -0.0838306 0" quat="0.707107 0.707107 0 0" type="cylinder"/>
        <geom name="//unnamed_geom_59" class="reward_collision_sphere" size="0.0597308" pos="0 -0.0733518 0"/>
        <body name="RR_thigh" pos="-0.00144408 -0.102627 0.00149922" quat="1 0.000252905 0.000324244 9.67009e-06">
          <inertial pos="-0.000753335 0.0238707 -0.0321249" quat="0.552081 -0.019682 0.0841077 0.829304" mass="1.08634" diaginertia="0.00511648 0.00722403 0.000691338"/>
          <joint name="RR_thigh_joint" pos="0 0 0" axis="0.0181497 -0.999833 -0.00201954" range="-4.54506 0.524987" armature="0.0092382" damping="0.0069015" frictionloss="0.203259"/>
          <geom name="//unnamed_geom_60" class="visual" material="metal" mesh="thigh_mirror_0"/>
          <geom name="//unnamed_geom_61" class="visual" material="gray" mesh="thigh_mirror_1"/>
          <geom name="//unnamed_geom_62" class="collision" size="0.106022 0.012195 0.0169237" pos="0 0 -0.102014" quat="0.707107 0 0.707107 0" type="box"/>
          <body name="RR_calf" pos="-0.00203497 -0.000524394 -0.204289" quat="1 -0.00044083 0.00037549 0.000778737">
            <inertial pos="0.0045458 0.000510555 -0.136034" quat="0.697059 -0.00807238 -0.00802807 0.716923" mass="0.232351" diaginertia="0.00129687 0.00189173 4.22518e-05"/>
            <joint name="RR_calf_joint" pos="0 0 0" axis="-0.00273231 -0.999996 0.000206794" stiffness="0.0116884" range="0.850228 2.71623" armature="0.00894479" damping="0.0185587" frictionloss="0.197766"/>
            <geom name="//unnamed_geom_63" class="visual" material="gray" mesh="calf_mirror_0"/>
            <geom name="//unnamed_geom_64" class="visual" material="black" mesh="calf_mirror_1"/>
            <geom name="RR_calf0" class="collision" size="0.0129417 0.0597308" pos="0.00980777 0 -0.0574729" quat="0.995004 0 -0.0998334 0" type="cylinder"/>
            <geom name="//unnamed_geom_66" class="collision" size="0.0109507 0.0323542" pos="0.0196155 0 -0.141767" quat="0.999688 0 0.0249974 0" type="cylinder"/>
            <geom name="//unnamed_geom_67" class="visual" pos="0 0 -0.204029" quat="1 0 0 0" material="black" mesh="foot"/>
            <geom name="RR_foot" class="foot" size="0.0197583" pos="-0.00196155 0 -0.204029"/>
            <geom name="//unnamed_geom_69" class="reward_collision_sphere" size="0.0248878"/>
            <geom name="//unnamed_geom_70" class="reward_collision_sphere" size="0.0248878" pos="-0.00196155 0 -0.204029"/>
            <site name="RR_foot" class="foot" pos="-0.00196155 0 -0.204029" size="0.00995514"/>
          </body>
        </body>
      </body>
    </body>
  </worldbody>

  <contact>
    <pair class="/" geom1="floor" geom2="FL_foot" name="//unnamed_contact_0"/>
    <pair class="/" geom1="floor" geom2="FR_foot" name="//unnamed_contact_1"/>
    <pair class="/" geom1="floor" geom2="RL_foot" name="//unnamed_contact_2"/>
    <pair class="/" geom1="floor" geom2="RR_foot" name="//unnamed_contact_3"/>
  </contact>

  <actuator>
    <general name="FL_hip" class="/" joint="FL_hip_joint" forcerange="-24.3532 24.3532" gainprm="19.8299" biasprm="0 -19.8299 -0.494317"/>
    <general name="FL_thigh" class="/" joint="FL_thigh_joint" forcerange="-21.3735 21.3735" gainprm="19.8299" biasprm="0 -19.8299 -0.494317"/>
    <general name="FL_calf" class="/" joint="FL_calf_joint" forcerange="-45.1674 45.1674" gainprm="19.8299" biasprm="0 -19.8299 -0.494317"/>
    <general name="FR_hip" class="/" joint="FR_hip_joint" forcerange="-21.2118 21.2118" gainprm="19.8299" biasprm="0 -19.8299 -0.494317"/>
    <general name="FR_thigh" class="/" joint="FR_thigh_joint" forcerange="-25.2426 25.2426" gainprm="19.8299" biasprm="0 -19.8299 -0.494317"/>
    <general name="FR_calf" class="/" joint="FR_calf_joint" forcerange="-40.5055 40.5055" gainprm="19.8299" biasprm="0 -19.8299 -0.494317"/>
    <general name="RL_hip" class="/" joint="RL_hip_joint" forcerange="-23.5043 23.5043" gainprm="19.8299" biasprm="0 -19.8299 -0.494317"/>
    <general name="RL_thigh" class="/" joint="RL_thigh_joint" forcerange="-21.3909 21.3909" gainprm="19.8299" biasprm="0 -19.8299 -0.494317"/>
    <general name="RL_calf" class="/" joint="RL_calf_joint" forcerange="-45.5986 45.5986" gainprm="19.8299" biasprm="0 -19.8299 -0.494317"/>
    <general name="RR_hip" class="/" joint="RR_hip_joint" forcerange="-22.7848 22.7848" gainprm="19.8299" biasprm="0 -19.8299 -0.494317"/>
    <general name="RR_thigh" class="/" joint="RR_thigh_joint" forcerange="-21.706 21.706" gainprm="19.8299" biasprm="0 -19.8299 -0.494317"/>
    <general name="RR_calf" class="/" joint="RR_calf_joint" forcerange="-49.8098 49.8098" gainprm="19.8299" biasprm="0 -19.8299 -0.494317"/>
  </actuator>

  <sensor>
    <gyro site="imu" name="imu_angular_velocity"/>
    <velocimeter site="imu" name="imu_linear_velocity"/>
    <framelinvel objtype="site" objname="FL_foot" name="FL_foot_global_linear_velocity"/>
    <framelinvel objtype="site" objname="FR_foot" name="FR_foot_global_linear_velocity"/>
    <framelinvel objtype="site" objname="RL_foot" name="RL_foot_global_linear_velocity"/>
    <framelinvel objtype="site" objname="RR_foot" name="RR_foot_global_linear_velocity"/>
  </sensor>

  <keyframe>
    <key name="home" qpos="0 0 0.325 1 0 0 0 0.1 0.8 -1.5 -0.1 -0.8 1.5 -0.1 0.8 -1.5 0.1 -0.8 1.5"/>
  </keyframe>
</mujoco>
