<mujoco model="go2">
  <compiler angle="radian" assetdir="assets" balanceinertia="true" inertiafromgeom="false"/>

  <option timestep="0.005" density="1.2" viscosity="2e-05"/>

  <size nkey="1"/>

  <visual>
    <quality shadowsize="8192"/>
    <map shadowclip="0.5"/>
  </visual>

  <default>
    <default class="/">
      <geom contype="0" conaffinity="0" group="1" solref="-1000 -80"/>
      <site size="0.01 0.005 0.005" group="5"/>
      <general forcelimited="true" biastype="affine" gainprm="20" biasprm="0 -20 -0.5"/>
      <default class="go2">
        <joint armature="0.01" damping="0.01" frictionloss="0.2"/>
        <geom condim="1" margin="0.001"/>
        <default class="visual">
          <geom type="mesh" group="2"/>
        </default>
        <default class="collision">
          <geom group="3"/>
          <default class="foot">
            <geom size="0.022 0 0" condim="6" priority="1" friction="0.8 0.02 0.01" solimp="0.015 1 0.022"/>
          </default>
        </default>
        <default class="reward_collision_sphere">
          <geom group="5" rgba="1 0 0 1"/>
        </default>
      </default>
    </default>
  </default>

  <asset>
    <texture type="skybox" colorspace="auto" name="//unnamed_texture_0" builtin="gradient" rgb1="0.95 0.95 0.95" rgb2="0.95 0.95 0.95" width="100" height="600"/>
    <texture type="2d" colorspace="auto" name="texplane" builtin="checker" rgb1="0.345 0.575 0.748" rgb2="0.345 0.575 0.748" markrgb="1 1 1" width="512" height="512"/>
    <material name="MatPlane" class="/" texture="texplane" texuniform="true" texrepeat="2 2" specular="0.9"/>
    <material name="metal" class="/" rgba="0.9 0.95 0.95 1"/>
    <material name="black" class="/" rgba="0 0 0 1"/>
    <material name="white" class="/"/>
    <material name="gray" class="/" rgba="0.671705 0.692426 0.77427 1"/>
    <mesh name="base_0" class="/" file="base_0.obj"/>
    <mesh name="base_1" class="/" file="base_1.obj"/>
    <mesh name="base_2" class="/" file="base_2.obj"/>
    <mesh name="base_3" class="/" file="base_3.obj"/>
    <mesh name="base_4" class="/" file="base_4.obj"/>
    <mesh name="hip_0" class="/" file="hip_0.obj"/>
    <mesh name="hip_1" class="/" file="hip_1.obj"/>
    <mesh name="thigh_0" class="/" file="thigh_0.obj"/>
    <mesh name="thigh_1" class="/" file="thigh_1.obj"/>
    <mesh name="thigh_mirror_0" class="/" file="thigh_mirror_0.obj"/>
    <mesh name="thigh_mirror_1" class="/" file="thigh_mirror_1.obj"/>
    <mesh name="calf_0" class="/" file="calf_0.obj"/>
    <mesh name="calf_1" class="/" file="calf_1.obj"/>
    <mesh name="calf_mirror_0" class="/" file="calf_mirror_0.obj"/>
    <mesh name="calf_mirror_1" class="/" file="calf_mirror_1.obj"/>
    <mesh name="foot" class="/" file="foot.obj"/>
  </asset>

  <worldbody>
    <geom name="floor" class="/" size="100 100 0.125" type="plane" group="0" material="MatPlane"/>
    <light name="toplight_shadow" class="/" pos="0 0 5" dir="0.0990148 0.0990148 -0.990148" type="directional" ambient="0.04 0.04 0.04" diffuse="0.55 0.55 0.55" specular="0.12 0.12 0.12"/>
    <light name="toplight_fill" class="/" pos="0 0 5" dir="0.0990148 0.0990148 -0.990148" type="directional" castshadow="false" ambient="0.04 0.04 0.04" diffuse="0.3 0.3 0.3" specular="0.08 0.08 0.08"/>
    <body name="trunk" childclass="go2" pos="0.000708298 0.000337789 0.000840854" quat="1 7.47716e-05 0.000435218 2.72392e-06">
      <inertial pos="0.0214405 -0.000713779 -0.00499845" quat="0.000403534 0.714183 -0.0012355 0.699958" mass="5.90827" diaginertia="0.0992253 0.0956252 0.0119676"/>
      <joint name="//unnamed_joint_0" type="free" armature="0" damping="0" frictionloss="0"/>
      <geom name="//unnamed_geom_1" class="visual" material="black" mesh="base_0"/>
      <geom name="//unnamed_geom_2" class="visual" material="black" mesh="base_1"/>
      <geom name="//unnamed_geom_3" class="visual" material="black" mesh="base_2"/>
      <geom name="//unnamed_geom_4" class="visual" material="white" mesh="base_3"/>
      <geom name="//unnamed_geom_5" class="visual" material="gray" mesh="base_4"/>
      <geom name="trunk_1" class="collision" size="0.178034 0.0442482 0.0539497" type="box"/>
      <geom name="trunk_2" class="collision" size="0.0473243 0.0425918" pos="0.279722 0 0.00863202" type="cylinder"/>
      <geom name="trunk_3" class="collision" size="0.0444848" pos="0.287573 0 -0.0517921"/>
      <geom name="//unnamed_geom_9" class="reward_collision_sphere" size="0.0946485"/>
      <geom name="//unnamed_geom_10" class="reward_collision_sphere" size="0.0567891" pos="0.274814 0 -0.0388441"/>
      <site name="imu" pos="-0.0296329 -0.00572024 0.0378176" size="0.00946485"/>
      <camera name="track" pos="0 -1.98955 0" quat="0.707107 0.707107 0 0" mode="trackcom"/>
      <camera name="ego_camera" pos="0.306221 0 0.0388441" quat="-0.5 -0.5 0.5 0.5"/>
      <body name="FL_hip" pos="0.189138 0.0462611 0.00218922" quat="1 6.46045e-05 -0.000243656 -0.000270721">
        <inertial pos="-0.00436005 0.00188695 -0.000491181" quat="0.494677 0.500958 0.504749 0.499564" mass="0.578774" diaginertia="0.000810457 0.000583423 0.000228961"/>
        <joint name="FL_hip_joint" pos="0 0 0" axis="0.999999 0.00161201 -0.000213684" stiffness="0.00124268" range="-1.04079 1.05199" armature="0.00919723" damping="0.0102914" frictionloss="0.185681"/>
        <geom name="//unnamed_geom_11" class="visual" material="metal" mesh="hip_0"/>
        <geom name="//unnamed_geom_12" class="visual" material="gray" mesh="hip_1"/>
        <geom name="//unnamed_geom_13" class="collision" size="0.0435383 0.0189297" pos="0 0.079582 0" quat="0.707107 0.707107 0 0" type="cylinder"/>
        <geom name="//unnamed_geom_14" class="reward_collision_sphere" size="0.0567891" pos="0 0.0696342 0"/>
        <body name="FL_thigh" pos="-0.000623237 0.0946613 0.00187228" quat="1 4.43614e-05 -0.000180042 -0.000193823">
          <inertial pos="-0.00411426 -0.0225707 -0.0292548" quat="0.829679 0.0840061 -0.0203639 0.551508" mass="0.967167" diaginertia="0.00542978 0.00573247 0.000422181"/>
          <joint name="FL_thigh_joint" pos="0 0 0" axis="-0.0026962 0.999996 -0.00105263" range="-1.57168 3.51404" armature="0.00975948" damping="0" frictionloss="0.189142"/>
          <geom name="//unnamed_geom_15" class="visual" material="metal" mesh="thigh_0"/>
          <geom name="//unnamed_geom_16" class="visual" material="gray" mesh="thigh_1"/>
          <geom name="//unnamed_geom_17" class="collision" size="0.100801 0.0115944 0.0160903" pos="0 0 -0.0919311" quat="0.707107 0 0.707107 0" type="box"/>
          <body name="FL_calf" pos="0.000234141 0.000611617 -0.184601" quat="1 -1.72304e-05 -3.39536e-05 -2.04611e-05">
            <inertial pos="0.00618105 0.000384941 -0.122152" quat="0.710662 0.00185483 -0.00477848 0.703515" mass="0.205904" diaginertia="0.00134573 0.00141959 2.54853e-05"/>
            <joint name="FL_calf_joint" pos="0 0 0" axis="-0.00596925 0.999978 -0.00304404" range="-2.7409 -0.837143" armature="0.00945853" damping="0.00428294" frictionloss="0.187609"/>
            <geom name="//unnamed_geom_18" class="visual" material="gray" mesh="calf_0"/>
            <geom name="//unnamed_geom_19" class="visual" material="black" mesh="calf_1"/>
            <geom name="FL_calf0" class="collision" size="0.0113578 0.0567891" pos="0.00785183 0 -0.0517921" quat="0.994493 0 -0.104807 0" type="cylinder"/>
            <geom name="//unnamed_geom_21" class="collision" size="0.0104113 0.0307608" pos="0.0196296 0 -0.127754" quat="0.999688 0 0.0249974 0" type="cylinder"/>
            <geom name="//unnamed_geom_22" class="visual" pos="0 0 -0.183862" quat="1 0 0 0" material="black" mesh="foot"/>
            <geom name="FL_foot" class="foot" size="0.0169013" pos="-0.00196296 0 -0.183862"/>
            <geom name="//unnamed_geom_24" class="reward_collision_sphere" size="0.0236621"/>
            <geom name="//unnamed_geom_25" class="reward_collision_sphere" size="0.0236621" pos="-0.00196296 0 -0.183862"/>
            <site name="FL_foot" class="foot" pos="-0.00196296 0 -0.183862" size="0.00946485"/>
          </body>
        </body>
      </body>
      <body name="FR_hip" pos="0.189403 -0.0464835 0.00128078" quat="1 -8.62448e-05 -8.59709e-05 -8.53298e-05">
        <inertial pos="-0.0054752 -0.00102387 -0.000679321" quat="0.498959 0.503702 0.499168 0.498152" mass="0.58039" diaginertia="0.000820285 0.000581209 0.000233261"/>
        <joint name="FR_hip_joint" pos="0 0 0" axis="0.999995 0.00293892 0.000820873" stiffness="0.00490337" range="-1.062 1.04372" armature="0.00947436" damping="0.0141923" frictionloss="0.188244"/>
        <geom name="//unnamed_geom_26" class="visual" pos="0 1.1462e-09 4.91629e-08" quat="4.63268e-05 1 0 0" material="metal" mesh="hip_0"/>
        <geom name="//unnamed_geom_27" class="visual" pos="0 1.85813e-09 -1.21599e-07" quat="4.63268e-05 1 0 0" material="gray" mesh="hip_1"/>
        <geom name="//unnamed_geom_28" class="collision" size="0.0435383 0.0189297" pos="0 -0.079582 0" quat="0.707107 0.707107 0 0" type="cylinder"/>
        <geom name="//unnamed_geom_29" class="reward_collision_sphere" size="0.0567891" pos="0 -0.0696342 0"/>
        <body name="FR_thigh" pos="-0.000679183 -0.0944852 0.00123035" quat="1 -1.06651e-06 1.78333e-06 9.43848e-07">
          <inertial pos="-0.003563 0.0222278 -0.0287625" quat="0.54955 -0.0243224 0.0811428 0.831155" mass="0.984389" diaginertia="0.0055177 0.00572851 0.000423912"/>
          <joint name="FR_thigh_joint" pos="0 0 0" axis="0.00214738 -0.999998 0.000165052" range="-3.5033 1.56174" armature="0.00964133" damping="0.0137117" frictionloss="0.193687"/>
          <geom name="//unnamed_geom_30" class="visual" material="metal" mesh="thigh_mirror_0"/>
          <geom name="//unnamed_geom_31" class="visual" material="gray" mesh="thigh_mirror_1"/>
          <geom name="//unnamed_geom_32" class="collision" size="0.100801 0.0115944 0.0160903" pos="0 0 -0.0919311" quat="0.707107 0 0.707107 0" type="box"/>
          <body name="FR_calf" pos="-0.000447402 -5.10909e-05 -0.183336" quat="1 -2.74899e-05 3.31965e-05 2.63704e-05">
            <inertial pos="0.00668146 0.00084107 -0.121044" quat="0.705136 -0.00830108 0.00103475 0.709023" mass="0.202624" diaginertia="0.00132694 0.00142216 2.49734e-05"/>
            <joint name="FR_calf_joint" pos="0 0 0" axis="0.00308062 -0.999994 0.00165041" range="0.840379 2.73851" armature="0.00916984" damping="0.00734159" frictionloss="0.189996"/>
            <geom name="//unnamed_geom_33" class="visual" material="gray" mesh="calf_mirror_0"/>
            <geom name="//unnamed_geom_34" class="visual" material="black" mesh="calf_mirror_1"/>
            <geom name="FR_calf0" class="collision" size="0.0123043 0.0567891" pos="0.00981479 0 -0.0517921" quat="0.995004 0 -0.0998334 0" type="cylinder"/>
            <geom name="//unnamed_geom_36" class="collision" size="0.0104113 0.0307608" pos="0.0196296 0 -0.127754" quat="0.999688 0 0.0249974 0" type="cylinder"/>
            <geom name="//unnamed_geom_37" class="visual" pos="0 0 -0.183862" quat="1 0 0 0" material="black" mesh="foot"/>
            <geom name="FR_foot" class="foot" size="0.0224211" pos="-0.00196296 0 -0.183862"/>
            <geom name="//unnamed_geom_39" class="reward_collision_sphere" size="0.0236621"/>
            <geom name="//unnamed_geom_40" class="reward_collision_sphere" size="0.0236621" pos="-0.00196296 0 -0.183862"/>
            <site name="FR_foot" class="foot" pos="-0.00196296 0 -0.183862" size="0.00946485"/>
          </body>
        </body>
      </body>
      <body name="RL_hip" pos="-0.190198 0.0473125 -0.00131603" quat="1 0.000357533 -0.000240408 7.93433e-05">
        <inertial pos="0.00541753 0.00215492 -0.000917112" quat="0.504508 0.499185 0.497101 0.499177" mass="0.576074" diaginertia="0.000803497 0.000585318 0.000228949"/>
        <joint name="RL_hip_joint" pos="0 0 0" axis="-0.999886 -0.00073752 0.0151098" stiffness="0.0021193" range="-1.02877 1.05075" armature="0.00943474" damping="0.00886993" frictionloss="0.191838"/>
        <geom name="//unnamed_geom_41" class="visual" pos="-1.03038e-09 0 -2.01978e-07" quat="4.63268e-05 0 1 0" material="metal" mesh="hip_0"/>
        <geom name="//unnamed_geom_42" class="visual" pos="-1.67037e-09 0 -1.79125e-07" quat="4.63268e-05 0 1 0" material="gray" mesh="hip_1"/>
        <geom name="//unnamed_geom_43" class="collision" size="0.0435383 0.0189297" pos="0 0.079582 0" quat="0.707107 0.707107 0 0" type="cylinder"/>
        <geom name="//unnamed_geom_44" class="reward_collision_sphere" size="0.0567891" pos="0 0.0696342 0"/>
        <body name="RL_thigh" pos="-0.000146872 0.0943711 -0.000967737" quat="1 -3.65795e-05 -1.44506e-06 3.04202e-05">
          <inertial pos="-0.00368287 -0.0217831 -0.0294105" quat="0.829867 0.0855701 -0.0199392 0.550999" mass="0.964116" diaginertia="0.00534336 0.00564488 0.000416479"/>
          <joint name="RL_thigh_joint" pos="0 0 0" axis="-9.39611e-05 1 9.19906e-05" stiffness="0.000246325" range="-0.528863 4.53017" armature="0.00930417" damping="0.0112279" frictionloss="0.187527"/>
          <geom name="//unnamed_geom_45" class="visual" material="metal" mesh="thigh_0"/>
          <geom name="//unnamed_geom_46" class="visual" material="gray" mesh="thigh_1"/>
          <geom name="//unnamed_geom_47" class="collision" size="0.100801 0.0115944 0.0160903" pos="0 0 -0.0919311" quat="0.707107 0 0.707107 0" type="box"/>
          <body name="RL_calf" pos="0.00121206 -0.00142645 -0.183517" quat="1 0.000143152 -7.76518e-05 0.000136307">
            <inertial pos="0.00525558 0.000480058 -0.122775" quat="0.711004 0.00169238 -0.00616981 0.703159" mass="0.205962" diaginertia="0.00135826 0.00141602 2.54983e-05"/>
            <joint name="RL_calf_joint" pos="0 0 0" axis="-0.00613702 0.999933 0.00978296" range="-2.72053 -0.837236" armature="0.00962231" damping="0.00078461" frictionloss="0.1808"/>
            <geom name="//unnamed_geom_48" class="visual" material="gray" mesh="calf_0"/>
            <geom name="//unnamed_geom_49" class="visual" material="black" mesh="calf_1"/>
            <geom name="RL_calf0" class="collision" size="0.0123043 0.0567891" pos="0.00981479 0 -0.0517921" quat="0.995004 0 -0.0998334 0" type="cylinder"/>
            <geom name="//unnamed_geom_51" class="collision" size="0.0104113 0.0307608" pos="0.0196296 0 -0.127754" quat="0.999688 0 0.0249974 0" type="cylinder"/>
            <geom name="//unnamed_geom_52" class="visual" pos="0 0 -0.183862" quat="1 0 0 0" material="black" mesh="foot"/>
            <geom name="RL_foot" class="foot" size="0.0186375" pos="-0.00196296 0 -0.183862"/>
            <geom name="//unnamed_geom_54" class="reward_collision_sphere" size="0.0236621"/>
            <geom name="//unnamed_geom_55" class="reward_collision_sphere" size="0.0236621" pos="-0.00196296 0 -0.183862"/>
            <site name="RL_foot" class="foot" pos="-0.00196296 0 -0.183862" size="0.00946485"/>
          </body>
        </body>
      </body>
      <body name="RR_hip" pos="-0.189945 -0.0469989 -0.00170356" quat="1 -7.67542e-05 4.94237e-05 -0.000248923">
        <inertial pos="0.00514822 -0.00186602 0.000747889" quat="0.499299 0.496851 0.498456 0.505353" mass="0.563716" diaginertia="0.000791255 0.000570309 0.00022728"/>
        <joint name="RR_hip_joint" pos="0 0 0" axis="-0.999992 -0.00169765 0.00367302" range="-1.05649 1.05473" armature="0.00991227" damping="0.00348467" frictionloss="0.187092"/>
        <geom name="//unnamed_geom_56" class="visual" pos="1.03084e-09 1.1462e-09 -2.51141e-07" quat="2.14617e-09 4.63268e-05 4.63268e-05 -1" material="metal" mesh="hip_0"/>
        <geom name="//unnamed_geom_57" class="visual" pos="1.66923e-09 1.85813e-09 -5.75268e-08" quat="2.14617e-09 4.63268e-05 4.63268e-05 -1" material="gray" mesh="hip_1"/>
        <geom name="//unnamed_geom_58" class="collision" size="0.0435383 0.0189297" pos="0 -0.079582 0" quat="0.707107 0.707107 0 0" type="cylinder"/>
        <geom name="//unnamed_geom_59" class="reward_collision_sphere" size="0.0567891" pos="0 -0.0696342 0"/>
        <body name="RR_thigh" pos="0.000631607 -0.0952023 -0.000769168" quat="1 2.88798e-06 6.6868e-06 2.71284e-06">
          <inertial pos="-0.00263068 0.0215754 -0.0282752" quat="0.551387 -0.0203919 0.085061 0.829651" mass="0.983039" diaginertia="0.00538708 0.0057115 0.000420811"/>
          <joint name="RR_thigh_joint" pos="0 0 0" axis="0.0017433 -0.999945 0.0103283" range="-4.54979 0.529281" armature="0.00936207" damping="0.0130978" frictionloss="0.191198"/>
          <geom name="//unnamed_geom_60" class="visual" material="metal" mesh="thigh_mirror_0"/>
          <geom name="//unnamed_geom_61" class="visual" material="gray" mesh="thigh_mirror_1"/>
          <geom name="//unnamed_geom_62" class="collision" size="0.100801 0.0115944 0.0160903" pos="0 0 -0.0919311" quat="0.707107 0 0.707107 0" type="box"/>
          <body name="RR_calf" pos="0.00165641 -8.07188e-05 -0.184531" quat="1 -3.92893e-05 6.31132e-05 -6.94707e-05">
            <inertial pos="0.00581904 0.000606507 -0.122174" quat="0.702319 -0.00365378 0.000940611 0.711853" mass="0.208219" diaginertia="0.00136277 0.00144324 2.56336e-05"/>
            <joint name="RR_calf_joint" pos="0 0 0" axis="-0.00427251 -0.999971 0.00636673" range="0.833444 2.70817" armature="0.00978465" damping="0.00523061" frictionloss="0.188205"/>
            <geom name="//unnamed_geom_63" class="visual" material="gray" mesh="calf_mirror_0"/>
            <geom name="//unnamed_geom_64" class="visual" material="black" mesh="calf_mirror_1"/>
            <geom name="RR_calf0" class="collision" size="0.0123043 0.0567891" pos="0.00981479 0 -0.0517921" quat="0.995004 0 -0.0998334 0" type="cylinder"/>
            <geom name="//unnamed_geom_66" class="collision" size="0.0104113 0.0307608" pos="0.0196296 0 -0.127754" quat="0.999688 0 0.0249974 0" type="cylinder"/>
            <geom name="//unnamed_geom_67" class="visual" pos="0 0 -0.183862" quat="1 0 0 0" material="black" mesh="foot"/>
            <geom name="RR_foot" class="foot" size="0.0228124" pos="-0.00196296 0 -0.183862"/>
            <geom name="//unnamed_geom_69" class="reward_collision_sphere" size="0.0236621"/>
            <geom name="//unnamed_geom_70" class="reward_collision_sphere" size="0.0236621" pos="-0.00196296 0 -0.183862"/>
            <site name="RR_foot" class="foot" pos="-0.00196296 0 -0.183862" size="0.00946485"/>
          </body>
        </body>
      </body>
    </body>
  </worldbody>

  <contact>
    <pair class="/" geom1="floor" geom2="FL_foot" name="//unnamed_contact_0"/>
    <pair class="/" geom1="floor" geom2="FR_foot" name="//unnamed_contact_1"/>
    <pair class="/" geom1="floor" geom2="RL_foot" name="//unnamed_contact_2"/>
    <pair class="/" geom1="floor" geom2="RR_foot" name="//unnamed_contact_3"/>
  </contact>

  <actuator>
    <general name="FL_hip" class="/" joint="FL_hip_joint" forcerange="-22.7359 22.7359" gainprm="19.0068" biasprm="0 -19.0068 -0.47231"/>
    <general name="FL_thigh" class="/" joint="FL_thigh_joint" forcerange="-22.4705 22.4705" gainprm="19.0068" biasprm="0 -19.0068 -0.47231"/>
    <general name="FL_calf" class="/" joint="FL_calf_joint" forcerange="-42.3194 42.3194" gainprm="19.0068" biasprm="0 -19.0068 -0.47231"/>
    <general name="FR_hip" class="/" joint="FR_hip_joint" forcerange="-22.319 22.319" gainprm="19.0068" biasprm="0 -19.0068 -0.47231"/>
    <general name="FR_thigh" class="/" joint="FR_thigh_joint" forcerange="-21.6121 21.6121" gainprm="19.0068" biasprm="0 -19.0068 -0.47231"/>
    <general name="FR_calf" class="/" joint="FR_calf_joint" forcerange="-45.1452 45.1452" gainprm="19.0068" biasprm="0 -19.0068 -0.47231"/>
    <general name="RL_hip" class="/" joint="RL_hip_joint" forcerange="-22.8601 22.8601" gainprm="19.0068" biasprm="0 -19.0068 -0.47231"/>
    <general name="RL_thigh" class="/" joint="RL_thigh_joint" forcerange="-21.7704 21.7704" gainprm="19.0068" biasprm="0 -19.0068 -0.47231"/>
    <general name="RL_calf" class="/" joint="RL_calf_joint" forcerange="-42.3739 42.3739" gainprm="19.0068" biasprm="0 -19.0068 -0.47231"/>
    <general name="RR_hip" class="/" joint="RR_hip_joint" forcerange="-22.6754 22.6754" gainprm="19.0068" biasprm="0 -19.0068 -0.47231"/>
    <general name="RR_thigh" class="/" joint="RR_thigh_joint" forcerange="-21.5333 21.5333" gainprm="19.0068" biasprm="0 -19.0068 -0.47231"/>
    <general name="RR_calf" class="/" joint="RR_calf_joint" forcerange="-43.7263 43.7263" gainprm="19.0068" biasprm="0 -19.0068 -0.47231"/>
  </actuator>

  <sensor>
    <gyro site="imu" name="imu_angular_velocity"/>
    <velocimeter site="imu" name="imu_linear_velocity"/>
    <framelinvel objtype="site" objname="FL_foot" name="FL_foot_global_linear_velocity"/>
    <framelinvel objtype="site" objname="FR_foot" name="FR_foot_global_linear_velocity"/>
    <framelinvel objtype="site" objname="RL_foot" name="RL_foot_global_linear_velocity"/>
    <framelinvel objtype="site" objname="RR_foot" name="RR_foot_global_linear_velocity"/>
  </sensor>

  <keyframe>
    <key name="home" qpos="0 0 0.325 1 0 0 0 0.1 0.8 -1.5 -0.1 -0.8 1.5 -0.1 0.8 -1.5 0.1 -0.8 1.5"/>
  </keyframe>
</mujoco>
