<mujoco model="go2">
  <compiler angle="radian" assetdir="assets" balanceinertia="true" inertiafromgeom="false"/>

  <option timestep="0.005" density="1.2" viscosity="2e-05"/>

  <size nkey="1"/>

  <visual>
    <quality shadowsize="8192"/>
    <map shadowclip="0.5"/>
  </visual>

  <default>
    <default class="/">
      <geom contype="0" conaffinity="0" group="1" solref="-1000 -80"/>
      <site size="0.01 0.005 0.005" group="5"/>
      <general forcelimited="true" biastype="affine" gainprm="20" biasprm="0 -20 -0.5"/>
      <default class="go2">
        <joint armature="0.01" damping="0.01" frictionloss="0.2"/>
        <geom condim="1" margin="0.001"/>
        <default class="visual">
          <geom type="mesh" group="2"/>
        </default>
        <default class="collision">
          <geom group="3"/>
          <default class="foot">
            <geom size="0.022 0 0" condim="6" priority="1" friction="0.8 0.02 0.01" solimp="0.015 1 0.022"/>
          </default>
        </default>
        <default class="reward_collision_sphere">
          <geom group="5" rgba="1 0 0 1"/>
        </default>
      </default>
    </default>
  </default>

  <asset>
    <texture type="skybox" colorspace="auto" name="//unnamed_texture_0" builtin="gradient" rgb1="0.95 0.95 0.95" rgb2="0.95 0.95 0.95" width="100" height="600"/>
    <texture type="2d" colorspace="auto" name="texplane" builtin="checker" rgb1="0.345 0.575 0.748" rgb2="0.345 0.575 0.748" markrgb="1 1 1" width="512" height="512"/>
    <material name="MatPlane" class="/" texture="texplane" texuniform="true" texrepeat="2 2" specular="0.9"/>
    <material name="metal" class="/" rgba="0.9 0.95 0.95 1"/>
    <material name="black" class="/" rgba="0 0 0 1"/>
    <material name="white" class="/"/>
    <material name="gray" class="/" rgba="0.671705 0.692426 0.77427 1"/>
    <mesh name="base_0" class="/" file="base_0.obj"/>
    <mesh name="base_1" class="/" file="base_1.obj"/>
    <mesh name="base_2" class="/" file="base_2.obj"/>
    <mesh name="base_3" class="/" file="base_3.obj"/>
    <mesh name="base_4" class="/" file="base_4.obj"/>
    <mesh name="hip_0" class="/" file="hip_0.obj"/>
    <mesh name="hip_1" class="/" file="hip_1.obj"/>
    <mesh name="thigh_0" class="/" file="thigh_0.obj"/>
    <mesh name="thigh_1" class="/" file="thigh_1.obj"/>
    <mesh name="thigh_mirror_0" class="/" file="thigh_mirror_0.obj"/>
    <mesh name="thigh_mirror_1" class="/" file="thigh_mirror_1.obj"/>
    <mesh name="calf_0" class="/" file="calf_0.obj"/>
    <mesh name="calf_1" class="/" file="calf_1.obj"/>
    <mesh name="calf_mirror_0" class="/" file="calf_mirror_0.obj"/>
    <mesh name="calf_mirror_1" class="/" file="calf_mirror_1.obj"/>
    <mesh name="foot" class="/" file="foot.obj"/>
  </asset>

  <worldbody>
    <geom name="floor" class="/" size="100 100 0.125" type="plane" group="0" material="MatPlane"/>
    <light name="toplight_shadow" class="/" pos="0 0 5" dir="0.0990148 0.0990148 -0.990148" type="directional" ambient="0.04 0.04 0.04" diffuse="0.55 0.55 0.55" specular="0.12 0.12 0.12"/>
    <light name="toplight_fill" class="/" pos="0 0 5" dir="0.0990148 0.0990148 -0.990148" type="directional" castshadow="false" ambient="0.04 0.04 0.04" diffuse="0.3 0.3 0.3" specular="0.08 0.08 0.08"/>
    <body name="trunk" childclass="go2" pos="-0.00153118 -0.000354061 -0.000120461" quat="1 0.000212731 -0.000350236 -0.000296486">
      <inertial pos="0.0194822 0.000161301 -0.00412028" quat="-0.00198983 0.720646 -0.00235777 0.693296" mass="4.81092" diaginertia="0.0797485 0.0531338 0.0107026"/>
      <joint name="//unnamed_joint_0" type="free" armature="0" damping="0" frictionloss="0"/>
      <geom name="//unnamed_geom_1" class="visual" material="black" mesh="base_0"/>
      <geom name="//unnamed_geom_2" class="visual" material="black" mesh="base_1"/>
      <geom name="//unnamed_geom_3" class="visual" material="black" mesh="base_2"/>
      <geom name="//unnamed_geom_4" class="visual" material="white" mesh="base_3"/>
      <geom name="//unnamed_geom_5" class="visual" material="gray" mesh="base_4"/>
      <geom name="trunk_1" class="collision" size="0.167294 0.0415789 0.0506951" type="box"/>
      <geom name="trunk_2" class="collision" size="0.0444694 0.0400225" pos="0.267652 0 0.00844441" type="cylinder"/>
      <geom name="trunk_3" class="collision" size="0.0418012" pos="0.275165 0 -0.0506665"/>
      <geom name="//unnamed_geom_9" class="reward_collision_sphere" size="0.0889388"/>
      <geom name="//unnamed_geom_10" class="reward_collision_sphere" size="0.0533633" pos="0.262957 0 -0.0379999"/>
      <site name="imu" pos="-0.0216707 -0.0131293 0.039763" size="0.00889388"/>
      <camera name="track" pos="0 -1.76918 0" quat="0.707107 0.707107 0 0" mode="trackcom"/>
      <camera name="ego_camera" pos="0.293009 0 0.0379999" quat="-0.5 -0.5 0.5 0.5"/>
      <body name="FL_hip" pos="0.180923 0.0422908 0.00111941" quat="0.999999 0.000689578 0.00128767 -3.34716e-05">
        <inertial pos="-0.00519001 0.00232672 0.000930597" quat="0.493933 0.494222 0.509142 0.502542" mass="0.492274" diaginertia="0.000667551 0.000332302 0.000213234"/>
        <joint name="FL_hip_joint" pos="0 0 0" axis="0.999958 -0.00600426 0.00689899" range="-0.99751 1.05307" armature="0.00972638" damping="0.00126638" frictionloss="0.182011"/>
        <geom name="//unnamed_geom_11" class="visual" material="metal" mesh="hip_0"/>
        <geom name="//unnamed_geom_12" class="visual" material="gray" mesh="hip_1"/>
        <geom name="//unnamed_geom_13" class="collision" size="0.0409119 0.0177878" pos="0 0.0707673 0" quat="0.707107 0.707107 0 0" type="cylinder"/>
        <geom name="//unnamed_geom_14" class="reward_collision_sphere" size="0.0533633" pos="0 0.0619214 0"/>
        <body name="FL_thigh" pos="-0.00118727 0.0852261 0.00142231" quat="1 -7.37825e-05 3.33023e-05 4.34187e-05">
          <inertial pos="-0.00376156 -0.0220907 -0.0301766" quat="0.82854 0.0845517 -0.0152174 0.553299" mass="0.823097" diaginertia="0.00434104 0.00316966 0.000376115"/>
          <joint name="FL_thigh_joint" pos="0 0 0" axis="-0.00102177 0.999999 0.000453981" stiffness="0.000738598" range="-1.56741 3.54293" armature="0.00881565" damping="0" frictionloss="0.17855"/>
          <geom name="//unnamed_geom_15" class="visual" material="metal" mesh="thigh_0"/>
          <geom name="//unnamed_geom_16" class="visual" material="gray" mesh="thigh_1"/>
          <geom name="//unnamed_geom_17" class="collision" size="0.0947198 0.010895 0.0151196" pos="0 0 -0.089933" quat="0.707107 0 0.707107 0" type="box"/>
          <body name="FL_calf" pos="0.00235094 0.00239401 -0.178562" quat="1 0.000131995 9.69848e-05 -2.48921e-05">
            <inertial pos="0.00706185 -0.000675471 -0.117705" quat="0.711143 0.00152069 -0.00458153 0.70303" mass="0.175393" diaginertia="0.00110865 0.000803573 2.28939e-05"/>
            <joint name="FL_calf_joint" pos="0 0 0" axis="0.00139175 0.999992 -0.003686" range="-2.70127 -0.883908" armature="0.00876747" damping="0" frictionloss="0.178983"/>
            <geom name="//unnamed_geom_18" class="visual" material="gray" mesh="calf_0"/>
            <geom name="//unnamed_geom_19" class="visual" material="black" mesh="calf_1"/>
            <geom name="FL_calf0" class="collision" size="0.0106727 0.0533633" pos="0.00751305 0 -0.0506665" quat="0.994493 0 -0.104807 0" type="cylinder"/>
            <geom name="//unnamed_geom_21" class="collision" size="0.00978327 0.0289051" pos="0.0187826 0 -0.124977" quat="0.999688 0 0.0249974 0" type="cylinder"/>
            <geom name="//unnamed_geom_22" class="visual" pos="0 0 -0.179866" quat="1 0 0 0" material="black" mesh="foot"/>
            <geom name="FL_foot" class="foot" size="0.0168952" pos="-0.00187826 0 -0.179866"/>
            <geom name="//unnamed_geom_24" class="reward_collision_sphere" size="0.0222347"/>
            <geom name="//unnamed_geom_25" class="reward_collision_sphere" size="0.0222347" pos="-0.00187826 0 -0.179866"/>
            <site name="FL_foot" class="foot" pos="-0.00187826 0 -0.179866" size="0.00889388"/>
          </body>
        </body>
      </body>
      <body name="FR_hip" pos="0.182585 -0.0401981 0.00290898" quat="1 -0.000202945 -0.00018414 -0.000124577">
        <inertial pos="-0.00381293 -0.00289124 0.000280416" quat="0.498154 0.495197 0.502847 0.503753" mass="0.492359" diaginertia="0.000664871 0.000331274 0.000210826"/>
        <joint name="FR_hip_joint" pos="0 0 0" axis="0.999994 -0.00124867 0.00323027" range="-1.01451 1.05906" armature="0.00895503" damping="0.0127464" frictionloss="0.169874"/>
        <geom name="//unnamed_geom_26" class="visual" pos="0 3.49773e-10 1.50025e-08" quat="4.63268e-05 1 0 0" material="metal" mesh="hip_0"/>
        <geom name="//unnamed_geom_27" class="visual" pos="0 5.67025e-10 -3.71069e-08" quat="4.63268e-05 1 0 0" material="gray" mesh="hip_1"/>
        <geom name="//unnamed_geom_28" class="collision" size="0.0409119 0.0177878" pos="0 -0.0707673 0" quat="0.707107 0.707107 0 0" type="cylinder"/>
        <geom name="//unnamed_geom_29" class="reward_collision_sphere" size="0.0533633" pos="0 -0.0619214 0"/>
        <body name="FR_thigh" pos="0.000614495 -0.0842899 -0.00128191" quat="1 0.000421669 -0.00010959 0.000287261">
          <inertial pos="-0.00317892 0.0197344 -0.0301469" quat="0.550543 -0.00861521 0.0908838 0.8298" mass="0.8263" diaginertia="0.0044728 0.00326684 0.000389749"/>
          <joint name="FR_thigh_joint" pos="0 0 0" axis="0.00122014 -0.999993 0.00363409" stiffness="0.00126373" range="-3.54271 1.60936" armature="0.00806136" damping="0.0129895" frictionloss="0.169125"/>
          <geom name="//unnamed_geom_30" class="visual" material="metal" mesh="thigh_mirror_0"/>
          <geom name="//unnamed_geom_31" class="visual" material="gray" mesh="thigh_mirror_1"/>
          <geom name="//unnamed_geom_32" class="collision" size="0.0947198 0.010895 0.0151196" pos="0 0 -0.089933" quat="0.707107 0 0.707107 0" type="box"/>
          <body name="FR_calf" pos="-0.000468665 0.000322239 -0.179804" quat="1 2.08804e-05 0.000109283 2.4927e-05">
            <inertial pos="0.00500674 0.000701164 -0.116982" quat="0.704546 -0.00367839 0.00239093 0.709645" mass="0.160392" diaginertia="0.00104643 0.000792242 2.13858e-05"/>
            <joint name="FR_calf_joint" pos="0 0 0" axis="-0.00227078 -0.999981 0.00565032" stiffness="0.00259653" range="0.836083 2.71916" armature="0.00967233" damping="0.013772" frictionloss="0.17781"/>
            <geom name="//unnamed_geom_33" class="visual" material="gray" mesh="calf_mirror_0"/>
            <geom name="//unnamed_geom_34" class="visual" material="black" mesh="calf_mirror_1"/>
            <geom name="FR_calf0" class="collision" size="0.011562 0.0533633" pos="0.00939131 0 -0.0506665" quat="0.995004 0 -0.0998334 0" type="cylinder"/>
            <geom name="//unnamed_geom_36" class="collision" size="0.00978327 0.0289051" pos="0.0187826 0 -0.124977" quat="0.999688 0 0.0249974 0" type="cylinder"/>
            <geom name="//unnamed_geom_37" class="visual" pos="0 0 -0.179866" quat="1 0 0 0" material="black" mesh="foot"/>
            <geom name="FR_foot" class="foot" size="0.0214818" pos="-0.00187826 0 -0.179866"/>
            <geom name="//unnamed_geom_39" class="reward_collision_sphere" size="0.0222347"/>
            <geom name="//unnamed_geom_40" class="reward_collision_sphere" size="0.0222347" pos="-0.00187826 0 -0.179866"/>
            <site name="FR_foot" class="foot" pos="-0.00187826 0 -0.179866" size="0.00889388"/>
          </body>
        </body>
      </body>
      <body name="RL_hip" pos="-0.180551 0.0408211 -0.00182495" quat="1 -1.87103e-05 -0.000206638 0.000166637">
        <inertial pos="0.00482737 0.00210754 -0.00230082" quat="0.50471 0.498479 0.497857 0.498924" mass="0.492517" diaginertia="0.000665388 0.000318072 0.000207353"/>
        <joint name="RL_hip_joint" pos="0 0 0" axis="-0.99976 0.0212384 0.00536658" range="-0.994614 1.09596" armature="0.00894808" damping="0" frictionloss="0.200005"/>
        <geom name="//unnamed_geom_41" class="visual" pos="-8.24897e-10 0 -1.61699e-07" quat="4.63268e-05 0 1 0" material="metal" mesh="hip_0"/>
        <geom name="//unnamed_geom_42" class="visual" pos="-1.33726e-09 0 -1.43404e-07" quat="4.63268e-05 0 1 0" material="gray" mesh="hip_1"/>
        <geom name="//unnamed_geom_43" class="collision" size="0.0409119 0.0177878" pos="0 0.0707673 0" quat="0.707107 0.707107 0 0" type="cylinder"/>
        <geom name="//unnamed_geom_44" class="reward_collision_sphere" size="0.0533633" pos="0 0.0619214 0"/>
        <body name="RL_thigh" pos="0.000690339 0.0851242 -0.000890383" quat="1 1.00154e-05 -6.45645e-06 -4.93167e-07">
          <inertial pos="-0.00587998 -0.0195441 -0.0303157" quat="0.83631 0.0840236 -0.0186363 0.54146" mass="0.81291" diaginertia="0.00417946 0.00315871 0.000363196"/>
          <joint name="RL_thigh_joint" pos="0 0 0" axis="0.0118388 0.99989 0.0088946" stiffness="0.00394111" range="-0.572546 4.55864" armature="0.0085814" damping="0.00379019" frictionloss="0.178781"/>
          <geom name="//unnamed_geom_45" class="visual" material="metal" mesh="thigh_0"/>
          <geom name="//unnamed_geom_46" class="visual" material="gray" mesh="thigh_1"/>
          <geom name="//unnamed_geom_47" class="collision" size="0.0947198 0.010895 0.0151196" pos="0 0 -0.089933" quat="0.707107 0 0.707107 0" type="box"/>
          <body name="RL_calf" pos="-0.000597744 -0.00160312 -0.182098" quat="1 -3.82818e-05 7.62039e-05 7.48294e-05">
            <inertial pos="0.0063303 -0.00126198 -0.118203" quat="0.714742 0.00534681 0.00298986 0.699361" mass="0.165577" diaginertia="0.00108473 0.000784385 2.29923e-05"/>
            <joint name="RL_calf_joint" pos="0 0 0" axis="0.00949837 0.999954 -0.000993345" range="-2.74265 -0.835811" armature="0.00893985" damping="0.000400401" frictionloss="0.18405"/>
            <geom name="//unnamed_geom_48" class="visual" material="gray" mesh="calf_0"/>
            <geom name="//unnamed_geom_49" class="visual" material="black" mesh="calf_1"/>
            <geom name="RL_calf0" class="collision" size="0.011562 0.0533633" pos="0.00939131 0 -0.0506665" quat="0.995004 0 -0.0998334 0" type="cylinder"/>
            <geom name="//unnamed_geom_51" class="collision" size="0.00978327 0.0289051" pos="0.0187826 0 -0.124977" quat="0.999688 0 0.0249974 0" type="cylinder"/>
            <geom name="//unnamed_geom_52" class="visual" pos="0 0 -0.179866" quat="1 0 0 0" material="black" mesh="foot"/>
            <geom name="RL_foot" class="foot" size="0.017953" pos="-0.00187826 0 -0.179866"/>
            <geom name="//unnamed_geom_54" class="reward_collision_sphere" size="0.0222347"/>
            <geom name="//unnamed_geom_55" class="reward_collision_sphere" size="0.0222347" pos="-0.00187826 0 -0.179866"/>
            <site name="RL_foot" class="foot" pos="-0.00187826 0 -0.179866" size="0.00889388"/>
          </body>
        </body>
      </body>
      <body name="RR_hip" pos="-0.181588 -0.0414349 -0.000305768" quat="1 0.000111454 6.14668e-06 -0.000106837">
        <inertial pos="0.00523458 0.000789872 -0.00172962" quat="0.499282 0.496992 0.498231 0.505453" mass="0.459232" diaginertia="0.000629391 0.000315351 0.000199047"/>
        <joint name="RR_hip_joint" pos="0 0 0" axis="-1 -0.000807423 6.32875e-05" range="-1.05843 1.00621" armature="0.00873154" damping="0" frictionloss="0.170519"/>
        <geom name="//unnamed_geom_56" class="visual" pos="8.23009e-10 3.49773e-10 -1.76701e-07" quat="2.14617e-09 4.63268e-05 4.63268e-05 -1" material="metal" mesh="hip_0"/>
        <geom name="//unnamed_geom_57" class="visual" pos="1.34193e-09 5.67025e-10 -1.06297e-07" quat="2.14617e-09 4.63268e-05 4.63268e-05 -1" material="gray" mesh="hip_1"/>
        <geom name="//unnamed_geom_58" class="collision" size="0.0409119 0.0177878" pos="0 -0.0707673 0" quat="0.707107 0.707107 0 0" type="cylinder"/>
        <geom name="//unnamed_geom_59" class="reward_collision_sphere" size="0.0533633" pos="0 -0.0619214 0"/>
        <body name="RR_thigh" pos="-0.000870252 -0.0856932 0.00169937" quat="1 -0.000203888 -0.000401318 -0.000103864">
          <inertial pos="-0.00428517 0.0214864 -0.0276538" quat="0.551493 -0.0193452 0.0855308 0.829558" mass="0.767765" diaginertia="0.00421776 0.00307073 0.000376779"/>
          <joint name="RR_thigh_joint" pos="0 0 0" axis="0.00719657 -0.999973 -0.001309" stiffness="0.00536027" range="-4.58925 0.573414" armature="0.0091311" damping="0.0114249" frictionloss="0.158452"/>
          <geom name="//unnamed_geom_60" class="visual" material="metal" mesh="thigh_mirror_0"/>
          <geom name="//unnamed_geom_61" class="visual" material="gray" mesh="thigh_mirror_1"/>
          <geom name="//unnamed_geom_62" class="collision" size="0.0947198 0.010895 0.0151196" pos="0 0 -0.089933" quat="0.707107 0 0.707107 0" type="box"/>
          <body name="RR_calf" pos="0.00315691 -0.00140807 -0.180744" quat="1 0.000289195 0.000142855 0.000189175">
            <inertial pos="0.00483263 0.000599076 -0.119761" quat="0.702874 -0.00609412 0.000124411 0.711288" mass="0.163453" diaginertia="0.00108411 0.00077706 2.26099e-05"/>
            <joint name="RR_calf_joint" pos="0 0 0" axis="0.000281917 -0.999997 -0.00226508" range="0.831045 2.73782" armature="0.00897088" damping="0.00331746" frictionloss="0.177045"/>
            <geom name="//unnamed_geom_63" class="visual" material="gray" mesh="calf_mirror_0"/>
            <geom name="//unnamed_geom_64" class="visual" material="black" mesh="calf_mirror_1"/>
            <geom name="RR_calf0" class="collision" size="0.011562 0.0533633" pos="0.00939131 0 -0.0506665" quat="0.995004 0 -0.0998334 0" type="cylinder"/>
            <geom name="//unnamed_geom_66" class="collision" size="0.00978327 0.0289051" pos="0.0187826 0 -0.124977" quat="0.999688 0 0.0249974 0" type="cylinder"/>
            <geom name="//unnamed_geom_67" class="visual" pos="0 0 -0.179866" quat="1 0 0 0" material="black" mesh="foot"/>
            <geom name="RR_foot" class="foot" size="0.0227023" pos="-0.00187826 0 -0.179866"/>
            <geom name="//unnamed_geom_69" class="reward_collision_sphere" size="0.0222347"/>
            <geom name="//unnamed_geom_70" class="reward_collision_sphere" size="0.0222347" pos="-0.00187826 0 -0.179866"/>
            <site name="RR_foot" class="foot" pos="-0.00187826 0 -0.179866" size="0.00889388"/>
          </body>
        </body>
      </body>
    </body>
  </worldbody>

  <contact>
    <pair class="/" geom1="floor" geom2="FL_foot" name="//unnamed_contact_0"/>
    <pair class="/" geom1="floor" geom2="FR_foot" name="//unnamed_contact_1"/>
    <pair class="/" geom1="floor" geom2="RL_foot" name="//unnamed_contact_2"/>
    <pair class="/" geom1="floor" geom2="RR_foot" name="//unnamed_contact_3"/>
  </contact>

  <actuator>
    <general name="FL_hip" class="/" joint="FL_hip_joint" forcerange="-20.6698 20.6698" gainprm="18.2859" biasprm="0 -18.2859 -0.471491"/>
    <general name="FL_thigh" class="/" joint="FL_thigh_joint" forcerange="-22.9335 22.9335" gainprm="18.2859" biasprm="0 -18.2859 -0.471491"/>
    <general name="FL_calf" class="/" joint="FL_calf_joint" forcerange="-36.5277 36.5277" gainprm="18.2859" biasprm="0 -18.2859 -0.471491"/>
    <general name="FR_hip" class="/" joint="FR_hip_joint" forcerange="-21.2119 21.2119" gainprm="18.2859" biasprm="0 -18.2859 -0.471491"/>
    <general name="FR_thigh" class="/" joint="FR_thigh_joint" forcerange="-21.5882 21.5882" gainprm="18.2859" biasprm="0 -18.2859 -0.471491"/>
    <general name="FR_calf" class="/" joint="FR_calf_joint" forcerange="-43.6947 43.6947" gainprm="18.2859" biasprm="0 -18.2859 -0.471491"/>
    <general name="RL_hip" class="/" joint="RL_hip_joint" forcerange="-23.0438 23.0438" gainprm="18.2859" biasprm="0 -18.2859 -0.471491"/>
    <general name="RL_thigh" class="/" joint="RL_thigh_joint" forcerange="-21.1674 21.1674" gainprm="18.2859" biasprm="0 -18.2859 -0.471491"/>
    <general name="RL_calf" class="/" joint="RL_calf_joint" forcerange="-41.2632 41.2632" gainprm="18.2859" biasprm="0 -18.2859 -0.471491"/>
    <general name="RR_hip" class="/" joint="RR_hip_joint" forcerange="-20.6665 20.6665" gainprm="18.2859" biasprm="0 -18.2859 -0.471491"/>
    <general name="RR_thigh" class="/" joint="RR_thigh_joint" forcerange="-19.0136 19.0136" gainprm="18.2859" biasprm="0 -18.2859 -0.471491"/>
    <general name="RR_calf" class="/" joint="RR_calf_joint" forcerange="-37.3275 37.3275" gainprm="18.2859" biasprm="0 -18.2859 -0.471491"/>
  </actuator>

  <sensor>
    <gyro site="imu" name="imu_angular_velocity"/>
    <velocimeter site="imu" name="imu_linear_velocity"/>
    <framelinvel objtype="site" objname="FL_foot" name="FL_foot_global_linear_velocity"/>
    <framelinvel objtype="site" objname="FR_foot" name="FR_foot_global_linear_velocity"/>
    <framelinvel objtype="site" objname="RL_foot" name="RL_foot_global_linear_velocity"/>
    <framelinvel objtype="site" objname="RR_foot" name="RR_foot_global_linear_velocity"/>
  </sensor>

  <keyframe>
    <key name="home" qpos="0 0 0.325 1 0 0 0 0.1 0.8 -1.5 -0.1 -0.8 1.5 -0.1 0.8 -1.5 0.1 -0.8 1.5"/>
  </keyframe>
</mujoco>
