<mujoco model="go2">
  <compiler angle="radian" assetdir="assets" balanceinertia="true" inertiafromgeom="false"/>

  <option timestep="0.005" density="1.2" viscosity="2e-05"/>

  <size nkey="1"/>

  <visual>
    <quality shadowsize="8192"/>
    <map shadowclip="0.5"/>
  </visual>

  <default>
    <default class="/">
      <geom contype="0" conaffinity="0" group="1" solref="-1000 -80"/>
      <site size="0.01 0.005 0.005" group="5"/>
      <general forcelimited="true" biastype="affine" gainprm="20" biasprm="0 -20 -0.5"/>
      <default class="go2">
        <joint armature="0.01" damping="0.01" frictionloss="0.2"/>
        <geom condim="1" margin="0.001"/>
        <default class="visual">
          <geom type="mesh" group="2"/>
        </default>
        <default class="collision">
          <geom group="3"/>
          <default class="foot">
            <geom size="0.022 0 0" condim="6" priority="1" friction="0.8 0.02 0.01" solimp="0.015 1 0.022"/>
          </default>
        </default>
        <default class="reward_collision_sphere">
          <geom group="5" rgba="1 0 0 1"/>
        </default>
      </default>
    </default>
  </default>

  <asset>
    <texture type="skybox" colorspace="auto" name="//unnamed_texture_0" builtin="gradient" rgb1="0.95 0.95 0.95" rgb2="0.95 0.95 0.95" width="100" height="600"/>
    <texture type="2d" colorspace="auto" name="texplane" builtin="checker" rgb1="0.345 0.575 0.748" rgb2="0.345 0.575 0.748" markrgb="1 1 1" width="512" height="512"/>
    <material name="MatPlane" class="/" texture="texplane" texuniform="true" texrepeat="2 2" specular="0.9"/>
    <material name="metal" class="/" rgba="0.9 0.95 0.95 1"/>
    <material name="black" class="/" rgba="0 0 0 1"/>
    <material name="white" class="/"/>
    <material name="gray" class="/" rgba="0.671705 0.692426 0.77427 1"/>
    <mesh name="base_0" class="/" file="base_0.obj"/>
    <mesh name="base_1" class="/" file="base_1.obj"/>
    <mesh name="base_2" class="/" file="base_2.obj"/>
    <mesh name="base_3" class="/" file="base_3.obj"/>
    <mesh name="base_4" class="/" file="base_4.obj"/>
    <mesh name="hip_0" class="/" file="hip_0.obj"/>
    <mesh name="hip_1" class="/" file="hip_1.obj"/>
    <mesh name="thigh_0" class="/" file="thigh_0.obj"/>
    <mesh name="thigh_1" class="/" file="thigh_1.obj"/>
    <mesh name="thigh_mirror_0" class="/" file="thigh_mirror_0.obj"/>
    <mesh name="thigh_mirror_1" class="/" file="thigh_mirror_1.obj"/>
    <mesh name="calf_0" class="/" file="calf_0.obj"/>
    <mesh name="calf_1" class="/" file="calf_1.obj"/>
    <mesh name="calf_mirror_0" class="/" file="calf_mirror_0.obj"/>
    <mesh name="calf_mirror_1" class="/" file="calf_mirror_1.obj"/>
    <mesh name="foot" class="/" file="foot.obj"/>
  </asset>

  <worldbody>
    <geom name="floor" class="/" size="100 100 0.125" type="plane" group="0" material="MatPlane"/>
    <light name="toplight_shadow" class="/" pos="0 0 5" dir="0.0990148 0.0990148 -0.990148" type="directional" ambient="0.04 0.04 0.04" diffuse="0.55 0.55 0.55" specular="0.12 0.12 0.12"/>
    <light name="toplight_fill" class="/" pos="0 0 5" dir="0.0990148 0.0990148 -0.990148" type="directional" castshadow="false" ambient="0.04 0.04 0.04" diffuse="0.3 0.3 0.3" specular="0.08 0.08 0.08"/>
    <body name="trunk" childclass="go2" pos="0.0103736 -0.00258757 0.00777722" quat="0.999989 0.00444406 -0.000551208 -0.00134486">
      <inertial pos="0.0361733 -0.00828329 -0.00676093" quat="-0.017726 0.672921 0.00291216 0.739496" mass="13.512" diaginertia="0.347658 0.420809 0.0379982"/>
      <joint name="//unnamed_joint_0" type="free" armature="0" damping="0" frictionloss="0"/>
      <geom name="//unnamed_geom_1" class="visual" material="black" mesh="base_0"/>
      <geom name="//unnamed_geom_2" class="visual" material="black" mesh="base_1"/>
      <geom name="//unnamed_geom_3" class="visual" material="black" mesh="base_2"/>
      <geom name="//unnamed_geom_4" class="visual" material="white" mesh="base_3"/>
      <geom name="//unnamed_geom_5" class="visual" material="gray" mesh="base_4"/>
      <geom name="trunk_1" class="collision" size="0.240235 0.0597075 0.0727985" type="box"/>
      <geom name="trunk_2" class="collision" size="0.0638583 0.0574725" pos="0.380818 0 0.0115548" type="cylinder"/>
      <geom name="trunk_3" class="collision" size="0.0600268" pos="0.391508 0 -0.069329"/>
      <geom name="//unnamed_geom_9" class="reward_collision_sphere" size="0.127717"/>
      <geom name="//unnamed_geom_10" class="reward_collision_sphere" size="0.07663" pos="0.374137 0 -0.0519968"/>
      <site name="imu" pos="-0.0760885 0.0781507 0.0783934" size="0.0127717"/>
      <camera name="track" pos="0 -2.67962 0" quat="0.707107 0.707107 0 0" mode="trackcom"/>
      <camera name="ego_camera" pos="0.416896 0 0.0519968" quat="-0.5 -0.5 0.5 0.5"/>
      <body name="FL_hip" pos="0.257802 0.0642574 0.00659452" quat="0.999971 0.00483241 0.00334688 -0.00483184">
        <inertial pos="0.000731494 0.00168314 0.00444183" quat="0.475983 0.487205 0.550105 0.483173" mass="1.16027" diaginertia="0.00313819 0.00215167 0.000736624"/>
        <joint name="FL_hip_joint" pos="0 0 0" axis="0.999121 -0.0383441 0.0169227" stiffness="0.0221939" range="-1.31765 1.01546" armature="0.00531476" damping="0.00572091" frictionloss="0.290521"/>
        <geom name="//unnamed_geom_11" class="visual" material="metal" mesh="hip_0"/>
        <geom name="//unnamed_geom_12" class="visual" material="gray" mesh="hip_1"/>
        <geom name="//unnamed_geom_13" class="collision" size="0.0587497 0.0255433" pos="0 0.107185 0" quat="0.707107 0.707107 0 0" type="cylinder"/>
        <geom name="//unnamed_geom_14" class="reward_collision_sphere" size="0.07663" pos="0 0.0937868 0"/>
        <body name="FL_thigh" pos="-7.79403e-05 0.131819 0.00501475" quat="1 -0.00055463 0.000215123 0.000567706">
          <inertial pos="-0.00437586 -0.0162128 -0.0221026" quat="0.827286 0.0908034 0.00340987 0.554384" mass="2.46862" diaginertia="0.0241218 0.0275462 0.00171539"/>
          <joint name="FL_thigh_joint" pos="0 0 0" axis="-0.0096693 0.999873 -0.0126877" range="-1.5506 3.19025" armature="0.0182708" damping="0.0865793" frictionloss="0.248955"/>
          <geom name="//unnamed_geom_15" class="visual" material="metal" mesh="thigh_0"/>
          <geom name="//unnamed_geom_16" class="visual" material="gray" mesh="thigh_1"/>
          <geom name="//unnamed_geom_17" class="collision" size="0.136018 0.0156453 0.0217118" pos="0 0 -0.123059" quat="0.707107 0 0.707107 0" type="box"/>
          <body name="FL_calf" pos="-0.0159038 -0.0144397 -0.25622" quat="1 -3.05625e-05 -1.62609e-05 -7.52934e-06">
            <inertial pos="0.0133982 0.00762539 -0.173309" quat="0.713448 0.00511792 -0.00432268 0.700676" mass="0.417904" diaginertia="0.00555535 0.00664226 0.000111062"/>
            <joint name="FL_calf_joint" pos="0 0 0" axis="-0.00775214 0.999881 -0.0133132" stiffness="0.0753784" range="-2.9185 -0.58235" armature="0.0138658" damping="0" frictionloss="0.28427"/>
            <geom name="//unnamed_geom_18" class="visual" material="gray" mesh="calf_0"/>
            <geom name="//unnamed_geom_19" class="visual" material="black" mesh="calf_1"/>
            <geom name="FL_calf0" class="collision" size="0.015326 0.07663" pos="0.0106896 0 -0.069329" quat="0.994493 0 -0.104807 0" type="cylinder"/>
            <geom name="//unnamed_geom_21" class="collision" size="0.0140488 0.0415079" pos="0.0267241 0 -0.171012" quat="0.999688 0 0.0249974 0" type="cylinder"/>
            <geom name="//unnamed_geom_22" class="visual" pos="0 0 -0.246118" quat="1 0 0 0" material="black" mesh="foot"/>
            <geom name="FL_foot" class="foot" size="0.0431034" pos="-0.00267241 0 -0.246118"/>
            <geom name="//unnamed_geom_24" class="reward_collision_sphere" size="0.0319292"/>
            <geom name="//unnamed_geom_25" class="reward_collision_sphere" size="0.0319292" pos="-0.00267241 0 -0.246118"/>
            <site name="FL_foot" class="foot" pos="-0.00267241 0 -0.246118" size="0.0127717"/>
          </body>
        </body>
      </body>
      <body name="FR_hip" pos="0.250907 -0.0701762 -0.0140564" quat="1 -2.09253e-05 3.73543e-05 6.84549e-05">
        <inertial pos="-0.00265091 0.00732849 -0.000262336" quat="0.444273 0.497178 0.533884 0.520003" mass="1.14641" diaginertia="0.00340612 0.00194123 0.000779781"/>
        <joint name="FR_hip_joint" pos="0 0 0" axis="0.999988 -0.00300545 -0.0039832" range="-1.26079 1.02353" armature="0.013286" damping="0.000519926" frictionloss="0.18407"/>
        <geom name="//unnamed_geom_26" class="visual" pos="0 1.60579e-09 6.88755e-08" quat="4.63268e-05 1 0 0" material="metal" mesh="hip_0"/>
        <geom name="//unnamed_geom_27" class="visual" pos="0 2.60317e-09 -1.70355e-07" quat="4.63268e-05 1 0 0" material="gray" mesh="hip_1"/>
        <geom name="//unnamed_geom_28" class="collision" size="0.0587497 0.0255433" pos="0 -0.107185 0" quat="0.707107 0.707107 0 0" type="cylinder"/>
        <geom name="//unnamed_geom_29" class="reward_collision_sphere" size="0.07663" pos="0 -0.0937868 0"/>
        <body name="FR_thigh" pos="-0.00737119 -0.127254 0.0114862" quat="0.999997 0.000633169 -0.000605919 0.00246944">
          <inertial pos="-0.00493474 0.0307799 -0.0234236" quat="0.551411 0.0541857 0.0563518 0.830563" mass="1.84966" diaginertia="0.0229822 0.0209183 0.0015017"/>
          <joint name="FR_thigh_joint" pos="0 0 0" axis="-0.00272787 -0.999983 -0.00512893" stiffness="0.0233348" range="-3.20967 1.34111" armature="0.0195575" damping="0.0157024" frictionloss="0.205537"/>
          <geom name="//unnamed_geom_30" class="visual" material="metal" mesh="thigh_mirror_0"/>
          <geom name="//unnamed_geom_31" class="visual" material="gray" mesh="thigh_mirror_1"/>
          <geom name="//unnamed_geom_32" class="collision" size="0.136018 0.0156453 0.0217118" pos="0 0 -0.123059" quat="0.707107 0 0.707107 0" type="box"/>
          <body name="FR_calf" pos="-0.0021974 -0.00134555 -0.245789" quat="1 0.000131761 -0.000388983 0.000165854">
            <inertial pos="0.00503171 0.000707615 -0.179385" quat="0.675002 -0.0125724 0.010801 0.73763" mass="0.687758" diaginertia="0.00698801 0.00611846 0.000153232"/>
            <joint name="FR_calf_joint" pos="0 0 0" axis="-0.018352 -0.99967 0.0180013" stiffness="0.0306001" range="0.84077 2.88395" armature="0.00599575" damping="0.00911805" frictionloss="0.253819"/>
            <geom name="//unnamed_geom_33" class="visual" material="gray" mesh="calf_mirror_0"/>
            <geom name="//unnamed_geom_34" class="visual" material="black" mesh="calf_mirror_1"/>
            <geom name="FR_calf0" class="collision" size="0.0166032 0.07663" pos="0.013362 0 -0.069329" quat="0.995004 0 -0.0998334 0" type="cylinder"/>
            <geom name="//unnamed_geom_36" class="collision" size="0.0140488 0.0415079" pos="0.0267241 0 -0.171012" quat="0.999688 0 0.0249974 0" type="cylinder"/>
            <geom name="//unnamed_geom_37" class="visual" pos="0 0 -0.246118" quat="1 0 0 0" material="black" mesh="foot"/>
            <geom name="FR_foot" class="foot" size="0.0217812" pos="-0.00267241 0 -0.246118"/>
            <geom name="//unnamed_geom_39" class="reward_collision_sphere" size="0.0319292"/>
            <geom name="//unnamed_geom_40" class="reward_collision_sphere" size="0.0319292" pos="-0.00267241 0 -0.246118"/>
            <site name="FR_foot" class="foot" pos="-0.00267241 0 -0.246118" size="0.0127717"/>
          </body>
        </body>
      </body>
      <body name="RL_hip" pos="-0.255158 0.0697243 0.0136796" quat="1 0.000228509 0.000609233 -6.24129e-05">
        <inertial pos="0.00768344 0.00397617 0.0133206" quat="0.50362 0.503214 0.487873 0.505097" mass="1.20707" diaginertia="0.00325978 0.00296795 0.00099783"/>
        <joint name="RL_hip_joint" pos="0 0 0" axis="-0.999923 0.00586856 0.0109336" range="-1.35219 0.781217" armature="0.0123162" damping="0.0537983" frictionloss="0.0858032"/>
        <geom name="//unnamed_geom_41" class="visual" pos="-1.57436e-09 0 -3.08611e-07" quat="4.63268e-05 0 1 0" material="metal" mesh="hip_0"/>
        <geom name="//unnamed_geom_42" class="visual" pos="-2.55223e-09 0 -2.73694e-07" quat="4.63268e-05 0 1 0" material="gray" mesh="hip_1"/>
        <geom name="//unnamed_geom_43" class="collision" size="0.0587497 0.0255433" pos="0 0.107185 0" quat="0.707107 0.707107 0 0" type="cylinder"/>
        <geom name="//unnamed_geom_44" class="reward_collision_sphere" size="0.07663" pos="0 0.0937868 0"/>
        <body name="RL_thigh" pos="-0.00112899 0.132229 -0.00343298" quat="1 -0.000110203 9.16273e-06 0.000128898">
          <inertial pos="0.00797097 -0.032838 -0.0222187" quat="0.85247 0.0664134 0.0279893 0.517785" mass="2.28922" diaginertia="0.0273178 0.0230572 0.00193905"/>
          <joint name="RL_thigh_joint" pos="0 0 0" axis="-0.0176112 0.997917 -0.0620635" stiffness="0.0274099" range="-0.259223 4.60696" armature="0.00884549" damping="0" frictionloss="0.252731"/>
          <geom name="//unnamed_geom_45" class="visual" material="metal" mesh="thigh_0"/>
          <geom name="//unnamed_geom_46" class="visual" material="gray" mesh="thigh_1"/>
          <geom name="//unnamed_geom_47" class="collision" size="0.136018 0.0156453 0.0217118" pos="0 0 -0.123059" quat="0.707107 0 0.707107 0" type="box"/>
          <body name="RL_calf" pos="0.00918605 -0.00682377 -0.235238" quat="1 9.41632e-05 -0.000146277 -0.000375729">
            <inertial pos="-0.00011116 0.00812491 -0.173148" quat="0.725626 -0.000802354 0.0488424 0.686354" mass="0.57709" diaginertia="0.00633361 0.00587434 0.000118536"/>
            <joint name="RL_calf_joint" pos="0 0 0" axis="-0.0351837 0.999202 -0.0189106" stiffness="0.0785066" range="-2.83451 -0.829494" armature="0.010527" damping="0.000596083" frictionloss="0.143896"/>
            <geom name="//unnamed_geom_48" class="visual" material="gray" mesh="calf_0"/>
            <geom name="//unnamed_geom_49" class="visual" material="black" mesh="calf_1"/>
            <geom name="RL_calf0" class="collision" size="0.0166032 0.07663" pos="0.013362 0 -0.069329" quat="0.995004 0 -0.0998334 0" type="cylinder"/>
            <geom name="//unnamed_geom_51" class="collision" size="0.0140488 0.0415079" pos="0.0267241 0 -0.171012" quat="0.999688 0 0.0249974 0" type="cylinder"/>
            <geom name="//unnamed_geom_52" class="visual" pos="0 0 -0.246118" quat="1 0 0 0" material="black" mesh="foot"/>
            <geom name="RL_foot" class="foot" size="0.0216227" pos="-0.00267241 0 -0.246118"/>
            <geom name="//unnamed_geom_54" class="reward_collision_sphere" size="0.0319292"/>
            <geom name="//unnamed_geom_55" class="reward_collision_sphere" size="0.0319292" pos="-0.00267241 0 -0.246118"/>
            <site name="RL_foot" class="foot" pos="-0.00267241 0 -0.246118" size="0.0127717"/>
          </body>
        </body>
      </body>
      <body name="RR_hip" pos="-0.257673 -0.0572697 -0.000942984" quat="0.999995 0.00256512 -0.000136145 -0.00167109">
        <inertial pos="0.00715782 -0.0156727 0.010234" quat="0.49897 0.496651 0.498914 0.505423" mass="1.53148" diaginertia="0.00464108 0.00318619 0.00118755"/>
        <joint name="RR_hip_joint" pos="0 0 0" axis="-0.999631 0.00179836 -0.0271001" range="-1.1689 1.28151" armature="0.0176797" damping="0.069317" frictionloss="0.180276"/>
        <geom name="//unnamed_geom_56" class="visual" pos="1.57449e-09 1.60579e-09 -3.77486e-07" quat="2.14617e-09 4.63268e-05 4.63268e-05 -1" material="metal" mesh="hip_0"/>
        <geom name="//unnamed_geom_57" class="visual" pos="2.55192e-09 2.60317e-09 -1.03339e-07" quat="2.14617e-09 4.63268e-05 4.63268e-05 -1" material="gray" mesh="hip_1"/>
        <geom name="//unnamed_geom_58" class="collision" size="0.0587497 0.0255433" pos="0 -0.107185 0" quat="0.707107 0.707107 0 0" type="cylinder"/>
        <geom name="//unnamed_geom_59" class="reward_collision_sphere" size="0.07663" pos="0 -0.0937868 0"/>
        <body name="RR_thigh" pos="-0.00336267 -0.125736 -0.0139939" quat="1 0.000442748 -0.000212441 -8.60835e-05">
          <inertial pos="0.00418274 0.0194438 -0.0375624" quat="0.552599 -0.0241238 0.0813884 0.829113" mass="3.1658" diaginertia="0.026516 0.0296105 0.00177481"/>
          <joint name="RR_thigh_joint" pos="0 0 0" axis="-0.018037 -0.99953 -0.0247991" range="-4.25767 0.260022" armature="0.0121142" damping="0.00175648" frictionloss="0.408918"/>
          <geom name="//unnamed_geom_60" class="visual" material="metal" mesh="thigh_mirror_0"/>
          <geom name="//unnamed_geom_61" class="visual" material="gray" mesh="thigh_mirror_1"/>
          <geom name="//unnamed_geom_62" class="collision" size="0.136018 0.0156453 0.0217118" pos="0 0 -0.123059" quat="0.707107 0 0.707107 0" type="box"/>
          <body name="RR_calf" pos="-0.0143032 0.00217788 -0.248709" quat="0.999999 0.000193946 -0.000224234 -0.00146682">
            <inertial pos="0.00269416 0.000195256 -0.164617" quat="0.701329 -0.0174329 0.00529848 0.712605" mass="0.641317" diaginertia="0.00745804 0.0072276 0.00012121"/>
            <joint name="RR_calf_joint" pos="0 0 0" axis="0.0376589 -0.999119 0.0185027" stiffness="0.0551279" range="0.887897 2.5494" armature="0.0170658" damping="0.0766749" frictionloss="0.252614"/>
            <geom name="//unnamed_geom_63" class="visual" material="gray" mesh="calf_mirror_0"/>
            <geom name="//unnamed_geom_64" class="visual" material="black" mesh="calf_mirror_1"/>
            <geom name="RR_calf0" class="collision" size="0.0166032 0.07663" pos="0.013362 0 -0.069329" quat="0.995004 0 -0.0998334 0" type="cylinder"/>
            <geom name="//unnamed_geom_66" class="collision" size="0.0140488 0.0415079" pos="0.0267241 0 -0.171012" quat="0.999688 0 0.0249974 0" type="cylinder"/>
            <geom name="//unnamed_geom_67" class="visual" pos="0 0 -0.246118" quat="1 0 0 0" material="black" mesh="foot"/>
            <geom name="RR_foot" class="foot" size="0.03194" pos="-0.00267241 0 -0.246118"/>
            <geom name="//unnamed_geom_69" class="reward_collision_sphere" size="0.0319292"/>
            <geom name="//unnamed_geom_70" class="reward_collision_sphere" size="0.0319292" pos="-0.00267241 0 -0.246118"/>
            <site name="RR_foot" class="foot" pos="-0.00267241 0 -0.246118" size="0.0127717"/>
          </body>
        </body>
      </body>
    </body>
  </worldbody>

  <contact>
    <pair class="/" geom1="floor" geom2="FL_foot" name="//unnamed_contact_0"/>
    <pair class="/" geom1="floor" geom2="FR_foot" name="//unnamed_contact_1"/>
    <pair class="/" geom1="floor" geom2="RL_foot" name="//unnamed_contact_2"/>
    <pair class="/" geom1="floor" geom2="RR_foot" name="//unnamed_contact_3"/>
  </contact>

  <actuator>
    <general name="FL_hip" class="/" joint="FL_hip_joint" forcerange="-26.739 26.739" gainprm="29.0829" biasprm="0 -29.0829 -0.432634"/>
    <general name="FL_thigh" class="/" joint="FL_thigh_joint" forcerange="-16.2862 16.2862" gainprm="29.0829" biasprm="0 -29.0829 -0.432634"/>
    <general name="FL_calf" class="/" joint="FL_calf_joint" forcerange="-87.2417 87.2417" gainprm="29.0829" biasprm="0 -29.0829 -0.432634"/>
    <general name="FR_hip" class="/" joint="FR_hip_joint" forcerange="-28.56 28.56" gainprm="29.0829" biasprm="0 -29.0829 -0.432634"/>
    <general name="FR_thigh" class="/" joint="FR_thigh_joint" forcerange="-20.0633 20.0633" gainprm="29.0829" biasprm="0 -29.0829 -0.432634"/>
    <general name="FR_calf" class="/" joint="FR_calf_joint" forcerange="-23.1398 23.1398" gainprm="29.0829" biasprm="0 -29.0829 -0.432634"/>
    <general name="RL_hip" class="/" joint="RL_hip_joint" forcerange="-14.8192 14.8192" gainprm="29.0829" biasprm="0 -29.0829 -0.432634"/>
    <general name="RL_thigh" class="/" joint="RL_thigh_joint" forcerange="-21.808 21.808" gainprm="29.0829" biasprm="0 -29.0829 -0.432634"/>
    <general name="RL_calf" class="/" joint="RL_calf_joint" forcerange="-59.0316 59.0316" gainprm="29.0829" biasprm="0 -29.0829 -0.432634"/>
    <general name="RR_hip" class="/" joint="RR_hip_joint" forcerange="-30.5484 30.5484" gainprm="29.0829" biasprm="0 -29.0829 -0.432634"/>
    <general name="RR_thigh" class="/" joint="RR_thigh_joint" forcerange="-47.5908 47.5908" gainprm="29.0829" biasprm="0 -29.0829 -0.432634"/>
    <general name="RR_calf" class="/" joint="RR_calf_joint" forcerange="-83.351 83.351" gainprm="29.0829" biasprm="0 -29.0829 -0.432634"/>
  </actuator>

  <sensor>
    <gyro site="imu" name="imu_angular_velocity"/>
    <velocimeter site="imu" name="imu_linear_velocity"/>
    <framelinvel objtype="site" objname="FL_foot" name="FL_foot_global_linear_velocity"/>
    <framelinvel objtype="site" objname="FR_foot" name="FR_foot_global_linear_velocity"/>
    <framelinvel objtype="site" objname="RL_foot" name="RL_foot_global_linear_velocity"/>
    <framelinvel objtype="site" objname="RR_foot" name="RR_foot_global_linear_velocity"/>
  </sensor>

  <keyframe>
    <key name="home" qpos="0 0 0.325 1 0 0 0 0.1 0.8 -1.5 -0.1 -0.8 1.5 -0.1 0.8 -1.5 0.1 -0.8 1.5"/>
  </keyframe>
</mujoco>
