<mujoco model="go2">
  <compiler angle="radian" assetdir="assets" balanceinertia="true" inertiafromgeom="false"/>

  <option timestep="0.005" density="1.2" viscosity="2e-05"/>

  <size nkey="1"/>

  <visual>
    <quality shadowsize="8192"/>
    <map shadowclip="0.5"/>
  </visual>

  <default>
    <default class="/">
      <geom contype="0" conaffinity="0" group="1" solref="-1000 -80"/>
      <site size="0.01 0.005 0.005" group="5"/>
      <general forcelimited="true" biastype="affine" gainprm="20" biasprm="0 -20 -0.5"/>
      <default class="go2">
        <joint armature="0.01" damping="0.01" frictionloss="0.2"/>
        <geom condim="1" margin="0.001"/>
        <default class="visual">
          <geom type="mesh" group="2"/>
        </default>
        <default class="collision">
          <geom group="3"/>
          <default class="foot">
            <geom size="0.022 0 0" condim="6" priority="1" friction="0.8 0.02 0.01" solimp="0.015 1 0.022"/>
          </default>
        </default>
        <default class="reward_collision_sphere">
          <geom group="5" rgba="1 0 0 1"/>
        </default>
      </default>
    </default>
  </default>

  <asset>
    <texture type="skybox" colorspace="auto" name="//unnamed_texture_0" builtin="gradient" rgb1="0.95 0.95 0.95" rgb2="0.95 0.95 0.95" width="100" height="600"/>
    <texture type="2d" colorspace="auto" name="texplane" builtin="checker" rgb1="0.345 0.575 0.748" rgb2="0.345 0.575 0.748" markrgb="1 1 1" width="512" height="512"/>
    <material name="MatPlane" class="/" texture="texplane" texuniform="true" texrepeat="2 2" specular="0.9"/>
    <material name="metal" class="/" rgba="0.9 0.95 0.95 1"/>
    <material name="black" class="/" rgba="0 0 0 1"/>
    <material name="white" class="/"/>
    <material name="gray" class="/" rgba="0.671705 0.692426 0.77427 1"/>
    <mesh name="base_0" class="/" file="base_0.obj"/>
    <mesh name="base_1" class="/" file="base_1.obj"/>
    <mesh name="base_2" class="/" file="base_2.obj"/>
    <mesh name="base_3" class="/" file="base_3.obj"/>
    <mesh name="base_4" class="/" file="base_4.obj"/>
    <mesh name="hip_0" class="/" file="hip_0.obj"/>
    <mesh name="hip_1" class="/" file="hip_1.obj"/>
    <mesh name="thigh_0" class="/" file="thigh_0.obj"/>
    <mesh name="thigh_1" class="/" file="thigh_1.obj"/>
    <mesh name="thigh_mirror_0" class="/" file="thigh_mirror_0.obj"/>
    <mesh name="thigh_mirror_1" class="/" file="thigh_mirror_1.obj"/>
    <mesh name="calf_0" class="/" file="calf_0.obj"/>
    <mesh name="calf_1" class="/" file="calf_1.obj"/>
    <mesh name="calf_mirror_0" class="/" file="calf_mirror_0.obj"/>
    <mesh name="calf_mirror_1" class="/" file="calf_mirror_1.obj"/>
    <mesh name="foot" class="/" file="foot.obj"/>
  </asset>

  <worldbody>
    <geom name="floor" class="/" size="100 100 0.125" type="plane" group="0" material="MatPlane"/>
    <light name="toplight_shadow" class="/" pos="0 0 5" dir="0.0990148 0.0990148 -0.990148" type="directional" ambient="0.04 0.04 0.04" diffuse="0.55 0.55 0.55" specular="0.12 0.12 0.12"/>
    <light name="toplight_fill" class="/" pos="0 0 5" dir="0.0990148 0.0990148 -0.990148" type="directional" castshadow="false" ambient="0.04 0.04 0.04" diffuse="0.3 0.3 0.3" specular="0.08 0.08 0.08"/>
    <body name="trunk" childclass="go2" pos="0.00532113 0.000634828 -0.00663233" quat="0.999992 0.00141452 0.00211093 0.00302745">
      <inertial pos="0.0414286 0.0133775 0.00284565" quat="-0.0212134 0.718216 -0.0110643 0.695409" mass="5.22297" diaginertia="0.240051 0.0472516 0.013777"/>
      <joint name="//unnamed_joint_0" type="free" armature="0" damping="0" frictionloss="0"/>
      <geom name="//unnamed_geom_1" class="visual" material="black" mesh="base_0"/>
      <geom name="//unnamed_geom_2" class="visual" material="black" mesh="base_1"/>
      <geom name="//unnamed_geom_3" class="visual" material="black" mesh="base_2"/>
      <geom name="//unnamed_geom_4" class="visual" material="white" mesh="base_3"/>
      <geom name="//unnamed_geom_5" class="visual" material="gray" mesh="base_4"/>
      <geom name="trunk_1" class="collision" size="0.185216 0.0460331 0.0561259" type="box"/>
      <geom name="trunk_2" class="collision" size="0.0492333 0.0443099" pos="0.336426 0 0.00906137" type="cylinder"/>
      <geom name="trunk_3" class="collision" size="0.0462793" pos="0.34587 0 -0.0543682"/>
      <geom name="//unnamed_geom_9" class="reward_collision_sphere" size="0.0984665"/>
      <geom name="//unnamed_geom_10" class="reward_collision_sphere" size="0.0590799" pos="0.330524 0 -0.0407761"/>
      <site name="imu" pos="-0.102941 -0.00395549 0.110824" size="0.00984665"/>
      <camera name="track" pos="0 -1.73483 0" quat="0.707107 0.707107 0 0" mode="trackcom"/>
      <camera name="ego_camera" pos="0.368298 0 0.0407761" quat="-0.5 -0.5 0.5 0.5"/>
      <body name="FL_hip" pos="0.240222 0.0527595 0.0114979" quat="0.999999 -0.00103613 -0.000318107 -0.00119137">
        <inertial pos="-0.00640198 0.0134467 0.00218078" quat="0.493812 0.501403 0.507272 0.497413" mass="0.69576" diaginertia="0.00243241 0.000408163 0.000357088"/>
        <joint name="FL_hip_joint" pos="0 0 0" axis="0.999567 0.0286791 -0.00655785" stiffness="0.0525428" range="-1.06071 0.895853" armature="0.00927818" damping="0" frictionloss="0.301021"/>
        <geom name="//unnamed_geom_11" class="visual" material="metal" mesh="hip_0"/>
        <geom name="//unnamed_geom_12" class="visual" material="gray" mesh="hip_1"/>
        <geom name="//unnamed_geom_13" class="collision" size="0.0452946 0.0196933" pos="0 0.0693933 0" quat="0.707107 0.707107 0 0" type="cylinder"/>
        <geom name="//unnamed_geom_14" class="reward_collision_sphere" size="0.0590799" pos="0 0.0607191 0"/>
        <body name="FL_thigh" pos="0.00932696 0.0674946 -0.00841619" quat="0.999976 0.00575922 0.00092193 0.00381132">
          <inertial pos="-0.00551046 -0.0200161 -0.0387054" quat="0.857023 0.049843 -0.0282243 0.512085" mass="1.2879" diaginertia="0.013886 0.0035371 0.000511337"/>
          <joint name="FL_thigh_joint" pos="0 0 0" axis="0.0219721 0.999693 0.0114944" stiffness="0.00612311" range="-1.84092 3.28147" armature="0.012352" damping="0" frictionloss="0.288913"/>
          <geom name="//unnamed_geom_15" class="visual" material="metal" mesh="thigh_0"/>
          <geom name="//unnamed_geom_16" class="visual" material="gray" mesh="thigh_1"/>
          <geom name="//unnamed_geom_17" class="collision" size="0.104867 0.0120621 0.0167393" pos="0 0 -0.0965036" quat="0.707107 0 0.707107 0" type="box"/>
          <body name="FL_calf" pos="-0.000151125 -0.0138796 -0.188346" quat="0.999997 -0.00219748 0.00103055 -0.000352715">
            <inertial pos="0.00746784 -0.00501811 -0.119875" quat="0.709647 -0.000520263 -0.00301071 0.704551" mass="0.242341" diaginertia="0.00415998 0.000730428 3.21507e-05"/>
            <joint name="FL_calf_joint" pos="0 0 0" axis="-0.012232 0.999915 -0.0045418" stiffness="0.0656766" range="-2.93052 -0.84501" armature="0.0069773" damping="0" frictionloss="0.192996"/>
            <geom name="//unnamed_geom_18" class="visual" material="gray" mesh="calf_0"/>
            <geom name="//unnamed_geom_19" class="visual" material="black" mesh="calf_1"/>
            <geom name="FL_calf0" class="collision" size="0.011816 0.0590799" pos="0.00944354 0 -0.0543682" quat="0.994493 0 -0.104807 0" type="cylinder"/>
            <geom name="//unnamed_geom_21" class="collision" size="0.0108313 0.0320016" pos="0.0236089 0 -0.134108" quat="0.999688 0 0.0249974 0" type="cylinder"/>
            <geom name="//unnamed_geom_22" class="visual" pos="0 0 -0.193007" quat="1 0 0 0" material="black" mesh="foot"/>
            <geom name="FL_foot" class="foot" size="0.0216729" pos="-0.00236089 0 -0.193007"/>
            <geom name="//unnamed_geom_24" class="reward_collision_sphere" size="0.0246166"/>
            <geom name="//unnamed_geom_25" class="reward_collision_sphere" size="0.0246166" pos="-0.00236089 0 -0.193007"/>
            <site name="FL_foot" class="foot" pos="-0.00236089 0 -0.193007" size="0.00984665"/>
          </body>
        </body>
      </body>
      <body name="FR_hip" pos="0.243183 -0.0481716 0.00463176" quat="1 -0.000475744 -5.39072e-05 0.000433111">
        <inertial pos="0.00373448 0.0150749 0.0103182" quat="0.466116 0.463423 0.555954 0.508813" mass="0.632823" diaginertia="0.0022249 0.000228546 0.000319916"/>
        <joint name="FR_hip_joint" pos="0 0 0" axis="0.998096 -0.0587946 0.0186431" range="-1.12294 1.02864" armature="0.00907252" damping="0.0605938" frictionloss="0.128806"/>
        <geom name="//unnamed_geom_26" class="visual" pos="0 -3.3732e-10 -1.44684e-08" quat="4.63268e-05 1 0 0" material="metal" mesh="hip_0"/>
        <geom name="//unnamed_geom_27" class="visual" pos="0 -5.46837e-10 3.57858e-08" quat="4.63268e-05 1 0 0" material="gray" mesh="hip_1"/>
        <geom name="//unnamed_geom_28" class="collision" size="0.0452946 0.0196933" pos="0 -0.0693933 0" quat="0.707107 0.707107 0 0" type="cylinder"/>
        <geom name="//unnamed_geom_29" class="reward_collision_sphere" size="0.0590799" pos="0 -0.0607191 0"/>
        <body name="FR_thigh" pos="-0.00897572 -0.0739464 0.0128644" quat="0.999979 0.0024747 0.00489289 -0.00337196">
          <inertial pos="-0.0190589 0.0253403 -0.020289" quat="0.527405 0.000128411 0.119125 0.841222" mass="0.982483" diaginertia="0.0161734 0.00350303 0.00046192"/>
          <joint name="FR_thigh_joint" pos="0 0 0" axis="0.0140751 -0.999634 -0.0230946" stiffness="0.00437229" range="-3.62312 1.65758" armature="0.0144225" damping="0" frictionloss="0.12256"/>
          <geom name="//unnamed_geom_30" class="visual" material="metal" mesh="thigh_mirror_0"/>
          <geom name="//unnamed_geom_31" class="visual" material="gray" mesh="thigh_mirror_1"/>
          <geom name="//unnamed_geom_32" class="collision" size="0.104867 0.0120621 0.0167393" pos="0 0 -0.0965036" quat="0.707107 0 0.707107 0" type="box"/>
          <body name="FR_calf" pos="0.00961394 -0.00391567 -0.197157" quat="0.999989 -0.00439749 0.000776061 0.00141299">
            <inertial pos="0.0193318 0.000411414 -0.128351" quat="0.696476 0.00511911 -0.0750107 0.71363" mass="0.172227" diaginertia="0.00262879 0.000671246 2.76536e-05"/>
            <joint name="FR_calf_joint" pos="0 0 0" axis="-0.00706841 -0.999879 0.0138245" stiffness="0.0720206" range="1.13483 2.91716" armature="0.00318432" damping="0" frictionloss="0.118603"/>
            <geom name="//unnamed_geom_33" class="visual" material="gray" mesh="calf_mirror_0"/>
            <geom name="//unnamed_geom_34" class="visual" material="black" mesh="calf_mirror_1"/>
            <geom name="FR_calf0" class="collision" size="0.0128006 0.0590799" pos="0.0118044 0 -0.0543682" quat="0.995004 0 -0.0998334 0" type="cylinder"/>
            <geom name="//unnamed_geom_36" class="collision" size="0.0108313 0.0320016" pos="0.0236089 0 -0.134108" quat="0.999688 0 0.0249974 0" type="cylinder"/>
            <geom name="//unnamed_geom_37" class="visual" pos="0 0 -0.193007" quat="1 0 0 0" material="black" mesh="foot"/>
            <geom name="FR_foot" class="foot" size="0.0313962" pos="-0.00236089 0 -0.193007"/>
            <geom name="//unnamed_geom_39" class="reward_collision_sphere" size="0.0246166"/>
            <geom name="//unnamed_geom_40" class="reward_collision_sphere" size="0.0246166" pos="-0.00236089 0 -0.193007"/>
            <site name="FR_foot" class="foot" pos="-0.00236089 0 -0.193007" size="0.00984665"/>
          </body>
        </body>
      </body>
      <body name="RL_hip" pos="-0.241954 0.0512501 0.0133338" quat="1 0.000107828 -0.000249276 0.000607016">
        <inertial pos="0.00526339 -0.00913094 0.0152016" quat="0.553421 0.499392 0.474419 0.468252" mass="0.523628" diaginertia="0.00130196 0.000252093 0.000265297"/>
        <joint name="RL_hip_joint" pos="0 0 0" axis="-0.998101 -0.0269498 -0.055395" stiffness="0.0378077" range="-1.04292 0.913739" armature="0.0105215" damping="0.0779326" frictionloss="0.192549"/>
        <geom name="//unnamed_geom_41" class="visual" pos="-2.38964e-09 0 -4.68425e-07" quat="4.63268e-05 0 1 0" material="metal" mesh="hip_0"/>
        <geom name="//unnamed_geom_42" class="visual" pos="-3.8739e-09 0 -4.15427e-07" quat="4.63268e-05 0 1 0" material="gray" mesh="hip_1"/>
        <geom name="//unnamed_geom_43" class="collision" size="0.0452946 0.0196933" pos="0 0.0693933 0" quat="0.707107 0.707107 0 0" type="cylinder"/>
        <geom name="//unnamed_geom_44" class="reward_collision_sphere" size="0.0590799" pos="0 0.0607191 0"/>
        <body name="RL_thigh" pos="-0.000440841 0.0904206 -0.00795972" quat="0.999994 0.00227485 0.00252132 0.000762347">
          <inertial pos="0.0120715 -0.025841 -0.0143306" quat="0.829491 0.0841487 -0.0193989 0.551803" mass="1.36692" diaginertia="0.0186089 0.00281552 0.000557814"/>
          <joint name="RL_thigh_joint" pos="0 0 0" axis="-0.00188132 0.99999 0.0040869" range="-0.350479 4.74708" armature="0.0076398" damping="0.0664514" frictionloss="0.189054"/>
          <geom name="//unnamed_geom_45" class="visual" material="metal" mesh="thigh_0"/>
          <geom name="//unnamed_geom_46" class="visual" material="gray" mesh="thigh_1"/>
          <geom name="//unnamed_geom_47" class="collision" size="0.104867 0.0120621 0.0167393" pos="0 0 -0.0965036" quat="0.707107 0 0.707107 0" type="box"/>
          <body name="RL_calf" pos="0.0072903 -0.00702817 -0.186304" quat="1 0.000515207 0.000692546 -0.000198181">
            <inertial pos="-0.0012514 -0.0141577 -0.121835" quat="0.712187 -0.0327576 -0.0411425 0.700017" mass="0.180492" diaginertia="0.00306508 0.000474245 2.37631e-05"/>
            <joint name="RL_calf_joint" pos="0 0 0" axis="0.00981956 0.999949 0.00243206" range="-2.98752 -0.620414" armature="0.00266327" damping="0" frictionloss="0.322175"/>
            <geom name="//unnamed_geom_48" class="visual" material="gray" mesh="calf_0"/>
            <geom name="//unnamed_geom_49" class="visual" material="black" mesh="calf_1"/>
            <geom name="RL_calf0" class="collision" size="0.0128006 0.0590799" pos="0.0118044 0 -0.0543682" quat="0.995004 0 -0.0998334 0" type="cylinder"/>
            <geom name="//unnamed_geom_51" class="collision" size="0.0108313 0.0320016" pos="0.0236089 0 -0.134108" quat="0.999688 0 0.0249974 0" type="cylinder"/>
            <geom name="//unnamed_geom_52" class="visual" pos="0 0 -0.193007" quat="1 0 0 0" material="black" mesh="foot"/>
            <geom name="RL_foot" class="foot" size="0.015833" pos="-0.00236089 0 -0.193007"/>
            <geom name="//unnamed_geom_54" class="reward_collision_sphere" size="0.0246166"/>
            <geom name="//unnamed_geom_55" class="reward_collision_sphere" size="0.0246166" pos="-0.00236089 0 -0.193007"/>
            <site name="RL_foot" class="foot" pos="-0.00236089 0 -0.193007" size="0.00984665"/>
          </body>
        </body>
      </body>
      <body name="RR_hip" pos="-0.244825 -0.0419684 -0.00750051" quat="1 -9.75057e-05 -0.000904384 -0.000275822">
        <inertial pos="0.0160457 -0.0106999 0.0150559" quat="0.509465 0.530961 0.425009 0.527156" mass="0.654181" diaginertia="0.00245723 0.000350125 0.000348804"/>
        <joint name="RR_hip_joint" pos="0 0 0" axis="-0.997439 -0.014123 0.0701086" range="-0.770853 0.869023" armature="0.0137328" damping="0.0540696" frictionloss="0.200676"/>
        <geom name="//unnamed_geom_56" class="visual" pos="2.37881e-09 -3.3732e-10 -4.53957e-07" quat="2.14617e-09 4.63268e-05 4.63268e-05 -1" material="metal" mesh="hip_0"/>
        <geom name="//unnamed_geom_57" class="visual" pos="3.9007e-09 -5.46837e-10 -4.51212e-07" quat="2.14617e-09 4.63268e-05 4.63268e-05 -1" material="gray" mesh="hip_1"/>
        <geom name="//unnamed_geom_58" class="collision" size="0.0452946 0.0196933" pos="0 -0.0693933 0" quat="0.707107 0.707107 0 0" type="cylinder"/>
        <geom name="//unnamed_geom_59" class="reward_collision_sphere" size="0.0590799" pos="0 -0.0607191 0"/>
        <body name="RR_thigh" pos="-0.0153936 -0.0895034 0.0137592" quat="0.999979 -0.00182241 -0.00606122 0.00120774">
          <inertial pos="-0.00552941 0.00976893 -0.0346304" quat="0.550849 -0.0217816 0.0820516 0.830276" mass="1.41901" diaginertia="0.0176141 0.00332304 0.000628702"/>
          <joint name="RR_thigh_joint" pos="0 0 0" axis="-0.0194267 -0.999801 0.00455369" stiffness="0.0130599" range="-4.73133 0.645077" armature="0.0117842" damping="0" frictionloss="0.193914"/>
          <geom name="//unnamed_geom_60" class="visual" material="metal" mesh="thigh_mirror_0"/>
          <geom name="//unnamed_geom_61" class="visual" material="gray" mesh="thigh_mirror_1"/>
          <geom name="//unnamed_geom_62" class="collision" size="0.104867 0.0120621 0.0167393" pos="0 0 -0.0965036" quat="0.707107 0 0.707107 0" type="box"/>
          <body name="RR_calf" pos="-0.00493191 -0.0123738 -0.189306" quat="0.999973 -0.00360205 -0.00577493 -0.00258953">
            <inertial pos="-0.00506506 0.00842581 -0.133751" quat="0.691428 0.0519921 -0.00803099 0.720528" mass="0.218309" diaginertia="0.00381153 0.000709164 3.61777e-05"/>
            <joint name="RR_calf_joint" pos="0 0 0" axis="0.0263165 -0.99927 0.0276878" range="0.870008 2.44176" armature="0.0106854" damping="0" frictionloss="0.119401"/>
            <geom name="//unnamed_geom_63" class="visual" material="gray" mesh="calf_mirror_0"/>
            <geom name="//unnamed_geom_64" class="visual" material="black" mesh="calf_mirror_1"/>
            <geom name="RR_calf0" class="collision" size="0.0128006 0.0590799" pos="0.0118044 0 -0.0543682" quat="0.995004 0 -0.0998334 0" type="cylinder"/>
            <geom name="//unnamed_geom_66" class="collision" size="0.0108313 0.0320016" pos="0.0236089 0 -0.134108" quat="0.999688 0 0.0249974 0" type="cylinder"/>
            <geom name="//unnamed_geom_67" class="visual" pos="0 0 -0.193007" quat="1 0 0 0" material="black" mesh="foot"/>
            <geom name="RR_foot" class="foot" size="0.0304032" pos="-0.00236089 0 -0.193007"/>
            <geom name="//unnamed_geom_69" class="reward_collision_sphere" size="0.0246166"/>
            <geom name="//unnamed_geom_70" class="reward_collision_sphere" size="0.0246166" pos="-0.00236089 0 -0.193007"/>
            <site name="RR_foot" class="foot" pos="-0.00236089 0 -0.193007" size="0.00984665"/>
          </body>
        </body>
      </body>
    </body>
  </worldbody>

  <contact>
    <pair class="/" geom1="floor" geom2="FL_foot" name="//unnamed_contact_0"/>
    <pair class="/" geom1="floor" geom2="FR_foot" name="//unnamed_contact_1"/>
    <pair class="/" geom1="floor" geom2="RL_foot" name="//unnamed_contact_2"/>
    <pair class="/" geom1="floor" geom2="RR_foot" name="//unnamed_contact_3"/>
  </contact>

  <actuator>
    <general name="FL_hip" class="/" joint="FL_hip_joint" forcerange="-33.8572 33.8572" gainprm="24.3143" biasprm="0 -24.3143 -0.606438"/>
    <general name="FL_thigh" class="/" joint="FL_thigh_joint" forcerange="-36.5616 36.5616" gainprm="24.3143" biasprm="0 -24.3143 -0.606438"/>
    <general name="FL_calf" class="/" joint="FL_calf_joint" forcerange="-55.6053 55.6053" gainprm="24.3143" biasprm="0 -24.3143 -0.606438"/>
    <general name="FR_hip" class="/" joint="FR_hip_joint" forcerange="-22.672 22.672" gainprm="24.3143" biasprm="0 -24.3143 -0.606438"/>
    <general name="FR_thigh" class="/" joint="FR_thigh_joint" forcerange="-13.6622 13.6622" gainprm="24.3143" biasprm="0 -24.3143 -0.606438"/>
    <general name="FR_calf" class="/" joint="FR_calf_joint" forcerange="-52.0234 52.0234" gainprm="24.3143" biasprm="0 -24.3143 -0.606438"/>
    <general name="RL_hip" class="/" joint="RL_hip_joint" forcerange="-23.3789 23.3789" gainprm="24.3143" biasprm="0 -24.3143 -0.606438"/>
    <general name="RL_thigh" class="/" joint="RL_thigh_joint" forcerange="-33.3629 33.3629" gainprm="24.3143" biasprm="0 -24.3143 -0.606438"/>
    <general name="RL_calf" class="/" joint="RL_calf_joint" forcerange="-33.3621 33.3621" gainprm="24.3143" biasprm="0 -24.3143 -0.606438"/>
    <general name="RR_hip" class="/" joint="RR_hip_joint" forcerange="-26.2344 26.2344" gainprm="24.3143" biasprm="0 -24.3143 -0.606438"/>
    <general name="RR_thigh" class="/" joint="RR_thigh_joint" forcerange="-11.7246 11.7246" gainprm="24.3143" biasprm="0 -24.3143 -0.606438"/>
    <general name="RR_calf" class="/" joint="RR_calf_joint" forcerange="-36.9493 36.9493" gainprm="24.3143" biasprm="0 -24.3143 -0.606438"/>
  </actuator>

  <sensor>
    <gyro site="imu" name="imu_angular_velocity"/>
    <velocimeter site="imu" name="imu_linear_velocity"/>
    <framelinvel objtype="site" objname="FL_foot" name="FL_foot_global_linear_velocity"/>
    <framelinvel objtype="site" objname="FR_foot" name="FR_foot_global_linear_velocity"/>
    <framelinvel objtype="site" objname="RL_foot" name="RL_foot_global_linear_velocity"/>
    <framelinvel objtype="site" objname="RR_foot" name="RR_foot_global_linear_velocity"/>
  </sensor>

  <keyframe>
    <key name="home" qpos="0 0 0.325 1 0 0 0 0.1 0.8 -1.5 -0.1 -0.8 1.5 -0.1 0.8 -1.5 0.1 -0.8 1.5"/>
  </keyframe>
</mujoco>
