<mujoco model="go2">
  <compiler angle="radian" assetdir="assets" balanceinertia="true" inertiafromgeom="false"/>

  <option timestep="0.005" density="1.2" viscosity="2e-05"/>

  <size nkey="1"/>

  <visual>
    <quality shadowsize="8192"/>
    <map shadowclip="0.5"/>
  </visual>

  <default>
    <default class="/">
      <geom contype="0" conaffinity="0" group="1" solref="-1000 -80"/>
      <site size="0.01 0.005 0.005" group="5"/>
      <general forcelimited="true" biastype="affine" gainprm="20" biasprm="0 -20 -0.5"/>
      <default class="go2">
        <joint armature="0.01" damping="0.01" frictionloss="0.2"/>
        <geom condim="1" margin="0.001"/>
        <default class="visual">
          <geom type="mesh" group="2"/>
        </default>
        <default class="collision">
          <geom group="3"/>
          <default class="foot">
            <geom size="0.022 0 0" condim="6" priority="1" friction="0.8 0.02 0.01" solimp="0.015 1 0.022"/>
          </default>
        </default>
        <default class="reward_collision_sphere">
          <geom group="5" rgba="1 0 0 1"/>
        </default>
      </default>
    </default>
  </default>

  <asset>
    <texture type="skybox" colorspace="auto" name="//unnamed_texture_0" builtin="gradient" rgb1="0.95 0.95 0.95" rgb2="0.95 0.95 0.95" width="100" height="600"/>
    <texture type="2d" colorspace="auto" name="texplane" builtin="checker" rgb1="0.345 0.575 0.748" rgb2="0.345 0.575 0.748" markrgb="1 1 1" width="512" height="512"/>
    <material name="MatPlane" class="/" texture="texplane" texuniform="true" texrepeat="2 2" specular="0.9"/>
    <material name="metal" class="/" rgba="0.9 0.95 0.95 1"/>
    <material name="black" class="/" rgba="0 0 0 1"/>
    <material name="white" class="/"/>
    <material name="gray" class="/" rgba="0.671705 0.692426 0.77427 1"/>
    <mesh name="base_0" class="/" file="base_0.obj"/>
    <mesh name="base_1" class="/" file="base_1.obj"/>
    <mesh name="base_2" class="/" file="base_2.obj"/>
    <mesh name="base_3" class="/" file="base_3.obj"/>
    <mesh name="base_4" class="/" file="base_4.obj"/>
    <mesh name="hip_0" class="/" file="hip_0.obj"/>
    <mesh name="hip_1" class="/" file="hip_1.obj"/>
    <mesh name="thigh_0" class="/" file="thigh_0.obj"/>
    <mesh name="thigh_1" class="/" file="thigh_1.obj"/>
    <mesh name="thigh_mirror_0" class="/" file="thigh_mirror_0.obj"/>
    <mesh name="thigh_mirror_1" class="/" file="thigh_mirror_1.obj"/>
    <mesh name="calf_0" class="/" file="calf_0.obj"/>
    <mesh name="calf_1" class="/" file="calf_1.obj"/>
    <mesh name="calf_mirror_0" class="/" file="calf_mirror_0.obj"/>
    <mesh name="calf_mirror_1" class="/" file="calf_mirror_1.obj"/>
    <mesh name="foot" class="/" file="foot.obj"/>
  </asset>

  <worldbody>
    <geom name="floor" class="/" size="100 100 0.125" type="plane" group="0" material="MatPlane"/>
    <light name="toplight_shadow" class="/" pos="0 0 5" dir="0.0990148 0.0990148 -0.990148" type="directional" ambient="0.04 0.04 0.04" diffuse="0.55 0.55 0.55" specular="0.12 0.12 0.12"/>
    <light name="toplight_fill" class="/" pos="0 0 5" dir="0.0990148 0.0990148 -0.990148" type="directional" castshadow="false" ambient="0.04 0.04 0.04" diffuse="0.3 0.3 0.3" specular="0.08 0.08 0.08"/>
    <body name="trunk" childclass="go2" pos="0.00249584 0.00107283 -0.00376748" quat="0.999997 -0.000960413 -0.000273665 0.00230006">
      <inertial pos="0.0395901 0.0104488 -0.000618205" quat="-0.00449337 0.713905 0.00716992 0.700191" mass="7.23386" diaginertia="0.311881 0.0821608 0.0252925"/>
      <joint name="//unnamed_joint_0" type="free" armature="0" damping="0" frictionloss="0"/>
      <geom name="//unnamed_geom_1" class="visual" material="black" mesh="base_0"/>
      <geom name="//unnamed_geom_2" class="visual" material="black" mesh="base_1"/>
      <geom name="//unnamed_geom_3" class="visual" material="black" mesh="base_2"/>
      <geom name="//unnamed_geom_4" class="visual" material="white" mesh="base_3"/>
      <geom name="//unnamed_geom_5" class="visual" material="gray" mesh="base_4"/>
      <geom name="trunk_1" class="collision" size="0.201286 0.0500273 0.0609958" type="box"/>
      <geom name="trunk_2" class="collision" size="0.0535051 0.0481546" pos="0.351505 0 0.0100945" type="cylinder"/>
      <geom name="trunk_3" class="collision" size="0.0502948" pos="0.361372 0 -0.060567"/>
      <geom name="//unnamed_geom_9" class="reward_collision_sphere" size="0.10701"/>
      <geom name="//unnamed_geom_10" class="reward_collision_sphere" size="0.0642061" pos="0.345338 0 -0.0454253"/>
      <site name="imu" pos="-0.0895633 0.000836789 0.100467" size="0.010701"/>
      <camera name="track" pos="0 -1.93501 0" quat="0.707107 0.707107 0 0" mode="trackcom"/>
      <camera name="ego_camera" pos="0.384805 0 0.0454253" quat="-0.5 -0.5 0.5 0.5"/>
      <body name="FL_hip" pos="0.247615 0.0545354 0.00916936" quat="1 7.64166e-05 0.000140417 0.000108157">
        <inertial pos="-0.00606357 0.0107142 -0.000356759" quat="0.49885 0.497322 0.505682 0.498101" mass="0.900951" diaginertia="0.00300284 0.000661388 0.000594607"/>
        <joint name="FL_hip_joint" pos="0 0 0" axis="0.999637 0.0156908 0.021911" stiffness="0.0377553" range="-1.04845 0.953731" armature="0.0112762" damping="0" frictionloss="0.295879"/>
        <geom name="//unnamed_geom_11" class="visual" material="metal" mesh="hip_0"/>
        <geom name="//unnamed_geom_12" class="visual" material="gray" mesh="hip_1"/>
        <geom name="//unnamed_geom_13" class="collision" size="0.0492247 0.021402" pos="0 0.0774004 0" quat="0.707107 0.707107 0 0" type="cylinder"/>
        <geom name="//unnamed_geom_14" class="reward_collision_sphere" size="0.0642061" pos="0 0.0677254 0"/>
        <body name="FL_thigh" pos="0.00654633 0.0800031 -0.00583398" quat="0.999985 0.0024204 0.00460492 0.00175666">
          <inertial pos="-0.00322506 -0.0211329 -0.0391864" quat="0.820006 0.0606732 -0.0542091 0.566543" mass="1.54976" diaginertia="0.016816 0.00573262 0.000882507"/>
          <joint name="FL_thigh_joint" pos="0 0 0" axis="0.0099664 0.999949 -0.00170414" range="-1.78215 3.34005" armature="0.0120407" damping="0" frictionloss="0.282853"/>
          <geom name="//unnamed_geom_15" class="visual" material="metal" mesh="thigh_0"/>
          <geom name="//unnamed_geom_16" class="visual" material="gray" mesh="thigh_1"/>
          <geom name="//unnamed_geom_17" class="collision" size="0.113966 0.0131088 0.0181917" pos="0 0 -0.107507" quat="0.707107 0 0.707107 0" type="box"/>
          <body name="FL_calf" pos="-0.00114885 -0.0109494 -0.211535" quat="0.999999 -4.5816e-06 0.00106074 -0.000181597">
            <inertial pos="0.00623716 -0.0022601 -0.137361" quat="0.708926 0.00355261 -0.010594 0.705195" mass="0.305655" diaginertia="0.00485097 0.00126074 5.53245e-05"/>
            <joint name="FL_calf_joint" pos="0 0 0" axis="0.00159033 0.999999 -0.000235527" stiffness="0.0508949" range="-2.872 -0.808033" armature="0.0089541" damping="0.0116148" frictionloss="0.229326"/>
            <geom name="//unnamed_geom_18" class="visual" material="gray" mesh="calf_0"/>
            <geom name="//unnamed_geom_19" class="visual" material="black" mesh="calf_1"/>
            <geom name="FL_calf0" class="collision" size="0.0128412 0.0642061" pos="0.00986681 0 -0.060567" quat="0.994493 0 -0.104807 0" type="cylinder"/>
            <geom name="//unnamed_geom_21" class="collision" size="0.0117711 0.0347783" pos="0.024667 0 -0.149399" quat="0.999688 0 0.0249974 0" type="cylinder"/>
            <geom name="//unnamed_geom_22" class="visual" pos="0 0 -0.215013" quat="1 0 0 0" material="black" mesh="foot"/>
            <geom name="FL_foot" class="foot" size="0.025591" pos="-0.0024667 0 -0.215013"/>
            <geom name="//unnamed_geom_24" class="reward_collision_sphere" size="0.0267526"/>
            <geom name="//unnamed_geom_25" class="reward_collision_sphere" size="0.0267526" pos="-0.0024667 0 -0.215013"/>
            <site name="FL_foot" class="foot" pos="-0.0024667 0 -0.215013" size="0.010701"/>
          </body>
        </body>
      </body>
      <body name="FR_hip" pos="0.250429 -0.0509786 0.00208685" quat="0.999999 -0.000924417 -4.09596e-05 -0.000944013">
        <inertial pos="0.000518321 0.0119341 0.00739711" quat="0.504481 0.53799 0.509264 0.443526" mass="0.815491" diaginertia="0.00277885 0.000427127 0.000550513"/>
        <joint name="FR_hip_joint" pos="0 0 0" axis="0.998878 -0.0131138 -0.0455058" range="-1.06743 1.0107" armature="0.0108085" damping="0.0483734" frictionloss="0.17072"/>
        <geom name="//unnamed_geom_26" class="visual" pos="0 -3.65413e-10 -1.56733e-08" quat="4.63268e-05 1 0 0" material="metal" mesh="hip_0"/>
        <geom name="//unnamed_geom_27" class="visual" pos="0 -5.92378e-10 3.87661e-08" quat="4.63268e-05 1 0 0" material="gray" mesh="hip_1"/>
        <geom name="//unnamed_geom_28" class="collision" size="0.0492247 0.021402" pos="0 -0.0774004 0" quat="0.707107 0.707107 0 0" type="cylinder"/>
        <geom name="//unnamed_geom_29" class="reward_collision_sphere" size="0.0642061" pos="0 -0.0677254 0"/>
        <body name="FR_thigh" pos="-0.00617112 -0.0862781 0.0100293" quat="0.999988 -0.00336255 -0.00297915 0.00213939">
          <inertial pos="-0.0163483 0.0247559 -0.0265555" quat="0.532396 -0.0283833 0.109177 0.838945" mass="1.27224" diaginertia="0.0188442 0.00566325 0.000800991"/>
          <joint name="FR_thigh_joint" pos="0 0 0" axis="-0.00128969 -0.999703 -0.0243386" range="-3.5659 1.60164" armature="0.014312" damping="0" frictionloss="0.164057"/>
          <geom name="//unnamed_geom_30" class="visual" material="metal" mesh="thigh_mirror_0"/>
          <geom name="//unnamed_geom_31" class="visual" material="gray" mesh="thigh_mirror_1"/>
          <geom name="//unnamed_geom_32" class="collision" size="0.113966 0.0131088 0.0181917" pos="0 0 -0.107507" quat="0.707107 0 0.707107 0" type="box"/>
          <body name="FR_calf" pos="0.00663343 -0.00209576 -0.217206" quat="0.999995 0.000690334 -0.00153157 -0.00276231">
            <inertial pos="0.0167433 0.000686417 -0.142065" quat="0.671781 0.025664 0.0361749 0.739421" mass="0.240142" diaginertia="0.00355018 0.00116914 5.01641e-05"/>
            <joint name="FR_calf_joint" pos="0 0 0" axis="-0.0122 -0.999638 0.0239933" stiffness="0.0573688" range="1.07595 2.8588" armature="0.00523659" damping="0" frictionloss="0.159839"/>
            <geom name="//unnamed_geom_33" class="visual" material="gray" mesh="calf_mirror_0"/>
            <geom name="//unnamed_geom_34" class="visual" material="black" mesh="calf_mirror_1"/>
            <geom name="FR_calf0" class="collision" size="0.0139113 0.0642061" pos="0.0123335 0 -0.060567" quat="0.995004 0 -0.0998334 0" type="cylinder"/>
            <geom name="//unnamed_geom_36" class="collision" size="0.0117711 0.0347783" pos="0.024667 0 -0.149399" quat="0.999688 0 0.0249974 0" type="cylinder"/>
            <geom name="//unnamed_geom_37" class="visual" pos="0 0 -0.215013" quat="1 0 0 0" material="black" mesh="foot"/>
            <geom name="FR_foot" class="foot" size="0.0315736" pos="-0.0024667 0 -0.215013"/>
            <geom name="//unnamed_geom_39" class="reward_collision_sphere" size="0.0267526"/>
            <geom name="//unnamed_geom_40" class="reward_collision_sphere" size="0.0267526" pos="-0.0024667 0 -0.215013"/>
            <site name="FR_foot" class="foot" pos="-0.0024667 0 -0.215013" size="0.010701"/>
          </body>
        </body>
      </body>
      <body name="RL_hip" pos="-0.249224 0.0529012 0.0105879" quat="1 -0.000610496 -0.000357918 0.00028269">
        <inertial pos="0.00625666 -0.00599627 0.0123" quat="0.46638 0.501971 0.52001 0.510004" mass="0.704199" diaginertia="0.00177374 0.000439886 0.000460275"/>
        <joint name="RL_hip_joint" pos="0 0 0" axis="-0.998898 0.0447605 -0.0141023" stiffness="0.0239628" range="-1.07431 0.970576" armature="0.0102282" damping="0.0636627" frictionloss="0.211338"/>
        <geom name="//unnamed_geom_41" class="visual" pos="-1.95052e-09 0 -3.82348e-07" quat="4.63268e-05 0 1 0" material="metal" mesh="hip_0"/>
        <geom name="//unnamed_geom_42" class="visual" pos="-3.16203e-09 0 -3.39088e-07" quat="4.63268e-05 0 1 0" material="gray" mesh="hip_1"/>
        <geom name="//unnamed_geom_43" class="collision" size="0.0492247 0.021402" pos="0 0.0774004 0" quat="0.707107 0.707107 0 0" type="cylinder"/>
        <geom name="//unnamed_geom_44" class="reward_collision_sphere" size="0.0642061" pos="0 0.0677254 0"/>
        <body name="RL_thigh" pos="-0.00119542 0.0969761 -0.00514152" quat="0.999998 -0.00109753 0.00172342 3.00353e-05">
          <inertial pos="0.00892203 -0.0252144 -0.0206601" quat="0.828937 0.0778884 -0.0189158 0.553569" mass="1.64213" diaginertia="0.0217356 0.00490375 0.000962724"/>
          <joint name="RL_thigh_joint" pos="0 0 0" axis="0.0166076 0.999827 0.00837128" range="-0.408325 4.68874" armature="0.00976509" damping="0.0517392" frictionloss="0.206718"/>
          <geom name="//unnamed_geom_45" class="visual" material="metal" mesh="thigh_0"/>
          <geom name="//unnamed_geom_46" class="visual" material="gray" mesh="thigh_1"/>
          <geom name="//unnamed_geom_47" class="collision" size="0.113966 0.0131088 0.0181917" pos="0 0 -0.107507" quat="0.707107 0 0.707107 0" type="box"/>
          <body name="RL_calf" pos="0.00443656 -0.00437071 -0.210476" quat="1 4.61764e-06 2.70434e-05 -0.000443796">
            <inertial pos="0.00198177 -0.0112759 -0.139309" quat="0.728446 0.0260249 -0.00658608 0.684577" mass="0.24334" diaginertia="0.00386555 0.000894684 4.43171e-05"/>
            <joint name="RL_calf_joint" pos="0 0 0" axis="0.00450626 0.999989 0.00114064" range="-2.92882 -0.678662" armature="0.00456506" damping="0" frictionloss="0.318704"/>
            <geom name="//unnamed_geom_48" class="visual" material="gray" mesh="calf_0"/>
            <geom name="//unnamed_geom_49" class="visual" material="black" mesh="calf_1"/>
            <geom name="RL_calf0" class="collision" size="0.0139113 0.0642061" pos="0.0123335 0 -0.060567" quat="0.995004 0 -0.0998334 0" type="cylinder"/>
            <geom name="//unnamed_geom_51" class="collision" size="0.0117711 0.0347783" pos="0.024667 0 -0.149399" quat="0.999688 0 0.0249974 0" type="cylinder"/>
            <geom name="//unnamed_geom_52" class="visual" pos="0 0 -0.215013" quat="1 0 0 0" material="black" mesh="foot"/>
            <geom name="RL_foot" class="foot" size="0.0196908" pos="-0.0024667 0 -0.215013"/>
            <geom name="//unnamed_geom_54" class="reward_collision_sphere" size="0.0267526"/>
            <geom name="//unnamed_geom_55" class="reward_collision_sphere" size="0.0267526" pos="-0.0024667 0 -0.215013"/>
            <site name="RL_foot" class="foot" pos="-0.0024667 0 -0.215013" size="0.010701"/>
          </body>
        </body>
      </body>
      <body name="RR_hip" pos="-0.252111 -0.0444109 -0.00463163" quat="1 -0.000166459 -0.000132137 -7.98629e-05">
        <inertial pos="0.0134297 -0.00797457 0.0120753" quat="0.481137 0.491673 0.55409 0.468775" mass="0.849427" diaginertia="0.00297445 0.000599171 0.000580871"/>
        <joint name="RR_hip_joint" pos="0 0 0" axis="-0.99838 0.00415877 -0.0567514" stiffness="0.00180229" range="-0.829606 0.927409" armature="0.0132317" damping="0.0390094" frictionloss="0.218065"/>
        <geom name="//unnamed_geom_56" class="visual" pos="1.94132e-09 -3.65413e-10 -3.66674e-07" quat="2.14617e-09 4.63268e-05 4.63268e-05 -1" material="metal" mesh="hip_0"/>
        <geom name="//unnamed_geom_57" class="visual" pos="3.1848e-09 -5.92378e-10 -3.77854e-07" quat="2.14617e-09 4.63268e-05 4.63268e-05 -1" material="gray" mesh="hip_1"/>
        <geom name="//unnamed_geom_58" class="collision" size="0.0492247 0.021402" pos="0 -0.0774004 0" quat="0.707107 0.707107 0 0" type="cylinder"/>
        <geom name="//unnamed_geom_59" class="reward_collision_sphere" size="0.0642061" pos="0 -0.0677254 0"/>
        <body name="RR_thigh" pos="-0.0124632 -0.0964555 0.0108539" quat="0.999987 0.000541231 -0.00434003 0.00243666">
          <inertial pos="-0.00363655 0.0149223 -0.0351916" quat="0.555174 -0.0224725 0.0857149 0.827001" mass="1.70603" diaginertia="0.0205434 0.00537759 0.00101"/>
          <joint name="RR_thigh_joint" pos="0 0 0" axis="-0.00476643 -0.999971 0.00594739" stiffness="0.00156637" range="-4.67312 0.587828" armature="0.0113855" damping="0" frictionloss="0.199139"/>
          <geom name="//unnamed_geom_60" class="visual" material="metal" mesh="thigh_mirror_0"/>
          <geom name="//unnamed_geom_61" class="visual" material="gray" mesh="thigh_mirror_1"/>
          <geom name="//unnamed_geom_62" class="collision" size="0.113966 0.0131088 0.0181917" pos="0 0 -0.107507" quat="0.707107 0 0.707107 0" type="box"/>
          <body name="RR_calf" pos="-0.00216747 -0.00960819 -0.214136" quat="0.999983 -0.00271242 -0.00417814 0.00300535">
            <inertial pos="-0.00179974 0.00560774 -0.145519" quat="0.717943 -0.00787705 0.0406696 0.694869" mass="0.2826" diaginertia="0.00447232 0.00123223 6.03144e-05"/>
            <joint name="RR_calf_joint" pos="0 0 0" axis="-0.0274908 -0.999587 -0.00840515" range="0.868587 2.50073" armature="0.0112406" damping="0" frictionloss="0.160677"/>
            <geom name="//unnamed_geom_63" class="visual" material="gray" mesh="calf_mirror_0"/>
            <geom name="//unnamed_geom_64" class="visual" material="black" mesh="calf_mirror_1"/>
            <geom name="RR_calf0" class="collision" size="0.0139113 0.0642061" pos="0.0123335 0 -0.060567" quat="0.995004 0 -0.0998334 0" type="cylinder"/>
            <geom name="//unnamed_geom_66" class="collision" size="0.0117711 0.0347783" pos="0.024667 0 -0.149399" quat="0.999688 0 0.0249974 0" type="cylinder"/>
            <geom name="//unnamed_geom_67" class="visual" pos="0 0 -0.215013" quat="1 0 0 0" material="black" mesh="foot"/>
            <geom name="RR_foot" class="foot" size="0.0305365" pos="-0.0024667 0 -0.215013"/>
            <geom name="//unnamed_geom_69" class="reward_collision_sphere" size="0.0267526"/>
            <geom name="//unnamed_geom_70" class="reward_collision_sphere" size="0.0267526" pos="-0.0024667 0 -0.215013"/>
            <site name="RR_foot" class="foot" pos="-0.0024667 0 -0.215013" size="0.010701"/>
          </body>
        </body>
      </body>
    </body>
  </worldbody>

  <contact>
    <pair class="/" geom1="floor" geom2="FL_foot" name="//unnamed_contact_0"/>
    <pair class="/" geom1="floor" geom2="FR_foot" name="//unnamed_contact_1"/>
    <pair class="/" geom1="floor" geom2="RL_foot" name="//unnamed_contact_2"/>
    <pair class="/" geom1="floor" geom2="RR_foot" name="//unnamed_contact_3"/>
  </contact>

  <actuator>
    <general name="FL_hip" class="/" joint="FL_hip_joint" forcerange="-34.004 34.004" gainprm="24.8667" biasprm="0 -24.8667 -0.620194"/>
    <general name="FL_thigh" class="/" joint="FL_thigh_joint" forcerange="-36.9302 36.9302" gainprm="24.8667" biasprm="0 -24.8667 -0.620194"/>
    <general name="FL_calf" class="/" joint="FL_calf_joint" forcerange="-55.2236 55.2236" gainprm="24.8667" biasprm="0 -24.8667 -0.620194"/>
    <general name="FR_hip" class="/" joint="FR_hip_joint" forcerange="-26.5862 26.5862" gainprm="24.8667" biasprm="0 -24.8667 -0.620194"/>
    <general name="FR_thigh" class="/" joint="FR_thigh_joint" forcerange="-17.6355 17.6355" gainprm="24.8667" biasprm="0 -24.8667 -0.620194"/>
    <general name="FR_calf" class="/" joint="FR_calf_joint" forcerange="-51.4283 51.4283" gainprm="24.8667" biasprm="0 -24.8667 -0.620194"/>
    <general name="RL_hip" class="/" joint="RL_hip_joint" forcerange="-24.2158 24.2158" gainprm="24.8667" biasprm="0 -24.8667 -0.620194"/>
    <general name="RL_thigh" class="/" joint="RL_thigh_joint" forcerange="-33.4802 33.4802" gainprm="24.8667" biasprm="0 -24.8667 -0.620194"/>
    <general name="RL_calf" class="/" joint="RL_calf_joint" forcerange="-41.4735 41.4735" gainprm="24.8667" biasprm="0 -24.8667 -0.620194"/>
    <general name="RR_hip" class="/" joint="RR_hip_joint" forcerange="-25.9748 25.9748" gainprm="24.8667" biasprm="0 -24.8667 -0.620194"/>
    <general name="RR_thigh" class="/" joint="RR_thigh_joint" forcerange="-15.5346 15.5346" gainprm="24.8667" biasprm="0 -24.8667 -0.620194"/>
    <general name="RR_calf" class="/" joint="RR_calf_joint" forcerange="-45.2879 45.2879" gainprm="24.8667" biasprm="0 -24.8667 -0.620194"/>
  </actuator>

  <sensor>
    <gyro site="imu" name="imu_angular_velocity"/>
    <velocimeter site="imu" name="imu_linear_velocity"/>
    <framelinvel objtype="site" objname="FL_foot" name="FL_foot_global_linear_velocity"/>
    <framelinvel objtype="site" objname="FR_foot" name="FR_foot_global_linear_velocity"/>
    <framelinvel objtype="site" objname="RL_foot" name="RL_foot_global_linear_velocity"/>
    <framelinvel objtype="site" objname="RR_foot" name="RR_foot_global_linear_velocity"/>
  </sensor>

  <keyframe>
    <key name="home" qpos="0 0 0.325 1 0 0 0 0.1 0.8 -1.5 -0.1 -0.8 1.5 -0.1 0.8 -1.5 0.1 -0.8 1.5"/>
  </keyframe>
</mujoco>
