<mujoco model="go2">
  <compiler angle="radian" assetdir="assets" balanceinertia="true" inertiafromgeom="false"/>

  <option timestep="0.005" density="1.2" viscosity="2e-05"/>

  <size nkey="1"/>

  <visual>
    <quality shadowsize="8192"/>
    <map shadowclip="0.5"/>
  </visual>

  <default>
    <default class="/">
      <geom contype="0" conaffinity="0" group="1" solref="-1000 -80"/>
      <site size="0.01 0.005 0.005" group="5"/>
      <general forcelimited="true" biastype="affine" gainprm="20" biasprm="0 -20 -0.5"/>
      <default class="go2">
        <joint armature="0.01" damping="0.01" frictionloss="0.2"/>
        <geom condim="1" margin="0.001"/>
        <default class="visual">
          <geom type="mesh" group="2"/>
        </default>
        <default class="collision">
          <geom group="3"/>
          <default class="foot">
            <geom size="0.022 0 0" condim="6" priority="1" friction="0.8 0.02 0.01" solimp="0.015 1 0.022"/>
          </default>
        </default>
        <default class="reward_collision_sphere">
          <geom group="5" rgba="1 0 0 1"/>
        </default>
      </default>
    </default>
  </default>

  <asset>
    <texture type="skybox" colorspace="auto" name="//unnamed_texture_0" builtin="gradient" rgb1="0.95 0.95 0.95" rgb2="0.95 0.95 0.95" width="100" height="600"/>
    <texture type="2d" colorspace="auto" name="texplane" builtin="checker" rgb1="0.345 0.575 0.748" rgb2="0.345 0.575 0.748" markrgb="1 1 1" width="512" height="512"/>
    <material name="MatPlane" class="/" texture="texplane" texuniform="true" texrepeat="2 2" specular="0.9"/>
    <material name="metal" class="/" rgba="0.9 0.95 0.95 1"/>
    <material name="black" class="/" rgba="0 0 0 1"/>
    <material name="white" class="/"/>
    <material name="gray" class="/" rgba="0.671705 0.692426 0.77427 1"/>
    <mesh name="base_0" class="/" file="base_0.obj"/>
    <mesh name="base_1" class="/" file="base_1.obj"/>
    <mesh name="base_2" class="/" file="base_2.obj"/>
    <mesh name="base_3" class="/" file="base_3.obj"/>
    <mesh name="base_4" class="/" file="base_4.obj"/>
    <mesh name="hip_0" class="/" file="hip_0.obj"/>
    <mesh name="hip_1" class="/" file="hip_1.obj"/>
    <mesh name="thigh_0" class="/" file="thigh_0.obj"/>
    <mesh name="thigh_1" class="/" file="thigh_1.obj"/>
    <mesh name="thigh_mirror_0" class="/" file="thigh_mirror_0.obj"/>
    <mesh name="thigh_mirror_1" class="/" file="thigh_mirror_1.obj"/>
    <mesh name="calf_0" class="/" file="calf_0.obj"/>
    <mesh name="calf_1" class="/" file="calf_1.obj"/>
    <mesh name="calf_mirror_0" class="/" file="calf_mirror_0.obj"/>
    <mesh name="calf_mirror_1" class="/" file="calf_mirror_1.obj"/>
    <mesh name="foot" class="/" file="foot.obj"/>
  </asset>

  <worldbody>
    <geom name="floor" class="/" size="100 100 0.125" type="plane" group="0" material="MatPlane"/>
    <light name="toplight_shadow" class="/" pos="0 0 5" dir="0.0990148 0.0990148 -0.990148" type="directional" ambient="0.04 0.04 0.04" diffuse="0.55 0.55 0.55" specular="0.12 0.12 0.12"/>
    <light name="toplight_fill" class="/" pos="0 0 5" dir="0.0990148 0.0990148 -0.990148" type="directional" castshadow="false" ambient="0.04 0.04 0.04" diffuse="0.3 0.3 0.3" specular="0.08 0.08 0.08"/>
    <body name="trunk" childclass="go2" pos="0.00053742 4.96643e-05 -0.000966024" quat="1 0.000457563 -9.7449e-05 -0.00011572">
      <inertial pos="0.0188418 -0.0013544 -0.00336891" quat="-0.00158644 0.713421 -0.0010996 0.700733" mass="5.88588" diaginertia="0.112176 0.100472 0.00832554"/>
      <joint name="//unnamed_joint_0" type="free" armature="0" damping="0" frictionloss="0"/>
      <geom name="//unnamed_geom_1" class="visual" material="black" mesh="base_0"/>
      <geom name="//unnamed_geom_2" class="visual" material="black" mesh="base_1"/>
      <geom name="//unnamed_geom_3" class="visual" material="black" mesh="base_2"/>
      <geom name="//unnamed_geom_4" class="visual" material="white" mesh="base_3"/>
      <geom name="//unnamed_geom_5" class="visual" material="gray" mesh="base_4"/>
      <geom name="trunk_1" class="collision" size="0.176636 0.0439008 0.0535261" type="box"/>
      <geom name="trunk_2" class="collision" size="0.0469527 0.0422574" pos="0.287349 0 0.00805545" type="cylinder"/>
      <geom name="trunk_3" class="collision" size="0.0441355" pos="0.295415 0 -0.0483327"/>
      <geom name="//unnamed_geom_9" class="reward_collision_sphere" size="0.0939054"/>
      <geom name="//unnamed_geom_10" class="reward_collision_sphere" size="0.0563432" pos="0.282308 0 -0.0362495"/>
      <site name="imu" pos="-0.0170646 -0.000104865 0.0254711" size="0.00939054"/>
      <camera name="track" pos="0 -2.00675 0" quat="0.707107 0.707107 0 0" mode="trackcom"/>
      <camera name="ego_camera" pos="0.314572 0 0.0362495" quat="-0.5 -0.5 0.5 0.5"/>
      <body name="FL_hip" pos="0.193688 0.0460695 0.0016492" quat="1 -5.574e-05 0.000138607 7.32923e-05">
        <inertial pos="-0.00531503 0.0018452 -0.000358029" quat="0.497176 0.499433 0.505598 0.497748" mass="0.540288" diaginertia="0.000892236 0.000582421 0.000157966"/>
        <joint name="FL_hip_joint" pos="0 0 0" axis="1 0.000542541 -0.000591493" range="-1.04654 1.02938" armature="0.00933012" damping="0.00232943" frictionloss="0.188178"/>
        <geom name="//unnamed_geom_11" class="visual" material="metal" mesh="hip_0"/>
        <geom name="//unnamed_geom_12" class="visual" material="gray" mesh="hip_1"/>
        <geom name="//unnamed_geom_13" class="collision" size="0.0431965 0.0187811" pos="0 0.08027 0" quat="0.707107 0.707107 0 0" type="cylinder"/>
        <geom name="//unnamed_geom_14" class="reward_collision_sphere" size="0.0563432" pos="0 0.0702363 0"/>
        <body name="FL_thigh" pos="-0.000259205 0.0972545 0.00148076" quat="1 0.00045513 -0.000565337 0.000235543">
          <inertial pos="-0.00400529 -0.0223558 -0.0268527" quat="0.829986 0.0814503 -0.0202371 0.551433" mass="0.946004" diaginertia="0.00617074 0.00574885 0.0002933"/>
          <joint name="FL_thigh_joint" pos="0 0 0" axis="0.00593275 0.99995 -0.00808369" stiffness="0.0021867" range="-1.54008 3.49153" armature="0.00962324" damping="0.00907404" frictionloss="0.19295"/>
          <geom name="//unnamed_geom_15" class="visual" material="metal" mesh="thigh_0"/>
          <geom name="//unnamed_geom_16" class="visual" material="gray" mesh="thigh_1"/>
          <geom name="//unnamed_geom_17" class="collision" size="0.100009 0.0115034 0.0159639" pos="0 0 -0.0857905" quat="0.707107 0 0.707107 0" type="box"/>
          <body name="FL_calf" pos="-0.000926562 0.000309887 -0.171783" quat="1 1.83267e-05 2.36555e-06 1.20619e-05">
            <inertial pos="0.00654734 -0.000743731 -0.112581" quat="0.710328 0.00121645 -0.00600754 0.703844" mass="0.199768" diaginertia="0.00152906 0.00149498 1.79581e-05"/>
            <joint name="FL_calf_joint" pos="0 0 0" axis="-0.00378941 0.999986 -0.00374956" range="-2.72725 -0.84065" armature="0.00897461" damping="0.00089524" frictionloss="0.185522"/>
            <geom name="//unnamed_geom_18" class="visual" material="gray" mesh="calf_0"/>
            <geom name="//unnamed_geom_19" class="visual" material="black" mesh="calf_1"/>
            <geom name="FL_calf0" class="collision" size="0.0112686 0.0563432" pos="0.00806594 0 -0.0483327" quat="0.994493 0 -0.104807 0" type="cylinder"/>
            <geom name="//unnamed_geom_21" class="collision" size="0.0103296 0.0305193" pos="0.0201648 0 -0.119221" quat="0.999688 0 0.0249974 0" type="cylinder"/>
            <geom name="//unnamed_geom_22" class="visual" pos="0 0 -0.171581" quat="1 0 0 0" material="black" mesh="foot"/>
            <geom name="FL_foot" class="foot" size="0.0178644" pos="-0.00201648 0 -0.171581"/>
            <geom name="//unnamed_geom_24" class="reward_collision_sphere" size="0.0234764"/>
            <geom name="//unnamed_geom_25" class="reward_collision_sphere" size="0.0234764" pos="-0.00201648 0 -0.171581"/>
            <site name="FL_foot" class="foot" pos="-0.00201648 0 -0.171581" size="0.00939054"/>
          </body>
        </body>
      </body>
      <body name="FR_hip" pos="0.193865 -0.0476308 0.000960412" quat="1 1.97977e-06 3.53626e-05 -3.91738e-05">
        <inertial pos="-0.00492952 -0.00409985 -0.000300611" quat="0.490206 0.512028 0.49991 0.497609" mass="0.560452" diaginertia="0.000914935 0.000620919 0.000162292"/>
        <joint name="FR_hip_joint" pos="0 0 0" axis="0.999969 0.000378553 0.00789095" range="-1.04672 1.04916" armature="0.00954133" damping="0.00567996" frictionloss="0.178473"/>
        <geom name="//unnamed_geom_26" class="visual" pos="0 1.72342e-09 7.39209e-08" quat="4.63268e-05 1 0 0" material="metal" mesh="hip_0"/>
        <geom name="//unnamed_geom_27" class="visual" pos="0 2.79387e-09 -1.82835e-07" quat="4.63268e-05 1 0 0" material="gray" mesh="hip_1"/>
        <geom name="//unnamed_geom_28" class="collision" size="0.0431965 0.0187811" pos="0 -0.08027 0" quat="0.707107 0.707107 0 0" type="cylinder"/>
        <geom name="//unnamed_geom_29" class="reward_collision_sphere" size="0.0563432" pos="0 -0.0702363 0"/>
        <body name="FR_thigh" pos="-0.000193082 -0.095997 -0.00110011" quat="1 0.000139787 0.000192187 0.000597466">
          <inertial pos="-0.00181448 0.023313 -0.0257199" quat="0.549894 -0.0192905 0.0853162 0.830642" mass="0.961941" diaginertia="0.00621305 0.00585972 0.000304457"/>
          <joint name="FR_thigh_joint" pos="0 0 0" axis="-0.00018784 -0.999996 0.00297045" range="-3.51043 1.57401" armature="0.00945325" damping="0.010618" frictionloss="0.178513"/>
          <geom name="//unnamed_geom_30" class="visual" material="metal" mesh="thigh_mirror_0"/>
          <geom name="//unnamed_geom_31" class="visual" material="gray" mesh="thigh_mirror_1"/>
          <geom name="//unnamed_geom_32" class="collision" size="0.100009 0.0115034 0.0159639" pos="0 0 -0.0857905" quat="0.707107 0 0.707107 0" type="box"/>
          <body name="FR_calf" pos="0.0004786 -0.000633646 -0.170619" quat="1 -0.000159849 4.96832e-05 -0.00014959">
            <inertial pos="0.00577693 0.000696337 -0.114278" quat="0.699053 -0.00561965 -0.00642901 0.715019" mass="0.20043" diaginertia="0.00154654 0.00151937 1.82323e-05"/>
            <joint name="FR_calf_joint" pos="0 0 0" axis="0.00145099 -0.999998 0.00168208" range="0.800164 2.73202" armature="0.00981557" damping="0.0170848" frictionloss="0.17887"/>
            <geom name="//unnamed_geom_33" class="visual" material="gray" mesh="calf_mirror_0"/>
            <geom name="//unnamed_geom_34" class="visual" material="black" mesh="calf_mirror_1"/>
            <geom name="FR_calf0" class="collision" size="0.0122077 0.0563432" pos="0.0100824 0 -0.0483327" quat="0.995004 0 -0.0998334 0" type="cylinder"/>
            <geom name="//unnamed_geom_36" class="collision" size="0.0103296 0.0305193" pos="0.0201648 0 -0.119221" quat="0.999688 0 0.0249974 0" type="cylinder"/>
            <geom name="//unnamed_geom_37" class="visual" pos="0 0 -0.171581" quat="1 0 0 0" material="black" mesh="foot"/>
            <geom name="FR_foot" class="foot" size="0.0217582" pos="-0.00201648 0 -0.171581"/>
            <geom name="//unnamed_geom_39" class="reward_collision_sphere" size="0.0234764"/>
            <geom name="//unnamed_geom_40" class="reward_collision_sphere" size="0.0234764" pos="-0.00201648 0 -0.171581"/>
            <site name="FR_foot" class="foot" pos="-0.00201648 0 -0.171581" size="0.00939054"/>
          </body>
        </body>
      </body>
      <body name="RL_hip" pos="-0.193572 0.0471719 -0.00234331" quat="1 0.000185697 0.000168501 -0.000186702">
        <inertial pos="0.00561943 0.00229114 -0.00200516" quat="0.50369 0.496458 0.500107 0.499719" mass="0.575055" diaginertia="0.000969765 0.000622061 0.000168034"/>
        <joint name="RL_hip_joint" pos="0 0 0" axis="-0.999808 -0.000968791 0.0195635" stiffness="0.00410738" range="-1.04323 1.029" armature="0.00918778" damping="0" frictionloss="0.188067"/>
        <geom name="//unnamed_geom_41" class="visual" pos="-1.76582e-09 0 -3.46141e-07" quat="4.63268e-05 0 1 0" material="metal" mesh="hip_0"/>
        <geom name="//unnamed_geom_42" class="visual" pos="-2.8626e-09 0 -3.06978e-07" quat="4.63268e-05 0 1 0" material="gray" mesh="hip_1"/>
        <geom name="//unnamed_geom_43" class="collision" size="0.0431965 0.0187811" pos="0 0.08027 0" quat="0.707107 0.707107 0 0" type="cylinder"/>
        <geom name="//unnamed_geom_44" class="reward_collision_sphere" size="0.0563432" pos="0 0.0702363 0"/>
        <body name="RL_thigh" pos="-0.000244875 0.096954 -0.000785569" quat="1 -0.000230725 -0.000467898 0.000171998">
          <inertial pos="-0.00590903 -0.0232196 -0.0283762" quat="0.829582 0.0841666 -0.0199637 0.551644" mass="0.963685" diaginertia="0.00601836 0.00593918 0.000293637"/>
          <joint name="RL_thigh_joint" pos="0 0 0" axis="0.000587214 0.999985 -0.0055016" stiffness="0.0113764" range="-0.506596 4.53822" armature="0.00936011" damping="0.00265635" frictionloss="0.189384"/>
          <geom name="//unnamed_geom_45" class="visual" material="metal" mesh="thigh_0"/>
          <geom name="//unnamed_geom_46" class="visual" material="gray" mesh="thigh_1"/>
          <geom name="//unnamed_geom_47" class="collision" size="0.100009 0.0115034 0.0159639" pos="0 0 -0.0857905" quat="0.707107 0 0.707107 0" type="box"/>
          <body name="RL_calf" pos="0.00117147 -0.000919499 -0.170715" quat="1 -3.27528e-05 1.33969e-05 3.16306e-05">
            <inertial pos="0.00554728 0.00100821 -0.112836" quat="0.710485 0.00257453 -0.00523198 0.703688" mass="0.205905" diaginertia="0.00159647 0.00155531 1.83473e-05"/>
            <joint name="RL_calf_joint" pos="0 0 0" axis="-0.00349744 0.999924 0.0118587" range="-2.69668 -0.841606" armature="0.0101941" damping="0.00880054" frictionloss="0.178564"/>
            <geom name="//unnamed_geom_48" class="visual" material="gray" mesh="calf_0"/>
            <geom name="//unnamed_geom_49" class="visual" material="black" mesh="calf_1"/>
            <geom name="RL_calf0" class="collision" size="0.0122077 0.0563432" pos="0.0100824 0 -0.0483327" quat="0.995004 0 -0.0998334 0" type="cylinder"/>
            <geom name="//unnamed_geom_51" class="collision" size="0.0103296 0.0305193" pos="0.0201648 0 -0.119221" quat="0.999688 0 0.0249974 0" type="cylinder"/>
            <geom name="//unnamed_geom_52" class="visual" pos="0 0 -0.171581" quat="1 0 0 0" material="black" mesh="foot"/>
            <geom name="RL_foot" class="foot" size="0.0179967" pos="-0.00201648 0 -0.171581"/>
            <geom name="//unnamed_geom_54" class="reward_collision_sphere" size="0.0234764"/>
            <geom name="//unnamed_geom_55" class="reward_collision_sphere" size="0.0234764" pos="-0.00201648 0 -0.171581"/>
            <site name="RL_foot" class="foot" pos="-0.00201648 0 -0.171581" size="0.00939054"/>
          </body>
        </body>
      </body>
      <body name="RR_hip" pos="-0.192784 -0.0467304 -0.00269977" quat="1 8.53834e-06 3.79135e-05 1.59854e-05">
        <inertial pos="0.0057506 -0.00260456 -0.001975" quat="0.494783 0.50395 0.491329 0.509726" mass="0.552955" diaginertia="0.000895215 0.000587706 0.000158664"/>
        <joint name="RR_hip_joint" pos="0 0 0" axis="-0.999959 0.00904837 0.000157165" range="-1.07487 1.03052" armature="0.00983757" damping="0.0078967" frictionloss="0.18851"/>
        <geom name="//unnamed_geom_56" class="visual" pos="1.76565e-09 1.72342e-09 -4.20062e-07" quat="2.14617e-09 4.63268e-05 4.63268e-05 -1" material="metal" mesh="hip_0"/>
        <geom name="//unnamed_geom_57" class="visual" pos="2.86302e-09 2.79387e-09 -1.24143e-07" quat="2.14617e-09 4.63268e-05 4.63268e-05 -1" material="gray" mesh="hip_1"/>
        <geom name="//unnamed_geom_58" class="collision" size="0.0431965 0.0187811" pos="0 -0.08027 0" quat="0.707107 0.707107 0 0" type="cylinder"/>
        <geom name="//unnamed_geom_59" class="reward_collision_sphere" size="0.0563432" pos="0 -0.0702363 0"/>
        <body name="RR_thigh" pos="0.0020951 -0.0965227 -0.00182992" quat="1 0.000455183 0.000232305 -0.000240678">
          <inertial pos="-0.00385146 0.0219512 -0.0268791" quat="0.551601 -0.0200552 0.0847497 0.829549" mass="0.950933" diaginertia="0.0061756 0.00592518 0.000297154"/>
          <joint name="RR_thigh_joint" pos="0 0 0" axis="0.00550391 -0.999975 -0.00437161" range="-4.54788 0.541044" armature="0.00931597" damping="0.00991045" frictionloss="0.185882"/>
          <geom name="//unnamed_geom_60" class="visual" material="metal" mesh="thigh_mirror_0"/>
          <geom name="//unnamed_geom_61" class="visual" material="gray" mesh="thigh_mirror_1"/>
          <geom name="//unnamed_geom_62" class="collision" size="0.100009 0.0115034 0.0159639" pos="0 0 -0.0857905" quat="0.707107 0 0.707107 0" type="box"/>
          <body name="RR_calf" pos="-0.000533311 0.00129445 -0.17152" quat="1 0.000430952 -7.07154e-05 0.000696046">
            <inertial pos="0.00700879 0.00159098 -0.114633" quat="0.701363 -0.00434389 0.00188662 0.712788" mass="0.20298" diaginertia="0.00157565 0.00148904 1.82211e-05"/>
            <joint name="RR_calf_joint" pos="0 0 0" axis="0.00241375 -0.999992 0.00330275" stiffness="9.3847e-05" range="0.843054 2.75806" armature="0.00939714" damping="0.0152766" frictionloss="0.17862"/>
            <geom name="//unnamed_geom_63" class="visual" material="gray" mesh="calf_mirror_0"/>
            <geom name="//unnamed_geom_64" class="visual" material="black" mesh="calf_mirror_1"/>
            <geom name="RR_calf0" class="collision" size="0.0122077 0.0563432" pos="0.0100824 0 -0.0483327" quat="0.995004 0 -0.0998334 0" type="cylinder"/>
            <geom name="//unnamed_geom_66" class="collision" size="0.0103296 0.0305193" pos="0.0201648 0 -0.119221" quat="0.999688 0 0.0249974 0" type="cylinder"/>
            <geom name="//unnamed_geom_67" class="visual" pos="0 0 -0.171581" quat="1 0 0 0" material="black" mesh="foot"/>
            <geom name="RR_foot" class="foot" size="0.0219347" pos="-0.00201648 0 -0.171581"/>
            <geom name="//unnamed_geom_69" class="reward_collision_sphere" size="0.0234764"/>
            <geom name="//unnamed_geom_70" class="reward_collision_sphere" size="0.0234764" pos="-0.00201648 0 -0.171581"/>
            <site name="RR_foot" class="foot" pos="-0.00201648 0 -0.171581" size="0.00939054"/>
          </body>
        </body>
      </body>
    </body>
  </worldbody>

  <contact>
    <pair class="/" geom1="floor" geom2="FL_foot" name="//unnamed_contact_0"/>
    <pair class="/" geom1="floor" geom2="FR_foot" name="//unnamed_contact_1"/>
    <pair class="/" geom1="floor" geom2="RL_foot" name="//unnamed_contact_2"/>
    <pair class="/" geom1="floor" geom2="RR_foot" name="//unnamed_contact_3"/>
  </contact>

  <actuator>
    <general name="FL_hip" class="/" joint="FL_hip_joint" forcerange="-21.6163 21.6163" gainprm="19.1516" biasprm="0 -19.1516 -0.476852"/>
    <general name="FL_thigh" class="/" joint="FL_thigh_joint" forcerange="-20.6968 20.6968" gainprm="19.1516" biasprm="0 -19.1516 -0.476852"/>
    <general name="FL_calf" class="/" joint="FL_calf_joint" forcerange="-44.022 44.022" gainprm="19.1516" biasprm="0 -19.1516 -0.476852"/>
    <general name="FR_hip" class="/" joint="FR_hip_joint" forcerange="-21.9495 21.9495" gainprm="19.1516" biasprm="0 -19.1516 -0.476852"/>
    <general name="FR_thigh" class="/" joint="FR_thigh_joint" forcerange="-22.3795 22.3795" gainprm="19.1516" biasprm="0 -19.1516 -0.476852"/>
    <general name="FR_calf" class="/" joint="FR_calf_joint" forcerange="-42.4856 42.4856" gainprm="19.1516" biasprm="0 -19.1516 -0.476852"/>
    <general name="RL_hip" class="/" joint="RL_hip_joint" forcerange="-22.0982 22.0982" gainprm="19.1516" biasprm="0 -19.1516 -0.476852"/>
    <general name="RL_thigh" class="/" joint="RL_thigh_joint" forcerange="-22.0177 22.0177" gainprm="19.1516" biasprm="0 -19.1516 -0.476852"/>
    <general name="RL_calf" class="/" joint="RL_calf_joint" forcerange="-41.0449 41.0449" gainprm="19.1516" biasprm="0 -19.1516 -0.476852"/>
    <general name="RR_hip" class="/" joint="RR_hip_joint" forcerange="-21.9071 21.9071" gainprm="19.1516" biasprm="0 -19.1516 -0.476852"/>
    <general name="RR_thigh" class="/" joint="RR_thigh_joint" forcerange="-23.2882 23.2882" gainprm="19.1516" biasprm="0 -19.1516 -0.476852"/>
    <general name="RR_calf" class="/" joint="RR_calf_joint" forcerange="-41.8246 41.8246" gainprm="19.1516" biasprm="0 -19.1516 -0.476852"/>
  </actuator>

  <sensor>
    <gyro site="imu" name="imu_angular_velocity"/>
    <velocimeter site="imu" name="imu_linear_velocity"/>
    <framelinvel objtype="site" objname="FL_foot" name="FL_foot_global_linear_velocity"/>
    <framelinvel objtype="site" objname="FR_foot" name="FR_foot_global_linear_velocity"/>
    <framelinvel objtype="site" objname="RL_foot" name="RL_foot_global_linear_velocity"/>
    <framelinvel objtype="site" objname="RR_foot" name="RR_foot_global_linear_velocity"/>
  </sensor>

  <keyframe>
    <key name="home" qpos="0 0 0.325 1 0 0 0 0.1 0.8 -1.5 -0.1 -0.8 1.5 -0.1 0.8 -1.5 0.1 -0.8 1.5"/>
  </keyframe>
</mujoco>
