<mujoco model="go2">
  <compiler angle="radian" assetdir="assets" balanceinertia="true" inertiafromgeom="false"/>

  <option timestep="0.005" density="1.2" viscosity="2e-05"/>

  <size nkey="1"/>

  <visual>
    <quality shadowsize="8192"/>
    <map shadowclip="0.5"/>
  </visual>

  <default>
    <default class="/">
      <geom contype="0" conaffinity="0" group="1" solref="-1000 -80"/>
      <site size="0.01 0.005 0.005" group="5"/>
      <general forcelimited="true" biastype="affine" gainprm="20" biasprm="0 -20 -0.5"/>
      <default class="go2">
        <joint armature="0.01" damping="0.01" frictionloss="0.2"/>
        <geom condim="1" margin="0.001"/>
        <default class="visual">
          <geom type="mesh" group="2"/>
        </default>
        <default class="collision">
          <geom group="3"/>
          <default class="foot">
            <geom size="0.022 0 0" condim="6" priority="1" friction="0.8 0.02 0.01" solimp="0.015 1 0.022"/>
          </default>
        </default>
        <default class="reward_collision_sphere">
          <geom group="5" rgba="1 0 0 1"/>
        </default>
      </default>
    </default>
  </default>

  <asset>
    <texture type="skybox" colorspace="auto" name="//unnamed_texture_0" builtin="gradient" rgb1="0.95 0.95 0.95" rgb2="0.95 0.95 0.95" width="100" height="600"/>
    <texture type="2d" colorspace="auto" name="texplane" builtin="checker" rgb1="0.345 0.575 0.748" rgb2="0.345 0.575 0.748" markrgb="1 1 1" width="512" height="512"/>
    <material name="MatPlane" class="/" texture="texplane" texuniform="true" texrepeat="2 2" specular="0.9"/>
    <material name="metal" class="/" rgba="0.9 0.95 0.95 1"/>
    <material name="black" class="/" rgba="0 0 0 1"/>
    <material name="white" class="/"/>
    <material name="gray" class="/" rgba="0.671705 0.692426 0.77427 1"/>
    <mesh name="base_0" class="/" file="base_0.obj"/>
    <mesh name="base_1" class="/" file="base_1.obj"/>
    <mesh name="base_2" class="/" file="base_2.obj"/>
    <mesh name="base_3" class="/" file="base_3.obj"/>
    <mesh name="base_4" class="/" file="base_4.obj"/>
    <mesh name="hip_0" class="/" file="hip_0.obj"/>
    <mesh name="hip_1" class="/" file="hip_1.obj"/>
    <mesh name="thigh_0" class="/" file="thigh_0.obj"/>
    <mesh name="thigh_1" class="/" file="thigh_1.obj"/>
    <mesh name="thigh_mirror_0" class="/" file="thigh_mirror_0.obj"/>
    <mesh name="thigh_mirror_1" class="/" file="thigh_mirror_1.obj"/>
    <mesh name="calf_0" class="/" file="calf_0.obj"/>
    <mesh name="calf_1" class="/" file="calf_1.obj"/>
    <mesh name="calf_mirror_0" class="/" file="calf_mirror_0.obj"/>
    <mesh name="calf_mirror_1" class="/" file="calf_mirror_1.obj"/>
    <mesh name="foot" class="/" file="foot.obj"/>
  </asset>

  <worldbody>
    <geom name="floor" class="/" size="100 100 0.125" type="plane" group="0" material="MatPlane"/>
    <light name="toplight_shadow" class="/" pos="0 0 5" dir="0.0990148 0.0990148 -0.990148" type="directional" ambient="0.04 0.04 0.04" diffuse="0.55 0.55 0.55" specular="0.12 0.12 0.12"/>
    <light name="toplight_fill" class="/" pos="0 0 5" dir="0.0990148 0.0990148 -0.990148" type="directional" castshadow="false" ambient="0.04 0.04 0.04" diffuse="0.3 0.3 0.3" specular="0.08 0.08 0.08"/>
    <body name="trunk" childclass="go2" pos="0.000680027 0.000128391 -0.00101581" quat="1 -0.000413906 0.000169603 -6.75336e-05">
      <inertial pos="0.0186534 -0.00159142 -0.0033661" quat="-7.73178e-05 0.713216 0.000201623 0.700945" mass="5.87968" diaginertia="0.110687 0.101279 0.00819121"/>
      <joint name="//unnamed_joint_0" type="free" armature="0" damping="0" frictionloss="0"/>
      <geom name="//unnamed_geom_1" class="visual" material="black" mesh="base_0"/>
      <geom name="//unnamed_geom_2" class="visual" material="black" mesh="base_1"/>
      <geom name="//unnamed_geom_3" class="visual" material="black" mesh="base_2"/>
      <geom name="//unnamed_geom_4" class="visual" material="white" mesh="base_3"/>
      <geom name="//unnamed_geom_5" class="visual" material="gray" mesh="base_4"/>
      <geom name="trunk_1" class="collision" size="0.176374 0.0438357 0.0534467" type="box"/>
      <geom name="trunk_2" class="collision" size="0.0468831 0.0421948" pos="0.286501 0 0.00803032" type="cylinder"/>
      <geom name="trunk_3" class="collision" size="0.0440701" pos="0.294543 0 -0.0481819"/>
      <geom name="//unnamed_geom_9" class="reward_collision_sphere" size="0.0937662"/>
      <geom name="//unnamed_geom_10" class="reward_collision_sphere" size="0.0562597" pos="0.281475 0 -0.0361365"/>
      <site name="imu" pos="-0.0160488 -0.000396329 0.0244171" size="0.00937662"/>
      <camera name="track" pos="0 -2.00937 0" quat="0.707107 0.707107 0 0" mode="trackcom"/>
      <camera name="ego_camera" pos="0.313643 0 0.0361365" quat="-0.5 -0.5 0.5 0.5"/>
      <body name="FL_hip" pos="0.192847 0.0458732 0.00136771" quat="1 -9.0057e-06 8.19584e-05 3.56199e-06">
        <inertial pos="-0.00530877 0.00163002 -0.000486171" quat="0.49643 0.499633 0.505363 0.49853" mass="0.537863" diaginertia="0.000877162 0.000583661 0.0001554"/>
        <joint name="FL_hip_joint" pos="0 0 0" axis="1 0.000590804 0.000116248" range="-1.04713 1.02976" armature="0.00936582" damping="0.00288438" frictionloss="0.185967"/>
        <geom name="//unnamed_geom_11" class="visual" material="metal" mesh="hip_0"/>
        <geom name="//unnamed_geom_12" class="visual" material="gray" mesh="hip_1"/>
        <geom name="//unnamed_geom_13" class="collision" size="0.0431324 0.0187532" pos="0 0.0803749 0" quat="0.707107 0.707107 0 0" type="cylinder"/>
        <geom name="//unnamed_geom_14" class="reward_collision_sphere" size="0.0562597" pos="0 0.0703281 0"/>
        <body name="FL_thigh" pos="-0.00045509 0.0975148 0.00159587" quat="1 7.7515e-05 8.36646e-05 0.000846057">
          <inertial pos="-0.00394221 -0.0224126 -0.026634" quat="0.831907 0.0855649 -0.0196115 0.547928" mass="0.938646" diaginertia="0.00607917 0.00577197 0.000288198"/>
          <joint name="FL_thigh_joint" pos="0 0 0" axis="0.00988864 0.999948 -0.00244999" stiffness="0.00257715" range="-1.53585 3.4955" armature="0.00968348" damping="0.00988851" frictionloss="0.19118"/>
          <geom name="//unnamed_geom_15" class="visual" material="metal" mesh="thigh_0"/>
          <geom name="//unnamed_geom_16" class="visual" material="gray" mesh="thigh_1"/>
          <geom name="//unnamed_geom_17" class="collision" size="0.099861 0.0114864 0.0159402" pos="0 0 -0.085523" quat="0.707107 0 0.707107 0" type="box"/>
          <body name="FL_calf" pos="-0.00088019 0.000509295 -0.171149" quat="1 -7.78724e-05 -3.68912e-06 1.0751e-05">
            <inertial pos="0.00662661 -0.000912234 -0.112355" quat="0.711283 0.000123948 -0.00432766 0.702893" mass="0.199031" diaginertia="0.00150507 0.00150789 1.76762e-05"/>
            <joint name="FL_calf_joint" pos="0 0 0" axis="0.00506528 0.999984 0.00232061" range="-2.72311 -0.84244" armature="0.00893091" damping="0.00108593" frictionloss="0.184729"/>
            <geom name="//unnamed_geom_18" class="visual" material="gray" mesh="calf_0"/>
            <geom name="//unnamed_geom_19" class="visual" material="black" mesh="calf_1"/>
            <geom name="FL_calf0" class="collision" size="0.0112519 0.0562597" pos="0.00804213 0 -0.0481819" quat="0.994493 0 -0.104807 0" type="cylinder"/>
            <geom name="//unnamed_geom_21" class="collision" size="0.0103143 0.030474" pos="0.0201053 0 -0.118849" quat="0.999688 0 0.0249974 0" type="cylinder"/>
            <geom name="//unnamed_geom_22" class="visual" pos="0 0 -0.171046" quat="1 0 0 0" material="black" mesh="foot"/>
            <geom name="FL_foot" class="foot" size="0.0176584" pos="-0.00201053 0 -0.171046"/>
            <geom name="//unnamed_geom_24" class="reward_collision_sphere" size="0.0234415"/>
            <geom name="//unnamed_geom_25" class="reward_collision_sphere" size="0.0234415" pos="-0.00201053 0 -0.171046"/>
            <site name="FL_foot" class="foot" pos="-0.00201053 0 -0.171046" size="0.00937662"/>
          </body>
        </body>
      </body>
      <body name="FR_hip" pos="0.193077 -0.0477191 0.000937157" quat="1 4.12115e-05 5.96909e-05 -7.078e-06">
        <inertial pos="-0.00509591 -0.00420672 -0.000516956" quat="0.501495 0.512828 0.494466 0.490933" mass="0.556486" diaginertia="0.000897457 0.00062543 0.000159063"/>
        <joint name="FR_hip_joint" pos="0 0 0" axis="0.99996 0.00698827 0.00558174" range="-1.04972 1.05136" armature="0.00948842" damping="0.00458347" frictionloss="0.177975"/>
        <geom name="//unnamed_geom_26" class="visual" pos="0 1.75673e-09 7.53496e-08" quat="4.63268e-05 1 0 0" material="metal" mesh="hip_0"/>
        <geom name="//unnamed_geom_27" class="visual" pos="0 2.84786e-09 -1.86368e-07" quat="4.63268e-05 1 0 0" material="gray" mesh="hip_1"/>
        <geom name="//unnamed_geom_28" class="collision" size="0.0431324 0.0187532" pos="0 -0.0803749 0" quat="0.707107 0.707107 0 0" type="cylinder"/>
        <geom name="//unnamed_geom_29" class="reward_collision_sphere" size="0.0562597" pos="0 -0.0703281 0"/>
        <body name="FR_thigh" pos="-5.80482e-05 -0.0962665 -0.00130002" quat="1 0.000150678 0.000181812 -0.000697882">
          <inertial pos="-0.00164915 0.0234274 -0.0258081" quat="0.552492 -0.0191033 0.0846861 0.828985" mass="0.962199" diaginertia="0.00611893 0.00589273 0.000300997"/>
          <joint name="FR_thigh_joint" pos="0 0 0" axis="0.00298284 -0.999995 0.000581227" range="-3.51159 1.57735" armature="0.00935339" damping="0.00997437" frictionloss="0.178555"/>
          <geom name="//unnamed_geom_30" class="visual" material="metal" mesh="thigh_mirror_0"/>
          <geom name="//unnamed_geom_31" class="visual" material="gray" mesh="thigh_mirror_1"/>
          <geom name="//unnamed_geom_32" class="collision" size="0.099861 0.0114864 0.0159402" pos="0 0 -0.085523" quat="0.707107 0 0.707107 0" type="box"/>
          <body name="FR_calf" pos="0.000355334 -0.000381068 -0.169975" quat="1 -2.81578e-05 -0.000127855 3.80377e-05">
            <inertial pos="0.00552352 0.000738951 -0.113982" quat="0.710757 -0.00083283 0.00285137 0.703431" mass="0.200523" diaginertia="0.00152856 0.00153232 1.79897e-05"/>
            <joint name="FR_calf_joint" pos="0 0 0" axis="0.000181919 -0.999999 0.00117551" range="0.796586 2.72862" armature="0.00991781" damping="0.0178794" frictionloss="0.17919"/>
            <geom name="//unnamed_geom_33" class="visual" material="gray" mesh="calf_mirror_0"/>
            <geom name="//unnamed_geom_34" class="visual" material="black" mesh="calf_mirror_1"/>
            <geom name="FR_calf0" class="collision" size="0.0121896 0.0562597" pos="0.0100527 0 -0.0481819" quat="0.995004 0 -0.0998334 0" type="cylinder"/>
            <geom name="//unnamed_geom_36" class="collision" size="0.0103143 0.030474" pos="0.0201053 0 -0.118849" quat="0.999688 0 0.0249974 0" type="cylinder"/>
            <geom name="//unnamed_geom_37" class="visual" pos="0 0 -0.171046" quat="1 0 0 0" material="black" mesh="foot"/>
            <geom name="FR_foot" class="foot" size="0.0217032" pos="-0.00201053 0 -0.171046"/>
            <geom name="//unnamed_geom_39" class="reward_collision_sphere" size="0.0234415"/>
            <geom name="//unnamed_geom_40" class="reward_collision_sphere" size="0.0234415" pos="-0.00201053 0 -0.171046"/>
            <site name="FR_foot" class="foot" pos="-0.00201053 0 -0.171046" size="0.00937662"/>
          </body>
        </body>
      </body>
      <body name="RL_hip" pos="-0.192769 0.0470691 -0.00250681" quat="1 8.5399e-05 0.000323056 9.47728e-05">
        <inertial pos="0.00560273 0.00250619 -0.00205232" quat="0.503162 0.498673 0.49484 0.503277" mass="0.573346" diaginertia="0.000958863 0.000628734 0.000165504"/>
        <joint name="RL_hip_joint" pos="0 0 0" axis="-0.999823 -0.0106715 -0.0154936" stiffness="0.00373166" range="-1.04221 1.02753" armature="0.00918289" damping="0" frictionloss="0.187158"/>
        <geom name="//unnamed_geom_41" class="visual" pos="-1.76178e-09 0 -3.45349e-07" quat="4.63268e-05 0 1 0" material="metal" mesh="hip_0"/>
        <geom name="//unnamed_geom_42" class="visual" pos="-2.85605e-09 0 -3.06275e-07" quat="4.63268e-05 0 1 0" material="gray" mesh="hip_1"/>
        <geom name="//unnamed_geom_43" class="collision" size="0.0431324 0.0187532" pos="0 0.0803749 0" quat="0.707107 0.707107 0 0" type="cylinder"/>
        <geom name="//unnamed_geom_44" class="reward_collision_sphere" size="0.0562597" pos="0 0.0703281 0"/>
        <body name="RL_thigh" pos="-0.000227376 0.0971259 -0.000642726" quat="1 0.000165353 -6.00969e-05 -0.000522357">
          <inertial pos="-0.00602062 -0.0232943 -0.0284646" quat="0.829762 0.084373 -0.0209664 0.551305" mass="0.956598" diaginertia="0.00590319 0.00597793 0.000288215"/>
          <joint name="RL_thigh_joint" pos="0 0 0" axis="-0.0067771 0.999975 0.00206358" stiffness="0.0123047" range="-0.508729 4.534" armature="0.00926898" damping="0.0015291" frictionloss="0.188966"/>
          <geom name="//unnamed_geom_45" class="visual" material="metal" mesh="thigh_0"/>
          <geom name="//unnamed_geom_46" class="visual" material="gray" mesh="thigh_1"/>
          <geom name="//unnamed_geom_47" class="collision" size="0.099861 0.0114864 0.0159402" pos="0 0 -0.085523" quat="0.707107 0 0.707107 0" type="box"/>
          <body name="RL_calf" pos="0.00108682 -0.000832425 -0.170076" quat="1 -3.70569e-05 -5.25929e-05 -4.98468e-05">
            <inertial pos="0.00563726 0.00120628 -0.11241" quat="0.710465 0.00171158 -0.00454392 0.703715" mass="0.205345" diaginertia="0.00157111 0.00157184 1.80659e-05"/>
            <joint name="RL_calf_joint" pos="0 0 0" axis="-0.00271879 0.999909 0.0132216" range="-2.69236 -0.845907" armature="0.0102649" damping="0.00996533" frictionloss="0.176202"/>
            <geom name="//unnamed_geom_48" class="visual" material="gray" mesh="calf_0"/>
            <geom name="//unnamed_geom_49" class="visual" material="black" mesh="calf_1"/>
            <geom name="RL_calf0" class="collision" size="0.0121896 0.0562597" pos="0.0100527 0 -0.0481819" quat="0.995004 0 -0.0998334 0" type="cylinder"/>
            <geom name="//unnamed_geom_51" class="collision" size="0.0103143 0.030474" pos="0.0201053 0 -0.118849" quat="0.999688 0 0.0249974 0" type="cylinder"/>
            <geom name="//unnamed_geom_52" class="visual" pos="0 0 -0.171046" quat="1 0 0 0" material="black" mesh="foot"/>
            <geom name="RL_foot" class="foot" size="0.0179551" pos="-0.00201053 0 -0.171046"/>
            <geom name="//unnamed_geom_54" class="reward_collision_sphere" size="0.0234415"/>
            <geom name="//unnamed_geom_55" class="reward_collision_sphere" size="0.0234415" pos="-0.00201053 0 -0.171046"/>
            <site name="RL_foot" class="foot" pos="-0.00201053 0 -0.171046" size="0.00937662"/>
          </body>
        </body>
      </body>
      <body name="RR_hip" pos="-0.192092 -0.0469488 -0.0026086" quat="1 -9.20813e-06 -3.64269e-06 -2.46005e-05">
        <inertial pos="0.00556366 -0.00246648 -0.00216497" quat="0.489543 0.500487 0.504586 0.505227" mass="0.551069" diaginertia="0.000881443 0.000590105 0.000155898"/>
        <joint name="RR_hip_joint" pos="0 0 0" axis="-0.99995 -0.00521107 0.00849919" stiffness="0.000934117" range="-1.07903 1.03268" armature="0.00981216" damping="0.00742536" frictionloss="0.188581"/>
        <geom name="//unnamed_geom_56" class="visual" pos="1.76176e-09 1.75673e-09 -4.20698e-07" quat="2.14617e-09 4.63268e-05 4.63268e-05 -1" material="metal" mesh="hip_0"/>
        <geom name="//unnamed_geom_57" class="visual" pos="2.8561e-09 2.84786e-09 -1.19907e-07" quat="2.14617e-09 4.63268e-05 4.63268e-05 -1" material="gray" mesh="hip_1"/>
        <geom name="//unnamed_geom_58" class="collision" size="0.0431324 0.0187532" pos="0 -0.0803749 0" quat="0.707107 0.707107 0 0" type="cylinder"/>
        <geom name="//unnamed_geom_59" class="reward_collision_sphere" size="0.0562597" pos="0 -0.0703281 0"/>
        <body name="RR_thigh" pos="0.00224176 -0.0965973 -0.00186959" quat="1 -0.000444647 0.000167049 -0.000470855">
          <inertial pos="-0.00385723 0.0221443 -0.0269515" quat="0.551639 -0.019708 0.0846262 0.829544" mass="0.941782" diaginertia="0.00605326 0.00594522 0.000292102"/>
          <joint name="RR_thigh_joint" pos="0 0 0" axis="-0.00603673 -0.999978 0.00284538" range="-4.54445 0.543343" armature="0.00936898" damping="0.00997284" frictionloss="0.18612"/>
          <geom name="//unnamed_geom_60" class="visual" material="metal" mesh="thigh_mirror_0"/>
          <geom name="//unnamed_geom_61" class="visual" material="gray" mesh="thigh_mirror_1"/>
          <geom name="//unnamed_geom_62" class="collision" size="0.099861 0.0114864 0.0159402" pos="0 0 -0.085523" quat="0.707107 0 0.707107 0" type="box"/>
          <body name="RR_calf" pos="-0.000586197 0.00145227 -0.170854" quat="1 0.000329115 -0.000564422 -0.000640282">
            <inertial pos="0.00721021 0.00152749 -0.114411" quat="0.700602 -0.00441523 0.00070148 0.713538" mass="0.202392" diaginertia="0.00155 0.00149905 1.79353e-05"/>
            <joint name="RR_calf_joint" pos="0 0 0" axis="-0.00237562 -0.999991 -0.00362894" range="0.843483 2.76202" armature="0.0093546" damping="0.0159937" frictionloss="0.178849"/>
            <geom name="//unnamed_geom_63" class="visual" material="gray" mesh="calf_mirror_0"/>
            <geom name="//unnamed_geom_64" class="visual" material="black" mesh="calf_mirror_1"/>
            <geom name="RR_calf0" class="collision" size="0.0121896 0.0562597" pos="0.0100527 0 -0.0481819" quat="0.995004 0 -0.0998334 0" type="cylinder"/>
            <geom name="//unnamed_geom_66" class="collision" size="0.0103143 0.030474" pos="0.0201053 0 -0.118849" quat="0.999688 0 0.0249974 0" type="cylinder"/>
            <geom name="//unnamed_geom_67" class="visual" pos="0 0 -0.171046" quat="1 0 0 0" material="black" mesh="foot"/>
            <geom name="RR_foot" class="foot" size="0.0217545" pos="-0.00201053 0 -0.171046"/>
            <geom name="//unnamed_geom_69" class="reward_collision_sphere" size="0.0234415"/>
            <geom name="//unnamed_geom_70" class="reward_collision_sphere" size="0.0234415" pos="-0.00201053 0 -0.171046"/>
            <site name="RR_foot" class="foot" pos="-0.00201053 0 -0.171046" size="0.00937662"/>
          </body>
        </body>
      </body>
    </body>
  </worldbody>

  <contact>
    <pair class="/" geom1="floor" geom2="FL_foot" name="//unnamed_contact_0"/>
    <pair class="/" geom1="floor" geom2="FR_foot" name="//unnamed_contact_1"/>
    <pair class="/" geom1="floor" geom2="RL_foot" name="//unnamed_contact_2"/>
    <pair class="/" geom1="floor" geom2="RR_foot" name="//unnamed_contact_3"/>
  </contact>

  <actuator>
    <general name="FL_hip" class="/" joint="FL_hip_joint" forcerange="-21.3918 21.3918" gainprm="19.0529" biasprm="0 -19.0529 -0.474215"/>
    <general name="FL_thigh" class="/" joint="FL_thigh_joint" forcerange="-20.521 20.521" gainprm="19.0529" biasprm="0 -19.0529 -0.474215"/>
    <general name="FL_calf" class="/" joint="FL_calf_joint" forcerange="-44.0322 44.0322" gainprm="19.0529" biasprm="0 -19.0529 -0.474215"/>
    <general name="FR_hip" class="/" joint="FR_hip_joint" forcerange="-21.9569 21.9569" gainprm="19.0529" biasprm="0 -19.0529 -0.474215"/>
    <general name="FR_thigh" class="/" joint="FR_thigh_joint" forcerange="-22.528 22.528" gainprm="19.0529" biasprm="0 -19.0529 -0.474215"/>
    <general name="FR_calf" class="/" joint="FR_calf_joint" forcerange="-42.6719 42.6719" gainprm="19.0529" biasprm="0 -19.0529 -0.474215"/>
    <general name="RL_hip" class="/" joint="RL_hip_joint" forcerange="-22.1284 22.1284" gainprm="19.0529" biasprm="0 -19.0529 -0.474215"/>
    <general name="RL_thigh" class="/" joint="RL_thigh_joint" forcerange="-21.7993 21.7993" gainprm="19.0529" biasprm="0 -19.0529 -0.474215"/>
    <general name="RL_calf" class="/" joint="RL_calf_joint" forcerange="-40.9653 40.9653" gainprm="19.0529" biasprm="0 -19.0529 -0.474215"/>
    <general name="RR_hip" class="/" joint="RR_hip_joint" forcerange="-21.9476 21.9476" gainprm="19.0529" biasprm="0 -19.0529 -0.474215"/>
    <general name="RR_thigh" class="/" joint="RR_thigh_joint" forcerange="-23.4345 23.4345" gainprm="19.0529" biasprm="0 -19.0529 -0.474215"/>
    <general name="RR_calf" class="/" joint="RR_calf_joint" forcerange="-41.5401 41.5401" gainprm="19.0529" biasprm="0 -19.0529 -0.474215"/>
  </actuator>

  <sensor>
    <gyro site="imu" name="imu_angular_velocity"/>
    <velocimeter site="imu" name="imu_linear_velocity"/>
    <framelinvel objtype="site" objname="FL_foot" name="FL_foot_global_linear_velocity"/>
    <framelinvel objtype="site" objname="FR_foot" name="FR_foot_global_linear_velocity"/>
    <framelinvel objtype="site" objname="RL_foot" name="RL_foot_global_linear_velocity"/>
    <framelinvel objtype="site" objname="RR_foot" name="RR_foot_global_linear_velocity"/>
  </sensor>

  <keyframe>
    <key name="home" qpos="0 0 0.325 1 0 0 0 0.1 0.8 -1.5 -0.1 -0.8 1.5 -0.1 0.8 -1.5 0.1 -0.8 1.5"/>
  </keyframe>
</mujoco>
