<mujoco model="go2">
  <compiler angle="radian" assetdir="assets" balanceinertia="true" inertiafromgeom="false"/>

  <option timestep="0.005" density="1.2" viscosity="2e-05"/>

  <size nkey="1"/>

  <visual>
    <quality shadowsize="8192"/>
    <map shadowclip="0.5"/>
  </visual>

  <default>
    <default class="/">
      <geom contype="0" conaffinity="0" group="1" solref="-1000 -80"/>
      <site size="0.01 0.005 0.005" group="5"/>
      <general forcelimited="true" biastype="affine" gainprm="20" biasprm="0 -20 -0.5"/>
      <default class="go2">
        <joint armature="0.01" damping="0.01" frictionloss="0.2"/>
        <geom condim="1" margin="0.001"/>
        <default class="visual">
          <geom type="mesh" group="2"/>
        </default>
        <default class="collision">
          <geom group="3"/>
          <default class="foot">
            <geom size="0.022 0 0" condim="6" priority="1" friction="0.8 0.02 0.01" solimp="0.015 1 0.022"/>
          </default>
        </default>
        <default class="reward_collision_sphere">
          <geom group="5" rgba="1 0 0 1"/>
        </default>
      </default>
    </default>
  </default>

  <asset>
    <texture type="skybox" colorspace="auto" name="//unnamed_texture_0" builtin="gradient" rgb1="0.95 0.95 0.95" rgb2="0.95 0.95 0.95" width="100" height="600"/>
    <texture type="2d" colorspace="auto" name="texplane" builtin="checker" rgb1="0.345 0.575 0.748" rgb2="0.345 0.575 0.748" markrgb="1 1 1" width="512" height="512"/>
    <material name="MatPlane" class="/" texture="texplane" texuniform="true" texrepeat="2 2" specular="0.9"/>
    <material name="metal" class="/" rgba="0.9 0.95 0.95 1"/>
    <material name="black" class="/" rgba="0 0 0 1"/>
    <material name="white" class="/"/>
    <material name="gray" class="/" rgba="0.671705 0.692426 0.77427 1"/>
    <mesh name="base_0" class="/" file="base_0.obj"/>
    <mesh name="base_1" class="/" file="base_1.obj"/>
    <mesh name="base_2" class="/" file="base_2.obj"/>
    <mesh name="base_3" class="/" file="base_3.obj"/>
    <mesh name="base_4" class="/" file="base_4.obj"/>
    <mesh name="hip_0" class="/" file="hip_0.obj"/>
    <mesh name="hip_1" class="/" file="hip_1.obj"/>
    <mesh name="thigh_0" class="/" file="thigh_0.obj"/>
    <mesh name="thigh_1" class="/" file="thigh_1.obj"/>
    <mesh name="thigh_mirror_0" class="/" file="thigh_mirror_0.obj"/>
    <mesh name="thigh_mirror_1" class="/" file="thigh_mirror_1.obj"/>
    <mesh name="calf_0" class="/" file="calf_0.obj"/>
    <mesh name="calf_1" class="/" file="calf_1.obj"/>
    <mesh name="calf_mirror_0" class="/" file="calf_mirror_0.obj"/>
    <mesh name="calf_mirror_1" class="/" file="calf_mirror_1.obj"/>
    <mesh name="foot" class="/" file="foot.obj"/>
  </asset>

  <worldbody>
    <geom name="floor" class="/" size="100 100 0.125" type="plane" group="0" material="MatPlane"/>
    <light name="toplight_shadow" class="/" pos="0 0 5" dir="0.0990148 0.0990148 -0.990148" type="directional" ambient="0.04 0.04 0.04" diffuse="0.55 0.55 0.55" specular="0.12 0.12 0.12"/>
    <light name="toplight_fill" class="/" pos="0 0 5" dir="0.0990148 0.0990148 -0.990148" type="directional" castshadow="false" ambient="0.04 0.04 0.04" diffuse="0.3 0.3 0.3" specular="0.08 0.08 0.08"/>
    <body name="trunk" childclass="go2" pos="-0.000609431 -0.000299692 -0.000436161" quat="1 -0.000734327 0.000142854 0.000189168">
      <inertial pos="0.0341287 0.00668856 -0.00450292" quat="-0.00178585 0.716861 -0.00142292 0.697213" mass="8.16135" diaginertia="0.225793 0.11506 0.0366915"/>
      <joint name="//unnamed_joint_0" type="free" armature="0" damping="0" frictionloss="0"/>
      <geom name="//unnamed_geom_1" class="visual" material="black" mesh="base_0"/>
      <geom name="//unnamed_geom_2" class="visual" material="black" mesh="base_1"/>
      <geom name="//unnamed_geom_3" class="visual" material="black" mesh="base_2"/>
      <geom name="//unnamed_geom_4" class="visual" material="white" mesh="base_3"/>
      <geom name="//unnamed_geom_5" class="visual" material="gray" mesh="base_4"/>
      <geom name="trunk_1" class="collision" size="0.20453 0.0508335 0.0619788" type="box"/>
      <geom name="trunk_2" class="collision" size="0.0543674 0.0489306" pos="0.329267 0 0.0107579" type="cylinder"/>
      <geom name="trunk_3" class="collision" size="0.0511053" pos="0.33851 0 -0.0645476"/>
      <geom name="//unnamed_geom_9" class="reward_collision_sphere" size="0.108735"/>
      <geom name="//unnamed_geom_10" class="reward_collision_sphere" size="0.0652408" pos="0.323491 0 -0.0484107"/>
      <site name="imu" pos="-0.068752 0.00150455 0.0844643" size="0.0108735"/>
      <camera name="track" pos="0 -2.06185 0" quat="0.707107 0.707107 0 0" mode="trackcom"/>
      <camera name="ego_camera" pos="0.360461 0 0.0484107" quat="-0.5 -0.5 0.5 0.5"/>
      <body name="FL_hip" pos="0.228795 0.0538395 0.00572435" quat="0.999999 -0.000976863 -9.72656e-05 -0.000306944">
        <inertial pos="-0.0064538 0.00713032 -0.00209777" quat="0.494508 0.500832 0.506672 0.497908" mass="0.950071" diaginertia="0.00207031 0.00083549 0.000770947"/>
        <joint name="FL_hip_joint" pos="0 0 0" axis="0.999921 -0.00952105 -0.00823015" stiffness="0.0196782" range="-1.04461 1.02295" armature="0.0118315" damping="0" frictionloss="0.26107"/>
        <geom name="//unnamed_geom_11" class="visual" material="metal" mesh="hip_0"/>
        <geom name="//unnamed_geom_12" class="visual" material="gray" mesh="hip_1"/>
        <geom name="//unnamed_geom_13" class="collision" size="0.050018 0.0217469" pos="0 0.082474 0" quat="0.707107 0.707107 0 0" type="cylinder"/>
        <geom name="//unnamed_geom_14" class="reward_collision_sphere" size="0.0652408" pos="0 0.0721647 0"/>
        <body name="FL_thigh" pos="0.00292679 0.0898706 -0.00261621" quat="0.999993 0.00258026 0.00229491 -0.00112764">
          <inertial pos="-0.00225375 -0.022613 -0.0378044" quat="0.822189 0.0645516 -0.0116457 0.565422" mass="1.52288" diaginertia="0.0120297 0.00738151 0.00123546"/>
          <joint name="FL_thigh_joint" pos="0 0 0" axis="-0.0032982 0.999994 0.00108216" range="-1.70761 3.41273" armature="0.0106091" damping="0" frictionloss="0.248546"/>
          <geom name="//unnamed_geom_15" class="visual" material="metal" mesh="thigh_0"/>
          <geom name="//unnamed_geom_16" class="visual" material="gray" mesh="thigh_1"/>
          <geom name="//unnamed_geom_17" class="collision" size="0.115802 0.01332 0.0184849" pos="0 0 -0.114572" quat="0.707107 0 0.707107 0" type="box"/>
          <body name="FL_calf" pos="-0.0022005 -0.00715791 -0.228061" quat="1 -0.000264636 -0.000168025 0.000252659">
            <inertial pos="0.00643767 0.000626663 -0.1501" quat="0.712704 -0.00355357 -0.00760583 0.701414" mass="0.306358" diaginertia="0.00324148 0.00171488 7.62371e-05"/>
            <joint name="FL_calf_joint" pos="0 0 0" axis="0.00513518 0.999984 0.00219033" stiffness="0.0324081" range="-2.79929 -0.814367" armature="0.0107403" damping="0.0150583" frictionloss="0.230017"/>
            <geom name="//unnamed_geom_18" class="visual" material="gray" mesh="calf_0"/>
            <geom name="//unnamed_geom_19" class="visual" material="black" mesh="calf_1"/>
            <geom name="FL_calf0" class="collision" size="0.0130482 0.0652408" pos="0.00924259 0 -0.0645476" quat="0.994493 0 -0.104807 0" type="cylinder"/>
            <geom name="//unnamed_geom_21" class="collision" size="0.0119608 0.0353388" pos="0.0231065 0 -0.159217" quat="0.999688 0 0.0249974 0" type="cylinder"/>
            <geom name="//unnamed_geom_22" class="visual" pos="0 0 -0.229144" quat="1 0 0 0" material="black" mesh="foot"/>
            <geom name="FL_foot" class="foot" size="0.0249276" pos="-0.00231065 0 -0.229144"/>
            <geom name="//unnamed_geom_24" class="reward_collision_sphere" size="0.0271837"/>
            <geom name="//unnamed_geom_25" class="reward_collision_sphere" size="0.0271837" pos="-0.00231065 0 -0.229144"/>
            <site name="FL_foot" class="foot" pos="-0.00231065 0 -0.229144" size="0.0108735"/>
          </body>
        </body>
      </body>
      <body name="FR_hip" pos="0.231558 -0.050511 -0.000427108" quat="1 5.60188e-05 -0.000669126 0.000235287">
        <inertial pos="-0.00268326 0.00803391 0.00372528" quat="0.474474 0.496861 0.535718 0.490928" mass="0.866094" diaginertia="0.00198576 0.000639717 0.000749791"/>
        <joint name="FR_hip_joint" pos="0 0 0" axis="0.999567 -0.026956 0.0117663" stiffness="0.000186684" range="-1.01452 1.04135" armature="0.0107001" damping="0.0327092" frictionloss="0.21014"/>
        <geom name="//unnamed_geom_26" class="visual" pos="0 -3.90877e-10 -1.67655e-08" quat="4.63268e-05 1 0 0" material="metal" mesh="hip_0"/>
        <geom name="//unnamed_geom_27" class="visual" pos="0 -6.33658e-10 4.14676e-08" quat="4.63268e-05 1 0 0" material="gray" mesh="hip_1"/>
        <geom name="//unnamed_geom_28" class="collision" size="0.050018 0.0217469" pos="0 -0.082474 0" quat="0.707107 0.707107 0 0" type="cylinder"/>
        <geom name="//unnamed_geom_29" class="reward_collision_sphere" size="0.0652408" pos="0 -0.0721647 0"/>
        <body name="FR_thigh" pos="-0.00266864 -0.0956161 0.00660734" quat="0.999995 -0.0015082 -0.00173074 -0.00215722">
          <inertial pos="-0.0123661 0.0230003 -0.0322565" quat="0.546878 -0.0213098 0.0994467 0.831012" mass="1.35618" diaginertia="0.0125789 0.00720055 0.00112185"/>
          <joint name="FR_thigh_joint" pos="0 0 0" axis="-0.00871253 -0.999953 0.00421265" range="-3.49948 1.54389" armature="0.0127562" damping="0" frictionloss="0.204125"/>
          <geom name="//unnamed_geom_30" class="visual" material="metal" mesh="thigh_mirror_0"/>
          <geom name="//unnamed_geom_31" class="visual" material="gray" mesh="thigh_mirror_1"/>
          <geom name="//unnamed_geom_32" class="collision" size="0.115802 0.01332 0.0184849" pos="0 0 -0.114572" quat="0.707107 0 0.707107 0" type="box"/>
          <body name="FR_calf" pos="0.00290527 0.000700889 -0.228162" quat="0.999999 -0.000420487 0.000207007 0.00138768">
            <inertial pos="0.0125532 0.000855459 -0.153" quat="0.677391 0.0023014 0.0259992 0.73516" mass="0.278072" diaginertia="0.00281678 0.00162071 7.15858e-05"/>
            <joint name="FR_calf_joint" pos="0 0 0" axis="0.01824 -0.999708 0.0158513" stiffness="0.0389813" range="1.00043 2.78615" armature="0.00752944" damping="0" frictionloss="0.20027"/>
            <geom name="//unnamed_geom_33" class="visual" material="gray" mesh="calf_mirror_0"/>
            <geom name="//unnamed_geom_34" class="visual" material="black" mesh="calf_mirror_1"/>
            <geom name="FR_calf0" class="collision" size="0.0141355 0.0652408" pos="0.0115532 0 -0.0645476" quat="0.995004 0 -0.0998334 0" type="cylinder"/>
            <geom name="//unnamed_geom_36" class="collision" size="0.0119608 0.0353388" pos="0.0231065 0 -0.159217" quat="0.999688 0 0.0249974 0" type="cylinder"/>
            <geom name="//unnamed_geom_37" class="visual" pos="0 0 -0.229144" quat="1 0 0 0" material="black" mesh="foot"/>
            <geom name="FR_foot" class="foot" size="0.028814" pos="-0.00231065 0 -0.229144"/>
            <geom name="//unnamed_geom_39" class="reward_collision_sphere" size="0.0271837"/>
            <geom name="//unnamed_geom_40" class="reward_collision_sphere" size="0.0271837" pos="-0.00231065 0 -0.229144"/>
            <site name="FR_foot" class="foot" pos="-0.00231065 0 -0.229144" size="0.0108735"/>
          </body>
        </body>
      </body>
      <body name="RL_hip" pos="-0.230356 0.0520713 0.00703775" quat="0.999999 0.00124612 0.000335346 -0.000123963">
        <inertial pos="0.00710227 -0.00214873 0.00880999" quat="0.526557 0.501844 0.485825 0.484628" mass="0.786072" diaginertia="0.00142784 0.00061471 0.000640257"/>
        <joint name="RL_hip_joint" pos="0 0 0" axis="-0.999605 -0.0280708 -0.00167898" stiffness="0.00793801" range="-1.06494 1.03709" armature="0.00947841" damping="0.0454944" frictionloss="0.222385"/>
        <geom name="//unnamed_geom_41" class="visual" pos="-6.92833e-10 0 -1.35811e-07" quat="4.63268e-05 0 1 0" material="metal" mesh="hip_0"/>
        <geom name="//unnamed_geom_42" class="visual" pos="-1.12316e-09 0 -1.20445e-07" quat="4.63268e-05 0 1 0" material="gray" mesh="hip_1"/>
        <geom name="//unnamed_geom_43" class="collision" size="0.050018 0.0217469" pos="0 0.082474 0" quat="0.707107 0.707107 0 0" type="cylinder"/>
        <geom name="//unnamed_geom_44" class="reward_collision_sphere" size="0.0652408" pos="0 0.0721647 0"/>
        <body name="RL_thigh" pos="-0.00017913 0.0992634 -0.00211176" quat="1 0.000341924 -0.000154448 -6.56368e-06">
          <inertial pos="0.00541901 -0.0232867 -0.0266199" quat="0.828134 0.083421 -0.0167994 0.554033" mass="1.58435" diaginertia="0.0144131 0.00678439 0.0013248"/>
          <joint name="RL_thigh_joint" pos="0 0 0" axis="0.0113007 0.999645 -0.0241456" range="-0.478809 4.61638" armature="0.0115491" damping="0.0335927" frictionloss="0.224249"/>
          <geom name="//unnamed_geom_45" class="visual" material="metal" mesh="thigh_0"/>
          <geom name="//unnamed_geom_46" class="visual" material="gray" mesh="thigh_1"/>
          <geom name="//unnamed_geom_47" class="collision" size="0.115802 0.01332 0.0184849" pos="0 0 -0.114572" quat="0.707107 0 0.707107 0" type="box"/>
          <body name="RL_calf" pos="0.00127831 -0.00154171 -0.227839" quat="1 0.000291175 0.000550416 0.000235062">
            <inertial pos="0.00500868 -0.00759038 -0.151989" quat="0.718538 -0.0108818 0.000987545 0.695402" mass="0.274067" diaginertia="0.00282534 0.00136913 6.71369e-05"/>
            <joint name="RL_calf_joint" pos="0 0 0" axis="0.006594 0.999888 0.0134337" range="-2.85444 -0.750824" armature="0.00667211" damping="0" frictionloss="0.28343"/>
            <geom name="//unnamed_geom_48" class="visual" material="gray" mesh="calf_0"/>
            <geom name="//unnamed_geom_49" class="visual" material="black" mesh="calf_1"/>
            <geom name="RL_calf0" class="collision" size="0.0141355 0.0652408" pos="0.0115532 0 -0.0645476" quat="0.995004 0 -0.0998334 0" type="cylinder"/>
            <geom name="//unnamed_geom_51" class="collision" size="0.0119608 0.0353388" pos="0.0231065 0 -0.159217" quat="0.999688 0 0.0249974 0" type="cylinder"/>
            <geom name="//unnamed_geom_52" class="visual" pos="0 0 -0.229144" quat="1 0 0 0" material="black" mesh="foot"/>
            <geom name="RL_foot" class="foot" size="0.0219612" pos="-0.00231065 0 -0.229144"/>
            <geom name="//unnamed_geom_54" class="reward_collision_sphere" size="0.0271837"/>
            <geom name="//unnamed_geom_55" class="reward_collision_sphere" size="0.0271837" pos="-0.00231065 0 -0.229144"/>
            <site name="RL_foot" class="foot" pos="-0.00231065 0 -0.229144" size="0.0108735"/>
          </body>
        </body>
      </body>
      <body name="RR_hip" pos="-0.233218 -0.046081 -0.00120541" quat="0.999999 -0.00053322 0.000688297 -0.000756971">
        <inertial pos="0.00942003 -0.00453357 0.00827231" quat="0.504286 0.530381 0.460924 0.501937" mass="0.900185" diaginertia="0.0020228 0.000786546 0.000778725"/>
        <joint name="RR_hip_joint" pos="0 0 0" axis="-0.999269 -0.0372668 -0.00846806" stiffness="0.00867348" range="-0.904582 0.999291" armature="0.0114543" damping="0.0209428" frictionloss="0.211771"/>
        <geom name="//unnamed_geom_56" class="visual" pos="6.88526e-10 -3.90877e-10 -1.19046e-07" quat="2.14617e-09 4.63268e-05 4.63268e-05 -1" material="metal" mesh="hip_0"/>
        <geom name="//unnamed_geom_57" class="visual" pos="1.13382e-09 -6.33658e-10 -1.61913e-07" quat="2.14617e-09 4.63268e-05 4.63268e-05 -1" material="gray" mesh="hip_1"/>
        <geom name="//unnamed_geom_58" class="collision" size="0.050018 0.0217469" pos="0 -0.082474 0" quat="0.707107 0.707107 0 0" type="cylinder"/>
        <geom name="//unnamed_geom_59" class="reward_collision_sphere" size="0.0652408" pos="0 -0.0721647 0"/>
        <body name="RR_thigh" pos="-0.0086931 -0.0996302 0.00717527" quat="0.999995 0.0012785 -0.00141767 -0.00258094">
          <inertial pos="-0.00296999 0.0199507 -0.0343193" quat="0.552921 -0.0209852 0.084371 0.828686" mass="1.6443" diaginertia="0.0136121 0.00692351 0.00129189"/>
          <joint name="RR_thigh_joint" pos="0 0 0" axis="0.00339275 -0.999994 -0.00102743" range="-4.60114 0.522487" armature="0.0100706" damping="0" frictionloss="0.214407"/>
          <geom name="//unnamed_geom_60" class="visual" material="metal" mesh="thigh_mirror_0"/>
          <geom name="//unnamed_geom_61" class="visual" material="gray" mesh="thigh_mirror_1"/>
          <geom name="//unnamed_geom_62" class="collision" size="0.115802 0.01332 0.0184849" pos="0 0 -0.114572" quat="0.707107 0 0.707107 0" type="box"/>
          <body name="RR_calf" pos="0.00090326 -0.00624876 -0.231167" quat="0.999992 -0.00175039 -0.000109508 -0.00354099">
            <inertial pos="0.00141454 0.00222673 -0.151732" quat="0.713737 0.0158845 -0.00622446 0.700206" mass="0.298916" diaginertia="0.0030855 0.00170008 7.81537e-05"/>
            <joint name="RR_calf_joint" pos="0 0 0" axis="0.00101067 -0.999931 -0.011737" stiffness="0.00270874" range="0.831521 2.57586" armature="0.0106256" damping="0" frictionloss="0.201009"/>
            <geom name="//unnamed_geom_63" class="visual" material="gray" mesh="calf_mirror_0"/>
            <geom name="//unnamed_geom_64" class="visual" material="black" mesh="calf_mirror_1"/>
            <geom name="RR_calf0" class="collision" size="0.0141355 0.0652408" pos="0.0115532 0 -0.0645476" quat="0.995004 0 -0.0998334 0" type="cylinder"/>
            <geom name="//unnamed_geom_66" class="collision" size="0.0119608 0.0353388" pos="0.0231065 0 -0.159217" quat="0.999688 0 0.0249974 0" type="cylinder"/>
            <geom name="//unnamed_geom_67" class="visual" pos="0 0 -0.229144" quat="1 0 0 0" material="black" mesh="foot"/>
            <geom name="RR_foot" class="foot" size="0.0278675" pos="-0.00231065 0 -0.229144"/>
            <geom name="//unnamed_geom_69" class="reward_collision_sphere" size="0.0271837"/>
            <geom name="//unnamed_geom_70" class="reward_collision_sphere" size="0.0271837" pos="-0.00231065 0 -0.229144"/>
            <site name="RR_foot" class="foot" pos="-0.00231065 0 -0.229144" size="0.0108735"/>
          </body>
        </body>
      </body>
    </body>
  </worldbody>

  <contact>
    <pair class="/" geom1="floor" geom2="FL_foot" name="//unnamed_contact_0"/>
    <pair class="/" geom1="floor" geom2="FR_foot" name="//unnamed_contact_1"/>
    <pair class="/" geom1="floor" geom2="RL_foot" name="//unnamed_contact_2"/>
    <pair class="/" geom1="floor" geom2="RR_foot" name="//unnamed_contact_3"/>
  </contact>

  <actuator>
    <general name="FL_hip" class="/" joint="FL_hip_joint" forcerange="-30.9781 30.9781" gainprm="23.3251" biasprm="0 -23.3251 -0.581702"/>
    <general name="FL_thigh" class="/" joint="FL_thigh_joint" forcerange="-33.8783 33.8783" gainprm="23.3251" biasprm="0 -23.3251 -0.581702"/>
    <general name="FL_calf" class="/" joint="FL_calf_joint" forcerange="-49.9996 49.9996" gainprm="23.3251" biasprm="0 -23.3251 -0.581702"/>
    <general name="FR_hip" class="/" joint="FR_hip_joint" forcerange="-27.234 27.234" gainprm="23.3251" biasprm="0 -23.3251 -0.581702"/>
    <general name="FR_thigh" class="/" joint="FR_thigh_joint" forcerange="-21.4561 21.4561" gainprm="23.3251" biasprm="0 -23.3251 -0.581702"/>
    <general name="FR_calf" class="/" joint="FR_calf_joint" forcerange="-46.9314 46.9314" gainprm="23.3251" biasprm="0 -23.3251 -0.581702"/>
    <general name="RL_hip" class="/" joint="RL_hip_joint" forcerange="-25.4419 25.4419" gainprm="23.3251" biasprm="0 -23.3251 -0.581702"/>
    <general name="RL_thigh" class="/" joint="RL_thigh_joint" forcerange="-30.4689 30.4689" gainprm="23.3251" biasprm="0 -23.3251 -0.581702"/>
    <general name="RL_calf" class="/" joint="RL_calf_joint" forcerange="-48.2938 48.2938" gainprm="23.3251" biasprm="0 -23.3251 -0.581702"/>
    <general name="RR_hip" class="/" joint="RR_hip_joint" forcerange="-24.0852 24.0852" gainprm="23.3251" biasprm="0 -23.3251 -0.581702"/>
    <general name="RR_thigh" class="/" joint="RR_thigh_joint" forcerange="-19.3871 19.3871" gainprm="23.3251" biasprm="0 -23.3251 -0.581702"/>
    <general name="RR_calf" class="/" joint="RR_calf_joint" forcerange="-51.5337 51.5337" gainprm="23.3251" biasprm="0 -23.3251 -0.581702"/>
  </actuator>

  <sensor>
    <gyro site="imu" name="imu_angular_velocity"/>
    <velocimeter site="imu" name="imu_linear_velocity"/>
    <framelinvel objtype="site" objname="FL_foot" name="FL_foot_global_linear_velocity"/>
    <framelinvel objtype="site" objname="FR_foot" name="FR_foot_global_linear_velocity"/>
    <framelinvel objtype="site" objname="RL_foot" name="RL_foot_global_linear_velocity"/>
    <framelinvel objtype="site" objname="RR_foot" name="RR_foot_global_linear_velocity"/>
  </sensor>

  <keyframe>
    <key name="home" qpos="0 0 0.325 1 0 0 0 0.1 0.8 -1.5 -0.1 -0.8 1.5 -0.1 0.8 -1.5 0.1 -0.8 1.5"/>
  </keyframe>
</mujoco>
