<mujoco model="go2">
  <compiler angle="radian" assetdir="assets" balanceinertia="true" inertiafromgeom="false"/>

  <option timestep="0.005" density="1.2" viscosity="2e-05"/>

  <size nkey="1"/>

  <visual>
    <quality shadowsize="8192"/>
    <map shadowclip="0.5"/>
  </visual>

  <default>
    <default class="/">
      <geom contype="0" conaffinity="0" group="1" solref="-1000 -80"/>
      <site size="0.01 0.005 0.005" group="5"/>
      <general forcelimited="true" biastype="affine" gainprm="20" biasprm="0 -20 -0.5"/>
      <default class="go2">
        <joint armature="0.01" damping="0.01" frictionloss="0.2"/>
        <geom condim="1" margin="0.001"/>
        <default class="visual">
          <geom type="mesh" group="2"/>
        </default>
        <default class="collision">
          <geom group="3"/>
          <default class="foot">
            <geom size="0.022 0 0" condim="6" priority="1" friction="0.8 0.02 0.01" solimp="0.015 1 0.022"/>
          </default>
        </default>
        <default class="reward_collision_sphere">
          <geom group="5" rgba="1 0 0 1"/>
        </default>
      </default>
    </default>
  </default>

  <asset>
    <texture type="skybox" colorspace="auto" name="//unnamed_texture_0" builtin="gradient" rgb1="0.95 0.95 0.95" rgb2="0.95 0.95 0.95" width="100" height="600"/>
    <texture type="2d" colorspace="auto" name="texplane" builtin="checker" rgb1="0.345 0.575 0.748" rgb2="0.345 0.575 0.748" markrgb="1 1 1" width="512" height="512"/>
    <material name="MatPlane" class="/" texture="texplane" texuniform="true" texrepeat="2 2" specular="0.9"/>
    <material name="metal" class="/" rgba="0.9 0.95 0.95 1"/>
    <material name="black" class="/" rgba="0 0 0 1"/>
    <material name="white" class="/"/>
    <material name="gray" class="/" rgba="0.671705 0.692426 0.77427 1"/>
    <mesh name="base_0" class="/" file="base_0.obj"/>
    <mesh name="base_1" class="/" file="base_1.obj"/>
    <mesh name="base_2" class="/" file="base_2.obj"/>
    <mesh name="base_3" class="/" file="base_3.obj"/>
    <mesh name="base_4" class="/" file="base_4.obj"/>
    <mesh name="hip_0" class="/" file="hip_0.obj"/>
    <mesh name="hip_1" class="/" file="hip_1.obj"/>
    <mesh name="thigh_0" class="/" file="thigh_0.obj"/>
    <mesh name="thigh_1" class="/" file="thigh_1.obj"/>
    <mesh name="thigh_mirror_0" class="/" file="thigh_mirror_0.obj"/>
    <mesh name="thigh_mirror_1" class="/" file="thigh_mirror_1.obj"/>
    <mesh name="calf_0" class="/" file="calf_0.obj"/>
    <mesh name="calf_1" class="/" file="calf_1.obj"/>
    <mesh name="calf_mirror_0" class="/" file="calf_mirror_0.obj"/>
    <mesh name="calf_mirror_1" class="/" file="calf_mirror_1.obj"/>
    <mesh name="foot" class="/" file="foot.obj"/>
  </asset>

  <worldbody>
    <geom name="floor" class="/" size="100 100 0.125" type="plane" group="0" material="MatPlane"/>
    <light name="toplight_shadow" class="/" pos="0 0 5" dir="0.0990148 0.0990148 -0.990148" type="directional" ambient="0.04 0.04 0.04" diffuse="0.55 0.55 0.55" specular="0.12 0.12 0.12"/>
    <light name="toplight_fill" class="/" pos="0 0 5" dir="0.0990148 0.0990148 -0.990148" type="directional" castshadow="false" ambient="0.04 0.04 0.04" diffuse="0.3 0.3 0.3" specular="0.08 0.08 0.08"/>
    <body name="trunk" childclass="go2" pos="0.000236033 -9.82268e-05 -0.000792957" quat="1 -0.000351574 0.000227387 0.00026373">
      <inertial pos="0.0191625 -0.000882461 -0.0034929" quat="-0.000782205 0.713337 -0.0017425 0.700819" mass="5.88644" diaginertia="0.112215 0.0982135 0.00885175"/>
      <joint name="//unnamed_joint_0" type="free" armature="0" damping="0" frictionloss="0"/>
      <geom name="//unnamed_geom_1" class="visual" material="black" mesh="base_0"/>
      <geom name="//unnamed_geom_2" class="visual" material="black" mesh="base_1"/>
      <geom name="//unnamed_geom_3" class="visual" material="black" mesh="base_2"/>
      <geom name="//unnamed_geom_4" class="visual" material="white" mesh="base_3"/>
      <geom name="//unnamed_geom_5" class="visual" material="gray" mesh="base_4"/>
      <geom name="trunk_1" class="collision" size="0.177082 0.0440116 0.0536612" type="box"/>
      <geom name="trunk_2" class="collision" size="0.0470712 0.0423641" pos="0.287611 0 0.00815425" type="cylinder"/>
      <geom name="trunk_3" class="collision" size="0.0442469" pos="0.295684 0 -0.0489255"/>
      <geom name="//unnamed_geom_9" class="reward_collision_sphere" size="0.0941424"/>
      <geom name="//unnamed_geom_10" class="reward_collision_sphere" size="0.0564855" pos="0.282565 0 -0.0366941"/>
      <site name="imu" pos="-0.0190676 0.000403283 0.0278798" size="0.00941424"/>
      <camera name="track" pos="0 -1.99938 0" quat="0.707107 0.707107 0 0" mode="trackcom"/>
      <camera name="ego_camera" pos="0.314858 0 0.0366941" quat="-0.5 -0.5 0.5 0.5"/>
      <body name="FL_hip" pos="0.194377 0.046412 0.00207346" quat="1 -0.000172363 -3.74994e-05 -0.000233016">
        <inertial pos="-0.00528582 0.00222628 -0.000105246" quat="0.496997 0.499273 0.505402 0.498286" mass="0.545381" diaginertia="0.000901541 0.000577053 0.000168446"/>
        <joint name="FL_hip_joint" pos="0 0 0" axis="1 0.000709793 7.67959e-06" range="-1.04776 1.03039" armature="0.00928286" damping="0.00165797" frictionloss="0.19197"/>
        <geom name="//unnamed_geom_11" class="visual" material="metal" mesh="hip_0"/>
        <geom name="//unnamed_geom_12" class="visual" material="gray" mesh="hip_1"/>
        <geom name="//unnamed_geom_13" class="collision" size="0.0433055 0.0188285" pos="0 0.079975 0" quat="0.707107 0.707107 0 0" type="cylinder"/>
        <geom name="//unnamed_geom_14" class="reward_collision_sphere" size="0.0564855" pos="0 0.0699781 0"/>
        <body name="FL_thigh" pos="6.41222e-05 0.0966306 0.00125226" quat="1 0.000326461 -0.000356486 0.000313585">
          <inertial pos="-0.004085 -0.022132 -0.0273637" quat="0.829827 0.0839694 -0.019217 0.551333" mass="0.95984" diaginertia="0.00620239 0.0056803 0.000313415"/>
          <joint name="FL_thigh_joint" pos="0 0 0" axis="-0.00783699 0.999957 -0.00498754" stiffness="0.00211518" range="-1.54868 3.48476" armature="0.0094943" damping="0.00755111" frictionloss="0.195654"/>
          <geom name="//unnamed_geom_15" class="visual" material="metal" mesh="thigh_0"/>
          <geom name="//unnamed_geom_16" class="visual" material="gray" mesh="thigh_1"/>
          <geom name="//unnamed_geom_17" class="collision" size="0.100262 0.0115324 0.0160042" pos="0 0 -0.0868427" quat="0.707107 0 0.707107 0" type="box"/>
          <body name="FL_calf" pos="-0.000927417 -4.82605e-05 -0.174033" quat="1 -3.42581e-05 -1.97707e-05 -6.00266e-05">
            <inertial pos="0.0063577 -0.000425817 -0.113808" quat="0.710443 0.00061722 -0.00409235 0.703743" mass="0.200941" diaginertia="0.00154022 0.00146133 1.91025e-05"/>
            <joint name="FL_calf_joint" pos="0 0 0" axis="0.00468046 0.999988 0.00166659" range="-2.73424 -0.836278" armature="0.00908946" damping="0.000463371" frictionloss="0.187556"/>
            <geom name="//unnamed_geom_18" class="visual" material="gray" mesh="calf_0"/>
            <geom name="//unnamed_geom_19" class="visual" material="black" mesh="calf_1"/>
            <geom name="FL_calf0" class="collision" size="0.0112971 0.0564855" pos="0.00807328 0 -0.0489255" quat="0.994493 0 -0.104807 0" type="cylinder"/>
            <geom name="//unnamed_geom_21" class="collision" size="0.0103557 0.0305963" pos="0.0201832 0 -0.120683" quat="0.999688 0 0.0249974 0" type="cylinder"/>
            <geom name="//unnamed_geom_22" class="visual" pos="0 0 -0.173685" quat="1 0 0 0" material="black" mesh="foot"/>
            <geom name="FL_foot" class="foot" size="0.0182347" pos="-0.00201832 0 -0.173685"/>
            <geom name="//unnamed_geom_24" class="reward_collision_sphere" size="0.0235356"/>
            <geom name="//unnamed_geom_25" class="reward_collision_sphere" size="0.0235356" pos="-0.00201832 0 -0.173685"/>
            <site name="FL_foot" class="foot" pos="-0.00201832 0 -0.173685" size="0.00941424"/>
          </body>
        </body>
      </body>
      <body name="FR_hip" pos="0.194488 -0.0473208 0.000956945" quat="1 1.22182e-05 -1.2289e-06 2.6867e-05">
        <inertial pos="-0.00464225 -0.00383443 7.22039e-05" quat="0.504774 0.506328 0.494007 0.494765" mass="0.567518" diaginertia="0.000926247 0.000608006 0.000173796"/>
        <joint name="FR_hip_joint" pos="0 0 0" axis="0.999983 0.00201881 -0.00544592" range="-1.042 1.04581" armature="0.00961109" damping="0.00790628" frictionloss="0.180151"/>
        <geom name="//unnamed_geom_26" class="visual" pos="0 1.60522e-09 6.88513e-08" quat="4.63268e-05 1 0 0" material="metal" mesh="hip_0"/>
        <geom name="//unnamed_geom_27" class="visual" pos="0 2.60226e-09 -1.70296e-07" quat="4.63268e-05 1 0 0" material="gray" mesh="hip_1"/>
        <geom name="//unnamed_geom_28" class="collision" size="0.0433055 0.0188285" pos="0 -0.079975 0" quat="0.707107 0.707107 0 0" type="cylinder"/>
        <geom name="//unnamed_geom_29" class="reward_collision_sphere" size="0.0564855" pos="0 -0.0699781 0"/>
        <body name="FR_thigh" pos="-0.000376648 -0.0954168 -0.000683957" quat="1 0.000302158 0.000284789 0.000191989">
          <inertial pos="-0.00215116 0.0230036 -0.0257814" quat="0.55065 -0.0167102 0.0852091 0.830208" mass="0.961066" diaginertia="0.00624614 0.00576613 0.000321016"/>
          <joint name="FR_thigh_joint" pos="0 0 0" axis="0.00285355 -0.999995 0.00105692" range="-3.50669 1.5679" armature="0.00962238" damping="0.0120821" frictionloss="0.179201"/>
          <geom name="//unnamed_geom_30" class="visual" material="metal" mesh="thigh_mirror_0"/>
          <geom name="//unnamed_geom_31" class="visual" material="gray" mesh="thigh_mirror_1"/>
          <geom name="//unnamed_geom_32" class="collision" size="0.100262 0.0115324 0.0160042" pos="0 0 -0.0868427" quat="0.707107 0 0.707107 0" type="box"/>
          <body name="FR_calf" pos="0.000634798 -0.00109347 -0.173" quat="1 -0.000155639 -8.5823e-05 0.00031677">
            <inertial pos="0.00621852 0.000670467 -0.115493" quat="0.701348 -0.0052197 0.00938679 0.712738" mass="0.200235" diaginertia="0.00154628 0.00148458 1.92741e-05"/>
            <joint name="FR_calf_joint" pos="0 0 0" axis="0.00305788 -0.999993 -0.00232424" range="0.807819 2.73717" armature="0.00961775" damping="0.015404" frictionloss="0.179017"/>
            <geom name="//unnamed_geom_33" class="visual" material="gray" mesh="calf_mirror_0"/>
            <geom name="//unnamed_geom_34" class="visual" material="black" mesh="calf_mirror_1"/>
            <geom name="FR_calf0" class="collision" size="0.0122385 0.0564855" pos="0.0100916 0 -0.0489255" quat="0.995004 0 -0.0998334 0" type="cylinder"/>
            <geom name="//unnamed_geom_36" class="collision" size="0.0103557 0.0305963" pos="0.0201832 0 -0.120683" quat="0.999688 0 0.0249974 0" type="cylinder"/>
            <geom name="//unnamed_geom_37" class="visual" pos="0 0 -0.173685" quat="1 0 0 0" material="black" mesh="foot"/>
            <geom name="FR_foot" class="foot" size="0.0217896" pos="-0.00201832 0 -0.173685"/>
            <geom name="//unnamed_geom_39" class="reward_collision_sphere" size="0.0235356"/>
            <geom name="//unnamed_geom_40" class="reward_collision_sphere" size="0.0235356" pos="-0.00201832 0 -0.173685"/>
            <site name="FR_foot" class="foot" pos="-0.00201832 0 -0.173685" size="0.00941424"/>
          </body>
        </body>
      </body>
      <body name="RL_hip" pos="-0.194215 0.0472282 -0.00199111" quat="1 1.10539e-05 0.000168589 -3.80071e-05">
        <inertial pos="0.00552661 0.0019197 -0.00186552" quat="0.505189 0.497696 0.4986 0.498478" mass="0.576822" diaginertia="0.000966518 0.000605627 0.000178183"/>
        <joint name="RL_hip_joint" pos="0 0 0" axis="-0.999791 -0.00532003 0.0197444" stiffness="0.00444182" range="-1.04622 1.03317" armature="0.00923662" damping="0.00108279" frictionloss="0.189218"/>
        <geom name="//unnamed_geom_41" class="visual" pos="-1.68775e-09 0 -3.30837e-07" quat="4.63268e-05 0 1 0" material="metal" mesh="hip_0"/>
        <geom name="//unnamed_geom_42" class="visual" pos="-2.73604e-09 0 -2.93405e-07" quat="4.63268e-05 0 1 0" material="gray" mesh="hip_1"/>
        <geom name="//unnamed_geom_43" class="collision" size="0.0433055 0.0188285" pos="0 0.079975 0" quat="0.707107 0.707107 0 0" type="cylinder"/>
        <geom name="//unnamed_geom_44" class="reward_collision_sphere" size="0.0564855" pos="0 0.0699781 0"/>
        <body name="RL_thigh" pos="-0.000237597 0.0963541 -0.00102255" quat="1 2.4835e-05 -0.000207655 0.000456182">
          <inertial pos="-0.00562137 -0.0229677 -0.0283254" quat="0.829499 0.0846784 -0.0203728 0.551676" mass="0.975007" diaginertia="0.00610015 0.00583101 0.0003141"/>
          <joint name="RL_thigh_joint" pos="0 0 0" axis="-0.000566898 0.999998 0.00178912" stiffness="0.0093129" range="-0.504114 4.54553" armature="0.00952081" damping="0.00479545" frictionloss="0.189216"/>
          <geom name="//unnamed_geom_45" class="visual" material="metal" mesh="thigh_0"/>
          <geom name="//unnamed_geom_46" class="visual" material="gray" mesh="thigh_1"/>
          <geom name="//unnamed_geom_47" class="collision" size="0.100262 0.0115324 0.0160042" pos="0 0 -0.0868427" quat="0.707107 0 0.707107 0" type="box"/>
          <body name="RL_calf" pos="0.00125516 -0.00109224 -0.17312" quat="1 -3.37333e-06 9.03581e-06 6.63486e-05">
            <inertial pos="0.00542214 0.000603593 -0.114452" quat="0.710404 0.00253512 -0.00186161 0.703787" mass="0.206455" diaginertia="0.00160553 0.00151373 1.94951e-05"/>
            <joint name="RL_calf_joint" pos="0 0 0" axis="0.00297352 0.999955 0.00900129" range="-2.70532 -0.833895" armature="0.0100412" damping="0.00650174" frictionloss="0.183092"/>
            <geom name="//unnamed_geom_48" class="visual" material="gray" mesh="calf_0"/>
            <geom name="//unnamed_geom_49" class="visual" material="black" mesh="calf_1"/>
            <geom name="RL_calf0" class="collision" size="0.0122385 0.0564855" pos="0.0100916 0 -0.0489255" quat="0.995004 0 -0.0998334 0" type="cylinder"/>
            <geom name="//unnamed_geom_51" class="collision" size="0.0103557 0.0305963" pos="0.0201832 0 -0.120683" quat="0.999688 0 0.0249974 0" type="cylinder"/>
            <geom name="//unnamed_geom_52" class="visual" pos="0 0 -0.173685" quat="1 0 0 0" material="black" mesh="foot"/>
            <geom name="RL_foot" class="foot" size="0.0181129" pos="-0.00201832 0 -0.173685"/>
            <geom name="//unnamed_geom_54" class="reward_collision_sphere" size="0.0235356"/>
            <geom name="//unnamed_geom_55" class="reward_collision_sphere" size="0.0235356" pos="-0.00201832 0 -0.173685"/>
            <site name="RL_foot" class="foot" pos="-0.00201832 0 -0.173685" size="0.00941424"/>
          </body>
        </body>
      </body>
      <body name="RR_hip" pos="-0.193237 -0.0463059 -0.00266796" quat="1 -0.000103194 0.000104259 2.89672e-05">
        <inertial pos="0.00602564 -0.00279034 -0.00156717" quat="0.49901 0.505449 0.494081 0.501393" mass="0.556384" diaginertia="0.000901801 0.000580539 0.000169183"/>
        <joint name="RR_hip_joint" pos="0 0 0" axis="-0.999975 0.00213242 0.00678962" range="-1.06646 1.02809" armature="0.00984634" damping="0.00851178" frictionloss="0.187899"/>
        <geom name="//unnamed_geom_56" class="visual" pos="1.68742e-09 1.60522e-09 -3.99688e-07" quat="2.14617e-09 4.63268e-05 4.63268e-05 -1" material="metal" mesh="hip_0"/>
        <geom name="//unnamed_geom_57" class="visual" pos="2.73685e-09 2.60226e-09 -1.2311e-07" quat="2.14617e-09 4.63268e-05 4.63268e-05 -1" material="gray" mesh="hip_1"/>
        <geom name="//unnamed_geom_58" class="collision" size="0.0433055 0.0188285" pos="0 -0.079975 0" quat="0.707107 0.707107 0 0" type="cylinder"/>
        <geom name="//unnamed_geom_59" class="reward_collision_sphere" size="0.0564855" pos="0 -0.0699781 0"/>
        <body name="RR_thigh" pos="0.00177256 -0.0962093 -0.00172088" quat="1 -0.000306227 0.000151199 9.56719e-05">
          <inertial pos="-0.00374399 0.021622 -0.0268826" quat="0.551421 -0.0204254 0.0852796 0.829605" mass="0.966894" diaginertia="0.00626067 0.00585352 0.000316912"/>
          <joint name="RR_thigh_joint" pos="0 0 0" axis="-0.00289652 -0.999972 0.00693118" range="-4.5531 0.53539" armature="0.00923199" damping="0.0102566" frictionloss="0.186259"/>
          <geom name="//unnamed_geom_60" class="visual" material="metal" mesh="thigh_mirror_0"/>
          <geom name="//unnamed_geom_61" class="visual" material="gray" mesh="thigh_mirror_1"/>
          <geom name="//unnamed_geom_62" class="collision" size="0.100262 0.0115324 0.0160042" pos="0 0 -0.0868427" quat="0.707107 0 0.707107 0" type="box"/>
          <body name="RR_calf" pos="-0.000362222 0.000966424 -0.173886" quat="1 0.000555541 -0.000109808 -0.000264436">
            <inertial pos="0.00659773 0.0016259 -0.115748" quat="0.702942 -0.00456391 0.00106176 0.711232" mass="0.203758" diaginertia="0.00158423 0.00146141 1.93589e-05"/>
            <joint name="RR_calf_joint" pos="0 0 0" axis="-0.00246424 -0.999996 0.00155431" stiffness="0.000704847" range="0.840172 2.74983" armature="0.00948744" damping="0.0139246" frictionloss="0.178947"/>
            <geom name="//unnamed_geom_63" class="visual" material="gray" mesh="calf_mirror_0"/>
            <geom name="//unnamed_geom_64" class="visual" material="black" mesh="calf_mirror_1"/>
            <geom name="RR_calf0" class="collision" size="0.0122385 0.0564855" pos="0.0100916 0 -0.0489255" quat="0.995004 0 -0.0998334 0" type="cylinder"/>
            <geom name="//unnamed_geom_66" class="collision" size="0.0103557 0.0305963" pos="0.0201832 0 -0.120683" quat="0.999688 0 0.0249974 0" type="cylinder"/>
            <geom name="//unnamed_geom_67" class="visual" pos="0 0 -0.173685" quat="1 0 0 0" material="black" mesh="foot"/>
            <geom name="RR_foot" class="foot" size="0.0221879" pos="-0.00201832 0 -0.173685"/>
            <geom name="//unnamed_geom_69" class="reward_collision_sphere" size="0.0235356"/>
            <geom name="//unnamed_geom_70" class="reward_collision_sphere" size="0.0235356" pos="-0.00201832 0 -0.173685"/>
            <site name="RR_foot" class="foot" pos="-0.00201832 0 -0.173685" size="0.00941424"/>
          </body>
        </body>
      </body>
    </body>
  </worldbody>

  <contact>
    <pair class="/" geom1="floor" geom2="FL_foot" name="//unnamed_contact_0"/>
    <pair class="/" geom1="floor" geom2="FR_foot" name="//unnamed_contact_1"/>
    <pair class="/" geom1="floor" geom2="RL_foot" name="//unnamed_contact_2"/>
    <pair class="/" geom1="floor" geom2="RR_foot" name="//unnamed_contact_3"/>
  </contact>

  <actuator>
    <general name="FL_hip" class="/" joint="FL_hip_joint" forcerange="-22.0352 22.0352" gainprm="19.3028" biasprm="0 -19.3028 -0.480995"/>
    <general name="FL_thigh" class="/" joint="FL_thigh_joint" forcerange="-21.0634 21.0634" gainprm="19.3028" biasprm="0 -19.3028 -0.480995"/>
    <general name="FL_calf" class="/" joint="FL_calf_joint" forcerange="-43.8675 43.8675" gainprm="19.3028" biasprm="0 -19.3028 -0.480995"/>
    <general name="FR_hip" class="/" joint="FR_hip_joint" forcerange="-22.0065 22.0065" gainprm="19.3028" biasprm="0 -19.3028 -0.480995"/>
    <general name="FR_thigh" class="/" joint="FR_thigh_joint" forcerange="-22.1123 22.1123" gainprm="19.3028" biasprm="0 -19.3028 -0.480995"/>
    <general name="FR_calf" class="/" joint="FR_calf_joint" forcerange="-42.1622 42.1622" gainprm="19.3028" biasprm="0 -19.3028 -0.480995"/>
    <general name="RL_hip" class="/" joint="RL_hip_joint" forcerange="-22.0971 22.0971" gainprm="19.3028" biasprm="0 -19.3028 -0.480995"/>
    <general name="RL_thigh" class="/" joint="RL_thigh_joint" forcerange="-22.4098 22.4098" gainprm="19.3028" biasprm="0 -19.3028 -0.480995"/>
    <general name="RL_calf" class="/" joint="RL_calf_joint" forcerange="-41.3161 41.3161" gainprm="19.3028" biasprm="0 -19.3028 -0.480995"/>
    <general name="RR_hip" class="/" joint="RR_hip_joint" forcerange="-21.8926 21.8926" gainprm="19.3028" biasprm="0 -19.3028 -0.480995"/>
    <general name="RR_thigh" class="/" joint="RR_thigh_joint" forcerange="-22.986 22.986" gainprm="19.3028" biasprm="0 -19.3028 -0.480995"/>
    <general name="RR_calf" class="/" joint="RR_calf_joint" forcerange="-42.4024 42.4024" gainprm="19.3028" biasprm="0 -19.3028 -0.480995"/>
  </actuator>

  <sensor>
    <gyro site="imu" name="imu_angular_velocity"/>
    <velocimeter site="imu" name="imu_linear_velocity"/>
    <framelinvel objtype="site" objname="FL_foot" name="FL_foot_global_linear_velocity"/>
    <framelinvel objtype="site" objname="FR_foot" name="FR_foot_global_linear_velocity"/>
    <framelinvel objtype="site" objname="RL_foot" name="RL_foot_global_linear_velocity"/>
    <framelinvel objtype="site" objname="RR_foot" name="RR_foot_global_linear_velocity"/>
  </sensor>

  <keyframe>
    <key name="home" qpos="0 0 0.325 1 0 0 0 0.1 0.8 -1.5 -0.1 -0.8 1.5 -0.1 0.8 -1.5 0.1 -0.8 1.5"/>
  </keyframe>
</mujoco>
