<mujoco model="go2">
  <compiler angle="radian" assetdir="assets" balanceinertia="true" inertiafromgeom="false"/>

  <option timestep="0.005" density="1.2" viscosity="2e-05"/>

  <size nkey="1"/>

  <visual>
    <quality shadowsize="8192"/>
    <map shadowclip="0.5"/>
  </visual>

  <default>
    <default class="/">
      <geom contype="0" conaffinity="0" group="1" solref="-1000 -80"/>
      <site size="0.01 0.005 0.005" group="5"/>
      <general forcelimited="true" biastype="affine" gainprm="20" biasprm="0 -20 -0.5"/>
      <default class="go2">
        <joint armature="0.01" damping="0.01" frictionloss="0.2"/>
        <geom condim="1" margin="0.001"/>
        <default class="visual">
          <geom type="mesh" group="2"/>
        </default>
        <default class="collision">
          <geom group="3"/>
          <default class="foot">
            <geom size="0.022 0 0" condim="6" priority="1" friction="0.8 0.02 0.01" solimp="0.015 1 0.022"/>
          </default>
        </default>
        <default class="reward_collision_sphere">
          <geom group="5" rgba="1 0 0 1"/>
        </default>
      </default>
    </default>
  </default>

  <asset>
    <texture type="skybox" colorspace="auto" name="//unnamed_texture_0" builtin="gradient" rgb1="0.95 0.95 0.95" rgb2="0.95 0.95 0.95" width="100" height="600"/>
    <texture type="2d" colorspace="auto" name="texplane" builtin="checker" rgb1="0.345 0.575 0.748" rgb2="0.345 0.575 0.748" markrgb="1 1 1" width="512" height="512"/>
    <material name="MatPlane" class="/" texture="texplane" texuniform="true" texrepeat="2 2" specular="0.9"/>
    <material name="metal" class="/" rgba="0.9 0.95 0.95 1"/>
    <material name="black" class="/" rgba="0 0 0 1"/>
    <material name="white" class="/"/>
    <material name="gray" class="/" rgba="0.671705 0.692426 0.77427 1"/>
    <mesh name="base_0" class="/" file="base_0.obj"/>
    <mesh name="base_1" class="/" file="base_1.obj"/>
    <mesh name="base_2" class="/" file="base_2.obj"/>
    <mesh name="base_3" class="/" file="base_3.obj"/>
    <mesh name="base_4" class="/" file="base_4.obj"/>
    <mesh name="hip_0" class="/" file="hip_0.obj"/>
    <mesh name="hip_1" class="/" file="hip_1.obj"/>
    <mesh name="thigh_0" class="/" file="thigh_0.obj"/>
    <mesh name="thigh_1" class="/" file="thigh_1.obj"/>
    <mesh name="thigh_mirror_0" class="/" file="thigh_mirror_0.obj"/>
    <mesh name="thigh_mirror_1" class="/" file="thigh_mirror_1.obj"/>
    <mesh name="calf_0" class="/" file="calf_0.obj"/>
    <mesh name="calf_1" class="/" file="calf_1.obj"/>
    <mesh name="calf_mirror_0" class="/" file="calf_mirror_0.obj"/>
    <mesh name="calf_mirror_1" class="/" file="calf_mirror_1.obj"/>
    <mesh name="foot" class="/" file="foot.obj"/>
  </asset>

  <worldbody>
    <geom name="floor" class="/" size="100 100 0.125" type="plane" group="0" material="MatPlane"/>
    <light name="toplight_shadow" class="/" pos="0 0 5" dir="0.0990148 0.0990148 -0.990148" type="directional" ambient="0.04 0.04 0.04" diffuse="0.55 0.55 0.55" specular="0.12 0.12 0.12"/>
    <light name="toplight_fill" class="/" pos="0 0 5" dir="0.0990148 0.0990148 -0.990148" type="directional" castshadow="false" ambient="0.04 0.04 0.04" diffuse="0.3 0.3 0.3" specular="0.08 0.08 0.08"/>
    <body name="trunk" childclass="go2" pos="0.000917504 0.000223836 -0.00102213" quat="1 -0.000230072 -6.85996e-05 0.000246976">
      <inertial pos="0.0182356 -0.00204671 -0.00349896" quat="0.00100485 0.714694 0.000892405 0.699436" mass="5.8612" diaginertia="0.104847 0.102237 0.0082343"/>
      <joint name="//unnamed_joint_0" type="free" armature="0" damping="0" frictionloss="0"/>
      <geom name="//unnamed_geom_1" class="visual" material="black" mesh="base_0"/>
      <geom name="//unnamed_geom_2" class="visual" material="black" mesh="base_1"/>
      <geom name="//unnamed_geom_3" class="visual" material="black" mesh="base_2"/>
      <geom name="//unnamed_geom_4" class="visual" material="white" mesh="base_3"/>
      <geom name="//unnamed_geom_5" class="visual" material="gray" mesh="base_4"/>
      <geom name="trunk_1" class="collision" size="0.175873 0.0437111 0.0532948" type="box"/>
      <geom name="trunk_2" class="collision" size="0.0467498 0.0420748" pos="0.283374 0 0.00804266" type="cylinder"/>
      <geom name="trunk_3" class="collision" size="0.0439448" pos="0.291328 0 -0.0482559"/>
      <geom name="//unnamed_geom_9" class="reward_collision_sphere" size="0.0934996"/>
      <geom name="//unnamed_geom_10" class="reward_collision_sphere" size="0.0560998" pos="0.278402 0 -0.0361919"/>
      <site name="imu" pos="-0.0140735 -0.000592979 0.0227543" size="0.00934996"/>
      <camera name="track" pos="0 -2.01286 0" quat="0.707107 0.707107 0 0" mode="trackcom"/>
      <camera name="ego_camera" pos="0.310219 0 0.0361919" quat="-0.5 -0.5 0.5 0.5"/>
      <body name="FL_hip" pos="0.190198 0.0454686 0.000673892" quat="1 -2.38289e-05 -9.64533e-05 3.26698e-05">
        <inertial pos="-0.00522099 0.00116682 -0.000695764" quat="0.497248 0.499646 0.505099 0.49797" mass="0.534244" diaginertia="0.000828263 0.000584019 0.000156562"/>
        <joint name="FL_hip_joint" pos="0 0 0" axis="1 -0.000346877 -6.62873e-05" range="-1.04999 1.03247" armature="0.00945084" damping="0.0044784" frictionloss="0.181152"/>
        <geom name="//unnamed_geom_11" class="visual" material="metal" mesh="hip_0"/>
        <geom name="//unnamed_geom_12" class="visual" material="gray" mesh="hip_1"/>
        <geom name="//unnamed_geom_13" class="collision" size="0.0430098 0.0186999" pos="0 0.0805144 0" quat="0.707107 0.707107 0 0" type="cylinder"/>
        <geom name="//unnamed_geom_14" class="reward_collision_sphere" size="0.0560998" pos="0 0.0704501 0"/>
        <body name="FL_thigh" pos="-0.000900297 0.0979411 0.00181202" quat="0.999999 -0.000521448 -9.32544e-05 0.000875311">
          <inertial pos="-0.00377926 -0.022351 -0.0263212" quat="0.830812 0.090727 -0.0209182 0.54871" mass="0.92516" diaginertia="0.00575222 0.00580428 0.00028994"/>
          <joint name="FL_thigh_joint" pos="0 0 0" axis="-0.00619263 0.999951 0.00772416" stiffness="0.00393022" range="-1.5279 3.50438" armature="0.00978374" damping="0.0115687" frictionloss="0.186989"/>
          <geom name="//unnamed_geom_15" class="visual" material="metal" mesh="thigh_0"/>
          <geom name="//unnamed_geom_16" class="visual" material="gray" mesh="thigh_1"/>
          <geom name="//unnamed_geom_17" class="collision" size="0.0995771 0.0114537 0.0158949" pos="0 0 -0.0856543" quat="0.707107 0 0.707107 0" type="box"/>
          <body name="FL_calf" pos="-0.000695473 0.000938712 -0.171192" quat="1 -0.000151724 -5.89099e-05 0.000122637">
            <inertial pos="0.00669125 -0.00123154 -0.112874" quat="0.710411 0.00122194 -0.00564468 0.703763" mass="0.197649" diaginertia="0.00142251 0.00152609 1.78133e-05"/>
            <joint name="FL_calf_joint" pos="0 0 0" axis="-0.00412186 0.999981 0.00468544" range="-2.71384 -0.843948" armature="0.00888552" damping="0.00138358" frictionloss="0.184078"/>
            <geom name="//unnamed_geom_18" class="visual" material="gray" mesh="calf_0"/>
            <geom name="//unnamed_geom_19" class="visual" material="black" mesh="calf_1"/>
            <geom name="FL_calf0" class="collision" size="0.01122 0.0560998" pos="0.00795434 0 -0.0482559" quat="0.994493 0 -0.104807 0" type="cylinder"/>
            <geom name="//unnamed_geom_21" class="collision" size="0.010285 0.0303874" pos="0.0198859 0 -0.119031" quat="0.999688 0 0.0249974 0" type="cylinder"/>
            <geom name="//unnamed_geom_22" class="visual" pos="0 0 -0.171309" quat="1 0 0 0" material="black" mesh="foot"/>
            <geom name="FL_foot" class="foot" size="0.0172349" pos="-0.00198859 0 -0.171309"/>
            <geom name="//unnamed_geom_24" class="reward_collision_sphere" size="0.0233749"/>
            <geom name="//unnamed_geom_25" class="reward_collision_sphere" size="0.0233749" pos="-0.00198859 0 -0.171309"/>
            <site name="FL_foot" class="foot" pos="-0.00198859 0 -0.171309" size="0.00934996"/>
          </body>
        </body>
      </body>
      <body name="FR_hip" pos="0.19057 -0.0477579 0.000841434" quat="1 -3.80347e-05 1.6585e-05 2.88528e-05">
        <inertial pos="-0.00546305 -0.00435524 -0.0009941" quat="0.504311 0.506826 0.501984 0.486632" mass="0.549066" diaginertia="0.000841252 0.000631071 0.000158707"/>
        <joint name="FR_hip_joint" pos="0 0 0" axis="0.99994 0.00947603 -0.00545194" range="-1.05648 1.05557" armature="0.00937791" damping="0.00247669" frictionloss="0.177912"/>
        <geom name="//unnamed_geom_26" class="visual" pos="0 1.76117e-09 7.55403e-08" quat="4.63268e-05 1 0 0" material="metal" mesh="hip_0"/>
        <geom name="//unnamed_geom_27" class="visual" pos="0 2.85507e-09 -1.8684e-07" quat="4.63268e-05 1 0 0" material="gray" mesh="hip_1"/>
        <geom name="//unnamed_geom_28" class="collision" size="0.0430098 0.0186999" pos="0 -0.0805144 0" quat="0.707107 0.707107 0 0" type="cylinder"/>
        <geom name="//unnamed_geom_29" class="reward_collision_sphere" size="0.0560998" pos="0 -0.0704501 0"/>
        <body name="FR_thigh" pos="0.000295355 -0.0967787 -0.00166572" quat="1 0.000412655 -0.000791791 0.000220392">
          <inertial pos="-0.00133835 0.0235579 -0.0262588" quat="0.55144 -0.0204035 0.0852752 0.829593" mass="0.963428" diaginertia="0.005784 0.00593511 0.000305807"/>
          <joint name="FR_thigh_joint" pos="0 0 0" axis="0.00229445 -0.999994 0.00258476" range="-3.51206 1.58388" armature="0.00913411" damping="0.00916343" frictionloss="0.17959"/>
          <geom name="//unnamed_geom_30" class="visual" material="metal" mesh="thigh_mirror_0"/>
          <geom name="//unnamed_geom_31" class="visual" material="gray" mesh="thigh_mirror_1"/>
          <geom name="//unnamed_geom_32" class="collision" size="0.0995771 0.0114537 0.0158949" pos="0 0 -0.0856543" quat="0.707107 0 0.707107 0" type="box"/>
          <body name="FR_calf" pos="1.99812e-05 4.97908e-05 -0.170134" quat="1 -2.01408e-05 5.33934e-05 -4.50457e-05">
            <inertial pos="0.00496901 0.000774746 -0.114124" quat="0.698174 -0.0143119 0.00174214 0.715783" mass="0.200976" diaginertia="0.00145788 0.00155003 1.81924e-05"/>
            <joint name="FR_calf_joint" pos="0 0 0" axis="0.00112055 -0.999999 -0.000123474" range="0.790265 2.7203" armature="0.0101256" damping="0.019274" frictionloss="0.180759"/>
            <geom name="//unnamed_geom_33" class="visual" material="gray" mesh="calf_mirror_0"/>
            <geom name="//unnamed_geom_34" class="visual" material="black" mesh="calf_mirror_1"/>
            <geom name="FR_calf0" class="collision" size="0.0121549 0.0560998" pos="0.00994293 0 -0.0482559" quat="0.995004 0 -0.0998334 0" type="cylinder"/>
            <geom name="//unnamed_geom_36" class="collision" size="0.010285 0.0303874" pos="0.0198859 0 -0.119031" quat="0.999688 0 0.0249974 0" type="cylinder"/>
            <geom name="//unnamed_geom_37" class="visual" pos="0 0 -0.171309" quat="1 0 0 0" material="black" mesh="foot"/>
            <geom name="FR_foot" class="foot" size="0.0215079" pos="-0.00198859 0 -0.171309"/>
            <geom name="//unnamed_geom_39" class="reward_collision_sphere" size="0.0233749"/>
            <geom name="//unnamed_geom_40" class="reward_collision_sphere" size="0.0233749" pos="-0.00198859 0 -0.171309"/>
            <site name="FR_foot" class="foot" pos="-0.00198859 0 -0.171309" size="0.00934996"/>
          </body>
        </body>
      </body>
      <body name="RL_hip" pos="-0.190221 0.04672 -0.00279424" quat="1 5.92198e-05 -4.27235e-05 0.000293996">
        <inertial pos="0.00542721 0.00298208 -0.00209168" quat="0.50721 0.503466 0.493515 0.495685" mass="0.569776" diaginertia="0.000912777 0.000639036 0.000166667"/>
        <joint name="RL_hip_joint" pos="0 0 0" axis="-0.99986 -0.000333776 -0.0167076" stiffness="0.00251073" range="-1.04189 1.02626" armature="0.00922344" damping="0" frictionloss="0.18581"/>
        <geom name="//unnamed_geom_41" class="visual" pos="-1.65544e-09 0 -3.24505e-07" quat="4.63268e-05 0 1 0" material="metal" mesh="hip_0"/>
        <geom name="//unnamed_geom_42" class="visual" pos="-2.68367e-09 0 -2.87789e-07" quat="4.63268e-05 0 1 0" material="gray" mesh="hip_1"/>
        <geom name="//unnamed_geom_43" class="collision" size="0.0430098 0.0186999" pos="0 0.0805144 0" quat="0.707107 0.707107 0 0" type="cylinder"/>
        <geom name="//unnamed_geom_44" class="reward_collision_sphere" size="0.0560998" pos="0 0.0704501 0"/>
        <body name="RL_thigh" pos="-0.000153077 0.0971942 -0.000316885" quat="1 0.00036858 -0.000130413 0.000318533">
          <inertial pos="-0.00616456 -0.023324 -0.0287964" quat="0.829365 0.0853597 -0.0215798 0.551727" mass="0.94132" diaginertia="0.00553881 0.00602938 0.000288909"/>
          <joint name="RL_thigh_joint" pos="0 0 0" axis="-0.00845895 0.99996 0.00304985" stiffness="0.0138225" range="-0.514748 4.52474" armature="0.00908826" damping="0" frictionloss="0.187256"/>
          <geom name="//unnamed_geom_45" class="visual" material="metal" mesh="thigh_0"/>
          <geom name="//unnamed_geom_46" class="visual" material="gray" mesh="thigh_1"/>
          <geom name="//unnamed_geom_47" class="collision" size="0.0995771 0.0114537 0.0158949" pos="0 0 -0.0856543" quat="0.707107 0 0.707107 0" type="box"/>
          <body name="RL_calf" pos="0.000832689 -0.000676997 -0.170261" quat="1 9.55207e-06 5.27084e-05 -4.12798e-05">
            <inertial pos="0.00587034 0.00157863 -0.112546" quat="0.710463 0.00331193 -0.00404804 0.703715" mass="0.203871" diaginertia="0.00148157 0.00159682 1.82149e-05"/>
            <joint name="RL_calf_joint" pos="0 0 0" axis="-0.00513336 0.999895 -0.0135276" range="-2.68408 -0.855104" armature="0.010395" damping="0.0122731" frictionloss="0.171546"/>
            <geom name="//unnamed_geom_48" class="visual" material="gray" mesh="calf_0"/>
            <geom name="//unnamed_geom_49" class="visual" material="black" mesh="calf_1"/>
            <geom name="RL_calf0" class="collision" size="0.0121549 0.0560998" pos="0.00994293 0 -0.0482559" quat="0.995004 0 -0.0998334 0" type="cylinder"/>
            <geom name="//unnamed_geom_51" class="collision" size="0.010285 0.0303874" pos="0.0198859 0 -0.119031" quat="0.999688 0 0.0249974 0" type="cylinder"/>
            <geom name="//unnamed_geom_52" class="visual" pos="0 0 -0.171309" quat="1 0 0 0" material="black" mesh="foot"/>
            <geom name="RL_foot" class="foot" size="0.0179348" pos="-0.00198859 0 -0.171309"/>
            <geom name="//unnamed_geom_54" class="reward_collision_sphere" size="0.0233749"/>
            <geom name="//unnamed_geom_55" class="reward_collision_sphere" size="0.0233749" pos="-0.00198859 0 -0.171309"/>
            <site name="RL_foot" class="foot" pos="-0.00198859 0 -0.171309" size="0.00934996"/>
          </body>
        </body>
      </body>
      <body name="RR_hip" pos="-0.189791 -0.0473728 -0.00218577" quat="1 -6.05964e-05 -0.000172042 -2.44951e-05">
        <inertial pos="0.00510018 -0.00210322 -0.00249886" quat="0.502749 0.486327 0.504387 0.506283" mass="0.547888" diaginertia="0.000833725 0.000593492 0.000156419"/>
        <joint name="RR_hip_joint" pos="0 0 0" axis="-0.999932 0.00593706 -0.010011" stiffness="0.00308913" range="-1.08693 1.03887" armature="0.0097206" damping="0.00617601" frictionloss="0.18772"/>
        <geom name="//unnamed_geom_56" class="visual" pos="1.65586e-09 1.76117e-09 -4.00045e-07" quat="2.14617e-09 4.63268e-05 4.63268e-05 -1" material="metal" mesh="hip_0"/>
        <geom name="//unnamed_geom_57" class="visual" pos="2.68263e-09 2.85507e-09 -1.00949e-07" quat="2.14617e-09 4.63268e-05 4.63268e-05 -1" material="gray" mesh="hip_1"/>
        <geom name="//unnamed_geom_58" class="collision" size="0.0430098 0.0186999" pos="0 -0.0805144 0" quat="0.707107 0.707107 0 0" type="cylinder"/>
        <geom name="//unnamed_geom_59" class="reward_collision_sphere" size="0.0560998" pos="0 -0.0704501 0"/>
        <body name="RR_thigh" pos="0.00249183 -0.0965984 -0.0019095" quat="1 -0.000303498 -0.000793782 -0.00016388">
          <inertial pos="-0.00374872 0.022583 -0.0272569" quat="0.552133 -0.0192903 0.0850556 0.829182" mass="0.923135" diaginertia="0.00566479 0.00596205 0.000293574"/>
          <joint name="RR_thigh_joint" pos="0 0 0" axis="0.00499277 -0.999984 0.00283761" stiffness="0.00106312" range="-4.53615 0.546257" armature="0.00948984" damping="0.0107029" frictionloss="0.187303"/>
          <geom name="//unnamed_geom_60" class="visual" material="metal" mesh="thigh_mirror_0"/>
          <geom name="//unnamed_geom_61" class="visual" material="gray" mesh="thigh_mirror_1"/>
          <geom name="//unnamed_geom_62" class="collision" size="0.0995771 0.0114537 0.0158949" pos="0 0 -0.0856543" quat="0.707107 0 0.707107 0" type="box"/>
          <body name="RR_calf" pos="-0.000611855 0.00174255 -0.170872" quat="0.999999 0.000347552 -0.000811696 0.000625433">
            <inertial pos="0.00758892 0.0013057 -0.114801" quat="0.701615 -0.00793381 -0.00331667 0.712505" mass="0.201122" diaginertia="0.00145899 0.00151256 1.80355e-05"/>
            <joint name="RR_calf_joint" pos="0 0 0" axis="-0.00392967 -0.999992 0.000720479" range="0.841671 2.76929" armature="0.00931132" damping="0.0174971" frictionloss="0.180242"/>
            <geom name="//unnamed_geom_63" class="visual" material="gray" mesh="calf_mirror_0"/>
            <geom name="//unnamed_geom_64" class="visual" material="black" mesh="calf_mirror_1"/>
            <geom name="RR_calf0" class="collision" size="0.0121549 0.0560998" pos="0.00994293 0 -0.0482559" quat="0.995004 0 -0.0998334 0" type="cylinder"/>
            <geom name="//unnamed_geom_66" class="collision" size="0.010285 0.0303874" pos="0.0198859 0 -0.119031" quat="0.999688 0 0.0249974 0" type="cylinder"/>
            <geom name="//unnamed_geom_67" class="visual" pos="0 0 -0.171309" quat="1 0 0 0" material="black" mesh="foot"/>
            <geom name="RR_foot" class="foot" size="0.0212982" pos="-0.00198859 0 -0.171309"/>
            <geom name="//unnamed_geom_69" class="reward_collision_sphere" size="0.0233749"/>
            <geom name="//unnamed_geom_70" class="reward_collision_sphere" size="0.0233749" pos="-0.00198859 0 -0.171309"/>
            <site name="RR_foot" class="foot" pos="-0.00198859 0 -0.171309" size="0.00934996"/>
          </body>
        </body>
      </body>
    </body>
  </worldbody>

  <contact>
    <pair class="/" geom1="floor" geom2="FL_foot" name="//unnamed_contact_0"/>
    <pair class="/" geom1="floor" geom2="FR_foot" name="//unnamed_contact_1"/>
    <pair class="/" geom1="floor" geom2="RL_foot" name="//unnamed_contact_2"/>
    <pair class="/" geom1="floor" geom2="RR_foot" name="//unnamed_contact_3"/>
  </contact>

  <actuator>
    <general name="FL_hip" class="/" joint="FL_hip_joint" forcerange="-20.9404 20.9404" gainprm="18.8236" biasprm="0 -18.8236 -0.468195"/>
    <general name="FL_thigh" class="/" joint="FL_thigh_joint" forcerange="-20.2098 20.2098" gainprm="18.8236" biasprm="0 -18.8236 -0.468195"/>
    <general name="FL_calf" class="/" joint="FL_calf_joint" forcerange="-43.9115 43.9115" gainprm="18.8236" biasprm="0 -18.8236 -0.468195"/>
    <general name="FR_hip" class="/" joint="FR_hip_joint" forcerange="-22.0484 22.0484" gainprm="18.8236" biasprm="0 -18.8236 -0.468195"/>
    <general name="FR_thigh" class="/" joint="FR_thigh_joint" forcerange="-22.8553 22.8553" gainprm="18.8236" biasprm="0 -18.8236 -0.468195"/>
    <general name="FR_calf" class="/" joint="FR_calf_joint" forcerange="-43.0732 43.0732" gainprm="18.8236" biasprm="0 -18.8236 -0.468195"/>
    <general name="RL_hip" class="/" joint="RL_hip_joint" forcerange="-22.2257 22.2257" gainprm="18.8236" biasprm="0 -18.8236 -0.468195"/>
    <general name="RL_thigh" class="/" joint="RL_thigh_joint" forcerange="-21.3439 21.3439" gainprm="18.8236" biasprm="0 -18.8236 -0.468195"/>
    <general name="RL_calf" class="/" joint="RL_calf_joint" forcerange="-40.9614 40.9614" gainprm="18.8236" biasprm="0 -18.8236 -0.468195"/>
    <general name="RR_hip" class="/" joint="RR_hip_joint" forcerange="-22.0978 22.0978" gainprm="18.8236" biasprm="0 -18.8236 -0.468195"/>
    <general name="RR_thigh" class="/" joint="RR_thigh_joint" forcerange="-23.7164 23.7164" gainprm="18.8236" biasprm="0 -18.8236 -0.468195"/>
    <general name="RR_calf" class="/" joint="RR_calf_joint" forcerange="-41.0509 41.0509" gainprm="18.8236" biasprm="0 -18.8236 -0.468195"/>
  </actuator>

  <sensor>
    <gyro site="imu" name="imu_angular_velocity"/>
    <velocimeter site="imu" name="imu_linear_velocity"/>
    <framelinvel objtype="site" objname="FL_foot" name="FL_foot_global_linear_velocity"/>
    <framelinvel objtype="site" objname="FR_foot" name="FR_foot_global_linear_velocity"/>
    <framelinvel objtype="site" objname="RL_foot" name="RL_foot_global_linear_velocity"/>
    <framelinvel objtype="site" objname="RR_foot" name="RR_foot_global_linear_velocity"/>
  </sensor>

  <keyframe>
    <key name="home" qpos="0 0 0.325 1 0 0 0 0.1 0.8 -1.5 -0.1 -0.8 1.5 -0.1 0.8 -1.5 0.1 -0.8 1.5"/>
  </keyframe>
</mujoco>
