<mujoco model="go2">
  <compiler angle="radian" assetdir="assets" balanceinertia="true" inertiafromgeom="false"/>

  <option timestep="0.005" density="1.2" viscosity="2e-05"/>

  <size nkey="1"/>

  <visual>
    <quality shadowsize="8192"/>
    <map shadowclip="0.5"/>
  </visual>

  <default>
    <default class="/">
      <geom contype="0" conaffinity="0" group="1" solref="-1000 -80"/>
      <site size="0.01 0.005 0.005" group="5"/>
      <general forcelimited="true" biastype="affine" gainprm="20" biasprm="0 -20 -0.5"/>
      <default class="go2">
        <joint armature="0.01" damping="0.01" frictionloss="0.2"/>
        <geom condim="1" margin="0.001"/>
        <default class="visual">
          <geom type="mesh" group="2"/>
        </default>
        <default class="collision">
          <geom group="3"/>
          <default class="foot">
            <geom size="0.022 0 0" condim="6" priority="1" friction="0.8 0.02 0.01" solimp="0.015 1 0.022"/>
          </default>
        </default>
        <default class="reward_collision_sphere">
          <geom group="5" rgba="1 0 0 1"/>
        </default>
      </default>
    </default>
  </default>

  <asset>
    <texture type="skybox" colorspace="auto" name="//unnamed_texture_0" builtin="gradient" rgb1="0.95 0.95 0.95" rgb2="0.95 0.95 0.95" width="100" height="600"/>
    <texture type="2d" colorspace="auto" name="texplane" builtin="checker" rgb1="0.345 0.575 0.748" rgb2="0.345 0.575 0.748" markrgb="1 1 1" width="512" height="512"/>
    <material name="MatPlane" class="/" texture="texplane" texuniform="true" texrepeat="2 2" specular="0.9"/>
    <material name="metal" class="/" rgba="0.9 0.95 0.95 1"/>
    <material name="black" class="/" rgba="0 0 0 1"/>
    <material name="white" class="/"/>
    <material name="gray" class="/" rgba="0.671705 0.692426 0.77427 1"/>
    <mesh name="base_0" class="/" file="base_0.obj"/>
    <mesh name="base_1" class="/" file="base_1.obj"/>
    <mesh name="base_2" class="/" file="base_2.obj"/>
    <mesh name="base_3" class="/" file="base_3.obj"/>
    <mesh name="base_4" class="/" file="base_4.obj"/>
    <mesh name="hip_0" class="/" file="hip_0.obj"/>
    <mesh name="hip_1" class="/" file="hip_1.obj"/>
    <mesh name="thigh_0" class="/" file="thigh_0.obj"/>
    <mesh name="thigh_1" class="/" file="thigh_1.obj"/>
    <mesh name="thigh_mirror_0" class="/" file="thigh_mirror_0.obj"/>
    <mesh name="thigh_mirror_1" class="/" file="thigh_mirror_1.obj"/>
    <mesh name="calf_0" class="/" file="calf_0.obj"/>
    <mesh name="calf_1" class="/" file="calf_1.obj"/>
    <mesh name="calf_mirror_0" class="/" file="calf_mirror_0.obj"/>
    <mesh name="calf_mirror_1" class="/" file="calf_mirror_1.obj"/>
    <mesh name="foot" class="/" file="foot.obj"/>
  </asset>

  <worldbody>
    <geom name="floor" class="/" size="100 100 0.125" type="plane" group="0" material="MatPlane"/>
    <light name="toplight_shadow" class="/" pos="0 0 5" dir="0.0990148 0.0990148 -0.990148" type="directional" ambient="0.04 0.04 0.04" diffuse="0.55 0.55 0.55" specular="0.12 0.12 0.12"/>
    <light name="toplight_fill" class="/" pos="0 0 5" dir="0.0990148 0.0990148 -0.990148" type="directional" castshadow="false" ambient="0.04 0.04 0.04" diffuse="0.3 0.3 0.3" specular="0.08 0.08 0.08"/>
    <body name="trunk" childclass="go2" pos="0.000815027 0.00102917 -0.00257565" quat="1 -0.000459265 -0.000662165 -3.94019e-06">
      <inertial pos="0.0177112 0.00263578 -0.00358625" quat="-0.000150671 0.713727 -0.00171993 0.700422" mass="5.09573" diaginertia="0.0667489 0.100559 0.00769434"/>
      <joint name="//unnamed_joint_0" type="free" armature="0" damping="0" frictionloss="0"/>
      <geom name="//unnamed_geom_1" class="visual" material="black" mesh="base_0"/>
      <geom name="//unnamed_geom_2" class="visual" material="black" mesh="base_1"/>
      <geom name="//unnamed_geom_3" class="visual" material="black" mesh="base_2"/>
      <geom name="//unnamed_geom_4" class="visual" material="white" mesh="base_3"/>
      <geom name="//unnamed_geom_5" class="visual" material="gray" mesh="base_4"/>
      <geom name="trunk_1" class="collision" size="0.168734 0.0419368 0.0511315" type="box"/>
      <geom name="trunk_2" class="collision" size="0.0448522 0.040367" pos="0.25791 0 0.00785878" type="cylinder"/>
      <geom name="trunk_3" class="collision" size="0.0421611" pos="0.265149 0 -0.0471527"/>
      <geom name="//unnamed_geom_9" class="reward_collision_sphere" size="0.0897044"/>
      <geom name="//unnamed_geom_10" class="reward_collision_sphere" size="0.0538226" pos="0.253385 0 -0.0353645"/>
      <site name="imu" pos="-0.0178919 0.0138905 0.0423856" size="0.00897044"/>
      <camera name="track" pos="0 -2.00061 0" quat="0.707107 0.707107 0 0" mode="trackcom"/>
      <camera name="ego_camera" pos="0.282343 0 0.0353645" quat="-0.5 -0.5 0.5 0.5"/>
      <body name="FL_hip" pos="0.172978 0.0466397 0.00318619" quat="0.999999 -0.000544515 -0.000777199 -0.000624171">
        <inertial pos="-0.00416688 -0.000526198 0.000545356" quat="0.494887 0.498578 0.504018 0.502467" mass="0.475878" diaginertia="0.000544102 0.000620086 0.000144312"/>
        <joint name="FL_hip_joint" pos="0 0 0" axis="0.999996 0.00093355 0.0026949" range="-1.02702 1.06859" armature="0.00898245" damping="0.0221185" frictionloss="0.181094"/>
        <geom name="//unnamed_geom_11" class="visual" material="metal" mesh="hip_0"/>
        <geom name="//unnamed_geom_12" class="visual" material="gray" mesh="hip_1"/>
        <geom name="//unnamed_geom_13" class="collision" size="0.041264 0.0179409" pos="0 0.0800246 0" quat="0.707107 0.707107 0 0" type="cylinder"/>
        <geom name="//unnamed_geom_14" class="reward_collision_sphere" size="0.0538226" pos="0 0.0700215 0"/>
        <body name="FL_thigh" pos="0.00150953 0.0959781 0.00307898" quat="0.999999 0.000513434 0.000569981 -0.000712398">
          <inertial pos="-0.00101609 -0.0249806 -0.0273834" quat="0.829569 0.0848386 -0.0200125 0.551559" mass="0.813357" diaginertia="0.00360456 0.00557987 0.000256328"/>
          <joint name="FL_thigh_joint" pos="0 0 0" axis="-0.000883582 0.999996 0.00270634" stiffness="0.00133231" range="-1.51624 3.50014" armature="0.00800485" damping="0.013562" frictionloss="0.162841"/>
          <geom name="//unnamed_geom_15" class="visual" material="metal" mesh="thigh_0"/>
          <geom name="//unnamed_geom_16" class="visual" material="gray" mesh="thigh_1"/>
          <geom name="//unnamed_geom_17" class="collision" size="0.0955352 0.0109888 0.0152497" pos="0 0 -0.083696" quat="0.707107 0 0.707107 0" type="box"/>
          <body name="FL_calf" pos="-0.000381522 -0.00177293 -0.168964" quat="0.999999 0.000621996 -0.000899881 0.000935428">
            <inertial pos="0.00335787 -0.00102473 -0.107827" quat="0.709591 -0.00902734 -0.00488405 0.704539" mass="0.173907" diaginertia="0.00087887 0.00152911 1.632e-05"/>
            <joint name="FL_calf_joint" pos="0 0 0" axis="-0.0118776 0.999765 0.0181172" stiffness="0.013783" range="-2.75637 -0.856854" armature="0.0100568" damping="0" frictionloss="0.204113"/>
            <geom name="//unnamed_geom_18" class="visual" material="gray" mesh="calf_0"/>
            <geom name="//unnamed_geom_19" class="visual" material="black" mesh="calf_1"/>
            <geom name="FL_calf0" class="collision" size="0.0107645 0.0538226" pos="0.00723957 0 -0.0471527" quat="0.994493 0 -0.104807 0" type="cylinder"/>
            <geom name="//unnamed_geom_21" class="collision" size="0.00986748 0.0291539" pos="0.0180989 0 -0.11631" quat="0.999688 0 0.0249974 0" type="cylinder"/>
            <geom name="//unnamed_geom_22" class="visual" pos="0 0 -0.167392" quat="1 0 0 0" material="black" mesh="foot"/>
            <geom name="FL_foot" class="foot" size="0.0168429" pos="-0.00180989 0 -0.167392"/>
            <geom name="//unnamed_geom_24" class="reward_collision_sphere" size="0.0224261"/>
            <geom name="//unnamed_geom_25" class="reward_collision_sphere" size="0.0224261" pos="-0.00180989 0 -0.167392"/>
            <site name="FL_foot" class="foot" pos="-0.00180989 0 -0.167392" size="0.00897044"/>
          </body>
        </body>
      </body>
      <body name="FR_hip" pos="0.175199 -0.045467 -0.00067152" quat="0.999999 0.000789822 -0.000498123 0.000664674">
        <inertial pos="-0.00191476 -0.0039226 -0.000325388" quat="0.493441 0.505547 0.494525 0.506343" mass="0.48682" diaginertia="0.000500634 0.000575855 0.000133923"/>
        <joint name="FR_hip_joint" pos="0 0 0" axis="0.99988 -0.0115327 0.0103" range="-1.01488 1.04488" armature="0.00948937" damping="0.00552984" frictionloss="0.159549"/>
        <geom name="//unnamed_geom_26" class="visual" pos="0 1.86802e-09 8.01232e-08" quat="4.63268e-05 1 0 0" material="metal" mesh="hip_0"/>
        <geom name="//unnamed_geom_27" class="visual" pos="0 3.02828e-09 -1.98175e-07" quat="4.63268e-05 1 0 0" material="gray" mesh="hip_1"/>
        <geom name="//unnamed_geom_28" class="collision" size="0.041264 0.0179409" pos="0 -0.0800246 0" quat="0.707107 0.707107 0 0" type="cylinder"/>
        <geom name="//unnamed_geom_29" class="reward_collision_sphere" size="0.0538226" pos="0 -0.0700215 0"/>
        <body name="FR_thigh" pos="0.000659386 -0.0963508 0.00300406" quat="1 0.000448493 -0.000291699 -0.000288422">
          <inertial pos="-0.000315132 0.0198188 -0.0246176" quat="0.552127 -0.0303804 0.0942626 0.827857" mass="0.832923" diaginertia="0.003538 0.00554605 0.000262168"/>
          <joint name="FR_thigh_joint" pos="0 0 0" axis="3.47493e-05 -1 -0.000892445" range="-3.47701 1.61752" armature="0.00908797" damping="0.00567129" frictionloss="0.201628"/>
          <geom name="//unnamed_geom_30" class="visual" material="metal" mesh="thigh_mirror_0"/>
          <geom name="//unnamed_geom_31" class="visual" material="gray" mesh="thigh_mirror_1"/>
          <geom name="//unnamed_geom_32" class="collision" size="0.0955352 0.0109888 0.0152497" pos="0 0 -0.083696" quat="0.707107 0 0.707107 0" type="box"/>
          <body name="FR_calf" pos="0.000789133 -0.0026077 -0.16911" quat="1 -5.67089e-05 -6.12112e-05 -0.000147332">
            <inertial pos="0.00527989 -0.000233118 -0.111231" quat="0.707637 -0.0119115 0.000228187 0.706476" mass="0.175743" diaginertia="0.000907051 0.00146499 1.53749e-05"/>
            <joint name="FR_calf_joint" pos="0 0 0" axis="-0.00782445 -0.999967 0.00206449" range="0.817278 2.77568" armature="0.00823842" damping="0.0233178" frictionloss="0.159475"/>
            <geom name="//unnamed_geom_33" class="visual" material="gray" mesh="calf_mirror_0"/>
            <geom name="//unnamed_geom_34" class="visual" material="black" mesh="calf_mirror_1"/>
            <geom name="FR_calf0" class="collision" size="0.0116616 0.0538226" pos="0.00904947 0 -0.0471527" quat="0.995004 0 -0.0998334 0" type="cylinder"/>
            <geom name="//unnamed_geom_36" class="collision" size="0.00986748 0.0291539" pos="0.0180989 0 -0.11631" quat="0.999688 0 0.0249974 0" type="cylinder"/>
            <geom name="//unnamed_geom_37" class="visual" pos="0 0 -0.167392" quat="1 0 0 0" material="black" mesh="foot"/>
            <geom name="FR_foot" class="foot" size="0.0200159" pos="-0.00180989 0 -0.167392"/>
            <geom name="//unnamed_geom_39" class="reward_collision_sphere" size="0.0224261"/>
            <geom name="//unnamed_geom_40" class="reward_collision_sphere" size="0.0224261" pos="-0.00180989 0 -0.167392"/>
            <site name="FR_foot" class="foot" pos="-0.00180989 0 -0.167392" size="0.00897044"/>
          </body>
        </body>
      </body>
      <body name="RL_hip" pos="-0.173508 0.0452228 -0.00288044" quat="1 -0.000397777 8.85207e-05 -0.000300057">
        <inertial pos="0.00669894 0.00347029 -0.00261065" quat="0.503605 0.498688 0.499178 0.498512" mass="0.500179" diaginertia="0.000531387 0.00060135 0.000147585"/>
        <joint name="RL_hip_joint" pos="0 0 0" axis="-0.999841 -0.0178448 -0.000443144" stiffness="0.0124189" range="-1.03321 0.988492" armature="0.00800686" damping="0" frictionloss="0.196784"/>
        <geom name="//unnamed_geom_41" class="visual" pos="-1.03728e-09 0 -2.0333e-07" quat="4.63268e-05 0 1 0" material="metal" mesh="hip_0"/>
        <geom name="//unnamed_geom_42" class="visual" pos="-1.68155e-09 0 -1.80325e-07" quat="4.63268e-05 0 1 0" material="gray" mesh="hip_1"/>
        <geom name="//unnamed_geom_43" class="collision" size="0.041264 0.0179409" pos="0 0.0800246 0" quat="0.707107 0.707107 0 0" type="cylinder"/>
        <geom name="//unnamed_geom_44" class="reward_collision_sphere" size="0.0538226" pos="0 0.0700215 0"/>
        <body name="RL_thigh" pos="0.000656971 0.0929107 0.00142534" quat="1 -6.06762e-05 -0.000225966 0.000275658">
          <inertial pos="-0.00340121 -0.0225387 -0.0258533" quat="0.828435 0.0911629 -0.0268086 0.551965" mass="0.855969" diaginertia="0.00362208 0.00590158 0.000276223"/>
          <joint name="RL_thigh_joint" pos="0 0 0" axis="0.0069509 0.999871 0.0144788" stiffness="0.0106626" range="-0.539591 4.53258" armature="0.0100775" damping="0" frictionloss="0.180742"/>
          <geom name="//unnamed_geom_45" class="visual" material="metal" mesh="thigh_0"/>
          <geom name="//unnamed_geom_46" class="visual" material="gray" mesh="thigh_1"/>
          <geom name="//unnamed_geom_47" class="collision" size="0.0955352 0.0109888 0.0152497" pos="0 0 -0.083696" quat="0.707107 0 0.707107 0" type="box"/>
          <body name="RL_calf" pos="0.000340151 -0.00132501 -0.168909" quat="1 -2.85593e-05 0.000184581 0.000197578">
            <inertial pos="0.00378114 0.000552868 -0.111976" quat="0.711738 0.00305726 -0.0180246 0.702207" mass="0.178174" diaginertia="0.000891298 0.00147912 1.60657e-05"/>
            <joint name="RL_calf_joint" pos="0 0 0" axis="0.00257912 0.999956 0.00900998" range="-2.71725 -0.786597" armature="0.010118" damping="0" frictionloss="0.190444"/>
            <geom name="//unnamed_geom_48" class="visual" material="gray" mesh="calf_0"/>
            <geom name="//unnamed_geom_49" class="visual" material="black" mesh="calf_1"/>
            <geom name="RL_calf0" class="collision" size="0.0116616 0.0538226" pos="0.00904947 0 -0.0471527" quat="0.995004 0 -0.0998334 0" type="cylinder"/>
            <geom name="//unnamed_geom_51" class="collision" size="0.00986748 0.0291539" pos="0.0180989 0 -0.11631" quat="0.999688 0 0.0249974 0" type="cylinder"/>
            <geom name="//unnamed_geom_52" class="visual" pos="0 0 -0.167392" quat="1 0 0 0" material="black" mesh="foot"/>
            <geom name="RL_foot" class="foot" size="0.0161813" pos="-0.00180989 0 -0.167392"/>
            <geom name="//unnamed_geom_54" class="reward_collision_sphere" size="0.0224261"/>
            <geom name="//unnamed_geom_55" class="reward_collision_sphere" size="0.0224261" pos="-0.00180989 0 -0.167392"/>
            <site name="RL_foot" class="foot" pos="-0.00180989 0 -0.167392" size="0.00897044"/>
          </body>
        </body>
      </body>
      <body name="RR_hip" pos="-0.172957 -0.0498388 -0.00353513" quat="1 1.75903e-05 -5.62186e-05 0.000442684">
        <inertial pos="0.00610503 0.000891208 -0.00157705" quat="0.504552 0.504115 0.496228 0.495028" mass="0.489674" diaginertia="0.000537917 0.000602648 0.000146137"/>
        <joint name="RR_hip_joint" pos="0 0 0" axis="-0.999985 0.00534004 -0.00077778" stiffness="0.0102621" range="-1.00491 1.0409" armature="0.00772843" damping="0.00289648" frictionloss="0.178526"/>
        <geom name="//unnamed_geom_56" class="visual" pos="1.04058e-09 1.86802e-09 -2.83453e-07" quat="2.14617e-09 4.63268e-05 4.63268e-05 -1" material="metal" mesh="hip_0"/>
        <geom name="//unnamed_geom_57" class="visual" pos="1.67338e-09 3.02828e-09 1.78505e-08" quat="2.14617e-09 4.63268e-05 4.63268e-05 -1" material="gray" mesh="hip_1"/>
        <geom name="//unnamed_geom_58" class="collision" size="0.041264 0.0179409" pos="0 -0.0800246 0" quat="0.707107 0.707107 0 0" type="cylinder"/>
        <geom name="//unnamed_geom_59" class="reward_collision_sphere" size="0.0538226" pos="0 -0.0700215 0"/>
        <body name="RR_thigh" pos="-4.14495e-05 -0.0967254 -0.000307123" quat="1 0.000125531 5.44006e-05 1.68346e-05">
          <inertial pos="-0.00256093 0.0228671 -0.0256242" quat="0.552315 -0.0187852 0.0842288 0.829157" mass="0.810851" diaginertia="0.00363506 0.00607196 0.000265362"/>
          <joint name="RR_thigh_joint" pos="0 0 0" axis="-8.80543e-05 -1 1.87479e-05" stiffness="0.00992185" range="-4.542 0.566415" armature="0.00943112" damping="0.0140876" frictionloss="0.179188"/>
          <geom name="//unnamed_geom_60" class="visual" material="metal" mesh="thigh_mirror_0"/>
          <geom name="//unnamed_geom_61" class="visual" material="gray" mesh="thigh_mirror_1"/>
          <geom name="//unnamed_geom_62" class="collision" size="0.0955352 0.0109888 0.0152497" pos="0 0 -0.083696" quat="0.707107 0 0.707107 0" type="box"/>
          <body name="RR_calf" pos="0.00174759 -0.00257018 -0.165359" quat="1 0.000302021 -0.000499725 -0.000136254">
            <inertial pos="0.00281368 -8.52687e-05 -0.111485" quat="0.706313 -0.017312 0.00489518 0.707671" mass="0.17616" diaginertia="0.000925766 0.00145796 1.63749e-05"/>
            <joint name="RR_calf_joint" pos="0 0 0" axis="-0.0130324 -0.999913 0.00180776" stiffness="0.0017723" range="0.810038 2.71324" armature="0.00846937" damping="0.0199287" frictionloss="0.169832"/>
            <geom name="//unnamed_geom_63" class="visual" material="gray" mesh="calf_mirror_0"/>
            <geom name="//unnamed_geom_64" class="visual" material="black" mesh="calf_mirror_1"/>
            <geom name="RR_calf0" class="collision" size="0.0116616 0.0538226" pos="0.00904947 0 -0.0471527" quat="0.995004 0 -0.0998334 0" type="cylinder"/>
            <geom name="//unnamed_geom_66" class="collision" size="0.00986748 0.0291539" pos="0.0180989 0 -0.11631" quat="0.999688 0 0.0249974 0" type="cylinder"/>
            <geom name="//unnamed_geom_67" class="visual" pos="0 0 -0.167392" quat="1 0 0 0" material="black" mesh="foot"/>
            <geom name="RR_foot" class="foot" size="0.0188911" pos="-0.00180989 0 -0.167392"/>
            <geom name="//unnamed_geom_69" class="reward_collision_sphere" size="0.0224261"/>
            <geom name="//unnamed_geom_70" class="reward_collision_sphere" size="0.0224261" pos="-0.00180989 0 -0.167392"/>
            <site name="RR_foot" class="foot" pos="-0.00180989 0 -0.167392" size="0.00897044"/>
          </body>
        </body>
      </body>
    </body>
  </worldbody>

  <contact>
    <pair class="/" geom1="floor" geom2="FL_foot" name="//unnamed_contact_0"/>
    <pair class="/" geom1="floor" geom2="FR_foot" name="//unnamed_contact_1"/>
    <pair class="/" geom1="floor" geom2="RL_foot" name="//unnamed_contact_2"/>
    <pair class="/" geom1="floor" geom2="RR_foot" name="//unnamed_contact_3"/>
  </contact>

  <actuator>
    <general name="FL_hip" class="/" joint="FL_hip_joint" forcerange="-21.4861 21.4861" gainprm="19.291" biasprm="0 -19.291 -0.420014"/>
    <general name="FL_thigh" class="/" joint="FL_thigh_joint" forcerange="-19.1366 19.1366" gainprm="19.291" biasprm="0 -19.291 -0.420014"/>
    <general name="FL_calf" class="/" joint="FL_calf_joint" forcerange="-41.6013 41.6013" gainprm="19.291" biasprm="0 -19.291 -0.420014"/>
    <general name="FR_hip" class="/" joint="FR_hip_joint" forcerange="-21.6356 21.6356" gainprm="19.291" biasprm="0 -19.291 -0.420014"/>
    <general name="FR_thigh" class="/" joint="FR_thigh_joint" forcerange="-23.3784 23.3784" gainprm="19.291" biasprm="0 -19.291 -0.420014"/>
    <general name="FR_calf" class="/" joint="FR_calf_joint" forcerange="-40.624 40.624" gainprm="19.291" biasprm="0 -19.291 -0.420014"/>
    <general name="RL_hip" class="/" joint="RL_hip_joint" forcerange="-22.2592 22.2592" gainprm="19.291" biasprm="0 -19.291 -0.420014"/>
    <general name="RL_thigh" class="/" joint="RL_thigh_joint" forcerange="-19.2575 19.2575" gainprm="19.291" biasprm="0 -19.291 -0.420014"/>
    <general name="RL_calf" class="/" joint="RL_calf_joint" forcerange="-38.4107 38.4107" gainprm="19.291" biasprm="0 -19.291 -0.420014"/>
    <general name="RR_hip" class="/" joint="RR_hip_joint" forcerange="-19.0683 19.0683" gainprm="19.291" biasprm="0 -19.291 -0.420014"/>
    <general name="RR_thigh" class="/" joint="RR_thigh_joint" forcerange="-22.5478 22.5478" gainprm="19.291" biasprm="0 -19.291 -0.420014"/>
    <general name="RR_calf" class="/" joint="RR_calf_joint" forcerange="-40.6915 40.6915" gainprm="19.291" biasprm="0 -19.291 -0.420014"/>
  </actuator>

  <sensor>
    <gyro site="imu" name="imu_angular_velocity"/>
    <velocimeter site="imu" name="imu_linear_velocity"/>
    <framelinvel objtype="site" objname="FL_foot" name="FL_foot_global_linear_velocity"/>
    <framelinvel objtype="site" objname="FR_foot" name="FR_foot_global_linear_velocity"/>
    <framelinvel objtype="site" objname="RL_foot" name="RL_foot_global_linear_velocity"/>
    <framelinvel objtype="site" objname="RR_foot" name="RR_foot_global_linear_velocity"/>
  </sensor>

  <keyframe>
    <key name="home" qpos="0 0 0.325 1 0 0 0 0.1 0.8 -1.5 -0.1 -0.8 1.5 -0.1 0.8 -1.5 0.1 -0.8 1.5"/>
  </keyframe>
</mujoco>
