<mujoco model="go2">
  <compiler angle="radian" assetdir="assets" balanceinertia="true" inertiafromgeom="false"/>

  <option timestep="0.005" density="1.2" viscosity="2e-05"/>

  <size nkey="1"/>

  <visual>
    <quality shadowsize="8192"/>
    <map shadowclip="0.5"/>
  </visual>

  <default>
    <default class="/">
      <geom contype="0" conaffinity="0" group="1" solref="-1000 -80"/>
      <site size="0.01 0.005 0.005" group="5"/>
      <general forcelimited="true" biastype="affine" gainprm="20" biasprm="0 -20 -0.5"/>
      <default class="go2">
        <joint armature="0.01" damping="0.01" frictionloss="0.2"/>
        <geom condim="1" margin="0.001"/>
        <default class="visual">
          <geom type="mesh" group="2"/>
        </default>
        <default class="collision">
          <geom group="3"/>
          <default class="foot">
            <geom size="0.022 0 0" condim="6" priority="1" friction="0.8 0.02 0.01" solimp="0.015 1 0.022"/>
          </default>
        </default>
        <default class="reward_collision_sphere">
          <geom group="5" rgba="1 0 0 1"/>
        </default>
      </default>
    </default>
  </default>

  <asset>
    <texture type="skybox" colorspace="auto" name="//unnamed_texture_0" builtin="gradient" rgb1="0.95 0.95 0.95" rgb2="0.95 0.95 0.95" width="100" height="600"/>
    <texture type="2d" colorspace="auto" name="texplane" builtin="checker" rgb1="0.345 0.575 0.748" rgb2="0.345 0.575 0.748" markrgb="1 1 1" width="512" height="512"/>
    <material name="MatPlane" class="/" texture="texplane" texuniform="true" texrepeat="2 2" specular="0.9"/>
    <material name="metal" class="/" rgba="0.9 0.95 0.95 1"/>
    <material name="black" class="/" rgba="0 0 0 1"/>
    <material name="white" class="/"/>
    <material name="gray" class="/" rgba="0.671705 0.692426 0.77427 1"/>
    <mesh name="base_0" class="/" file="base_0.obj"/>
    <mesh name="base_1" class="/" file="base_1.obj"/>
    <mesh name="base_2" class="/" file="base_2.obj"/>
    <mesh name="base_3" class="/" file="base_3.obj"/>
    <mesh name="base_4" class="/" file="base_4.obj"/>
    <mesh name="hip_0" class="/" file="hip_0.obj"/>
    <mesh name="hip_1" class="/" file="hip_1.obj"/>
    <mesh name="thigh_0" class="/" file="thigh_0.obj"/>
    <mesh name="thigh_1" class="/" file="thigh_1.obj"/>
    <mesh name="thigh_mirror_0" class="/" file="thigh_mirror_0.obj"/>
    <mesh name="thigh_mirror_1" class="/" file="thigh_mirror_1.obj"/>
    <mesh name="calf_0" class="/" file="calf_0.obj"/>
    <mesh name="calf_1" class="/" file="calf_1.obj"/>
    <mesh name="calf_mirror_0" class="/" file="calf_mirror_0.obj"/>
    <mesh name="calf_mirror_1" class="/" file="calf_mirror_1.obj"/>
    <mesh name="foot" class="/" file="foot.obj"/>
  </asset>

  <worldbody>
    <geom name="floor" class="/" size="100 100 0.125" type="plane" group="0" material="MatPlane"/>
    <light name="toplight_shadow" class="/" pos="0 0 5" dir="0.0990148 0.0990148 -0.990148" type="directional" ambient="0.04 0.04 0.04" diffuse="0.55 0.55 0.55" specular="0.12 0.12 0.12"/>
    <light name="toplight_fill" class="/" pos="0 0 5" dir="0.0990148 0.0990148 -0.990148" type="directional" castshadow="false" ambient="0.04 0.04 0.04" diffuse="0.3 0.3 0.3" specular="0.08 0.08 0.08"/>
    <body name="trunk" childclass="go2" pos="-0.00240713 0.000127939 -0.00250641" quat="1 -0.000603506 -1.48252e-05 0.000101171">
      <inertial pos="0.0193211 0.00275652 -0.00549846" quat="0.00175073 0.719295 0.000540099 0.694702" mass="5.59877" diaginertia="0.0445778 0.136415 0.0108044"/>
      <joint name="//unnamed_joint_0" type="free" armature="0" damping="0" frictionloss="0"/>
      <geom name="//unnamed_geom_1" class="visual" material="black" mesh="base_0"/>
      <geom name="//unnamed_geom_2" class="visual" material="black" mesh="base_1"/>
      <geom name="//unnamed_geom_3" class="visual" material="black" mesh="base_2"/>
      <geom name="//unnamed_geom_4" class="visual" material="white" mesh="base_3"/>
      <geom name="//unnamed_geom_5" class="visual" material="gray" mesh="base_4"/>
      <geom name="trunk_1" class="collision" size="0.171328 0.0425815 0.0519175" type="box"/>
      <geom name="trunk_2" class="collision" size="0.0455417 0.0409875" pos="0.237661 0 0.00837989" type="cylinder"/>
      <geom name="trunk_3" class="collision" size="0.0428092" pos="0.244332 0 -0.0502793"/>
      <geom name="//unnamed_geom_9" class="reward_collision_sphere" size="0.0910833"/>
      <geom name="//unnamed_geom_10" class="reward_collision_sphere" size="0.05465" pos="0.233491 0 -0.0377095"/>
      <site name="imu" pos="-0.0219311 0.0109188 0.0310849" size="0.00910833"/>
      <camera name="track" pos="0 -2.12123 0" quat="0.707107 0.707107 0 0" mode="trackcom"/>
      <camera name="ego_camera" pos="0.260176 0 0.0377095" quat="-0.5 -0.5 0.5 0.5"/>
      <body name="FL_hip" pos="0.158707 0.0471912 0.00265027" quat="0.999999 0.000558733 0.000864371 0.000761688">
        <inertial pos="-0.00190786 0.00122997 -0.00178643" quat="0.497551 0.497289 0.505656 0.499458" mass="0.509747" diaginertia="0.000354775 0.000845454 0.000198635"/>
        <joint name="FL_hip_joint" pos="0 0 0" axis="0.999913 -0.0126809 0.00352217" range="-1.08876 1.03504" armature="0.00925225" damping="0.0214998" frictionloss="0.184591"/>
        <geom name="//unnamed_geom_11" class="visual" material="metal" mesh="hip_0"/>
        <geom name="//unnamed_geom_12" class="visual" material="gray" mesh="hip_1"/>
        <geom name="//unnamed_geom_13" class="collision" size="0.0418983 0.0182167" pos="0 0.0848492 0" quat="0.707107 0.707107 0 0" type="cylinder"/>
        <geom name="//unnamed_geom_14" class="reward_collision_sphere" size="0.05465" pos="0 0.074243 0"/>
        <body name="FL_thigh" pos="0.00174137 0.100574 0.00188513" quat="1 -2.55453e-05 5.97047e-05 6.64337e-05">
          <inertial pos="-0.00225888 -0.0251844 -0.0263479" quat="0.829455 0.0849191 -0.0197169 0.551728" mass="0.863657" diaginertia="0.00244246 0.00774042 0.000346419"/>
          <joint name="FL_thigh_joint" pos="0 0 0" axis="-0.00991898 0.999936 0.00545773" stiffness="0.0164956" range="-1.51803 3.48848" armature="0.00791166" damping="0.00253685" frictionloss="0.15705"/>
          <geom name="//unnamed_geom_15" class="visual" material="metal" mesh="thigh_0"/>
          <geom name="//unnamed_geom_16" class="visual" material="gray" mesh="thigh_1"/>
          <geom name="//unnamed_geom_17" class="collision" size="0.0970038 0.0111577 0.0154842" pos="0 0 -0.0892458" quat="0.707107 0 0.707107 0" type="box"/>
          <body name="FL_calf" pos="0.000218655 0.000966061 -0.180556" quat="1 0.000353567 -0.000431912 -0.000677858">
            <inertial pos="0.00512076 -0.000171486 -0.116824" quat="0.704119 0.00308964 -0.0143891 0.70993" mass="0.181747" diaginertia="0.00056649 0.00193621 2.1918e-05"/>
            <joint name="FL_calf_joint" pos="0 0 0" axis="0.00424009 0.999742 -0.022328" stiffness="0.00733033" range="-2.70063 -0.836924" armature="0.0100705" damping="0.00737421" frictionloss="0.203116"/>
            <geom name="//unnamed_geom_18" class="visual" material="gray" mesh="calf_0"/>
            <geom name="//unnamed_geom_19" class="visual" material="black" mesh="calf_1"/>
            <geom name="FL_calf0" class="collision" size="0.01093 0.05465" pos="0.00667117 0 -0.0502793" quat="0.994493 0 -0.104807 0" type="cylinder"/>
            <geom name="//unnamed_geom_21" class="collision" size="0.0100192 0.0296021" pos="0.0166779 0 -0.124022" quat="0.999688 0 0.0249974 0" type="cylinder"/>
            <geom name="//unnamed_geom_22" class="visual" pos="0 0 -0.178492" quat="1 0 0 0" material="black" mesh="foot"/>
            <geom name="FL_foot" class="foot" size="0.0158204" pos="-0.00166779 0 -0.178492"/>
            <geom name="//unnamed_geom_24" class="reward_collision_sphere" size="0.0227708"/>
            <geom name="//unnamed_geom_25" class="reward_collision_sphere" size="0.0227708" pos="-0.00166779 0 -0.178492"/>
            <site name="FL_foot" class="foot" pos="-0.00166779 0 -0.178492" size="0.00910833"/>
          </body>
        </body>
      </body>
      <body name="FR_hip" pos="0.163471 -0.047103 0.00188246" quat="1 -2.06299e-05 -0.000147915 -4.08239e-05">
        <inertial pos="-0.00209876 -0.00147049 -0.000190586" quat="0.498247 0.505472 0.499267 0.496971" mass="0.515082" diaginertia="0.000343737 0.000777627 0.000189318"/>
        <joint name="FR_hip_joint" pos="0 0 0" axis="0.999931 0.00133432 -0.0116378" range="-0.99601 1.05589" armature="0.0101929" damping="0.0122314" frictionloss="0.183688"/>
        <geom name="//unnamed_geom_26" class="visual" pos="0 1.93942e-09 8.31859e-08" quat="4.63268e-05 1 0 0" material="metal" mesh="hip_0"/>
        <geom name="//unnamed_geom_27" class="visual" pos="0 3.14404e-09 -2.05751e-07" quat="4.63268e-05 1 0 0" material="gray" mesh="hip_1"/>
        <geom name="//unnamed_geom_28" class="collision" size="0.0418983 0.0182167" pos="0 -0.0848492 0" quat="0.707107 0.707107 0 0" type="cylinder"/>
        <geom name="//unnamed_geom_29" class="reward_collision_sphere" size="0.05465" pos="0 -0.074243 0"/>
        <body name="FR_thigh" pos="0.000222115 -0.09905 0.00311297" quat="1 0.000110967 -0.000143191 9.10513e-05">
          <inertial pos="-0.000828178 0.0230206 -0.027616" quat="0.546989 -0.0226414 0.0898087 0.832" mass="0.862113" diaginertia="0.00231698 0.00734221 0.000352025"/>
          <joint name="FR_thigh_joint" pos="0 0 0" axis="0.0108752 -0.99993 0.0046265" range="-3.51432 1.57466" armature="0.00890626" damping="0.000740138" frictionloss="0.20613"/>
          <geom name="//unnamed_geom_30" class="visual" material="metal" mesh="thigh_mirror_0"/>
          <geom name="//unnamed_geom_31" class="visual" material="gray" mesh="thigh_mirror_1"/>
          <geom name="//unnamed_geom_32" class="collision" size="0.0970038 0.0111577 0.0154842" pos="0 0 -0.0892458" quat="0.707107 0 0.707107 0" type="box"/>
          <body name="FR_calf" pos="-0.00203489 -0.000462672 -0.180979" quat="1 0.00014437 2.07017e-05 0.000118895">
            <inertial pos="0.0054455 0.000610574 -0.11952" quat="0.70381 -0.0011762 8.36513e-05 0.710387" mass="0.183894" diaginertia="0.000597733 0.00196053 2.16863e-05"/>
            <joint name="FR_calf_joint" pos="0 0 0" axis="0.00435163 -0.999981 -0.00436007" stiffness="0.00778773" range="0.833265 2.74362" armature="0.00785692" damping="0.0105961" frictionloss="0.157598"/>
            <geom name="//unnamed_geom_33" class="visual" material="gray" mesh="calf_mirror_0"/>
            <geom name="//unnamed_geom_34" class="visual" material="black" mesh="calf_mirror_1"/>
            <geom name="FR_calf0" class="collision" size="0.0118408 0.05465" pos="0.00833897 0 -0.0502793" quat="0.995004 0 -0.0998334 0" type="cylinder"/>
            <geom name="//unnamed_geom_36" class="collision" size="0.0100192 0.0296021" pos="0.0166779 0 -0.124022" quat="0.999688 0 0.0249974 0" type="cylinder"/>
            <geom name="//unnamed_geom_37" class="visual" pos="0 0 -0.178492" quat="1 0 0 0" material="black" mesh="foot"/>
            <geom name="FR_foot" class="foot" size="0.0197957" pos="-0.00166779 0 -0.178492"/>
            <geom name="//unnamed_geom_39" class="reward_collision_sphere" size="0.0227708"/>
            <geom name="//unnamed_geom_40" class="reward_collision_sphere" size="0.0227708" pos="-0.00166779 0 -0.178492"/>
            <site name="FR_foot" class="foot" pos="-0.00166779 0 -0.178492" size="0.00910833"/>
          </body>
        </body>
      </body>
      <body name="RL_hip" pos="-0.160472 0.0482408 -0.000642595" quat="1 -0.000370785 0.000157636 7.11504e-06">
        <inertial pos="0.00698845 0.000500378 -0.000864446" quat="0.498135 0.492693 0.506366 0.502701" mass="0.516411" diaginertia="0.000367053 0.00083049 0.000201142"/>
        <joint name="RL_hip_joint" pos="0 0 0" axis="-0.99975 0.0112768 0.0192864" stiffness="0.0043688" range="-1.06717 1.00688" armature="0.00906579" damping="0" frictionloss="0.175862"/>
        <geom name="//unnamed_geom_41" class="visual" pos="3.56497e-11 0 6.98818e-09" quat="4.63268e-05 0 1 0" material="metal" mesh="hip_0"/>
        <geom name="//unnamed_geom_42" class="visual" pos="5.77925e-11 0 6.19752e-09" quat="4.63268e-05 0 1 0" material="gray" mesh="hip_1"/>
        <geom name="//unnamed_geom_43" class="collision" size="0.0418983 0.0182167" pos="0 0.0848492 0" quat="0.707107 0.707107 0 0" type="cylinder"/>
        <geom name="//unnamed_geom_44" class="reward_collision_sphere" size="0.05465" pos="0 0.074243 0"/>
        <body name="RL_thigh" pos="-0.000527958 0.101657 -0.00101257" quat="1 -0.000101891 -0.000226696 -0.000402483">
          <inertial pos="-0.00324362 -0.0235925 -0.0256367" quat="0.824946 0.0754554 -0.0239153 0.559642" mass="0.878914" diaginertia="0.00245485 0.00824882 0.000381754"/>
          <joint name="RL_thigh_joint" pos="0 0 0" axis="0.00307163 0.999968 -0.00733287" stiffness="9.1894e-05" range="-0.528831 4.53117" armature="0.00940109" damping="0" frictionloss="0.180584"/>
          <geom name="//unnamed_geom_45" class="visual" material="metal" mesh="thigh_0"/>
          <geom name="//unnamed_geom_46" class="visual" material="gray" mesh="thigh_1"/>
          <geom name="//unnamed_geom_47" class="collision" size="0.0970038 0.0111577 0.0154842" pos="0 0 -0.0892458" quat="0.707107 0 0.707107 0" type="box"/>
          <body name="RL_calf" pos="-8.26781e-05 -0.00197765 -0.177111" quat="0.999999 -0.000512483 0.00102989 0.000184822">
            <inertial pos="0.00247369 -0.00264845 -0.118862" quat="0.709663 0.012399 -0.00756927 0.704391" mass="0.188157" diaginertia="0.000604348 0.00202076 2.33224e-05"/>
            <joint name="RL_calf_joint" pos="0 0 0" axis="-0.0194375 0.999725 0.013096" stiffness="0.0148699" range="-2.73345 -0.786006" armature="0.00997051" damping="0" frictionloss="0.165697"/>
            <geom name="//unnamed_geom_48" class="visual" material="gray" mesh="calf_0"/>
            <geom name="//unnamed_geom_49" class="visual" material="black" mesh="calf_1"/>
            <geom name="RL_calf0" class="collision" size="0.0118408 0.05465" pos="0.00833897 0 -0.0502793" quat="0.995004 0 -0.0998334 0" type="cylinder"/>
            <geom name="//unnamed_geom_51" class="collision" size="0.0100192 0.0296021" pos="0.0166779 0 -0.124022" quat="0.999688 0 0.0249974 0" type="cylinder"/>
            <geom name="//unnamed_geom_52" class="visual" pos="0 0 -0.178492" quat="1 0 0 0" material="black" mesh="foot"/>
            <geom name="RL_foot" class="foot" size="0.0174816" pos="-0.00166779 0 -0.178492"/>
            <geom name="//unnamed_geom_54" class="reward_collision_sphere" size="0.0227708"/>
            <geom name="//unnamed_geom_55" class="reward_collision_sphere" size="0.0227708" pos="-0.00166779 0 -0.178492"/>
            <site name="RL_foot" class="foot" pos="-0.00166779 0 -0.178492" size="0.00910833"/>
          </body>
        </body>
      </body>
      <body name="RR_hip" pos="-0.158223 -0.0519694 -0.00459285" quat="1 0.000330286 0.000221861 -0.000860916">
        <inertial pos="0.00266554 -0.00110467 0.00150113" quat="0.499653 0.49305 0.497219 0.509924" mass="0.514517" diaginertia="0.00036165 0.000810239 0.000198301"/>
        <joint name="RR_hip_joint" pos="0 0 0" axis="-0.999943 0.00986983 -0.00414573" stiffness="0.00341384" range="-0.989749 1.07592" armature="0.00787483" damping="0" frictionloss="0.198472"/>
        <geom name="//unnamed_geom_56" class="visual" pos="-2.78007e-11 1.93942e-09 -7.61977e-08" quat="2.14617e-09 4.63268e-05 4.63268e-05 -1" material="metal" mesh="hip_0"/>
        <geom name="//unnamed_geom_57" class="visual" pos="-7.72066e-11 3.14404e-09 2.11948e-07" quat="2.14617e-09 4.63268e-05 4.63268e-05 -1" material="gray" mesh="hip_1"/>
        <geom name="//unnamed_geom_58" class="collision" size="0.0418983 0.0182167" pos="0 -0.0848492 0" quat="0.707107 0.707107 0 0" type="cylinder"/>
        <geom name="//unnamed_geom_59" class="reward_collision_sphere" size="0.05465" pos="0 -0.074243 0"/>
        <body name="RR_thigh" pos="-0.00144948 -0.103202 0.00262442" quat="1 0.000541777 0.000419132 0.000315343">
          <inertial pos="-0.00424064 0.0232428 -0.0274858" quat="0.554631 -0.0179534 0.084279 0.827623" mass="0.870451" diaginertia="0.00234461 0.00796617 0.000362006"/>
          <joint name="RR_thigh_joint" pos="0 0 0" axis="-0.0116162 -0.999932 -0.00120847" stiffness="0.00937669" range="-4.52877 0.517504" armature="0.00889963" damping="0.0229861" frictionloss="0.199139"/>
          <geom name="//unnamed_geom_60" class="visual" material="metal" mesh="thigh_mirror_0"/>
          <geom name="//unnamed_geom_61" class="visual" material="gray" mesh="thigh_mirror_1"/>
          <geom name="//unnamed_geom_62" class="collision" size="0.0970038 0.0111577 0.0154842" pos="0 0 -0.0892458" quat="0.707107 0 0.707107 0" type="box"/>
          <body name="RR_calf" pos="0.00393822 -0.000950286 -0.176374" quat="1 0.00011795 -0.000217672 -0.000216321">
            <inertial pos="0.00414096 0.00176435 -0.117944" quat="0.698339 -0.00663045 0.00957083 0.715673" mass="0.181974" diaginertia="0.000619203 0.00193474 2.19259e-05"/>
            <joint name="RR_calf_joint" pos="0 0 0" axis="0.00246652 -0.999997 -0.000617602" range="0.788011 2.73608" armature="0.00794175" damping="0.00534039" frictionloss="0.158664"/>
            <geom name="//unnamed_geom_63" class="visual" material="gray" mesh="calf_mirror_0"/>
            <geom name="//unnamed_geom_64" class="visual" material="black" mesh="calf_mirror_1"/>
            <geom name="RR_calf0" class="collision" size="0.0118408 0.05465" pos="0.00833897 0 -0.0502793" quat="0.995004 0 -0.0998334 0" type="cylinder"/>
            <geom name="//unnamed_geom_66" class="collision" size="0.0100192 0.0296021" pos="0.0166779 0 -0.124022" quat="0.999688 0 0.0249974 0" type="cylinder"/>
            <geom name="//unnamed_geom_67" class="visual" pos="0 0 -0.178492" quat="1 0 0 0" material="black" mesh="foot"/>
            <geom name="RR_foot" class="foot" size="0.0199672" pos="-0.00166779 0 -0.178492"/>
            <geom name="//unnamed_geom_69" class="reward_collision_sphere" size="0.0227708"/>
            <geom name="//unnamed_geom_70" class="reward_collision_sphere" size="0.0227708" pos="-0.00166779 0 -0.178492"/>
            <site name="RR_foot" class="foot" pos="-0.00166779 0 -0.178492" size="0.00910833"/>
          </body>
        </body>
      </body>
    </body>
  </worldbody>

  <contact>
    <pair class="/" geom1="floor" geom2="FL_foot" name="//unnamed_contact_0"/>
    <pair class="/" geom1="floor" geom2="FR_foot" name="//unnamed_contact_1"/>
    <pair class="/" geom1="floor" geom2="RL_foot" name="//unnamed_contact_2"/>
    <pair class="/" geom1="floor" geom2="RR_foot" name="//unnamed_contact_3"/>
  </contact>

  <actuator>
    <general name="FL_hip" class="/" joint="FL_hip_joint" forcerange="-21.1241 21.1241" gainprm="19.1768" biasprm="0 -19.1768 -0.444579"/>
    <general name="FL_thigh" class="/" joint="FL_thigh_joint" forcerange="-19.8191 19.8191" gainprm="19.1768" biasprm="0 -19.1768 -0.444579"/>
    <general name="FL_calf" class="/" joint="FL_calf_joint" forcerange="-39.3793 39.3793" gainprm="19.1768" biasprm="0 -19.1768 -0.444579"/>
    <general name="FR_hip" class="/" joint="FR_hip_joint" forcerange="-22.1189 22.1189" gainprm="19.1768" biasprm="0 -19.1768 -0.444579"/>
    <general name="FR_thigh" class="/" joint="FR_thigh_joint" forcerange="-23.3548 23.3548" gainprm="19.1768" biasprm="0 -19.1768 -0.444579"/>
    <general name="FR_calf" class="/" joint="FR_calf_joint" forcerange="-42.8125 42.8125" gainprm="19.1768" biasprm="0 -19.1768 -0.444579"/>
    <general name="RL_hip" class="/" joint="RL_hip_joint" forcerange="-20.2265 20.2265" gainprm="19.1768" biasprm="0 -19.1768 -0.444579"/>
    <general name="RL_thigh" class="/" joint="RL_thigh_joint" forcerange="-19.691 19.691" gainprm="19.1768" biasprm="0 -19.1768 -0.444579"/>
    <general name="RL_calf" class="/" joint="RL_calf_joint" forcerange="-43.6164 43.6164" gainprm="19.1768" biasprm="0 -19.1768 -0.444579"/>
    <general name="RR_hip" class="/" joint="RR_hip_joint" forcerange="-20.5004 20.5004" gainprm="19.1768" biasprm="0 -19.1768 -0.444579"/>
    <general name="RR_thigh" class="/" joint="RR_thigh_joint" forcerange="-20.5984 20.5984" gainprm="19.1768" biasprm="0 -19.1768 -0.444579"/>
    <general name="RR_calf" class="/" joint="RR_calf_joint" forcerange="-44.7418 44.7418" gainprm="19.1768" biasprm="0 -19.1768 -0.444579"/>
  </actuator>

  <sensor>
    <gyro site="imu" name="imu_angular_velocity"/>
    <velocimeter site="imu" name="imu_linear_velocity"/>
    <framelinvel objtype="site" objname="FL_foot" name="FL_foot_global_linear_velocity"/>
    <framelinvel objtype="site" objname="FR_foot" name="FR_foot_global_linear_velocity"/>
    <framelinvel objtype="site" objname="RL_foot" name="RL_foot_global_linear_velocity"/>
    <framelinvel objtype="site" objname="RR_foot" name="RR_foot_global_linear_velocity"/>
  </sensor>

  <keyframe>
    <key name="home" qpos="0 0 0.325 1 0 0 0 0.1 0.8 -1.5 -0.1 -0.8 1.5 -0.1 0.8 -1.5 0.1 -0.8 1.5"/>
  </keyframe>
</mujoco>
