<mujoco model="go2">
  <compiler angle="radian" assetdir="assets" balanceinertia="true" inertiafromgeom="false"/>

  <option timestep="0.005" density="1.2" viscosity="2e-05"/>

  <size nkey="1"/>

  <visual>
    <quality shadowsize="8192"/>
    <map shadowclip="0.5"/>
  </visual>

  <default>
    <default class="/">
      <geom contype="0" conaffinity="0" group="1" solref="-1000 -80"/>
      <site size="0.01 0.005 0.005" group="5"/>
      <general forcelimited="true" biastype="affine" gainprm="20" biasprm="0 -20 -0.5"/>
      <default class="go2">
        <joint armature="0.01" damping="0.01" frictionloss="0.2"/>
        <geom condim="1" margin="0.001"/>
        <default class="visual">
          <geom type="mesh" group="2"/>
        </default>
        <default class="collision">
          <geom group="3"/>
          <default class="foot">
            <geom size="0.022 0 0" condim="6" priority="1" friction="0.8 0.02 0.01" solimp="0.015 1 0.022"/>
          </default>
        </default>
        <default class="reward_collision_sphere">
          <geom group="5" rgba="1 0 0 1"/>
        </default>
      </default>
    </default>
  </default>

  <asset>
    <texture type="skybox" colorspace="auto" name="//unnamed_texture_0" builtin="gradient" rgb1="0.95 0.95 0.95" rgb2="0.95 0.95 0.95" width="100" height="600"/>
    <texture type="2d" colorspace="auto" name="texplane" builtin="checker" rgb1="0.345 0.575 0.748" rgb2="0.345 0.575 0.748" markrgb="1 1 1" width="512" height="512"/>
    <material name="MatPlane" class="/" texture="texplane" texuniform="true" texrepeat="2 2" specular="0.9"/>
    <material name="metal" class="/" rgba="0.9 0.95 0.95 1"/>
    <material name="black" class="/" rgba="0 0 0 1"/>
    <material name="white" class="/"/>
    <material name="gray" class="/" rgba="0.671705 0.692426 0.77427 1"/>
    <mesh name="base_0" class="/" file="base_0.obj"/>
    <mesh name="base_1" class="/" file="base_1.obj"/>
    <mesh name="base_2" class="/" file="base_2.obj"/>
    <mesh name="base_3" class="/" file="base_3.obj"/>
    <mesh name="base_4" class="/" file="base_4.obj"/>
    <mesh name="hip_0" class="/" file="hip_0.obj"/>
    <mesh name="hip_1" class="/" file="hip_1.obj"/>
    <mesh name="thigh_0" class="/" file="thigh_0.obj"/>
    <mesh name="thigh_1" class="/" file="thigh_1.obj"/>
    <mesh name="thigh_mirror_0" class="/" file="thigh_mirror_0.obj"/>
    <mesh name="thigh_mirror_1" class="/" file="thigh_mirror_1.obj"/>
    <mesh name="calf_0" class="/" file="calf_0.obj"/>
    <mesh name="calf_1" class="/" file="calf_1.obj"/>
    <mesh name="calf_mirror_0" class="/" file="calf_mirror_0.obj"/>
    <mesh name="calf_mirror_1" class="/" file="calf_mirror_1.obj"/>
    <mesh name="foot" class="/" file="foot.obj"/>
  </asset>

  <worldbody>
    <geom name="floor" class="/" size="100 100 0.125" type="plane" group="0" material="MatPlane"/>
    <light name="toplight_shadow" class="/" pos="0 0 5" dir="0.0990148 0.0990148 -0.990148" type="directional" ambient="0.04 0.04 0.04" diffuse="0.55 0.55 0.55" specular="0.12 0.12 0.12"/>
    <light name="toplight_fill" class="/" pos="0 0 5" dir="0.0990148 0.0990148 -0.990148" type="directional" castshadow="false" ambient="0.04 0.04 0.04" diffuse="0.3 0.3 0.3" specular="0.08 0.08 0.08"/>
    <body name="trunk" childclass="go2" pos="-0.000109917 -0.00282594 -0.000881736" quat="1 -1.56783e-05 1.08033e-05 -3.06382e-05">
      <inertial pos="0.022706 -0.00291832 -0.00437794" quat="-0.00610976 0.713476 0.00287287 0.700647" mass="6.65782" diaginertia="0.132467 0.136933 0.0110212"/>
      <joint name="//unnamed_joint_0" type="free" armature="0" damping="0" frictionloss="0"/>
      <geom name="//unnamed_geom_1" class="visual" material="black" mesh="base_0"/>
      <geom name="//unnamed_geom_2" class="visual" material="black" mesh="base_1"/>
      <geom name="//unnamed_geom_3" class="visual" material="black" mesh="base_2"/>
      <geom name="//unnamed_geom_4" class="visual" material="white" mesh="base_3"/>
      <geom name="//unnamed_geom_5" class="visual" material="gray" mesh="base_4"/>
      <geom name="trunk_1" class="collision" size="0.186718 0.0464066 0.0565814" type="box"/>
      <geom name="trunk_2" class="collision" size="0.0496328 0.0446695" pos="0.299321 0 0.00853465" type="cylinder"/>
      <geom name="trunk_3" class="collision" size="0.0466548" pos="0.307723 0 -0.0512079"/>
      <geom name="//unnamed_geom_9" class="reward_collision_sphere" size="0.0992655"/>
      <geom name="//unnamed_geom_10" class="reward_collision_sphere" size="0.0595593" pos="0.29407 0 -0.0384059"/>
      <site name="imu" pos="-0.0127046 0.0119107 0.0219862" size="0.00992655"/>
      <camera name="track" pos="0 -2.1485 0" quat="0.707107 0.707107 0 0" mode="trackcom"/>
      <camera name="ego_camera" pos="0.327678 0 0.0384059" quat="-0.5 -0.5 0.5 0.5"/>
      <body name="FL_hip" pos="0.205351 0.0515133 0.00208944" quat="0.999999 -0.000960101 -0.000237835 0.000731197">
        <inertial pos="-0.00464052 0.00224445 0.00202739" quat="0.501125 0.496797 0.504052 0.497995" mass="0.637037" diaginertia="0.00112822 0.000813431 0.000216681"/>
        <joint name="FL_hip_joint" pos="0 0 0" axis="0.999977 -0.00532651 0.00415215" stiffness="0.0120953" range="-1.01971 1.09121" armature="0.00995886" damping="0" frictionloss="0.225807"/>
        <geom name="//unnamed_geom_11" class="visual" material="metal" mesh="hip_0"/>
        <geom name="//unnamed_geom_12" class="visual" material="gray" mesh="hip_1"/>
        <geom name="//unnamed_geom_13" class="collision" size="0.0456621 0.0198531" pos="0 0.08594 0" quat="0.707107 0.707107 0 0" type="cylinder"/>
        <geom name="//unnamed_geom_14" class="reward_collision_sphere" size="0.0595593" pos="0 0.0751975 0"/>
        <body name="FL_thigh" pos="-0.000513884 0.10414 0.000440838" quat="0.999999 -0.000448964 -0.00131459 -0.000747537">
          <inertial pos="-0.001146 -0.0213576 -0.0288263" quat="0.830616 0.0717154 -0.0220172 0.55177" mass="1.12535" diaginertia="0.0074897 0.00831298 0.000395052"/>
          <joint name="FL_thigh_joint" pos="0 0 0" axis="-0.0176105 0.999831 0.0052379" stiffness="0.00478602" range="-1.52888 3.53605" armature="0.0113073" damping="0" frictionloss="0.208477"/>
          <geom name="//unnamed_geom_15" class="visual" material="metal" mesh="thigh_0"/>
          <geom name="//unnamed_geom_16" class="visual" material="gray" mesh="thigh_1"/>
          <geom name="//unnamed_geom_17" class="collision" size="0.105718 0.01216 0.0168751" pos="0 0 -0.0908941" quat="0.707107 0 0.707107 0" type="box"/>
          <body name="FL_calf" pos="-0.000271405 -0.00252133 -0.183076" quat="0.999999 -0.000821114 -0.000388018 -0.000712576">
            <inertial pos="0.0093451 -0.000838379 -0.122109" quat="0.710572 0.00153864 -0.0047212 0.703607" mass="0.239811" diaginertia="0.00184132 0.0021562 2.35042e-05"/>
            <joint name="FL_calf_joint" pos="0 0 0" axis="-0.00730296 0.999971 0.00214065" range="-2.7604 -0.828247" armature="0.00860706" damping="0.00352597" frictionloss="0.201394"/>
            <geom name="//unnamed_geom_18" class="visual" material="gray" mesh="calf_0"/>
            <geom name="//unnamed_geom_19" class="visual" material="black" mesh="calf_1"/>
            <geom name="FL_calf0" class="collision" size="0.0119119 0.0595593" pos="0.008402 0 -0.0512079" quat="0.994493 0 -0.104807 0" type="cylinder"/>
            <geom name="//unnamed_geom_21" class="collision" size="0.0109192 0.0322613" pos="0.021005 0 -0.126313" quat="0.999688 0 0.0249974 0" type="cylinder"/>
            <geom name="//unnamed_geom_22" class="visual" pos="0 0 -0.181788" quat="1 0 0 0" material="black" mesh="foot"/>
            <geom name="FL_foot" class="foot" size="0.0159516" pos="-0.0021005 0 -0.181788"/>
            <geom name="//unnamed_geom_24" class="reward_collision_sphere" size="0.0248164"/>
            <geom name="//unnamed_geom_25" class="reward_collision_sphere" size="0.0248164" pos="-0.0021005 0 -0.181788"/>
            <site name="FL_foot" class="foot" pos="-0.0021005 0 -0.181788" size="0.00992655"/>
          </body>
        </body>
      </body>
      <body name="FR_hip" pos="0.203006 -0.0525079 -0.002474" quat="1 2.54268e-07 -3.45016e-06 -1.94082e-06">
        <inertial pos="-0.00598105 -0.00297173 -0.000152517" quat="0.497251 0.505605 0.498315 0.498785" mass="0.634901" diaginertia="0.00111284 0.000828463 0.00022266"/>
        <joint name="FR_hip_joint" pos="0 0 0" axis="0.999911 0.00219675 -0.0131511" range="-1.05051 1.05945" armature="0.0100385" damping="0.0111494" frictionloss="0.20699"/>
        <geom name="//unnamed_geom_26" class="visual" pos="0 1.92338e-09 8.24979e-08" quat="4.63268e-05 1 0 0" material="metal" mesh="hip_0"/>
        <geom name="//unnamed_geom_27" class="visual" pos="0 3.11804e-09 -2.04049e-07" quat="4.63268e-05 1 0 0" material="gray" mesh="hip_1"/>
        <geom name="//unnamed_geom_28" class="collision" size="0.0456621 0.0198531" pos="0 -0.08594 0" quat="0.707107 0.707107 0 0" type="cylinder"/>
        <geom name="//unnamed_geom_29" class="reward_collision_sphere" size="0.0595593" pos="0 -0.0751975 0"/>
        <body name="FR_thigh" pos="0.00222976 -0.101207 0.0020662" quat="0.999999 0.000646403 0.000160901 0.000800924">
          <inertial pos="-0.00443644 0.0221964 -0.0274056" quat="0.545611 -0.0211669 0.0954701 0.832314" mass="1.20639" diaginertia="0.0077885 0.00866467 0.000405695"/>
          <joint name="FR_thigh_joint" pos="0 0 0" axis="-0.00035692 -0.999988 0.00496717" range="-3.53293 1.56881" armature="0.0094284" damping="0.0139301" frictionloss="0.198909"/>
          <geom name="//unnamed_geom_30" class="visual" material="metal" mesh="thigh_mirror_0"/>
          <geom name="//unnamed_geom_31" class="visual" material="gray" mesh="thigh_mirror_1"/>
          <geom name="//unnamed_geom_32" class="collision" size="0.105718 0.01216 0.0168751" pos="0 0 -0.0908941" quat="0.707107 0 0.707107 0" type="box"/>
          <body name="FR_calf" pos="-0.00258484 -0.00143441 -0.183845" quat="0.999999 0.000217668 0.000188313 -0.00129049">
            <inertial pos="0.00804942 0.000923942 -0.118309" quat="0.698455 -0.00644496 0.0121619 0.715522" mass="0.233275" diaginertia="0.00188986 0.00208429 2.41788e-05"/>
            <joint name="FR_calf_joint" pos="0 0 0" axis="-0.0024342 -0.999957 -0.00894687" range="0.816792 2.71936" armature="0.0109926" damping="0.0206222" frictionloss="0.171939"/>
            <geom name="//unnamed_geom_33" class="visual" material="gray" mesh="calf_mirror_0"/>
            <geom name="//unnamed_geom_34" class="visual" material="black" mesh="calf_mirror_1"/>
            <geom name="FR_calf0" class="collision" size="0.0129045 0.0595593" pos="0.0105025 0 -0.0512079" quat="0.995004 0 -0.0998334 0" type="cylinder"/>
            <geom name="//unnamed_geom_36" class="collision" size="0.0109192 0.0322613" pos="0.021005 0 -0.126313" quat="0.999688 0 0.0249974 0" type="cylinder"/>
            <geom name="//unnamed_geom_37" class="visual" pos="0 0 -0.181788" quat="1 0 0 0" material="black" mesh="foot"/>
            <geom name="FR_foot" class="foot" size="0.0202262" pos="-0.0021005 0 -0.181788"/>
            <geom name="//unnamed_geom_39" class="reward_collision_sphere" size="0.0248164"/>
            <geom name="//unnamed_geom_40" class="reward_collision_sphere" size="0.0248164" pos="-0.0021005 0 -0.181788"/>
            <site name="FR_foot" class="foot" pos="-0.0021005 0 -0.181788" size="0.00992655"/>
          </body>
        </body>
      </body>
      <body name="RL_hip" pos="-0.203728 0.0511382 0.00193542" quat="1 0.000301852 -0.00012443 0.000459252">
        <inertial pos="0.00560529 -0.000465693 0.00238788" quat="0.506073 0.497532 0.496773 0.499568" mass="0.677173" diaginertia="0.00114659 0.00086679 0.000220413"/>
        <joint name="RL_hip_joint" pos="0 0 0" axis="-0.999711 -0.0197818 0.0136778" range="-1.05522 1.0126" armature="0.00990486" damping="0.0108054" frictionloss="0.191102"/>
        <geom name="//unnamed_geom_41" class="visual" pos="-1.71431e-09 0 -3.36044e-07" quat="4.63268e-05 0 1 0" material="metal" mesh="hip_0"/>
        <geom name="//unnamed_geom_42" class="visual" pos="-2.7791e-09 0 -2.98023e-07" quat="4.63268e-05 0 1 0" material="gray" mesh="hip_1"/>
        <geom name="//unnamed_geom_43" class="collision" size="0.0456621 0.0198531" pos="0 0.08594 0" quat="0.707107 0.707107 0 0" type="cylinder"/>
        <geom name="//unnamed_geom_44" class="reward_collision_sphere" size="0.0595593" pos="0 0.0751975 0"/>
        <body name="RL_thigh" pos="-0.00230843 0.102471 -0.00124558" quat="1 -7.19528e-05 0.000151188 0.000272976">
          <inertial pos="-0.00412729 -0.0226899 -0.0302758" quat="0.826762 0.0889611 -0.0307691 0.554621" mass="1.16374" diaginertia="0.00770879 0.00861676 0.000407509"/>
          <joint name="RL_thigh_joint" pos="0 0 0" axis="0.00301927 0.999989 0.00352035" stiffness="0.00572463" range="-0.578995 4.58826" armature="0.00941426" damping="0" frictionloss="0.207423"/>
          <geom name="//unnamed_geom_45" class="visual" material="metal" mesh="thigh_0"/>
          <geom name="//unnamed_geom_46" class="visual" material="gray" mesh="thigh_1"/>
          <geom name="//unnamed_geom_47" class="collision" size="0.105718 0.01216 0.0168751" pos="0 0 -0.0908941" quat="0.707107 0 0.707107 0" type="box"/>
          <body name="RL_calf" pos="-0.00199747 -0.00208366 -0.181544" quat="1 0.000142619 9.66139e-05 0.000172397">
            <inertial pos="0.00737277 -0.00018633 -0.119549" quat="0.711676 0.00232138 -0.00441503 0.70249" mass="0.251346" diaginertia="0.00202887 0.0021696 2.47458e-05"/>
            <joint name="RL_calf_joint" pos="0 0 0" axis="0.0121098 0.999899 -0.00742138" stiffness="0.00275448" range="-2.68444 -0.893286" armature="0.0100767" damping="0" frictionloss="0.19339"/>
            <geom name="//unnamed_geom_48" class="visual" material="gray" mesh="calf_0"/>
            <geom name="//unnamed_geom_49" class="visual" material="black" mesh="calf_1"/>
            <geom name="RL_calf0" class="collision" size="0.0129045 0.0595593" pos="0.0105025 0 -0.0512079" quat="0.995004 0 -0.0998334 0" type="cylinder"/>
            <geom name="//unnamed_geom_51" class="collision" size="0.0109192 0.0322613" pos="0.021005 0 -0.126313" quat="0.999688 0 0.0249974 0" type="cylinder"/>
            <geom name="//unnamed_geom_52" class="visual" pos="0 0 -0.181788" quat="1 0 0 0" material="black" mesh="foot"/>
            <geom name="RL_foot" class="foot" size="0.0202567" pos="-0.0021005 0 -0.181788"/>
            <geom name="//unnamed_geom_54" class="reward_collision_sphere" size="0.0248164"/>
            <geom name="//unnamed_geom_55" class="reward_collision_sphere" size="0.0248164" pos="-0.0021005 0 -0.181788"/>
            <site name="RL_foot" class="foot" pos="-0.0021005 0 -0.181788" size="0.00992655"/>
          </body>
        </body>
      </body>
      <body name="RR_hip" pos="-0.203634 -0.0493903 -0.00333933" quat="0.999999 0.00110054 0.000549919 -1.19521e-05">
        <inertial pos="0.00530543 0.000764707 -0.00292615" quat="0.499421 0.498049 0.497783 0.504715" mass="0.681875" diaginertia="0.00120475 0.000889762 0.000230474"/>
        <joint name="RR_hip_joint" pos="0 0 0" axis="-0.99995 0.00789786 -0.00605721" stiffness="0.00642183" range="-1.02376 0.998985" armature="0.009811" damping="0.00346663" frictionloss="0.188524"/>
        <geom name="//unnamed_geom_56" class="visual" pos="1.71514e-09 1.92338e-09 -4.18542e-07" quat="2.14617e-09 4.63268e-05 4.63268e-05 -1" material="metal" mesh="hip_0"/>
        <geom name="//unnamed_geom_57" class="visual" pos="2.77704e-09 3.11804e-09 -9.39743e-08" quat="2.14617e-09 4.63268e-05 4.63268e-05 -1" material="gray" mesh="hip_1"/>
        <geom name="//unnamed_geom_58" class="collision" size="0.0456621 0.0198531" pos="0 -0.08594 0" quat="0.707107 0.707107 0 0" type="cylinder"/>
        <geom name="//unnamed_geom_59" class="reward_collision_sphere" size="0.0595593" pos="0 -0.0751975 0"/>
        <body name="RR_thigh" pos="0.000173686 -0.100002 0.00159395" quat="0.999999 0.000956051 0.000827068 -0.000636464">
          <inertial pos="-0.00359223 0.0215491 -0.0254335" quat="0.549332 -0.020486 0.0850331 0.831014" mass="1.0885" diaginertia="0.00728769 0.00811143 0.000386037"/>
          <joint name="RR_thigh_joint" pos="0 0 0" axis="-0.00213544 -0.999993 -0.00297628" range="-4.55742 0.572917" armature="0.0100909" damping="0.0111937" frictionloss="0.189815"/>
          <geom name="//unnamed_geom_60" class="visual" material="metal" mesh="thigh_mirror_0"/>
          <geom name="//unnamed_geom_61" class="visual" material="gray" mesh="thigh_mirror_1"/>
          <geom name="//unnamed_geom_62" class="collision" size="0.105718 0.01216 0.0168751" pos="0 0 -0.0908941" quat="0.707107 0 0.707107 0" type="box"/>
          <body name="RR_calf" pos="-0.000539303 -0.000131089 -0.180933" quat="1 -0.000803835 -0.000388868 -0.000280898">
            <inertial pos="0.00781013 0.000592612 -0.120456" quat="0.705166 -0.00396657 0.00661131 0.709" mass="0.239271" diaginertia="0.00197496 0.00210166 2.40191e-05"/>
            <joint name="RR_calf_joint" pos="0 0 0" axis="-0.00277019 -0.999988 -0.00408626" range="0.779623 2.77195" armature="0.00866109" damping="0.0123782" frictionloss="0.203403"/>
            <geom name="//unnamed_geom_63" class="visual" material="gray" mesh="calf_mirror_0"/>
            <geom name="//unnamed_geom_64" class="visual" material="black" mesh="calf_mirror_1"/>
            <geom name="RR_calf0" class="collision" size="0.0129045 0.0595593" pos="0.0105025 0 -0.0512079" quat="0.995004 0 -0.0998334 0" type="cylinder"/>
            <geom name="//unnamed_geom_66" class="collision" size="0.0109192 0.0322613" pos="0.021005 0 -0.126313" quat="0.999688 0 0.0249974 0" type="cylinder"/>
            <geom name="//unnamed_geom_67" class="visual" pos="0 0 -0.181788" quat="1 0 0 0" material="black" mesh="foot"/>
            <geom name="RR_foot" class="foot" size="0.0196632" pos="-0.0021005 0 -0.181788"/>
            <geom name="//unnamed_geom_69" class="reward_collision_sphere" size="0.0248164"/>
            <geom name="//unnamed_geom_70" class="reward_collision_sphere" size="0.0248164" pos="-0.0021005 0 -0.181788"/>
            <site name="RR_foot" class="foot" pos="-0.0021005 0 -0.181788" size="0.00992655"/>
          </body>
        </body>
      </body>
    </body>
  </worldbody>

  <contact>
    <pair class="/" geom1="floor" geom2="FL_foot" name="//unnamed_contact_0"/>
    <pair class="/" geom1="floor" geom2="FR_foot" name="//unnamed_contact_1"/>
    <pair class="/" geom1="floor" geom2="RL_foot" name="//unnamed_contact_2"/>
    <pair class="/" geom1="floor" geom2="RR_foot" name="//unnamed_contact_3"/>
  </contact>

  <actuator>
    <general name="FL_hip" class="/" joint="FL_hip_joint" forcerange="-24.904 24.904" gainprm="21.046" biasprm="0 -21.046 -0.506108"/>
    <general name="FL_thigh" class="/" joint="FL_thigh_joint" forcerange="-21.1859 21.1859" gainprm="21.046" biasprm="0 -21.046 -0.506108"/>
    <general name="FL_calf" class="/" joint="FL_calf_joint" forcerange="-44.4348 44.4348" gainprm="21.046" biasprm="0 -21.046 -0.506108"/>
    <general name="FR_hip" class="/" joint="FR_hip_joint" forcerange="-25.4542 25.4542" gainprm="21.046" biasprm="0 -21.046 -0.506108"/>
    <general name="FR_thigh" class="/" joint="FR_thigh_joint" forcerange="-25.4389 25.4389" gainprm="21.046" biasprm="0 -21.046 -0.506108"/>
    <general name="FR_calf" class="/" joint="FR_calf_joint" forcerange="-49.4347 49.4347" gainprm="21.046" biasprm="0 -21.046 -0.506108"/>
    <general name="RL_hip" class="/" joint="RL_hip_joint" forcerange="-23.8067 23.8067" gainprm="21.046" biasprm="0 -21.046 -0.506108"/>
    <general name="RL_thigh" class="/" joint="RL_thigh_joint" forcerange="-22.6117 22.6117" gainprm="21.046" biasprm="0 -21.046 -0.506108"/>
    <general name="RL_calf" class="/" joint="RL_calf_joint" forcerange="-40.9764 40.9764" gainprm="21.046" biasprm="0 -21.046 -0.506108"/>
    <general name="RR_hip" class="/" joint="RR_hip_joint" forcerange="-21.8498 21.8498" gainprm="21.046" biasprm="0 -21.046 -0.506108"/>
    <general name="RR_thigh" class="/" joint="RR_thigh_joint" forcerange="-24.4511 24.4511" gainprm="21.046" biasprm="0 -21.046 -0.506108"/>
    <general name="RR_calf" class="/" joint="RR_calf_joint" forcerange="-45.7768 45.7768" gainprm="21.046" biasprm="0 -21.046 -0.506108"/>
  </actuator>

  <sensor>
    <gyro site="imu" name="imu_angular_velocity"/>
    <velocimeter site="imu" name="imu_linear_velocity"/>
    <framelinvel objtype="site" objname="FL_foot" name="FL_foot_global_linear_velocity"/>
    <framelinvel objtype="site" objname="FR_foot" name="FR_foot_global_linear_velocity"/>
    <framelinvel objtype="site" objname="RL_foot" name="RL_foot_global_linear_velocity"/>
    <framelinvel objtype="site" objname="RR_foot" name="RR_foot_global_linear_velocity"/>
  </sensor>

  <keyframe>
    <key name="home" qpos="0 0 0.325 1 0 0 0 0.1 0.8 -1.5 -0.1 -0.8 1.5 -0.1 0.8 -1.5 0.1 -0.8 1.5"/>
  </keyframe>
</mujoco>
