<mujoco model="go2">
  <compiler angle="radian" assetdir="assets" balanceinertia="true" inertiafromgeom="false"/>

  <option timestep="0.005" density="1.2" viscosity="2e-05"/>

  <size nkey="1"/>

  <visual>
    <quality shadowsize="8192"/>
    <map shadowclip="0.5"/>
  </visual>

  <default>
    <default class="/">
      <geom contype="0" conaffinity="0" group="1" solref="-1000 -80"/>
      <site size="0.01 0.005 0.005" group="5"/>
      <general forcelimited="true" biastype="affine" gainprm="20" biasprm="0 -20 -0.5"/>
      <default class="go2">
        <joint armature="0.01" damping="0.01" frictionloss="0.2"/>
        <geom condim="1" margin="0.001"/>
        <default class="visual">
          <geom type="mesh" group="2"/>
        </default>
        <default class="collision">
          <geom group="3"/>
          <default class="foot">
            <geom size="0.022 0 0" condim="6" priority="1" friction="0.8 0.02 0.01" solimp="0.015 1 0.022"/>
          </default>
        </default>
        <default class="reward_collision_sphere">
          <geom group="5" rgba="1 0 0 1"/>
        </default>
      </default>
    </default>
  </default>

  <asset>
    <texture type="skybox" colorspace="auto" name="//unnamed_texture_0" builtin="gradient" rgb1="0.95 0.95 0.95" rgb2="0.95 0.95 0.95" width="100" height="600"/>
    <texture type="2d" colorspace="auto" name="texplane" builtin="checker" rgb1="0.345 0.575 0.748" rgb2="0.345 0.575 0.748" markrgb="1 1 1" width="512" height="512"/>
    <material name="MatPlane" class="/" texture="texplane" texuniform="true" texrepeat="2 2" specular="0.9"/>
    <material name="metal" class="/" rgba="0.9 0.95 0.95 1"/>
    <material name="black" class="/" rgba="0 0 0 1"/>
    <material name="white" class="/"/>
    <material name="gray" class="/" rgba="0.671705 0.692426 0.77427 1"/>
    <mesh name="base_0" class="/" file="base_0.obj"/>
    <mesh name="base_1" class="/" file="base_1.obj"/>
    <mesh name="base_2" class="/" file="base_2.obj"/>
    <mesh name="base_3" class="/" file="base_3.obj"/>
    <mesh name="base_4" class="/" file="base_4.obj"/>
    <mesh name="hip_0" class="/" file="hip_0.obj"/>
    <mesh name="hip_1" class="/" file="hip_1.obj"/>
    <mesh name="thigh_0" class="/" file="thigh_0.obj"/>
    <mesh name="thigh_1" class="/" file="thigh_1.obj"/>
    <mesh name="thigh_mirror_0" class="/" file="thigh_mirror_0.obj"/>
    <mesh name="thigh_mirror_1" class="/" file="thigh_mirror_1.obj"/>
    <mesh name="calf_0" class="/" file="calf_0.obj"/>
    <mesh name="calf_1" class="/" file="calf_1.obj"/>
    <mesh name="calf_mirror_0" class="/" file="calf_mirror_0.obj"/>
    <mesh name="calf_mirror_1" class="/" file="calf_mirror_1.obj"/>
    <mesh name="foot" class="/" file="foot.obj"/>
  </asset>

  <worldbody>
    <geom name="floor" class="/" size="100 100 0.125" type="plane" group="0" material="MatPlane"/>
    <light name="toplight_shadow" class="/" pos="0 0 5" dir="0.0990148 0.0990148 -0.990148" type="directional" ambient="0.04 0.04 0.04" diffuse="0.55 0.55 0.55" specular="0.12 0.12 0.12"/>
    <light name="toplight_fill" class="/" pos="0 0 5" dir="0.0990148 0.0990148 -0.990148" type="directional" castshadow="false" ambient="0.04 0.04 0.04" diffuse="0.3 0.3 0.3" specular="0.08 0.08 0.08"/>
    <body name="trunk" childclass="go2" pos="-0.000477884 -0.00211387 -0.000828619" quat="1 -2.26395e-05 6.08876e-06 -1.26977e-05">
      <inertial pos="0.0243318 -0.00194592 -0.00497869" quat="2.15695e-06 0.713005 0.00175028 0.701157" mass="7.36817" diaginertia="0.141972 0.189969 0.0114421"/>
      <joint name="//unnamed_joint_0" type="free" armature="0" damping="0" frictionloss="0"/>
      <geom name="//unnamed_geom_1" class="visual" material="black" mesh="base_0"/>
      <geom name="//unnamed_geom_2" class="visual" material="black" mesh="base_1"/>
      <geom name="//unnamed_geom_3" class="visual" material="black" mesh="base_2"/>
      <geom name="//unnamed_geom_4" class="visual" material="white" mesh="base_3"/>
      <geom name="//unnamed_geom_5" class="visual" material="gray" mesh="base_4"/>
      <geom name="trunk_1" class="collision" size="0.192556 0.0478576 0.0583504" type="box"/>
      <geom name="trunk_2" class="collision" size="0.0511845 0.0460661" pos="0.303494 0 0.00859441" type="cylinder"/>
      <geom name="trunk_3" class="collision" size="0.0481135" pos="0.312013 0 -0.0515664"/>
      <geom name="//unnamed_geom_9" class="reward_collision_sphere" size="0.102369"/>
      <geom name="//unnamed_geom_10" class="reward_collision_sphere" size="0.0614215" pos="0.29817 0 -0.0386748"/>
      <site name="imu" pos="-0.015976 0.0140326 0.0257679" size="0.0102369"/>
      <camera name="track" pos="0 -2.29348 0" quat="0.707107 0.707107 0 0" mode="trackcom"/>
      <camera name="ego_camera" pos="0.332246 0 0.0386748" quat="-0.5 -0.5 0.5 0.5"/>
      <body name="FL_hip" pos="0.208198 0.0527659 0.000588554" quat="1 0.000723103 -0.000171426 0.000260236">
        <inertial pos="-0.00569738 0.00244833 0.00246031" quat="0.496195 0.498954 0.503858 0.500962" mass="0.713539" diaginertia="0.00121062 0.00115557 0.000223113"/>
        <joint name="FL_hip_joint" pos="0 0 0" axis="0.99996 0.00465368 0.00766996" stiffness="0.00343882" range="-1.06211 1.10463" armature="0.0106265" damping="0.00146687" frictionloss="0.231463"/>
        <geom name="//unnamed_geom_11" class="visual" material="metal" mesh="hip_0"/>
        <geom name="//unnamed_geom_12" class="visual" material="gray" mesh="hip_1"/>
        <geom name="//unnamed_geom_13" class="collision" size="0.0470898 0.0204738" pos="0 0.0917392 0" quat="0.707107 0.707107 0 0" type="cylinder"/>
        <geom name="//unnamed_geom_14" class="reward_collision_sphere" size="0.0614215" pos="0 0.0802718 0"/>
        <body name="FL_thigh" pos="-0.00161429 0.109056 -0.000457536" quat="0.999999 0.000170854 -0.000828269 0.00109373">
          <inertial pos="-0.0014918 -0.0227617 -0.027835" quat="0.827034 0.0902434 -0.0177694 0.554577" mass="1.23527" diaginertia="0.0079717 0.0114294 0.000397424"/>
          <joint name="FL_thigh_joint" pos="0 0 0" axis="-0.00224841 0.999919 -0.0125053" stiffness="0.00329749" range="-1.51349 3.50318" armature="0.0111712" damping="0.00751382" frictionloss="0.228874"/>
          <geom name="//unnamed_geom_15" class="visual" material="metal" mesh="thigh_0"/>
          <geom name="//unnamed_geom_16" class="visual" material="gray" mesh="thigh_1"/>
          <geom name="//unnamed_geom_17" class="collision" size="0.109023 0.0125402 0.0174027" pos="0 0 -0.0915304" quat="0.707107 0 0.707107 0" type="box"/>
          <body name="FL_calf" pos="-0.00244864 -0.000811936 -0.185431" quat="0.999999 0.000207282 0.00129773 -0.000605885">
            <inertial pos="0.00936203 -0.000417794 -0.121079" quat="0.71165 0.00334081 -0.0054499 0.702505" mass="0.261633" diaginertia="0.00199512 0.00293427 2.49799e-05"/>
            <joint name="FL_calf_joint" pos="0 0 0" axis="-0.00387016 0.999973 0.00629822" stiffness="0.00164942" range="-2.72274 -0.835021" armature="0.00885032" damping="0.00668142" frictionloss="0.204051"/>
            <geom name="//unnamed_geom_18" class="visual" material="gray" mesh="calf_0"/>
            <geom name="//unnamed_geom_19" class="visual" material="black" mesh="calf_1"/>
            <geom name="FL_calf0" class="collision" size="0.0122843 0.0614215" pos="0.00851914 0 -0.0515664" quat="0.994493 0 -0.104807 0" type="cylinder"/>
            <geom name="//unnamed_geom_21" class="collision" size="0.0112606 0.03327" pos="0.0212978 0 -0.127197" quat="0.999688 0 0.0249974 0" type="cylinder"/>
            <geom name="//unnamed_geom_22" class="visual" pos="0 0 -0.183061" quat="1 0 0 0" material="black" mesh="foot"/>
            <geom name="FL_foot" class="foot" size="0.0165009" pos="-0.00212978 0 -0.183061"/>
            <geom name="//unnamed_geom_24" class="reward_collision_sphere" size="0.0255923"/>
            <geom name="//unnamed_geom_25" class="reward_collision_sphere" size="0.0255923" pos="-0.00212978 0 -0.183061"/>
            <site name="FL_foot" class="foot" pos="-0.00212978 0 -0.183061" size="0.0102369"/>
          </body>
        </body>
      </body>
      <body name="FR_hip" pos="0.20733 -0.0562396 -0.00220076" quat="1 -2.04967e-05 -0.000641406 -0.00014722">
        <inertial pos="-0.00751322 -0.00187611 0.00131689" quat="0.494287 0.508424 0.500297 0.496879" mass="0.70724" diaginertia="0.00116877 0.00117887 0.000228026"/>
        <joint name="FR_hip_joint" pos="0 0 0" axis="0.999911 -0.00683335 -0.0114575" range="-1.04649 1.07185" armature="0.0111258" damping="0.01315" frictionloss="0.227927"/>
        <geom name="//unnamed_geom_26" class="visual" pos="0 2.50283e-09 1.07352e-07" quat="4.63268e-05 1 0 0" material="metal" mesh="hip_0"/>
        <geom name="//unnamed_geom_27" class="visual" pos="0 4.05739e-09 -2.65522e-07" quat="4.63268e-05 1 0 0" material="gray" mesh="hip_1"/>
        <geom name="//unnamed_geom_28" class="collision" size="0.0470898 0.0204738" pos="0 -0.0917392 0" quat="0.707107 0.707107 0 0" type="cylinder"/>
        <geom name="//unnamed_geom_29" class="reward_collision_sphere" size="0.0614215" pos="0 -0.0802718 0"/>
        <body name="FR_thigh" pos="0.000431558 -0.110088 -0.000120083" quat="0.999999 -0.000677752 0.000990557 0.000836845">
          <inertial pos="-0.00604964 0.0257955 -0.0271178" quat="0.562402 -0.01536 0.0825235 0.822592" mass="1.30125" diaginertia="0.00822808 0.0118054 0.000408108"/>
          <joint name="FR_thigh_joint" pos="0 0 0" axis="0.00252082 -0.999995 -0.00205034" range="-3.4989 1.57219" armature="0.00990849" damping="0.0211886" frictionloss="0.204957"/>
          <geom name="//unnamed_geom_30" class="visual" material="metal" mesh="thigh_mirror_0"/>
          <geom name="//unnamed_geom_31" class="visual" material="gray" mesh="thigh_mirror_1"/>
          <geom name="//unnamed_geom_32" class="collision" size="0.109023 0.0125402 0.0174027" pos="0 0 -0.0915304" quat="0.707107 0 0.707107 0" type="box"/>
          <body name="FR_calf" pos="-0.000975242 -0.00165356 -0.185095" quat="1 0.000189381 0.000178283 -0.000657866">
            <inertial pos="0.00932863 0.000635429 -0.119247" quat="0.700666 -0.00013055 0.0139547 0.713353" mass="0.256657" diaginertia="0.00207031 0.00292343 2.55885e-05"/>
            <joint name="FR_calf_joint" pos="0 0 0" axis="-1.58153e-05 -1 -0.000132113" range="0.83853 2.70046" armature="0.0105467" damping="0.0118936" frictionloss="0.189156"/>
            <geom name="//unnamed_geom_33" class="visual" material="gray" mesh="calf_mirror_0"/>
            <geom name="//unnamed_geom_34" class="visual" material="black" mesh="calf_mirror_1"/>
            <geom name="FR_calf0" class="collision" size="0.013308 0.0614215" pos="0.0106489 0 -0.0515664" quat="0.995004 0 -0.0998334 0" type="cylinder"/>
            <geom name="//unnamed_geom_36" class="collision" size="0.0112606 0.03327" pos="0.0212978 0 -0.127197" quat="0.999688 0 0.0249974 0" type="cylinder"/>
            <geom name="//unnamed_geom_37" class="visual" pos="0 0 -0.183061" quat="1 0 0 0" material="black" mesh="foot"/>
            <geom name="FR_foot" class="foot" size="0.0201171" pos="-0.00212978 0 -0.183061"/>
            <geom name="//unnamed_geom_39" class="reward_collision_sphere" size="0.0255923"/>
            <geom name="//unnamed_geom_40" class="reward_collision_sphere" size="0.0255923" pos="-0.00212978 0 -0.183061"/>
            <site name="FR_foot" class="foot" pos="-0.00212978 0 -0.183061" size="0.0102369"/>
          </body>
        </body>
      </body>
      <body name="RL_hip" pos="-0.206557 0.0535301 0.00192181" quat="0.999999 -0.000426274 0.000584488 0.000819923">
        <inertial pos="0.00634975 0.000555001 0.00272035" quat="0.509283 0.50138 0.497182 0.491995" mass="0.767686" diaginertia="0.00125681 0.00122258 0.000231332"/>
        <joint name="RL_hip_joint" pos="0 0 0" axis="-0.99961 0.0211442 -0.018252" range="-1.02584 0.991346" armature="0.0104855" damping="0.00586297" frictionloss="0.211299"/>
        <geom name="//unnamed_geom_41" class="visual" pos="-1.78981e-09 0 -3.50843e-07" quat="4.63268e-05 0 1 0" material="metal" mesh="hip_0"/>
        <geom name="//unnamed_geom_42" class="visual" pos="-2.90149e-09 0 -3.11148e-07" quat="4.63268e-05 0 1 0" material="gray" mesh="hip_1"/>
        <geom name="//unnamed_geom_43" class="collision" size="0.0470898 0.0204738" pos="0 0.0917392 0" quat="0.707107 0.707107 0 0" type="cylinder"/>
        <geom name="//unnamed_geom_44" class="reward_collision_sphere" size="0.0614215" pos="0 0.0802718 0"/>
        <body name="RL_thigh" pos="-0.00233418 0.109274 0.000122838" quat="1 -0.000411097 7.86017e-05 -0.000102214">
          <inertial pos="-0.00325173 -0.0244881 -0.0287533" quat="0.835081 0.0747689 -0.0238024 0.544502" mass="1.26409" diaginertia="0.00823398 0.0123133 0.00042862"/>
          <joint name="RL_thigh_joint" pos="0 0 0" axis="0.0118504 0.999921 0.004103" stiffness="0.00385941" range="-0.565785 4.59327" armature="0.00910779" damping="0" frictionloss="0.21318"/>
          <geom name="//unnamed_geom_45" class="visual" material="metal" mesh="thigh_0"/>
          <geom name="//unnamed_geom_46" class="visual" material="gray" mesh="thigh_1"/>
          <geom name="//unnamed_geom_47" class="collision" size="0.109023 0.0125402 0.0174027" pos="0 0 -0.0915304" quat="0.707107 0 0.707107 0" type="box"/>
          <body name="RL_calf" pos="-0.00160519 0.000182501 -0.181835" quat="1 0.000283976 -2.06563e-05 0.000423075">
            <inertial pos="0.00749879 -0.000197072 -0.121267" quat="0.710445 0.00181216 0.00051002 0.70375" mass="0.277078" diaginertia="0.00214745 0.00304049 2.57854e-05"/>
            <joint name="RL_calf_joint" pos="0 0 0" axis="0.000198821 0.999934 0.0114993" stiffness="0.0020987" range="-2.72405 -0.8808" armature="0.0098145" damping="0" frictionloss="0.207406"/>
            <geom name="//unnamed_geom_48" class="visual" material="gray" mesh="calf_0"/>
            <geom name="//unnamed_geom_49" class="visual" material="black" mesh="calf_1"/>
            <geom name="RL_calf0" class="collision" size="0.013308 0.0614215" pos="0.0106489 0 -0.0515664" quat="0.995004 0 -0.0998334 0" type="cylinder"/>
            <geom name="//unnamed_geom_51" class="collision" size="0.0112606 0.03327" pos="0.0212978 0 -0.127197" quat="0.999688 0 0.0249974 0" type="cylinder"/>
            <geom name="//unnamed_geom_52" class="visual" pos="0 0 -0.183061" quat="1 0 0 0" material="black" mesh="foot"/>
            <geom name="RL_foot" class="foot" size="0.0220779" pos="-0.00212978 0 -0.183061"/>
            <geom name="//unnamed_geom_54" class="reward_collision_sphere" size="0.0255923"/>
            <geom name="//unnamed_geom_55" class="reward_collision_sphere" size="0.0255923" pos="-0.00212978 0 -0.183061"/>
            <site name="RL_foot" class="foot" pos="-0.00212978 0 -0.183061" size="0.0102369"/>
          </body>
        </body>
      </body>
      <body name="RR_hip" pos="-0.205123 -0.0524834 -0.0023632" quat="1 -0.000433917 0.00046789 -0.000162881">
        <inertial pos="0.00687434 -0.000512173 -0.0029303" quat="0.496411 0.495261 0.503631 0.504626" mass="0.743692" diaginertia="0.00128796 0.00125966 0.000235204"/>
        <joint name="RR_hip_joint" pos="0 0 0" axis="-0.999995 0.00302991 -0.000587239" stiffness="0.012366" range="-1.03737 1.02951" armature="0.0103945" damping="0.00418274" frictionloss="0.197903"/>
        <geom name="//unnamed_geom_56" class="visual" pos="1.79264e-09 2.50283e-09 -4.58195e-07" quat="2.14617e-09 4.63268e-05 4.63268e-05 -1" material="metal" mesh="hip_0"/>
        <geom name="//unnamed_geom_57" class="visual" pos="2.89448e-09 4.05739e-09 -4.56259e-08" quat="2.14617e-09 4.63268e-05 4.63268e-05 -1" material="gray" mesh="hip_1"/>
        <geom name="//unnamed_geom_58" class="collision" size="0.0470898 0.0204738" pos="0 -0.0917392 0" quat="0.707107 0.707107 0 0" type="cylinder"/>
        <geom name="//unnamed_geom_59" class="reward_collision_sphere" size="0.0614215" pos="0 -0.0802718 0"/>
        <body name="RR_thigh" pos="-9.97196e-05 -0.107398 0.00147106" quat="1 -0.000136922 0.000691221 -0.000272289">
          <inertial pos="-0.00375075 0.0246318 -0.0254215" quat="0.547762 -0.0203574 0.0854747 0.832007" mass="1.17822" diaginertia="0.007779 0.0110681 0.000397069"/>
          <joint name="RR_thigh_joint" pos="0 0 0" axis="0.000266286 -0.99999 -0.00452642" range="-4.5376 0.581523" armature="0.0107687" damping="0.0058353" frictionloss="0.208813"/>
          <geom name="//unnamed_geom_60" class="visual" material="metal" mesh="thigh_mirror_0"/>
          <geom name="//unnamed_geom_61" class="visual" material="gray" mesh="thigh_mirror_1"/>
          <geom name="//unnamed_geom_62" class="collision" size="0.109023 0.0125402 0.0174027" pos="0 0 -0.0915304" quat="0.707107 0 0.707107 0" type="box"/>
          <body name="RR_calf" pos="0.0016467 0.00122854 -0.181245" quat="0.999999 -0.00107101 -0.000618997 -0.000496375">
            <inertial pos="0.00580902 0.000886729 -0.122939" quat="0.705945 0.00713347 0.00148648 0.70823" mass="0.261737" diaginertia="0.00206026 0.00283284 2.51084e-05"/>
            <joint name="RR_calf_joint" pos="0 0 0" axis="-0.00336219 -0.999994 0.000954236" range="0.798256 2.73894" armature="0.00969709" damping="0.011621" frictionloss="0.20543"/>
            <geom name="//unnamed_geom_63" class="visual" material="gray" mesh="calf_mirror_0"/>
            <geom name="//unnamed_geom_64" class="visual" material="black" mesh="calf_mirror_1"/>
            <geom name="RR_calf0" class="collision" size="0.013308 0.0614215" pos="0.0106489 0 -0.0515664" quat="0.995004 0 -0.0998334 0" type="cylinder"/>
            <geom name="//unnamed_geom_66" class="collision" size="0.0112606 0.03327" pos="0.0212978 0 -0.127197" quat="0.999688 0 0.0249974 0" type="cylinder"/>
            <geom name="//unnamed_geom_67" class="visual" pos="0 0 -0.183061" quat="1 0 0 0" material="black" mesh="foot"/>
            <geom name="RR_foot" class="foot" size="0.020443" pos="-0.00212978 0 -0.183061"/>
            <geom name="//unnamed_geom_69" class="reward_collision_sphere" size="0.0255923"/>
            <geom name="//unnamed_geom_70" class="reward_collision_sphere" size="0.0255923" pos="-0.00212978 0 -0.183061"/>
            <site name="RR_foot" class="foot" pos="-0.00212978 0 -0.183061" size="0.0102369"/>
          </body>
        </body>
      </body>
    </body>
  </worldbody>

  <contact>
    <pair class="/" geom1="floor" geom2="FL_foot" name="//unnamed_contact_0"/>
    <pair class="/" geom1="floor" geom2="FR_foot" name="//unnamed_contact_1"/>
    <pair class="/" geom1="floor" geom2="RL_foot" name="//unnamed_contact_2"/>
    <pair class="/" geom1="floor" geom2="RR_foot" name="//unnamed_contact_3"/>
  </contact>

  <actuator>
    <general name="FL_hip" class="/" joint="FL_hip_joint" forcerange="-23.7854 23.7854" gainprm="20.84" biasprm="0 -20.84 -0.541578"/>
    <general name="FL_thigh" class="/" joint="FL_thigh_joint" forcerange="-21.8634 21.8634" gainprm="20.84" biasprm="0 -20.84 -0.541578"/>
    <general name="FL_calf" class="/" joint="FL_calf_joint" forcerange="-43.0776 43.0776" gainprm="20.84" biasprm="0 -20.84 -0.541578"/>
    <general name="FR_hip" class="/" joint="FR_hip_joint" forcerange="-24.7518 24.7518" gainprm="20.84" biasprm="0 -20.84 -0.541578"/>
    <general name="FR_thigh" class="/" joint="FR_thigh_joint" forcerange="-24.7247 24.7247" gainprm="20.84" biasprm="0 -20.84 -0.541578"/>
    <general name="FR_calf" class="/" joint="FR_calf_joint" forcerange="-50.6888 50.6888" gainprm="20.84" biasprm="0 -20.84 -0.541578"/>
    <general name="RL_hip" class="/" joint="RL_hip_joint" forcerange="-23.1723 23.1723" gainprm="20.84" biasprm="0 -20.84 -0.541578"/>
    <general name="RL_thigh" class="/" joint="RL_thigh_joint" forcerange="-24.1974 24.1974" gainprm="20.84" biasprm="0 -20.84 -0.541578"/>
    <general name="RL_calf" class="/" joint="RL_calf_joint" forcerange="-41.516 41.516" gainprm="20.84" biasprm="0 -20.84 -0.541578"/>
    <general name="RR_hip" class="/" joint="RR_hip_joint" forcerange="-24.2413 24.2413" gainprm="20.84" biasprm="0 -20.84 -0.541578"/>
    <general name="RR_thigh" class="/" joint="RR_thigh_joint" forcerange="-24.5144 24.5144" gainprm="20.84" biasprm="0 -20.84 -0.541578"/>
    <general name="RR_calf" class="/" joint="RR_calf_joint" forcerange="-47.5392 47.5392" gainprm="20.84" biasprm="0 -20.84 -0.541578"/>
  </actuator>

  <sensor>
    <gyro site="imu" name="imu_angular_velocity"/>
    <velocimeter site="imu" name="imu_linear_velocity"/>
    <framelinvel objtype="site" objname="FL_foot" name="FL_foot_global_linear_velocity"/>
    <framelinvel objtype="site" objname="FR_foot" name="FR_foot_global_linear_velocity"/>
    <framelinvel objtype="site" objname="RL_foot" name="RL_foot_global_linear_velocity"/>
    <framelinvel objtype="site" objname="RR_foot" name="RR_foot_global_linear_velocity"/>
  </sensor>

  <keyframe>
    <key name="home" qpos="0 0 0.325 1 0 0 0 0.1 0.8 -1.5 -0.1 -0.8 1.5 -0.1 0.8 -1.5 0.1 -0.8 1.5"/>
  </keyframe>
</mujoco>
