<mujoco model="go2">
  <compiler angle="radian" assetdir="assets" balanceinertia="true" inertiafromgeom="false"/>

  <option timestep="0.005" density="1.2" viscosity="2e-05"/>

  <size nkey="1"/>

  <visual>
    <quality shadowsize="8192"/>
    <map shadowclip="0.5"/>
  </visual>

  <default>
    <default class="/">
      <geom contype="0" conaffinity="0" group="1" solref="-1000 -80"/>
      <site size="0.01 0.005 0.005" group="5"/>
      <general forcelimited="true" biastype="affine" gainprm="20" biasprm="0 -20 -0.5"/>
      <default class="go2">
        <joint armature="0.01" damping="0.01" frictionloss="0.2"/>
        <geom condim="1" margin="0.001"/>
        <default class="visual">
          <geom type="mesh" group="2"/>
        </default>
        <default class="collision">
          <geom group="3"/>
          <default class="foot">
            <geom size="0.022 0 0" condim="6" priority="1" friction="0.8 0.02 0.01" solimp="0.015 1 0.022"/>
          </default>
        </default>
        <default class="reward_collision_sphere">
          <geom group="5" rgba="1 0 0 1"/>
        </default>
      </default>
    </default>
  </default>

  <asset>
    <texture type="skybox" colorspace="auto" name="//unnamed_texture_0" builtin="gradient" rgb1="0.95 0.95 0.95" rgb2="0.95 0.95 0.95" width="100" height="600"/>
    <texture type="2d" colorspace="auto" name="texplane" builtin="checker" rgb1="0.345 0.575 0.748" rgb2="0.345 0.575 0.748" markrgb="1 1 1" width="512" height="512"/>
    <material name="MatPlane" class="/" texture="texplane" texuniform="true" texrepeat="2 2" specular="0.9"/>
    <material name="metal" class="/" rgba="0.9 0.95 0.95 1"/>
    <material name="black" class="/" rgba="0 0 0 1"/>
    <material name="white" class="/"/>
    <material name="gray" class="/" rgba="0.671705 0.692426 0.77427 1"/>
    <mesh name="base_0" class="/" file="base_0.obj"/>
    <mesh name="base_1" class="/" file="base_1.obj"/>
    <mesh name="base_2" class="/" file="base_2.obj"/>
    <mesh name="base_3" class="/" file="base_3.obj"/>
    <mesh name="base_4" class="/" file="base_4.obj"/>
    <mesh name="hip_0" class="/" file="hip_0.obj"/>
    <mesh name="hip_1" class="/" file="hip_1.obj"/>
    <mesh name="thigh_0" class="/" file="thigh_0.obj"/>
    <mesh name="thigh_1" class="/" file="thigh_1.obj"/>
    <mesh name="thigh_mirror_0" class="/" file="thigh_mirror_0.obj"/>
    <mesh name="thigh_mirror_1" class="/" file="thigh_mirror_1.obj"/>
    <mesh name="calf_0" class="/" file="calf_0.obj"/>
    <mesh name="calf_1" class="/" file="calf_1.obj"/>
    <mesh name="calf_mirror_0" class="/" file="calf_mirror_0.obj"/>
    <mesh name="calf_mirror_1" class="/" file="calf_mirror_1.obj"/>
    <mesh name="foot" class="/" file="foot.obj"/>
  </asset>

  <worldbody>
    <geom name="floor" class="/" size="100 100 0.125" type="plane" group="0" material="MatPlane"/>
    <light name="toplight_shadow" class="/" pos="0 0 5" dir="0.0990148 0.0990148 -0.990148" type="directional" ambient="0.04 0.04 0.04" diffuse="0.55 0.55 0.55" specular="0.12 0.12 0.12"/>
    <light name="toplight_fill" class="/" pos="0 0 5" dir="0.0990148 0.0990148 -0.990148" type="directional" castshadow="false" ambient="0.04 0.04 0.04" diffuse="0.3 0.3 0.3" specular="0.08 0.08 0.08"/>
    <body name="trunk" childclass="go2" pos="0.000148572 0.000564552 -0.000234605" quat="1 1.5798e-06 2.8968e-06 1.04891e-05">
      <inertial pos="0.0202435 0.000293739 -0.00490428" quat="0.00197386 0.716904 -0.00287903 0.697164" mass="5.72241" diaginertia="0.0925167 0.0806361 0.0128814"/>
      <joint name="//unnamed_joint_0" type="free" armature="0" damping="0" frictionloss="0"/>
      <geom name="//unnamed_geom_1" class="visual" material="black" mesh="base_0"/>
      <geom name="//unnamed_geom_2" class="visual" material="black" mesh="base_1"/>
      <geom name="//unnamed_geom_3" class="visual" material="black" mesh="base_2"/>
      <geom name="//unnamed_geom_4" class="visual" material="white" mesh="base_3"/>
      <geom name="//unnamed_geom_5" class="visual" material="gray" mesh="base_4"/>
      <geom name="trunk_1" class="collision" size="0.176036 0.0437516 0.0533442" type="box"/>
      <geom name="trunk_2" class="collision" size="0.0467932 0.0421138" pos="0.276205 0 0.00879414" type="cylinder"/>
      <geom name="trunk_3" class="collision" size="0.0439856" pos="0.283958 0 -0.0527648"/>
      <geom name="//unnamed_geom_9" class="reward_collision_sphere" size="0.0935863"/>
      <geom name="//unnamed_geom_10" class="reward_collision_sphere" size="0.0561518" pos="0.271359 0 -0.0395736"/>
      <site name="imu" pos="-0.0280617 -0.00447196 0.0400628" size="0.00935863"/>
      <camera name="track" pos="0 -1.91807 0" quat="0.707107 0.707107 0 0" mode="trackcom"/>
      <camera name="ego_camera" pos="0.302372 0 0.0395736" quat="-0.5 -0.5 0.5 0.5"/>
      <body name="FL_hip" pos="0.185931 0.0459243 0.00213004" quat="1 -0.000135634 5.16969e-05 8.669e-06">
        <inertial pos="-0.00541328 0.00207023 -0.000991684" quat="0.497234 0.499588 0.505129 0.49801" mass="0.559065" diaginertia="0.00075535 0.00048976 0.000253851"/>
        <joint name="FL_hip_joint" pos="0 0 0" axis="0.999989 -0.00384759 0.00262085" stiffness="0.00457416" range="-1.02598 1.03351" armature="0.00952475" damping="0.0049583" frictionloss="0.179166"/>
        <geom name="//unnamed_geom_11" class="visual" material="metal" mesh="hip_0"/>
        <geom name="//unnamed_geom_12" class="visual" material="gray" mesh="hip_1"/>
        <geom name="//unnamed_geom_13" class="collision" size="0.0430497 0.0187173" pos="0 0.0767227 0" quat="0.707107 0.707107 0 0" type="cylinder"/>
        <geom name="//unnamed_geom_14" class="reward_collision_sphere" size="0.0561518" pos="0 0.0671324 0"/>
        <body name="FL_thigh" pos="-0.00109007 0.0923937 0.0015755" quat="1 -0.000177699 -0.000188128 0.000371828">
          <inertial pos="-0.0047719 -0.0220931 -0.028209" quat="0.829734 0.0846213 -0.0202914 0.551333" mass="0.943723" diaginertia="0.00506104 0.00472874 0.000459748"/>
          <joint name="FL_thigh_joint" pos="0 0 0" axis="0.000577463 0.999997 -0.00254617" stiffness="0.00515084" range="-1.58407 3.50142" armature="0.00918539" damping="0.0100784" frictionloss="0.185539"/>
          <geom name="//unnamed_geom_15" class="visual" material="metal" mesh="thigh_0"/>
          <geom name="//unnamed_geom_16" class="visual" material="gray" mesh="thigh_1"/>
          <geom name="//unnamed_geom_17" class="collision" size="0.0996694 0.0114643 0.0159097" pos="0 0 -0.0936576" quat="0.707107 0 0.707107 0" type="box"/>
          <body name="FL_calf" pos="-0.00128884 -0.00117783 -0.187109" quat="1 -0.000317595 0.000190229 0.000193954">
            <inertial pos="0.00532547 -0.000569118 -0.124804" quat="0.710894 0.00200803 -0.00398512 0.703285" mass="0.197372" diaginertia="0.00128189 0.00119331 2.768e-05"/>
            <joint name="FL_calf_joint" pos="0 0 0" axis="0.00131196 0.999983 0.00567567" stiffness="0.00126475" range="-2.74045 -0.836388" armature="0.00980993" damping="0.00096155" frictionloss="0.186246"/>
            <geom name="//unnamed_geom_18" class="visual" material="gray" mesh="calf_0"/>
            <geom name="//unnamed_geom_19" class="visual" material="black" mesh="calf_1"/>
            <geom name="FL_calf0" class="collision" size="0.0112304 0.0561518" pos="0.00775313 0 -0.0527648" quat="0.994493 0 -0.104807 0" type="cylinder"/>
            <geom name="//unnamed_geom_21" class="collision" size="0.0102945 0.0304156" pos="0.0193828 0 -0.130153" quat="0.999688 0 0.0249974 0" type="cylinder"/>
            <geom name="//unnamed_geom_22" class="visual" pos="0 0 -0.187315" quat="1 0 0 0" material="black" mesh="foot"/>
            <geom name="FL_foot" class="foot" size="0.0183502" pos="-0.00193828 0 -0.187315"/>
            <geom name="//unnamed_geom_24" class="reward_collision_sphere" size="0.0233966"/>
            <geom name="//unnamed_geom_25" class="reward_collision_sphere" size="0.0233966" pos="-0.00193828 0 -0.187315"/>
            <site name="FL_foot" class="foot" pos="-0.00193828 0 -0.187315" size="0.00935863"/>
          </body>
        </body>
      </body>
      <body name="FR_hip" pos="0.188475 -0.0431108 -0.000109311" quat="1 -3.56654e-05 -0.000127309 8.6385e-05">
        <inertial pos="-0.00524639 -0.00141296 -0.000179362" quat="0.497114 0.505887 0.499093 0.497858" mass="0.554129" diaginertia="0.000751503 0.000475135 0.000250155"/>
        <joint name="FR_hip_joint" pos="0 0 0" axis="0.999983 -0.00374463 -0.00456413" stiffness="0.00581333" range="-1.04956 1.05622" armature="0.00946072" damping="0.0163672" frictionloss="0.186438"/>
        <geom name="//unnamed_geom_26" class="visual" pos="0 6.93619e-10 2.97508e-08" quat="4.63268e-05 1 0 0" material="metal" mesh="hip_0"/>
        <geom name="//unnamed_geom_27" class="visual" pos="0 1.12444e-09 -7.3585e-08" quat="4.63268e-05 1 0 0" material="gray" mesh="hip_1"/>
        <geom name="//unnamed_geom_28" class="collision" size="0.0430497 0.0187173" pos="0 -0.0767227 0" quat="0.707107 0.707107 0 0" type="cylinder"/>
        <geom name="//unnamed_geom_29" class="reward_collision_sphere" size="0.0561518" pos="0 -0.0671324 0"/>
        <body name="FR_thigh" pos="0.00129491 -0.0905344 0.00072385" quat="1 -3.74813e-05 -0.000373126 5.63077e-05">
          <inertial pos="-0.0037252 0.020672 -0.0283932" quat="0.548232 -0.0189975 0.0867845 0.831594" mass="0.931554" diaginertia="0.00504949 0.00472583 0.000462063"/>
          <joint name="FR_thigh_joint" pos="0 0 0" axis="-5.36138e-05 -1 -0.000164422" range="-3.5034 1.57167" armature="0.0093036" damping="0.015743" frictionloss="0.187675"/>
          <geom name="//unnamed_geom_30" class="visual" material="metal" mesh="thigh_mirror_0"/>
          <geom name="//unnamed_geom_31" class="visual" material="gray" mesh="thigh_mirror_1"/>
          <geom name="//unnamed_geom_32" class="collision" size="0.0996694 0.0114643 0.0159097" pos="0 0 -0.0936576" quat="0.707107 0 0.707107 0" type="box"/>
          <body name="FR_calf" pos="-0.000373002 -9.15029e-05 -0.18624" quat="1 -1.98323e-05 2.59662e-05 -2.87722e-05">
            <inertial pos="0.00552365 0.000765413 -0.125522" quat="0.703605 -0.00616155 0.00580542 0.710541" mass="0.197121" diaginertia="0.00128135 0.00118671 2.79826e-05"/>
            <joint name="FR_calf_joint" pos="0 0 0" axis="-0.00398167 -0.999985 -0.00377074" stiffness="0.000112604" range="0.843338 2.71554" armature="0.00953995" damping="0.0126036" frictionloss="0.188797"/>
            <geom name="//unnamed_geom_33" class="visual" material="gray" mesh="calf_mirror_0"/>
            <geom name="//unnamed_geom_34" class="visual" material="black" mesh="calf_mirror_1"/>
            <geom name="FR_calf0" class="collision" size="0.0121662 0.0561518" pos="0.00969141 0 -0.0527648" quat="0.995004 0 -0.0998334 0" type="cylinder"/>
            <geom name="//unnamed_geom_36" class="collision" size="0.0102945 0.0304156" pos="0.0193828 0 -0.130153" quat="0.999688 0 0.0249974 0" type="cylinder"/>
            <geom name="//unnamed_geom_37" class="visual" pos="0 0 -0.187315" quat="1 0 0 0" material="black" mesh="foot"/>
            <geom name="FR_foot" class="foot" size="0.0222963" pos="-0.00193828 0 -0.187315"/>
            <geom name="//unnamed_geom_39" class="reward_collision_sphere" size="0.0233966"/>
            <geom name="//unnamed_geom_40" class="reward_collision_sphere" size="0.0233966" pos="-0.00193828 0 -0.187315"/>
            <site name="FR_foot" class="foot" pos="-0.00193828 0 -0.187315" size="0.00935863"/>
          </body>
        </body>
      </body>
      <body name="RL_hip" pos="-0.187969 0.0442038 -0.00104298" quat="1 0.000190848 0.000121825 0.000150202">
        <inertial pos="0.00505755 0.00264053 -0.000816756" quat="0.505259 0.497225 0.497507 0.499967" mass="0.554364" diaginertia="0.000751224 0.000480974 0.000251243"/>
        <joint name="RL_hip_joint" pos="0 0 0" axis="-0.999818 -0.0185995 -0.00413138" stiffness="0.00144275" range="-1.03978 1.05809" armature="0.00936297" damping="0.014092" frictionloss="0.191709"/>
        <geom name="//unnamed_geom_41" class="visual" pos="-7.81665e-10 0 -1.53224e-07" quat="4.63268e-05 0 1 0" material="metal" mesh="hip_0"/>
        <geom name="//unnamed_geom_42" class="visual" pos="-1.26717e-09 0 -1.35888e-07" quat="4.63268e-05 0 1 0" material="gray" mesh="hip_1"/>
        <geom name="//unnamed_geom_43" class="collision" size="0.0430497 0.0187173" pos="0 0.0767227 0" quat="0.707107 0.707107 0 0" type="cylinder"/>
        <geom name="//unnamed_geom_44" class="reward_collision_sphere" size="0.0561518" pos="0 0.0671324 0"/>
        <body name="RL_thigh" pos="0.000632468 0.0911233 -0.000960002" quat="1 7.17937e-05 -0.000216124 -0.00014227">
          <inertial pos="-0.00355196 -0.0210351 -0.0291785" quat="0.828258 0.0873372 -0.0232827 0.553008" mass="0.954237" diaginertia="0.00504916 0.00470118 0.000462428"/>
          <joint name="RL_thigh_joint" pos="0 0 0" axis="0.00213565 0.999994 -0.00271226" range="-0.510951 4.52076" armature="0.00946949" damping="0.00952335" frictionloss="0.18941"/>
          <geom name="//unnamed_geom_45" class="visual" material="metal" mesh="thigh_0"/>
          <geom name="//unnamed_geom_46" class="visual" material="gray" mesh="thigh_1"/>
          <geom name="//unnamed_geom_47" class="collision" size="0.0996694 0.0114643 0.0159097" pos="0 0 -0.0936576" quat="0.707107 0 0.707107 0" type="box"/>
          <body name="RL_calf" pos="0.000790465 -0.00164966 -0.187546" quat="1 -4.86825e-06 -8.27787e-05 -0.000115528">
            <inertial pos="0.00635615 -0.000541462 -0.124483" quat="0.71042 0.000584982 -0.0036876 0.703768" mass="0.193323" diaginertia="0.00125839 0.00117774 2.76631e-05"/>
            <joint name="RL_calf_joint" pos="0 0 0" axis="-0.00971674 0.999943 -0.0043951" range="-2.70604 -0.824032" armature="0.00935649" damping="0.00102635" frictionloss="0.185354"/>
            <geom name="//unnamed_geom_48" class="visual" material="gray" mesh="calf_0"/>
            <geom name="//unnamed_geom_49" class="visual" material="black" mesh="calf_1"/>
            <geom name="RL_calf0" class="collision" size="0.0121662 0.0561518" pos="0.00969141 0 -0.0527648" quat="0.995004 0 -0.0998334 0" type="cylinder"/>
            <geom name="//unnamed_geom_51" class="collision" size="0.0102945 0.0304156" pos="0.0193828 0 -0.130153" quat="0.999688 0 0.0249974 0" type="cylinder"/>
            <geom name="//unnamed_geom_52" class="visual" pos="0 0 -0.187315" quat="1 0 0 0" material="black" mesh="foot"/>
            <geom name="RL_foot" class="foot" size="0.0176404" pos="-0.00193828 0 -0.187315"/>
            <geom name="//unnamed_geom_54" class="reward_collision_sphere" size="0.0233966"/>
            <geom name="//unnamed_geom_55" class="reward_collision_sphere" size="0.0233966" pos="-0.00193828 0 -0.187315"/>
            <site name="RL_foot" class="foot" pos="-0.00193828 0 -0.187315" size="0.00935863"/>
          </body>
        </body>
      </body>
      <body name="RR_hip" pos="-0.186616 -0.0452945 -0.000312586" quat="1 7.0525e-06 -6.32652e-05 -4.03448e-05">
        <inertial pos="0.00564097 -0.00206182 0.000942465" quat="0.497359 0.497982 0.498323 0.506283" mass="0.548216" diaginertia="0.000741263 0.000476868 0.000250628"/>
        <joint name="RR_hip_joint" pos="0 0 0" axis="-0.999998 -0.00111246 -0.0017361" range="-1.04736 1.04347" armature="0.00935378" damping="0.00701202" frictionloss="0.186055"/>
        <geom name="//unnamed_geom_56" class="visual" pos="7.81315e-10 6.93619e-10 -1.82975e-07" quat="2.14617e-09 4.63268e-05 4.63268e-05 -1" material="metal" mesh="hip_0"/>
        <geom name="//unnamed_geom_57" class="visual" pos="1.26804e-09 1.12444e-09 -6.23031e-08" quat="2.14617e-09 4.63268e-05 4.63268e-05 -1" material="gray" mesh="hip_1"/>
        <geom name="//unnamed_geom_58" class="collision" size="0.0430497 0.0187173" pos="0 -0.0767227 0" quat="0.707107 0.707107 0 0" type="cylinder"/>
        <geom name="//unnamed_geom_59" class="reward_collision_sphere" size="0.0561518" pos="0 -0.0671324 0"/>
        <body name="RR_thigh" pos="0.000452598 -0.092645 -0.00164351" quat="1 2.89678e-05 4.20929e-05 -7.17267e-06">
          <inertial pos="-0.00336889 0.021286 -0.029723" quat="0.551302 -0.0224548 0.0854466 0.829615" mass="0.952433" diaginertia="0.00512783 0.0047931 0.000467316"/>
          <joint name="RR_thigh_joint" pos="0 0 0" axis="0.00191628 -0.999996 -0.00207522" stiffness="0.0021642" range="-4.53356 0.505992" armature="0.00951405" damping="0.0128589" frictionloss="0.191266"/>
          <geom name="//unnamed_geom_60" class="visual" material="metal" mesh="thigh_mirror_0"/>
          <geom name="//unnamed_geom_61" class="visual" material="gray" mesh="thigh_mirror_1"/>
          <geom name="//unnamed_geom_62" class="collision" size="0.0996694 0.0114643 0.0159097" pos="0 0 -0.0936576" quat="0.707107 0 0.707107 0" type="box"/>
          <body name="RR_calf" pos="-0.000860879 -0.000480532 -0.188195" quat="1 0.000181766 -0.000318629 -0.000277795">
            <inertial pos="0.00709779 0.000692546 -0.124977" quat="0.702915 -0.00536645 0.00193467 0.711251" mass="0.199062" diaginertia="0.00128091 0.00118641 2.81904e-05"/>
            <joint name="RR_calf_joint" pos="0 0 0" axis="-0.00254812 -0.999994 0.00235471" stiffness="0.00138067" range="0.848193 2.73362" armature="0.0092598" damping="0.0100628" frictionloss="0.188052"/>
            <geom name="//unnamed_geom_63" class="visual" material="gray" mesh="calf_mirror_0"/>
            <geom name="//unnamed_geom_64" class="visual" material="black" mesh="calf_mirror_1"/>
            <geom name="RR_calf0" class="collision" size="0.0121662 0.0561518" pos="0.00969141 0 -0.0527648" quat="0.995004 0 -0.0998334 0" type="cylinder"/>
            <geom name="//unnamed_geom_66" class="collision" size="0.0102945 0.0304156" pos="0.0193828 0 -0.130153" quat="0.999688 0 0.0249974 0" type="cylinder"/>
            <geom name="//unnamed_geom_67" class="visual" pos="0 0 -0.187315" quat="1 0 0 0" material="black" mesh="foot"/>
            <geom name="RR_foot" class="foot" size="0.0214578" pos="-0.00193828 0 -0.187315"/>
            <geom name="//unnamed_geom_69" class="reward_collision_sphere" size="0.0233966"/>
            <geom name="//unnamed_geom_70" class="reward_collision_sphere" size="0.0233966" pos="-0.00193828 0 -0.187315"/>
            <site name="RR_foot" class="foot" pos="-0.00193828 0 -0.187315" size="0.00935863"/>
          </body>
        </body>
      </body>
    </body>
  </worldbody>

  <contact>
    <pair class="/" geom1="floor" geom2="FL_foot" name="//unnamed_contact_0"/>
    <pair class="/" geom1="floor" geom2="FR_foot" name="//unnamed_contact_1"/>
    <pair class="/" geom1="floor" geom2="RL_foot" name="//unnamed_contact_2"/>
    <pair class="/" geom1="floor" geom2="RR_foot" name="//unnamed_contact_3"/>
  </contact>

  <actuator>
    <general name="FL_hip" class="/" joint="FL_hip_joint" forcerange="-22.9954 22.9954" gainprm="19.0323" biasprm="0 -19.0323 -0.470108"/>
    <general name="FL_thigh" class="/" joint="FL_thigh_joint" forcerange="-22.9741 22.9741" gainprm="19.0323" biasprm="0 -19.0323 -0.470108"/>
    <general name="FL_calf" class="/" joint="FL_calf_joint" forcerange="-41.8314 41.8314" gainprm="19.0323" biasprm="0 -19.0323 -0.470108"/>
    <general name="FR_hip" class="/" joint="FR_hip_joint" forcerange="-22.5117 22.5117" gainprm="19.0323" biasprm="0 -19.0323 -0.470108"/>
    <general name="FR_thigh" class="/" joint="FR_thigh_joint" forcerange="-22.5441 22.5441" gainprm="19.0323" biasprm="0 -19.0323 -0.470108"/>
    <general name="FR_calf" class="/" joint="FR_calf_joint" forcerange="-41.018 41.018" gainprm="19.0323" biasprm="0 -19.0323 -0.470108"/>
    <general name="RL_hip" class="/" joint="RL_hip_joint" forcerange="-21.7879 21.7879" gainprm="19.0323" biasprm="0 -19.0323 -0.470108"/>
    <general name="RL_thigh" class="/" joint="RL_thigh_joint" forcerange="-22.4479 22.4479" gainprm="19.0323" biasprm="0 -19.0323 -0.470108"/>
    <general name="RL_calf" class="/" joint="RL_calf_joint" forcerange="-43.8846 43.8846" gainprm="19.0323" biasprm="0 -19.0323 -0.470108"/>
    <general name="RR_hip" class="/" joint="RR_hip_joint" forcerange="-21.5514 21.5514" gainprm="19.0323" biasprm="0 -19.0323 -0.470108"/>
    <general name="RR_thigh" class="/" joint="RR_thigh_joint" forcerange="-22.0641 22.0641" gainprm="19.0323" biasprm="0 -19.0323 -0.470108"/>
    <general name="RR_calf" class="/" joint="RR_calf_joint" forcerange="-42.4791 42.4791" gainprm="19.0323" biasprm="0 -19.0323 -0.470108"/>
  </actuator>

  <sensor>
    <gyro site="imu" name="imu_angular_velocity"/>
    <velocimeter site="imu" name="imu_linear_velocity"/>
    <framelinvel objtype="site" objname="FL_foot" name="FL_foot_global_linear_velocity"/>
    <framelinvel objtype="site" objname="FR_foot" name="FR_foot_global_linear_velocity"/>
    <framelinvel objtype="site" objname="RL_foot" name="RL_foot_global_linear_velocity"/>
    <framelinvel objtype="site" objname="RR_foot" name="RR_foot_global_linear_velocity"/>
  </sensor>

  <keyframe>
    <key name="home" qpos="0 0 0.325 1 0 0 0 0.1 0.8 -1.5 -0.1 -0.8 1.5 -0.1 0.8 -1.5 0.1 -0.8 1.5"/>
  </keyframe>
</mujoco>
