<mujoco model="go2">
  <compiler angle="radian" assetdir="assets" balanceinertia="true" inertiafromgeom="false"/>

  <option timestep="0.005" density="1.2" viscosity="2e-05"/>

  <size nkey="1"/>

  <visual>
    <quality shadowsize="8192"/>
    <map shadowclip="0.5"/>
  </visual>

  <default>
    <default class="/">
      <geom contype="0" conaffinity="0" group="1" solref="-1000 -80"/>
      <site size="0.01 0.005 0.005" group="5"/>
      <general forcelimited="true" biastype="affine" gainprm="20" biasprm="0 -20 -0.5"/>
      <default class="go2">
        <joint armature="0.01" damping="0.01" frictionloss="0.2"/>
        <geom condim="1" margin="0.001"/>
        <default class="visual">
          <geom type="mesh" group="2"/>
        </default>
        <default class="collision">
          <geom group="3"/>
          <default class="foot">
            <geom size="0.022 0 0" condim="6" priority="1" friction="0.8 0.02 0.01" solimp="0.015 1 0.022"/>
          </default>
        </default>
        <default class="reward_collision_sphere">
          <geom group="5" rgba="1 0 0 1"/>
        </default>
      </default>
    </default>
  </default>

  <asset>
    <texture type="skybox" colorspace="auto" name="//unnamed_texture_0" builtin="gradient" rgb1="0.95 0.95 0.95" rgb2="0.95 0.95 0.95" width="100" height="600"/>
    <texture type="2d" colorspace="auto" name="texplane" builtin="checker" rgb1="0.345 0.575 0.748" rgb2="0.345 0.575 0.748" markrgb="1 1 1" width="512" height="512"/>
    <material name="MatPlane" class="/" texture="texplane" texuniform="true" texrepeat="2 2" specular="0.9"/>
    <material name="metal" class="/" rgba="0.9 0.95 0.95 1"/>
    <material name="black" class="/" rgba="0 0 0 1"/>
    <material name="white" class="/"/>
    <material name="gray" class="/" rgba="0.671705 0.692426 0.77427 1"/>
    <mesh name="base_0" class="/" file="base_0.obj"/>
    <mesh name="base_1" class="/" file="base_1.obj"/>
    <mesh name="base_2" class="/" file="base_2.obj"/>
    <mesh name="base_3" class="/" file="base_3.obj"/>
    <mesh name="base_4" class="/" file="base_4.obj"/>
    <mesh name="hip_0" class="/" file="hip_0.obj"/>
    <mesh name="hip_1" class="/" file="hip_1.obj"/>
    <mesh name="thigh_0" class="/" file="thigh_0.obj"/>
    <mesh name="thigh_1" class="/" file="thigh_1.obj"/>
    <mesh name="thigh_mirror_0" class="/" file="thigh_mirror_0.obj"/>
    <mesh name="thigh_mirror_1" class="/" file="thigh_mirror_1.obj"/>
    <mesh name="calf_0" class="/" file="calf_0.obj"/>
    <mesh name="calf_1" class="/" file="calf_1.obj"/>
    <mesh name="calf_mirror_0" class="/" file="calf_mirror_0.obj"/>
    <mesh name="calf_mirror_1" class="/" file="calf_mirror_1.obj"/>
    <mesh name="foot" class="/" file="foot.obj"/>
  </asset>

  <worldbody>
    <geom name="floor" class="/" size="100 100 0.125" type="plane" group="0" material="MatPlane"/>
    <light name="toplight_shadow" class="/" pos="0 0 5" dir="0.0990148 0.0990148 -0.990148" type="directional" ambient="0.04 0.04 0.04" diffuse="0.55 0.55 0.55" specular="0.12 0.12 0.12"/>
    <light name="toplight_fill" class="/" pos="0 0 5" dir="0.0990148 0.0990148 -0.990148" type="directional" castshadow="false" ambient="0.04 0.04 0.04" diffuse="0.3 0.3 0.3" specular="0.08 0.08 0.08"/>
    <body name="trunk" childclass="go2" pos="0.000654995 0.000674344 0.000990969" quat="1 3.97497e-05 7.29414e-06 3.89595e-05">
      <inertial pos="0.0235828 0.00113745 -0.00469005" quat="7.87697e-05 0.715252 -0.0251074 0.698415" mass="8.07943" diaginertia="0.109416 0.309246 0.0126874"/>
      <joint name="//unnamed_joint_0" type="free" armature="0" damping="0" frictionloss="0"/>
      <geom name="//unnamed_geom_1" class="visual" material="black" mesh="base_0"/>
      <geom name="//unnamed_geom_2" class="visual" material="black" mesh="base_1"/>
      <geom name="//unnamed_geom_3" class="visual" material="black" mesh="base_2"/>
      <geom name="//unnamed_geom_4" class="visual" material="white" mesh="base_3"/>
      <geom name="//unnamed_geom_5" class="visual" material="gray" mesh="base_4"/>
      <geom name="trunk_1" class="collision" size="0.197438 0.0490709 0.0598297" type="box"/>
      <geom name="trunk_2" class="collision" size="0.0524822 0.047234" pos="0.287479 0 0.00876497" type="cylinder"/>
      <geom name="trunk_3" class="collision" size="0.0493333" pos="0.295549 0 -0.0525898"/>
      <geom name="//unnamed_geom_9" class="reward_collision_sphere" size="0.104964"/>
      <geom name="//unnamed_geom_10" class="reward_collision_sphere" size="0.0629786" pos="0.282436 0 -0.0394424"/>
      <site name="imu" pos="-0.0278421 0.00636525 0.0404009" size="0.0104964"/>
      <camera name="track" pos="0 -2.52747 0" quat="0.707107 0.707107 0 0" mode="trackcom"/>
      <camera name="ego_camera" pos="0.314714 0 0.0394424" quat="-0.5 -0.5 0.5 0.5"/>
      <body name="FL_hip" pos="0.195409 0.0543216 -0.00275757" quat="1 -0.000247281 -8.62164e-05 0.000550511">
        <inertial pos="-0.00717415 0.00249217 0.00119463" quat="0.501939 0.495439 0.504146 0.498432" mass="0.795305" diaginertia="0.00092452 0.00198816 0.000244821"/>
        <joint name="FL_hip_joint" pos="0 0 0" axis="0.999999 -0.000852708 0.00122113" range="-1.14064 1.07983" armature="0.0103798" damping="0.0139427" frictionloss="0.214204"/>
        <geom name="//unnamed_geom_11" class="visual" material="metal" mesh="hip_0"/>
        <geom name="//unnamed_geom_12" class="visual" material="gray" mesh="hip_1"/>
        <geom name="//unnamed_geom_13" class="collision" size="0.0482836 0.0209929" pos="0 0.101099 0" quat="0.707107 0.707107 0 0" type="cylinder"/>
        <geom name="//unnamed_geom_14" class="reward_collision_sphere" size="0.0629786" pos="0 0.0884615 0"/>
        <body name="FL_thigh" pos="-0.00107458 0.116359 -0.00162929" quat="1 2.52466e-05 7.56338e-05 3.13107e-05">
          <inertial pos="-0.00368707 -0.0271669 -0.0265" quat="0.831221 0.0770462 -0.015569 0.550357" mass="1.3343" diaginertia="0.00630855 0.0189244 0.000440439"/>
          <joint name="FL_thigh_joint" pos="0 0 0" axis="-0.000450629 0.999995 -0.00302942" stiffness="0.000354044" range="-1.5334 3.43198" armature="0.00986865" damping="0.0199971" frictionloss="0.235302"/>
          <geom name="//unnamed_geom_15" class="visual" material="metal" mesh="thigh_0"/>
          <geom name="//unnamed_geom_16" class="visual" material="gray" mesh="thigh_1"/>
          <geom name="//unnamed_geom_17" class="collision" size="0.111787 0.0128581 0.0178439" pos="0 0 -0.0933469" quat="0.707107 0 0.707107 0" type="box"/>
          <body name="FL_calf" pos="-0.00373542 0.00281369 -0.188913" quat="1 0.000544197 0.000349473 -0.000450041">
            <inertial pos="0.00690293 -0.000966375 -0.119823" quat="0.710394 -0.00142538 -0.00503048 0.703785" mass="0.271135" diaginertia="0.00155166 0.0044864 2.84343e-05"/>
            <joint name="FL_calf_joint" pos="0 0 0" axis="0.00414418 0.999986 -0.00337576" range="-2.64786 -0.856271" armature="0.0101338" damping="0.010622" frictionloss="0.208125"/>
            <geom name="//unnamed_geom_18" class="visual" material="gray" mesh="calf_0"/>
            <geom name="//unnamed_geom_19" class="visual" material="black" mesh="calf_1"/>
            <geom name="FL_calf0" class="collision" size="0.0125957 0.0629786" pos="0.00806959 0 -0.0525898" quat="0.994493 0 -0.104807 0" type="cylinder"/>
            <geom name="//unnamed_geom_21" class="collision" size="0.0115461 0.0341134" pos="0.020174 0 -0.129722" quat="0.999688 0 0.0249974 0" type="cylinder"/>
            <geom name="//unnamed_geom_22" class="visual" pos="0 0 -0.186694" quat="1 0 0 0" material="black" mesh="foot"/>
            <geom name="FL_foot" class="foot" size="0.0190441" pos="-0.0020174 0 -0.186694"/>
            <geom name="//unnamed_geom_24" class="reward_collision_sphere" size="0.0262411"/>
            <geom name="//unnamed_geom_25" class="reward_collision_sphere" size="0.0262411" pos="-0.0020174 0 -0.186694"/>
            <site name="FL_foot" class="foot" pos="-0.0020174 0 -0.186694" size="0.0104964"/>
          </body>
        </body>
      </body>
      <body name="FR_hip" pos="0.198538 -0.0603391 -0.000899353" quat="1 0.000122072 0.000311687 -0.000411815">
        <inertial pos="-0.00764278 -0.00025155 0.00222883" quat="0.497431 0.506778 0.49865 0.497077" mass="0.811969" diaginertia="0.000903212 0.00205556 0.00024802"/>
        <joint name="FR_hip_joint" pos="0 0 0" axis="0.999997 0.00258207 -0.000378759" range="-1.05003 1.04418" armature="0.0118112" damping="0.0169387" frictionloss="0.236183"/>
        <geom name="//unnamed_geom_26" class="visual" pos="0 3.37347e-09 1.44695e-07" quat="4.63268e-05 1 0 0" material="metal" mesh="hip_0"/>
        <geom name="//unnamed_geom_27" class="visual" pos="0 5.46879e-09 -3.57886e-07" quat="4.63268e-05 1 0 0" material="gray" mesh="hip_1"/>
        <geom name="//unnamed_geom_28" class="collision" size="0.0482836 0.0209929" pos="0 -0.101099 0" quat="0.707107 0.707107 0 0" type="cylinder"/>
        <geom name="//unnamed_geom_29" class="reward_collision_sphere" size="0.0629786" pos="0 -0.0884615 0"/>
        <body name="FR_thigh" pos="-0.00313492 -0.125024 -0.00433926" quat="1 -3.2973e-05 0.000866631 -0.000395339">
          <inertial pos="-0.00585774 0.0322905 -0.028962" quat="0.547928 -0.0180019 0.0840393 0.832099" mass="1.31028" diaginertia="0.00616897 0.0185813 0.000433776"/>
          <joint name="FR_thigh_joint" pos="0 0 0" axis="0.00430883 -0.999977 0.00525257" range="-3.42728 1.56721" armature="0.0111351" damping="0.0244615" frictionloss="0.208352"/>
          <geom name="//unnamed_geom_30" class="visual" material="metal" mesh="thigh_mirror_0"/>
          <geom name="//unnamed_geom_31" class="visual" material="gray" mesh="thigh_mirror_1"/>
          <geom name="//unnamed_geom_32" class="collision" size="0.111787 0.0128581 0.0178439" pos="0 0 -0.0933469" quat="0.707107 0 0.707107 0" type="box"/>
          <body name="FR_calf" pos="0.00281244 0.000325884 -0.18711" quat="1 -0.000573749 0.000421556 -0.000561939">
            <inertial pos="0.00875553 0.00108908 -0.123761" quat="0.701538 -0.00687597 -0.00106439 0.712598" mass="0.281852" diaginertia="0.00160105 0.00469568 2.8318e-05"/>
            <joint name="FR_calf_joint" pos="0 0 0" axis="-0.00476964 -0.999816 0.0185766" range="0.877758 2.71464" armature="0.00906976" damping="0" frictionloss="0.227431"/>
            <geom name="//unnamed_geom_33" class="visual" material="gray" mesh="calf_mirror_0"/>
            <geom name="//unnamed_geom_34" class="visual" material="black" mesh="calf_mirror_1"/>
            <geom name="FR_calf0" class="collision" size="0.0136454 0.0629786" pos="0.010087 0 -0.0525898" quat="0.995004 0 -0.0998334 0" type="cylinder"/>
            <geom name="//unnamed_geom_36" class="collision" size="0.0115461 0.0341134" pos="0.020174 0 -0.129722" quat="0.999688 0 0.0249974 0" type="cylinder"/>
            <geom name="//unnamed_geom_37" class="visual" pos="0 0 -0.186694" quat="1 0 0 0" material="black" mesh="foot"/>
            <geom name="FR_foot" class="foot" size="0.0209444" pos="-0.0020174 0 -0.186694"/>
            <geom name="//unnamed_geom_39" class="reward_collision_sphere" size="0.0262411"/>
            <geom name="//unnamed_geom_40" class="reward_collision_sphere" size="0.0262411" pos="-0.0020174 0 -0.186694"/>
            <site name="FR_foot" class="foot" pos="-0.0020174 0 -0.186694" size="0.0104964"/>
          </body>
        </body>
      </body>
      <body name="RL_hip" pos="-0.19409 0.0570426 0.00156675" quat="0.999999 0.000139273 -0.000863869 -0.000574843">
        <inertial pos="0.00495089 0.00373585 0.00118432" quat="0.501877 0.49569 0.508087 0.494226" mass="0.831717" diaginertia="0.000945518 0.00197245 0.000257673"/>
        <joint name="RL_hip_joint" pos="0 0 0" axis="-0.99995 0.00824229 0.00567925" range="-0.997614 1.00195" armature="0.0105343" damping="0.00628664" frictionloss="0.234388"/>
        <geom name="//unnamed_geom_41" class="visual" pos="-1.15169e-09 0 -2.25757e-07" quat="4.63268e-05 0 1 0" material="metal" mesh="hip_0"/>
        <geom name="//unnamed_geom_42" class="visual" pos="-1.86702e-09 0 -2.00214e-07" quat="4.63268e-05 0 1 0" material="gray" mesh="hip_1"/>
        <geom name="//unnamed_geom_43" class="collision" size="0.0482836 0.0209929" pos="0 0.101099 0" quat="0.707107 0.707107 0 0" type="cylinder"/>
        <geom name="//unnamed_geom_44" class="reward_collision_sphere" size="0.0629786" pos="0 0.0884615 0"/>
        <body name="RL_thigh" pos="-0.000473651 0.120769 0.00353744" quat="0.999999 0.000447623 0.00064287 0.000975937">
          <inertial pos="-0.00388811 -0.0291177 -0.0255892" quat="0.827176 0.0888365 -0.0221233 0.554436" mass="1.29565" diaginertia="0.00619465 0.019932 0.000462442"/>
          <joint name="RL_thigh_joint" pos="0 0 0" axis="0.0212009 0.99977 0.00315306" range="-0.51109 4.55654" armature="0.0093673" damping="0.0133278" frictionloss="0.199451"/>
          <geom name="//unnamed_geom_45" class="visual" material="metal" mesh="thigh_0"/>
          <geom name="//unnamed_geom_46" class="visual" material="gray" mesh="thigh_1"/>
          <geom name="//unnamed_geom_47" class="collision" size="0.111787 0.0128581 0.0178439" pos="0 0 -0.0933469" quat="0.707107 0 0.707107 0" type="box"/>
          <body name="RL_calf" pos="0.000530852 0.00426986 -0.185306" quat="0.999999 -0.000518246 -0.00102076 0.000106844">
            <inertial pos="0.00534182 -0.00150107 -0.125713" quat="0.710235 0.00183841 -0.00510822 0.703944" mass="0.285816" diaginertia="0.00153806 0.00476306 2.79202e-05"/>
            <joint name="RL_calf_joint" pos="0 0 0" axis="-0.000706235 0.999999 0.000729052" range="-2.80175 -0.826981" armature="0.0101569" damping="0.00286278" frictionloss="0.218574"/>
            <geom name="//unnamed_geom_48" class="visual" material="gray" mesh="calf_0"/>
            <geom name="//unnamed_geom_49" class="visual" material="black" mesh="calf_1"/>
            <geom name="RL_calf0" class="collision" size="0.0136454 0.0629786" pos="0.010087 0 -0.0525898" quat="0.995004 0 -0.0998334 0" type="cylinder"/>
            <geom name="//unnamed_geom_51" class="collision" size="0.0115461 0.0341134" pos="0.020174 0 -0.129722" quat="0.999688 0 0.0249974 0" type="cylinder"/>
            <geom name="//unnamed_geom_52" class="visual" pos="0 0 -0.186694" quat="1 0 0 0" material="black" mesh="foot"/>
            <geom name="RL_foot" class="foot" size="0.0231842" pos="-0.0020174 0 -0.186694"/>
            <geom name="//unnamed_geom_54" class="reward_collision_sphere" size="0.0262411"/>
            <geom name="//unnamed_geom_55" class="reward_collision_sphere" size="0.0262411" pos="-0.0020174 0 -0.186694"/>
            <site name="RL_foot" class="foot" pos="-0.0020174 0 -0.186694" size="0.0104964"/>
          </body>
        </body>
      </body>
      <body name="RR_hip" pos="-0.19323 -0.0597018 0.000933379" quat="1 0.000401635 0.000732284 -0.000321167">
        <inertial pos="0.00775077 -0.00397537 -0.000722294" quat="0.49035 0.494058 0.505713 0.509624" mass="0.795867" diaginertia="0.000932157 0.00200928 0.000243394"/>
        <joint name="RR_hip_joint" pos="0 0 0" axis="-0.999921 -0.0118578 0.00407614" stiffness="0.00850339" range="-1.07938 1.10024" armature="0.0103586" damping="0.00595335" frictionloss="0.22322"/>
        <geom name="//unnamed_geom_56" class="visual" pos="1.16052e-09 3.37347e-09 -3.70452e-07" quat="2.14617e-09 4.63268e-05 4.63268e-05 -1" material="metal" mesh="hip_0"/>
        <geom name="//unnamed_geom_57" class="visual" pos="1.84518e-09 5.46879e-09 1.57672e-07" quat="2.14617e-09 4.63268e-05 4.63268e-05 -1" material="gray" mesh="hip_1"/>
        <geom name="//unnamed_geom_58" class="collision" size="0.0482836 0.0209929" pos="0 -0.101099 0" quat="0.707107 0.707107 0 0" type="cylinder"/>
        <geom name="//unnamed_geom_59" class="reward_collision_sphere" size="0.0629786" pos="0 -0.0884615 0"/>
        <body name="RR_thigh" pos="-0.000416849 -0.120962 -4.73114e-05" quat="1 0.00049192 5.65986e-05 0.000868153">
          <inertial pos="-0.00380014 0.0306909 -0.0277153" quat="0.552912 -0.0255248 0.07394 0.82956" mass="1.31587" diaginertia="0.00620116 0.0184995 0.000448923"/>
          <joint name="RR_thigh_joint" pos="0 0 0" axis="0.0156143 -0.999794 0.0129441" range="-4.49954 0.551" armature="0.01044" damping="0.0128194" frictionloss="0.232941"/>
          <geom name="//unnamed_geom_60" class="visual" material="metal" mesh="thigh_mirror_0"/>
          <geom name="//unnamed_geom_61" class="visual" material="gray" mesh="thigh_mirror_1"/>
          <geom name="//unnamed_geom_62" class="collision" size="0.111787 0.0128581 0.0178439" pos="0 0 -0.0933469" quat="0.707107 0 0.707107 0" type="box"/>
          <body name="RR_calf" pos="0.00542891 0.00212091 -0.184858" quat="1 -0.000736657 0.000369244 -0.000393576">
            <inertial pos="0.00157331 0.000671552 -0.126624" quat="0.695792 -0.00224193 0.00597077 0.718215" mass="0.274594" diaginertia="0.00148962 0.00451639 2.80016e-05"/>
            <joint name="RR_calf_joint" pos="0 0 0" axis="-0.0192142 -0.999806 0.00439951" range="0.861617 2.66666" armature="0.0118535" damping="0.00329999" frictionloss="0.200763"/>
            <geom name="//unnamed_geom_63" class="visual" material="gray" mesh="calf_mirror_0"/>
            <geom name="//unnamed_geom_64" class="visual" material="black" mesh="calf_mirror_1"/>
            <geom name="RR_calf0" class="collision" size="0.0136454 0.0629786" pos="0.010087 0 -0.0525898" quat="0.995004 0 -0.0998334 0" type="cylinder"/>
            <geom name="//unnamed_geom_66" class="collision" size="0.0115461 0.0341134" pos="0.020174 0 -0.129722" quat="0.999688 0 0.0249974 0" type="cylinder"/>
            <geom name="//unnamed_geom_67" class="visual" pos="0 0 -0.186694" quat="1 0 0 0" material="black" mesh="foot"/>
            <geom name="RR_foot" class="foot" size="0.0224512" pos="-0.0020174 0 -0.186694"/>
            <geom name="//unnamed_geom_69" class="reward_collision_sphere" size="0.0262411"/>
            <geom name="//unnamed_geom_70" class="reward_collision_sphere" size="0.0262411" pos="-0.0020174 0 -0.186694"/>
            <site name="RR_foot" class="foot" pos="-0.0020174 0 -0.186694" size="0.0104964"/>
          </body>
        </body>
      </body>
    </body>
  </worldbody>

  <contact>
    <pair class="/" geom1="floor" geom2="FL_foot" name="//unnamed_contact_0"/>
    <pair class="/" geom1="floor" geom2="FR_foot" name="//unnamed_contact_1"/>
    <pair class="/" geom1="floor" geom2="RL_foot" name="//unnamed_contact_2"/>
    <pair class="/" geom1="floor" geom2="RR_foot" name="//unnamed_contact_3"/>
  </contact>

  <actuator>
    <general name="FL_hip" class="/" joint="FL_hip_joint" forcerange="-20.7164 20.7164" gainprm="19.4633" biasprm="0 -19.4633 -0.559122"/>
    <general name="FL_thigh" class="/" joint="FL_thigh_joint" forcerange="-24.4318 24.4318" gainprm="19.4633" biasprm="0 -19.4633 -0.559122"/>
    <general name="FL_calf" class="/" joint="FL_calf_joint" forcerange="-42.9297 42.9297" gainprm="19.4633" biasprm="0 -19.4633 -0.559122"/>
    <general name="FR_hip" class="/" joint="FR_hip_joint" forcerange="-22.047 22.047" gainprm="19.4633" biasprm="0 -19.4633 -0.559122"/>
    <general name="FR_thigh" class="/" joint="FR_thigh_joint" forcerange="-22.011 22.011" gainprm="19.4633" biasprm="0 -19.4633 -0.559122"/>
    <general name="FR_calf" class="/" joint="FR_calf_joint" forcerange="-48.1446 48.1446" gainprm="19.4633" biasprm="0 -19.4633 -0.559122"/>
    <general name="RL_hip" class="/" joint="RL_hip_joint" forcerange="-22.5205 22.5205" gainprm="19.4633" biasprm="0 -19.4633 -0.559122"/>
    <general name="RL_thigh" class="/" joint="RL_thigh_joint" forcerange="-26.6943 26.6943" gainprm="19.4633" biasprm="0 -19.4633 -0.559122"/>
    <general name="RL_calf" class="/" joint="RL_calf_joint" forcerange="-45.4935 45.4935" gainprm="19.4633" biasprm="0 -19.4633 -0.559122"/>
    <general name="RR_hip" class="/" joint="RR_hip_joint" forcerange="-28.3583 28.3583" gainprm="19.4633" biasprm="0 -19.4633 -0.559122"/>
    <general name="RR_thigh" class="/" joint="RR_thigh_joint" forcerange="-23.3155 23.3155" gainprm="19.4633" biasprm="0 -19.4633 -0.559122"/>
    <general name="RR_calf" class="/" joint="RR_calf_joint" forcerange="-46.3993 46.3993" gainprm="19.4633" biasprm="0 -19.4633 -0.559122"/>
  </actuator>

  <sensor>
    <gyro site="imu" name="imu_angular_velocity"/>
    <velocimeter site="imu" name="imu_linear_velocity"/>
    <framelinvel objtype="site" objname="FL_foot" name="FL_foot_global_linear_velocity"/>
    <framelinvel objtype="site" objname="FR_foot" name="FR_foot_global_linear_velocity"/>
    <framelinvel objtype="site" objname="RL_foot" name="RL_foot_global_linear_velocity"/>
    <framelinvel objtype="site" objname="RR_foot" name="RR_foot_global_linear_velocity"/>
  </sensor>

  <keyframe>
    <key name="home" qpos="0 0 0.325 1 0 0 0 0.1 0.8 -1.5 -0.1 -0.8 1.5 -0.1 0.8 -1.5 0.1 -0.8 1.5"/>
  </keyframe>
</mujoco>
