<mujoco model="go2">
  <compiler angle="radian" assetdir="assets" balanceinertia="true" inertiafromgeom="false"/>

  <option timestep="0.005" density="1.2" viscosity="2e-05"/>

  <size nkey="1"/>

  <visual>
    <quality shadowsize="8192"/>
    <map shadowclip="0.5"/>
  </visual>

  <default>
    <default class="/">
      <geom contype="0" conaffinity="0" group="1" solref="-1000 -80"/>
      <site size="0.01 0.005 0.005" group="5"/>
      <general forcelimited="true" biastype="affine" gainprm="20" biasprm="0 -20 -0.5"/>
      <default class="go2">
        <joint armature="0.01" damping="0.01" frictionloss="0.2"/>
        <geom condim="1" margin="0.001"/>
        <default class="visual">
          <geom type="mesh" group="2"/>
        </default>
        <default class="collision">
          <geom group="3"/>
          <default class="foot">
            <geom size="0.022 0 0" condim="6" priority="1" friction="0.8 0.02 0.01" solimp="0.015 1 0.022"/>
          </default>
        </default>
        <default class="reward_collision_sphere">
          <geom group="5" rgba="1 0 0 1"/>
        </default>
      </default>
    </default>
  </default>

  <asset>
    <texture type="skybox" colorspace="auto" name="//unnamed_texture_0" builtin="gradient" rgb1="0.95 0.95 0.95" rgb2="0.95 0.95 0.95" width="100" height="600"/>
    <texture type="2d" colorspace="auto" name="texplane" builtin="checker" rgb1="0.345 0.575 0.748" rgb2="0.345 0.575 0.748" markrgb="1 1 1" width="512" height="512"/>
    <material name="MatPlane" class="/" texture="texplane" texuniform="true" texrepeat="2 2" specular="0.9"/>
    <material name="metal" class="/" rgba="0.9 0.95 0.95 1"/>
    <material name="black" class="/" rgba="0 0 0 1"/>
    <material name="white" class="/"/>
    <material name="gray" class="/" rgba="0.671705 0.692426 0.77427 1"/>
    <mesh name="base_0" class="/" file="base_0.obj"/>
    <mesh name="base_1" class="/" file="base_1.obj"/>
    <mesh name="base_2" class="/" file="base_2.obj"/>
    <mesh name="base_3" class="/" file="base_3.obj"/>
    <mesh name="base_4" class="/" file="base_4.obj"/>
    <mesh name="hip_0" class="/" file="hip_0.obj"/>
    <mesh name="hip_1" class="/" file="hip_1.obj"/>
    <mesh name="thigh_0" class="/" file="thigh_0.obj"/>
    <mesh name="thigh_1" class="/" file="thigh_1.obj"/>
    <mesh name="thigh_mirror_0" class="/" file="thigh_mirror_0.obj"/>
    <mesh name="thigh_mirror_1" class="/" file="thigh_mirror_1.obj"/>
    <mesh name="calf_0" class="/" file="calf_0.obj"/>
    <mesh name="calf_1" class="/" file="calf_1.obj"/>
    <mesh name="calf_mirror_0" class="/" file="calf_mirror_0.obj"/>
    <mesh name="calf_mirror_1" class="/" file="calf_mirror_1.obj"/>
    <mesh name="foot" class="/" file="foot.obj"/>
  </asset>

  <worldbody>
    <geom name="floor" class="/" size="100 100 0.125" type="plane" group="0" material="MatPlane"/>
    <light name="toplight_shadow" class="/" pos="0 0 5" dir="0.0990148 0.0990148 -0.990148" type="directional" ambient="0.04 0.04 0.04" diffuse="0.55 0.55 0.55" specular="0.12 0.12 0.12"/>
    <light name="toplight_fill" class="/" pos="0 0 5" dir="0.0990148 0.0990148 -0.990148" type="directional" castshadow="false" ambient="0.04 0.04 0.04" diffuse="0.3 0.3 0.3" specular="0.08 0.08 0.08"/>
    <body name="trunk" childclass="go2" pos="-0.000514927 -0.00236943 -0.000964257" quat="1 -6.06825e-05 1.7648e-05 -1.61831e-05">
      <inertial pos="0.0241112 -0.00225324 -0.00481128" quat="-0.00140466 0.713649 -0.00205363 0.700499" mass="7.22856" diaginertia="0.142158 0.176916 0.0113321"/>
      <joint name="//unnamed_joint_0" type="free" armature="0" damping="0" frictionloss="0"/>
      <geom name="//unnamed_geom_1" class="visual" material="black" mesh="base_0"/>
      <geom name="//unnamed_geom_2" class="visual" material="black" mesh="base_1"/>
      <geom name="//unnamed_geom_3" class="visual" material="black" mesh="base_2"/>
      <geom name="//unnamed_geom_4" class="visual" material="white" mesh="base_3"/>
      <geom name="//unnamed_geom_5" class="visual" material="gray" mesh="base_4"/>
      <geom name="trunk_1" class="collision" size="0.191484 0.0475911 0.0580255" type="box"/>
      <geom name="trunk_2" class="collision" size="0.0508995 0.0458096" pos="0.303663 0 0.00857898" type="cylinder"/>
      <geom name="trunk_3" class="collision" size="0.0478455" pos="0.312187 0 -0.0514739"/>
      <geom name="//unnamed_geom_9" class="reward_collision_sphere" size="0.101799"/>
      <geom name="//unnamed_geom_10" class="reward_collision_sphere" size="0.0610794" pos="0.298335 0 -0.0386054"/>
      <site name="imu" pos="-0.0148444 0.0141203 0.024431" size="0.0101799"/>
      <camera name="track" pos="0 -2.26118 0" quat="0.707107 0.707107 0 0" mode="trackcom"/>
      <camera name="ego_camera" pos="0.332431 0 0.0386054" quat="-0.5 -0.5 0.5 0.5"/>
      <body name="FL_hip" pos="0.208414 0.0525184 0.000981546" quat="1 -4.7502e-05 0.000411723 0.00083093">
        <inertial pos="-0.00541949 0.00227967 0.00246176" quat="0.49825 0.495576 0.506485 0.499625" mass="0.69776" diaginertia="0.00121359 0.00106871 0.000221346"/>
        <joint name="FL_hip_joint" pos="0 0 0" axis="0.999956 -0.000597439 0.00934816" stiffness="0.00562745" range="-1.05184 1.10388" armature="0.0105396" damping="0.000138181" frictionloss="0.231592"/>
        <geom name="//unnamed_geom_11" class="visual" material="metal" mesh="hip_0"/>
        <geom name="//unnamed_geom_12" class="visual" material="gray" mesh="hip_1"/>
        <geom name="//unnamed_geom_13" class="collision" size="0.0468276 0.0203598" pos="0 0.0904472 0" quat="0.707107 0.707107 0 0" type="cylinder"/>
        <geom name="//unnamed_geom_14" class="reward_collision_sphere" size="0.0610794" pos="0 0.0791413 0"/>
        <body name="FL_thigh" pos="-0.00144357 0.108001 -0.000245384" quat="0.999999 0.00047201 0.00101371 0.00096919">
          <inertial pos="-0.00131872 -0.0223378 -0.0281036" quat="0.833988 0.082259 -0.02325 0.54512" mass="1.21436" diaginertia="0.00798359 0.0106374 0.000395633"/>
          <joint name="FL_thigh_joint" pos="0 0 0" axis="0.0124303 0.999898 0.00702304" stiffness="0.0033405" range="-1.51477 3.51174" armature="0.0112581" damping="0.00538866" frictionloss="0.225377"/>
          <geom name="//unnamed_geom_15" class="visual" material="metal" mesh="thigh_0"/>
          <geom name="//unnamed_geom_16" class="visual" material="gray" mesh="thigh_1"/>
          <geom name="//unnamed_geom_17" class="collision" size="0.108416 0.0124704 0.0173058" pos="0 0 -0.0913662" quat="0.707107 0 0.707107 0" type="box"/>
          <body name="FL_calf" pos="-0.00201765 -0.00126133 -0.18494" quat="0.999999 0.000417237 -0.0013736 -2.78498e-05">
            <inertial pos="0.00949015 -0.000499018 -0.121327" quat="0.709372 -0.000191982 -0.00426742 0.704821" mass="0.258306" diaginertia="0.00199632 0.00275104 2.4635e-05"/>
            <joint name="FL_calf_joint" pos="0 0 0" axis="-0.00845903 0.999958 0.00347062" stiffness="0.00131699" range="-2.73215 -0.831156" armature="0.00874804" damping="0.00590472" frictionloss="0.204548"/>
            <geom name="//unnamed_geom_18" class="visual" material="gray" mesh="calf_0"/>
            <geom name="//unnamed_geom_19" class="visual" material="black" mesh="calf_1"/>
            <geom name="FL_calf0" class="collision" size="0.0122159 0.0610794" pos="0.00852387 0 -0.0514739" quat="0.994493 0 -0.104807 0" type="cylinder"/>
            <geom name="//unnamed_geom_21" class="collision" size="0.0111979 0.0330847" pos="0.0213097 0 -0.126969" quat="0.999688 0 0.0249974 0" type="cylinder"/>
            <geom name="//unnamed_geom_22" class="visual" pos="0 0 -0.182732" quat="1 0 0 0" material="black" mesh="foot"/>
            <geom name="FL_foot" class="foot" size="0.0163013" pos="-0.00213097 0 -0.182732"/>
            <geom name="//unnamed_geom_24" class="reward_collision_sphere" size="0.0254498"/>
            <geom name="//unnamed_geom_25" class="reward_collision_sphere" size="0.0254498" pos="-0.00213097 0 -0.182732"/>
            <site name="FL_foot" class="foot" pos="-0.00213097 0 -0.182732" size="0.0101799"/>
          </body>
        </body>
      </body>
      <body name="FR_hip" pos="0.207094 -0.0555086 -0.00231197" quat="1 -0.00048443 -8.04207e-05 -0.000233091">
        <inertial pos="-0.00725618 -0.00217607 0.00103383" quat="0.496997 0.507415 0.495752 0.499754" mass="0.691305" diaginertia="0.00117461 0.00108953 0.000226445"/>
        <joint name="FR_hip_joint" pos="0 0 0" axis="0.999903 0.00521545 0.0129217" range="-1.04747 1.07153" armature="0.010919" damping="0.0123795" frictionloss="0.22424"/>
        <geom name="//unnamed_geom_26" class="visual" pos="0 2.37557e-09 1.01893e-07" quat="4.63268e-05 1 0 0" material="metal" mesh="hip_0"/>
        <geom name="//unnamed_geom_27" class="visual" pos="0 3.85109e-09 -2.52021e-07" quat="4.63268e-05 1 0 0" material="gray" mesh="hip_1"/>
        <geom name="//unnamed_geom_28" class="collision" size="0.0468276 0.0203598" pos="0 -0.0904472 0" quat="0.707107 0.707107 0 0" type="cylinder"/>
        <geom name="//unnamed_geom_29" class="reward_collision_sphere" size="0.0610794" pos="0 -0.0791413 0"/>
        <body name="FR_thigh" pos="0.000880817 -0.108064 0.000422596" quat="0.999999 -0.00120182 0.000267449 -0.000720109">
          <inertial pos="-0.00579458 0.0249421 -0.0270663" quat="0.553546 -0.0205347 0.0707714 0.829552" mass="1.28742" diaginertia="0.0082731 0.0110568 0.000407066"/>
          <joint name="FR_thigh_joint" pos="0 0 0" axis="-0.00323796 -0.999991 0.00282018" range="-3.50764 1.57049" armature="0.00975688" damping="0.0197717" frictionloss="0.202789"/>
          <geom name="//unnamed_geom_30" class="visual" material="metal" mesh="thigh_mirror_0"/>
          <geom name="//unnamed_geom_31" class="visual" material="gray" mesh="thigh_mirror_1"/>
          <geom name="//unnamed_geom_32" class="collision" size="0.108416 0.0124704 0.0173058" pos="0 0 -0.0913662" quat="0.707107 0 0.707107 0" type="box"/>
          <body name="FR_calf" pos="-0.00140822 -0.00175435 -0.184858" quat="1 -8.03698e-05 0.000662567 -0.000580109">
            <inertial pos="0.00915925 0.000692494 -0.118904" quat="0.709523 0.00138541 0.0110764 0.704594" mass="0.252143" diaginertia="0.0020687 0.00272079 2.52895e-05"/>
            <joint name="FR_calf_joint" pos="0 0 0" axis="-0.00198763 -0.999998 -0.00100735" range="0.83242 2.70305" armature="0.0106927" damping="0.0141828" frictionloss="0.184632"/>
            <geom name="//unnamed_geom_33" class="visual" material="gray" mesh="calf_mirror_0"/>
            <geom name="//unnamed_geom_34" class="visual" material="black" mesh="calf_mirror_1"/>
            <geom name="FR_calf0" class="collision" size="0.0132339 0.0610794" pos="0.0106548 0 -0.0514739" quat="0.995004 0 -0.0998334 0" type="cylinder"/>
            <geom name="//unnamed_geom_36" class="collision" size="0.0111979 0.0330847" pos="0.0213097 0 -0.126969" quat="0.999688 0 0.0249974 0" type="cylinder"/>
            <geom name="//unnamed_geom_37" class="visual" pos="0 0 -0.182732" quat="1 0 0 0" material="black" mesh="foot"/>
            <geom name="FR_foot" class="foot" size="0.0200968" pos="-0.00213097 0 -0.182732"/>
            <geom name="//unnamed_geom_39" class="reward_collision_sphere" size="0.0254498"/>
            <geom name="//unnamed_geom_40" class="reward_collision_sphere" size="0.0254498" pos="-0.00213097 0 -0.182732"/>
            <site name="FR_foot" class="foot" pos="-0.00213097 0 -0.182732" size="0.0101799"/>
          </body>
        </body>
      </body>
      <body name="RL_hip" pos="-0.20678 0.053098 0.00195001" quat="0.999999 0.000370948 0.000716018 0.000611152">
        <inertial pos="0.0063127 0.000235158 0.00275204" quat="0.504527 0.502028 0.499686 0.493695" mass="0.750766" diaginertia="0.00125617 0.00113656 0.00022849"/>
        <joint name="RL_hip_joint" pos="0 0 0" axis="-0.999595 0.0110285 -0.0262496" range="-1.03231 0.994043" armature="0.0103529" damping="0.0064458" frictionloss="0.206733"/>
        <geom name="//unnamed_geom_41" class="visual" pos="-1.8084e-09 0 -3.54487e-07" quat="4.63268e-05 0 1 0" material="metal" mesh="hip_0"/>
        <geom name="//unnamed_geom_42" class="visual" pos="-2.93162e-09 0 -3.1438e-07" quat="4.63268e-05 0 1 0" material="gray" mesh="hip_1"/>
        <geom name="//unnamed_geom_43" class="collision" size="0.0468276 0.0203598" pos="0 0.0904472 0" quat="0.707107 0.707107 0 0" type="cylinder"/>
        <geom name="//unnamed_geom_44" class="reward_collision_sphere" size="0.0610794" pos="0 0.0791413 0"/>
        <body name="RL_thigh" pos="-0.00242937 0.107821 -0.000253901" quat="1 -3.04653e-05 0.000165897 -0.00019403">
          <inertial pos="-0.00338917 -0.0239521 -0.0291522" quat="0.828721 0.0974738 -0.026108 0.55049" mass="1.24783" diaginertia="0.00826856 0.0114181 0.000424402"/>
          <joint name="RL_thigh_joint" pos="0 0 0" axis="-0.00827554 0.999941 0.00709477" stiffness="0.0047146" range="-0.570675 4.59448" armature="0.00915017" damping="0" frictionloss="0.213413"/>
          <geom name="//unnamed_geom_45" class="visual" material="metal" mesh="thigh_0"/>
          <geom name="//unnamed_geom_46" class="visual" material="gray" mesh="thigh_1"/>
          <geom name="//unnamed_geom_47" class="collision" size="0.108416 0.0124704 0.0173058" pos="0 0 -0.0913662" quat="0.707107 0 0.707107 0" type="box"/>
          <body name="RL_calf" pos="-0.00178127 -0.000356792 -0.18167" quat="1 0.00016049 0.00013842 -0.000279195">
            <inertial pos="0.00762111 -5.82465e-05 -0.120771" quat="0.708184 0.00316272 -0.00165719 0.706019" mass="0.272902" diaginertia="0.00216448 0.00283314 2.55231e-05"/>
            <joint name="RL_calf_joint" pos="0 0 0" axis="0.0065947 0.99992 0.010781" stiffness="0.00256242" range="-2.71419 -0.885555" armature="0.00986441" damping="0" frictionloss="0.203993"/>
            <geom name="//unnamed_geom_48" class="visual" material="gray" mesh="calf_0"/>
            <geom name="//unnamed_geom_49" class="visual" material="black" mesh="calf_1"/>
            <geom name="RL_calf0" class="collision" size="0.0132339 0.0610794" pos="0.0106548 0 -0.0514739" quat="0.995004 0 -0.0998334 0" type="cylinder"/>
            <geom name="//unnamed_geom_51" class="collision" size="0.0111979 0.0330847" pos="0.0213097 0 -0.126969" quat="0.999688 0 0.0249974 0" type="cylinder"/>
            <geom name="//unnamed_geom_52" class="visual" pos="0 0 -0.182732" quat="1 0 0 0" material="black" mesh="foot"/>
            <geom name="RL_foot" class="foot" size="0.0217606" pos="-0.00213097 0 -0.182732"/>
            <geom name="//unnamed_geom_54" class="reward_collision_sphere" size="0.0254498"/>
            <geom name="//unnamed_geom_55" class="reward_collision_sphere" size="0.0254498" pos="-0.00213097 0 -0.182732"/>
            <site name="RL_foot" class="foot" pos="-0.00213097 0 -0.182732" size="0.0101799"/>
          </body>
        </body>
      </body>
      <body name="RR_hip" pos="-0.20553 -0.0516446 -0.00269257" quat="1 -0.000270271 0.000262042 0.00073455">
        <inertial pos="0.00656341 -0.00013815 -0.00305304" quat="0.495693 0.498253 0.501106 0.504901" mass="0.732372" diaginertia="0.00129558 0.00117072 0.000234378"/>
        <joint name="RR_hip_joint" pos="0 0 0" axis="-0.999988 -0.00487403 0.000487685" stiffness="0.011684" range="-1.03219 1.02127" armature="0.0102727" damping="0.00396981" frictionloss="0.194847"/>
        <geom name="//unnamed_geom_56" class="visual" pos="1.81065e-09 2.37557e-09 -4.5638e-07" quat="2.14617e-09 4.63268e-05 4.63268e-05 -1" material="metal" mesh="hip_0"/>
        <geom name="//unnamed_geom_57" class="visual" pos="2.92605e-09 3.85109e-09 -6.23586e-08" quat="2.14617e-09 4.63268e-05 4.63268e-05 -1" material="gray" mesh="hip_1"/>
        <geom name="//unnamed_geom_58" class="collision" size="0.0468276 0.0203598" pos="0 -0.0904472 0" quat="0.707107 0.707107 0 0" type="cylinder"/>
        <geom name="//unnamed_geom_59" class="reward_collision_sphere" size="0.0610794" pos="0 -0.0791413 0"/>
        <body name="RR_thigh" pos="-2.4251e-05 -0.105661 0.00157515" quat="1 -0.000762324 0.000559441 5.95596e-05">
          <inertial pos="-0.00361606 0.0238727 -0.0253091" quat="0.553681 -0.0215008 0.0853965 0.828059" mass="1.15889" diaginertia="0.00778389 0.0103241 0.000393251"/>
          <joint name="RR_thigh_joint" pos="0 0 0" axis="0.00239101 -0.999997 0.000854006" range="-4.54343 0.581851" armature="0.0106853" damping="0.00613252" frictionloss="0.204347"/>
          <geom name="//unnamed_geom_60" class="visual" material="metal" mesh="thigh_mirror_0"/>
          <geom name="//unnamed_geom_61" class="visual" material="gray" mesh="thigh_mirror_1"/>
          <geom name="//unnamed_geom_62" class="collision" size="0.108416 0.0124704 0.0173058" pos="0 0 -0.0913662" quat="0.707107 0 0.707107 0" type="box"/>
          <body name="RR_calf" pos="0.00113236 0.000951472 -0.181062" quat="0.999999 -0.000988781 0.000196834 -0.000811707">
            <inertial pos="0.00631914 0.000873261 -0.122375" quat="0.699367 -0.0138704 -0.000199337 0.714628" mass="0.258145" diaginertia="0.00208206 0.00265601 2.48483e-05"/>
            <joint name="RR_calf_joint" pos="0 0 0" axis="-0.00113734 -0.999999 0.00088259" range="0.79208 2.7476" armature="0.00943117" damping="0.0121497" frictionloss="0.206248"/>
            <geom name="//unnamed_geom_63" class="visual" material="gray" mesh="calf_mirror_0"/>
            <geom name="//unnamed_geom_64" class="visual" material="black" mesh="calf_mirror_1"/>
            <geom name="RR_calf0" class="collision" size="0.0132339 0.0610794" pos="0.0106548 0 -0.0514739" quat="0.995004 0 -0.0998334 0" type="cylinder"/>
            <geom name="//unnamed_geom_66" class="collision" size="0.0111979 0.0330847" pos="0.0213097 0 -0.126969" quat="0.999688 0 0.0249974 0" type="cylinder"/>
            <geom name="//unnamed_geom_67" class="visual" pos="0 0 -0.182732" quat="1 0 0 0" material="black" mesh="foot"/>
            <geom name="RR_foot" class="foot" size="0.0202309" pos="-0.00213097 0 -0.182732"/>
            <geom name="//unnamed_geom_69" class="reward_collision_sphere" size="0.0254498"/>
            <geom name="//unnamed_geom_70" class="reward_collision_sphere" size="0.0254498" pos="-0.00213097 0 -0.182732"/>
            <site name="RR_foot" class="foot" pos="-0.00213097 0 -0.182732" size="0.0101799"/>
          </body>
        </body>
      </body>
    </body>
  </worldbody>

  <contact>
    <pair class="/" geom1="floor" geom2="FL_foot" name="//unnamed_contact_0"/>
    <pair class="/" geom1="floor" geom2="FR_foot" name="//unnamed_contact_1"/>
    <pair class="/" geom1="floor" geom2="RL_foot" name="//unnamed_contact_2"/>
    <pair class="/" geom1="floor" geom2="RR_foot" name="//unnamed_contact_3"/>
  </contact>

  <actuator>
    <general name="FL_hip" class="/" joint="FL_hip_joint" forcerange="-24.114 24.114" gainprm="20.9472" biasprm="0 -20.9472 -0.535244"/>
    <general name="FL_thigh" class="/" joint="FL_thigh_joint" forcerange="-21.6344 21.6344" gainprm="20.9472" biasprm="0 -20.9472 -0.535244"/>
    <general name="FL_calf" class="/" joint="FL_calf_joint" forcerange="-43.3453 43.3453" gainprm="20.9472" biasprm="0 -20.9472 -0.535244"/>
    <general name="FR_hip" class="/" joint="FR_hip_joint" forcerange="-25.0028 25.0028" gainprm="20.9472" biasprm="0 -20.9472 -0.535244"/>
    <general name="FR_thigh" class="/" joint="FR_thigh_joint" forcerange="-24.9778 24.9778" gainprm="20.9472" biasprm="0 -20.9472 -0.535244"/>
    <general name="FR_calf" class="/" joint="FR_calf_joint" forcerange="-50.6501 50.6501" gainprm="20.9472" biasprm="0 -20.9472 -0.535244"/>
    <general name="RL_hip" class="/" joint="RL_hip_joint" forcerange="-23.3371 23.3371" gainprm="20.9472" biasprm="0 -20.9472 -0.535244"/>
    <general name="RL_thigh" class="/" joint="RL_thigh_joint" forcerange="-23.7979 23.7979" gainprm="20.9472" biasprm="0 -20.9472 -0.535244"/>
    <general name="RL_calf" class="/" joint="RL_calf_joint" forcerange="-41.2449 41.2449" gainprm="20.9472" biasprm="0 -20.9472 -0.535244"/>
    <general name="RR_hip" class="/" joint="RR_hip_joint" forcerange="-23.6799 23.6799" gainprm="20.9472" biasprm="0 -20.9472 -0.535244"/>
    <general name="RR_thigh" class="/" joint="RR_thigh_joint" forcerange="-24.615 24.615" gainprm="20.9472" biasprm="0 -20.9472 -0.535244"/>
    <general name="RR_calf" class="/" joint="RR_calf_joint" forcerange="-47.4385 47.4385" gainprm="20.9472" biasprm="0 -20.9472 -0.535244"/>
  </actuator>

  <sensor>
    <gyro site="imu" name="imu_angular_velocity"/>
    <velocimeter site="imu" name="imu_linear_velocity"/>
    <framelinvel objtype="site" objname="FL_foot" name="FL_foot_global_linear_velocity"/>
    <framelinvel objtype="site" objname="FR_foot" name="FR_foot_global_linear_velocity"/>
    <framelinvel objtype="site" objname="RL_foot" name="RL_foot_global_linear_velocity"/>
    <framelinvel objtype="site" objname="RR_foot" name="RR_foot_global_linear_velocity"/>
  </sensor>

  <keyframe>
    <key name="home" qpos="0 0 0.325 1 0 0 0 0.1 0.8 -1.5 -0.1 -0.8 1.5 -0.1 0.8 -1.5 0.1 -0.8 1.5"/>
  </keyframe>
</mujoco>
