<mujoco model="go2">
  <compiler angle="radian" assetdir="assets" balanceinertia="true" inertiafromgeom="false"/>

  <option timestep="0.005" density="1.2" viscosity="2e-05"/>

  <size nkey="1"/>

  <visual>
    <quality shadowsize="8192"/>
    <map shadowclip="0.5"/>
  </visual>

  <default>
    <default class="/">
      <geom contype="0" conaffinity="0" group="1" solref="-1000 -80"/>
      <site size="0.01 0.005 0.005" group="5"/>
      <general forcelimited="true" biastype="affine" gainprm="20" biasprm="0 -20 -0.5"/>
      <default class="go2">
        <joint armature="0.01" damping="0.01" frictionloss="0.2"/>
        <geom condim="1" margin="0.001"/>
        <default class="visual">
          <geom type="mesh" group="2"/>
        </default>
        <default class="collision">
          <geom group="3"/>
          <default class="foot">
            <geom size="0.022 0 0" condim="6" priority="1" friction="0.8 0.02 0.01" solimp="0.015 1 0.022"/>
          </default>
        </default>
        <default class="reward_collision_sphere">
          <geom group="5" rgba="1 0 0 1"/>
        </default>
      </default>
    </default>
  </default>

  <asset>
    <texture type="skybox" colorspace="auto" name="//unnamed_texture_0" builtin="gradient" rgb1="0.95 0.95 0.95" rgb2="0.95 0.95 0.95" width="100" height="600"/>
    <texture type="2d" colorspace="auto" name="texplane" builtin="checker" rgb1="0.345 0.575 0.748" rgb2="0.345 0.575 0.748" markrgb="1 1 1" width="512" height="512"/>
    <material name="MatPlane" class="/" texture="texplane" texuniform="true" texrepeat="2 2" specular="0.9"/>
    <material name="metal" class="/" rgba="0.9 0.95 0.95 1"/>
    <material name="black" class="/" rgba="0 0 0 1"/>
    <material name="white" class="/"/>
    <material name="gray" class="/" rgba="0.671705 0.692426 0.77427 1"/>
    <mesh name="base_0" class="/" file="base_0.obj"/>
    <mesh name="base_1" class="/" file="base_1.obj"/>
    <mesh name="base_2" class="/" file="base_2.obj"/>
    <mesh name="base_3" class="/" file="base_3.obj"/>
    <mesh name="base_4" class="/" file="base_4.obj"/>
    <mesh name="hip_0" class="/" file="hip_0.obj"/>
    <mesh name="hip_1" class="/" file="hip_1.obj"/>
    <mesh name="thigh_0" class="/" file="thigh_0.obj"/>
    <mesh name="thigh_1" class="/" file="thigh_1.obj"/>
    <mesh name="thigh_mirror_0" class="/" file="thigh_mirror_0.obj"/>
    <mesh name="thigh_mirror_1" class="/" file="thigh_mirror_1.obj"/>
    <mesh name="calf_0" class="/" file="calf_0.obj"/>
    <mesh name="calf_1" class="/" file="calf_1.obj"/>
    <mesh name="calf_mirror_0" class="/" file="calf_mirror_0.obj"/>
    <mesh name="calf_mirror_1" class="/" file="calf_mirror_1.obj"/>
    <mesh name="foot" class="/" file="foot.obj"/>
  </asset>

  <worldbody>
    <geom name="floor" class="/" size="100 100 0.125" type="plane" group="0" material="MatPlane"/>
    <light name="toplight_shadow" class="/" pos="0 0 5" dir="0.0990148 0.0990148 -0.990148" type="directional" ambient="0.04 0.04 0.04" diffuse="0.55 0.55 0.55" specular="0.12 0.12 0.12"/>
    <light name="toplight_fill" class="/" pos="0 0 5" dir="0.0990148 0.0990148 -0.990148" type="directional" castshadow="false" ambient="0.04 0.04 0.04" diffuse="0.3 0.3 0.3" specular="0.08 0.08 0.08"/>
    <body name="trunk" childclass="go2" pos="-0.0001964 -0.000405607 0.000351062" quat="1 -1.6346e-05 -2.2642e-05 -1.03423e-05">
      <inertial pos="0.0196309 -0.000800177 -0.00462885" quat="0.00272744 0.711064 -0.0113751 0.70303" mass="5.70968" diaginertia="0.0936232 0.0861595 0.0121927"/>
      <joint name="//unnamed_joint_0" type="free" armature="0" damping="0" frictionloss="0"/>
      <geom name="//unnamed_geom_1" class="visual" material="black" mesh="base_0"/>
      <geom name="//unnamed_geom_2" class="visual" material="black" mesh="base_1"/>
      <geom name="//unnamed_geom_3" class="visual" material="black" mesh="base_2"/>
      <geom name="//unnamed_geom_4" class="visual" material="white" mesh="base_3"/>
      <geom name="//unnamed_geom_5" class="visual" material="gray" mesh="base_4"/>
      <geom name="trunk_1" class="collision" size="0.176461 0.0438573 0.053473" type="box"/>
      <geom name="trunk_2" class="collision" size="0.0469062 0.0422156" pos="0.276992 0 0.00870393" type="cylinder"/>
      <geom name="trunk_3" class="collision" size="0.0440918" pos="0.284767 0 -0.0522236"/>
      <geom name="//unnamed_geom_9" class="reward_collision_sphere" size="0.0938124"/>
      <geom name="//unnamed_geom_10" class="reward_collision_sphere" size="0.0562874" pos="0.272133 0 -0.0391677"/>
      <site name="imu" pos="-0.0236192 -0.00370445 0.0348453" size="0.00938124"/>
      <camera name="track" pos="0 -1.94415 0" quat="0.707107 0.707107 0 0" mode="trackcom"/>
      <camera name="ego_camera" pos="0.303234 0 0.0391677" quat="-0.5 -0.5 0.5 0.5"/>
      <body name="FL_hip" pos="0.187076 0.0474271 0.00272959" quat="1 -0.000137619 0.000274644 -0.000135407">
        <inertial pos="-0.00560057 0.00196907 -0.000820933" quat="0.496225 0.497916 0.505853 0.499953" mass="0.559503" diaginertia="0.000765905 0.000517291 0.000241634"/>
        <joint name="FL_hip_joint" pos="0 0 0" axis="0.999987 0.00502836 0.000300466" stiffness="0.0106471" range="-1.00621 1.03149" armature="0.00943279" damping="0.00109977" frictionloss="0.185431"/>
        <geom name="//unnamed_geom_11" class="visual" material="metal" mesh="hip_0"/>
        <geom name="//unnamed_geom_12" class="visual" material="gray" mesh="hip_1"/>
        <geom name="//unnamed_geom_13" class="collision" size="0.0431537 0.0187625" pos="0 0.077766 0" quat="0.707107 0.707107 0 0" type="cylinder"/>
        <geom name="//unnamed_geom_14" class="reward_collision_sphere" size="0.0562874" pos="0 0.0680453 0"/>
        <body name="FL_thigh" pos="-0.00110585 0.0946136 0.00221365" quat="1 -1.44483e-05 -2.26376e-05 -7.98363e-06">
          <inertial pos="-0.00395893 -0.0220705 -0.0279204" quat="0.827558 0.0860121 -0.0163114 0.554512" mass="0.951743" diaginertia="0.00517562 0.00505628 0.000441371"/>
          <joint name="FL_thigh_joint" pos="0 0 0" axis="0.00843405 0.999964 -0.00121452" stiffness="0.00526272" range="-1.58781 3.52425" armature="0.00970517" damping="0.00982874" frictionloss="0.179121"/>
          <geom name="//unnamed_geom_15" class="visual" material="metal" mesh="thigh_0"/>
          <geom name="//unnamed_geom_16" class="visual" material="gray" mesh="thigh_1"/>
          <geom name="//unnamed_geom_17" class="collision" size="0.0999102 0.011492 0.0159481" pos="0 0 -0.0926968" quat="0.707107 0 0.707107 0" type="box"/>
          <body name="FL_calf" pos="-0.000298907 -0.00233941 -0.184597" quat="1 -0.000204596 0.000362022 6.36348e-06">
            <inertial pos="0.00590465 -0.000416296 -0.12463" quat="0.710752 0.00207976 -0.00383364 0.703429" mass="0.198475" diaginertia="0.00129084 0.00130057 2.60243e-05"/>
            <joint name="FL_calf_joint" pos="0 0 0" axis="-0.00735182 0.999967 -0.00341942" stiffness="0.00236435" range="-2.76171 -0.834517" armature="0.00965607" damping="0.000834128" frictionloss="0.188958"/>
            <geom name="//unnamed_geom_18" class="visual" material="gray" mesh="calf_0"/>
            <geom name="//unnamed_geom_19" class="visual" material="black" mesh="calf_1"/>
            <geom name="FL_calf0" class="collision" size="0.0112575 0.0562874" pos="0.00777522 0 -0.0522236" quat="0.994493 0 -0.104807 0" type="cylinder"/>
            <geom name="//unnamed_geom_21" class="collision" size="0.0103194 0.030489" pos="0.019438 0 -0.128818" quat="0.999688 0 0.0249974 0" type="cylinder"/>
            <geom name="//unnamed_geom_22" class="visual" pos="0 0 -0.185394" quat="1 0 0 0" material="black" mesh="foot"/>
            <geom name="FL_foot" class="foot" size="0.0181262" pos="-0.0019438 0 -0.185394"/>
            <geom name="//unnamed_geom_24" class="reward_collision_sphere" size="0.0234531"/>
            <geom name="//unnamed_geom_25" class="reward_collision_sphere" size="0.0234531" pos="-0.0019438 0 -0.185394"/>
            <site name="FL_foot" class="foot" pos="-0.0019438 0 -0.185394" size="0.00938124"/>
          </body>
        </body>
      </body>
      <body name="FR_hip" pos="0.18838 -0.0444104 -0.000923175" quat="1 -5.55527e-05 -8.18623e-05 -2.38948e-05">
        <inertial pos="-0.00447965 -0.00126608 -0.00100028" quat="0.498163 0.505458 0.499215 0.497122" mass="0.55398" diaginertia="0.000775384 0.000505351 0.000242351"/>
        <joint name="FR_hip_joint" pos="0 0 0" axis="0.999996 -0.00291104 6.54755e-05" stiffness="0.00705743" range="-1.05055 1.0478" armature="0.00907952" damping="0.0177665" frictionloss="0.179693"/>
        <geom name="//unnamed_geom_26" class="visual" pos="0 8.85813e-10 3.79943e-08" quat="4.63268e-05 1 0 0" material="metal" mesh="hip_0"/>
        <geom name="//unnamed_geom_27" class="visual" pos="0 1.43601e-09 -9.39745e-08" quat="4.63268e-05 1 0 0" material="gray" mesh="hip_1"/>
        <geom name="//unnamed_geom_28" class="collision" size="0.0431537 0.0187625" pos="0 -0.077766 0" quat="0.707107 0.707107 0 0" type="cylinder"/>
        <geom name="//unnamed_geom_29" class="reward_collision_sphere" size="0.0562874" pos="0 -0.0680453 0"/>
        <body name="FR_thigh" pos="0.00232686 -0.0909788 0.00193281" quat="1 -1.74991e-05 0.00029456 0.000403179">
          <inertial pos="-0.0028307 0.0198386 -0.0283684" quat="0.550749 -0.0216292 0.0871386 0.829828" mass="0.960403" diaginertia="0.00522681 0.00511615 0.000448608"/>
          <joint name="FR_thigh_joint" pos="0 0 0" axis="0.000595142 -0.999998 0.00196934" stiffness="0.00167503" range="-3.52542 1.56853" armature="0.00959337" damping="0.0124992" frictionloss="0.187364"/>
          <geom name="//unnamed_geom_30" class="visual" material="metal" mesh="thigh_mirror_0"/>
          <geom name="//unnamed_geom_31" class="visual" material="gray" mesh="thigh_mirror_1"/>
          <geom name="//unnamed_geom_32" class="collision" size="0.0999102 0.011492 0.0159481" pos="0 0 -0.0926968" quat="0.707107 0 0.707107 0" type="box"/>
          <body name="FR_calf" pos="-0.00154094 0.000268895 -0.1849" quat="1 -0.000242469 0.000425385 0.000211834">
            <inertial pos="0.00504411 0.000647512 -0.123645" quat="0.704849 -0.00635422 0.00104542 0.709328" mass="0.200024" diaginertia="0.00129199 0.00126889 2.63138e-05"/>
            <joint name="FR_calf_joint" pos="0 0 0" axis="-0.00440876 -0.999949 0.00913622" stiffness="0.00273303" range="0.845313 2.71699" armature="0.0100907" damping="0.0181554" frictionloss="0.178672"/>
            <geom name="//unnamed_geom_33" class="visual" material="gray" mesh="calf_mirror_0"/>
            <geom name="//unnamed_geom_34" class="visual" material="black" mesh="calf_mirror_1"/>
            <geom name="FR_calf0" class="collision" size="0.0121956 0.0562874" pos="0.00971902 0 -0.0522236" quat="0.995004 0 -0.0998334 0" type="cylinder"/>
            <geom name="//unnamed_geom_36" class="collision" size="0.0103194 0.030489" pos="0.019438 0 -0.128818" quat="0.999688 0 0.0249974 0" type="cylinder"/>
            <geom name="//unnamed_geom_37" class="visual" pos="0 0 -0.185394" quat="1 0 0 0" material="black" mesh="foot"/>
            <geom name="FR_foot" class="foot" size="0.0219007" pos="-0.0019438 0 -0.185394"/>
            <geom name="//unnamed_geom_39" class="reward_collision_sphere" size="0.0234531"/>
            <geom name="//unnamed_geom_40" class="reward_collision_sphere" size="0.0234531" pos="-0.0019438 0 -0.185394"/>
            <site name="FR_foot" class="foot" pos="-0.0019438 0 -0.185394" size="0.00938124"/>
          </body>
        </body>
      </body>
      <body name="RL_hip" pos="-0.188009 0.0449714 -0.000510762" quat="1 -7.51068e-06 -7.18437e-06 3.73163e-05">
        <inertial pos="0.00529483 0.00158413 -0.000556649" quat="0.50737 0.49651 0.49714 0.498904" mass="0.549087" diaginertia="0.00075661 0.000511145 0.000236137"/>
        <joint name="RL_hip_joint" pos="0 0 0" axis="-0.999924 -0.0107856 -0.00604304" stiffness="0.00480118" range="-1.04985 1.06692" armature="0.0092934" damping="0.0102661" frictionloss="0.189651"/>
        <geom name="//unnamed_geom_41" class="visual" pos="-8.84309e-10 0 -1.73345e-07" quat="4.63268e-05 0 1 0" material="metal" mesh="hip_0"/>
        <geom name="//unnamed_geom_42" class="visual" pos="-1.43357e-09 0 -1.53732e-07" quat="4.63268e-05 0 1 0" material="gray" mesh="hip_1"/>
        <geom name="//unnamed_geom_43" class="collision" size="0.0431537 0.0187625" pos="0 0.077766 0" quat="0.707107 0.707107 0 0" type="cylinder"/>
        <geom name="//unnamed_geom_44" class="reward_collision_sphere" size="0.0562874" pos="0 0.0680453 0"/>
        <body name="RL_thigh" pos="0.000336448 0.092238 -0.00154136" quat="1 -6.57758e-05 5.07663e-05 -4.81174e-05">
          <inertial pos="-0.00367495 -0.022005 -0.030095" quat="0.827669 0.0854849 -0.0210204 0.554269" mass="0.964729" diaginertia="0.00512115 0.00495005 0.000432059"/>
          <joint name="RL_thigh_joint" pos="0 0 0" axis="-0.00383335 0.999972 0.00643259" range="-0.529882 4.52572" armature="0.00977677" damping="0.00421985" frictionloss="0.184363"/>
          <geom name="//unnamed_geom_45" class="visual" material="metal" mesh="thigh_0"/>
          <geom name="//unnamed_geom_46" class="visual" material="gray" mesh="thigh_1"/>
          <geom name="//unnamed_geom_47" class="collision" size="0.0999102 0.011492 0.0159481" pos="0 0 -0.0926968" quat="0.707107 0 0.707107 0" type="box"/>
          <body name="RL_calf" pos="0.000272829 -0.00266927 -0.186192" quat="1 1.15827e-05 -0.000132069 -6.12053e-05">
            <inertial pos="0.00583764 -0.000314925 -0.123512" quat="0.710329 0.00159111 -0.00477759 0.703851" mass="0.196417" diaginertia="0.00129999 0.00126228 2.63118e-05"/>
            <joint name="RL_calf_joint" pos="0 0 0" axis="0.00124994 0.999996 0.00241348" range="-2.68346 -0.842542" armature="0.00921737" damping="0.0055515" frictionloss="0.188923"/>
            <geom name="//unnamed_geom_48" class="visual" material="gray" mesh="calf_0"/>
            <geom name="//unnamed_geom_49" class="visual" material="black" mesh="calf_1"/>
            <geom name="RL_calf0" class="collision" size="0.0121956 0.0562874" pos="0.00971902 0 -0.0522236" quat="0.995004 0 -0.0998334 0" type="cylinder"/>
            <geom name="//unnamed_geom_51" class="collision" size="0.0103194 0.030489" pos="0.019438 0 -0.128818" quat="0.999688 0 0.0249974 0" type="cylinder"/>
            <geom name="//unnamed_geom_52" class="visual" pos="0 0 -0.185394" quat="1 0 0 0" material="black" mesh="foot"/>
            <geom name="RL_foot" class="foot" size="0.0170785" pos="-0.0019438 0 -0.185394"/>
            <geom name="//unnamed_geom_54" class="reward_collision_sphere" size="0.0234531"/>
            <geom name="//unnamed_geom_55" class="reward_collision_sphere" size="0.0234531" pos="-0.0019438 0 -0.185394"/>
            <site name="RL_foot" class="foot" pos="-0.0019438 0 -0.185394" size="0.00938124"/>
          </body>
        </body>
      </body>
      <body name="RR_hip" pos="-0.187576 -0.0464137 -0.000959073" quat="1 0.000150923 -0.000363062 0.000212044">
        <inertial pos="0.00515192 -0.000954606 0.000433354" quat="0.49981 0.497296 0.497631 0.505223" mass="0.553201" diaginertia="0.000762245 0.000506777 0.00024205"/>
        <joint name="RR_hip_joint" pos="0 0 0" axis="-0.999975 0.0070743 0.000116668" range="-1.05775 1.02009" armature="0.00938751" damping="0.00613846" frictionloss="0.19203"/>
        <geom name="//unnamed_geom_56" class="visual" pos="8.84315e-10 8.85813e-10 -2.11339e-07" quat="2.14617e-09 4.63268e-05 4.63268e-05 -1" material="metal" mesh="hip_0"/>
        <geom name="//unnamed_geom_57" class="visual" pos="1.43356e-09 1.43601e-09 -5.97577e-08" quat="2.14617e-09 4.63268e-05 4.63268e-05 -1" material="gray" mesh="hip_1"/>
        <geom name="//unnamed_geom_58" class="collision" size="0.0431537 0.0187625" pos="0 -0.077766 0" quat="0.707107 0.707107 0 0" type="cylinder"/>
        <geom name="//unnamed_geom_59" class="reward_collision_sphere" size="0.0562874" pos="0 -0.0680453 0"/>
        <body name="RR_thigh" pos="0.000399734 -0.0927903 -0.000894144" quat="1 -0.000260694 -0.000117455 -0.000418782">
          <inertial pos="-0.00359087 0.0203972 -0.0290607" quat="0.551514 -0.0198592 0.0848657 0.8296" mass="0.956336" diaginertia="0.00521916 0.00508866 0.00044218"/>
          <joint name="RR_thigh_joint" pos="0 0 0" axis="-0.00284286 -0.999976 -0.00634316" stiffness="0.00240283" range="-4.52863 0.509944" armature="0.00941988" damping="0.0147555" frictionloss="0.190886"/>
          <geom name="//unnamed_geom_60" class="visual" material="metal" mesh="thigh_mirror_0"/>
          <geom name="//unnamed_geom_61" class="visual" material="gray" mesh="thigh_mirror_1"/>
          <geom name="//unnamed_geom_62" class="collision" size="0.0999102 0.011492 0.0159481" pos="0 0 -0.0926968" quat="0.707107 0 0.707107 0" type="box"/>
          <body name="RR_calf" pos="-0.0017599 -0.000721213 -0.186642" quat="1 -8.9885e-05 -0.000463571 -0.000179319">
            <inertial pos="0.00805037 0.000729087 -0.123238" quat="0.702894 -0.00136985 0.004925 0.711276" mass="0.199036" diaginertia="0.00131434 0.00127816 2.65853e-05"/>
            <joint name="RR_calf_joint" pos="0 0 0" axis="0.00197883 -0.999969 0.00762262" range="0.827117 2.75734" armature="0.00876196" damping="0.00639137" frictionloss="0.188445"/>
            <geom name="//unnamed_geom_63" class="visual" material="gray" mesh="calf_mirror_0"/>
            <geom name="//unnamed_geom_64" class="visual" material="black" mesh="calf_mirror_1"/>
            <geom name="RR_calf0" class="collision" size="0.0121956 0.0562874" pos="0.00971902 0 -0.0522236" quat="0.995004 0 -0.0998334 0" type="cylinder"/>
            <geom name="//unnamed_geom_66" class="collision" size="0.0103194 0.030489" pos="0.019438 0 -0.128818" quat="0.999688 0 0.0249974 0" type="cylinder"/>
            <geom name="//unnamed_geom_67" class="visual" pos="0 0 -0.185394" quat="1 0 0 0" material="black" mesh="foot"/>
            <geom name="RR_foot" class="foot" size="0.0206348" pos="-0.0019438 0 -0.185394"/>
            <geom name="//unnamed_geom_69" class="reward_collision_sphere" size="0.0234531"/>
            <geom name="//unnamed_geom_70" class="reward_collision_sphere" size="0.0234531" pos="-0.0019438 0 -0.185394"/>
            <site name="RR_foot" class="foot" pos="-0.0019438 0 -0.185394" size="0.00938124"/>
          </body>
        </body>
      </body>
    </body>
  </worldbody>

  <contact>
    <pair class="/" geom1="floor" geom2="FL_foot" name="//unnamed_contact_0"/>
    <pair class="/" geom1="floor" geom2="FR_foot" name="//unnamed_contact_1"/>
    <pair class="/" geom1="floor" geom2="RL_foot" name="//unnamed_contact_2"/>
    <pair class="/" geom1="floor" geom2="RR_foot" name="//unnamed_contact_3"/>
  </contact>

  <actuator>
    <general name="FL_hip" class="/" joint="FL_hip_joint" forcerange="-23.923 23.923" gainprm="19.6168" biasprm="0 -19.6168 -0.461122"/>
    <general name="FL_thigh" class="/" joint="FL_thigh_joint" forcerange="-22.6255 22.6255" gainprm="19.6168" biasprm="0 -19.6168 -0.461122"/>
    <general name="FL_calf" class="/" joint="FL_calf_joint" forcerange="-43.25 43.25" gainprm="19.6168" biasprm="0 -19.6168 -0.461122"/>
    <general name="FR_hip" class="/" joint="FR_hip_joint" forcerange="-23.5263 23.5263" gainprm="19.6168" biasprm="0 -19.6168 -0.461122"/>
    <general name="FR_thigh" class="/" joint="FR_thigh_joint" forcerange="-23.5485 23.5485" gainprm="19.6168" biasprm="0 -19.6168 -0.461122"/>
    <general name="FR_calf" class="/" joint="FR_calf_joint" forcerange="-42.1606 42.1606" gainprm="19.6168" biasprm="0 -19.6168 -0.461122"/>
    <general name="RL_hip" class="/" joint="RL_hip_joint" forcerange="-22.3348 22.3348" gainprm="19.6168" biasprm="0 -19.6168 -0.461122"/>
    <general name="RL_thigh" class="/" joint="RL_thigh_joint" forcerange="-22.6965 22.6965" gainprm="19.6168" biasprm="0 -19.6168 -0.461122"/>
    <general name="RL_calf" class="/" joint="RL_calf_joint" forcerange="-43.8304 43.8304" gainprm="19.6168" biasprm="0 -19.6168 -0.461122"/>
    <general name="RR_hip" class="/" joint="RR_hip_joint" forcerange="-20.687 20.687" gainprm="19.6168" biasprm="0 -19.6168 -0.461122"/>
    <general name="RR_thigh" class="/" joint="RR_thigh_joint" forcerange="-21.7895 21.7895" gainprm="19.6168" biasprm="0 -19.6168 -0.461122"/>
    <general name="RR_calf" class="/" joint="RR_calf_joint" forcerange="-43.0542 43.0542" gainprm="19.6168" biasprm="0 -19.6168 -0.461122"/>
  </actuator>

  <sensor>
    <gyro site="imu" name="imu_angular_velocity"/>
    <velocimeter site="imu" name="imu_linear_velocity"/>
    <framelinvel objtype="site" objname="FL_foot" name="FL_foot_global_linear_velocity"/>
    <framelinvel objtype="site" objname="FR_foot" name="FR_foot_global_linear_velocity"/>
    <framelinvel objtype="site" objname="RL_foot" name="RL_foot_global_linear_velocity"/>
    <framelinvel objtype="site" objname="RR_foot" name="RR_foot_global_linear_velocity"/>
  </sensor>

  <keyframe>
    <key name="home" qpos="0 0 0.325 1 0 0 0 0.1 0.8 -1.5 -0.1 -0.8 1.5 -0.1 0.8 -1.5 0.1 -0.8 1.5"/>
  </keyframe>
</mujoco>
