<mujoco model="go2">
  <compiler angle="radian" assetdir="assets" balanceinertia="true" inertiafromgeom="false"/>

  <option timestep="0.005" density="1.2" viscosity="2e-05"/>

  <size nkey="1"/>

  <visual>
    <quality shadowsize="8192"/>
    <map shadowclip="0.5"/>
  </visual>

  <default>
    <default class="/">
      <geom contype="0" conaffinity="0" group="1" solref="-1000 -80"/>
      <site size="0.01 0.005 0.005" group="5"/>
      <general forcelimited="true" biastype="affine" gainprm="20" biasprm="0 -20 -0.5"/>
      <default class="go2">
        <joint armature="0.01" damping="0.01" frictionloss="0.2"/>
        <geom condim="1" margin="0.001"/>
        <default class="visual">
          <geom type="mesh" group="2"/>
        </default>
        <default class="collision">
          <geom group="3"/>
          <default class="foot">
            <geom size="0.022 0 0" condim="6" priority="1" friction="0.8 0.02 0.01" solimp="0.015 1 0.022"/>
          </default>
        </default>
        <default class="reward_collision_sphere">
          <geom group="5" rgba="1 0 0 1"/>
        </default>
      </default>
    </default>
  </default>

  <asset>
    <texture type="skybox" colorspace="auto" name="//unnamed_texture_0" builtin="gradient" rgb1="0.95 0.95 0.95" rgb2="0.95 0.95 0.95" width="100" height="600"/>
    <texture type="2d" colorspace="auto" name="texplane" builtin="checker" rgb1="0.345 0.575 0.748" rgb2="0.345 0.575 0.748" markrgb="1 1 1" width="512" height="512"/>
    <material name="MatPlane" class="/" texture="texplane" texuniform="true" texrepeat="2 2" specular="0.9"/>
    <material name="metal" class="/" rgba="0.9 0.95 0.95 1"/>
    <material name="black" class="/" rgba="0 0 0 1"/>
    <material name="white" class="/"/>
    <material name="gray" class="/" rgba="0.671705 0.692426 0.77427 1"/>
    <mesh name="base_0" class="/" file="base_0.obj"/>
    <mesh name="base_1" class="/" file="base_1.obj"/>
    <mesh name="base_2" class="/" file="base_2.obj"/>
    <mesh name="base_3" class="/" file="base_3.obj"/>
    <mesh name="base_4" class="/" file="base_4.obj"/>
    <mesh name="hip_0" class="/" file="hip_0.obj"/>
    <mesh name="hip_1" class="/" file="hip_1.obj"/>
    <mesh name="thigh_0" class="/" file="thigh_0.obj"/>
    <mesh name="thigh_1" class="/" file="thigh_1.obj"/>
    <mesh name="thigh_mirror_0" class="/" file="thigh_mirror_0.obj"/>
    <mesh name="thigh_mirror_1" class="/" file="thigh_mirror_1.obj"/>
    <mesh name="calf_0" class="/" file="calf_0.obj"/>
    <mesh name="calf_1" class="/" file="calf_1.obj"/>
    <mesh name="calf_mirror_0" class="/" file="calf_mirror_0.obj"/>
    <mesh name="calf_mirror_1" class="/" file="calf_mirror_1.obj"/>
    <mesh name="foot" class="/" file="foot.obj"/>
  </asset>

  <worldbody>
    <geom name="floor" class="/" size="100 100 0.125" type="plane" group="0" material="MatPlane"/>
    <light name="toplight_shadow" class="/" pos="0 0 5" dir="0.0990148 0.0990148 -0.990148" type="directional" ambient="0.04 0.04 0.04" diffuse="0.55 0.55 0.55" specular="0.12 0.12 0.12"/>
    <light name="toplight_fill" class="/" pos="0 0 5" dir="0.0990148 0.0990148 -0.990148" type="directional" castshadow="false" ambient="0.04 0.04 0.04" diffuse="0.3 0.3 0.3" specular="0.08 0.08 0.08"/>
    <body name="trunk" childclass="go2" pos="-0.000362227 -8.23635e-05 0.00617239" quat="1 -0.000227416 0.000854364 3.59658e-05">
      <inertial pos="0.0286703 -0.00997687 -0.0118435" quat="-0.000389384 0.713084 -0.000887189 0.701078" mass="7.52042" diaginertia="0.342155 0.0578692 0.0126168"/>
      <joint name="//unnamed_joint_0" type="free" armature="0" damping="0" frictionloss="0"/>
      <geom name="//unnamed_geom_1" class="visual" material="black" mesh="base_0"/>
      <geom name="//unnamed_geom_2" class="visual" material="black" mesh="base_1"/>
      <geom name="//unnamed_geom_3" class="visual" material="black" mesh="base_2"/>
      <geom name="//unnamed_geom_4" class="visual" material="white" mesh="base_3"/>
      <geom name="//unnamed_geom_5" class="visual" material="gray" mesh="base_4"/>
      <geom name="trunk_1" class="collision" size="0.190698 0.0473957 0.0577873" type="box"/>
      <geom name="trunk_2" class="collision" size="0.0506906 0.0456215" pos="0.364733 0 0.00872603" type="cylinder"/>
      <geom name="trunk_3" class="collision" size="0.0476491" pos="0.374971 0 -0.0523562"/>
      <geom name="//unnamed_geom_9" class="reward_collision_sphere" size="0.101381"/>
      <geom name="//unnamed_geom_10" class="reward_collision_sphere" size="0.0608287" pos="0.358334 0 -0.0392671"/>
      <site name="imu" pos="-0.0416937 0.0210193 0.0262174" size="0.0101381"/>
      <camera name="track" pos="0 -1.77813 0" quat="0.707107 0.707107 0 0" mode="trackcom"/>
      <camera name="ego_camera" pos="0.399287 0 0.0392671" quat="-0.5 -0.5 0.5 0.5"/>
      <body name="FL_hip" pos="0.245063 0.0465464 0.00251325" quat="1 -2.92518e-05 2.75249e-06 -0.000370286">
        <inertial pos="0.00145137 -3.39703e-05 0.00378982" quat="0.496511 0.499734 0.508136 0.495521" mass="0.722917" diaginertia="0.00306004 0.000352436 0.000232502"/>
        <joint name="FL_hip_joint" pos="0 0 0" axis="1 0.000428237 0.000506853" range="-0.9904 1.04875" armature="0.00741652" damping="0" frictionloss="0.282456"/>
        <geom name="//unnamed_geom_11" class="visual" material="metal" mesh="hip_0"/>
        <geom name="//unnamed_geom_12" class="visual" material="gray" mesh="hip_1"/>
        <geom name="//unnamed_geom_13" class="collision" size="0.0466353 0.0202762" pos="0 0.0711253 0" quat="0.707107 0.707107 0 0" type="cylinder"/>
        <geom name="//unnamed_geom_14" class="reward_collision_sphere" size="0.0608287" pos="0 0.0622347 0"/>
        <body name="FL_thigh" pos="-0.00339932 0.0851733 -0.00268406" quat="1 6.00333e-05 8.51745e-06 -0.000116092">
          <inertial pos="-0.00653751 -0.0207539 -0.0244521" quat="0.827448 0.0786866 -0.0246661 0.555455" mass="1.32249" diaginertia="0.0199284 0.00328 0.000559042"/>
          <joint name="FL_thigh_joint" pos="0 0 0" axis="-0.00475187 0.999879 -0.0148381" stiffness="0.00795016" range="-1.463 3.4341" armature="0.00948555" damping="0.0197272" frictionloss="0.216149"/>
          <geom name="//unnamed_geom_15" class="visual" material="metal" mesh="thigh_0"/>
          <geom name="//unnamed_geom_16" class="visual" material="gray" mesh="thigh_1"/>
          <geom name="//unnamed_geom_17" class="collision" size="0.107971 0.0124192 0.0172348" pos="0 0 -0.0929322" quat="0.707107 0 0.707107 0" type="box"/>
          <body name="FL_calf" pos="0.00273499 -0.00597006 -0.192661" quat="0.999989 -0.000402466 -0.0044635 0.0014975">
            <inertial pos="0.00646972 -0.000813722 -0.123928" quat="0.710081 0.00228417 -0.00584986 0.704092" mass="0.279153" diaginertia="0.00506176 0.000844273 2.96902e-05"/>
            <joint name="FL_calf_joint" pos="0 0 0" axis="-0.00292477 0.999984 -0.00476541" stiffness="0.00776246" range="-2.70415 -0.844495" armature="0.0118183" damping="0" frictionloss="0.265642"/>
            <geom name="//unnamed_geom_18" class="visual" material="gray" mesh="calf_0"/>
            <geom name="//unnamed_geom_19" class="visual" material="black" mesh="calf_1"/>
            <geom name="FL_calf0" class="collision" size="0.0121657 0.0608287" pos="0.0102381 0 -0.0523562" quat="0.994493 0 -0.104807 0" type="cylinder"/>
            <geom name="//unnamed_geom_21" class="collision" size="0.0111519 0.0329489" pos="0.0255953 0 -0.129145" quat="0.999688 0 0.0249974 0" type="cylinder"/>
            <geom name="//unnamed_geom_22" class="visual" pos="0 0 -0.185864" quat="1 0 0 0" material="black" mesh="foot"/>
            <geom name="FL_foot" class="foot" size="0.0154441" pos="-0.00255953 0 -0.185864"/>
            <geom name="//unnamed_geom_24" class="reward_collision_sphere" size="0.0253453"/>
            <geom name="//unnamed_geom_25" class="reward_collision_sphere" size="0.0253453" pos="-0.00255953 0 -0.185864"/>
            <site name="FL_foot" class="foot" pos="-0.00255953 0 -0.185864" size="0.0101381"/>
          </body>
        </body>
      </body>
      <body name="FR_hip" pos="0.245998 -0.0368887 -0.000952905" quat="0.999993 -0.000759439 0.0011838 -0.00350394">
        <inertial pos="-0.0065077 -0.00107945 -0.000772608" quat="0.494534 0.503322 0.502958 0.499136" mass="0.772564" diaginertia="0.00330471 0.00038431 0.000239415"/>
        <joint name="FR_hip_joint" pos="0 0 0" axis="0.999897 -0.00695776 0.012592" range="-1.18858 1.23427" armature="0.00924117" damping="0.00388791" frictionloss="0.256123"/>
        <geom name="//unnamed_geom_26" class="visual" pos="0 1.43425e-10 6.15179e-09" quat="4.63268e-05 1 0 0" material="metal" mesh="hip_0"/>
        <geom name="//unnamed_geom_27" class="visual" pos="0 2.32509e-10 -1.52157e-08" quat="4.63268e-05 1 0 0" material="gray" mesh="hip_1"/>
        <geom name="//unnamed_geom_28" class="collision" size="0.0466353 0.0202762" pos="0 -0.0711253 0" quat="0.707107 0.707107 0 0" type="cylinder"/>
        <geom name="//unnamed_geom_29" class="reward_collision_sphere" size="0.0608287" pos="0 -0.0622347 0"/>
        <body name="FR_thigh" pos="-0.0107132 -0.0895032 -0.00151771" quat="1 5.29482e-05 0.000440554 0.000367916">
          <inertial pos="-0.00218631 0.0189308 -0.028884" quat="0.554352 -0.0158264 0.0846496 0.827815" mass="1.08082" diaginertia="0.0196665 0.00289527 0.000383837"/>
          <joint name="FR_thigh_joint" pos="0 0 0" axis="-0.0305319 -0.998782 0.0387495" range="-3.71597 1.75861" armature="0.0109839" damping="0.0403238" frictionloss="0.20612"/>
          <geom name="//unnamed_geom_30" class="visual" material="metal" mesh="thigh_mirror_0"/>
          <geom name="//unnamed_geom_31" class="visual" material="gray" mesh="thigh_mirror_1"/>
          <geom name="//unnamed_geom_32" class="collision" size="0.107971 0.0124192 0.0172348" pos="0 0 -0.0929322" quat="0.707107 0 0.707107 0" type="box"/>
          <body name="FR_calf" pos="-0.00966913 -0.000213845 -0.18977" quat="1 -3.45206e-05 4.10925e-05 -8.91e-05">
            <inertial pos="0.0103717 0.00087449 -0.133974" quat="0.701126 -0.00880174 0.000922441 0.712982" mass="0.291568" diaginertia="0.00487455 0.000804799 2.66165e-05"/>
            <joint name="FR_calf_joint" pos="0 0 0" axis="0.0382774 -0.998329 -0.0432925" stiffness="0.0111955" range="0.818165 2.87908" armature="0.0104066" damping="0.0104257" frictionloss="0.317177"/>
            <geom name="//unnamed_geom_33" class="visual" material="gray" mesh="calf_mirror_0"/>
            <geom name="//unnamed_geom_34" class="visual" material="black" mesh="calf_mirror_1"/>
            <geom name="FR_calf0" class="collision" size="0.0131796 0.0608287" pos="0.0127977 0 -0.0523562" quat="0.995004 0 -0.0998334 0" type="cylinder"/>
            <geom name="//unnamed_geom_36" class="collision" size="0.0111519 0.0329489" pos="0.0255953 0 -0.129145" quat="0.999688 0 0.0249974 0" type="cylinder"/>
            <geom name="//unnamed_geom_37" class="visual" pos="0 0 -0.185864" quat="1 0 0 0" material="black" mesh="foot"/>
            <geom name="FR_foot" class="foot" size="0.0220718" pos="-0.00255953 0 -0.185864"/>
            <geom name="//unnamed_geom_39" class="reward_collision_sphere" size="0.0253453"/>
            <geom name="//unnamed_geom_40" class="reward_collision_sphere" size="0.0253453" pos="-0.00255953 0 -0.185864"/>
            <site name="FR_foot" class="foot" pos="-0.00255953 0 -0.185864" size="0.0101381"/>
          </body>
        </body>
      </body>
      <body name="RL_hip" pos="-0.247474 0.0347898 0.000281779" quat="1 -0.000281239 0.000711281 0.000217892">
        <inertial pos="0.0104786 0.00978674 0.000469644" quat="0.456619 0.526356 0.515922 0.498269" mass="0.809319" diaginertia="0.00297186 0.000308735 0.000252065"/>
        <joint name="RL_hip_joint" pos="0 0 0" axis="-0.999532 -0.00390456 -0.0303378" stiffness="0.0346766" range="-1.05345 1.11871" armature="0.0102357" damping="0.0338859" frictionloss="0.164083"/>
        <geom name="//unnamed_geom_41" class="visual" pos="-3.54703e-09 0 -6.953e-07" quat="4.63268e-05 0 1 0" material="metal" mesh="hip_0"/>
        <geom name="//unnamed_geom_42" class="visual" pos="-5.75016e-09 0 -6.16632e-07" quat="4.63268e-05 0 1 0" material="gray" mesh="hip_1"/>
        <geom name="//unnamed_geom_43" class="collision" size="0.0466353 0.0202762" pos="0 0.0711253 0" quat="0.707107 0.707107 0 0" type="cylinder"/>
        <geom name="//unnamed_geom_44" class="reward_collision_sphere" size="0.0608287" pos="0 0.0622347 0"/>
        <body name="RL_thigh" pos="0.000887659 0.0929916 -0.00137995" quat="0.999998 -0.00139389 -4.02947e-05 -0.00142081">
          <inertial pos="-0.00301335 -0.0137791 -0.0285463" quat="0.827777 0.0956762 -0.0234807 0.55234" mass="1.15625" diaginertia="0.0179065 0.00301048 0.000374356"/>
          <joint name="RL_thigh_joint" pos="0 0 0" axis="0.00288022 0.999995 0.00140941" range="-0.51347 4.54597" armature="0.0106923" damping="0.0157038" frictionloss="0.201169"/>
          <geom name="//unnamed_geom_45" class="visual" material="metal" mesh="thigh_0"/>
          <geom name="//unnamed_geom_46" class="visual" material="gray" mesh="thigh_1"/>
          <geom name="//unnamed_geom_47" class="collision" size="0.107971 0.0124192 0.0172348" pos="0 0 -0.0929322" quat="0.707107 0 0.707107 0" type="box"/>
          <body name="RL_calf" pos="-0.00681257 0.00121403 -0.186694" quat="0.999993 0.000198717 0.00350923 0.0015458">
            <inertial pos="0.00102514 0.0011369 -0.117634" quat="0.709969 0.0026028 -0.00494979 0.704211" mass="0.237295" diaginertia="0.0044291 0.000612716 1.95005e-05"/>
            <joint name="RL_calf_joint" pos="0 0 0" axis="0.025573 0.999669 0.00263409" stiffness="0.00846829" range="-2.71964 -0.598791" armature="0.0101197" damping="0" frictionloss="0.167597"/>
            <geom name="//unnamed_geom_48" class="visual" material="gray" mesh="calf_0"/>
            <geom name="//unnamed_geom_49" class="visual" material="black" mesh="calf_1"/>
            <geom name="RL_calf0" class="collision" size="0.0131796 0.0608287" pos="0.0127977 0 -0.0523562" quat="0.995004 0 -0.0998334 0" type="cylinder"/>
            <geom name="//unnamed_geom_51" class="collision" size="0.0111519 0.0329489" pos="0.0255953 0 -0.129145" quat="0.999688 0 0.0249974 0" type="cylinder"/>
            <geom name="//unnamed_geom_52" class="visual" pos="0 0 -0.185864" quat="1 0 0 0" material="black" mesh="foot"/>
            <geom name="RL_foot" class="foot" size="0.0304263" pos="-0.00255953 0 -0.185864"/>
            <geom name="//unnamed_geom_54" class="reward_collision_sphere" size="0.0253453"/>
            <geom name="//unnamed_geom_55" class="reward_collision_sphere" size="0.0253453" pos="-0.00255953 0 -0.185864"/>
            <site name="RL_foot" class="foot" pos="-0.00255953 0 -0.185864" size="0.0101381"/>
          </body>
        </body>
      </body>
      <body name="RR_hip" pos="-0.248309 -0.0483052 -0.0060744" quat="0.999991 -0.000888097 0.000262181 0.00409071">
        <inertial pos="0.00676554 -0.00522062 0.00288155" quat="0.485801 0.466786 0.493098 0.550421" mass="0.762515" diaginertia="0.00303647 0.000369443 0.000259922"/>
        <joint name="RR_hip_joint" pos="0 0 0" axis="-0.999966 -0.000652459 -0.00820215" stiffness="0.00749799" range="-0.883989 1.04" armature="0.0148805" damping="0.0269422" frictionloss="0.151097"/>
        <geom name="//unnamed_geom_56" class="visual" pos="3.5335e-09 1.43425e-10 -7.01451e-07" quat="2.14617e-09 4.63268e-05 4.63268e-05 -1" material="metal" mesh="hip_0"/>
        <geom name="//unnamed_geom_57" class="visual" pos="5.78362e-09 2.32509e-10 -6.01416e-07" quat="2.14617e-09 4.63268e-05 4.63268e-05 -1" material="gray" mesh="hip_1"/>
        <geom name="//unnamed_geom_58" class="collision" size="0.0466353 0.0202762" pos="0 -0.0711253 0" quat="0.707107 0.707107 0 0" type="cylinder"/>
        <geom name="//unnamed_geom_59" class="reward_collision_sphere" size="0.0608287" pos="0 -0.0622347 0"/>
        <body name="RR_thigh" pos="-0.000590672 -0.0855576 0.00998175" quat="1 -0.000198718 0.000109151 0.000139543">
          <inertial pos="-0.00445149 0.00831386 -0.0329675" quat="0.555893 -0.0296731 0.0504255 0.829192" mass="1.36222" diaginertia="0.0228586 0.00362957 0.000499638"/>
          <joint name="RR_thigh_joint" pos="0 0 0" axis="0.0056422 -0.999671 -0.0250396" range="-4.59066 0.713669" armature="0.00386434" damping="0" frictionloss="0.1889"/>
          <geom name="//unnamed_geom_60" class="visual" material="metal" mesh="thigh_mirror_0"/>
          <geom name="//unnamed_geom_61" class="visual" material="gray" mesh="thigh_mirror_1"/>
          <geom name="//unnamed_geom_62" class="collision" size="0.107971 0.0124192 0.0172348" pos="0 0 -0.0929322" quat="0.707107 0 0.707107 0" type="box"/>
          <body name="RR_calf" pos="0.00219667 0.00722438 -0.186284" quat="0.999995 -0.00131472 0.00289582 0.00064006">
            <inertial pos="0.00445125 -0.00133126 -0.125363" quat="0.730663 0.0174205 0.0257748 0.682029" mass="0.292918" diaginertia="0.00536497 0.000863922 2.40625e-05"/>
            <joint name="RR_calf_joint" pos="0 0 0" axis="0.0111647 -0.998981 -0.0437263" range="0.691262 2.54759" armature="0.00934122" damping="0" frictionloss="0.210182"/>
            <geom name="//unnamed_geom_63" class="visual" material="gray" mesh="calf_mirror_0"/>
            <geom name="//unnamed_geom_64" class="visual" material="black" mesh="calf_mirror_1"/>
            <geom name="RR_calf0" class="collision" size="0.0131796 0.0608287" pos="0.0127977 0 -0.0523562" quat="0.995004 0 -0.0998334 0" type="cylinder"/>
            <geom name="//unnamed_geom_66" class="collision" size="0.0111519 0.0329489" pos="0.0255953 0 -0.129145" quat="0.999688 0 0.0249974 0" type="cylinder"/>
            <geom name="//unnamed_geom_67" class="visual" pos="0 0 -0.185864" quat="1 0 0 0" material="black" mesh="foot"/>
            <geom name="RR_foot" class="foot" size="0.031705" pos="-0.00255953 0 -0.185864"/>
            <geom name="//unnamed_geom_69" class="reward_collision_sphere" size="0.0253453"/>
            <geom name="//unnamed_geom_70" class="reward_collision_sphere" size="0.0253453" pos="-0.00255953 0 -0.185864"/>
            <site name="RR_foot" class="foot" pos="-0.00255953 0 -0.185864" size="0.0101381"/>
          </body>
        </body>
      </body>
    </body>
  </worldbody>

  <contact>
    <pair class="/" geom1="floor" geom2="FL_foot" name="//unnamed_contact_0"/>
    <pair class="/" geom1="floor" geom2="FR_foot" name="//unnamed_contact_1"/>
    <pair class="/" geom1="floor" geom2="RL_foot" name="//unnamed_contact_2"/>
    <pair class="/" geom1="floor" geom2="RR_foot" name="//unnamed_contact_3"/>
  </contact>

  <actuator>
    <general name="FL_hip" class="/" joint="FL_hip_joint" forcerange="-27.943 27.943" gainprm="15.3876" biasprm="0 -15.3876 -0.472244"/>
    <general name="FL_thigh" class="/" joint="FL_thigh_joint" forcerange="-34.0989 34.0989" gainprm="15.3876" biasprm="0 -15.3876 -0.472244"/>
    <general name="FL_calf" class="/" joint="FL_calf_joint" forcerange="-44.8491 44.8491" gainprm="15.3876" biasprm="0 -15.3876 -0.472244"/>
    <general name="FR_hip" class="/" joint="FR_hip_joint" forcerange="-25.1541 25.1541" gainprm="15.3876" biasprm="0 -15.3876 -0.472244"/>
    <general name="FR_thigh" class="/" joint="FR_thigh_joint" forcerange="-22.3271 22.3271" gainprm="15.3876" biasprm="0 -15.3876 -0.472244"/>
    <general name="FR_calf" class="/" joint="FR_calf_joint" forcerange="-51.486 51.486" gainprm="15.3876" biasprm="0 -15.3876 -0.472244"/>
    <general name="RL_hip" class="/" joint="RL_hip_joint" forcerange="-19.0301 19.0301" gainprm="15.3876" biasprm="0 -15.3876 -0.472244"/>
    <general name="RL_thigh" class="/" joint="RL_thigh_joint" forcerange="-23.9576 23.9576" gainprm="15.3876" biasprm="0 -15.3876 -0.472244"/>
    <general name="RL_calf" class="/" joint="RL_calf_joint" forcerange="-52.819 52.819" gainprm="15.3876" biasprm="0 -15.3876 -0.472244"/>
    <general name="RR_hip" class="/" joint="RR_hip_joint" forcerange="-33.8775 33.8775" gainprm="15.3876" biasprm="0 -15.3876 -0.472244"/>
    <general name="RR_thigh" class="/" joint="RR_thigh_joint" forcerange="-23.7497 23.7497" gainprm="15.3876" biasprm="0 -15.3876 -0.472244"/>
    <general name="RR_calf" class="/" joint="RR_calf_joint" forcerange="-46.4315 46.4315" gainprm="15.3876" biasprm="0 -15.3876 -0.472244"/>
  </actuator>

  <sensor>
    <gyro site="imu" name="imu_angular_velocity"/>
    <velocimeter site="imu" name="imu_linear_velocity"/>
    <framelinvel objtype="site" objname="FL_foot" name="FL_foot_global_linear_velocity"/>
    <framelinvel objtype="site" objname="FR_foot" name="FR_foot_global_linear_velocity"/>
    <framelinvel objtype="site" objname="RL_foot" name="RL_foot_global_linear_velocity"/>
    <framelinvel objtype="site" objname="RR_foot" name="RR_foot_global_linear_velocity"/>
  </sensor>

  <keyframe>
    <key name="home" qpos="0 0 0.325 1 0 0 0 0.1 0.8 -1.5 -0.1 -0.8 1.5 -0.1 0.8 -1.5 0.1 -0.8 1.5"/>
  </keyframe>
</mujoco>
