<mujoco model="go2">
  <compiler angle="radian" assetdir="assets" balanceinertia="true" inertiafromgeom="false"/>

  <option timestep="0.005" density="1.2" viscosity="2e-05"/>

  <size nkey="1"/>

  <visual>
    <quality shadowsize="8192"/>
    <map shadowclip="0.5"/>
  </visual>

  <default>
    <default class="/">
      <geom contype="0" conaffinity="0" group="1" solref="-1000 -80"/>
      <site size="0.01 0.005 0.005" group="5"/>
      <general forcelimited="true" biastype="affine" gainprm="20" biasprm="0 -20 -0.5"/>
      <default class="go2">
        <joint armature="0.01" damping="0.01" frictionloss="0.2"/>
        <geom condim="1" margin="0.001"/>
        <default class="visual">
          <geom type="mesh" group="2"/>
        </default>
        <default class="collision">
          <geom group="3"/>
          <default class="foot">
            <geom size="0.022 0 0" condim="6" priority="1" friction="0.8 0.02 0.01" solimp="0.015 1 0.022"/>
          </default>
        </default>
        <default class="reward_collision_sphere">
          <geom group="5" rgba="1 0 0 1"/>
        </default>
      </default>
    </default>
  </default>

  <asset>
    <texture type="skybox" colorspace="auto" name="//unnamed_texture_0" builtin="gradient" rgb1="0.95 0.95 0.95" rgb2="0.95 0.95 0.95" width="100" height="600"/>
    <texture type="2d" colorspace="auto" name="texplane" builtin="checker" rgb1="0.345 0.575 0.748" rgb2="0.345 0.575 0.748" markrgb="1 1 1" width="512" height="512"/>
    <material name="MatPlane" class="/" texture="texplane" texuniform="true" texrepeat="2 2" specular="0.9"/>
    <material name="metal" class="/" rgba="0.9 0.95 0.95 1"/>
    <material name="black" class="/" rgba="0 0 0 1"/>
    <material name="white" class="/"/>
    <material name="gray" class="/" rgba="0.671705 0.692426 0.77427 1"/>
    <mesh name="base_0" class="/" file="base_0.obj"/>
    <mesh name="base_1" class="/" file="base_1.obj"/>
    <mesh name="base_2" class="/" file="base_2.obj"/>
    <mesh name="base_3" class="/" file="base_3.obj"/>
    <mesh name="base_4" class="/" file="base_4.obj"/>
    <mesh name="hip_0" class="/" file="hip_0.obj"/>
    <mesh name="hip_1" class="/" file="hip_1.obj"/>
    <mesh name="thigh_0" class="/" file="thigh_0.obj"/>
    <mesh name="thigh_1" class="/" file="thigh_1.obj"/>
    <mesh name="thigh_mirror_0" class="/" file="thigh_mirror_0.obj"/>
    <mesh name="thigh_mirror_1" class="/" file="thigh_mirror_1.obj"/>
    <mesh name="calf_0" class="/" file="calf_0.obj"/>
    <mesh name="calf_1" class="/" file="calf_1.obj"/>
    <mesh name="calf_mirror_0" class="/" file="calf_mirror_0.obj"/>
    <mesh name="calf_mirror_1" class="/" file="calf_mirror_1.obj"/>
    <mesh name="foot" class="/" file="foot.obj"/>
  </asset>

  <worldbody>
    <geom name="floor" class="/" size="100 100 0.125" type="plane" group="0" material="MatPlane"/>
    <light name="toplight_shadow" class="/" pos="0 0 5" dir="0.0990148 0.0990148 -0.990148" type="directional" ambient="0.04 0.04 0.04" diffuse="0.55 0.55 0.55" specular="0.12 0.12 0.12"/>
    <light name="toplight_fill" class="/" pos="0 0 5" dir="0.0990148 0.0990148 -0.990148" type="directional" castshadow="false" ambient="0.04 0.04 0.04" diffuse="0.3 0.3 0.3" specular="0.08 0.08 0.08"/>
    <body name="trunk" childclass="go2" pos="-2.52451e-05 -4.16852e-05 0.000628851" quat="1 -5.74631e-05 -7.50895e-05 -7.17479e-05">
      <inertial pos="0.0196836 0.000615221 -0.00492" quat="-0.000772512 0.713444 -0.00159255 0.70071" mass="5.83908" diaginertia="0.0829631 0.103645 0.0118027"/>
      <joint name="//unnamed_joint_0" type="free" armature="0" damping="0" frictionloss="0"/>
      <geom name="//unnamed_geom_1" class="visual" material="black" mesh="base_0"/>
      <geom name="//unnamed_geom_2" class="visual" material="black" mesh="base_1"/>
      <geom name="//unnamed_geom_3" class="visual" material="black" mesh="base_2"/>
      <geom name="//unnamed_geom_4" class="visual" material="white" mesh="base_3"/>
      <geom name="//unnamed_geom_5" class="visual" material="gray" mesh="base_4"/>
      <geom name="trunk_1" class="collision" size="0.176731 0.0439243 0.0535548" type="box"/>
      <geom name="trunk_2" class="collision" size="0.0469779 0.0422801" pos="0.270093 0 0.00861875" type="cylinder"/>
      <geom name="trunk_3" class="collision" size="0.0441592" pos="0.277674 0 -0.0517125"/>
      <geom name="//unnamed_geom_9" class="reward_collision_sphere" size="0.0939558"/>
      <geom name="//unnamed_geom_10" class="reward_collision_sphere" size="0.0563735" pos="0.265354 0 -0.0387844"/>
      <site name="imu" pos="-0.0258448 0.00473593 0.0340662" size="0.00939558"/>
      <camera name="track" pos="0 -2.01821 0" quat="0.707107 0.707107 0 0" mode="trackcom"/>
      <camera name="ego_camera" pos="0.29568 0 0.0387844" quat="-0.5 -0.5 0.5 0.5"/>
      <body name="FL_hip" pos="0.182521 0.0478859 0.00118974" quat="1 -1.3967e-05 3.56141e-05 9.25922e-05">
        <inertial pos="-0.00516936 0.00240684 0.000784444" quat="0.497463 0.497784 0.504969 0.499748" mass="0.560779" diaginertia="0.000676247 0.00063084 0.000225523"/>
        <joint name="FL_hip_joint" pos="0 0 0" axis="0.999991 0.00139771 0.00403518" stiffness="2.74371e-05" range="-1.03547 1.05084" armature="0.00898114" damping="0.00210995" frictionloss="0.188161"/>
        <geom name="//unnamed_geom_11" class="visual" material="metal" mesh="hip_0"/>
        <geom name="//unnamed_geom_12" class="visual" material="gray" mesh="hip_1"/>
        <geom name="//unnamed_geom_13" class="collision" size="0.0432197 0.0187912" pos="0 0.0807285 0" quat="0.707107 0.707107 0 0" type="cylinder"/>
        <geom name="//unnamed_geom_14" class="reward_collision_sphere" size="0.0563735" pos="0 0.0706375 0"/>
        <body name="FL_thigh" pos="-9.94384e-05 0.0963853 0.00159053" quat="1 -6.31576e-08 -1.29933e-06 6.93526e-07">
          <inertial pos="-0.00348115 -0.0223843 -0.0271704" quat="0.829609 0.0845048 -0.0185187 0.551602" mass="0.95441" diaginertia="0.00456875 0.00606102 0.000410156"/>
          <joint name="FL_thigh_joint" pos="0 0 0" axis="-0.00158313 0.999997 -0.00181994" stiffness="0.00566429" range="-1.55038 3.47529" armature="0.00956536" damping="0.00398139" frictionloss="0.18843"/>
          <geom name="//unnamed_geom_15" class="visual" material="metal" mesh="thigh_0"/>
          <geom name="//unnamed_geom_16" class="visual" material="gray" mesh="thigh_1"/>
          <geom name="//unnamed_geom_17" class="collision" size="0.100063 0.0115096 0.0159725" pos="0 0 -0.0917897" quat="0.707107 0 0.707107 0" type="box"/>
          <body name="FL_calf" pos="0.000207967 -0.00136448 -0.183784" quat="1 0.000153421 0.000224111 -0.000170885">
            <inertial pos="0.00624922 -0.000532642 -0.121224" quat="0.710674 0.00130948 -0.00459707 0.703506" mass="0.202474" diaginertia="0.00114038 0.00152443 2.53586e-05"/>
            <joint name="FL_calf_joint" pos="0 0 0" axis="0.00544587 0.999984 -0.00138123" stiffness="0.000887725" range="-2.71955 -0.846997" armature="0.00960592" damping="0" frictionloss="0.193852"/>
            <geom name="//unnamed_geom_18" class="visual" material="gray" mesh="calf_0"/>
            <geom name="//unnamed_geom_19" class="visual" material="black" mesh="calf_1"/>
            <geom name="FL_calf0" class="collision" size="0.0112747 0.0563735" pos="0.00758154 0 -0.0517125" quat="0.994493 0 -0.104807 0" type="cylinder"/>
            <geom name="//unnamed_geom_21" class="collision" size="0.0103351 0.0305356" pos="0.0189539 0 -0.127557" quat="0.999688 0 0.0249974 0" type="cylinder"/>
            <geom name="//unnamed_geom_22" class="visual" pos="0 0 -0.183579" quat="1 0 0 0" material="black" mesh="foot"/>
            <geom name="FL_foot" class="foot" size="0.0176395" pos="-0.00189539 0 -0.183579"/>
            <geom name="//unnamed_geom_24" class="reward_collision_sphere" size="0.023489"/>
            <geom name="//unnamed_geom_25" class="reward_collision_sphere" size="0.023489" pos="-0.00189539 0 -0.183579"/>
            <site name="FL_foot" class="foot" pos="-0.00189539 0 -0.183579" size="0.00939558"/>
          </body>
        </body>
      </body>
      <body name="FR_hip" pos="0.182944 -0.0453165 0.000295311" quat="1 -6.1198e-05 -0.000103693 -0.000170329">
        <inertial pos="-0.00497767 -0.0019834 -0.00085912" quat="0.498608 0.505857 0.498817 0.496669" mass="0.559023" diaginertia="0.000673974 0.000627384 0.000228401"/>
        <joint name="FR_hip_joint" pos="0 0 0" axis="1 0.000363161 3.97787e-05" range="-1.05528 1.03563" armature="0.00936285" damping="0.0120009" frictionloss="0.19604"/>
        <geom name="//unnamed_geom_26" class="visual" pos="0 1.28262e-09 5.50143e-08" quat="4.63268e-05 1 0 0" material="metal" mesh="hip_0"/>
        <geom name="//unnamed_geom_27" class="visual" pos="0 2.07928e-09 -1.36071e-07" quat="4.63268e-05 1 0 0" material="gray" mesh="hip_1"/>
        <geom name="//unnamed_geom_28" class="collision" size="0.0432197 0.0187912" pos="0 -0.0807285 0" quat="0.707107 0.707107 0 0" type="cylinder"/>
        <geom name="//unnamed_geom_29" class="reward_collision_sphere" size="0.0563735" pos="0 -0.0706375 0"/>
        <body name="FR_thigh" pos="0.0015623 -0.0965108 -6.0819e-05" quat="1 4.55725e-05 4.57622e-06 -0.000223233">
          <inertial pos="-0.00370348 0.0221857 -0.0280478" quat="0.55151 -0.0198633 0.0845458 0.829635" mass="0.981692" diaginertia="0.00458426 0.00626728 0.000427267"/>
          <joint name="FR_thigh_joint" pos="0 0 0" axis="0.00595602 -0.999981 -0.00177185" stiffness="0.000593895" range="-3.46427 1.55599" armature="0.00938587" damping="0.0108292" frictionloss="0.184443"/>
          <geom name="//unnamed_geom_30" class="visual" material="metal" mesh="thigh_mirror_0"/>
          <geom name="//unnamed_geom_31" class="visual" material="gray" mesh="thigh_mirror_1"/>
          <geom name="//unnamed_geom_32" class="collision" size="0.100063 0.0115096 0.0159725" pos="0 0 -0.0917897" quat="0.707107 0 0.707107 0" type="box"/>
          <body name="FR_calf" pos="0.000456304 -0.000702064 -0.184329" quat="1 -0.000169202 -0.000177072 1.25354e-05">
            <inertial pos="0.00633164 0.000285325 -0.121109" quat="0.703503 -0.00462296 0.00162755 0.710676" mass="0.196521" diaginertia="0.00112589 0.0015345 2.53141e-05"/>
            <joint name="FR_calf_joint" pos="0 0 0" axis="0.00835364 -0.999961 0.0027962" range="0.837184 2.72206" armature="0.00945977" damping="0.00865849" frictionloss="0.175271"/>
            <geom name="//unnamed_geom_33" class="visual" material="gray" mesh="calf_mirror_0"/>
            <geom name="//unnamed_geom_34" class="visual" material="black" mesh="calf_mirror_1"/>
            <geom name="FR_calf0" class="collision" size="0.0122143 0.0563735" pos="0.00947693 0 -0.0517125" quat="0.995004 0 -0.0998334 0" type="cylinder"/>
            <geom name="//unnamed_geom_36" class="collision" size="0.0103351 0.0305356" pos="0.0189539 0 -0.127557" quat="0.999688 0 0.0249974 0" type="cylinder"/>
            <geom name="//unnamed_geom_37" class="visual" pos="0 0 -0.183579" quat="1 0 0 0" material="black" mesh="foot"/>
            <geom name="FR_foot" class="foot" size="0.0215938" pos="-0.00189539 0 -0.183579"/>
            <geom name="//unnamed_geom_39" class="reward_collision_sphere" size="0.023489"/>
            <geom name="//unnamed_geom_40" class="reward_collision_sphere" size="0.023489" pos="-0.00189539 0 -0.183579"/>
            <site name="FR_foot" class="foot" pos="-0.00189539 0 -0.183579" size="0.00939558"/>
          </body>
        </body>
      </body>
      <body name="RL_hip" pos="-0.183934 0.0471577 -4.65312e-07" quat="1 1.73795e-05 -9.74989e-05 -0.000115342">
        <inertial pos="0.00595462 0.00233055 0.000527226" quat="0.505095 0.494383 0.503346 0.497099" mass="0.552394" diaginertia="0.000673653 0.000617543 0.000230578"/>
        <joint name="RL_hip_joint" pos="0 0 0" axis="-0.9999 0.0141042 0.000528408" range="-1.04023 1.06347" armature="0.00938636" damping="0.0158623" frictionloss="0.179158"/>
        <geom name="//unnamed_geom_41" class="visual" pos="-7.47614e-10 0 -1.4655e-07" quat="4.63268e-05 0 1 0" material="metal" mesh="hip_0"/>
        <geom name="//unnamed_geom_42" class="visual" pos="-1.21197e-09 0 -1.29969e-07" quat="4.63268e-05 0 1 0" material="gray" mesh="hip_1"/>
        <geom name="//unnamed_geom_43" class="collision" size="0.0432197 0.0187912" pos="0 0.0807285 0" quat="0.707107 0.707107 0 0" type="cylinder"/>
        <geom name="//unnamed_geom_44" class="reward_collision_sphere" size="0.0563735" pos="0 0.0706375 0"/>
        <body name="RL_thigh" pos="0.000165346 0.0963325 -0.000351479" quat="1 -0.000108093 0.000455269 0.000119622">
          <inertial pos="-0.00314153 -0.0216005 -0.028233" quat="0.828635 0.0827412 -0.0203901 0.553265" mass="0.965553" diaginertia="0.00455752 0.00623769 0.00041681"/>
          <joint name="RL_thigh_joint" pos="0 0 0" axis="-0.000652934 1 4.27716e-05" range="-0.524786 4.53448" armature="0.00940118" damping="0.00992858" frictionloss="0.189077"/>
          <geom name="//unnamed_geom_45" class="visual" material="metal" mesh="thigh_0"/>
          <geom name="//unnamed_geom_46" class="visual" material="gray" mesh="thigh_1"/>
          <geom name="//unnamed_geom_47" class="collision" size="0.100063 0.0115096 0.0159725" pos="0 0 -0.0917897" quat="0.707107 0 0.707107 0" type="box"/>
          <body name="RL_calf" pos="0.000210094 -0.000678607 -0.183784" quat="1 3.97287e-06 1.39617e-05 -3.03817e-05">
            <inertial pos="0.00558138 -0.000391077 -0.121142" quat="0.710701 0.00133749 -0.00456734 0.703478" mass="0.203218" diaginertia="0.00116275 0.00157147 2.62524e-05"/>
            <joint name="RL_calf_joint" pos="0 0 0" axis="0.00929952 0.999956 -0.000862871" range="-2.72459 -0.868768" armature="0.00944734" damping="0" frictionloss="0.179752"/>
            <geom name="//unnamed_geom_48" class="visual" material="gray" mesh="calf_0"/>
            <geom name="//unnamed_geom_49" class="visual" material="black" mesh="calf_1"/>
            <geom name="RL_calf0" class="collision" size="0.0122143 0.0563735" pos="0.00947693 0 -0.0517125" quat="0.995004 0 -0.0998334 0" type="cylinder"/>
            <geom name="//unnamed_geom_51" class="collision" size="0.0103351 0.0305356" pos="0.0189539 0 -0.127557" quat="0.999688 0 0.0249974 0" type="cylinder"/>
            <geom name="//unnamed_geom_52" class="visual" pos="0 0 -0.183579" quat="1 0 0 0" material="black" mesh="foot"/>
            <geom name="RL_foot" class="foot" size="0.0172765" pos="-0.00189539 0 -0.183579"/>
            <geom name="//unnamed_geom_54" class="reward_collision_sphere" size="0.023489"/>
            <geom name="//unnamed_geom_55" class="reward_collision_sphere" size="0.023489" pos="-0.00189539 0 -0.183579"/>
            <site name="RL_foot" class="foot" pos="-0.00189539 0 -0.183579" size="0.00939558"/>
          </body>
        </body>
      </body>
      <body name="RR_hip" pos="-0.183357 -0.048687 -0.0011964" quat="1 1.29183e-05 -0.000144303 0.000211558">
        <inertial pos="0.00552941 -0.00282909 0.000609492" quat="0.498226 0.492013 0.500805 0.50881" mass="0.566933" diaginertia="0.000675102 0.000637072 0.000230245"/>
        <joint name="RR_hip_joint" pos="0 0 0" axis="-0.999986 0.000703967 0.00527841" stiffness="0.000920219" range="-1.04819 1.05639" armature="0.009258" damping="0.0101968" frictionloss="0.179571"/>
        <geom name="//unnamed_geom_56" class="visual" pos="7.4974e-10 1.28262e-09 -2.01564e-07" quat="2.14617e-09 4.63268e-05 4.63268e-05 -1" material="metal" mesh="hip_0"/>
        <geom name="//unnamed_geom_57" class="visual" pos="1.20671e-09 2.07928e-09 6.10284e-09" quat="2.14617e-09 4.63268e-05 4.63268e-05 -1" material="gray" mesh="hip_1"/>
        <geom name="//unnamed_geom_58" class="collision" size="0.0432197 0.0187912" pos="0 -0.0807285 0" quat="0.707107 0.707107 0 0" type="cylinder"/>
        <geom name="//unnamed_geom_59" class="reward_collision_sphere" size="0.0563735" pos="0 -0.0706375 0"/>
        <body name="RR_thigh" pos="0.000182678 -0.0970387 -0.00268533" quat="1 0.000154151 3.86374e-05 -7.84623e-05">
          <inertial pos="-0.00339843 0.0240038 -0.0292145" quat="0.552013 -0.0187384 0.0848607 0.829295" mass="0.940465" diaginertia="0.00448426 0.00601078 0.000410365"/>
          <joint name="RR_thigh_joint" pos="0 0 0" axis="-0.00233452 -0.999953 0.00940329" range="-4.55149 0.511078" armature="0.0100872" damping="0.01746" frictionloss="0.186948"/>
          <geom name="//unnamed_geom_60" class="visual" material="metal" mesh="thigh_mirror_0"/>
          <geom name="//unnamed_geom_61" class="visual" material="gray" mesh="thigh_mirror_1"/>
          <geom name="//unnamed_geom_62" class="collision" size="0.100063 0.0115096 0.0159725" pos="0 0 -0.0917897" quat="0.707107 0 0.707107 0" type="box"/>
          <body name="RR_calf" pos="0.000808415 -0.000553866 -0.184001" quat="1 6.42442e-05 -4.803e-05 -0.000111122">
            <inertial pos="0.00487561 0.00083398 -0.122268" quat="0.706342 -0.00694057 0.000296414 0.707837" mass="0.201205" diaginertia="0.00115945 0.00155018 2.60192e-05"/>
            <joint name="RR_calf_joint" pos="0 0 0" axis="0.0015755 -0.999997 -0.00211757" stiffness="4.80121e-05" range="0.83471 2.7334" armature="0.00953273" damping="0.00939958" frictionloss="0.192039"/>
            <geom name="//unnamed_geom_63" class="visual" material="gray" mesh="calf_mirror_0"/>
            <geom name="//unnamed_geom_64" class="visual" material="black" mesh="calf_mirror_1"/>
            <geom name="RR_calf0" class="collision" size="0.0122143 0.0563735" pos="0.00947693 0 -0.0517125" quat="0.995004 0 -0.0998334 0" type="cylinder"/>
            <geom name="//unnamed_geom_66" class="collision" size="0.0103351 0.0305356" pos="0.0189539 0 -0.127557" quat="0.999688 0 0.0249974 0" type="cylinder"/>
            <geom name="//unnamed_geom_67" class="visual" pos="0 0 -0.183579" quat="1 0 0 0" material="black" mesh="foot"/>
            <geom name="RR_foot" class="foot" size="0.0210475" pos="-0.00189539 0 -0.183579"/>
            <geom name="//unnamed_geom_69" class="reward_collision_sphere" size="0.023489"/>
            <geom name="//unnamed_geom_70" class="reward_collision_sphere" size="0.023489" pos="-0.00189539 0 -0.183579"/>
            <site name="RR_foot" class="foot" pos="-0.00189539 0 -0.183579" size="0.00939558"/>
          </body>
        </body>
      </body>
    </body>
  </worldbody>

  <contact>
    <pair class="/" geom1="floor" geom2="FL_foot" name="//unnamed_contact_0"/>
    <pair class="/" geom1="floor" geom2="FR_foot" name="//unnamed_contact_1"/>
    <pair class="/" geom1="floor" geom2="RL_foot" name="//unnamed_contact_2"/>
    <pair class="/" geom1="floor" geom2="RR_foot" name="//unnamed_contact_3"/>
  </contact>

  <actuator>
    <general name="FL_hip" class="/" joint="FL_hip_joint" forcerange="-22.9968 22.9968" gainprm="19.2676" biasprm="0 -19.2676 -0.463302"/>
    <general name="FL_thigh" class="/" joint="FL_thigh_joint" forcerange="-21.2101 21.2101" gainprm="19.2676" biasprm="0 -19.2676 -0.463302"/>
    <general name="FL_calf" class="/" joint="FL_calf_joint" forcerange="-42.712 42.712" gainprm="19.2676" biasprm="0 -19.2676 -0.463302"/>
    <general name="FR_hip" class="/" joint="FR_hip_joint" forcerange="-22.1851 22.1851" gainprm="19.2676" biasprm="0 -19.2676 -0.463302"/>
    <general name="FR_thigh" class="/" joint="FR_thigh_joint" forcerange="-21.8415 21.8415" gainprm="19.2676" biasprm="0 -19.2676 -0.463302"/>
    <general name="FR_calf" class="/" joint="FR_calf_joint" forcerange="-43.6455 43.6455" gainprm="19.2676" biasprm="0 -19.2676 -0.463302"/>
    <general name="RL_hip" class="/" joint="RL_hip_joint" forcerange="-21.6252 21.6252" gainprm="19.2676" biasprm="0 -19.2676 -0.463302"/>
    <general name="RL_thigh" class="/" joint="RL_thigh_joint" forcerange="-22.3106 22.3106" gainprm="19.2676" biasprm="0 -19.2676 -0.463302"/>
    <general name="RL_calf" class="/" joint="RL_calf_joint" forcerange="-44.1562 44.1562" gainprm="19.2676" biasprm="0 -19.2676 -0.463302"/>
    <general name="RR_hip" class="/" joint="RR_hip_joint" forcerange="-21.2417 21.2417" gainprm="19.2676" biasprm="0 -19.2676 -0.463302"/>
    <general name="RR_thigh" class="/" joint="RR_thigh_joint" forcerange="-21.8476 21.8476" gainprm="19.2676" biasprm="0 -19.2676 -0.463302"/>
    <general name="RR_calf" class="/" joint="RR_calf_joint" forcerange="-41.9917 41.9917" gainprm="19.2676" biasprm="0 -19.2676 -0.463302"/>
  </actuator>

  <sensor>
    <gyro site="imu" name="imu_angular_velocity"/>
    <velocimeter site="imu" name="imu_linear_velocity"/>
    <framelinvel objtype="site" objname="FL_foot" name="FL_foot_global_linear_velocity"/>
    <framelinvel objtype="site" objname="FR_foot" name="FR_foot_global_linear_velocity"/>
    <framelinvel objtype="site" objname="RL_foot" name="RL_foot_global_linear_velocity"/>
    <framelinvel objtype="site" objname="RR_foot" name="RR_foot_global_linear_velocity"/>
  </sensor>

  <keyframe>
    <key name="home" qpos="0 0 0.325 1 0 0 0 0.1 0.8 -1.5 -0.1 -0.8 1.5 -0.1 0.8 -1.5 0.1 -0.8 1.5"/>
  </keyframe>
</mujoco>
