<mujoco model="go2">
  <compiler angle="radian" assetdir="assets" balanceinertia="true" inertiafromgeom="false"/>

  <option timestep="0.005" density="1.2" viscosity="2e-05"/>

  <size nkey="1"/>

  <visual>
    <quality shadowsize="8192"/>
    <map shadowclip="0.5"/>
  </visual>

  <default>
    <default class="/">
      <geom contype="0" conaffinity="0" group="1" solref="-1000 -80"/>
      <site size="0.01 0.005 0.005" group="5"/>
      <general forcelimited="true" biastype="affine" gainprm="20" biasprm="0 -20 -0.5"/>
      <default class="go2">
        <joint armature="0.01" damping="0.01" frictionloss="0.2"/>
        <geom condim="1" margin="0.001"/>
        <default class="visual">
          <geom type="mesh" group="2"/>
        </default>
        <default class="collision">
          <geom group="3"/>
          <default class="foot">
            <geom size="0.022 0 0" condim="6" priority="1" friction="0.8 0.02 0.01" solimp="0.015 1 0.022"/>
          </default>
        </default>
        <default class="reward_collision_sphere">
          <geom group="5" rgba="1 0 0 1"/>
        </default>
      </default>
    </default>
  </default>

  <asset>
    <texture type="skybox" colorspace="auto" name="//unnamed_texture_0" builtin="gradient" rgb1="0.95 0.95 0.95" rgb2="0.95 0.95 0.95" width="100" height="600"/>
    <texture type="2d" colorspace="auto" name="texplane" builtin="checker" rgb1="0.345 0.575 0.748" rgb2="0.345 0.575 0.748" markrgb="1 1 1" width="512" height="512"/>
    <material name="MatPlane" class="/" texture="texplane" texuniform="true" texrepeat="2 2" specular="0.9"/>
    <material name="metal" class="/" rgba="0.9 0.95 0.95 1"/>
    <material name="black" class="/" rgba="0 0 0 1"/>
    <material name="white" class="/"/>
    <material name="gray" class="/" rgba="0.671705 0.692426 0.77427 1"/>
    <mesh name="base_0" class="/" file="base_0.obj"/>
    <mesh name="base_1" class="/" file="base_1.obj"/>
    <mesh name="base_2" class="/" file="base_2.obj"/>
    <mesh name="base_3" class="/" file="base_3.obj"/>
    <mesh name="base_4" class="/" file="base_4.obj"/>
    <mesh name="hip_0" class="/" file="hip_0.obj"/>
    <mesh name="hip_1" class="/" file="hip_1.obj"/>
    <mesh name="thigh_0" class="/" file="thigh_0.obj"/>
    <mesh name="thigh_1" class="/" file="thigh_1.obj"/>
    <mesh name="thigh_mirror_0" class="/" file="thigh_mirror_0.obj"/>
    <mesh name="thigh_mirror_1" class="/" file="thigh_mirror_1.obj"/>
    <mesh name="calf_0" class="/" file="calf_0.obj"/>
    <mesh name="calf_1" class="/" file="calf_1.obj"/>
    <mesh name="calf_mirror_0" class="/" file="calf_mirror_0.obj"/>
    <mesh name="calf_mirror_1" class="/" file="calf_mirror_1.obj"/>
    <mesh name="foot" class="/" file="foot.obj"/>
  </asset>

  <worldbody>
    <geom name="floor" class="/" size="100 100 0.125" type="plane" group="0" material="MatPlane"/>
    <light name="toplight_shadow" class="/" pos="0 0 5" dir="0.0990148 0.0990148 -0.990148" type="directional" ambient="0.04 0.04 0.04" diffuse="0.55 0.55 0.55" specular="0.12 0.12 0.12"/>
    <light name="toplight_fill" class="/" pos="0 0 5" dir="0.0990148 0.0990148 -0.990148" type="directional" castshadow="false" ambient="0.04 0.04 0.04" diffuse="0.3 0.3 0.3" specular="0.08 0.08 0.08"/>
    <body name="trunk" childclass="go2" pos="0.000118612 4.06416e-05 -0.000612539" quat="1 7.485e-06 9.58944e-06 9.10947e-06">
      <inertial pos="0.0195498 0.00196721 -0.00379384" quat="-0.000419112 0.713467 -0.00192955 0.700686" mass="6.01631" diaginertia="0.0685521 0.118214 0.0157207"/>
      <joint name="//unnamed_joint_0" type="free" armature="0" damping="0" frictionloss="0"/>
      <geom name="//unnamed_geom_1" class="visual" material="black" mesh="base_0"/>
      <geom name="//unnamed_geom_2" class="visual" material="black" mesh="base_1"/>
      <geom name="//unnamed_geom_3" class="visual" material="black" mesh="base_2"/>
      <geom name="//unnamed_geom_4" class="visual" material="white" mesh="base_3"/>
      <geom name="//unnamed_geom_5" class="visual" material="gray" mesh="base_4"/>
      <geom name="trunk_1" class="collision" size="0.179244 0.044549 0.0543164" type="box"/>
      <geom name="trunk_2" class="collision" size="0.047646 0.0428814" pos="0.259197 0 0.0091429" type="cylinder"/>
      <geom name="trunk_3" class="collision" size="0.0447872" pos="0.266473 0 -0.0548574"/>
      <geom name="//unnamed_geom_9" class="reward_collision_sphere" size="0.095292"/>
      <geom name="//unnamed_geom_10" class="reward_collision_sphere" size="0.0571752" pos="0.25465 0 -0.0411431"/>
      <site name="imu" pos="-0.0284175 0.00203825 0.0335429" size="0.0095292"/>
      <camera name="track" pos="0 -2.07001 0" quat="0.707107 0.707107 0 0" mode="trackcom"/>
      <camera name="ego_camera" pos="0.283752 0 0.0411431" quat="-0.5 -0.5 0.5 0.5"/>
      <body name="FL_hip" pos="0.174726 0.0485643 0.000178383" quat="1 -4.6099e-05 0.000150997 -0.000161497">
        <inertial pos="-0.00640098 0.00201223 0.000328001" quat="0.497525 0.49829 0.505571 0.498572" mass="0.599178" diaginertia="0.000556012 0.000720535 0.000309049"/>
        <joint name="FL_hip_joint" pos="0 0 0" axis="0.999994 0.00271603 -0.00206052" stiffness="0.00249962" range="-1.02974 1.04568" armature="0.00949562" damping="0.00342184" frictionloss="0.176992"/>
        <geom name="//unnamed_geom_11" class="visual" material="metal" mesh="hip_0"/>
        <geom name="//unnamed_geom_12" class="visual" material="gray" mesh="hip_1"/>
        <geom name="//unnamed_geom_13" class="collision" size="0.0438343 0.0190584" pos="0 0.0828006 0" quat="0.707107 0.707107 0 0" type="cylinder"/>
        <geom name="//unnamed_geom_14" class="reward_collision_sphere" size="0.0571752" pos="0 0.0724505 0"/>
        <body name="FL_thigh" pos="-0.00122713 0.0981638 0.00189254" quat="1 9.81427e-05 8.05782e-05 0.000133303">
          <inertial pos="-0.0035715 -0.0229867 -0.0292887" quat="0.82991 0.084234 -0.0197383 0.551148" mass="0.965768" diaginertia="0.00371295 0.00687419 0.000532705"/>
          <joint name="FL_thigh_joint" pos="0 0 0" axis="-0.000833359 0.999995 -0.00290432" stiffness="0.00664977" range="-1.57097 3.47481" armature="0.00931385" damping="0.00485805" frictionloss="0.195718"/>
          <geom name="//unnamed_geom_15" class="visual" material="metal" mesh="thigh_0"/>
          <geom name="//unnamed_geom_16" class="visual" material="gray" mesh="thigh_1"/>
          <geom name="//unnamed_geom_17" class="collision" size="0.101486 0.0116733 0.0161996" pos="0 0 -0.0973719" quat="0.707107 0 0.707107 0" type="box"/>
          <body name="FL_calf" pos="-0.000749509 -0.000312762 -0.193749" quat="0.999999 4.41589e-05 -0.00105946 -0.000128028">
            <inertial pos="0.00521346 -0.000535333 -0.128798" quat="0.710257 0.00160594 -0.00432718 0.703928" mass="0.209316" diaginertia="0.000928575 0.00170295 3.37975e-05"/>
            <joint name="FL_calf_joint" pos="0 0 0" axis="-0.00689833 0.999975 -0.00163408" stiffness="0.00119965" range="-2.71461 -0.837155" armature="0.00990277" damping="0.00659834" frictionloss="0.184721"/>
            <geom name="//unnamed_geom_18" class="visual" material="gray" mesh="calf_0"/>
            <geom name="//unnamed_geom_19" class="visual" material="black" mesh="calf_1"/>
            <geom name="FL_calf0" class="collision" size="0.011435 0.0571752" pos="0.0072757 0 -0.0548574" quat="0.994493 0 -0.104807 0" type="cylinder"/>
            <geom name="//unnamed_geom_21" class="collision" size="0.0104821 0.0309699" pos="0.0181893 0 -0.135315" quat="0.999688 0 0.0249974 0" type="cylinder"/>
            <geom name="//unnamed_geom_22" class="visual" pos="0 0 -0.194744" quat="1 0 0 0" material="black" mesh="foot"/>
            <geom name="FL_foot" class="foot" size="0.0185541" pos="-0.00181893 0 -0.194744"/>
            <geom name="//unnamed_geom_24" class="reward_collision_sphere" size="0.023823"/>
            <geom name="//unnamed_geom_25" class="reward_collision_sphere" size="0.023823" pos="-0.00181893 0 -0.194744"/>
            <site name="FL_foot" class="foot" pos="-0.00181893 0 -0.194744" size="0.0095292"/>
          </body>
        </body>
      </body>
      <body name="FR_hip" pos="0.175363 -0.0472543 -0.000288322" quat="1 -8.29206e-05 -0.000539434 6.08826e-05">
        <inertial pos="-0.00473949 -0.00148019 -0.000120843" quat="0.498236 0.505834 0.499136 0.496745" mass="0.566256" diaginertia="0.000533989 0.00069738 0.00030664"/>
        <joint name="FR_hip_joint" pos="0 0 0" axis="0.999992 -0.00295353 -0.00256606" range="-1.02764 1.00829" armature="0.00965893" damping="0.0101513" frictionloss="0.189536"/>
        <geom name="//unnamed_geom_26" class="visual" pos="0 1.05164e-09 4.5107e-08" quat="4.63268e-05 1 0 0" material="metal" mesh="hip_0"/>
        <geom name="//unnamed_geom_27" class="visual" pos="0 1.70483e-09 -1.11567e-07" quat="4.63268e-05 1 0 0" material="gray" mesh="hip_1"/>
        <geom name="//unnamed_geom_28" class="collision" size="0.0438343 0.0190584" pos="0 -0.0828006 0" quat="0.707107 0.707107 0 0" type="cylinder"/>
        <geom name="//unnamed_geom_29" class="reward_collision_sphere" size="0.0571752" pos="0 -0.0724505 0"/>
        <body name="FR_thigh" pos="0.0027635 -0.0981057 0.000654201" quat="1 0.000163966 9.2518e-05 0.000499235">
          <inertial pos="-0.00280929 0.022951 -0.0298754" quat="0.551624 -0.0200504 0.0846216 0.829547" mass="1.03547" diaginertia="0.00371698 0.00722898 0.000576599"/>
          <joint name="FR_thigh_joint" pos="0 0 0" axis="0.00740214 -0.999957 0.00556805" range="-3.4422 1.52806" armature="0.00939916" damping="0.00264215" frictionloss="0.195971"/>
          <geom name="//unnamed_geom_30" class="visual" material="metal" mesh="thigh_mirror_0"/>
          <geom name="//unnamed_geom_31" class="visual" material="gray" mesh="thigh_mirror_1"/>
          <geom name="//unnamed_geom_32" class="collision" size="0.101486 0.0116733 0.0161996" pos="0 0 -0.0973719" quat="0.707107 0 0.707107 0" type="box"/>
          <body name="FR_calf" pos="0.00189373 -0.00112716 -0.194794" quat="1 3.7558e-05 2.50279e-05 -0.000157908">
            <inertial pos="0.00662059 0.00131571 -0.127313" quat="0.704007 -1.36638e-05 0.00121839 0.710192" mass="0.202626" diaginertia="0.000926259 0.00174362 3.40668e-05"/>
            <joint name="FR_calf_joint" pos="0 0 0" axis="-0.00107701 -0.999944 0.0105049" stiffness="0.00254913" range="0.820038 2.69291" armature="0.00954759" damping="0.0165759" frictionloss="0.167424"/>
            <geom name="//unnamed_geom_33" class="visual" material="gray" mesh="calf_mirror_0"/>
            <geom name="//unnamed_geom_34" class="visual" material="black" mesh="calf_mirror_1"/>
            <geom name="FR_calf0" class="collision" size="0.012388 0.0571752" pos="0.00909463 0 -0.0548574" quat="0.995004 0 -0.0998334 0" type="cylinder"/>
            <geom name="//unnamed_geom_36" class="collision" size="0.0104821 0.0309699" pos="0.0181893 0 -0.135315" quat="0.999688 0 0.0249974 0" type="cylinder"/>
            <geom name="//unnamed_geom_37" class="visual" pos="0 0 -0.194744" quat="1 0 0 0" material="black" mesh="foot"/>
            <geom name="FR_foot" class="foot" size="0.0223306" pos="-0.00181893 0 -0.194744"/>
            <geom name="//unnamed_geom_39" class="reward_collision_sphere" size="0.023823"/>
            <geom name="//unnamed_geom_40" class="reward_collision_sphere" size="0.023823" pos="-0.00181893 0 -0.194744"/>
            <site name="FR_foot" class="foot" pos="-0.00181893 0 -0.194744" size="0.0095292"/>
          </body>
        </body>
      </body>
      <body name="RL_hip" pos="-0.175252 0.0496791 -0.000813086" quat="1 0.000129958 0.0001036 6.93529e-05">
        <inertial pos="0.00551701 0.000910189 -0.000283579" quat="0.503186 0.508603 0.490664 0.497369" mass="0.569062" diaginertia="0.000543474 0.000710571 0.000310302"/>
        <joint name="RL_hip_joint" pos="0 0 0" axis="-0.999847 0.0174691 -0.000690221" range="-1.05777 1.05857" armature="0.00953774" damping="0.0103061" frictionloss="0.185039"/>
        <geom name="//unnamed_geom_41" class="visual" pos="4.20526e-11 0 8.2433e-09" quat="4.63268e-05 0 1 0" material="metal" mesh="hip_0"/>
        <geom name="//unnamed_geom_42" class="visual" pos="6.81724e-11 0 7.31063e-09" quat="4.63268e-05 0 1 0" material="gray" mesh="hip_1"/>
        <geom name="//unnamed_geom_43" class="collision" size="0.0438343 0.0190584" pos="0 0.0828006 0" quat="0.707107 0.707107 0 0" type="cylinder"/>
        <geom name="//unnamed_geom_44" class="reward_collision_sphere" size="0.0571752" pos="0 0.0724505 0"/>
        <body name="RL_thigh" pos="-0.000175214 0.0973056 -0.000815226" quat="1 -0.000153701 -0.000149593 -1.43142e-05">
          <inertial pos="-0.00233532 -0.023371 -0.0300269" quat="0.831405 0.0851748 -0.0236498 0.548591" mass="1.00618" diaginertia="0.00380159 0.0071502 0.000570851"/>
          <joint name="RL_thigh_joint" pos="0 0 0" axis="-0.00970126 0.999952 -0.00143993" range="-0.519125 4.54287" armature="0.00951563" damping="0.00888724" frictionloss="0.189204"/>
          <geom name="//unnamed_geom_45" class="visual" material="metal" mesh="thigh_0"/>
          <geom name="//unnamed_geom_46" class="visual" material="gray" mesh="thigh_1"/>
          <geom name="//unnamed_geom_47" class="collision" size="0.101486 0.0116733 0.0161996" pos="0 0 -0.0973719" quat="0.707107 0 0.707107 0" type="box"/>
          <body name="RL_calf" pos="0.00156462 0.000129331 -0.194705" quat="1 9.12373e-05 -0.000751919 -6.52546e-05">
            <inertial pos="0.00675425 0.000441886 -0.129733" quat="0.710672 0.00154165 -0.00450124 0.703507" mass="0.210602" diaginertia="0.000967851 0.00183633 3.61048e-05"/>
            <joint name="RL_calf_joint" pos="0 0 0" axis="0.0129043 0.999892 -0.00702253" range="-2.71881 -0.88673" armature="0.00937271" damping="0.000664874" frictionloss="0.183983"/>
            <geom name="//unnamed_geom_48" class="visual" material="gray" mesh="calf_0"/>
            <geom name="//unnamed_geom_49" class="visual" material="black" mesh="calf_1"/>
            <geom name="RL_calf0" class="collision" size="0.012388 0.0571752" pos="0.00909463 0 -0.0548574" quat="0.995004 0 -0.0998334 0" type="cylinder"/>
            <geom name="//unnamed_geom_51" class="collision" size="0.0104821 0.0309699" pos="0.0181893 0 -0.135315" quat="0.999688 0 0.0249974 0" type="cylinder"/>
            <geom name="//unnamed_geom_52" class="visual" pos="0 0 -0.194744" quat="1 0 0 0" material="black" mesh="foot"/>
            <geom name="RL_foot" class="foot" size="0.0165987" pos="-0.00181893 0 -0.194744"/>
            <geom name="//unnamed_geom_54" class="reward_collision_sphere" size="0.023823"/>
            <geom name="//unnamed_geom_55" class="reward_collision_sphere" size="0.023823" pos="-0.00181893 0 -0.194744"/>
            <site name="RL_foot" class="foot" pos="-0.00181893 0 -0.194744" size="0.0095292"/>
          </body>
        </body>
      </body>
      <body name="RR_hip" pos="-0.17568 -0.0486382 -0.00251042" quat="1 -0.000194229 0.000858187 -0.000159955">
        <inertial pos="0.00438515 -0.00268405 0.000878695" quat="0.502495 0.496875 0.488455 0.511884" mass="0.590975" diaginertia="0.000548604 0.000711843 0.000306333"/>
        <joint name="RR_hip_joint" pos="0 0 0" axis="-0.999981 0.00483121 0.00388518" stiffness="0.0017812" range="-1.0779 1.03771" armature="0.00864286" damping="0.0122307" frictionloss="0.190785"/>
        <geom name="//unnamed_geom_56" class="visual" pos="-3.77063e-11 1.05164e-09 -3.68637e-08" quat="2.14617e-09 4.63268e-05 4.63268e-05 -1" material="metal" mesh="hip_0"/>
        <geom name="//unnamed_geom_57" class="visual" pos="-7.89229e-11 1.70483e-09 1.18877e-07" quat="2.14617e-09 4.63268e-05 4.63268e-05 -1" material="gray" mesh="hip_1"/>
        <geom name="//unnamed_geom_58" class="collision" size="0.0438343 0.0190584" pos="0 -0.0828006 0" quat="0.707107 0.707107 0 0" type="cylinder"/>
        <geom name="//unnamed_geom_59" class="reward_collision_sphere" size="0.0571752" pos="0 -0.0724505 0"/>
        <body name="RR_thigh" pos="-0.000222568 -0.0990042 -0.00325568" quat="1 -7.70048e-05 -6.70106e-05 -0.000260395">
          <inertial pos="-0.00318317 0.0256412 -0.0302909" quat="0.551575 -0.0174987 0.0797793 0.830117" mass="0.963459" diaginertia="0.00357044 0.0067434 0.000540465"/>
          <joint name="RR_thigh_joint" pos="0 0 0" axis="-0.00555295 -0.999984 0.000926433" stiffness="0.00122209" range="-4.55823 0.48318" armature="0.0108048" damping="0.0144838" frictionloss="0.181263"/>
          <geom name="//unnamed_geom_60" class="visual" material="metal" mesh="thigh_mirror_0"/>
          <geom name="//unnamed_geom_61" class="visual" material="gray" mesh="thigh_mirror_1"/>
          <geom name="//unnamed_geom_62" class="collision" size="0.101486 0.0116733 0.0161996" pos="0 0 -0.0973719" quat="0.707107 0 0.707107 0" type="box"/>
          <body name="RR_calf" pos="-0.000538679 -0.00184929 -0.194939" quat="1 0.000374159 -0.000363886 -4.34255e-05">
            <inertial pos="0.00479203 0.000901333 -0.129073" quat="0.696416 -0.00196821 -0.0031023 0.717629" mass="0.205463" diaginertia="0.000932265 0.00177325 3.5278e-05"/>
            <joint name="RR_calf_joint" pos="0 0 0" axis="-0.00358994 -0.99999 0.00269194" stiffness="0.00773628" range="0.863057 2.76185" armature="0.00941532" damping="0.0126262" frictionloss="0.192672"/>
            <geom name="//unnamed_geom_63" class="visual" material="gray" mesh="calf_mirror_0"/>
            <geom name="//unnamed_geom_64" class="visual" material="black" mesh="calf_mirror_1"/>
            <geom name="RR_calf0" class="collision" size="0.012388 0.0571752" pos="0.00909463 0 -0.0548574" quat="0.995004 0 -0.0998334 0" type="cylinder"/>
            <geom name="//unnamed_geom_66" class="collision" size="0.0104821 0.0309699" pos="0.0181893 0 -0.135315" quat="0.999688 0 0.0249974 0" type="cylinder"/>
            <geom name="//unnamed_geom_67" class="visual" pos="0 0 -0.194744" quat="1 0 0 0" material="black" mesh="foot"/>
            <geom name="RR_foot" class="foot" size="0.0208284" pos="-0.00181893 0 -0.194744"/>
            <geom name="//unnamed_geom_69" class="reward_collision_sphere" size="0.023823"/>
            <geom name="//unnamed_geom_70" class="reward_collision_sphere" size="0.023823" pos="-0.00181893 0 -0.194744"/>
            <site name="RR_foot" class="foot" pos="-0.00181893 0 -0.194744" size="0.0095292"/>
          </body>
        </body>
      </body>
    </body>
  </worldbody>

  <contact>
    <pair class="/" geom1="floor" geom2="FL_foot" name="//unnamed_contact_0"/>
    <pair class="/" geom1="floor" geom2="FR_foot" name="//unnamed_contact_1"/>
    <pair class="/" geom1="floor" geom2="RL_foot" name="//unnamed_contact_2"/>
    <pair class="/" geom1="floor" geom2="RR_foot" name="//unnamed_contact_3"/>
  </contact>

  <actuator>
    <general name="FL_hip" class="/" joint="FL_hip_joint" forcerange="-22.7981 22.7981" gainprm="20.1788" biasprm="0 -20.1788 -0.464944"/>
    <general name="FL_thigh" class="/" joint="FL_thigh_joint" forcerange="-20.5863 20.5863" gainprm="20.1788" biasprm="0 -20.1788 -0.464944"/>
    <general name="FL_calf" class="/" joint="FL_calf_joint" forcerange="-41.7959 41.7959" gainprm="20.1788" biasprm="0 -20.1788 -0.464944"/>
    <general name="FR_hip" class="/" joint="FR_hip_joint" forcerange="-23.2699 23.2699" gainprm="20.1788" biasprm="0 -20.1788 -0.464944"/>
    <general name="FR_thigh" class="/" joint="FR_thigh_joint" forcerange="-21.6181 21.6181" gainprm="20.1788" biasprm="0 -20.1788 -0.464944"/>
    <general name="FR_calf" class="/" joint="FR_calf_joint" forcerange="-44.4524 44.4524" gainprm="20.1788" biasprm="0 -20.1788 -0.464944"/>
    <general name="RL_hip" class="/" joint="RL_hip_joint" forcerange="-22.8568 22.8568" gainprm="20.1788" biasprm="0 -20.1788 -0.464944"/>
    <general name="RL_thigh" class="/" joint="RL_thigh_joint" forcerange="-22.6223 22.6223" gainprm="20.1788" biasprm="0 -20.1788 -0.464944"/>
    <general name="RL_calf" class="/" joint="RL_calf_joint" forcerange="-44.1855 44.1855" gainprm="20.1788" biasprm="0 -20.1788 -0.464944"/>
    <general name="RR_hip" class="/" joint="RR_hip_joint" forcerange="-20.5767 20.5767" gainprm="20.1788" biasprm="0 -20.1788 -0.464944"/>
    <general name="RR_thigh" class="/" joint="RR_thigh_joint" forcerange="-22.6326 22.6326" gainprm="20.1788" biasprm="0 -20.1788 -0.464944"/>
    <general name="RR_calf" class="/" joint="RR_calf_joint" forcerange="-43.4226 43.4226" gainprm="20.1788" biasprm="0 -20.1788 -0.464944"/>
  </actuator>

  <sensor>
    <gyro site="imu" name="imu_angular_velocity"/>
    <velocimeter site="imu" name="imu_linear_velocity"/>
    <framelinvel objtype="site" objname="FL_foot" name="FL_foot_global_linear_velocity"/>
    <framelinvel objtype="site" objname="FR_foot" name="FR_foot_global_linear_velocity"/>
    <framelinvel objtype="site" objname="RL_foot" name="RL_foot_global_linear_velocity"/>
    <framelinvel objtype="site" objname="RR_foot" name="RR_foot_global_linear_velocity"/>
  </sensor>

  <keyframe>
    <key name="home" qpos="0 0 0.325 1 0 0 0 0.1 0.8 -1.5 -0.1 -0.8 1.5 -0.1 0.8 -1.5 0.1 -0.8 1.5"/>
  </keyframe>
</mujoco>
