<mujoco model="Golem">
  <compiler angle="radian" assetdir="assets" balanceinertia="true" inertiafromgeom="false"/>

  <option timestep="0.005" density="1.2" viscosity="2e-05"/>

  <size nkey="1"/>

  <visual>
    <quality shadowsize="8192"/>
    <map shadowclip="0.5"/>
  </visual>

  <default>
    <default class="/">
      <joint armature="0.01" damping="0.01" frictionloss="0.01"/>
      <geom contype="0" conaffinity="0" group="1" solref="-1000 -80"/>
      <site size="0.01 0.005 0.005" group="5"/>
      <general forcelimited="true" biastype="affine" gainprm="25" biasprm="0 -25 -0.5"/>
      <default class="visual">
        <geom type="mesh" group="2"/>
      </default>
      <default class="collision">
        <geom group="3"/>
      </default>
      <default class="foot">
        <geom size="0.01 0 0" condim="6" group="4" priority="1" solimp="0.015 1 0.01"/>
      </default>
      <default class="reward_collision_sphere">
        <geom group="5" rgba="1 0 0 1"/>
      </default>
    </default>
  </default>

  <asset>
    <texture type="skybox" colorspace="auto" name="//unnamed_texture_0" builtin="gradient" rgb1="0.95 0.95 0.95" rgb2="0.95 0.95 0.95" width="100" height="600"/>
    <texture type="2d" colorspace="auto" name="texplane" builtin="checker" rgb1="0.345 0.575 0.748" rgb2="0.345 0.575 0.748" markrgb="1 1 1" width="512" height="512"/>
    <material name="MatPlane" class="/" texture="texplane" texuniform="true" texrepeat="2 2" specular="0.9"/>
    <mesh name="body" class="/" file="body.stl" scale="0.001 0.001 0.001"/>
    <mesh name="coxa" class="/" file="coxa.stl" scale="0.001 0.001 0.001"/>
    <mesh name="femur" class="/" file="femur.stl" scale="0.001 0.001 0.001"/>
    <mesh name="tibia" class="/" file="tibia.stl" scale="0.001 0.001 0.001"/>
    <mesh name="tarsus" class="/" file="tarsus.stl" scale="0.001 0.001 0.001"/>
  </asset>

  <worldbody>
    <geom name="floor" class="/" size="100 100 0.125" type="plane" group="0" material="MatPlane"/>
    <light name="toplight_shadow" class="/" pos="0 0 5" dir="0.0990148 0.0990148 -0.990148" type="directional" ambient="0.04 0.04 0.04" diffuse="0.55 0.55 0.55" specular="0.12 0.12 0.12"/>
    <light name="toplight_fill" class="/" pos="0 0 5" dir="0.0990148 0.0990148 -0.990148" type="directional" castshadow="false" ambient="0.04 0.04 0.04" diffuse="0.3 0.3 0.3" specular="0.08 0.08 0.08"/>
    <body name="trunk" pos="0.000617541 -0.000780848 0.00105884" quat="1 -0.000104911 -0.000435439 -0.00028299">
      <inertial pos="0.00224955 -0.00149108 -0.000852039" quat="0.999998 -9.72552e-05 0.000296199 0.00185671" mass="2.93293" diaginertia="0.0103154 0.000715445 0.0217034"/>
      <joint name="//unnamed_joint_0" type="free"/>
      <geom name="//unnamed_geom_1" class="/" pos="0 0 0.0739916" quat="1 0 0 0" type="mesh" rgba="0.9 0.9 0.9 1" mesh="body"/>
      <site name="imu" class="/" pos="0.130657 -0.00267894 0.102791" size="0.0091211"/>
      <camera name="track" class="/" pos="0 -1.17361 0" quat="0.707107 0.707107 0 0" mode="trackcom"/>
      <camera name="ego_camera" class="/" pos="0.129143 0 0.115612" quat="-0.5 -0.5 0.5 0.5"/>
      <body name="coxa_RR" pos="-0.175785 -0.0498331 0.0751162" quat="0.382863 -3.43225e-06 -0.000127588 -0.923805">
        <inertial pos="9.00769e-05 -0.000429449 0.000849258" quat="0.999999 -0.000919245 -0.000959662 0.000474199" mass="0.15074" diaginertia="0.00963091 0.00068925 0.0204039"/>
        <joint name="coxa_joint_RR" class="/" pos="0 0 0" axis="0.00941111 0.00232363 -0.999953" range="-3.16192 3.14238" armature="0.00886845" damping="0" frictionloss="0.00907183"/>
        <geom name="//unnamed_geom_2" class="/" type="mesh" rgba="0.2 0.2 0.2 1" mesh="coxa"/>
        <geom name="//unnamed_geom_3" class="reward_collision_sphere" size="0.0364844" pos="-0.0298022 0 0"/>
        <body name="femur_RR" pos="0.0615573 0.00119122 0.0012089" quat="0.499825 -0.500196 0.500006 0.499973">
          <inertial pos="-0.00110537 -0.000412099 -0.000613932" quat="0.999998 -0.000725043 0.000619222 -0.00173145" mass="0.148982" diaginertia="0.009697 0.000677394 0.0201292"/>
          <joint name="femur_joint_RR" class="/" pos="0 0 0" axis="-0.0129082 -0.00357521 -0.99991" range="-3.13799 3.12106" armature="0.00910557" damping="0.000586073" frictionloss="0.0090133"/>
          <geom name="//unnamed_geom_4" class="/" type="mesh" rgba="0.9 0.9 0.9 1" mesh="femur"/>
          <geom name="//unnamed_geom_5" class="reward_collision_sphere" size="0.0364844"/>
          <body name="tibia_RR" pos="-0.00114961 -0.0637563 -0.00164241" quat="5.38967e-05 1 -7.00295e-05 -9.20489e-05">
            <inertial pos="-0.000420821 -0.00245876 0.000304365" quat="0.999913 -0.00524239 0.011779 0.00260978" mass="0.151861" diaginertia="0.00989196 0.000693582 0.0202693"/>
            <joint name="tibia_joint_RR" class="/" pos="0 0 0" axis="-0.00038305 0.00811426 0.999967" range="-3.11454 3.15994" armature="0.00908247" damping="0.00655256" frictionloss="0.00941605"/>
            <geom name="//unnamed_geom_6" class="/" type="mesh" rgba="0.2 0.2 0.2 1" mesh="tibia"/>
            <geom name="//unnamed_geom_7" class="reward_collision_sphere" size="0.0364844"/>
            <body name="tarsus_RR" pos="0.0858835 -0.0026679 -0.00142576" quat="1 -0.000184854 -5.90508e-05 0.000155946">
              <inertial pos="0.0596936 0.000714069 -0.00137005" quat="0.504546 0.497419 0.506748 0.491136" mass="0.156812" diaginertia="0.00986632 0.000706855 0.0202435"/>
              <joint name="tarsus_joint_RR" class="/" pos="0 0 0" axis="-0.00142568 -0.000285586 0.999999" range="-3.16393 3.15233" armature="0.00956966" damping="0.000258328" frictionloss="0.010008"/>
              <geom name="//unnamed_geom_8" class="/" type="mesh" rgba="0.9 0.9 0.9 1" mesh="tarsus"/>
              <geom name="foot_1" class="foot" size="0.00914637" pos="0.111262 0 0" quat="0 -0.707107 0 0.707107"/>
              <geom name="//unnamed_geom_10" class="reward_collision_sphere" size="0.0364844"/>
              <geom name="//unnamed_geom_11" class="reward_collision_sphere" size="0.0136816" pos="0.106791 0 0"/>
              <site name="foot_1" class="foot" pos="0.111262 0 0" quat="0 -0.707107 0 0.707107" size="0.0091211"/>
            </body>
          </body>
        </body>
      </body>
      <body name="coxa_RM" pos="-0.00119793 -0.0793927 0.0737877" quat="0.707596 0.000471613 -0.000785498 -0.706616">
        <inertial pos="0.00173085 0.000232848 -0.00181032" quat="1 -0.000236357 -0.000152111 9.37714e-06" mass="0.153395" diaginertia="0.00969502 0.000712476 0.02049"/>
        <joint name="coxa_joint_RM" class="/" pos="0 0 0" axis="0.00297887 -0.000689165 -0.999995" range="-3.13115 3.14384" armature="0.00989381" damping="0.0188492" frictionloss="0.00879717"/>
        <geom name="//unnamed_geom_12" class="/" type="mesh" rgba="0.2 0.2 0.2 1" mesh="coxa"/>
        <geom name="//unnamed_geom_13" class="reward_collision_sphere" size="0.0364844" pos="-0.0298022 0 0"/>
        <body name="femur_RM" pos="0.0563022 -0.00291378 0.0013566" quat="0.4999 -0.499576 0.500246 0.500278">
          <inertial pos="0.00255632 -0.00113261 -0.000193235" quat="0.999991 0.00188821 0.00342632 -0.00150188" mass="0.146861" diaginertia="0.00908291 0.000673045 0.0193527"/>
          <joint name="femur_joint_RM" class="/" pos="0 0 0" axis="0.00694546 -0.00122097 -0.999975" range="-3.13496 3.08834" armature="0.0086661" damping="0.0167052" frictionloss="0.008934"/>
          <geom name="//unnamed_geom_14" class="/" type="mesh" rgba="0.9 0.9 0.9 1" mesh="femur"/>
          <geom name="//unnamed_geom_15" class="reward_collision_sphere" size="0.0364844"/>
          <body name="tibia_RM" pos="-0.000244855 -0.060845 -0.000878348" quat="0.000174615 1 0.000376182 3.56231e-05">
            <inertial pos="-0.0009383 0.00285136 0.000372175" quat="0.999992 -0.00247432 0.00169982 -0.00251747" mass="0.148875" diaginertia="0.009605 0.000687512 0.0203518"/>
            <joint name="tibia_joint_RM" class="/" pos="0 0 0" axis="-0.00168595 -0.0015797 0.999997" range="-3.12877 3.15944" armature="0.00957081" damping="0.0214457" frictionloss="0.00922034"/>
            <geom name="//unnamed_geom_16" class="/" type="mesh" rgba="0.2 0.2 0.2 1" mesh="tibia"/>
            <geom name="//unnamed_geom_17" class="reward_collision_sphere" size="0.0364844"/>
            <body name="tarsus_RM" pos="0.084651 -0.00156406 0.000304814" quat="1 -3.22558e-05 1.71857e-05 -4.80124e-05">
              <inertial pos="0.0619081 -0.000153698 -0.000759076" quat="0.501691 0.500602 0.499677 0.498024" mass="0.156699" diaginertia="0.00966349 0.000695173 0.0213425"/>
              <joint name="tarsus_joint_RM" class="/" pos="0 0 0" axis="-0.00216487 0.00587856 0.99998" range="-3.17636 3.09574" armature="0.0092578" damping="0.00688151" frictionloss="0.00827803"/>
              <geom name="//unnamed_geom_18" class="/" type="mesh" rgba="0.9 0.9 0.9 1" mesh="tarsus"/>
              <geom name="foot_2" class="foot" size="0.00958906" pos="0.111262 0 0" quat="0 -0.707107 0 0.707107"/>
              <geom name="//unnamed_geom_20" class="reward_collision_sphere" size="0.0364844"/>
              <geom name="//unnamed_geom_21" class="reward_collision_sphere" size="0.0136816" pos="0.106791 0 0"/>
              <site name="foot_2" class="foot" pos="0.111262 0 0" quat="0 -0.707107 0 0.707107" size="0.0091211"/>
            </body>
          </body>
        </body>
      </body>
      <body name="coxa_RF" pos="0.177228 -0.0512193 0.0768232" quat="0.923852 0.000105157 -0.000172142 -0.382749">
        <inertial pos="0.00120843 -0.0025996 0.0020424" quat="0.99992 0.0074825 0.000374912 0.0101739" mass="0.145112" diaginertia="0.00956672 0.00068188 0.0202911"/>
        <joint name="coxa_joint_RF" class="/" pos="0 0 0" axis="7.4376e-05 -0.00690444 -0.999976" range="-3.08687 3.1433" armature="0.00813528" damping="0" frictionloss="0.00894646"/>
        <geom name="//unnamed_geom_22" class="/" type="mesh" rgba="0.2 0.2 0.2 1" mesh="coxa"/>
        <geom name="//unnamed_geom_23" class="reward_collision_sphere" size="0.0364844" pos="-0.0298022 0 0"/>
        <body name="femur_RF" pos="0.0599727 -0.00031908 -0.000997314" quat="0.500042 -0.499938 0.50006 0.49996">
          <inertial pos="-0.00157252 0.0024037 0.000545684" quat="0.999987 0.00237079 0.00407104 -0.00197655" mass="0.151855" diaginertia="0.0100006 0.000717865 0.0215893"/>
          <joint name="femur_joint_RF" class="/" pos="0 0 0" axis="-0.000182367 -0.000268998 -1" range="-3.14591 3.13706" armature="0.00917276" damping="0.00689253" frictionloss="0.00910721"/>
          <geom name="//unnamed_geom_24" class="/" type="mesh" rgba="0.9 0.9 0.9 1" mesh="femur"/>
          <geom name="//unnamed_geom_25" class="reward_collision_sphere" size="0.0364844"/>
          <body name="tibia_RF" pos="0.000387822 -0.064029 -0.000495616" quat="4.01491e-05 1 -3.21481e-05 0.00020813">
            <inertial pos="5.75789e-05 -0.00027338 -0.00268214" quat="0.999933 0.00127403 0.00601777 -0.00983511" mass="0.154007" diaginertia="0.00992461 0.000682454 0.0214275"/>
            <joint name="tibia_joint_RF" class="/" pos="0 0 0" axis="-0.00405954 -0.00328821 0.999986" range="-3.14765 3.14652" armature="0.00913889" damping="0.00979778" frictionloss="0.00937357"/>
            <geom name="//unnamed_geom_26" class="/" type="mesh" rgba="0.2 0.2 0.2 1" mesh="tibia"/>
            <geom name="//unnamed_geom_27" class="reward_collision_sphere" size="0.0364844"/>
            <body name="tarsus_RF" pos="0.0873206 0.000188626 -0.000122317" quat="1 -3.98481e-05 0.000867865 -0.000200259">
              <inertial pos="0.0597366 -0.000760309 -0.000996917" quat="0.499337 0.498894 0.501836 0.499928" mass="0.153965" diaginertia="0.00989575 0.000681268 0.0201769"/>
              <joint name="tarsus_joint_RF" class="/" pos="0 0 0" axis="-0.00316736 0.000786769 0.999995" stiffness="0.0237376" range="-3.10186 3.14153" armature="0.00856175" damping="0" frictionloss="0.00874921"/>
              <geom name="//unnamed_geom_28" class="/" type="mesh" rgba="0.9 0.9 0.9 1" mesh="tarsus"/>
              <geom name="foot_3" class="foot" size="0.009417" pos="0.111262 0 0" quat="0 -0.707107 0 0.707107"/>
              <geom name="//unnamed_geom_30" class="reward_collision_sphere" size="0.0364844"/>
              <geom name="//unnamed_geom_31" class="reward_collision_sphere" size="0.0136816" pos="0.106791 0 0"/>
              <site name="foot_3" class="foot" pos="0.111262 0 0" quat="0 -0.707107 0 0.707107" size="0.0091211"/>
            </body>
          </body>
        </body>
      </body>
      <body name="coxa_LR" pos="-0.17467 0.0503998 0.0755305" quat="0.382401 -0.000146253 -2.93781e-06 0.923997">
        <inertial pos="-0.00135638 -0.0023135 -0.00066544" quat="0.99996 -0.00793355 -0.00274551 0.00314254" mass="0.147386" diaginertia="0.00979186 0.000667913 0.0195699"/>
        <joint name="coxa_joint_LR" class="/" pos="0 0 0" axis="-0.00157877 -0.000970094 -0.999998" range="-3.14995 3.13653" armature="0.00891948" damping="0.0193201" frictionloss="0.00936298"/>
        <geom name="//unnamed_geom_32" class="/" type="mesh" rgba="0.2 0.2 0.2 1" mesh="coxa"/>
        <geom name="//unnamed_geom_33" class="reward_collision_sphere" size="0.0364844" pos="-0.0298022 0 0"/>
        <body name="femur_LR" pos="0.0620582 -0.00368072 0.000121034" quat="0.499494 -0.500165 0.499953 0.500387">
          <inertial pos="-0.000181628 -0.00272503 -0.000686436" quat="1 5.22372e-05 4.67132e-05 0.000129988" mass="0.151193" diaginertia="0.00934452 0.000706799 0.0199431"/>
          <joint name="femur_joint_LR" class="/" pos="0 0 0" axis="0.000117002 -0.00017962 1" range="-3.0915 3.13927" armature="0.00916167" damping="0" frictionloss="0.00909495"/>
          <geom name="//unnamed_geom_34" class="/" type="mesh" rgba="0.9 0.9 0.9 1" mesh="femur"/>
          <geom name="//unnamed_geom_35" class="reward_collision_sphere" size="0.0364844"/>
          <body name="tibia_LR" pos="0.0019668 -0.0662643 -0.00348419" quat="-0.000170359 1 4.85945e-05 -0.00019414">
            <inertial pos="0.000441274 -0.00193606 0.000175096" quat="0.999932 -0.00679269 0.00613502 -0.0071615" mass="0.14921" diaginertia="0.0093079 0.000680302 0.0204017"/>
            <joint name="tibia_joint_LR" class="/" pos="0 0 0" axis="0.000709789 0.000985674 -0.999999" range="-3.13035 3.18897" armature="0.00866374" damping="0" frictionloss="0.00911218"/>
            <geom name="//unnamed_geom_36" class="/" type="mesh" rgba="0.2 0.2 0.2 1" mesh="tibia"/>
            <geom name="//unnamed_geom_37" class="reward_collision_sphere" size="0.0364844"/>
            <body name="tarsus_LR" pos="0.0870988 0.00216761 -0.00206894" quat="1 -0.000436554 6.72228e-05 0.000603807">
              <inertial pos="0.0624347 -0.0022882 -0.00225207" quat="0.498169 0.501388 0.499901 0.500537" mass="0.152159" diaginertia="0.00958628 0.000690548 0.0199544"/>
              <joint name="tarsus_joint_LR" class="/" pos="0 0 0" axis="0.00878802 -0.012302 -0.999886" range="-3.13222 3.12286" armature="0.00841573" damping="0" frictionloss="0.00876781"/>
              <geom name="//unnamed_geom_38" class="/" type="mesh" rgba="0.9 0.9 0.9 1" mesh="tarsus"/>
              <geom name="foot_4" class="foot" size="0.0100718" pos="0.111262 0 0" quat="0.707107 0 -0.707107 0"/>
              <geom name="//unnamed_geom_40" class="reward_collision_sphere" size="0.0364844"/>
              <geom name="//unnamed_geom_41" class="reward_collision_sphere" size="0.0136816" pos="0.106791 0 0"/>
              <site name="foot_4" class="foot" pos="0.111262 0 0" quat="0.707107 0 -0.707107 0" size="0.0091211"/>
            </body>
          </body>
        </body>
      </body>
      <body name="coxa_LM" pos="-0.00340275 0.0775485 0.0753747" quat="0.707085 0.000187 0.000541134 0.707129">
        <inertial pos="0.00123623 -0.0016024 -0.00036587" quat="0.999931 -0.00917959 -0.00120107 0.00724994" mass="0.152759" diaginertia="0.00987465 0.00071861 0.0213331"/>
        <joint name="coxa_joint_LM" class="/" pos="0 0 0" axis="0.0103075 -0.00830534 -0.999912" range="-3.12881 3.11758" armature="0.00868231" damping="0.00778718" frictionloss="0.0095194"/>
        <geom name="//unnamed_geom_42" class="/" type="mesh" rgba="0.2 0.2 0.2 1" mesh="coxa"/>
        <geom name="//unnamed_geom_43" class="reward_collision_sphere" size="0.0364844" pos="-0.0298022 0 0"/>
        <body name="femur_LM" pos="0.0537821 0.00134616 -0.00104598" quat="0.499977 -0.499939 0.500218 0.499866">
          <inertial pos="0.00138697 0.000455655 0.00105806" quat="0.999961 -0.00301505 -0.0076481 0.00337386" mass="0.154585" diaginertia="0.00958825 0.000735009 0.0213839"/>
          <joint name="femur_joint_LM" class="/" pos="0 0 0" axis="-0.00285328 0.000459827 0.999996" range="-3.16024 3.1446" armature="0.00951767" damping="0.00375317" frictionloss="0.00848705"/>
          <geom name="//unnamed_geom_44" class="/" type="mesh" rgba="0.9 0.9 0.9 1" mesh="femur"/>
          <geom name="//unnamed_geom_45" class="reward_collision_sphere" size="0.0364844"/>
          <body name="tibia_LM" pos="-0.00119774 -0.0586235 0.00108285" quat="0.000169309 1 0.000547087 -0.000786752">
            <inertial pos="0.00085454 0.000137203 -0.00229126" quat="0.999925 -0.00805554 -0.00754046 -0.00532982" mass="0.151796" diaginertia="0.00967375 0.000723676 0.0210697"/>
            <joint name="tibia_joint_LM" class="/" pos="0 0 0" axis="0.00397333 -0.00187185 -0.99999" range="-3.13436 3.13785" armature="0.00927483" damping="0" frictionloss="0.00819405"/>
            <geom name="//unnamed_geom_46" class="/" type="mesh" rgba="0.2 0.2 0.2 1" mesh="tibia"/>
            <geom name="//unnamed_geom_47" class="reward_collision_sphere" size="0.0364844"/>
            <body name="tarsus_LM" pos="0.0859802 -0.000378853 -0.000180671" quat="1 -0.000500794 6.9477e-05 -0.000852906">
              <inertial pos="0.060566 -0.00128862 0.000470369" quat="0.499238 0.503648 0.490274 0.506686" mass="0.156125" diaginertia="0.00998646 0.000700652 0.0206269"/>
              <joint name="tarsus_joint_LM" class="/" pos="0 0 0" axis="0.00412355 0.0104111 -0.999937" stiffness="0.00351273" range="-3.1358 3.13174" armature="0.00895941" damping="0" frictionloss="0.0102319"/>
              <geom name="//unnamed_geom_48" class="/" type="mesh" rgba="0.9 0.9 0.9 1" mesh="tarsus"/>
              <geom name="foot_5" class="foot" size="0.00906114" pos="0.111262 0 0" quat="0.707107 0 -0.707107 0"/>
              <geom name="//unnamed_geom_50" class="reward_collision_sphere" size="0.0364844"/>
              <geom name="//unnamed_geom_51" class="reward_collision_sphere" size="0.0136816" pos="0.106791 0 0"/>
              <site name="foot_5" class="foot" pos="0.111262 0 0" quat="0.707107 0 -0.707107 0" size="0.0091211"/>
            </body>
          </body>
        </body>
      </body>
      <body name="coxa_LF" pos="0.179099 0.0479956 0.0722807" quat="0.923775 -0.000262273 8.47871e-05 0.382935">
        <inertial pos="-0.000558225 0.000415273 0.00240056" quat="0.999963 -0.0070591 0.00485368 7.83086e-05" mass="0.148826" diaginertia="0.00931083 0.000712584 0.0202075"/>
        <joint name="coxa_joint_LF" class="/" pos="0 0 0" axis="-0.0115291 0.00916406 -0.999892" range="-3.12612 3.13765" armature="0.00814903" damping="0" frictionloss="0.010318"/>
        <geom name="//unnamed_geom_52" class="/" type="mesh" rgba="0.2 0.2 0.2 1" mesh="coxa"/>
        <geom name="//unnamed_geom_53" class="reward_collision_sphere" size="0.0364844" pos="-0.0298022 0 0"/>
        <body name="femur_LF" pos="0.0591286 0.00055765 0.000347447" quat="0.499926 -0.500088 0.500105 0.49988">
          <inertial pos="-0.00270046 -6.5683e-05 0.00259327" quat="0.999998 -0.0014206 0.00115828 0.000177222" mass="0.152871" diaginertia="0.0100466 0.000699115 0.0207117"/>
          <joint name="femur_joint_LF" class="/" pos="0 0 0" axis="-0.00201187 -0.00285965 0.999994" range="-3.12844 3.12853" armature="0.00955279" damping="0" frictionloss="0.0086429"/>
          <geom name="//unnamed_geom_54" class="/" type="mesh" rgba="0.9 0.9 0.9 1" mesh="femur"/>
          <geom name="//unnamed_geom_55" class="reward_collision_sphere" size="0.0364844"/>
          <body name="tibia_LF" pos="-0.000486203 -0.0626895 0.000299971" quat="0.000104762 1 -0.000179005 -0.000284751">
            <inertial pos="0.000335026 -0.00239632 0.000270813" quat="1 -0.00017211 -0.000285942 0.000472479" mass="0.145769" diaginertia="0.00905088 0.000674671 0.0197625"/>
            <joint name="tibia_joint_LF" class="/" pos="0 0 0" axis="-0.00459985 0.0002227 -0.999989" range="-3.1414 3.13529" armature="0.00983287" damping="0" frictionloss="0.00926975"/>
            <geom name="//unnamed_geom_56" class="/" type="mesh" rgba="0.2 0.2 0.2 1" mesh="tibia"/>
            <geom name="//unnamed_geom_57" class="reward_collision_sphere" size="0.0364844"/>
            <body name="tarsus_LF" pos="0.0854502 0.000781483 0.00197327" quat="1 0.000154455 -0.000158996 0.00019793">
              <inertial pos="0.0593665 0.00119232 0.000535627" quat="0.497868 0.503579 0.496927 0.501598" mass="0.143375" diaginertia="0.00928346 0.0006558 0.0198956"/>
              <joint name="tarsus_joint_LF" class="/" pos="0 0 0" axis="0.00136135 -9.2283e-05 -0.999999" stiffness="0.000824769" range="-3.15728 3.13394" armature="0.0100916" damping="0.011912" frictionloss="0.00791702"/>
              <geom name="//unnamed_geom_58" class="/" type="mesh" rgba="0.9 0.9 0.9 1" mesh="tarsus"/>
              <geom name="foot_6" class="foot" size="0.00881502" pos="0.111262 0 0" quat="0.707107 0 -0.707107 0"/>
              <geom name="//unnamed_geom_60" class="reward_collision_sphere" size="0.0364844"/>
              <geom name="//unnamed_geom_61" class="reward_collision_sphere" size="0.0136816" pos="0.106791 0 0"/>
              <site name="foot_6" class="foot" pos="0.111262 0 0" quat="0.707107 0 -0.707107 0" size="0.0091211"/>
            </body>
          </body>
        </body>
      </body>
    </body>
  </worldbody>

  <contact>
    <pair class="/" geom1="floor" geom2="foot_1" name="//unnamed_contact_0"/>
    <pair class="/" geom1="floor" geom2="foot_2" name="//unnamed_contact_1"/>
    <pair class="/" geom1="floor" geom2="foot_3" name="//unnamed_contact_2"/>
    <pair class="/" geom1="floor" geom2="foot_4" name="//unnamed_contact_3"/>
    <pair class="/" geom1="floor" geom2="foot_5" name="//unnamed_contact_4"/>
    <pair class="/" geom1="floor" geom2="foot_6" name="//unnamed_contact_5"/>
  </contact>

  <actuator>
    <general name="coxa_joint_RR" class="/" joint="coxa_joint_RR" forcerange="-6.85364 6.85364" gainprm="22.9759" biasprm="0 -22.9759 -0.4871"/>
    <general name="femur_joint_RR" class="/" joint="femur_joint_RR" forcerange="-6.62233 6.62233" gainprm="22.9759" biasprm="0 -22.9759 -0.4871"/>
    <general name="tibia_joint_RR" class="/" joint="tibia_joint_RR" forcerange="-6.91529 6.91529" gainprm="22.9759" biasprm="0 -22.9759 -0.4871"/>
    <general name="tarsus_joint_RR" class="/" joint="tarsus_joint_RR" forcerange="-7.25195 7.25195" gainprm="22.9759" biasprm="0 -22.9759 -0.4871"/>
    <general name="coxa_joint_RM" class="/" joint="coxa_joint_RM" forcerange="-6.67368 6.67368" gainprm="22.9759" biasprm="0 -22.9759 -0.4871"/>
    <general name="femur_joint_RM" class="/" joint="femur_joint_RM" forcerange="-6.65327 6.65327" gainprm="22.9759" biasprm="0 -22.9759 -0.4871"/>
    <general name="tibia_joint_RM" class="/" joint="tibia_joint_RM" forcerange="-6.577 6.577" gainprm="22.9759" biasprm="0 -22.9759 -0.4871"/>
    <general name="tarsus_joint_RM" class="/" joint="tarsus_joint_RM" forcerange="-7.31439 7.31439" gainprm="22.9759" biasprm="0 -22.9759 -0.4871"/>
    <general name="coxa_joint_RF" class="/" joint="coxa_joint_RF" forcerange="-6.75912 6.75912" gainprm="22.9759" biasprm="0 -22.9759 -0.4871"/>
    <general name="femur_joint_RF" class="/" joint="femur_joint_RF" forcerange="-6.01751 6.01751" gainprm="22.9759" biasprm="0 -22.9759 -0.4871"/>
    <general name="tibia_joint_RF" class="/" joint="tibia_joint_RF" forcerange="-6.93578 6.93578" gainprm="22.9759" biasprm="0 -22.9759 -0.4871"/>
    <general name="tarsus_joint_RF" class="/" joint="tarsus_joint_RF" forcerange="-6.30914 6.30914" gainprm="22.9759" biasprm="0 -22.9759 -0.4871"/>
    <general name="coxa_joint_LR" class="/" joint="coxa_joint_LR" forcerange="-6.46813 6.46813" gainprm="22.9759" biasprm="0 -22.9759 -0.4871"/>
    <general name="femur_joint_LR" class="/" joint="femur_joint_LR" forcerange="-6.78752 6.78752" gainprm="22.9759" biasprm="0 -22.9759 -0.4871"/>
    <general name="tibia_joint_LR" class="/" joint="tibia_joint_LR" forcerange="-6.62071 6.62071" gainprm="22.9759" biasprm="0 -22.9759 -0.4871"/>
    <general name="tarsus_joint_LR" class="/" joint="tarsus_joint_LR" forcerange="-6.45931 6.45931" gainprm="22.9759" biasprm="0 -22.9759 -0.4871"/>
    <general name="coxa_joint_LM" class="/" joint="coxa_joint_LM" forcerange="-6.84701 6.84701" gainprm="22.9759" biasprm="0 -22.9759 -0.4871"/>
    <general name="femur_joint_LM" class="/" joint="femur_joint_LM" forcerange="-6.38636 6.38636" gainprm="22.9759" biasprm="0 -22.9759 -0.4871"/>
    <general name="tibia_joint_LM" class="/" joint="tibia_joint_LM" forcerange="-6.8163 6.8163" gainprm="22.9759" biasprm="0 -22.9759 -0.4871"/>
    <general name="tarsus_joint_LM" class="/" joint="tarsus_joint_LM" forcerange="-6.89097 6.89097" gainprm="22.9759" biasprm="0 -22.9759 -0.4871"/>
    <general name="coxa_joint_LF" class="/" joint="coxa_joint_LF" forcerange="-6.07722 6.07722" gainprm="22.9759" biasprm="0 -22.9759 -0.4871"/>
    <general name="femur_joint_LF" class="/" joint="femur_joint_LF" forcerange="-6.4626 6.4626" gainprm="22.9759" biasprm="0 -22.9759 -0.4871"/>
    <general name="tibia_joint_LF" class="/" joint="tibia_joint_LF" forcerange="-6.84427 6.84427" gainprm="22.9759" biasprm="0 -22.9759 -0.4871"/>
    <general name="tarsus_joint_LF" class="/" joint="tarsus_joint_LF" forcerange="-6.85302 6.85302" gainprm="22.9759" biasprm="0 -22.9759 -0.4871"/>
  </actuator>

  <sensor>
    <gyro site="imu" name="imu_angular_velocity"/>
    <velocimeter site="imu" name="imu_linear_velocity"/>
    <framelinvel objtype="site" objname="foot_1" name="foot_1_global_linear_velocity"/>
    <framelinvel objtype="site" objname="foot_2" name="foot_2_global_linear_velocity"/>
    <framelinvel objtype="site" objname="foot_3" name="foot_3_global_linear_velocity"/>
    <framelinvel objtype="site" objname="foot_4" name="foot_4_global_linear_velocity"/>
    <framelinvel objtype="site" objname="foot_5" name="foot_5_global_linear_velocity"/>
    <framelinvel objtype="site" objname="foot_6" name="foot_6_global_linear_velocity"/>
  </sensor>

  <keyframe>
    <key name="home" qpos="0 0 0.1457 1 0 0 0 0 0 0 0 0 0 0 0 0 0 0 0 0 0 0 0 0 0 0 0 0 0 0 0"/>
  </keyframe>
</mujoco>
