<mujoco model="Golem">
  <compiler angle="radian" assetdir="assets" balanceinertia="true" inertiafromgeom="false"/>

  <option timestep="0.005" density="1.2" viscosity="2e-05"/>

  <size nkey="1"/>

  <visual>
    <quality shadowsize="8192"/>
    <map shadowclip="0.5"/>
  </visual>

  <default>
    <default class="/">
      <joint armature="0.01" damping="0.01" frictionloss="0.01"/>
      <geom contype="0" conaffinity="0" group="1" solref="-1000 -80"/>
      <site size="0.01 0.005 0.005" group="5"/>
      <general forcelimited="true" biastype="affine" gainprm="25" biasprm="0 -25 -0.5"/>
      <default class="visual">
        <geom type="mesh" group="2"/>
      </default>
      <default class="collision">
        <geom group="3"/>
      </default>
      <default class="foot">
        <geom size="0.01 0 0" condim="6" group="4" priority="1" solimp="0.015 1 0.01"/>
      </default>
      <default class="reward_collision_sphere">
        <geom group="5" rgba="1 0 0 1"/>
      </default>
    </default>
  </default>

  <asset>
    <texture type="skybox" colorspace="auto" name="//unnamed_texture_0" builtin="gradient" rgb1="0.95 0.95 0.95" rgb2="0.95 0.95 0.95" width="100" height="600"/>
    <texture type="2d" colorspace="auto" name="texplane" builtin="checker" rgb1="0.345 0.575 0.748" rgb2="0.345 0.575 0.748" markrgb="1 1 1" width="512" height="512"/>
    <material name="MatPlane" class="/" texture="texplane" texuniform="true" texrepeat="2 2" specular="0.9"/>
    <mesh name="body" class="/" file="body.stl" scale="0.001 0.001 0.001"/>
    <mesh name="coxa" class="/" file="coxa.stl" scale="0.001 0.001 0.001"/>
    <mesh name="femur" class="/" file="femur.stl" scale="0.001 0.001 0.001"/>
    <mesh name="tibia" class="/" file="tibia.stl" scale="0.001 0.001 0.001"/>
    <mesh name="tarsus" class="/" file="tarsus.stl" scale="0.001 0.001 0.001"/>
  </asset>

  <worldbody>
    <geom name="floor" class="/" size="100 100 0.125" type="plane" group="0" material="MatPlane"/>
    <light name="toplight_shadow" class="/" pos="0 0 5" dir="0.0990148 0.0990148 -0.990148" type="directional" ambient="0.04 0.04 0.04" diffuse="0.55 0.55 0.55" specular="0.12 0.12 0.12"/>
    <light name="toplight_fill" class="/" pos="0 0 5" dir="0.0990148 0.0990148 -0.990148" type="directional" castshadow="false" ambient="0.04 0.04 0.04" diffuse="0.3 0.3 0.3" specular="0.08 0.08 0.08"/>
    <body name="trunk" pos="-0.000400183 0.000271646 0.00030435" quat="1 -4.54226e-05 -5.42588e-05 0.000141535">
      <inertial pos="0.000511119 -0.00107397 -0.00154547" quat="0.999991 -0.000747427 0.00355932 0.00198022" mass="2.81933" diaginertia="0.00884855 0.00104364 0.0180074"/>
      <joint name="//unnamed_joint_0" type="free"/>
      <geom name="//unnamed_geom_1" class="/" pos="0 0 0.0716804" quat="1 0 0 0" type="mesh" rgba="0.9 0.9 0.9 1" mesh="body"/>
      <site name="imu" class="/" pos="0.127714 0.00222746 0.104882" size="0.00906779"/>
      <camera name="track" class="/" pos="0 -1.26505 0" quat="0.707107 0.707107 0 0" mode="trackcom"/>
      <camera name="ego_camera" class="/" pos="0.125815 0 0.112001" quat="-0.5 -0.5 0.5 0.5"/>
      <body name="coxa_RR" pos="-0.172701 -0.0531872 0.0730911" quat="0.382723 -2.8526e-05 -0.000111068 -0.923863">
        <inertial pos="-0.000437445 0.000811728 0.0005658" quat="1 9.18684e-05 0.000125691 4.53952e-05" mass="0.149514" diaginertia="0.00855455 0.00103333 0.0175673"/>
        <joint name="coxa_joint_RR" class="/" pos="0 0 0" axis="0.00513223 0.00454114 -0.999977" range="-3.13157 3.1365" armature="0.00922713" damping="0" frictionloss="0.00911797"/>
        <geom name="//unnamed_geom_2" class="/" type="mesh" rgba="0.2 0.2 0.2 1" mesh="coxa"/>
        <geom name="//unnamed_geom_3" class="reward_collision_sphere" size="0.0362712" pos="-0.0290342 0 0"/>
        <body name="femur_RR" pos="0.0587673 -0.000189938 -0.00117573" quat="0.499753 -0.500241 0.499881 0.500126">
          <inertial pos="-0.000303365 -8.5768e-06 0.000741116" quat="0.999999 -0.000154125 -0.000809602 0.00132837" mass="0.147114" diaginertia="0.0085485 0.000996747 0.0172332"/>
          <joint name="femur_joint_RR" class="/" pos="0 0 0" axis="-0.0046929 0.00512358 -0.999976" range="-3.13923 3.12271" armature="0.0090774" damping="0.000832956" frictionloss="0.00862113"/>
          <geom name="//unnamed_geom_4" class="/" type="mesh" rgba="0.9 0.9 0.9 1" mesh="femur"/>
          <geom name="//unnamed_geom_5" class="reward_collision_sphere" size="0.0362712"/>
          <body name="tibia_RR" pos="0.00120849 -0.0690033 -0.00111183" quat="-4.73243e-06 1 -1.56554e-07 3.7314e-06">
            <inertial pos="-0.000154699 -0.00144251 0.000108401" quat="0.999965 -0.00745205 0.00300902 -0.00249799" mass="0.149259" diaginertia="0.00861069 0.00101632 0.017658"/>
            <joint name="tibia_joint_RR" class="/" pos="0 0 0" axis="0.000342712 -0.000203519 1" range="-3.14548 3.14523" armature="0.00918841" damping="0" frictionloss="0.00949379"/>
            <geom name="//unnamed_geom_6" class="/" type="mesh" rgba="0.2 0.2 0.2 1" mesh="tibia"/>
            <geom name="//unnamed_geom_7" class="reward_collision_sphere" size="0.0362712"/>
            <body name="tarsus_RR" pos="0.0819408 -0.00153985 0.00021639" quat="1 -0.00035039 2.17741e-05 -0.000174605">
              <inertial pos="0.0581657 0.000470178 0.000206591" quat="0.49951 0.503587 0.495556 0.501313" mass="0.150435" diaginertia="0.00851368 0.00100953 0.0174545"/>
              <joint name="tarsus_joint_RR" class="/" pos="0 0 0" axis="-1.97252e-05 -0.000444225 1" range="-3.13305 3.13186" armature="0.00934022" damping="0.00677497" frictionloss="0.00924484"/>
              <geom name="//unnamed_geom_8" class="/" type="mesh" rgba="0.9 0.9 0.9 1" mesh="tarsus"/>
              <geom name="foot_1" class="foot" size="0.00867942" pos="0.108394 0 0" quat="0 -0.707107 0 0.707107"/>
              <geom name="//unnamed_geom_10" class="reward_collision_sphere" size="0.0362712"/>
              <geom name="//unnamed_geom_11" class="reward_collision_sphere" size="0.0136017" pos="0.104039 0 0"/>
              <site name="foot_1" class="foot" pos="0.108394 0 0" quat="0 -0.707107 0 0.707107" size="0.00906779"/>
            </body>
          </body>
        </body>
      </body>
      <body name="coxa_RM" pos="0.000183876 -0.0842085 0.0723154" quat="0.707535 0.000470516 0.000462717 -0.706678">
        <inertial pos="0.000116601 -0.000185383 -0.000486165" quat="1 0.00023818 -4.37323e-05 9.47679e-05" mass="0.150295" diaginertia="0.00854001 0.00102166 0.0176018"/>
        <joint name="coxa_joint_RM" class="/" pos="0 0 0" axis="0.000508327 0.00190132 -0.999998" range="-3.13295 3.13596" armature="0.00908731" damping="0.00943886" frictionloss="0.0086539"/>
        <geom name="//unnamed_geom_12" class="/" type="mesh" rgba="0.2 0.2 0.2 1" mesh="coxa"/>
        <geom name="//unnamed_geom_13" class="reward_collision_sphere" size="0.0362712" pos="-0.0290342 0 0"/>
        <body name="femur_RM" pos="0.0561479 -0.00177235 0.00048909" quat="0.49984 -0.500186 0.499955 0.500019">
          <inertial pos="0.00157361 0.000379026 -0.000124248" quat="0.999991 -0.000861579 -0.00308671 0.00267541" mass="0.146882" diaginertia="0.00823168 0.000997827 0.0169969"/>
          <joint name="femur_joint_RM" class="/" pos="0 0 0" axis="0.00056372 -0.000778797 -1" range="-3.14386 3.11233" armature="0.00886381" damping="0.00657146" frictionloss="0.00943669"/>
          <geom name="//unnamed_geom_14" class="/" type="mesh" rgba="0.9 0.9 0.9 1" mesh="femur"/>
          <geom name="//unnamed_geom_15" class="reward_collision_sphere" size="0.0362712"/>
          <body name="tibia_RM" pos="0.000836308 -0.0672047 -0.000325777" quat="-9.18104e-06 1 8.98554e-05 -0.000284663">
            <inertial pos="0.000636472 0.00191419 0.000428948" quat="0.999995 -0.00179248 0.00161193 0.00194579" mass="0.150678" diaginertia="0.00857177 0.00102279 0.0177764"/>
            <joint name="tibia_joint_RM" class="/" pos="0 0 0" axis="-0.00165328 -0.000446593 0.999999" range="-3.1431 3.12938" armature="0.00936301" damping="0.0141259" frictionloss="0.00900098"/>
            <geom name="//unnamed_geom_16" class="/" type="mesh" rgba="0.2 0.2 0.2 1" mesh="tibia"/>
            <geom name="//unnamed_geom_17" class="reward_collision_sphere" size="0.0362712"/>
            <body name="tarsus_RM" pos="0.0829418 -0.000670772 0.00044086" quat="1 4.41193e-05 4.43417e-05 1.15119e-06">
              <inertial pos="0.0589721 6.28218e-05 -0.000471842" quat="0.49933 0.499931 0.500291 0.500447" mass="0.152854" diaginertia="0.00848709 0.00101907 0.0180749"/>
              <joint name="tarsus_joint_RM" class="/" pos="0 0 0" axis="-0.00033537 -0.00306243 0.999995" stiffness="0.00111755" range="-3.14493 3.12574" armature="0.00891984" damping="0.00816177" frictionloss="0.008941"/>
              <geom name="//unnamed_geom_18" class="/" type="mesh" rgba="0.9 0.9 0.9 1" mesh="tarsus"/>
              <geom name="foot_2" class="foot" size="0.00898792" pos="0.108394 0 0" quat="0 -0.707107 0 0.707107"/>
              <geom name="//unnamed_geom_20" class="reward_collision_sphere" size="0.0362712"/>
              <geom name="//unnamed_geom_21" class="reward_collision_sphere" size="0.0136017" pos="0.104039 0 0"/>
              <site name="foot_2" class="foot" pos="0.108394 0 0" quat="0 -0.707107 0 0.707107" size="0.00906779"/>
            </body>
          </body>
        </body>
      </body>
      <body name="coxa_RF" pos="0.173288 -0.0530885 0.0732865" quat="0.923915 -0.000384621 -4.47845e-05 -0.382598">
        <inertial pos="0.000318741 -0.00147032 0.000531955" quat="0.999978 0.00475067 -0.00280346 0.00366386" mass="0.148298" diaginertia="0.00859878 0.00101441 0.0176391"/>
        <joint name="coxa_joint_RF" class="/" pos="0 0 0" axis="-0.000323992 0.000681477 -1" range="-3.10807 3.12132" armature="0.00877443" damping="0" frictionloss="0.00921118"/>
        <geom name="//unnamed_geom_22" class="/" type="mesh" rgba="0.2 0.2 0.2 1" mesh="coxa"/>
        <geom name="//unnamed_geom_23" class="reward_collision_sphere" size="0.0362712" pos="-0.0290342 0 0"/>
        <body name="femur_RF" pos="0.058376 0.00132905 -0.000222615" quat="0.499974 -0.500018 0.499966 0.500042">
          <inertial pos="6.32546e-05 0.00123394 1.79201e-05" quat="0.999996 -0.00265881 0.0011225 -0.000409966" mass="0.149919" diaginertia="0.00877904 0.00103221 0.0181669"/>
          <joint name="femur_joint_RF" class="/" pos="0 0 0" axis="0.000254972 0.00177811 -0.999998" range="-3.14563 3.15686" armature="0.00898771" damping="0.0100723" frictionloss="0.00949529"/>
          <geom name="//unnamed_geom_24" class="/" type="mesh" rgba="0.9 0.9 0.9 1" mesh="femur"/>
          <geom name="//unnamed_geom_25" class="reward_collision_sphere" size="0.0362712"/>
          <body name="tibia_RF" pos="0.000773313 -0.0680886 -0.000607042" quat="-3.34131e-05 1 1.89162e-05 -2.37972e-05">
            <inertial pos="0.000347329 0.000220817 -0.00186565" quat="0.99999 0.00390196 0.00198296 0.0013537" mass="0.151169" diaginertia="0.0085921 0.00100473 0.0178611"/>
            <joint name="tibia_joint_RF" class="/" pos="0 0 0" axis="0.00197409 -0.0038498 0.999991" stiffness="0.00102007" range="-3.13371 3.12202" armature="0.00890477" damping="0.0121794" frictionloss="0.00872931"/>
            <geom name="//unnamed_geom_26" class="/" type="mesh" rgba="0.2 0.2 0.2 1" mesh="tibia"/>
            <geom name="//unnamed_geom_27" class="reward_collision_sphere" size="0.0362712"/>
            <body name="tarsus_RF" pos="0.085657 0.000992594 -0.000849407" quat="1 -1.23966e-05 5.86841e-06 -0.000120056">
              <inertial pos="0.0587242 9.94265e-05 -0.000502367" quat="0.499619 0.501183 0.499903 0.499293" mass="0.147681" diaginertia="0.00849395 0.000990183 0.0171087"/>
              <joint name="tarsus_joint_RF" class="/" pos="0 0 0" axis="0.0014688 0.00327664 0.999994" stiffness="0.0231882" range="-3.13277 3.14146" armature="0.00902871" damping="0" frictionloss="0.00917559"/>
              <geom name="//unnamed_geom_28" class="/" type="mesh" rgba="0.9 0.9 0.9 1" mesh="tarsus"/>
              <geom name="foot_3" class="foot" size="0.00906301" pos="0.108394 0 0" quat="0 -0.707107 0 0.707107"/>
              <geom name="//unnamed_geom_30" class="reward_collision_sphere" size="0.0362712"/>
              <geom name="//unnamed_geom_31" class="reward_collision_sphere" size="0.0136017" pos="0.104039 0 0"/>
              <site name="foot_3" class="foot" pos="0.108394 0 0" quat="0 -0.707107 0 0.707107" size="0.00906779"/>
            </body>
          </body>
        </body>
      </body>
      <body name="coxa_LR" pos="-0.171083 0.0547016 0.0735444" quat="0.382764 0.000171754 0.000172137 0.923846">
        <inertial pos="0.000173862 -0.000778645 0.00101852" quat="0.999999 -0.00107923 0.000180347 2.94326e-06" mass="0.149683" diaginertia="0.00869381 0.00101155 0.0171974"/>
        <joint name="coxa_joint_LR" class="/" pos="0 0 0" axis="-0.00205011 2.74849e-05 -0.999998" range="-3.12427 3.11869" armature="0.00861408" damping="0.00578426" frictionloss="0.00910938"/>
        <geom name="//unnamed_geom_32" class="/" type="mesh" rgba="0.2 0.2 0.2 1" mesh="coxa"/>
        <geom name="//unnamed_geom_33" class="reward_collision_sphere" size="0.0362712" pos="-0.0290342 0 0"/>
        <body name="femur_LR" pos="0.0584619 -0.0025842 -0.000517081" quat="0.49974 -0.500163 0.499695 0.500402">
          <inertial pos="0.000314614 -0.00223548 0.000372236" quat="1 -0.000112938 -1.55132e-05 0.000259375" mass="0.149823" diaginertia="0.00832582 0.00101102 0.017239"/>
          <joint name="femur_joint_LR" class="/" pos="0 0 0" axis="0.0013149 0.00214921 0.999997" stiffness="0.00030456" range="-3.11742 3.13811" armature="0.00882296" damping="0" frictionloss="0.00903996"/>
          <geom name="//unnamed_geom_34" class="/" type="mesh" rgba="0.9 0.9 0.9 1" mesh="femur"/>
          <geom name="//unnamed_geom_35" class="reward_collision_sphere" size="0.0362712"/>
          <body name="tibia_LR" pos="0.0018664 -0.0690712 -0.00350762" quat="-0.00019831 1 -0.000131799 0.000286911">
            <inertial pos="-0.000942819 -0.000430828 0.000983113" quat="0.999989 0.0010623 -0.000200394 0.00448732" mass="0.149914" diaginertia="0.00842642 0.00101927 0.0176196"/>
            <joint name="tibia_joint_LR" class="/" pos="0 0 0" axis="-0.00286329 0.00149377 -0.999995" stiffness="0.00125585" range="-3.15522 3.164" armature="0.00874539" damping="0" frictionloss="0.00904116"/>
            <geom name="//unnamed_geom_36" class="/" type="mesh" rgba="0.2 0.2 0.2 1" mesh="tibia"/>
            <geom name="//unnamed_geom_37" class="reward_collision_sphere" size="0.0362712"/>
            <body name="tarsus_LR" pos="0.0854277 -2.96003e-05 -0.000756057" quat="1 -5.05582e-06 4.79505e-06 -4.81212e-05">
              <inertial pos="0.0602168 -0.00124082 -0.000999723" quat="0.495865 0.502298 0.500867 0.500945" mass="0.148758" diaginertia="0.00839086 0.00102387 0.0173893"/>
              <joint name="tarsus_joint_LR" class="/" pos="0 0 0" axis="0.00298616 -0.00930158 -0.999952" range="-3.11825 3.151" armature="0.00903751" damping="0" frictionloss="0.00935093"/>
              <geom name="//unnamed_geom_38" class="/" type="mesh" rgba="0.9 0.9 0.9 1" mesh="tarsus"/>
              <geom name="foot_4" class="foot" size="0.0097199" pos="0.108394 0 0" quat="0.707107 0 -0.707107 0"/>
              <geom name="//unnamed_geom_40" class="reward_collision_sphere" size="0.0362712"/>
              <geom name="//unnamed_geom_41" class="reward_collision_sphere" size="0.0136017" pos="0.104039 0 0"/>
              <site name="foot_4" class="foot" pos="0.108394 0 0" quat="0.707107 0 -0.707107 0" size="0.00906779"/>
            </body>
          </body>
        </body>
      </body>
      <body name="coxa_LM" pos="-0.00281619 0.0832152 0.0739067" quat="0.707118 1.27056e-05 -0.000127527 0.707096">
        <inertial pos="0.000844991 -3.39162e-05 -0.000590486" quat="0.999988 0.0018609 7.60636e-05 -0.00447636" mass="0.151469" diaginertia="0.00860476 0.00103494 0.0180366"/>
        <joint name="coxa_joint_LM" class="/" pos="0 0 0" axis="0.0106598 -1.7691e-05 -0.999943" range="-3.14458 3.13534" armature="0.00875029" damping="0.00632572" frictionloss="0.00881177"/>
        <geom name="//unnamed_geom_42" class="/" type="mesh" rgba="0.2 0.2 0.2 1" mesh="coxa"/>
        <geom name="//unnamed_geom_43" class="reward_collision_sphere" size="0.0362712" pos="-0.0290342 0 0"/>
        <body name="femur_LM" pos="0.0525688 0.00189903 -0.000310154" quat="0.500042 -0.499928 0.499891 0.500138">
          <inertial pos="-0.000198539 -0.000253022 0.000551471" quat="0.999999 0.000693731 0.000732927 3.91942e-05" mass="0.147749" diaginertia="0.00838722 0.00103663 0.017831"/>
          <joint name="femur_joint_LM" class="/" pos="0 0 0" axis="-0.00224173 -0.00109654 0.999997" stiffness="1.52792e-05" range="-3.15101 3.14767" armature="0.00893127" damping="0" frictionloss="0.0091466"/>
          <geom name="//unnamed_geom_44" class="/" type="mesh" rgba="0.9 0.9 0.9 1" mesh="femur"/>
          <geom name="//unnamed_geom_45" class="reward_collision_sphere" size="0.0362712"/>
          <body name="tibia_LM" pos="0.00089029 -0.0653673 0.00205286" quat="0.000298672 1 -9.20219e-05 -0.000158377">
            <inertial pos="-0.000645684 -0.00120737 -0.000883757" quat="0.999983 -0.00206156 -0.00111907 0.00527607" mass="0.148139" diaginertia="0.00845663 0.00102953 0.0176291"/>
            <joint name="tibia_joint_LM" class="/" pos="0 0 0" axis="-0.00126116 -0.0014378 -0.999998" range="-3.14266 3.1397" armature="0.00897429" damping="0.00123066" frictionloss="0.00884084"/>
            <geom name="//unnamed_geom_46" class="/" type="mesh" rgba="0.2 0.2 0.2 1" mesh="tibia"/>
            <geom name="//unnamed_geom_47" class="reward_collision_sphere" size="0.0362712"/>
            <body name="tarsus_LM" pos="0.0864386 -0.000687314 -0.000819652" quat="1 -0.000306956 -8.56586e-05 0.000195832">
              <inertial pos="0.05784 0.000509254 -0.000829702" quat="0.499127 0.505105 0.497381 0.498351" mass="0.149995" diaginertia="0.00864115 0.00101801 0.0175173"/>
              <joint name="tarsus_joint_LM" class="/" pos="0 0 0" axis="0.00526756 0.00382744 -0.999979" range="-3.1292 3.13193" armature="0.00900879" damping="0.00214085" frictionloss="0.00957792"/>
              <geom name="//unnamed_geom_48" class="/" type="mesh" rgba="0.9 0.9 0.9 1" mesh="tarsus"/>
              <geom name="foot_5" class="foot" size="0.00904453" pos="0.108394 0 0" quat="0.707107 0 -0.707107 0"/>
              <geom name="//unnamed_geom_50" class="reward_collision_sphere" size="0.0362712"/>
              <geom name="//unnamed_geom_51" class="reward_collision_sphere" size="0.0136017" pos="0.104039 0 0"/>
              <site name="foot_5" class="foot" pos="0.108394 0 0" quat="0.707107 0 -0.707107 0" size="0.00906779"/>
            </body>
          </body>
        </body>
      </body>
      <body name="coxa_LF" pos="0.173333 0.0522603 0.0717526" quat="0.923905 -7.12288e-05 2.71691e-05 0.382621">
        <inertial pos="0.000322049 -0.000190069 0.00103609" quat="1 -0.000605819 0.000267195 0.000107251" mass="0.150193" diaginertia="0.00837368 0.00102985 0.0177211"/>
        <joint name="coxa_joint_LF" class="/" pos="0 0 0" axis="0.00558988 -0.00577088 -0.999968" range="-3.14664 3.1389" armature="0.00883448" damping="0.00880924" frictionloss="0.00997416"/>
        <geom name="//unnamed_geom_52" class="/" type="mesh" rgba="0.2 0.2 0.2 1" mesh="coxa"/>
        <geom name="//unnamed_geom_53" class="reward_collision_sphere" size="0.0362712" pos="-0.0290342 0 0"/>
        <body name="femur_LF" pos="0.0576637 0.000254532 0.000287663" quat="0.499987 -0.499958 0.50003 0.500024">
          <inertial pos="-0.00193685 0.000602513 0.00199504" quat="0.999999 -0.00129681 -0.000930375 -0.000297529" mass="0.150759" diaginertia="0.00861675 0.00101825 0.0176512"/>
          <joint name="femur_joint_LF" class="/" pos="0 0 0" axis="-0.00154902 0.000325904 0.999999" range="-3.14232 3.13761" armature="0.00884486" damping="0" frictionloss="0.00896344"/>
          <geom name="//unnamed_geom_54" class="/" type="mesh" rgba="0.9 0.9 0.9 1" mesh="femur"/>
          <geom name="//unnamed_geom_55" class="reward_collision_sphere" size="0.0362712"/>
          <body name="tibia_LF" pos="-0.000554921 -0.0680525 0.00086636" quat="-0.000118898 1 0.000222403 0.000301226">
            <inertial pos="0.000944136 -0.00185212 -0.000695652" quat="1 0.00014172 -0.000169514 0.000111744" mass="0.143532" diaginertia="0.00809313 0.00098405 0.0169978"/>
            <joint name="tibia_joint_LF" class="/" pos="0 0 0" axis="0.00154895 0.00431198 -0.99999" stiffness="0.00194544" range="-3.1343 3.14971" armature="0.00898762" damping="0" frictionloss="0.00891936"/>
            <geom name="//unnamed_geom_56" class="/" type="mesh" rgba="0.2 0.2 0.2 1" mesh="tibia"/>
            <geom name="//unnamed_geom_57" class="reward_collision_sphere" size="0.0362712"/>
            <body name="tarsus_LF" pos="0.083973 0.000764065 0.00119563" quat="1 -1.77873e-05 -0.000154155 7.40599e-05">
              <inertial pos="0.0584742 -0.000297001 -0.000437593" quat="0.500287 0.49969 0.501463 0.498556" mass="0.145078" diaginertia="0.0081905 0.00098241 0.016992"/>
              <joint name="tarsus_joint_LF" class="/" pos="0 0 0" axis="-0.00505591 0.00219278 -0.999985" range="-3.13798 3.14158" armature="0.00925281" damping="0.0148773" frictionloss="0.0082596"/>
              <geom name="//unnamed_geom_58" class="/" type="mesh" rgba="0.9 0.9 0.9 1" mesh="tarsus"/>
              <geom name="foot_6" class="foot" size="0.00871194" pos="0.108394 0 0" quat="0.707107 0 -0.707107 0"/>
              <geom name="//unnamed_geom_60" class="reward_collision_sphere" size="0.0362712"/>
              <geom name="//unnamed_geom_61" class="reward_collision_sphere" size="0.0136017" pos="0.104039 0 0"/>
              <site name="foot_6" class="foot" pos="0.108394 0 0" quat="0.707107 0 -0.707107 0" size="0.00906779"/>
            </body>
          </body>
        </body>
      </body>
    </body>
  </worldbody>

  <contact>
    <pair class="/" geom1="floor" geom2="foot_1" name="//unnamed_contact_0"/>
    <pair class="/" geom1="floor" geom2="foot_2" name="//unnamed_contact_1"/>
    <pair class="/" geom1="floor" geom2="foot_3" name="//unnamed_contact_2"/>
    <pair class="/" geom1="floor" geom2="foot_4" name="//unnamed_contact_3"/>
    <pair class="/" geom1="floor" geom2="foot_5" name="//unnamed_contact_4"/>
    <pair class="/" geom1="floor" geom2="foot_6" name="//unnamed_contact_5"/>
  </contact>

  <actuator>
    <general name="coxa_joint_RR" class="/" joint="coxa_joint_RR" forcerange="-6.83916 6.83916" gainprm="21.9851" biasprm="0 -21.9851 -0.485909"/>
    <general name="femur_joint_RR" class="/" joint="femur_joint_RR" forcerange="-6.50464 6.50464" gainprm="21.9851" biasprm="0 -21.9851 -0.485909"/>
    <general name="tibia_joint_RR" class="/" joint="tibia_joint_RR" forcerange="-6.76473 6.76473" gainprm="21.9851" biasprm="0 -21.9851 -0.485909"/>
    <general name="tarsus_joint_RR" class="/" joint="tarsus_joint_RR" forcerange="-6.87013 6.87013" gainprm="21.9851" biasprm="0 -21.9851 -0.485909"/>
    <general name="coxa_joint_RM" class="/" joint="coxa_joint_RM" forcerange="-6.74576 6.74576" gainprm="21.9851" biasprm="0 -21.9851 -0.485909"/>
    <general name="femur_joint_RM" class="/" joint="femur_joint_RM" forcerange="-6.6036 6.6036" gainprm="21.9851" biasprm="0 -21.9851 -0.485909"/>
    <general name="tibia_joint_RM" class="/" joint="tibia_joint_RM" forcerange="-6.65442 6.65442" gainprm="21.9851" biasprm="0 -21.9851 -0.485909"/>
    <general name="tarsus_joint_RM" class="/" joint="tarsus_joint_RM" forcerange="-7.02879 7.02879" gainprm="21.9851" biasprm="0 -21.9851 -0.485909"/>
    <general name="coxa_joint_RF" class="/" joint="coxa_joint_RF" forcerange="-6.41685 6.41685" gainprm="21.9851" biasprm="0 -21.9851 -0.485909"/>
    <general name="femur_joint_RF" class="/" joint="femur_joint_RF" forcerange="-6.2632 6.2632" gainprm="21.9851" biasprm="0 -21.9851 -0.485909"/>
    <general name="tibia_joint_RF" class="/" joint="tibia_joint_RF" forcerange="-6.52118 6.52118" gainprm="21.9851" biasprm="0 -21.9851 -0.485909"/>
    <general name="tarsus_joint_RF" class="/" joint="tarsus_joint_RF" forcerange="-6.66089 6.66089" gainprm="21.9851" biasprm="0 -21.9851 -0.485909"/>
    <general name="coxa_joint_LR" class="/" joint="coxa_joint_LR" forcerange="-6.7776 6.7776" gainprm="21.9851" biasprm="0 -21.9851 -0.485909"/>
    <general name="femur_joint_LR" class="/" joint="femur_joint_LR" forcerange="-6.56532 6.56532" gainprm="21.9851" biasprm="0 -21.9851 -0.485909"/>
    <general name="tibia_joint_LR" class="/" joint="tibia_joint_LR" forcerange="-6.64897 6.64897" gainprm="21.9851" biasprm="0 -21.9851 -0.485909"/>
    <general name="tarsus_joint_LR" class="/" joint="tarsus_joint_LR" forcerange="-6.77212 6.77212" gainprm="21.9851" biasprm="0 -21.9851 -0.485909"/>
    <general name="coxa_joint_LM" class="/" joint="coxa_joint_LM" forcerange="-6.54631 6.54631" gainprm="21.9851" biasprm="0 -21.9851 -0.485909"/>
    <general name="femur_joint_LM" class="/" joint="femur_joint_LM" forcerange="-6.72307 6.72307" gainprm="21.9851" biasprm="0 -21.9851 -0.485909"/>
    <general name="tibia_joint_LM" class="/" joint="tibia_joint_LM" forcerange="-6.85473 6.85473" gainprm="21.9851" biasprm="0 -21.9851 -0.485909"/>
    <general name="tarsus_joint_LM" class="/" joint="tarsus_joint_LM" forcerange="-6.59742 6.59742" gainprm="21.9851" biasprm="0 -21.9851 -0.485909"/>
    <general name="coxa_joint_LF" class="/" joint="coxa_joint_LF" forcerange="-6.38894 6.38894" gainprm="21.9851" biasprm="0 -21.9851 -0.485909"/>
    <general name="femur_joint_LF" class="/" joint="femur_joint_LF" forcerange="-6.77352 6.77352" gainprm="21.9851" biasprm="0 -21.9851 -0.485909"/>
    <general name="tibia_joint_LF" class="/" joint="tibia_joint_LF" forcerange="-6.46027 6.46027" gainprm="21.9851" biasprm="0 -21.9851 -0.485909"/>
    <general name="tarsus_joint_LF" class="/" joint="tarsus_joint_LF" forcerange="-6.83744 6.83744" gainprm="21.9851" biasprm="0 -21.9851 -0.485909"/>
  </actuator>

  <sensor>
    <gyro site="imu" name="imu_angular_velocity"/>
    <velocimeter site="imu" name="imu_linear_velocity"/>
    <framelinvel objtype="site" objname="foot_1" name="foot_1_global_linear_velocity"/>
    <framelinvel objtype="site" objname="foot_2" name="foot_2_global_linear_velocity"/>
    <framelinvel objtype="site" objname="foot_3" name="foot_3_global_linear_velocity"/>
    <framelinvel objtype="site" objname="foot_4" name="foot_4_global_linear_velocity"/>
    <framelinvel objtype="site" objname="foot_5" name="foot_5_global_linear_velocity"/>
    <framelinvel objtype="site" objname="foot_6" name="foot_6_global_linear_velocity"/>
  </sensor>

  <keyframe>
    <key name="home" qpos="0 0 0.1457 1 0 0 0 0 0 0 0 0 0 0 0 0 0 0 0 0 0 0 0 0 0 0 0 0 0 0 0"/>
  </keyframe>
</mujoco>
