<mujoco model="Golem">
  <compiler angle="radian" assetdir="assets" balanceinertia="true" inertiafromgeom="false"/>

  <option timestep="0.005" density="1.2" viscosity="2e-05"/>

  <size nkey="1"/>

  <visual>
    <quality shadowsize="8192"/>
    <map shadowclip="0.5"/>
  </visual>

  <default>
    <default class="/">
      <joint armature="0.01" damping="0.01" frictionloss="0.01"/>
      <geom contype="0" conaffinity="0" group="1" solref="-1000 -80"/>
      <site size="0.01 0.005 0.005" group="5"/>
      <general forcelimited="true" biastype="affine" gainprm="25" biasprm="0 -25 -0.5"/>
      <default class="visual">
        <geom type="mesh" group="2"/>
      </default>
      <default class="collision">
        <geom group="3"/>
      </default>
      <default class="foot">
        <geom size="0.01 0 0" condim="6" group="4" priority="1" solimp="0.015 1 0.01"/>
      </default>
      <default class="reward_collision_sphere">
        <geom group="5" rgba="1 0 0 1"/>
      </default>
    </default>
  </default>

  <asset>
    <texture type="skybox" colorspace="auto" name="//unnamed_texture_0" builtin="gradient" rgb1="0.95 0.95 0.95" rgb2="0.95 0.95 0.95" width="100" height="600"/>
    <texture type="2d" colorspace="auto" name="texplane" builtin="checker" rgb1="0.345 0.575 0.748" rgb2="0.345 0.575 0.748" markrgb="1 1 1" width="512" height="512"/>
    <material name="MatPlane" class="/" texture="texplane" texuniform="true" texrepeat="2 2" specular="0.9"/>
    <mesh name="body" class="/" file="body.stl" scale="0.001 0.001 0.001"/>
    <mesh name="coxa" class="/" file="coxa.stl" scale="0.001 0.001 0.001"/>
    <mesh name="femur" class="/" file="femur.stl" scale="0.001 0.001 0.001"/>
    <mesh name="tibia" class="/" file="tibia.stl" scale="0.001 0.001 0.001"/>
    <mesh name="tarsus" class="/" file="tarsus.stl" scale="0.001 0.001 0.001"/>
  </asset>

  <worldbody>
    <geom name="floor" class="/" size="100 100 0.125" type="plane" group="0" material="MatPlane"/>
    <light name="toplight_shadow" class="/" pos="0 0 5" dir="0.0990148 0.0990148 -0.990148" type="directional" ambient="0.04 0.04 0.04" diffuse="0.55 0.55 0.55" specular="0.12 0.12 0.12"/>
    <light name="toplight_fill" class="/" pos="0 0 5" dir="0.0990148 0.0990148 -0.990148" type="directional" castshadow="false" ambient="0.04 0.04 0.04" diffuse="0.3 0.3 0.3" specular="0.08 0.08 0.08"/>
    <body name="trunk" pos="0.0024657 0.00230082 0.00201544" quat="1 1.56773e-05 6.67606e-06 -1.70426e-05">
      <inertial pos="0.000182082 -0.00107974 -0.00114689" quat="0.999999 -0.000924706 0.000169907 -0.000738882" mass="5.08781" diaginertia="0.0250064 0.00554491 0.0284921"/>
      <joint name="//unnamed_joint_0" type="free"/>
      <geom name="//unnamed_geom_1" class="/" pos="0 0 0.0788764" quat="1 0 0 0" type="mesh" rgba="0.9 0.9 0.9 1" mesh="body"/>
      <site name="imu" class="/" pos="0.171234 0.013679 0.123381" size="0.0111235"/>
      <camera name="track" class="/" pos="0 -1.7799 0" quat="0.707107 0.707107 0 0" mode="trackcom"/>
      <camera name="ego_camera" class="/" pos="0.157905 0 0.123244" quat="-0.5 -0.5 0.5 0.5"/>
      <body name="coxa_RR" pos="-0.216499 -0.0749939 0.0785252" quat="0.382648 3.79405e-05 -7.62902e-05 -0.923894">
        <inertial pos="-0.000492602 -0.00222333 -0.00087224" quat="0.999909 -0.000390196 -0.00407284 0.0128349" mass="0.264477" diaginertia="0.0252816 0.00533488 0.027145"/>
        <joint name="coxa_joint_RR" class="/" pos="0 0 0" axis="0.00235188 -0.000185766 -0.999997" range="-3.13348 3.14095" armature="0.00970355" damping="0" frictionloss="0.0111625"/>
        <geom name="//unnamed_geom_2" class="/" type="mesh" rgba="0.2 0.2 0.2 1" mesh="coxa"/>
        <geom name="//unnamed_geom_3" class="reward_collision_sphere" size="0.0444939" pos="-0.0364395 0 0"/>
        <body name="femur_RR" pos="0.0694028 -0.000925762 -0.00383832" quat="0.500109 -0.500111 0.499846 0.499934">
          <inertial pos="-0.00169803 -0.000959788 -0.000393616" quat="1 -0.000668052 -0.000202386 1.30419e-05" mass="0.276376" diaginertia="0.0266093 0.00560996 0.0292798"/>
          <joint name="femur_joint_RR" class="/" pos="0 0 0" axis="-0.00100072 -0.000534408 -0.999999" range="-3.19458 3.08548" armature="0.0113048" damping="0.00948716" frictionloss="0.0126776"/>
          <geom name="//unnamed_geom_4" class="/" type="mesh" rgba="0.9 0.9 0.9 1" mesh="femur"/>
          <geom name="//unnamed_geom_5" class="reward_collision_sphere" size="0.0444939"/>
          <body name="tibia_RR" pos="-0.00436887 -0.098913 0.00253448" quat="-0.000933846 0.999999 -0.00056076 -2.33816e-05">
            <inertial pos="-0.00276183 0.000726742 -0.000177819" quat="0.999999 0.000156313 -0.000276833 0.00161485" mass="0.27655" diaginertia="0.0259607 0.00543225 0.0267589"/>
            <joint name="tibia_joint_RR" class="/" pos="0 0 0" axis="-0.0100042 -0.00778774 0.99992" range="-3.11151 3.18678" armature="0.0117032" damping="0" frictionloss="0.0110829"/>
            <geom name="//unnamed_geom_6" class="/" type="mesh" rgba="0.2 0.2 0.2 1" mesh="tibia"/>
            <geom name="//unnamed_geom_7" class="reward_collision_sphere" size="0.0444939"/>
            <body name="tarsus_RR" pos="0.108589 -0.000366581 0.00221909" quat="1 2.98153e-05 2.88113e-07 1.5595e-05">
              <inertial pos="0.0763459 0.000523841 0.00161033" quat="0.498459 0.500425 0.501066 0.500047" mass="0.27835" diaginertia="0.0265353 0.00572663 0.0289077"/>
              <joint name="tarsus_joint_RR" class="/" pos="0 0 0" axis="-0.00672951 0.00147526 0.999976" range="-3.19388 3.18934" armature="0.0112388" damping="0.0411786" frictionloss="0.0101969"/>
              <geom name="//unnamed_geom_8" class="/" type="mesh" rgba="0.9 0.9 0.9 1" mesh="tarsus"/>
              <geom name="foot_1" class="foot" size="0.0112769" pos="0.136041 0 0" quat="0 -0.707107 0 0.707107"/>
              <geom name="//unnamed_geom_10" class="reward_collision_sphere" size="0.0444939"/>
              <geom name="//unnamed_geom_11" class="reward_collision_sphere" size="0.0166852" pos="0.130575 0 0"/>
              <site name="foot_1" class="foot" pos="0.136041 0 0" quat="0 -0.707107 0 0.707107" size="0.0111235"/>
            </body>
          </body>
        </body>
      </body>
      <body name="coxa_RM" pos="-0.000516694 -0.117804 0.0801577" quat="0.707065 0.00121243 -0.000105707 -0.707147">
        <inertial pos="0.00285494 0.000241492 -0.00121168" quat="0.999973 -0.00322199 -0.00531876 -0.00396481" mass="0.271758" diaginertia="0.0258954 0.00543945 0.0294733"/>
        <joint name="coxa_joint_RM" class="/" pos="0 0 0" axis="0.00191347 -0.00045451 -0.999998" stiffness="0.00777988" range="-3.15573 3.12164" armature="0.011001" damping="0.000543453" frictionloss="0.0100941"/>
        <geom name="//unnamed_geom_12" class="/" type="mesh" rgba="0.2 0.2 0.2 1" mesh="coxa"/>
        <geom name="//unnamed_geom_13" class="reward_collision_sphere" size="0.0444939" pos="-0.0364395 0 0"/>
        <body name="femur_RM" pos="0.0705644 0.00249965 -0.000728282" quat="0.498989 -0.499953 0.500618 0.500438">
          <inertial pos="-0.000552652 -0.00136177 0.000172855" quat="0.999996 -0.00189247 0.00213546 -0.000801152" mass="0.283032" diaginertia="0.0271861 0.00553784 0.0293918"/>
          <joint name="femur_joint_RM" class="/" pos="0 0 0" axis="-0.00114815 0.0110983 -0.999938" stiffness="0.00747831" range="-3.15569 3.14534" armature="0.0102319" damping="0.0256395" frictionloss="0.0110644"/>
          <geom name="//unnamed_geom_14" class="/" type="mesh" rgba="0.9 0.9 0.9 1" mesh="femur"/>
          <geom name="//unnamed_geom_15" class="reward_collision_sphere" size="0.0444939"/>
          <body name="tibia_RM" pos="0.00149225 -0.0944566 0.0021269" quat="1.06377e-07 1 -1.04857e-07 -3.17886e-07">
            <inertial pos="0.00267174 -0.00246582 0.000290279" quat="0.999908 0.00303248 -0.00551972 -0.0119975" mass="0.263397" diaginertia="0.0260224 0.00568407 0.0285449"/>
            <joint name="tibia_joint_RM" class="/" pos="0 0 0" axis="0.000573609 5.49431e-05 1" range="-3.19396 3.17661" armature="0.0109745" damping="0.0141992" frictionloss="0.010792"/>
            <geom name="//unnamed_geom_16" class="/" type="mesh" rgba="0.2 0.2 0.2 1" mesh="tibia"/>
            <geom name="//unnamed_geom_17" class="reward_collision_sphere" size="0.0444939"/>
            <body name="tarsus_RM" pos="0.106559 -0.000134599 0.00289743" quat="1 -5.74576e-06 -1.17934e-05 -2.1125e-05">
              <inertial pos="0.0726577 -0.0021466 0.0029741" quat="0.502073 0.507727 0.498668 0.491393" mass="0.283158" diaginertia="0.0255027 0.00541347 0.0274063"/>
              <joint name="tarsus_joint_RM" class="/" pos="0 0 0" axis="0.00024936 7.57842e-07 1" range="-3.0898 3.14113" armature="0.0118221" damping="0.0107772" frictionloss="0.0108523"/>
              <geom name="//unnamed_geom_18" class="/" type="mesh" rgba="0.9 0.9 0.9 1" mesh="tarsus"/>
              <geom name="foot_2" class="foot" size="0.0110824" pos="0.136041 0 0" quat="0 -0.707107 0 0.707107"/>
              <geom name="//unnamed_geom_20" class="reward_collision_sphere" size="0.0444939"/>
              <geom name="//unnamed_geom_21" class="reward_collision_sphere" size="0.0166852" pos="0.130575 0 0"/>
              <site name="foot_2" class="foot" pos="0.136041 0 0" quat="0 -0.707107 0 0.707107" size="0.0111235"/>
            </body>
          </body>
        </body>
      </body>
      <body name="coxa_RF" pos="0.214979 -0.0717704 0.0812998" quat="0.924083 -0.000289018 0.000136795 -0.382192">
        <inertial pos="3.65075e-05 0.00211658 0.000165144" quat="1 -2.77289e-05 -2.93801e-05 -5.975e-05" mass="0.27124" diaginertia="0.0264361 0.00555996 0.0276622"/>
        <joint name="coxa_joint_RF" class="/" pos="0 0 0" axis="0.00119339 -0.000809967 -0.999999" range="-3.13652 3.12996" armature="0.0126692" damping="0.00555263" frictionloss="0.010841"/>
        <geom name="//unnamed_geom_22" class="/" type="mesh" rgba="0.2 0.2 0.2 1" mesh="coxa"/>
        <geom name="//unnamed_geom_23" class="reward_collision_sphere" size="0.0444939" pos="-0.0364395 0 0"/>
        <body name="femur_RF" pos="0.0734814 -0.000866429 -0.00128167" quat="0.499677 -0.500092 0.500082 0.500149">
          <inertial pos="0.00125173 -0.00264544 -6.98372e-05" quat="0.99998 0.00338985 -0.00217733 0.00484847" mass="0.269684" diaginertia="0.0264278 0.00530696 0.028776"/>
          <joint name="femur_joint_RF" class="/" pos="0 0 0" axis="-0.00142378 0.000579979 -0.999999" stiffness="0.00674139" range="-3.18725 3.14216" armature="0.00944373" damping="0.00827547" frictionloss="0.0126761"/>
          <geom name="//unnamed_geom_24" class="/" type="mesh" rgba="0.9 0.9 0.9 1" mesh="femur"/>
          <geom name="//unnamed_geom_25" class="reward_collision_sphere" size="0.0444939"/>
          <body name="tibia_RF" pos="-0.0027774 -0.0969711 0.00150892" quat="-2.46467e-07 1 0.000188903 9.65592e-05">
            <inertial pos="-0.00199609 0.000301687 0.000785852" quat="1 -0.000146795 0.000664391 -0.000109242" mass="0.281671" diaginertia="0.0254419 0.00570012 0.0280306"/>
            <joint name="tibia_joint_RF" class="/" pos="0 0 0" axis="-0.00233184 0.0105133 0.999942" range="-3.13267 3.09184" armature="0.0107575" damping="0.0075111" frictionloss="0.0111792"/>
            <geom name="//unnamed_geom_26" class="/" type="mesh" rgba="0.2 0.2 0.2 1" mesh="tibia"/>
            <geom name="//unnamed_geom_27" class="reward_collision_sphere" size="0.0444939"/>
            <body name="tarsus_RF" pos="0.103707 0.00218844 0.00338938" quat="0.999999 -0.001157 -0.000561865 0.000127297">
              <inertial pos="0.0725509 -0.000714614 0.00029549" quat="0.499874 0.500093 0.500082 0.499951" mass="0.277282" diaginertia="0.0260437 0.00562291 0.0291404"/>
              <joint name="tarsus_joint_RF" class="/" pos="0 0 0" axis="-0.00331976 0.0135738 0.999902" range="-3.15924 3.1469" armature="0.0123903" damping="0.0138936" frictionloss="0.0101025"/>
              <geom name="//unnamed_geom_28" class="/" type="mesh" rgba="0.9 0.9 0.9 1" mesh="tarsus"/>
              <geom name="foot_3" class="foot" size="0.0121621" pos="0.136041 0 0" quat="0 -0.707107 0 0.707107"/>
              <geom name="//unnamed_geom_30" class="reward_collision_sphere" size="0.0444939"/>
              <geom name="//unnamed_geom_31" class="reward_collision_sphere" size="0.0166852" pos="0.130575 0 0"/>
              <site name="foot_3" class="foot" pos="0.136041 0 0" quat="0 -0.707107 0 0.707107" size="0.0111235"/>
            </body>
          </body>
        </body>
      </body>
      <body name="coxa_LR" pos="-0.218367 0.0752798 0.079397" quat="0.38291 9.30941e-05 7.81017e-05 0.923786">
        <inertial pos="-0.00247208 0.00147699 -0.00150556" quat="0.999932 0.00108354 -0.011545 0.000862646" mass="0.275284" diaginertia="0.0274337 0.005911 0.0295055"/>
        <joint name="coxa_joint_LR" class="/" pos="0 0 0" axis="-0.0151969 -0.00035238 -0.999884" stiffness="0.0103318" range="-3.13637 3.10025" armature="0.00987001" damping="0.00148092" frictionloss="0.00956441"/>
        <geom name="//unnamed_geom_32" class="/" type="mesh" rgba="0.2 0.2 0.2 1" mesh="coxa"/>
        <geom name="//unnamed_geom_33" class="reward_collision_sphere" size="0.0444939" pos="-0.0364395 0 0"/>
        <body name="femur_LR" pos="0.075804 -0.00262402 -0.00154737" quat="0.499976 -0.499963 0.500159 0.499902">
          <inertial pos="-0.000869831 -0.000905448 0.000542442" quat="0.999945 -0.000982367 -0.00479368 -0.00932784" mass="0.275028" diaginertia="0.0267434 0.00581014 0.0288223"/>
          <joint name="femur_joint_LR" class="/" pos="0 0 0" axis="-0.0119708 0.00258758 0.999925" range="-3.13879 3.14942" armature="0.0106694" damping="0" frictionloss="0.00991868"/>
          <geom name="//unnamed_geom_34" class="/" type="mesh" rgba="0.9 0.9 0.9 1" mesh="femur"/>
          <geom name="//unnamed_geom_35" class="reward_collision_sphere" size="0.0444939"/>
          <body name="tibia_LR" pos="-0.00185373 -0.0965649 0.00219187" quat="-0.000541194 0.999999 0.0012645 -1.2937e-05">
            <inertial pos="-0.000240014 -0.000124329 0.000207205" quat="0.999987 -0.0045338 0.00178198 -0.00179344" mass="0.282623" diaginertia="0.0269497 0.00571043 0.0294388"/>
            <joint name="tibia_joint_LR" class="/" pos="0 0 0" axis="0.00656708 0.00526437 -0.999965" range="-3.178 3.08312" armature="0.011473" damping="0.00562378" frictionloss="0.0107774"/>
            <geom name="//unnamed_geom_36" class="/" type="mesh" rgba="0.2 0.2 0.2 1" mesh="tibia"/>
            <geom name="//unnamed_geom_37" class="reward_collision_sphere" size="0.0444939"/>
            <body name="tarsus_LR" pos="0.105216 0.000442408 0.00304672" quat="0.999999 0.000984035 0.000170343 -0.000868101">
              <inertial pos="0.0758571 0.000357815 -0.00213218" quat="0.49973 0.499238 0.50022 0.50081" mass="0.267613" diaginertia="0.0265882 0.00541076 0.0287539"/>
              <joint name="tarsus_joint_LR" class="/" pos="0 0 0" axis="-0.00755406 -0.00705745 -0.999947" range="-3.19567 3.08335" armature="0.0106495" damping="0" frictionloss="0.0114479"/>
              <geom name="//unnamed_geom_38" class="/" type="mesh" rgba="0.9 0.9 0.9 1" mesh="tarsus"/>
              <geom name="foot_4" class="foot" size="0.0121661" pos="0.136041 0 0" quat="0.707107 0 -0.707107 0"/>
              <geom name="//unnamed_geom_40" class="reward_collision_sphere" size="0.0444939"/>
              <geom name="//unnamed_geom_41" class="reward_collision_sphere" size="0.0166852" pos="0.130575 0 0"/>
              <site name="foot_4" class="foot" pos="0.136041 0 0" quat="0.707107 0 -0.707107 0" size="0.0111235"/>
            </body>
          </body>
        </body>
      </body>
      <body name="coxa_LM" pos="0.00246675 0.11802 0.0813747" quat="0.70653 -0.00010019 -0.000693292 0.707683">
        <inertial pos="5.35805e-05 -0.00069652 -0.000978497" quat="0.999921 -0.00996645 0.00741434 -0.00192461" mass="0.272982" diaginertia="0.0255555 0.00546477 0.0282605"/>
        <joint name="coxa_joint_LM" class="/" pos="0 0 0" axis="-0.00406405 -0.00427525 -0.999983" range="-3.08345 3.12864" armature="0.0119543" damping="0.0209143" frictionloss="0.012682"/>
        <geom name="//unnamed_geom_42" class="/" type="mesh" rgba="0.2 0.2 0.2 1" mesh="coxa"/>
        <geom name="//unnamed_geom_43" class="reward_collision_sphere" size="0.0444939" pos="-0.0364395 0 0"/>
        <body name="femur_LM" pos="0.070727 0.00149728 0.00156878" quat="0.500469 -0.500196 0.500373 0.498961">
          <inertial pos="0.00164815 -0.00295984 0.00210368" quat="0.999923 -0.0104681 0.00623974 0.00247605" mass="0.2745" diaginertia="0.0270078 0.00543664 0.0286493"/>
          <joint name="femur_joint_LM" class="/" pos="0 0 0" axis="0.00905278 0.0113105 0.999895" range="-3.14406 3.08318" armature="0.0122651" damping="0" frictionloss="0.0111066"/>
          <geom name="//unnamed_geom_44" class="/" type="mesh" rgba="0.9 0.9 0.9 1" mesh="femur"/>
          <geom name="//unnamed_geom_45" class="reward_collision_sphere" size="0.0444939"/>
          <body name="tibia_LM" pos="-0.00236208 -0.0943634 -0.00236765" quat="0.000718895 0.999999 0.000565313 -0.000594523">
            <inertial pos="-0.00060926 -0.00292191 0.000338233" quat="0.999918 0.00281982 0.00262974 -0.0122049" mass="0.273213" diaginertia="0.0266228 0.00577905 0.0286222"/>
            <joint name="tibia_joint_LM" class="/" pos="0 0 0" axis="0.00040492 -0.00174892 -0.999998" range="-3.13176 3.14173" armature="0.0124821" damping="0.00358433" frictionloss="0.010014"/>
            <geom name="//unnamed_geom_46" class="/" type="mesh" rgba="0.2 0.2 0.2 1" mesh="tibia"/>
            <geom name="//unnamed_geom_47" class="reward_collision_sphere" size="0.0444939"/>
            <body name="tarsus_LM" pos="0.107678 1.59341e-05 0.00211951" quat="1 0.000767871 0.000314296 -0.00044974">
              <inertial pos="0.0702255 -0.000500241 -0.00190343" quat="0.499969 0.500083 0.499992 0.499956" mass="0.276722" diaginertia="0.0254196 0.0054822 0.0286293"/>
              <joint name="tarsus_joint_LM" class="/" pos="0 0 0" axis="-0.00294792 -0.00184775 -0.999994" range="-3.09673 3.12948" armature="0.0126657" damping="0.00440489" frictionloss="0.0117028"/>
              <geom name="//unnamed_geom_48" class="/" type="mesh" rgba="0.9 0.9 0.9 1" mesh="tarsus"/>
              <geom name="foot_5" class="foot" size="0.011625" pos="0.136041 0 0" quat="0.707107 0 -0.707107 0"/>
              <geom name="//unnamed_geom_50" class="reward_collision_sphere" size="0.0444939"/>
              <geom name="//unnamed_geom_51" class="reward_collision_sphere" size="0.0166852" pos="0.130575 0 0"/>
              <site name="foot_5" class="foot" pos="0.136041 0 0" quat="0.707107 0 -0.707107 0" size="0.0111235"/>
            </body>
          </body>
        </body>
      </body>
      <body name="coxa_LF" pos="0.218399 0.0768969 0.0764891" quat="0.923967 -0.000405818 -0.000213843 0.382472">
        <inertial pos="0.000193684 -0.000422005 -0.000835915" quat="0.999912 0.0044598 0.0115582 -0.0047802" mass="0.259684" diaginertia="0.025535 0.00544895 0.0279591"/>
        <joint name="coxa_joint_LF" class="/" pos="0 0 0" axis="-0.00272028 -0.00254636 -0.999993" stiffness="0.0118346" range="-3.16873 3.18103" armature="0.0125069" damping="0.00821224" frictionloss="0.0096766"/>
        <geom name="//unnamed_geom_52" class="/" type="mesh" rgba="0.2 0.2 0.2 1" mesh="coxa"/>
        <geom name="//unnamed_geom_53" class="reward_collision_sphere" size="0.0444939" pos="-0.0364395 0 0"/>
        <body name="femur_LF" pos="0.0730282 -0.00228704 0.000836265" quat="0.500225 -0.500794 0.499871 0.499108">
          <inertial pos="0.00220518 -0.000538268 -0.000393902" quat="0.999999 -0.000973786 -0.000222033 0.000829467" mass="0.278764" diaginertia="0.0264055 0.00554841 0.0275692"/>
          <joint name="femur_joint_LF" class="/" pos="0 0 0" axis="0.000216596 -0.0005708 1" range="-3.09087 3.12163" armature="0.0126638" damping="0.0192063" frictionloss="0.0113466"/>
          <geom name="//unnamed_geom_54" class="/" type="mesh" rgba="0.9 0.9 0.9 1" mesh="femur"/>
          <geom name="//unnamed_geom_55" class="reward_collision_sphere" size="0.0444939"/>
          <body name="tibia_LF" pos="-0.000895653 -0.0943003 0.00298037" quat="-0.000230829 1 -0.000215815 -8.40298e-05">
            <inertial pos="-0.000277151 0.00288707 0.00133485" quat="1 -0.000388359 -0.000249186 9.84568e-05" mass="0.269985" diaginertia="0.0264603 0.00553709 0.0283311"/>
            <joint name="tibia_joint_LF" class="/" pos="0 0 0" axis="-0.0051937 -0.00191368 -0.999985" range="-3.14481 3.12584" armature="0.00965947" damping="0" frictionloss="0.0121449"/>
            <geom name="//unnamed_geom_56" class="/" type="mesh" rgba="0.2 0.2 0.2 1" mesh="tibia"/>
            <geom name="//unnamed_geom_57" class="reward_collision_sphere" size="0.0444939"/>
            <body name="tarsus_LF" pos="0.10851 0.00186008 0.00112084" quat="0.999999 -0.000930757 0.000503435 0.000685862">
              <inertial pos="0.073693 -0.000365274 -0.00167052" quat="0.49058 0.500753 0.509737 0.498743" mass="0.281827" diaginertia="0.0261988 0.0057701 0.0290296"/>
              <joint name="tarsus_joint_LF" class="/" pos="0 0 0" axis="-0.00237292 0.00853409 -0.999961" stiffness="0.0258796" range="-3.19457 3.17099" armature="0.0109701" damping="0.0229228" frictionloss="0.0114605"/>
              <geom name="//unnamed_geom_58" class="/" type="mesh" rgba="0.9 0.9 0.9 1" mesh="tarsus"/>
              <geom name="foot_6" class="foot" size="0.0106478" pos="0.136041 0 0" quat="0.707107 0 -0.707107 0"/>
              <geom name="//unnamed_geom_60" class="reward_collision_sphere" size="0.0444939"/>
              <geom name="//unnamed_geom_61" class="reward_collision_sphere" size="0.0166852" pos="0.130575 0 0"/>
              <site name="foot_6" class="foot" pos="0.136041 0 0" quat="0.707107 0 -0.707107 0" size="0.0111235"/>
            </body>
          </body>
        </body>
      </body>
    </body>
  </worldbody>

  <contact>
    <pair class="/" geom1="floor" geom2="foot_1" name="//unnamed_contact_0"/>
    <pair class="/" geom1="floor" geom2="foot_2" name="//unnamed_contact_1"/>
    <pair class="/" geom1="floor" geom2="foot_3" name="//unnamed_contact_2"/>
    <pair class="/" geom1="floor" geom2="foot_4" name="//unnamed_contact_3"/>
    <pair class="/" geom1="floor" geom2="foot_5" name="//unnamed_contact_4"/>
    <pair class="/" geom1="floor" geom2="foot_6" name="//unnamed_contact_5"/>
  </contact>

  <actuator>
    <general name="coxa_joint_RR" class="/" joint="coxa_joint_RR" forcerange="-7.82934 7.82934" gainprm="26.3242" biasprm="0 -26.3242 -0.60134"/>
    <general name="femur_joint_RR" class="/" joint="femur_joint_RR" forcerange="-8.1648 8.1648" gainprm="26.3242" biasprm="0 -26.3242 -0.60134"/>
    <general name="tibia_joint_RR" class="/" joint="tibia_joint_RR" forcerange="-8.21287 8.21287" gainprm="26.3242" biasprm="0 -26.3242 -0.60134"/>
    <general name="tarsus_joint_RR" class="/" joint="tarsus_joint_RR" forcerange="-8.96772 8.96772" gainprm="26.3242" biasprm="0 -26.3242 -0.60134"/>
    <general name="coxa_joint_RM" class="/" joint="coxa_joint_RM" forcerange="-7.41045 7.41045" gainprm="26.3242" biasprm="0 -26.3242 -0.60134"/>
    <general name="femur_joint_RM" class="/" joint="femur_joint_RM" forcerange="-8.37505 8.37505" gainprm="26.3242" biasprm="0 -26.3242 -0.60134"/>
    <general name="tibia_joint_RM" class="/" joint="tibia_joint_RM" forcerange="-7.38673 7.38673" gainprm="26.3242" biasprm="0 -26.3242 -0.60134"/>
    <general name="tarsus_joint_RM" class="/" joint="tarsus_joint_RM" forcerange="-7.85634 7.85634" gainprm="26.3242" biasprm="0 -26.3242 -0.60134"/>
    <general name="coxa_joint_RF" class="/" joint="coxa_joint_RF" forcerange="-7.34123 7.34123" gainprm="26.3242" biasprm="0 -26.3242 -0.60134"/>
    <general name="femur_joint_RF" class="/" joint="femur_joint_RF" forcerange="-7.48447 7.48447" gainprm="26.3242" biasprm="0 -26.3242 -0.60134"/>
    <general name="tibia_joint_RF" class="/" joint="tibia_joint_RF" forcerange="-7.46768 7.46768" gainprm="26.3242" biasprm="0 -26.3242 -0.60134"/>
    <general name="tarsus_joint_RF" class="/" joint="tarsus_joint_RF" forcerange="-8.70139 8.70139" gainprm="26.3242" biasprm="0 -26.3242 -0.60134"/>
    <general name="coxa_joint_LR" class="/" joint="coxa_joint_LR" forcerange="-8.07512 8.07512" gainprm="26.3242" biasprm="0 -26.3242 -0.60134"/>
    <general name="femur_joint_LR" class="/" joint="femur_joint_LR" forcerange="-8.10611 8.10611" gainprm="26.3242" biasprm="0 -26.3242 -0.60134"/>
    <general name="tibia_joint_LR" class="/" joint="tibia_joint_LR" forcerange="-8.13642 8.13642" gainprm="26.3242" biasprm="0 -26.3242 -0.60134"/>
    <general name="tarsus_joint_LR" class="/" joint="tarsus_joint_LR" forcerange="-8.31017 8.31017" gainprm="26.3242" biasprm="0 -26.3242 -0.60134"/>
    <general name="coxa_joint_LM" class="/" joint="coxa_joint_LM" forcerange="-8.97319 8.97319" gainprm="26.3242" biasprm="0 -26.3242 -0.60134"/>
    <general name="femur_joint_LM" class="/" joint="femur_joint_LM" forcerange="-8.07851 8.07851" gainprm="26.3242" biasprm="0 -26.3242 -0.60134"/>
    <general name="tibia_joint_LM" class="/" joint="tibia_joint_LM" forcerange="-8.35976 8.35976" gainprm="26.3242" biasprm="0 -26.3242 -0.60134"/>
    <general name="tarsus_joint_LM" class="/" joint="tarsus_joint_LM" forcerange="-8.0839 8.0839" gainprm="26.3242" biasprm="0 -26.3242 -0.60134"/>
    <general name="coxa_joint_LF" class="/" joint="coxa_joint_LF" forcerange="-7.50349 7.50349" gainprm="26.3242" biasprm="0 -26.3242 -0.60134"/>
    <general name="femur_joint_LF" class="/" joint="femur_joint_LF" forcerange="-8.27053 8.27053" gainprm="26.3242" biasprm="0 -26.3242 -0.60134"/>
    <general name="tibia_joint_LF" class="/" joint="tibia_joint_LF" forcerange="-7.91752 7.91752" gainprm="26.3242" biasprm="0 -26.3242 -0.60134"/>
    <general name="tarsus_joint_LF" class="/" joint="tarsus_joint_LF" forcerange="-7.47321 7.47321" gainprm="26.3242" biasprm="0 -26.3242 -0.60134"/>
  </actuator>

  <sensor>
    <gyro site="imu" name="imu_angular_velocity"/>
    <velocimeter site="imu" name="imu_linear_velocity"/>
    <framelinvel objtype="site" objname="foot_1" name="foot_1_global_linear_velocity"/>
    <framelinvel objtype="site" objname="foot_2" name="foot_2_global_linear_velocity"/>
    <framelinvel objtype="site" objname="foot_3" name="foot_3_global_linear_velocity"/>
    <framelinvel objtype="site" objname="foot_4" name="foot_4_global_linear_velocity"/>
    <framelinvel objtype="site" objname="foot_5" name="foot_5_global_linear_velocity"/>
    <framelinvel objtype="site" objname="foot_6" name="foot_6_global_linear_velocity"/>
  </sensor>

  <keyframe>
    <key name="home" qpos="0 0 0.1457 1 0 0 0 0 0 0 0 0 0 0 0 0 0 0 0 0 0 0 0 0 0 0 0 0 0 0 0"/>
  </keyframe>
</mujoco>
