<mujoco model="Golem">
  <compiler angle="radian" assetdir="assets" balanceinertia="true" inertiafromgeom="false"/>

  <option timestep="0.005" density="1.2" viscosity="2e-05"/>

  <size nkey="1"/>

  <visual>
    <quality shadowsize="8192"/>
    <map shadowclip="0.5"/>
  </visual>

  <default>
    <default class="/">
      <joint armature="0.01" damping="0.01" frictionloss="0.01"/>
      <geom contype="0" conaffinity="0" group="1" solref="-1000 -80"/>
      <site size="0.01 0.005 0.005" group="5"/>
      <general forcelimited="true" biastype="affine" gainprm="25" biasprm="0 -25 -0.5"/>
      <default class="visual">
        <geom type="mesh" group="2"/>
      </default>
      <default class="collision">
        <geom group="3"/>
      </default>
      <default class="foot">
        <geom size="0.01 0 0" condim="6" group="4" priority="1" solimp="0.015 1 0.01"/>
      </default>
      <default class="reward_collision_sphere">
        <geom group="5" rgba="1 0 0 1"/>
      </default>
    </default>
  </default>

  <asset>
    <texture type="skybox" colorspace="auto" name="//unnamed_texture_0" builtin="gradient" rgb1="0.95 0.95 0.95" rgb2="0.95 0.95 0.95" width="100" height="600"/>
    <texture type="2d" colorspace="auto" name="texplane" builtin="checker" rgb1="0.345 0.575 0.748" rgb2="0.345 0.575 0.748" markrgb="1 1 1" width="512" height="512"/>
    <material name="MatPlane" class="/" texture="texplane" texuniform="true" texrepeat="2 2" specular="0.9"/>
    <mesh name="body" class="/" file="body.stl" scale="0.001 0.001 0.001"/>
    <mesh name="coxa" class="/" file="coxa.stl" scale="0.001 0.001 0.001"/>
    <mesh name="femur" class="/" file="femur.stl" scale="0.001 0.001 0.001"/>
    <mesh name="tibia" class="/" file="tibia.stl" scale="0.001 0.001 0.001"/>
    <mesh name="tarsus" class="/" file="tarsus.stl" scale="0.001 0.001 0.001"/>
  </asset>

  <worldbody>
    <geom name="floor" class="/" size="100 100 0.125" type="plane" group="0" material="MatPlane"/>
    <light name="toplight_shadow" class="/" pos="0 0 5" dir="0.0990148 0.0990148 -0.990148" type="directional" ambient="0.04 0.04 0.04" diffuse="0.55 0.55 0.55" specular="0.12 0.12 0.12"/>
    <light name="toplight_fill" class="/" pos="0 0 5" dir="0.0990148 0.0990148 -0.990148" type="directional" castshadow="false" ambient="0.04 0.04 0.04" diffuse="0.3 0.3 0.3" specular="0.08 0.08 0.08"/>
    <body name="trunk" pos="0.00157141 -0.000586941 -0.000794785" quat="1 -5.06064e-06 4.22094e-05 -7.42362e-06">
      <inertial pos="6.61304e-05 -1.7462e-06 -0.00319603" quat="0.999999 -0.000457191 -0.00129807 -0.000374178" mass="3.37857" diaginertia="0.0138782 0.00245218 0.0163295"/>
      <joint name="//unnamed_joint_0" type="free"/>
      <geom name="//unnamed_geom_1" class="/" pos="0 0 0.0706781" quat="1 0 0 0" type="mesh" rgba="0.9 0.9 0.9 1" mesh="body"/>
      <site name="imu" class="/" pos="0.145219 0.00524707 0.107329" size="0.00977686"/>
      <camera name="track" class="/" pos="0 -1.51852 0" quat="0.707107 0.707107 0 0" mode="trackcom"/>
      <camera name="ego_camera" class="/" pos="0.139029 0 0.110434" quat="-0.5 -0.5 0.5 0.5"/>
      <body name="coxa_RR" pos="-0.19106 -0.0635515 0.0701596" quat="0.382653 0.00034893 2.36785e-05 -0.923892">
        <inertial pos="3.34775e-06 -0.00174272 0.00157199" quat="1 -6.98594e-07 -5.28921e-06 -1.2257e-06" mass="0.183115" diaginertia="0.0140359 0.00252827 0.0164018"/>
        <joint name="coxa_joint_RR" class="/" pos="0 0 0" axis="-0.00183981 -0.00682896 -0.999975" range="-3.13899 3.14184" armature="0.00942386" damping="0" frictionloss="0.0098149"/>
        <geom name="//unnamed_geom_2" class="/" type="mesh" rgba="0.2 0.2 0.2 1" mesh="coxa"/>
        <geom name="//unnamed_geom_3" class="reward_collision_sphere" size="0.0391074" pos="-0.0320835 0 0"/>
        <body name="femur_RR" pos="0.0625248 0.000717094 -0.000537423" quat="0.500012 -0.49991 0.499938 0.500141">
          <inertial pos="0.000954105 0.000861324 0.00031237" quat="0.999994 0.000717153 -0.00275733 -0.00190087" mass="0.187125" diaginertia="0.0139919 0.00250654 0.0168528"/>
          <joint name="femur_joint_RR" class="/" pos="0 0 0" axis="-0.00169704 0.00334505 -0.999993" range="-3.15943 3.14003" armature="0.00996932" damping="0" frictionloss="0.0101369"/>
          <geom name="//unnamed_geom_4" class="/" type="mesh" rgba="0.9 0.9 0.9 1" mesh="femur"/>
          <geom name="//unnamed_geom_5" class="reward_collision_sphere" size="0.0391074"/>
          <body name="tibia_RR" pos="2.5695e-05 -0.0843359 0.00217889" quat="0.000408899 1 -0.000275904 -0.000584954">
            <inertial pos="-0.000939623 0.000262511 0.000143114" quat="0.999999 -0.000895313 0.00064459 0.00113083" mass="0.189164" diaginertia="0.0139995 0.00255577 0.0166282"/>
            <joint name="tibia_joint_RR" class="/" pos="0 0 0" axis="7.95972e-05 0.00326534 0.999995" range="-3.15907 3.12881" armature="0.00959885" damping="0.00319357" frictionloss="0.00979336"/>
            <geom name="//unnamed_geom_6" class="/" type="mesh" rgba="0.2 0.2 0.2 1" mesh="tibia"/>
            <geom name="//unnamed_geom_7" class="reward_collision_sphere" size="0.0391074"/>
            <body name="tarsus_RR" pos="0.094461 0.0013635 0.000757128" quat="1 1.36901e-05 2.04523e-08 4.04304e-07">
              <inertial pos="0.0663334 0.000406986 -0.00100187" quat="0.499579 0.499812 0.501403 0.499203" mass="0.186043" diaginertia="0.0138637 0.0024841 0.0162841"/>
              <joint name="tarsus_joint_RR" class="/" pos="0 0 0" axis="0.00621621 -0.00498661 0.999968" stiffness="0.00240782" range="-3.15702 3.13166" armature="0.0100044" damping="0.0394095" frictionloss="0.0102351"/>
              <geom name="//unnamed_geom_8" class="/" type="mesh" rgba="0.9 0.9 0.9 1" mesh="tarsus"/>
              <geom name="foot_1" class="foot" size="0.00963176" pos="0.119779 0 0" quat="0 -0.707107 0 0.707107"/>
              <geom name="//unnamed_geom_10" class="reward_collision_sphere" size="0.0391074"/>
              <geom name="//unnamed_geom_11" class="reward_collision_sphere" size="0.0146653" pos="0.114966 0 0"/>
              <site name="foot_1" class="foot" pos="0.119779 0 0" quat="0 -0.707107 0 0.707107" size="0.00977686"/>
            </body>
          </body>
        </body>
      </body>
      <body name="coxa_RM" pos="-0.000373222 -0.101744 0.0707654" quat="0.70709 0.000167304 9.70825e-05 -0.707124">
        <inertial pos="0.000297254 0.000114578 0.00165817" quat="0.999988 0.00223745 0.00235429 0.00362688" mass="0.189541" diaginertia="0.0141584 0.0024739 0.0164114"/>
        <joint name="coxa_joint_RM" class="/" pos="0 0 0" axis="-0.00320424 -0.000363558 -0.999995" range="-3.11954 3.14421" armature="0.00967429" damping="0.00693383" frictionloss="0.00876401"/>
        <geom name="//unnamed_geom_12" class="/" type="mesh" rgba="0.2 0.2 0.2 1" mesh="coxa"/>
        <geom name="//unnamed_geom_13" class="reward_collision_sphere" size="0.0391074" pos="-0.0320835 0 0"/>
        <body name="femur_RM" pos="0.0619233 7.24497e-05 2.14275e-05" quat="0.500285 -0.499736 0.500402 0.499577">
          <inertial pos="-0.000177573 0.000788398 0.000158799" quat="0.99999 -0.000877155 -0.00305153 0.00305516" mass="0.191485" diaginertia="0.0143132 0.00256067 0.0168055"/>
          <joint name="femur_joint_RM" class="/" pos="0 0 0" axis="-0.00331045 0.000952864 -0.999994" range="-3.1312 3.13916" armature="0.0102514" damping="0.0103208" frictionloss="0.00973575"/>
          <geom name="//unnamed_geom_14" class="/" type="mesh" rgba="0.9 0.9 0.9 1" mesh="femur"/>
          <geom name="//unnamed_geom_15" class="reward_collision_sphere" size="0.0391074"/>
          <body name="tibia_RM" pos="0.00076534 -0.0810494 0.00116011" quat="-8.95649e-05 1 -9.11511e-05 -5.87571e-05">
            <inertial pos="-6.96913e-05 -0.00190763 -0.00025654" quat="0.999984 0.00257137 -0.00501451 0.000253665" mass="0.186685" diaginertia="0.0141954 0.00261098 0.0165305"/>
            <joint name="tibia_joint_RM" class="/" pos="0 0 0" axis="-0.000979817 -0.000372733 0.999999" range="-3.16253 3.18001" armature="0.00972057" damping="0.0122237" frictionloss="0.00970291"/>
            <geom name="//unnamed_geom_16" class="/" type="mesh" rgba="0.2 0.2 0.2 1" mesh="tibia"/>
            <geom name="//unnamed_geom_17" class="reward_collision_sphere" size="0.0391074"/>
            <body name="tarsus_RM" pos="0.0936366 0.000283375 0.000290066" quat="1 0.000106992 -9.40282e-05 -2.98691e-05">
              <inertial pos="0.0638397 0.000752039 0.000580524" quat="0.497928 0.503028 0.494131 0.504841" mass="0.190667" diaginertia="0.0138006 0.00253947 0.016326"/>
              <joint name="tarsus_joint_RM" class="/" pos="0 0 0" axis="0.000420669 -0.000109164 1" range="-3.1469 3.14871" armature="0.00928724" damping="0.00626648" frictionloss="0.00978478"/>
              <geom name="//unnamed_geom_18" class="/" type="mesh" rgba="0.9 0.9 0.9 1" mesh="tarsus"/>
              <geom name="foot_2" class="foot" size="0.00962297" pos="0.119779 0 0" quat="0 -0.707107 0 0.707107"/>
              <geom name="//unnamed_geom_20" class="reward_collision_sphere" size="0.0391074"/>
              <geom name="//unnamed_geom_21" class="reward_collision_sphere" size="0.0146653" pos="0.114966 0 0"/>
              <site name="foot_2" class="foot" pos="0.119779 0 0" quat="0 -0.707107 0 0.707107" size="0.00977686"/>
            </body>
          </body>
        </body>
      </body>
      <body name="coxa_RF" pos="0.190964 -0.0615229 0.0725157" quat="0.923977 -0.000209537 0.000131479 -0.382448">
        <inertial pos="0.000746215 -0.000788539 -3.07566e-05" quat="1 6.80329e-06 -3.94259e-05 6.95065e-05" mass="0.188005" diaginertia="0.0139752 0.00250783 0.0167206"/>
        <joint name="coxa_joint_RF" class="/" pos="0 0 0" axis="-0.00386111 0.00308389 -0.999988" range="-3.14348 3.13253" armature="0.0101678" damping="0.0130758" frictionloss="0.00987648"/>
        <geom name="//unnamed_geom_22" class="/" type="mesh" rgba="0.2 0.2 0.2 1" mesh="coxa"/>
        <geom name="//unnamed_geom_23" class="reward_collision_sphere" size="0.0391074" pos="-0.0320835 0 0"/>
        <body name="femur_RF" pos="0.0629644 0.000478739 -0.00182504" quat="0.500338 -0.499934 0.499852 0.499875">
          <inertial pos="-0.000852597 0.00011825 -0.000180126" quat="0.999988 -0.0034538 -0.000959056 0.0034118" mass="0.189038" diaginertia="0.0139873 0.00256912 0.0168965"/>
          <joint name="femur_joint_RF" class="/" pos="0 0 0" axis="0.000333833 1.85918e-06 -1" range="-3.17298 3.12363" armature="0.00930353" damping="0.0121622" frictionloss="0.00996846"/>
          <geom name="//unnamed_geom_24" class="/" type="mesh" rgba="0.9 0.9 0.9 1" mesh="femur"/>
          <geom name="//unnamed_geom_25" class="reward_collision_sphere" size="0.0391074"/>
          <body name="tibia_RF" pos="-0.00100651 -0.0825495 0.00158488" quat="3.755e-05 1 3.52356e-05 -1.75822e-05">
            <inertial pos="-0.00175378 0.000275585 7.52455e-05" quat="1 3.73161e-06 -1.8057e-06 3.93872e-06" mass="0.189985" diaginertia="0.0140886 0.00250902 0.0164484"/>
            <joint name="tibia_joint_RF" class="/" pos="0 0 0" axis="0.00672199 0.00134169 0.999977" range="-3.13179 3.10343" armature="0.0101798" damping="0.0113592" frictionloss="0.00981937"/>
            <geom name="//unnamed_geom_26" class="/" type="mesh" rgba="0.2 0.2 0.2 1" mesh="tibia"/>
            <geom name="//unnamed_geom_27" class="reward_collision_sphere" size="0.0391074"/>
            <body name="tarsus_RF" pos="0.0937017 0.0012368 0.00114415" quat="1 -0.000646843 -0.000147714 0.00042896">
              <inertial pos="0.0642801 0.000161603 -0.000208984" quat="0.499744 0.500767 0.499625 0.499864" mass="0.185507" diaginertia="0.0140053 0.00251525 0.0162624"/>
              <joint name="tarsus_joint_RF" class="/" pos="0 0 0" axis="-0.00164046 7.72563e-05 0.999999" range="-3.12027 3.14401" armature="0.00950422" damping="0.000351224" frictionloss="0.0102067"/>
              <geom name="//unnamed_geom_28" class="/" type="mesh" rgba="0.9 0.9 0.9 1" mesh="tarsus"/>
              <geom name="foot_3" class="foot" size="0.0098385" pos="0.119779 0 0" quat="0 -0.707107 0 0.707107"/>
              <geom name="//unnamed_geom_30" class="reward_collision_sphere" size="0.0391074"/>
              <geom name="//unnamed_geom_31" class="reward_collision_sphere" size="0.0146653" pos="0.114966 0 0"/>
              <site name="foot_3" class="foot" pos="0.119779 0 0" quat="0 -0.707107 0 0.707107" size="0.00977686"/>
            </body>
          </body>
        </body>
      </body>
      <body name="coxa_LR" pos="-0.191332 0.0660462 0.0703707" quat="0.382609 3.32886e-05 -3.75393e-05 0.92391">
        <inertial pos="-0.00121535 -0.0011381 -0.00128432" quat="0.999963 0.00281502 -0.00104254 0.00811456" mass="0.187454" diaginertia="0.0139511 0.00258996 0.0162869"/>
        <joint name="coxa_joint_LR" class="/" pos="0 0 0" axis="0.00813022 -0.00708074 -0.999942" range="-3.12882 3.15509" armature="0.0100779" damping="0.0152057" frictionloss="0.00951277"/>
        <geom name="//unnamed_geom_32" class="/" type="mesh" rgba="0.2 0.2 0.2 1" mesh="coxa"/>
        <geom name="//unnamed_geom_33" class="reward_collision_sphere" size="0.0391074" pos="-0.0320835 0 0"/>
        <body name="femur_LR" pos="0.0645756 -0.00200683 -0.0015874" quat="0.500144 -0.499828 0.500038 0.49999">
          <inertial pos="0.000705444 0.000291536 -0.000334178" quat="0.999993 0.00256262 -0.00191036 0.00185929" mass="0.186844" diaginertia="0.0139323 0.00253154 0.0162955"/>
          <joint name="femur_joint_LR" class="/" pos="0 0 0" axis="0.000287088 -0.000855502 1" range="-3.15253 3.13463" armature="0.00978771" damping="0.0122293" frictionloss="0.00886246"/>
          <geom name="//unnamed_geom_34" class="/" type="mesh" rgba="0.9 0.9 0.9 1" mesh="femur"/>
          <geom name="//unnamed_geom_35" class="reward_collision_sphere" size="0.0391074"/>
          <body name="tibia_LR" pos="0.000208693 -0.0818431 -0.000569803" quat="0.0006315 1 0.000222679 3.33639e-07">
            <inertial pos="-0.000181357 0.000140899 5.94801e-05" quat="0.999998 -0.00141992 -0.00057959 0.00118469" mass="0.182986" diaginertia="0.0138322 0.0025127 0.0161328"/>
            <joint name="tibia_joint_LR" class="/" pos="0 0 0" axis="-0.00123665 0.00608372 -0.999981" stiffness="0.000881573" range="-3.12252 3.12893" armature="0.00962835" damping="0.00815541" frictionloss="0.00991913"/>
            <geom name="//unnamed_geom_36" class="/" type="mesh" rgba="0.2 0.2 0.2 1" mesh="tibia"/>
            <geom name="//unnamed_geom_37" class="reward_collision_sphere" size="0.0391074"/>
            <body name="tarsus_LR" pos="0.0938542 -0.000546303 0.00190957" quat="1 0.000332729 0.000743656 -4.82367e-05">
              <inertial pos="0.0667395 0.000140591 -0.00168435" quat="0.500148 0.49939 0.499786 0.500675" mass="0.185981" diaginertia="0.0138932 0.00249594 0.0162114"/>
              <joint name="tarsus_joint_LR" class="/" pos="0 0 0" axis="-0.00165233 -0.000533029 -0.999998" range="-3.15518 3.12265" armature="0.0100095" damping="0.000213823" frictionloss="0.00934859"/>
              <geom name="//unnamed_geom_38" class="/" type="mesh" rgba="0.9 0.9 0.9 1" mesh="tarsus"/>
              <geom name="foot_4" class="foot" size="0.00940217" pos="0.119779 0 0" quat="0.707107 0 -0.707107 0"/>
              <geom name="//unnamed_geom_40" class="reward_collision_sphere" size="0.0391074"/>
              <geom name="//unnamed_geom_41" class="reward_collision_sphere" size="0.0146653" pos="0.114966 0 0"/>
              <site name="foot_4" class="foot" pos="0.119779 0 0" quat="0.707107 0 -0.707107 0" size="0.00977686"/>
            </body>
          </body>
        </body>
      </body>
      <body name="coxa_LM" pos="-0.000109725 0.0993309 0.0717308" quat="0.706948 -0.000182316 7.18446e-05 0.707266">
        <inertial pos="-0.000270939 0.000900418 0.00121082" quat="0.999999 -0.00158931 0.000624591 -1.11465e-05" mass="0.189021" diaginertia="0.0142828 0.00256839 0.0166354"/>
        <joint name="coxa_joint_LM" class="/" pos="0 0 0" axis="0.000990658 0.000231086 -0.999999" range="-3.12347 3.14251" armature="0.00932091" damping="0.00451067" frictionloss="0.0100236"/>
        <geom name="//unnamed_geom_42" class="/" type="mesh" rgba="0.2 0.2 0.2 1" mesh="coxa"/>
        <geom name="//unnamed_geom_43" class="reward_collision_sphere" size="0.0391074" pos="-0.0320835 0 0"/>
        <body name="femur_LM" pos="0.0604918 0.000600326 0.00034187" quat="0.500146 -0.499959 0.499924 0.499971">
          <inertial pos="-0.00105965 -0.000959036 0.00193007" quat="0.99997 -0.00670347 0.00372918 0.000887701" mass="0.185792" diaginertia="0.0137608 0.00244398 0.0161363"/>
          <joint name="femur_joint_LM" class="/" pos="0 0 0" axis="-0.00179882 -0.000457397 0.999998" range="-3.14253 3.12802" armature="0.00948244" damping="0.00432964" frictionloss="0.00987975"/>
          <geom name="//unnamed_geom_44" class="/" type="mesh" rgba="0.9 0.9 0.9 1" mesh="femur"/>
          <geom name="//unnamed_geom_45" class="reward_collision_sphere" size="0.0391074"/>
          <body name="tibia_LM" pos="0.00111213 -0.0785868 -0.000320312" quat="0.000821988 0.999999 5.15203e-05 -0.000627726">
            <inertial pos="5.67379e-06 -0.00265249 -0.000829139" quat="0.999999 -0.000503076 -0.000478206 -0.00117084" mass="0.188902" diaginertia="0.0138346 0.00255787 0.0162461"/>
            <joint name="tibia_joint_LM" class="/" pos="0 0 0" axis="0.00053349 -0.000537886 -1" range="-3.13855 3.12596" armature="0.0103179" damping="0" frictionloss="0.0101715"/>
            <geom name="//unnamed_geom_46" class="/" type="mesh" rgba="0.2 0.2 0.2 1" mesh="tibia"/>
            <geom name="//unnamed_geom_47" class="reward_collision_sphere" size="0.0391074"/>
            <body name="tarsus_LM" pos="0.094736 -0.000774976 -0.00107148" quat="1 -0.000399751 0.000851244 -0.000321479">
              <inertial pos="0.0645695 0.00058821 0.000779332" quat="0.499999 0.499997 0.500005 0.499999" mass="0.182092" diaginertia="0.013823 0.00246437 0.0160707"/>
              <joint name="tarsus_joint_LM" class="/" pos="0 0 0" axis="0.00250471 0.000491732 -0.999997" stiffness="0.000733699" range="-3.10104 3.13331" armature="0.0103273" damping="0" frictionloss="0.00929905"/>
              <geom name="//unnamed_geom_48" class="/" type="mesh" rgba="0.9 0.9 0.9 1" mesh="tarsus"/>
              <geom name="foot_5" class="foot" size="0.00946752" pos="0.119779 0 0" quat="0.707107 0 -0.707107 0"/>
              <geom name="//unnamed_geom_50" class="reward_collision_sphere" size="0.0391074"/>
              <geom name="//unnamed_geom_51" class="reward_collision_sphere" size="0.0146653" pos="0.114966 0 0"/>
              <site name="foot_5" class="foot" pos="0.119779 0 0" quat="0.707107 0 -0.707107 0" size="0.00977686"/>
            </body>
          </body>
        </body>
      </body>
      <body name="coxa_LF" pos="0.192123 0.0652561 0.0689378" quat="0.923869 -8.52395e-05 -0.000131229 0.382708">
        <inertial pos="0.000147908 0.000311149 0.00130494" quat="1 -0.000273688 0.000168486 -0.000349512" mass="0.184512" diaginertia="0.0137144 0.00247019 0.015983"/>
        <joint name="coxa_joint_LF" class="/" pos="0 0 0" axis="-0.00325199 0.00364807 -0.999988" range="-3.11901 3.17531" armature="0.0102837" damping="0.000665394" frictionloss="0.0098768"/>
        <geom name="//unnamed_geom_52" class="/" type="mesh" rgba="0.2 0.2 0.2 1" mesh="coxa"/>
        <geom name="//unnamed_geom_53" class="reward_collision_sphere" size="0.0391074" pos="-0.0320835 0 0"/>
        <body name="femur_LF" pos="0.063324 -0.000811168 -0.000232885" quat="0.499537 -0.500306 0.499709 0.500447">
          <inertial pos="0.00177177 -0.000109004 2.21312e-05" quat="0.999998 0.00212371 3.52876e-06 0.000358463" mass="0.187641" diaginertia="0.014065 0.00254727 0.0166179"/>
          <joint name="femur_joint_LF" class="/" pos="0 0 0" axis="-0.00154526 -0.00444759 0.999989" range="-3.14834 3.14171" armature="0.0102416" damping="0.00440653" frictionloss="0.00993406"/>
          <geom name="//unnamed_geom_54" class="/" type="mesh" rgba="0.9 0.9 0.9 1" mesh="femur"/>
          <geom name="//unnamed_geom_55" class="reward_collision_sphere" size="0.0391074"/>
          <body name="tibia_LF" pos="0.000962471 -0.0809816 0.000611391" quat="0.00018321 1 4.6225e-05 -0.000309102">
            <inertial pos="-0.00011631 0.000366469 -0.000992224" quat="0.999996 -0.00216839 0.00038681 0.00160915" mass="0.189279" diaginertia="0.0141034 0.00253582 0.0164182"/>
            <joint name="tibia_joint_LF" class="/" pos="0 0 0" axis="-0.00124403 0.000625265 -0.999999" range="-3.14215 3.14513" armature="0.0100265" damping="5.13792e-05" frictionloss="0.00934729"/>
            <geom name="//unnamed_geom_56" class="/" type="mesh" rgba="0.2 0.2 0.2 1" mesh="tibia"/>
            <geom name="//unnamed_geom_57" class="reward_collision_sphere" size="0.0391074"/>
            <body name="tarsus_LF" pos="0.0937947 -0.000209094 -0.000760987" quat="1 0.000422304 0.000316023 -0.000527618">
              <inertial pos="0.064171 0.000571105 0.000994603" quat="0.499738 0.500172 0.499861 0.500228" mass="0.183816" diaginertia="0.0139463 0.00252275 0.0161323"/>
              <joint name="tarsus_joint_LF" class="/" pos="0 0 0" axis="-0.00141193 -0.00541302 -0.999984" stiffness="0.0259328" range="-3.14558 3.11844" armature="0.00972738" damping="0.0281138" frictionloss="0.00964191"/>
              <geom name="//unnamed_geom_58" class="/" type="mesh" rgba="0.9 0.9 0.9 1" mesh="tarsus"/>
              <geom name="foot_6" class="foot" size="0.00991593" pos="0.119779 0 0" quat="0.707107 0 -0.707107 0"/>
              <geom name="//unnamed_geom_60" class="reward_collision_sphere" size="0.0391074"/>
              <geom name="//unnamed_geom_61" class="reward_collision_sphere" size="0.0146653" pos="0.114966 0 0"/>
              <site name="foot_6" class="foot" pos="0.119779 0 0" quat="0.707107 0 -0.707107 0" size="0.00977686"/>
            </body>
          </body>
        </body>
      </body>
    </body>
  </worldbody>

  <contact>
    <pair class="/" geom1="floor" geom2="foot_1" name="//unnamed_contact_0"/>
    <pair class="/" geom1="floor" geom2="foot_2" name="//unnamed_contact_1"/>
    <pair class="/" geom1="floor" geom2="foot_3" name="//unnamed_contact_2"/>
    <pair class="/" geom1="floor" geom2="foot_4" name="//unnamed_contact_3"/>
    <pair class="/" geom1="floor" geom2="foot_5" name="//unnamed_contact_4"/>
    <pair class="/" geom1="floor" geom2="foot_6" name="//unnamed_contact_5"/>
  </contact>

  <actuator>
    <general name="coxa_joint_RR" class="/" joint="coxa_joint_RR" forcerange="-7.27725 7.27725" gainprm="23.5445" biasprm="0 -23.5445 -0.512148"/>
    <general name="femur_joint_RR" class="/" joint="femur_joint_RR" forcerange="-7.1721 7.1721" gainprm="23.5445" biasprm="0 -23.5445 -0.512148"/>
    <general name="tibia_joint_RR" class="/" joint="tibia_joint_RR" forcerange="-7.18167 7.18167" gainprm="23.5445" biasprm="0 -23.5445 -0.512148"/>
    <general name="tarsus_joint_RR" class="/" joint="tarsus_joint_RR" forcerange="-7.21712 7.21712" gainprm="23.5445" biasprm="0 -23.5445 -0.512148"/>
    <general name="coxa_joint_RM" class="/" joint="coxa_joint_RM" forcerange="-6.67532 6.67532" gainprm="23.5445" biasprm="0 -23.5445 -0.512148"/>
    <general name="femur_joint_RM" class="/" joint="femur_joint_RM" forcerange="-7.1136 7.1136" gainprm="23.5445" biasprm="0 -23.5445 -0.512148"/>
    <general name="tibia_joint_RM" class="/" joint="tibia_joint_RM" forcerange="-7.26565 7.26565" gainprm="23.5445" biasprm="0 -23.5445 -0.512148"/>
    <general name="tarsus_joint_RM" class="/" joint="tarsus_joint_RM" forcerange="-7.26236 7.26236" gainprm="23.5445" biasprm="0 -23.5445 -0.512148"/>
    <general name="coxa_joint_RF" class="/" joint="coxa_joint_RF" forcerange="-6.75142 6.75142" gainprm="23.5445" biasprm="0 -23.5445 -0.512148"/>
    <general name="femur_joint_RF" class="/" joint="femur_joint_RF" forcerange="-7.34018 7.34018" gainprm="23.5445" biasprm="0 -23.5445 -0.512148"/>
    <general name="tibia_joint_RF" class="/" joint="tibia_joint_RF" forcerange="-6.63409 6.63409" gainprm="23.5445" biasprm="0 -23.5445 -0.512148"/>
    <general name="tarsus_joint_RF" class="/" joint="tarsus_joint_RF" forcerange="-6.90976 6.90976" gainprm="23.5445" biasprm="0 -23.5445 -0.512148"/>
    <general name="coxa_joint_LR" class="/" joint="coxa_joint_LR" forcerange="-7.13227 7.13227" gainprm="23.5445" biasprm="0 -23.5445 -0.512148"/>
    <general name="femur_joint_LR" class="/" joint="femur_joint_LR" forcerange="-7.1064 7.1064" gainprm="23.5445" biasprm="0 -23.5445 -0.512148"/>
    <general name="tibia_joint_LR" class="/" joint="tibia_joint_LR" forcerange="-7.1742 7.1742" gainprm="23.5445" biasprm="0 -23.5445 -0.512148"/>
    <general name="tarsus_joint_LR" class="/" joint="tarsus_joint_LR" forcerange="-6.90351 6.90351" gainprm="23.5445" biasprm="0 -23.5445 -0.512148"/>
    <general name="coxa_joint_LM" class="/" joint="coxa_joint_LM" forcerange="-7.32356 7.32356" gainprm="23.5445" biasprm="0 -23.5445 -0.512148"/>
    <general name="femur_joint_LM" class="/" joint="femur_joint_LM" forcerange="-7.12367 7.12367" gainprm="23.5445" biasprm="0 -23.5445 -0.512148"/>
    <general name="tibia_joint_LM" class="/" joint="tibia_joint_LM" forcerange="-7.02957 7.02957" gainprm="23.5445" biasprm="0 -23.5445 -0.512148"/>
    <general name="tarsus_joint_LM" class="/" joint="tarsus_joint_LM" forcerange="-7.11812 7.11812" gainprm="23.5445" biasprm="0 -23.5445 -0.512148"/>
    <general name="coxa_joint_LF" class="/" joint="coxa_joint_LF" forcerange="-6.61032 6.61032" gainprm="23.5445" biasprm="0 -23.5445 -0.512148"/>
    <general name="femur_joint_LF" class="/" joint="femur_joint_LF" forcerange="-7.0542 7.0542" gainprm="23.5445" biasprm="0 -23.5445 -0.512148"/>
    <general name="tibia_joint_LF" class="/" joint="tibia_joint_LF" forcerange="-7.11394 7.11394" gainprm="23.5445" biasprm="0 -23.5445 -0.512148"/>
    <general name="tarsus_joint_LF" class="/" joint="tarsus_joint_LF" forcerange="-7.33236 7.33236" gainprm="23.5445" biasprm="0 -23.5445 -0.512148"/>
  </actuator>

  <sensor>
    <gyro site="imu" name="imu_angular_velocity"/>
    <velocimeter site="imu" name="imu_linear_velocity"/>
    <framelinvel objtype="site" objname="foot_1" name="foot_1_global_linear_velocity"/>
    <framelinvel objtype="site" objname="foot_2" name="foot_2_global_linear_velocity"/>
    <framelinvel objtype="site" objname="foot_3" name="foot_3_global_linear_velocity"/>
    <framelinvel objtype="site" objname="foot_4" name="foot_4_global_linear_velocity"/>
    <framelinvel objtype="site" objname="foot_5" name="foot_5_global_linear_velocity"/>
    <framelinvel objtype="site" objname="foot_6" name="foot_6_global_linear_velocity"/>
  </sensor>

  <keyframe>
    <key name="home" qpos="0 0 0.1457 1 0 0 0 0 0 0 0 0 0 0 0 0 0 0 0 0 0 0 0 0 0 0 0 0 0 0 0"/>
  </keyframe>
</mujoco>
