<mujoco model="Golem">
  <compiler angle="radian" assetdir="assets" balanceinertia="true" inertiafromgeom="false"/>

  <option timestep="0.005" density="1.2" viscosity="2e-05"/>

  <size nkey="1"/>

  <visual>
    <quality shadowsize="8192"/>
    <map shadowclip="0.5"/>
  </visual>

  <default>
    <default class="/">
      <joint armature="0.01" damping="0.01" frictionloss="0.01"/>
      <geom contype="0" conaffinity="0" group="1" solref="-1000 -80"/>
      <site size="0.01 0.005 0.005" group="5"/>
      <general forcelimited="true" biastype="affine" gainprm="25" biasprm="0 -25 -0.5"/>
      <default class="visual">
        <geom type="mesh" group="2"/>
      </default>
      <default class="collision">
        <geom group="3"/>
      </default>
      <default class="foot">
        <geom size="0.01 0 0" condim="6" group="4" priority="1" solimp="0.015 1 0.01"/>
      </default>
      <default class="reward_collision_sphere">
        <geom group="5" rgba="1 0 0 1"/>
      </default>
    </default>
  </default>

  <asset>
    <texture type="skybox" colorspace="auto" name="//unnamed_texture_0" builtin="gradient" rgb1="0.95 0.95 0.95" rgb2="0.95 0.95 0.95" width="100" height="600"/>
    <texture type="2d" colorspace="auto" name="texplane" builtin="checker" rgb1="0.345 0.575 0.748" rgb2="0.345 0.575 0.748" markrgb="1 1 1" width="512" height="512"/>
    <material name="MatPlane" class="/" texture="texplane" texuniform="true" texrepeat="2 2" specular="0.9"/>
    <mesh name="body" class="/" file="body.stl" scale="0.001 0.001 0.001"/>
    <mesh name="coxa" class="/" file="coxa.stl" scale="0.001 0.001 0.001"/>
    <mesh name="femur" class="/" file="femur.stl" scale="0.001 0.001 0.001"/>
    <mesh name="tibia" class="/" file="tibia.stl" scale="0.001 0.001 0.001"/>
    <mesh name="tarsus" class="/" file="tarsus.stl" scale="0.001 0.001 0.001"/>
  </asset>

  <worldbody>
    <geom name="floor" class="/" size="100 100 0.125" type="plane" group="0" material="MatPlane"/>
    <light name="toplight_shadow" class="/" pos="0 0 5" dir="0.0990148 0.0990148 -0.990148" type="directional" ambient="0.04 0.04 0.04" diffuse="0.55 0.55 0.55" specular="0.12 0.12 0.12"/>
    <light name="toplight_fill" class="/" pos="0 0 5" dir="0.0990148 0.0990148 -0.990148" type="directional" castshadow="false" ambient="0.04 0.04 0.04" diffuse="0.3 0.3 0.3" specular="0.08 0.08 0.08"/>
    <body name="trunk" pos="-0.0103018 -0.00524 -0.00458249" quat="1 -9.58264e-05 0.000133069 7.92051e-05">
      <inertial pos="-0.00119264 -7.85181e-05 -0.00397059" quat="0.999961 -0.00293459 0.000828076 -0.00825703" mass="5.76893" diaginertia="0.0466043 0.0573078 0.00184537"/>
      <joint name="//unnamed_joint_0" type="free"/>
      <geom name="//unnamed_geom_1" class="/" pos="0 0 0.045638" quat="1 0 0 0" type="mesh" rgba="0.9 0.9 0.9 1" mesh="body"/>
      <site name="imu" class="/" pos="0.123811 -0.0448018 0.0635299" size="0.0114292"/>
      <camera name="track" class="/" pos="0 -2.80227 0" quat="0.707107 0.707107 0 0" mode="trackcom"/>
      <camera name="ego_camera" class="/" pos="0.170888 0 0.0713093" quat="-0.5 -0.5 0.5 0.5"/>
      <body name="coxa_RR" pos="-0.232863 -0.117151 0.0559455" quat="0.382523 -4.27141e-05 -2.39642e-05 -0.923946">
        <inertial pos="-0.00153936 0.0110058 0.00354189" quat="0.999447 -0.0264478 -0.0192293 0.00595563" mass="0.33878" diaginertia="0.0423202 0.0583842 0.0020073"/>
        <joint name="coxa_joint_RR" class="/" pos="0 0 0" axis="0.0165811 0.00551978 -0.999847" stiffness="0.0468302" range="-3.14955 3.15189" armature="0.0157893" damping="0.0174593" frictionloss="0.0116542"/>
        <geom name="//unnamed_geom_2" class="/" type="mesh" rgba="0.2 0.2 0.2 1" mesh="coxa"/>
        <geom name="//unnamed_geom_3" class="reward_collision_sphere" size="0.0457167" pos="-0.0394358 0 0"/>
        <body name="femur_RR" pos="0.0877598 0.00435663 -0.000778082" quat="0.500386 -0.499535 0.499985 0.500094">
          <inertial pos="0.00391209 0.00269136 -0.00165368" quat="0.999964 -0.000616899 0.0070712 0.00474914" mass="0.304177" diaginertia="0.0396891 0.053973 0.00159955"/>
          <joint name="femur_joint_RR" class="/" pos="0 0 0" axis="0.00478407 -0.00404619 -0.99998" stiffness="0.0475202" range="-2.96274 3.2684" armature="0.0120696" damping="0.00117422" frictionloss="0.0067184"/>
          <geom name="//unnamed_geom_4" class="/" type="mesh" rgba="0.9 0.9 0.9 1" mesh="femur"/>
          <geom name="//unnamed_geom_5" class="reward_collision_sphere" size="0.0457167"/>
          <body name="tibia_RR" pos="0.00706694 -0.141555 -0.0111752" quat="-0.00172175 0.999985 -0.00106876 0.00500912">
            <inertial pos="0.0088935 0.000100974 -0.00211716" quat="0.999961 -0.0056337 -0.00481517 -0.00484967" mass="0.288472" diaginertia="0.0412769 0.0585069 0.00210571"/>
            <joint name="tibia_joint_RR" class="/" pos="0 0 0" axis="0.0271599 -0.0339766 0.999054" range="-3.20912 3.02861" armature="0.0112771" damping="0.0211138" frictionloss="0.0113345"/>
            <geom name="//unnamed_geom_6" class="/" type="mesh" rgba="0.2 0.2 0.2 1" mesh="tibia"/>
            <geom name="//unnamed_geom_7" class="reward_collision_sphere" size="0.0457167"/>
            <body name="tarsus_RR" pos="0.108007 0.0017304 -0.00837687" quat="1 -6.64297e-05 -2.82813e-05 -0.000111235">
              <inertial pos="0.0702814 0.000847938 -0.00373076" quat="0.496414 0.503085 0.499326 0.50115" mass="0.298904" diaginertia="0.0394936 0.0526181 0.00185303"/>
              <joint name="tarsus_joint_RR" class="/" pos="0 0 0" axis="0.00531717 -0.00189561 0.999984" range="-2.96418 3.02147" armature="0.0121606" damping="0.0355408" frictionloss="0.0136718"/>
              <geom name="//unnamed_geom_8" class="/" type="mesh" rgba="0.9 0.9 0.9 1" mesh="tarsus"/>
              <geom name="foot_1" class="foot" size="0.011611" pos="0.147227 0 0" quat="0 -0.707107 0 0.707107"/>
              <geom name="//unnamed_geom_10" class="reward_collision_sphere" size="0.0457167"/>
              <geom name="//unnamed_geom_11" class="reward_collision_sphere" size="0.0171438" pos="0.141312 0 0"/>
              <site name="foot_1" class="foot" pos="0.147227 0 0" quat="0 -0.707107 0 0.707107" size="0.0114292"/>
            </body>
          </body>
        </body>
      </body>
      <body name="coxa_RM" pos="-0.00187944 -0.188876 0.0438249" quat="0.70791 -0.00260732 0.00031343 -0.706298">
        <inertial pos="-0.00687893 0.000388576 0.00370273" quat="0.999838 0.0166155 -0.00654489 0.00241299" mass="0.30991" diaginertia="0.0412709 0.0609645 0.00169436"/>
        <joint name="coxa_joint_RM" class="/" pos="0 0 0" axis="0.00196872 -0.00205759 -0.999996" range="-3.08744 3.13493" armature="0.0104379" damping="0.0428574" frictionloss="0.0183263"/>
        <geom name="//unnamed_geom_12" class="/" type="mesh" rgba="0.2 0.2 0.2 1" mesh="coxa"/>
        <geom name="//unnamed_geom_13" class="reward_collision_sphere" size="0.0457167" pos="-0.0394358 0 0"/>
        <body name="femur_RM" pos="0.0761458 -0.00831697 0.00219057" quat="0.500898 -0.496872 0.498701 0.503503">
          <inertial pos="-0.000719549 0.00302018 0.000430876" quat="0.999933 -0.00972939 -0.00497498 0.00382001" mass="0.251878" diaginertia="0.033765 0.0511881 0.00161878"/>
          <joint name="femur_joint_RM" class="/" pos="0 0 0" axis="-0.00535966 0.0259005 -0.99965" range="-3.11387 3.12768" armature="0.0136668" damping="0" frictionloss="0.0111341"/>
          <geom name="//unnamed_geom_14" class="/" type="mesh" rgba="0.9 0.9 0.9 1" mesh="femur"/>
          <geom name="//unnamed_geom_15" class="reward_collision_sphere" size="0.0457167"/>
          <body name="tibia_RM" pos="-0.000371719 -0.150687 -0.0108144" quat="0.000586774 1 0.000250226 0.000436178">
            <inertial pos="-0.0062333 0.0106758 0.00213606" quat="0.998954 -0.00561399 0.00733578 -0.0447764" mass="0.341968" diaginertia="0.0396157 0.0479218 0.00189338"/>
            <joint name="tibia_joint_RM" class="/" pos="0 0 0" axis="0.00358644 -0.00249911 0.99999" stiffness="0.000534146" range="-2.95612 2.89914" armature="0.0115624" damping="0.0178376" frictionloss="0.0110481"/>
            <geom name="//unnamed_geom_16" class="/" type="mesh" rgba="0.2 0.2 0.2 1" mesh="tibia"/>
            <geom name="//unnamed_geom_17" class="reward_collision_sphere" size="0.0457167"/>
            <body name="tarsus_RM" pos="0.117812 0.000306343 -0.0059277" quat="1 0.000379396 7.20022e-05 -6.73047e-06">
              <inertial pos="0.0787586 0.00612687 -0.00719048" quat="0.543387 0.495556 0.484639 0.473582" mass="0.259984" diaginertia="0.0437606 0.0577565 0.00202519"/>
              <joint name="tarsus_joint_RM" class="/" pos="0 0 0" axis="-0.00335026 -0.00264283 0.999991" stiffness="0.031375" range="-3.25437 3.16463" armature="0.00964538" damping="0" frictionloss="0.0105641"/>
              <geom name="//unnamed_geom_18" class="/" type="mesh" rgba="0.9 0.9 0.9 1" mesh="tarsus"/>
              <geom name="foot_2" class="foot" size="0.0109442" pos="0.147227 0 0" quat="0 -0.707107 0 0.707107"/>
              <geom name="//unnamed_geom_20" class="reward_collision_sphere" size="0.0457167"/>
              <geom name="//unnamed_geom_21" class="reward_collision_sphere" size="0.0171438" pos="0.141312 0 0"/>
              <site name="foot_2" class="foot" pos="0.147227 0 0" quat="0 -0.707107 0 0.707107" size="0.0114292"/>
            </body>
          </body>
        </body>
      </body>
      <body name="coxa_RF" pos="0.236116 -0.126947 0.0368768" quat="0.923469 0.000694354 0.000131532 -0.383671">
        <inertial pos="0.00183418 -0.00471319 0.00179493" quat="1 -0.000568765 0.000376991 -0.00047611" mass="0.302284" diaginertia="0.0391021 0.0525791 0.00192487"/>
        <joint name="coxa_joint_RF" class="/" pos="0 0 0" axis="-0.000582847 0.00173634 -0.999998" stiffness="0.00730735" range="-3.10183 3.12" armature="0.00661384" damping="0.0170723" frictionloss="0.0122947"/>
        <geom name="//unnamed_geom_22" class="/" type="mesh" rgba="0.2 0.2 0.2 1" mesh="coxa"/>
        <geom name="//unnamed_geom_23" class="reward_collision_sphere" size="0.0457167" pos="-0.0394358 0 0"/>
        <body name="femur_RF" pos="0.0737755 0.00257594 0.00554394" quat="0.49929 -0.500838 0.499568 0.500303">
          <inertial pos="-0.00303361 0.00584083 0.00194959" quat="0.999867 -0.00212171 -0.00385947 -0.0157205" mass="0.312308" diaginertia="0.0391632 0.0604547 0.00169914"/>
          <joint name="femur_joint_RF" class="/" pos="0 0 0" axis="-0.000805244 0.00165734 -0.999998" range="-2.92687 3.10288" armature="0.016752" damping="0.00128637" frictionloss="0.00714213"/>
          <geom name="//unnamed_geom_24" class="/" type="mesh" rgba="0.9 0.9 0.9 1" mesh="femur"/>
          <geom name="//unnamed_geom_25" class="reward_collision_sphere" size="0.0457167"/>
          <body name="tibia_RF" pos="0.00745667 -0.151588 -0.0112937" quat="0.000852965 0.999999 -0.00055819 8.5224e-05">
            <inertial pos="0.0110785 -0.00127687 0.000266906" quat="0.999996 -0.00159712 0.00185158 -0.00123985" mass="0.261117" diaginertia="0.0415986 0.0499177 0.00186981"/>
            <joint name="tibia_joint_RF" class="/" pos="0 0 0" axis="0.0276532 0.0456393 0.998575" range="-3.1189 3.35409" armature="0.0127339" damping="0.00899494" frictionloss="0.0117246"/>
            <geom name="//unnamed_geom_26" class="/" type="mesh" rgba="0.2 0.2 0.2 1" mesh="tibia"/>
            <geom name="//unnamed_geom_27" class="reward_collision_sphere" size="0.0457167"/>
            <body name="tarsus_RF" pos="0.120486 -0.00967942 -0.00850279" quat="0.999987 0.00386352 0.000236787 -0.00318121">
              <inertial pos="0.0779878 -0.000204106 0.00119536" quat="0.499641 0.495541 0.497705 0.507038" mass="0.294546" diaginertia="0.0393382 0.0542776 0.00172988"/>
              <joint name="tarsus_joint_RF" class="/" pos="0 0 0" axis="0.00744195 0.0265249 0.99962" stiffness="0.0156158" range="-3.08322 3.15759" armature="0.00856147" damping="0.000957367" frictionloss="0.0138444"/>
              <geom name="//unnamed_geom_28" class="/" type="mesh" rgba="0.9 0.9 0.9 1" mesh="tarsus"/>
              <geom name="foot_3" class="foot" size="0.00837528" pos="0.147227 0 0" quat="0 -0.707107 0 0.707107"/>
              <geom name="//unnamed_geom_30" class="reward_collision_sphere" size="0.0457167"/>
              <geom name="//unnamed_geom_31" class="reward_collision_sphere" size="0.0171438" pos="0.141312 0 0"/>
              <site name="foot_3" class="foot" pos="0.147227 0 0" quat="0 -0.707107 0 0.707107" size="0.0114292"/>
            </body>
          </body>
        </body>
      </body>
      <body name="coxa_LR" pos="-0.223153 0.1181 0.0470064" quat="0.382851 0.000331568 -0.000283399 0.92381">
        <inertial pos="0.00978631 -0.00422624 0.0116579" quat="0.998548 0.0524762 0.00599371 0.0106278" mass="0.294631" diaginertia="0.0366922 0.0420469 0.00164639"/>
        <joint name="coxa_joint_LR" class="/" pos="0 0 0" axis="-0.0126955 -0.0485762 -0.998739" range="-3.11214 3.22912" armature="0.0143619" damping="0.00902579" frictionloss="0.0158984"/>
        <geom name="//unnamed_geom_32" class="/" type="mesh" rgba="0.2 0.2 0.2 1" mesh="coxa"/>
        <geom name="//unnamed_geom_33" class="reward_collision_sphere" size="0.0457167" pos="-0.0394358 0 0"/>
        <body name="femur_LR" pos="0.0706668 0.00288401 0.00139833" quat="0.499887 -0.499951 0.500007 0.500155">
          <inertial pos="0.00265532 0.00126532 -0.00107181" quat="0.999715 0.0233234 0.0050215 -0.000984766" mass="0.298543" diaginertia="0.0408684 0.0497132 0.00185098"/>
          <joint name="femur_joint_LR" class="/" pos="0 0 0" axis="-0.0265486 -0.00105817 0.999647" range="-3.17101 3.10868" armature="0.0113125" damping="0.0129794" frictionloss="0.0178621"/>
          <geom name="//unnamed_geom_34" class="/" type="mesh" rgba="0.9 0.9 0.9 1" mesh="femur"/>
          <geom name="//unnamed_geom_35" class="reward_collision_sphere" size="0.0457167"/>
          <body name="tibia_LR" pos="0.0070409 -0.151863 -0.0088134" quat="0.00260485 0.999989 -0.00173763 0.00361133">
            <inertial pos="0.00133901 0.00167242 -0.000633336" quat="0.999999 0.00102467 -0.00106918 0.000131688" mass="0.276133" diaginertia="0.0379903 0.0521389 0.00172855"/>
            <joint name="tibia_joint_LR" class="/" pos="0 0 0" axis="0.0145146 -0.0197831 -0.999699" range="-3.05217 3.29406" armature="0.0107143" damping="0.00746049" frictionloss="0.0122511"/>
            <geom name="//unnamed_geom_36" class="/" type="mesh" rgba="0.2 0.2 0.2 1" mesh="tibia"/>
            <geom name="//unnamed_geom_37" class="reward_collision_sphere" size="0.0457167"/>
            <body name="tarsus_LR" pos="0.124513 -5.51829e-05 -0.00759047" quat="0.999987 -0.000946971 -0.00308662 -0.00386219">
              <inertial pos="0.0676627 0.00055051 0.0109841" quat="0.497969 0.49642 0.50083 0.504742" mass="0.312653" diaginertia="0.0388923 0.0572511 0.00176753"/>
              <joint name="tarsus_joint_LR" class="/" pos="0 0 0" axis="-0.0274467 0.0365813 -0.998954" range="-2.97221 3.30643" armature="0.0121006" damping="0.0205513" frictionloss="0.0101139"/>
              <geom name="//unnamed_geom_38" class="/" type="mesh" rgba="0.9 0.9 0.9 1" mesh="tarsus"/>
              <geom name="foot_4" class="foot" size="0.00923315" pos="0.147227 0 0" quat="0.707107 0 -0.707107 0"/>
              <geom name="//unnamed_geom_40" class="reward_collision_sphere" size="0.0457167"/>
              <geom name="//unnamed_geom_41" class="reward_collision_sphere" size="0.0171438" pos="0.141312 0 0"/>
              <site name="foot_4" class="foot" pos="0.147227 0 0" quat="0.707107 0 -0.707107 0" size="0.0114292"/>
            </body>
          </body>
        </body>
      </body>
      <body name="coxa_LM" pos="-0.00759607 0.186728 0.0373229" quat="0.70819 -0.000912922 0.000513227 0.706021">
        <inertial pos="-0.00101499 0.00226993 0.00464232" quat="0.999569 -0.0278188 0.00931684 0.00126696" mass="0.306284" diaginertia="0.0427722 0.05616 0.00189821"/>
        <joint name="coxa_joint_LM" class="/" pos="0 0 0" axis="0.00246659 0.00045338 -0.999997" stiffness="0.028211" range="-3.30501 3.17317" armature="0.00937294" damping="0" frictionloss="0.00700315"/>
        <geom name="//unnamed_geom_42" class="/" type="mesh" rgba="0.2 0.2 0.2 1" mesh="coxa"/>
        <geom name="//unnamed_geom_43" class="reward_collision_sphere" size="0.0457167" pos="-0.0394358 0 0"/>
        <body name="femur_LM" pos="0.07593 -0.00244316 -0.01069" quat="0.497396 -0.501763 0.499699 0.501131">
          <inertial pos="-0.00391425 0.00836896 -0.0114639" quat="0.998694 0.0386566 0.00864221 0.0322744" mass="0.29298" diaginertia="0.0365116 0.0611172 0.00175585"/>
          <joint name="femur_joint_LM" class="/" pos="0 0 0" axis="0.028232 -0.00551977 0.999586" range="-3.13589 3.29684" armature="0.00879381" damping="0.0141426" frictionloss="0.0120116"/>
          <geom name="//unnamed_geom_44" class="/" type="mesh" rgba="0.9 0.9 0.9 1" mesh="femur"/>
          <geom name="//unnamed_geom_45" class="reward_collision_sphere" size="0.0457167"/>
          <body name="tibia_LM" pos="0.00429069 -0.147446 0.00874473" quat="0.00246923 0.999983 -0.00442703 0.00270361">
            <inertial pos="-0.000776133 0.0120234 -0.00188062" quat="0.999544 -0.0191455 -0.0219 0.00805665" mass="0.308029" diaginertia="0.0382415 0.0478034 0.00179728"/>
            <joint name="tibia_joint_LM" class="/" pos="0 0 0" axis="-0.00379737 0.0187234 -0.999817" stiffness="0.0107336" range="-3.11366 3.10286" armature="0.006544" damping="0.0593757" frictionloss="0.014026"/>
            <geom name="//unnamed_geom_46" class="/" type="mesh" rgba="0.2 0.2 0.2 1" mesh="tibia"/>
            <geom name="//unnamed_geom_47" class="reward_collision_sphere" size="0.0457167"/>
            <body name="tarsus_LM" pos="0.11429 0.000903247 -0.0056553" quat="0.999982 -0.00491091 -0.00265955 0.00222917">
              <inertial pos="0.0853382 -0.00159756 0.00455074" quat="0.499732 0.499327 0.501185 0.499754" mass="0.314181" diaginertia="0.0464243 0.0620349 0.00192032"/>
              <joint name="tarsus_joint_LM" class="/" pos="0 0 0" axis="-0.000189847 -9.58993e-05 -1" stiffness="0.0212802" range="-3.36702 3.1199" armature="0.00611161" damping="0.0660317" frictionloss="0.00975159"/>
              <geom name="//unnamed_geom_48" class="/" type="mesh" rgba="0.9 0.9 0.9 1" mesh="tarsus"/>
              <geom name="foot_5" class="foot" size="0.0103434" pos="0.147227 0 0" quat="0.707107 0 -0.707107 0"/>
              <geom name="//unnamed_geom_50" class="reward_collision_sphere" size="0.0457167"/>
              <geom name="//unnamed_geom_51" class="reward_collision_sphere" size="0.0171438" pos="0.141312 0 0"/>
              <site name="foot_5" class="foot" pos="0.147227 0 0" quat="0.707107 0 -0.707107 0" size="0.0114292"/>
            </body>
          </body>
        </body>
      </body>
      <body name="coxa_LF" pos="0.222406 0.106115 0.0562412" quat="0.923846 0.000788825 0.000108536 0.382763">
        <inertial pos="-0.000771821 0.0010779 0.00287581" quat="0.999481 0.00921923 -0.0307575 -0.00249802" mass="0.35941" diaginertia="0.0453369 0.0623189 0.00207269"/>
        <joint name="coxa_joint_LF" class="/" pos="0 0 0" axis="-0.000478791 -0.00110118 -0.999999" stiffness="0.0201816" range="-3.06998 2.91321" armature="0.00663272" damping="0.0675712" frictionloss="0.0149718"/>
        <geom name="//unnamed_geom_52" class="/" type="mesh" rgba="0.2 0.2 0.2 1" mesh="coxa"/>
        <geom name="//unnamed_geom_53" class="reward_collision_sphere" size="0.0457167" pos="-0.0394358 0 0"/>
        <body name="femur_LF" pos="0.0761176 0.0102442 -0.00309208" quat="0.502351 -0.496951 0.498256 0.502418">
          <inertial pos="-0.0110721 -0.000111875 0.00138095" quat="0.999983 0.000484206 -0.0032481 -0.00479423" mass="0.303858" diaginertia="0.0399725 0.0538293 0.00201305"/>
          <joint name="femur_joint_LF" class="/" pos="0 0 0" axis="-0.000391647 0.00492617 0.999988" range="-3.25238 3.13645" armature="0.00661841" damping="0" frictionloss="0.0119785"/>
          <geom name="//unnamed_geom_54" class="/" type="mesh" rgba="0.9 0.9 0.9 1" mesh="femur"/>
          <geom name="//unnamed_geom_55" class="reward_collision_sphere" size="0.0457167"/>
          <body name="tibia_LF" pos="0.00475221 -0.160828 -0.00550367" quat="-0.000538553 1 -0.000185556 0.000221611">
            <inertial pos="0.000887407 -0.00705621 -0.00337787" quat="0.999976 0.00452109 -0.00501633 -0.00166174" mass="0.313079" diaginertia="0.0400362 0.0550067 0.00185656"/>
            <joint name="tibia_joint_LF" class="/" pos="0 0 0" axis="-0.000450097 0.00129724 -0.999999" stiffness="0.027573" range="-3.12877 3.16562" armature="0.0148926" damping="0.0390245" frictionloss="0.00901304"/>
            <geom name="//unnamed_geom_56" class="/" type="mesh" rgba="0.2 0.2 0.2 1" mesh="tibia"/>
            <geom name="//unnamed_geom_57" class="reward_collision_sphere" size="0.0457167"/>
            <body name="tarsus_LF" pos="0.114362 -0.00460645 -0.00449849" quat="0.999987 0.00175675 -0.00288824 -0.00389419">
              <inertial pos="0.0784043 0.00242385 0.00399871" quat="0.52643 0.482097 0.502211 0.488096" mass="0.276642" diaginertia="0.0392716 0.0479105 0.0017185"/>
              <joint name="tarsus_joint_LF" class="/" pos="0 0 0" axis="0.0119304 -0.0162484 -0.999797" range="-2.99058 3.05969" armature="0.0119212" damping="0.0642025" frictionloss="0.0106037"/>
              <geom name="//unnamed_geom_58" class="/" type="mesh" rgba="0.9 0.9 0.9 1" mesh="tarsus"/>
              <geom name="foot_6" class="foot" size="0.0105509" pos="0.147227 0 0" quat="0.707107 0 -0.707107 0"/>
              <geom name="//unnamed_geom_60" class="reward_collision_sphere" size="0.0457167"/>
              <geom name="//unnamed_geom_61" class="reward_collision_sphere" size="0.0171438" pos="0.141312 0 0"/>
              <site name="foot_6" class="foot" pos="0.147227 0 0" quat="0.707107 0 -0.707107 0" size="0.0114292"/>
            </body>
          </body>
        </body>
      </body>
    </body>
  </worldbody>

  <contact>
    <pair class="/" geom1="floor" geom2="foot_1" name="//unnamed_contact_0"/>
    <pair class="/" geom1="floor" geom2="foot_2" name="//unnamed_contact_1"/>
    <pair class="/" geom1="floor" geom2="foot_3" name="//unnamed_contact_2"/>
    <pair class="/" geom1="floor" geom2="foot_4" name="//unnamed_contact_3"/>
    <pair class="/" geom1="floor" geom2="foot_5" name="//unnamed_contact_4"/>
    <pair class="/" geom1="floor" geom2="foot_6" name="//unnamed_contact_5"/>
  </contact>

  <actuator>
    <general name="coxa_joint_RR" class="/" joint="coxa_joint_RR" forcerange="-8.69829 8.69829" gainprm="26.7602" biasprm="0 -26.7602 -0.549954"/>
    <general name="femur_joint_RR" class="/" joint="femur_joint_RR" forcerange="-8.35738 8.35738" gainprm="26.7602" biasprm="0 -26.7602 -0.549954"/>
    <general name="tibia_joint_RR" class="/" joint="tibia_joint_RR" forcerange="-8.76016 8.76016" gainprm="26.7602" biasprm="0 -26.7602 -0.549954"/>
    <general name="tarsus_joint_RR" class="/" joint="tarsus_joint_RR" forcerange="-6.06445 6.06445" gainprm="26.7602" biasprm="0 -26.7602 -0.549954"/>
    <general name="coxa_joint_RM" class="/" joint="coxa_joint_RM" forcerange="-11.713 11.713" gainprm="26.7602" biasprm="0 -26.7602 -0.549954"/>
    <general name="femur_joint_RM" class="/" joint="femur_joint_RM" forcerange="-8.42133 8.42133" gainprm="26.7602" biasprm="0 -26.7602 -0.549954"/>
    <general name="tibia_joint_RM" class="/" joint="tibia_joint_RM" forcerange="-10.0786 10.0786" gainprm="26.7602" biasprm="0 -26.7602 -0.549954"/>
    <general name="tarsus_joint_RM" class="/" joint="tarsus_joint_RM" forcerange="-8.72518 8.72518" gainprm="26.7602" biasprm="0 -26.7602 -0.549954"/>
    <general name="coxa_joint_RF" class="/" joint="coxa_joint_RF" forcerange="-11.4537 11.4537" gainprm="26.7602" biasprm="0 -26.7602 -0.549954"/>
    <general name="femur_joint_RF" class="/" joint="femur_joint_RF" forcerange="-9.82852 9.82852" gainprm="26.7602" biasprm="0 -26.7602 -0.549954"/>
    <general name="tibia_joint_RF" class="/" joint="tibia_joint_RF" forcerange="-11.8822 11.8822" gainprm="26.7602" biasprm="0 -26.7602 -0.549954"/>
    <general name="tarsus_joint_RF" class="/" joint="tarsus_joint_RF" forcerange="-6.97733 6.97733" gainprm="26.7602" biasprm="0 -26.7602 -0.549954"/>
    <general name="coxa_joint_LR" class="/" joint="coxa_joint_LR" forcerange="-8.20446 8.20446" gainprm="26.7602" biasprm="0 -26.7602 -0.549954"/>
    <general name="femur_joint_LR" class="/" joint="femur_joint_LR" forcerange="-8.87743 8.87743" gainprm="26.7602" biasprm="0 -26.7602 -0.549954"/>
    <general name="tibia_joint_LR" class="/" joint="tibia_joint_LR" forcerange="-7.80537 7.80537" gainprm="26.7602" biasprm="0 -26.7602 -0.549954"/>
    <general name="tarsus_joint_LR" class="/" joint="tarsus_joint_LR" forcerange="-7.60535 7.60535" gainprm="26.7602" biasprm="0 -26.7602 -0.549954"/>
    <general name="coxa_joint_LM" class="/" joint="coxa_joint_LM" forcerange="-5.7931 5.7931" gainprm="26.7602" biasprm="0 -26.7602 -0.549954"/>
    <general name="femur_joint_LM" class="/" joint="femur_joint_LM" forcerange="-8.19234 8.19234" gainprm="26.7602" biasprm="0 -26.7602 -0.549954"/>
    <general name="tibia_joint_LM" class="/" joint="tibia_joint_LM" forcerange="-7.94591 7.94591" gainprm="26.7602" biasprm="0 -26.7602 -0.549954"/>
    <general name="tarsus_joint_LM" class="/" joint="tarsus_joint_LM" forcerange="-8.87519 8.87519" gainprm="26.7602" biasprm="0 -26.7602 -0.549954"/>
    <general name="coxa_joint_LF" class="/" joint="coxa_joint_LF" forcerange="-11.9808 11.9808" gainprm="26.7602" biasprm="0 -26.7602 -0.549954"/>
    <general name="femur_joint_LF" class="/" joint="femur_joint_LF" forcerange="-8.8865 8.8865" gainprm="26.7602" biasprm="0 -26.7602 -0.549954"/>
    <general name="tibia_joint_LF" class="/" joint="tibia_joint_LF" forcerange="-8.17053 8.17053" gainprm="26.7602" biasprm="0 -26.7602 -0.549954"/>
    <general name="tarsus_joint_LF" class="/" joint="tarsus_joint_LF" forcerange="-9.84658 9.84658" gainprm="26.7602" biasprm="0 -26.7602 -0.549954"/>
  </actuator>

  <sensor>
    <gyro site="imu" name="imu_angular_velocity"/>
    <velocimeter site="imu" name="imu_linear_velocity"/>
    <framelinvel objtype="site" objname="foot_1" name="foot_1_global_linear_velocity"/>
    <framelinvel objtype="site" objname="foot_2" name="foot_2_global_linear_velocity"/>
    <framelinvel objtype="site" objname="foot_3" name="foot_3_global_linear_velocity"/>
    <framelinvel objtype="site" objname="foot_4" name="foot_4_global_linear_velocity"/>
    <framelinvel objtype="site" objname="foot_5" name="foot_5_global_linear_velocity"/>
    <framelinvel objtype="site" objname="foot_6" name="foot_6_global_linear_velocity"/>
  </sensor>

  <keyframe>
    <key name="home" qpos="0 0 0.1457 1 0 0 0 0 0 0 0 0 0 0 0 0 0 0 0 0 0 0 0 0 0 0 0 0 0 0 0"/>
  </keyframe>
</mujoco>
