<mujoco model="Golem">
  <compiler angle="radian" assetdir="assets" balanceinertia="true" inertiafromgeom="false"/>

  <option timestep="0.005" density="1.2" viscosity="2e-05"/>

  <size nkey="1"/>

  <visual>
    <quality shadowsize="8192"/>
    <map shadowclip="0.5"/>
  </visual>

  <default>
    <default class="/">
      <joint armature="0.01" damping="0.01" frictionloss="0.01"/>
      <geom contype="0" conaffinity="0" group="1" solref="-1000 -80"/>
      <site size="0.01 0.005 0.005" group="5"/>
      <general forcelimited="true" biastype="affine" gainprm="25" biasprm="0 -25 -0.5"/>
      <default class="visual">
        <geom type="mesh" group="2"/>
      </default>
      <default class="collision">
        <geom group="3"/>
      </default>
      <default class="foot">
        <geom size="0.01 0 0" condim="6" group="4" priority="1" solimp="0.015 1 0.01"/>
      </default>
      <default class="reward_collision_sphere">
        <geom group="5" rgba="1 0 0 1"/>
      </default>
    </default>
  </default>

  <asset>
    <texture type="skybox" colorspace="auto" name="//unnamed_texture_0" builtin="gradient" rgb1="0.95 0.95 0.95" rgb2="0.95 0.95 0.95" width="100" height="600"/>
    <texture type="2d" colorspace="auto" name="texplane" builtin="checker" rgb1="0.345 0.575 0.748" rgb2="0.345 0.575 0.748" markrgb="1 1 1" width="512" height="512"/>
    <material name="MatPlane" class="/" texture="texplane" texuniform="true" texrepeat="2 2" specular="0.9"/>
    <mesh name="body" class="/" file="body.stl" scale="0.001 0.001 0.001"/>
    <mesh name="coxa" class="/" file="coxa.stl" scale="0.001 0.001 0.001"/>
    <mesh name="femur" class="/" file="femur.stl" scale="0.001 0.001 0.001"/>
    <mesh name="tibia" class="/" file="tibia.stl" scale="0.001 0.001 0.001"/>
    <mesh name="tarsus" class="/" file="tarsus.stl" scale="0.001 0.001 0.001"/>
  </asset>

  <worldbody>
    <geom name="floor" class="/" size="100 100 0.125" type="plane" group="0" material="MatPlane"/>
    <light name="toplight_shadow" class="/" pos="0 0 5" dir="0.0990148 0.0990148 -0.990148" type="directional" ambient="0.04 0.04 0.04" diffuse="0.55 0.55 0.55" specular="0.12 0.12 0.12"/>
    <light name="toplight_fill" class="/" pos="0 0 5" dir="0.0990148 0.0990148 -0.990148" type="directional" castshadow="false" ambient="0.04 0.04 0.04" diffuse="0.3 0.3 0.3" specular="0.08 0.08 0.08"/>
    <body name="trunk" pos="-0.000151847 0.000210764 -0.00043412" quat="0.999999 0.000448205 0.000451633 0.000864103">
      <inertial pos="0.000735563 -0.000982448 -0.00236648" quat="0.999999 0.000969738 -0.000368415 0.000199632" mass="1.59332" diaginertia="0.0051795 6.6905e-05 0.00978768"/>
      <joint name="//unnamed_joint_0" type="free"/>
      <geom name="//unnamed_geom_1" class="/" pos="0 0 0.0638554" quat="1 0 0 0" type="mesh" rgba="0.9 0.9 0.9 1" mesh="body"/>
      <site name="imu" class="/" pos="0.12642 -0.0112894 0.102195" size="0.00749114"/>
      <camera name="track" class="/" pos="0 -0.740595 0" quat="0.707107 0.707107 0 0" mode="trackcom"/>
      <camera name="ego_camera" class="/" pos="0.11431 0 0.0997741" quat="-0.5 -0.5 0.5 0.5"/>
      <body name="coxa_RR" pos="-0.157614 -0.029778 0.0611333" quat="0.382265 0.00099135 -4.64954e-06 -0.924052">
        <inertial pos="0.0001807 -0.000142542 0.00309295" quat="0.99992 -0.0100025 0.00662524 0.00409491" mass="0.0877758" diaginertia="0.00545486 7.24771e-05 0.0102097"/>
        <joint name="coxa_joint_RR" class="/" pos="0 0 0" axis="-0.00385076 -0.00196083 -0.999991" range="-3.19453 3.08653" armature="0.00748912" damping="0.0152906" frictionloss="0.00835743"/>
        <geom name="//unnamed_geom_2" class="/" type="mesh" rgba="0.2 0.2 0.2 1" mesh="coxa"/>
        <geom name="//unnamed_geom_3" class="reward_collision_sphere" size="0.0299646" pos="-0.0263791 0 0"/>
        <body name="femur_RR" pos="0.0537758 0.0014182 0.000657058" quat="0.499726 -0.499974 0.500474 0.499825">
          <inertial pos="0.000699613 -0.000525392 0.000741756" quat="0.999995 0.000244358 -0.0025588 0.00200216" mass="0.083774" diaginertia="0.00536258 7.13099e-05 0.00984944"/>
          <joint name="femur_joint_RR" class="/" pos="0 0 0" axis="0.00923174 -0.00187035 -0.999956" range="-3.08708 3.13854" armature="0.0064169" damping="0" frictionloss="0.0074054"/>
          <geom name="//unnamed_geom_4" class="/" type="mesh" rgba="0.9 0.9 0.9 1" mesh="femur"/>
          <geom name="//unnamed_geom_5" class="reward_collision_sphere" size="0.0299646"/>
          <body name="tibia_RR" pos="-0.00245737 -0.0376574 0.00196371" quat="-0.000454323 0.999999 -0.000570385 0.00111608">
            <inertial pos="0.00290013 0.00241214 -0.00113918" quat="0.999993 -0.000673102 0.00281345 0.00225382" mass="0.0869013" diaginertia="0.00522416 6.9587e-05 0.00953452"/>
            <joint name="tibia_joint_RR" class="/" pos="0 0 0" axis="-0.00865063 -0.00935788 0.999919" range="-3.08886 3.13643" armature="0.00651178" damping="0" frictionloss="0.00787931"/>
            <geom name="//unnamed_geom_6" class="/" type="mesh" rgba="0.2 0.2 0.2 1" mesh="tibia"/>
            <geom name="//unnamed_geom_7" class="reward_collision_sphere" size="0.0299646"/>
            <body name="tarsus_RR" pos="0.0745442 0.00177988 -0.00241942" quat="1 -0.000136052 0.000384315 -0.000265261">
              <inertial pos="0.0506245 0.00133267 -0.00124046" quat="0.499293 0.499635 0.501164 0.499906" mass="0.0876177" diaginertia="0.00550841 6.9442e-05 0.0104529"/>
              <joint name="tarsus_joint_RR" class="/" pos="0 0 0" axis="-0.0129578 0.00312794 0.999911" stiffness="0.00212252" range="-3.17184 3.15778" armature="0.00766094" damping="0" frictionloss="0.00715089"/>
              <geom name="//unnamed_geom_8" class="/" type="mesh" rgba="0.9 0.9 0.9 1" mesh="tarsus"/>
              <geom name="foot_1" class="foot" size="0.00750769" pos="0.0984821 0 0" quat="0 -0.707107 0 0.707107"/>
              <geom name="//unnamed_geom_10" class="reward_collision_sphere" size="0.0299646"/>
              <geom name="//unnamed_geom_11" class="reward_collision_sphere" size="0.0112367" pos="0.0945252 0 0"/>
              <site name="foot_1" class="foot" pos="0.0984821 0 0" quat="0 -0.707107 0 0.707107" size="0.00749114"/>
            </body>
          </body>
        </body>
      </body>
      <body name="coxa_RM" pos="-0.00120231 -0.0495971 0.0649513" quat="0.706922 -0.000964951 -0.000927696 -0.70729">
        <inertial pos="0.00195831 -0.00256633 0.0019158" quat="0.999993 0.000786886 0.00349076 -0.000790747" mass="0.0812766" diaginertia="0.00509701 6.9829e-05 0.00985412"/>
        <joint name="coxa_joint_RM" class="/" pos="0 0 0" axis="0.00651768 -0.0121464 -0.999905" range="-3.13515 3.19389" armature="0.00831763" damping="7.28624e-05" frictionloss="0.00648534"/>
        <geom name="//unnamed_geom_12" class="/" type="mesh" rgba="0.2 0.2 0.2 1" mesh="coxa"/>
        <geom name="//unnamed_geom_13" class="reward_collision_sphere" size="0.0299646" pos="-0.0263791 0 0"/>
        <body name="femur_RM" pos="0.0494159 6.68776e-05 -0.00177634" quat="0.499965 -0.500067 0.500023 0.499945">
          <inertial pos="0.00248402 -0.000566045 -0.000508095" quat="0.999997 0.00054676 8.7173e-05 -0.00221398" mass="0.0885164" diaginertia="0.00527146 7.08395e-05 0.0100516"/>
          <joint name="femur_joint_RM" class="/" pos="0 0 0" axis="0.00345599 -0.00067657 -0.999994" range="-3.17641 3.13511" armature="0.00763332" damping="0.0173745" frictionloss="0.00846429"/>
          <geom name="//unnamed_geom_14" class="/" type="mesh" rgba="0.9 0.9 0.9 1" mesh="femur"/>
          <geom name="//unnamed_geom_15" class="reward_collision_sphere" size="0.0299646"/>
          <body name="tibia_RM" pos="0.000741822 -0.037102 -0.000365567" quat="0.000526437 1 3.52513e-05 0.00025634">
            <inertial pos="0.00109492 -0.00275068 -0.0027522" quat="0.999905 0.00753181 -0.0106721 -0.00450706" mass="0.0847728" diaginertia="0.00545026 6.95367e-05 0.0102683"/>
            <joint name="tibia_joint_RM" class="/" pos="0 0 0" axis="0.000782017 0.000680924 0.999999" range="-3.157 3.1129" armature="0.00839568" damping="0.0120148" frictionloss="0.00834957"/>
            <geom name="//unnamed_geom_16" class="/" type="mesh" rgba="0.2 0.2 0.2 1" mesh="tibia"/>
            <geom name="//unnamed_geom_17" class="reward_collision_sphere" size="0.0299646"/>
            <body name="tarsus_RM" pos="0.0779435 0.000380391 -0.0002509" quat="1 5.11633e-05 -1.58817e-05 1.87907e-05">
              <inertial pos="0.0556381 -0.000240342 0.000889079" quat="0.490175 0.497853 0.505444 0.506357" mass="0.0831077" diaginertia="0.00536257 7.06301e-05 0.00955891"/>
              <joint name="tarsus_joint_RM" class="/" pos="0 0 0" axis="0.000164736 0.000761218 1" range="-3.08918 3.17482" armature="0.00835162" damping="0.00686695" frictionloss="0.00739432"/>
              <geom name="//unnamed_geom_18" class="/" type="mesh" rgba="0.9 0.9 0.9 1" mesh="tarsus"/>
              <geom name="foot_2" class="foot" size="0.00825428" pos="0.0984821 0 0" quat="0 -0.707107 0 0.707107"/>
              <geom name="//unnamed_geom_20" class="reward_collision_sphere" size="0.0299646"/>
              <geom name="//unnamed_geom_21" class="reward_collision_sphere" size="0.0112367" pos="0.0945252 0 0"/>
              <site name="foot_2" class="foot" pos="0.0984821 0 0" quat="0 -0.707107 0 0.707107" size="0.00749114"/>
            </body>
          </body>
        </body>
      </body>
      <body name="coxa_RF" pos="0.154249 -0.0295568 0.0645802" quat="0.923868 0.000260834 -0.000277814 -0.38271">
        <inertial pos="-0.00252294 -0.0020452 0.00291297" quat="0.99991 0.0131112 0.00250427 0.00157821" mass="0.0839987" diaginertia="0.00543491 6.89832e-05 0.00989556"/>
        <joint name="coxa_joint_RF" class="/" pos="0 0 0" axis="-0.00211169 0.00254896 -0.999995" range="-3.16569 3.19081" armature="0.0065794" damping="0.00712467" frictionloss="0.00788993"/>
        <geom name="//unnamed_geom_22" class="/" type="mesh" rgba="0.2 0.2 0.2 1" mesh="coxa"/>
        <geom name="//unnamed_geom_23" class="reward_collision_sphere" size="0.0299646" pos="-0.0263791 0 0"/>
        <body name="femur_RF" pos="0.0539684 -0.00219906 -0.000215148" quat="0.501055 -0.499326 0.499883 0.499734">
          <inertial pos="-0.000258565 -0.00290837 0.00269418" quat="0.999921 -0.00507568 0.000653291 0.0114704" mass="0.0839187" diaginertia="0.00506233 6.70157e-05 0.00990692"/>
          <joint name="femur_joint_RF" class="/" pos="0 0 0" axis="0.00289498 -0.00121704 -0.999995" range="-3.087 3.13925" armature="0.00727361" damping="0" frictionloss="0.00649978"/>
          <geom name="//unnamed_geom_24" class="/" type="mesh" rgba="0.9 0.9 0.9 1" mesh="femur"/>
          <geom name="//unnamed_geom_25" class="reward_collision_sphere" size="0.0299646"/>
          <body name="tibia_RF" pos="0.00184817 -0.0399725 0.001731" quat="0.00071212 0.999999 0.000895301 0.0008485">
            <inertial pos="8.50138e-05 0.00245616 -0.000979317" quat="0.999916 0.0128182 0.00119793 -0.00174606" mass="0.0852765" diaginertia="0.00533959 6.96883e-05 0.00997577"/>
            <joint name="tibia_joint_RF" class="/" pos="0 0 0" axis="-0.0103858 -0.00737902 0.999919" stiffness="0.00187004" range="-3.12561 3.12557" armature="0.00725761" damping="0.000639345" frictionloss="0.00750386"/>
            <geom name="//unnamed_geom_26" class="/" type="mesh" rgba="0.2 0.2 0.2 1" mesh="tibia"/>
            <geom name="//unnamed_geom_27" class="reward_collision_sphere" size="0.0299646"/>
            <body name="tarsus_RF" pos="0.0757731 -0.000402868 -0.00166137" quat="0.999999 -0.000199546 -0.00135074 -1.48241e-05">
              <inertial pos="0.0502429 0.000830533 0.00222408" quat="0.492631 0.510692 0.495795 0.500695" mass="0.0791718" diaginertia="0.00525516 6.82796e-05 0.00952013"/>
              <joint name="tarsus_joint_RF" class="/" pos="0 0 0" axis="-0.00641504 -0.0120963 0.999906" range="-3.08987 3.13184" armature="0.00745769" damping="0.00482043" frictionloss="0.00846159"/>
              <geom name="//unnamed_geom_28" class="/" type="mesh" rgba="0.9 0.9 0.9 1" mesh="tarsus"/>
              <geom name="foot_3" class="foot" size="0.00747233" pos="0.0984821 0 0" quat="0 -0.707107 0 0.707107"/>
              <geom name="//unnamed_geom_30" class="reward_collision_sphere" size="0.0299646"/>
              <geom name="//unnamed_geom_31" class="reward_collision_sphere" size="0.0112367" pos="0.0945252 0 0"/>
              <site name="foot_3" class="foot" pos="0.0984821 0 0" quat="0 -0.707107 0 0.707107" size="0.00749114"/>
            </body>
          </body>
        </body>
      </body>
      <body name="coxa_LR" pos="-0.154088 0.0348321 0.0648691" quat="0.382043 -0.000819163 -0.00096254 0.924144">
        <inertial pos="0.00296844 -0.000107461 -0.00199473" quat="0.999904 0.00209939 0.0083451 -0.0108329" mass="0.0845511" diaginertia="0.00518599 7.0091e-05 0.00995385"/>
        <joint name="coxa_joint_LR" class="/" pos="0 0 0" axis="-0.0104526 -0.00183446 -0.999944" range="-3.12376 3.1212" armature="0.00708077" damping="0.00259167" frictionloss="0.00729504"/>
        <geom name="//unnamed_geom_32" class="/" type="mesh" rgba="0.2 0.2 0.2 1" mesh="coxa"/>
        <geom name="//unnamed_geom_33" class="reward_collision_sphere" size="0.0299646" pos="-0.0263791 0 0"/>
        <body name="femur_LR" pos="0.0527231 -0.00368979 0.000565287" quat="0.498898 -0.500552 0.499982 0.500566">
          <inertial pos="0.000559122 0.000523213 -0.000834963" quat="0.999997 -0.00101392 -0.00227464 -0.000261218" mass="0.0860669" diaginertia="0.00532228 7.06498e-05 0.0101961"/>
          <joint name="femur_joint_LR" class="/" pos="0 0 0" axis="0.00251701 0.000529951 0.999997" range="-3.10487 3.18094" armature="0.00786594" damping="0" frictionloss="0.00834719"/>
          <geom name="//unnamed_geom_34" class="/" type="mesh" rgba="0.9 0.9 0.9 1" mesh="femur"/>
          <geom name="//unnamed_geom_35" class="reward_collision_sphere" size="0.0299646"/>
          <body name="tibia_LR" pos="-0.00050152 -0.0432487 -0.0050091" quat="0.000248009 1 -0.000403099 -0.000182712">
            <inertial pos="0.000684746 -0.00273027 0.00287384" quat="1 0.000791773 0.000362206 0.000453282" mass="0.0828911" diaginertia="0.00532421 7.27579e-05 0.0099985"/>
            <joint name="tibia_joint_LR" class="/" pos="0 0 0" axis="-0.000449134 0.00726026 -0.999974" range="-3.1389 3.0842" armature="0.00657877" damping="0.00826865" frictionloss="0.00675627"/>
            <geom name="//unnamed_geom_36" class="/" type="mesh" rgba="0.2 0.2 0.2 1" mesh="tibia"/>
            <geom name="//unnamed_geom_37" class="reward_collision_sphere" size="0.0299646"/>
            <body name="tarsus_LR" pos="0.0769524 0.00369565 0.000260268" quat="1 0.00016356 1.281e-05 -8.87894e-05">
              <inertial pos="0.0525066 -0.000995162 0.00049925" quat="0.499919 0.499978 0.50009 0.500012" mass="0.0834571" diaginertia="0.00519578 6.8165e-05 0.00984372"/>
              <joint name="tarsus_joint_LR" class="/" pos="0 0 0" axis="0.00141531 0.00426618 -0.99999" range="-3.0874 3.14285" armature="0.00757076" damping="0.000860236" frictionloss="0.00709131"/>
              <geom name="//unnamed_geom_38" class="/" type="mesh" rgba="0.9 0.9 0.9 1" mesh="tarsus"/>
              <geom name="foot_4" class="foot" size="0.00676511" pos="0.0984821 0 0" quat="0.707107 0 -0.707107 0"/>
              <geom name="//unnamed_geom_40" class="reward_collision_sphere" size="0.0299646"/>
              <geom name="//unnamed_geom_41" class="reward_collision_sphere" size="0.0112367" pos="0.0945252 0 0"/>
              <site name="foot_4" class="foot" pos="0.0984821 0 0" quat="0.707107 0 -0.707107 0" size="0.00749114"/>
            </body>
          </body>
        </body>
      </body>
      <body name="coxa_LM" pos="-0.00374741 0.0481612 0.0619003" quat="0.706663 0.000175677 0.000916481 0.70755">
        <inertial pos="-0.000589553 -2.05437e-05 0.00276216" quat="0.999987 0.00283227 -0.000966938 -0.00403991" mass="0.0856394" diaginertia="0.00554909 7.14589e-05 0.0103318"/>
        <joint name="coxa_joint_LM" class="/" pos="0 0 0" axis="0.000426911 0.000879601 -1" stiffness="0.00653993" range="-3.19509 3.15409" armature="0.00643277" damping="0.000429763" frictionloss="0.008531"/>
        <geom name="//unnamed_geom_42" class="/" type="mesh" rgba="0.2 0.2 0.2 1" mesh="coxa"/>
        <geom name="//unnamed_geom_43" class="reward_collision_sphere" size="0.0299646" pos="-0.0263791 0 0"/>
        <body name="femur_LM" pos="0.0476901 0.00375243 0.00138856" quat="0.500019 -0.500016 0.499893 0.500072">
          <inertial pos="-0.000499427 -0.00282742 6.94703e-06" quat="0.999934 0.00551565 0.00574634 -0.00829127" mass="0.0788014" diaginertia="0.00509214 6.7722e-05 0.00958705"/>
          <joint name="femur_joint_LM" class="/" pos="0 0 0" axis="0.00632495 0.00931438 0.999937" range="-3.14847 3.15615" armature="0.0067636" damping="0.00723809" frictionloss="0.00841158"/>
          <geom name="//unnamed_geom_44" class="/" type="mesh" rgba="0.9 0.9 0.9 1" mesh="femur"/>
          <geom name="//unnamed_geom_45" class="reward_collision_sphere" size="0.0299646"/>
          <body name="tibia_LM" pos="-0.000843938 -0.0381201 0.0016622" quat="-0.000159502 1 0.000355436 4.53454e-05">
            <inertial pos="-0.00241264 0.000950283 -0.00094576" quat="1 4.52509e-05 -1.83493e-05 1.88825e-05" mass="0.086113" diaginertia="0.00502222 6.92088e-05 0.00967872"/>
            <joint name="tibia_joint_LM" class="/" pos="0 0 0" axis="0.000334264 0.000180835 -1" range="-3.08559 3.13714" armature="0.00728951" damping="0" frictionloss="0.00668639"/>
            <geom name="//unnamed_geom_46" class="/" type="mesh" rgba="0.2 0.2 0.2 1" mesh="tibia"/>
            <geom name="//unnamed_geom_47" class="reward_collision_sphere" size="0.0299646"/>
            <body name="tarsus_LM" pos="0.0803595 -0.000386753 -0.00332033" quat="1 2.81455e-05 0.000240351 0.000193301">
              <inertial pos="0.0510655 -0.00014632 -0.000193249" quat="0.49971 0.496922 0.499397 0.503945" mass="0.080469" diaginertia="0.0051311 6.87452e-05 0.0101017"/>
              <joint name="tarsus_joint_LM" class="/" pos="0 0 0" axis="0.00329444 0.0119152 -0.999924" range="-3.13937 3.08463" armature="0.0075253" damping="0.0126869" frictionloss="0.00644983"/>
              <geom name="//unnamed_geom_48" class="/" type="mesh" rgba="0.9 0.9 0.9 1" mesh="tarsus"/>
              <geom name="foot_5" class="foot" size="0.00723864" pos="0.0984821 0 0" quat="0.707107 0 -0.707107 0"/>
              <geom name="//unnamed_geom_50" class="reward_collision_sphere" size="0.0299646"/>
              <geom name="//unnamed_geom_51" class="reward_collision_sphere" size="0.0112367" pos="0.0945252 0 0"/>
              <site name="foot_5" class="foot" pos="0.0984821 0 0" quat="0.707107 0 -0.707107 0" size="0.00749114"/>
            </body>
          </body>
        </body>
      </body>
      <body name="coxa_LF" pos="0.155486 0.0332576 0.0650101" quat="0.923661 -0.00054527 -0.000521192 0.38321">
        <inertial pos="0.00147481 -0.00254432 0.000802956" quat="0.999998 0.000223758 0.000435525 -0.0020046" mass="0.0815414" diaginertia="0.00508559 6.48968e-05 0.00956954"/>
        <joint name="coxa_joint_LF" class="/" pos="0 0 0" axis="0.00497399 -0.00679738 -0.999965" range="-3.1916 3.12389" armature="0.00755749" damping="0" frictionloss="0.00820784"/>
        <geom name="//unnamed_geom_52" class="/" type="mesh" rgba="0.2 0.2 0.2 1" mesh="coxa"/>
        <geom name="//unnamed_geom_53" class="reward_collision_sphere" size="0.0299646" pos="-0.0263791 0 0"/>
        <body name="femur_LF" pos="0.0493031 0.00277322 -0.00213785" quat="0.501094 -0.499614 0.499746 0.499544">
          <inertial pos="-0.00037594 -0.000362619 0.00105747" quat="0.999938 0.000587454 -0.00364857 -0.0104899" mass="0.083483" diaginertia="0.00521168 6.68997e-05 0.00953638"/>
          <joint name="femur_joint_LF" class="/" pos="0 0 0" axis="-0.0103348 0.00914009 0.999905" range="-3.1439 3.10812" armature="0.00778928" damping="0.0117231" frictionloss="0.00671035"/>
          <geom name="//unnamed_geom_54" class="/" type="mesh" rgba="0.9 0.9 0.9 1" mesh="femur"/>
          <geom name="//unnamed_geom_55" class="reward_collision_sphere" size="0.0299646"/>
          <body name="tibia_LF" pos="-0.000161075 -0.0389812 -0.000829782" quat="-2.29105e-05 1 -2.80035e-06 1.53882e-05">
            <inertial pos="-0.000598117 0.000627587 3.49149e-05" quat="0.999958 0.00345055 -0.00268536 -0.00800923" mass="0.0867094" diaginertia="0.00524555 6.80066e-05 0.00964176"/>
            <joint name="tibia_joint_LF" class="/" pos="0 0 0" axis="-0.0130954 0.00273263 -0.999911" stiffness="0.0062121" range="-3.18639 3.13022" armature="0.00826232" damping="0.0120117" frictionloss="0.00653066"/>
            <geom name="//unnamed_geom_56" class="/" type="mesh" rgba="0.2 0.2 0.2 1" mesh="tibia"/>
            <geom name="//unnamed_geom_57" class="reward_collision_sphere" size="0.0299646"/>
            <body name="tarsus_LF" pos="0.078904 0.000655666 0.00140661" quat="1 -3.3896e-05 -4.39437e-05 -8.51322e-06">
              <inertial pos="0.0520705 -0.000156097 0.00240426" quat="0.500371 0.499673 0.500047 0.499909" mass="0.0839655" diaginertia="0.00520917 6.88565e-05 0.00964953"/>
              <joint name="tarsus_joint_LF" class="/" pos="0 0 0" axis="-0.0145113 -0.00529659 -0.999881" stiffness="0.0296631" range="-3.13616 3.18278" armature="0.00736736" damping="0.0229508" frictionloss="0.00708948"/>
              <geom name="//unnamed_geom_58" class="/" type="mesh" rgba="0.9 0.9 0.9 1" mesh="tarsus"/>
              <geom name="foot_6" class="foot" size="0.00731014" pos="0.0984821 0 0" quat="0.707107 0 -0.707107 0"/>
              <geom name="//unnamed_geom_60" class="reward_collision_sphere" size="0.0299646"/>
              <geom name="//unnamed_geom_61" class="reward_collision_sphere" size="0.0112367" pos="0.0945252 0 0"/>
              <site name="foot_6" class="foot" pos="0.0984821 0 0" quat="0.707107 0 -0.707107 0" size="0.00749114"/>
            </body>
          </body>
        </body>
      </body>
    </body>
  </worldbody>

  <contact>
    <pair class="/" geom1="floor" geom2="foot_1" name="//unnamed_contact_0"/>
    <pair class="/" geom1="floor" geom2="foot_2" name="//unnamed_contact_1"/>
    <pair class="/" geom1="floor" geom2="foot_3" name="//unnamed_contact_2"/>
    <pair class="/" geom1="floor" geom2="foot_4" name="//unnamed_contact_3"/>
    <pair class="/" geom1="floor" geom2="foot_5" name="//unnamed_contact_4"/>
    <pair class="/" geom1="floor" geom2="foot_6" name="//unnamed_contact_5"/>
  </contact>

  <actuator>
    <general name="coxa_joint_RR" class="/" joint="coxa_joint_RR" forcerange="-6.02177 6.02177" gainprm="17.3822" biasprm="0 -17.3822 -0.363604"/>
    <general name="femur_joint_RR" class="/" joint="femur_joint_RR" forcerange="-5.73676 5.73676" gainprm="17.3822" biasprm="0 -17.3822 -0.363604"/>
    <general name="tibia_joint_RR" class="/" joint="tibia_joint_RR" forcerange="-5.55756 5.55756" gainprm="17.3822" biasprm="0 -17.3822 -0.363604"/>
    <general name="tarsus_joint_RR" class="/" joint="tarsus_joint_RR" forcerange="-5.29252 5.29252" gainprm="17.3822" biasprm="0 -17.3822 -0.363604"/>
    <general name="coxa_joint_RM" class="/" joint="coxa_joint_RM" forcerange="-6.02624 6.02624" gainprm="17.3822" biasprm="0 -17.3822 -0.363604"/>
    <general name="femur_joint_RM" class="/" joint="femur_joint_RM" forcerange="-6.03958 6.03958" gainprm="17.3822" biasprm="0 -17.3822 -0.363604"/>
    <general name="tibia_joint_RM" class="/" joint="tibia_joint_RM" forcerange="-5.17308 5.17308" gainprm="17.3822" biasprm="0 -17.3822 -0.363604"/>
    <general name="tarsus_joint_RM" class="/" joint="tarsus_joint_RM" forcerange="-5.94461 5.94461" gainprm="17.3822" biasprm="0 -17.3822 -0.363604"/>
    <general name="coxa_joint_RF" class="/" joint="coxa_joint_RF" forcerange="-6.01468 6.01468" gainprm="17.3822" biasprm="0 -17.3822 -0.363604"/>
    <general name="femur_joint_RF" class="/" joint="femur_joint_RF" forcerange="-4.92547 4.92547" gainprm="17.3822" biasprm="0 -17.3822 -0.363604"/>
    <general name="tibia_joint_RF" class="/" joint="tibia_joint_RF" forcerange="-5.22769 5.22769" gainprm="17.3822" biasprm="0 -17.3822 -0.363604"/>
    <general name="tarsus_joint_RF" class="/" joint="tarsus_joint_RF" forcerange="-5.39566 5.39566" gainprm="17.3822" biasprm="0 -17.3822 -0.363604"/>
    <general name="coxa_joint_LR" class="/" joint="coxa_joint_LR" forcerange="-5.83131 5.83131" gainprm="17.3822" biasprm="0 -17.3822 -0.363604"/>
    <general name="femur_joint_LR" class="/" joint="femur_joint_LR" forcerange="-4.93186 4.93186" gainprm="17.3822" biasprm="0 -17.3822 -0.363604"/>
    <general name="tibia_joint_LR" class="/" joint="tibia_joint_LR" forcerange="-5.20075 5.20075" gainprm="17.3822" biasprm="0 -17.3822 -0.363604"/>
    <general name="tarsus_joint_LR" class="/" joint="tarsus_joint_LR" forcerange="-5.68938 5.68938" gainprm="17.3822" biasprm="0 -17.3822 -0.363604"/>
    <general name="coxa_joint_LM" class="/" joint="coxa_joint_LM" forcerange="-5.44723 5.44723" gainprm="17.3822" biasprm="0 -17.3822 -0.363604"/>
    <general name="femur_joint_LM" class="/" joint="femur_joint_LM" forcerange="-5.49746 5.49746" gainprm="17.3822" biasprm="0 -17.3822 -0.363604"/>
    <general name="tibia_joint_LM" class="/" joint="tibia_joint_LM" forcerange="-4.98781 4.98781" gainprm="17.3822" biasprm="0 -17.3822 -0.363604"/>
    <general name="tarsus_joint_LM" class="/" joint="tarsus_joint_LM" forcerange="-5.50002 5.50002" gainprm="17.3822" biasprm="0 -17.3822 -0.363604"/>
    <general name="coxa_joint_LF" class="/" joint="coxa_joint_LF" forcerange="-6.03823 6.03823" gainprm="17.3822" biasprm="0 -17.3822 -0.363604"/>
    <general name="femur_joint_LF" class="/" joint="femur_joint_LF" forcerange="-6.03367 6.03367" gainprm="17.3822" biasprm="0 -17.3822 -0.363604"/>
    <general name="tibia_joint_LF" class="/" joint="tibia_joint_LF" forcerange="-5.35921 5.35921" gainprm="17.3822" biasprm="0 -17.3822 -0.363604"/>
    <general name="tarsus_joint_LF" class="/" joint="tarsus_joint_LF" forcerange="-5.49205 5.49205" gainprm="17.3822" biasprm="0 -17.3822 -0.363604"/>
  </actuator>

  <sensor>
    <gyro site="imu" name="imu_angular_velocity"/>
    <velocimeter site="imu" name="imu_linear_velocity"/>
    <framelinvel objtype="site" objname="foot_1" name="foot_1_global_linear_velocity"/>
    <framelinvel objtype="site" objname="foot_2" name="foot_2_global_linear_velocity"/>
    <framelinvel objtype="site" objname="foot_3" name="foot_3_global_linear_velocity"/>
    <framelinvel objtype="site" objname="foot_4" name="foot_4_global_linear_velocity"/>
    <framelinvel objtype="site" objname="foot_5" name="foot_5_global_linear_velocity"/>
    <framelinvel objtype="site" objname="foot_6" name="foot_6_global_linear_velocity"/>
  </sensor>

  <keyframe>
    <key name="home" qpos="0 0 0.1457 1 0 0 0 0 0 0 0 0 0 0 0 0 0 0 0 0 0 0 0 0 0 0 0 0 0 0 0"/>
  </keyframe>
</mujoco>
