<mujoco model="Golem">
  <compiler angle="radian" assetdir="assets" balanceinertia="true" inertiafromgeom="false"/>

  <option timestep="0.005" density="1.2" viscosity="2e-05"/>

  <size nkey="1"/>

  <visual>
    <quality shadowsize="8192"/>
    <map shadowclip="0.5"/>
  </visual>

  <default>
    <default class="/">
      <joint armature="0.01" damping="0.01" frictionloss="0.01"/>
      <geom contype="0" conaffinity="0" group="1" solref="-1000 -80"/>
      <site size="0.01 0.005 0.005" group="5"/>
      <general forcelimited="true" biastype="affine" gainprm="25" biasprm="0 -25 -0.5"/>
      <default class="visual">
        <geom type="mesh" group="2"/>
      </default>
      <default class="collision">
        <geom group="3"/>
      </default>
      <default class="foot">
        <geom size="0.01 0 0" condim="6" group="4" priority="1" solimp="0.015 1 0.01"/>
      </default>
      <default class="reward_collision_sphere">
        <geom group="5" rgba="1 0 0 1"/>
      </default>
    </default>
  </default>

  <asset>
    <texture type="skybox" colorspace="auto" name="//unnamed_texture_0" builtin="gradient" rgb1="0.95 0.95 0.95" rgb2="0.95 0.95 0.95" width="100" height="600"/>
    <texture type="2d" colorspace="auto" name="texplane" builtin="checker" rgb1="0.345 0.575 0.748" rgb2="0.345 0.575 0.748" markrgb="1 1 1" width="512" height="512"/>
    <material name="MatPlane" class="/" texture="texplane" texuniform="true" texrepeat="2 2" specular="0.9"/>
    <mesh name="body" class="/" file="body.stl" scale="0.001 0.001 0.001"/>
    <mesh name="coxa" class="/" file="coxa.stl" scale="0.001 0.001 0.001"/>
    <mesh name="femur" class="/" file="femur.stl" scale="0.001 0.001 0.001"/>
    <mesh name="tibia" class="/" file="tibia.stl" scale="0.001 0.001 0.001"/>
    <mesh name="tarsus" class="/" file="tarsus.stl" scale="0.001 0.001 0.001"/>
  </asset>

  <worldbody>
    <geom name="floor" class="/" size="100 100 0.125" type="plane" group="0" material="MatPlane"/>
    <light name="toplight_shadow" class="/" pos="0 0 5" dir="0.0990148 0.0990148 -0.990148" type="directional" ambient="0.04 0.04 0.04" diffuse="0.55 0.55 0.55" specular="0.12 0.12 0.12"/>
    <light name="toplight_fill" class="/" pos="0 0 5" dir="0.0990148 0.0990148 -0.990148" type="directional" castshadow="false" ambient="0.04 0.04 0.04" diffuse="0.3 0.3 0.3" specular="0.08 0.08 0.08"/>
    <body name="trunk" pos="-0.000832035 0.000814879 0.00242659" quat="0.999996 -0.00279699 -1.72225e-05 0.000371411">
      <inertial pos="0.00259358 -0.00135908 -0.00397522" quat="0.999999 0.00110419 -0.000581209 0.000194224" mass="1.35005" diaginertia="0.00267206 5.66952e-05 0.014335"/>
      <joint name="//unnamed_joint_0" type="free"/>
      <geom name="//unnamed_geom_1" class="/" pos="0 0 0.0682813" quat="1 0 0 0" type="mesh" rgba="0.9 0.9 0.9 1" mesh="body"/>
      <site name="imu" class="/" pos="0.0749864 0.000752889 0.104084" size="0.00727629"/>
      <camera name="track" class="/" pos="0 -0.707524 0" quat="0.707107 0.707107 0 0" mode="trackcom"/>
      <camera name="ego_camera" class="/" pos="0.0990899 0 0.10669" quat="-0.5 -0.5 0.5 0.5"/>
      <body name="coxa_RR" pos="-0.132631 -0.0358538 0.0618499" quat="0.38208 -0.000212951 0.00265611 -0.924126">
        <inertial pos="6.88076e-05 -0.000379993 -0.00218116" quat="0.999991 0.00356491 -0.00166133 0.00157485" mass="0.0723277" diaginertia="0.00251857 5.3778e-05 0.0132852"/>
        <joint name="coxa_joint_RR" class="/" pos="0 0 0" axis="0.0143935 0.000290391 -0.999896" range="-3.09343 3.22084" armature="0.00726815" damping="0.000541713" frictionloss="0.00717965"/>
        <geom name="//unnamed_geom_2" class="/" type="mesh" rgba="0.2 0.2 0.2 1" mesh="coxa"/>
        <geom name="//unnamed_geom_3" class="reward_collision_sphere" size="0.0291052" pos="-0.0228669 0 0"/>
        <body name="femur_RR" pos="0.0438833 3.6149e-05 0.00490184" quat="0.50037 -0.500408 0.49909 0.50013">
          <inertial pos="-0.000907984 -2.05188e-05 -0.00236366" quat="0.999966 -0.00553254 -0.00412627 0.00457407" mass="0.0773528" diaginertia="0.00257109 5.50484e-05 0.0133225"/>
          <joint name="femur_joint_RR" class="/" pos="0 0 0" axis="-0.00129277 0.00336167 -0.999994" range="-3.21987 3.15615" armature="0.00859556" damping="0.00690125" frictionloss="0.00651458"/>
          <geom name="//unnamed_geom_4" class="/" type="mesh" rgba="0.9 0.9 0.9 1" mesh="femur"/>
          <geom name="//unnamed_geom_5" class="reward_collision_sphere" size="0.0291052"/>
          <body name="tibia_RR" pos="0.00291174 -0.0437632 -0.00113069" quat="0.00038222 1 -0.000697251 -0.000227417">
            <inertial pos="-0.00252107 3.80623e-05 0.00107564" quat="0.999961 0.00434162 -0.00693858 -0.00316951" mass="0.0745607" diaginertia="0.0025093 5.59918e-05 0.014344"/>
            <joint name="tibia_joint_RR" class="/" pos="0 0 0" axis="-0.0215137 -0.00348545 0.999762" stiffness="0.00178795" range="-3.22781 3.15892" armature="0.00813095" damping="0.0177397" frictionloss="0.0063785"/>
            <geom name="//unnamed_geom_6" class="/" type="mesh" rgba="0.2 0.2 0.2 1" mesh="tibia"/>
            <geom name="//unnamed_geom_7" class="reward_collision_sphere" size="0.0291052"/>
            <body name="tarsus_RR" pos="0.0699584 0.000216415 0.00150524" quat="1 -4.48214e-05 -0.000757956 0.000394801">
              <inertial pos="0.0486884 -0.000511516 0.00272029" quat="0.500896 0.501374 0.499555 0.498168" mass="0.0746883" diaginertia="0.00259675 5.56369e-05 0.0137711"/>
              <joint name="tarsus_joint_RR" class="/" pos="0 0 0" axis="-0.0142163 -0.00268898 0.999895" range="-3.15572 3.09022" armature="0.00634749" damping="0.00382345" frictionloss="0.00819247"/>
              <geom name="//unnamed_geom_8" class="/" type="mesh" rgba="0.9 0.9 0.9 1" mesh="tarsus"/>
              <geom name="foot_1" class="foot" size="0.00768289" pos="0.0853697 0 0" quat="0 -0.707107 0 0.707107"/>
              <geom name="//unnamed_geom_10" class="reward_collision_sphere" size="0.0291052"/>
              <geom name="//unnamed_geom_11" class="reward_collision_sphere" size="0.0109144" pos="0.0819397 0 0"/>
              <site name="foot_1" class="foot" pos="0.0853697 0 0" quat="0 -0.707107 0 0.707107" size="0.00727629"/>
            </body>
          </body>
        </body>
      </body>
      <body name="coxa_RM" pos="-0.00376516 -0.0410237 0.0741845" quat="0.70706 -0.00081922 -0.00179132 -0.707151">
        <inertial pos="0.000918016 0.00339515 0.00163505" quat="0.999962 0.00250676 -0.00156445 -0.00826081" mass="0.0780272" diaginertia="0.00264283 5.31021e-05 0.0133634"/>
        <joint name="coxa_joint_RM" class="/" pos="0 0 0" axis="-0.0140295 -0.00987811 -0.999853" range="-3.1251 3.08469" armature="0.005497" damping="0.0273845" frictionloss="0.00780653"/>
        <geom name="//unnamed_geom_12" class="/" type="mesh" rgba="0.2 0.2 0.2 1" mesh="coxa"/>
        <geom name="//unnamed_geom_13" class="reward_collision_sphere" size="0.0291052" pos="-0.0228669 0 0"/>
        <body name="femur_RM" pos="0.0427141 -0.00449265 -1.89625e-05" quat="0.500011 -0.4999 0.500096 0.499993">
          <inertial pos="-0.00067316 0.00155402 0.00152514" quat="0.999926 0.000624283 -0.00734808 0.00968495" mass="0.0763254" diaginertia="0.00266577 5.33322e-05 0.0133182"/>
          <joint name="femur_joint_RM" class="/" pos="0 0 0" axis="0.00151825 0.00911287 -0.999957" range="-3.15136 3.1255" armature="0.00670585" damping="0.00298975" frictionloss="0.00688974"/>
          <geom name="//unnamed_geom_14" class="/" type="mesh" rgba="0.9 0.9 0.9 1" mesh="femur"/>
          <geom name="//unnamed_geom_15" class="reward_collision_sphere" size="0.0291052"/>
          <body name="tibia_RM" pos="0.000463048 -0.0324093 -0.00377031" quat="-0.000816215 0.999999 -0.00085777 0.00028596">
            <inertial pos="0.00155807 -0.00269198 0.00356837" quat="0.999884 -0.0041887 0.00330429 0.0142778" mass="0.0762289" diaginertia="0.00246249 5.66831e-05 0.0134209"/>
            <joint name="tibia_joint_RM" class="/" pos="0 0 0" axis="-0.00394486 -0.00350485 0.999986" stiffness="0.000451878" range="-3.08959 3.11462" armature="0.00600708" damping="0.00863972" frictionloss="0.00537702"/>
            <geom name="//unnamed_geom_16" class="/" type="mesh" rgba="0.2 0.2 0.2 1" mesh="tibia"/>
            <geom name="//unnamed_geom_17" class="reward_collision_sphere" size="0.0291052"/>
            <body name="tarsus_RM" pos="0.0689081 -0.000627272 0.00211742" quat="1 0.000107895 -2.99901e-05 -7.7904e-06">
              <inertial pos="0.0448924 -0.00123458 -0.00128622" quat="0.500949 0.500531 0.495384 0.503105" mass="0.0797034" diaginertia="0.0026032 5.64311e-05 0.0140155"/>
              <joint name="tarsus_joint_RM" class="/" pos="0 0 0" axis="-0.00188983 -0.00113313 0.999998" range="-3.22871 3.15061" armature="0.0051546" damping="0.000744308" frictionloss="0.00771162"/>
              <geom name="//unnamed_geom_18" class="/" type="mesh" rgba="0.9 0.9 0.9 1" mesh="tarsus"/>
              <geom name="foot_2" class="foot" size="0.00615343" pos="0.0853697 0 0" quat="0 -0.707107 0 0.707107"/>
              <geom name="//unnamed_geom_20" class="reward_collision_sphere" size="0.0291052"/>
              <geom name="//unnamed_geom_21" class="reward_collision_sphere" size="0.0109144" pos="0.0819397 0 0"/>
              <site name="foot_2" class="foot" pos="0.0853697 0 0" quat="0 -0.707107 0 0.707107" size="0.00727629"/>
            </body>
          </body>
        </body>
      </body>
      <body name="coxa_RF" pos="0.138898 -0.0315901 0.0623384" quat="0.923861 0.000273221 -4.40912e-05 -0.382727">
        <inertial pos="0.00182896 0.00584106 -0.000489023" quat="0.999973 -0.00176015 0.0045786 -0.00541218" mass="0.0741879" diaginertia="0.00250295 5.65545e-05 0.0136565"/>
        <joint name="coxa_joint_RF" class="/" pos="0 0 0" axis="0.000227594 0.000236628 -1" range="-3.16309 3.05612" armature="0.00741415" damping="0.0246427" frictionloss="0.0064403"/>
        <geom name="//unnamed_geom_22" class="/" type="mesh" rgba="0.2 0.2 0.2 1" mesh="coxa"/>
        <geom name="//unnamed_geom_23" class="reward_collision_sphere" size="0.0291052" pos="-0.0228669 0 0"/>
        <body name="femur_RF" pos="0.0393242 0.000230114 0.00763806" quat="0.500325 -0.498636 0.499787 0.501248">
          <inertial pos="0.0016464 0.00159636 -0.0040451" quat="0.999747 -0.00657645 0.00556013 0.0207702" mass="0.0751203" diaginertia="0.00260521 5.88971e-05 0.0134611"/>
          <joint name="femur_joint_RF" class="/" pos="0 0 0" axis="0.00293984 -0.0082483 -0.999962" stiffness="0.00752907" range="-3.16372 3.13873" armature="0.00800646" damping="0.00392037" frictionloss="0.0086971"/>
          <geom name="//unnamed_geom_24" class="/" type="mesh" rgba="0.9 0.9 0.9 1" mesh="femur"/>
          <geom name="//unnamed_geom_25" class="reward_collision_sphere" size="0.0291052"/>
          <body name="tibia_RF" pos="-0.0012853 -0.0376424 0.000357955" quat="-7.89668e-05 1 -0.000643319 -0.000480965">
            <inertial pos="-0.000357354 0.000204882 -0.00148272" quat="0.999986 -0.000883112 -0.00365553 0.00376294" mass="0.0761867" diaginertia="0.00254032 5.39929e-05 0.0130183"/>
            <joint name="tibia_joint_RF" class="/" pos="0 0 0" axis="-0.00264409 -0.0166238 0.999858" range="-3.1899 3.14329" armature="0.00660369" damping="0.0177358" frictionloss="0.00731014"/>
            <geom name="//unnamed_geom_26" class="/" type="mesh" rgba="0.2 0.2 0.2 1" mesh="tibia"/>
            <geom name="//unnamed_geom_27" class="reward_collision_sphere" size="0.0291052"/>
            <body name="tarsus_RF" pos="0.0661796 -0.000192316 -5.65422e-05" quat="0.999998 0.00155092 3.57255e-05 -0.00112311">
              <inertial pos="0.0499178 9.0104e-05 -0.00546781" quat="0.500971 0.499353 0.505901 0.493698" mass="0.0811362" diaginertia="0.00257562 5.65864e-05 0.0148131"/>
              <joint name="tarsus_joint_RF" class="/" pos="0 0 0" axis="0.0181056 0.0136943 0.999742" range="-3.23037 3.18641" armature="0.00714339" damping="0.00826603" frictionloss="0.00689894"/>
              <geom name="//unnamed_geom_28" class="/" type="mesh" rgba="0.9 0.9 0.9 1" mesh="tarsus"/>
              <geom name="foot_3" class="foot" size="0.00783597" pos="0.0853697 0 0" quat="0 -0.707107 0 0.707107"/>
              <geom name="//unnamed_geom_30" class="reward_collision_sphere" size="0.0291052"/>
              <geom name="//unnamed_geom_31" class="reward_collision_sphere" size="0.0109144" pos="0.0819397 0 0"/>
              <site name="foot_3" class="foot" pos="0.0853697 0 0" quat="0 -0.707107 0 0.707107" size="0.00727629"/>
            </body>
          </body>
        </body>
      </body>
      <body name="coxa_LR" pos="-0.134865 0.0383403 0.061774" quat="0.382117 -0.00156029 0.00115002 0.924112">
        <inertial pos="-0.00358885 -2.40526e-05 0.000569367" quat="0.999947 -0.00532905 -0.00167545 -0.00867279" mass="0.0773238" diaginertia="0.00266227 5.54553e-05 0.0138369"/>
        <joint name="coxa_joint_LR" class="/" pos="0 0 0" axis="-0.00539185 -0.0219086 -0.999745" range="-3.19005 3.17763" armature="0.00668089" damping="0.0351187" frictionloss="0.00727816"/>
        <geom name="//unnamed_geom_32" class="/" type="mesh" rgba="0.2 0.2 0.2 1" mesh="coxa"/>
        <geom name="//unnamed_geom_33" class="reward_collision_sphere" size="0.0291052" pos="-0.0228669 0 0"/>
        <body name="femur_LR" pos="0.0470576 8.67504e-05 0.00390484" quat="0.499297 -0.499354 0.501539 0.499807">
          <inertial pos="0.00187408 -0.00226889 0.0013105" quat="1 -0.00010214 0.00019899 -0.000229049" mass="0.0729077" diaginertia="0.00250706 5.45244e-05 0.0136364"/>
          <joint name="femur_joint_LR" class="/" pos="0 0 0" axis="-7.00915e-05 9.11475e-05 1" stiffness="0.0102913" range="-3.12561 3.02393" armature="0.00660121" damping="0.0158289" frictionloss="0.00536281"/>
          <geom name="//unnamed_geom_34" class="/" type="mesh" rgba="0.9 0.9 0.9 1" mesh="femur"/>
          <geom name="//unnamed_geom_35" class="reward_collision_sphere" size="0.0291052"/>
          <body name="tibia_LR" pos="0.00684262 -0.0364781 -0.00721013" quat="0.000246674 0.999999 0.000109221 0.0013415">
            <inertial pos="0.00244759 -0.00303084 0.00331981" quat="0.999932 0.0097419 0.00544312 0.00328605" mass="0.0743255" diaginertia="0.0024842 5.27198e-05 0.0133699"/>
            <joint name="tibia_joint_LR" class="/" pos="0 0 0" axis="-0.0066829 0.00230576 -0.999975" range="-3.09549 3.20701" armature="0.00894505" damping="0" frictionloss="0.00714005"/>
            <geom name="//unnamed_geom_36" class="/" type="mesh" rgba="0.2 0.2 0.2 1" mesh="tibia"/>
            <geom name="//unnamed_geom_37" class="reward_collision_sphere" size="0.0291052"/>
            <body name="tarsus_LR" pos="0.066188 0.00711565 0.00775297" quat="0.999999 -0.000863908 -1.47829e-05 0.000514084">
              <inertial pos="0.0478145 -0.000271071 -0.0017152" quat="0.501106 0.501345 0.501245 0.496285" mass="0.078652" diaginertia="0.00264418 5.60446e-05 0.0143232"/>
              <joint name="tarsus_joint_LR" class="/" pos="0 0 0" axis="-0.00410505 -0.0104968 -0.999936" stiffness="0.0022342" range="-3.22144 3.154" armature="0.00734671" damping="0.036679" frictionloss="0.00815568"/>
              <geom name="//unnamed_geom_38" class="/" type="mesh" rgba="0.9 0.9 0.9 1" mesh="tarsus"/>
              <geom name="foot_4" class="foot" size="0.00819048" pos="0.0853697 0 0" quat="0.707107 0 -0.707107 0"/>
              <geom name="//unnamed_geom_40" class="reward_collision_sphere" size="0.0291052"/>
              <geom name="//unnamed_geom_41" class="reward_collision_sphere" size="0.0109144" pos="0.0819397 0 0"/>
              <site name="foot_4" class="foot" pos="0.0853697 0 0" quat="0.707107 0 -0.707107 0" size="0.00727629"/>
            </body>
          </body>
        </body>
      </body>
      <body name="coxa_LM" pos="0.00233513 0.0404724 0.0744774" quat="0.706737 -0.0017198 0.00226954 0.707471">
        <inertial pos="-0.0013787 0.000195367 -0.000349925" quat="0.999942 -0.00290641 -0.0027529 -0.00995127" mass="0.0697729" diaginertia="0.00223173 5.11257e-05 0.0129802"/>
        <joint name="coxa_joint_LM" class="/" pos="0 0 0" axis="0.00241889 -0.0019958 -0.999995" range="-3.0878 3.08914" armature="0.00774926" damping="0.01056" frictionloss="0.0064737"/>
        <geom name="//unnamed_geom_42" class="/" type="mesh" rgba="0.2 0.2 0.2 1" mesh="coxa"/>
        <geom name="//unnamed_geom_43" class="reward_collision_sphere" size="0.0291052" pos="-0.0228669 0 0"/>
        <body name="femur_LM" pos="0.0436337 -0.000830624 -0.00219251" quat="0.50002 -0.49997 0.500014 0.499996">
          <inertial pos="0.000657791 0.0015152 0.00105418" quat="0.999999 -0.000500883 -0.000932319 -0.000550109" mass="0.0833365" diaginertia="0.00265654 5.92364e-05 0.0148407"/>
          <joint name="femur_joint_LM" class="/" pos="0 0 0" axis="-0.00470166 -0.000325345 0.999989" stiffness="0.00632686" range="-3.09109 3.10107" armature="0.00705489" damping="0.000408148" frictionloss="0.00705086"/>
          <geom name="//unnamed_geom_44" class="/" type="mesh" rgba="0.9 0.9 0.9 1" mesh="femur"/>
          <geom name="//unnamed_geom_45" class="reward_collision_sphere" size="0.0291052"/>
          <body name="tibia_LM" pos="0.000862522 -0.0328463 0.00129806" quat="-8.70408e-05 0.999999 -0.000369431 -0.00107873">
            <inertial pos="0.00465748 -0.00593405 0.00196306" quat="1 0.0001017 0.000665379 -0.000496745" mass="0.0772979" diaginertia="0.00274013 5.74443e-05 0.0146077"/>
            <joint name="tibia_joint_LM" class="/" pos="0 0 0" axis="-0.00182984 -0.00358274 -0.999992" stiffness="0.0115493" range="-3.17212 3.1311" armature="0.00741085" damping="0.00358358" frictionloss="0.00725446"/>
            <geom name="//unnamed_geom_46" class="/" type="mesh" rgba="0.2 0.2 0.2 1" mesh="tibia"/>
            <geom name="//unnamed_geom_47" class="reward_collision_sphere" size="0.0291052"/>
            <body name="tarsus_LM" pos="0.0671492 -0.000540548 -0.000130953" quat="1 0.000220869 -0.000233861 -0.000739019">
              <inertial pos="0.044676 -0.00142068 0.000313119" quat="0.492725 0.49831 0.501183 0.507666" mass="0.0800271" diaginertia="0.00271845 5.70444e-05 0.0138062"/>
              <joint name="tarsus_joint_LM" class="/" pos="0 0 0" axis="-0.0117929 -0.00150469 -0.999929" range="-3.09552 3.16849" armature="0.00722987" damping="0" frictionloss="0.00818196"/>
              <geom name="//unnamed_geom_48" class="/" type="mesh" rgba="0.9 0.9 0.9 1" mesh="tarsus"/>
              <geom name="foot_5" class="foot" size="0.00800088" pos="0.0853697 0 0" quat="0.707107 0 -0.707107 0"/>
              <geom name="//unnamed_geom_50" class="reward_collision_sphere" size="0.0291052"/>
              <geom name="//unnamed_geom_51" class="reward_collision_sphere" size="0.0109144" pos="0.0819397 0 0"/>
              <site name="foot_5" class="foot" pos="0.0853697 0 0" quat="0.707107 0 -0.707107 0" size="0.00727629"/>
            </body>
          </body>
        </body>
      </body>
      <body name="coxa_LF" pos="0.136066 0.0239809 0.0685837" quat="0.923981 -0.000137642 2.08616e-05 0.382438">
        <inertial pos="-0.00270263 0.00145121 -0.00157289" quat="0.999927 -0.00274572 0.00996268 -0.00628342" mass="0.0793243" diaginertia="0.00264599 5.89238e-05 0.0143113"/>
        <joint name="coxa_joint_LF" class="/" pos="0 0 0" axis="-0.00027144 -0.00345977 -0.999994" stiffness="0.00446521" range="-3.1172 3.10315" armature="0.00705585" damping="0.00983849" frictionloss="0.00744099"/>
        <geom name="//unnamed_geom_52" class="/" type="mesh" rgba="0.2 0.2 0.2 1" mesh="coxa"/>
        <geom name="//unnamed_geom_53" class="reward_collision_sphere" size="0.0291052" pos="-0.0228669 0 0"/>
        <body name="femur_LF" pos="0.0468677 -0.00450345 0.00522218" quat="0.500099 -0.499889 0.499856 0.500156">
          <inertial pos="1.10273e-05 0.00112547 -0.00266035" quat="0.999632 -0.00226054 -0.0170246 -0.0210124" mass="0.0774678" diaginertia="0.00251939 5.84802e-05 0.0139662"/>
          <joint name="femur_joint_LF" class="/" pos="0 0 0" axis="-0.000384649 0.000767904 1" range="-3.11679 3.12007" armature="0.00659321" damping="0" frictionloss="0.00939081"/>
          <geom name="//unnamed_geom_54" class="/" type="mesh" rgba="0.9 0.9 0.9 1" mesh="femur"/>
          <geom name="//unnamed_geom_55" class="reward_collision_sphere" size="0.0291052"/>
          <body name="tibia_LF" pos="0.00152485 -0.0412814 -0.0032895" quat="-5.2698e-05 1 8.50142e-05 -3.64278e-05">
            <inertial pos="0.00156419 -0.000890272 0.00134071" quat="0.999996 0.000491744 -0.00187651 -0.00217354" mass="0.0767374" diaginertia="0.00251707 5.53216e-05 0.0138373"/>
            <joint name="tibia_joint_LF" class="/" pos="0 0 0" axis="0.00129453 -0.000599154 -0.999999" range="-3.03728 3.16636" armature="0.00741931" damping="0" frictionloss="0.00761608"/>
            <geom name="//unnamed_geom_56" class="/" type="mesh" rgba="0.2 0.2 0.2 1" mesh="tibia"/>
            <geom name="//unnamed_geom_57" class="reward_collision_sphere" size="0.0291052"/>
            <body name="tarsus_LF" pos="0.0687469 0.00177918 0.000747284" quat="1 0.000176585 -0.000281057 -0.000135764">
              <inertial pos="0.045109 -0.000667309 -0.0048905" quat="0.500131 0.502589 0.500497 0.496766" mass="0.0731734" diaginertia="0.0025889 5.42065e-05 0.0139109"/>
              <joint name="tarsus_joint_LF" class="/" pos="0 0 0" axis="0.00673064 0.0065448 -0.999956" stiffness="0.0212595" range="-3.14474 3.13524" armature="0.00712176" damping="0.0404835" frictionloss="0.00812477"/>
              <geom name="//unnamed_geom_58" class="/" type="mesh" rgba="0.9 0.9 0.9 1" mesh="tarsus"/>
              <geom name="foot_6" class="foot" size="0.00730406" pos="0.0853697 0 0" quat="0.707107 0 -0.707107 0"/>
              <geom name="//unnamed_geom_60" class="reward_collision_sphere" size="0.0291052"/>
              <geom name="//unnamed_geom_61" class="reward_collision_sphere" size="0.0109144" pos="0.0819397 0 0"/>
              <site name="foot_6" class="foot" pos="0.0853697 0 0" quat="0.707107 0 -0.707107 0" size="0.00727629"/>
            </body>
          </body>
        </body>
      </body>
    </body>
  </worldbody>

  <contact>
    <pair class="/" geom1="floor" geom2="foot_1" name="//unnamed_contact_0"/>
    <pair class="/" geom1="floor" geom2="foot_2" name="//unnamed_contact_1"/>
    <pair class="/" geom1="floor" geom2="foot_3" name="//unnamed_contact_2"/>
    <pair class="/" geom1="floor" geom2="foot_4" name="//unnamed_contact_3"/>
    <pair class="/" geom1="floor" geom2="foot_5" name="//unnamed_contact_4"/>
    <pair class="/" geom1="floor" geom2="foot_6" name="//unnamed_contact_5"/>
  </contact>

  <actuator>
    <general name="coxa_joint_RR" class="/" joint="coxa_joint_RR" forcerange="-5.01752 5.01752" gainprm="20.507" biasprm="0 -20.507 -0.409316"/>
    <general name="femur_joint_RR" class="/" joint="femur_joint_RR" forcerange="-5.55467 5.55467" gainprm="20.507" biasprm="0 -20.507 -0.409316"/>
    <general name="tibia_joint_RR" class="/" joint="tibia_joint_RR" forcerange="-4.82955 4.82955" gainprm="20.507" biasprm="0 -20.507 -0.409316"/>
    <general name="tarsus_joint_RR" class="/" joint="tarsus_joint_RR" forcerange="-5.81428 5.81428" gainprm="20.507" biasprm="0 -20.507 -0.409316"/>
    <general name="coxa_joint_RM" class="/" joint="coxa_joint_RM" forcerange="-4.98871 4.98871" gainprm="20.507" biasprm="0 -20.507 -0.409316"/>
    <general name="femur_joint_RM" class="/" joint="femur_joint_RM" forcerange="-4.76788 4.76788" gainprm="20.507" biasprm="0 -20.507 -0.409316"/>
    <general name="tibia_joint_RM" class="/" joint="tibia_joint_RM" forcerange="-5.10026 5.10026" gainprm="20.507" biasprm="0 -20.507 -0.409316"/>
    <general name="tarsus_joint_RM" class="/" joint="tarsus_joint_RM" forcerange="-4.28581 4.28581" gainprm="20.507" biasprm="0 -20.507 -0.409316"/>
    <general name="coxa_joint_RF" class="/" joint="coxa_joint_RF" forcerange="-4.55157 4.55157" gainprm="20.507" biasprm="0 -20.507 -0.409316"/>
    <general name="femur_joint_RF" class="/" joint="femur_joint_RF" forcerange="-6.08505 6.08505" gainprm="20.507" biasprm="0 -20.507 -0.409316"/>
    <general name="tibia_joint_RF" class="/" joint="tibia_joint_RF" forcerange="-5.04451 5.04451" gainprm="20.507" biasprm="0 -20.507 -0.409316"/>
    <general name="tarsus_joint_RF" class="/" joint="tarsus_joint_RF" forcerange="-5.5735 5.5735" gainprm="20.507" biasprm="0 -20.507 -0.409316"/>
    <general name="coxa_joint_LR" class="/" joint="coxa_joint_LR" forcerange="-5.44626 5.44626" gainprm="20.507" biasprm="0 -20.507 -0.409316"/>
    <general name="femur_joint_LR" class="/" joint="femur_joint_LR" forcerange="-5.5425 5.5425" gainprm="20.507" biasprm="0 -20.507 -0.409316"/>
    <general name="tibia_joint_LR" class="/" joint="tibia_joint_LR" forcerange="-5.07149 5.07149" gainprm="20.507" biasprm="0 -20.507 -0.409316"/>
    <general name="tarsus_joint_LR" class="/" joint="tarsus_joint_LR" forcerange="-4.85466 4.85466" gainprm="20.507" biasprm="0 -20.507 -0.409316"/>
    <general name="coxa_joint_LM" class="/" joint="coxa_joint_LM" forcerange="-5.22826 5.22826" gainprm="20.507" biasprm="0 -20.507 -0.409316"/>
    <general name="femur_joint_LM" class="/" joint="femur_joint_LM" forcerange="-5.25425 5.25425" gainprm="20.507" biasprm="0 -20.507 -0.409316"/>
    <general name="tibia_joint_LM" class="/" joint="tibia_joint_LM" forcerange="-6.32084 6.32084" gainprm="20.507" biasprm="0 -20.507 -0.409316"/>
    <general name="tarsus_joint_LM" class="/" joint="tarsus_joint_LM" forcerange="-5.28489 5.28489" gainprm="20.507" biasprm="0 -20.507 -0.409316"/>
    <general name="coxa_joint_LF" class="/" joint="coxa_joint_LF" forcerange="-4.74846 4.74846" gainprm="20.507" biasprm="0 -20.507 -0.409316"/>
    <general name="femur_joint_LF" class="/" joint="femur_joint_LF" forcerange="-4.68349 4.68349" gainprm="20.507" biasprm="0 -20.507 -0.409316"/>
    <general name="tibia_joint_LF" class="/" joint="tibia_joint_LF" forcerange="-5.32499 5.32499" gainprm="20.507" biasprm="0 -20.507 -0.409316"/>
    <general name="tarsus_joint_LF" class="/" joint="tarsus_joint_LF" forcerange="-4.85528 4.85528" gainprm="20.507" biasprm="0 -20.507 -0.409316"/>
  </actuator>

  <sensor>
    <gyro site="imu" name="imu_angular_velocity"/>
    <velocimeter site="imu" name="imu_linear_velocity"/>
    <framelinvel objtype="site" objname="foot_1" name="foot_1_global_linear_velocity"/>
    <framelinvel objtype="site" objname="foot_2" name="foot_2_global_linear_velocity"/>
    <framelinvel objtype="site" objname="foot_3" name="foot_3_global_linear_velocity"/>
    <framelinvel objtype="site" objname="foot_4" name="foot_4_global_linear_velocity"/>
    <framelinvel objtype="site" objname="foot_5" name="foot_5_global_linear_velocity"/>
    <framelinvel objtype="site" objname="foot_6" name="foot_6_global_linear_velocity"/>
  </sensor>

  <keyframe>
    <key name="home" qpos="0 0 0.1457 1 0 0 0 0 0 0 0 0 0 0 0 0 0 0 0 0 0 0 0 0 0 0 0 0 0 0 0"/>
  </keyframe>
</mujoco>
