<mujoco model="Golem">
  <compiler angle="radian" assetdir="assets" balanceinertia="true" inertiafromgeom="false"/>

  <option timestep="0.005" density="1.2" viscosity="2e-05"/>

  <size nkey="1"/>

  <visual>
    <quality shadowsize="8192"/>
    <map shadowclip="0.5"/>
  </visual>

  <default>
    <default class="/">
      <joint armature="0.01" damping="0.01" frictionloss="0.01"/>
      <geom contype="0" conaffinity="0" group="1" solref="-1000 -80"/>
      <site size="0.01 0.005 0.005" group="5"/>
      <general forcelimited="true" biastype="affine" gainprm="25" biasprm="0 -25 -0.5"/>
      <default class="visual">
        <geom type="mesh" group="2"/>
      </default>
      <default class="collision">
        <geom group="3"/>
      </default>
      <default class="foot">
        <geom size="0.01 0 0" condim="6" group="4" priority="1" solimp="0.015 1 0.01"/>
      </default>
      <default class="reward_collision_sphere">
        <geom group="5" rgba="1 0 0 1"/>
      </default>
    </default>
  </default>

  <asset>
    <texture type="skybox" colorspace="auto" name="//unnamed_texture_0" builtin="gradient" rgb1="0.95 0.95 0.95" rgb2="0.95 0.95 0.95" width="100" height="600"/>
    <texture type="2d" colorspace="auto" name="texplane" builtin="checker" rgb1="0.345 0.575 0.748" rgb2="0.345 0.575 0.748" markrgb="1 1 1" width="512" height="512"/>
    <material name="MatPlane" class="/" texture="texplane" texuniform="true" texrepeat="2 2" specular="0.9"/>
    <mesh name="body" class="/" file="body.stl" scale="0.001 0.001 0.001"/>
    <mesh name="coxa" class="/" file="coxa.stl" scale="0.001 0.001 0.001"/>
    <mesh name="femur" class="/" file="femur.stl" scale="0.001 0.001 0.001"/>
    <mesh name="tibia" class="/" file="tibia.stl" scale="0.001 0.001 0.001"/>
    <mesh name="tarsus" class="/" file="tarsus.stl" scale="0.001 0.001 0.001"/>
  </asset>

  <worldbody>
    <geom name="floor" class="/" size="100 100 0.125" type="plane" group="0" material="MatPlane"/>
    <light name="toplight_shadow" class="/" pos="0 0 5" dir="0.0990148 0.0990148 -0.990148" type="directional" ambient="0.04 0.04 0.04" diffuse="0.55 0.55 0.55" specular="0.12 0.12 0.12"/>
    <light name="toplight_fill" class="/" pos="0 0 5" dir="0.0990148 0.0990148 -0.990148" type="directional" castshadow="false" ambient="0.04 0.04 0.04" diffuse="0.3 0.3 0.3" specular="0.08 0.08 0.08"/>
    <body name="trunk" pos="0.000354608 0.000201444 -0.000224717" quat="1 0.000194823 0.000439343 5.54417e-05">
      <inertial pos="-0.00026921 0.00114379 -0.00275332" quat="0.99999 -0.000535735 0.00429529 -0.00120427" mass="2.52115" diaginertia="0.00985966 0.00117042 0.00914155"/>
      <joint name="//unnamed_joint_0" type="free"/>
      <geom name="//unnamed_geom_1" class="/" pos="0 0 0.0628995" quat="1 0 0 0" type="mesh" rgba="0.9 0.9 0.9 1" mesh="body"/>
      <site name="imu" class="/" pos="0.130129 0.00101259 0.102941" size="0.00877365"/>
      <camera name="track" class="/" pos="0 -1.30184 0" quat="0.707107 0.707107 0 0" mode="trackcom"/>
      <camera name="ego_camera" class="/" pos="0.129788 0 0.0982805" quat="-0.5 -0.5 0.5 0.5"/>
      <body name="coxa_RR" pos="-0.177078 -0.0544189 0.0620558" quat="0.382461 -8.48076e-05 0.000164387 -0.923971">
        <inertial pos="-0.000874173 -0.000761043 -0.000651992" quat="0.999974 -0.00531636 -0.0035347 -0.00336235" mass="0.138266" diaginertia="0.0100221 0.0011697 0.00928217"/>
        <joint name="coxa_joint_RR" class="/" pos="0 0 0" axis="0.000461713 0.00154488 -0.999999" range="-3.13854 3.1101" armature="0.00934465" damping="0.00158776" frictionloss="0.00876123"/>
        <geom name="//unnamed_geom_2" class="/" type="mesh" rgba="0.2 0.2 0.2 1" mesh="coxa"/>
        <geom name="//unnamed_geom_3" class="reward_collision_sphere" size="0.0350946" pos="-0.0299511 0 0"/>
        <body name="femur_RR" pos="0.059124 0.000825743 -0.00103309" quat="0.500056 -0.499885 0.500173 0.499885">
          <inertial pos="0.000689826 -0.000856365 8.7539e-05" quat="0.999996 -0.00210043 0.000116169 -0.00196847" mass="0.134082" diaginertia="0.00981791 0.00115666 0.00913538"/>
          <joint name="femur_joint_RR" class="/" pos="0 0 0" axis="0.000868456 0.00205649 -0.999998" range="-3.15719 3.1539" armature="0.00881034" damping="0.000432509" frictionloss="0.00841048"/>
          <geom name="//unnamed_geom_4" class="/" type="mesh" rgba="0.9 0.9 0.9 1" mesh="femur"/>
          <geom name="//unnamed_geom_5" class="reward_collision_sphere" size="0.0350946"/>
          <body name="tibia_RR" pos="0.000784605 -0.0703978 -0.000530349" quat="0.00021642 1 -0.000142636 0.00024339">
            <inertial pos="0.000364892 0.000527772 -0.000236507" quat="0.999991 -7.60357e-05 -0.00316408 0.00288048" mass="0.137532" diaginertia="0.00982293 0.00116831 0.00915383"/>
            <joint name="tibia_joint_RR" class="/" pos="0 0 0" axis="0.000900919 -0.00117201 0.999999" range="-3.12435 3.14253" armature="0.00884617" damping="0" frictionloss="0.00869649"/>
            <geom name="//unnamed_geom_6" class="/" type="mesh" rgba="0.2 0.2 0.2 1" mesh="tibia"/>
            <geom name="//unnamed_geom_7" class="reward_collision_sphere" size="0.0350946"/>
            <body name="tarsus_RR" pos="0.0877866 0.000757406 -0.000321566" quat="1 0.000325696 0.000193687 0.000219962">
              <inertial pos="0.0616378 0.000575451 0.000595716" quat="0.499204 0.500034 0.500358 0.500403" mass="0.136556" diaginertia="0.0099626 0.00118142 0.00923183"/>
              <joint name="tarsus_joint_RR" class="/" pos="0 0 0" axis="0.000413658 0.00266729 0.999996" stiffness="0.00192306" range="-3.13725 3.13815" armature="0.00896547" damping="0.0419347" frictionloss="0.0087876"/>
              <geom name="//unnamed_geom_8" class="/" type="mesh" rgba="0.9 0.9 0.9 1" mesh="tarsus"/>
              <geom name="foot_1" class="foot" size="0.00857484" pos="0.111818 0 0" quat="0 -0.707107 0 0.707107"/>
              <geom name="//unnamed_geom_10" class="reward_collision_sphere" size="0.0350946"/>
              <geom name="//unnamed_geom_11" class="reward_collision_sphere" size="0.0131605" pos="0.107325 0 0"/>
              <site name="foot_1" class="foot" pos="0.111818 0 0" quat="0 -0.707107 0 0.707107" size="0.00877365"/>
            </body>
          </body>
        </body>
      </body>
      <body name="coxa_RM" pos="-0.00104855 -0.086282 0.0622206" quat="0.7069 9.41519e-05 -2.88315e-05 -0.707314">
        <inertial pos="-0.000325926 5.16608e-06 -3.42087e-05" quat="1 -0.000791879 0.000461135 -0.000286408" mass="0.136269" diaginertia="0.0101278 0.00116587 0.00922183"/>
        <joint name="coxa_joint_RM" class="/" pos="0 0 0" axis="0.00162433 0.000987748 -0.999998" range="-3.14082 3.13553" armature="0.00860743" damping="0.00687103" frictionloss="0.00882155"/>
        <geom name="//unnamed_geom_12" class="/" type="mesh" rgba="0.2 0.2 0.2 1" mesh="coxa"/>
        <geom name="//unnamed_geom_13" class="reward_collision_sphere" size="0.0350946" pos="-0.0299511 0 0"/>
        <body name="femur_RM" pos="0.0585698 0.000593402 0.000239952" quat="0.500048 -0.4996 0.49999 0.500362">
          <inertial pos="0.000334472 0.000664279 -0.000675273" quat="0.999982 -0.00192114 0.00148821 0.00546547" mass="0.131139" diaginertia="0.00985271 0.00114329 0.00898403"/>
          <joint name="femur_joint_RM" class="/" pos="0 0 0" axis="0.000966636 0.00118339 -0.999999" range="-3.16589 3.14089" armature="0.00878881" damping="0.00929791" frictionloss="0.00878745"/>
          <geom name="//unnamed_geom_14" class="/" type="mesh" rgba="0.9 0.9 0.9 1" mesh="femur"/>
          <geom name="//unnamed_geom_15" class="reward_collision_sphere" size="0.0350946"/>
          <body name="tibia_RM" pos="-5.30092e-05 -0.0687856 -0.000802148" quat="3.90781e-05 1 0.000479313 -0.000409941">
            <inertial pos="0.000412752 -6.53637e-05 7.3893e-06" quat="1 0.000772699 -0.000353145 0.00050764" mass="0.135479" diaginertia="0.00992492 0.00115599 0.00898628"/>
            <joint name="tibia_joint_RM" class="/" pos="0 0 0" axis="-0.00192316 -0.00186694 0.999996" range="-3.13983 3.13583" armature="0.00855418" damping="0.00396007" frictionloss="0.00878664"/>
            <geom name="//unnamed_geom_16" class="/" type="mesh" rgba="0.2 0.2 0.2 1" mesh="tibia"/>
            <geom name="//unnamed_geom_17" class="reward_collision_sphere" size="0.0350946"/>
            <body name="tarsus_RM" pos="0.0882358 0.000292697 0.000845458" quat="1 -0.000271376 5.27525e-05 8.75103e-05">
              <inertial pos="0.0599938 0.000230949 0.000162544" quat="0.498492 0.500649 0.501981 0.49887" mass="0.135511" diaginertia="0.00983536 0.00117232 0.00900909"/>
              <joint name="tarsus_joint_RM" class="/" pos="0 0 0" axis="0.00131954 -0.000760992 0.999999" stiffness="0.000397816" range="-3.12987 3.16566" armature="0.00915381" damping="0.00491896" frictionloss="0.00818189"/>
              <geom name="//unnamed_geom_18" class="/" type="mesh" rgba="0.9 0.9 0.9 1" mesh="tarsus"/>
              <geom name="foot_2" class="foot" size="0.00869759" pos="0.111818 0 0" quat="0 -0.707107 0 0.707107"/>
              <geom name="//unnamed_geom_20" class="reward_collision_sphere" size="0.0350946"/>
              <geom name="//unnamed_geom_21" class="reward_collision_sphere" size="0.0131605" pos="0.107325 0 0"/>
              <site name="foot_2" class="foot" pos="0.111818 0 0" quat="0 -0.707107 0 0.707107" size="0.00877365"/>
            </body>
          </body>
        </body>
      </body>
      <body name="coxa_RF" pos="0.17723 -0.0542653 0.0622119" quat="0.923819 5.83591e-05 -8.2602e-05 -0.382829">
        <inertial pos="0.00099117 0.000791762 0.000280469" quat="0.999999 0.000163115 0.00106252 -0.00111617" mass="0.135898" diaginertia="0.0098933 0.00117905 0.00915203"/>
        <joint name="coxa_joint_RF" class="/" pos="0 0 0" axis="-0.000346561 -0.00023699 -1" range="-3.15831 3.12064" armature="0.00910639" damping="0.00302557" frictionloss="0.00897123"/>
        <geom name="//unnamed_geom_22" class="/" type="mesh" rgba="0.2 0.2 0.2 1" mesh="coxa"/>
        <geom name="//unnamed_geom_23" class="reward_collision_sphere" size="0.0350946" pos="-0.0299511 0 0"/>
        <body name="femur_RF" pos="0.0584973 0.000507522 -0.000628895" quat="0.499885 -0.500062 0.500102 0.499951">
          <inertial pos="0.000500402 0.000600177 0.00125763" quat="0.999999 -0.0010269 -0.000993296 -0.000159812" mass="0.132045" diaginertia="0.00979873 0.00115225 0.00894481"/>
          <joint name="femur_joint_RF" class="/" pos="0 0 0" axis="-0.0067921 -0.000176906 -0.999977" range="-3.14332 3.15583" armature="0.00939633" damping="0.00975244" frictionloss="0.00868575"/>
          <geom name="//unnamed_geom_24" class="/" type="mesh" rgba="0.9 0.9 0.9 1" mesh="femur"/>
          <geom name="//unnamed_geom_25" class="reward_collision_sphere" size="0.0350946"/>
          <body name="tibia_RF" pos="0.000880262 -0.0712388 0.000565515" quat="-0.00044035 1 -0.000116915 -0.000294914">
            <inertial pos="0.000664928 8.77077e-05 3.88133e-05" quat="1 -4.08065e-05 0.000321734 0.000216382" mass="0.13456" diaginertia="0.00999235 0.00116809 0.00934374"/>
            <joint name="tibia_joint_RF" class="/" pos="0 0 0" axis="-1.27297e-05 3.84819e-06 1" range="-3.13969 3.15451" armature="0.00892167" damping="0.0116402" frictionloss="0.00851862"/>
            <geom name="//unnamed_geom_26" class="/" type="mesh" rgba="0.2 0.2 0.2 1" mesh="tibia"/>
            <geom name="//unnamed_geom_27" class="reward_collision_sphere" size="0.0350946"/>
            <body name="tarsus_RF" pos="0.0866352 0.00039518 -0.000369555" quat="1 -0.000254274 1.6576e-05 0.000516717">
              <inertial pos="0.0588418 0.000308097 -0.000427883" quat="0.49881 0.502135 0.501076 0.497968" mass="0.136187" diaginertia="0.01004 0.00118176 0.00919875"/>
              <joint name="tarsus_joint_RF" class="/" pos="0 0 0" axis="0.00376438 0.00686315 0.999969" stiffness="0.000459843" range="-3.13981 3.14102" armature="0.00881534" damping="0" frictionloss="0.00843497"/>
              <geom name="//unnamed_geom_28" class="/" type="mesh" rgba="0.9 0.9 0.9 1" mesh="tarsus"/>
              <geom name="foot_3" class="foot" size="0.00880803" pos="0.111818 0 0" quat="0 -0.707107 0 0.707107"/>
              <geom name="//unnamed_geom_30" class="reward_collision_sphere" size="0.0350946"/>
              <geom name="//unnamed_geom_31" class="reward_collision_sphere" size="0.0131605" pos="0.107325 0 0"/>
              <site name="foot_3" class="foot" pos="0.111818 0 0" quat="0 -0.707107 0 0.707107" size="0.00877365"/>
            </body>
          </body>
        </body>
      </body>
      <body name="coxa_LR" pos="-0.175481 0.0567989 0.064661" quat="0.382855 -0.000136221 -5.668e-05 0.923808">
        <inertial pos="-0.000161662 -4.56018e-05 0.000297603" quat="0.999999 3.67063e-05 0.00102834 0.000532289" mass="0.136148" diaginertia="0.00984427 0.00117164 0.00898854"/>
        <joint name="coxa_joint_LR" class="/" pos="0 0 0" axis="-0.000297199 0.00552765 -0.999985" range="-3.13635 3.14036" armature="0.00922861" damping="0.00475595" frictionloss="0.00875322"/>
        <geom name="//unnamed_geom_32" class="/" type="mesh" rgba="0.2 0.2 0.2 1" mesh="coxa"/>
        <geom name="//unnamed_geom_33" class="reward_collision_sphere" size="0.0350946" pos="-0.0299511 0 0"/>
        <body name="femur_LR" pos="0.0610842 -0.00196379 -0.00135756" quat="0.499652 -0.500335 0.499858 0.500155">
          <inertial pos="0.000213927 -0.000666331 -0.0011054" quat="0.999991 0.00409074 0.000639928 0.000212838" mass="0.134064" diaginertia="0.00981029 0.00118251 0.00908636"/>
          <joint name="femur_joint_LR" class="/" pos="0 0 0" axis="0.000106495 0.000362644 1" range="-3.15276 3.14983" armature="0.00874661" damping="0" frictionloss="0.00891277"/>
          <geom name="//unnamed_geom_34" class="/" type="mesh" rgba="0.9 0.9 0.9 1" mesh="femur"/>
          <geom name="//unnamed_geom_35" class="reward_collision_sphere" size="0.0350946"/>
          <body name="tibia_LR" pos="0.000609654 -0.0713421 -0.00135663" quat="1.10713e-05 1 -2.19667e-06 2.63004e-05">
            <inertial pos="-0.00163722 0.000593538 -0.00064359" quat="0.999997 0.000856734 -0.00163134 -0.00175099" mass="0.135069" diaginertia="0.00984937 0.00116643 0.00918253"/>
            <joint name="tibia_joint_LR" class="/" pos="0 0 0" axis="0.00095717 -0.00110777 -0.999999" range="-3.12357 3.13711" armature="0.00916599" damping="0.00340488" frictionloss="0.00906947"/>
            <geom name="//unnamed_geom_36" class="/" type="mesh" rgba="0.2 0.2 0.2 1" mesh="tibia"/>
            <geom name="//unnamed_geom_37" class="reward_collision_sphere" size="0.0350946"/>
            <body name="tarsus_LR" pos="0.088931 0.00104296 0.00132361" quat="1 -1.25512e-05 -1.33979e-05 7.45519e-06">
              <inertial pos="0.0607889 0.000903148 -0.000113028" quat="0.500248 0.499711 0.500804 0.499235" mass="0.137598" diaginertia="0.0100983 0.00116792 0.00923411"/>
              <joint name="tarsus_joint_LR" class="/" pos="0 0 0" axis="-0.0065679 -0.0007607 -0.999978" stiffness="0.00379442" range="-3.14946 3.14364" armature="0.00860741" damping="0.0288947" frictionloss="0.00869769"/>
              <geom name="//unnamed_geom_38" class="/" type="mesh" rgba="0.9 0.9 0.9 1" mesh="tarsus"/>
              <geom name="foot_4" class="foot" size="0.00852337" pos="0.111818 0 0" quat="0.707107 0 -0.707107 0"/>
              <geom name="//unnamed_geom_40" class="reward_collision_sphere" size="0.0350946"/>
              <geom name="//unnamed_geom_41" class="reward_collision_sphere" size="0.0131605" pos="0.107325 0 0"/>
              <site name="foot_4" class="foot" pos="0.111818 0 0" quat="0.707107 0 -0.707107 0" size="0.00877365"/>
            </body>
          </body>
        </body>
      </body>
      <body name="coxa_LM" pos="-0.00150928 0.0846766 0.0633032" quat="0.707149 6.57755e-05 -0.000108348 0.707065">
        <inertial pos="0.00110684 0.00113396 2.40253e-05" quat="1 -0.000128002 -0.000218132 -0.000130951" mass="0.135237" diaginertia="0.0098991 0.00117129 0.0092024"/>
        <joint name="coxa_joint_LM" class="/" pos="0 0 0" axis="0.00195877 0.00365768 -0.999991" range="-3.15397 3.15423" armature="0.00892334" damping="0.00742344" frictionloss="0.00841527"/>
        <geom name="//unnamed_geom_42" class="/" type="mesh" rgba="0.2 0.2 0.2 1" mesh="coxa"/>
        <geom name="//unnamed_geom_43" class="reward_collision_sphere" size="0.0350946" pos="-0.0299511 0 0"/>
        <body name="femur_LM" pos="0.0552056 0.000516891 -0.000279769" quat="0.500373 -0.499562 0.500341 0.499723">
          <inertial pos="0.00044259 -0.000875055 -0.000354874" quat="1 -0.000270655 -0.000240045 0.000485834" mass="0.134855" diaginertia="0.0098908 0.00117549 0.00916636"/>
          <joint name="femur_joint_LM" class="/" pos="0 0 0" axis="-0.00277334 -0.0017313 0.999995" range="-3.15661 3.14058" armature="0.00826972" damping="0.00400298" frictionloss="0.00878322"/>
          <geom name="//unnamed_geom_44" class="/" type="mesh" rgba="0.9 0.9 0.9 1" mesh="femur"/>
          <geom name="//unnamed_geom_45" class="reward_collision_sphere" size="0.0350946"/>
          <body name="tibia_LM" pos="0.000593838 -0.0689302 0.00114357" quat="-5.11319e-05 1 3.69084e-05 9.76823e-06">
            <inertial pos="-0.000718122 -0.0010371 -0.00100357" quat="0.999996 0.000160889 -0.000882622 0.00281484" mass="0.134579" diaginertia="0.00994614 0.00118288 0.00937225"/>
            <joint name="tibia_joint_LM" class="/" pos="0 0 0" axis="-0.000683579 0.00133954 -0.999999" range="-3.12793 3.13312" armature="0.00888176" damping="0.000410136" frictionloss="0.00910935"/>
            <geom name="//unnamed_geom_46" class="/" type="mesh" rgba="0.2 0.2 0.2 1" mesh="tibia"/>
            <geom name="//unnamed_geom_47" class="reward_collision_sphere" size="0.0350946"/>
            <body name="tarsus_LM" pos="0.0863354 -1.94752e-05 -0.00160935" quat="1 6.99209e-06 1.31225e-05 9.08286e-05">
              <inertial pos="0.0602578 -9.36121e-05 -8.65627e-05" quat="0.497821 0.503284 0.497989 0.500887" mass="0.138073" diaginertia="0.00986618 0.00118124 0.00918259"/>
              <joint name="tarsus_joint_LM" class="/" pos="0 0 0" axis="0.0058033 -0.00560111 -0.999967" range="-3.13832 3.14968" armature="0.00886243" damping="0.00666619" frictionloss="0.0087802"/>
              <geom name="//unnamed_geom_48" class="/" type="mesh" rgba="0.9 0.9 0.9 1" mesh="tarsus"/>
              <geom name="foot_5" class="foot" size="0.00854409" pos="0.111818 0 0" quat="0.707107 0 -0.707107 0"/>
              <geom name="//unnamed_geom_50" class="reward_collision_sphere" size="0.0350946"/>
              <geom name="//unnamed_geom_51" class="reward_collision_sphere" size="0.0131605" pos="0.107325 0 0"/>
              <site name="foot_5" class="foot" pos="0.111818 0 0" quat="0.707107 0 -0.707107 0" size="0.00877365"/>
            </body>
          </body>
        </body>
      </body>
      <body name="coxa_LF" pos="0.1777 0.0542279 0.0629404" quat="0.923872 3.08793e-05 6.34506e-05 0.382703">
        <inertial pos="4.15841e-05 3.79785e-05 0.000469491" quat="1 7.52514e-05 6.88471e-05 -3.74074e-05" mass="0.133417" diaginertia="0.00988134 0.0011604 0.0091184"/>
        <joint name="coxa_joint_LF" class="/" pos="0 0 0" axis="0.000425789 0.000825822 -1" range="-3.13531 3.15702" armature="0.00870931" damping="0.00381447" frictionloss="0.00873136"/>
        <geom name="//unnamed_geom_52" class="/" type="mesh" rgba="0.2 0.2 0.2 1" mesh="coxa"/>
        <geom name="//unnamed_geom_53" class="reward_collision_sphere" size="0.0350946" pos="-0.0299511 0 0"/>
        <body name="femur_LF" pos="0.0596179 0.00179805 -0.00186475" quat="0.500205 -0.499962 0.499822 0.500011">
          <inertial pos="-0.000336336 -0.000826699 0.00012772" quat="0.999999 0.000135006 -0.000175159 0.00153975" mass="0.136175" diaginertia="0.00992135 0.00118468 0.00927249"/>
          <joint name="femur_joint_LF" class="/" pos="0 0 0" axis="0.00293258 -0.00280246 0.999992" range="-3.13824 3.12652" armature="0.00877098" damping="0" frictionloss="0.00888597"/>
          <geom name="//unnamed_geom_54" class="/" type="mesh" rgba="0.9 0.9 0.9 1" mesh="femur"/>
          <geom name="//unnamed_geom_55" class="reward_collision_sphere" size="0.0350946"/>
          <body name="tibia_LF" pos="-0.00037441 -0.0707175 -0.000614226" quat="0.000140573 1 4.50865e-05 2.26703e-05">
            <inertial pos="-0.000437302 -0.000975276 0.000578954" quat="0.999994 0.00128568 -0.00235789 0.00224805" mass="0.135083" diaginertia="0.00993692 0.00115499 0.00908723"/>
            <joint name="tibia_joint_LF" class="/" pos="0 0 0" axis="0.00220986 -0.0025743 -0.999994" range="-3.1445 3.15716" armature="0.00816577" damping="0.00204448" frictionloss="0.00880261"/>
            <geom name="//unnamed_geom_56" class="/" type="mesh" rgba="0.2 0.2 0.2 1" mesh="tibia"/>
            <geom name="//unnamed_geom_57" class="reward_collision_sphere" size="0.0350946"/>
            <body name="tarsus_LF" pos="0.0870668 -0.000573612 -0.000407478" quat="1 0.00033156 -0.000426746 0.000489528">
              <inertial pos="0.060037 -0.000133223 6.60695e-05" quat="0.499195 0.500703 0.499689 0.500412" mass="0.135052" diaginertia="0.00996341 0.00117095 0.00912978"/>
              <joint name="tarsus_joint_LF" class="/" pos="0 0 0" axis="-0.00206117 -0.00274818 -0.999994" range="-3.13275 3.14674" armature="0.00888366" damping="0.00933974" frictionloss="0.00888339"/>
              <geom name="//unnamed_geom_58" class="/" type="mesh" rgba="0.9 0.9 0.9 1" mesh="tarsus"/>
              <geom name="foot_6" class="foot" size="0.00870324" pos="0.111818 0 0" quat="0.707107 0 -0.707107 0"/>
              <geom name="//unnamed_geom_60" class="reward_collision_sphere" size="0.0350946"/>
              <geom name="//unnamed_geom_61" class="reward_collision_sphere" size="0.0131605" pos="0.107325 0 0"/>
              <site name="foot_6" class="foot" pos="0.111818 0 0" quat="0.707107 0 -0.707107 0" size="0.00877365"/>
            </body>
          </body>
        </body>
      </body>
    </body>
  </worldbody>

  <contact>
    <pair class="/" geom1="floor" geom2="foot_1" name="//unnamed_contact_0"/>
    <pair class="/" geom1="floor" geom2="foot_2" name="//unnamed_contact_1"/>
    <pair class="/" geom1="floor" geom2="foot_3" name="//unnamed_contact_2"/>
    <pair class="/" geom1="floor" geom2="foot_4" name="//unnamed_contact_3"/>
    <pair class="/" geom1="floor" geom2="foot_5" name="//unnamed_contact_4"/>
    <pair class="/" geom1="floor" geom2="foot_6" name="//unnamed_contact_5"/>
  </contact>

  <actuator>
    <general name="coxa_joint_RR" class="/" joint="coxa_joint_RR" forcerange="-6.46558 6.46558" gainprm="20.8666" biasprm="0 -20.8666 -0.459036"/>
    <general name="femur_joint_RR" class="/" joint="femur_joint_RR" forcerange="-6.38914 6.38914" gainprm="20.8666" biasprm="0 -20.8666 -0.459036"/>
    <general name="tibia_joint_RR" class="/" joint="tibia_joint_RR" forcerange="-6.33572 6.33572" gainprm="20.8666" biasprm="0 -20.8666 -0.459036"/>
    <general name="tarsus_joint_RR" class="/" joint="tarsus_joint_RR" forcerange="-6.43423 6.43423" gainprm="20.8666" biasprm="0 -20.8666 -0.459036"/>
    <general name="coxa_joint_RM" class="/" joint="coxa_joint_RM" forcerange="-6.4863 6.4863" gainprm="20.8666" biasprm="0 -20.8666 -0.459036"/>
    <general name="femur_joint_RM" class="/" joint="femur_joint_RM" forcerange="-6.43162 6.43162" gainprm="20.8666" biasprm="0 -20.8666 -0.459036"/>
    <general name="tibia_joint_RM" class="/" joint="tibia_joint_RM" forcerange="-6.38589 6.38589" gainprm="20.8666" biasprm="0 -20.8666 -0.459036"/>
    <general name="tarsus_joint_RM" class="/" joint="tarsus_joint_RM" forcerange="-6.25684 6.25684" gainprm="20.8666" biasprm="0 -20.8666 -0.459036"/>
    <general name="coxa_joint_RF" class="/" joint="coxa_joint_RF" forcerange="-6.37603 6.37603" gainprm="20.8666" biasprm="0 -20.8666 -0.459036"/>
    <general name="femur_joint_RF" class="/" joint="femur_joint_RF" forcerange="-6.47622 6.47622" gainprm="20.8666" biasprm="0 -20.8666 -0.459036"/>
    <general name="tibia_joint_RF" class="/" joint="tibia_joint_RF" forcerange="-6.30164 6.30164" gainprm="20.8666" biasprm="0 -20.8666 -0.459036"/>
    <general name="tarsus_joint_RF" class="/" joint="tarsus_joint_RF" forcerange="-6.19196 6.19196" gainprm="20.8666" biasprm="0 -20.8666 -0.459036"/>
    <general name="coxa_joint_LR" class="/" joint="coxa_joint_LR" forcerange="-6.31644 6.31644" gainprm="20.8666" biasprm="0 -20.8666 -0.459036"/>
    <general name="femur_joint_LR" class="/" joint="femur_joint_LR" forcerange="-6.6246 6.6246" gainprm="20.8666" biasprm="0 -20.8666 -0.459036"/>
    <general name="tibia_joint_LR" class="/" joint="tibia_joint_LR" forcerange="-6.19149 6.19149" gainprm="20.8666" biasprm="0 -20.8666 -0.459036"/>
    <general name="tarsus_joint_LR" class="/" joint="tarsus_joint_LR" forcerange="-6.6843 6.6843" gainprm="20.8666" biasprm="0 -20.8666 -0.459036"/>
    <general name="coxa_joint_LM" class="/" joint="coxa_joint_LM" forcerange="-6.18087 6.18087" gainprm="20.8666" biasprm="0 -20.8666 -0.459036"/>
    <general name="femur_joint_LM" class="/" joint="femur_joint_LM" forcerange="-6.45651 6.45651" gainprm="20.8666" biasprm="0 -20.8666 -0.459036"/>
    <general name="tibia_joint_LM" class="/" joint="tibia_joint_LM" forcerange="-6.42501 6.42501" gainprm="20.8666" biasprm="0 -20.8666 -0.459036"/>
    <general name="tarsus_joint_LM" class="/" joint="tarsus_joint_LM" forcerange="-6.59991 6.59991" gainprm="20.8666" biasprm="0 -20.8666 -0.459036"/>
    <general name="coxa_joint_LF" class="/" joint="coxa_joint_LF" forcerange="-6.44192 6.44192" gainprm="20.8666" biasprm="0 -20.8666 -0.459036"/>
    <general name="femur_joint_LF" class="/" joint="femur_joint_LF" forcerange="-6.41875 6.41875" gainprm="20.8666" biasprm="0 -20.8666 -0.459036"/>
    <general name="tibia_joint_LF" class="/" joint="tibia_joint_LF" forcerange="-6.26011 6.26011" gainprm="20.8666" biasprm="0 -20.8666 -0.459036"/>
    <general name="tarsus_joint_LF" class="/" joint="tarsus_joint_LF" forcerange="-6.34793 6.34793" gainprm="20.8666" biasprm="0 -20.8666 -0.459036"/>
  </actuator>

  <sensor>
    <gyro site="imu" name="imu_angular_velocity"/>
    <velocimeter site="imu" name="imu_linear_velocity"/>
    <framelinvel objtype="site" objname="foot_1" name="foot_1_global_linear_velocity"/>
    <framelinvel objtype="site" objname="foot_2" name="foot_2_global_linear_velocity"/>
    <framelinvel objtype="site" objname="foot_3" name="foot_3_global_linear_velocity"/>
    <framelinvel objtype="site" objname="foot_4" name="foot_4_global_linear_velocity"/>
    <framelinvel objtype="site" objname="foot_5" name="foot_5_global_linear_velocity"/>
    <framelinvel objtype="site" objname="foot_6" name="foot_6_global_linear_velocity"/>
  </sensor>

  <keyframe>
    <key name="home" qpos="0 0 0.1457 1 0 0 0 0 0 0 0 0 0 0 0 0 0 0 0 0 0 0 0 0 0 0 0 0 0 0 0"/>
  </keyframe>
</mujoco>
