<mujoco model="Golem">
  <compiler angle="radian" assetdir="assets" balanceinertia="true" inertiafromgeom="false"/>

  <option timestep="0.005" density="1.2" viscosity="2e-05"/>

  <size nkey="1"/>

  <visual>
    <quality shadowsize="8192"/>
    <map shadowclip="0.5"/>
  </visual>

  <default>
    <default class="/">
      <joint armature="0.01" damping="0.01" frictionloss="0.01"/>
      <geom contype="0" conaffinity="0" group="1" solref="-1000 -80"/>
      <site size="0.01 0.005 0.005" group="5"/>
      <general forcelimited="true" biastype="affine" gainprm="25" biasprm="0 -25 -0.5"/>
      <default class="visual">
        <geom type="mesh" group="2"/>
      </default>
      <default class="collision">
        <geom group="3"/>
      </default>
      <default class="foot">
        <geom size="0.01 0 0" condim="6" group="4" priority="1" solimp="0.015 1 0.01"/>
      </default>
      <default class="reward_collision_sphere">
        <geom group="5" rgba="1 0 0 1"/>
      </default>
    </default>
  </default>

  <asset>
    <texture type="skybox" colorspace="auto" name="//unnamed_texture_0" builtin="gradient" rgb1="0.95 0.95 0.95" rgb2="0.95 0.95 0.95" width="100" height="600"/>
    <texture type="2d" colorspace="auto" name="texplane" builtin="checker" rgb1="0.345 0.575 0.748" rgb2="0.345 0.575 0.748" markrgb="1 1 1" width="512" height="512"/>
    <material name="MatPlane" class="/" texture="texplane" texuniform="true" texrepeat="2 2" specular="0.9"/>
    <mesh name="body" class="/" file="body.stl" scale="0.001 0.001 0.001"/>
    <mesh name="coxa" class="/" file="coxa.stl" scale="0.001 0.001 0.001"/>
    <mesh name="femur" class="/" file="femur.stl" scale="0.001 0.001 0.001"/>
    <mesh name="tibia" class="/" file="tibia.stl" scale="0.001 0.001 0.001"/>
    <mesh name="tarsus" class="/" file="tarsus.stl" scale="0.001 0.001 0.001"/>
  </asset>

  <worldbody>
    <geom name="floor" class="/" size="100 100 0.125" type="plane" group="0" material="MatPlane"/>
    <light name="toplight_shadow" class="/" pos="0 0 5" dir="0.0990148 0.0990148 -0.990148" type="directional" ambient="0.04 0.04 0.04" diffuse="0.55 0.55 0.55" specular="0.12 0.12 0.12"/>
    <light name="toplight_fill" class="/" pos="0 0 5" dir="0.0990148 0.0990148 -0.990148" type="directional" castshadow="false" ambient="0.04 0.04 0.04" diffuse="0.3 0.3 0.3" specular="0.08 0.08 0.08"/>
    <body name="trunk" pos="0.000120388 0.00195341 0.0066308" quat="1 7.47895e-05 2.48533e-05 -0.00022108">
      <inertial pos="-0.000382535 -0.000130507 -0.00629968" quat="0.999901 0.00584181 0.0127122 0.001277" mass="3.9442" diaginertia="0.027776 0.00194056 0.021706"/>
      <joint name="//unnamed_joint_0" type="free"/>
      <geom name="//unnamed_geom_1" class="/" pos="0 0 0.0742647" quat="1 0 0 0" type="mesh" rgba="0.9 0.9 0.9 1" mesh="body"/>
      <site name="imu" class="/" pos="0.166002 -0.0107798 0.124166" size="0.0102735"/>
      <camera name="track" class="/" pos="0 -1.44421 0" quat="0.707107 0.707107 0 0" mode="trackcom"/>
      <camera name="ego_camera" class="/" pos="0.155941 0 0.116039" quat="-0.5 -0.5 0.5 0.5"/>
      <body name="coxa_RR" pos="-0.210575 -0.0620737 0.0776667" quat="0.382363 -0.000679557 -0.000391541 -0.924012">
        <inertial pos="0.000241198 0.00636855 0.00230232" quat="0.999945 0.00307152 0.00957193 0.00283691" mass="0.236847" diaginertia="0.0281422 0.00202566 0.0234913"/>
        <joint name="coxa_joint_RR" class="/" pos="0 0 0" axis="-0.0241065 0.0324101 -0.999184" range="-3.1463 3.18422" armature="0.0108526" damping="0.0184221" frictionloss="0.0114313"/>
        <geom name="//unnamed_geom_2" class="/" type="mesh" rgba="0.2 0.2 0.2 1" mesh="coxa"/>
        <geom name="//unnamed_geom_3" class="reward_collision_sphere" size="0.0410938" pos="-0.0359864 0 0"/>
        <body name="femur_RR" pos="0.0686918 0.00264176 -0.00726399" quat="0.49952 -0.499418 0.500249 0.500811">
          <inertial pos="-0.00221323 -0.00116251 0.000874228" quat="1 -1.25362e-07 3.24029e-07 -2.75941e-07" mass="0.209526" diaginertia="0.023969 0.00192188 0.0206581"/>
          <joint name="femur_joint_RR" class="/" pos="0 0 0" axis="0.000370015 -0.000301342 -1" range="-3.10309 3.24917" armature="0.0113996" damping="0.0311773" frictionloss="0.00891038"/>
          <geom name="//unnamed_geom_4" class="/" type="mesh" rgba="0.9 0.9 0.9 1" mesh="femur"/>
          <geom name="//unnamed_geom_5" class="reward_collision_sphere" size="0.0410938"/>
          <body name="tibia_RR" pos="-0.00561856 -0.0804263 -0.00225323" quat="0.00032607 1 0.000108501 -2.66858e-05">
            <inertial pos="0.00464575 0.00179407 -0.000273131" quat="0.999874 -0.0151295 0.00261227 0.0040245" mass="0.21652" diaginertia="0.0252001 0.00186063 0.0198856"/>
            <joint name="tibia_joint_RR" class="/" pos="0 0 0" axis="-0.00299994 -0.00175494 0.999994" range="-3.01595 3.12749" armature="0.0116656" damping="0.0172982" frictionloss="0.0113916"/>
            <geom name="//unnamed_geom_6" class="/" type="mesh" rgba="0.2 0.2 0.2 1" mesh="tibia"/>
            <geom name="//unnamed_geom_7" class="reward_collision_sphere" size="0.0410938"/>
            <body name="tarsus_RR" pos="0.105816 -0.00238782 -0.00170509" quat="1 0.000105696 -0.000585578 0.000567312">
              <inertial pos="0.0763969 -0.00519208 0.00282955" quat="0.499546 0.503198 0.498158 0.499082" mass="0.224024" diaginertia="0.0252429 0.00200158 0.021424"/>
              <joint name="tarsus_joint_RR" class="/" pos="0 0 0" axis="-0.00925359 -6.91731e-05 0.999957" stiffness="0.0349186" range="-3.08968 3.1291" armature="0.00858597" damping="0.0182168" frictionloss="0.00845029"/>
              <geom name="//unnamed_geom_8" class="/" type="mesh" rgba="0.9 0.9 0.9 1" mesh="tarsus"/>
              <geom name="foot_1" class="foot" size="0.0110988" pos="0.134349 0 0" quat="0 -0.707107 0 0.707107"/>
              <geom name="//unnamed_geom_10" class="reward_collision_sphere" size="0.0410938"/>
              <geom name="//unnamed_geom_11" class="reward_collision_sphere" size="0.0154102" pos="0.128951 0 0"/>
              <site name="foot_1" class="foot" pos="0.134349 0 0" quat="0 -0.707107 0 0.707107" size="0.0102735"/>
            </body>
          </body>
        </body>
      </body>
      <body name="coxa_RM" pos="-0.000370419 -0.0965568 0.0808685" quat="0.705369 0.00148277 0.00208978 -0.708836">
        <inertial pos="0.00478908 -0.000394315 4.61662e-05" quat="0.999936 -0.00109442 0.0100425 0.00510224" mass="0.221984" diaginertia="0.0265792 0.0020297 0.0204634"/>
        <joint name="coxa_joint_RM" class="/" pos="0 0 0" axis="-0.00326543 0.00244233 -0.999992" range="-2.99405 3.14167" armature="0.00954555" damping="0.00409149" frictionloss="0.0100061"/>
        <geom name="//unnamed_geom_12" class="/" type="mesh" rgba="0.2 0.2 0.2 1" mesh="coxa"/>
        <geom name="//unnamed_geom_13" class="reward_collision_sphere" size="0.0410938" pos="-0.0359864 0 0"/>
        <body name="femur_RM" pos="0.0726391 -0.00104477 -0.000985641" quat="0.498569 -0.499034 0.50062 0.501771">
          <inertial pos="-0.00024245 -0.000574784 0.000428854" quat="0.999705 0.020334 0.00228196 0.013101" mass="0.204834" diaginertia="0.0237445 0.001952 0.0195359"/>
          <joint name="femur_joint_RM" class="/" pos="0 0 0" axis="-0.00560746 0.00665464 -0.999962" stiffness="0.031503" range="-3.15897 3.1383" armature="0.0114176" damping="0.0162093" frictionloss="0.00999555"/>
          <geom name="//unnamed_geom_14" class="/" type="mesh" rgba="0.9 0.9 0.9 1" mesh="femur"/>
          <geom name="//unnamed_geom_15" class="reward_collision_sphere" size="0.0410938"/>
          <body name="tibia_RM" pos="0.00246325 -0.0757204 -0.00518324" quat="0.000383387 0.999999 -0.000340911 0.00112951">
            <inertial pos="-0.00166755 -0.00792793 0.00189228" quat="0.999951 -0.00445704 0.00788687 -0.00405951" mass="0.20073" diaginertia="0.0232025 0.00180077 0.0190889"/>
            <joint name="tibia_joint_RM" class="/" pos="0 0 0" axis="0.00658347 -0.00175958 0.999977" range="-3.18995 3.30178" armature="0.00984636" damping="0.0346762" frictionloss="0.0111971"/>
            <geom name="//unnamed_geom_16" class="/" type="mesh" rgba="0.2 0.2 0.2 1" mesh="tibia"/>
            <geom name="//unnamed_geom_17" class="reward_collision_sphere" size="0.0410938"/>
            <body name="tarsus_RM" pos="0.110372 0.00550557 -0.000721232" quat="0.999999 0.000991042 0.000574055 -0.000880001">
              <inertial pos="0.0724707 -0.00677842 0.00107424" quat="0.500411 0.499188 0.500137 0.500263" mass="0.244846" diaginertia="0.0257009 0.00208339 0.0218729"/>
              <joint name="tarsus_joint_RM" class="/" pos="0 0 0" axis="0.00156967 -0.00485581 0.999987" range="-3.1573 3.09717" armature="0.00959784" damping="0.00380357" frictionloss="0.0101062"/>
              <geom name="//unnamed_geom_18" class="/" type="mesh" rgba="0.9 0.9 0.9 1" mesh="tarsus"/>
              <geom name="foot_2" class="foot" size="0.0105227" pos="0.134349 0 0" quat="0 -0.707107 0 0.707107"/>
              <geom name="//unnamed_geom_20" class="reward_collision_sphere" size="0.0410938"/>
              <geom name="//unnamed_geom_21" class="reward_collision_sphere" size="0.0154102" pos="0.128951 0 0"/>
              <site name="foot_2" class="foot" pos="0.134349 0 0" quat="0 -0.707107 0 0.707107" size="0.0102735"/>
            </body>
          </body>
        </body>
      </body>
      <body name="coxa_RF" pos="0.211909 -0.0608272 0.0797361" quat="0.923986 -0.000828507 0.000393556 -0.382424">
        <inertial pos="0.00529726 0.00199312 -0.00396173" quat="0.999982 -0.0046062 0.00288223 -0.00239928" mass="0.198083" diaginertia="0.0228715 0.00194559 0.0194368"/>
        <joint name="coxa_joint_RF" class="/" pos="0 0 0" axis="-0.00741948 0.00183369 -0.999971" range="-3.11083 3.13433" armature="0.0123419" damping="0" frictionloss="0.00937316"/>
        <geom name="//unnamed_geom_22" class="/" type="mesh" rgba="0.2 0.2 0.2 1" mesh="coxa"/>
        <geom name="//unnamed_geom_23" class="reward_collision_sphere" size="0.0410938" pos="-0.0359864 0 0"/>
        <body name="femur_RF" pos="0.0650713 -0.000425264 0.00236822" quat="0.500775 -0.497924 0.500237 0.501058">
          <inertial pos="-0.00230005 1.43691e-05 0.00213053" quat="0.999936 0.00826048 -0.00167771 -0.00750209" mass="0.250625" diaginertia="0.025107 0.00211566 0.0234111"/>
          <joint name="femur_joint_RF" class="/" pos="0 0 0" axis="-0.00794833 0.00289285 -0.999964" stiffness="0.0344764" range="-3.12869 3.25955" armature="0.0139962" damping="0.0176142" frictionloss="0.0140113"/>
          <geom name="//unnamed_geom_24" class="/" type="mesh" rgba="0.9 0.9 0.9 1" mesh="femur"/>
          <geom name="//unnamed_geom_25" class="reward_collision_sphere" size="0.0410938"/>
          <body name="tibia_RF" pos="0.000273014 -0.0843965 -0.00670786" quat="2.45295e-05 1 -0.000127212 -7.9485e-05">
            <inertial pos="0.00557612 -0.00164389 0.000578795" quat="0.99996 -0.00796616 0.00413027 -0.000668562" mass="0.228112" diaginertia="0.0265782 0.00200623 0.02163"/>
            <joint name="tibia_joint_RF" class="/" pos="0 0 0" axis="0.00361178 0.00200686 0.999991" stiffness="0.000174873" range="-3.17612 3.17098" armature="0.0108382" damping="0.0305222" frictionloss="0.00958187"/>
            <geom name="//unnamed_geom_26" class="/" type="mesh" rgba="0.2 0.2 0.2 1" mesh="tibia"/>
            <geom name="//unnamed_geom_27" class="reward_collision_sphere" size="0.0410938"/>
            <body name="tarsus_RF" pos="0.103051 -0.00125372 0.005324" quat="0.999999 0.00074002 -0.00109608 -0.000402252">
              <inertial pos="0.0769061 0.00132553 -0.00152681" quat="0.490793 0.471433 0.518954 0.517262" mass="0.223761" diaginertia="0.0250177 0.00191195 0.022966"/>
              <joint name="tarsus_joint_RF" class="/" pos="0 0 0" axis="-0.00212131 0.00421241 0.999989" stiffness="0.00342571" range="-3.17408 3.12396" armature="0.0134774" damping="0.00482008" frictionloss="0.0126369"/>
              <geom name="//unnamed_geom_28" class="/" type="mesh" rgba="0.9 0.9 0.9 1" mesh="tarsus"/>
              <geom name="foot_3" class="foot" size="0.0100868" pos="0.134349 0 0" quat="0 -0.707107 0 0.707107"/>
              <geom name="//unnamed_geom_30" class="reward_collision_sphere" size="0.0410938"/>
              <geom name="//unnamed_geom_31" class="reward_collision_sphere" size="0.0154102" pos="0.128951 0 0"/>
              <site name="foot_3" class="foot" pos="0.134349 0 0" quat="0 -0.707107 0 0.707107" size="0.0102735"/>
            </body>
          </body>
        </body>
      </body>
      <body name="coxa_LR" pos="-0.215812 0.0603017 0.0792479" quat="0.382884 -0.000778492 -2.26194e-05 0.923796">
        <inertial pos="0.000829347 0.000222843 -0.00125216" quat="0.999493 -0.0217141 0.0218365 0.00807425" mass="0.208756" diaginertia="0.0250523 0.00182333 0.020946"/>
        <joint name="coxa_joint_LR" class="/" pos="0 0 0" axis="0.00189874 -0.000125031 -0.999998" range="-3.15424 3.13413" armature="0.00819877" damping="0.0220574" frictionloss="0.010699"/>
        <geom name="//unnamed_geom_32" class="/" type="mesh" rgba="0.2 0.2 0.2 1" mesh="coxa"/>
        <geom name="//unnamed_geom_33" class="reward_collision_sphere" size="0.0410938" pos="-0.0359864 0 0"/>
        <body name="femur_LR" pos="0.076565 -0.00171622 -0.00371825" quat="0.499583 -0.499101 0.500982 0.500332">
          <inertial pos="0.00450473 0.00605587 -0.00601334" quat="0.999998 0.000985979 0.00142081 -0.000209516" mass="0.198921" diaginertia="0.024378 0.0018187 0.0205574"/>
          <joint name="femur_joint_LR" class="/" pos="0 0 0" axis="-0.0339077 0.000265052 0.999425" stiffness="0.00306721" range="-3.08668 3.2051" armature="0.00606384" damping="0.0217535" frictionloss="0.012536"/>
          <geom name="//unnamed_geom_34" class="/" type="mesh" rgba="0.9 0.9 0.9 1" mesh="femur"/>
          <geom name="//unnamed_geom_35" class="reward_collision_sphere" size="0.0410938"/>
          <body name="tibia_LR" pos="-0.000607429 -0.0750554 0.00267209" quat="-2.68726e-06 0.999999 0.000736311 0.000956024">
            <inertial pos="-0.000223691 0.00608367 -0.00105993" quat="0.999994 0.00345455 -0.000125453 0.000198293" mass="0.233815" diaginertia="0.0261981 0.00200542 0.0235752"/>
            <joint name="tibia_joint_LR" class="/" pos="0 0 0" axis="0.00802086 0.0267306 -0.99961" stiffness="0.0268771" range="-3.14433 3.24426" armature="0.0101424" damping="0.0264719" frictionloss="0.00895526"/>
            <geom name="//unnamed_geom_36" class="/" type="mesh" rgba="0.2 0.2 0.2 1" mesh="tibia"/>
            <geom name="//unnamed_geom_37" class="reward_collision_sphere" size="0.0410938"/>
            <body name="tarsus_LR" pos="0.0979547 0.0056288 0.00171814" quat="0.999999 0.000863053 -0.000420858 0.00064527">
              <inertial pos="0.0712184 0.000275723 0.00346865" quat="0.50574 0.493741 0.500901 0.499545" mass="0.221498" diaginertia="0.0251304 0.0019207 0.0214525"/>
              <joint name="tarsus_joint_LR" class="/" pos="0 0 0" axis="-0.0157888 -0.0144765 -0.999771" stiffness="0.00853954" range="-3.07119 3.10207" armature="0.0125937" damping="0.0328868" frictionloss="0.00944997"/>
              <geom name="//unnamed_geom_38" class="/" type="mesh" rgba="0.9 0.9 0.9 1" mesh="tarsus"/>
              <geom name="foot_4" class="foot" size="0.0103774" pos="0.134349 0 0" quat="0.707107 0 -0.707107 0"/>
              <geom name="//unnamed_geom_40" class="reward_collision_sphere" size="0.0410938"/>
              <geom name="//unnamed_geom_41" class="reward_collision_sphere" size="0.0154102" pos="0.128951 0 0"/>
              <site name="foot_4" class="foot" pos="0.134349 0 0" quat="0.707107 0 -0.707107 0" size="0.0102735"/>
            </body>
          </body>
        </body>
      </body>
      <body name="coxa_LM" pos="-0.00656633 0.096339 0.0731434" quat="0.706967 0.000246587 -0.000410801 0.707246">
        <inertial pos="-0.0017462 0.000989307 0.000831247" quat="0.999992 0.0012124 0.00316033 0.00200437" mass="0.223141" diaginertia="0.0229664 0.00191639 0.0209042"/>
        <joint name="coxa_joint_LM" class="/" pos="0 0 0" axis="-0.0223838 0.0157699 -0.999625" range="-3.14059 2.99516" armature="0.0104539" damping="0.0199877" frictionloss="0.0100313"/>
        <geom name="//unnamed_geom_42" class="/" type="mesh" rgba="0.2 0.2 0.2 1" mesh="coxa"/>
        <geom name="//unnamed_geom_43" class="reward_collision_sphere" size="0.0410938" pos="-0.0359864 0 0"/>
        <body name="femur_LM" pos="0.0628491 0.00244753 0.00160519" quat="0.499194 -0.499962 0.498895 0.501944">
          <inertial pos="-0.00308944 -0.00248909 0.00249195" quat="0.999989 0.00309626 -0.00358168 -0.000257005" mass="0.190751" diaginertia="0.0230875 0.00185811 0.0191201"/>
          <joint name="femur_joint_LM" class="/" pos="0 0 0" axis="-0.00700389 0.0157171 0.999852" range="-3.02341 3.25303" armature="0.0107327" damping="0" frictionloss="0.00895942"/>
          <geom name="//unnamed_geom_44" class="/" type="mesh" rgba="0.9 0.9 0.9 1" mesh="femur"/>
          <geom name="//unnamed_geom_45" class="reward_collision_sphere" size="0.0410938"/>
          <body name="tibia_LM" pos="-0.00144404 -0.0782837 0.00268451" quat="-0.000157264 1 -0.000266013 0.000649149">
            <inertial pos="-0.00248288 -0.000879609 0.00135038" quat="0.999995 8.93913e-05 0.00260928 0.00198893" mass="0.213538" diaginertia="0.024177 0.00209988 0.0202567"/>
            <joint name="tibia_joint_LM" class="/" pos="0 0 0" axis="-0.0116116 -0.00340011 -0.999927" stiffness="0.0392939" range="-3.16894 3.15061" armature="0.0131391" damping="0.0329986" frictionloss="0.00963739"/>
            <geom name="//unnamed_geom_46" class="/" type="mesh" rgba="0.2 0.2 0.2 1" mesh="tibia"/>
            <geom name="//unnamed_geom_47" class="reward_collision_sphere" size="0.0410938"/>
            <body name="tarsus_LM" pos="0.10022 -0.0003336 0.00116802" quat="1 0.000201896 0.000108246 -0.000204723">
              <inertial pos="0.0712828 -0.000446429 -0.00395023" quat="0.499582 0.501932 0.500407 0.498072" mass="0.217258" diaginertia="0.0269946 0.00186582 0.0209877"/>
              <joint name="tarsus_joint_LM" class="/" pos="0 0 0" axis="-0.0144917 -0.00913544 -0.999853" stiffness="0.0153156" range="-3.16249 3.17578" armature="0.00923882" damping="0" frictionloss="0.0103391"/>
              <geom name="//unnamed_geom_48" class="/" type="mesh" rgba="0.9 0.9 0.9 1" mesh="tarsus"/>
              <geom name="foot_5" class="foot" size="0.0132696" pos="0.134349 0 0" quat="0.707107 0 -0.707107 0"/>
              <geom name="//unnamed_geom_50" class="reward_collision_sphere" size="0.0410938"/>
              <geom name="//unnamed_geom_51" class="reward_collision_sphere" size="0.0154102" pos="0.128951 0 0"/>
              <site name="foot_5" class="foot" pos="0.134349 0 0" quat="0.707107 0 -0.707107 0" size="0.0102735"/>
            </body>
          </body>
        </body>
      </body>
      <body name="coxa_LF" pos="0.207032 0.0616214 0.0781013" quat="0.923145 -0.000249906 -0.00232931 0.384445">
        <inertial pos="0.000521137 0.00134443 -0.00372992" quat="0.999971 0.00358966 -0.00180836 -0.00649797" mass="0.214876" diaginertia="0.0241465 0.00215826 0.0211489"/>
        <joint name="coxa_joint_LF" class="/" pos="0 0 0" axis="0.0130314 -0.0171831 -0.999767" range="-3.09552 3.18593" armature="0.0113265" damping="0.0218151" frictionloss="0.0124108"/>
        <geom name="//unnamed_geom_52" class="/" type="mesh" rgba="0.2 0.2 0.2 1" mesh="coxa"/>
        <geom name="//unnamed_geom_53" class="reward_collision_sphere" size="0.0410938" pos="-0.0359864 0 0"/>
        <body name="femur_LF" pos="0.0670143 0.00432055 0.0017457" quat="0.499905 -0.500038 0.500029 0.500028">
          <inertial pos="-0.000567423 0.00118894 -0.00583183" quat="0.999919 0.00401294 -0.0062575 0.0103152" mass="0.195912" diaginertia="0.0261235 0.00193574 0.0209947"/>
          <joint name="femur_joint_LF" class="/" pos="0 0 0" axis="0.0134694 0.00989449 0.99986" range="-3.09255 3.15121" armature="0.0100314" damping="0.0123094" frictionloss="0.00771381"/>
          <geom name="//unnamed_geom_54" class="/" type="mesh" rgba="0.9 0.9 0.9 1" mesh="femur"/>
          <geom name="//unnamed_geom_55" class="reward_collision_sphere" size="0.0410938"/>
          <body name="tibia_LF" pos="-0.00203947 -0.086629 -0.00431715" quat="-0.000477913 0.999995 0.00279142 -0.00159">
            <inertial pos="0.00222022 -0.00337009 0.00388239" quat="0.999516 0.00907087 0.0198053 -0.0221992" mass="0.200048" diaginertia="0.0237368 0.00193943 0.0209032"/>
            <joint name="tibia_joint_LF" class="/" pos="0 0 0" axis="-0.00183721 -0.000941632 -0.999998" stiffness="0.0226036" range="-3.29793 3.13572" armature="0.00912649" damping="0" frictionloss="0.0101813"/>
            <geom name="//unnamed_geom_56" class="/" type="mesh" rgba="0.2 0.2 0.2 1" mesh="tibia"/>
            <geom name="//unnamed_geom_57" class="reward_collision_sphere" size="0.0410938"/>
            <body name="tarsus_LF" pos="0.0983911 -0.00401123 -0.000799636" quat="1 0.000224509 -9.45174e-05 0.00021871">
              <inertial pos="0.0787361 -0.000369139 0.000551721" quat="0.497949 0.501183 0.499546 0.501315" mass="0.22878" diaginertia="0.0260311 0.00207749 0.0200507"/>
              <joint name="tarsus_joint_LF" class="/" pos="0 0 0" axis="0.021408 0.0113509 -0.999706" stiffness="0.0221225" range="-3.13162 3.2214" armature="0.00738462" damping="0.0148299" frictionloss="0.00641218"/>
              <geom name="//unnamed_geom_58" class="/" type="mesh" rgba="0.9 0.9 0.9 1" mesh="tarsus"/>
              <geom name="foot_6" class="foot" size="0.0110063" pos="0.134349 0 0" quat="0.707107 0 -0.707107 0"/>
              <geom name="//unnamed_geom_60" class="reward_collision_sphere" size="0.0410938"/>
              <geom name="//unnamed_geom_61" class="reward_collision_sphere" size="0.0154102" pos="0.128951 0 0"/>
              <site name="foot_6" class="foot" pos="0.134349 0 0" quat="0.707107 0 -0.707107 0" size="0.0102735"/>
            </body>
          </body>
        </body>
      </body>
    </body>
  </worldbody>

  <contact>
    <pair class="/" geom1="floor" geom2="foot_1" name="//unnamed_contact_0"/>
    <pair class="/" geom1="floor" geom2="foot_2" name="//unnamed_contact_1"/>
    <pair class="/" geom1="floor" geom2="foot_3" name="//unnamed_contact_2"/>
    <pair class="/" geom1="floor" geom2="foot_4" name="//unnamed_contact_3"/>
    <pair class="/" geom1="floor" geom2="foot_5" name="//unnamed_contact_4"/>
    <pair class="/" geom1="floor" geom2="foot_6" name="//unnamed_contact_5"/>
  </contact>

  <actuator>
    <general name="coxa_joint_RR" class="/" joint="coxa_joint_RR" forcerange="-6.98803 6.98803" gainprm="25.7633" biasprm="0 -25.7633 -0.527264"/>
    <general name="femur_joint_RR" class="/" joint="femur_joint_RR" forcerange="-6.63142 6.63142" gainprm="25.7633" biasprm="0 -25.7633 -0.527264"/>
    <general name="tibia_joint_RR" class="/" joint="tibia_joint_RR" forcerange="-8.46969 8.46969" gainprm="25.7633" biasprm="0 -25.7633 -0.527264"/>
    <general name="tarsus_joint_RR" class="/" joint="tarsus_joint_RR" forcerange="-8.66509 8.66509" gainprm="25.7633" biasprm="0 -25.7633 -0.527264"/>
    <general name="coxa_joint_RM" class="/" joint="coxa_joint_RM" forcerange="-9.13002 9.13002" gainprm="25.7633" biasprm="0 -25.7633 -0.527264"/>
    <general name="femur_joint_RM" class="/" joint="femur_joint_RM" forcerange="-8.11266 8.11266" gainprm="25.7633" biasprm="0 -25.7633 -0.527264"/>
    <general name="tibia_joint_RM" class="/" joint="tibia_joint_RM" forcerange="-7.35959 7.35959" gainprm="25.7633" biasprm="0 -25.7633 -0.527264"/>
    <general name="tarsus_joint_RM" class="/" joint="tarsus_joint_RM" forcerange="-7.01735 7.01735" gainprm="25.7633" biasprm="0 -25.7633 -0.527264"/>
    <general name="coxa_joint_RF" class="/" joint="coxa_joint_RF" forcerange="-8.1051 8.1051" gainprm="25.7633" biasprm="0 -25.7633 -0.527264"/>
    <general name="femur_joint_RF" class="/" joint="femur_joint_RF" forcerange="-5.3129 5.3129" gainprm="25.7633" biasprm="0 -25.7633 -0.527264"/>
    <general name="tibia_joint_RF" class="/" joint="tibia_joint_RF" forcerange="-5.78346 5.78346" gainprm="25.7633" biasprm="0 -25.7633 -0.527264"/>
    <general name="tarsus_joint_RF" class="/" joint="tarsus_joint_RF" forcerange="-5.9957 5.9957" gainprm="25.7633" biasprm="0 -25.7633 -0.527264"/>
    <general name="coxa_joint_LR" class="/" joint="coxa_joint_LR" forcerange="-7.30419 7.30419" gainprm="25.7633" biasprm="0 -25.7633 -0.527264"/>
    <general name="femur_joint_LR" class="/" joint="femur_joint_LR" forcerange="-7.68214 7.68214" gainprm="25.7633" biasprm="0 -25.7633 -0.527264"/>
    <general name="tibia_joint_LR" class="/" joint="tibia_joint_LR" forcerange="-5.42617 5.42617" gainprm="25.7633" biasprm="0 -25.7633 -0.527264"/>
    <general name="tarsus_joint_LR" class="/" joint="tarsus_joint_LR" forcerange="-5.78383 5.78383" gainprm="25.7633" biasprm="0 -25.7633 -0.527264"/>
    <general name="coxa_joint_LM" class="/" joint="coxa_joint_LM" forcerange="-8.00322 8.00322" gainprm="25.7633" biasprm="0 -25.7633 -0.527264"/>
    <general name="femur_joint_LM" class="/" joint="femur_joint_LM" forcerange="-6.87285 6.87285" gainprm="25.7633" biasprm="0 -25.7633 -0.527264"/>
    <general name="tibia_joint_LM" class="/" joint="tibia_joint_LM" forcerange="-7.51432 7.51432" gainprm="25.7633" biasprm="0 -25.7633 -0.527264"/>
    <general name="tarsus_joint_LM" class="/" joint="tarsus_joint_LM" forcerange="-7.36637 7.36637" gainprm="25.7633" biasprm="0 -25.7633 -0.527264"/>
    <general name="coxa_joint_LF" class="/" joint="coxa_joint_LF" forcerange="-7.66206 7.66206" gainprm="25.7633" biasprm="0 -25.7633 -0.527264"/>
    <general name="femur_joint_LF" class="/" joint="femur_joint_LF" forcerange="-6.07512 6.07512" gainprm="25.7633" biasprm="0 -25.7633 -0.527264"/>
    <general name="tibia_joint_LF" class="/" joint="tibia_joint_LF" forcerange="-6.27248 6.27248" gainprm="25.7633" biasprm="0 -25.7633 -0.527264"/>
    <general name="tarsus_joint_LF" class="/" joint="tarsus_joint_LF" forcerange="-8.10989 8.10989" gainprm="25.7633" biasprm="0 -25.7633 -0.527264"/>
  </actuator>

  <sensor>
    <gyro site="imu" name="imu_angular_velocity"/>
    <velocimeter site="imu" name="imu_linear_velocity"/>
    <framelinvel objtype="site" objname="foot_1" name="foot_1_global_linear_velocity"/>
    <framelinvel objtype="site" objname="foot_2" name="foot_2_global_linear_velocity"/>
    <framelinvel objtype="site" objname="foot_3" name="foot_3_global_linear_velocity"/>
    <framelinvel objtype="site" objname="foot_4" name="foot_4_global_linear_velocity"/>
    <framelinvel objtype="site" objname="foot_5" name="foot_5_global_linear_velocity"/>
    <framelinvel objtype="site" objname="foot_6" name="foot_6_global_linear_velocity"/>
  </sensor>

  <keyframe>
    <key name="home" qpos="0 0 0.1457 1 0 0 0 0 0 0 0 0 0 0 0 0 0 0 0 0 0 0 0 0 0 0 0 0 0 0 0"/>
  </keyframe>
</mujoco>
