<mujoco model="Golem">
  <compiler angle="radian" assetdir="assets" balanceinertia="true" inertiafromgeom="false"/>

  <option timestep="0.005" density="1.2" viscosity="2e-05"/>

  <size nkey="1"/>

  <visual>
    <quality shadowsize="8192"/>
    <map shadowclip="0.5"/>
  </visual>

  <default>
    <default class="/">
      <joint armature="0.01" damping="0.01" frictionloss="0.01"/>
      <geom contype="0" conaffinity="0" group="1" solref="-1000 -80"/>
      <site size="0.01 0.005 0.005" group="5"/>
      <general forcelimited="true" biastype="affine" gainprm="25" biasprm="0 -25 -0.5"/>
      <default class="visual">
        <geom type="mesh" group="2"/>
      </default>
      <default class="collision">
        <geom group="3"/>
      </default>
      <default class="foot">
        <geom size="0.01 0 0" condim="6" group="4" priority="1" solimp="0.015 1 0.01"/>
      </default>
      <default class="reward_collision_sphere">
        <geom group="5" rgba="1 0 0 1"/>
      </default>
    </default>
  </default>

  <asset>
    <texture type="skybox" colorspace="auto" name="//unnamed_texture_0" builtin="gradient" rgb1="0.95 0.95 0.95" rgb2="0.95 0.95 0.95" width="100" height="600"/>
    <texture type="2d" colorspace="auto" name="texplane" builtin="checker" rgb1="0.345 0.575 0.748" rgb2="0.345 0.575 0.748" markrgb="1 1 1" width="512" height="512"/>
    <material name="MatPlane" class="/" texture="texplane" texuniform="true" texrepeat="2 2" specular="0.9"/>
    <mesh name="body" class="/" file="body.stl" scale="0.001 0.001 0.001"/>
    <mesh name="coxa" class="/" file="coxa.stl" scale="0.001 0.001 0.001"/>
    <mesh name="femur" class="/" file="femur.stl" scale="0.001 0.001 0.001"/>
    <mesh name="tibia" class="/" file="tibia.stl" scale="0.001 0.001 0.001"/>
    <mesh name="tarsus" class="/" file="tarsus.stl" scale="0.001 0.001 0.001"/>
  </asset>

  <worldbody>
    <geom name="floor" class="/" size="100 100 0.125" type="plane" group="0" material="MatPlane"/>
    <light name="toplight_shadow" class="/" pos="0 0 5" dir="0.0990148 0.0990148 -0.990148" type="directional" ambient="0.04 0.04 0.04" diffuse="0.55 0.55 0.55" specular="0.12 0.12 0.12"/>
    <light name="toplight_fill" class="/" pos="0 0 5" dir="0.0990148 0.0990148 -0.990148" type="directional" castshadow="false" ambient="0.04 0.04 0.04" diffuse="0.3 0.3 0.3" specular="0.08 0.08 0.08"/>
    <body name="trunk" pos="0.000674919 0.000550561 -0.00239385" quat="1 -9.03614e-05 -5.79711e-05 0.000114049">
      <inertial pos="8.57327e-05 -0.000103204 -0.00214468" quat="0.99999 -0.00194855 0.00133939 -0.00379761" mass="3.33077" diaginertia="0.00773572 0.00299296 0.0191"/>
      <joint name="//unnamed_joint_0" type="free"/>
      <geom name="//unnamed_geom_1" class="/" pos="0 0 0.0729199" quat="1 0 0 0" type="mesh" rgba="0.9 0.9 0.9 1" mesh="body"/>
      <site name="imu" class="/" pos="0.126872 -0.00242775 0.109227" size="0.00958983"/>
      <camera name="track" class="/" pos="0 -1.56575 0" quat="0.707107 0.707107 0 0" mode="trackcom"/>
      <camera name="ego_camera" class="/" pos="0.124111 0 0.113937" quat="-0.5 -0.5 0.5 0.5"/>
      <body name="coxa_RR" pos="-0.170685 -0.0656803 0.0724915" quat="0.382664 1.91903e-05 1.05643e-05 -0.923887">
        <inertial pos="0.00018412 -0.00228985 0.000974021" quat="0.999997 -0.00174126 -0.00067167 -0.00167375" mass="0.170923" diaginertia="0.00761152 0.00291464 0.018346"/>
        <joint name="coxa_joint_RR" class="/" pos="0 0 0" axis="-0.00627875 0.00459313 -0.99997" range="-3.13582 3.12802" armature="0.00965246" damping="0.0142395" frictionloss="0.00972247"/>
        <geom name="//unnamed_geom_2" class="/" type="mesh" rgba="0.2 0.2 0.2 1" mesh="coxa"/>
        <geom name="//unnamed_geom_3" class="reward_collision_sphere" size="0.0383593" pos="-0.0286411 0 0"/>
        <body name="femur_RR" pos="0.0581585 -0.000701968 0.000338659" quat="0.499793 -0.500056 0.499986 0.500164">
          <inertial pos="0.000849516 -0.000229571 0.000328183" quat="0.999999 2.14273e-05 0.00141984 -0.00025393" mass="0.175766" diaginertia="0.00789546 0.00290914 0.0190752"/>
          <joint name="femur_joint_RR" class="/" pos="0 0 0" axis="0.000955863 -0.00122837 -0.999999" range="-3.15638 3.09701" armature="0.00928647" damping="0" frictionloss="0.00997547"/>
          <geom name="//unnamed_geom_4" class="/" type="mesh" rgba="0.9 0.9 0.9 1" mesh="femur"/>
          <geom name="//unnamed_geom_5" class="reward_collision_sphere" size="0.0383593"/>
          <body name="tibia_RR" pos="0.00112111 -0.083567 0.00190569" quat="-0.000193501 1 -2.54993e-05 -0.000118708">
            <inertial pos="-0.00166294 -6.9066e-05 -8.5628e-05" quat="0.999985 -0.00153567 -0.00190221 -0.00490999" mass="0.176042" diaginertia="0.00783688 0.00293159 0.0192246"/>
            <joint name="tibia_joint_RR" class="/" pos="0 0 0" axis="0.00395839 0.000154542 0.999992" range="-3.18561 3.15778" armature="0.00915411" damping="0" frictionloss="0.00981285"/>
            <geom name="//unnamed_geom_6" class="/" type="mesh" rgba="0.2 0.2 0.2 1" mesh="tibia"/>
            <geom name="//unnamed_geom_7" class="reward_collision_sphere" size="0.0383593"/>
            <body name="tarsus_RR" pos="0.0821683 0.00135338 0.00032641" quat="1 -0.000400016 -0.000222799 -2.62427e-05">
              <inertial pos="0.0561326 0.00240465 -0.00085361" quat="0.503435 0.496438 0.500646 0.499455" mass="0.175252" diaginertia="0.00792527 0.00291916 0.019207"/>
              <joint name="tarsus_joint_RR" class="/" pos="0 0 0" axis="0.000473364 -0.000492003 1" range="-3.13652 3.13487" armature="0.0101146" damping="0.00803335" frictionloss="0.0102108"/>
              <geom name="//unnamed_geom_8" class="/" type="mesh" rgba="0.9 0.9 0.9 1" mesh="tarsus"/>
              <geom name="foot_1" class="foot" size="0.00923212" pos="0.106927 0 0" quat="0 -0.707107 0 0.707107"/>
              <geom name="//unnamed_geom_10" class="reward_collision_sphere" size="0.0383593"/>
              <geom name="//unnamed_geom_11" class="reward_collision_sphere" size="0.0143847" pos="0.10263 0 0"/>
              <site name="foot_1" class="foot" pos="0.106927 0 0" quat="0 -0.707107 0 0.707107" size="0.00958983"/>
            </body>
          </body>
        </body>
      </body>
      <body name="coxa_RM" pos="-0.000339734 -0.104641 0.070857" quat="0.706708 -0.000440786 -0.00105106 -0.707504">
        <inertial pos="-0.00168734 0.000254058 0.00109952" quat="1 0.000228239 -8.99702e-06 -0.000620103" mass="0.173841" diaginertia="0.00771902 0.00288554 0.0194881"/>
        <joint name="coxa_joint_RM" class="/" pos="0 0 0" axis="-5.04206e-05 0.000429232 -1" range="-3.18949 3.14285" armature="0.0101904" damping="0.0118969" frictionloss="0.00952537"/>
        <geom name="//unnamed_geom_12" class="/" type="mesh" rgba="0.2 0.2 0.2 1" mesh="coxa"/>
        <geom name="//unnamed_geom_13" class="reward_collision_sphere" size="0.0383593" pos="-0.0286411 0 0"/>
        <body name="femur_RM" pos="0.0546542 0.000568941 -0.000302249" quat="0.500162 -0.500439 0.49919 0.500208">
          <inertial pos="-0.000672671 0.000820302 -0.000875553" quat="0.999956 0.006567 0.00382311 -0.0055578" mass="0.17971" diaginertia="0.0080824 0.00294556 0.0194041"/>
          <joint name="femur_joint_RM" class="/" pos="0 0 0" axis="-0.00200284 -0.00130628 -0.999997" range="-3.13802 3.14223" armature="0.00970429" damping="0.0101626" frictionloss="0.0100429"/>
          <geom name="//unnamed_geom_14" class="/" type="mesh" rgba="0.9 0.9 0.9 1" mesh="femur"/>
          <geom name="//unnamed_geom_15" class="reward_collision_sphere" size="0.0383593"/>
          <body name="tibia_RM" pos="-0.000367477 -0.0834565 0.00143055" quat="-8.64842e-05 1 -4.28418e-05 -3.78148e-06">
            <inertial pos="0.00127651 0.0018452 0.000345523" quat="0.999995 0.00287687 -0.000188464 0.00154206" mass="0.181863" diaginertia="0.008181 0.00302272 0.0197276"/>
            <joint name="tibia_joint_RM" class="/" pos="0 0 0" axis="4.94753e-05 -0.000651162 1" range="-3.12628 3.08783" armature="0.0093966" damping="0" frictionloss="0.00983334"/>
            <geom name="//unnamed_geom_16" class="/" type="mesh" rgba="0.2 0.2 0.2 1" mesh="tibia"/>
            <geom name="//unnamed_geom_17" class="reward_collision_sphere" size="0.0383593"/>
            <body name="tarsus_RM" pos="0.0813824 -0.00226822 0.000211411" quat="1 1.95112e-05 -7.61183e-05 -0.000453749">
              <inertial pos="0.0564569 0.00287455 -0.000894318" quat="0.500168 0.500649 0.499319 0.499864" mass="0.169006" diaginertia="0.00787217 0.00288778 0.0191191"/>
              <joint name="tarsus_joint_RM" class="/" pos="0 0 0" axis="-0.00107572 -3.68464e-05 0.999999" range="-3.13743 3.14739" armature="0.00958715" damping="0.00422887" frictionloss="0.00951827"/>
              <geom name="//unnamed_geom_18" class="/" type="mesh" rgba="0.9 0.9 0.9 1" mesh="tarsus"/>
              <geom name="foot_2" class="foot" size="0.00930325" pos="0.106927 0 0" quat="0 -0.707107 0 0.707107"/>
              <geom name="//unnamed_geom_20" class="reward_collision_sphere" size="0.0383593"/>
              <geom name="//unnamed_geom_21" class="reward_collision_sphere" size="0.0143847" pos="0.10263 0 0"/>
              <site name="foot_2" class="foot" pos="0.106927 0 0" quat="0 -0.707107 0 0.707107" size="0.00958983"/>
            </body>
          </body>
        </body>
      </body>
      <body name="coxa_RF" pos="0.170772 -0.0644947 0.0723721" quat="0.92392 0.000339377 -9.24082e-05 -0.382585">
        <inertial pos="-0.00195186 -0.000871297 0.0017733" quat="1 0.000310421 6.13329e-05 0.000221176" mass="0.179679" diaginertia="0.00814502 0.0029376 0.0196795"/>
        <joint name="coxa_joint_RF" class="/" pos="0 0 0" axis="-0.00297163 0.00172803 -0.999994" range="-3.14064 3.1366" armature="0.00888703" damping="0.0045333" frictionloss="0.00971678"/>
        <geom name="//unnamed_geom_22" class="/" type="mesh" rgba="0.2 0.2 0.2 1" mesh="coxa"/>
        <geom name="//unnamed_geom_23" class="reward_collision_sphere" size="0.0383593" pos="-0.0286411 0 0"/>
        <body name="femur_RF" pos="0.0586757 -0.00140227 -0.000455671" quat="0.500803 -0.499453 0.499817 0.499925">
          <inertial pos="-1.5521e-05 0.000554337 0.000364253" quat="0.999999 -0.000135296 0.000436862 0.00109457" mass="0.167163" diaginertia="0.00790001 0.00288458 0.0185979"/>
          <joint name="femur_joint_RF" class="/" pos="0 0 0" axis="0.00211165 0.000466478 -0.999998" range="-3.15863 3.0931" armature="0.00845896" damping="0.0033008" frictionloss="0.00839338"/>
          <geom name="//unnamed_geom_24" class="/" type="mesh" rgba="0.9 0.9 0.9 1" mesh="femur"/>
          <geom name="//unnamed_geom_25" class="reward_collision_sphere" size="0.0383593"/>
          <body name="tibia_RF" pos="-0.000986433 -0.0822282 0.00215727" quat="0.000132534 1 8.29338e-06 0.000120095">
            <inertial pos="-0.00205714 0.000621476 -9.9328e-06" quat="0.999997 -0.00172119 0.00101426 -0.00153852" mass="0.176605" diaginertia="0.00776375 0.00292933 0.0191309"/>
            <joint name="tibia_joint_RF" class="/" pos="0 0 0" axis="0.000628375 0.00101451 0.999999" range="-3.1343 3.14785" armature="0.00941227" damping="0" frictionloss="0.00959922"/>
            <geom name="//unnamed_geom_26" class="/" type="mesh" rgba="0.2 0.2 0.2 1" mesh="tibia"/>
            <geom name="//unnamed_geom_27" class="reward_collision_sphere" size="0.0383593"/>
            <body name="tarsus_RF" pos="0.0821707 -0.00156496 -0.0016851" quat="1 0.000147172 -0.000359644 -8.4975e-05">
              <inertial pos="0.0555124 0.000128431 -0.000422954" quat="0.491619 0.505521 0.506763 0.495933" mass="0.176081" diaginertia="0.0079794 0.00298642 0.0187297"/>
              <joint name="tarsus_joint_RF" class="/" pos="0 0 0" axis="-0.00118376 0.000592319 0.999999" stiffness="0.000326341" range="-3.12373 3.14154" armature="0.00844622" damping="0.00237847" frictionloss="0.00873608"/>
              <geom name="//unnamed_geom_28" class="/" type="mesh" rgba="0.9 0.9 0.9 1" mesh="tarsus"/>
              <geom name="foot_3" class="foot" size="0.00923981" pos="0.106927 0 0" quat="0 -0.707107 0 0.707107"/>
              <geom name="//unnamed_geom_30" class="reward_collision_sphere" size="0.0383593"/>
              <geom name="//unnamed_geom_31" class="reward_collision_sphere" size="0.0143847" pos="0.10263 0 0"/>
              <site name="foot_3" class="foot" pos="0.106927 0 0" quat="0 -0.707107 0 0.707107" size="0.00958983"/>
            </body>
          </body>
        </body>
      </body>
      <body name="coxa_LR" pos="-0.169345 0.0678754 0.0714975" quat="0.38288 -5.39906e-06 2.67735e-05 0.923798">
        <inertial pos="-0.000843703 -0.000241412 -8.63283e-05" quat="0.999932 0.00876667 -0.00629722 0.00450299" mass="0.17829" diaginertia="0.00790666 0.00298922 0.0191748"/>
        <joint name="coxa_joint_LR" class="/" pos="0 0 0" axis="3.87061e-05 -2.51521e-05 -1" range="-3.13683 3.12703" armature="0.0102578" damping="0.0141119" frictionloss="0.00910301"/>
        <geom name="//unnamed_geom_32" class="/" type="mesh" rgba="0.2 0.2 0.2 1" mesh="coxa"/>
        <geom name="//unnamed_geom_33" class="reward_collision_sphere" size="0.0383593" pos="-0.0286411 0 0"/>
        <body name="femur_LR" pos="0.055977 -0.000693903 0.000814877" quat="0.499963 -0.499979 0.49977 0.500288">
          <inertial pos="-0.00185964 -0.00236191 0.00206733" quat="1 -3.61327e-05 -5.53161e-05 -7.82361e-05" mass="0.180543" diaginertia="0.00786368 0.00300182 0.0193709"/>
          <joint name="femur_joint_LR" class="/" pos="0 0 0" axis="0.0066143 -0.0109192 0.999919" range="-3.15623 3.11609" armature="0.010805" damping="0.000129622" frictionloss="0.00877568"/>
          <geom name="//unnamed_geom_34" class="/" type="mesh" rgba="0.9 0.9 0.9 1" mesh="femur"/>
          <geom name="//unnamed_geom_35" class="reward_collision_sphere" size="0.0383593"/>
          <body name="tibia_LR" pos="0.00142256 -0.0874815 -0.000761645" quat="-7.89401e-05 1 0.000135268 0.000229851">
            <inertial pos="-0.000146128 -0.00214466 8.46789e-06" quat="0.999998 -0.000303248 0.00182207 -4.01354e-05" mass="0.171843" diaginertia="0.00782986 0.00290226 0.0184236"/>
            <joint name="tibia_joint_LR" class="/" pos="0 0 0" axis="-0.00925468 0.000200283 -0.999957" range="-3.13978 3.09848" armature="0.00947473" damping="0" frictionloss="0.00995147"/>
            <geom name="//unnamed_geom_36" class="/" type="mesh" rgba="0.2 0.2 0.2 1" mesh="tibia"/>
            <geom name="//unnamed_geom_37" class="reward_collision_sphere" size="0.0383593"/>
            <body name="tarsus_LR" pos="0.0873057 -0.000687387 0.000155027" quat="1 3.86125e-06 0.000255037 -0.000112715">
              <inertial pos="0.0588703 -0.000277407 -0.00111328" quat="0.501893 0.499894 0.499293 0.498914" mass="0.175164" diaginertia="0.0079255 0.00293898 0.01897"/>
              <joint name="tarsus_joint_LR" class="/" pos="0 0 0" axis="0.000845213 -0.00193422 -0.999998" range="-3.16606 3.13365" armature="0.00881349" damping="0.0273615" frictionloss="0.00940078"/>
              <geom name="//unnamed_geom_38" class="/" type="mesh" rgba="0.9 0.9 0.9 1" mesh="tarsus"/>
              <geom name="foot_4" class="foot" size="0.00978471" pos="0.106927 0 0" quat="0.707107 0 -0.707107 0"/>
              <geom name="//unnamed_geom_40" class="reward_collision_sphere" size="0.0383593"/>
              <geom name="//unnamed_geom_41" class="reward_collision_sphere" size="0.0143847" pos="0.10263 0 0"/>
              <site name="foot_4" class="foot" pos="0.106927 0 0" quat="0.707107 0 -0.707107 0" size="0.00958983"/>
            </body>
          </body>
        </body>
      </body>
      <body name="coxa_LM" pos="0.00188529 0.102481 0.0735651" quat="0.707057 -4.53512e-05 0.000163 0.707157">
        <inertial pos="0.00074984 -0.00110717 -0.000417748" quat="0.999999 -0.000675532 -0.000569113 0.00129843" mass="0.171438" diaginertia="0.00803189 0.00294585 0.0188339"/>
        <joint name="coxa_joint_LM" class="/" pos="0 0 0" axis="-0.00951873 0.00257735 -0.999951" range="-3.15328 3.18869" armature="0.00956116" damping="0.00964413" frictionloss="0.00973799"/>
        <geom name="//unnamed_geom_42" class="/" type="mesh" rgba="0.2 0.2 0.2 1" mesh="coxa"/>
        <geom name="//unnamed_geom_43" class="reward_collision_sphere" size="0.0383593" pos="-0.0286411 0 0"/>
        <body name="femur_LM" pos="0.0563408 0.000736337 -0.00328451" quat="0.499285 -0.499934 0.500133 0.500647">
          <inertial pos="0.00106632 -6.61013e-05 -0.000780173" quat="1 0.000336351 0.000265007 6.35586e-05" mass="0.184624" diaginertia="0.0081424 0.00298777 0.0198727"/>
          <joint name="femur_joint_LM" class="/" pos="0 0 0" axis="-0.00333532 -0.00229893 0.999992" stiffness="0.00927496" range="-3.18419 3.09609" armature="0.00913041" damping="0" frictionloss="0.00994966"/>
          <geom name="//unnamed_geom_44" class="/" type="mesh" rgba="0.9 0.9 0.9 1" mesh="femur"/>
          <geom name="//unnamed_geom_45" class="reward_collision_sphere" size="0.0383593"/>
          <body name="tibia_LM" pos="0.00188038 -0.081389 -0.000183403" quat="-0.000182561 1 -4.37007e-05 -0.000514334">
            <inertial pos="0.000718796 -0.00147675 0.000281541" quat="0.999988 -0.00337996 -0.00343988 0.000796064" mass="0.174739" diaginertia="0.00796545 0.00285297 0.0192557"/>
            <joint name="tibia_joint_LM" class="/" pos="0 0 0" axis="0.00142285 -0.00195374 -0.999997" range="-3.1465 3.13963" armature="0.00862836" damping="0" frictionloss="0.00952577"/>
            <geom name="//unnamed_geom_46" class="/" type="mesh" rgba="0.2 0.2 0.2 1" mesh="tibia"/>
            <geom name="//unnamed_geom_47" class="reward_collision_sphere" size="0.0383593"/>
            <body name="tarsus_LM" pos="0.0859657 -0.0004902 -0.000714705" quat="1 9.68266e-05 0.000220239 -0.000139087">
              <inertial pos="0.0578858 0.00030262 0.00149396" quat="0.500135 0.500935 0.498142 0.500783" mass="0.177593" diaginertia="0.00767848 0.00299187 0.0192569"/>
              <joint name="tarsus_joint_LM" class="/" pos="0 0 0" axis="0.000157449 0.000307811 -1" range="-3.11737 3.14622" armature="0.00937334" damping="0.00137646" frictionloss="0.00961581"/>
              <geom name="//unnamed_geom_48" class="/" type="mesh" rgba="0.9 0.9 0.9 1" mesh="tarsus"/>
              <geom name="foot_5" class="foot" size="0.00875347" pos="0.106927 0 0" quat="0.707107 0 -0.707107 0"/>
              <geom name="//unnamed_geom_50" class="reward_collision_sphere" size="0.0383593"/>
              <geom name="//unnamed_geom_51" class="reward_collision_sphere" size="0.0143847" pos="0.10263 0 0"/>
              <site name="foot_5" class="foot" pos="0.106927 0 0" quat="0.707107 0 -0.707107 0" size="0.00958983"/>
            </body>
          </body>
        </body>
      </body>
      <body name="coxa_LF" pos="0.172134 0.0650033 0.0723223" quat="0.924274 -0.000372895 0.000296783 0.38173">
        <inertial pos="0.000547733 -8.72851e-05 0.00160381" quat="0.999988 -0.00189272 0.00452799 -0.000129753" mass="0.178266" diaginertia="0.00805401 0.00287706 0.0193588"/>
        <joint name="coxa_joint_LF" class="/" pos="0 0 0" axis="0.00992822 0.00489901 -0.999939" range="-3.14978 3.14349" armature="0.00970828" damping="0.0073885" frictionloss="0.0088276"/>
        <geom name="//unnamed_geom_52" class="/" type="mesh" rgba="0.2 0.2 0.2 1" mesh="coxa"/>
        <geom name="//unnamed_geom_53" class="reward_collision_sphere" size="0.0383593" pos="-0.0286411 0 0"/>
        <body name="femur_LF" pos="0.0577261 0.000609592 -0.000305125" quat="0.49996 -0.500007 0.500283 0.49975">
          <inertial pos="-0.000145885 5.01967e-05 0.0021869" quat="0.999993 -0.00143912 -0.00282947 0.0019089" mass="0.182294" diaginertia="0.00781281 0.00297853 0.0192812"/>
          <joint name="femur_joint_LF" class="/" pos="0 0 0" axis="-0.000392582 0.00700342 0.999975" range="-3.13584 3.1383" armature="0.00977658" damping="0.00643232" frictionloss="0.0105152"/>
          <geom name="//unnamed_geom_54" class="/" type="mesh" rgba="0.9 0.9 0.9 1" mesh="femur"/>
          <geom name="//unnamed_geom_55" class="reward_collision_sphere" size="0.0383593"/>
          <body name="tibia_LF" pos="0.0006106 -0.0828017 0.00222505" quat="0.00107331 0.999999 -0.000156515 -0.000425728">
            <inertial pos="-0.000620444 0.00128455 -0.00194145" quat="0.999934 -0.00419555 -0.0009166 -0.0106994" mass="0.181647" diaginertia="0.007994 0.0029533 0.0192251"/>
            <joint name="tibia_joint_LF" class="/" pos="0 0 0" axis="-0.00191585 -0.00158665 -0.999997" range="-3.08894 3.12615" armature="0.00948377" damping="0.013401" frictionloss="0.00961486"/>
            <geom name="//unnamed_geom_56" class="/" type="mesh" rgba="0.2 0.2 0.2 1" mesh="tibia"/>
            <geom name="//unnamed_geom_57" class="reward_collision_sphere" size="0.0383593"/>
            <body name="tarsus_LF" pos="0.0858646 0.00209601 0.000549142" quat="1 0.000132428 -7.6518e-05 -0.000151795">
              <inertial pos="0.0552217 0.00109419 -0.000278479" quat="0.500421 0.49999 0.499996 0.499592" mass="0.174163" diaginertia="0.00786074 0.00289844 0.0194886"/>
              <joint name="tarsus_joint_LF" class="/" pos="0 0 0" axis="0.0105875 0.00251279 -0.999941" range="-3.13775 3.10738" armature="0.0106106" damping="0.00579577" frictionloss="0.0107992"/>
              <geom name="//unnamed_geom_58" class="/" type="mesh" rgba="0.9 0.9 0.9 1" mesh="tarsus"/>
              <geom name="foot_6" class="foot" size="0.00913892" pos="0.106927 0 0" quat="0.707107 0 -0.707107 0"/>
              <geom name="//unnamed_geom_60" class="reward_collision_sphere" size="0.0383593"/>
              <geom name="//unnamed_geom_61" class="reward_collision_sphere" size="0.0143847" pos="0.10263 0 0"/>
              <site name="foot_6" class="foot" pos="0.106927 0 0" quat="0.707107 0 -0.707107 0" size="0.00958983"/>
            </body>
          </body>
        </body>
      </body>
    </body>
  </worldbody>

  <contact>
    <pair class="/" geom1="floor" geom2="foot_1" name="//unnamed_contact_0"/>
    <pair class="/" geom1="floor" geom2="foot_2" name="//unnamed_contact_1"/>
    <pair class="/" geom1="floor" geom2="foot_3" name="//unnamed_contact_2"/>
    <pair class="/" geom1="floor" geom2="foot_4" name="//unnamed_contact_3"/>
    <pair class="/" geom1="floor" geom2="foot_5" name="//unnamed_contact_4"/>
    <pair class="/" geom1="floor" geom2="foot_6" name="//unnamed_contact_5"/>
  </contact>

  <actuator>
    <general name="coxa_joint_RR" class="/" joint="coxa_joint_RR" forcerange="-7.08227 7.08227" gainprm="23.213" biasprm="0 -23.213 -0.497478"/>
    <general name="femur_joint_RR" class="/" joint="femur_joint_RR" forcerange="-7.27733 7.27733" gainprm="23.213" biasprm="0 -23.213 -0.497478"/>
    <general name="tibia_joint_RR" class="/" joint="tibia_joint_RR" forcerange="-6.67631 6.67631" gainprm="23.213" biasprm="0 -23.213 -0.497478"/>
    <general name="tarsus_joint_RR" class="/" joint="tarsus_joint_RR" forcerange="-6.58727 6.58727" gainprm="23.213" biasprm="0 -23.213 -0.497478"/>
    <general name="coxa_joint_RM" class="/" joint="coxa_joint_RM" forcerange="-6.42336 6.42336" gainprm="23.213" biasprm="0 -23.213 -0.497478"/>
    <general name="femur_joint_RM" class="/" joint="femur_joint_RM" forcerange="-6.90659 6.90659" gainprm="23.213" biasprm="0 -23.213 -0.497478"/>
    <general name="tibia_joint_RM" class="/" joint="tibia_joint_RM" forcerange="-7.08042 7.08042" gainprm="23.213" biasprm="0 -23.213 -0.497478"/>
    <general name="tarsus_joint_RM" class="/" joint="tarsus_joint_RM" forcerange="-6.87834 6.87834" gainprm="23.213" biasprm="0 -23.213 -0.497478"/>
    <general name="coxa_joint_RF" class="/" joint="coxa_joint_RF" forcerange="-7.12526 7.12526" gainprm="23.213" biasprm="0 -23.213 -0.497478"/>
    <general name="femur_joint_RF" class="/" joint="femur_joint_RF" forcerange="-7.66922 7.66922" gainprm="23.213" biasprm="0 -23.213 -0.497478"/>
    <general name="tibia_joint_RF" class="/" joint="tibia_joint_RF" forcerange="-7.59895 7.59895" gainprm="23.213" biasprm="0 -23.213 -0.497478"/>
    <general name="tarsus_joint_RF" class="/" joint="tarsus_joint_RF" forcerange="-7.54011 7.54011" gainprm="23.213" biasprm="0 -23.213 -0.497478"/>
    <general name="coxa_joint_LR" class="/" joint="coxa_joint_LR" forcerange="-7.04697 7.04697" gainprm="23.213" biasprm="0 -23.213 -0.497478"/>
    <general name="femur_joint_LR" class="/" joint="femur_joint_LR" forcerange="-6.93505 6.93505" gainprm="23.213" biasprm="0 -23.213 -0.497478"/>
    <general name="tibia_joint_LR" class="/" joint="tibia_joint_LR" forcerange="-7.65963 7.65963" gainprm="23.213" biasprm="0 -23.213 -0.497478"/>
    <general name="tarsus_joint_LR" class="/" joint="tarsus_joint_LR" forcerange="-7.59685 7.59685" gainprm="23.213" biasprm="0 -23.213 -0.497478"/>
    <general name="coxa_joint_LM" class="/" joint="coxa_joint_LM" forcerange="-7.1316 7.1316" gainprm="23.213" biasprm="0 -23.213 -0.497478"/>
    <general name="femur_joint_LM" class="/" joint="femur_joint_LM" forcerange="-6.90714 6.90714" gainprm="23.213" biasprm="0 -23.213 -0.497478"/>
    <general name="tibia_joint_LM" class="/" joint="tibia_joint_LM" forcerange="-7.02421 7.02421" gainprm="23.213" biasprm="0 -23.213 -0.497478"/>
    <general name="tarsus_joint_LM" class="/" joint="tarsus_joint_LM" forcerange="-7.24278 7.24278" gainprm="23.213" biasprm="0 -23.213 -0.497478"/>
    <general name="coxa_joint_LF" class="/" joint="coxa_joint_LF" forcerange="-6.962 6.962" gainprm="23.213" biasprm="0 -23.213 -0.497478"/>
    <general name="femur_joint_LF" class="/" joint="femur_joint_LF" forcerange="-7.51433 7.51433" gainprm="23.213" biasprm="0 -23.213 -0.497478"/>
    <general name="tibia_joint_LF" class="/" joint="tibia_joint_LF" forcerange="-7.44101 7.44101" gainprm="23.213" biasprm="0 -23.213 -0.497478"/>
    <general name="tarsus_joint_LF" class="/" joint="tarsus_joint_LF" forcerange="-7.11224 7.11224" gainprm="23.213" biasprm="0 -23.213 -0.497478"/>
  </actuator>

  <sensor>
    <gyro site="imu" name="imu_angular_velocity"/>
    <velocimeter site="imu" name="imu_linear_velocity"/>
    <framelinvel objtype="site" objname="foot_1" name="foot_1_global_linear_velocity"/>
    <framelinvel objtype="site" objname="foot_2" name="foot_2_global_linear_velocity"/>
    <framelinvel objtype="site" objname="foot_3" name="foot_3_global_linear_velocity"/>
    <framelinvel objtype="site" objname="foot_4" name="foot_4_global_linear_velocity"/>
    <framelinvel objtype="site" objname="foot_5" name="foot_5_global_linear_velocity"/>
    <framelinvel objtype="site" objname="foot_6" name="foot_6_global_linear_velocity"/>
  </sensor>

  <keyframe>
    <key name="home" qpos="0 0 0.1457 1 0 0 0 0 0 0 0 0 0 0 0 0 0 0 0 0 0 0 0 0 0 0 0 0 0 0 0"/>
  </keyframe>
</mujoco>
