<mujoco model="Golem">
  <compiler angle="radian" assetdir="assets" balanceinertia="true" inertiafromgeom="false"/>

  <option timestep="0.005" density="1.2" viscosity="2e-05"/>

  <size nkey="1"/>

  <visual>
    <quality shadowsize="8192"/>
    <map shadowclip="0.5"/>
  </visual>

  <default>
    <default class="/">
      <joint armature="0.01" damping="0.01" frictionloss="0.01"/>
      <geom contype="0" conaffinity="0" group="1" solref="-1000 -80"/>
      <site size="0.01 0.005 0.005" group="5"/>
      <general forcelimited="true" biastype="affine" gainprm="25" biasprm="0 -25 -0.5"/>
      <default class="visual">
        <geom type="mesh" group="2"/>
      </default>
      <default class="collision">
        <geom group="3"/>
      </default>
      <default class="foot">
        <geom size="0.01 0 0" condim="6" group="4" priority="1" solimp="0.015 1 0.01"/>
      </default>
      <default class="reward_collision_sphere">
        <geom group="5" rgba="1 0 0 1"/>
      </default>
    </default>
  </default>

  <asset>
    <texture type="skybox" colorspace="auto" name="//unnamed_texture_0" builtin="gradient" rgb1="0.95 0.95 0.95" rgb2="0.95 0.95 0.95" width="100" height="600"/>
    <texture type="2d" colorspace="auto" name="texplane" builtin="checker" rgb1="0.345 0.575 0.748" rgb2="0.345 0.575 0.748" markrgb="1 1 1" width="512" height="512"/>
    <material name="MatPlane" class="/" texture="texplane" texuniform="true" texrepeat="2 2" specular="0.9"/>
    <mesh name="body" class="/" file="body.stl" scale="0.001 0.001 0.001"/>
    <mesh name="coxa" class="/" file="coxa.stl" scale="0.001 0.001 0.001"/>
    <mesh name="femur" class="/" file="femur.stl" scale="0.001 0.001 0.001"/>
    <mesh name="tibia" class="/" file="tibia.stl" scale="0.001 0.001 0.001"/>
    <mesh name="tarsus" class="/" file="tarsus.stl" scale="0.001 0.001 0.001"/>
  </asset>

  <worldbody>
    <geom name="floor" class="/" size="100 100 0.125" type="plane" group="0" material="MatPlane"/>
    <light name="toplight_shadow" class="/" pos="0 0 5" dir="0.0990148 0.0990148 -0.990148" type="directional" ambient="0.04 0.04 0.04" diffuse="0.55 0.55 0.55" specular="0.12 0.12 0.12"/>
    <light name="toplight_fill" class="/" pos="0 0 5" dir="0.0990148 0.0990148 -0.990148" type="directional" castshadow="false" ambient="0.04 0.04 0.04" diffuse="0.3 0.3 0.3" specular="0.08 0.08 0.08"/>
    <body name="trunk" pos="0.000912877 -7.60612e-05 -0.0011716" quat="1 2.75056e-05 -1.08667e-05 1.10422e-05">
      <inertial pos="-0.000619371 -0.000412569 -0.00357763" quat="0.999997 -0.00213253 0.001149 7.786e-05" mass="2.98339" diaginertia="0.00704359 0.00299449 0.0141747"/>
      <joint name="//unnamed_joint_0" type="free"/>
      <geom name="//unnamed_geom_1" class="/" pos="0 0 0.0687526" quat="1 0 0 0" type="mesh" rgba="0.9 0.9 0.9 1" mesh="body"/>
      <site name="imu" class="/" pos="0.121616 -0.000984707 0.10745" size="0.00932353"/>
      <camera name="track" class="/" pos="0 -1.57374 0" quat="0.707107 0.707107 0 0" mode="trackcom"/>
      <camera name="ego_camera" class="/" pos="0.121671 0 0.107426" quat="-0.5 -0.5 0.5 0.5"/>
      <body name="coxa_RR" pos="-0.167546 -0.0661246 0.0681369" quat="0.382714 -5.64249e-05 -0.000140892 -0.923867">
        <inertial pos="7.91514e-05 -0.00102732 0.000278511" quat="0.999998 0.00146371 -6.16106e-05 -0.0015835" mass="0.158798" diaginertia="0.00708849 0.00297102 0.0139617"/>
        <joint name="coxa_joint_RR" class="/" pos="0 0 0" axis="0.00183371 0.00360238 -0.999992" range="-3.14142 3.15213" armature="0.00977161" damping="0.0118566" frictionloss="0.00951556"/>
        <geom name="//unnamed_geom_2" class="/" type="mesh" rgba="0.2 0.2 0.2 1" mesh="coxa"/>
        <geom name="//unnamed_geom_3" class="reward_collision_sphere" size="0.0372941" pos="-0.0280779 0 0"/>
        <body name="femur_RR" pos="0.0566569 -0.000638787 0.000408086" quat="0.500078 -0.499678 0.500243 0.5">
          <inertial pos="-0.000217762 -0.00095469 0.000980408" quat="0.999999 -0.000697057 -0.000831671 -2.42096e-05" mass="0.161993" diaginertia="0.00716281 0.00301719 0.0142882"/>
          <joint name="femur_joint_RR" class="/" pos="0 0 0" axis="-0.000600803 0.00169006 -0.999998" stiffness="0.00262091" range="-3.13592 3.12485" armature="0.00964825" damping="0.00145054" frictionloss="0.00906992"/>
          <geom name="//unnamed_geom_4" class="/" type="mesh" rgba="0.9 0.9 0.9 1" mesh="femur"/>
          <geom name="//unnamed_geom_5" class="reward_collision_sphere" size="0.0372941"/>
          <body name="tibia_RR" pos="0.00103962 -0.0852612 0.00076539" quat="3.49969e-05 1 0.000472534 -5.03938e-05">
            <inertial pos="-0.000113884 0.000918562 0.000158102" quat="0.999999 -0.00133698 -0.00102104 0.000227328" mass="0.16199" diaginertia="0.00715623 0.0029958 0.0141363"/>
            <joint name="tibia_joint_RR" class="/" pos="0 0 0" axis="-0.00442173 0.00482726 0.999979" range="-3.15937 3.15327" armature="0.00950386" damping="0.00150897" frictionloss="0.00943067"/>
            <geom name="//unnamed_geom_6" class="/" type="mesh" rgba="0.2 0.2 0.2 1" mesh="tibia"/>
            <geom name="//unnamed_geom_7" class="reward_collision_sphere" size="0.0372941"/>
            <body name="tarsus_RR" pos="0.0813752 0.00119755 0.000539532" quat="1 -2.01437e-06 -8.16447e-07 4.54747e-06">
              <inertial pos="0.0564895 0.00101607 0.00043724" quat="0.499871 0.502293 0.4998 0.498026" mass="0.163332" diaginertia="0.00724248 0.00299962 0.014372"/>
              <joint name="tarsus_joint_RR" class="/" pos="0 0 0" axis="0.000304637 -0.000436391 1" range="-3.12915 3.14104" armature="0.00911225" damping="0.00836164" frictionloss="0.00923933"/>
              <geom name="//unnamed_geom_8" class="/" type="mesh" rgba="0.9 0.9 0.9 1" mesh="tarsus"/>
              <geom name="foot_1" class="foot" size="0.0094351" pos="0.104824 0 0" quat="0 -0.707107 0 0.707107"/>
              <geom name="//unnamed_geom_10" class="reward_collision_sphere" size="0.0372941"/>
              <geom name="//unnamed_geom_11" class="reward_collision_sphere" size="0.0139853" pos="0.100612 0 0"/>
              <site name="foot_1" class="foot" pos="0.104824 0 0" quat="0 -0.707107 0 0.707107" size="0.00932353"/>
            </body>
          </body>
        </body>
      </body>
      <body name="coxa_RM" pos="-0.000589713 -0.105695 0.068091" quat="0.706903 -0.000276508 0.000564088 -0.70731">
        <inertial pos="-0.000153453 -7.06271e-05 0.00118815" quat="0.999997 -0.00142 0.00141105 -0.00132793" mass="0.161004" diaginertia="0.00699379 0.00298203 0.0143798"/>
        <joint name="coxa_joint_RM" class="/" pos="0 0 0" axis="0.000109779 -0.000279506 -1" range="-3.16753 3.13385" armature="0.00968584" damping="0.0132197" frictionloss="0.00937494"/>
        <geom name="//unnamed_geom_12" class="/" type="mesh" rgba="0.2 0.2 0.2 1" mesh="coxa"/>
        <geom name="//unnamed_geom_13" class="reward_collision_sphere" size="0.0372941" pos="-0.0280779 0 0"/>
        <body name="femur_RM" pos="0.0550443 -0.000780098 -0.00105254" quat="0.500116 -0.499823 0.499949 0.500112">
          <inertial pos="-0.000752582 0.000709404 -0.000669979" quat="0.999998 0.00199375 0.000444168 0.000144343" mass="0.16177" diaginertia="0.00716955 0.00302151 0.0142841"/>
          <joint name="femur_joint_RM" class="/" pos="0 0 0" axis="0.000918813 -0.00104707 -0.999999" range="-3.13564 3.13557" armature="0.0094616" damping="0.011822" frictionloss="0.00965632"/>
          <geom name="//unnamed_geom_14" class="/" type="mesh" rgba="0.9 0.9 0.9 1" mesh="femur"/>
          <geom name="//unnamed_geom_15" class="reward_collision_sphere" size="0.0372941"/>
          <body name="tibia_RM" pos="0.0006856 -0.0840335 0.000116099" quat="-1.81408e-06 1 0.000166251 -0.000251693">
            <inertial pos="0.000802685 0.000761784 -0.000328046" quat="0.999999 0.000954404 0.000494516 -0.00130234" mass="0.164095" diaginertia="0.0072517 0.00306038 0.0143318"/>
            <joint name="tibia_joint_RM" class="/" pos="0 0 0" axis="-0.00346204 0.00181066 0.999992" range="-3.15206 3.10476" armature="0.00896511" damping="0" frictionloss="0.00922882"/>
            <geom name="//unnamed_geom_16" class="/" type="mesh" rgba="0.2 0.2 0.2 1" mesh="tibia"/>
            <geom name="//unnamed_geom_17" class="reward_collision_sphere" size="0.0372941"/>
            <body name="tarsus_RM" pos="0.081092 -0.00113422 -0.000624054" quat="1 0.000207472 -9.63009e-05 -7.48921e-06">
              <inertial pos="0.0553014 0.00149134 -0.000414424" quat="0.49943 0.499577 0.500465 0.500527" mass="0.160207" diaginertia="0.00720651 0.00305022 0.0145666"/>
              <joint name="tarsus_joint_RM" class="/" pos="0 0 0" axis="0.00236392 0.00521092 0.999984" range="-3.13624 3.12956" armature="0.00889474" damping="0.0046558" frictionloss="0.00936109"/>
              <geom name="//unnamed_geom_18" class="/" type="mesh" rgba="0.9 0.9 0.9 1" mesh="tarsus"/>
              <geom name="foot_2" class="foot" size="0.00911773" pos="0.104824 0 0" quat="0 -0.707107 0 0.707107"/>
              <geom name="//unnamed_geom_20" class="reward_collision_sphere" size="0.0372941"/>
              <geom name="//unnamed_geom_21" class="reward_collision_sphere" size="0.0139853" pos="0.100612 0 0"/>
              <site name="foot_2" class="foot" pos="0.104824 0 0" quat="0 -0.707107 0 0.707107" size="0.00932353"/>
            </body>
          </body>
        </body>
      </body>
      <body name="coxa_RF" pos="0.165827 -0.0643629 0.0687668" quat="0.923946 -0.000159431 -0.000185485 -0.382524">
        <inertial pos="-0.000407507 0.000200802 0.000438288" quat="0.999989 -0.00120698 0.00404894 -0.00193323" mass="0.164947" diaginertia="0.00740284 0.00301405 0.0147335"/>
        <joint name="coxa_joint_RF" class="/" pos="0 0 0" axis="-0.00421031 -0.00519448 -0.999978" range="-3.12143 3.13817" armature="0.00938681" damping="0.00317559" frictionloss="0.00893957"/>
        <geom name="//unnamed_geom_22" class="/" type="mesh" rgba="0.2 0.2 0.2 1" mesh="coxa"/>
        <geom name="//unnamed_geom_23" class="reward_collision_sphere" size="0.0372941" pos="-0.0280779 0 0"/>
        <body name="femur_RF" pos="0.0563074 -0.000220263 0.000439178" quat="0.499892 -0.500084 0.499815 0.500209">
          <inertial pos="-0.000427413 0.000904071 0.000547612" quat="0.999998 -0.000179486 0.000167167 0.00215384" mass="0.158579" diaginertia="0.00713042 0.00296898 0.014194"/>
          <joint name="femur_joint_RF" class="/" pos="0 0 0" axis="0.000113231 -0.000428114 -1" range="-3.1543 3.1195" armature="0.00861278" damping="0.0111191" frictionloss="0.00866399"/>
          <geom name="//unnamed_geom_24" class="/" type="mesh" rgba="0.9 0.9 0.9 1" mesh="femur"/>
          <geom name="//unnamed_geom_25" class="reward_collision_sphere" size="0.0372941"/>
          <body name="tibia_RF" pos="-3.26645e-05 -0.083944 0.000680653" quat="-7.28612e-05 1 1.16685e-05 -2.72833e-05">
            <inertial pos="-0.000784935 -0.000182931 -0.000165429" quat="0.999999 -0.00026527 -1.99672e-05 0.000992692" mass="0.164063" diaginertia="0.00726597 0.00304741 0.0144477"/>
            <joint name="tibia_joint_RF" class="/" pos="0 0 0" axis="0.00300321 0.000534205 0.999995" range="-3.15562 3.1353" armature="0.00940368" damping="0" frictionloss="0.00890153"/>
            <geom name="//unnamed_geom_26" class="/" type="mesh" rgba="0.2 0.2 0.2 1" mesh="tibia"/>
            <geom name="//unnamed_geom_27" class="reward_collision_sphere" size="0.0372941"/>
            <body name="tarsus_RF" pos="0.0813219 -0.000598684 0.000147404" quat="1 -9.1945e-05 0.000277576 -8.77939e-05">
              <inertial pos="0.0556587 0.00112483 0.00019701" quat="0.500751 0.500359 0.493744 0.50508" mass="0.164798" diaginertia="0.0072722 0.00303103 0.0142557"/>
              <joint name="tarsus_joint_RF" class="/" pos="0 0 0" axis="-0.00144926 -0.000694038 0.999999" range="-3.14268 3.13811" armature="0.0088203" damping="0.00702321" frictionloss="0.00918734"/>
              <geom name="//unnamed_geom_28" class="/" type="mesh" rgba="0.9 0.9 0.9 1" mesh="tarsus"/>
              <geom name="foot_3" class="foot" size="0.00951273" pos="0.104824 0 0" quat="0 -0.707107 0 0.707107"/>
              <geom name="//unnamed_geom_30" class="reward_collision_sphere" size="0.0372941"/>
              <geom name="//unnamed_geom_31" class="reward_collision_sphere" size="0.0139853" pos="0.100612 0 0"/>
              <site name="foot_3" class="foot" pos="0.104824 0 0" quat="0 -0.707107 0 0.707107" size="0.00932353"/>
            </body>
          </body>
        </body>
      </body>
      <body name="coxa_LR" pos="-0.16527 0.0682257 0.0693366" quat="0.382624 0.000100911 0.000200251 0.923904">
        <inertial pos="-0.000627496 -0.000170281 0.000604137" quat="0.999986 -0.00296577 0.00129751 0.00423605" mass="0.164469" diaginertia="0.00713636 0.00304096 0.0142894"/>
        <joint name="coxa_joint_LR" class="/" pos="0 0 0" axis="-0.00251668 0.00207546 -0.999995" range="-3.13628 3.1204" armature="0.0092645" damping="0.00845664" frictionloss="0.0090577"/>
        <geom name="//unnamed_geom_32" class="/" type="mesh" rgba="0.2 0.2 0.2 1" mesh="coxa"/>
        <geom name="//unnamed_geom_33" class="reward_collision_sphere" size="0.0372941" pos="-0.0280779 0 0"/>
        <body name="femur_LR" pos="0.0565075 -0.00212792 -0.000128692" quat="0.499816 -0.500005 0.499979 0.5002">
          <inertial pos="-0.000525227 -0.00114365 0.000736512" quat="1 -0.000168803 -1.36939e-05 0.000283987" mass="0.161907" diaginertia="0.00700987 0.00300113 0.0142086"/>
          <joint name="femur_joint_LR" class="/" pos="0 0 0" axis="-0.00535187 0.00115633 0.999985" range="-3.12899 3.14524" armature="0.0101321" damping="0.00912757" frictionloss="0.00922921"/>
          <geom name="//unnamed_geom_34" class="/" type="mesh" rgba="0.9 0.9 0.9 1" mesh="femur"/>
          <geom name="//unnamed_geom_35" class="reward_collision_sphere" size="0.0372941"/>
          <body name="tibia_LR" pos="1.84493e-06 -0.0868863 -0.000740928" quat="3.12381e-05 1 -3.73681e-05 1.92057e-05">
            <inertial pos="-0.000749172 -0.000699141 0.000412775" quat="0.999988 0.0034422 0.00335697 -0.000168905" mass="0.163632" diaginertia="0.00730466 0.00299953 0.0141842"/>
            <joint name="tibia_joint_LR" class="/" pos="0 0 0" axis="0.000189089 -0.00105082 -0.999999" range="-3.13922 3.12752" armature="0.0093848" damping="0" frictionloss="0.00905502"/>
            <geom name="//unnamed_geom_36" class="/" type="mesh" rgba="0.2 0.2 0.2 1" mesh="tibia"/>
            <geom name="//unnamed_geom_37" class="reward_collision_sphere" size="0.0372941"/>
            <body name="tarsus_LR" pos="0.0846239 0.000997634 0.00130323" quat="1 0.000272405 0.000240069 -4.19549e-05">
              <inertial pos="0.0584609 -0.000678199 0.00033323" quat="0.499609 0.500328 0.500864 0.499198" mass="0.164019" diaginertia="0.00717146 0.00299015 0.0143741"/>
              <joint name="tarsus_joint_LR" class="/" pos="0 0 0" axis="-0.00399779 -0.00420339 -0.999983" range="-3.13557 3.13328" armature="0.00926504" damping="0.0270442" frictionloss="0.00946249"/>
              <geom name="//unnamed_geom_38" class="/" type="mesh" rgba="0.9 0.9 0.9 1" mesh="tarsus"/>
              <geom name="foot_4" class="foot" size="0.00932068" pos="0.104824 0 0" quat="0.707107 0 -0.707107 0"/>
              <geom name="//unnamed_geom_40" class="reward_collision_sphere" size="0.0372941"/>
              <geom name="//unnamed_geom_41" class="reward_collision_sphere" size="0.0139853" pos="0.100612 0 0"/>
              <site name="foot_4" class="foot" pos="0.104824 0 0" quat="0.707107 0 -0.707107 0" size="0.00932353"/>
            </body>
          </body>
        </body>
      </body>
      <body name="coxa_LM" pos="0.000588731 0.103156 0.0689503" quat="0.7067 7.8547e-05 6.75765e-05 0.707513">
        <inertial pos="-0.00043932 -0.000605285 -0.000449453" quat="0.999988 -0.00475624 -0.000649155 -8.75051e-05" mass="0.161746" diaginertia="0.00719197 0.00305206 0.0142975"/>
        <joint name="coxa_joint_LM" class="/" pos="0 0 0" axis="0.00279028 -0.00232173 -0.999993" range="-3.1576 3.16645" armature="0.00932778" damping="0.00988521" frictionloss="0.00929603"/>
        <geom name="//unnamed_geom_42" class="/" type="mesh" rgba="0.2 0.2 0.2 1" mesh="coxa"/>
        <geom name="//unnamed_geom_43" class="reward_collision_sphere" size="0.0372941" pos="-0.0280779 0 0"/>
        <body name="femur_LM" pos="0.0538027 0.00108277 -0.000879978" quat="0.500004 -0.500217 0.499975 0.499803">
          <inertial pos="-0.000473815 -0.000846006 0.000533105" quat="1 -0.000501028 0.00039419 -0.000728184" mass="0.163902" diaginertia="0.00714795 0.00301775 0.014271"/>
          <joint name="femur_joint_LM" class="/" pos="0 0 0" axis="0.00305218 -0.0025237 0.999992" stiffness="0.00135247" range="-3.15665 3.12388" armature="0.00911115" damping="0" frictionloss="0.00905451"/>
          <geom name="//unnamed_geom_44" class="/" type="mesh" rgba="0.9 0.9 0.9 1" mesh="femur"/>
          <geom name="//unnamed_geom_45" class="reward_collision_sphere" size="0.0372941"/>
          <body name="tibia_LM" pos="-0.000610017 -0.0817592 0.00118329" quat="-9.47812e-05 1 -4.94129e-05 -0.000243602">
            <inertial pos="-0.000842102 -0.000939772 -0.000327985" quat="0.999995 0.00222777 0.00103124 0.00221499" mass="0.158661" diaginertia="0.00710573 0.00293199 0.0139945"/>
            <joint name="tibia_joint_LM" class="/" pos="0 0 0" axis="-0.00213703 0.00419828 -0.999989" range="-3.13468 3.13935" armature="0.00902557" damping="0" frictionloss="0.0094642"/>
            <geom name="//unnamed_geom_46" class="/" type="mesh" rgba="0.2 0.2 0.2 1" mesh="tibia"/>
            <geom name="//unnamed_geom_47" class="reward_collision_sphere" size="0.0372941"/>
            <body name="tarsus_LM" pos="0.0824674 -0.000309759 -0.000374347" quat="1 0.000214404 0.00012166 0.000107471">
              <inertial pos="0.056523 -0.000617809 -5.41082e-06" quat="0.500663 0.502352 0.50098 0.495982" mass="0.163918" diaginertia="0.00706179 0.00301537 0.0142684"/>
              <joint name="tarsus_joint_LM" class="/" pos="0 0 0" axis="-6.13037e-05 0.000128954 -1" range="-3.12876 3.13076" armature="0.0092115" damping="0" frictionloss="0.00933608"/>
              <geom name="//unnamed_geom_48" class="/" type="mesh" rgba="0.9 0.9 0.9 1" mesh="tarsus"/>
              <geom name="foot_5" class="foot" size="0.00887271" pos="0.104824 0 0" quat="0.707107 0 -0.707107 0"/>
              <geom name="//unnamed_geom_50" class="reward_collision_sphere" size="0.0372941"/>
              <geom name="//unnamed_geom_51" class="reward_collision_sphere" size="0.0139853" pos="0.100612 0 0"/>
              <site name="foot_5" class="foot" pos="0.104824 0 0" quat="0.707107 0 -0.707107 0" size="0.00932353"/>
            </body>
          </body>
        </body>
      </body>
      <body name="coxa_LF" pos="0.16765 0.0664342 0.0684627" quat="0.923888 -0.000444916 -0.000216245 0.382663">
        <inertial pos="-0.000141161 0.000199219 0.000225952" quat="1 0.000201594 -0.000197958 0.000280252" mass="0.163907" diaginertia="0.00718305 0.00298079 0.0144778"/>
        <joint name="coxa_joint_LF" class="/" pos="0 0 0" axis="0.00403981 -0.000256901 -0.999992" range="-3.12983 3.14676" armature="0.00951131" damping="0" frictionloss="0.0092809"/>
        <geom name="//unnamed_geom_52" class="/" type="mesh" rgba="0.2 0.2 0.2 1" mesh="coxa"/>
        <geom name="//unnamed_geom_53" class="reward_collision_sphere" size="0.0372941" pos="-0.0280779 0 0"/>
        <body name="femur_LF" pos="0.0557942 0.0010169 -0.000382982" quat="0.500315 -0.499936 0.499855 0.499893">
          <inertial pos="-2.48904e-05 -0.000372794 0.000771369" quat="0.999996 -0.000837618 0.000294467 -0.00277905" mass="0.165378" diaginertia="0.00718831 0.00301104 0.0142612"/>
          <joint name="femur_joint_LF" class="/" pos="0 0 0" axis="0.000302019 0.000304671 1" range="-3.12998 3.13984" armature="0.00923157" damping="0" frictionloss="0.00954159"/>
          <geom name="//unnamed_geom_54" class="/" type="mesh" rgba="0.9 0.9 0.9 1" mesh="femur"/>
          <geom name="//unnamed_geom_55" class="reward_collision_sphere" size="0.0372941"/>
          <body name="tibia_LF" pos="0.000190609 -0.0836261 0.00105909" quat="6.64989e-05 1 -0.00020104 0.000496962">
            <inertial pos="0.000242474 0.000928198 -0.000727058" quat="0.999987 0.00341396 0.00367712 -0.000382181" mass="0.16184" diaginertia="0.00714795 0.00302975 0.0143306"/>
            <joint name="tibia_joint_LF" class="/" pos="0 0 0" axis="-0.000906049 0.000647802 -0.999999" range="-3.10731 3.12091" armature="0.0091865" damping="0.00466995" frictionloss="0.00934858"/>
            <geom name="//unnamed_geom_56" class="/" type="mesh" rgba="0.2 0.2 0.2 1" mesh="tibia"/>
            <geom name="//unnamed_geom_57" class="reward_collision_sphere" size="0.0372941"/>
            <body name="tarsus_LF" pos="0.0829648 0.000554093 -0.000361539" quat="1 -0.000429921 -0.00011871 0.000214307">
              <inertial pos="0.0552966 0.000589985 -0.000185561" quat="0.500065 0.500384 0.499681 0.49987" mass="0.164556" diaginertia="0.00729109 0.00306132 0.0145774"/>
              <joint name="tarsus_joint_LF" class="/" pos="0 0 0" axis="0.00253498 -0.00188202 -0.999995" range="-3.14215 3.13726" armature="0.00959835" damping="0.0172267" frictionloss="0.0100214"/>
              <geom name="//unnamed_geom_58" class="/" type="mesh" rgba="0.9 0.9 0.9 1" mesh="tarsus"/>
              <geom name="foot_6" class="foot" size="0.00924277" pos="0.104824 0 0" quat="0.707107 0 -0.707107 0"/>
              <geom name="//unnamed_geom_60" class="reward_collision_sphere" size="0.0372941"/>
              <geom name="//unnamed_geom_61" class="reward_collision_sphere" size="0.0139853" pos="0.100612 0 0"/>
              <site name="foot_6" class="foot" pos="0.104824 0 0" quat="0.707107 0 -0.707107 0" size="0.00932353"/>
            </body>
          </body>
        </body>
      </body>
    </body>
  </worldbody>

  <contact>
    <pair class="/" geom1="floor" geom2="foot_1" name="//unnamed_contact_0"/>
    <pair class="/" geom1="floor" geom2="foot_2" name="//unnamed_contact_1"/>
    <pair class="/" geom1="floor" geom2="foot_3" name="//unnamed_contact_2"/>
    <pair class="/" geom1="floor" geom2="foot_4" name="//unnamed_contact_3"/>
    <pair class="/" geom1="floor" geom2="foot_5" name="//unnamed_contact_4"/>
    <pair class="/" geom1="floor" geom2="foot_6" name="//unnamed_contact_5"/>
  </contact>

  <actuator>
    <general name="coxa_joint_RR" class="/" joint="coxa_joint_RR" forcerange="-6.60196 6.60196" gainprm="22.7741" biasprm="0 -22.7741 -0.487943"/>
    <general name="femur_joint_RR" class="/" joint="femur_joint_RR" forcerange="-6.71195 6.71195" gainprm="22.7741" biasprm="0 -22.7741 -0.487943"/>
    <general name="tibia_joint_RR" class="/" joint="tibia_joint_RR" forcerange="-6.86551 6.86551" gainprm="22.7741" biasprm="0 -22.7741 -0.487943"/>
    <general name="tarsus_joint_RR" class="/" joint="tarsus_joint_RR" forcerange="-6.78671 6.78671" gainprm="22.7741" biasprm="0 -22.7741 -0.487943"/>
    <general name="coxa_joint_RM" class="/" joint="coxa_joint_RM" forcerange="-6.59452 6.59452" gainprm="22.7741" biasprm="0 -22.7741 -0.487943"/>
    <general name="femur_joint_RM" class="/" joint="femur_joint_RM" forcerange="-6.93282 6.93282" gainprm="22.7741" biasprm="0 -22.7741 -0.487943"/>
    <general name="tibia_joint_RM" class="/" joint="tibia_joint_RM" forcerange="-6.79817 6.79817" gainprm="22.7741" biasprm="0 -22.7741 -0.487943"/>
    <general name="tarsus_joint_RM" class="/" joint="tarsus_joint_RM" forcerange="-6.87091 6.87091" gainprm="22.7741" biasprm="0 -22.7741 -0.487943"/>
    <general name="coxa_joint_RF" class="/" joint="coxa_joint_RF" forcerange="-6.85993 6.85993" gainprm="22.7741" biasprm="0 -22.7741 -0.487943"/>
    <general name="femur_joint_RF" class="/" joint="femur_joint_RF" forcerange="-7.21096 7.21096" gainprm="22.7741" biasprm="0 -22.7741 -0.487943"/>
    <general name="tibia_joint_RF" class="/" joint="tibia_joint_RF" forcerange="-7.05156 7.05156" gainprm="22.7741" biasprm="0 -22.7741 -0.487943"/>
    <general name="tarsus_joint_RF" class="/" joint="tarsus_joint_RF" forcerange="-6.96592 6.96592" gainprm="22.7741" biasprm="0 -22.7741 -0.487943"/>
    <general name="coxa_joint_LR" class="/" joint="coxa_joint_LR" forcerange="-6.77464 6.77464" gainprm="22.7741" biasprm="0 -22.7741 -0.487943"/>
    <general name="femur_joint_LR" class="/" joint="femur_joint_LR" forcerange="-6.8 6.8" gainprm="22.7741" biasprm="0 -22.7741 -0.487943"/>
    <general name="tibia_joint_LR" class="/" joint="tibia_joint_LR" forcerange="-7.17649 7.17649" gainprm="22.7741" biasprm="0 -22.7741 -0.487943"/>
    <general name="tarsus_joint_LR" class="/" joint="tarsus_joint_LR" forcerange="-7.04907 7.04907" gainprm="22.7741" biasprm="0 -22.7741 -0.487943"/>
    <general name="coxa_joint_LM" class="/" joint="coxa_joint_LM" forcerange="-6.75145 6.75145" gainprm="22.7741" biasprm="0 -22.7741 -0.487943"/>
    <general name="femur_joint_LM" class="/" joint="femur_joint_LM" forcerange="-6.71777 6.71777" gainprm="22.7741" biasprm="0 -22.7741 -0.487943"/>
    <general name="tibia_joint_LM" class="/" joint="tibia_joint_LM" forcerange="-6.81208 6.81208" gainprm="22.7741" biasprm="0 -22.7741 -0.487943"/>
    <general name="tarsus_joint_LM" class="/" joint="tarsus_joint_LM" forcerange="-7.00035 7.00035" gainprm="22.7741" biasprm="0 -22.7741 -0.487943"/>
    <general name="coxa_joint_LF" class="/" joint="coxa_joint_LF" forcerange="-6.81908 6.81908" gainprm="22.7741" biasprm="0 -22.7741 -0.487943"/>
    <general name="femur_joint_LF" class="/" joint="femur_joint_LF" forcerange="-6.93416 6.93416" gainprm="22.7741" biasprm="0 -22.7741 -0.487943"/>
    <general name="tibia_joint_LF" class="/" joint="tibia_joint_LF" forcerange="-6.85267 6.85267" gainprm="22.7741" biasprm="0 -22.7741 -0.487943"/>
    <general name="tarsus_joint_LF" class="/" joint="tarsus_joint_LF" forcerange="-6.87632 6.87632" gainprm="22.7741" biasprm="0 -22.7741 -0.487943"/>
  </actuator>

  <sensor>
    <gyro site="imu" name="imu_angular_velocity"/>
    <velocimeter site="imu" name="imu_linear_velocity"/>
    <framelinvel objtype="site" objname="foot_1" name="foot_1_global_linear_velocity"/>
    <framelinvel objtype="site" objname="foot_2" name="foot_2_global_linear_velocity"/>
    <framelinvel objtype="site" objname="foot_3" name="foot_3_global_linear_velocity"/>
    <framelinvel objtype="site" objname="foot_4" name="foot_4_global_linear_velocity"/>
    <framelinvel objtype="site" objname="foot_5" name="foot_5_global_linear_velocity"/>
    <framelinvel objtype="site" objname="foot_6" name="foot_6_global_linear_velocity"/>
  </sensor>

  <keyframe>
    <key name="home" qpos="0 0 0.1457 1 0 0 0 0 0 0 0 0 0 0 0 0 0 0 0 0 0 0 0 0 0 0 0 0 0 0 0"/>
  </keyframe>
</mujoco>
