<mujoco model="Golem">
  <compiler angle="radian" assetdir="assets" balanceinertia="true" inertiafromgeom="false"/>

  <option timestep="0.005" density="1.2" viscosity="2e-05"/>

  <size nkey="1"/>

  <visual>
    <quality shadowsize="8192"/>
    <map shadowclip="0.5"/>
  </visual>

  <default>
    <default class="/">
      <joint armature="0.01" damping="0.01" frictionloss="0.01"/>
      <geom contype="0" conaffinity="0" group="1" solref="-1000 -80"/>
      <site size="0.01 0.005 0.005" group="5"/>
      <general forcelimited="true" biastype="affine" gainprm="25" biasprm="0 -25 -0.5"/>
      <default class="visual">
        <geom type="mesh" group="2"/>
      </default>
      <default class="collision">
        <geom group="3"/>
      </default>
      <default class="foot">
        <geom size="0.01 0 0" condim="6" group="4" priority="1" solimp="0.015 1 0.01"/>
      </default>
      <default class="reward_collision_sphere">
        <geom group="5" rgba="1 0 0 1"/>
      </default>
    </default>
  </default>

  <asset>
    <texture type="skybox" colorspace="auto" name="//unnamed_texture_0" builtin="gradient" rgb1="0.95 0.95 0.95" rgb2="0.95 0.95 0.95" width="100" height="600"/>
    <texture type="2d" colorspace="auto" name="texplane" builtin="checker" rgb1="0.345 0.575 0.748" rgb2="0.345 0.575 0.748" markrgb="1 1 1" width="512" height="512"/>
    <material name="MatPlane" class="/" texture="texplane" texuniform="true" texrepeat="2 2" specular="0.9"/>
    <mesh name="body" class="/" file="body.stl" scale="0.001 0.001 0.001"/>
    <mesh name="coxa" class="/" file="coxa.stl" scale="0.001 0.001 0.001"/>
    <mesh name="femur" class="/" file="femur.stl" scale="0.001 0.001 0.001"/>
    <mesh name="tibia" class="/" file="tibia.stl" scale="0.001 0.001 0.001"/>
    <mesh name="tarsus" class="/" file="tarsus.stl" scale="0.001 0.001 0.001"/>
  </asset>

  <worldbody>
    <geom name="floor" class="/" size="100 100 0.125" type="plane" group="0" material="MatPlane"/>
    <light name="toplight_shadow" class="/" pos="0 0 5" dir="0.0990148 0.0990148 -0.990148" type="directional" ambient="0.04 0.04 0.04" diffuse="0.55 0.55 0.55" specular="0.12 0.12 0.12"/>
    <light name="toplight_fill" class="/" pos="0 0 5" dir="0.0990148 0.0990148 -0.990148" type="directional" castshadow="false" ambient="0.04 0.04 0.04" diffuse="0.3 0.3 0.3" specular="0.08 0.08 0.08"/>
    <body name="trunk" pos="0.00800919 0.00719968 -0.00206214" quat="0.999996 -0.00110508 0.000359825 -0.00242798">
      <inertial pos="-0.00788675 -0.001305 0.012923" quat="0.999314 0.0190175 -0.0315281 0.00393403" mass="8.61772" diaginertia="0.0486869 0.0547733 0.0247103"/>
      <joint name="//unnamed_joint_0" type="free"/>
      <geom name="//unnamed_geom_1" class="/" pos="0 0 0.079805" quat="1 0 0 0" type="mesh" rgba="0.9 0.9 0.9 1" mesh="body"/>
      <site name="imu" class="/" pos="0.129323 -0.0399082 0.118883" size="0.0135874"/>
      <camera name="track" class="/" pos="0 -2.87112 0" quat="0.707107 0.707107 0 0" mode="trackcom"/>
      <camera name="ego_camera" class="/" pos="0.181183 0 0.124695" quat="-0.5 -0.5 0.5 0.5"/>
      <body name="coxa_RR" pos="-0.243846 -0.108724 0.0905392" quat="0.382535 -0.000901337 -0.00172678 -0.923939">
        <inertial pos="-0.00075714 -0.00157702 -0.00422103" quat="0.999983 -0.00207617 0.00437783 0.00329169" mass="0.484569" diaginertia="0.0554133 0.0585111 0.0341125"/>
        <joint name="coxa_joint_RR" class="/" pos="0 0 0" axis="0.00157368 0.000308893 -0.999999" stiffness="0.00325302" range="-3.11711 3.24187" armature="0.0148998" damping="0.0243921" frictionloss="0.0138691"/>
        <geom name="//unnamed_geom_2" class="/" type="mesh" rgba="0.2 0.2 0.2 1" mesh="coxa"/>
        <geom name="//unnamed_geom_3" class="reward_collision_sphere" size="0.0543497" pos="-0.0418115 0 0"/>
        <body name="femur_RR" pos="0.0735645 -0.0139796 0.00109777" quat="0.500226 -0.499937 0.499288 0.500549">
          <inertial pos="0.0131289 0.00076147 0.0142489" quat="0.997741 -0.0337352 0.0551353 -0.0182978" mass="0.56062" diaginertia="0.0585303 0.0682397 0.0342276"/>
          <joint name="femur_joint_RR" class="/" pos="0 0 0" axis="-0.00103315 0.0300557 -0.999548" range="-3.07201 3.11343" armature="0.0132935" damping="0" frictionloss="0.0143042"/>
          <geom name="//unnamed_geom_4" class="/" type="mesh" rgba="0.9 0.9 0.9 1" mesh="femur"/>
          <geom name="//unnamed_geom_5" class="reward_collision_sphere" size="0.0543497"/>
          <body name="tibia_RR" pos="-0.00644611 -0.156386 0.0128267" quat="-2.01417e-05 1 1.34932e-05 5.7926e-05">
            <inertial pos="0.00103056 0.00086733 0.0109022" quat="0.999365 0.00883629 0.0169931 0.0300369" mass="0.382305" diaginertia="0.0440238 0.0440758 0.0249539"/>
            <joint name="tibia_joint_RR" class="/" pos="0 0 0" axis="-0.0493366 0.0101897 0.99873" stiffness="0.0332841" range="-2.99326 3.13407" armature="0.0175144" damping="0.00989322" frictionloss="0.0200624"/>
            <geom name="//unnamed_geom_6" class="/" type="mesh" rgba="0.2 0.2 0.2 1" mesh="tibia"/>
            <geom name="//unnamed_geom_7" class="reward_collision_sphere" size="0.0543497"/>
            <body name="tarsus_RR" pos="0.122471 -0.00497515 0.00234567" quat="1 -0.000511135 7.7256e-05 4.11142e-05">
              <inertial pos="0.0890113 -0.000378749 0.00151848" quat="0.472526 0.551677 0.503998 0.467288" mass="0.450941" diaginertia="0.0538144 0.0675189 0.0285002"/>
              <joint name="tarsus_joint_RR" class="/" pos="0 0 0" axis="0.0175018 -0.0663165 0.997645" range="-3.13733 3.29628" armature="0.0170826" damping="0.0196638" frictionloss="0.0112841"/>
              <geom name="//unnamed_geom_8" class="/" type="mesh" rgba="0.9 0.9 0.9 1" mesh="tarsus"/>
              <geom name="foot_1" class="foot" size="0.0146238" pos="0.156096 0 0" quat="0 -0.707107 0 0.707107"/>
              <geom name="//unnamed_geom_10" class="reward_collision_sphere" size="0.0543497"/>
              <geom name="//unnamed_geom_11" class="reward_collision_sphere" size="0.0203811" pos="0.149824 0 0"/>
              <site name="foot_1" class="foot" pos="0.156096 0 0" quat="0 -0.707107 0 0.707107" size="0.0135874"/>
            </body>
          </body>
        </body>
      </body>
      <body name="coxa_RM" pos="0.00137072 -0.202461 0.0799246" quat="0.710098 -0.00242124 -0.00482571 -0.704082">
        <inertial pos="0.0101761 0.000779752 0.0119703" quat="0.99894 0.0373349 0.0261051 0.0065309" mass="0.495067" diaginertia="0.0669698 0.0609059 0.0335918"/>
        <joint name="coxa_joint_RM" class="/" pos="0 0 0" axis="0.0121282 0.00286747 -0.999922" range="-3.0947 3.15776" armature="0.0126691" damping="0.0145476" frictionloss="0.0172426"/>
        <geom name="//unnamed_geom_12" class="/" type="mesh" rgba="0.2 0.2 0.2 1" mesh="coxa"/>
        <geom name="//unnamed_geom_13" class="reward_collision_sphere" size="0.0543497" pos="-0.0418115 0 0"/>
        <body name="femur_RM" pos="0.0724398 0.00157005 0.0105699" quat="0.499389 -0.502052 0.501915 0.496625">
          <inertial pos="-0.0122919 0.000983263 0.000140916" quat="0.997886 -0.053415 -0.0197723 0.0312832" mass="0.522685" diaginertia="0.05088 0.069044 0.0309729"/>
          <joint name="femur_joint_RM" class="/" pos="0 0 0" axis="0.0233478 0.0448524 -0.998721" stiffness="0.0352359" range="-3.12529 3.11195" armature="0.010711" damping="0" frictionloss="0.0140399"/>
          <geom name="//unnamed_geom_14" class="/" type="mesh" rgba="0.9 0.9 0.9 1" mesh="femur"/>
          <geom name="//unnamed_geom_15" class="reward_collision_sphere" size="0.0543497"/>
          <body name="tibia_RM" pos="-0.00632363 -0.155634 -0.0021143" quat="9.8648e-05 1 -0.000152849 0.000663348">
            <inertial pos="0.0130631 -0.00502145 0.00730762" quat="0.999967 0.00284081 -0.00405831 -0.00642432" mass="0.440431" diaginertia="0.0444283 0.0651782 0.0336728"/>
            <joint name="tibia_joint_RM" class="/" pos="0 0 0" axis="-0.0290465 0.0277358 0.999193" stiffness="0.0127073" range="-3.13113 3.23704" armature="0.0140303" damping="0.0249902" frictionloss="0.0167877"/>
            <geom name="//unnamed_geom_16" class="/" type="mesh" rgba="0.2 0.2 0.2 1" mesh="tibia"/>
            <geom name="//unnamed_geom_17" class="reward_collision_sphere" size="0.0543497"/>
            <body name="tarsus_RM" pos="0.114009 -0.00516891 -0.00190165" quat="1 -7.52545e-05 4.74519e-06 2.03879e-05">
              <inertial pos="0.0862929 0.00381698 0.000523066" quat="0.492181 0.509004 0.498148 0.500521" mass="0.474042" diaginertia="0.0569782 0.0570571 0.0253495"/>
              <joint name="tarsus_joint_RM" class="/" pos="0 0 0" axis="-0.0225055 -0.0415424 0.998883" range="-3.14158 3.15184" armature="0.0139457" damping="0.00356782" frictionloss="0.0134742"/>
              <geom name="//unnamed_geom_18" class="/" type="mesh" rgba="0.9 0.9 0.9 1" mesh="tarsus"/>
              <geom name="foot_2" class="foot" size="0.0194895" pos="0.156096 0 0" quat="0 -0.707107 0 0.707107"/>
              <geom name="//unnamed_geom_20" class="reward_collision_sphere" size="0.0543497"/>
              <geom name="//unnamed_geom_21" class="reward_collision_sphere" size="0.0203811" pos="0.149824 0 0"/>
              <site name="foot_2" class="foot" pos="0.156096 0 0" quat="0 -0.707107 0 0.707107" size="0.0135874"/>
            </body>
          </body>
        </body>
      </body>
      <body name="coxa_RF" pos="0.24725 -0.130182 0.0851799" quat="0.923918 -0.000176098 -0.000115591 -0.382591">
        <inertial pos="0.0138974 -0.001814 0.000716784" quat="0.998614 0.0026767 0.018469 -0.0492217" mass="0.383427" diaginertia="0.0448311 0.0659392 0.0278773"/>
        <joint name="coxa_joint_RF" class="/" pos="0 0 0" axis="-0.000282921 -0.00300069 -0.999995" range="-3.0341 3.15399" armature="0.00775555" damping="0.0235071" frictionloss="0.0163663"/>
        <geom name="//unnamed_geom_22" class="/" type="mesh" rgba="0.2 0.2 0.2 1" mesh="coxa"/>
        <geom name="//unnamed_geom_23" class="reward_collision_sphere" size="0.0543497" pos="-0.0418115 0 0"/>
        <body name="femur_RF" pos="0.0809327 -0.00333627 -0.012114" quat="0.498635 -0.499551 0.501239 0.500571">
          <inertial pos="-0.00693768 -0.0130103 -0.00654254" quat="0.999999 -0.0012364 0.000489591 -0.00101985" mass="0.562069" diaginertia="0.0481751 0.0699696 0.0309529"/>
          <joint name="femur_joint_RF" class="/" pos="0 0 0" axis="-0.021361 -0.0321159 -0.999256" stiffness="0.0633805" range="-3.17249 3.30244" armature="0.0145414" damping="0" frictionloss="0.0156622"/>
          <geom name="//unnamed_geom_24" class="/" type="mesh" rgba="0.9 0.9 0.9 1" mesh="femur"/>
          <geom name="//unnamed_geom_25" class="reward_collision_sphere" size="0.0543497"/>
          <body name="tibia_RF" pos="0.00605118 -0.164823 -0.00978722" quat="4.0114e-06 1 1.57736e-05 6.24182e-06">
            <inertial pos="0.0116671 0.00868592 -0.0105946" quat="0.999395 -0.00349972 -0.0345034 0.00274922" mass="0.448678" diaginertia="0.05208 0.0611468 0.0306511"/>
            <joint name="tibia_joint_RF" class="/" pos="0 0 0" axis="-0.011777 -0.00165387 0.999929" range="-3.14347 3.31658" armature="0.0134923" damping="0.0774651" frictionloss="0.0136855"/>
            <geom name="//unnamed_geom_26" class="/" type="mesh" rgba="0.2 0.2 0.2 1" mesh="tibia"/>
            <geom name="//unnamed_geom_27" class="reward_collision_sphere" size="0.0543497"/>
            <body name="tarsus_RF" pos="0.112511 -0.0117988 0.0112765" quat="0.999991 -0.00380407 -0.0013404 0.000940467">
              <inertial pos="0.0840009 -0.000117218 -0.000841464" quat="0.507075 0.493528 0.505711 0.493519" mass="0.466873" diaginertia="0.0482178 0.0498898 0.0334265"/>
              <joint name="tarsus_joint_RF" class="/" pos="0 0 0" axis="0.022102 0.00218279 0.999753" stiffness="0.0182481" range="-3.01051 3.16493" armature="0.00713926" damping="0" frictionloss="0.00408907"/>
              <geom name="//unnamed_geom_28" class="/" type="mesh" rgba="0.9 0.9 0.9 1" mesh="tarsus"/>
              <geom name="foot_3" class="foot" size="0.0072994" pos="0.156096 0 0" quat="0 -0.707107 0 0.707107"/>
              <geom name="//unnamed_geom_30" class="reward_collision_sphere" size="0.0543497"/>
              <geom name="//unnamed_geom_31" class="reward_collision_sphere" size="0.0203811" pos="0.149824 0 0"/>
              <site name="foot_3" class="foot" pos="0.156096 0 0" quat="0 -0.707107 0 0.707107" size="0.0135874"/>
            </body>
          </body>
        </body>
      </body>
      <body name="coxa_LR" pos="-0.252194 0.115377 0.0886635" quat="0.379474 0.00105847 -0.00467567 0.92519">
        <inertial pos="0.00152516 -0.00283081 0.0134693" quat="0.998858 0.0201699 -0.0117302 -0.0416863" mass="0.671082" diaginertia="0.0627597 0.0712709 0.0347362"/>
        <joint name="coxa_joint_LR" class="/" pos="0 0 0" axis="0.000272408 -0.00279075 -0.999996" range="-3.06753 2.86682" armature="0.00709009" damping="0" frictionloss="0.0227977"/>
        <geom name="//unnamed_geom_32" class="/" type="mesh" rgba="0.2 0.2 0.2 1" mesh="coxa"/>
        <geom name="//unnamed_geom_33" class="reward_collision_sphere" size="0.0543497" pos="-0.0418115 0 0"/>
        <body name="femur_LR" pos="0.082144 -0.00768969 0.00228359" quat="0.500024 -0.500084 0.499855 0.500038">
          <inertial pos="1.17095e-05 0.000391292 0.000764662" quat="0.999397 -0.024211 -0.00912233 0.0231593" mass="0.546718" diaginertia="0.0606942 0.0545354 0.0325434"/>
          <joint name="femur_joint_LR" class="/" pos="0 0 0" axis="0.00650761 0.0180273 0.999816" stiffness="0.0385315" range="-3.13408 3.3291" armature="0.00837979" damping="0" frictionloss="0.0160653"/>
          <geom name="//unnamed_geom_34" class="/" type="mesh" rgba="0.9 0.9 0.9 1" mesh="femur"/>
          <geom name="//unnamed_geom_35" class="reward_collision_sphere" size="0.0543497"/>
          <body name="tibia_LR" pos="0.010358 -0.1552 0.00358844" quat="0.00105587 0.999989 0.0028284 0.00369798">
            <inertial pos="-0.00770822 -0.0125669 0.0005226" quat="0.99878 -0.0267597 0.0319316 0.0264964" mass="0.55897" diaginertia="0.0435999 0.0533689 0.0353957"/>
            <joint name="tibia_joint_LR" class="/" pos="0 0 0" axis="0.00926539 -0.00656587 -0.999936" range="-3.15983 3.11443" armature="0.0107024" damping="0" frictionloss="0.00892238"/>
            <geom name="//unnamed_geom_36" class="/" type="mesh" rgba="0.2 0.2 0.2 1" mesh="tibia"/>
            <geom name="//unnamed_geom_37" class="reward_collision_sphere" size="0.0543497"/>
            <body name="tarsus_LR" pos="0.111074 0.00432228 0.0060893" quat="0.999996 0.000929074 -0.00131576 0.00221996">
              <inertial pos="0.089679 0.00767198 0.00426011" quat="0.475341 0.507706 0.511802 0.504326" mass="0.599199" diaginertia="0.0633309 0.0731684 0.035632"/>
              <joint name="tarsus_joint_LR" class="/" pos="0 0 0" axis="-0.000521838 0.00549724 -0.999985" range="-3.10491 3.18506" armature="0.023418" damping="0.0160829" frictionloss="0.0165182"/>
              <geom name="//unnamed_geom_38" class="/" type="mesh" rgba="0.9 0.9 0.9 1" mesh="tarsus"/>
              <geom name="foot_4" class="foot" size="0.0122661" pos="0.156096 0 0" quat="0.707107 0 -0.707107 0"/>
              <geom name="//unnamed_geom_40" class="reward_collision_sphere" size="0.0543497"/>
              <geom name="//unnamed_geom_41" class="reward_collision_sphere" size="0.0203811" pos="0.149824 0 0"/>
              <site name="foot_4" class="foot" pos="0.156096 0 0" quat="0.707107 0 -0.707107 0" size="0.0135874"/>
            </body>
          </body>
        </body>
      </body>
      <body name="coxa_LM" pos="0.00816842 0.193596 0.0795957" quat="0.708814 -0.00669912 0.00190374 0.705361">
        <inertial pos="-0.0105132 0.0115676 0.00715887" quat="0.998662 0.0180879 -0.00284763 -0.0483627" mass="0.488643" diaginertia="0.0543611 0.0550616 0.0274284"/>
        <joint name="coxa_joint_LM" class="/" pos="0 0 0" axis="-0.00634662 -0.000783447 -0.99998" range="-3.16065 3.15933" armature="0.00460068" damping="0.0398196" frictionloss="0.0109039"/>
        <geom name="//unnamed_geom_42" class="/" type="mesh" rgba="0.2 0.2 0.2 1" mesh="coxa"/>
        <geom name="//unnamed_geom_43" class="reward_collision_sphere" size="0.0543497" pos="-0.0418115 0 0"/>
        <body name="femur_LM" pos="0.069658 -0.00177727 0.0069746" quat="0.501994 -0.502478 0.498335 0.497172">
          <inertial pos="0.0101406 -0.000617464 0.0116584" quat="0.999358 -0.0281564 -0.0216286 0.00484153" mass="0.383853" diaginertia="0.0483603 0.0537092 0.0269701"/>
          <joint name="femur_joint_LM" class="/" pos="0 0 0" axis="0.00069282 -0.00272645 0.999996" range="-3.2943 3.07198" armature="0.00782877" damping="0.0337234" frictionloss="0.0139017"/>
          <geom name="//unnamed_geom_44" class="/" type="mesh" rgba="0.9 0.9 0.9 1" mesh="femur"/>
          <geom name="//unnamed_geom_45" class="reward_collision_sphere" size="0.0543497"/>
          <body name="tibia_LM" pos="-0.00792864 -0.159492 -0.0016831" quat="-0.000245702 0.999998 -0.00131327 0.00122157">
            <inertial pos="-0.0131862 -0.0138225 -0.0142183" quat="0.999983 0.00558811 0.000738108 0.00174147" mass="0.494916" diaginertia="0.0562134 0.0695277 0.0267025"/>
            <joint name="tibia_joint_LM" class="/" pos="0 0 0" axis="-0.0146631 0.0302972 -0.999433" stiffness="0.0447583" range="-3.20758 3.16469" armature="0.00772121" damping="0" frictionloss="0.0200068"/>
            <geom name="//unnamed_geom_46" class="/" type="mesh" rgba="0.2 0.2 0.2 1" mesh="tibia"/>
            <geom name="//unnamed_geom_47" class="reward_collision_sphere" size="0.0543497"/>
            <body name="tarsus_LM" pos="0.127233 0.0109275 -0.0100072" quat="0.999992 0.0036785 -0.000599148 0.00153884">
              <inertial pos="0.0790224 -0.00512299 -0.00754319" quat="0.500146 0.497868 0.498917 0.503054" mass="0.420464" diaginertia="0.0506426 0.041429 0.0267781"/>
              <joint name="tarsus_joint_LM" class="/" pos="0 0 0" axis="-0.0497335 0.00388936 -0.998755" range="-2.84017 3.11835" armature="0.01297" damping="0" frictionloss="0.0144021"/>
              <geom name="//unnamed_geom_48" class="/" type="mesh" rgba="0.9 0.9 0.9 1" mesh="tarsus"/>
              <geom name="foot_5" class="foot" size="0.014372" pos="0.156096 0 0" quat="0.707107 0 -0.707107 0"/>
              <geom name="//unnamed_geom_50" class="reward_collision_sphere" size="0.0543497"/>
              <geom name="//unnamed_geom_51" class="reward_collision_sphere" size="0.0203811" pos="0.149824 0 0"/>
              <site name="foot_5" class="foot" pos="0.156096 0 0" quat="0.707107 0 -0.707107 0" size="0.0135874"/>
            </body>
          </body>
        </body>
      </body>
      <body name="coxa_LF" pos="0.240022 0.125567 0.0806488" quat="0.924856 0.00201102 -0.00494046 0.38028">
        <inertial pos="-0.000748477 -0.0134793 -0.000785128" quat="0.999999 0.00125912 -0.000147625 0.000238794" mass="0.46789" diaginertia="0.0477225 0.0445437 0.0253486"/>
        <joint name="coxa_joint_LF" class="/" pos="0 0 0" axis="0.0100609 0.0379439 -0.999229" range="-3.11261 3.13236" armature="0.00420004" damping="0.00274483" frictionloss="0.0111527"/>
        <geom name="//unnamed_geom_52" class="/" type="mesh" rgba="0.2 0.2 0.2 1" mesh="coxa"/>
        <geom name="//unnamed_geom_53" class="reward_collision_sphere" size="0.0543497" pos="-0.0418115 0 0"/>
        <body name="femur_LF" pos="0.0863111 0.0149594 0.0125533" quat="0.496633 -0.502631 0.498495 0.502217">
          <inertial pos="-0.00839195 0.00220984 -0.0141892" quat="0.998435 -0.0203196 -0.0407144 -0.0325014" mass="0.499171" diaginertia="0.0578961 0.0501835 0.0304412"/>
          <joint name="femur_joint_LF" class="/" pos="0 0 0" axis="-0.0466189 -0.0115704 0.998846" stiffness="0.0501102" range="-3.16064 3.39895" armature="0.0148345" damping="0.0474257" frictionloss="0.0116164"/>
          <geom name="//unnamed_geom_54" class="/" type="mesh" rgba="0.9 0.9 0.9 1" mesh="femur"/>
          <geom name="//unnamed_geom_55" class="reward_collision_sphere" size="0.0543497"/>
          <body name="tibia_LF" pos="0.00908056 -0.148767 0.00033207" quat="0.00392513 0.999984 -0.00394247 0.00115721">
            <inertial pos="-0.00266762 0.0125724 -0.000148585" quat="0.999967 -0.00791941 0.00132944 -0.000937376" mass="0.501648" diaginertia="0.0574765 0.0617336 0.0319429"/>
            <joint name="tibia_joint_LF" class="/" pos="0 0 0" axis="-0.0524704 0.00114323 -0.998622" stiffness="0.00168018" range="-2.92789 3.13588" armature="0.00852116" damping="0.0124187" frictionloss="0.00546745"/>
            <geom name="//unnamed_geom_56" class="/" type="mesh" rgba="0.2 0.2 0.2 1" mesh="tibia"/>
            <geom name="//unnamed_geom_57" class="reward_collision_sphere" size="0.0543497"/>
            <body name="tarsus_LF" pos="0.125005 -0.00778969 0.00544209" quat="0.999974 0.000686226 -0.00662075 0.00292299">
              <inertial pos="0.0916813 0.00162807 -6.29432e-05" quat="0.498646 0.499816 0.502168 0.499362" mass="0.484159" diaginertia="0.0557616 0.0636835 0.0342602"/>
              <joint name="tarsus_joint_LF" class="/" pos="0 0 0" axis="-0.0585927 -0.0400348 -0.997479" range="-3.22822 3.34827" armature="0.0106539" damping="0.0669015" frictionloss="0.0093107"/>
              <geom name="//unnamed_geom_58" class="/" type="mesh" rgba="0.9 0.9 0.9 1" mesh="tarsus"/>
              <geom name="foot_6" class="foot" size="0.0189758" pos="0.156096 0 0" quat="0.707107 0 -0.707107 0"/>
              <geom name="//unnamed_geom_60" class="reward_collision_sphere" size="0.0543497"/>
              <geom name="//unnamed_geom_61" class="reward_collision_sphere" size="0.0203811" pos="0.149824 0 0"/>
              <site name="foot_6" class="foot" pos="0.156096 0 0" quat="0.707107 0 -0.707107 0" size="0.0135874"/>
            </body>
          </body>
        </body>
      </body>
    </body>
  </worldbody>

  <contact>
    <pair class="/" geom1="floor" geom2="foot_1" name="//unnamed_contact_0"/>
    <pair class="/" geom1="floor" geom2="foot_2" name="//unnamed_contact_1"/>
    <pair class="/" geom1="floor" geom2="foot_3" name="//unnamed_contact_2"/>
    <pair class="/" geom1="floor" geom2="foot_4" name="//unnamed_contact_3"/>
    <pair class="/" geom1="floor" geom2="foot_5" name="//unnamed_contact_4"/>
    <pair class="/" geom1="floor" geom2="foot_6" name="//unnamed_contact_5"/>
  </contact>

  <actuator>
    <general name="coxa_joint_RR" class="/" joint="coxa_joint_RR" forcerange="-14.6421 14.6421" gainprm="29.854" biasprm="0 -29.854 -0.806559"/>
    <general name="femur_joint_RR" class="/" joint="femur_joint_RR" forcerange="-7.74517 7.74517" gainprm="29.854" biasprm="0 -29.854 -0.806559"/>
    <general name="tibia_joint_RR" class="/" joint="tibia_joint_RR" forcerange="-15.0626 15.0626" gainprm="29.854" biasprm="0 -29.854 -0.806559"/>
    <general name="tarsus_joint_RR" class="/" joint="tarsus_joint_RR" forcerange="-7.40822 7.40822" gainprm="29.854" biasprm="0 -29.854 -0.806559"/>
    <general name="coxa_joint_RM" class="/" joint="coxa_joint_RM" forcerange="-10.0525 10.0525" gainprm="29.854" biasprm="0 -29.854 -0.806559"/>
    <general name="femur_joint_RM" class="/" joint="femur_joint_RM" forcerange="-9.73781 9.73781" gainprm="29.854" biasprm="0 -29.854 -0.806559"/>
    <general name="tibia_joint_RM" class="/" joint="tibia_joint_RM" forcerange="-14.2471 14.2471" gainprm="29.854" biasprm="0 -29.854 -0.806559"/>
    <general name="tarsus_joint_RM" class="/" joint="tarsus_joint_RM" forcerange="-4.93022 4.93022" gainprm="29.854" biasprm="0 -29.854 -0.806559"/>
    <general name="coxa_joint_RF" class="/" joint="coxa_joint_RF" forcerange="-8.98155 8.98155" gainprm="29.854" biasprm="0 -29.854 -0.806559"/>
    <general name="femur_joint_RF" class="/" joint="femur_joint_RF" forcerange="-9.7182 9.7182" gainprm="29.854" biasprm="0 -29.854 -0.806559"/>
    <general name="tibia_joint_RF" class="/" joint="tibia_joint_RF" forcerange="-5.31422 5.31422" gainprm="29.854" biasprm="0 -29.854 -0.806559"/>
    <general name="tarsus_joint_RF" class="/" joint="tarsus_joint_RF" forcerange="-7.83172 7.83172" gainprm="29.854" biasprm="0 -29.854 -0.806559"/>
    <general name="coxa_joint_LR" class="/" joint="coxa_joint_LR" forcerange="-10.1768 10.1768" gainprm="29.854" biasprm="0 -29.854 -0.806559"/>
    <general name="femur_joint_LR" class="/" joint="femur_joint_LR" forcerange="-13.7417 13.7417" gainprm="29.854" biasprm="0 -29.854 -0.806559"/>
    <general name="tibia_joint_LR" class="/" joint="tibia_joint_LR" forcerange="-11.9694 11.9694" gainprm="29.854" biasprm="0 -29.854 -0.806559"/>
    <general name="tarsus_joint_LR" class="/" joint="tarsus_joint_LR" forcerange="-12.9731 12.9731" gainprm="29.854" biasprm="0 -29.854 -0.806559"/>
    <general name="coxa_joint_LM" class="/" joint="coxa_joint_LM" forcerange="-11.9713 11.9713" gainprm="29.854" biasprm="0 -29.854 -0.806559"/>
    <general name="femur_joint_LM" class="/" joint="femur_joint_LM" forcerange="-11.19 11.19" gainprm="29.854" biasprm="0 -29.854 -0.806559"/>
    <general name="tibia_joint_LM" class="/" joint="tibia_joint_LM" forcerange="-13.2799 13.2799" gainprm="29.854" biasprm="0 -29.854 -0.806559"/>
    <general name="tarsus_joint_LM" class="/" joint="tarsus_joint_LM" forcerange="-10.8097 10.8097" gainprm="29.854" biasprm="0 -29.854 -0.806559"/>
    <general name="coxa_joint_LF" class="/" joint="coxa_joint_LF" forcerange="-11.5983 11.5983" gainprm="29.854" biasprm="0 -29.854 -0.806559"/>
    <general name="femur_joint_LF" class="/" joint="femur_joint_LF" forcerange="-8.78488 8.78488" gainprm="29.854" biasprm="0 -29.854 -0.806559"/>
    <general name="tibia_joint_LF" class="/" joint="tibia_joint_LF" forcerange="-6.81449 6.81449" gainprm="29.854" biasprm="0 -29.854 -0.806559"/>
    <general name="tarsus_joint_LF" class="/" joint="tarsus_joint_LF" forcerange="-11.9047 11.9047" gainprm="29.854" biasprm="0 -29.854 -0.806559"/>
  </actuator>

  <sensor>
    <gyro site="imu" name="imu_angular_velocity"/>
    <velocimeter site="imu" name="imu_linear_velocity"/>
    <framelinvel objtype="site" objname="foot_1" name="foot_1_global_linear_velocity"/>
    <framelinvel objtype="site" objname="foot_2" name="foot_2_global_linear_velocity"/>
    <framelinvel objtype="site" objname="foot_3" name="foot_3_global_linear_velocity"/>
    <framelinvel objtype="site" objname="foot_4" name="foot_4_global_linear_velocity"/>
    <framelinvel objtype="site" objname="foot_5" name="foot_5_global_linear_velocity"/>
    <framelinvel objtype="site" objname="foot_6" name="foot_6_global_linear_velocity"/>
  </sensor>

  <keyframe>
    <key name="home" qpos="0 0 0.1457 1 0 0 0 0 0 0 0 0 0 0 0 0 0 0 0 0 0 0 0 0 0 0 0 0 0 0 0"/>
  </keyframe>
</mujoco>
