<mujoco model="Golem">
  <compiler angle="radian" assetdir="assets" balanceinertia="true" inertiafromgeom="false"/>

  <option timestep="0.005" density="1.2" viscosity="2e-05"/>

  <size nkey="1"/>

  <visual>
    <quality shadowsize="8192"/>
    <map shadowclip="0.5"/>
  </visual>

  <default>
    <default class="/">
      <joint armature="0.01" damping="0.01" frictionloss="0.01"/>
      <geom contype="0" conaffinity="0" group="1" solref="-1000 -80"/>
      <site size="0.01 0.005 0.005" group="5"/>
      <general forcelimited="true" biastype="affine" gainprm="25" biasprm="0 -25 -0.5"/>
      <default class="visual">
        <geom type="mesh" group="2"/>
      </default>
      <default class="collision">
        <geom group="3"/>
      </default>
      <default class="foot">
        <geom size="0.01 0 0" condim="6" group="4" priority="1" solimp="0.015 1 0.01"/>
      </default>
      <default class="reward_collision_sphere">
        <geom group="5" rgba="1 0 0 1"/>
      </default>
    </default>
  </default>

  <asset>
    <texture type="skybox" colorspace="auto" name="//unnamed_texture_0" builtin="gradient" rgb1="0.95 0.95 0.95" rgb2="0.95 0.95 0.95" width="100" height="600"/>
    <texture type="2d" colorspace="auto" name="texplane" builtin="checker" rgb1="0.345 0.575 0.748" rgb2="0.345 0.575 0.748" markrgb="1 1 1" width="512" height="512"/>
    <material name="MatPlane" class="/" texture="texplane" texuniform="true" texrepeat="2 2" specular="0.9"/>
    <mesh name="body" class="/" file="body.stl" scale="0.001 0.001 0.001"/>
    <mesh name="coxa" class="/" file="coxa.stl" scale="0.001 0.001 0.001"/>
    <mesh name="femur" class="/" file="femur.stl" scale="0.001 0.001 0.001"/>
    <mesh name="tibia" class="/" file="tibia.stl" scale="0.001 0.001 0.001"/>
    <mesh name="tarsus" class="/" file="tarsus.stl" scale="0.001 0.001 0.001"/>
  </asset>

  <worldbody>
    <geom name="floor" class="/" size="100 100 0.125" type="plane" group="0" material="MatPlane"/>
    <light name="toplight_shadow" class="/" pos="0 0 5" dir="0.0990148 0.0990148 -0.990148" type="directional" ambient="0.04 0.04 0.04" diffuse="0.55 0.55 0.55" specular="0.12 0.12 0.12"/>
    <light name="toplight_fill" class="/" pos="0 0 5" dir="0.0990148 0.0990148 -0.990148" type="directional" castshadow="false" ambient="0.04 0.04 0.04" diffuse="0.3 0.3 0.3" specular="0.08 0.08 0.08"/>
    <body name="trunk" pos="0.0129554 0.0121405 -0.00691327" quat="0.999987 0.00379826 -0.00318929 0.00140112">
      <inertial pos="-0.0128238 -0.00615754 0.017925" quat="0.998094 0.034532 -0.0490754 -0.0143978" mass="9.84454" diaginertia="0.0202713 0.0920206 0.0442368"/>
      <joint name="//unnamed_joint_0" type="free"/>
      <geom name="//unnamed_geom_1" class="/" pos="0 0 0.0922302" quat="1 0 0 0" type="mesh" rgba="0.9 0.9 0.9 1" mesh="body"/>
      <site name="imu" class="/" pos="0.0793712 -0.0646385 0.1591" size="0.014256"/>
      <camera name="track" class="/" pos="0 -3.27108 0" quat="0.707107 0.707107 0 0" mode="trackcom"/>
      <camera name="ego_camera" class="/" pos="0.15602 0 0.14411" quat="-0.5 -0.5 0.5 0.5"/>
      <body name="coxa_RR" pos="-0.204505 -0.120241 0.107948" quat="0.385914 -0.00065164 0.00262789 -0.922531">
        <inertial pos="0.00293331 -0.00639728 -0.00913902" quat="0.999889 -0.00773856 0.0125784 -0.00180682" mass="0.52524" diaginertia="0.025956 0.09899 0.0693348"/>
        <joint name="coxa_joint_RR" class="/" pos="0 0 0" axis="0.0116964 0.0176532 -0.999776" range="-3.17657 3.34023" armature="0.0192997" damping="0.0506628" frictionloss="0.0179267"/>
        <geom name="//unnamed_geom_2" class="/" type="mesh" rgba="0.2 0.2 0.2 1" mesh="coxa"/>
        <geom name="//unnamed_geom_3" class="reward_collision_sphere" size="0.0570239" pos="-0.0360046 0 0"/>
        <body name="femur_RR" pos="0.0571855 -0.0189319 0.0060323" quat="0.499314 -0.499682 0.500231 0.500771">
          <inertial pos="0.0180816 -0.00222087 0.0192158" quat="0.995765 0.0108728 0.0384479 0.0827959" mass="0.68661" diaginertia="0.0308792 0.146188 0.0788519"/>
          <joint name="femur_joint_RR" class="/" pos="0 0 0" axis="0.0276662 0.0469986 -0.998512" range="-2.97415 3.18277" armature="0.0170714" damping="0" frictionloss="0.0129581"/>
          <geom name="//unnamed_geom_4" class="/" type="mesh" rgba="0.9 0.9 0.9 1" mesh="femur"/>
          <geom name="//unnamed_geom_5" class="reward_collision_sphere" size="0.0570239"/>
          <body name="tibia_RR" pos="-0.0114129 -0.174057 0.0177922" quat="-0.00203927 0.999997 0.000750848 -0.00110164">
            <inertial pos="0.000620907 0.000846645 0.0158616" quat="0.998181 0.00181571 0.0407094 -0.044442" mass="0.381061" diaginertia="0.0203932 0.0727031 0.0453828"/>
            <joint name="tibia_joint_RR" class="/" pos="0 0 0" axis="-0.0747419 -0.00555977 0.997187" stiffness="0.0573935" range="-2.89436 3.11265" armature="0.0221226" damping="0.0307611" frictionloss="0.0245787"/>
            <geom name="//unnamed_geom_6" class="/" type="mesh" rgba="0.2 0.2 0.2 1" mesh="tibia"/>
            <geom name="//unnamed_geom_7" class="reward_collision_sphere" size="0.0570239"/>
            <body name="tarsus_RR" pos="0.100474 -0.00988902 -0.0017396" quat="0.999999 -0.000842283 0.0005907 -0.00123139">
              <inertial pos="0.0821099 0.00322611 -0.00293402" quat="0.430423 0.533823 0.546075 0.481219" mass="0.50836" diaginertia="0.0251351 0.129208 0.0575902"/>
              <joint name="tarsus_joint_RR" class="/" pos="0 0 0" axis="0.0814206 0.0454754 0.995642" range="-3.04369 3.39513" armature="0.0212039" damping="3.17473e-05" frictionloss="0.0083516"/>
              <geom name="//unnamed_geom_8" class="/" type="mesh" rgba="0.9 0.9 0.9 1" mesh="tarsus"/>
              <geom name="foot_1" class="foot" size="0.0131071" pos="0.134417 0 0" quat="0 -0.707107 0 0.707107"/>
              <geom name="//unnamed_geom_10" class="reward_collision_sphere" size="0.0570239"/>
              <geom name="//unnamed_geom_11" class="reward_collision_sphere" size="0.021384" pos="0.129016 0 0"/>
              <site name="foot_1" class="foot" pos="0.134417 0 0" quat="0 -0.707107 0 0.707107" size="0.014256"/>
            </body>
          </body>
        </body>
      </body>
      <body name="coxa_RM" pos="0.00628976 -0.234056 0.0874536" quat="0.710874 0.00763125 -0.000118548 -0.703278">
        <inertial pos="0.0151275 -0.00353415 0.0169104" quat="0.997495 0.0435596 -0.0470562 0.0298797" mass="0.563168" diaginertia="0.0352868 0.115262 0.0775163"/>
        <joint name="coxa_joint_RM" class="/" pos="0 0 0" axis="-0.000508033 -0.00043264 -1" range="-2.99753 3.25346" armature="0.00963869" damping="0.036356" frictionloss="0.0215987"/>
        <geom name="//unnamed_geom_12" class="/" type="mesh" rgba="0.2 0.2 0.2 1" mesh="coxa"/>
        <geom name="//unnamed_geom_13" class="reward_collision_sphere" size="0.0570239" pos="-0.0360046 0 0"/>
        <body name="femur_RM" pos="0.0560738 0.00649785 0.0132221" quat="0.494525 -0.504049 0.500919 0.500459">
          <inertial pos="-0.0172514 -0.00280013 0.000780593" quat="0.995965 0.0516048 0.0428744 -0.0595944" mass="0.624911" diaginertia="0.022055 0.136695 0.0661174"/>
          <joint name="femur_joint_RM" class="/" pos="0 0 0" axis="-0.068229 -0.0318619 -0.997161" stiffness="0.0598983" range="-3.2151 3.18666" armature="0.0079615" damping="0" frictionloss="0.0181291"/>
          <geom name="//unnamed_geom_14" class="/" type="mesh" rgba="0.9 0.9 0.9 1" mesh="femur"/>
          <geom name="//unnamed_geom_15" class="reward_collision_sphere" size="0.0570239"/>
          <body name="tibia_RM" pos="-0.00492585 -0.181737 0.00158087" quat="-0.000472925 1 -0.000231505 0.00066395">
            <inertial pos="0.0180375 -0.00996003 0.0122416" quat="0.999479 0.027397 0.0126011 0.0114663" mass="0.444189" diaginertia="0.0183124 0.123711 0.0684982"/>
            <joint name="tibia_joint_RM" class="/" pos="0 0 0" axis="-0.0302756 -0.0571725 0.997905" stiffness="0.0372657" range="-3.22313 3.33543" armature="0.0117993" damping="0.000953371" frictionloss="0.0211195"/>
            <geom name="//unnamed_geom_16" class="/" type="mesh" rgba="0.2 0.2 0.2 1" mesh="tibia"/>
            <geom name="//unnamed_geom_17" class="reward_collision_sphere" size="0.0570239"/>
            <body name="tarsus_RM" pos="0.0939037 -0.0101036 -0.00680591" quat="0.999997 0.00114406 -0.000673833 0.00181601">
              <inertial pos="0.0794581 0.00868344 0.00518489" quat="0.492925 0.475086 0.524921 0.505743" mass="0.481649" diaginertia="0.026612 0.107695 0.0454705"/>
              <joint name="tarsus_joint_RM" class="/" pos="0 0 0" axis="-0.0014991 0.0720171 0.997402" range="-3.23566 3.1133" armature="0.014797" damping="0.0169169" frictionloss="0.0107804"/>
              <geom name="//unnamed_geom_18" class="/" type="mesh" rgba="0.9 0.9 0.9 1" mesh="tarsus"/>
              <geom name="foot_2" class="foot" size="0.0231181" pos="0.134417 0 0" quat="0 -0.707107 0 0.707107"/>
              <geom name="//unnamed_geom_20" class="reward_collision_sphere" size="0.0570239"/>
              <geom name="//unnamed_geom_21" class="reward_collision_sphere" size="0.021384" pos="0.129016 0 0"/>
              <site name="foot_2" class="foot" pos="0.134417 0 0" quat="0 -0.707107 0 0.707107" size="0.014256"/>
            </body>
          </body>
        </body>
      </body>
      <body name="coxa_RF" pos="0.211684 -0.151671 0.10234" quat="0.924158 -0.000571664 -0.000256011 -0.38201">
        <inertial pos="0.0188624 -0.00669274 -0.00406898" quat="0.997002 0.0128921 -0.00867403 -0.075803" mass="0.382276" diaginertia="0.0184879 0.124659 0.0559626"/>
        <joint name="coxa_joint_RF" class="/" pos="0 0 0" axis="-0.00294522 0.00112127 -0.999995" range="-2.93563 3.14292" armature="0.00482777" damping="0.0498119" frictionloss="0.0206704"/>
        <geom name="//unnamed_geom_22" class="/" type="mesh" rgba="0.2 0.2 0.2 1" mesh="coxa"/>
        <geom name="//unnamed_geom_23" class="reward_collision_sphere" size="0.0570239" pos="-0.0360046 0 0"/>
        <body name="femur_RF" pos="0.0738872 -0.00801225 -0.0168981" quat="0.499178 -0.501767 0.502292 0.496744">
          <inertial pos="-0.0118835 -0.0179718 -0.0114837" quat="0.999679 -0.0153111 0.0130773 -0.0153506" mass="0.656541" diaginertia="0.0203475 0.135676 0.0647255"/>
          <joint name="femur_joint_RF" class="/" pos="0 0 0" axis="-0.0549898 0.0311853 -0.998" stiffness="0.087844" range="-3.26957 3.40146" armature="0.0129199" damping="0" frictionloss="0.0199136"/>
          <geom name="//unnamed_geom_24" class="/" type="mesh" rgba="0.9 0.9 0.9 1" mesh="femur"/>
          <geom name="//unnamed_geom_25" class="reward_collision_sphere" size="0.0570239"/>
          <body name="tibia_RF" pos="0.0105272 -0.191363 -0.0146717" quat="0.0013511 0.999997 0.000290973 0.00192626">
            <inertial pos="0.0166186 0.0136068 -0.0155038" quat="0.998231 0.0581761 -0.0115431 -0.00416888" mass="0.480434" diaginertia="0.0258253 0.110044 0.0595214"/>
            <joint name="tibia_joint_RF" class="/" pos="0 0 0" axis="-0.0309114 -0.0140784 0.999423" range="-3.23523 3.41578" armature="0.0173415" damping="0.105916" frictionloss="0.0110396"/>
            <geom name="//unnamed_geom_26" class="/" type="mesh" rgba="0.2 0.2 0.2 1" mesh="tibia"/>
            <geom name="//unnamed_geom_27" class="reward_collision_sphere" size="0.0570239"/>
            <body name="tarsus_RF" pos="0.0905288 -0.0167495 0.0162557" quat="0.999978 0.00654061 0.000971192 7.64398e-05">
              <inertial pos="0.0765504 -0.00083214 0.00378739" quat="0.468031 0.508869 0.515927 0.505785" mass="0.525822" diaginertia="0.0222351 0.0924092 0.0758205"/>
              <joint name="tarsus_joint_RF" class="/" pos="0 0 0" axis="0.0415387 0.0215802 0.998904" stiffness="0.0404812" range="-2.91181 3.09783" armature="0.0041961" damping="0" frictionloss="0.000746702"/>
              <geom name="//unnamed_geom_28" class="/" type="mesh" rgba="0.9 0.9 0.9 1" mesh="tarsus"/>
              <geom name="foot_3" class="foot" size="0.00500962" pos="0.134417 0 0" quat="0 -0.707107 0 0.707107"/>
              <geom name="//unnamed_geom_30" class="reward_collision_sphere" size="0.0570239"/>
              <geom name="//unnamed_geom_31" class="reward_collision_sphere" size="0.021384" pos="0.129016 0 0"/>
              <site name="foot_3" class="foot" pos="0.134417 0 0" quat="0 -0.707107 0 0.707107" size="0.014256"/>
            </body>
          </body>
        </body>
      </body>
      <body name="coxa_LR" pos="-0.222617 0.127189 0.105542" quat="0.388356 -0.00545118 0.00166644 0.921492">
        <inertial pos="0.006371 -0.00773362 0.018454" quat="0.997369 0.0370721 -0.00550827 -0.0620589" mass="0.86051" diaginertia="0.0305665 0.149506 0.0706563"/>
        <joint name="coxa_joint_LR" class="/" pos="0 0 0" axis="0.00482514 0.00239629 -0.999985" range="-2.96969 2.76751" armature="0.00413642" damping="0" frictionloss="0.0274622"/>
        <geom name="//unnamed_geom_32" class="/" type="mesh" rgba="0.2 0.2 0.2 1" mesh="coxa"/>
        <geom name="//unnamed_geom_33" class="reward_collision_sphere" size="0.0570239" pos="-0.0360046 0 0"/>
        <body name="femur_LR" pos="0.0755219 -0.0125143 -0.00260746" quat="0.500211 -0.498616 0.499483 0.501686">
          <inertial pos="-0.0013664 0.00512403 0.00540905" quat="0.998235 0.0158241 -0.044269 -0.0362916" mass="0.6675" diaginertia="0.0321293 0.102309 0.0666953"/>
          <joint name="femur_joint_LR" class="/" pos="0 0 0" axis="-0.0417148 -0.011961 0.999058" stiffness="0.0630072" range="-3.22816 3.42827" armature="0.00549755" damping="0" frictionloss="0.0203456"/>
          <geom name="//unnamed_geom_34" class="/" type="mesh" rgba="0.9 0.9 0.9 1" mesh="femur"/>
          <geom name="//unnamed_geom_35" class="reward_collision_sphere" size="0.0570239"/>
          <body name="tibia_LR" pos="0.0153569 -0.181591 0.00843526" quat="-0.00340106 0.999974 -0.000544924 -0.00637227">
            <inertial pos="-0.0126444 -0.0175254 -0.00353933" quat="0.99725 -0.0611665 -0.0146705 0.0391779" mass="0.721578" diaginertia="0.020216 0.100767 0.0813549"/>
            <joint name="tibia_joint_LR" class="/" pos="0 0 0" axis="-0.00318007 -0.00057833 -0.999995" range="-3.07637 3.18626" armature="0.00750599" damping="0" frictionloss="0.00584359"/>
            <geom name="//unnamed_geom_36" class="/" type="mesh" rgba="0.2 0.2 0.2 1" mesh="tibia"/>
            <geom name="//unnamed_geom_37" class="reward_collision_sphere" size="0.0570239"/>
            <body name="tarsus_LR" pos="0.0891737 0.00909299 0.0110589" quat="0.999986 -0.00214548 0.00472013 -0.000484545">
              <inertial pos="0.0829604 0.0126089 0.00919957" quat="0.456879 0.529092 0.511899 0.499283" mass="0.771498" diaginertia="0.0334306 0.140418 0.078267"/>
              <joint name="tarsus_joint_LR" class="/" pos="0 0 0" axis="0.00219918 -0.0256096 -0.99967" stiffness="0.00320823" range="-3.00821 3.28214" armature="0.0283269" damping="0" frictionloss="0.0208281"/>
              <geom name="//unnamed_geom_38" class="/" type="mesh" rgba="0.9 0.9 0.9 1" mesh="tarsus"/>
              <geom name="foot_4" class="foot" size="0.0102745" pos="0.134417 0 0" quat="0.707107 0 -0.707107 0"/>
              <geom name="//unnamed_geom_40" class="reward_collision_sphere" size="0.0570239"/>
              <geom name="//unnamed_geom_41" class="reward_collision_sphere" size="0.021384" pos="0.129016 0 0"/>
              <site name="foot_4" class="foot" pos="0.134417 0 0" quat="0.707107 0 -0.707107 0" size="0.014256"/>
            </body>
          </body>
        </body>
      </body>
      <body name="coxa_LM" pos="0.0130307 0.225068 0.0870595" quat="0.711225 0.000643011 -0.00789312 0.70292">
        <inertial pos="-0.0154718 0.0165342 0.0120815" quat="0.997073 0.0177075 -0.0742589 0.00407329" mass="0.55705" diaginertia="0.0253354 0.0925553 0.0557128"/>
        <joint name="coxa_joint_LM" class="/" pos="0 0 0" axis="0.00140649 -0.00710365 -0.999974" range="-3.07312 3.0765" armature="0.00150775" damping="0.063393" frictionloss="0.0079477"/>
        <geom name="//unnamed_geom_42" class="/" type="mesh" rgba="0.2 0.2 0.2 1" mesh="coxa"/>
        <geom name="//unnamed_geom_43" class="reward_collision_sphere" size="0.0570239" pos="-0.0360046 0 0"/>
        <body name="femur_LM" pos="0.0532935 0.000751049 0.0102984" quat="0.502722 -0.501472 0.501815 0.493942">
          <inertial pos="0.0151077 0.000932166 0.0166254" quat="0.998168 -0.03937 -0.0394158 -0.02361" mass="0.382763" diaginertia="0.0225671 0.0901266 0.0520868"/>
          <joint name="femur_joint_LM" class="/" pos="0 0 0" axis="0.0131785 -0.0161927 0.999782" stiffness="0.0100157" range="-3.39321 2.97411" armature="0.00446747" damping="0.0620579" frictionloss="0.0133875"/>
          <geom name="//unnamed_geom_44" class="/" type="mesh" rgba="0.9 0.9 0.9 1" mesh="femur"/>
          <geom name="//unnamed_geom_45" class="reward_collision_sphere" size="0.0570239"/>
          <body name="tibia_LM" pos="-0.0123665 -0.185956 0.0014448" quat="0.00114713 0.999991 0.00395573 -0.00106232">
            <inertial pos="-0.0181339 -0.0187884 -0.0191914" quat="0.999892 0.000800098 -0.0117852 0.00879624" mass="0.624653" diaginertia="0.0297881 0.14891 0.0541969"/>
            <joint name="tibia_joint_LM" class="/" pos="0 0 0" axis="-0.0358767 0.0457379 -0.998309" stiffness="0.0693243" range="-3.30566 3.0846" armature="0.00433624" damping="0" frictionloss="0.0245244"/>
            <geom name="//unnamed_geom_46" class="/" type="mesh" rgba="0.2 0.2 0.2 1" mesh="tibia"/>
            <geom name="//unnamed_geom_47" class="reward_collision_sphere" size="0.0570239"/>
            <body name="tarsus_LM" pos="0.115235 0.0158635 -0.0149703" quat="0.999979 -0.00404577 0.00142111 0.00489344">
              <inertial pos="0.06251 -0.0100572 -0.0124999" quat="0.515887 0.493053 0.509674 0.480616" mass="0.449062" diaginertia="0.0233868 0.0679935 0.0540498"/>
              <joint name="tarsus_joint_LM" class="/" pos="0 0 0" axis="-0.0732122 -0.0144166 -0.997212" range="-2.74075 3.02204" armature="0.0125895" damping="0" frictionloss="0.0127655"/>
              <geom name="//unnamed_geom_48" class="/" type="mesh" rgba="0.9 0.9 0.9 1" mesh="tarsus"/>
              <geom name="foot_5" class="foot" size="0.0132941" pos="0.134417 0 0" quat="0.707107 0 -0.707107 0"/>
              <geom name="//unnamed_geom_50" class="reward_collision_sphere" size="0.0570239"/>
              <geom name="//unnamed_geom_51" class="reward_collision_sphere" size="0.021384" pos="0.129016 0 0"/>
              <site name="foot_5" class="foot" pos="0.134417 0 0" quat="0.707107 0 -0.707107 0" size="0.014256"/>
            </body>
          </body>
        </body>
      </body>
      <body name="coxa_LF" pos="0.200758 0.146914 0.0980111" quat="0.925557 0.00179541 -0.00689623 0.378541">
        <inertial pos="0.00268223 -0.0184406 0.00361551" quat="0.999761 -0.00278102 -0.00519334 0.0210565" mass="0.52754" diaginertia="0.0220869 0.073542 0.0457889"/>
        <joint name="coxa_joint_LF" class="/" pos="0 0 0" axis="-0.0141086 -0.0625094 -0.997945" range="-3.1821 3.0373" armature="0.00109165" damping="0" frictionloss="0.00821206"/>
        <geom name="//unnamed_geom_52" class="/" type="mesh" rgba="0.2 0.2 0.2 1" mesh="coxa"/>
        <geom name="//unnamed_geom_53" class="reward_collision_sphere" size="0.0570239" pos="-0.0360046 0 0"/>
        <body name="femur_LF" pos="0.0795639 0.0198708 0.0175672" quat="0.503258 -0.494326 0.49882 0.50354">
          <inertial pos="-0.0133596 0.00711495 -0.019157" quat="0.996741 0.0400925 -0.0315013 0.0625044" mass="0.543275" diaginertia="0.0290384 0.0892695 0.0666382"/>
          <joint name="femur_joint_LF" class="/" pos="0 0 0" axis="0.0661297 0.0301396 0.997356" stiffness="0.0529386" range="-3.07486 3.49832" armature="0.0138936" damping="0.0769575" frictionloss="0.00870753"/>
          <geom name="//unnamed_geom_54" class="/" type="mesh" rgba="0.9 0.9 0.9 1" mesh="femur"/>
          <geom name="//unnamed_geom_55" class="reward_collision_sphere" size="0.0570239"/>
          <body name="tibia_LF" pos="0.013721 -0.165521 -0.00419923" quat="-0.00612377 0.999967 -0.00398426 -0.00364298">
            <inertial pos="-0.00757719 0.0175337 0.00153586" quat="0.99948 0.00674838 -0.027451 -0.0154871" mass="0.597631" diaginertia="0.0280647 0.115804 0.0680035"/>
            <joint name="tibia_joint_LF" class="/" pos="0 0 0" axis="0.0642352 -0.0429737 -0.997009" stiffness="0.0216197" range="-2.82874 3.04171" armature="0.00562485" damping="0.010309" frictionloss="0.00220111"/>
            <geom name="//unnamed_geom_56" class="/" type="mesh" rgba="0.2 0.2 0.2 1" mesh="tibia"/>
            <geom name="//unnamed_geom_57" class="reward_collision_sphere" size="0.0570239"/>
            <body name="tarsus_LF" pos="0.110951 -0.0126222 0.0103798" quat="0.999952 -0.0038466 0.0026032 0.00858088">
              <inertial pos="0.0848627 0.00632104 0.00443003" quat="0.479532 0.516235 0.503724 0.499813" mass="0.545989" diaginertia="0.0259763 0.120123 0.069977"/>
              <joint name="tarsus_joint_LF" class="/" pos="0 0 0" axis="0.0916152 -0.0279104 -0.995403" range="-3.32648 3.44752" armature="0.00791182" damping="0.0864175" frictionloss="0.00625"/>
              <geom name="//unnamed_geom_58" class="/" type="mesh" rgba="0.9 0.9 0.9 1" mesh="tarsus"/>
              <geom name="foot_6" class="foot" size="0.0225679" pos="0.134417 0 0" quat="0.707107 0 -0.707107 0"/>
              <geom name="//unnamed_geom_60" class="reward_collision_sphere" size="0.0570239"/>
              <geom name="//unnamed_geom_61" class="reward_collision_sphere" size="0.021384" pos="0.129016 0 0"/>
              <site name="foot_6" class="foot" pos="0.134417 0 0" quat="0.707107 0 -0.707107 0" size="0.014256"/>
            </body>
          </body>
        </body>
      </body>
    </body>
  </worldbody>

  <contact>
    <pair class="/" geom1="floor" geom2="foot_1" name="//unnamed_contact_0"/>
    <pair class="/" geom1="floor" geom2="foot_2" name="//unnamed_contact_1"/>
    <pair class="/" geom1="floor" geom2="foot_3" name="//unnamed_contact_2"/>
    <pair class="/" geom1="floor" geom2="foot_4" name="//unnamed_contact_3"/>
    <pair class="/" geom1="floor" geom2="foot_5" name="//unnamed_contact_4"/>
    <pair class="/" geom1="floor" geom2="foot_6" name="//unnamed_contact_5"/>
  </contact>

  <actuator>
    <general name="coxa_joint_RR" class="/" joint="coxa_joint_RR" forcerange="-17.3002 17.3002" gainprm="27.2619" biasprm="0 -27.2619 -0.93565"/>
    <general name="femur_joint_RR" class="/" joint="femur_joint_RR" forcerange="-6.2025 6.2025" gainprm="27.2619" biasprm="0 -27.2619 -0.93565"/>
    <general name="tibia_joint_RR" class="/" joint="tibia_joint_RR" forcerange="-17.7423 17.7423" gainprm="27.2619" biasprm="0 -27.2619 -0.93565"/>
    <general name="tarsus_joint_RR" class="/" joint="tarsus_joint_RR" forcerange="-5.84581 5.84581" gainprm="27.2619" biasprm="0 -27.2619 -0.93565"/>
    <general name="coxa_joint_RM" class="/" joint="coxa_joint_RM" forcerange="-10.508 10.508" gainprm="27.2619" biasprm="0 -27.2619 -0.93565"/>
    <general name="femur_joint_RM" class="/" joint="femur_joint_RM" forcerange="-10.366 10.366" gainprm="27.2619" biasprm="0 -27.2619 -0.93565"/>
    <general name="tibia_joint_RM" class="/" joint="tibia_joint_RM" forcerange="-16.8844 16.8844" gainprm="27.2619" biasprm="0 -27.2619 -0.93565"/>
    <general name="tarsus_joint_RM" class="/" joint="tarsus_joint_RM" forcerange="-3.23438 3.23438" gainprm="27.2619" biasprm="0 -27.2619 -0.93565"/>
    <general name="coxa_joint_RF" class="/" joint="coxa_joint_RF" forcerange="-7.52443 7.52443" gainprm="27.2619" biasprm="0 -27.2619 -0.93565"/>
    <general name="femur_joint_RF" class="/" joint="femur_joint_RF" forcerange="-11.9675 11.9675" gainprm="27.2619" biasprm="0 -27.2619 -0.93565"/>
    <general name="tibia_joint_RF" class="/" joint="tibia_joint_RF" forcerange="-3.63821 3.63821" gainprm="27.2619" biasprm="0 -27.2619 -0.93565"/>
    <general name="tarsus_joint_RF" class="/" joint="tarsus_joint_RF" forcerange="-6.29434 6.29434" gainprm="27.2619" biasprm="0 -27.2619 -0.93565"/>
    <general name="coxa_joint_LR" class="/" joint="coxa_joint_LR" forcerange="-9.86149 9.86149" gainprm="27.2619" biasprm="0 -27.2619 -0.93565"/>
    <general name="femur_joint_LR" class="/" joint="femur_joint_LR" forcerange="-16.3521 16.3521" gainprm="27.2619" biasprm="0 -27.2619 -0.93565"/>
    <general name="tibia_joint_LR" class="/" joint="tibia_joint_LR" forcerange="-14.4805 14.4805" gainprm="27.2619" biasprm="0 -27.2619 -0.93565"/>
    <general name="tarsus_joint_LR" class="/" joint="tarsus_joint_LR" forcerange="-15.5423 15.5423" gainprm="27.2619" biasprm="0 -27.2619 -0.93565"/>
    <general name="coxa_joint_LM" class="/" joint="coxa_joint_LM" forcerange="-14.4822 14.4822" gainprm="27.2619" biasprm="0 -27.2619 -0.93565"/>
    <general name="femur_joint_LM" class="/" joint="femur_joint_LM" forcerange="-13.6494 13.6494" gainprm="27.2619" biasprm="0 -27.2619 -0.93565"/>
    <general name="tibia_joint_LM" class="/" joint="tibia_joint_LM" forcerange="-15.8657 15.8657" gainprm="27.2619" biasprm="0 -27.2619 -0.93565"/>
    <general name="tarsus_joint_LM" class="/" joint="tarsus_joint_LM" forcerange="-13.2398 13.2398" gainprm="27.2619" biasprm="0 -27.2619 -0.93565"/>
    <general name="coxa_joint_LF" class="/" joint="coxa_joint_LF" forcerange="-14.0859 14.0859" gainprm="27.2619" biasprm="0 -27.2619 -0.93565"/>
    <general name="femur_joint_LF" class="/" joint="femur_joint_LF" forcerange="-7.31047 7.31047" gainprm="27.2619" biasprm="0 -27.2619 -0.93565"/>
    <general name="tibia_joint_LF" class="/" joint="tibia_joint_LF" forcerange="-5.21864 5.21864" gainprm="27.2619" biasprm="0 -27.2619 -0.93565"/>
    <general name="tarsus_joint_LF" class="/" joint="tarsus_joint_LF" forcerange="-14.4113 14.4113" gainprm="27.2619" biasprm="0 -27.2619 -0.93565"/>
  </actuator>

  <sensor>
    <gyro site="imu" name="imu_angular_velocity"/>
    <velocimeter site="imu" name="imu_linear_velocity"/>
    <framelinvel objtype="site" objname="foot_1" name="foot_1_global_linear_velocity"/>
    <framelinvel objtype="site" objname="foot_2" name="foot_2_global_linear_velocity"/>
    <framelinvel objtype="site" objname="foot_3" name="foot_3_global_linear_velocity"/>
    <framelinvel objtype="site" objname="foot_4" name="foot_4_global_linear_velocity"/>
    <framelinvel objtype="site" objname="foot_5" name="foot_5_global_linear_velocity"/>
    <framelinvel objtype="site" objname="foot_6" name="foot_6_global_linear_velocity"/>
  </sensor>

  <keyframe>
    <key name="home" qpos="0 0 0.1457 1 0 0 0 0 0 0 0 0 0 0 0 0 0 0 0 0 0 0 0 0 0 0 0 0 0 0 0"/>
  </keyframe>
</mujoco>
