<mujoco model="Golem">
  <compiler angle="radian" assetdir="assets" balanceinertia="true" inertiafromgeom="false"/>

  <option timestep="0.005" density="1.2" viscosity="2e-05"/>

  <size nkey="1"/>

  <visual>
    <quality shadowsize="8192"/>
    <map shadowclip="0.5"/>
  </visual>

  <default>
    <default class="/">
      <joint armature="0.01" damping="0.01" frictionloss="0.01"/>
      <geom contype="0" conaffinity="0" group="1" solref="-1000 -80"/>
      <site size="0.01 0.005 0.005" group="5"/>
      <general forcelimited="true" biastype="affine" gainprm="25" biasprm="0 -25 -0.5"/>
      <default class="visual">
        <geom type="mesh" group="2"/>
      </default>
      <default class="collision">
        <geom group="3"/>
      </default>
      <default class="foot">
        <geom size="0.01 0 0" condim="6" group="4" priority="1" solimp="0.015 1 0.01"/>
      </default>
      <default class="reward_collision_sphere">
        <geom group="5" rgba="1 0 0 1"/>
      </default>
    </default>
  </default>

  <asset>
    <texture type="skybox" colorspace="auto" name="//unnamed_texture_0" builtin="gradient" rgb1="0.95 0.95 0.95" rgb2="0.95 0.95 0.95" width="100" height="600"/>
    <texture type="2d" colorspace="auto" name="texplane" builtin="checker" rgb1="0.345 0.575 0.748" rgb2="0.345 0.575 0.748" markrgb="1 1 1" width="512" height="512"/>
    <material name="MatPlane" class="/" texture="texplane" texuniform="true" texrepeat="2 2" specular="0.9"/>
    <mesh name="body" class="/" file="body.stl" scale="0.001 0.001 0.001"/>
    <mesh name="coxa" class="/" file="coxa.stl" scale="0.001 0.001 0.001"/>
    <mesh name="femur" class="/" file="femur.stl" scale="0.001 0.001 0.001"/>
    <mesh name="tibia" class="/" file="tibia.stl" scale="0.001 0.001 0.001"/>
    <mesh name="tarsus" class="/" file="tarsus.stl" scale="0.001 0.001 0.001"/>
  </asset>

  <worldbody>
    <geom name="floor" class="/" size="100 100 0.125" type="plane" group="0" material="MatPlane"/>
    <light name="toplight_shadow" class="/" pos="0 0 5" dir="0.0990148 0.0990148 -0.990148" type="directional" ambient="0.04 0.04 0.04" diffuse="0.55 0.55 0.55" specular="0.12 0.12 0.12"/>
    <light name="toplight_fill" class="/" pos="0 0 5" dir="0.0990148 0.0990148 -0.990148" type="directional" castshadow="false" ambient="0.04 0.04 0.04" diffuse="0.3 0.3 0.3" specular="0.08 0.08 0.08"/>
    <body name="trunk" pos="8.36475e-05 -0.000869657 -0.00239171" quat="1 -0.000481718 -0.000536511 0.000161693">
      <inertial pos="0.00318369 -0.00310623 -0.000332547" quat="0.999925 0.000371154 -0.0114806 0.00427435" mass="3.96228" diaginertia="0.00763667 0.00673132 0.0270453"/>
      <joint name="//unnamed_joint_0" type="free"/>
      <geom name="//unnamed_geom_1" class="/" pos="0 0 0.078108" quat="1 0 0 0" type="mesh" rgba="0.9 0.9 0.9 1" mesh="body"/>
      <site name="imu" class="/" pos="0.114246 0.00630859 0.118484" size="0.0103787"/>
      <camera name="track" class="/" pos="0 -1.87399 0" quat="0.707107 0.707107 0 0" mode="trackcom"/>
      <camera name="ego_camera" class="/" pos="0.124304 0 0.122044" quat="-0.5 -0.5 0.5 0.5"/>
      <body name="coxa_RR" pos="-0.170935 -0.0784841 0.0787153" quat="0.382999 -0.000313049 0.000204403 -0.923749">
        <inertial pos="0.00180067 0.00239826 -0.00244167" quat="0.999903 0.0029093 0.00178834 -0.0134727" mass="0.220413" diaginertia="0.0075707 0.00708589 0.0259238"/>
        <joint name="coxa_joint_RR" class="/" pos="0 0 0" axis="-0.00676367 -0.00476272 -0.999966" stiffness="0.00735357" range="-3.08355 3.09169" armature="0.0108117" damping="0" frictionloss="0.0117545"/>
        <geom name="//unnamed_geom_2" class="/" type="mesh" rgba="0.2 0.2 0.2 1" mesh="coxa"/>
        <geom name="//unnamed_geom_3" class="reward_collision_sphere" size="0.0415149" pos="-0.0286856 0 0"/>
        <body name="femur_RR" pos="0.0544234 -0.00216246 -0.00100068" quat="0.500008 -0.499995 0.500003 0.499994">
          <inertial pos="-0.000295745 -0.000474977 0.00269568" quat="0.999924 -0.0122935 0.000400269 0.000198453" mass="0.219529" diaginertia="0.00816727 0.00689838 0.0267497"/>
          <joint name="femur_joint_RR" class="/" pos="0 0 0" axis="0.000113646 -0.000526016 -1" range="-3.09099 3.08993" armature="0.0109579" damping="0.0177387" frictionloss="0.0102278"/>
          <geom name="//unnamed_geom_4" class="/" type="mesh" rgba="0.9 0.9 0.9 1" mesh="femur"/>
          <geom name="//unnamed_geom_5" class="reward_collision_sphere" size="0.0415149"/>
          <body name="tibia_RR" pos="-0.00201501 -0.0987502 0.00167792" quat="-8.21889e-05 1 -0.000160319 -0.00027997">
            <inertial pos="0.000341067 0.000179103 0.00102244" quat="1 -0.000765005 -0.000456979 -0.000374887" mass="0.220636" diaginertia="0.00787927 0.0071146 0.0265431"/>
            <joint name="tibia_joint_RR" class="/" pos="0 0 0" axis="0.00165716 -0.00234521 0.999996" range="-3.13691 3.16563" armature="0.0088658" damping="0.0156097" frictionloss="0.00975736"/>
            <geom name="//unnamed_geom_6" class="/" type="mesh" rgba="0.2 0.2 0.2 1" mesh="tibia"/>
            <geom name="//unnamed_geom_7" class="reward_collision_sphere" size="0.0415149"/>
            <body name="tarsus_RR" pos="0.08356 0.00170148 0.000285134" quat="0.999999 0.0013585 -0.000155589 -8.85013e-05">
              <inertial pos="0.0605296 -0.000633336 0.00216001" quat="0.506213 0.493024 0.492998 0.507571" mass="0.221425" diaginertia="0.00801114 0.00696115 0.0264366"/>
              <joint name="tarsus_joint_RR" class="/" pos="0 0 0" axis="0.00872331 0.00869895 0.999924" range="-3.19348 3.14722" armature="0.00913839" damping="0.0153951" frictionloss="0.0105307"/>
              <geom name="//unnamed_geom_8" class="/" type="mesh" rgba="0.9 0.9 0.9 1" mesh="tarsus"/>
              <geom name="foot_1" class="foot" size="0.00992932" pos="0.107093 0 0" quat="0 -0.707107 0 0.707107"/>
              <geom name="//unnamed_geom_10" class="reward_collision_sphere" size="0.0415149"/>
              <geom name="//unnamed_geom_11" class="reward_collision_sphere" size="0.0155681" pos="0.10279 0 0"/>
              <site name="foot_1" class="foot" pos="0.107093 0 0" quat="0 -0.707107 0 0.707107" size="0.0103787"/>
            </body>
          </body>
        </body>
      </body>
      <body name="coxa_RM" pos="-0.00101026 -0.124342 0.0806074" quat="0.70685 -0.000504281 0.000394056 -0.707363">
        <inertial pos="-0.000158696 0.000497296 -0.00110696" quat="0.999994 -0.00115936 -0.00311023 0.000616033" mass="0.213705" diaginertia="0.00783489 0.00715399 0.0274011"/>
        <joint name="coxa_joint_RM" class="/" pos="0 0 0" axis="0.00153819 0.00209836 -0.999997" range="-3.13361 3.08354" armature="0.00929522" damping="0.0220872" frictionloss="0.0115942"/>
        <geom name="//unnamed_geom_12" class="/" type="mesh" rgba="0.2 0.2 0.2 1" mesh="coxa"/>
        <geom name="//unnamed_geom_13" class="reward_collision_sphere" size="0.0415149" pos="-0.0286856 0 0"/>
        <body name="femur_RM" pos="0.0579281 0.00105935 -0.00180526" quat="0.5 -0.499994 0.500019 0.499986">
          <inertial pos="-0.000591274 0.00199465 -0.000550064" quat="0.999991 -0.00212976 -0.003147 -0.00170093" mass="0.231992" diaginertia="0.00791083 0.00733628 0.026222"/>
          <joint name="femur_joint_RM" class="/" pos="0 0 0" axis="0.00239437 0.000735758 -0.999997" stiffness="0.000503418" range="-3.11105 3.19473" armature="0.0114663" damping="0.0205546" frictionloss="0.0107505"/>
          <geom name="//unnamed_geom_14" class="/" type="mesh" rgba="0.9 0.9 0.9 1" mesh="femur"/>
          <geom name="//unnamed_geom_15" class="reward_collision_sphere" size="0.0415149"/>
          <body name="tibia_RM" pos="2.4583e-05 -0.101146 -0.000850634" quat="2.20753e-06 1 6.01243e-06 -9.10871e-06">
            <inertial pos="-0.000652576 0.000261511 0.00176133" quat="0.999979 -0.00557288 0.000510979 0.0033721" mass="0.224577" diaginertia="0.00810383 0.00724346 0.0261746"/>
            <joint name="tibia_joint_RM" class="/" pos="0 0 0" axis="0.000409608 0.000302331 1" stiffness="0.000737372" range="-3.08518 3.18349" armature="0.0103662" damping="0.0191291" frictionloss="0.0105031"/>
            <geom name="//unnamed_geom_16" class="/" type="mesh" rgba="0.2 0.2 0.2 1" mesh="tibia"/>
            <geom name="//unnamed_geom_17" class="reward_collision_sphere" size="0.0415149"/>
            <body name="tarsus_RM" pos="0.0855497 0.000902562 0.00200269" quat="0.999999 -0.000264057 -0.000985454 -0.000319868">
              <inertial pos="0.0568224 -0.00192012 -0.000331559" quat="0.50202 0.496987 0.498784 0.50219" mass="0.229469" diaginertia="0.00810442 0.0072588 0.0270287"/>
              <joint name="tarsus_joint_RM" class="/" pos="0 0 0" axis="0.0081301 0.0104144 0.999913" range="-3.08666 3.11031" armature="0.00892713" damping="0.00880586" frictionloss="0.0112654"/>
              <geom name="//unnamed_geom_18" class="/" type="mesh" rgba="0.9 0.9 0.9 1" mesh="tarsus"/>
              <geom name="foot_2" class="foot" size="0.00939826" pos="0.107093 0 0" quat="0 -0.707107 0 0.707107"/>
              <geom name="//unnamed_geom_20" class="reward_collision_sphere" size="0.0415149"/>
              <geom name="//unnamed_geom_21" class="reward_collision_sphere" size="0.0155681" pos="0.10279 0 0"/>
              <site name="foot_2" class="foot" pos="0.107093 0 0" quat="0 -0.707107 0 0.707107" size="0.0103787"/>
            </body>
          </body>
        </body>
      </body>
      <body name="coxa_RF" pos="0.172939 -0.076792 0.0796611" quat="0.923878 -0.000106525 -7.43947e-05 -0.382687">
        <inertial pos="-1.74766e-05 -0.000551905 -0.00166089" quat="0.999923 0.00785361 0.00931461 0.00249167" mass="0.220907" diaginertia="0.00784951 0.00711843 0.0263863"/>
        <joint name="coxa_joint_RF" class="/" pos="0 0 0" axis="-0.00514283 0.00742111 -0.999959" range="-3.14971 3.08957" armature="0.00992637" damping="0.00444794" frictionloss="0.0106913"/>
        <geom name="//unnamed_geom_22" class="/" type="mesh" rgba="0.2 0.2 0.2 1" mesh="coxa"/>
        <geom name="//unnamed_geom_23" class="reward_collision_sphere" size="0.0415149" pos="-0.0286856 0 0"/>
        <body name="femur_RF" pos="0.0567597 -0.00152257 0.00209478" quat="0.499335 -0.500293 0.500112 0.50026">
          <inertial pos="0.000635369 -0.00105207 -0.00182447" quat="0.999908 -0.00617999 0.0104237 0.00611081" mass="0.221807" diaginertia="0.00766121 0.00698498 0.0262769"/>
          <joint name="femur_joint_RF" class="/" pos="0 0 0" axis="-0.00419991 -0.0130145 -0.999906" range="-3.08403 3.1474" armature="0.0101114" damping="0.00900821" frictionloss="0.010462"/>
          <geom name="//unnamed_geom_24" class="/" type="mesh" rgba="0.9 0.9 0.9 1" mesh="femur"/>
          <geom name="//unnamed_geom_25" class="reward_collision_sphere" size="0.0415149"/>
          <body name="tibia_RF" pos="-0.00137895 -0.101198 0.000817157" quat="0.00132564 0.999999 4.98378e-05 -0.000178988">
            <inertial pos="0.000311881 -0.000398817 -0.00152418" quat="0.999994 -0.00209659 0.00160295 0.00238936" mass="0.234511" diaginertia="0.00783707 0.00718705 0.0273031"/>
            <joint name="tibia_joint_RF" class="/" pos="0 0 0" axis="0.00105277 0.00198295 0.999997" stiffness="0.0208438" range="-3.1954 3.12229" armature="0.0098505" damping="0.0351943" frictionloss="0.00903875"/>
            <geom name="//unnamed_geom_26" class="/" type="mesh" rgba="0.2 0.2 0.2 1" mesh="tibia"/>
            <geom name="//unnamed_geom_27" class="reward_collision_sphere" size="0.0415149"/>
            <body name="tarsus_RF" pos="0.0856474 -0.00307564 0.000658451" quat="1 4.1902e-05 -3.25053e-05 -3.89049e-05">
              <inertial pos="0.0600515 0.00110893 8.6053e-05" quat="0.496981 0.498417 0.493593 0.510838" mass="0.213618" diaginertia="0.00744413 0.00685882 0.0263465"/>
              <joint name="tarsus_joint_RF" class="/" pos="0 0 0" axis="0.00111411 -0.00277392 0.999996" stiffness="0.0076441" range="-3.15118 3.10774" armature="0.00928693" damping="0.00839303" frictionloss="0.0117634"/>
              <geom name="//unnamed_geom_28" class="/" type="mesh" rgba="0.9 0.9 0.9 1" mesh="tarsus"/>
              <geom name="foot_3" class="foot" size="0.0113169" pos="0.107093 0 0" quat="0 -0.707107 0 0.707107"/>
              <geom name="//unnamed_geom_30" class="reward_collision_sphere" size="0.0415149"/>
              <geom name="//unnamed_geom_31" class="reward_collision_sphere" size="0.0155681" pos="0.10279 0 0"/>
              <site name="foot_3" class="foot" pos="0.107093 0 0" quat="0 -0.707107 0 0.707107" size="0.0103787"/>
            </body>
          </body>
        </body>
      </body>
      <body name="coxa_LR" pos="-0.169104 0.080671 0.0793172" quat="0.382906 0.000447681 -0.000246167 0.923787">
        <inertial pos="-0.00264005 0.00125088 -0.000881057" quat="0.999976 0.00326547 0.00311927 -0.00518016" mass="0.229159" diaginertia="0.00786872 0.00712095 0.027573"/>
        <joint name="coxa_joint_LR" class="/" pos="0 0 0" axis="-0.00966151 -0.00395715 -0.999945" stiffness="0.0141539" range="-3.19522 3.14954" armature="0.0103825" damping="0.013973" frictionloss="0.0114402"/>
        <geom name="//unnamed_geom_32" class="/" type="mesh" rgba="0.2 0.2 0.2 1" mesh="coxa"/>
        <geom name="//unnamed_geom_33" class="reward_collision_sphere" size="0.0415149" pos="-0.0286856 0 0"/>
        <body name="femur_LR" pos="0.0572144 0.00175237 -0.000246344" quat="0.49916 -0.499929 0.499962 0.500948">
          <inertial pos="-0.000186144 0.0019954 0.00238815" quat="1 -0.000242721 -5.42918e-05 9.75465e-05" mass="0.210917" diaginertia="0.00799146 0.00685051 0.0256792"/>
          <joint name="femur_joint_LR" class="/" pos="0 0 0" axis="0.00707797 -0.00158845 0.999974" range="-3.19576 3.19289" armature="0.0098365" damping="0.0123603" frictionloss="0.00989621"/>
          <geom name="//unnamed_geom_34" class="/" type="mesh" rgba="0.9 0.9 0.9 1" mesh="femur"/>
          <geom name="//unnamed_geom_35" class="reward_collision_sphere" size="0.0415149"/>
          <body name="tibia_LR" pos="0.000347928 -0.101278 -0.00232803" quat="0.00122172 0.999999 -0.000492602 -8.48589e-05">
            <inertial pos="-0.0026715 0.00265182 0.00174451" quat="0.999941 0.00907797 0.00111098 0.00588653" mass="0.230213" diaginertia="0.00829542 0.00763193 0.0266923"/>
            <joint name="tibia_joint_LR" class="/" pos="0 0 0" axis="0.0038555 0.00442528 -0.999983" range="-3.14151 3.17861" armature="0.00950304" damping="0" frictionloss="0.010375"/>
            <geom name="//unnamed_geom_36" class="/" type="mesh" rgba="0.2 0.2 0.2 1" mesh="tibia"/>
            <geom name="//unnamed_geom_37" class="reward_collision_sphere" size="0.0415149"/>
            <body name="tarsus_LR" pos="0.0865542 -0.00166624 -0.000444218" quat="1 -9.93623e-05 6.19447e-05 -2.5194e-05">
              <inertial pos="0.0572417 -0.00084552 0.00129066" quat="0.499631 0.500202 0.500824 0.499342" mass="0.215441" diaginertia="0.00772447 0.00689588 0.0271171"/>
              <joint name="tarsus_joint_LR" class="/" pos="0 0 0" axis="0.00277663 0.00383976 -0.999989" stiffness="0.0100186" range="-3.17175 3.19025" armature="0.0103696" damping="0.00787511" frictionloss="0.00903747"/>
              <geom name="//unnamed_geom_38" class="/" type="mesh" rgba="0.9 0.9 0.9 1" mesh="tarsus"/>
              <geom name="foot_4" class="foot" size="0.0114404" pos="0.107093 0 0" quat="0.707107 0 -0.707107 0"/>
              <geom name="//unnamed_geom_40" class="reward_collision_sphere" size="0.0415149"/>
              <geom name="//unnamed_geom_41" class="reward_collision_sphere" size="0.0155681" pos="0.10279 0 0"/>
              <site name="foot_4" class="foot" pos="0.107093 0 0" quat="0.707107 0 -0.707107 0" size="0.0103787"/>
            </body>
          </body>
        </body>
      </body>
      <body name="coxa_LM" pos="0.0014617 0.123197 0.0773232" quat="0.706656 -0.000471077 0.000714555 0.707557">
        <inertial pos="-0.00048573 -0.000734586 -0.000126188" quat="0.999984 -0.0052321 -0.00202322 0.00102697" mass="0.221771" diaginertia="0.00849524 0.00746613 0.0276687"/>
        <joint name="coxa_joint_LM" class="/" pos="0 0 0" axis="0.0128742 0.00409333 -0.999909" range="-3.16238 3.16" armature="0.0117683" damping="0.009734" frictionloss="0.0105184"/>
        <geom name="//unnamed_geom_42" class="/" type="mesh" rgba="0.2 0.2 0.2 1" mesh="coxa"/>
        <geom name="//unnamed_geom_43" class="reward_collision_sphere" size="0.0415149" pos="-0.0286856 0 0"/>
        <body name="femur_LM" pos="0.0539314 0.00257857 -0.000456205" quat="0.49986 -0.499752 0.500269 0.500118">
          <inertial pos="-0.00189526 0.000749918 0.000902844" quat="0.999956 -0.00212653 0.00574754 -0.00710853" mass="0.218504" diaginertia="0.00769495 0.00699717 0.0258051"/>
          <joint name="femur_joint_LM" class="/" pos="0 0 0" axis="-0.0110434 -0.00374184 0.999932" stiffness="0.00917195" range="-3.10187 3.15155" armature="0.00917308" damping="0.00985704" frictionloss="0.00973298"/>
          <geom name="//unnamed_geom_44" class="/" type="mesh" rgba="0.9 0.9 0.9 1" mesh="femur"/>
          <geom name="//unnamed_geom_45" class="reward_collision_sphere" size="0.0415149"/>
          <body name="tibia_LM" pos="-0.000756662 -0.0989493 -0.000621663" quat="0.000432455 0.999999 0.000985504 -0.00104374">
            <inertial pos="0.00294676 -0.000741759 -0.000111477" quat="0.999989 0.00198864 -0.00414582 -0.00104691" mass="0.234619" diaginertia="0.00808578 0.00733102 0.0274265"/>
            <joint name="tibia_joint_LM" class="/" pos="0 0 0" axis="0.00548804 0.00380802 -0.999978" stiffness="0.00534522" range="-3.11164 3.08321" armature="0.0095044" damping="0.0164504" frictionloss="0.0111482"/>
            <geom name="//unnamed_geom_46" class="/" type="mesh" rgba="0.2 0.2 0.2 1" mesh="tibia"/>
            <geom name="//unnamed_geom_47" class="reward_collision_sphere" size="0.0415149"/>
            <body name="tarsus_LM" pos="0.083274 -0.00186269 -0.000418462" quat="1 7.94884e-05 0.000162149 1.86554e-05">
              <inertial pos="0.0544408 -0.00110955 -0.000715989" quat="0.496641 0.492151 0.500188 0.51083" mass="0.229483" diaginertia="0.00790219 0.00745871 0.026575"/>
              <joint name="tarsus_joint_LM" class="/" pos="0 0 0" axis="0.00897701 -0.01055 -0.999904" range="-3.13524 3.13117" armature="0.00966661" damping="0.00468724" frictionloss="0.010101"/>
              <geom name="//unnamed_geom_48" class="/" type="mesh" rgba="0.9 0.9 0.9 1" mesh="tarsus"/>
              <geom name="foot_5" class="foot" size="0.0114818" pos="0.107093 0 0" quat="0.707107 0 -0.707107 0"/>
              <geom name="//unnamed_geom_50" class="reward_collision_sphere" size="0.0415149"/>
              <geom name="//unnamed_geom_51" class="reward_collision_sphere" size="0.0155681" pos="0.10279 0 0"/>
              <site name="foot_5" class="foot" pos="0.107093 0 0" quat="0.707107 0 -0.707107 0" size="0.0103787"/>
            </body>
          </body>
        </body>
      </body>
      <body name="coxa_LF" pos="0.170277 0.0780664 0.0763675" quat="0.923966 0.000264175 -0.000974192 0.382474">
        <inertial pos="-9.36995e-05 0.00112394 -0.00209299" quat="0.999934 -0.00486077 -0.00930419 -0.00460009" mass="0.221624" diaginertia="0.00782658 0.00715863 0.0271202"/>
        <joint name="coxa_joint_LF" class="/" pos="0 0 0" axis="0.000475162 0.000613511 -1" range="-3.19298 3.13412" armature="0.0118521" damping="0.0216176" frictionloss="0.00943034"/>
        <geom name="//unnamed_geom_52" class="/" type="mesh" rgba="0.2 0.2 0.2 1" mesh="coxa"/>
        <geom name="//unnamed_geom_53" class="reward_collision_sphere" size="0.0415149" pos="-0.0286856 0 0"/>
        <body name="femur_LF" pos="0.0578363 0.000432338 0.000183004" quat="0.499286 -0.500465 0.500188 0.50006">
          <inertial pos="0.000471487 -0.00278888 0.0022551" quat="1 -0.00012004 -0.000415013 -0.000458959" mass="0.227708" diaginertia="0.0079219 0.00711703 0.0268365"/>
          <joint name="femur_joint_LF" class="/" pos="0 0 0" axis="0.000523727 0.00317801 0.999995" range="-3.19563 3.17253" armature="0.0110669" damping="0" frictionloss="0.0108578"/>
          <geom name="//unnamed_geom_54" class="/" type="mesh" rgba="0.9 0.9 0.9 1" mesh="femur"/>
          <geom name="//unnamed_geom_55" class="reward_collision_sphere" size="0.0415149"/>
          <body name="tibia_LF" pos="0.00114871 -0.101911 0.00250903" quat="0.000518363 0.999999 -0.000459321 -0.00117714">
            <inertial pos="0.00245105 0.000697393 -0.00273622" quat="0.999995 0.00227056 0.00200911 -0.00013847" mass="0.22512" diaginertia="0.00758882 0.00713999 0.025586"/>
            <joint name="tibia_joint_LF" class="/" pos="0 0 0" axis="0.0058942 -0.0085696 -0.999946" stiffness="0.0138793" range="-3.15292 3.10656" armature="0.00899243" damping="0.0169935" frictionloss="0.0114941"/>
            <geom name="//unnamed_geom_56" class="/" type="mesh" rgba="0.2 0.2 0.2 1" mesh="tibia"/>
            <geom name="//unnamed_geom_57" class="reward_collision_sphere" size="0.0415149"/>
            <body name="tarsus_LF" pos="0.0814997 0.00144461 -0.00178968" quat="1 2.16303e-05 2.78761e-05 -6.01653e-05">
              <inertial pos="0.0588281 0.0025377 -0.0021724" quat="0.50309 0.500484 0.501931 0.494451" mass="0.214591" diaginertia="0.00788446 0.00713486 0.0269266"/>
              <joint name="tarsus_joint_LF" class="/" pos="0 0 0" axis="-0.00174406 0.00874352 -0.99996" stiffness="0.0313738" range="-3.08449 3.09775" armature="0.0105926" damping="0.020085" frictionloss="0.00892863"/>
              <geom name="//unnamed_geom_58" class="/" type="mesh" rgba="0.9 0.9 0.9 1" mesh="tarsus"/>
              <geom name="foot_6" class="foot" size="0.0108705" pos="0.107093 0 0" quat="0.707107 0 -0.707107 0"/>
              <geom name="//unnamed_geom_60" class="reward_collision_sphere" size="0.0415149"/>
              <geom name="//unnamed_geom_61" class="reward_collision_sphere" size="0.0155681" pos="0.10279 0 0"/>
              <site name="foot_6" class="foot" pos="0.107093 0 0" quat="0.707107 0 -0.707107 0" size="0.0103787"/>
            </body>
          </body>
        </body>
      </body>
    </body>
  </worldbody>

  <contact>
    <pair class="/" geom1="floor" geom2="foot_1" name="//unnamed_contact_0"/>
    <pair class="/" geom1="floor" geom2="foot_2" name="//unnamed_contact_1"/>
    <pair class="/" geom1="floor" geom2="foot_3" name="//unnamed_contact_2"/>
    <pair class="/" geom1="floor" geom2="foot_4" name="//unnamed_contact_3"/>
    <pair class="/" geom1="floor" geom2="foot_5" name="//unnamed_contact_4"/>
    <pair class="/" geom1="floor" geom2="foot_6" name="//unnamed_contact_5"/>
  </contact>

  <actuator>
    <general name="coxa_joint_RR" class="/" joint="coxa_joint_RR" forcerange="-7.50433 7.50433" gainprm="24.9155" biasprm="0 -24.9155 -0.570565"/>
    <general name="femur_joint_RR" class="/" joint="femur_joint_RR" forcerange="-8.17726 8.17726" gainprm="24.9155" biasprm="0 -24.9155 -0.570565"/>
    <general name="tibia_joint_RR" class="/" joint="tibia_joint_RR" forcerange="-7.55073 7.55073" gainprm="24.9155" biasprm="0 -24.9155 -0.570565"/>
    <general name="tarsus_joint_RR" class="/" joint="tarsus_joint_RR" forcerange="-7.99852 7.99852" gainprm="24.9155" biasprm="0 -24.9155 -0.570565"/>
    <general name="coxa_joint_RM" class="/" joint="coxa_joint_RM" forcerange="-6.80631 6.80631" gainprm="24.9155" biasprm="0 -24.9155 -0.570565"/>
    <general name="femur_joint_RM" class="/" joint="femur_joint_RM" forcerange="-7.97992 7.97992" gainprm="24.9155" biasprm="0 -24.9155 -0.570565"/>
    <general name="tibia_joint_RM" class="/" joint="tibia_joint_RM" forcerange="-8.22543 8.22543" gainprm="24.9155" biasprm="0 -24.9155 -0.570565"/>
    <general name="tarsus_joint_RM" class="/" joint="tarsus_joint_RM" forcerange="-8.365 8.365" gainprm="24.9155" biasprm="0 -24.9155 -0.570565"/>
    <general name="coxa_joint_RF" class="/" joint="coxa_joint_RF" forcerange="-7.14988 7.14988" gainprm="24.9155" biasprm="0 -24.9155 -0.570565"/>
    <general name="femur_joint_RF" class="/" joint="femur_joint_RF" forcerange="-7.71074 7.71074" gainprm="24.9155" biasprm="0 -24.9155 -0.570565"/>
    <general name="tibia_joint_RF" class="/" joint="tibia_joint_RF" forcerange="-8.31351 8.31351" gainprm="24.9155" biasprm="0 -24.9155 -0.570565"/>
    <general name="tarsus_joint_RF" class="/" joint="tarsus_joint_RF" forcerange="-7.81258 7.81258" gainprm="24.9155" biasprm="0 -24.9155 -0.570565"/>
    <general name="coxa_joint_LR" class="/" joint="coxa_joint_LR" forcerange="-7.49313 7.49313" gainprm="24.9155" biasprm="0 -24.9155 -0.570565"/>
    <general name="femur_joint_LR" class="/" joint="femur_joint_LR" forcerange="-7.6119 7.6119" gainprm="24.9155" biasprm="0 -24.9155 -0.570565"/>
    <general name="tibia_joint_LR" class="/" joint="tibia_joint_LR" forcerange="-7.6396 7.6396" gainprm="24.9155" biasprm="0 -24.9155 -0.570565"/>
    <general name="tarsus_joint_LR" class="/" joint="tarsus_joint_LR" forcerange="-7.31453 7.31453" gainprm="24.9155" biasprm="0 -24.9155 -0.570565"/>
    <general name="coxa_joint_LM" class="/" joint="coxa_joint_LM" forcerange="-7.14428 7.14428" gainprm="24.9155" biasprm="0 -24.9155 -0.570565"/>
    <general name="femur_joint_LM" class="/" joint="femur_joint_LM" forcerange="-7.23474 7.23474" gainprm="24.9155" biasprm="0 -24.9155 -0.570565"/>
    <general name="tibia_joint_LM" class="/" joint="tibia_joint_LM" forcerange="-7.51289 7.51289" gainprm="24.9155" biasprm="0 -24.9155 -0.570565"/>
    <general name="tarsus_joint_LM" class="/" joint="tarsus_joint_LM" forcerange="-8.35481 8.35481" gainprm="24.9155" biasprm="0 -24.9155 -0.570565"/>
    <general name="coxa_joint_LF" class="/" joint="coxa_joint_LF" forcerange="-6.79562 6.79562" gainprm="24.9155" biasprm="0 -24.9155 -0.570565"/>
    <general name="femur_joint_LF" class="/" joint="femur_joint_LF" forcerange="-7.68436 7.68436" gainprm="24.9155" biasprm="0 -24.9155 -0.570565"/>
    <general name="tibia_joint_LF" class="/" joint="tibia_joint_LF" forcerange="-7.56464 7.56464" gainprm="24.9155" biasprm="0 -24.9155 -0.570565"/>
    <general name="tarsus_joint_LF" class="/" joint="tarsus_joint_LF" forcerange="-7.70067 7.70067" gainprm="24.9155" biasprm="0 -24.9155 -0.570565"/>
  </actuator>

  <sensor>
    <gyro site="imu" name="imu_angular_velocity"/>
    <velocimeter site="imu" name="imu_linear_velocity"/>
    <framelinvel objtype="site" objname="foot_1" name="foot_1_global_linear_velocity"/>
    <framelinvel objtype="site" objname="foot_2" name="foot_2_global_linear_velocity"/>
    <framelinvel objtype="site" objname="foot_3" name="foot_3_global_linear_velocity"/>
    <framelinvel objtype="site" objname="foot_4" name="foot_4_global_linear_velocity"/>
    <framelinvel objtype="site" objname="foot_5" name="foot_5_global_linear_velocity"/>
    <framelinvel objtype="site" objname="foot_6" name="foot_6_global_linear_velocity"/>
  </sensor>

  <keyframe>
    <key name="home" qpos="0 0 0.1457 1 0 0 0 0 0 0 0 0 0 0 0 0 0 0 0 0 0 0 0 0 0 0 0 0 0 0 0"/>
  </keyframe>
</mujoco>
