<mujoco model="T1">
  <compiler angle="radian" assetdir="assets" balanceinertia="true" inertiafromgeom="false"/>

  <option timestep="0.005" density="1.2" viscosity="2e-05"/>

  <size nkey="1"/>

  <visual>
    <quality shadowsize="8192"/>
    <map shadowclip="0.5"/>
  </visual>

  <default>
    <default class="/">
      <joint armature="0.01" damping="0.01" frictionloss="0.1"/>
      <geom contype="0" conaffinity="0" group="1" solref="-1000 -80"/>
      <site size="0.01 0.005 0.005" group="5"/>
      <general forcelimited="true" biastype="affine" gainprm="25" biasprm="0 -25 -0.6"/>
      <default class="t1">
        <geom rgba="0.25 0.25 0.25 1"/>
        <default class="visual">
          <geom type="mesh" group="2"/>
        </default>
        <default class="collision">
          <geom group="3"/>
        </default>
        <default class="foot">
          <geom size="0.1115 0.05 0.015" type="box" condim="6" group="4" priority="1" solimp="0.015 1 0.015"/>
        </default>
        <default class="reward_collision_sphere">
          <geom group="5" rgba="1 0 0 1"/>
        </default>
      </default>
    </default>
  </default>

  <asset>
    <texture type="skybox" colorspace="auto" name="//unnamed_texture_0" builtin="gradient" rgb1="0.95 0.95 0.95" rgb2="0.95 0.95 0.95" width="100" height="600"/>
    <texture type="2d" colorspace="auto" name="texplane" builtin="checker" rgb1="0.345 0.575 0.748" rgb2="0.345 0.575 0.748" markrgb="1 1 1" width="512" height="512"/>
    <material name="MatPlane" class="/" texture="texplane" texuniform="true" texrepeat="2 2" specular="0.9"/>
    <mesh name="Trunk" class="/" file="Trunk.stl"/>
    <mesh name="H1" class="/" file="H1.stl"/>
    <mesh name="H2" class="/" file="H2.stl"/>
    <mesh name="AL1" class="/" file="AL1.stl"/>
    <mesh name="AL2" class="/" file="AL2.stl"/>
    <mesh name="AL3" class="/" file="AL3.stl"/>
    <mesh name="left_hand_link" class="/" file="left_hand_link.stl"/>
    <mesh name="AR1" class="/" file="AR1.stl"/>
    <mesh name="AR2" class="/" file="AR2.stl"/>
    <mesh name="AR3" class="/" file="AR3.stl"/>
    <mesh name="right_hand_link" class="/" file="right_hand_link.stl"/>
    <mesh name="Waist" class="/" file="Waist.stl"/>
    <mesh name="Hip_Pitch_Left" class="/" file="Hip_Pitch_Left.stl"/>
    <mesh name="Hip_Roll_Left" class="/" file="Hip_Roll_Left.stl"/>
    <mesh name="Hip_Yaw_Left" class="/" file="Hip_Yaw_Left.stl"/>
    <mesh name="Shank_Left" class="/" file="Shank_Left.stl"/>
    <mesh name="Ankle_Cross_Left" class="/" file="Ankle_Cross_Left.stl"/>
    <mesh name="left_foot_link" class="/" file="left_foot_link.stl"/>
    <mesh name="Hip_Pitch_Right" class="/" file="Hip_Pitch_Right.stl"/>
    <mesh name="Hip_Roll_Right" class="/" file="Hip_Roll_Right.stl"/>
    <mesh name="Hip_Yaw_Right" class="/" file="Hip_Yaw_Right.stl"/>
    <mesh name="Shank_Right" class="/" file="Shank_Right.stl"/>
    <mesh name="Ankle_Cross_Right" class="/" file="Ankle_Cross_Right.stl"/>
    <mesh name="right_foot_link" class="/" file="right_foot_link.stl"/>
  </asset>

  <worldbody>
    <geom name="floor" class="/" size="100 100 0.125" type="plane" group="0" material="MatPlane"/>
    <light name="toplight_shadow" class="/" pos="0 0 5" dir="0.0990148 0.0990148 -0.990148" type="directional" ambient="0.04 0.04 0.04" diffuse="0.55 0.55 0.55" specular="0.12 0.12 0.12"/>
    <light name="toplight_fill" class="/" pos="0 0 5" dir="0.0990148 0.0990148 -0.990148" type="directional" castshadow="false" ambient="0.04 0.04 0.04" diffuse="0.3 0.3 0.3" specular="0.08 0.08 0.08"/>
    <body name="trunk" childclass="t1" pos="0.00963669 0.015613 -0.0139039" quat="0.999968 -0.00348356 -0.00453669 0.00562898">
      <inertial pos="0.0709138 -0.00864638 0.0227695" quat="0.999904 0.00557216 -0.0103612 0.00728955" mass="4.58706" diaginertia="0.196998 0.00951079 9.03877e-05"/>
      <joint name="//unnamed_joint_0" type="free" armature="0" damping="0" frictionloss="0"/>
      <geom name="//unnamed_geom_1" class="visual" rgba="0.76 0.76 0.76 1" mesh="Trunk"/>
      <geom name="//unnamed_geom_2" class="collision" size="0.0559089 0.0745451 0.111818" pos="0.0755483 0 0.0366669" type="box"/>
      <geom name="//unnamed_geom_3" class="reward_collision_sphere" size="0.0857269" pos="0.0755483 0 0.0305557"/>
      <geom name="//unnamed_geom_4" class="reward_collision_sphere" size="0.0111818" pos="0.0755483 0.057091 0"/>
      <geom name="//unnamed_geom_5" class="reward_collision_sphere" size="0.0111818" pos="0.0755483 -0.057091 0"/>
      <geom name="//unnamed_geom_6" class="reward_collision_sphere" size="0.0111818" pos="0.0755483 0.0718675 0.0550003"/>
      <geom name="//unnamed_geom_7" class="reward_collision_sphere" size="0.0111818" pos="0.0755483 -0.0718675 0.0550003"/>
      <site name="imu" pos="-0.0695283 0.0402247 -0.0389836" size="0.00745451"/>
      <camera name="track" pos="0 -1.34332 0" quat="0.707107 0.707107 0 0" mode="trackcom"/>
      <camera name="ego_camera" pos="0.153615 0 0.128334" quat="-0.5 -0.5 0.5 0.5"/>
      <body name="H1" pos="0.0626387 -0.016187 0.0880046" quat="1 -1.81537e-06 -9.44466e-06 2.12615e-05">
        <inertial pos="0.0138851 -0.0109076 0.00353095" quat="0.756487 0.0289297 0.0850344 0.647812" mass="0.227281" diaginertia="0.000813942 2.92802e-05 4.51308e-07"/>
        <joint name="AAHead_yaw" pos="0 0 0" axis="-0.0217878 -0.026393 0.999414" range="-1.3674 1.86079" armature="0.0135132" damping="0.0334816" frictionloss="0.00465091"/>
        <geom name="//unnamed_geom_8" class="visual" mesh="H1"/>
        <body name="H2" pos="0.00436281 -0.00113712 0.00644045" quat="1 -0.000207399 -0.000263399 0.000866626">
          <inertial pos="0.00235702 0.00329256 0.0313011" quat="0.986674 0.0894781 -0.0592719 -0.122288" mass="0.331652" diaginertia="0.00873482 0.000275718 4.32236e-06"/>
          <joint name="Head_pitch" pos="0 0 0" axis="0.0273057 -0.999568 -0.0108959" range="-1.13481 0.255092" armature="0.0145611" damping="0.0157695" frictionloss="0.103796"/>
          <geom name="//unnamed_geom_9" class="visual" mesh="H2"/>
          <geom name="//unnamed_geom_10" class="collision" size="0.0596361" pos="0.0125914 0 0.0336113"/>
          <geom name="//unnamed_geom_11" class="reward_collision_sphere" size="0.0670906" pos="0.0251828 0 0.0305557"/>
        </body>
      </body>
      <body name="AL1" pos="0.0783498 0.065118 0.0743523" quat="0.999999 -0.000990931 0.000583341 0.000220946">
        <inertial pos="0.010536 0.0316262 -0.00746316" quat="0.565167 0.463389 -0.522012 0.439728" mass="0.247187" diaginertia="0.00434447 0.000158561 6.55575e-07"/>
        <joint name="Left_Shoulder_Pitch" pos="0 0 0" axis="-0.0251492 0.998205 -0.0543452" stiffness="0.0172349" range="-3.30737 1.0212" armature="0.00819948" damping="0" frictionloss="0.0971417"/>
        <geom name="//unnamed_geom_12" class="visual" rgba="0.76 0.76 0.76 1" mesh="AL1"/>
        <body name="AL2" pos="-0.000585794 0.0308668 0.0105866" quat="0.999999 0.000171048 0.00120184 -0.000171549">
          <inertial pos="0.00237864 0.0372317 0.00406027" quat="0.47862 0.510481 -0.496712 0.513429" mass="0.069912" diaginertia="0.00143762 4.74506e-05 5.56652e-07"/>
          <joint name="Left_Shoulder_Roll" pos="0 0 0" axis="-0.999551 -0.016954 0.0246958" stiffness="0.0278284" range="-1.36796 1.49606" armature="0.00666241" damping="0.0284531" frictionloss="0.0942137"/>
          <geom name="//unnamed_geom_13" class="visual" mesh="AL2"/>
          <body name="AL3" pos="-0.0149754 0.0427857 -0.0111106" quat="0.999975 0.00269372 -0.00344008 0.0055279">
            <inertial pos="0.0173631 0.0531042 0.00107422" quat="0.698881 0.714636 0.00217769 -0.0292705" mass="0.353987" diaginertia="0.0354466 0.00213392 1.57763e-06"/>
            <joint name="Left_Elbow_Pitch" pos="0 0 0" axis="0.0188952 -0.999748 0.0120932" stiffness="0.0270553" range="-2.22824 2.27872" armature="0.0114909" damping="0.0166097" frictionloss="0.0987573"/>
            <geom name="//unnamed_geom_14" class="visual" mesh="AL3"/>
            <geom name="//unnamed_geom_15" class="collision" size="0.0223635 0.0559089" pos="0 0.0335829 0" quat="0.707105 0.707108 0 0" type="cylinder"/>
            <geom name="//unnamed_geom_16" class="reward_collision_sphere" size="0.0268363"/>
            <body name="left_hand_link" pos="0.0113255 0.0993548 0.0185478" quat="0.999967 0.00745227 0.00169669 -0.00290178">
              <inertial pos="0.00262099 0.0865273 -0.0130005" quat="0.732403 0.679431 -0.0034465 0.0441373" mass="0.179386" diaginertia="0.0253685 0.00140905 8.28698e-07"/>
              <joint name="Left_Elbow_Yaw" pos="0 0 0" axis="0.00916172 -0.0275325 0.999579" range="-2.32248 0.188389" armature="0.0092677" damping="0" frictionloss="0.0836869"/>
              <geom name="//unnamed_geom_17" class="visual" mesh="left_hand_link"/>
              <geom name="//unnamed_geom_18" class="collision" size="0.0223635 0.065227" pos="0 0.0873156 0" quat="0.707105 0.707108 0 0" type="cylinder"/>
              <geom name="//unnamed_geom_19" class="reward_collision_sphere" size="0.0372726"/>
              <geom name="//unnamed_geom_20" class="reward_collision_sphere" size="0.0260908" pos="0 0.0738824 0"/>
              <geom name="//unnamed_geom_21" class="reward_collision_sphere" size="0.0260908" pos="0 0.144407 0"/>
            </body>
          </body>
        </body>
      </body>
      <body name="AR1" pos="0.0607182 -0.0538765 0.0779537" quat="0.999996 -1.82881e-05 -0.00177922 0.00227838">
        <inertial pos="-0.00359203 -0.0148088 -0.0172773" quat="0.528404 0.484027 -0.502599 0.483634" mass="0.251523" diaginertia="0.00486989 0.000245985 9.04153e-07"/>
        <joint name="Right_Shoulder_Pitch" pos="0 0 0" axis="0.00914436 -0.996496 0.0831364" stiffness="0.0113805" range="-1.51214 3.38995" armature="0.00405278" damping="0" frictionloss="0.0209187"/>
        <geom name="//unnamed_geom_22" class="visual" rgba="0.76 0.76 0.76 1" mesh="AR1"/>
        <body name="AR2" pos="0.000250413 -0.0200266 0.00311396" quat="0.999982 -0.000469766 0.00382699 0.00456522">
          <inertial pos="0.0167711 -0.0278915 0.0121922" quat="0.534031 0.466009 -0.541361 0.452299" mass="0.046458" diaginertia="0.000945336 3.77796e-05 4.4382e-07"/>
          <joint name="Right_Shoulder_Roll" pos="0 0 0" axis="-0.99848 0.0189482 0.0517527" stiffness="0.0421848" range="-1.78884 1.64136" armature="0.0129958" damping="0.0159356" frictionloss="0.0960405"/>
          <geom name="//unnamed_geom_23" class="visual" mesh="AR2"/>
          <body name="AR3" pos="0.00551963 -0.0250877 -0.0163892" quat="0.999972 0.000811474 -0.000798449 0.0073483">
            <inertial pos="-0.0186018 -0.0617262 -0.0158851" quat="0.711046 0.703081 -0.00821033 -0.00469373" mass="0.495426" diaginertia="0.0575677 0.00202488 2.15329e-06"/>
            <joint name="Right_Elbow_Pitch" pos="0 0 0" axis="-0.00252877 0.999997 0.000430938" stiffness="0.0541137" range="-2.13481 2.31838" armature="0.0074381" damping="0.0210774" frictionloss="0.00471927"/>
            <geom name="//unnamed_geom_24" class="visual" mesh="AR3"/>
            <geom name="//unnamed_geom_25" class="collision" size="0.0223635 0.0559089" pos="0 -0.0335829 0" quat="0.707105 0.707108 0 0" type="cylinder"/>
            <geom name="//unnamed_geom_26" class="reward_collision_sphere" size="0.0268363"/>
            <body name="right_hand_link" pos="0.0123995 -0.102528 -0.00597818" quat="0.999999 0.000193676 0.000874018 0.000747717">
              <inertial pos="0.0049686 -0.0816417 0.00728667" quat="0.699774 0.714255 -0.000158947 0.012481" mass="0.124881" diaginertia="0.0203492 0.00086801 5.04377e-07"/>
              <joint name="Right_Elbow_Yaw" pos="0 0 0" axis="0.0443702 -0.0783889 0.995935" stiffness="0.0127069" range="0.166309 2.43602" armature="0.0118471" damping="0.0186526" frictionloss="0.0309783"/>
              <geom name="//unnamed_geom_27" class="visual" mesh="right_hand_link"/>
              <geom name="//unnamed_geom_28" class="collision" size="0.0223635 0.065227" pos="0 -0.0873156 0" quat="0.707105 0.707108 0 0" type="cylinder"/>
              <geom name="//unnamed_geom_29" class="reward_collision_sphere" size="0.0372726"/>
              <geom name="//unnamed_geom_30" class="reward_collision_sphere" size="0.0260908" pos="0 -0.0738824 0"/>
              <geom name="//unnamed_geom_31" class="reward_collision_sphere" size="0.0260908" pos="0 -0.144407 0"/>
            </body>
          </body>
        </body>
      </body>
      <body name="Waist" pos="0.0974572 0.0102476 -0.0368705" quat="0.999962 0.00519724 -0.00559443 0.00415972">
        <inertial pos="0.0196279 -0.0139253 0.015822" quat="0.981421 -0.043044 -0.172228 -0.0727884" mass="1.41962" diaginertia="0.0181609 0.00088208 1.52208e-05"/>
        <joint name="Waist" pos="0 0 0" axis="0.0217745 0.058356 0.998058" range="-1.57971 1.41941" armature="0.00677779" damping="0" frictionloss="0.0664703"/>
        <geom name="//unnamed_geom_32" class="visual" mesh="Waist"/>
        <body name="Hip_Pitch_Left" pos="-0.00209487 0.085297 -0.0155274" quat="0.999993 -0.00297919 -0.00200758 0.00100245">
          <inertial pos="-0.0159491 -0.00866961 -0.00733444" quat="0.967976 0.237025 0.0387933 -0.0730466" mass="0.338566" diaginertia="0.00584791 0.000139078 3.12809e-06"/>
          <joint name="Left_Hip_Pitch" pos="0 0 0" axis="0.071586 0.997432 -0.00228316" range="-1.99668 1.70624" armature="0.00307252" damping="0.0113873" frictionloss="0.0601338"/>
          <geom name="//unnamed_geom_33" class="visual" rgba="0.76 0.76 0.76 1" mesh="Hip_Pitch_Left"/>
          <body name="Hip_Roll_Left" pos="0.00733676 0.0105662 0.00485672" quat="1 -0.000824479 4.30933e-05 -0.000306094">
            <inertial pos="0.00194029 0.0180746 -0.00639605" quat="0.706858 -0.00970185 -0.00268528 0.707284" mass="0.19079" diaginertia="0.00774698 0.000296169 1.23391e-06"/>
            <joint name="Left_Hip_Roll" pos="0 0 0" axis="-0.998604 -0.0193655 -0.0491472" range="-1.43343 -0.0236141" armature="0.00492345" damping="0.0935319" frictionloss="0.0214679"/>
            <geom name="//unnamed_geom_34" class="visual" mesh="Hip_Roll_Left"/>
            <geom name="//unnamed_geom_35" class="reward_collision_sphere" size="0.0409998"/>
            <body name="Hip_Yaw_Left" pos="-0.00610854 0.0108656 -0.034998" quat="0.999982 -0.00167059 -0.00276805 0.00507708">
              <inertial pos="-0.0157531 -0.00806817 -0.013726" quat="0.685344 0.00429038 -0.0458819 0.72676" mass="0.835377" diaginertia="0.0960192 0.0042825 8.46554e-06"/>
              <joint name="Left_Hip_Yaw" pos="0 0 0" axis="-0.00627142 -0.00109961 -0.99998" stiffness="0.0805118" range="-0.64253 1.11692" armature="0.00858594" damping="0.00176077" frictionloss="0.0673825"/>
              <geom name="//unnamed_geom_36" class="visual" mesh="Hip_Yaw_Left"/>
              <geom name="//unnamed_geom_37" class="collision" size="0.0372726 0.0596361" type="cylinder"/>
              <body name="Shank_Left" pos="-0.0221356 -0.00230208 -0.0382883" quat="1 -0.000109336 8.7463e-05 3.00972e-05">
                <inertial pos="0.00668235 0.00160221 -0.0432145" quat="0.996472 0.0261978 0.0294899 0.0740796" mass="0.676491" diaginertia="0.0838425 0.00527125 5.3403e-06"/>
                <joint name="Left_Knee_Pitch" pos="0 0 0" axis="0.016864 0.998725 0.0475881" range="0.00497304 2.59294" armature="0.00184969" damping="0.0754739" frictionloss="0.0892478"/>
                <geom name="//unnamed_geom_38" class="visual" mesh="Shank_Left"/>
                <geom name="//unnamed_geom_39" class="collision" size="0.0372726 0.0559089" pos="0 0 -0.0366669" type="cylinder"/>
                <geom name="//unnamed_geom_40" class="reward_collision_sphere" size="0.0484543"/>
                <body name="Ankle_Cross_Left" pos="-0.0144955 -0.00272209 -0.104544" quat="0.999983 0.00523507 -0.00210695 -0.00117827">
                  <inertial pos="0.0141102 -0.00636227 -0.0141302" quat="0.454758 0.552859 0.538322 0.444692" mass="0.0274304" diaginertia="0.000102673 3.42414e-06 2.58489e-08"/>
                  <joint name="Left_Ankle_Pitch" pos="0 0 0" axis="0.00609834 0.999979 -0.00238879" stiffness="0.0740948" range="-0.860784 0.350756" armature="0.000189283" damping="0" frictionloss="0.0599983"/>
                  <geom name="//unnamed_geom_41" class="visual" mesh="Ankle_Cross_Left"/>
                  <body name="left_foot_link" pos="0.00877524 0.013243 -0.0171094" quat="0.999955 0.00426401 0.00213826 0.00814622">
                    <inertial pos="0.0138904 0.0114934 0.00292279" quat="0.0341892 0.61885 0.0748924 0.781183" mass="0.211196" diaginertia="0.00754967 0.000303653 4.05199e-06"/>
                    <joint name="Left_Ankle_Roll" pos="0 0 0" axis="-0.995718 0.019532 -0.0903515" range="-0.613381 0.184908" armature="0.00725303" damping="0.0748028" frictionloss="0.101908"/>
                    <geom name="//unnamed_geom_42" class="visual" mesh="left_foot_link"/>
                    <geom name="left_foot" class="foot" size="0.0476619 0.056167 0.0118428" pos="0.0125914 0 -0.00458336"/>
                    <geom name="//unnamed_geom_44" class="reward_collision_sphere" size="0.0387635" pos="0.0125914 0 -0.00458336"/>
                    <geom name="//unnamed_geom_45" class="reward_collision_sphere" size="0.0223635" pos="0.119618 -0.0154481 -0.00458336"/>
                    <geom name="//unnamed_geom_46" class="reward_collision_sphere" size="0.0223635" pos="-0.0881397 -0.0154481 -0.00458336"/>
                    <site name="left_foot" class="foot" pos="0.0125914 0 -0.00458336" size="0.00745451"/>
                  </body>
                </body>
              </body>
            </body>
          </body>
        </body>
        <body name="Hip_Pitch_Right" pos="0.00715144 -0.0593517 0.0182731" quat="0.999997 0.00208958 0.000465516 -0.00126949">
          <inertial pos="0.0180089 0.0210754 0.00340486" quat="0.980101 -0.195671 0.0216406 -0.0254136" mass="0.412478" diaginertia="0.00474515 0.000162275 3.30109e-06"/>
          <joint name="Right_Hip_Pitch" pos="0 0 0" axis="0.0105711 -0.999293 0.0360729" stiffness="0.0460237" range="-1.4207 2.05529" armature="0.0110773" damping="0.0878456" frictionloss="0.0381483"/>
          <geom name="//unnamed_geom_47" class="visual" rgba="0.76 0.76 0.76 1" mesh="Hip_Pitch_Right"/>
          <body name="Hip_Roll_Right" pos="0.0127516 -0.00203575 0.0120764" quat="0.999982 0.00178242 -0.00568066 0.00123039">
            <inertial pos="0.0148119 -0.00909802 -0.0297732" quat="0.677501 0.00944039 -0.0712704 0.732" mass="0.149894" diaginertia="0.00463249 0.000245532 1.53652e-06"/>
            <joint name="Right_Hip_Roll" pos="0 0 0" axis="-0.999265 -0.00878973 -0.0373196" stiffness="0.0020254" range="-0.0777608 1.48506" armature="0.00953366" damping="0" frictionloss="0.0251656"/>
            <geom name="//unnamed_geom_48" class="visual" mesh="Hip_Roll_Right"/>
            <geom name="//unnamed_geom_49" class="reward_collision_sphere" size="0.0409998"/>
            <body name="Hip_Yaw_Right" pos="0.0179594 0.00114707 -0.0158732" quat="0.999999 -0.00113169 0.000154149 0.00121357">
              <inertial pos="-0.00325198 0.00748467 -0.0395797" quat="0.718516 -0.0455939 -0.0375945 0.692995" mass="1.00066" diaginertia="0.067197 0.00403068 5.64858e-06"/>
              <joint name="Right_Hip_Yaw" pos="0 0 0" axis="-0.0183518 0.0157853 -0.999707" stiffness="0.0367405" range="-0.959422 1.03073" armature="0.00515115" damping="0" frictionloss="0.107932"/>
              <geom name="//unnamed_geom_50" class="visual" mesh="Hip_Yaw_Right"/>
              <geom name="//unnamed_geom_51" class="collision" size="0.0372726 0.0596361" type="cylinder"/>
              <body name="Shank_Right" pos="-0.00207442 4.5876e-05 -0.0273932" quat="0.99999 0.00343202 0.000104027 0.00300217">
                <inertial pos="-0.0104064 0.0150469 -0.0360059" quat="0.995481 -0.037713 -0.00669153 -0.0868889" mass="0.623502" diaginertia="0.129899 0.00496377 6.57874e-06"/>
                <joint name="Right_Knee_Pitch" pos="0 0 0" axis="-0.0171022 -0.999851 0.00237899" range="-2.01075 -0.0698608" armature="0.0101839" damping="0.00909821" frictionloss="0.0959732"/>
                <geom name="//unnamed_geom_52" class="visual" mesh="Shank_Right"/>
                <geom name="//unnamed_geom_53" class="collision" size="0.0372726 0.0559089" pos="0 0 -0.0366669" type="cylinder"/>
                <geom name="//unnamed_geom_54" class="reward_collision_sphere" size="0.0484543"/>
                <body name="Ankle_Cross_Right" pos="0.00706275 -0.00724304 -0.07585" quat="1 -0.000663164 8.13811e-05 0.000255779">
                  <inertial pos="-0.00255307 -0.0112348 -0.00239776" quat="0.442771 0.550876 0.55122 0.443449" mass="0.0332983" diaginertia="6.96836e-05 3.8766e-06 2.2943e-08"/>
                  <joint name="Right_Ankle_Pitch" pos="0 0 0" axis="-0.0710982 -0.996781 0.0370456" stiffness="0.0729731" range="-0.598174 1.15155" armature="0.00725938" damping="0" frictionloss="0.0677493"/>
                  <geom name="//unnamed_geom_55" class="visual" mesh="Ankle_Cross_Right"/>
                  <body name="right_foot_link" pos="0.0018274 -0.0154141 -0.00701148" quat="0.999999 0.000648914 -0.0010762 -0.000165919">
                    <inertial pos="-0.00037487 -0.0154426 0.0154849" quat="0.0697942 0.609305 0.0312619 0.789239" mass="0.396721" diaginertia="0.00986492 0.000393976 8.7891e-06"/>
                    <joint name="Right_Ankle_Roll" pos="0 0 0" axis="-0.998955 0.0152194 -0.0430944" range="-0.144217 0.0986123" armature="0.0140416" damping="0.0984569" frictionloss="0.0241194"/>
                    <geom name="//unnamed_geom_56" class="visual" mesh="right_foot_link"/>
                    <geom name="right_foot" class="foot" size="0.0780683 0.0581726 0.00465741" pos="0.0125914 0 -0.00458336"/>
                    <geom name="//unnamed_geom_58" class="reward_collision_sphere" size="0.0298181"/>
                    <geom name="//unnamed_geom_59" class="reward_collision_sphere" size="0.0223635" pos="0.0125914 0 -0.00458336"/>
                    <geom name="//unnamed_geom_60" class="reward_collision_sphere" size="0.0223635" pos="0.119618 0.0154481 -0.00458336"/>
                    <geom name="//unnamed_geom_61" class="reward_collision_sphere" size="0.0223635" pos="-0.0881397 0.0154481 -0.00458336"/>
                    <site name="right_foot" class="foot" pos="0.0125914 0 -0.00458336" size="0.00745451"/>
                  </body>
                </body>
              </body>
            </body>
          </body>
        </body>
      </body>
    </body>
  </worldbody>

  <contact>
    <pair class="/" geom1="floor" geom2="left_foot" name="//unnamed_contact_0"/>
    <pair class="/" geom1="floor" geom2="right_foot" name="//unnamed_contact_1"/>
  </contact>

  <actuator>
    <general name="AAHead_yaw" class="/" joint="AAHead_yaw" forcerange="-5.60466 5.60466" gainprm="23.5664" biasprm="0 -23.5664 -0.318637"/>
    <general name="Head_pitch" class="/" joint="Head_pitch" forcerange="-4.58561 4.58561" gainprm="23.5664" biasprm="0 -23.5664 -0.318637"/>
    <general name="Left_Shoulder_Pitch" class="/" joint="Left_Shoulder_Pitch" forcerange="-22.818 22.818" gainprm="23.5664" biasprm="0 -23.5664 -0.318637"/>
    <general name="Left_Shoulder_Roll" class="/" joint="Left_Shoulder_Roll" forcerange="-21.4438 21.4438" gainprm="23.5664" biasprm="0 -23.5664 -0.318637"/>
    <general name="Left_Elbow_Pitch" class="/" joint="Left_Elbow_Pitch" forcerange="-6.9172 6.9172" gainprm="23.5664" biasprm="0 -23.5664 -0.318637"/>
    <general name="Left_Elbow_Yaw" class="/" joint="Left_Elbow_Yaw" forcerange="-14.7256 14.7256" gainprm="23.5664" biasprm="0 -23.5664 -0.318637"/>
    <general name="Right_Shoulder_Pitch" class="/" joint="Right_Shoulder_Pitch" forcerange="-16.8642 16.8642" gainprm="23.5664" biasprm="0 -23.5664 -0.318637"/>
    <general name="Right_Shoulder_Roll" class="/" joint="Right_Shoulder_Roll" forcerange="-6.60594 6.60594" gainprm="23.5664" biasprm="0 -23.5664 -0.318637"/>
    <general name="Right_Elbow_Pitch" class="/" joint="Right_Elbow_Pitch" forcerange="-10.1494 10.1494" gainprm="23.5664" biasprm="0 -23.5664 -0.318637"/>
    <general name="Right_Elbow_Yaw" class="/" joint="Right_Elbow_Yaw" forcerange="-17.2608 17.2608" gainprm="23.5664" biasprm="0 -23.5664 -0.318637"/>
    <general name="Waist" class="/" joint="Waist" forcerange="-34.9802 34.9802" gainprm="23.5664" biasprm="0 -23.5664 -0.318637"/>
    <general name="Left_Hip_Pitch" class="/" joint="Left_Hip_Pitch" forcerange="-26.8401 26.8401" gainprm="23.5664" biasprm="0 -23.5664 -0.318637"/>
    <general name="Left_Hip_Roll" class="/" joint="Left_Hip_Roll" forcerange="-14.445 14.445" gainprm="23.5664" biasprm="0 -23.5664 -0.318637"/>
    <general name="Left_Hip_Yaw" class="/" joint="Left_Hip_Yaw" forcerange="-32.3195 32.3195" gainprm="23.5664" biasprm="0 -23.5664 -0.318637"/>
    <general name="Left_Knee_Pitch" class="/" joint="Left_Knee_Pitch" forcerange="-48.7514 48.7514" gainprm="23.5664" biasprm="0 -23.5664 -0.318637"/>
    <general name="Left_Ankle_Pitch" class="/" joint="Left_Ankle_Pitch" forcerange="-14.9445 14.9445" gainprm="23.5664" biasprm="0 -23.5664 -0.318637"/>
    <general name="Left_Ankle_Roll" class="/" joint="Left_Ankle_Roll" forcerange="-7.51107 7.51107" gainprm="23.5664" biasprm="0 -23.5664 -0.318637"/>
    <general name="Right_Hip_Pitch" class="/" joint="Right_Hip_Pitch" forcerange="-13.3003 13.3003" gainprm="23.5664" biasprm="0 -23.5664 -0.318637"/>
    <general name="Right_Hip_Roll" class="/" joint="Right_Hip_Roll" forcerange="-7.02969 7.02969" gainprm="23.5664" biasprm="0 -23.5664 -0.318637"/>
    <general name="Right_Hip_Yaw" class="/" joint="Right_Hip_Yaw" forcerange="-24.2075 24.2075" gainprm="23.5664" biasprm="0 -23.5664 -0.318637"/>
    <general name="Right_Knee_Pitch" class="/" joint="Right_Knee_Pitch" forcerange="-25.6807 25.6807" gainprm="23.5664" biasprm="0 -23.5664 -0.318637"/>
    <general name="Right_Ankle_Pitch" class="/" joint="Right_Ankle_Pitch" forcerange="-24.9845 24.9845" gainprm="23.5664" biasprm="0 -23.5664 -0.318637"/>
    <general name="Right_Ankle_Roll" class="/" joint="Right_Ankle_Roll" forcerange="-5.01743 5.01743" gainprm="23.5664" biasprm="0 -23.5664 -0.318637"/>
  </actuator>

  <sensor>
    <gyro site="imu" name="imu_angular_velocity"/>
    <velocimeter site="imu" name="imu_linear_velocity"/>
    <framelinvel objtype="site" objname="left_foot" name="left_foot_global_linear_velocity"/>
    <framelinvel objtype="site" objname="right_foot" name="right_foot_global_linear_velocity"/>
  </sensor>

  <keyframe>
    <key name="home" qpos="0 0 0.6385 1 0 0 0 0 0 0 1.4 0 -0.4 0 -1.4 0 0.4 0 -0.4 0 0 0.8 -0.4 0 0.4 0 0 -0.8 0.4 0"/>
  </keyframe>
</mujoco>
