<mujoco model="T1">
  <compiler angle="radian" assetdir="assets" balanceinertia="true" inertiafromgeom="false"/>

  <option timestep="0.005" density="1.2" viscosity="2e-05"/>

  <size nkey="1"/>

  <visual>
    <quality shadowsize="8192"/>
    <map shadowclip="0.5"/>
  </visual>

  <default>
    <default class="/">
      <joint armature="0.01" damping="0.01" frictionloss="0.1"/>
      <geom contype="0" conaffinity="0" group="1" solref="-1000 -80"/>
      <site size="0.01 0.005 0.005" group="5"/>
      <general forcelimited="true" biastype="affine" gainprm="25" biasprm="0 -25 -0.6"/>
      <default class="t1">
        <geom rgba="0.25 0.25 0.25 1"/>
        <default class="visual">
          <geom type="mesh" group="2"/>
        </default>
        <default class="collision">
          <geom group="3"/>
        </default>
        <default class="foot">
          <geom size="0.1115 0.05 0.015" type="box" condim="6" group="4" priority="1" solimp="0.015 1 0.015"/>
        </default>
        <default class="reward_collision_sphere">
          <geom group="5" rgba="1 0 0 1"/>
        </default>
      </default>
    </default>
  </default>

  <asset>
    <texture type="skybox" colorspace="auto" name="//unnamed_texture_0" builtin="gradient" rgb1="0.95 0.95 0.95" rgb2="0.95 0.95 0.95" width="100" height="600"/>
    <texture type="2d" colorspace="auto" name="texplane" builtin="checker" rgb1="0.345 0.575 0.748" rgb2="0.345 0.575 0.748" markrgb="1 1 1" width="512" height="512"/>
    <material name="MatPlane" class="/" texture="texplane" texuniform="true" texrepeat="2 2" specular="0.9"/>
    <mesh name="Trunk" class="/" file="Trunk.stl"/>
    <mesh name="H1" class="/" file="H1.stl"/>
    <mesh name="H2" class="/" file="H2.stl"/>
    <mesh name="AL1" class="/" file="AL1.stl"/>
    <mesh name="AL2" class="/" file="AL2.stl"/>
    <mesh name="AL3" class="/" file="AL3.stl"/>
    <mesh name="left_hand_link" class="/" file="left_hand_link.stl"/>
    <mesh name="AR1" class="/" file="AR1.stl"/>
    <mesh name="AR2" class="/" file="AR2.stl"/>
    <mesh name="AR3" class="/" file="AR3.stl"/>
    <mesh name="right_hand_link" class="/" file="right_hand_link.stl"/>
    <mesh name="Waist" class="/" file="Waist.stl"/>
    <mesh name="Hip_Pitch_Left" class="/" file="Hip_Pitch_Left.stl"/>
    <mesh name="Hip_Roll_Left" class="/" file="Hip_Roll_Left.stl"/>
    <mesh name="Hip_Yaw_Left" class="/" file="Hip_Yaw_Left.stl"/>
    <mesh name="Shank_Left" class="/" file="Shank_Left.stl"/>
    <mesh name="Ankle_Cross_Left" class="/" file="Ankle_Cross_Left.stl"/>
    <mesh name="left_foot_link" class="/" file="left_foot_link.stl"/>
    <mesh name="Hip_Pitch_Right" class="/" file="Hip_Pitch_Right.stl"/>
    <mesh name="Hip_Roll_Right" class="/" file="Hip_Roll_Right.stl"/>
    <mesh name="Hip_Yaw_Right" class="/" file="Hip_Yaw_Right.stl"/>
    <mesh name="Shank_Right" class="/" file="Shank_Right.stl"/>
    <mesh name="Ankle_Cross_Right" class="/" file="Ankle_Cross_Right.stl"/>
    <mesh name="right_foot_link" class="/" file="right_foot_link.stl"/>
  </asset>

  <worldbody>
    <geom name="floor" class="/" size="100 100 0.125" type="plane" group="0" material="MatPlane"/>
    <light name="toplight_shadow" class="/" pos="0 0 5" dir="0.0990148 0.0990148 -0.990148" type="directional" ambient="0.04 0.04 0.04" diffuse="0.55 0.55 0.55" specular="0.12 0.12 0.12"/>
    <light name="toplight_fill" class="/" pos="0 0 5" dir="0.0990148 0.0990148 -0.990148" type="directional" castshadow="false" ambient="0.04 0.04 0.04" diffuse="0.3 0.3 0.3" specular="0.08 0.08 0.08"/>
    <body name="trunk" childclass="t1" pos="-0.00214937 -0.00221006 0.00270521" quat="0.999999 0.000476777 0.000751825 0.000492595">
      <inertial pos="0.0373317 0.000377934 0.101002" quat="0.999976 0.00134747 -0.00678073 0.000443958" mass="7.3426" diaginertia="0.0143868 0.0559911 0.0422089"/>
      <joint name="//unnamed_joint_0" type="free" armature="0" damping="0" frictionloss="0"/>
      <geom name="//unnamed_geom_1" class="visual" rgba="0.76 0.76 0.76 1" mesh="Trunk"/>
      <geom name="//unnamed_geom_2" class="collision" size="0.0642254 0.0856338 0.128451" pos="0.041142 0 0.112822" type="box"/>
      <geom name="//unnamed_geom_3" class="reward_collision_sphere" size="0.0984789" pos="0.041142 0 0.094018"/>
      <geom name="//unnamed_geom_4" class="reward_collision_sphere" size="0.0128451" pos="0.041142 0.0801665 0"/>
      <geom name="//unnamed_geom_5" class="reward_collision_sphere" size="0.0128451" pos="0.041142 -0.0801665 0"/>
      <geom name="//unnamed_geom_6" class="reward_collision_sphere" size="0.0128451" pos="0.041142 0.100915 0.169232"/>
      <geom name="//unnamed_geom_7" class="reward_collision_sphere" size="0.0128451" pos="0.041142 -0.100915 0.169232"/>
      <site name="imu" pos="0.0135253 -0.0058816 0.00496482" size="0.00856338"/>
      <camera name="track" pos="0 -1.88627 0" quat="0.707107 0.707107 0 0" mode="trackcom"/>
      <camera name="ego_camera" pos="0.0836553 0 0.394876" quat="-0.5 -0.5 0.5 0.5"/>
      <body name="H1" pos="0.0444116 0.0018876 0.225423" quat="1 2.4091e-05 -0.000140687 3.81371e-05">
        <inertial pos="-0.00349281 0.000549752 0.0566615" quat="0.764245 -0.0147204 0.00441154 0.644743" mass="0.269378" diaginertia="3.50581e-05 0.000166718 0.000106303"/>
        <joint name="AAHead_yaw" pos="0 0 0" axis="-0.0013334 -0.000360553 0.999999" stiffness="0.00195691" range="-1.6168 1.51964" armature="0.00739134" damping="0.00686409" frictionloss="0.0882779"/>
        <geom name="//unnamed_geom_8" class="visual" mesh="H1"/>
        <body name="H2" pos="0.000587428 -0.000117857 0.0607607" quat="1 -0.000240662 -5.03002e-05 -5.07265e-05">
          <inertial pos="0.00497931 0.00182666 0.0927966" quat="0.988639 0.0999326 -0.0709138 -0.0870497" mass="0.389588" diaginertia="0.0002901 0.00143454 0.00125595"/>
          <joint name="Head_pitch" pos="0 0 0" axis="-0.00161854 -0.999998 -0.00126712" range="-1.1989 0.330312" armature="0.00783036" damping="0.0121341" frictionloss="0.0812109"/>
          <geom name="//unnamed_geom_9" class="visual" mesh="H2"/>
          <geom name="//unnamed_geom_10" class="collision" size="0.068507" pos="0.00685699 0 0.10342"/>
          <geom name="//unnamed_geom_11" class="reward_collision_sphere" size="0.0770704" pos="0.013714 0 0.094018"/>
        </body>
      </body>
      <body name="AL1" pos="0.0406373 0.101987 0.204752" quat="1 -0.00015655 0.000309479 -1.40877e-05">
        <inertial pos="-0.00357856 0.0418285 0.000215264" quat="0.500231 0.495671 -0.506595 0.497433" mass="0.335288" diaginertia="0.000208253 0.00100484 0.00022289"/>
        <joint name="Left_Shoulder_Pitch" pos="0 0 0" axis="0.0155604 0.999874 -0.00311317" stiffness="0.00489311" range="-3.29755 1.26692" armature="0.00887344" damping="0.00979764" frictionloss="0.0870041"/>
        <geom name="//unnamed_geom_12" class="visual" rgba="0.76 0.76 0.76 1" mesh="AL1"/>
        <body name="AL2" pos="0.00059267 0.0451685 -0.00252403" quat="1 -0.000101196 -6.7574e-05 -1.74146e-05">
          <inertial pos="0.00128219 0.0328306 0.000341853" quat="0.487966 0.511742 -0.487984 0.511742" mass="0.0979696" diaginertia="5.95678e-05 0.00025497 0.000128424"/>
          <joint name="Left_Shoulder_Roll" pos="0 0 0" axis="-0.999997 -0.00091952 -0.00234049" range="-1.62279 1.79663" armature="0.00876973" damping="0.0113086" frictionloss="0.0891234"/>
          <geom name="//unnamed_geom_13" class="visual" mesh="AL2"/>
          <body name="AL3" pos="0.00294308 0.0565706 0.00313983" quat="0.999999 -0.0011261 0.000710155 0.000405842">
            <inertial pos="-0.00157647 0.0793842 -0.000495873" quat="0.707092 0.707122 -0.000574774 -0.000173039" mass="0.664809" diaginertia="0.00202227 0.00937214 0.000451666"/>
            <joint name="Left_Elbow_Pitch" pos="0 0 0" axis="-0.00458695 -0.999989 0.000150359" range="-2.27711 2.2741" armature="0.00747855" damping="0.0165192" frictionloss="0.085685"/>
            <geom name="//unnamed_geom_14" class="visual" mesh="AL3"/>
            <geom name="//unnamed_geom_15" class="collision" size="0.0256901 0.0642254" pos="0 0.0471568 0" quat="0.707105 0.707108 0 0" type="cylinder"/>
            <geom name="//unnamed_geom_16" class="reward_collision_sphere" size="0.0308282"/>
            <body name="left_hand_link" pos="-0.00207469 0.139704 -0.000302488" quat="1 0.000444473 9.93831e-05 -0.00081121">
              <inertial pos="0.000329523 0.100741 0.00333067" quat="0.699005 0.715091 -0.00509574 -0.00329157" mass="0.19804" diaginertia="0.00124534 0.00600137 0.000150305"/>
              <joint name="Left_Elbow_Yaw" pos="0 0 0" axis="-0.00106168 0.000693011 0.999999" stiffness="0.0100291" range="-2.43611 -0.0395376" armature="0.00897052" damping="0.0102852" frictionloss="0.0849994"/>
              <geom name="//unnamed_geom_17" class="visual" mesh="left_hand_link"/>
              <geom name="//unnamed_geom_18" class="collision" size="0.0256901 0.0749296" pos="0 0.122608 0" quat="0.707105 0.707108 0 0" type="cylinder"/>
              <geom name="//unnamed_geom_19" class="reward_collision_sphere" size="0.0428169"/>
              <geom name="//unnamed_geom_20" class="reward_collision_sphere" size="0.0299718" pos="0 0.103745 0"/>
              <geom name="//unnamed_geom_21" class="reward_collision_sphere" size="0.0299718" pos="0 0.202774 0"/>
            </body>
          </body>
        </body>
      </body>
      <body name="AR1" pos="0.0417429 -0.10085 0.203455" quat="1 0.000107901 0.000252456 -3.92354e-05">
        <inertial pos="-0.00175678 -0.0447686 0.00128371" quat="0.503402 0.497633 -0.503975 0.494931" mass="0.320412" diaginertia="0.000200998 0.000914044 0.000207341"/>
        <joint name="Right_Shoulder_Pitch" pos="0 0 0" axis="-0.00613555 -0.999976 -0.0032044" stiffness="0.00810472" range="-1.17394 3.33213" armature="0.00934553" damping="0.0071146" frictionloss="0.0967238"/>
        <geom name="//unnamed_geom_22" class="visual" rgba="0.76 0.76 0.76 1" mesh="AR1"/>
        <body name="AR2" pos="-0.000804241 -0.0462134 -0.00125354" quat="0.999999 0.00117342 -1.44646e-05 0.000528219">
          <inertial pos="-0.000270133 -0.0359032 -0.00237468" quat="0.519089 0.49214 -0.501269 0.486903" mass="0.101221" diaginertia="6.15573e-05 0.000262484 0.000129654"/>
          <joint name="Right_Shoulder_Roll" pos="0 0 0" axis="-0.999785 -0.017586 -0.0109622" range="-1.7391 1.58874" armature="0.00788611" damping="0.0061441" frictionloss="0.0879157"/>
          <geom name="//unnamed_geom_23" class="visual" mesh="AR2"/>
          <body name="AR3" pos="0.000363372 -0.0594064 0.00157439" quat="0.999999 -0.00055163 0.000659235 -0.000843914">
            <inertial pos="0.000558758 -0.0817015 0.00214185" quat="0.706994 0.707217 0.00140099 -0.00099263" mass="0.617344" diaginertia="0.00184451 0.00917961 0.000429307"/>
            <joint name="Right_Elbow_Pitch" pos="0 0 0" axis="-0.000291334 1 0.000570735" range="-2.27627 2.26824" armature="0.00859582" damping="0.0134096" frictionloss="0.0883294"/>
            <geom name="//unnamed_geom_24" class="visual" mesh="AR3"/>
            <geom name="//unnamed_geom_25" class="collision" size="0.0256901 0.0642254" pos="0 -0.0471568 0" quat="0.707105 0.707108 0 0" type="cylinder"/>
            <geom name="//unnamed_geom_26" class="reward_collision_sphere" size="0.0308282"/>
            <body name="right_hand_link" pos="-0.00334518 -0.139211 -0.000427541" quat="1 -1.50464e-06 -1.98111e-06 -0.000119022">
              <inertial pos="-0.000248197 -0.101824 0.000802685" quat="0.706607 0.707602 0.00248371 -0.000419505" mass="0.20206" diaginertia="0.00125311 0.00615714 0.000155415"/>
              <joint name="Right_Elbow_Yaw" pos="0 0 0" axis="0.00161779 -0.00388235 0.999991" stiffness="0.00316238" range="-0.0274503 2.44288" armature="0.00744732" damping="0.0088087" frictionloss="0.0975737"/>
              <geom name="//unnamed_geom_27" class="visual" mesh="right_hand_link"/>
              <geom name="//unnamed_geom_28" class="collision" size="0.0256901 0.0749296" pos="0 -0.122608 0" quat="0.707105 0.707108 0 0" type="cylinder"/>
              <geom name="//unnamed_geom_29" class="reward_collision_sphere" size="0.0428169"/>
              <geom name="//unnamed_geom_30" class="reward_collision_sphere" size="0.0299718" pos="0 -0.103745 0"/>
              <geom name="//unnamed_geom_31" class="reward_collision_sphere" size="0.0299718" pos="0 -0.202774 0"/>
            </body>
          </body>
        </body>
      </body>
      <body name="Waist" pos="0.0426176 -0.00372205 -0.106308" quat="1 -0.00026484 0.000885445 -6.07773e-05">
        <inertial pos="-0.000250762 0.00221619 0.00413813" quat="0.983502 0.00381681 -0.180663 0.00841113" mass="1.55715" diaginertia="0.000802489 0.0038227 0.00339734"/>
        <joint name="Waist" pos="0 0 0" axis="0.0019906 -0.013596 0.999906" stiffness="0.00911794" range="-1.57326 1.58381" armature="0.00860867" damping="0.013066" frictionloss="0.0872779"/>
        <geom name="//unnamed_geom_32" class="visual" mesh="Waist"/>
        <body name="Hip_Pitch_Left" pos="-0.00127298 0.0969187 0.00101639" quat="1 -0.00045932 0.000353811 -0.000139893">
          <inertial pos="0.0023022 -0.00838413 -0.0168902" quat="0.974649 0.223194 0.0111481 0.0109377" mass="0.655245" diaginertia="0.00027647 0.00116382 0.00093808"/>
          <joint name="Left_Hip_Pitch" pos="0 0 0" axis="0.0104674 0.999944 0.0016097" stiffness="0.0111059" range="-1.75772 1.56688" armature="0.00975703" damping="0.010558" frictionloss="0.0815807"/>
          <geom name="//unnamed_geom_33" class="visual" rgba="0.76 0.76 0.76 1" mesh="Hip_Pitch_Left"/>
          <body name="Hip_Roll_Left" pos="5.61488e-05 -0.0030886 -0.0172069" quat="1 -0.000147224 0.000134154 8.88092e-05">
            <inertial pos="0.00127836 -0.00100729 -0.0530325" quat="0.706803 -0.00602295 -0.00590971 0.70736" mass="0.23189" diaginertia="0.000248652 0.00107636 0.000368792"/>
            <joint name="Left_Hip_Roll" pos="0 0 0" axis="-0.999932 -0.0112033 0.00311129" range="-1.5711 0.255295" armature="0.00878661" damping="0.00872011" frictionloss="0.0969089"/>
            <geom name="//unnamed_geom_34" class="visual" mesh="Hip_Roll_Left"/>
            <geom name="//unnamed_geom_35" class="reward_collision_sphere" size="0.0470986"/>
            <body name="Hip_Yaw_Left" pos="0.00426445 -0.00338627 -0.0740443" quat="0.999999 0.000629852 0.00120333 -0.000369976">
              <inertial pos="-0.00465513 0.000418633 -0.0867719" quat="0.698215 -0.0394407 -0.0373555 0.713824" mass="1.36061" diaginertia="0.00378069 0.0187362 0.00187693"/>
              <joint name="Left_Hip_Yaw" pos="0 0 0" axis="-0.000900512 0.00193564 -0.999998" range="-1.02445 1.01823" armature="0.00829683" damping="0.0133156" frictionloss="0.0877534"/>
              <geom name="//unnamed_geom_36" class="visual" mesh="Hip_Yaw_Left"/>
              <geom name="//unnamed_geom_37" class="collision" size="0.0428169 0.068507" type="cylinder"/>
              <body name="Shank_Left" pos="-0.00572363 -0.00119276 -0.122482" quat="1 6.7431e-05 -0.000202848 -0.000221485">
                <inertial pos="-0.0066873 0.000172188 -0.117548" quat="0.997705 0.0147946 -0.0204545 0.062832" mass="1.09399" diaginertia="0.0054714 0.0255362 0.00132825"/>
                <joint name="Left_Knee_Pitch" pos="0 0 0" axis="-8.19308e-05 0.999967 0.00818244" range="-0.000386964 2.28328" armature="0.00991185" damping="0" frictionloss="0.0899168"/>
                <geom name="//unnamed_geom_38" class="visual" mesh="Shank_Left"/>
                <geom name="//unnamed_geom_39" class="collision" size="0.0428169 0.0642254" pos="0 0 -0.112822" type="cylinder"/>
                <geom name="//unnamed_geom_40" class="reward_collision_sphere" size="0.055662"/>
                <body name="Ankle_Cross_Left" pos="0.00198698 -0.000867971 -0.264154" quat="0.999999 0.000369627 -0.000683254 0.00109586">
                  <inertial pos="-0.00310551 9.72025e-05 -0.00479599" quat="0.441683 0.549596 0.551045 0.446329" mass="0.0456755" diaginertia="4.26411e-06 1.92563e-05 8.60358e-06"/>
                  <joint name="Left_Ankle_Pitch" pos="0 0 0" axis="-0.0009173 0.999998 0.00165107" range="-0.868402 0.35153" armature="0.00895711" damping="0.0192109" frictionloss="0.0815633"/>
                  <geom name="//unnamed_geom_41" class="visual" mesh="Ankle_Cross_Left"/>
                  <body name="left_foot_link" pos="-0.00262692 -0.00310903 -0.00916304" quat="1 -0.000174248 7.10888e-05 0.000216502">
                    <inertial pos="-0.00284346 -0.00252705 -0.00806782" quat="-0.00656044 0.622707 0.00596897 0.782405" mass="0.43269" diaginertia="0.000400946 0.00175816 0.00165795"/>
                    <joint name="Left_Ankle_Roll" pos="0 0 0" axis="-0.999992 0.00291177 0.00275693" range="-0.413951 0.496922" armature="0.00872559" damping="0" frictionloss="0.0828231"/>
                    <geom name="//unnamed_geom_42" class="visual" mesh="left_foot_link"/>
                    <geom name="left_foot" class="foot" size="0.107892 0.0396159 0.0133987" pos="0.00685699 0 -0.0141027"/>
                    <geom name="//unnamed_geom_44" class="reward_collision_sphere" size="0.0445296" pos="0.00685699 0 -0.0141027"/>
                    <geom name="//unnamed_geom_45" class="reward_collision_sphere" size="0.0256901" pos="0.0651414 -0.0216921 -0.0141027"/>
                    <geom name="//unnamed_geom_46" class="reward_collision_sphere" size="0.0256901" pos="-0.047999 -0.0216921 -0.0141027"/>
                    <site name="left_foot" class="foot" pos="0.00685699 0 -0.0141027" size="0.00856338"/>
                  </body>
                </body>
              </body>
            </body>
          </body>
        </body>
        <body name="Hip_Pitch_Right" pos="-0.00297595 -0.1028 0.00091643" quat="1 0.000252543 -0.000341432 -0.000593186">
          <inertial pos="-0.00121192 0.00506703 -0.0183371" quat="0.973596 -0.228059 0.0099484 -0.000841586" mass="0.641588" diaginertia="0.000283979 0.00113276 0.000925312"/>
          <joint name="Right_Hip_Pitch" pos="0 0 0" axis="0.00108612 -0.999999 0.000439172" range="-1.58478 1.7404" armature="0.00764866" damping="0.00112222" frictionloss="0.0951264"/>
          <geom name="//unnamed_geom_47" class="visual" rgba="0.76 0.76 0.76 1" mesh="Hip_Pitch_Right"/>
          <body name="Hip_Roll_Right" pos="-0.00317553 -0.00175283 -0.0181045" quat="0.999999 0.000324271 0.00116864 -0.00088968">
            <inertial pos="-0.00179697 0.00139677 -0.0475979" quat="0.702715 -0.00178311 0.00244444 0.711465" mass="0.250194" diaginertia="0.000270526 0.00112017 0.000384349"/>
            <joint name="Right_Hip_Roll" pos="0 0 0" axis="-1 0.00026871 -0.000464694" stiffness="0.00493154" range="-0.194325 1.55792" armature="0.00881163" damping="0.0134635" frictionloss="0.097612"/>
            <geom name="//unnamed_geom_48" class="visual" mesh="Hip_Roll_Right"/>
            <geom name="//unnamed_geom_49" class="reward_collision_sphere" size="0.0470986"/>
            <body name="Hip_Yaw_Right" pos="-0.000223613 -0.00128893 -0.0814159" quat="1 0.000230496 -5.70845e-05 2.62627e-07">
              <inertial pos="-0.00409864 -0.00119663 -0.0811937" quat="0.71263 -0.0308551 -0.0343405 0.700019" mass="1.39622" diaginertia="0.00400926 0.0188996 0.00194935"/>
              <joint name="Right_Hip_Yaw" pos="0 0 0" axis="-0.00588675 -0.00344058 -0.999977" range="-0.999616 1.00123" armature="0.00841" damping="0.01224" frictionloss="0.0780055"/>
              <geom name="//unnamed_geom_50" class="visual" mesh="Hip_Yaw_Right"/>
              <geom name="//unnamed_geom_51" class="collision" size="0.0428169 0.068507" type="cylinder"/>
              <body name="Shank_Right" pos="-0.011076 -0.00225853 -0.128297" quat="1 -0.000185408 0.000756009 -0.000514054">
                <inertial pos="-0.00414221 -0.00256816 -0.115941" quat="0.998758 -0.00873219 -0.031422 -0.0376787" mass="1.16714" diaginertia="0.0052544 0.0263721 0.00142318"/>
                <joint name="Right_Knee_Pitch" pos="0 0 0" axis="-0.00232566 -0.999988 -0.00419834" range="-2.37706 -0.00750603" armature="0.00818758" damping="0.00735512" frictionloss="0.0879988"/>
                <geom name="//unnamed_geom_52" class="visual" mesh="Shank_Right"/>
                <geom name="//unnamed_geom_53" class="collision" size="0.0428169 0.0642254" pos="0 0 -0.112822" type="cylinder"/>
                <geom name="//unnamed_geom_54" class="reward_collision_sphere" size="0.055662"/>
                <body name="Ankle_Cross_Right" pos="-0.000995534 0.000191214 -0.267189" quat="1 -7.73237e-05 -4.13206e-05 -1.49515e-05">
                  <inertial pos="-0.00122651 0.00313279 -0.00748978" quat="0.442928 0.550866 0.550823 0.443797" mass="0.0437408" diaginertia="4.4522e-06 1.82692e-05 8.43869e-06"/>
                  <joint name="Right_Ankle_Pitch" pos="0 0 0" axis="-0.00579758 -0.999949 0.00822162" range="-0.29358 0.815758" armature="0.00851134" damping="0.0207482" frictionloss="0.0878731"/>
                  <geom name="//unnamed_geom_55" class="visual" mesh="Ankle_Cross_Right"/>
                  <body name="right_foot_link" pos="0.00248595 0.00143869 -0.0162373" quat="1 2.11961e-05 8.20425e-05 -0.000115157">
                    <inertial pos="-0.00010692 0.00223427 -0.00946495" quat="-0.00869537 0.620588 -0.00714055 0.784056" mass="0.413927" diaginertia="0.000401967 0.00177951 0.00157073"/>
                    <joint name="Right_Ankle_Roll" pos="0 0 0" axis="-0.999975 0.000292604 -0.00707881" range="-0.489083 0.471102" armature="0.00847108" damping="0.00726836" frictionloss="0.0974734"/>
                    <geom name="//unnamed_geom_56" class="visual" mesh="right_foot_link"/>
                    <geom name="right_foot" class="foot" size="0.0991851 0.0387784 0.0138081" pos="0.00685699 0 -0.0141027"/>
                    <geom name="//unnamed_geom_58" class="reward_collision_sphere" size="0.0342535"/>
                    <geom name="//unnamed_geom_59" class="reward_collision_sphere" size="0.0256901" pos="0.00685699 0 -0.0141027"/>
                    <geom name="//unnamed_geom_60" class="reward_collision_sphere" size="0.0256901" pos="0.0651414 0.0216921 -0.0141027"/>
                    <geom name="//unnamed_geom_61" class="reward_collision_sphere" size="0.0256901" pos="-0.047999 0.0216921 -0.0141027"/>
                    <site name="right_foot" class="foot" pos="0.00685699 0 -0.0141027" size="0.00856338"/>
                  </body>
                </body>
              </body>
            </body>
          </body>
        </body>
      </body>
    </body>
  </worldbody>

  <contact>
    <pair class="/" geom1="floor" geom2="left_foot" name="//unnamed_contact_0"/>
    <pair class="/" geom1="floor" geom2="right_foot" name="//unnamed_contact_1"/>
  </contact>

  <actuator>
    <general name="AAHead_yaw" class="/" joint="AAHead_yaw" forcerange="-5.88519 5.88519" gainprm="19.9951" biasprm="0 -19.9951 -0.540512"/>
    <general name="Head_pitch" class="/" joint="Head_pitch" forcerange="-5.86686 5.86686" gainprm="19.9951" biasprm="0 -19.9951 -0.540512"/>
    <general name="Left_Shoulder_Pitch" class="/" joint="Left_Shoulder_Pitch" forcerange="-14.9907 14.9907" gainprm="19.9951" biasprm="0 -19.9951 -0.540512"/>
    <general name="Left_Shoulder_Roll" class="/" joint="Left_Shoulder_Roll" forcerange="-14.1719 14.1719" gainprm="19.9951" biasprm="0 -19.9951 -0.540512"/>
    <general name="Left_Elbow_Pitch" class="/" joint="Left_Elbow_Pitch" forcerange="-17.1077 17.1077" gainprm="19.9951" biasprm="0 -19.9951 -0.540512"/>
    <general name="Left_Elbow_Yaw" class="/" joint="Left_Elbow_Yaw" forcerange="-15.4316 15.4316" gainprm="19.9951" biasprm="0 -19.9951 -0.540512"/>
    <general name="Right_Shoulder_Pitch" class="/" joint="Right_Shoulder_Pitch" forcerange="-15.3971 15.3971" gainprm="19.9951" biasprm="0 -19.9951 -0.540512"/>
    <general name="Right_Shoulder_Roll" class="/" joint="Right_Shoulder_Roll" forcerange="-17.0065 17.0065" gainprm="19.9951" biasprm="0 -19.9951 -0.540512"/>
    <general name="Right_Elbow_Pitch" class="/" joint="Right_Elbow_Pitch" forcerange="-15.4879 15.4879" gainprm="19.9951" biasprm="0 -19.9951 -0.540512"/>
    <general name="Right_Elbow_Yaw" class="/" joint="Right_Elbow_Yaw" forcerange="-14.7027 14.7027" gainprm="19.9951" biasprm="0 -19.9951 -0.540512"/>
    <general name="Waist" class="/" joint="Waist" forcerange="-23.4572 23.4572" gainprm="19.9951" biasprm="0 -19.9951 -0.540512"/>
    <general name="Left_Hip_Pitch" class="/" joint="Left_Hip_Pitch" forcerange="-37.3162 37.3162" gainprm="19.9951" biasprm="0 -19.9951 -0.540512"/>
    <general name="Left_Hip_Roll" class="/" joint="Left_Hip_Roll" forcerange="-27.6812 27.6812" gainprm="19.9951" biasprm="0 -19.9951 -0.540512"/>
    <general name="Left_Hip_Yaw" class="/" joint="Left_Hip_Yaw" forcerange="-23.0168 23.0168" gainprm="19.9951" biasprm="0 -19.9951 -0.540512"/>
    <general name="Left_Knee_Pitch" class="/" joint="Left_Knee_Pitch" forcerange="-51.2155 51.2155" gainprm="19.9951" biasprm="0 -19.9951 -0.540512"/>
    <general name="Left_Ankle_Pitch" class="/" joint="Left_Ankle_Pitch" forcerange="-17.2415 17.2415" gainprm="19.9951" biasprm="0 -19.9951 -0.540512"/>
    <general name="Left_Ankle_Roll" class="/" joint="Left_Ankle_Roll" forcerange="-13.6379 13.6379" gainprm="19.9951" biasprm="0 -19.9951 -0.540512"/>
    <general name="Right_Hip_Pitch" class="/" joint="Right_Hip_Pitch" forcerange="-41.4626 41.4626" gainprm="19.9951" biasprm="0 -19.9951 -0.540512"/>
    <general name="Right_Hip_Roll" class="/" joint="Right_Hip_Roll" forcerange="-26.5323 26.5323" gainprm="19.9951" biasprm="0 -19.9951 -0.540512"/>
    <general name="Right_Hip_Yaw" class="/" joint="Right_Hip_Yaw" forcerange="-25.3396 25.3396" gainprm="19.9951" biasprm="0 -19.9951 -0.540512"/>
    <general name="Right_Knee_Pitch" class="/" joint="Right_Knee_Pitch" forcerange="-56.4428 56.4428" gainprm="19.9951" biasprm="0 -19.9951 -0.540512"/>
    <general name="Right_Ankle_Pitch" class="/" joint="Right_Ankle_Pitch" forcerange="-16.4579 16.4579" gainprm="19.9951" biasprm="0 -19.9951 -0.540512"/>
    <general name="Right_Ankle_Roll" class="/" joint="Right_Ankle_Roll" forcerange="-14.0596 14.0596" gainprm="19.9951" biasprm="0 -19.9951 -0.540512"/>
  </actuator>

  <sensor>
    <gyro site="imu" name="imu_angular_velocity"/>
    <velocimeter site="imu" name="imu_linear_velocity"/>
    <framelinvel objtype="site" objname="left_foot" name="left_foot_global_linear_velocity"/>
    <framelinvel objtype="site" objname="right_foot" name="right_foot_global_linear_velocity"/>
  </sensor>

  <keyframe>
    <key name="home" qpos="0 0 0.6385 1 0 0 0 0 0 0 1.4 0 -0.4 0 -1.4 0 0.4 0 -0.4 0 0 0.8 -0.4 0 0.4 0 0 -0.8 0.4 0"/>
  </keyframe>
</mujoco>
