<mujoco model="T1">
  <compiler angle="radian" assetdir="assets" balanceinertia="true" inertiafromgeom="false"/>

  <option timestep="0.005" density="1.2" viscosity="2e-05"/>

  <size nkey="1"/>

  <visual>
    <quality shadowsize="8192"/>
    <map shadowclip="0.5"/>
  </visual>

  <default>
    <default class="/">
      <joint armature="0.01" damping="0.01" frictionloss="0.1"/>
      <geom contype="0" conaffinity="0" group="1" solref="-1000 -80"/>
      <site size="0.01 0.005 0.005" group="5"/>
      <general forcelimited="true" biastype="affine" gainprm="25" biasprm="0 -25 -0.6"/>
      <default class="t1">
        <geom rgba="0.25 0.25 0.25 1"/>
        <default class="visual">
          <geom type="mesh" group="2"/>
        </default>
        <default class="collision">
          <geom group="3"/>
        </default>
        <default class="foot">
          <geom size="0.1115 0.05 0.015" type="box" condim="6" group="4" priority="1" solimp="0.015 1 0.015"/>
        </default>
        <default class="reward_collision_sphere">
          <geom group="5" rgba="1 0 0 1"/>
        </default>
      </default>
    </default>
  </default>

  <asset>
    <texture type="skybox" colorspace="auto" name="//unnamed_texture_0" builtin="gradient" rgb1="0.95 0.95 0.95" rgb2="0.95 0.95 0.95" width="100" height="600"/>
    <texture type="2d" colorspace="auto" name="texplane" builtin="checker" rgb1="0.345 0.575 0.748" rgb2="0.345 0.575 0.748" markrgb="1 1 1" width="512" height="512"/>
    <material name="MatPlane" class="/" texture="texplane" texuniform="true" texrepeat="2 2" specular="0.9"/>
    <mesh name="Trunk" class="/" file="Trunk.stl"/>
    <mesh name="H1" class="/" file="H1.stl"/>
    <mesh name="H2" class="/" file="H2.stl"/>
    <mesh name="AL1" class="/" file="AL1.stl"/>
    <mesh name="AL2" class="/" file="AL2.stl"/>
    <mesh name="AL3" class="/" file="AL3.stl"/>
    <mesh name="left_hand_link" class="/" file="left_hand_link.stl"/>
    <mesh name="AR1" class="/" file="AR1.stl"/>
    <mesh name="AR2" class="/" file="AR2.stl"/>
    <mesh name="AR3" class="/" file="AR3.stl"/>
    <mesh name="right_hand_link" class="/" file="right_hand_link.stl"/>
    <mesh name="Waist" class="/" file="Waist.stl"/>
    <mesh name="Hip_Pitch_Left" class="/" file="Hip_Pitch_Left.stl"/>
    <mesh name="Hip_Roll_Left" class="/" file="Hip_Roll_Left.stl"/>
    <mesh name="Hip_Yaw_Left" class="/" file="Hip_Yaw_Left.stl"/>
    <mesh name="Shank_Left" class="/" file="Shank_Left.stl"/>
    <mesh name="Ankle_Cross_Left" class="/" file="Ankle_Cross_Left.stl"/>
    <mesh name="left_foot_link" class="/" file="left_foot_link.stl"/>
    <mesh name="Hip_Pitch_Right" class="/" file="Hip_Pitch_Right.stl"/>
    <mesh name="Hip_Roll_Right" class="/" file="Hip_Roll_Right.stl"/>
    <mesh name="Hip_Yaw_Right" class="/" file="Hip_Yaw_Right.stl"/>
    <mesh name="Shank_Right" class="/" file="Shank_Right.stl"/>
    <mesh name="Ankle_Cross_Right" class="/" file="Ankle_Cross_Right.stl"/>
    <mesh name="right_foot_link" class="/" file="right_foot_link.stl"/>
  </asset>

  <worldbody>
    <geom name="floor" class="/" size="100 100 0.125" type="plane" group="0" material="MatPlane"/>
    <light name="toplight_shadow" class="/" pos="0 0 5" dir="0.0990148 0.0990148 -0.990148" type="directional" ambient="0.04 0.04 0.04" diffuse="0.55 0.55 0.55" specular="0.12 0.12 0.12"/>
    <light name="toplight_fill" class="/" pos="0 0 5" dir="0.0990148 0.0990148 -0.990148" type="directional" castshadow="false" ambient="0.04 0.04 0.04" diffuse="0.3 0.3 0.3" specular="0.08 0.08 0.08"/>
    <body name="trunk" childclass="t1" pos="0.000865347 0.000271983 0.00335865" quat="0.999998 0.00117927 -0.000820525 0.00154449">
      <inertial pos="0.0457246 -0.00131471 0.100076" quat="0.99996 0.000911936 -0.0087682 0.00144928" mass="12.0409" diaginertia="0.0382954 0.191161 0.0414166"/>
      <joint name="//unnamed_joint_0" type="free" armature="0" damping="0" frictionloss="0"/>
      <geom name="//unnamed_geom_1" class="visual" rgba="0.76 0.76 0.76 1" mesh="Trunk"/>
      <geom name="//unnamed_geom_2" class="collision" size="0.0740787 0.0987716 0.148157" pos="0.0502272 0 0.112636" type="box"/>
      <geom name="//unnamed_geom_3" class="reward_collision_sphere" size="0.113587" pos="0.0502272 0 0.0938633"/>
      <geom name="//unnamed_geom_4" class="reward_collision_sphere" size="0.0148157" pos="0.0502272 0.100929 0"/>
      <geom name="//unnamed_geom_5" class="reward_collision_sphere" size="0.0148157" pos="0.0502272 -0.100929 0"/>
      <geom name="//unnamed_geom_6" class="reward_collision_sphere" size="0.0148157" pos="0.0502272 0.127051 0.168954"/>
      <geom name="//unnamed_geom_7" class="reward_collision_sphere" size="0.0148157" pos="0.0502272 -0.127051 0.168954"/>
      <site name="imu" pos="0.0159042 -0.00820224 0.00357031" size="0.00987716"/>
      <camera name="track" pos="0 -2.37479 0" quat="0.707107 0.707107 0 0" mode="trackcom"/>
      <camera name="ego_camera" pos="0.102129 0 0.394226" quat="-0.5 -0.5 0.5 0.5"/>
      <body name="H1" pos="0.0517093 3.53655e-05 0.226959" quat="0.999999 0.000460896 0.00110805 -0.000592458">
        <inertial pos="-0.00229432 -0.000506536 0.0564847" quat="0.762904 -0.0103818 -0.00148564 0.646427" mass="0.442711" diaginertia="0.000103838 0.000528863 0.000112791"/>
        <joint name="AAHead_yaw" pos="0 0 0" axis="0.00216259 -0.00592274 0.99998" range="-1.47331 1.52104" armature="0.0105189" damping="0" frictionloss="0.109193"/>
        <geom name="//unnamed_geom_8" class="visual" mesh="H1"/>
        <body name="H2" pos="-0.0041053 0.00232127 0.0568474" quat="0.999998 -0.000266121 -0.00165488 -0.00085717">
          <inertial pos="0.00638708 0.00310315 0.0935848" quat="0.988435 0.106336 -0.0745542 -0.0783017" mass="0.631716" diaginertia="0.000831327 0.00454014 0.00124723"/>
          <joint name="Head_pitch" pos="0 0 0" axis="-0.00916957 -0.999892 -0.0115208" range="-1.21085 0.284472" armature="0.00876474" damping="0" frictionloss="0.0799115"/>
          <geom name="//unnamed_geom_9" class="visual" mesh="H2"/>
          <geom name="//unnamed_geom_10" class="collision" size="0.0790173" pos="0.0083712 0 0.10325"/>
          <geom name="//unnamed_geom_11" class="reward_collision_sphere" size="0.0888944" pos="0.0167424 0 0.0938633"/>
        </body>
      </body>
      <body name="AL1" pos="0.0451726 0.127544 0.206949" quat="0.999999 0.000130145 0.00164242 -7.57998e-05">
        <inertial pos="0.00321752 0.0513731 -0.00192348" quat="0.504405 0.493904 -0.503261 0.498361" mass="0.507851" diaginertia="0.000575109 0.00284479 0.000207437"/>
        <joint name="Left_Shoulder_Pitch" pos="0 0 0" axis="-0.000430108 1 7.72333e-05" range="-3.33918 1.21764" armature="0.0103008" damping="0.0131735" frictionloss="0.0887348"/>
        <geom name="//unnamed_geom_12" class="visual" rgba="0.76 0.76 0.76 1" mesh="AL1"/>
        <body name="AL2" pos="0.00369025 0.0554039 0.00402822" quat="0.999999 0.000228868 0.000141919 0.00162964">
          <inertial pos="0.00137507 0.0451687 0.00222259" quat="0.48752 0.5181 -0.481169 0.512224" mass="0.151118" diaginertia="0.000158447 0.000805157 0.000131921"/>
          <joint name="Left_Shoulder_Roll" pos="0 0 0" axis="-0.999858 0.0168115 -0.00144657" range="-1.59039 1.69013" armature="0.0111268" damping="0.00794306" frictionloss="0.115089"/>
          <geom name="//unnamed_geom_13" class="visual" mesh="AL2"/>
          <body name="AL3" pos="0.00380235 0.0707463 -0.000917688" quat="0.999999 0.00124184 -0.000452652 -0.000211386">
            <inertial pos="-0.00266415 0.101142 -0.00246793" quat="0.70726 0.706946 -0.00128058 -0.00313892" mass="0.976533" diaginertia="0.00541817 0.0297794 0.00044646"/>
            <joint name="Left_Elbow_Pitch" pos="0 0 0" axis="-0.00651049 -0.999908 0.011926" range="-2.22793 2.28131" armature="0.00874584" damping="0.0130626" frictionloss="0.108404"/>
            <geom name="//unnamed_geom_14" class="visual" mesh="AL3"/>
            <geom name="//unnamed_geom_15" class="collision" size="0.0296315 0.0740787" pos="0 0.0593697 0" quat="0.707105 0.707108 0 0" type="cylinder"/>
            <geom name="//unnamed_geom_16" class="reward_collision_sphere" size="0.0355578"/>
            <body name="left_hand_link" pos="-3.78979e-05 0.177867 -0.00412854" quat="0.999999 0.000114321 -0.000639573 0.000959506">
              <inertial pos="-0.000253297 0.131765 0.000165039" quat="0.706996 0.707217 -0.000487531 -0.000403341" mass="0.292151" diaginertia="0.00333292 0.0182203 0.000148144"/>
              <joint name="Left_Elbow_Yaw" pos="0 0 0" axis="-0.00835164 -0.00683066 0.999942" range="-2.39527 0.00538973" armature="0.0112333" damping="0.0133881" frictionloss="0.100695"/>
              <geom name="//unnamed_geom_17" class="visual" mesh="left_hand_link"/>
              <geom name="//unnamed_geom_18" class="collision" size="0.0296315 0.0864251" pos="0 0.154361 0" quat="0.707105 0.707108 0 0" type="cylinder"/>
              <geom name="//unnamed_geom_19" class="reward_collision_sphere" size="0.0493858"/>
              <geom name="//unnamed_geom_20" class="reward_collision_sphere" size="0.0345701" pos="0 0.130613 0"/>
              <geom name="//unnamed_geom_21" class="reward_collision_sphere" size="0.0345701" pos="0 0.25529 0"/>
            </body>
          </body>
        </body>
      </body>
      <body name="AR1" pos="0.04747 -0.122348 0.204046" quat="0.999999 0.000421958 -0.000539537 -0.000813517">
        <inertial pos="-0.00057942 -0.0553308 0.00257384" quat="0.501283 0.49349 -0.502676 0.502493" mass="0.49428" diaginertia="0.000555443 0.00293418 0.00020872"/>
        <joint name="Right_Shoulder_Pitch" pos="0 0 0" axis="-0.00218742 -0.999818 -0.0189528" stiffness="0.00630022" range="-1.23438 3.31498" armature="0.0088895" damping="0.00884785" frictionloss="0.107459"/>
        <geom name="//unnamed_geom_22" class="visual" rgba="0.76 0.76 0.76 1" mesh="AR1"/>
        <body name="AR2" pos="0.000762609 -0.0522927 0.00392218" quat="1 0.000208874 -8.9389e-05 2.75194e-05">
          <inertial pos="0.00100947 -0.0458038 0.000151295" quat="0.511721 0.488058 -0.511629 0.488033" mass="0.157613" diaginertia="0.000155499 0.000788834 0.000131648"/>
          <joint name="Right_Shoulder_Roll" pos="0 0 0" axis="-0.999994 -0.00335998 0.000681268" range="-1.68429 1.55484" armature="0.00954567" damping="0.0146721" frictionloss="0.0881803"/>
          <geom name="//unnamed_geom_23" class="visual" mesh="AR2"/>
          <body name="AR3" pos="0.0032906 -0.0732037 -0.00292934" quat="0.999999 -0.00103899 0.000818504 -0.000109221">
            <inertial pos="0.00380758 -0.101088 0.00287407" quat="0.707596 0.706615 -0.00155693 0.000419153" mass="0.963801" diaginertia="0.00538928 0.031463 0.000453491"/>
            <joint name="Right_Elbow_Pitch" pos="0 0 0" axis="0.00513854 0.999977 -0.00436482" stiffness="0.0180494" range="-2.26035 2.23927" armature="0.0104174" damping="0.00365388" frictionloss="0.0905842"/>
            <geom name="//unnamed_geom_24" class="visual" mesh="AR3"/>
            <geom name="//unnamed_geom_25" class="collision" size="0.0296315 0.0740787" pos="0 -0.0593697 0" quat="0.707105 0.707108 0 0" type="cylinder"/>
            <geom name="//unnamed_geom_26" class="reward_collision_sphere" size="0.0355578"/>
            <body name="right_hand_link" pos="-0.000841726 -0.173061 -0.00400814" quat="1 -0.000346698 0.000390738 -0.000166358">
              <inertial pos="0.000327719 -0.130863 -0.00173929" quat="0.704549 0.709546 0.010654 -0.00647109" mass="0.307628" diaginertia="0.00337857 0.0183191 0.000156567"/>
              <joint name="Right_Elbow_Yaw" pos="0 0 0" axis="-0.00676846 -0.000300541 0.999977" range="-0.0332901 2.44417" armature="0.00877378" damping="0.000766903" frictionloss="0.104081"/>
              <geom name="//unnamed_geom_27" class="visual" mesh="right_hand_link"/>
              <geom name="//unnamed_geom_28" class="collision" size="0.0296315 0.0864251" pos="0 -0.154361 0" quat="0.707105 0.707108 0 0" type="cylinder"/>
              <geom name="//unnamed_geom_29" class="reward_collision_sphere" size="0.0493858"/>
              <geom name="//unnamed_geom_30" class="reward_collision_sphere" size="0.0345701" pos="0 -0.130613 0"/>
              <geom name="//unnamed_geom_31" class="reward_collision_sphere" size="0.0345701" pos="0 -0.25529 0"/>
            </body>
          </body>
        </body>
      </body>
      <body name="Waist" pos="0.0501287 -0.00447664 -0.109416" quat="1 0.000198042 0.000135182 -0.000479232">
        <inertial pos="0.0038001 -0.00053594 0.00913001" quat="0.983508 0.000514518 -0.180844 0.00252885" mass="2.57484" diaginertia="0.00226003 0.0124435 0.00353206"/>
        <joint name="Waist" pos="0 0 0" axis="0.00900212 0.0106839 0.999902" range="-1.55705 1.59783" armature="0.00965643" damping="0.0180531" frictionloss="0.10252"/>
        <geom name="//unnamed_geom_32" class="visual" mesh="Waist"/>
        <body name="Hip_Pitch_Left" pos="0.00308152 0.121398 -0.00263044" quat="1 -0.000177309 0.000214253 0.000103136">
          <inertial pos="0.000653452 -0.00890911 -0.0129103" quat="0.974886 0.221509 0.0181867 0.0141535" mass="0.94846" diaginertia="0.000746103 0.00347692 0.00094017"/>
          <joint name="Left_Hip_Pitch" pos="0 0 0" axis="0.00248179 0.999997 -2.07289e-05" stiffness="0.00237769" range="-1.83073 1.5665" armature="0.00963734" damping="0.0117026" frictionloss="0.107495"/>
          <geom name="//unnamed_geom_33" class="visual" rgba="0.76 0.76 0.76 1" mesh="Hip_Pitch_Left"/>
          <body name="Hip_Roll_Left" pos="0.00202601 -0.00089068 -0.0215971" quat="1 -0.000448173 0.000285365 -0.000173328">
            <inertial pos="0.0011527 -0.00264089 -0.0500025" quat="0.710084 -0.0135702 -0.00730864 0.703948" mass="0.362383" diaginertia="0.000690184 0.00359743 0.000372433"/>
            <joint name="Left_Hip_Roll" pos="0 0 0" axis="-0.99995 -0.00552014 0.00831394" stiffness="0.00548876" range="-1.57618 0.210099" armature="0.00992628" damping="0.00838199" frictionloss="0.100411"/>
            <geom name="//unnamed_geom_34" class="visual" mesh="Hip_Roll_Left"/>
            <geom name="//unnamed_geom_35" class="reward_collision_sphere" size="0.0543244"/>
            <body name="Hip_Yaw_Left" pos="0.00153403 0.0021537 -0.0818304" quat="1 -0.000217583 0.000199212 -3.13916e-05">
              <inertial pos="-0.00307237 -0.000507363 -0.0808328" quat="0.691811 -0.0309818 -0.040719 0.720264" mass="2.07874" diaginertia="0.00988656 0.0612519 0.00186"/>
              <joint name="Left_Hip_Yaw" pos="0 0 0" axis="0.00420304 -0.0023134 -0.999988" stiffness="0.0193911" range="-0.995836 0.990636" armature="0.0100707" damping="0" frictionloss="0.110139"/>
              <geom name="//unnamed_geom_36" class="visual" mesh="Hip_Yaw_Left"/>
              <geom name="//unnamed_geom_37" class="collision" size="0.0493858 0.0790173" type="cylinder"/>
              <body name="Shank_Left" pos="-0.0116021 -0.00278136 -0.128439" quat="0.999998 0.00166959 -0.000701573 0.000714438">
                <inertial pos="-0.00333647 0.00507814 -0.119317" quat="0.996773 0.00763089 -0.027934 0.0748708" mass="1.70719" diaginertia="0.0142725 0.0818217 0.00138837"/>
                <joint name="Left_Knee_Pitch" pos="0 0 0" axis="-0.00748407 0.999945 0.00730449" range="-0.0535787 2.34721" armature="0.00976729" damping="0" frictionloss="0.112422"/>
                <geom name="//unnamed_geom_38" class="visual" mesh="Shank_Left"/>
                <geom name="//unnamed_geom_39" class="collision" size="0.0493858 0.0740787" pos="0 0 -0.112636" type="cylinder"/>
                <geom name="//unnamed_geom_40" class="reward_collision_sphere" size="0.0642015"/>
                <body name="Ankle_Cross_Left" pos="0.00374791 -0.00231977 -0.262806" quat="1 -4.44454e-05 4.31757e-06 4.40038e-05">
                  <inertial pos="-0.00124714 -0.00101709 -0.00685265" quat="0.438651 0.566447 0.544765 0.435837" mass="0.0747274" diaginertia="1.18968e-05 6.10379e-05 8.42704e-06"/>
                  <joint name="Left_Ankle_Pitch" pos="0 0 0" axis="1.34352e-05 1 -0.000102393" range="-0.893732 0.392638" armature="0.00938859" damping="0" frictionloss="0.101497"/>
                  <geom name="//unnamed_geom_41" class="visual" mesh="Ankle_Cross_Left"/>
                  <body name="left_foot_link" pos="-0.00102434 0.000355556 -0.0110174" quat="1 2.05734e-06 -2.1285e-05 -7.19869e-05">
                    <inertial pos="-9.60619e-05 -0.000270493 -0.0130399" quat="-0.00117957 0.620945 0.000844615 0.783853" mass="0.638386" diaginertia="0.00108377 0.00539338 0.00152552"/>
                    <joint name="Left_Ankle_Roll" pos="0 0 0" axis="-0.999981 0.00599468 -0.00116089" stiffness="0.00417976" range="-0.439751 0.475852" armature="0.00967428" damping="0" frictionloss="0.100143"/>
                    <geom name="//unnamed_geom_42" class="visual" mesh="left_foot_link"/>
                    <geom name="left_foot" class="foot" size="0.0988717 0.043609 0.0154984" pos="0.0083712 0 -0.0140795"/>
                    <geom name="//unnamed_geom_44" class="reward_collision_sphere" size="0.0513612" pos="0.0083712 0 -0.0140795"/>
                    <geom name="//unnamed_geom_45" class="reward_collision_sphere" size="0.0296315" pos="0.0795264 -0.0273101 -0.0140795"/>
                    <geom name="//unnamed_geom_46" class="reward_collision_sphere" size="0.0296315" pos="-0.0585984 -0.0273101 -0.0140795"/>
                    <site name="left_foot" class="foot" pos="0.0083712 0 -0.0140795" size="0.00987716"/>
                  </body>
                </body>
              </body>
            </body>
          </body>
        </body>
        <body name="Hip_Pitch_Right" pos="0.000239152 -0.126224 -0.00236341" quat="0.999999 -0.00149128 0.000446882 -0.000187077">
          <inertial pos="-0.000140905 0.0129576 -0.0140572" quat="0.975258 -0.220841 0.00891805 -0.00463813" mass="1.01473" diaginertia="0.0007843 0.00355908 0.000954585"/>
          <joint name="Right_Hip_Pitch" pos="0 0 0" axis="0.00390647 -0.999992 0.000840625" range="-1.56056 1.8396" armature="0.00959925" damping="0.0124579" frictionloss="0.0803983"/>
          <geom name="//unnamed_geom_47" class="visual" rgba="0.76 0.76 0.76 1" mesh="Hip_Pitch_Right"/>
          <body name="Hip_Roll_Right" pos="0.00220742 -0.00148045 -0.0196751" quat="1 -0.000118236 0.000354342 0.000395098">
            <inertial pos="-0.00126127 -0.000550974 -0.0486023" quat="0.707655 -0.00635794 -0.00743122 0.70649" mass="0.370062" diaginertia="0.00075934 0.0036741 0.000385557"/>
            <joint name="Right_Hip_Roll" pos="0 0 0" axis="-0.999947 -0.00762973 -0.00696578" stiffness="0.000483461" range="-0.196444 1.52181" armature="0.00989715" damping="0" frictionloss="0.0914228"/>
            <geom name="//unnamed_geom_48" class="visual" mesh="Hip_Roll_Right"/>
            <geom name="//unnamed_geom_49" class="reward_collision_sphere" size="0.0543244"/>
            <body name="Hip_Yaw_Right" pos="-0.00162426 0.0012432 -0.0788231" quat="1 -0.000773928 -0.000156983 -0.00030123">
              <inertial pos="-0.00407612 -0.00457225 -0.0814271" quat="0.714724 -0.0306317 -0.0339504 0.69791" mass="2.14272" diaginertia="0.0108252 0.0649586 0.00194029"/>
              <joint name="Right_Hip_Yaw" pos="0 0 0" axis="-0.00866422 0.0112322 -0.999899" range="-0.969763 1.015" armature="0.00983671" damping="0" frictionloss="0.098635"/>
              <geom name="//unnamed_geom_50" class="visual" mesh="Hip_Yaw_Right"/>
              <geom name="//unnamed_geom_51" class="collision" size="0.0493858 0.0790173" type="cylinder"/>
              <body name="Shank_Right" pos="-0.0149321 -0.00185638 -0.12985" quat="1 1.47043e-05 1.97242e-05 -7.65545e-05">
                <inertial pos="-3.05678e-05 0.00246905 -0.115351" quat="0.998705 0.0105131 -0.0392447 -0.0306299" mass="1.80328" diaginertia="0.0146463 0.0856283 0.00151229"/>
                <joint name="Right_Knee_Pitch" pos="0 0 0" axis="0.00343335 -0.999991 -0.00245318" stiffness="0.00768119" range="-2.33815 0.0464744" armature="0.00948858" damping="0.00659978" frictionloss="0.0995575"/>
                <geom name="//unnamed_geom_52" class="visual" mesh="Shank_Right"/>
                <geom name="//unnamed_geom_53" class="collision" size="0.0493858 0.0740787" pos="0 0 -0.112636" type="cylinder"/>
                <geom name="//unnamed_geom_54" class="reward_collision_sphere" size="0.0642015"/>
                <body name="Ankle_Cross_Right" pos="-0.000994252 -0.00179276 -0.260919" quat="0.999999 -0.000622359 -0.000892842 -0.000447745">
                  <inertial pos="-0.00364635 -0.000968653 -0.00889437" quat="0.44351 0.549624 0.5548 0.439784" mass="0.0673441" diaginertia="1.14213e-05 5.71132e-05 8.00901e-06"/>
                  <joint name="Right_Ankle_Pitch" pos="0 0 0" axis="0.00110044 -0.999997 -0.00212192" range="-0.450532 0.876457" armature="0.00873168" damping="0.0159213" frictionloss="0.0945727"/>
                  <geom name="//unnamed_geom_55" class="visual" mesh="Ankle_Cross_Right"/>
                  <body name="right_foot_link" pos="-0.0033537 -0.00308626 -0.011614" quat="1 -3.28337e-05 0.00012751 4.0924e-05">
                    <inertial pos="0.000918704 -0.00205441 -0.0126619" quat="-0.00365872 0.613414 0.00528459 0.789736" mass="0.638418" diaginertia="0.00111512 0.00558993 0.00153815"/>
                    <joint name="Right_Ankle_Roll" pos="0 0 0" axis="-1 -0.000176807 -0.000458724" range="-0.492851 0.440717" armature="0.01094" damping="0" frictionloss="0.0743171"/>
                    <geom name="//unnamed_geom_56" class="visual" mesh="right_foot_link"/>
                    <geom name="right_foot" class="foot" size="0.100489 0.0565103 0.0122313" pos="0.0083712 0 -0.0140795"/>
                    <geom name="//unnamed_geom_58" class="reward_collision_sphere" size="0.0395086"/>
                    <geom name="//unnamed_geom_59" class="reward_collision_sphere" size="0.0296315" pos="0.0083712 0 -0.0140795"/>
                    <geom name="//unnamed_geom_60" class="reward_collision_sphere" size="0.0296315" pos="0.0795264 0.0273101 -0.0140795"/>
                    <geom name="//unnamed_geom_61" class="reward_collision_sphere" size="0.0296315" pos="-0.0585984 0.0273101 -0.0140795"/>
                    <site name="right_foot" class="foot" pos="0.0083712 0 -0.0140795" size="0.00987716"/>
                  </body>
                </body>
              </body>
            </body>
          </body>
        </body>
      </body>
    </body>
  </worldbody>

  <contact>
    <pair class="/" geom1="floor" geom2="left_foot" name="//unnamed_contact_0"/>
    <pair class="/" geom1="floor" geom2="right_foot" name="//unnamed_contact_1"/>
  </contact>

  <actuator>
    <general name="AAHead_yaw" class="/" joint="AAHead_yaw" forcerange="-6.85868 6.85868" gainprm="24.0017" biasprm="0 -24.0017 -0.588026"/>
    <general name="Head_pitch" class="/" joint="Head_pitch" forcerange="-7.3546 7.3546" gainprm="24.0017" biasprm="0 -24.0017 -0.588026"/>
    <general name="Left_Shoulder_Pitch" class="/" joint="Left_Shoulder_Pitch" forcerange="-16.4822 16.4822" gainprm="24.0017" biasprm="0 -24.0017 -0.588026"/>
    <general name="Left_Shoulder_Roll" class="/" joint="Left_Shoulder_Roll" forcerange="-19.3234 19.3234" gainprm="24.0017" biasprm="0 -24.0017 -0.588026"/>
    <general name="Left_Elbow_Pitch" class="/" joint="Left_Elbow_Pitch" forcerange="-19.1483 19.1483" gainprm="24.0017" biasprm="0 -24.0017 -0.588026"/>
    <general name="Left_Elbow_Yaw" class="/" joint="Left_Elbow_Yaw" forcerange="-17.9818 17.9818" gainprm="24.0017" biasprm="0 -24.0017 -0.588026"/>
    <general name="Right_Shoulder_Pitch" class="/" joint="Right_Shoulder_Pitch" forcerange="-19.8117 19.8117" gainprm="24.0017" biasprm="0 -24.0017 -0.588026"/>
    <general name="Right_Shoulder_Roll" class="/" joint="Right_Shoulder_Roll" forcerange="-18.2581 18.2581" gainprm="24.0017" biasprm="0 -24.0017 -0.588026"/>
    <general name="Right_Elbow_Pitch" class="/" joint="Right_Elbow_Pitch" forcerange="-17.5971 17.5971" gainprm="24.0017" biasprm="0 -24.0017 -0.588026"/>
    <general name="Right_Elbow_Yaw" class="/" joint="Right_Elbow_Yaw" forcerange="-18.1137 18.1137" gainprm="24.0017" biasprm="0 -24.0017 -0.588026"/>
    <general name="Waist" class="/" joint="Waist" forcerange="-30.0151 30.0151" gainprm="24.0017" biasprm="0 -24.0017 -0.588026"/>
    <general name="Left_Hip_Pitch" class="/" joint="Left_Hip_Pitch" forcerange="-43.3229 43.3229" gainprm="24.0017" biasprm="0 -24.0017 -0.588026"/>
    <general name="Left_Hip_Roll" class="/" joint="Left_Hip_Roll" forcerange="-25.4739 25.4739" gainprm="24.0017" biasprm="0 -24.0017 -0.588026"/>
    <general name="Left_Hip_Yaw" class="/" joint="Left_Hip_Yaw" forcerange="-29.0859 29.0859" gainprm="24.0017" biasprm="0 -24.0017 -0.588026"/>
    <general name="Left_Knee_Pitch" class="/" joint="Left_Knee_Pitch" forcerange="-51.9525 51.9525" gainprm="24.0017" biasprm="0 -24.0017 -0.588026"/>
    <general name="Left_Ankle_Pitch" class="/" joint="Left_Ankle_Pitch" forcerange="-19.263 19.263" gainprm="24.0017" biasprm="0 -24.0017 -0.588026"/>
    <general name="Left_Ankle_Roll" class="/" joint="Left_Ankle_Roll" forcerange="-14.2219 14.2219" gainprm="24.0017" biasprm="0 -24.0017 -0.588026"/>
    <general name="Right_Hip_Pitch" class="/" joint="Right_Hip_Pitch" forcerange="-48.3751 48.3751" gainprm="24.0017" biasprm="0 -24.0017 -0.588026"/>
    <general name="Right_Hip_Roll" class="/" joint="Right_Hip_Roll" forcerange="-27.5885 27.5885" gainprm="24.0017" biasprm="0 -24.0017 -0.588026"/>
    <general name="Right_Hip_Yaw" class="/" joint="Right_Hip_Yaw" forcerange="-30.0675 30.0675" gainprm="24.0017" biasprm="0 -24.0017 -0.588026"/>
    <general name="Right_Knee_Pitch" class="/" joint="Right_Knee_Pitch" forcerange="-56.6519 56.6519" gainprm="24.0017" biasprm="0 -24.0017 -0.588026"/>
    <general name="Right_Ankle_Pitch" class="/" joint="Right_Ankle_Pitch" forcerange="-19.2073 19.2073" gainprm="24.0017" biasprm="0 -24.0017 -0.588026"/>
    <general name="Right_Ankle_Roll" class="/" joint="Right_Ankle_Roll" forcerange="-14.233 14.233" gainprm="24.0017" biasprm="0 -24.0017 -0.588026"/>
  </actuator>

  <sensor>
    <gyro site="imu" name="imu_angular_velocity"/>
    <velocimeter site="imu" name="imu_linear_velocity"/>
    <framelinvel objtype="site" objname="left_foot" name="left_foot_global_linear_velocity"/>
    <framelinvel objtype="site" objname="right_foot" name="right_foot_global_linear_velocity"/>
  </sensor>

  <keyframe>
    <key name="home" qpos="0 0 0.6385 1 0 0 0 0 0 0 1.4 0 -0.4 0 -1.4 0 0.4 0 -0.4 0 0 0.8 -0.4 0 0.4 0 0 -0.8 0.4 0"/>
  </keyframe>
</mujoco>
