<mujoco model="T1">
  <compiler angle="radian" assetdir="assets" balanceinertia="true" inertiafromgeom="false"/>

  <option timestep="0.005" density="1.2" viscosity="2e-05"/>

  <size nkey="1"/>

  <visual>
    <quality shadowsize="8192"/>
    <map shadowclip="0.5"/>
  </visual>

  <default>
    <default class="/">
      <joint armature="0.01" damping="0.01" frictionloss="0.1"/>
      <geom contype="0" conaffinity="0" group="1" solref="-1000 -80"/>
      <site size="0.01 0.005 0.005" group="5"/>
      <general forcelimited="true" biastype="affine" gainprm="25" biasprm="0 -25 -0.6"/>
      <default class="t1">
        <geom rgba="0.25 0.25 0.25 1"/>
        <default class="visual">
          <geom type="mesh" group="2"/>
        </default>
        <default class="collision">
          <geom group="3"/>
        </default>
        <default class="foot">
          <geom size="0.1115 0.05 0.015" type="box" condim="6" group="4" priority="1" solimp="0.015 1 0.015"/>
        </default>
        <default class="reward_collision_sphere">
          <geom group="5" rgba="1 0 0 1"/>
        </default>
      </default>
    </default>
  </default>

  <asset>
    <texture type="skybox" colorspace="auto" name="//unnamed_texture_0" builtin="gradient" rgb1="0.95 0.95 0.95" rgb2="0.95 0.95 0.95" width="100" height="600"/>
    <texture type="2d" colorspace="auto" name="texplane" builtin="checker" rgb1="0.345 0.575 0.748" rgb2="0.345 0.575 0.748" markrgb="1 1 1" width="512" height="512"/>
    <material name="MatPlane" class="/" texture="texplane" texuniform="true" texrepeat="2 2" specular="0.9"/>
    <mesh name="Trunk" class="/" file="Trunk.stl"/>
    <mesh name="H1" class="/" file="H1.stl"/>
    <mesh name="H2" class="/" file="H2.stl"/>
    <mesh name="AL1" class="/" file="AL1.stl"/>
    <mesh name="AL2" class="/" file="AL2.stl"/>
    <mesh name="AL3" class="/" file="AL3.stl"/>
    <mesh name="left_hand_link" class="/" file="left_hand_link.stl"/>
    <mesh name="AR1" class="/" file="AR1.stl"/>
    <mesh name="AR2" class="/" file="AR2.stl"/>
    <mesh name="AR3" class="/" file="AR3.stl"/>
    <mesh name="right_hand_link" class="/" file="right_hand_link.stl"/>
    <mesh name="Waist" class="/" file="Waist.stl"/>
    <mesh name="Hip_Pitch_Left" class="/" file="Hip_Pitch_Left.stl"/>
    <mesh name="Hip_Roll_Left" class="/" file="Hip_Roll_Left.stl"/>
    <mesh name="Hip_Yaw_Left" class="/" file="Hip_Yaw_Left.stl"/>
    <mesh name="Shank_Left" class="/" file="Shank_Left.stl"/>
    <mesh name="Ankle_Cross_Left" class="/" file="Ankle_Cross_Left.stl"/>
    <mesh name="left_foot_link" class="/" file="left_foot_link.stl"/>
    <mesh name="Hip_Pitch_Right" class="/" file="Hip_Pitch_Right.stl"/>
    <mesh name="Hip_Roll_Right" class="/" file="Hip_Roll_Right.stl"/>
    <mesh name="Hip_Yaw_Right" class="/" file="Hip_Yaw_Right.stl"/>
    <mesh name="Shank_Right" class="/" file="Shank_Right.stl"/>
    <mesh name="Ankle_Cross_Right" class="/" file="Ankle_Cross_Right.stl"/>
    <mesh name="right_foot_link" class="/" file="right_foot_link.stl"/>
  </asset>

  <worldbody>
    <geom name="floor" class="/" size="100 100 0.125" type="plane" group="0" material="MatPlane"/>
    <light name="toplight_shadow" class="/" pos="0 0 5" dir="0.0990148 0.0990148 -0.990148" type="directional" ambient="0.04 0.04 0.04" diffuse="0.55 0.55 0.55" specular="0.12 0.12 0.12"/>
    <light name="toplight_fill" class="/" pos="0 0 5" dir="0.0990148 0.0990148 -0.990148" type="directional" castshadow="false" ambient="0.04 0.04 0.04" diffuse="0.3 0.3 0.3" specular="0.08 0.08 0.08"/>
    <body name="trunk" childclass="t1" pos="-0.00144205 -0.00774539 0.01214" quat="0.999979 -0.00163876 0.00279233 0.00569338">
      <inertial pos="0.0536872 0.000726064 0.0703145" quat="0.999937 -0.00144674 -0.00973402 0.0053735" mass="14.5646" diaginertia="0.0971924 0.58444 0.00904922"/>
      <joint name="//unnamed_joint_0" type="free" armature="0" damping="0" frictionloss="0"/>
      <geom name="//unnamed_geom_1" class="visual" rgba="0.76 0.76 0.76 1" mesh="Trunk"/>
      <geom name="//unnamed_geom_2" class="collision" size="0.0780317 0.104042 0.156063" pos="0.0582558 0 0.0799567" type="box"/>
      <geom name="//unnamed_geom_3" class="reward_collision_sphere" size="0.119649" pos="0.0582558 0 0.0666306"/>
      <geom name="//unnamed_geom_4" class="reward_collision_sphere" size="0.0156063" pos="0.0582558 0.126143 0"/>
      <geom name="//unnamed_geom_5" class="reward_collision_sphere" size="0.0156063" pos="0.0582558 -0.126143 0"/>
      <geom name="//unnamed_geom_6" class="reward_collision_sphere" size="0.0156063" pos="0.0582558 0.158792 0.119935"/>
      <geom name="//unnamed_geom_7" class="reward_collision_sphere" size="0.0156063" pos="0.0582558 -0.158792 0.119935"/>
      <site name="imu" pos="0.0596996 0.00160361 -0.00697896" size="0.0104042"/>
      <camera name="track" pos="0 -2.96807 0" quat="0.707107 0.707107 0 0" mode="trackcom"/>
      <camera name="ego_camera" pos="0.118453 0 0.279848" quat="-0.5 -0.5 0.5 0.5"/>
      <body name="H1" pos="0.0527493 -0.000470661 0.153571" quat="0.999984 -0.00459423 0.00339079 -0.000331292">
        <inertial pos="-0.0101933 -0.00807393 0.0354428" quat="0.76422 -0.0116979 0.000753763 0.644849" mass="0.442117" diaginertia="0.000187405 0.00136097 2.12548e-05"/>
        <joint name="AAHead_yaw" pos="0 0 0" axis="0.000735803 -0.000240063 1" range="-1.29557 1.63458" armature="0.0103277" damping="0.0354756" frictionloss="0.0797662"/>
        <geom name="//unnamed_geom_8" class="visual" mesh="H1"/>
        <body name="H2" pos="0.0028172 -0.00313789 0.0324813" quat="0.99998 0.0010876 0.00489671 -0.00383993">
          <inertial pos="0.00580678 0.000112064 0.0642768" quat="0.988483 0.105101 -0.0742632 -0.0796227" mass="0.839969" diaginertia="0.00197931 0.0157192 0.000230272"/>
          <joint name="Head_pitch" pos="0 0 0" axis="-0.0559474 -0.998283 -0.017357" stiffness="0.027534" range="-1.04404 0.108534" armature="0.00506625" damping="0" frictionloss="0.0382168"/>
          <geom name="//unnamed_geom_9" class="visual" mesh="H2"/>
          <geom name="//unnamed_geom_10" class="collision" size="0.0832338" pos="0.0097093 0 0.0732937"/>
          <geom name="//unnamed_geom_11" class="reward_collision_sphere" size="0.0936381" pos="0.0194186 0 0.0666306"/>
        </body>
      </body>
      <body name="AL1" pos="0.0436297 0.15071 0.139583" quat="1 -1.52518e-05 0.000453078 5.39128e-05">
        <inertial pos="0.0122547 0.07185 0.00574248" quat="0.498681 0.470383 -0.540049 0.488267" mass="0.654037" diaginertia="0.00123417 0.00840079 4.20132e-05"/>
        <joint name="Left_Shoulder_Pitch" pos="0 0 0" axis="9.66522e-05 1 6.92809e-05" range="-3.27922 1.23777" armature="0.0101281" damping="0" frictionloss="0.129701"/>
        <geom name="//unnamed_geom_12" class="visual" rgba="0.76 0.76 0.76 1" mesh="AL1"/>
        <body name="AL2" pos="-0.00151 0.0725208 0.0125386" quat="0.999982 -0.00371546 0.00197625 -0.00426162">
          <inertial pos="0.00829259 0.0551168 0.0107758" quat="0.504478 0.512093 -0.491343 0.491777" mass="0.161565" diaginertia="0.0003648 0.00276451 2.27233e-05"/>
          <joint name="Left_Shoulder_Roll" pos="0 0 0" axis="-0.998152 -0.0119939 -0.0595688" range="-1.54078 1.79076" armature="0.00972088" damping="0.00287203" frictionloss="0.166848"/>
          <geom name="//unnamed_geom_13" class="visual" mesh="AL2"/>
          <body name="AL3" pos="0.0124644 0.0956609 0.00160064" quat="1 4.34372e-05 6.33188e-05 -4.64186e-05">
            <inertial pos="0.00180769 0.126479 -0.0110484" quat="0.707195 0.706988 -0.00286218 -0.0059461" mass="1.12678" diaginertia="0.0102083 0.0909417 8.68599e-05"/>
            <joint name="Left_Elbow_Pitch" pos="0 0 0" axis="0.0357804 -0.998395 0.0438898" stiffness="0.00130262" range="-2.30808 2.2745" armature="0.012485" damping="0.00620061" frictionloss="0.0776531"/>
            <geom name="//unnamed_geom_14" class="visual" mesh="AL3"/>
            <geom name="//unnamed_geom_15" class="collision" size="0.0312127 0.0780317" pos="0 0.0742017 0" quat="0.707105 0.707108 0 0" type="cylinder"/>
            <geom name="//unnamed_geom_16" class="reward_collision_sphere" size="0.0374552"/>
            <body name="left_hand_link" pos="0.00788104 0.229861 -0.0131104" quat="0.999998 -0.00190731 0.000216715 0.000996299">
              <inertial pos="-0.000495445 0.156998 -0.00837537" quat="0.709785 0.704411 -0.00293622 0.00129058" mass="0.328883" diaginertia="0.00682974 0.0441075 2.3528e-05"/>
              <joint name="Left_Elbow_Yaw" pos="0 0 0" axis="-0.0528227 -0.0119059 0.998533" stiffness="0.0432355" range="-2.51468 0.0191672" armature="0.0102849" damping="0.0126955" frictionloss="0.064596"/>
              <geom name="//unnamed_geom_17" class="visual" mesh="left_hand_link"/>
              <geom name="//unnamed_geom_18" class="collision" size="0.0312127 0.091037" pos="0 0.192924 0" quat="0.707105 0.707108 0 0" type="cylinder"/>
              <geom name="//unnamed_geom_19" class="reward_collision_sphere" size="0.0520211"/>
              <geom name="//unnamed_geom_20" class="reward_collision_sphere" size="0.0364148" pos="0 0.163244 0"/>
              <geom name="//unnamed_geom_21" class="reward_collision_sphere" size="0.0364148" pos="0 0.319067 0"/>
            </body>
          </body>
        </body>
      </body>
      <body name="AR1" pos="0.0464936 -0.157457 0.135611" quat="0.999982 -0.00347377 0.00479192 0.00126331">
        <inertial pos="-0.000257966 -0.0612364 -0.00239402" quat="0.49893 0.492107 -0.527649 0.480089" mass="0.62234" diaginertia="0.00139578 0.00998507 3.98196e-05"/>
        <joint name="Right_Shoulder_Pitch" pos="0 0 0" axis="0.00379328 -0.999867 0.0158339" stiffness="0.0529667" range="-1.22414 3.15469" armature="0.0121159" damping="0.0583977" frictionloss="0.101745"/>
        <geom name="//unnamed_geom_22" class="visual" rgba="0.76 0.76 0.76 1" mesh="AR1"/>
        <body name="AR2" pos="-0.000746343 -0.0733818 -0.00353745" quat="0.999993 -0.00272848 -0.000957641 0.00234107">
          <inertial pos="0.0086264 -0.0558491 -0.00811576" quat="0.510577 0.484914 -0.515705 0.488076" mass="0.203197" diaginertia="0.000287709 0.00250847 2.61767e-05"/>
          <joint name="Right_Shoulder_Roll" pos="0 0 0" axis="-0.999963 0.00772974 0.00386344" range="-1.80222 1.5985" armature="0.0095026" damping="0" frictionloss="0.048092"/>
          <geom name="//unnamed_geom_23" class="visual" mesh="AR2"/>
          <body name="AR3" pos="-0.00237638 -0.0999284 0.00368933" quat="0.999999 -0.00047727 -0.0013697 -0.000440935">
            <inertial pos="0.0126523 -0.125406 -0.00244344" quat="0.679498 0.733483 -0.00413004 -0.0163753" mass="0.956422" diaginertia="0.0119338 0.101649 8.11727e-05"/>
            <joint name="Right_Elbow_Pitch" pos="0 0 0" axis="0.0146373 0.999502 -0.0279666" stiffness="0.0662798" range="-2.27349 2.39209" armature="0.0157465" damping="0.0110777" frictionloss="0.105879"/>
            <geom name="//unnamed_geom_24" class="visual" mesh="AR3"/>
            <geom name="//unnamed_geom_25" class="collision" size="0.0312127 0.0780317" pos="0 -0.0742017 0" quat="0.707105 0.707108 0 0" type="cylinder"/>
            <geom name="//unnamed_geom_26" class="reward_collision_sphere" size="0.0374552"/>
            <body name="right_hand_link" pos="0.000443821 -0.218919 -0.0127423" quat="1 0.00082052 2.08976e-05 -0.000207346">
              <inertial pos="0.00788257 -0.171707 0.00391221" quat="0.711937 0.702077 -0.00542225 0.0142628" mass="0.394887" diaginertia="0.00713065 0.0664744 2.8092e-05"/>
              <joint name="Right_Elbow_Yaw" pos="0 0 0" axis="0.0180424 -0.00196399 0.999835" stiffness="0.0166437" range="0.00291439 2.41961" armature="0.0127949" damping="0.0349756" frictionloss="0.105463"/>
              <geom name="//unnamed_geom_27" class="visual" mesh="right_hand_link"/>
              <geom name="//unnamed_geom_28" class="collision" size="0.0312127 0.091037" pos="0 -0.192924 0" quat="0.707105 0.707108 0 0" type="cylinder"/>
              <geom name="//unnamed_geom_29" class="reward_collision_sphere" size="0.0520211"/>
              <geom name="//unnamed_geom_30" class="reward_collision_sphere" size="0.0364148" pos="0 -0.163244 0"/>
              <geom name="//unnamed_geom_31" class="reward_collision_sphere" size="0.0364148" pos="0 -0.319067 0"/>
            </body>
          </body>
        </body>
      </body>
      <body name="Waist" pos="0.0621883 0.00142746 -0.0851865" quat="1 -0.000418637 -0.000190982 3.10483e-05">
        <inertial pos="-0.00434438 0.000884633 3.49514e-05" quat="0.983514 0.00521707 -0.180754 0.000118281" mass="2.85165" diaginertia="0.0049243 0.0317819 0.000660514"/>
        <joint name="Waist" pos="0 0 0" axis="0.00898093 -0.0112433 0.999896" stiffness="0.0362907" range="-1.39254 1.44578" armature="0.0115767" damping="0.0658666" frictionloss="0.0967527"/>
        <geom name="//unnamed_geom_32" class="visual" mesh="Waist"/>
        <body name="Hip_Pitch_Left" pos="0.00134856 0.14403 -0.0109513" quat="1 0.000351693 -9.47093e-05 -0.00036274">
          <inertial pos="0.00827778 -0.00999443 0.000990989" quat="0.97328 0.228156 0.0255128 0.00443014" mass="0.994489" diaginertia="0.00142722 0.0106835 0.000163135"/>
          <joint name="Left_Hip_Pitch" pos="0 0 0" axis="-0.0331986 0.999375 0.0121331" stiffness="0.0488339" range="-1.99817 1.58996" armature="0.0103391" damping="0.0586742" frictionloss="0.157636"/>
          <geom name="//unnamed_geom_33" class="visual" rgba="0.76 0.76 0.76 1" mesh="Hip_Pitch_Left"/>
          <body name="Hip_Roll_Left" pos="-0.00541823 0.00104127 -0.0155866" quat="1 0.000166438 0.000385228 -0.000350627">
            <inertial pos="0.000759071 0.00198911 -0.0354501" quat="0.69913 -0.0307767 -0.00867904 0.714279" mass="0.386644" diaginertia="0.00137157 0.00888571 6.10339e-05"/>
            <joint name="Left_Hip_Roll" pos="0 0 0" axis="-0.999801 0.0198671 0.00158192" range="-1.74175 0.175005" armature="0.0104027" damping="0" frictionloss="0.148491"/>
            <geom name="//unnamed_geom_34" class="visual" mesh="Hip_Roll_Left"/>
            <geom name="//unnamed_geom_35" class="reward_collision_sphere" size="0.0572233"/>
            <body name="Hip_Yaw_Left" pos="0.0094804 -0.00164382 -0.0678967" quat="1 -0.000434114 1.79276e-05 0.000266087">
              <inertial pos="-0.00889529 0.00115824 -0.0477326" quat="0.710479 -0.0370064 -0.0251512 0.702295" mass="2.72933" diaginertia="0.0186433 0.176404 0.000351762"/>
              <joint name="Left_Hip_Yaw" pos="0 0 0" axis="0.0291169 0.0343603 -0.998985" stiffness="0.0672146" range="-1.03657 0.823757" armature="0.0152063" damping="0.0445031" frictionloss="0.160908"/>
              <geom name="//unnamed_geom_36" class="visual" mesh="Hip_Yaw_Left"/>
              <geom name="//unnamed_geom_37" class="collision" size="0.0520211 0.0832338" type="cylinder"/>
              <body name="Shank_Left" pos="-0.00642105 -0.0115916 -0.0998235" quat="0.99998 -0.00493767 -0.00160784 0.00366536">
                <inertial pos="-0.0119002 0.0139691 -0.0784002" quat="0.997806 0.0087529 0.0303609 0.0581725" mass="1.77394" diaginertia="0.0242974 0.229435 0.000227662"/>
                <joint name="Left_Knee_Pitch" pos="0 0 0" axis="-0.0314751 0.999499 0.00318328" stiffness="0.00361174" range="0.0564946 2.3163" armature="0.00587957" damping="0.0215928" frictionloss="0.163682"/>
                <geom name="//unnamed_geom_38" class="visual" mesh="Shank_Left"/>
                <geom name="//unnamed_geom_39" class="collision" size="0.0520211 0.0780317" pos="0 0 -0.0799567" type="cylinder"/>
                <geom name="//unnamed_geom_40" class="reward_collision_sphere" size="0.0676275"/>
                <body name="Ankle_Cross_Left" pos="0.0126702 0.00425888 -0.18818" quat="1 -8.84146e-05 -0.000156475 -0.000531495">
                  <inertial pos="-0.00367716 6.1204e-05 -0.00469063" quat="0.443926 0.519124 0.536717 0.495353" mass="0.0747755" diaginertia="2.48269e-05 0.000177336 1.44666e-06"/>
                  <joint name="Left_Ankle_Pitch" pos="0 0 0" axis="-0.0343145 0.999325 0.0131493" range="-0.846493 0.565298" armature="0.0114317" damping="0.00776705" frictionloss="0.0970322"/>
                  <geom name="//unnamed_geom_41" class="visual" mesh="Ankle_Cross_Left"/>
                  <body name="left_foot_link" pos="-0.00875583 0.00103599 -0.00989631" quat="0.999993 -0.00315341 0.00034494 0.00208806">
                    <inertial pos="0.000258424 -0.000465689 -0.0194765" quat="-0.0015467 0.620866 0.00243839 0.783911" mass="0.889501" diaginertia="0.00271732 0.0180037 0.000326761"/>
                    <joint name="Left_Ankle_Roll" pos="0 0 0" axis="-0.999391 -0.0197892 -0.0287293" range="-0.273732 0.334415" armature="0.0102491" damping="0" frictionloss="0.10522"/>
                    <geom name="//unnamed_geom_42" class="visual" mesh="left_foot_link"/>
                    <geom name="left_foot" class="foot" size="0.0663691 0.0287987 0.0123284" pos="0.0097093 0 -0.00999459"/>
                    <geom name="//unnamed_geom_44" class="reward_collision_sphere" size="0.054102" pos="0.0097093 0 -0.00999459"/>
                    <geom name="//unnamed_geom_45" class="reward_collision_sphere" size="0.0312127" pos="0.0922384 -0.0341328 -0.00999459"/>
                    <geom name="//unnamed_geom_46" class="reward_collision_sphere" size="0.0312127" pos="-0.0679651 -0.0341328 -0.00999459"/>
                    <site name="left_foot" class="foot" pos="0.0097093 0 -0.00999459" size="0.0104042"/>
                  </body>
                </body>
              </body>
            </body>
          </body>
        </body>
        <body name="Hip_Pitch_Right" pos="0.00899544 -0.157952 -0.0108085" quat="0.999983 0.00530093 0.00261534 -9.90165e-05">
          <inertial pos="0.0010963 0.0240692 -0.0148279" quat="0.972877 -0.228972 0.0144128 -0.0295713" mass="1.10938" diaginertia="0.001488 0.0100461 0.000145648"/>
          <joint name="Right_Hip_Pitch" pos="0 0 0" axis="-0.0019355 -0.999998 0.000583107" stiffness="0.0341653" range="-1.71851 2.01373" armature="0.0108631" damping="0" frictionloss="0.038747"/>
          <geom name="//unnamed_geom_47" class="visual" rgba="0.76 0.76 0.76 1" mesh="Hip_Pitch_Right"/>
          <body name="Hip_Roll_Right" pos="0.011091 -0.000937102 -0.0227088" quat="1 3.12314e-05 -0.000309204 7.24699e-05">
            <inertial pos="0.00512924 0.00104722 -0.0415375" quat="0.707119 -0.00611904 -0.00608643 0.707042" mass="0.432618" diaginertia="0.00175691 0.0102712 6.40207e-05"/>
            <joint name="Right_Hip_Roll" pos="0 0 0" axis="-0.999516 0.0290575 0.0110837" range="-0.355963 1.65869" armature="0.00925305" damping="0.0357873" frictionloss="0.05217"/>
            <geom name="//unnamed_geom_48" class="visual" mesh="Hip_Roll_Right"/>
            <geom name="//unnamed_geom_49" class="reward_collision_sphere" size="0.0572233"/>
            <body name="Hip_Yaw_Right" pos="-0.00964595 -0.00243081 -0.0649139" quat="1 -0.000268047 0.000551119 -0.000544697">
              <inertial pos="0.00328829 -0.0136 -0.0615212" quat="0.712175 -0.0344807 -0.033967 0.700331" mass="3.00151" diaginertia="0.0223121 0.202399 0.000420343"/>
              <joint name="Right_Hip_Yaw" pos="0 0 0" axis="0.0204894 0.00790341 -0.999759" stiffness="0.00812111" range="-1.03519 0.998786" armature="0.010766" damping="0" frictionloss="0.105591"/>
              <geom name="//unnamed_geom_50" class="visual" mesh="Hip_Yaw_Right"/>
              <geom name="//unnamed_geom_51" class="collision" size="0.0520211 0.0832338" type="cylinder"/>
              <body name="Shank_Right" pos="-0.014254 -0.00112391 -0.102054" quat="1 -0.00026747 -3.2718e-05 -1.07119e-05">
                <inertial pos="0.00842464 -0.00444682 -0.0736497" quat="0.999002 -0.0439365 0.0035977 0.00719876" mass="2.09352" diaginertia="0.0360329 0.258531 0.000300513"/>
                <joint name="Right_Knee_Pitch" pos="0 0 0" axis="0.00136069 -0.999991 0.00400697" range="-2.35532 0.222025" armature="0.0113536" damping="0" frictionloss="0.147338"/>
                <geom name="//unnamed_geom_52" class="visual" mesh="Shank_Right"/>
                <geom name="//unnamed_geom_53" class="collision" size="0.0520211 0.0780317" pos="0 0 -0.0799567" type="cylinder"/>
                <geom name="//unnamed_geom_54" class="reward_collision_sphere" size="0.0676275"/>
                <body name="Ankle_Cross_Right" pos="0.00632814 0.00553326 -0.175921" quat="0.999998 2.88098e-05 -0.000327431 -0.00204113">
                  <inertial pos="-0.00488864 0.00635337 -0.00564051" quat="0.453591 0.544746 0.56838 0.417675" mass="0.0928166" diaginertia="2.64814e-05 0.000194151 1.56338e-06"/>
                  <joint name="Right_Ankle_Pitch" pos="0 0 0" axis="-0.00629594 -0.999979 0.00159953" range="-0.629477 0.718215" armature="0.0109437" damping="0" frictionloss="0.111434"/>
                  <geom name="//unnamed_geom_55" class="visual" mesh="Ankle_Cross_Right"/>
                  <body name="right_foot_link" pos="0.000876309 0.00146071 -0.0156085" quat="1 -0.000265368 -0.000260336 0.000478176">
                    <inertial pos="-0.000251303 0.00457066 -0.0190803" quat="-0.00336292 0.624543 -0.00214893 0.78098" mass="0.780375" diaginertia="0.00226936 0.0186639 0.000296433"/>
                    <joint name="Right_Ankle_Roll" pos="0 0 0" axis="-0.999996 0.00280199 -0.000250695" stiffness="0.000580341" range="-0.380107 0.460969" armature="0.0101792" damping="0.0288903" frictionloss="0.031719"/>
                    <geom name="//unnamed_geom_56" class="visual" mesh="right_foot_link"/>
                    <geom name="right_foot" class="foot" size="0.0790291 0.0782316 0.00745883" pos="0.0097093 0 -0.00999459"/>
                    <geom name="//unnamed_geom_58" class="reward_collision_sphere" size="0.0416169"/>
                    <geom name="//unnamed_geom_59" class="reward_collision_sphere" size="0.0312127" pos="0.0097093 0 -0.00999459"/>
                    <geom name="//unnamed_geom_60" class="reward_collision_sphere" size="0.0312127" pos="0.0922384 0.0341328 -0.00999459"/>
                    <geom name="//unnamed_geom_61" class="reward_collision_sphere" size="0.0312127" pos="-0.0679651 0.0341328 -0.00999459"/>
                    <site name="right_foot" class="foot" pos="0.0097093 0 -0.00999459" size="0.0104042"/>
                  </body>
                </body>
              </body>
            </body>
          </body>
        </body>
      </body>
    </body>
  </worldbody>

  <contact>
    <pair class="/" geom1="floor" geom2="left_foot" name="//unnamed_contact_0"/>
    <pair class="/" geom1="floor" geom2="right_foot" name="//unnamed_contact_1"/>
  </contact>

  <actuator>
    <general name="AAHead_yaw" class="/" joint="AAHead_yaw" forcerange="-7.12716 7.12716" gainprm="19.8926" biasprm="0 -19.8926 -0.618361"/>
    <general name="Head_pitch" class="/" joint="Head_pitch" forcerange="-5.75672 5.75672" gainprm="19.8926" biasprm="0 -19.8926 -0.618361"/>
    <general name="Left_Shoulder_Pitch" class="/" joint="Left_Shoulder_Pitch" forcerange="-22.4231 22.4231" gainprm="19.8926" biasprm="0 -19.8926 -0.618361"/>
    <general name="Left_Shoulder_Roll" class="/" joint="Left_Shoulder_Roll" forcerange="-16.5703 16.5703" gainprm="19.8926" biasprm="0 -19.8926 -0.618361"/>
    <general name="Left_Elbow_Pitch" class="/" joint="Left_Elbow_Pitch" forcerange="-26.1525 26.1525" gainprm="19.8926" biasprm="0 -19.8926 -0.618361"/>
    <general name="Left_Elbow_Yaw" class="/" joint="Left_Elbow_Yaw" forcerange="-18.9241 18.9241" gainprm="19.8926" biasprm="0 -19.8926 -0.618361"/>
    <general name="Right_Shoulder_Pitch" class="/" joint="Right_Shoulder_Pitch" forcerange="-17.2768 17.2768" gainprm="19.8926" biasprm="0 -19.8926 -0.618361"/>
    <general name="Right_Shoulder_Roll" class="/" joint="Right_Shoulder_Roll" forcerange="-13.7277 13.7277" gainprm="19.8926" biasprm="0 -19.8926 -0.618361"/>
    <general name="Right_Elbow_Pitch" class="/" joint="Right_Elbow_Pitch" forcerange="-18.6278 18.6278" gainprm="19.8926" biasprm="0 -19.8926 -0.618361"/>
    <general name="Right_Elbow_Yaw" class="/" joint="Right_Elbow_Yaw" forcerange="-19.0742 19.0742" gainprm="19.8926" biasprm="0 -19.8926 -0.618361"/>
    <general name="Waist" class="/" joint="Waist" forcerange="-30.8501 30.8501" gainprm="19.8926" biasprm="0 -19.8926 -0.618361"/>
    <general name="Left_Hip_Pitch" class="/" joint="Left_Hip_Pitch" forcerange="-46.141 46.141" gainprm="19.8926" biasprm="0 -19.8926 -0.618361"/>
    <general name="Left_Hip_Roll" class="/" joint="Left_Hip_Roll" forcerange="-16.4899 16.4899" gainprm="19.8926" biasprm="0 -19.8926 -0.618361"/>
    <general name="Left_Hip_Yaw" class="/" joint="Left_Hip_Yaw" forcerange="-39.8906 39.8906" gainprm="19.8926" biasprm="0 -19.8926 -0.618361"/>
    <general name="Left_Knee_Pitch" class="/" joint="Left_Knee_Pitch" forcerange="-34.344 34.344" gainprm="19.8926" biasprm="0 -19.8926 -0.618361"/>
    <general name="Left_Ankle_Pitch" class="/" joint="Left_Ankle_Pitch" forcerange="-26.4242 26.4242" gainprm="19.8926" biasprm="0 -19.8926 -0.618361"/>
    <general name="Left_Ankle_Roll" class="/" joint="Left_Ankle_Roll" forcerange="-19.4744 19.4744" gainprm="19.8926" biasprm="0 -19.8926 -0.618361"/>
    <general name="Right_Hip_Pitch" class="/" joint="Right_Hip_Pitch" forcerange="-66.1843 66.1843" gainprm="19.8926" biasprm="0 -19.8926 -0.618361"/>
    <general name="Right_Hip_Roll" class="/" joint="Right_Hip_Roll" forcerange="-32.2391 32.2391" gainprm="19.8926" biasprm="0 -19.8926 -0.618361"/>
    <general name="Right_Hip_Yaw" class="/" joint="Right_Hip_Yaw" forcerange="-22.2441 22.2441" gainprm="19.8926" biasprm="0 -19.8926 -0.618361"/>
    <general name="Right_Knee_Pitch" class="/" joint="Right_Knee_Pitch" forcerange="-66.3133 66.3133" gainprm="19.8926" biasprm="0 -19.8926 -0.618361"/>
    <general name="Right_Ankle_Pitch" class="/" joint="Right_Ankle_Pitch" forcerange="-21.8953 21.8953" gainprm="19.8926" biasprm="0 -19.8926 -0.618361"/>
    <general name="Right_Ankle_Roll" class="/" joint="Right_Ankle_Roll" forcerange="-15.4624 15.4624" gainprm="19.8926" biasprm="0 -19.8926 -0.618361"/>
  </actuator>

  <sensor>
    <gyro site="imu" name="imu_angular_velocity"/>
    <velocimeter site="imu" name="imu_linear_velocity"/>
    <framelinvel objtype="site" objname="left_foot" name="left_foot_global_linear_velocity"/>
    <framelinvel objtype="site" objname="right_foot" name="right_foot_global_linear_velocity"/>
  </sensor>

  <keyframe>
    <key name="home" qpos="0 0 0.6385 1 0 0 0 0 0 0 1.4 0 -0.4 0 -1.4 0 0.4 0 -0.4 0 0 0.8 -0.4 0 0.4 0 0 -0.8 0.4 0"/>
  </keyframe>
</mujoco>
