<mujoco model="T1">
  <compiler angle="radian" assetdir="assets" balanceinertia="true" inertiafromgeom="false"/>

  <option timestep="0.005" density="1.2" viscosity="2e-05"/>

  <size nkey="1"/>

  <visual>
    <quality shadowsize="8192"/>
    <map shadowclip="0.5"/>
  </visual>

  <default>
    <default class="/">
      <joint armature="0.01" damping="0.01" frictionloss="0.1"/>
      <geom contype="0" conaffinity="0" group="1" solref="-1000 -80"/>
      <site size="0.01 0.005 0.005" group="5"/>
      <general forcelimited="true" biastype="affine" gainprm="25" biasprm="0 -25 -0.6"/>
      <default class="t1">
        <geom rgba="0.25 0.25 0.25 1"/>
        <default class="visual">
          <geom type="mesh" group="2"/>
        </default>
        <default class="collision">
          <geom group="3"/>
        </default>
        <default class="foot">
          <geom size="0.1115 0.05 0.015" type="box" condim="6" group="4" priority="1" solimp="0.015 1 0.015"/>
        </default>
        <default class="reward_collision_sphere">
          <geom group="5" rgba="1 0 0 1"/>
        </default>
      </default>
    </default>
  </default>

  <asset>
    <texture type="skybox" colorspace="auto" name="//unnamed_texture_0" builtin="gradient" rgb1="0.95 0.95 0.95" rgb2="0.95 0.95 0.95" width="100" height="600"/>
    <texture type="2d" colorspace="auto" name="texplane" builtin="checker" rgb1="0.345 0.575 0.748" rgb2="0.345 0.575 0.748" markrgb="1 1 1" width="512" height="512"/>
    <material name="MatPlane" class="/" texture="texplane" texuniform="true" texrepeat="2 2" specular="0.9"/>
    <mesh name="Trunk" class="/" file="Trunk.stl"/>
    <mesh name="H1" class="/" file="H1.stl"/>
    <mesh name="H2" class="/" file="H2.stl"/>
    <mesh name="AL1" class="/" file="AL1.stl"/>
    <mesh name="AL2" class="/" file="AL2.stl"/>
    <mesh name="AL3" class="/" file="AL3.stl"/>
    <mesh name="left_hand_link" class="/" file="left_hand_link.stl"/>
    <mesh name="AR1" class="/" file="AR1.stl"/>
    <mesh name="AR2" class="/" file="AR2.stl"/>
    <mesh name="AR3" class="/" file="AR3.stl"/>
    <mesh name="right_hand_link" class="/" file="right_hand_link.stl"/>
    <mesh name="Waist" class="/" file="Waist.stl"/>
    <mesh name="Hip_Pitch_Left" class="/" file="Hip_Pitch_Left.stl"/>
    <mesh name="Hip_Roll_Left" class="/" file="Hip_Roll_Left.stl"/>
    <mesh name="Hip_Yaw_Left" class="/" file="Hip_Yaw_Left.stl"/>
    <mesh name="Shank_Left" class="/" file="Shank_Left.stl"/>
    <mesh name="Ankle_Cross_Left" class="/" file="Ankle_Cross_Left.stl"/>
    <mesh name="left_foot_link" class="/" file="left_foot_link.stl"/>
    <mesh name="Hip_Pitch_Right" class="/" file="Hip_Pitch_Right.stl"/>
    <mesh name="Hip_Roll_Right" class="/" file="Hip_Roll_Right.stl"/>
    <mesh name="Hip_Yaw_Right" class="/" file="Hip_Yaw_Right.stl"/>
    <mesh name="Shank_Right" class="/" file="Shank_Right.stl"/>
    <mesh name="Ankle_Cross_Right" class="/" file="Ankle_Cross_Right.stl"/>
    <mesh name="right_foot_link" class="/" file="right_foot_link.stl"/>
  </asset>

  <worldbody>
    <geom name="floor" class="/" size="100 100 0.125" type="plane" group="0" material="MatPlane"/>
    <light name="toplight_shadow" class="/" pos="0 0 5" dir="0.0990148 0.0990148 -0.990148" type="directional" ambient="0.04 0.04 0.04" diffuse="0.55 0.55 0.55" specular="0.12 0.12 0.12"/>
    <light name="toplight_fill" class="/" pos="0 0 5" dir="0.0990148 0.0990148 -0.990148" type="directional" castshadow="false" ambient="0.04 0.04 0.04" diffuse="0.3 0.3 0.3" specular="0.08 0.08 0.08"/>
    <body name="trunk" childclass="t1" pos="-6.53304e-05 -0.000841578 -0.000586825" quat="1 -0.000321361 0.000100714 0.000331749">
      <inertial pos="0.0412995 -0.000563734 0.117568" quat="0.999958 -0.000201714 -0.00911377 -7.47968e-05" mass="9.41847" diaginertia="0.0226752 0.049872 0.0977397"/>
      <joint name="//unnamed_joint_0" type="free" armature="0" damping="0" frictionloss="0"/>
      <geom name="//unnamed_geom_1" class="visual" rgba="0.76 0.76 0.76 1" mesh="Trunk"/>
      <geom name="//unnamed_geom_2" class="collision" size="0.0698698 0.0931597 0.13974" pos="0.0453544 0 0.134199" type="box"/>
      <geom name="//unnamed_geom_3" class="reward_collision_sphere" size="0.107134" pos="0.0453544 0 0.111833"/>
      <geom name="//unnamed_geom_4" class="reward_collision_sphere" size="0.013974" pos="0.0453544 0.0782475 0"/>
      <geom name="//unnamed_geom_5" class="reward_collision_sphere" size="0.013974" pos="0.0453544 -0.0782475 0"/>
      <geom name="//unnamed_geom_6" class="reward_collision_sphere" size="0.013974" pos="0.0453544 0.0984998 0.201299"/>
      <geom name="//unnamed_geom_7" class="reward_collision_sphere" size="0.013974" pos="0.0453544 -0.0984998 0.201299"/>
      <site name="imu" pos="-0.00254817 -0.000498169 -0.000985717" size="0.00931597"/>
      <camera name="track" pos="0 -1.84112 0" quat="0.707107 0.707107 0 0" mode="trackcom"/>
      <camera name="ego_camera" pos="0.0922206 0 0.469697" quat="-0.5 -0.5 0.5 0.5"/>
      <body name="H1" pos="0.0460193 -0.000360878 0.271054" quat="1 -0.000173666 -0.000125557 -1.91627e-05">
        <inertial pos="-0.00147276 -0.00231598 0.0644324" quat="0.763426 -0.0142026 0.00221733 0.645735" mass="0.357293" diaginertia="5.9306e-05 0.000148809 0.000266359"/>
        <joint name="AAHead_yaw" pos="0 0 0" axis="-0.000541439 0.000508607 1" range="-1.59349 1.56874" armature="0.00928241" damping="0.0146509" frictionloss="0.0907168"/>
        <geom name="//unnamed_geom_8" class="visual" mesh="H1"/>
        <body name="H2" pos="-7.20534e-05 -4.92055e-06 0.0686231" quat="1 -0.000348876 0.000142855 -0.000197597">
          <inertial pos="0.00535934 0.00119121 0.110149" quat="0.988435 0.106206 -0.0746046 -0.0784256" mass="0.505941" diaginertia="0.000507854 0.00128363 0.00302299"/>
          <joint name="Head_pitch" pos="0 0 0" axis="-0.00266324 -0.999996 0.000241527" stiffness="0.000643389" range="-1.20994 0.362273" armature="0.00930207" damping="0.0103128" frictionloss="0.0967837"/>
          <geom name="//unnamed_geom_9" class="visual" mesh="H2"/>
          <geom name="//unnamed_geom_10" class="collision" size="0.0745278" pos="0.00755906 0 0.123016"/>
          <geom name="//unnamed_geom_11" class="reward_collision_sphere" size="0.0838438" pos="0.0151181 0 0.111833"/>
        </body>
      </body>
      <body name="AL1" pos="0.0452219 0.0978206 0.244391" quat="1 -0.000215141 0.000364977 0.000103829">
        <inertial pos="-0.00160446 0.0418754 0.000875934" quat="0.503999 0.498115 -0.50322 0.494607" mass="0.433119" diaginertia="0.000341575 0.000877371 0.000517572"/>
        <joint name="Left_Shoulder_Pitch" pos="0 0 0" axis="0.00108187 0.999998 0.00190137" range="-3.3139 1.22157" armature="0.00916161" damping="0.0030121" frictionloss="0.0960155"/>
        <geom name="//unnamed_geom_12" class="visual" rgba="0.76 0.76 0.76 1" mesh="AL1"/>
        <body name="AL2" pos="0.00119549 0.0440309 -0.000284038" quat="1 -1.13962e-05 -0.000103406 5.82343e-05">
          <inertial pos="0.00308831 0.035 -0.000381951" quat="0.48673 0.513879 -0.489213 0.509601" mass="0.128865" diaginertia="9.88752e-05 0.000231148 0.000310224"/>
          <joint name="Left_Shoulder_Roll" pos="0 0 0" axis="-0.999992 0.00313078 -0.00228087" stiffness="8.53519e-05" range="-1.56888 1.73314" armature="0.00956281" damping="0.00536336" frictionloss="0.0905471"/>
          <geom name="//unnamed_geom_13" class="visual" mesh="AL2"/>
          <body name="AL3" pos="4.89594e-05 0.0567892 -0.000257843" quat="1 0.000312455 2.90324e-05 5.25814e-06">
            <inertial pos="-0.00084086 0.0785624 -0.000176501" quat="0.706192 0.70802 -0.000498022 0.000232442" mass="0.82787" diaginertia="0.00314598 0.00847101 0.00109857"/>
            <joint name="Left_Elbow_Pitch" pos="0 0 0" axis="-0.000382324 -1 -0.000830281" range="-2.26373 2.26674" armature="0.00918499" damping="0.00797765" frictionloss="0.090095"/>
            <geom name="//unnamed_geom_14" class="visual" mesh="AL3"/>
            <geom name="//unnamed_geom_15" class="collision" size="0.0279479 0.0698698" pos="0 0.0460279 0" quat="0.707105 0.707108 0 0" type="cylinder"/>
            <geom name="//unnamed_geom_16" class="reward_collision_sphere" size="0.0335375"/>
            <body name="left_hand_link" pos="0.00125482 0.134977 0.00191623" quat="1 -0.000113593 -0.000153404 -0.000168365">
              <inertial pos="-4.00397e-05 0.100202 -0.00023044" quat="0.708433 0.705777 1.85879e-05 0.000948518" mass="0.269816" diaginertia="0.00201666 0.00538181 0.000380134"/>
              <joint name="Left_Elbow_Yaw" pos="0 0 0" axis="0.00330001 -0.00314385 0.99999" range="-2.4461 -0.00374252" armature="0.00950276" damping="0.0101134" frictionloss="0.0891085"/>
              <geom name="//unnamed_geom_17" class="visual" mesh="left_hand_link"/>
              <geom name="//unnamed_geom_18" class="collision" size="0.0279479 0.0815148" pos="0 0.119673 0" quat="0.707105 0.707108 0 0" type="cylinder"/>
              <geom name="//unnamed_geom_19" class="reward_collision_sphere" size="0.0465799"/>
              <geom name="//unnamed_geom_20" class="reward_collision_sphere" size="0.0326059" pos="0 0.101261 0"/>
              <geom name="//unnamed_geom_21" class="reward_collision_sphere" size="0.0326059" pos="0 0.19792 0"/>
            </body>
          </body>
        </body>
      </body>
      <body name="AR1" pos="0.0425537 -0.0965376 0.244717" quat="1 5.7981e-05 0.000467818 0.000171646">
        <inertial pos="-0.000385097 -0.0407757 0.000240828" quat="0.505285 0.497122 -0.505321 0.492146" mass="0.432029" diaginertia="0.000340124 0.000860962 0.0005135"/>
        <joint name="Right_Shoulder_Pitch" pos="0 0 0" axis="0.0003461 -1 -0.000302127" range="-1.22589 3.29264" armature="0.00902797" damping="0.00795554" frictionloss="0.0939524"/>
        <geom name="//unnamed_geom_22" class="visual" rgba="0.76 0.76 0.76 1" mesh="AR1"/>
        <body name="AR2" pos="-0.000812014 -0.0432446 -0.000953698" quat="1 0.00012712 -0.000203493 -0.000201975">
          <inertial pos="0.00350782 -0.0348894 -0.000297105" quat="0.511296 0.488708 -0.511358 0.488113" mass="0.129235" diaginertia="0.000100089 0.000226938 0.000308536"/>
          <joint name="Right_Shoulder_Roll" pos="0 0 0" axis="-0.999979 0.00176254 0.00618188" range="-1.73737 1.57556" armature="0.00929968" damping="0.00199704" frictionloss="0.0933892"/>
          <geom name="//unnamed_geom_23" class="visual" mesh="AR2"/>
          <body name="AR3" pos="-0.000181476 -0.0560407 0.000173606" quat="1 -2.11135e-05 -4.53798e-05 1.50249e-05">
            <inertial pos="-0.00122304 -0.0787852 0.000391644" quat="0.709212 0.70499 -0.00276993 0.000255378" mass="0.836546" diaginertia="0.00322935 0.00854956 0.00108795"/>
            <joint name="Right_Elbow_Pitch" pos="0 0 0" axis="0.00366323 0.999988 -0.0032056" range="-2.27327 2.28786" armature="0.00952488" damping="0.00812098" frictionloss="0.092631"/>
            <geom name="//unnamed_geom_24" class="visual" mesh="AR3"/>
            <geom name="//unnamed_geom_25" class="collision" size="0.0279479 0.0698698" pos="0 -0.0460279 0" quat="0.707105 0.707108 0 0" type="cylinder"/>
            <geom name="//unnamed_geom_26" class="reward_collision_sphere" size="0.0335375"/>
            <body name="right_hand_link" pos="-0.000449056 -0.135184 0.000218747" quat="1 3.45065e-05 -1.02277e-06 -1.06324e-05">
              <inertial pos="0.000468297 -0.101317 0.000863048" quat="0.706368 0.707845 0.000140788 4.07946e-05" mass="0.267225" diaginertia="0.00202399 0.00546952 0.000375984"/>
              <joint name="Right_Elbow_Yaw" pos="0 0 0" axis="-0.000342945 -0.000536753 1" stiffness="0.00323128" range="-2.26405e-06 2.4396" armature="0.00931999" damping="0.00909807" frictionloss="0.0921574"/>
              <geom name="//unnamed_geom_27" class="visual" mesh="right_hand_link"/>
              <geom name="//unnamed_geom_28" class="collision" size="0.0279479 0.0815148" pos="0 -0.119673 0" quat="0.707105 0.707108 0 0" type="cylinder"/>
              <geom name="//unnamed_geom_29" class="reward_collision_sphere" size="0.0465799"/>
              <geom name="//unnamed_geom_30" class="reward_collision_sphere" size="0.0326059" pos="0 -0.101261 0"/>
              <geom name="//unnamed_geom_31" class="reward_collision_sphere" size="0.0326059" pos="0 -0.19792 0"/>
            </body>
          </body>
        </body>
      </body>
      <body name="Waist" pos="0.0470678 -0.000738598 -0.129905" quat="1 3.75858e-05 -3.99699e-05 2.03407e-05">
        <inertial pos="0.000510383 -0.000822578 0.00753348" quat="0.983545 0.000234634 -0.180644 0.00277637" mass="2.10147" diaginertia="0.00134717 0.00353919 0.00843854"/>
        <joint name="Waist" pos="0 0 0" axis="0.000529047 -0.000214236 1" stiffness="0.00174612" range="-1.55756 1.55293" armature="0.00937745" damping="0" frictionloss="0.0936522"/>
        <geom name="//unnamed_geom_32" class="visual" mesh="Waist"/>
        <body name="Hip_Pitch_Left" pos="0.000925978 0.0982793 -0.000312552" quat="1 -0.000365067 8.49683e-05 -0.000205325">
          <inertial pos="0.00145119 -0.00696735 -0.0213589" quat="0.97486 0.222375 0.0138885 0.00190021" mass="0.830093" diaginertia="0.000441175 0.000962187 0.00220826"/>
          <joint name="Left_Hip_Pitch" pos="0 0 0" axis="-0.00562392 0.999982 0.002166" range="-1.80587 1.57019" armature="0.00932384" damping="0.0110293" frictionloss="0.0937585"/>
          <geom name="//unnamed_geom_33" class="visual" rgba="0.76 0.76 0.76 1" mesh="Hip_Pitch_Left"/>
          <body name="Hip_Roll_Left" pos="-0.000953137 0.000786779 -0.0236206" quat="1 6.36124e-05 7.55538e-05 5.85075e-05">
            <inertial pos="0.00159624 -0.000542251 -0.0601944" quat="0.704856 -0.00396464 -0.00637241 0.709311" mass="0.30899" diaginertia="0.000424125 0.000983704 0.000891405"/>
            <joint name="Left_Hip_Roll" pos="0 0 0" axis="-0.999997 0.00143693 0.00179237" range="-1.58244 0.203139" armature="0.009281" damping="0.00590954" frictionloss="0.0963267"/>
            <geom name="//unnamed_geom_34" class="visual" mesh="Hip_Roll_Left"/>
            <geom name="//unnamed_geom_35" class="reward_collision_sphere" size="0.0512379"/>
            <body name="Hip_Yaw_Left" pos="0.000981283 0.000450375 -0.0914909" quat="1 3.70858e-05 -3.0585e-05 -1.32497e-05">
              <inertial pos="-0.00470753 -0.00067417 -0.100298" quat="0.697233 -0.0352643 -0.0313716 0.715289" mass="1.76872" diaginertia="0.00644807 0.016714 0.00454733"/>
              <joint name="Left_Hip_Yaw" pos="0 0 0" axis="0.00168522 -0.00389417 -0.999991" range="-1.00876 0.995066" armature="0.00956997" damping="0.0128116" frictionloss="0.0925788"/>
              <geom name="//unnamed_geom_36" class="visual" mesh="Hip_Yaw_Left"/>
              <geom name="//unnamed_geom_37" class="collision" size="0.0465799 0.0745278" type="cylinder"/>
              <body name="Shank_Left" pos="-0.00953453 0.000427791 -0.150756" quat="1 4.26271e-05 0.000406784 8.26586e-05">
                <inertial pos="-0.00551223 -0.000614469 -0.138619" quat="0.997518 0.00144669 -0.023992 0.0661891" mass="1.38253" diaginertia="0.00844027 0.0226395 0.00320342"/>
                <joint name="Left_Knee_Pitch" pos="0 0 0" axis="0.000241577 0.999998 -0.00217632" range="-0.00625593 2.34139" armature="0.0090076" damping="0.00783858" frictionloss="0.0917199"/>
                <geom name="//unnamed_geom_38" class="visual" mesh="Shank_Left"/>
                <geom name="//unnamed_geom_39" class="collision" size="0.0465799 0.0698698" pos="0 0 -0.134199" type="cylinder"/>
                <geom name="//unnamed_geom_40" class="reward_collision_sphere" size="0.0605538"/>
                <body name="Ankle_Cross_Left" pos="-0.000940533 0.000274903 -0.313474" quat="1 2.9245e-05 0.000149074 5.24789e-07">
                  <inertial pos="-0.00253316 0.000199991 -0.00924044" quat="0.445833 0.551626 0.550171 0.440741" mass="0.0588339" diaginertia="7.13834e-06 1.68992e-05 1.98165e-05"/>
                  <joint name="Left_Ankle_Pitch" pos="0 0 0" axis="0.00110687 0.99999 0.00440619" stiffness="6.57107e-05" range="-0.865323 0.347725" armature="0.00943029" damping="0.00626787" frictionloss="0.0926096"/>
                  <geom name="//unnamed_geom_41" class="visual" mesh="Ankle_Cross_Left"/>
                  <body name="left_foot_link" pos="-0.00107434 -0.000269027 -0.0138139" quat="1 -0.00039919 0.00022761 7.46306e-05">
                    <inertial pos="-0.000130602 0.000307506 -0.0090874" quat="-0.000171019 0.620495 -3.69452e-05 0.78421" mass="0.561974" diaginertia="0.0006737 0.00158714 0.00388486"/>
                    <joint name="Left_Ankle_Roll" pos="0 0 0" axis="-0.999996 0.0026244 0.000811761" range="-0.427182 0.424808" armature="0.00932715" damping="0.0131359" frictionloss="0.0934641"/>
                    <geom name="//unnamed_geom_42" class="visual" mesh="left_foot_link"/>
                    <geom name="left_foot" class="foot" size="0.104958 0.0501321 0.0138338" pos="0.00755906 0 -0.0167749"/>
                    <geom name="//unnamed_geom_44" class="reward_collision_sphere" size="0.0484431" pos="0.00755906 0 -0.0167749"/>
                    <geom name="//unnamed_geom_45" class="reward_collision_sphere" size="0.0279479" pos="0.0718111 -0.0211729 -0.0167749"/>
                    <geom name="//unnamed_geom_46" class="reward_collision_sphere" size="0.0279479" pos="-0.0529135 -0.0211729 -0.0167749"/>
                    <site name="left_foot" class="foot" pos="0.00755906 0 -0.0167749" size="0.00931597"/>
                  </body>
                </body>
              </body>
            </body>
          </body>
        </body>
        <body name="Hip_Pitch_Right" pos="-0.00029038 -0.096506 3.41168e-05" quat="1 3.08686e-05 5.86568e-05 -2.50116e-05">
          <inertial pos="0.000167148 0.00607845 -0.0197521" quat="0.973523 -0.227972 0.0150285 -0.00744244" mass="0.827695" diaginertia="0.000448173 0.000968254 0.00216613"/>
          <joint name="Right_Hip_Pitch" pos="0 0 0" axis="0.000433996 -0.999999 -0.00131802" range="-1.58896 1.7978" armature="0.00923792" damping="0.00295722" frictionloss="0.0966376"/>
          <geom name="//unnamed_geom_47" class="visual" rgba="0.76 0.76 0.76 1" mesh="Hip_Pitch_Right"/>
          <body name="Hip_Roll_Right" pos="-0.000782559 -2.08924e-06 -0.0226052" quat="1 -7.40235e-06 -4.10451e-05 1.3357e-05">
            <inertial pos="0.00109977 -0.00030899 -0.0608975" quat="0.707039 -0.00590821 -0.00598304 0.707124" mass="0.311559" diaginertia="0.000423818 0.000998244 0.000898535"/>
            <joint name="Right_Hip_Roll" pos="0 0 0" axis="-0.999999 0.001256 -0.000440427" range="-0.218066 1.58057" armature="0.00933502" damping="0.011517" frictionloss="0.0920046"/>
            <geom name="//unnamed_geom_48" class="visual" mesh="Hip_Roll_Right"/>
            <geom name="//unnamed_geom_49" class="reward_collision_sphere" size="0.0512379"/>
            <body name="Hip_Yaw_Right" pos="5.41707e-05 -0.000161725 -0.0918803" quat="1 -5.4969e-06 3.176e-06 5.27027e-06">
              <inertial pos="-0.00492796 0.000642553 -0.0994152" quat="0.714268 -0.0328571 -0.0334506 0.6983" mass="1.74029" diaginertia="0.00629332 0.016498 0.00450911"/>
              <joint name="Right_Hip_Yaw" pos="0 0 0" axis="-0.000262095 -0.000235144 -1" range="-0.995787 1.00357" armature="0.00929586" damping="0.00696442" frictionloss="0.0928782"/>
              <geom name="//unnamed_geom_50" class="visual" mesh="Hip_Yaw_Right"/>
              <geom name="//unnamed_geom_51" class="collision" size="0.0465799 0.0745278" type="cylinder"/>
              <body name="Shank_Right" pos="-0.0104651 -0.000318993 -0.149338" quat="1 2.65724e-05 3.2455e-05 -8.27867e-06">
                <inertial pos="-0.00607042 -0.000483672 -0.136404" quat="0.999385 -0.000642573 -0.0229547 -0.0265021" mass="1.41999" diaginertia="0.00855114 0.0227298 0.00339424"/>
                <joint name="Right_Knee_Pitch" pos="0 0 0" axis="0.00777147 -0.99997 -0.000357396" range="-2.3394 -0.00849626" armature="0.00942146" damping="0.00672924" frictionloss="0.0965957"/>
                <geom name="//unnamed_geom_52" class="visual" mesh="Shank_Right"/>
                <geom name="//unnamed_geom_53" class="collision" size="0.0465799 0.0698698" pos="0 0 -0.134199" type="cylinder"/>
                <geom name="//unnamed_geom_54" class="reward_collision_sphere" size="0.0605538"/>
                <body name="Ankle_Cross_Right" pos="0.00136 0.000464431 -0.313222" quat="1 6.74519e-05 0.000207624 4.88052e-05">
                  <inertial pos="-0.00234997 0.00114391 -0.00879764" quat="0.441166 0.551018 0.554451 0.440835" mass="0.0596144" diaginertia="7.16554e-06 1.68612e-05 1.98388e-05"/>
                  <joint name="Right_Ankle_Pitch" pos="0 0 0" axis="-0.000162047 -1 7.3929e-05" range="-0.325667 0.85091" armature="0.0090422" damping="0.00663043" frictionloss="0.0931296"/>
                  <geom name="//unnamed_geom_55" class="visual" mesh="Ankle_Cross_Right"/>
                  <body name="right_foot_link" pos="0.000306967 -0.00116181 -0.0139023" quat="1 7.72398e-06 -5.04569e-05 8.99553e-05">
                    <inertial pos="-0.000145053 0.000494218 -0.00928134" quat="0.00107319 0.619465 0.00126837 0.785022" mass="0.549678" diaginertia="0.000663487 0.00159149 0.00381707"/>
                    <joint name="Right_Ankle_Roll" pos="0 0 0" axis="-0.999999 0.00100572 0.000445445" range="-0.442758 0.433451" armature="0.00957106" damping="0.0120496" frictionloss="0.0988359"/>
                    <geom name="//unnamed_geom_56" class="visual" mesh="right_foot_link"/>
                    <geom name="right_foot" class="foot" size="0.101483 0.0433988 0.0147624" pos="0.00755906 0 -0.0167749"/>
                    <geom name="//unnamed_geom_58" class="reward_collision_sphere" size="0.0372639"/>
                    <geom name="//unnamed_geom_59" class="reward_collision_sphere" size="0.0279479" pos="0.00755906 0 -0.0167749"/>
                    <geom name="//unnamed_geom_60" class="reward_collision_sphere" size="0.0279479" pos="0.0718111 0.0211729 -0.0167749"/>
                    <geom name="//unnamed_geom_61" class="reward_collision_sphere" size="0.0279479" pos="-0.0529135 0.0211729 -0.0167749"/>
                    <site name="right_foot" class="foot" pos="0.00755906 0 -0.0167749" size="0.00931597"/>
                  </body>
                </body>
              </body>
            </body>
          </body>
        </body>
      </body>
    </body>
  </worldbody>

  <contact>
    <pair class="/" geom1="floor" geom2="left_foot" name="//unnamed_contact_0"/>
    <pair class="/" geom1="floor" geom2="right_foot" name="//unnamed_contact_1"/>
  </contact>

  <actuator>
    <general name="AAHead_yaw" class="/" joint="AAHead_yaw" forcerange="-6.49445 6.49445" gainprm="22.9115" biasprm="0 -22.9115 -0.551239"/>
    <general name="Head_pitch" class="/" joint="Head_pitch" forcerange="-6.32931 6.32931" gainprm="22.9115" biasprm="0 -22.9115 -0.551239"/>
    <general name="Left_Shoulder_Pitch" class="/" joint="Left_Shoulder_Pitch" forcerange="-17.1293 17.1293" gainprm="22.9115" biasprm="0 -22.9115 -0.551239"/>
    <general name="Left_Shoulder_Roll" class="/" joint="Left_Shoulder_Roll" forcerange="-16.8327 16.8327" gainprm="22.9115" biasprm="0 -22.9115 -0.551239"/>
    <general name="Left_Elbow_Pitch" class="/" joint="Left_Elbow_Pitch" forcerange="-16.8543 16.8543" gainprm="22.9115" biasprm="0 -22.9115 -0.551239"/>
    <general name="Left_Elbow_Yaw" class="/" joint="Left_Elbow_Yaw" forcerange="-16.8625 16.8625" gainprm="22.9115" biasprm="0 -22.9115 -0.551239"/>
    <general name="Right_Shoulder_Pitch" class="/" joint="Right_Shoulder_Pitch" forcerange="-17.1687 17.1687" gainprm="22.9115" biasprm="0 -22.9115 -0.551239"/>
    <general name="Right_Shoulder_Roll" class="/" joint="Right_Shoulder_Roll" forcerange="-16.2159 16.2159" gainprm="22.9115" biasprm="0 -22.9115 -0.551239"/>
    <general name="Right_Elbow_Pitch" class="/" joint="Right_Elbow_Pitch" forcerange="-16.751 16.751" gainprm="22.9115" biasprm="0 -22.9115 -0.551239"/>
    <general name="Right_Elbow_Yaw" class="/" joint="Right_Elbow_Yaw" forcerange="-16.4958 16.4958" gainprm="22.9115" biasprm="0 -22.9115 -0.551239"/>
    <general name="Waist" class="/" joint="Waist" forcerange="-28.1548 28.1548" gainprm="22.9115" biasprm="0 -22.9115 -0.551239"/>
    <general name="Left_Hip_Pitch" class="/" joint="Left_Hip_Pitch" forcerange="-41.565 41.565" gainprm="22.9115" biasprm="0 -22.9115 -0.551239"/>
    <general name="Left_Hip_Roll" class="/" joint="Left_Hip_Roll" forcerange="-28.733 28.733" gainprm="22.9115" biasprm="0 -22.9115 -0.551239"/>
    <general name="Left_Hip_Yaw" class="/" joint="Left_Hip_Yaw" forcerange="-28.8812 28.8812" gainprm="22.9115" biasprm="0 -22.9115 -0.551239"/>
    <general name="Left_Knee_Pitch" class="/" joint="Left_Knee_Pitch" forcerange="-56.6423 56.6423" gainprm="22.9115" biasprm="0 -22.9115 -0.551239"/>
    <general name="Left_Ankle_Pitch" class="/" joint="Left_Ankle_Pitch" forcerange="-19.2617 19.2617" gainprm="22.9115" biasprm="0 -22.9115 -0.551239"/>
    <general name="Left_Ankle_Roll" class="/" joint="Left_Ankle_Roll" forcerange="-14.4571 14.4571" gainprm="22.9115" biasprm="0 -22.9115 -0.551239"/>
    <general name="Right_Hip_Pitch" class="/" joint="Right_Hip_Pitch" forcerange="-41.8066 41.8066" gainprm="22.9115" biasprm="0 -22.9115 -0.551239"/>
    <general name="Right_Hip_Roll" class="/" joint="Right_Hip_Roll" forcerange="-27.6516 27.6516" gainprm="22.9115" biasprm="0 -22.9115 -0.551239"/>
    <general name="Right_Hip_Yaw" class="/" joint="Right_Hip_Yaw" forcerange="-27.0996 27.0996" gainprm="22.9115" biasprm="0 -22.9115 -0.551239"/>
    <general name="Right_Knee_Pitch" class="/" joint="Right_Knee_Pitch" forcerange="-56.3104 56.3104" gainprm="22.9115" biasprm="0 -22.9115 -0.551239"/>
    <general name="Right_Ankle_Pitch" class="/" joint="Right_Ankle_Pitch" forcerange="-18.5604 18.5604" gainprm="22.9115" biasprm="0 -22.9115 -0.551239"/>
    <general name="Right_Ankle_Roll" class="/" joint="Right_Ankle_Roll" forcerange="-14.096 14.096" gainprm="22.9115" biasprm="0 -22.9115 -0.551239"/>
  </actuator>

  <sensor>
    <gyro site="imu" name="imu_angular_velocity"/>
    <velocimeter site="imu" name="imu_linear_velocity"/>
    <framelinvel objtype="site" objname="left_foot" name="left_foot_global_linear_velocity"/>
    <framelinvel objtype="site" objname="right_foot" name="right_foot_global_linear_velocity"/>
  </sensor>

  <keyframe>
    <key name="home" qpos="0 0 0.6385 1 0 0 0 0 0 0 1.4 0 -0.4 0 -1.4 0 0.4 0 -0.4 0 0 0.8 -0.4 0 0.4 0 0 -0.8 0.4 0"/>
  </keyframe>
</mujoco>
