<mujoco model="T1">
  <compiler angle="radian" assetdir="assets" balanceinertia="true" inertiafromgeom="false"/>

  <option timestep="0.005" density="1.2" viscosity="2e-05"/>

  <size nkey="1"/>

  <visual>
    <quality shadowsize="8192"/>
    <map shadowclip="0.5"/>
  </visual>

  <default>
    <default class="/">
      <joint armature="0.01" damping="0.01" frictionloss="0.1"/>
      <geom contype="0" conaffinity="0" group="1" solref="-1000 -80"/>
      <site size="0.01 0.005 0.005" group="5"/>
      <general forcelimited="true" biastype="affine" gainprm="25" biasprm="0 -25 -0.6"/>
      <default class="t1">
        <geom rgba="0.25 0.25 0.25 1"/>
        <default class="visual">
          <geom type="mesh" group="2"/>
        </default>
        <default class="collision">
          <geom group="3"/>
        </default>
        <default class="foot">
          <geom size="0.1115 0.05 0.015" type="box" condim="6" group="4" priority="1" solimp="0.015 1 0.015"/>
        </default>
        <default class="reward_collision_sphere">
          <geom group="5" rgba="1 0 0 1"/>
        </default>
      </default>
    </default>
  </default>

  <asset>
    <texture type="skybox" colorspace="auto" name="//unnamed_texture_0" builtin="gradient" rgb1="0.95 0.95 0.95" rgb2="0.95 0.95 0.95" width="100" height="600"/>
    <texture type="2d" colorspace="auto" name="texplane" builtin="checker" rgb1="0.345 0.575 0.748" rgb2="0.345 0.575 0.748" markrgb="1 1 1" width="512" height="512"/>
    <material name="MatPlane" class="/" texture="texplane" texuniform="true" texrepeat="2 2" specular="0.9"/>
    <mesh name="Trunk" class="/" file="Trunk.stl"/>
    <mesh name="H1" class="/" file="H1.stl"/>
    <mesh name="H2" class="/" file="H2.stl"/>
    <mesh name="AL1" class="/" file="AL1.stl"/>
    <mesh name="AL2" class="/" file="AL2.stl"/>
    <mesh name="AL3" class="/" file="AL3.stl"/>
    <mesh name="left_hand_link" class="/" file="left_hand_link.stl"/>
    <mesh name="AR1" class="/" file="AR1.stl"/>
    <mesh name="AR2" class="/" file="AR2.stl"/>
    <mesh name="AR3" class="/" file="AR3.stl"/>
    <mesh name="right_hand_link" class="/" file="right_hand_link.stl"/>
    <mesh name="Waist" class="/" file="Waist.stl"/>
    <mesh name="Hip_Pitch_Left" class="/" file="Hip_Pitch_Left.stl"/>
    <mesh name="Hip_Roll_Left" class="/" file="Hip_Roll_Left.stl"/>
    <mesh name="Hip_Yaw_Left" class="/" file="Hip_Yaw_Left.stl"/>
    <mesh name="Shank_Left" class="/" file="Shank_Left.stl"/>
    <mesh name="Ankle_Cross_Left" class="/" file="Ankle_Cross_Left.stl"/>
    <mesh name="left_foot_link" class="/" file="left_foot_link.stl"/>
    <mesh name="Hip_Pitch_Right" class="/" file="Hip_Pitch_Right.stl"/>
    <mesh name="Hip_Roll_Right" class="/" file="Hip_Roll_Right.stl"/>
    <mesh name="Hip_Yaw_Right" class="/" file="Hip_Yaw_Right.stl"/>
    <mesh name="Shank_Right" class="/" file="Shank_Right.stl"/>
    <mesh name="Ankle_Cross_Right" class="/" file="Ankle_Cross_Right.stl"/>
    <mesh name="right_foot_link" class="/" file="right_foot_link.stl"/>
  </asset>

  <worldbody>
    <geom name="floor" class="/" size="100 100 0.125" type="plane" group="0" material="MatPlane"/>
    <light name="toplight_shadow" class="/" pos="0 0 5" dir="0.0990148 0.0990148 -0.990148" type="directional" ambient="0.04 0.04 0.04" diffuse="0.55 0.55 0.55" specular="0.12 0.12 0.12"/>
    <light name="toplight_fill" class="/" pos="0 0 5" dir="0.0990148 0.0990148 -0.990148" type="directional" castshadow="false" ambient="0.04 0.04 0.04" diffuse="0.3 0.3 0.3" specular="0.08 0.08 0.08"/>
    <body name="trunk" childclass="t1" pos="0.000855974 -0.0116605 0.0160831" quat="0.999964 0.00307878 0.00578191 0.00545274">
      <inertial pos="0.0483587 -0.000145286 0.0503466" quat="0.999963 2.38192e-05 -0.0085808 0.000828905" mass="14.0081" diaginertia="0.0895912 0.953281 0.00260769"/>
      <joint name="//unnamed_joint_0" type="free" armature="0" damping="0" frictionloss="0"/>
      <geom name="//unnamed_geom_1" class="visual" rgba="0.76 0.76 0.76 1" mesh="Trunk"/>
      <geom name="//unnamed_geom_2" class="collision" size="0.077255 0.103007 0.15451" pos="0.0563324 0 0.0612766" type="box"/>
      <geom name="//unnamed_geom_3" class="reward_collision_sphere" size="0.118458" pos="0.0563324 0 0.0510639"/>
      <geom name="//unnamed_geom_4" class="reward_collision_sphere" size="0.015451" pos="0.0563324 0.139459 0"/>
      <geom name="//unnamed_geom_5" class="reward_collision_sphere" size="0.015451" pos="0.0563324 -0.139459 0"/>
      <geom name="//unnamed_geom_6" class="reward_collision_sphere" size="0.015451" pos="0.0563324 0.175554 0.091915"/>
      <geom name="//unnamed_geom_7" class="reward_collision_sphere" size="0.015451" pos="0.0563324 -0.175554 0.091915"/>
      <site name="imu" pos="0.0794109 0.0198149 0.00711017" size="0.0103007"/>
      <camera name="track" pos="0 -3.28138 0" quat="0.707107 0.707107 0 0" mode="trackcom"/>
      <camera name="ego_camera" pos="0.114543 0 0.214468" quat="-0.5 -0.5 0.5 0.5"/>
      <body name="H1" pos="0.046851 -0.000696526 0.111843" quat="0.99997 -0.00625659 -0.00111402 -0.00432955">
        <inertial pos="-0.0140901 -0.0121757 0.0226743" quat="0.771726 -0.00457704 -0.00312322 0.635931" mass="0.38626" diaginertia="0.000142805 0.00201771 5.58546e-06"/>
        <joint name="AAHead_yaw" pos="0 0 0" axis="0.0119139 -0.0119695 0.999857" stiffness="0.00403649" range="-1.21662 1.71124" armature="0.0085367" damping="0.0531135" frictionloss="0.0590238"/>
        <geom name="//unnamed_geom_8" class="visual" mesh="H1"/>
        <body name="H2" pos="0.00669937 -0.00695279 0.0189458" quat="0.999966 0.000229019 0.00828521 -0.00016647">
          <inertial pos="0.00188299 -0.00341463 0.0514611" quat="0.988082 0.106694 -0.0752018 -0.0815732" mass="0.823062" diaginertia="0.00169263 0.0262538 5.94901e-05"/>
          <joint name="Head_pitch" pos="0 0 0" axis="0.0486837 -0.996934 0.0612548" stiffness="0.0474812" range="-0.965519 0.0295521" armature="0.00318252" damping="0" frictionloss="0.0175189"/>
          <geom name="//unnamed_geom_9" class="visual" mesh="H2"/>
          <geom name="//unnamed_geom_10" class="collision" size="0.0824053" pos="0.00938873 0 0.0561703"/>
          <geom name="//unnamed_geom_11" class="reward_collision_sphere" size="0.092706" pos="0.0187775 0 0.0510639"/>
        </body>
      </body>
      <body name="AL1" pos="0.0378232 0.163398 0.1015" quat="0.999998 -0.00161024 0.00105941 -0.000838055">
        <inertial pos="0.0162337 0.0827786 0.00964878" quat="0.543862 0.512319 -0.489005 0.45013" mass="0.654883" diaginertia="0.00103577 0.0136326 1.21294e-05"/>
        <joint name="Left_Shoulder_Pitch" pos="0 0 0" axis="0.0143086 0.999837 0.0109855" range="-3.20472 1.21076" armature="0.008017" damping="0" frictionloss="0.148386"/>
        <geom name="//unnamed_geom_12" class="visual" rgba="0.76 0.76 0.76 1" mesh="AL1"/>
        <body name="AL2" pos="-0.000463383 0.0771358 0.0162948" quat="0.999968 0.00736705 -0.00162998 0.00247127">
          <inertial pos="0.0120008 0.0642041 0.0147098" quat="0.449313 0.514581 -0.507992 0.524659" mass="0.142641" diaginertia="0.000310849 0.00459557 5.5002e-06"/>
          <joint name="Left_Shoulder_Roll" pos="0 0 0" axis="-0.996745 0.0805568 0.00304721" range="-1.59731 1.86672" armature="0.00751213" damping="0" frictionloss="0.18549"/>
          <geom name="//unnamed_geom_13" class="visual" mesh="AL2"/>
          <body name="AL3" pos="0.0164028 0.109126 0.00487851" quat="0.999998 -0.00100204 0.00135824 -0.00109983">
            <inertial pos="0.00559048 0.14044 -0.0149693" quat="0.70735 0.70686 -0.0022509 -0.000247077" mass="1.15668" diaginertia="0.00829107 0.159069 2.4325e-05"/>
            <joint name="Left_Elbow_Pitch" pos="0 0 0" axis="0.0182682 -0.997088 -0.0740338" range="-2.38347 2.25594" armature="0.0145336" damping="0.0155007" frictionloss="0.0568887"/>
            <geom name="//unnamed_geom_14" class="visual" mesh="AL3"/>
            <geom name="//unnamed_geom_15" class="collision" size="0.030902 0.077255" pos="0 0.0820344 0" quat="0.707105 0.707108 0 0" type="cylinder"/>
            <geom name="//unnamed_geom_16" class="reward_collision_sphere" size="0.0370824"/>
            <body name="left_hand_link" pos="0.0118037 0.256897 -0.0170959" quat="0.999992 0.00306967 0.00272311 0.000151939">
              <inertial pos="0.000493774 0.170285 -0.0123929" quat="0.712332 0.701763 0.00683861 0.00804585" mass="0.314063" diaginertia="0.00566594 0.064827 5.93305e-06"/>
              <joint name="Left_Elbow_Yaw" pos="0 0 0" axis="-0.0639878 -0.0370661 0.997262" stiffness="0.063232" range="-2.59151 -0.0471595" armature="0.0084537" damping="0" frictionloss="0.043796"/>
              <geom name="//unnamed_geom_17" class="visual" mesh="left_hand_link"/>
              <geom name="//unnamed_geom_18" class="collision" size="0.030902 0.0901309" pos="0 0.213289 0" quat="0.707105 0.707108 0 0" type="cylinder"/>
              <geom name="//unnamed_geom_19" class="reward_collision_sphere" size="0.0515033"/>
              <geom name="//unnamed_geom_20" class="reward_collision_sphere" size="0.0360523" pos="0 0.180476 0"/>
              <geom name="//unnamed_geom_21" class="reward_collision_sphere" size="0.0360523" pos="0 0.352748 0"/>
            </body>
          </body>
        </body>
      </body>
      <body name="AR1" pos="0.0407073 -0.177997 0.0975718" quat="0.999969 0.000841684 0.00376649 -0.00688506">
        <inertial pos="-0.00120173 -0.0643817 -0.00620529" quat="0.534372 0.494689 -0.509571 0.458332" mass="0.658449" diaginertia="0.00128819 0.0167037 1.14214e-05"/>
        <joint name="Right_Shoulder_Pitch" pos="0 0 0" axis="0.035613 -0.999364 0.00175162" stiffness="0.0729684" range="-1.23007 3.07626" armature="0.0141473" damping="0.0801201" frictionloss="0.0818733"/>
        <geom name="//unnamed_geom_22" class="visual" rgba="0.76 0.76 0.76 1" mesh="AR1"/>
        <body name="AR2" pos="0.00200264 -0.084699 -0.00742932" quat="0.999984 0.0039628 0.00389813 0.00115386">
          <inertial pos="0.0123805 -0.0629037 -0.0120406" quat="0.505785 0.487411 -0.520691 0.485277" mass="0.206083" diaginertia="0.000229283 0.00434082 7.23209e-06"/>
          <joint name="Right_Shoulder_Roll" pos="0 0 0" axis="-0.999985 -0.00539892 3.93185e-05" stiffness="0.0164135" range="-1.87914 1.54579" armature="0.00931098" damping="0" frictionloss="0.0273361"/>
          <geom name="//unnamed_geom_23" class="visual" mesh="AR2"/>
          <body name="AR3" pos="-0.00623648 -0.113354 0.00763915" quat="0.999994 0.00033081 -0.0012376 -0.00321298">
            <inertial pos="0.0166003 -0.141989 -0.00624641" quat="0.711099 0.700364 -0.00256276 0.0618208" mass="0.832652" diaginertia="0.0100443 0.166979 2.13805e-05"/>
            <joint name="Right_Elbow_Pitch" pos="0 0 0" axis="-0.0196995 0.998694 0.0471322" stiffness="0.0862105" range="-2.25716 2.47007" armature="0.0178128" damping="0.0181999" frictionloss="0.1236"/>
            <geom name="//unnamed_geom_24" class="visual" mesh="AR3"/>
            <geom name="//unnamed_geom_25" class="collision" size="0.030902 0.077255" pos="0 -0.0820344 0" quat="0.707105 0.707108 0 0" type="cylinder"/>
            <geom name="//unnamed_geom_26" class="reward_collision_sphere" size="0.0370824"/>
            <body name="right_hand_link" pos="0.00403689 -0.23906 -0.0166415" quat="1 -1.09729e-05 2.65713e-05 4.74717e-06">
              <inertial pos="0.0117818 -0.192799 0.00765038" quat="0.707826 0.70546 -0.0352231 0.00829347" mass="0.397205" diaginertia="0.00598061 0.120021 7.35757e-06"/>
              <joint name="Right_Elbow_Yaw" pos="0 0 0" axis="0.0365864 0.000882901 0.99933" stiffness="0.0364313" range="0.0745715 2.45108" armature="0.0148512" damping="0.0521994" frictionloss="0.0861712"/>
              <geom name="//unnamed_geom_27" class="visual" mesh="right_hand_link"/>
              <geom name="//unnamed_geom_28" class="collision" size="0.030902 0.0901309" pos="0 -0.213289 0" quat="0.707105 0.707108 0 0" type="cylinder"/>
              <geom name="//unnamed_geom_29" class="reward_collision_sphere" size="0.0515033"/>
              <geom name="//unnamed_geom_30" class="reward_collision_sphere" size="0.0360523" pos="0 -0.180476 0"/>
              <geom name="//unnamed_geom_31" class="reward_collision_sphere" size="0.0360523" pos="0 -0.352748 0"/>
            </body>
          </body>
        </body>
      </body>
      <body name="Waist" pos="0.0578425 0.00540809 -0.0707308" quat="1 -0.000175242 -1.30255e-05 3.33771e-06">
        <inertial pos="-0.0083459 -0.00231377 -0.00499862" quat="0.982502 0.00224194 -0.185908 0.0110836" mass="2.62228" diaginertia="0.00413827 0.0470648 0.000173579"/>
        <joint name="Waist" pos="0 0 0" axis="0.0295352 -0.0155773 0.999442" stiffness="0.0560894" range="-1.31406 1.36781" armature="0.0101272" damping="0.0878035" frictionloss="0.105792"/>
        <geom name="//unnamed_geom_32" class="visual" mesh="Waist"/>
        <body name="Hip_Pitch_Left" pos="-0.00257648 0.156704 -0.014731" quat="1 -0.000155574 -3.57432e-05 -2.16431e-06">
          <inertial pos="0.0121537 -0.0143833 0.00775563" quat="0.976179 0.214875 0.00698678 -0.0292247" mass="0.900255" diaginertia="0.00112991 0.0167093 4.06403e-05"/>
          <joint name="Left_Hip_Pitch" pos="0 0 0" axis="0.0260527 0.998493 0.0483045" stiffness="0.0689403" range="-2.07678 1.52469" armature="0.0109001" damping="0.0802211" frictionloss="0.176328"/>
          <geom name="//unnamed_geom_33" class="visual" rgba="0.76 0.76 0.76 1" mesh="Hip_Pitch_Left"/>
          <body name="Hip_Roll_Left" pos="-0.0093445 -0.00144437 -0.010214" quat="1 0.000111825 0.000429548 0.000284745">
            <inertial pos="0.00405671 0.00579028 -0.0277498" quat="0.706503 -0.00346475 0.0404937 0.706542" mass="0.370516" diaginertia="0.00114637 0.0131264 1.46392e-05"/>
            <joint name="Left_Hip_Roll" pos="0 0 0" axis="-0.999231 0.0100642 0.0378866" range="-1.8203 0.205775" armature="0.0108618" damping="0" frictionloss="0.167214"/>
            <geom name="//unnamed_geom_34" class="visual" mesh="Hip_Roll_Left"/>
            <geom name="//unnamed_geom_35" class="reward_collision_sphere" size="0.0566537"/>
            <body name="Hip_Yaw_Left" pos="0.0133836 -0.00534206 -0.0589441" quat="1 -0.000232759 -4.19633e-05 -0.000476216">
              <inertial pos="-0.0124387 -0.00185761 -0.0299016" quat="0.712297 -0.00159699 -0.0398762 0.700743" mass="2.66107" diaginertia="0.0142576 0.266138 8.6571e-05"/>
              <joint name="Left_Hip_Yaw" pos="0 0 0" axis="0.0060149 0.064324 -0.997911" stiffness="0.087333" range="-0.980571 0.745228" armature="0.0172689" damping="0.0660071" frictionloss="0.179583"/>
              <geom name="//unnamed_geom_36" class="visual" mesh="Hip_Yaw_Left"/>
              <geom name="//unnamed_geom_37" class="collision" size="0.0515033 0.0824053" type="cylinder"/>
              <body name="Shank_Left" pos="-0.00209227 -0.0155286 -0.0827113" quat="0.999965 0.00208236 -0.00734402 -0.00334423">
                <inertial pos="-0.0155999 0.0179555 -0.0551455" quat="0.996071 0.0145827 -0.0842894 0.0229249" mass="1.69363" diaginertia="0.0183714 0.374986 5.45899e-05"/>
                <joint name="Left_Knee_Pitch" pos="0 0 0" axis="0.0285034 0.998685 0.0426089" range="0.132944 2.34628" armature="0.00392374" damping="0.0426871" frictionloss="0.182344"/>
                <geom name="//unnamed_geom_38" class="visual" mesh="Shank_Left"/>
                <geom name="//unnamed_geom_39" class="collision" size="0.0515033 0.077255" pos="0 0 -0.0612766" type="cylinder"/>
                <geom name="//unnamed_geom_40" class="reward_collision_sphere" size="0.0669543"/>
                <body name="Ankle_Cross_Left" pos="0.0165308 0.00813775 -0.147485" quat="1 9.96781e-07 -4.68197e-05 -0.000109184">
                  <inertial pos="-0.0071129 0.00367153 -0.00684899" quat="0.380822 0.532639 0.598509 0.461581" mass="0.0654247" diaginertia="2.08508e-05 0.000290788 3.53274e-07"/>
                  <joint name="Left_Ankle_Pitch" pos="0 0 0" axis="-0.0141163 0.998418 0.0544318" stiffness="0.00101176" range="-0.892035 0.644026" armature="0.0102311" damping="0" frictionloss="0.111311"/>
                  <geom name="//unnamed_geom_41" class="visual" mesh="Ankle_Cross_Left"/>
                  <body name="left_foot_link" pos="-0.0127143 -0.00214151 -0.0105801" quat="0.999983 -0.00254184 0.000495219 -0.00513472">
                    <inertial pos="-0.00299016 0.000411047 -0.0220001" quat="0.00107644 0.620597 -0.000935951 0.784128" mass="0.943122" diaginertia="0.00250904 0.0324817 9.44226e-05"/>
                    <joint name="Left_Ankle_Roll" pos="0 0 0" axis="-0.998518 -0.012917 0.0528681" range="-0.195223 0.256711" armature="0.0100538" damping="0" frictionloss="0.101732"/>
                    <geom name="//unnamed_geom_42" class="visual" mesh="left_foot_link"/>
                    <geom name="left_foot" class="foot" size="0.0485798 0.0207709 0.00992008" pos="0.00938873 0 -0.00765958"/>
                    <geom name="//unnamed_geom_44" class="reward_collision_sphere" size="0.0535635" pos="0.00938873 0 -0.00765958"/>
                    <geom name="//unnamed_geom_45" class="reward_collision_sphere" size="0.030902" pos="0.089193 -0.0377358 -0.00765958"/>
                    <geom name="//unnamed_geom_46" class="reward_collision_sphere" size="0.030902" pos="-0.0657211 -0.0377358 -0.00765958"/>
                    <site name="left_foot" class="foot" pos="0.00938873 0 -0.00765958" size="0.0103007"/>
                  </body>
                </body>
              </body>
            </body>
          </body>
        </body>
        <body name="Hip_Pitch_Right" pos="0.012979 -0.175243 -0.0147197" quat="0.999969 -0.00348034 0.00680839 -0.00191883">
          <inertial pos="0.00191512 0.0291939 -0.0158203" quat="0.963972 -0.262554 0.0409819 -0.0119674" mass="1.01685" diaginertia="0.00114005 0.015887 3.46565e-05"/>
          <joint name="Right_Hip_Pitch" pos="0 0 0" axis="0.0103714 -0.999881 0.0114571" stiffness="0.054291" range="-1.79679 2.09247" armature="0.00954778" damping="0" frictionloss="0.0180452"/>
          <geom name="//unnamed_geom_47" class="visual" rgba="0.76 0.76 0.76 1" mesh="Hip_Pitch_Right"/>
          <body name="Hip_Roll_Right" pos="0.0150738 0.00289608 -0.0235453" quat="0.999999 0.000448017 0.000777688 0.000933841">
            <inertial pos="0.00896368 -0.000304565 -0.0370775" quat="0.707907 -0.00869001 -0.00542171 0.706231" mass="0.421562" diaginertia="0.00156568 0.0162813 1.62523e-05"/>
            <joint name="Right_Hip_Roll" pos="0 0 0" axis="-0.998717 0.0447553 -0.0237063" range="-0.43425 1.73585" armature="0.0105878" damping="0.0572474" frictionloss="0.0314024"/>
            <geom name="//unnamed_geom_48" class="visual" mesh="Hip_Roll_Right"/>
            <geom name="//unnamed_geom_49" class="reward_collision_sphere" size="0.0566537"/>
            <body name="Hip_Yaw_Right" pos="-0.0134759 -0.00014539 -0.0561152" quat="1 -0.000114435 0.000188977 -6.70849e-05">
              <inertial pos="0.00745079 -0.0175731 -0.051425" quat="0.716501 -0.0386064 -0.0238628 0.696108" mass="3.17528" diaginertia="0.0185379 0.330806 0.000121124"/>
              <joint name="Right_Hip_Yaw" pos="0 0 0" axis="-0.0154914 0.0382947 -0.999146" stiffness="0.0278803" range="-1.11011 0.928737" armature="0.0111427" damping="0" frictionloss="0.0994947"/>
              <geom name="//unnamed_geom_50" class="visual" mesh="Hip_Yaw_Right"/>
              <geom name="//unnamed_geom_51" class="collision" size="0.0515033 0.0824053" type="cylinder"/>
              <body name="Shank_Right" pos="-0.00986769 0.00265957 -0.0851431" quat="0.999999 0.00108995 -0.00025579 0.000863426">
                <inertial pos="0.0125725 -0.00840574 -0.050641" quat="0.997636 -0.0591863 -0.0201924 0.0284775" mass="2.00269" diaginertia="0.0332303 0.420615 7.92563e-05"/>
                <joint name="Right_Knee_Pitch" pos="0 0 0" axis="-0.000478945 -0.999989 -0.00476616" range="-2.33564 0.300815" armature="0.00995102" damping="0" frictionloss="0.166059"/>
                <geom name="//unnamed_geom_52" class="visual" mesh="Shank_Right"/>
                <geom name="//unnamed_geom_53" class="collision" size="0.0515033 0.077255" pos="0 0 -0.0612766" type="cylinder"/>
                <geom name="//unnamed_geom_54" class="reward_collision_sphere" size="0.0669543"/>
                <body name="Ankle_Cross_Right" pos="0.010298 0.00947342 -0.128364" quat="0.999992 0.000490655 0.00141181 -0.00371192">
                  <inertial pos="-0.00125669 0.010245 -0.000850367" quat="0.404951 0.584477 0.539467 0.450973" mass="0.0984621" diaginertia="2.2664e-05 0.00035083 4.28979e-07"/>
                  <joint name="Right_Ankle_Pitch" pos="0 0 0" axis="-0.000754327 -0.999998 0.00182012" range="-0.708394 0.639781" armature="0.0125768" damping="0" frictionloss="0.0992434"/>
                  <geom name="//unnamed_geom_55" class="visual" mesh="Ankle_Cross_Right"/>
                  <body name="right_foot_link" pos="0.00481474 0.00530709 -0.0175821" quat="0.999999 -0.000810201 0.000608201 0.000134025">
                    <inertial pos="-0.00373578 0.00843579 -0.0216095" quat="0.0237561 0.624916 0.00532024 0.780312" mass="0.796152" diaginertia="0.00199844 0.0323619 8.23852e-05"/>
                    <joint name="Right_Ankle_Roll" pos="0 0 0" axis="-0.999996 0.00103877 0.00262703" range="-0.303719 0.395265" armature="0.00835592" damping="0.0462162" frictionloss="0.0110587"/>
                    <geom name="//unnamed_geom_56" class="visual" mesh="right_foot_link"/>
                    <geom name="right_foot" class="foot" size="0.0610605 0.0850202 0.00508469" pos="0.00938873 0 -0.00765958"/>
                    <geom name="//unnamed_geom_58" class="reward_collision_sphere" size="0.0412027"/>
                    <geom name="//unnamed_geom_59" class="reward_collision_sphere" size="0.030902" pos="0.00938873 0 -0.00765958"/>
                    <geom name="//unnamed_geom_60" class="reward_collision_sphere" size="0.030902" pos="0.089193 0.0377358 -0.00765958"/>
                    <geom name="//unnamed_geom_61" class="reward_collision_sphere" size="0.030902" pos="-0.0657211 0.0377358 -0.00765958"/>
                    <site name="right_foot" class="foot" pos="0.00938873 0 -0.00765958" size="0.0103007"/>
                  </body>
                </body>
              </body>
            </body>
          </body>
        </body>
      </body>
    </body>
  </worldbody>

  <contact>
    <pair class="/" geom1="floor" geom2="left_foot" name="//unnamed_contact_0"/>
    <pair class="/" geom1="floor" geom2="right_foot" name="//unnamed_contact_1"/>
  </contact>

  <actuator>
    <general name="AAHead_yaw" class="/" joint="AAHead_yaw" forcerange="-7.14367 7.14367" gainprm="17.1747" biasprm="0 -17.1747 -0.604212"/>
    <general name="Head_pitch" class="/" joint="Head_pitch" forcerange="-4.64799 4.64799" gainprm="17.1747" biasprm="0 -17.1747 -0.604212"/>
    <general name="Left_Shoulder_Pitch" class="/" joint="Left_Shoulder_Pitch" forcerange="-24.9009 24.9009" gainprm="17.1747" biasprm="0 -17.1747 -0.604212"/>
    <general name="Left_Shoulder_Roll" class="/" joint="Left_Shoulder_Roll" forcerange="-13.7498 13.7498" gainprm="17.1747" biasprm="0 -17.1747 -0.604212"/>
    <general name="Left_Elbow_Pitch" class="/" joint="Left_Elbow_Pitch" forcerange="-28.6295 28.6295" gainprm="17.1747" biasprm="0 -17.1747 -0.604212"/>
    <general name="Left_Elbow_Yaw" class="/" joint="Left_Elbow_Yaw" forcerange="-18.1365 18.1365" gainprm="17.1747" biasprm="0 -17.1747 -0.604212"/>
    <general name="Right_Shoulder_Pitch" class="/" joint="Right_Shoulder_Pitch" forcerange="-14.4678 14.4678" gainprm="17.1747" biasprm="0 -17.1747 -0.604212"/>
    <general name="Right_Shoulder_Roll" class="/" joint="Right_Shoulder_Roll" forcerange="-10.8738 10.8738" gainprm="17.1747" biasprm="0 -17.1747 -0.604212"/>
    <general name="Right_Elbow_Pitch" class="/" joint="Right_Elbow_Pitch" forcerange="-18.8154 18.8154" gainprm="17.1747" biasprm="0 -17.1747 -0.604212"/>
    <general name="Right_Elbow_Yaw" class="/" joint="Right_Elbow_Yaw" forcerange="-16.4824 16.4824" gainprm="17.1747" biasprm="0 -17.1747 -0.604212"/>
    <general name="Waist" class="/" joint="Waist" forcerange="-34.306 34.306" gainprm="17.1747" biasprm="0 -17.1747 -0.604212"/>
    <general name="Left_Hip_Pitch" class="/" joint="Left_Hip_Pitch" forcerange="-46.7414 46.7414" gainprm="17.1747" biasprm="0 -17.1747 -0.604212"/>
    <general name="Left_Hip_Roll" class="/" joint="Left_Hip_Roll" forcerange="-11.7542 11.7542" gainprm="17.1747" biasprm="0 -17.1747 -0.604212"/>
    <general name="Left_Hip_Yaw" class="/" joint="Left_Hip_Yaw" forcerange="-44.0275 44.0275" gainprm="17.1747" biasprm="0 -17.1747 -0.604212"/>
    <general name="Left_Knee_Pitch" class="/" joint="Left_Knee_Pitch" forcerange="-24.8719 24.8719" gainprm="17.1747" biasprm="0 -17.1747 -0.604212"/>
    <general name="Left_Ankle_Pitch" class="/" joint="Left_Ankle_Pitch" forcerange="-29.1818 29.1818" gainprm="17.1747" biasprm="0 -17.1747 -0.604212"/>
    <general name="Left_Ankle_Roll" class="/" joint="Left_Ankle_Roll" forcerange="-21.5424 21.5424" gainprm="17.1747" biasprm="0 -17.1747 -0.604212"/>
    <general name="Right_Hip_Pitch" class="/" joint="Right_Hip_Pitch" forcerange="-72.3602 72.3602" gainprm="17.1747" biasprm="0 -17.1747 -0.604212"/>
    <general name="Right_Hip_Roll" class="/" joint="Right_Hip_Roll" forcerange="-36.2136 36.2136" gainprm="17.1747" biasprm="0 -17.1747 -0.604212"/>
    <general name="Right_Hip_Yaw" class="/" joint="Right_Hip_Yaw" forcerange="-17.4854 17.4854" gainprm="17.1747" biasprm="0 -17.1747 -0.604212"/>
    <general name="Right_Knee_Pitch" class="/" joint="Right_Knee_Pitch" forcerange="-60.9629 60.9629" gainprm="17.1747" biasprm="0 -17.1747 -0.604212"/>
    <general name="Right_Ankle_Pitch" class="/" joint="Right_Ankle_Pitch" forcerange="-20.2408 20.2408" gainprm="17.1747" biasprm="0 -17.1747 -0.604212"/>
    <general name="Right_Ankle_Roll" class="/" joint="Right_Ankle_Roll" forcerange="-17.3654 17.3654" gainprm="17.1747" biasprm="0 -17.1747 -0.604212"/>
  </actuator>

  <sensor>
    <gyro site="imu" name="imu_angular_velocity"/>
    <velocimeter site="imu" name="imu_linear_velocity"/>
    <framelinvel objtype="site" objname="left_foot" name="left_foot_global_linear_velocity"/>
    <framelinvel objtype="site" objname="right_foot" name="right_foot_global_linear_velocity"/>
  </sensor>

  <keyframe>
    <key name="home" qpos="0 0 0.6385 1 0 0 0 0 0 0 1.4 0 -0.4 0 -1.4 0 0.4 0 -0.4 0 0 0.8 -0.4 0 0.4 0 0 -0.8 0.4 0"/>
  </keyframe>
</mujoco>
