<mujoco model="T1">
  <compiler angle="radian" assetdir="assets" balanceinertia="true" inertiafromgeom="false"/>

  <option timestep="0.005" density="1.2" viscosity="2e-05"/>

  <size nkey="1"/>

  <visual>
    <quality shadowsize="8192"/>
    <map shadowclip="0.5"/>
  </visual>

  <default>
    <default class="/">
      <joint armature="0.01" damping="0.01" frictionloss="0.1"/>
      <geom contype="0" conaffinity="0" group="1" solref="-1000 -80"/>
      <site size="0.01 0.005 0.005" group="5"/>
      <general forcelimited="true" biastype="affine" gainprm="25" biasprm="0 -25 -0.6"/>
      <default class="t1">
        <geom rgba="0.25 0.25 0.25 1"/>
        <default class="visual">
          <geom type="mesh" group="2"/>
        </default>
        <default class="collision">
          <geom group="3"/>
        </default>
        <default class="foot">
          <geom size="0.1115 0.05 0.015" type="box" condim="6" group="4" priority="1" solimp="0.015 1 0.015"/>
        </default>
        <default class="reward_collision_sphere">
          <geom group="5" rgba="1 0 0 1"/>
        </default>
      </default>
    </default>
  </default>

  <asset>
    <texture type="skybox" colorspace="auto" name="//unnamed_texture_0" builtin="gradient" rgb1="0.95 0.95 0.95" rgb2="0.95 0.95 0.95" width="100" height="600"/>
    <texture type="2d" colorspace="auto" name="texplane" builtin="checker" rgb1="0.345 0.575 0.748" rgb2="0.345 0.575 0.748" markrgb="1 1 1" width="512" height="512"/>
    <material name="MatPlane" class="/" texture="texplane" texuniform="true" texrepeat="2 2" specular="0.9"/>
    <mesh name="Trunk" class="/" file="Trunk.stl"/>
    <mesh name="H1" class="/" file="H1.stl"/>
    <mesh name="H2" class="/" file="H2.stl"/>
    <mesh name="AL1" class="/" file="AL1.stl"/>
    <mesh name="AL2" class="/" file="AL2.stl"/>
    <mesh name="AL3" class="/" file="AL3.stl"/>
    <mesh name="left_hand_link" class="/" file="left_hand_link.stl"/>
    <mesh name="AR1" class="/" file="AR1.stl"/>
    <mesh name="AR2" class="/" file="AR2.stl"/>
    <mesh name="AR3" class="/" file="AR3.stl"/>
    <mesh name="right_hand_link" class="/" file="right_hand_link.stl"/>
    <mesh name="Waist" class="/" file="Waist.stl"/>
    <mesh name="Hip_Pitch_Left" class="/" file="Hip_Pitch_Left.stl"/>
    <mesh name="Hip_Roll_Left" class="/" file="Hip_Roll_Left.stl"/>
    <mesh name="Hip_Yaw_Left" class="/" file="Hip_Yaw_Left.stl"/>
    <mesh name="Shank_Left" class="/" file="Shank_Left.stl"/>
    <mesh name="Ankle_Cross_Left" class="/" file="Ankle_Cross_Left.stl"/>
    <mesh name="left_foot_link" class="/" file="left_foot_link.stl"/>
    <mesh name="Hip_Pitch_Right" class="/" file="Hip_Pitch_Right.stl"/>
    <mesh name="Hip_Roll_Right" class="/" file="Hip_Roll_Right.stl"/>
    <mesh name="Hip_Yaw_Right" class="/" file="Hip_Yaw_Right.stl"/>
    <mesh name="Shank_Right" class="/" file="Shank_Right.stl"/>
    <mesh name="Ankle_Cross_Right" class="/" file="Ankle_Cross_Right.stl"/>
    <mesh name="right_foot_link" class="/" file="right_foot_link.stl"/>
  </asset>

  <worldbody>
    <geom name="floor" class="/" size="100 100 0.125" type="plane" group="0" material="MatPlane"/>
    <light name="toplight_shadow" class="/" pos="0 0 5" dir="0.0990148 0.0990148 -0.990148" type="directional" ambient="0.04 0.04 0.04" diffuse="0.55 0.55 0.55" specular="0.12 0.12 0.12"/>
    <light name="toplight_fill" class="/" pos="0 0 5" dir="0.0990148 0.0990148 -0.990148" type="directional" castshadow="false" ambient="0.04 0.04 0.04" diffuse="0.3 0.3 0.3" specular="0.08 0.08 0.08"/>
    <body name="trunk" childclass="t1" pos="5.78461e-05 0.00233625 0.000161643" quat="1 0.000297517 8.53133e-05 -0.000303511">
      <inertial pos="0.0410768 -0.000125763 0.1062" quat="0.99995 0.000407142 -0.009818 -0.00205779" mass="10.6295" diaginertia="0.0231031 0.129843 0.0573056"/>
      <joint name="//unnamed_joint_0" type="free" armature="0" damping="0" frictionloss="0"/>
      <geom name="//unnamed_geom_1" class="visual" rgba="0.76 0.76 0.76 1" mesh="Trunk"/>
      <geom name="//unnamed_geom_2" class="collision" size="0.0720257 0.0960342 0.144051" pos="0.0458805 0 0.121562" type="box"/>
      <geom name="//unnamed_geom_3" class="reward_collision_sphere" size="0.110439" pos="0.0458805 0 0.101301"/>
      <geom name="//unnamed_geom_4" class="reward_collision_sphere" size="0.0144051" pos="0.0458805 0.0937837 0"/>
      <geom name="//unnamed_geom_5" class="reward_collision_sphere" size="0.0144051" pos="0.0458805 -0.0937837 0"/>
      <geom name="//unnamed_geom_6" class="reward_collision_sphere" size="0.0144051" pos="0.0458805 0.118057 0.182343"/>
      <geom name="//unnamed_geom_7" class="reward_collision_sphere" size="0.0144051" pos="0.0458805 -0.118057 0.182343"/>
      <site name="imu" pos="9.6672e-05 0.000227815 0.0032114" size="0.00960342"/>
      <camera name="track" pos="0 -2.20668 0" quat="0.707107 0.707107 0 0" mode="trackcom"/>
      <camera name="ego_camera" pos="0.0932904 0 0.425466" quat="-0.5 -0.5 0.5 0.5"/>
      <body name="H1" pos="0.0490482 -9.18693e-05 0.247124" quat="1 0.000152056 0.000133717 4.85728e-05">
        <inertial pos="0.00017799 0.000877924 0.0602468" quat="0.765194 -0.0129805 0.00445127 0.643654" mass="0.411406" diaginertia="6.6349e-05 0.0003749 0.000158265"/>
        <joint name="AAHead_yaw" pos="0 0 0" axis="0.00120886 0.00154797 0.999998" range="-1.54292 1.5261" armature="0.00948175" damping="0" frictionloss="0.109091"/>
        <geom name="//unnamed_geom_8" class="visual" mesh="H1"/>
        <body name="H2" pos="-0.00388722 0.00197137 0.0636773" quat="1 -0.000178654 0.000152827 -3.69695e-05">
          <inertial pos="0.00520744 0.00186169 0.100189" quat="0.988412 0.106313 -0.074847 -0.0783433" mass="0.56119" diaginertia="0.000516531 0.00306598 0.00182426"/>
          <joint name="Head_pitch" pos="0 0 0" axis="0.000683826 -1 0.000612956" range="-1.26 0.347722" armature="0.0099144" damping="0.00492698" frictionloss="0.0934598"/>
          <geom name="//unnamed_geom_9" class="visual" mesh="H2"/>
          <geom name="//unnamed_geom_10" class="collision" size="0.0768274" pos="0.00764675 0 0.111432"/>
          <geom name="//unnamed_geom_11" class="reward_collision_sphere" size="0.0864308" pos="0.0152935 0 0.101301"/>
        </body>
      </body>
      <body name="AL1" pos="0.0442885 0.120387 0.22473" quat="1 -5.38142e-05 0.000574318 -0.000108535">
        <inertial pos="-7.75193e-06 0.0466454 -0.00314996" quat="0.508423 0.495336 -0.507488 0.488472" mass="0.453757" diaginertia="0.000356 0.00201288 0.000303022"/>
        <joint name="Left_Shoulder_Pitch" pos="0 0 0" axis="0.00105042 0.99999 0.00438198" range="-3.32149 1.22674" armature="0.00937242" damping="0.0224225" frictionloss="0.0826139"/>
        <geom name="//unnamed_geom_12" class="visual" rgba="0.76 0.76 0.76 1" mesh="AL1"/>
        <body name="AL2" pos="0.00175099 0.0509066 0.000485263" quat="1 6.96079e-06 1.71585e-05 7.44901e-06">
          <inertial pos="0.000430162 0.0430051 -0.000745976" quat="0.47731 0.509653 -0.493981 0.518085" mass="0.142997" diaginertia="0.000100984 0.00054207 0.000191413"/>
          <joint name="Left_Shoulder_Roll" pos="0 0 0" axis="-0.999998 -0.000388522 0.00184512" range="-1.58621 1.70269" armature="0.0100524" damping="0.0047139" frictionloss="0.0965916"/>
          <geom name="//unnamed_geom_13" class="visual" mesh="AL2"/>
          <body name="AL3" pos="0.000678457 0.0644565 -0.00047176" quat="1 0.00024601 0.000137955 -4.92505e-05">
            <inertial pos="-0.00183449 0.0942602 0.000521709" quat="0.705971 0.708239 -0.00122429 0.000663097" mass="0.906547" diaginertia="0.00346034 0.020887 0.00063589"/>
            <joint name="Left_Elbow_Pitch" pos="0 0 0" axis="-0.000664334 -0.999998 -0.00168251" range="-2.24973 2.25712" armature="0.00858618" damping="0.0193023" frictionloss="0.109412"/>
            <geom name="//unnamed_geom_14" class="visual" mesh="AL3"/>
            <geom name="//unnamed_geom_15" class="collision" size="0.0288103 0.0720257" pos="0 0.0551669 0" quat="0.707105 0.707108 0 0" type="cylinder"/>
            <geom name="//unnamed_geom_16" class="reward_collision_sphere" size="0.0345723"/>
            <body name="left_hand_link" pos="-0.00204462 0.162645 -0.000839195" quat="0.999999 -0.000576253 7.70653e-05 -0.00121545">
              <inertial pos="-1.97854e-05 0.123686 0.00260333" quat="0.704523 0.709681 0.000486627 0.000658319" mass="0.277066" diaginertia="0.00212613 0.0135337 0.000227708"/>
              <joint name="Left_Elbow_Yaw" pos="0 0 0" axis="0.0013119 0.00382208 0.999992" range="-2.39674 -0.0211043" armature="0.010129" damping="0.00817239" frictionloss="0.107511"/>
              <geom name="//unnamed_geom_17" class="visual" mesh="left_hand_link"/>
              <geom name="//unnamed_geom_18" class="collision" size="0.0288103 0.08403" pos="0 0.143434 0" quat="0.707105 0.707108 0 0" type="cylinder"/>
              <geom name="//unnamed_geom_19" class="reward_collision_sphere" size="0.0480171"/>
              <geom name="//unnamed_geom_20" class="reward_collision_sphere" size="0.033612" pos="0 0.121367 0"/>
              <geom name="//unnamed_geom_21" class="reward_collision_sphere" size="0.033612" pos="0 0.237218 0"/>
            </body>
          </body>
        </body>
      </body>
      <body name="AR1" pos="0.0457637 -0.115861 0.223214" quat="1 8.79027e-05 0.000504759 -2.44848e-05">
        <inertial pos="-0.00287532 -0.0526725 0.00184732" quat="0.505426 0.49557 -0.513304 0.485257" mass="0.45918" diaginertia="0.000339786 0.00203518 0.00030481"/>
        <joint name="Right_Shoulder_Pitch" pos="0 0 0" axis="0.0148988 -0.999839 0.0100329" range="-1.22752 3.35595" armature="0.0089644" damping="0" frictionloss="0.0964314"/>
        <geom name="//unnamed_geom_22" class="visual" rgba="0.76 0.76 0.76 1" mesh="AR1"/>
        <body name="AR2" pos="-6.45673e-05 -0.0482248 0.00420072" quat="0.999999 0.00125215 7.54789e-05 6.29153e-05">
          <inertial pos="-4.34052e-05 -0.0415671 0.00243915" quat="0.513046 0.484969 -0.514976 0.486198" mass="0.140265" diaginertia="0.000103676 0.000558643 0.000186601"/>
          <joint name="Right_Shoulder_Roll" pos="0 0 0" axis="-0.999954 0.00452025 0.00843562" range="-1.69244 1.56744" armature="0.00949525" damping="0.0207688" frictionloss="0.0997948"/>
          <geom name="//unnamed_geom_23" class="visual" mesh="AR2"/>
          <body name="AR3" pos="0.00243631 -0.0653693 -0.00288415" quat="0.999999 1.07081e-05 -0.000991295 -0.000534917">
            <inertial pos="0.000452412 -0.0952359 0.00203496" quat="0.710012 0.704126 0.00903334 -0.00299728" mass="0.907" diaginertia="0.00328773 0.020712 0.000665385"/>
            <joint name="Right_Elbow_Pitch" pos="0 0 0" axis="-0.0129882 0.999906 -0.00445643" stiffness="0.00118122" range="-2.28588 2.20997" armature="0.0087643" damping="0.0137094" frictionloss="0.0961111"/>
            <geom name="//unnamed_geom_24" class="visual" mesh="AR3"/>
            <geom name="//unnamed_geom_25" class="collision" size="0.0288103 0.0720257" pos="0 -0.0551669 0" quat="0.707105 0.707108 0 0" type="cylinder"/>
            <geom name="//unnamed_geom_26" class="reward_collision_sphere" size="0.0345723"/>
            <body name="right_hand_link" pos="-7.12986e-05 -0.1614 -0.000540426" quat="1 6.64592e-06 -3.10812e-05 -5.06599e-05">
              <inertial pos="-0.00193654 -0.119078 -0.00155791" quat="0.713064 0.701061 0.00699357 0.0022804" mass="0.280739" diaginertia="0.00212769 0.0123885 0.000229055"/>
              <joint name="Right_Elbow_Yaw" pos="0 0 0" axis="-0.00304322 0.00683742 0.999972" range="0.00169612 2.43396" armature="0.00842465" damping="0" frictionloss="0.0932183"/>
              <geom name="//unnamed_geom_27" class="visual" mesh="right_hand_link"/>
              <geom name="//unnamed_geom_28" class="collision" size="0.0288103 0.08403" pos="0 -0.143434 0" quat="0.707105 0.707108 0 0" type="cylinder"/>
              <geom name="//unnamed_geom_29" class="reward_collision_sphere" size="0.0480171"/>
              <geom name="//unnamed_geom_30" class="reward_collision_sphere" size="0.033612" pos="0 -0.121367 0"/>
              <geom name="//unnamed_geom_31" class="reward_collision_sphere" size="0.033612" pos="0 -0.237218 0"/>
            </body>
          </body>
        </body>
      </body>
      <body name="Waist" pos="0.0472764 -0.00287955 -0.11526" quat="1 0.000276011 0.000361528 -0.000127538">
        <inertial pos="0.0051311 -0.00173483 0.0104149" quat="0.983112 -0.00138444 -0.182997 -0.000783693" mass="2.33541" diaginertia="0.00138645 0.00886099 0.00499417"/>
        <joint name="Waist" pos="0 0 0" axis="0.00084973 -0.0105431 0.999944" range="-1.60658 1.62608" armature="0.00916775" damping="0.00629508" frictionloss="0.0950213"/>
        <geom name="//unnamed_geom_32" class="visual" mesh="Waist"/>
        <body name="Hip_Pitch_Left" pos="0.00135694 0.115941 0.000496344" quat="1 -3.15281e-05 2.84354e-06 -8.60127e-05">
          <inertial pos="-0.00135687 -0.00900686 -0.0176222" quat="0.976029 0.217542 0.00616805 -0.00197419" mass="0.911571" diaginertia="0.000488772 0.0023753 0.00136307"/>
          <joint name="Left_Hip_Pitch" pos="0 0 0" axis="-0.00658352 0.999948 -0.00780634" range="-1.77526 1.55461" armature="0.00956409" damping="0" frictionloss="0.0909719"/>
          <geom name="//unnamed_geom_33" class="visual" rgba="0.76 0.76 0.76 1" mesh="Hip_Pitch_Left"/>
          <body name="Hip_Roll_Left" pos="0.00349618 0.000126356 -0.0208126" quat="1 -0.000232669 -6.22933e-06 -0.000259441">
            <inertial pos="0.00215163 -0.00140282 -0.0552735" quat="0.70349 0.00685607 -0.00815524 0.710626" mass="0.350489" diaginertia="0.000458469 0.00262272 0.000555343"/>
            <joint name="Left_Hip_Roll" pos="0 0 0" axis="-0.999947 -0.00695669 -0.00753576" stiffness="0.0010685" range="-1.52827 0.19897" armature="0.0093795" damping="0.0194917" frictionloss="0.0864021"/>
            <geom name="//unnamed_geom_34" class="visual" mesh="Hip_Roll_Left"/>
            <geom name="//unnamed_geom_35" class="reward_collision_sphere" size="0.0528188"/>
            <body name="Hip_Yaw_Left" pos="-0.000665226 0.000820441 -0.0844415" quat="1 1.54794e-05 3.14675e-05 -5.21996e-05">
              <inertial pos="-0.00322115 -0.00135551 -0.0906744" quat="0.688275 -0.0331015 -0.0373751 0.72373" mass="1.84626" diaginertia="0.00653606 0.0421671 0.00272066"/>
              <joint name="Left_Hip_Yaw" pos="0 0 0" axis="0.00689973 0.000132203 -0.999976" stiffness="0.00370415" range="-0.984646 1.04178" armature="0.00862231" damping="0" frictionloss="0.0928423"/>
              <geom name="//unnamed_geom_36" class="visual" mesh="Hip_Yaw_Left"/>
              <geom name="//unnamed_geom_37" class="collision" size="0.0480171 0.0768274" type="cylinder"/>
              <body name="Shank_Left" pos="-0.0119368 0.000253701 -0.135474" quat="1 9.70073e-05 0.000149824 -0.000239441">
                <inertial pos="-0.00162186 0.00166012 -0.129014" quat="0.99758 0.000686223 -0.0212642 0.0661931" mass="1.60236" diaginertia="0.00954042 0.0588071 0.00202865"/>
                <joint name="Left_Knee_Pitch" pos="0 0 0" axis="0.0171556 0.999823 0.00776381" range="-0.0446446 2.33617" armature="0.0105915" damping="0" frictionloss="0.0945904"/>
                <geom name="//unnamed_geom_38" class="visual" mesh="Shank_Left"/>
                <geom name="//unnamed_geom_39" class="collision" size="0.0480171 0.0720257" pos="0 0 -0.121562" type="cylinder"/>
                <geom name="//unnamed_geom_40" class="reward_collision_sphere" size="0.0624223"/>
                <body name="Ankle_Cross_Left" pos="0.000325229 -0.0029218 -0.283393" quat="1 0.000296571 0.000195681 0.000130253">
                  <inertial pos="-0.00274261 0.000462084 -0.00890636" quat="0.4449 0.54948 0.550895 0.443452" mass="0.0687367" diaginertia="7.59553e-06 4.31794e-05 1.24756e-05"/>
                  <joint name="Left_Ankle_Pitch" pos="0 0 0" axis="-0.006434 0.999957 -0.00664781" range="-0.867084 0.33382" armature="0.00933322" damping="0.00644682" frictionloss="0.100038"/>
                  <geom name="//unnamed_geom_41" class="visual" mesh="Ankle_Cross_Left"/>
                  <body name="left_foot_link" pos="0.00116357 -0.00126423 -0.0114481" quat="0.999999 -4.37846e-05 -0.00103319 0.00026899">
                    <inertial pos="-0.000692801 -0.000144311 -0.01032" quat="0.000192896 0.621163 0.000384667 0.783681" mass="0.569485" diaginertia="0.000665995 0.00379881 0.00218083"/>
                    <joint name="Left_Ankle_Roll" pos="0 0 0" axis="-0.999877 0.00222546 0.0155132" stiffness="0.00819466" range="-0.485477 0.496008" armature="0.00959502" damping="0.00514058" frictionloss="0.0948718"/>
                    <geom name="//unnamed_geom_42" class="visual" mesh="left_foot_link"/>
                    <geom name="left_foot" class="foot" size="0.107501 0.0475481 0.0159175" pos="0.00764675 0 -0.0151952"/>
                    <geom name="//unnamed_geom_44" class="reward_collision_sphere" size="0.0499378" pos="0.00764675 0 -0.0151952"/>
                    <geom name="//unnamed_geom_45" class="reward_collision_sphere" size="0.0288103" pos="0.0726442 -0.0253768 -0.0151952"/>
                    <geom name="//unnamed_geom_46" class="reward_collision_sphere" size="0.0288103" pos="-0.0535273 -0.0253768 -0.0151952"/>
                    <site name="left_foot" class="foot" pos="0.00764675 0 -0.0151952" size="0.00960342"/>
                  </body>
                </body>
              </body>
            </body>
          </body>
        </body>
        <body name="Hip_Pitch_Right" pos="-0.00230948 -0.115005 0.000670911" quat="1 2.93352e-05 -6.32878e-06 -4.49808e-05">
          <inertial pos="0.00141994 0.00906169 -0.0159988" quat="0.971246 -0.236622 0.0250468 -0.00800174" mass="0.929463" diaginertia="0.000486389 0.00244684 0.00141503"/>
          <joint name="Right_Hip_Pitch" pos="0 0 0" axis="-0.00329217 -0.99999 -0.00295355" range="-1.52204 1.78178" armature="0.00987071" damping="0.0215746" frictionloss="0.0938552"/>
          <geom name="//unnamed_geom_47" class="visual" rgba="0.76 0.76 0.76 1" mesh="Hip_Pitch_Right"/>
          <body name="Hip_Roll_Right" pos="-0.000710588 0.000689627 -0.0185694" quat="1 0.000182492 -7.30558e-05 -3.56415e-05">
            <inertial pos="-0.00119442 0.000393312 -0.0514437" quat="0.706376 -0.00492382 -0.00575529 0.707796" mass="0.341755" diaginertia="0.000464729 0.00256761 0.000567281"/>
            <joint name="Right_Hip_Roll" pos="0 0 0" axis="-0.999833 0.00895054 0.0159374" range="-0.154646 1.51304" armature="0.0101216" damping="0" frictionloss="0.102059"/>
            <geom name="//unnamed_geom_48" class="visual" mesh="Hip_Roll_Right"/>
            <geom name="//unnamed_geom_49" class="reward_collision_sphere" size="0.0528188"/>
            <body name="Hip_Yaw_Right" pos="0.00112057 0.00105344 -0.0821336" quat="1 0.000205973 -1.293e-05 -0.00036452">
              <inertial pos="-0.00619119 -0.00122958 -0.0891451" quat="0.714889 -0.030028 -0.0290896 0.697987" mass="1.8818" diaginertia="0.00686564 0.0432573 0.00270619"/>
              <joint name="Right_Hip_Yaw" pos="0 0 0" axis="-0.000557239 0.0180782 -0.999836" range="-0.98534 0.998541" armature="0.00962906" damping="0.0127545" frictionloss="0.0966186"/>
              <geom name="//unnamed_geom_50" class="visual" mesh="Hip_Yaw_Right"/>
              <geom name="//unnamed_geom_51" class="collision" size="0.0480171 0.0768274" type="cylinder"/>
              <body name="Shank_Right" pos="-0.0117591 0.00030816 -0.136519" quat="1 0.000102215 1.29422e-05 -0.000231011">
                <inertial pos="-0.00307625 0.0026172 -0.126639" quat="0.999246 -0.00207694 -0.021695 -0.0321423" mass="1.63706" diaginertia="0.00906054 0.0587712 0.00208786"/>
                <joint name="Right_Knee_Pitch" pos="0 0 0" axis="0.0074244 -0.999944 -0.00756624" stiffness="0.00946702" range="-2.35697 -0.0131261" armature="0.00909437" damping="0.00775519" frictionloss="0.0859351"/>
                <geom name="//unnamed_geom_52" class="visual" mesh="Shank_Right"/>
                <geom name="//unnamed_geom_53" class="collision" size="0.0480171 0.0720257" pos="0 0 -0.121562" type="cylinder"/>
                <geom name="//unnamed_geom_54" class="reward_collision_sphere" size="0.0624223"/>
                <body name="Ankle_Cross_Right" pos="-0.00230861 -0.00317086 -0.284617" quat="0.999999 0.000680108 0.00108886 -0.000232903">
                  <inertial pos="-0.00167293 -0.00242101 -0.00756834" quat="0.454756 0.548624 0.548221 0.437792" mass="0.0607925" diaginertia="7.32943e-06 4.05077e-05 1.18072e-05"/>
                  <joint name="Right_Ankle_Pitch" pos="0 0 0" axis="-0.00473369 -0.999987 0.00168099" range="-0.381243 0.916511" armature="0.00913856" damping="0.0173255" frictionloss="0.0964361"/>
                  <geom name="//unnamed_geom_55" class="visual" mesh="Ankle_Cross_Right"/>
                  <body name="right_foot_link" pos="-0.00187357 -0.00262184 -0.0104834" quat="1 1.83298e-05 0.000454344 0.000271283">
                    <inertial pos="-0.000339717 -0.00272553 -0.0100034" quat="-0.00163004 0.617657 0.000717013 0.786446" mass="0.596471" diaginertia="0.000709687 0.003775 0.00226096"/>
                    <joint name="Right_Ankle_Roll" pos="0 0 0" axis="-1 0.000748045 5.30546e-05" range="-0.484201 0.419383" armature="0.00982917" damping="0" frictionloss="0.0888976"/>
                    <geom name="//unnamed_geom_56" class="visual" mesh="right_foot_link"/>
                    <geom name="right_foot" class="foot" size="0.100581 0.0486296 0.0137803" pos="0.00764675 0 -0.0151952"/>
                    <geom name="//unnamed_geom_58" class="reward_collision_sphere" size="0.0384137"/>
                    <geom name="//unnamed_geom_59" class="reward_collision_sphere" size="0.0288103" pos="0.00764675 0 -0.0151952"/>
                    <geom name="//unnamed_geom_60" class="reward_collision_sphere" size="0.0288103" pos="0.0726442 0.0253768 -0.0151952"/>
                    <geom name="//unnamed_geom_61" class="reward_collision_sphere" size="0.0288103" pos="-0.0535273 0.0253768 -0.0151952"/>
                    <site name="right_foot" class="foot" pos="0.00764675 0 -0.0151952" size="0.00960342"/>
                  </body>
                </body>
              </body>
            </body>
          </body>
        </body>
      </body>
    </body>
  </worldbody>

  <contact>
    <pair class="/" geom1="floor" geom2="left_foot" name="//unnamed_contact_0"/>
    <pair class="/" geom1="floor" geom2="right_foot" name="//unnamed_contact_1"/>
  </contact>

  <actuator>
    <general name="AAHead_yaw" class="/" joint="AAHead_yaw" forcerange="-6.62766 6.62766" gainprm="24.9419" biasprm="0 -24.9419 -0.552147"/>
    <general name="Head_pitch" class="/" joint="Head_pitch" forcerange="-7.42736 7.42736" gainprm="24.9419" biasprm="0 -24.9419 -0.552147"/>
    <general name="Left_Shoulder_Pitch" class="/" joint="Left_Shoulder_Pitch" forcerange="-15.3735 15.3735" gainprm="24.9419" biasprm="0 -24.9419 -0.552147"/>
    <general name="Left_Shoulder_Roll" class="/" joint="Left_Shoulder_Roll" forcerange="-18.5078 18.5078" gainprm="24.9419" biasprm="0 -24.9419 -0.552147"/>
    <general name="Left_Elbow_Pitch" class="/" joint="Left_Elbow_Pitch" forcerange="-16.7761 16.7761" gainprm="24.9419" biasprm="0 -24.9419 -0.552147"/>
    <general name="Left_Elbow_Yaw" class="/" joint="Left_Elbow_Yaw" forcerange="-17.3837 17.3837" gainprm="24.9419" biasprm="0 -24.9419 -0.552147"/>
    <general name="Right_Shoulder_Pitch" class="/" joint="Right_Shoulder_Pitch" forcerange="-18.6205 18.6205" gainprm="24.9419" biasprm="0 -24.9419 -0.552147"/>
    <general name="Right_Shoulder_Roll" class="/" joint="Right_Shoulder_Roll" forcerange="-18.9343 18.9343" gainprm="24.9419" biasprm="0 -24.9419 -0.552147"/>
    <general name="Right_Elbow_Pitch" class="/" joint="Right_Elbow_Pitch" forcerange="-17.5223 17.5223" gainprm="24.9419" biasprm="0 -24.9419 -0.552147"/>
    <general name="Right_Elbow_Yaw" class="/" joint="Right_Elbow_Yaw" forcerange="-16.6086 16.6086" gainprm="24.9419" biasprm="0 -24.9419 -0.552147"/>
    <general name="Waist" class="/" joint="Waist" forcerange="-29.6469 29.6469" gainprm="24.9419" biasprm="0 -24.9419 -0.552147"/>
    <general name="Left_Hip_Pitch" class="/" joint="Left_Hip_Pitch" forcerange="-42.9061 42.9061" gainprm="24.9419" biasprm="0 -24.9419 -0.552147"/>
    <general name="Left_Hip_Roll" class="/" joint="Left_Hip_Roll" forcerange="-28.308 28.308" gainprm="24.9419" biasprm="0 -24.9419 -0.552147"/>
    <general name="Left_Hip_Yaw" class="/" joint="Left_Hip_Yaw" forcerange="-26.2309 26.2309" gainprm="24.9419" biasprm="0 -24.9419 -0.552147"/>
    <general name="Left_Knee_Pitch" class="/" joint="Left_Knee_Pitch" forcerange="-57.2264 57.2264" gainprm="24.9419" biasprm="0 -24.9419 -0.552147"/>
    <general name="Left_Ankle_Pitch" class="/" joint="Left_Ankle_Pitch" forcerange="-17.394 17.394" gainprm="24.9419" biasprm="0 -24.9419 -0.552147"/>
    <general name="Left_Ankle_Roll" class="/" joint="Left_Ankle_Roll" forcerange="-12.9677 12.9677" gainprm="24.9419" biasprm="0 -24.9419 -0.552147"/>
    <general name="Right_Hip_Pitch" class="/" joint="Right_Hip_Pitch" forcerange="-42.1828 42.1828" gainprm="24.9419" biasprm="0 -24.9419 -0.552147"/>
    <general name="Right_Hip_Roll" class="/" joint="Right_Hip_Roll" forcerange="-28.4107 28.4107" gainprm="24.9419" biasprm="0 -24.9419 -0.552147"/>
    <general name="Right_Hip_Yaw" class="/" joint="Right_Hip_Yaw" forcerange="-31.4513 31.4513" gainprm="24.9419" biasprm="0 -24.9419 -0.552147"/>
    <general name="Right_Knee_Pitch" class="/" joint="Right_Knee_Pitch" forcerange="-57.6982 57.6982" gainprm="24.9419" biasprm="0 -24.9419 -0.552147"/>
    <general name="Right_Ankle_Pitch" class="/" joint="Right_Ankle_Pitch" forcerange="-19.5105 19.5105" gainprm="24.9419" biasprm="0 -24.9419 -0.552147"/>
    <general name="Right_Ankle_Roll" class="/" joint="Right_Ankle_Roll" forcerange="-14.7411 14.7411" gainprm="24.9419" biasprm="0 -24.9419 -0.552147"/>
  </actuator>

  <sensor>
    <gyro site="imu" name="imu_angular_velocity"/>
    <velocimeter site="imu" name="imu_linear_velocity"/>
    <framelinvel objtype="site" objname="left_foot" name="left_foot_global_linear_velocity"/>
    <framelinvel objtype="site" objname="right_foot" name="right_foot_global_linear_velocity"/>
  </sensor>

  <keyframe>
    <key name="home" qpos="0 0 0.6385 1 0 0 0 0 0 0 1.4 0 -0.4 0 -1.4 0 0.4 0 -0.4 0 0 0.8 -0.4 0 0.4 0 0 -0.8 0.4 0"/>
  </keyframe>
</mujoco>
