<mujoco model="T1">
  <compiler angle="radian" assetdir="assets" balanceinertia="true" inertiafromgeom="false"/>

  <option timestep="0.005" density="1.2" viscosity="2e-05"/>

  <size nkey="1"/>

  <visual>
    <quality shadowsize="8192"/>
    <map shadowclip="0.5"/>
  </visual>

  <default>
    <default class="/">
      <joint armature="0.01" damping="0.01" frictionloss="0.1"/>
      <geom contype="0" conaffinity="0" group="1" solref="-1000 -80"/>
      <site size="0.01 0.005 0.005" group="5"/>
      <general forcelimited="true" biastype="affine" gainprm="25" biasprm="0 -25 -0.6"/>
      <default class="t1">
        <geom rgba="0.25 0.25 0.25 1"/>
        <default class="visual">
          <geom type="mesh" group="2"/>
        </default>
        <default class="collision">
          <geom group="3"/>
        </default>
        <default class="foot">
          <geom size="0.1115 0.05 0.015" type="box" condim="6" group="4" priority="1" solimp="0.015 1 0.015"/>
        </default>
        <default class="reward_collision_sphere">
          <geom group="5" rgba="1 0 0 1"/>
        </default>
      </default>
    </default>
  </default>

  <asset>
    <texture type="skybox" colorspace="auto" name="//unnamed_texture_0" builtin="gradient" rgb1="0.95 0.95 0.95" rgb2="0.95 0.95 0.95" width="100" height="600"/>
    <texture type="2d" colorspace="auto" name="texplane" builtin="checker" rgb1="0.345 0.575 0.748" rgb2="0.345 0.575 0.748" markrgb="1 1 1" width="512" height="512"/>
    <material name="MatPlane" class="/" texture="texplane" texuniform="true" texrepeat="2 2" specular="0.9"/>
    <mesh name="Trunk" class="/" file="Trunk.stl"/>
    <mesh name="H1" class="/" file="H1.stl"/>
    <mesh name="H2" class="/" file="H2.stl"/>
    <mesh name="AL1" class="/" file="AL1.stl"/>
    <mesh name="AL2" class="/" file="AL2.stl"/>
    <mesh name="AL3" class="/" file="AL3.stl"/>
    <mesh name="left_hand_link" class="/" file="left_hand_link.stl"/>
    <mesh name="AR1" class="/" file="AR1.stl"/>
    <mesh name="AR2" class="/" file="AR2.stl"/>
    <mesh name="AR3" class="/" file="AR3.stl"/>
    <mesh name="right_hand_link" class="/" file="right_hand_link.stl"/>
    <mesh name="Waist" class="/" file="Waist.stl"/>
    <mesh name="Hip_Pitch_Left" class="/" file="Hip_Pitch_Left.stl"/>
    <mesh name="Hip_Roll_Left" class="/" file="Hip_Roll_Left.stl"/>
    <mesh name="Hip_Yaw_Left" class="/" file="Hip_Yaw_Left.stl"/>
    <mesh name="Shank_Left" class="/" file="Shank_Left.stl"/>
    <mesh name="Ankle_Cross_Left" class="/" file="Ankle_Cross_Left.stl"/>
    <mesh name="left_foot_link" class="/" file="left_foot_link.stl"/>
    <mesh name="Hip_Pitch_Right" class="/" file="Hip_Pitch_Right.stl"/>
    <mesh name="Hip_Roll_Right" class="/" file="Hip_Roll_Right.stl"/>
    <mesh name="Hip_Yaw_Right" class="/" file="Hip_Yaw_Right.stl"/>
    <mesh name="Shank_Right" class="/" file="Shank_Right.stl"/>
    <mesh name="Ankle_Cross_Right" class="/" file="Ankle_Cross_Right.stl"/>
    <mesh name="right_foot_link" class="/" file="right_foot_link.stl"/>
  </asset>

  <worldbody>
    <geom name="floor" class="/" size="100 100 0.125" type="plane" group="0" material="MatPlane"/>
    <light name="toplight_shadow" class="/" pos="0 0 5" dir="0.0990148 0.0990148 -0.990148" type="directional" ambient="0.04 0.04 0.04" diffuse="0.55 0.55 0.55" specular="0.12 0.12 0.12"/>
    <light name="toplight_fill" class="/" pos="0 0 5" dir="0.0990148 0.0990148 -0.990148" type="directional" castshadow="false" ambient="0.04 0.04 0.04" diffuse="0.3 0.3 0.3" specular="0.08 0.08 0.08"/>
    <body name="trunk" childclass="t1" pos="0.000111375 -0.000866531 -9.06069e-05" quat="1 0.000111878 2.10084e-06 -0.000182511">
      <inertial pos="0.0422876 -0.000436 0.117243" quat="0.999962 0.000189314 -0.00868584 -0.000268389" mass="9.6195" diaginertia="0.0256942 0.0486396 0.0975455"/>
      <joint name="//unnamed_joint_0" type="free" armature="0" damping="0" frictionloss="0"/>
      <geom name="//unnamed_geom_1" class="visual" rgba="0.76 0.76 0.76 1" mesh="Trunk"/>
      <geom name="//unnamed_geom_2" class="collision" size="0.0701572 0.0935429 0.140314" pos="0.0464811 0 0.134059" type="box"/>
      <geom name="//unnamed_geom_3" class="reward_collision_sphere" size="0.107574" pos="0.0464811 0 0.111715"/>
      <geom name="//unnamed_geom_4" class="reward_collision_sphere" size="0.0140314" pos="0.0464811 0.0777279 0"/>
      <geom name="//unnamed_geom_5" class="reward_collision_sphere" size="0.0140314" pos="0.0464811 -0.0777279 0"/>
      <geom name="//unnamed_geom_6" class="reward_collision_sphere" size="0.0140314" pos="0.0464811 0.0978457 0.201088"/>
      <geom name="//unnamed_geom_7" class="reward_collision_sphere" size="0.0140314" pos="0.0464811 -0.0978457 0.201088"/>
      <site name="imu" pos="-0.000105612 0.000831151 -0.000818526" size="0.00935429"/>
      <camera name="track" pos="0 -1.82889 0" quat="0.707107 0.707107 0 0" mode="trackcom"/>
      <camera name="ego_camera" pos="0.0945116 0 0.469205" quat="-0.5 -0.5 0.5 0.5"/>
      <body name="H1" pos="0.0472523 -0.000257106 0.270651" quat="1 2.19762e-05 -3.60206e-06 -4.42084e-06">
        <inertial pos="-0.00169985 -0.00202246 0.0645681" quat="0.764237 -0.0129044 0.00305333 0.644799" mass="0.361289" diaginertia="6.71341e-05 0.000143031 0.000265058"/>
        <joint name="AAHead_yaw" pos="0 0 0" axis="-0.000331653 -0.00131502 0.999999" range="-1.58296 1.56348" armature="0.00922029" damping="0.0135311" frictionloss="0.0928009"/>
        <geom name="//unnamed_geom_8" class="visual" mesh="H1"/>
        <body name="H2" pos="-0.000513636 0.000227401 0.068384" quat="1 -6.36439e-06 -5.55843e-05 0.000157979">
          <inertial pos="0.00537422 0.000976077 0.110144" quat="0.988461 0.105962 -0.0745576 -0.078478" mass="0.514448" diaginertia="0.000573998 0.00124258 0.00300265"/>
          <joint name="Head_pitch" pos="0 0 0" axis="0.000182014 -1 0.000190847" stiffness="0.00216368" range="-1.20584 0.352532" armature="0.00913964" damping="0.00793474" frictionloss="0.094791"/>
          <geom name="//unnamed_geom_9" class="visual" mesh="H2"/>
          <geom name="//unnamed_geom_10" class="collision" size="0.0748343" pos="0.00774686 0 0.122887"/>
          <geom name="//unnamed_geom_11" class="reward_collision_sphere" size="0.0841886" pos="0.0154937 0 0.111715"/>
        </body>
      </body>
      <body name="AL1" pos="0.0458021 0.0970677 0.244037" quat="1 4.51007e-05 0.000493714 -1.47022e-05">
        <inertial pos="-0.00110101 0.0412724 0.000610256" quat="0.503536 0.499086 -0.502965 0.494359" mass="0.438454" diaginertia="0.000387154 0.000842547 0.000516027"/>
        <joint name="Left_Shoulder_Pitch" pos="0 0 0" axis="0.00226113 0.999997 0.000107068" range="-3.31099 1.22206" armature="0.00917272" damping="0.00366118" frictionloss="0.094751"/>
        <geom name="//unnamed_geom_12" class="visual" rgba="0.76 0.76 0.76 1" mesh="AL1"/>
        <body name="AL2" pos="0.000851515 0.044272 0.000238408" quat="1 -0.00011744 6.63796e-07 -2.16299e-05">
          <inertial pos="0.00278353 0.0344897 3.54951e-05" quat="0.488329 0.510237 -0.488191 0.512702" mass="0.130156" diaginertia="0.000111592 0.000223791 0.000309769"/>
          <joint name="Left_Shoulder_Roll" pos="0 0 0" axis="-0.999999 0.00130452 0.000613983" range="-1.56773 1.73052" armature="0.00948646" damping="0.00449821" frictionloss="0.0932289"/>
          <geom name="//unnamed_geom_13" class="visual" mesh="AL2"/>
          <body name="AL3" pos="0.000540023 0.0563769 -8.98486e-05" quat="1 -0.000122199 -6.27145e-06 8.41451e-05">
            <inertial pos="-0.000861426 0.0780615 -0.000612071" quat="0.706575 0.707638 0.000519039 -0.000212755" mass="0.836407" diaginertia="0.00356493 0.00819989 0.00108834"/>
            <joint name="Left_Elbow_Pitch" pos="0 0 0" axis="0.0013131 -0.999999 0.000421792" stiffness="0.000216934" range="-2.26544 2.26779" armature="0.00914909" damping="0.00701431" frictionloss="0.0920863"/>
            <geom name="//unnamed_geom_14" class="visual" mesh="AL3"/>
            <geom name="//unnamed_geom_15" class="collision" size="0.0280629 0.0701572" pos="0 0.0457223 0" quat="0.707105 0.707108 0 0" type="cylinder"/>
            <geom name="//unnamed_geom_16" class="reward_collision_sphere" size="0.0336754"/>
            <body name="left_hand_link" pos="0.00131497 0.134527 0.00140889" quat="1 -2.38962e-06 5.2693e-05 -5.01679e-05">
              <inertial pos="9.17381e-05 0.0998226 -0.000418402" quat="0.707606 0.706607 -0.000304668 -7.19303e-05" mass="0.270283" diaginertia="0.00227997 0.0051673 0.000376027"/>
              <joint name="Left_Elbow_Yaw" pos="0 0 0" axis="0.000118133 -0.00226112 0.999997" range="-2.43996 0.00146812" armature="0.00948865" damping="0.0100518" frictionloss="0.0894834"/>
              <geom name="//unnamed_geom_17" class="visual" mesh="left_hand_link"/>
              <geom name="//unnamed_geom_18" class="collision" size="0.0280629 0.08185" pos="0 0.118878 0" quat="0.707105 0.707108 0 0" type="cylinder"/>
              <geom name="//unnamed_geom_19" class="reward_collision_sphere" size="0.0467714"/>
              <geom name="//unnamed_geom_20" class="reward_collision_sphere" size="0.03274" pos="0 0.100589 0"/>
              <geom name="//unnamed_geom_21" class="reward_collision_sphere" size="0.03274" pos="0 0.196606 0"/>
            </body>
          </body>
        </body>
      </body>
      <body name="AR1" pos="0.0433568 -0.0961864 0.24402" quat="1 -1.29293e-05 0.000485759 -5.295e-06">
        <inertial pos="-0.000677627 -0.040778 0.00039699" quat="0.502852 0.496333 -0.506192 0.494532" mass="0.43439" diaginertia="0.000384321 0.000827199 0.000508072"/>
        <joint name="Right_Shoulder_Pitch" pos="0 0 0" axis="0.00260579 -0.999997 -0.000432498" range="-1.22631 3.29222" armature="0.00910558" damping="0.0092172" frictionloss="0.0930218"/>
        <geom name="//unnamed_geom_22" class="visual" rgba="0.76 0.76 0.76 1" mesh="AR1"/>
        <body name="AR2" pos="-0.000757128 -0.0426564 -0.000462668" quat="1 6.49797e-06 -0.000232508 -0.000199558">
          <inertial pos="0.00321816 -0.0345574 -0.000437633" quat="0.511794 0.487807 -0.51173 0.488101" mass="0.131702" diaginertia="0.000112593 0.000220424 0.000308978"/>
          <joint name="Right_Shoulder_Roll" pos="0 0 0" axis="-0.999965 -0.00571412 0.00606218" stiffness="0.00108546" range="-1.73193 1.57151" armature="0.00938155" damping="0.003599" frictionloss="0.0918365"/>
          <geom name="//unnamed_geom_23" class="visual" mesh="AR2"/>
          <body name="AR3" pos="0.000147633 -0.0560866 -9.22013e-05" quat="1 -0.000108559 0.000121185 -4.86922e-05">
            <inertial pos="-0.000704458 -0.0780474 0.000538547" quat="0.709834 0.704363 0.00204314 0.00220928" mass="0.839061" diaginertia="0.00363677 0.00827355 0.00108283"/>
            <joint name="Right_Elbow_Pitch" pos="0 0 0" axis="0.000408625 0.999993 0.00384838" range="-2.27452 2.28352" armature="0.00969849" damping="0.00675608" frictionloss="0.0942612"/>
            <geom name="//unnamed_geom_24" class="visual" mesh="AR3"/>
            <geom name="//unnamed_geom_25" class="collision" size="0.0280629 0.0701572" pos="0 -0.0457223 0" quat="0.707105 0.707108 0 0" type="cylinder"/>
            <geom name="//unnamed_geom_26" class="reward_collision_sphere" size="0.0336754"/>
            <body name="right_hand_link" pos="-0.000337398 -0.134518 -0.000287318" quat="1 9.01369e-06 -4.30739e-06 1.45976e-05">
              <inertial pos="0.000478575 -0.100902 0.000576138" quat="0.705525 0.708685 0.00042175 0.000902035" mass="0.269325" diaginertia="0.00229049 0.00524776 0.000374043"/>
              <joint name="Right_Elbow_Yaw" pos="0 0 0" axis="-0.000414621 -0.000427613 1" stiffness="0.00177489" range="0.00460046 2.43859" armature="0.00923399" damping="0.00768963" frictionloss="0.0921078"/>
              <geom name="//unnamed_geom_27" class="visual" mesh="right_hand_link"/>
              <geom name="//unnamed_geom_28" class="collision" size="0.0280629 0.08185" pos="0 -0.118878 0" quat="0.707105 0.707108 0 0" type="cylinder"/>
              <geom name="//unnamed_geom_29" class="reward_collision_sphere" size="0.0467714"/>
              <geom name="//unnamed_geom_30" class="reward_collision_sphere" size="0.03274" pos="0 -0.100589 0"/>
              <geom name="//unnamed_geom_31" class="reward_collision_sphere" size="0.03274" pos="0 -0.196606 0"/>
            </body>
          </body>
        </body>
      </body>
      <body name="Waist" pos="0.0483752 -0.000871627 -0.129677" quat="1 4.07537e-07 -8.98769e-05 6.18111e-05">
        <inertial pos="0.000571626 -0.000566693 0.00787258" quat="0.983722 2.84533e-05 -0.17968 0.00265745" mass="2.12394" diaginertia="0.00152233 0.0034034 0.00838662"/>
        <joint name="Waist" pos="0 0 0" axis="-0.00164526 0.000100377 0.999999" stiffness="0.000341493" range="-1.55392 1.55755" armature="0.00947021" damping="0.00100188" frictionloss="0.0941534"/>
        <geom name="//unnamed_geom_32" class="visual" mesh="Waist"/>
        <body name="Hip_Pitch_Left" pos="0.000856651 0.097119 -0.000727958" quat="1 -8.02247e-05 0.000207633 0.000283947">
          <inertial pos="0.00137702 -0.00684023 -0.0208187" quat="0.97559 0.219065 0.0152994 0.00107401" mass="0.835522" diaginertia="0.00049889 0.00093094 0.00219321"/>
          <joint name="Left_Hip_Pitch" pos="0 0 0" axis="0.00525853 0.999986 -9.52384e-05" range="-1.81272 1.57313" armature="0.00932802" damping="0.0124173" frictionloss="0.0958832"/>
          <geom name="//unnamed_geom_33" class="visual" rgba="0.76 0.76 0.76 1" mesh="Hip_Pitch_Left"/>
          <body name="Hip_Roll_Left" pos="-0.000779806 0.000461024 -0.0232885" quat="1 -1.82388e-05 -7.8207e-05 -5.67029e-05">
            <inertial pos="0.00124089 -0.000492843 -0.0598185" quat="0.706185 -0.00438031 -0.00674236 0.707982" mass="0.312927" diaginertia="0.000478729 0.000950614 0.000887307"/>
            <joint name="Left_Hip_Roll" pos="0 0 0" axis="-1 -0.000530031 0.000538031" range="-1.5859 0.200575" armature="0.00937738" damping="0.00524319" frictionloss="0.0974321"/>
            <geom name="//unnamed_geom_34" class="visual" mesh="Hip_Roll_Left"/>
            <geom name="//unnamed_geom_35" class="reward_collision_sphere" size="0.0514486"/>
            <body name="Hip_Yaw_Left" pos="0.00110047 0.000361984 -0.0919053" quat="1 -6.09825e-06 1.29197e-05 -4.18972e-05">
              <inertial pos="-0.00473274 -0.000320143 -0.0996992" quat="0.696675 -0.0340309 -0.0312978 0.715896" mass="1.79633" diaginertia="0.00725803 0.0162648 0.00452425"/>
              <joint name="Left_Hip_Yaw" pos="0 0 0" axis="-0.00351746 0.00365902 -0.999987" range="-1.01168 0.990413" armature="0.00969659" damping="0.0121952" frictionloss="0.0949646"/>
              <geom name="//unnamed_geom_36" class="visual" mesh="Hip_Yaw_Left"/>
              <geom name="//unnamed_geom_37" class="collision" size="0.0467714 0.0748343" type="cylinder"/>
              <body name="Shank_Left" pos="-0.00992318 1.49016e-05 -0.150873" quat="1 -1.00025e-05 0.000111457 -0.000109903">
                <inertial pos="-0.00541685 -7.89653e-05 -0.138873" quat="0.997527 0.00078781 -0.0232303 0.0663287" mass="1.40176" diaginertia="0.00953387 0.0220001 0.00320085"/>
                <joint name="Left_Knee_Pitch" pos="0 0 0" axis="0.000774125 0.999998 0.00193041" range="-0.0105634 2.34012" armature="0.00898114" damping="0.00661398" frictionloss="0.0942623"/>
                <geom name="//unnamed_geom_38" class="visual" mesh="Shank_Left"/>
                <geom name="//unnamed_geom_39" class="collision" size="0.0467714 0.0701572" pos="0 0 -0.134059" type="cylinder"/>
                <geom name="//unnamed_geom_40" class="reward_collision_sphere" size="0.0608029"/>
                <body name="Ankle_Cross_Left" pos="-0.000392434 -5.94878e-05 -0.312729" quat="1 0.000104101 5.47884e-05 8.8359e-05">
                  <inertial pos="-0.0028559 0.000335907 -0.00919988" quat="0.442205 0.551067 0.551795 0.44306" mass="0.0600639" diaginertia="8.07678e-06 1.64713e-05 1.97564e-05"/>
                  <joint name="Left_Ankle_Pitch" pos="0 0 0" axis="0.00122803 0.999991 -0.00399115" range="-0.869797 0.356072" armature="0.00937113" damping="0.00759949" frictionloss="0.0925533"/>
                  <geom name="//unnamed_geom_41" class="visual" mesh="Ankle_Cross_Left"/>
                  <body name="left_foot_link" pos="-0.00126401 -0.000161243 -0.01347" quat="1 -8.78002e-05 -0.000313619 -0.000310326">
                    <inertial pos="-9.84863e-05 0.000217615 -0.0095955" quat="-0.000187263 0.62091 0.000154815 0.783882" mass="0.566456" diaginertia="0.000759932 0.00152995 0.00383869"/>
                    <joint name="Left_Ankle_Roll" pos="0 0 0" axis="-0.999997 -0.002282 0.00121705" range="-0.424373 0.431274" armature="0.0093985" damping="0.0106217" frictionloss="0.0933881"/>
                    <geom name="//unnamed_geom_42" class="visual" mesh="left_foot_link"/>
                    <geom name="left_foot" class="foot" size="0.103814 0.0497515 0.0139791" pos="0.00774686 0 -0.0167573"/>
                    <geom name="//unnamed_geom_44" class="reward_collision_sphere" size="0.0486423" pos="0.00774686 0 -0.0167573"/>
                    <geom name="//unnamed_geom_45" class="reward_collision_sphere" size="0.0280629" pos="0.0735951 -0.0210322 -0.0167573"/>
                    <geom name="//unnamed_geom_46" class="reward_collision_sphere" size="0.0280629" pos="-0.054228 -0.0210322 -0.0167573"/>
                    <site name="left_foot" class="foot" pos="0.00774686 0 -0.0167573" size="0.00935429"/>
                  </body>
                </body>
              </body>
            </body>
          </body>
        </body>
        <body name="Hip_Pitch_Right" pos="0.000129002 -0.0964084 -0.000310202" quat="1 -0.000167846 -0.000179053 -0.000170271">
          <inertial pos="0.000636121 0.00653979 -0.0195617" quat="0.973748 -0.227109 0.0149757 -0.00340909" mass="0.840232" diaginertia="0.000506282 0.00094016 0.00216663"/>
          <joint name="Right_Hip_Pitch" pos="0 0 0" axis="-0.00189112 -0.999998 0.00100311" range="-1.58902 1.80616" armature="0.0092761" damping="0.00344107" frictionloss="0.0946565"/>
          <geom name="//unnamed_geom_47" class="visual" rgba="0.76 0.76 0.76 1" mesh="Hip_Pitch_Right"/>
          <body name="Hip_Roll_Right" pos="-0.000288128 0.000418334 -0.0228294" quat="1 -5.77028e-05 1.18384e-05 -4.88606e-05">
            <inertial pos="0.000854758 -0.000117587 -0.0605797" quat="0.70715 -0.00633365 -0.00599273 0.70701" mass="0.314968" diaginertia="0.000481794 0.000969041 0.000896852"/>
            <joint name="Right_Hip_Roll" pos="0 0 0" axis="-1 -7.07023e-05 -0.000920841" range="-0.219161 1.5734" armature="0.0092565" damping="0.00941569" frictionloss="0.0908019"/>
            <geom name="//unnamed_geom_48" class="visual" mesh="Hip_Roll_Right"/>
            <geom name="//unnamed_geom_49" class="reward_collision_sphere" size="0.0514486"/>
            <body name="Hip_Yaw_Right" pos="-0.000226805 -0.000356164 -0.0920884" quat="1 4.95257e-05 3.27625e-05 -7.59633e-05">
              <inertial pos="-0.00473887 0.000131618 -0.0993745" quat="0.714402 -0.0313132 -0.0338423 0.698215" mass="1.76532" diaginertia="0.00712195 0.0161313 0.00449441"/>
              <joint name="Right_Hip_Yaw" pos="0 0 0" axis="-0.00127227 -0.00085312 -0.999999" range="-0.997961 1.00215" armature="0.00938865" damping="0.00524623" frictionloss="0.09377"/>
              <geom name="//unnamed_geom_50" class="visual" mesh="Hip_Yaw_Right"/>
              <geom name="//unnamed_geom_51" class="collision" size="0.0467714 0.0748343" type="cylinder"/>
              <body name="Shank_Right" pos="-0.011015 1.91664e-05 -0.14967" quat="1 -5.22591e-06 8.39219e-07 3.3412e-06">
                <inertial pos="-0.00568169 -3.92347e-05 -0.136153" quat="0.999269 -0.00165867 -0.0240174 -0.0296834" mass="1.44513" diaginertia="0.00972712 0.0220684 0.00339963"/>
                <joint name="Right_Knee_Pitch" pos="0 0 0" axis="-0.00536472 -0.99998 -0.00321294" stiffness="0.00112251" range="-2.34315 0.000404343" armature="0.00946124" damping="0.00709953" frictionloss="0.0975426"/>
                <geom name="//unnamed_geom_52" class="visual" mesh="Shank_Right"/>
                <geom name="//unnamed_geom_53" class="collision" size="0.0467714 0.0701572" pos="0 0 -0.134059" type="cylinder"/>
                <geom name="//unnamed_geom_54" class="reward_collision_sphere" size="0.0608029"/>
                <body name="Ankle_Cross_Right" pos="0.00118426 0.000266083 -0.31242" quat="1 -1.539e-05 3.19847e-05 -6.70623e-06">
                  <inertial pos="-0.00247606 0.000934519 -0.00859105" quat="0.445509 0.551011 0.548272 0.444192" mass="0.0600685" diaginertia="8.05988e-06 1.63103e-05 1.96525e-05"/>
                  <joint name="Right_Ankle_Pitch" pos="0 0 0" axis="-2.03848e-05 -0.999999 -0.00131836" range="-0.335938 0.850997" armature="0.00913268" damping="0.00791259" frictionloss="0.0928731"/>
                  <geom name="//unnamed_geom_55" class="visual" mesh="Ankle_Cross_Right"/>
                  <body name="right_foot_link" pos="-0.00010827 -0.0013272 -0.0138419" quat="1 1.00393e-05 1.83356e-05 2.7071e-05">
                    <inertial pos="-0.000207919 0.000128196 -0.00978767" quat="0.00107068 0.620991 0.000646375 0.783817" mass="0.558363" diaginertia="0.000751359 0.00154219 0.00379051"/>
                    <joint name="Right_Ankle_Roll" pos="0 0 0" axis="-1 0.000702747 6.02492e-05" range="-0.447803 0.437341" armature="0.00949129" damping="0.0101041" frictionloss="0.0968322"/>
                    <geom name="//unnamed_geom_56" class="visual" mesh="right_foot_link"/>
                    <geom name="right_foot" class="foot" size="0.101829 0.0444188 0.0145601" pos="0.00774686 0 -0.0167573"/>
                    <geom name="//unnamed_geom_58" class="reward_collision_sphere" size="0.0374171"/>
                    <geom name="//unnamed_geom_59" class="reward_collision_sphere" size="0.0280629" pos="0.00774686 0 -0.0167573"/>
                    <geom name="//unnamed_geom_60" class="reward_collision_sphere" size="0.0280629" pos="0.0735951 0.0210322 -0.0167573"/>
                    <geom name="//unnamed_geom_61" class="reward_collision_sphere" size="0.0280629" pos="-0.054228 0.0210322 -0.0167573"/>
                    <site name="right_foot" class="foot" pos="0.00774686 0 -0.0167573" size="0.00935429"/>
                  </body>
                </body>
              </body>
            </body>
          </body>
        </body>
      </body>
    </body>
  </worldbody>

  <contact>
    <pair class="/" geom1="floor" geom2="left_foot" name="//unnamed_contact_0"/>
    <pair class="/" geom1="floor" geom2="right_foot" name="//unnamed_contact_1"/>
  </contact>

  <actuator>
    <general name="AAHead_yaw" class="/" joint="AAHead_yaw" forcerange="-6.53686 6.53686" gainprm="22.8371" biasprm="0 -22.8371 -0.553364"/>
    <general name="Head_pitch" class="/" joint="Head_pitch" forcerange="-6.4298 6.4298" gainprm="22.8371" biasprm="0 -22.8371 -0.553364"/>
    <general name="Left_Shoulder_Pitch" class="/" joint="Left_Shoulder_Pitch" forcerange="-16.9922 16.9922" gainprm="22.8371" biasprm="0 -22.8371 -0.553364"/>
    <general name="Left_Shoulder_Roll" class="/" joint="Left_Shoulder_Roll" forcerange="-17.0248 17.0248" gainprm="22.8371" biasprm="0 -22.8371 -0.553364"/>
    <general name="Left_Elbow_Pitch" class="/" joint="Left_Elbow_Pitch" forcerange="-17.1652 17.1652" gainprm="22.8371" biasprm="0 -22.8371 -0.553364"/>
    <general name="Left_Elbow_Yaw" class="/" joint="Left_Elbow_Yaw" forcerange="-16.9184 16.9184" gainprm="22.8371" biasprm="0 -22.8371 -0.553364"/>
    <general name="Right_Shoulder_Pitch" class="/" joint="Right_Shoulder_Pitch" forcerange="-17.2813 17.2813" gainprm="22.8371" biasprm="0 -22.8371 -0.553364"/>
    <general name="Right_Shoulder_Roll" class="/" joint="Right_Shoulder_Roll" forcerange="-16.3228 16.3228" gainprm="22.8371" biasprm="0 -22.8371 -0.553364"/>
    <general name="Right_Elbow_Pitch" class="/" joint="Right_Elbow_Pitch" forcerange="-16.8986 16.8986" gainprm="22.8371" biasprm="0 -22.8371 -0.553364"/>
    <general name="Right_Elbow_Yaw" class="/" joint="Right_Elbow_Yaw" forcerange="-16.593 16.593" gainprm="22.8371" biasprm="0 -22.8371 -0.553364"/>
    <general name="Waist" class="/" joint="Waist" forcerange="-28.1541 28.1541" gainprm="22.8371" biasprm="0 -22.8371 -0.553364"/>
    <general name="Left_Hip_Pitch" class="/" joint="Left_Hip_Pitch" forcerange="-42.0403 42.0403" gainprm="22.8371" biasprm="0 -22.8371 -0.553364"/>
    <general name="Left_Hip_Roll" class="/" joint="Left_Hip_Roll" forcerange="-28.3132 28.3132" gainprm="22.8371" biasprm="0 -22.8371 -0.553364"/>
    <general name="Left_Hip_Yaw" class="/" joint="Left_Hip_Yaw" forcerange="-28.9752 28.9752" gainprm="22.8371" biasprm="0 -22.8371 -0.553364"/>
    <general name="Left_Knee_Pitch" class="/" joint="Left_Knee_Pitch" forcerange="-55.8806 55.8806" gainprm="22.8371" biasprm="0 -22.8371 -0.553364"/>
    <general name="Left_Ankle_Pitch" class="/" joint="Left_Ankle_Pitch" forcerange="-19.2933 19.2933" gainprm="22.8371" biasprm="0 -22.8371 -0.553364"/>
    <general name="Left_Ankle_Roll" class="/" joint="Left_Ankle_Roll" forcerange="-14.4315 14.4315" gainprm="22.8371" biasprm="0 -22.8371 -0.553364"/>
    <general name="Right_Hip_Pitch" class="/" joint="Right_Hip_Pitch" forcerange="-42.6426 42.6426" gainprm="22.8371" biasprm="0 -22.8371 -0.553364"/>
    <general name="Right_Hip_Roll" class="/" joint="Right_Hip_Roll" forcerange="-28.046 28.046" gainprm="22.8371" biasprm="0 -22.8371 -0.553364"/>
    <general name="Right_Hip_Yaw" class="/" joint="Right_Hip_Yaw" forcerange="-27.1904 27.1904" gainprm="22.8371" biasprm="0 -22.8371 -0.553364"/>
    <general name="Right_Knee_Pitch" class="/" joint="Right_Knee_Pitch" forcerange="-55.873 55.873" gainprm="22.8371" biasprm="0 -22.8371 -0.553364"/>
    <general name="Right_Ankle_Pitch" class="/" joint="Right_Ankle_Pitch" forcerange="-18.5913 18.5913" gainprm="22.8371" biasprm="0 -22.8371 -0.553364"/>
    <general name="Right_Ankle_Roll" class="/" joint="Right_Ankle_Roll" forcerange="-14.2017 14.2017" gainprm="22.8371" biasprm="0 -22.8371 -0.553364"/>
  </actuator>

  <sensor>
    <gyro site="imu" name="imu_angular_velocity"/>
    <velocimeter site="imu" name="imu_linear_velocity"/>
    <framelinvel objtype="site" objname="left_foot" name="left_foot_global_linear_velocity"/>
    <framelinvel objtype="site" objname="right_foot" name="right_foot_global_linear_velocity"/>
  </sensor>

  <keyframe>
    <key name="home" qpos="0 0 0.6385 1 0 0 0 0 0 0 1.4 0 -0.4 0 -1.4 0 0.4 0 -0.4 0 0 0.8 -0.4 0 0.4 0 0 -0.8 0.4 0"/>
  </keyframe>
</mujoco>
