<mujoco model="T1">
  <compiler angle="radian" assetdir="assets" balanceinertia="true" inertiafromgeom="false"/>

  <option timestep="0.005" density="1.2" viscosity="2e-05"/>

  <size nkey="1"/>

  <visual>
    <quality shadowsize="8192"/>
    <map shadowclip="0.5"/>
  </visual>

  <default>
    <default class="/">
      <joint armature="0.01" damping="0.01" frictionloss="0.1"/>
      <geom contype="0" conaffinity="0" group="1" solref="-1000 -80"/>
      <site size="0.01 0.005 0.005" group="5"/>
      <general forcelimited="true" biastype="affine" gainprm="25" biasprm="0 -25 -0.6"/>
      <default class="t1">
        <geom rgba="0.25 0.25 0.25 1"/>
        <default class="visual">
          <geom type="mesh" group="2"/>
        </default>
        <default class="collision">
          <geom group="3"/>
        </default>
        <default class="foot">
          <geom size="0.1115 0.05 0.015" type="box" condim="6" group="4" priority="1" solimp="0.015 1 0.015"/>
        </default>
        <default class="reward_collision_sphere">
          <geom group="5" rgba="1 0 0 1"/>
        </default>
      </default>
    </default>
  </default>

  <asset>
    <texture type="skybox" colorspace="auto" name="//unnamed_texture_0" builtin="gradient" rgb1="0.95 0.95 0.95" rgb2="0.95 0.95 0.95" width="100" height="600"/>
    <texture type="2d" colorspace="auto" name="texplane" builtin="checker" rgb1="0.345 0.575 0.748" rgb2="0.345 0.575 0.748" markrgb="1 1 1" width="512" height="512"/>
    <material name="MatPlane" class="/" texture="texplane" texuniform="true" texrepeat="2 2" specular="0.9"/>
    <mesh name="Trunk" class="/" file="Trunk.stl"/>
    <mesh name="H1" class="/" file="H1.stl"/>
    <mesh name="H2" class="/" file="H2.stl"/>
    <mesh name="AL1" class="/" file="AL1.stl"/>
    <mesh name="AL2" class="/" file="AL2.stl"/>
    <mesh name="AL3" class="/" file="AL3.stl"/>
    <mesh name="left_hand_link" class="/" file="left_hand_link.stl"/>
    <mesh name="AR1" class="/" file="AR1.stl"/>
    <mesh name="AR2" class="/" file="AR2.stl"/>
    <mesh name="AR3" class="/" file="AR3.stl"/>
    <mesh name="right_hand_link" class="/" file="right_hand_link.stl"/>
    <mesh name="Waist" class="/" file="Waist.stl"/>
    <mesh name="Hip_Pitch_Left" class="/" file="Hip_Pitch_Left.stl"/>
    <mesh name="Hip_Roll_Left" class="/" file="Hip_Roll_Left.stl"/>
    <mesh name="Hip_Yaw_Left" class="/" file="Hip_Yaw_Left.stl"/>
    <mesh name="Shank_Left" class="/" file="Shank_Left.stl"/>
    <mesh name="Ankle_Cross_Left" class="/" file="Ankle_Cross_Left.stl"/>
    <mesh name="left_foot_link" class="/" file="left_foot_link.stl"/>
    <mesh name="Hip_Pitch_Right" class="/" file="Hip_Pitch_Right.stl"/>
    <mesh name="Hip_Roll_Right" class="/" file="Hip_Roll_Right.stl"/>
    <mesh name="Hip_Yaw_Right" class="/" file="Hip_Yaw_Right.stl"/>
    <mesh name="Shank_Right" class="/" file="Shank_Right.stl"/>
    <mesh name="Ankle_Cross_Right" class="/" file="Ankle_Cross_Right.stl"/>
    <mesh name="right_foot_link" class="/" file="right_foot_link.stl"/>
  </asset>

  <worldbody>
    <geom name="floor" class="/" size="100 100 0.125" type="plane" group="0" material="MatPlane"/>
    <light name="toplight_shadow" class="/" pos="0 0 5" dir="0.0990148 0.0990148 -0.990148" type="directional" ambient="0.04 0.04 0.04" diffuse="0.55 0.55 0.55" specular="0.12 0.12 0.12"/>
    <light name="toplight_fill" class="/" pos="0 0 5" dir="0.0990148 0.0990148 -0.990148" type="directional" castshadow="false" ambient="0.04 0.04 0.04" diffuse="0.3 0.3 0.3" specular="0.08 0.08 0.08"/>
    <body name="trunk" childclass="t1" pos="0.000184346 0.00192006 -0.00271021" quat="0.999999 -0.000217783 -0.00127666 -3.34507e-05">
      <inertial pos="0.0402848 -0.000435034 0.115114" quat="0.999959 -0.000139407 -0.00903653 -0.000696233" mass="9.45478" diaginertia="0.0193543 0.0735826 0.0847438"/>
      <joint name="//unnamed_joint_0" type="free" armature="0" damping="0" frictionloss="0"/>
      <geom name="//unnamed_geom_1" class="visual" rgba="0.76 0.76 0.76 1" mesh="Trunk"/>
      <geom name="//unnamed_geom_2" class="collision" size="0.0708161 0.0944214 0.141632" pos="0.0443526 0 0.131801" type="box"/>
      <geom name="//unnamed_geom_3" class="reward_collision_sphere" size="0.108585" pos="0.0443526 0 0.109834"/>
      <geom name="//unnamed_geom_4" class="reward_collision_sphere" size="0.0141632" pos="0.0443526 0.0845825 0"/>
      <geom name="//unnamed_geom_5" class="reward_collision_sphere" size="0.0141632" pos="0.0443526 -0.0845825 0"/>
      <geom name="//unnamed_geom_6" class="reward_collision_sphere" size="0.0141632" pos="0.0443526 0.106474 0.197702"/>
      <geom name="//unnamed_geom_7" class="reward_collision_sphere" size="0.0141632" pos="0.0443526 -0.106474 0.197702"/>
      <site name="imu" pos="-0.0136189 0.00266017 -0.00148757" size="0.00944214"/>
      <camera name="track" pos="0 -1.99018 0" quat="0.707107 0.707107 0 0" mode="trackcom"/>
      <camera name="ego_camera" pos="0.0901837 0 0.461304" quat="-0.5 -0.5 0.5 0.5"/>
      <body name="H1" pos="0.0470731 -0.000134871 0.268376" quat="0.999999 0.000683928 -0.000949335 0.000818242">
        <inertial pos="0.00112196 -0.00082244 0.0622052" quat="0.763967 -0.0128876 0.00169088 0.645124" mass="0.377342" diaginertia="5.34241e-05 0.000222442 0.00023011"/>
        <joint name="AAHead_yaw" pos="0 0 0" axis="-1.08927e-06 0.00055327 1" range="-1.62061 1.58445" armature="0.00927666" damping="0.00242596" frictionloss="0.0950526"/>
        <geom name="//unnamed_geom_8" class="visual" mesh="H1"/>
        <body name="H2" pos="-7.13943e-05 -0.000910794 0.0696761" quat="0.999999 0.000309282 -0.000636725 0.0011625">
          <inertial pos="0.00494064 1.51686e-05 0.108314" quat="0.988453 0.10606 -0.0747051 -0.0783081" mass="0.514003" diaginertia="0.000436961 0.00182193 0.00275146"/>
          <joint name="Head_pitch" pos="0 0 0" axis="0.0139695 -0.999901 -0.00167566" range="-1.26986 0.404083" armature="0.0107428" damping="0.0193235" frictionloss="0.106963"/>
          <geom name="//unnamed_geom_9" class="visual" mesh="H2"/>
          <geom name="//unnamed_geom_10" class="collision" size="0.0755371" pos="0.0073921 0 0.120818"/>
          <geom name="//unnamed_geom_11" class="reward_collision_sphere" size="0.0849793" pos="0.0147842 0 0.109834"/>
        </body>
      </body>
      <body name="AL1" pos="0.0459751 0.108171 0.242573" quat="1 -0.000320333 0.00051333 0.000241395">
        <inertial pos="-0.00321826 0.0440115 -0.00108444" quat="0.50864 0.50255 -0.500815 0.487764" mass="0.436882" diaginertia="0.000292892 0.0012736 0.000460722"/>
        <joint name="Left_Shoulder_Pitch" pos="0 0 0" axis="-0.000995319 1 7.21844e-05" stiffness="0.00190699" range="-3.2938 1.22088" armature="0.0095891" damping="0.0157251" frictionloss="0.0928434"/>
        <geom name="//unnamed_geom_12" class="visual" rgba="0.76 0.76 0.76 1" mesh="AL1"/>
        <body name="AL2" pos="-0.000316479 0.0490496 -0.00279769" quat="0.999999 -0.000913233 0.000575226 -0.000839535">
          <inertial pos="0.00287508 0.0369605 -0.00288317" quat="0.488574 0.509712 -0.489347 0.511886" mass="0.139686" diaginertia="8.99007e-05 0.000331201 0.000280962"/>
          <joint name="Left_Shoulder_Roll" pos="0 0 0" axis="-0.999925 -0.0119524 0.00250584" range="-1.56477 1.75805" armature="0.00892038" damping="0.00401893" frictionloss="0.0815914"/>
          <geom name="//unnamed_geom_13" class="visual" mesh="AL2"/>
          <body name="AL3" pos="-0.00206487 0.0590891 0.00131727" quat="1 0.000443544 -3.4862e-05 -0.000238728">
            <inertial pos="0.000719806 0.084943 0.0025519" quat="0.705328 0.708881 -0.000712651 0.000126972" mass="0.857327" diaginertia="0.00286757 0.0125411 0.000978978"/>
            <joint name="Left_Elbow_Pitch" pos="0 0 0" axis="0.00434289 -0.999907 -0.0129055" range="-2.29362 2.27155" armature="0.00970222" damping="0.00356337" frictionloss="0.0963247"/>
            <geom name="//unnamed_geom_14" class="visual" mesh="AL3"/>
            <geom name="//unnamed_geom_15" class="collision" size="0.0283264 0.0708161" pos="0 0.0497544 0" quat="0.707105 0.707108 0 0" type="cylinder"/>
            <geom name="//unnamed_geom_16" class="reward_collision_sphere" size="0.0339917"/>
            <body name="left_hand_link" pos="-0.00159774 0.14415 0.0028459" quat="1 -2.53876e-05 -1.03761e-06 -2.3266e-05">
              <inertial pos="0.000103643 0.109825 0.00286408" quat="0.707583 0.706627 -0.00134129 0.00164046" mass="0.282742" diaginertia="0.00179775 0.00840297 0.000355284"/>
              <joint name="Left_Elbow_Yaw" pos="0 0 0" axis="0.0152789 -0.00334683 0.999878" range="-2.4544 0.0136874" armature="0.00880971" damping="0.0125612" frictionloss="0.103105"/>
              <geom name="//unnamed_geom_17" class="visual" mesh="left_hand_link"/>
              <geom name="//unnamed_geom_18" class="collision" size="0.0283264 0.0826187" pos="0 0.129361 0" quat="0.707105 0.707108 0 0" type="cylinder"/>
              <geom name="//unnamed_geom_19" class="reward_collision_sphere" size="0.0472107"/>
              <geom name="//unnamed_geom_20" class="reward_collision_sphere" size="0.0330475" pos="0 0.10946 0"/>
              <geom name="//unnamed_geom_21" class="reward_collision_sphere" size="0.0330475" pos="0 0.213944 0"/>
            </body>
          </body>
        </body>
      </body>
      <body name="AR1" pos="0.0446893 -0.106619 0.24342" quat="0.999999 -0.000947083 0.000214633 0.00077833">
        <inertial pos="-1.15681e-05 -0.0457803 -0.00098121" quat="0.50432 0.496079 -0.501032 0.498532" mass="0.444177" diaginertia="0.000292298 0.00126397 0.000465963"/>
        <joint name="Right_Shoulder_Pitch" pos="0 0 0" axis="-0.000590759 -1 -0.000368494" range="-1.22436 3.34736" armature="0.0098087" damping="0" frictionloss="0.0913723"/>
        <geom name="//unnamed_geom_22" class="visual" rgba="0.76 0.76 0.76 1" mesh="AR1"/>
        <body name="AR2" pos="-0.000770365 -0.046199 0.000269301" quat="0.999999 0.000628736 0.000331676 -0.000748248">
          <inertial pos="0.00246571 -0.0379521 0.00259058" quat="0.512446 0.488628 -0.509399 0.489034" mass="0.12978" diaginertia="9.11347e-05 0.000340249 0.000272002"/>
          <joint name="Right_Shoulder_Roll" pos="0 0 0" axis="-0.999946 0.00397323 0.00956182" range="-1.75447 1.57059" armature="0.00945946" damping="0.0114622" frictionloss="0.107226"/>
          <geom name="//unnamed_geom_23" class="visual" mesh="AR2"/>
          <body name="AR3" pos="-0.00129281 -0.0575563 -8.90376e-06" quat="1 3.82104e-05 -0.000176835 0.000260612">
            <inertial pos="-0.00297124 -0.0844306 -0.000968015" quat="0.711039 0.70308 -0.00560352 -0.00844068" mass="0.876663" diaginertia="0.0027484 0.0119482 0.000990272"/>
            <joint name="Right_Elbow_Pitch" pos="0 0 0" axis="0.0036784 0.999985 -0.00410407" range="-2.26897 2.24387" armature="0.00815343" damping="0.00279175" frictionloss="0.0969771"/>
            <geom name="//unnamed_geom_24" class="visual" mesh="AR3"/>
            <geom name="//unnamed_geom_25" class="collision" size="0.0283264 0.0708161" pos="0 -0.0497544 0" quat="0.707105 0.707108 0 0" type="cylinder"/>
            <geom name="//unnamed_geom_26" class="reward_collision_sphere" size="0.0339917"/>
            <body name="right_hand_link" pos="-0.000357418 -0.146865 0.00268318" quat="1 7.03001e-07 6.73774e-06 7.69971e-06">
              <inertial pos="-0.0021955 -0.106424 0.00148937" quat="0.706292 0.707914 0.00207311 0.00223543" mass="0.273282" diaginertia="0.00178182 0.00782955 0.000343566"/>
              <joint name="Right_Elbow_Yaw" pos="0 0 0" axis="-0.000609066 -0.00443664 0.99999" range="0.00732422 2.44297" armature="0.00955655" damping="0.00648579" frictionloss="0.0942191"/>
              <geom name="//unnamed_geom_27" class="visual" mesh="right_hand_link"/>
              <geom name="//unnamed_geom_28" class="collision" size="0.0283264 0.0826187" pos="0 -0.129361 0" quat="0.707105 0.707108 0 0" type="cylinder"/>
              <geom name="//unnamed_geom_29" class="reward_collision_sphere" size="0.0472107"/>
              <geom name="//unnamed_geom_30" class="reward_collision_sphere" size="0.0330475" pos="0 -0.10946 0"/>
              <geom name="//unnamed_geom_31" class="reward_collision_sphere" size="0.0330475" pos="0 -0.213944 0"/>
            </body>
          </body>
        </body>
      </body>
      <body name="Waist" pos="0.0483565 0.000770715 -0.124762" quat="1 0.000130819 -0.000115177 -5.24776e-05">
        <inertial pos="0.00340405 0.000180022 0.00849609" quat="0.983866 0.000718401 -0.178832 0.00514834" mass="2.15063" diaginertia="0.00114387 0.00527696 0.00733019"/>
        <joint name="Waist" pos="0 0 0" axis="0.00529047 0.00207463 0.999984" range="-1.6167 1.59315" armature="0.00950906" damping="0" frictionloss="0.0959053"/>
        <geom name="//unnamed_geom_32" class="visual" mesh="Waist"/>
        <body name="Hip_Pitch_Left" pos="-0.000156616 0.108046 0.00281579" quat="1 8.31809e-05 2.54636e-05 -7.50893e-05">
          <inertial pos="-0.000857449 -0.00716782 -0.0226286" quat="0.975321 0.219976 0.0189314 0.00098007" mass="0.889735" diaginertia="0.000407934 0.00142815 0.00197858"/>
          <joint name="Left_Hip_Pitch" pos="0 0 0" axis="0.00110995 0.999991 0.00406896" range="-1.7469 1.58016" armature="0.00948851" damping="0" frictionloss="0.081915"/>
          <geom name="//unnamed_geom_33" class="visual" rgba="0.76 0.76 0.76 1" mesh="Hip_Pitch_Left"/>
          <body name="Hip_Roll_Left" pos="0.00201504 -0.000704866 -0.0207711" quat="1 -3.28078e-06 2.08825e-05 1.23969e-05">
            <inertial pos="0.000234668 0.00116651 -0.0593193" quat="0.705806 -0.00369783 -0.00480217 0.708379" mass="0.334729" diaginertia="0.00040106 0.00155207 0.000852181"/>
            <joint name="Left_Hip_Roll" pos="0 0 0" axis="-0.999994 -0.00295942 0.00168347" range="-1.52227 0.203172" armature="0.00941593" damping="0.0205414" frictionloss="0.083863"/>
            <geom name="//unnamed_geom_34" class="visual" mesh="Hip_Roll_Left"/>
            <geom name="//unnamed_geom_35" class="reward_collision_sphere" size="0.0519318"/>
            <body name="Hip_Yaw_Left" pos="-0.000964486 -0.00153042 -0.0877454" quat="1 4.2345e-05 -4.08752e-05 -2.88855e-05">
              <inertial pos="-0.00595586 0.000364105 -0.100974" quat="0.697321 -0.0346944 -0.031294 0.715234" mass="1.78708" diaginertia="0.0058909 0.0246968 0.00417498"/>
              <joint name="Left_Hip_Yaw" pos="0 0 0" axis="-0.000760764 -0.00924603 -0.999957" range="-1.0175 1.05594" armature="0.00835525" damping="0" frictionloss="0.0815431"/>
              <geom name="//unnamed_geom_36" class="visual" mesh="Hip_Yaw_Left"/>
              <geom name="//unnamed_geom_37" class="collision" size="0.0472107 0.0755371" type="cylinder"/>
              <body name="Shank_Left" pos="-0.0104404 0.00265136 -0.145081" quat="0.999999 0.00072975 -0.000379891 0.00105497">
                <inertial pos="-0.00338992 -0.00207174 -0.136662" quat="0.997436 0.0150434 -0.0248202 0.065411" mass="1.46468" diaginertia="0.00800072 0.034144 0.00301784"/>
                <joint name="Left_Knee_Pitch" pos="0 0 0" axis="0.0119242 0.999928 -0.000962945" range="0.0144855 2.3429" armature="0.0105175" damping="0.0150861" frictionloss="0.0816077"/>
                <geom name="//unnamed_geom_38" class="visual" mesh="Shank_Left"/>
                <geom name="//unnamed_geom_39" class="collision" size="0.0472107 0.0708161" pos="0 0 -0.131801" type="cylinder"/>
                <geom name="//unnamed_geom_40" class="reward_collision_sphere" size="0.0613739"/>
                <body name="Ankle_Cross_Left" pos="-0.00292443 -0.000279758 -0.30785" quat="1 1.38569e-05 1.15547e-05 -9.42629e-06">
                  <inertial pos="-0.00318209 0.000239738 -0.00858835" quat="0.453416 0.551781 0.542613 0.44218" mass="0.0607808" diaginertia="6.42033e-06 2.50937e-05 1.79704e-05"/>
                  <joint name="Left_Ankle_Pitch" pos="0 0 0" axis="0.0059265 0.99998 0.00224381" range="-0.873822 0.294643" armature="0.00939828" damping="0.0135833" frictionloss="0.0922241"/>
                  <geom name="//unnamed_geom_41" class="visual" mesh="Ankle_Cross_Left"/>
                  <body name="left_foot_link" pos="0.00182576 0.00035415 -0.0132724" quat="1 -0.000598128 0.000404207 0.00037949">
                    <inertial pos="3.58734e-05 -8.24317e-05 -0.0074481" quat="0.0001983 0.620063 -0.000678188 0.784552" mass="0.564252" diaginertia="0.000579522 0.00233347 0.00344709"/>
                    <joint name="Left_Ankle_Roll" pos="0 0 0" axis="-0.999939 -0.0106281 0.00302886" range="-0.486568 0.452605" armature="0.00934701" damping="0.0222271" frictionloss="0.0937628"/>
                    <geom name="//unnamed_geom_42" class="visual" mesh="left_foot_link"/>
                    <geom name="left_foot" class="foot" size="0.114068 0.0519879 0.0150612" pos="0.0073921 0 -0.0164752"/>
                    <geom name="//unnamed_geom_44" class="reward_collision_sphere" size="0.0490991" pos="0.0073921 0 -0.0164752"/>
                    <geom name="//unnamed_geom_45" class="reward_collision_sphere" size="0.0283264" pos="0.070225 -0.022887 -0.0164752"/>
                    <geom name="//unnamed_geom_46" class="reward_collision_sphere" size="0.0283264" pos="-0.0517447 -0.022887 -0.0164752"/>
                    <site name="left_foot" class="foot" pos="0.0073921 0 -0.0164752" size="0.00944214"/>
                  </body>
                </body>
              </body>
            </body>
          </body>
        </body>
        <body name="Hip_Pitch_Right" pos="-0.00339004 -0.106839 0.00245019" quat="0.999999 0.000909809 -3.92412e-05 -0.000672294">
          <inertial pos="-0.000149549 0.00497959 -0.020699" quat="0.97299 -0.230296 0.0153381 -0.00432783" mass="0.851864" diaginertia="0.000390793 0.00141019 0.00200494"/>
          <joint name="Right_Hip_Pitch" pos="0 0 0" axis="-0.00188225 -0.999998 1.30385e-05" range="-1.53474 1.74486" armature="0.00930709" damping="0.0161068" frictionloss="0.107046"/>
          <geom name="//unnamed_geom_47" class="visual" rgba="0.76 0.76 0.76 1" mesh="Hip_Pitch_Right"/>
          <body name="Hip_Roll_Right" pos="-0.00311024 0.000596895 -0.0195373" quat="1 0.000445915 -3.14002e-05 -7.3734e-05">
            <inertial pos="0.00164918 -0.000403286 -0.0580719" quat="0.707362 -0.00650158 -0.00607378 0.706795" mass="0.324219" diaginertia="0.000372793 0.00147903 0.000818639"/>
            <joint name="Right_Hip_Roll" pos="0 0 0" axis="-0.999938 0.0103577 -0.00410577" range="-0.161297 1.568" armature="0.00930837" damping="0.00528794" frictionloss="0.106719"/>
            <geom name="//unnamed_geom_48" class="visual" mesh="Hip_Roll_Right"/>
            <geom name="//unnamed_geom_49" class="reward_collision_sphere" size="0.0519318"/>
            <body name="Hip_Yaw_Right" pos="0.00236852 -0.000960184 -0.0877545" quat="1 0.000112352 -0.000298303 -2.08389e-05">
              <inertial pos="-0.00734239 0.00219253 -0.0991567" quat="0.71545 -0.0296119 -0.0337414 0.69722" mass="1.77109" diaginertia="0.00569281 0.0238146 0.00400691"/>
              <joint name="Right_Hip_Yaw" pos="0 0 0" axis="-0.00433951 -0.00269337 -0.999987" stiffness="0.00079213" range="-1.01796 1.00324" armature="0.00935193" damping="0.0200456" frictionloss="0.0948054"/>
              <geom name="//unnamed_geom_50" class="visual" mesh="Hip_Yaw_Right"/>
              <geom name="//unnamed_geom_51" class="collision" size="0.0472107 0.0755371" type="cylinder"/>
              <body name="Shank_Right" pos="-0.00849961 7.81411e-06 -0.144857" quat="1 -5.34782e-05 -0.000214138 -0.000129149">
                <inertial pos="-0.00688133 -0.000600476 -0.136877" quat="0.998717 0.00376882 -0.027638 -0.0422701" mass="1.4945" diaginertia="0.00760156 0.0339362 0.00304456"/>
                <joint name="Right_Knee_Pitch" pos="0 0 0" axis="-0.00373433 -0.999991 0.00221259" range="-2.33617 -0.0569441" armature="0.00965713" damping="0.00855243" frictionloss="0.0842738"/>
                <geom name="//unnamed_geom_52" class="visual" mesh="Shank_Right"/>
                <geom name="//unnamed_geom_53" class="collision" size="0.0472107 0.0708161" pos="0 0 -0.131801" type="cylinder"/>
                <geom name="//unnamed_geom_54" class="reward_collision_sphere" size="0.0613739"/>
                <body name="Ankle_Cross_Right" pos="-0.000874867 -0.00156755 -0.310569" quat="1 6.68695e-05 0.00012009 -2.6145e-05">
                  <inertial pos="-0.00309533 -0.000906819 -0.00855583" quat="0.439383 0.548336 0.553037 0.447682" mass="0.0608443" diaginertia="6.46689e-06 2.5537e-05 1.83269e-05"/>
                  <joint name="Right_Ankle_Pitch" pos="0 0 0" axis="-0.000642287 -0.999999 -0.0013316" range="-0.302544 0.905514" armature="0.0100223" damping="0.00552087" frictionloss="0.0931537"/>
                  <geom name="//unnamed_geom_55" class="visual" mesh="Ankle_Cross_Right"/>
                  <body name="right_foot_link" pos="0.00150164 -4.86667e-05 -0.0119793" quat="1 5.70099e-06 -0.000289449 9.82846e-05">
                    <inertial pos="-0.000156205 -0.000260645 -0.00739536" quat="-0.00106198 0.617036 -0.00132594 0.786933" mass="0.582709" diaginertia="0.000591285 0.00226587 0.00351642"/>
                    <joint name="Right_Ankle_Roll" pos="0 0 0" axis="-1 0.000252508 -0.000432942" range="-0.423058 0.448684" armature="0.00890232" damping="0.00539012" frictionloss="0.10586"/>
                    <geom name="//unnamed_geom_56" class="visual" mesh="right_foot_link"/>
                    <geom name="right_foot" class="foot" size="0.102133 0.0415477 0.015611" pos="0.0073921 0 -0.0164752"/>
                    <geom name="//unnamed_geom_58" class="reward_collision_sphere" size="0.0377686"/>
                    <geom name="//unnamed_geom_59" class="reward_collision_sphere" size="0.0283264" pos="0.0073921 0 -0.0164752"/>
                    <geom name="//unnamed_geom_60" class="reward_collision_sphere" size="0.0283264" pos="0.070225 0.022887 -0.0164752"/>
                    <geom name="//unnamed_geom_61" class="reward_collision_sphere" size="0.0283264" pos="-0.0517447 0.022887 -0.0164752"/>
                    <site name="right_foot" class="foot" pos="0.0073921 0 -0.0164752" size="0.00944214"/>
                  </body>
                </body>
              </body>
            </body>
          </body>
        </body>
      </body>
    </body>
  </worldbody>

  <contact>
    <pair class="/" geom1="floor" geom2="left_foot" name="//unnamed_contact_0"/>
    <pair class="/" geom1="floor" geom2="right_foot" name="//unnamed_contact_1"/>
  </contact>

  <actuator>
    <general name="AAHead_yaw" class="/" joint="AAHead_yaw" forcerange="-6.5676 6.5676" gainprm="25.0961" biasprm="0 -25.0961 -0.557387"/>
    <general name="Head_pitch" class="/" joint="Head_pitch" forcerange="-6.7843 6.7843" gainprm="25.0961" biasprm="0 -25.0961 -0.557387"/>
    <general name="Left_Shoulder_Pitch" class="/" joint="Left_Shoulder_Pitch" forcerange="-16.5363 16.5363" gainprm="25.0961" biasprm="0 -25.0961 -0.557387"/>
    <general name="Left_Shoulder_Roll" class="/" joint="Left_Shoulder_Roll" forcerange="-16.3828 16.3828" gainprm="25.0961" biasprm="0 -25.0961 -0.557387"/>
    <general name="Left_Elbow_Pitch" class="/" joint="Left_Elbow_Pitch" forcerange="-15.3884 15.3884" gainprm="25.0961" biasprm="0 -25.0961 -0.557387"/>
    <general name="Left_Elbow_Yaw" class="/" joint="Left_Elbow_Yaw" forcerange="-17.1241 17.1241" gainprm="25.0961" biasprm="0 -25.0961 -0.557387"/>
    <general name="Right_Shoulder_Pitch" class="/" joint="Right_Shoulder_Pitch" forcerange="-16.398 16.398" gainprm="25.0961" biasprm="0 -25.0961 -0.557387"/>
    <general name="Right_Shoulder_Roll" class="/" joint="Right_Shoulder_Roll" forcerange="-18.0549 18.0549" gainprm="25.0961" biasprm="0 -25.0961 -0.557387"/>
    <general name="Right_Elbow_Pitch" class="/" joint="Right_Elbow_Pitch" forcerange="-17.1838 17.1838" gainprm="25.0961" biasprm="0 -25.0961 -0.557387"/>
    <general name="Right_Elbow_Yaw" class="/" joint="Right_Elbow_Yaw" forcerange="-17.0842 17.0842" gainprm="25.0961" biasprm="0 -25.0961 -0.557387"/>
    <general name="Waist" class="/" joint="Waist" forcerange="-28.1007 28.1007" gainprm="25.0961" biasprm="0 -25.0961 -0.557387"/>
    <general name="Left_Hip_Pitch" class="/" joint="Left_Hip_Pitch" forcerange="-41.8183 41.8183" gainprm="25.0961" biasprm="0 -25.0961 -0.557387"/>
    <general name="Left_Hip_Roll" class="/" joint="Left_Hip_Roll" forcerange="-31.1757 31.1757" gainprm="25.0961" biasprm="0 -25.0961 -0.557387"/>
    <general name="Left_Hip_Yaw" class="/" joint="Left_Hip_Yaw" forcerange="-26.526 26.526" gainprm="25.0961" biasprm="0 -25.0961 -0.557387"/>
    <general name="Left_Knee_Pitch" class="/" joint="Left_Knee_Pitch" forcerange="-61.9545 61.9545" gainprm="25.0961" biasprm="0 -25.0961 -0.557387"/>
    <general name="Left_Ankle_Pitch" class="/" joint="Left_Ankle_Pitch" forcerange="-17.7129 17.7129" gainprm="25.0961" biasprm="0 -25.0961 -0.557387"/>
    <general name="Left_Ankle_Roll" class="/" joint="Left_Ankle_Roll" forcerange="-13.4611 13.4611" gainprm="25.0961" biasprm="0 -25.0961 -0.557387"/>
    <general name="Right_Hip_Pitch" class="/" joint="Right_Hip_Pitch" forcerange="-38.1999 38.1999" gainprm="25.0961" biasprm="0 -25.0961 -0.557387"/>
    <general name="Right_Hip_Roll" class="/" joint="Right_Hip_Roll" forcerange="-29.0494 29.0494" gainprm="25.0961" biasprm="0 -25.0961 -0.557387"/>
    <general name="Right_Hip_Yaw" class="/" joint="Right_Hip_Yaw" forcerange="-30.4201 30.4201" gainprm="25.0961" biasprm="0 -25.0961 -0.557387"/>
    <general name="Right_Knee_Pitch" class="/" joint="Right_Knee_Pitch" forcerange="-55.9679 55.9679" gainprm="25.0961" biasprm="0 -25.0961 -0.557387"/>
    <general name="Right_Ankle_Pitch" class="/" joint="Right_Ankle_Pitch" forcerange="-18.5922 18.5922" gainprm="25.0961" biasprm="0 -25.0961 -0.557387"/>
    <general name="Right_Ankle_Roll" class="/" joint="Right_Ankle_Roll" forcerange="-14.1875 14.1875" gainprm="25.0961" biasprm="0 -25.0961 -0.557387"/>
  </actuator>

  <sensor>
    <gyro site="imu" name="imu_angular_velocity"/>
    <velocimeter site="imu" name="imu_linear_velocity"/>
    <framelinvel objtype="site" objname="left_foot" name="left_foot_global_linear_velocity"/>
    <framelinvel objtype="site" objname="right_foot" name="right_foot_global_linear_velocity"/>
  </sensor>

  <keyframe>
    <key name="home" qpos="0 0 0.6385 1 0 0 0 0 0 0 1.4 0 -0.4 0 -1.4 0 0.4 0 -0.4 0 0 0.8 -0.4 0 0.4 0 0 -0.8 0.4 0"/>
  </keyframe>
</mujoco>
