<mujoco model="T1">
  <compiler angle="radian" assetdir="assets" balanceinertia="true" inertiafromgeom="false"/>

  <option timestep="0.005" density="1.2" viscosity="2e-05"/>

  <size nkey="1"/>

  <visual>
    <quality shadowsize="8192"/>
    <map shadowclip="0.5"/>
  </visual>

  <default>
    <default class="/">
      <joint armature="0.01" damping="0.01" frictionloss="0.1"/>
      <geom contype="0" conaffinity="0" group="1" solref="-1000 -80"/>
      <site size="0.01 0.005 0.005" group="5"/>
      <general forcelimited="true" biastype="affine" gainprm="25" biasprm="0 -25 -0.6"/>
      <default class="t1">
        <geom rgba="0.25 0.25 0.25 1"/>
        <default class="visual">
          <geom type="mesh" group="2"/>
        </default>
        <default class="collision">
          <geom group="3"/>
        </default>
        <default class="foot">
          <geom size="0.1115 0.05 0.015" type="box" condim="6" group="4" priority="1" solimp="0.015 1 0.015"/>
        </default>
        <default class="reward_collision_sphere">
          <geom group="5" rgba="1 0 0 1"/>
        </default>
      </default>
    </default>
  </default>

  <asset>
    <texture type="skybox" colorspace="auto" name="//unnamed_texture_0" builtin="gradient" rgb1="0.95 0.95 0.95" rgb2="0.95 0.95 0.95" width="100" height="600"/>
    <texture type="2d" colorspace="auto" name="texplane" builtin="checker" rgb1="0.345 0.575 0.748" rgb2="0.345 0.575 0.748" markrgb="1 1 1" width="512" height="512"/>
    <material name="MatPlane" class="/" texture="texplane" texuniform="true" texrepeat="2 2" specular="0.9"/>
    <mesh name="Trunk" class="/" file="Trunk.stl"/>
    <mesh name="H1" class="/" file="H1.stl"/>
    <mesh name="H2" class="/" file="H2.stl"/>
    <mesh name="AL1" class="/" file="AL1.stl"/>
    <mesh name="AL2" class="/" file="AL2.stl"/>
    <mesh name="AL3" class="/" file="AL3.stl"/>
    <mesh name="left_hand_link" class="/" file="left_hand_link.stl"/>
    <mesh name="AR1" class="/" file="AR1.stl"/>
    <mesh name="AR2" class="/" file="AR2.stl"/>
    <mesh name="AR3" class="/" file="AR3.stl"/>
    <mesh name="right_hand_link" class="/" file="right_hand_link.stl"/>
    <mesh name="Waist" class="/" file="Waist.stl"/>
    <mesh name="Hip_Pitch_Left" class="/" file="Hip_Pitch_Left.stl"/>
    <mesh name="Hip_Roll_Left" class="/" file="Hip_Roll_Left.stl"/>
    <mesh name="Hip_Yaw_Left" class="/" file="Hip_Yaw_Left.stl"/>
    <mesh name="Shank_Left" class="/" file="Shank_Left.stl"/>
    <mesh name="Ankle_Cross_Left" class="/" file="Ankle_Cross_Left.stl"/>
    <mesh name="left_foot_link" class="/" file="left_foot_link.stl"/>
    <mesh name="Hip_Pitch_Right" class="/" file="Hip_Pitch_Right.stl"/>
    <mesh name="Hip_Roll_Right" class="/" file="Hip_Roll_Right.stl"/>
    <mesh name="Hip_Yaw_Right" class="/" file="Hip_Yaw_Right.stl"/>
    <mesh name="Shank_Right" class="/" file="Shank_Right.stl"/>
    <mesh name="Ankle_Cross_Right" class="/" file="Ankle_Cross_Right.stl"/>
    <mesh name="right_foot_link" class="/" file="right_foot_link.stl"/>
  </asset>

  <worldbody>
    <geom name="floor" class="/" size="100 100 0.125" type="plane" group="0" material="MatPlane"/>
    <light name="toplight_shadow" class="/" pos="0 0 5" dir="0.0990148 0.0990148 -0.990148" type="directional" ambient="0.04 0.04 0.04" diffuse="0.55 0.55 0.55" specular="0.12 0.12 0.12"/>
    <light name="toplight_fill" class="/" pos="0 0 5" dir="0.0990148 0.0990148 -0.990148" type="directional" castshadow="false" ambient="0.04 0.04 0.04" diffuse="0.3 0.3 0.3" specular="0.08 0.08 0.08"/>
    <body name="trunk" childclass="t1" pos="0.00153634 -0.00033723 -0.000396214" quat="1 -0.000255755 -0.000376135 -0.000192557">
      <inertial pos="0.0418569 -0.000232602 0.108485" quat="0.999955 0.00306273 -0.00882774 0.00145331" mass="9.50319" diaginertia="0.0251495 0.0610292 0.0676208"/>
      <joint name="//unnamed_joint_0" type="free" armature="0" damping="0" frictionloss="0"/>
      <geom name="//unnamed_geom_1" class="visual" rgba="0.76 0.76 0.76 1" mesh="Trunk"/>
      <geom name="//unnamed_geom_2" class="collision" size="0.0689737 0.0919649 0.137947" pos="0.0460279 0 0.124433" type="box"/>
      <geom name="//unnamed_geom_3" class="reward_collision_sphere" size="0.10576" pos="0.0460279 0 0.103694"/>
      <geom name="//unnamed_geom_4" class="reward_collision_sphere" size="0.0137947" pos="0.0460279 0.0811643 0"/>
      <geom name="//unnamed_geom_5" class="reward_collision_sphere" size="0.0137947" pos="0.0460279 -0.0811643 0"/>
      <geom name="//unnamed_geom_6" class="reward_collision_sphere" size="0.0137947" pos="0.0460279 0.102172 0.186649"/>
      <geom name="//unnamed_geom_7" class="reward_collision_sphere" size="0.0137947" pos="0.0460279 -0.102172 0.186649"/>
      <site name="imu" pos="-0.0133588 0.000168891 0.00970605" size="0.00919649"/>
      <camera name="track" pos="0 -1.90975 0" quat="0.707107 0.707107 0 0" mode="trackcom"/>
      <camera name="ego_camera" pos="0.0935902 0 0.435515" quat="-0.5 -0.5 0.5 0.5"/>
      <body name="H1" pos="0.0449623 -0.00293882 0.249133" quat="1 -0.000410092 0.000355559 -7.2344e-05">
        <inertial pos="-0.00250146 -0.00215591 0.0591805" quat="0.757541 -0.0109917 -0.00712826 0.652656" mass="0.353083" diaginertia="6.42521e-05 0.000170558 0.00017819"/>
        <joint name="AAHead_yaw" pos="0 0 0" axis="-0.000404455 0.0136434 0.999907" range="-1.58053 1.55813" armature="0.0102493" damping="0.00596474" frictionloss="0.0957037"/>
        <geom name="//unnamed_geom_8" class="visual" mesh="H1"/>
        <body name="H2" pos="-0.00137417 -0.000544094 0.0639195" quat="0.999999 -0.000364904 0.000727207 -0.000759034">
          <inertial pos="0.00545989 -0.00171229 0.102026" quat="0.988195 0.104541 -0.0795614 -0.0788212" mass="0.510803" diaginertia="0.00054893 0.00155089 0.00210651"/>
          <joint name="Head_pitch" pos="0 0 0" axis="0.000239112 -1 -0.00010108" range="-1.2422 0.347957" armature="0.00988761" damping="0.00980801" frictionloss="0.0923365"/>
          <geom name="//unnamed_geom_9" class="visual" mesh="H2"/>
          <geom name="//unnamed_geom_10" class="collision" size="0.0735719" pos="0.00767132 0 0.114063"/>
          <geom name="//unnamed_geom_11" class="reward_collision_sphere" size="0.0827684" pos="0.0153426 0 0.103694"/>
        </body>
      </body>
      <body name="AL1" pos="0.0456095 0.104831 0.228389" quat="1 1.03302e-05 0.000467416 7.68361e-06">
        <inertial pos="-0.00311515 0.045495 -0.00217768" quat="0.504162 0.496552 -0.507393 0.491742" mass="0.418843" diaginertia="0.000372151 0.00104932 0.000352192"/>
        <joint name="Left_Shoulder_Pitch" pos="0 0 0" axis="-0.00449826 0.999978 0.00492313" stiffness="0.0113957" range="-3.30348 1.21626" armature="0.00985242" damping="0.00590894" frictionloss="0.0840699"/>
        <geom name="//unnamed_geom_12" class="visual" rgba="0.76 0.76 0.76 1" mesh="AL1"/>
        <body name="AL2" pos="-0.00091842 0.0482681 0.00163927" quat="1 5.02886e-05 -5.42311e-05 1.65123e-05">
          <inertial pos="0.0030549 0.0372697 0.000446785" quat="0.487991 0.511726 -0.488001 0.511718" mass="0.125098" diaginertia="0.000113102 0.000292655 0.000215311"/>
          <joint name="Left_Shoulder_Roll" pos="0 0 0" axis="-1 -3.0699e-05 -0.000564871" range="-1.54135 1.68824" armature="0.00929322" damping="0.019887" frictionloss="0.0937182"/>
          <geom name="//unnamed_geom_13" class="visual" mesh="AL2"/>
          <body name="AL3" pos="0.00328405 0.0575836 -0.000576687" quat="1 3.31237e-05 -0.000721037 0.000293603">
            <inertial pos="7.98273e-05 0.0803183 0.00210162" quat="0.702649 0.711467 -0.00272568 -0.00960187" mass="0.792349" diaginertia="0.00347741 0.0100568 0.00073569"/>
            <joint name="Left_Elbow_Pitch" pos="0 0 0" axis="-0.00231449 -0.999994 -0.00262969" range="-2.27186 2.3157" armature="0.00801767" damping="0.00323078" frictionloss="0.0897058"/>
            <geom name="//unnamed_geom_14" class="visual" mesh="AL3"/>
            <geom name="//unnamed_geom_15" class="collision" size="0.0275895 0.0689737" pos="0 0.0477437 0" quat="0.707105 0.707108 0 0" type="cylinder"/>
            <geom name="//unnamed_geom_16" class="reward_collision_sphere" size="0.0331074"/>
            <body name="left_hand_link" pos="0.000337104 0.140757 -0.000111814" quat="0.999999 -0.0005864 -0.000683528 0.00056934">
              <inertial pos="0.0024559 0.102327 0.00126946" quat="0.709201 0.705005 0.00131897 -9.97094e-05" mass="0.250674" diaginertia="0.00216465 0.00649451 0.000250473"/>
              <joint name="Left_Elbow_Yaw" pos="0 0 0" axis="0.00278006 0.00204146 0.999994" range="-2.43016 -0.023194" armature="0.0102087" damping="0.0217552" frictionloss="0.10211"/>
              <geom name="//unnamed_geom_17" class="visual" mesh="left_hand_link"/>
              <geom name="//unnamed_geom_18" class="collision" size="0.0275895 0.0804693" pos="0 0.124134 0" quat="0.707105 0.707108 0 0" type="cylinder"/>
              <geom name="//unnamed_geom_19" class="reward_collision_sphere" size="0.0459825"/>
              <geom name="//unnamed_geom_20" class="reward_collision_sphere" size="0.0321877" pos="0 0.105036 0"/>
              <geom name="//unnamed_geom_21" class="reward_collision_sphere" size="0.0321877" pos="0 0.205298 0"/>
            </body>
          </body>
        </body>
      </body>
      <body name="AR1" pos="0.0452265 -0.10324 0.226954" quat="1 -0.000452714 0.000762373 -0.000269523">
        <inertial pos="-0.00059133 -0.0439537 8.21435e-05" quat="0.504854 0.495744 -0.504002 0.495319" mass="0.413788" diaginertia="0.000367065 0.0010336 0.000349743"/>
        <joint name="Right_Shoulder_Pitch" pos="0 0 0" axis="-0.00083537 -0.999997 0.0022491" stiffness="0.0128545" range="-1.218 3.29328" armature="0.00988906" damping="0" frictionloss="0.0872483"/>
        <geom name="//unnamed_geom_22" class="visual" rgba="0.76 0.76 0.76 1" mesh="AR1"/>
        <body name="AR2" pos="0.00120738 -0.0438105 -0.00263807" quat="1 9.79203e-05 3.50173e-05 -0.000372034">
          <inertial pos="0.00183093 -0.0341149 -0.00247176" quat="0.511628 0.488139 -0.511842 0.487827" mass="0.127411" diaginertia="0.000108786 0.000270319 0.000215705"/>
          <joint name="Right_Shoulder_Roll" pos="0 0 0" axis="-0.999881 0.0153839 0.000800978" range="-1.68729 1.58509" armature="0.00926809" damping="0.0217427" frictionloss="0.0896465"/>
          <geom name="//unnamed_geom_23" class="visual" mesh="AR2"/>
          <body name="AR3" pos="0.00120321 -0.056625 -0.000444121" quat="1 -0.000100473 -8.39916e-05 6.20264e-05">
            <inertial pos="-0.00301298 -0.0820444 -0.000459391" quat="0.707217 0.706987 -0.000541943 0.00358284" mass="0.790745" diaginertia="0.00344646 0.0101218 0.000766059"/>
            <joint name="Right_Elbow_Pitch" pos="0 0 0" axis="-0.000705831 0.999996 0.00255832" range="-2.27055 2.23796" armature="0.00930607" damping="0.0136275" frictionloss="0.0797085"/>
            <geom name="//unnamed_geom_24" class="visual" mesh="AR3"/>
            <geom name="//unnamed_geom_25" class="collision" size="0.0275895 0.0689737" pos="0 -0.0477437 0" quat="0.707105 0.707108 0 0" type="cylinder"/>
            <geom name="//unnamed_geom_26" class="reward_collision_sphere" size="0.0331074"/>
            <body name="right_hand_link" pos="0.000267079 -0.139219 -0.000721458" quat="1 0.000130917 0.000247389 -0.000229134">
              <inertial pos="0.000596273 -0.10358 0.00334048" quat="0.706262 0.70795 2.96332e-05 -6.37073e-06" mass="0.255759" diaginertia="0.00215689 0.0062997 0.000259396"/>
              <joint name="Right_Elbow_Yaw" pos="0 0 0" axis="-0.00232011 -0.00086736 0.999997" stiffness="0.00591979" range="0.021169 2.45184" armature="0.00903844" damping="0.00510805" frictionloss="0.0799516"/>
              <geom name="//unnamed_geom_27" class="visual" mesh="right_hand_link"/>
              <geom name="//unnamed_geom_28" class="collision" size="0.0275895 0.0804693" pos="0 -0.124134 0" quat="0.707105 0.707108 0 0" type="cylinder"/>
              <geom name="//unnamed_geom_29" class="reward_collision_sphere" size="0.0459825"/>
              <geom name="//unnamed_geom_30" class="reward_collision_sphere" size="0.0321877" pos="0 -0.105036 0"/>
              <geom name="//unnamed_geom_31" class="reward_collision_sphere" size="0.0321877" pos="0 -0.205298 0"/>
            </body>
          </body>
        </body>
      </body>
      <body name="Waist" pos="0.0484046 -0.000479922 -0.120527" quat="1 8.06511e-05 -0.00050947 -0.000396101">
        <inertial pos="0.00167781 -0.000462098 0.0072291" quat="0.983722 0.00273693 -0.179551 0.00674563" mass="1.95729" diaginertia="0.00146936 0.00414086 0.00585769"/>
        <joint name="Waist" pos="0 0 0" axis="-0.00572887 0.0104758 0.999929" range="-1.594 1.54835" armature="0.00912447" damping="0.00829475" frictionloss="0.0800331"/>
        <geom name="//unnamed_geom_32" class="visual" mesh="Waist"/>
        <body name="Hip_Pitch_Left" pos="0.00202882 0.0997634 0.000483509" quat="1 -0.000372809 -0.000248211 -0.000465677">
          <inertial pos="0.000885387 -0.00957413 -0.0194524" quat="0.97565 0.218877 0.0140974 0.000916422" mass="0.788885" diaginertia="0.000471263 0.00118686 0.00154715"/>
          <joint name="Left_Hip_Pitch" pos="0 0 0" axis="0.00128535 0.999997 -0.00191866" stiffness="0.00392499" range="-1.78837 1.57669" armature="0.00989652" damping="0.0216971" frictionloss="0.0924149"/>
          <geom name="//unnamed_geom_33" class="visual" rgba="0.76 0.76 0.76 1" mesh="Hip_Pitch_Left"/>
          <body name="Hip_Roll_Left" pos="0.00272851 -0.000663768 -0.0212172" quat="0.999999 0.00060081 -0.000874767 0.00104133">
            <inertial pos="0.00281703 0.000842103 -0.0556068" quat="0.706253 -0.00352672 -0.00576551 0.707927" mass="0.28125" diaginertia="0.000432797 0.00116411 0.000589735"/>
            <joint name="Left_Hip_Roll" pos="0 0 0" axis="-0.999905 -0.000889218 -0.0137608" range="-1.51379 0.210233" armature="0.00875075" damping="0.00243481" frictionloss="0.0928116"/>
            <geom name="//unnamed_geom_34" class="visual" mesh="Hip_Roll_Left"/>
            <geom name="//unnamed_geom_35" class="reward_collision_sphere" size="0.0505807"/>
            <body name="Hip_Yaw_Left" pos="0.00164435 -0.0011039 -0.0847679" quat="0.999999 0.000177841 0.000375117 0.00130171">
              <inertial pos="-0.00778914 0.000748604 -0.0919856" quat="0.700409 -0.0342107 -0.0324165 0.712184" mass="1.6925" diaginertia="0.00714627 0.020459 0.0031528"/>
              <joint name="Left_Hip_Yaw" pos="0 0 0" axis="-3.33694e-05 3.9991e-05 -1" range="-0.951317 1.05874" armature="0.00922926" damping="0.00629435" frictionloss="0.102674"/>
              <geom name="//unnamed_geom_36" class="visual" mesh="Hip_Yaw_Left"/>
              <geom name="//unnamed_geom_37" class="collision" size="0.0459825 0.0735719" type="cylinder"/>
              <body name="Shank_Left" pos="-0.0113465 0.00216938 -0.139158" quat="1 -4.54741e-05 3.99182e-05 8.61293e-05">
                <inertial pos="-0.00727662 -1.88039e-05 -0.129763" quat="0.998111 -0.000544994 -0.0299458 0.053641" mass="1.33461" diaginertia="0.00927021 0.0284994 0.00228922"/>
                <joint name="Left_Knee_Pitch" pos="0 0 0" axis="0.00469145 0.999946 0.00930863" range="0.0053679 2.38185" armature="0.00833702" damping="0.00777018" frictionloss="0.104345"/>
                <geom name="//unnamed_geom_38" class="visual" mesh="Shank_Left"/>
                <geom name="//unnamed_geom_39" class="collision" size="0.0459825 0.0689737" pos="0 0 -0.124433" type="cylinder"/>
                <geom name="//unnamed_geom_40" class="reward_collision_sphere" size="0.0597772"/>
                <body name="Ankle_Cross_Left" pos="0.00110058 0.000139846 -0.291194" quat="1 4.12753e-06 5.25625e-05 0.0001436">
                  <inertial pos="-0.00288275 -0.000776614 -0.00802983" quat="0.442602 0.552299 0.550182 0.443135" mass="0.0573681" diaginertia="7.81073e-06 2.05252e-05 1.35548e-05"/>
                  <joint name="Left_Ankle_Pitch" pos="0 0 0" axis="0.00519793 0.999963 -0.00691928" range="-0.872474 0.316016" armature="0.010444" damping="0.0135875" frictionloss="0.0910671"/>
                  <geom name="//unnamed_geom_41" class="visual" mesh="Ankle_Cross_Left"/>
                  <body name="left_foot_link" pos="0.0019202 -0.000445683 -0.012931" quat="1 1.79119e-05 -0.000156336 6.75928e-05">
                    <inertial pos="-0.00270815 0.00172231 -0.00952489" quat="-0.000288529 0.622798 0.00246373 0.782379" mass="0.537513" diaginertia="0.000709056 0.00186147 0.00253215"/>
                    <joint name="Left_Ankle_Roll" pos="0 0 0" axis="-0.999986 -0.00480417 0.00215822" range="-0.421984 0.432106" armature="0.00932178" damping="0.000617877" frictionloss="0.0955514"/>
                    <geom name="//unnamed_geom_42" class="visual" mesh="left_foot_link"/>
                    <geom name="left_foot" class="foot" size="0.101497 0.0445057 0.013863" pos="0.00767132 0 -0.0155541"/>
                    <geom name="//unnamed_geom_44" class="reward_collision_sphere" size="0.0478218" pos="0.00767132 0 -0.0155541"/>
                    <geom name="//unnamed_geom_45" class="reward_collision_sphere" size="0.0275895" pos="0.0728776 -0.0219621 -0.0155541"/>
                    <geom name="//unnamed_geom_46" class="reward_collision_sphere" size="0.0275895" pos="-0.0536993 -0.0219621 -0.0155541"/>
                    <site name="left_foot" class="foot" pos="0.00767132 0 -0.0155541" size="0.00919649"/>
                  </body>
                </body>
              </body>
            </body>
          </body>
        </body>
        <body name="Hip_Pitch_Right" pos="-0.000471293 -0.100448 -0.00120477" quat="1 -8.79545e-05 6.97069e-05 -3.38549e-05">
          <inertial pos="0.00103691 0.00734696 -0.0210739" quat="0.9725 -0.232361 0.0148566 -0.0056803" mass="0.789035" diaginertia="0.000463446 0.0011994 0.00150279"/>
          <joint name="Right_Hip_Pitch" pos="0 0 0" axis="-0.000987454 -0.999999 -0.00087377" range="-1.62199 1.85429" armature="0.00919659" damping="0.0198348" frictionloss="0.0797408"/>
          <geom name="//unnamed_geom_47" class="visual" rgba="0.76 0.76 0.76 1" mesh="Hip_Pitch_Right"/>
          <body name="Hip_Roll_Right" pos="0.00279097 0.000275381 -0.0215462" quat="1 0.000274562 0.000166058 -0.000110218">
            <inertial pos="0.0018488 -0.00257007 -0.0534547" quat="0.708023 -0.00834944 -0.0027482 0.706134" mass="0.290644" diaginertia="0.000451662 0.00117302 0.000619353"/>
            <joint name="Right_Hip_Roll" pos="0 0 0" axis="-0.999888 0.00383142 -0.014459" range="-0.205185 1.59308" armature="0.00849433" damping="0.00413838" frictionloss="0.0871342"/>
            <geom name="//unnamed_geom_48" class="visual" mesh="Hip_Roll_Right"/>
            <geom name="//unnamed_geom_49" class="reward_collision_sphere" size="0.0505807"/>
            <body name="Hip_Yaw_Right" pos="-0.000960751 -0.000244209 -0.0876316" quat="1 0.000371795 -0.000237642 -2.71147e-06">
              <inertial pos="-0.00431615 0.00210071 -0.0939123" quat="0.716617 -0.0420434 -0.0405264 0.695018" mass="1.69221" diaginertia="0.00692453 0.0201787 0.0031381"/>
              <joint name="Right_Hip_Yaw" pos="0 0 0" axis="-0.00209048 -0.00286161 -0.999994" stiffness="0.00117839" range="-0.989618 0.984155" armature="0.00974287" damping="0.0149312" frictionloss="0.0915188"/>
              <geom name="//unnamed_geom_50" class="visual" mesh="Hip_Yaw_Right"/>
              <geom name="//unnamed_geom_51" class="collision" size="0.0459825 0.0735719" type="cylinder"/>
              <body name="Shank_Right" pos="-0.00962725 -0.00282513 -0.137254" quat="1 -3.19255e-06 1.27503e-05 -0.000102063">
                <inertial pos="-0.00711399 0.00208898 -0.127733" quat="0.999022 -0.00850804 -0.0315415 -0.029804" mass="1.41694" diaginertia="0.00896349 0.0267843 0.00231954"/>
                <joint name="Right_Knee_Pitch" pos="0 0 0" axis="0.00627225 -0.999978 -0.00225193" range="-2.35802 0.00623947" armature="0.00916573" damping="0.00258844" frictionloss="0.0910396"/>
                <geom name="//unnamed_geom_52" class="visual" mesh="Shank_Right"/>
                <geom name="//unnamed_geom_53" class="collision" size="0.0459825 0.0689737" pos="0 0 -0.124433" type="cylinder"/>
                <geom name="//unnamed_geom_54" class="reward_collision_sphere" size="0.0597772"/>
                <body name="Ankle_Cross_Right" pos="-0.000963793 -0.00148829 -0.289685" quat="1 1.14194e-05 2.76898e-07 -5.29441e-05">
                  <inertial pos="-0.00196022 -0.00221774 -0.0092299" quat="0.451895 0.554065 0.54819 0.433924" mass="0.0568025" diaginertia="7.70614e-06 1.90621e-05 1.3071e-05"/>
                  <joint name="Right_Ankle_Pitch" pos="0 0 0" axis="-0.00810913 -0.999965 -0.00192655" range="-0.34052 0.868495" armature="0.00996431" damping="0" frictionloss="0.089399"/>
                  <geom name="//unnamed_geom_55" class="visual" mesh="Ankle_Cross_Right"/>
                  <body name="right_foot_link" pos="-0.000437397 -0.00157097 -0.00965396" quat="1 1.9788e-05 4.32844e-05 2.27617e-05">
                    <inertial pos="0.000933369 -0.000300776 -0.00689611" quat="0.00480716 0.621335 -0.00346895 0.783523" mass="0.538896" diaginertia="0.000737658 0.0018737 0.00260107"/>
                    <joint name="Right_Ankle_Roll" pos="0 0 0" axis="-0.99999 0.000308922 -0.00454182" stiffness="0.00195082" range="-0.452162 0.411229" armature="0.00948131" damping="0.0133241" frictionloss="0.0846937"/>
                    <geom name="//unnamed_geom_56" class="visual" mesh="right_foot_link"/>
                    <geom name="right_foot" class="foot" size="0.104368 0.0444273 0.0139186" pos="0.00767132 0 -0.0155541"/>
                    <geom name="//unnamed_geom_58" class="reward_collision_sphere" size="0.036786"/>
                    <geom name="//unnamed_geom_59" class="reward_collision_sphere" size="0.0275895" pos="0.00767132 0 -0.0155541"/>
                    <geom name="//unnamed_geom_60" class="reward_collision_sphere" size="0.0275895" pos="0.0728776 0.0219621 -0.0155541"/>
                    <geom name="//unnamed_geom_61" class="reward_collision_sphere" size="0.0275895" pos="-0.0536993 0.0219621 -0.0155541"/>
                    <site name="right_foot" class="foot" pos="0.00767132 0 -0.0155541" size="0.00919649"/>
                  </body>
                </body>
              </body>
            </body>
          </body>
        </body>
      </body>
    </body>
  </worldbody>

  <contact>
    <pair class="/" geom1="floor" geom2="left_foot" name="//unnamed_contact_0"/>
    <pair class="/" geom1="floor" geom2="right_foot" name="//unnamed_contact_1"/>
  </contact>

  <actuator>
    <general name="AAHead_yaw" class="/" joint="AAHead_yaw" forcerange="-6.86413 6.86413" gainprm="22.6887" biasprm="0 -22.6887 -0.50972"/>
    <general name="Head_pitch" class="/" joint="Head_pitch" forcerange="-6.18815 6.18815" gainprm="22.6887" biasprm="0 -22.6887 -0.50972"/>
    <general name="Left_Shoulder_Pitch" class="/" joint="Left_Shoulder_Pitch" forcerange="-16.4565 16.4565" gainprm="22.6887" biasprm="0 -22.6887 -0.50972"/>
    <general name="Left_Shoulder_Roll" class="/" joint="Left_Shoulder_Roll" forcerange="-16.2071 16.2071" gainprm="22.6887" biasprm="0 -22.6887 -0.50972"/>
    <general name="Left_Elbow_Pitch" class="/" joint="Left_Elbow_Pitch" forcerange="-17.8332 17.8332" gainprm="22.6887" biasprm="0 -22.6887 -0.50972"/>
    <general name="Left_Elbow_Yaw" class="/" joint="Left_Elbow_Yaw" forcerange="-17.2847 17.2847" gainprm="22.6887" biasprm="0 -22.6887 -0.50972"/>
    <general name="Right_Shoulder_Pitch" class="/" joint="Right_Shoulder_Pitch" forcerange="-16.6555 16.6555" gainprm="22.6887" biasprm="0 -22.6887 -0.50972"/>
    <general name="Right_Shoulder_Roll" class="/" joint="Right_Shoulder_Roll" forcerange="-17.1748 17.1748" gainprm="22.6887" biasprm="0 -22.6887 -0.50972"/>
    <general name="Right_Elbow_Pitch" class="/" joint="Right_Elbow_Pitch" forcerange="-16.6026 16.6026" gainprm="22.6887" biasprm="0 -22.6887 -0.50972"/>
    <general name="Right_Elbow_Yaw" class="/" joint="Right_Elbow_Yaw" forcerange="-15.8481 15.8481" gainprm="22.6887" biasprm="0 -22.6887 -0.50972"/>
    <general name="Waist" class="/" joint="Waist" forcerange="-28.5843 28.5843" gainprm="22.6887" biasprm="0 -22.6887 -0.50972"/>
    <general name="Left_Hip_Pitch" class="/" joint="Left_Hip_Pitch" forcerange="-40.9761 40.9761" gainprm="22.6887" biasprm="0 -22.6887 -0.50972"/>
    <general name="Left_Hip_Roll" class="/" joint="Left_Hip_Roll" forcerange="-26.559 26.559" gainprm="22.6887" biasprm="0 -22.6887 -0.50972"/>
    <general name="Left_Hip_Yaw" class="/" joint="Left_Hip_Yaw" forcerange="-25.5529 25.5529" gainprm="22.6887" biasprm="0 -22.6887 -0.50972"/>
    <general name="Left_Knee_Pitch" class="/" joint="Left_Knee_Pitch" forcerange="-55.263 55.263" gainprm="22.6887" biasprm="0 -22.6887 -0.50972"/>
    <general name="Left_Ankle_Pitch" class="/" joint="Left_Ankle_Pitch" forcerange="-17.956 17.956" gainprm="22.6887" biasprm="0 -22.6887 -0.50972"/>
    <general name="Left_Ankle_Roll" class="/" joint="Left_Ankle_Roll" forcerange="-13.5262 13.5262" gainprm="22.6887" biasprm="0 -22.6887 -0.50972"/>
    <general name="Right_Hip_Pitch" class="/" joint="Right_Hip_Pitch" forcerange="-41.0788 41.0788" gainprm="22.6887" biasprm="0 -22.6887 -0.50972"/>
    <general name="Right_Hip_Roll" class="/" joint="Right_Hip_Roll" forcerange="-28.4317 28.4317" gainprm="22.6887" biasprm="0 -22.6887 -0.50972"/>
    <general name="Right_Hip_Yaw" class="/" joint="Right_Hip_Yaw" forcerange="-28.2849 28.2849" gainprm="22.6887" biasprm="0 -22.6887 -0.50972"/>
    <general name="Right_Knee_Pitch" class="/" joint="Right_Knee_Pitch" forcerange="-50.7263 50.7263" gainprm="22.6887" biasprm="0 -22.6887 -0.50972"/>
    <general name="Right_Ankle_Pitch" class="/" joint="Right_Ankle_Pitch" forcerange="-16.6733 16.6733" gainprm="22.6887" biasprm="0 -22.6887 -0.50972"/>
    <general name="Right_Ankle_Roll" class="/" joint="Right_Ankle_Roll" forcerange="-13.4347 13.4347" gainprm="22.6887" biasprm="0 -22.6887 -0.50972"/>
  </actuator>

  <sensor>
    <gyro site="imu" name="imu_angular_velocity"/>
    <velocimeter site="imu" name="imu_linear_velocity"/>
    <framelinvel objtype="site" objname="left_foot" name="left_foot_global_linear_velocity"/>
    <framelinvel objtype="site" objname="right_foot" name="right_foot_global_linear_velocity"/>
  </sensor>

  <keyframe>
    <key name="home" qpos="0 0 0.6385 1 0 0 0 0 0 0 1.4 0 -0.4 0 -1.4 0 0.4 0 -0.4 0 0 0.8 -0.4 0 0.4 0 0 -0.8 0.4 0"/>
  </keyframe>
</mujoco>
