<mujoco model="T1">
  <compiler angle="radian" assetdir="assets" balanceinertia="true" inertiafromgeom="false"/>

  <option timestep="0.005" density="1.2" viscosity="2e-05"/>

  <size nkey="1"/>

  <visual>
    <quality shadowsize="8192"/>
    <map shadowclip="0.5"/>
  </visual>

  <default>
    <default class="/">
      <joint armature="0.01" damping="0.01" frictionloss="0.1"/>
      <geom contype="0" conaffinity="0" group="1" solref="-1000 -80"/>
      <site size="0.01 0.005 0.005" group="5"/>
      <general forcelimited="true" biastype="affine" gainprm="25" biasprm="0 -25 -0.6"/>
      <default class="t1">
        <geom rgba="0.25 0.25 0.25 1"/>
        <default class="visual">
          <geom type="mesh" group="2"/>
        </default>
        <default class="collision">
          <geom group="3"/>
        </default>
        <default class="foot">
          <geom size="0.1115 0.05 0.015" type="box" condim="6" group="4" priority="1" solimp="0.015 1 0.015"/>
        </default>
        <default class="reward_collision_sphere">
          <geom group="5" rgba="1 0 0 1"/>
        </default>
      </default>
    </default>
  </default>

  <asset>
    <texture type="skybox" colorspace="auto" name="//unnamed_texture_0" builtin="gradient" rgb1="0.95 0.95 0.95" rgb2="0.95 0.95 0.95" width="100" height="600"/>
    <texture type="2d" colorspace="auto" name="texplane" builtin="checker" rgb1="0.345 0.575 0.748" rgb2="0.345 0.575 0.748" markrgb="1 1 1" width="512" height="512"/>
    <material name="MatPlane" class="/" texture="texplane" texuniform="true" texrepeat="2 2" specular="0.9"/>
    <mesh name="Trunk" class="/" file="Trunk.stl"/>
    <mesh name="H1" class="/" file="H1.stl"/>
    <mesh name="H2" class="/" file="H2.stl"/>
    <mesh name="AL1" class="/" file="AL1.stl"/>
    <mesh name="AL2" class="/" file="AL2.stl"/>
    <mesh name="AL3" class="/" file="AL3.stl"/>
    <mesh name="left_hand_link" class="/" file="left_hand_link.stl"/>
    <mesh name="AR1" class="/" file="AR1.stl"/>
    <mesh name="AR2" class="/" file="AR2.stl"/>
    <mesh name="AR3" class="/" file="AR3.stl"/>
    <mesh name="right_hand_link" class="/" file="right_hand_link.stl"/>
    <mesh name="Waist" class="/" file="Waist.stl"/>
    <mesh name="Hip_Pitch_Left" class="/" file="Hip_Pitch_Left.stl"/>
    <mesh name="Hip_Roll_Left" class="/" file="Hip_Roll_Left.stl"/>
    <mesh name="Hip_Yaw_Left" class="/" file="Hip_Yaw_Left.stl"/>
    <mesh name="Shank_Left" class="/" file="Shank_Left.stl"/>
    <mesh name="Ankle_Cross_Left" class="/" file="Ankle_Cross_Left.stl"/>
    <mesh name="left_foot_link" class="/" file="left_foot_link.stl"/>
    <mesh name="Hip_Pitch_Right" class="/" file="Hip_Pitch_Right.stl"/>
    <mesh name="Hip_Roll_Right" class="/" file="Hip_Roll_Right.stl"/>
    <mesh name="Hip_Yaw_Right" class="/" file="Hip_Yaw_Right.stl"/>
    <mesh name="Shank_Right" class="/" file="Shank_Right.stl"/>
    <mesh name="Ankle_Cross_Right" class="/" file="Ankle_Cross_Right.stl"/>
    <mesh name="right_foot_link" class="/" file="right_foot_link.stl"/>
  </asset>

  <worldbody>
    <geom name="floor" class="/" size="100 100 0.125" type="plane" group="0" material="MatPlane"/>
    <light name="toplight_shadow" class="/" pos="0 0 5" dir="0.0990148 0.0990148 -0.990148" type="directional" ambient="0.04 0.04 0.04" diffuse="0.55 0.55 0.55" specular="0.12 0.12 0.12"/>
    <light name="toplight_fill" class="/" pos="0 0 5" dir="0.0990148 0.0990148 -0.990148" type="directional" castshadow="false" ambient="0.04 0.04 0.04" diffuse="0.3 0.3 0.3" specular="0.08 0.08 0.08"/>
    <body name="trunk" childclass="t1" pos="0.000860678 -0.00214538 -0.000238541" quat="0.999999 -0.000100032 0.000969146 -0.000364247">
      <inertial pos="0.0329092 0.000233706 0.130479" quat="0.99998 -0.00236048 -0.00582808 -0.000994691" mass="7.82236" diaginertia="0.00766097 0.0253063 0.157211"/>
      <joint name="//unnamed_joint_0" type="free" armature="0" damping="0" frictionloss="0"/>
      <geom name="//unnamed_geom_1" class="visual" rgba="0.76 0.76 0.76 1" mesh="Trunk"/>
      <geom name="//unnamed_geom_2" class="collision" size="0.0659553 0.0879404 0.131911" pos="0.0365809 0 0.146742" type="box"/>
      <geom name="//unnamed_geom_3" class="reward_collision_sphere" size="0.101132" pos="0.0365809 0 0.122285"/>
      <geom name="//unnamed_geom_4" class="reward_collision_sphere" size="0.0131911" pos="0.0365809 0.0684826 0"/>
      <geom name="//unnamed_geom_5" class="reward_collision_sphere" size="0.0131911" pos="0.0365809 -0.0684826 0"/>
      <geom name="//unnamed_geom_6" class="reward_collision_sphere" size="0.0131911" pos="0.0365809 0.0862076 0.220114"/>
      <geom name="//unnamed_geom_7" class="reward_collision_sphere" size="0.0131911" pos="0.0365809 -0.0862076 0.220114"/>
      <site name="imu" pos="0.0191546 -0.020994 0.0181012" size="0.00879404"/>
      <camera name="track" pos="0 -1.61136 0" quat="0.707107 0.707107 0 0" mode="trackcom"/>
      <camera name="ego_camera" pos="0.0743812 0 0.513598" quat="-0.5 -0.5 0.5 0.5"/>
      <body name="H1" pos="0.0375871 -0.00285382 0.294732" quat="0.999998 0.000542487 0.00164605 -6.38275e-05">
        <inertial pos="-0.000876652 0.000128831 0.0724041" quat="0.76222 -0.0155983 -0.00907491 0.647067" mass="0.275153" diaginertia="2.00366e-05 7.57196e-05 0.000401343"/>
        <joint name="AAHead_yaw" pos="0 0 0" axis="-0.00262288 -0.000584548 0.999996" range="-1.52148 1.57342" armature="0.00692968" damping="0.0171023" frictionloss="0.0853209"/>
        <geom name="//unnamed_geom_8" class="visual" mesh="H1"/>
        <body name="H2" pos="-0.00546489 -0.000495984 0.0760546" quat="1 0.000436504 -0.000239712 -0.000306406">
          <inertial pos="0.00457688 0.00249787 0.119607" quat="0.988764 0.103313 -0.0824993 -0.0697508" mass="0.411349" diaginertia="0.000169936 0.000641163 0.00471026"/>
          <joint name="Head_pitch" pos="0 0 0" axis="0.00272459 -0.999996 0.000113006" range="-1.27073 0.340885" armature="0.00984856" damping="0" frictionloss="0.0790061"/>
          <geom name="//unnamed_geom_9" class="visual" mesh="H2"/>
          <geom name="//unnamed_geom_10" class="collision" size="0.0703524" pos="0.00609682 0 0.134514"/>
          <geom name="//unnamed_geom_11" class="reward_collision_sphere" size="0.0791464" pos="0.0121936 0 0.122285"/>
        </body>
      </body>
      <body name="AL1" pos="0.0401531 0.0856284 0.270479" quat="1 0.000521742 0.000248822 -4.38479e-06">
        <inertial pos="-7.89827e-05 0.0342246 0.000278595" quat="0.499852 0.502253 -0.497264 0.500618" mass="0.365828" diaginertia="0.000115649 0.00042771 0.000780692"/>
        <joint name="Left_Shoulder_Pitch" pos="0 0 0" axis="0.0107997 0.999941 0.000661512" range="-3.26999 1.18791" armature="0.00781591" damping="0.0104271" frictionloss="0.0872828"/>
        <geom name="//unnamed_geom_12" class="visual" rgba="0.76 0.76 0.76 1" mesh="AL1"/>
        <body name="AL2" pos="0.00128394 0.0397449 -0.000108678" quat="1 -0.000211299 -0.000214995 -6.35584e-05">
          <inertial pos="0.00439352 0.0280811 -0.00270958" quat="0.486842 0.512035 -0.485846 0.514547" mass="0.104909" diaginertia="3.40098e-05 0.000121211 0.000487432"/>
          <joint name="Left_Shoulder_Roll" pos="0 0 0" axis="-0.99999 0.00329006 -0.00317902" range="-1.64447 1.66901" armature="0.0103042" damping="0.0028822" frictionloss="0.0887372"/>
          <geom name="//unnamed_geom_13" class="visual" mesh="AL2"/>
          <body name="AL3" pos="-3.28966e-05 0.0469438 0.00277113" quat="0.999999 -0.000354695 0.000771945 0.000595755">
            <inertial pos="-0.000259333 0.0690042 -0.000915472" quat="0.708202 0.705987 0.00247923 0.00513645" mass="0.655853" diaginertia="0.00106168 0.00422121 0.00174412"/>
            <joint name="Left_Elbow_Pitch" pos="0 0 0" axis="0.0194952 -0.99971 0.0141517" stiffness="0.025164" range="-2.34824 2.23683" armature="0.0110561" damping="0.0389896" frictionloss="0.0908451"/>
            <geom name="//unnamed_geom_14" class="visual" mesh="AL3"/>
            <geom name="//unnamed_geom_15" class="collision" size="0.0263821 0.0659553" pos="0 0.0402839 0" quat="0.707105 0.707108 0 0" type="cylinder"/>
            <geom name="//unnamed_geom_16" class="reward_collision_sphere" size="0.0316586"/>
            <body name="left_hand_link" pos="0.00144312 0.117495 -0.00265309" quat="1 -0.00023787 6.59533e-05 0.000689253">
              <inertial pos="-0.0011713 0.0907029 0.00155896" quat="0.707934 0.706279 0.000107837 0.000121004" mass="0.226714" diaginertia="0.000662673 0.00268451 0.000609019"/>
              <joint name="Left_Elbow_Yaw" pos="0 0 0" axis="-0.000938631 -0.000156578 1" range="-2.46974 0.0240583" armature="0.00701724" damping="0.015806" frictionloss="0.0854113"/>
              <geom name="//unnamed_geom_17" class="visual" mesh="left_hand_link"/>
              <geom name="//unnamed_geom_18" class="collision" size="0.0263821 0.0769479" pos="0 0.104738 0" quat="0.707105 0.707108 0 0" type="cylinder"/>
              <geom name="//unnamed_geom_19" class="reward_collision_sphere" size="0.0439702"/>
              <geom name="//unnamed_geom_20" class="reward_collision_sphere" size="0.0307792" pos="0 0.0886246 0"/>
              <geom name="//unnamed_geom_21" class="reward_collision_sphere" size="0.0307792" pos="0 0.173221 0"/>
            </body>
          </body>
        </body>
      </body>
      <body name="AR1" pos="0.0369682 -0.0844556 0.267093" quat="0.999999 0.000721065 0.000411937 -0.000761284">
        <inertial pos="0.00292696 -0.0343208 -0.000729755" quat="0.524696 0.487257 -0.501139 0.485936" mass="0.367505" diaginertia="0.000114086 0.000435367 0.000766053"/>
        <joint name="Right_Shoulder_Pitch" pos="0 0 0" axis="-0.00517791 -0.999975 0.0048961" range="-1.2248 3.29896" armature="0.00874342" damping="0.00208446" frictionloss="0.0905129"/>
        <geom name="//unnamed_geom_22" class="visual" rgba="0.76 0.76 0.76 1" mesh="AR1"/>
        <body name="AR2" pos="-0.00265999 -0.0397232 -0.00123837" quat="0.999999 -0.000228085 -0.000307295 -0.0010071">
          <inertial pos="0.00478297 -0.0284805 0.00143197" quat="0.511412 0.487249 -0.51267 0.488073" mass="0.107328" diaginertia="3.44512e-05 0.000113482 0.000488662"/>
          <joint name="Right_Shoulder_Roll" pos="0 0 0" axis="-0.999939 0.000457541 -0.0110747" range="-1.71912 1.4861" armature="0.00922207" damping="0.00648037" frictionloss="0.098058"/>
          <geom name="//unnamed_geom_23" class="visual" mesh="AR2"/>
          <body name="AR3" pos="-0.00201446 -0.0517619 0.00287068" quat="1 -0.000155442 -0.000390879 0.000216614">
            <inertial pos="0.000681684 -0.0652032 -0.00162967" quat="0.709705 0.704491 0.000821603 -0.00315901" mass="0.70809" diaginertia="0.0010895 0.00434667 0.00165178"/>
            <joint name="Right_Elbow_Pitch" pos="0 0 0" axis="0.00358202 0.999969 0.00701972" stiffness="0.00742756" range="-2.26337 2.28729" armature="0.00862664" damping="0" frictionloss="0.0896523"/>
            <geom name="//unnamed_geom_24" class="visual" mesh="AR3"/>
            <geom name="//unnamed_geom_25" class="collision" size="0.0263821 0.0659553" pos="0 -0.0402839 0" quat="0.707105 0.707108 0 0" type="cylinder"/>
            <geom name="//unnamed_geom_26" class="reward_collision_sphere" size="0.0316586"/>
            <body name="right_hand_link" pos="-0.00266172 -0.117768 -0.00226178" quat="1 -0.000647354 6.84581e-05 0.000445841">
              <inertial pos="-0.000870579 -0.0908812 0.00222529" quat="0.70977 0.7044 0.00690764 8.23855e-05" mass="0.21767" diaginertia="0.000712669 0.00277005 0.000595221"/>
              <joint name="Right_Elbow_Yaw" pos="0 0 0" axis="-0.0105741 0.00639542 0.999924" range="0.0441382 2.43338" armature="0.00987925" damping="0" frictionloss="0.0867104"/>
              <geom name="//unnamed_geom_27" class="visual" mesh="right_hand_link"/>
              <geom name="//unnamed_geom_28" class="collision" size="0.0263821 0.0769479" pos="0 -0.104738 0" quat="0.707105 0.707108 0 0" type="cylinder"/>
              <geom name="//unnamed_geom_29" class="reward_collision_sphere" size="0.0439702"/>
              <geom name="//unnamed_geom_30" class="reward_collision_sphere" size="0.0307792" pos="0 -0.0886246 0"/>
              <geom name="//unnamed_geom_31" class="reward_collision_sphere" size="0.0307792" pos="0 -0.173221 0"/>
            </body>
          </body>
        </body>
      </body>
      <body name="Waist" pos="0.0344133 0.00299944 -0.141649" quat="1 -0.00077019 0.000194205 0.000124045">
        <inertial pos="0.00696359 -0.000972986 0.0086101" quat="0.983446 -0.00632593 -0.181071 -0.00286636" mass="1.65555" diaginertia="0.000464915 0.00169444 0.0128051"/>
        <joint name="Waist" pos="0 0 0" axis="0.0203396 -0.00628958 0.999773" range="-1.52434 1.52743" armature="0.00821638" damping="0" frictionloss="0.0900895"/>
        <geom name="//unnamed_geom_32" class="visual" mesh="Waist"/>
        <body name="Hip_Pitch_Left" pos="0.00387159 0.0850631 -0.000538899" quat="0.999996 -0.0011307 -0.00246132 0.000582065">
          <inertial pos="0.00170949 -0.00984363 -0.022856" quat="0.974673 0.223073 0.0155864 0.00276486" mass="0.743912" diaginertia="0.000160582 0.000505473 0.00343057"/>
          <joint name="Left_Hip_Pitch" pos="0 0 0" axis="-0.00270777 0.999915 0.0127486" stiffness="0.00946459" range="-1.85545 1.58095" armature="0.0094297" damping="0.00195375" frictionloss="0.0689364"/>
          <geom name="//unnamed_geom_33" class="visual" rgba="0.76 0.76 0.76 1" mesh="Hip_Pitch_Left"/>
          <body name="Hip_Roll_Left" pos="-0.0046102 -0.00056546 -0.0191776" quat="0.999996 0.00244477 -0.00140456 0.000695689">
            <inertial pos="0.000646235 -0.0016678 -0.0620653" quat="0.708841 -0.00484491 -0.0143113 0.705207" mass="0.269794" diaginertia="0.00014673 0.000540102 0.00145631"/>
            <joint name="Left_Hip_Roll" pos="0 0 0" axis="-0.999894 0.0121708 -0.00800252" stiffness="0.00704335" range="-1.57295 0.20521" armature="0.00858499" damping="0.00125756" frictionloss="0.089768"/>
            <geom name="//unnamed_geom_34" class="visual" mesh="Hip_Roll_Left"/>
            <geom name="//unnamed_geom_35" class="reward_collision_sphere" size="0.0483672"/>
            <body name="Hip_Yaw_Left" pos="0.00226716 0.00215566 -0.0996513" quat="1 -0.000247509 0.000550505 -0.000492612">
              <inertial pos="-0.00339889 -0.00553092 -0.112622" quat="0.7049 -0.0348143 -0.0270049 0.707937" mass="1.40049" diaginertia="0.00205529 0.00814435 0.00690801"/>
              <joint name="Left_Hip_Yaw" pos="0 0 0" axis="-0.0065064 0.00771372 -0.999949" range="-1.0253 1.00061" armature="0.0087444" damping="0" frictionloss="0.0871936"/>
              <geom name="//unnamed_geom_36" class="visual" mesh="Hip_Yaw_Left"/>
              <geom name="//unnamed_geom_37" class="collision" size="0.0439702 0.0703524" type="cylinder"/>
              <body name="Shank_Left" pos="-0.0120543 0.00306793 -0.16449" quat="1 0.000699836 -0.000271532 -1.96693e-05">
                <inertial pos="-0.00410682 0.000403576 -0.150248" quat="0.99665 0.00439482 -0.0189634 0.0794388" mass="1.10427" diaginertia="0.00285305 0.011473 0.00490641"/>
                <joint name="Left_Knee_Pitch" pos="0 0 0" axis="0.0127987 0.999917 -0.00154568" range="0.00639037 2.38665" armature="0.00825308" damping="0.00118864" frictionloss="0.0884567"/>
                <geom name="//unnamed_geom_38" class="visual" mesh="Shank_Left"/>
                <geom name="//unnamed_geom_39" class="collision" size="0.0439702 0.0659553" pos="0 0 -0.146742" type="cylinder"/>
                <geom name="//unnamed_geom_40" class="reward_collision_sphere" size="0.0571613"/>
                <body name="Ankle_Cross_Left" pos="0.000289573 0.00107534 -0.34141" quat="1 -3.72979e-05 0.000655857 -0.000524704">
                  <inertial pos="-0.00401975 0.00104495 -0.00750385" quat="0.443149 0.555473 0.548536 0.440656" mass="0.050997" diaginertia="2.47519e-06 8.97066e-06 3.18713e-05"/>
                  <joint name="Left_Ankle_Pitch" pos="0 0 0" axis="0.000439032 0.999994 0.0033392" range="-0.786901 0.270206" armature="0.0088527" damping="0.0335106" frictionloss="0.0895147"/>
                  <geom name="//unnamed_geom_41" class="visual" mesh="Ankle_Cross_Left"/>
                  <body name="left_foot_link" pos="-0.000834341 -0.00121536 -0.0118315" quat="0.999998 0.000987826 -0.00146011 0.00108964">
                    <inertial pos="-0.00278536 0.00302267 -0.00958629" quat="0.00596365 0.622271 -0.00373961 0.78277" mass="0.427551" diaginertia="0.000206674 0.000754254 0.00518753"/>
                    <joint name="Left_Ankle_Roll" pos="0 0 0" axis="-0.999934 -0.0105946 -0.00440813" range="-0.440056 0.351592" armature="0.00844166" damping="0.00684513" frictionloss="0.0623248"/>
                    <geom name="//unnamed_geom_42" class="visual" mesh="left_foot_link"/>
                    <geom name="left_foot" class="foot" size="0.104832 0.0518296 0.0102835" pos="0.00609682 0 -0.0183428"/>
                    <geom name="//unnamed_geom_44" class="reward_collision_sphere" size="0.045729" pos="0.00609682 0 -0.0183428"/>
                    <geom name="//unnamed_geom_45" class="reward_collision_sphere" size="0.0263821" pos="0.0579198 -0.0185306 -0.0183428"/>
                    <geom name="//unnamed_geom_46" class="reward_collision_sphere" size="0.0263821" pos="-0.0426777 -0.0185306 -0.0183428"/>
                    <site name="left_foot" class="foot" pos="0.00609682 0 -0.0183428" size="0.00879404"/>
                  </body>
                </body>
              </body>
            </body>
          </body>
        </body>
        <body name="Hip_Pitch_Right" pos="-0.000584146 -0.0859321 0.000745008" quat="1 -7.29852e-05 -0.000673617 -0.000188782">
          <inertial pos="-0.00166754 0.0056408 -0.0232267" quat="0.972588 -0.231495 0.0126624 0.0179673" mass="0.719753" diaginertia="0.000160646 0.000533889 0.00352709"/>
          <joint name="Right_Hip_Pitch" pos="0 0 0" axis="0.00717176 -0.999974 -0.000176879" stiffness="0.00262582" range="-1.55297 1.7842" armature="0.00943801" damping="0.00690264" frictionloss="0.0849802"/>
          <geom name="//unnamed_geom_47" class="visual" rgba="0.76 0.76 0.76 1" mesh="Hip_Pitch_Right"/>
          <body name="Hip_Roll_Right" pos="-0.00106474 -0.000670923 -0.0207705" quat="0.999999 -0.000957805 0.00036538 -0.000436461">
            <inertial pos="-0.000854039 1.95197e-05 -0.0653449" quat="0.709797 -0.00610934 -0.00230973 0.704376" mass="0.275255" diaginertia="0.000152574 0.000537471 0.00149891"/>
            <joint name="Right_Hip_Roll" pos="0 0 0" axis="-0.999875 -0.000649262 -0.0157944" stiffness="0.0356481" range="-0.252015 1.58679" armature="0.00848901" damping="0.00586471" frictionloss="0.0843981"/>
            <geom name="//unnamed_geom_48" class="visual" mesh="Hip_Roll_Right"/>
            <geom name="//unnamed_geom_49" class="reward_collision_sphere" size="0.0483672"/>
            <body name="Hip_Yaw_Right" pos="0.00223489 -0.00536118 -0.101123" quat="1 0.000416584 -6.2341e-05 7.96119e-05">
              <inertial pos="-0.00312499 -0.000599784 -0.104481" quat="0.709378 -0.0269488 -0.0337882 0.703502" mass="1.48005" diaginertia="0.0022492 0.00908336 0.00749463"/>
              <joint name="Right_Hip_Yaw" pos="0 0 0" axis="0.0159229 -0.00175595 -0.999872" range="-1.05573 0.9916" armature="0.00956775" damping="0" frictionloss="0.0879048"/>
              <geom name="//unnamed_geom_50" class="visual" mesh="Hip_Yaw_Right"/>
              <geom name="//unnamed_geom_51" class="collision" size="0.0439702 0.0703524" type="cylinder"/>
              <body name="Shank_Right" pos="-0.0072503 -0.00150568 -0.164433" quat="1 -0.000168257 0.000127481 -6.57984e-05">
                <inertial pos="-0.00922354 0.00284774 -0.151598" quat="0.998963 0.0050507 -0.0228063 -0.0390903" mass="1.25679" diaginertia="0.00303204 0.011781 0.00552811"/>
                <joint name="Right_Knee_Pitch" pos="0 0 0" axis="0.000999371 -0.999969 -0.00778087" range="-2.34497 0.0407166" armature="0.00884831" damping="0.00791499" frictionloss="0.0816668"/>
                <geom name="//unnamed_geom_52" class="visual" mesh="Shank_Right"/>
                <geom name="//unnamed_geom_53" class="collision" size="0.0439702 0.0659553" pos="0 0 -0.146742" type="cylinder"/>
                <geom name="//unnamed_geom_54" class="reward_collision_sphere" size="0.0571613"/>
                <body name="Ankle_Cross_Right" pos="-0.0015013 0.00426257 -0.343427" quat="0.999998 0.00142532 -0.000469162 0.00115992">
                  <inertial pos="-0.00485861 -0.000556804 -0.0119895" quat="0.443112 0.551069 0.551211 0.442878" mass="0.0501726" diaginertia="2.5502e-06 8.85213e-06 3.03663e-05"/>
                  <joint name="Right_Ankle_Pitch" pos="0 0 0" axis="0.008234 -0.999948 -0.0059533" stiffness="0.00401878" range="-0.375273 0.78099" armature="0.00821759" damping="0.00112554" frictionloss="0.0862415"/>
                  <geom name="//unnamed_geom_55" class="visual" mesh="Ankle_Cross_Right"/>
                  <body name="right_foot_link" pos="0.00113608 0.000364549 -0.0145778" quat="1 0.000672637 0.000234505 0.000340096">
                    <inertial pos="0.0012855 -0.00206427 -0.0110821" quat="-0.00538148 0.615056 0.0073692 0.78843" mass="0.468057" diaginertia="0.000239667 0.00081731 0.0058512"/>
                    <joint name="Right_Ankle_Roll" pos="0 0 0" axis="-0.999968 0.00706708 0.00381373" range="-0.428761 0.416117" armature="0.00971025" damping="0.0169726" frictionloss="0.0989832"/>
                    <geom name="//unnamed_geom_56" class="visual" mesh="right_foot_link"/>
                    <geom name="right_foot" class="foot" size="0.08726 0.0487739 0.0122473" pos="0.00609682 0 -0.0183428"/>
                    <geom name="//unnamed_geom_58" class="reward_collision_sphere" size="0.0351762"/>
                    <geom name="//unnamed_geom_59" class="reward_collision_sphere" size="0.0263821" pos="0.00609682 0 -0.0183428"/>
                    <geom name="//unnamed_geom_60" class="reward_collision_sphere" size="0.0263821" pos="0.0579198 0.0185306 -0.0183428"/>
                    <geom name="//unnamed_geom_61" class="reward_collision_sphere" size="0.0263821" pos="-0.0426777 0.0185306 -0.0183428"/>
                    <site name="right_foot" class="foot" pos="0.00609682 0 -0.0183428" size="0.00879404"/>
                  </body>
                </body>
              </body>
            </body>
          </body>
        </body>
      </body>
    </body>
  </worldbody>

  <contact>
    <pair class="/" geom1="floor" geom2="left_foot" name="//unnamed_contact_0"/>
    <pair class="/" geom1="floor" geom2="right_foot" name="//unnamed_contact_1"/>
  </contact>

  <actuator>
    <general name="AAHead_yaw" class="/" joint="AAHead_yaw" forcerange="-5.62687 5.62687" gainprm="24.1671" biasprm="0 -24.1671 -0.535347"/>
    <general name="Head_pitch" class="/" joint="Head_pitch" forcerange="-6.74179 6.74179" gainprm="24.1671" biasprm="0 -24.1671 -0.535347"/>
    <general name="Left_Shoulder_Pitch" class="/" joint="Left_Shoulder_Pitch" forcerange="-16.9026 16.9026" gainprm="24.1671" biasprm="0 -24.1671 -0.535347"/>
    <general name="Left_Shoulder_Roll" class="/" joint="Left_Shoulder_Roll" forcerange="-15.3137 15.3137" gainprm="24.1671" biasprm="0 -24.1671 -0.535347"/>
    <general name="Left_Elbow_Pitch" class="/" joint="Left_Elbow_Pitch" forcerange="-18.4278 18.4278" gainprm="24.1671" biasprm="0 -24.1671 -0.535347"/>
    <general name="Left_Elbow_Yaw" class="/" joint="Left_Elbow_Yaw" forcerange="-14.1479 14.1479" gainprm="24.1671" biasprm="0 -24.1671 -0.535347"/>
    <general name="Right_Shoulder_Pitch" class="/" joint="Right_Shoulder_Pitch" forcerange="-13.8764 13.8764" gainprm="24.1671" biasprm="0 -24.1671 -0.535347"/>
    <general name="Right_Shoulder_Roll" class="/" joint="Right_Shoulder_Roll" forcerange="-14.7352 14.7352" gainprm="24.1671" biasprm="0 -24.1671 -0.535347"/>
    <general name="Right_Elbow_Pitch" class="/" joint="Right_Elbow_Pitch" forcerange="-15.8642 15.8642" gainprm="24.1671" biasprm="0 -24.1671 -0.535347"/>
    <general name="Right_Elbow_Yaw" class="/" joint="Right_Elbow_Yaw" forcerange="-15.3511 15.3511" gainprm="24.1671" biasprm="0 -24.1671 -0.535347"/>
    <general name="Waist" class="/" joint="Waist" forcerange="-25.6983 25.6983" gainprm="24.1671" biasprm="0 -24.1671 -0.535347"/>
    <general name="Left_Hip_Pitch" class="/" joint="Left_Hip_Pitch" forcerange="-36.8003 36.8003" gainprm="24.1671" biasprm="0 -24.1671 -0.535347"/>
    <general name="Left_Hip_Roll" class="/" joint="Left_Hip_Roll" forcerange="-23.0763 23.0763" gainprm="24.1671" biasprm="0 -24.1671 -0.535347"/>
    <general name="Left_Hip_Yaw" class="/" joint="Left_Hip_Yaw" forcerange="-30.7983 30.7983" gainprm="24.1671" biasprm="0 -24.1671 -0.535347"/>
    <general name="Left_Knee_Pitch" class="/" joint="Left_Knee_Pitch" forcerange="-61.344 61.344" gainprm="24.1671" biasprm="0 -24.1671 -0.535347"/>
    <general name="Left_Ankle_Pitch" class="/" joint="Left_Ankle_Pitch" forcerange="-17.2133 17.2133" gainprm="24.1671" biasprm="0 -24.1671 -0.535347"/>
    <general name="Left_Ankle_Roll" class="/" joint="Left_Ankle_Roll" forcerange="-13.3844 13.3844" gainprm="24.1671" biasprm="0 -24.1671 -0.535347"/>
    <general name="Right_Hip_Pitch" class="/" joint="Right_Hip_Pitch" forcerange="-43.0316 43.0316" gainprm="24.1671" biasprm="0 -24.1671 -0.535347"/>
    <general name="Right_Hip_Roll" class="/" joint="Right_Hip_Roll" forcerange="-26.9124 26.9124" gainprm="24.1671" biasprm="0 -24.1671 -0.535347"/>
    <general name="Right_Hip_Yaw" class="/" joint="Right_Hip_Yaw" forcerange="-27.3869 27.3869" gainprm="24.1671" biasprm="0 -24.1671 -0.535347"/>
    <general name="Right_Knee_Pitch" class="/" joint="Right_Knee_Pitch" forcerange="-53.5153 53.5153" gainprm="24.1671" biasprm="0 -24.1671 -0.535347"/>
    <general name="Right_Ankle_Pitch" class="/" joint="Right_Ankle_Pitch" forcerange="-19.1849 19.1849" gainprm="24.1671" biasprm="0 -24.1671 -0.535347"/>
    <general name="Right_Ankle_Roll" class="/" joint="Right_Ankle_Roll" forcerange="-13.2751 13.2751" gainprm="24.1671" biasprm="0 -24.1671 -0.535347"/>
  </actuator>

  <sensor>
    <gyro site="imu" name="imu_angular_velocity"/>
    <velocimeter site="imu" name="imu_linear_velocity"/>
    <framelinvel objtype="site" objname="left_foot" name="left_foot_global_linear_velocity"/>
    <framelinvel objtype="site" objname="right_foot" name="right_foot_global_linear_velocity"/>
  </sensor>

  <keyframe>
    <key name="home" qpos="0 0 0.6385 1 0 0 0 0 0 0 1.4 0 -0.4 0 -1.4 0 0.4 0 -0.4 0 0 0.8 -0.4 0 0.4 0 0 -0.8 0.4 0"/>
  </keyframe>
</mujoco>
