<mujoco model="T1">
  <compiler angle="radian" assetdir="assets" balanceinertia="true" inertiafromgeom="false"/>

  <option timestep="0.005" density="1.2" viscosity="2e-05"/>

  <size nkey="1"/>

  <visual>
    <quality shadowsize="8192"/>
    <map shadowclip="0.5"/>
  </visual>

  <default>
    <default class="/">
      <joint armature="0.01" damping="0.01" frictionloss="0.1"/>
      <geom contype="0" conaffinity="0" group="1" solref="-1000 -80"/>
      <site size="0.01 0.005 0.005" group="5"/>
      <general forcelimited="true" biastype="affine" gainprm="25" biasprm="0 -25 -0.6"/>
      <default class="t1">
        <geom rgba="0.25 0.25 0.25 1"/>
        <default class="visual">
          <geom type="mesh" group="2"/>
        </default>
        <default class="collision">
          <geom group="3"/>
        </default>
        <default class="foot">
          <geom size="0.1115 0.05 0.015" type="box" condim="6" group="4" priority="1" solimp="0.015 1 0.015"/>
        </default>
        <default class="reward_collision_sphere">
          <geom group="5" rgba="1 0 0 1"/>
        </default>
      </default>
    </default>
  </default>

  <asset>
    <texture type="skybox" colorspace="auto" name="//unnamed_texture_0" builtin="gradient" rgb1="0.95 0.95 0.95" rgb2="0.95 0.95 0.95" width="100" height="600"/>
    <texture type="2d" colorspace="auto" name="texplane" builtin="checker" rgb1="0.345 0.575 0.748" rgb2="0.345 0.575 0.748" markrgb="1 1 1" width="512" height="512"/>
    <material name="MatPlane" class="/" texture="texplane" texuniform="true" texrepeat="2 2" specular="0.9"/>
    <mesh name="Trunk" class="/" file="Trunk.stl"/>
    <mesh name="H1" class="/" file="H1.stl"/>
    <mesh name="H2" class="/" file="H2.stl"/>
    <mesh name="AL1" class="/" file="AL1.stl"/>
    <mesh name="AL2" class="/" file="AL2.stl"/>
    <mesh name="AL3" class="/" file="AL3.stl"/>
    <mesh name="left_hand_link" class="/" file="left_hand_link.stl"/>
    <mesh name="AR1" class="/" file="AR1.stl"/>
    <mesh name="AR2" class="/" file="AR2.stl"/>
    <mesh name="AR3" class="/" file="AR3.stl"/>
    <mesh name="right_hand_link" class="/" file="right_hand_link.stl"/>
    <mesh name="Waist" class="/" file="Waist.stl"/>
    <mesh name="Hip_Pitch_Left" class="/" file="Hip_Pitch_Left.stl"/>
    <mesh name="Hip_Roll_Left" class="/" file="Hip_Roll_Left.stl"/>
    <mesh name="Hip_Yaw_Left" class="/" file="Hip_Yaw_Left.stl"/>
    <mesh name="Shank_Left" class="/" file="Shank_Left.stl"/>
    <mesh name="Ankle_Cross_Left" class="/" file="Ankle_Cross_Left.stl"/>
    <mesh name="left_foot_link" class="/" file="left_foot_link.stl"/>
    <mesh name="Hip_Pitch_Right" class="/" file="Hip_Pitch_Right.stl"/>
    <mesh name="Hip_Roll_Right" class="/" file="Hip_Roll_Right.stl"/>
    <mesh name="Hip_Yaw_Right" class="/" file="Hip_Yaw_Right.stl"/>
    <mesh name="Shank_Right" class="/" file="Shank_Right.stl"/>
    <mesh name="Ankle_Cross_Right" class="/" file="Ankle_Cross_Right.stl"/>
    <mesh name="right_foot_link" class="/" file="right_foot_link.stl"/>
  </asset>

  <worldbody>
    <geom name="floor" class="/" size="100 100 0.125" type="plane" group="0" material="MatPlane"/>
    <light name="toplight_shadow" class="/" pos="0 0 5" dir="0.0990148 0.0990148 -0.990148" type="directional" ambient="0.04 0.04 0.04" diffuse="0.55 0.55 0.55" specular="0.12 0.12 0.12"/>
    <light name="toplight_fill" class="/" pos="0 0 5" dir="0.0990148 0.0990148 -0.990148" type="directional" castshadow="false" ambient="0.04 0.04 0.04" diffuse="0.3 0.3 0.3" specular="0.08 0.08 0.08"/>
    <body name="trunk" childclass="t1" pos="0.000495784 -0.00193596 0.000357084" quat="0.999999 0.000512211 -0.000376184 -0.000999623">
      <inertial pos="0.0328448 -0.000305143 0.12797" quat="0.999958 -0.00347557 -0.00838406 -0.00104993" mass="7.70775" diaginertia="0.00835116 0.0262681 0.141543"/>
      <joint name="//unnamed_joint_0" type="free" armature="0" damping="0" frictionloss="0"/>
      <geom name="//unnamed_geom_1" class="visual" rgba="0.76 0.76 0.76 1" mesh="Trunk"/>
      <geom name="//unnamed_geom_2" class="collision" size="0.0656517 0.0875356 0.131303" pos="0.0371273 0 0.143545" type="box"/>
      <geom name="//unnamed_geom_3" class="reward_collision_sphere" size="0.100666" pos="0.0371273 0 0.119621"/>
      <geom name="//unnamed_geom_4" class="reward_collision_sphere" size="0.0131303" pos="0.0371273 0.0689409 0"/>
      <geom name="//unnamed_geom_5" class="reward_collision_sphere" size="0.0131303" pos="0.0371273 -0.0689409 0"/>
      <geom name="//unnamed_geom_6" class="reward_collision_sphere" size="0.0131303" pos="0.0371273 0.0867845 0.215318"/>
      <geom name="//unnamed_geom_7" class="reward_collision_sphere" size="0.0131303" pos="0.0371273 -0.0867845 0.215318"/>
      <site name="imu" pos="0.0153961 -0.0171861 0.0143703" size="0.00875356"/>
      <camera name="track" pos="0 -1.62214 0" quat="0.707107 0.707107 0 0" mode="trackcom"/>
      <camera name="ego_camera" pos="0.0754922 0 0.502408" quat="-0.5 -0.5 0.5 0.5"/>
      <body name="H1" pos="0.0379558 -0.00277779 0.288058" quat="0.999999 -0.00109424 -0.000798596 0.000108677">
        <inertial pos="-0.00106079 -0.000187001 0.0711139" quat="0.762743 -0.0178567 -0.0075298 0.646411" mass="0.276673" diaginertia="2.15995e-05 7.9172e-05 0.000362363"/>
        <joint name="AAHead_yaw" pos="0 0 0" axis="0.000378642 0.00521305 0.999986" range="-1.52541 1.58002" armature="0.00726388" damping="0.0146284" frictionloss="0.0841135"/>
        <geom name="//unnamed_geom_8" class="visual" mesh="H1"/>
        <body name="H2" pos="-0.0046835 -0.00103393 0.0746008" quat="1 0.000615605 -0.00026668 0.000456249">
          <inertial pos="0.00499966 0.00225978 0.117343" quat="0.988507 0.097549 -0.0806704 -0.082645" mass="0.405343" diaginertia="0.000182248 0.000666032 0.00424577"/>
          <joint name="Head_pitch" pos="0 0 0" axis="6.59375e-05 -1 0.000325165" range="-1.26878 0.3302" armature="0.00992653" damping="0" frictionloss="0.0797001"/>
          <geom name="//unnamed_geom_9" class="visual" mesh="H2"/>
          <geom name="//unnamed_geom_10" class="collision" size="0.0700285" pos="0.00618788 0 0.131583"/>
          <geom name="//unnamed_geom_11" class="reward_collision_sphere" size="0.078782" pos="0.0123758 0 0.119621"/>
        </body>
      </body>
      <body name="AL1" pos="0.0404052 0.0868375 0.264836" quat="1 0.000175279 0.000347627 -0.000103551">
        <inertial pos="-9.0761e-05 0.0351658 0.00037061" quat="0.49685 0.49271 -0.509238 0.501052" mass="0.3585" diaginertia="0.000125146 0.000439672 0.000695026"/>
        <joint name="Left_Shoulder_Pitch" pos="0 0 0" axis="0.00505127 0.999962 -0.00715388" range="-3.26279 1.19365" armature="0.00770903" damping="0.00880264" frictionloss="0.0843953"/>
        <geom name="//unnamed_geom_12" class="visual" rgba="0.76 0.76 0.76 1" mesh="AL1"/>
        <body name="AL2" pos="0.00058391 0.0405763 7.75349e-05" quat="1 -2.09266e-05 -0.000128733 0.000144235">
          <inertial pos="0.0040898 0.0282168 -0.002004" quat="0.487057 0.510945 -0.488225 0.513173" mass="0.105205" diaginertia="3.68972e-05 0.000125157 0.000442466"/>
          <joint name="Left_Shoulder_Roll" pos="0 0 0" axis="-0.999978 -0.00265084 -0.00607005" range="-1.62942 1.68381" armature="0.00996343" damping="0.000184585" frictionloss="0.0890831"/>
          <geom name="//unnamed_geom_13" class="visual" mesh="AL2"/>
          <body name="AL3" pos="0.000559584 0.0476685 0.00215471" quat="1 -0.000383991 0.000706099 -0.000421405">
            <inertial pos="0.000296547 0.0693726 -0.000884124" quat="0.711511 0.702661 -0.00197693 -0.00397081" mass="0.646632" diaginertia="0.00113124 0.00438303 0.00154343"/>
            <joint name="Left_Elbow_Pitch" pos="0 0 0" axis="0.00440726 -0.999796 0.0197211" stiffness="0.0218242" range="-2.33337 2.25048" armature="0.0106563" damping="0.0360316" frictionloss="0.087699"/>
            <geom name="//unnamed_geom_14" class="visual" mesh="AL3"/>
            <geom name="//unnamed_geom_15" class="collision" size="0.0262607 0.0656517" pos="0 0.0405535 0" quat="0.707105 0.707108 0 0" type="cylinder"/>
            <geom name="//unnamed_geom_16" class="reward_collision_sphere" size="0.0315128"/>
            <body name="left_hand_link" pos="0.000764285 0.11896 -0.00224406" quat="1 -0.000796416 -0.000499217 4.83108e-05">
              <inertial pos="-0.00087351 0.0911498 0.002029" quat="0.708029 0.706183 0.000914571 0.000170448" mass="0.223548" diaginertia="0.000723144 0.00281245 0.000545226"/>
              <joint name="Left_Elbow_Yaw" pos="0 0 0" axis="0.000772196 -0.00157362 0.999998" range="-2.47861 0.0170159" armature="0.00734712" damping="0.0145209" frictionloss="0.0827043"/>
              <geom name="//unnamed_geom_17" class="visual" mesh="left_hand_link"/>
              <geom name="//unnamed_geom_18" class="collision" size="0.0262607 0.0765936" pos="0 0.105439 0" quat="0.707105 0.707108 0 0" type="cylinder"/>
              <geom name="//unnamed_geom_19" class="reward_collision_sphere" size="0.0437678"/>
              <geom name="//unnamed_geom_20" class="reward_collision_sphere" size="0.0306374" pos="0 0.0892177 0"/>
              <geom name="//unnamed_geom_21" class="reward_collision_sphere" size="0.0306374" pos="0 0.17438 0"/>
            </body>
          </body>
        </body>
      </body>
      <body name="AR1" pos="0.0367839 -0.084436 0.260945" quat="1 0.000722937 -4.43037e-05 -0.000154291">
        <inertial pos="0.00217188 -0.0342786 -0.000110485" quat="0.500465 0.487708 -0.521649 0.489448" mass="0.362916" diaginertia="0.000121607 0.000445467 0.000689818"/>
        <joint name="Right_Shoulder_Pitch" pos="0 0 0" axis="-0.00265526 -0.999988 -0.00407066" range="-1.22846 3.30337" armature="0.00853433" damping="0.00399905" frictionloss="0.087386"/>
        <geom name="//unnamed_geom_22" class="visual" rgba="0.76 0.76 0.76 1" mesh="AR1"/>
        <body name="AR2" pos="-0.00279133 -0.0401026 -0.00133384" quat="0.999999 0.000682213 -0.00079725 0.000524561">
          <inertial pos="0.00500083 -0.0288942 0.00187953" quat="0.512941 0.487269 -0.51055 0.488671" mass="0.106319" diaginertia="3.69508e-05 0.000118435 0.000440521"/>
          <joint name="Right_Shoulder_Roll" pos="0 0 0" axis="-0.999912 0.00390522 0.0126579" range="-1.70958 1.50137" armature="0.00892614" damping="0.00923072" frictionloss="0.096909"/>
          <geom name="//unnamed_geom_23" class="visual" mesh="AR2"/>
          <body name="AR3" pos="-0.00177911 -0.0519661 0.00257747" quat="1 0.000122626 0.000274688 0.000293347">
            <inertial pos="0.000509555 -0.0664107 -0.000970967" quat="0.707053 0.70716 -3.41014e-05 -8.32721e-05" mass="0.698489" diaginertia="0.00117943 0.0044572 0.00149145"/>
            <joint name="Right_Elbow_Pitch" pos="0 0 0" axis="-0.00222643 0.99995 -0.00974775" stiffness="0.00878233" range="-2.25253 2.27458" armature="0.00855484" damping="0.00304441" frictionloss="0.0893628"/>
            <geom name="//unnamed_geom_24" class="visual" mesh="AR3"/>
            <geom name="//unnamed_geom_25" class="collision" size="0.0262607 0.0656517" pos="0 -0.0405535 0" quat="0.707105 0.707108 0 0" type="cylinder"/>
            <geom name="//unnamed_geom_26" class="reward_collision_sphere" size="0.0315128"/>
            <body name="right_hand_link" pos="-0.0025255 -0.118346 -0.00239479" quat="1 -0.000239023 -0.000460389 -0.000839236">
              <inertial pos="-0.00109537 -0.0913257 0.00151823" quat="0.703871 0.710306 -0.00547616 -0.00101536" mass="0.214616" diaginertia="0.000770394 0.00287869 0.000530698"/>
              <joint name="Right_Elbow_Yaw" pos="0 0 0" axis="-0.00165722 -0.0114966 0.999933" range="0.0402177 2.42755" armature="0.00968392" damping="0" frictionloss="0.088929"/>
              <geom name="//unnamed_geom_27" class="visual" mesh="right_hand_link"/>
              <geom name="//unnamed_geom_28" class="collision" size="0.0262607 0.0765936" pos="0 -0.105439 0" quat="0.707105 0.707108 0 0" type="cylinder"/>
              <geom name="//unnamed_geom_29" class="reward_collision_sphere" size="0.0437678"/>
              <geom name="//unnamed_geom_30" class="reward_collision_sphere" size="0.0306374" pos="0 -0.0892177 0"/>
              <geom name="//unnamed_geom_31" class="reward_collision_sphere" size="0.0306374" pos="0 -0.17438 0"/>
            </body>
          </body>
        </body>
      </body>
      <body name="Waist" pos="0.03529 0.0029777 -0.138829" quat="0.999999 -0.000772948 -0.000726149 0.000290591">
        <inertial pos="0.00614548 -0.000378657 0.00843848" quat="0.983486 -0.00570856 -0.18089 -0.00128297" mass="1.62429" diaginertia="0.000494569 0.00174456 0.0114969"/>
        <joint name="Waist" pos="0 0 0" axis="-0.0138585 0.0109488 0.999844" range="-1.51982 1.52249" armature="0.00798785" damping="0" frictionloss="0.0907035"/>
        <geom name="//unnamed_geom_32" class="visual" mesh="Waist"/>
        <body name="Hip_Pitch_Left" pos="0.00324267 0.0860843 7.23171e-05" quat="0.999997 1.37909e-05 -0.0023519 -0.000185166">
          <inertial pos="0.00102046 -0.0091399 -0.0219627" quat="0.975082 0.221394 0.014096 0.00139787" mass="0.730905" diaginertia="0.000170863 0.000517421 0.0030752"/>
          <joint name="Left_Hip_Pitch" pos="0 0 0" axis="0.00950835 0.999904 -0.0100573" stiffness="0.00939827" range="-1.85702 1.5743" armature="0.00906753" damping="0.00414309" frictionloss="0.0719653"/>
          <geom name="//unnamed_geom_33" class="visual" rgba="0.76 0.76 0.76 1" mesh="Hip_Pitch_Left"/>
          <body name="Hip_Roll_Left" pos="-0.00371822 -0.00130113 -0.0194651" quat="0.999997 0.00161026 0.00169184 -0.000990465">
            <inertial pos="0.00121249 -0.00207386 -0.0613707" quat="0.704472 -0.0121611 -0.00761055 0.709586" mass="0.264572" diaginertia="0.000158446 0.000556966 0.00131094"/>
            <joint name="Left_Hip_Roll" pos="0 0 0" axis="-0.999889 -0.0141443 0.00475206" stiffness="0.0062138" range="-1.57564 0.198826" armature="0.00878614" damping="0.00430691" frictionloss="0.089248"/>
            <geom name="//unnamed_geom_34" class="visual" mesh="Hip_Roll_Left"/>
            <geom name="//unnamed_geom_35" class="reward_collision_sphere" size="0.0481446"/>
            <body name="Hip_Yaw_Left" pos="0.00265592 0.00242827 -0.0970306" quat="1 0.000449304 0.000499171 8.16661e-05">
              <inertial pos="-0.0034165 -0.00476645 -0.109508" quat="0.698849 -0.0446097 -0.0250033 0.713438" mass="1.38985" diaginertia="0.00222535 0.00846605 0.0062225"/>
              <joint name="Left_Hip_Yaw" pos="0 0 0" axis="0.00269031 0.0107605 -0.999938" stiffness="0.00230631" range="-1.01609 1.00796" armature="0.0087335" damping="0" frictionloss="0.0893785"/>
              <geom name="//unnamed_geom_36" class="visual" mesh="Hip_Yaw_Left"/>
              <geom name="//unnamed_geom_37" class="collision" size="0.0437678 0.0700285" type="cylinder"/>
              <body name="Shank_Left" pos="-0.01193 0.00246802 -0.161527" quat="1 0.000235039 0.00027606 0.00016009">
                <inertial pos="-0.00436909 -0.000227686 -0.146579" quat="0.998152 0.00113338 -0.027293 0.0542843" mass="1.08994" diaginertia="0.00306508 0.0119339 0.00440235"/>
                <joint name="Left_Knee_Pitch" pos="0 0 0" axis="0.00939167 0.999894 0.0111137" range="0.0126632 2.37266" armature="0.00852661" damping="0" frictionloss="0.0872704"/>
                <geom name="//unnamed_geom_38" class="visual" mesh="Shank_Left"/>
                <geom name="//unnamed_geom_39" class="collision" size="0.0437678 0.0656517" pos="0 0 -0.143545" type="cylinder"/>
                <geom name="//unnamed_geom_40" class="reward_collision_sphere" size="0.0568981"/>
                <body name="Ankle_Cross_Left" pos="0.000830178 0.000353567 -0.334236" quat="0.999999 0.000577633 -0.000470582 -0.000728904">
                  <inertial pos="-0.00383681 0.000591785 -0.00707224" quat="0.443614 0.55138 0.551997 0.441005" mass="0.0499939" diaginertia="2.69067e-06 9.2695e-06 2.85276e-05"/>
                  <joint name="Left_Ankle_Pitch" pos="0 0 0" axis="-0.00458956 0.999988 0.00162429" range="-0.801822 0.28537" armature="0.00906751" damping="0.0300405" frictionloss="0.0915013"/>
                  <geom name="//unnamed_geom_41" class="visual" mesh="Ankle_Cross_Left"/>
                  <body name="left_foot_link" pos="-0.0013413 -0.0017583 -0.0122253" quat="0.999999 0.00053959 0.00155942 0.000383226">
                    <inertial pos="-0.00287799 0.00303929 -0.00968006" quat="-0.00314532 0.618951 -0.000782506 0.785423" mass="0.42588" diaginertia="0.000223803 0.000784677 0.0047455"/>
                    <joint name="Left_Ankle_Roll" pos="0 0 0" axis="-0.999969 1.66171e-05 0.00790989" range="-0.445406 0.366901" armature="0.00846851" damping="0.00733682" frictionloss="0.0655249"/>
                    <geom name="//unnamed_geom_42" class="visual" mesh="left_foot_link"/>
                    <geom name="left_foot" class="foot" size="0.104681 0.0504247 0.0106183" pos="0.00618788 0 -0.0179431"/>
                    <geom name="//unnamed_geom_44" class="reward_collision_sphere" size="0.0455185" pos="0.00618788 0 -0.0179431"/>
                    <geom name="//unnamed_geom_45" class="reward_collision_sphere" size="0.0262607" pos="0.0587849 -0.0186546 -0.0179431"/>
                    <geom name="//unnamed_geom_46" class="reward_collision_sphere" size="0.0262607" pos="-0.0433152 -0.0186546 -0.0179431"/>
                    <site name="left_foot" class="foot" pos="0.00618788 0 -0.0179431" size="0.00875356"/>
                  </body>
                </body>
              </body>
            </body>
          </body>
        </body>
        <body name="Hip_Pitch_Right" pos="-0.000897791 -0.0866138 0.000566244" quat="1 0.000109555 0.000356167 0.000332695">
          <inertial pos="-0.00203205 0.00587915 -0.0231671" quat="0.971314 -0.236383 0.0153516 -0.0208937" mass="0.700264" diaginertia="0.000171652 0.000550167 0.00311972"/>
          <joint name="Right_Hip_Pitch" pos="0 0 0" axis="-0.00630185 -0.99998 0.000958382" stiffness="0.000864247" range="-1.55948 1.77405" armature="0.00955956" damping="0.00693003" frictionloss="0.0838841"/>
          <geom name="//unnamed_geom_47" class="visual" rgba="0.76 0.76 0.76 1" mesh="Hip_Pitch_Right"/>
          <body name="Hip_Roll_Right" pos="-0.000561915 -0.0011367 -0.0209513" quat="0.999999 0.000806804 -0.000359377 0.000722237">
            <inertial pos="-0.000821396 0.000615665 -0.0638755" quat="0.708259 -0.00637982 -0.00717681 0.705887" mass="0.269378" diaginertia="0.000163652 0.00055349 0.00133166"/>
            <joint name="Right_Hip_Roll" pos="0 0 0" axis="-0.999857 0.0100199 0.0136471" stiffness="0.0328163" range="-0.249785 1.58663" armature="0.00819636" damping="0.00625715" frictionloss="0.0836564"/>
            <geom name="//unnamed_geom_48" class="visual" mesh="Hip_Roll_Right"/>
            <geom name="//unnamed_geom_49" class="reward_collision_sphere" size="0.0481446"/>
            <body name="Hip_Yaw_Right" pos="0.0015015 -0.00462223 -0.0989165" quat="1 -0.000423753 2.40865e-05 8.4051e-05">
              <inertial pos="-0.0038626 -0.000819848 -0.10287" quat="0.712846 -0.0343227 -0.0297541 0.699848" mass="1.47188" diaginertia="0.00240988 0.0093564 0.00668828"/>
              <joint name="Right_Hip_Yaw" pos="0 0 0" axis="-0.00567618 0.0148857 -0.999873" range="-1.04142 0.981301" armature="0.00938122" damping="0" frictionloss="0.0865465"/>
              <geom name="//unnamed_geom_50" class="visual" mesh="Hip_Yaw_Right"/>
              <geom name="//unnamed_geom_51" class="collision" size="0.0437678 0.0700285" type="cylinder"/>
              <body name="Shank_Right" pos="-0.00722116 -0.000910323 -0.160204" quat="1 -0.000227114 2.77046e-05 -0.000369936">
                <inertial pos="-0.00846137 0.00279357 -0.148725" quat="0.999003 -0.0030625 -0.0254851 -0.0365253" mass="1.21963" diaginertia="0.00323303 0.0121887 0.00489522"/>
                <joint name="Right_Knee_Pitch" pos="0 0 0" axis="0.00477426 -0.999989 -0.00027439" range="-2.33832 0.0399702" armature="0.00903287" damping="0.00555403" frictionloss="0.0842052"/>
                <geom name="//unnamed_geom_52" class="visual" mesh="Shank_Right"/>
                <geom name="//unnamed_geom_53" class="collision" size="0.0437678 0.0656517" pos="0 0 -0.143545" type="cylinder"/>
                <geom name="//unnamed_geom_54" class="reward_collision_sphere" size="0.0568981"/>
                <body name="Ankle_Cross_Right" pos="-0.00202002 0.00347267 -0.336102" quat="0.999999 0.00120959 0.000106864 0.000918781">
                  <inertial pos="-0.00486665 -0.000463892 -0.0115917" quat="0.443002 0.550653 0.552099 0.4424" mass="0.0494067" diaginertia="2.73037e-06 9.17082e-06 2.71827e-05"/>
                  <joint name="Right_Ankle_Pitch" pos="0 0 0" axis="0.00568847 -0.999933 0.0101194" stiffness="0.00596679" range="-0.384248 0.796346" armature="0.00833192" damping="0.00455971" frictionloss="0.0860107"/>
                  <geom name="//unnamed_geom_55" class="visual" mesh="Ankle_Cross_Right"/>
                  <body name="right_foot_link" pos="0.00107435 0.000150118 -0.0148036" quat="1 0.000290238 -0.00034417 -3.97375e-05">
                    <inertial pos="0.000614678 -0.00200566 -0.0110551" quat="-0.00716649 0.61847 0.0100211 0.785712" mass="0.460301" diaginertia="0.000255547 0.000837887 0.00521744"/>
                    <joint name="Right_Ankle_Roll" pos="0 0 0" axis="-0.999982 0.00402223 0.00441522" range="-0.418067 0.406883" armature="0.00975122" damping="0.0161906" frictionloss="0.0986737"/>
                    <geom name="//unnamed_geom_56" class="visual" mesh="right_foot_link"/>
                    <geom name="right_foot" class="foot" size="0.0868017 0.0475755 0.0123289" pos="0.00618788 0 -0.0179431"/>
                    <geom name="//unnamed_geom_58" class="reward_collision_sphere" size="0.0350142"/>
                    <geom name="//unnamed_geom_59" class="reward_collision_sphere" size="0.0262607" pos="0.00618788 0 -0.0179431"/>
                    <geom name="//unnamed_geom_60" class="reward_collision_sphere" size="0.0262607" pos="0.0587849 0.0186546 -0.0179431"/>
                    <geom name="//unnamed_geom_61" class="reward_collision_sphere" size="0.0262607" pos="-0.0433152 0.0186546 -0.0179431"/>
                    <site name="right_foot" class="foot" pos="0.00618788 0 -0.0179431" size="0.00875356"/>
                  </body>
                </body>
              </body>
            </body>
          </body>
        </body>
      </body>
    </body>
  </worldbody>

  <contact>
    <pair class="/" geom1="floor" geom2="left_foot" name="//unnamed_contact_0"/>
    <pair class="/" geom1="floor" geom2="right_foot" name="//unnamed_contact_1"/>
  </contact>

  <actuator>
    <general name="AAHead_yaw" class="/" joint="AAHead_yaw" forcerange="-5.55423 5.55423" gainprm="23.6453" biasprm="0 -23.6453 -0.524359"/>
    <general name="Head_pitch" class="/" joint="Head_pitch" forcerange="-6.7248 6.7248" gainprm="23.6453" biasprm="0 -23.6453 -0.524359"/>
    <general name="Left_Shoulder_Pitch" class="/" joint="Left_Shoulder_Pitch" forcerange="-16.6859 16.6859" gainprm="23.6453" biasprm="0 -23.6453 -0.524359"/>
    <general name="Left_Shoulder_Roll" class="/" joint="Left_Shoulder_Roll" forcerange="-14.9416 14.9416" gainprm="23.6453" biasprm="0 -23.6453 -0.524359"/>
    <general name="Left_Elbow_Pitch" class="/" joint="Left_Elbow_Pitch" forcerange="-17.8921 17.8921" gainprm="23.6453" biasprm="0 -23.6453 -0.524359"/>
    <general name="Left_Elbow_Yaw" class="/" joint="Left_Elbow_Yaw" forcerange="-14.5082 14.5082" gainprm="23.6453" biasprm="0 -23.6453 -0.524359"/>
    <general name="Right_Shoulder_Pitch" class="/" joint="Right_Shoulder_Pitch" forcerange="-14.2464 14.2464" gainprm="23.6453" biasprm="0 -23.6453 -0.524359"/>
    <general name="Right_Shoulder_Roll" class="/" joint="Right_Shoulder_Roll" forcerange="-14.4624 14.4624" gainprm="23.6453" biasprm="0 -23.6453 -0.524359"/>
    <general name="Right_Elbow_Pitch" class="/" joint="Right_Elbow_Pitch" forcerange="-15.7081 15.7081" gainprm="23.6453" biasprm="0 -23.6453 -0.524359"/>
    <general name="Right_Elbow_Yaw" class="/" joint="Right_Elbow_Yaw" forcerange="-15.2873 15.2873" gainprm="23.6453" biasprm="0 -23.6453 -0.524359"/>
    <general name="Waist" class="/" joint="Waist" forcerange="-25.8989 25.8989" gainprm="23.6453" biasprm="0 -23.6453 -0.524359"/>
    <general name="Left_Hip_Pitch" class="/" joint="Left_Hip_Pitch" forcerange="-36.1094 36.1094" gainprm="23.6453" biasprm="0 -23.6453 -0.524359"/>
    <general name="Left_Hip_Roll" class="/" joint="Left_Hip_Roll" forcerange="-23.6953 23.6953" gainprm="23.6453" biasprm="0 -23.6453 -0.524359"/>
    <general name="Left_Hip_Yaw" class="/" joint="Left_Hip_Yaw" forcerange="-29.8988 29.8988" gainprm="23.6453" biasprm="0 -23.6453 -0.524359"/>
    <general name="Left_Knee_Pitch" class="/" joint="Left_Knee_Pitch" forcerange="-59.5542 59.5542" gainprm="23.6453" biasprm="0 -23.6453 -0.524359"/>
    <general name="Left_Ankle_Pitch" class="/" joint="Left_Ankle_Pitch" forcerange="-16.9968 16.9968" gainprm="23.6453" biasprm="0 -23.6453 -0.524359"/>
    <general name="Left_Ankle_Roll" class="/" joint="Left_Ankle_Roll" forcerange="-13.2825 13.2825" gainprm="23.6453" biasprm="0 -23.6453 -0.524359"/>
    <general name="Right_Hip_Pitch" class="/" joint="Right_Hip_Pitch" forcerange="-43.1259 43.1259" gainprm="23.6453" biasprm="0 -23.6453 -0.524359"/>
    <general name="Right_Hip_Roll" class="/" joint="Right_Hip_Roll" forcerange="-26.9434 26.9434" gainprm="23.6453" biasprm="0 -23.6453 -0.524359"/>
    <general name="Right_Hip_Yaw" class="/" joint="Right_Hip_Yaw" forcerange="-27.7341 27.7341" gainprm="23.6453" biasprm="0 -23.6453 -0.524359"/>
    <general name="Right_Knee_Pitch" class="/" joint="Right_Knee_Pitch" forcerange="-52.7576 52.7576" gainprm="23.6453" biasprm="0 -23.6453 -0.524359"/>
    <general name="Right_Ankle_Pitch" class="/" joint="Right_Ankle_Pitch" forcerange="-18.6324 18.6324" gainprm="23.6453" biasprm="0 -23.6453 -0.524359"/>
    <general name="Right_Ankle_Roll" class="/" joint="Right_Ankle_Roll" forcerange="-13.1405 13.1405" gainprm="23.6453" biasprm="0 -23.6453 -0.524359"/>
  </actuator>

  <sensor>
    <gyro site="imu" name="imu_angular_velocity"/>
    <velocimeter site="imu" name="imu_linear_velocity"/>
    <framelinvel objtype="site" objname="left_foot" name="left_foot_global_linear_velocity"/>
    <framelinvel objtype="site" objname="right_foot" name="right_foot_global_linear_velocity"/>
  </sensor>

  <keyframe>
    <key name="home" qpos="0 0 0.6385 1 0 0 0 0 0 0 1.4 0 -0.4 0 -1.4 0 0.4 0 -0.4 0 0 0.8 -0.4 0 0.4 0 0 -0.8 0.4 0"/>
  </keyframe>
</mujoco>
