<mujoco model="T1">
  <compiler angle="radian" assetdir="assets" balanceinertia="true" inertiafromgeom="false"/>

  <option timestep="0.005" density="1.2" viscosity="2e-05"/>

  <size nkey="1"/>

  <visual>
    <quality shadowsize="8192"/>
    <map shadowclip="0.5"/>
  </visual>

  <default>
    <default class="/">
      <joint armature="0.01" damping="0.01" frictionloss="0.1"/>
      <geom contype="0" conaffinity="0" group="1" solref="-1000 -80"/>
      <site size="0.01 0.005 0.005" group="5"/>
      <general forcelimited="true" biastype="affine" gainprm="25" biasprm="0 -25 -0.6"/>
      <default class="t1">
        <geom rgba="0.25 0.25 0.25 1"/>
        <default class="visual">
          <geom type="mesh" group="2"/>
        </default>
        <default class="collision">
          <geom group="3"/>
        </default>
        <default class="foot">
          <geom size="0.1115 0.05 0.015" type="box" condim="6" group="4" priority="1" solimp="0.015 1 0.015"/>
        </default>
        <default class="reward_collision_sphere">
          <geom group="5" rgba="1 0 0 1"/>
        </default>
      </default>
    </default>
  </default>

  <asset>
    <texture type="skybox" colorspace="auto" name="//unnamed_texture_0" builtin="gradient" rgb1="0.95 0.95 0.95" rgb2="0.95 0.95 0.95" width="100" height="600"/>
    <texture type="2d" colorspace="auto" name="texplane" builtin="checker" rgb1="0.345 0.575 0.748" rgb2="0.345 0.575 0.748" markrgb="1 1 1" width="512" height="512"/>
    <material name="MatPlane" class="/" texture="texplane" texuniform="true" texrepeat="2 2" specular="0.9"/>
    <mesh name="Trunk" class="/" file="Trunk.stl"/>
    <mesh name="H1" class="/" file="H1.stl"/>
    <mesh name="H2" class="/" file="H2.stl"/>
    <mesh name="AL1" class="/" file="AL1.stl"/>
    <mesh name="AL2" class="/" file="AL2.stl"/>
    <mesh name="AL3" class="/" file="AL3.stl"/>
    <mesh name="left_hand_link" class="/" file="left_hand_link.stl"/>
    <mesh name="AR1" class="/" file="AR1.stl"/>
    <mesh name="AR2" class="/" file="AR2.stl"/>
    <mesh name="AR3" class="/" file="AR3.stl"/>
    <mesh name="right_hand_link" class="/" file="right_hand_link.stl"/>
    <mesh name="Waist" class="/" file="Waist.stl"/>
    <mesh name="Hip_Pitch_Left" class="/" file="Hip_Pitch_Left.stl"/>
    <mesh name="Hip_Roll_Left" class="/" file="Hip_Roll_Left.stl"/>
    <mesh name="Hip_Yaw_Left" class="/" file="Hip_Yaw_Left.stl"/>
    <mesh name="Shank_Left" class="/" file="Shank_Left.stl"/>
    <mesh name="Ankle_Cross_Left" class="/" file="Ankle_Cross_Left.stl"/>
    <mesh name="left_foot_link" class="/" file="left_foot_link.stl"/>
    <mesh name="Hip_Pitch_Right" class="/" file="Hip_Pitch_Right.stl"/>
    <mesh name="Hip_Roll_Right" class="/" file="Hip_Roll_Right.stl"/>
    <mesh name="Hip_Yaw_Right" class="/" file="Hip_Yaw_Right.stl"/>
    <mesh name="Shank_Right" class="/" file="Shank_Right.stl"/>
    <mesh name="Ankle_Cross_Right" class="/" file="Ankle_Cross_Right.stl"/>
    <mesh name="right_foot_link" class="/" file="right_foot_link.stl"/>
  </asset>

  <worldbody>
    <geom name="floor" class="/" size="100 100 0.125" type="plane" group="0" material="MatPlane"/>
    <light name="toplight_shadow" class="/" pos="0 0 5" dir="0.0990148 0.0990148 -0.990148" type="directional" ambient="0.04 0.04 0.04" diffuse="0.55 0.55 0.55" specular="0.12 0.12 0.12"/>
    <light name="toplight_fill" class="/" pos="0 0 5" dir="0.0990148 0.0990148 -0.990148" type="directional" castshadow="false" ambient="0.04 0.04 0.04" diffuse="0.3 0.3 0.3" specular="0.08 0.08 0.08"/>
    <body name="trunk" childclass="t1" pos="0.000791547 0.00883044 -0.0021919" quat="0.999983 -0.00201659 -0.00495978 0.00231075">
      <inertial pos="0.084292 0.00694197 0.173452" quat="0.998208 -0.0303301 -0.0153507 -0.0492403" mass="34.8095" diaginertia="0.622615 0.120731 0.547173"/>
      <joint name="//unnamed_joint_0" type="free" armature="0" damping="0" frictionloss="0"/>
      <geom name="//unnamed_geom_1" class="visual" rgba="0.76 0.76 0.76 1" mesh="Trunk"/>
      <geom name="//unnamed_geom_2" class="collision" size="0.108356 0.144474 0.216711" pos="0.0954037 0 0.197089" type="box"/>
      <geom name="//unnamed_geom_3" class="reward_collision_sphere" size="0.166145" pos="0.0954037 0 0.164241"/>
      <geom name="//unnamed_geom_4" class="reward_collision_sphere" size="0.0216711" pos="0.0954037 0.0936493 0"/>
      <geom name="//unnamed_geom_5" class="reward_collision_sphere" size="0.0216711" pos="0.0954037 -0.0936493 0"/>
      <geom name="//unnamed_geom_6" class="reward_collision_sphere" size="0.0216711" pos="0.0954037 0.117888 0.295633"/>
      <geom name="//unnamed_geom_7" class="reward_collision_sphere" size="0.0216711" pos="0.0954037 -0.117888 0.295633"/>
      <site name="imu" pos="-0.0565326 0.000917294 0.0557235" size="0.0144474"/>
      <camera name="track" pos="0 -2.20351 0" quat="0.707107 0.707107 0 0" mode="trackcom"/>
      <camera name="ego_camera" pos="0.193988 0 0.689811" quat="-0.5 -0.5 0.5 0.5"/>
      <body name="H1" pos="0.111802 -0.000335179 0.413843" quat="1 5.4999e-05 2.60348e-05 0.000180185">
        <inertial pos="-0.00113324 0.000688577 0.0950083" quat="0.765554 -0.0145407 0.0024583 0.643203" mass="1.30968" diaginertia="0.00280338 0.000341422 0.00177671"/>
        <joint name="AAHead_yaw" pos="0 0 0" axis="-9.20886e-07 0.0202492 0.999795" range="-1.79551 1.53775" armature="0.00381708" damping="0" frictionloss="0.0430194"/>
        <geom name="//unnamed_geom_8" class="visual" mesh="H1"/>
        <body name="H2" pos="0.00787086 0.0167506 0.107104" quat="0.999993 -0.00103278 -0.00319873 -0.00151171">
          <inertial pos="-8.41327e-05 0.0142754 0.177787" quat="0.980958 0.120347 -0.0641369 -0.138294" mass="1.66855" diaginertia="0.0193898 0.00365253 0.0200957"/>
          <joint name="Head_pitch" pos="0 0 0" axis="-0.0202635 -0.999455 -0.0260729" range="-1.28759 0.458179" armature="0.00692816" damping="0.076932" frictionloss="0.119811"/>
          <geom name="//unnamed_geom_9" class="visual" mesh="H2"/>
          <geom name="//unnamed_geom_10" class="collision" size="0.115579" pos="0.0159006 0 0.180665"/>
          <geom name="//unnamed_geom_11" class="reward_collision_sphere" size="0.130027" pos="0.0318012 0 0.164241"/>
        </body>
      </body>
      <body name="AL1" pos="0.0869218 0.116419 0.374311" quat="0.999972 -0.00215477 -0.00154573 0.00703513">
        <inertial pos="0.00926075 0.0466593 0.00240699" quat="0.504583 0.494048 -0.507622 0.493591" mass="1.76676" diaginertia="0.0153862 0.00278363 0.00453525"/>
        <joint name="Left_Shoulder_Pitch" pos="0 0 0" axis="0.0212399 0.998351 0.0533323" range="-3.11866 0.91607" armature="0.013872" damping="0.0779892" frictionloss="0.0790407"/>
        <geom name="//unnamed_geom_12" class="visual" rgba="0.76 0.76 0.76 1" mesh="AL1"/>
        <body name="AL2" pos="0.0139921 0.0447896 -0.00677789" quat="1 6.27602e-05 -6.32973e-06 -2.593e-05">
          <inertial pos="0.0139845 0.0273223 0.00859093" quat="0.477215 0.527203 -0.484419 0.509571" mass="0.436171" diaginertia="0.00350837 0.000461407 0.00206062"/>
          <joint name="Left_Shoulder_Roll" pos="0 0 0" axis="-0.999818 -0.0155672 0.0110686" stiffness="0.0831775" range="-1.74454 1.69658" armature="0.00371888" damping="0.000735393" frictionloss="0.150536"/>
          <geom name="//unnamed_geom_13" class="visual" mesh="AL2"/>
          <body name="AL3" pos="-0.00650862 0.068738 -0.00923677" quat="0.999997 -6.80589e-05 -0.000661699 -0.00244182">
            <inertial pos="-0.0136119 0.108639 -0.00752013" quat="0.688671 0.723938 0.0359237 -0.0188599" mass="4.17587" diaginertia="0.126352 0.0234497 0.00980796"/>
            <joint name="Left_Elbow_Pitch" pos="0 0 0" axis="-0.0317102 -0.999103 -0.0280646" stiffness="0.0380668" range="-1.96135 2.41989" armature="0.0027839" damping="0.0288834" frictionloss="0.153482"/>
            <geom name="//unnamed_geom_14" class="visual" mesh="AL3"/>
            <geom name="//unnamed_geom_15" class="collision" size="0.0433423 0.108356" pos="0 0.0550878 0" quat="0.707105 0.707108 0 0" type="cylinder"/>
            <geom name="//unnamed_geom_16" class="reward_collision_sphere" size="0.0520107"/>
            <body name="left_hand_link" pos="0.00523338 0.157834 0.0105218" quat="0.999971 -0.00316655 0.00177614 -0.00663423">
              <inertial pos="0.0153615 0.112993 -0.000307651" quat="0.714058 0.699646 -0.0230284 0.0093191" mass="0.981272" diaginertia="0.0961382 0.0118099 0.00210196"/>
              <joint name="Left_Elbow_Yaw" pos="0 0 0" axis="-0.000133955 0.00414284 0.999991" range="-2.39715 0.313325" armature="0.0171606" damping="0" frictionloss="0.138317"/>
              <geom name="//unnamed_geom_17" class="visual" mesh="left_hand_link"/>
              <geom name="//unnamed_geom_18" class="collision" size="0.0433423 0.126415" pos="0 0.143228 0" quat="0.707105 0.707108 0 0" type="cylinder"/>
              <geom name="//unnamed_geom_19" class="reward_collision_sphere" size="0.0722371"/>
              <geom name="//unnamed_geom_20" class="reward_collision_sphere" size="0.050566" pos="0 0.121193 0"/>
              <geom name="//unnamed_geom_21" class="reward_collision_sphere" size="0.050566" pos="0 0.236878 0"/>
            </body>
          </body>
        </body>
      </body>
      <body name="AR1" pos="0.0842614 -0.103047 0.355924" quat="0.999995 -0.0014956 -0.00290863 -0.000302327">
        <inertial pos="0.00919358 -0.0330418 0.00525086" quat="0.469457 0.529001 -0.513611 0.485768" mass="1.71334" diaginertia="0.0178914 0.00250196 0.00368849"/>
        <joint name="Right_Shoulder_Pitch" pos="0 0 0" axis="0.0447474 -0.997806 0.0487847" stiffness="0.0815556" range="-1.24536 3.49129" armature="0.00481484" damping="0.0473022" frictionloss="0.205532"/>
        <geom name="//unnamed_geom_22" class="visual" rgba="0.76 0.76 0.76 1" mesh="AR1"/>
        <body name="AR2" pos="-0.0156145 -0.0623174 0.0096595" quat="0.999975 0.00674681 -0.00167834 -0.00124033">
          <inertial pos="0.0165415 -0.0432237 0.00704413" quat="0.502815 0.487526 -0.488956 0.520017" mass="0.572947" diaginertia="0.0041269 0.000465431 0.00226242"/>
          <joint name="Right_Shoulder_Roll" pos="0 0 0" axis="-0.999782 0.0129698 -0.0163831" stiffness="0.0122823" range="-1.88091 1.43817" armature="0.0146102" damping="0" frictionloss="0.0249226"/>
          <geom name="//unnamed_geom_23" class="visual" mesh="AR2"/>
          <body name="AR3" pos="-0.00980393 -0.0736399 0.0168208" quat="1 4.20226e-05 -4.66544e-06 3.00719e-05">
            <inertial pos="-0.0016663 -0.0798367 0.00779148" quat="0.67508 0.736013 0.0503877 0.00358581" mass="3.06682" diaginertia="0.129616 0.0221458 0.00617519"/>
            <joint name="Right_Elbow_Pitch" pos="0 0 0" axis="-0.0296755 0.997681 -0.0612581" range="-1.99706 2.46504" armature="0.0254096" damping="0" frictionloss="0.0684914"/>
            <geom name="//unnamed_geom_24" class="visual" mesh="AR3"/>
            <geom name="//unnamed_geom_25" class="collision" size="0.0433423 0.108356" pos="0 -0.0550878 0" quat="0.707105 0.707108 0 0" type="cylinder"/>
            <geom name="//unnamed_geom_26" class="reward_collision_sphere" size="0.0520107"/>
            <body name="right_hand_link" pos="-0.000485682 -0.159312 -0.000918782" quat="0.99998 0.00330549 0.00116124 0.00525162">
              <inertial pos="-0.00205151 -0.11234 -0.0133765" quat="0.707532 0.706681 0.000549492 5.86138e-05" mass="1.14789" diaginertia="0.0950622 0.0142064 0.00282809"/>
              <joint name="Right_Elbow_Yaw" pos="0 0 0" axis="-0.0312122 0.0399799 0.998713" range="0.04034 2.22743" armature="0.00399547" damping="0.0910321" frictionloss="0.0611544"/>
              <geom name="//unnamed_geom_27" class="visual" mesh="right_hand_link"/>
              <geom name="//unnamed_geom_28" class="collision" size="0.0433423 0.126415" pos="0 -0.143228 0" quat="0.707105 0.707108 0 0" type="cylinder"/>
              <geom name="//unnamed_geom_29" class="reward_collision_sphere" size="0.0722371"/>
              <geom name="//unnamed_geom_30" class="reward_collision_sphere" size="0.050566" pos="0 -0.121193 0"/>
              <geom name="//unnamed_geom_31" class="reward_collision_sphere" size="0.050566" pos="0 -0.236878 0"/>
            </body>
          </body>
        </body>
      </body>
      <body name="Waist" pos="0.10095 0.0129009 -0.205246" quat="1 0.000153381 0.000235727 -1.64461e-05">
        <inertial pos="0.0176423 0.00475293 0.00805197" quat="0.972689 0.00205026 -0.22776 -0.0446933" mass="9.46867" diaginertia="0.0627538 0.0106747 0.0681864"/>
        <joint name="Waist" pos="0 0 0" axis="-0.0278439 -0.0628244 0.997636" stiffness="0.047268" range="-1.65909 1.85037" armature="0.0137797" damping="0" frictionloss="0.0477808"/>
        <geom name="//unnamed_geom_32" class="visual" mesh="Waist"/>
        <body name="Hip_Pitch_Left" pos="-0.00180389 0.117673 0.0044177" quat="0.99999 6.73708e-05 -0.00424636 0.00108055">
          <inertial pos="0.00377482 0.000345986 -0.0275231" quat="0.971733 0.235984 -0.00345073 -0.00593114" mass="2.68038" diaginertia="0.0182213 0.0018857 0.0130984"/>
          <joint name="Left_Hip_Pitch" pos="0 0 0" axis="0.0832932 0.996463 0.0111524" stiffness="0.076733" range="-1.78245 1.26484" armature="0.00830488" damping="0.0693298" frictionloss="0.153301"/>
          <geom name="//unnamed_geom_33" class="visual" rgba="0.76 0.76 0.76 1" mesh="Hip_Pitch_Left"/>
          <body name="Hip_Roll_Left" pos="0.00616155 -0.0168773 -0.0459422" quat="0.999966 0.00592095 0.00122949 0.0055421">
            <inertial pos="0.0142237 -0.000473589 -0.0925062" quat="0.721919 0.00689077 -0.0256854 0.691466" mass="1.47187" diaginertia="0.017461 0.00288504 0.00740939"/>
            <joint name="Left_Hip_Roll" pos="0 0 0" axis="-0.99712 -0.0260041 0.0712443" range="-1.72365 0.213175" armature="0.0207722" damping="0.023839" frictionloss="0.176583"/>
            <geom name="//unnamed_geom_34" class="visual" mesh="Hip_Roll_Left"/>
            <geom name="//unnamed_geom_35" class="reward_collision_sphere" size="0.0794608"/>
            <body name="Hip_Yaw_Left" pos="-0.00745958 -0.00367047 -0.126716" quat="1 -0.000144089 -0.000448939 -0.000180954">
              <inertial pos="-0.0137155 -0.00552034 -0.145525" quat="0.717771 -0.0981237 -0.049058 0.687582" mass="8.44203" diaginertia="0.259719 0.0506073 0.0365168"/>
              <joint name="Left_Hip_Yaw" pos="0 0 0" axis="0.00570121 -0.00424956 -0.999975" range="-0.770829 1.02057" armature="0.0141403" damping="0" frictionloss="0.12544"/>
              <geom name="//unnamed_geom_36" class="visual" mesh="Hip_Yaw_Left"/>
              <geom name="//unnamed_geom_37" class="collision" size="0.0722371 0.115579" type="cylinder"/>
              <body name="Shank_Left" pos="-0.0155426 0.0140982 -0.221068" quat="1 7.77517e-05 0.000126647 6.86446e-05">
                <inertial pos="-0.00224627 0.0122772 -0.201826" quat="0.99723 0.0581444 -0.0288049 0.0363674" mass="4.03515" diaginertia="0.310762 0.0497275 0.0229643"/>
                <joint name="Left_Knee_Pitch" pos="0 0 0" axis="0.0191786 0.999438 -0.0274846" range="-0.14222 2.51581" armature="0.00499528" damping="0.0685411" frictionloss="0.182344"/>
                <geom name="//unnamed_geom_38" class="visual" mesh="Shank_Left"/>
                <geom name="//unnamed_geom_39" class="collision" size="0.0722371 0.108356" pos="0 0 -0.197089" type="cylinder"/>
                <geom name="//unnamed_geom_40" class="reward_collision_sphere" size="0.0939082"/>
                <body name="Ankle_Cross_Left" pos="-0.000430709 -0.0113475 -0.447065" quat="0.999975 -0.00219706 -0.00133809 0.00655085">
                  <inertial pos="0.00252535 0.0158104 -0.00968656" quat="0.448855 0.565975 0.503328 0.474197" mass="0.226442" diaginertia="0.000302411 3.53614e-05 0.000118711"/>
                  <joint name="Left_Ankle_Pitch" pos="0 0 0" axis="-0.0037012 0.998641 -0.0519861" stiffness="0.0265444" range="-0.962112 0.22392" armature="0.0189714" damping="0.0183979" frictionloss="0.125707"/>
                  <geom name="//unnamed_geom_41" class="visual" mesh="Ankle_Cross_Left"/>
                  <body name="left_foot_link" pos="0.0129448 0.0155149 -0.0133324" quat="1 1.42334e-05 -3.77379e-05 -4.37335e-05">
                    <inertial pos="-0.0140182 0.00207032 -0.0312254" quat="-0.0167255 0.616257 0.01999 0.787113" mass="2.12971" diaginertia="0.0309542 0.00391176 0.0303579"/>
                    <joint name="Left_Ankle_Roll" pos="0 0 0" axis="-0.999999 -0.000886392 -0.00133468" range="-0.435527 0.435706" armature="0.0251313" damping="0.0601842" frictionloss="0.148671"/>
                    <geom name="//unnamed_geom_42" class="visual" mesh="left_foot_link"/>
                    <geom name="left_foot" class="foot" size="0.13177 0.100926 0.0171358" pos="0.0159006 0 -0.0246361"/>
                    <geom name="//unnamed_geom_44" class="reward_collision_sphere" size="0.0751266" pos="0.0159006 0 -0.0246361"/>
                    <geom name="//unnamed_geom_45" class="reward_collision_sphere" size="0.0433423" pos="0.151056 -0.0253404 -0.0246361"/>
                    <geom name="//unnamed_geom_46" class="reward_collision_sphere" size="0.0433423" pos="-0.111304 -0.0253404 -0.0246361"/>
                    <site name="left_foot" class="foot" pos="0.0159006 0 -0.0246361" size="0.0144474"/>
                  </body>
                </body>
              </body>
            </body>
          </body>
        </body>
        <body name="Hip_Pitch_Right" pos="0.0122885 -0.117045 0.0105838" quat="0.999967 0.00565499 -0.00577165 0.000162329">
          <inertial pos="0.00498384 0.0252213 -0.0305511" quat="0.970419 -0.239145 -0.0331032 0.00028067" mass="3.18145" diaginertia="0.0217451 0.00274687 0.0191344"/>
          <joint name="Right_Hip_Pitch" pos="0 0 0" axis="-3.98344e-06 -1 6.42231e-05" stiffness="0.0332637" range="-1.33929 1.81495" armature="0.0205926" damping="0.00400357" frictionloss="0.0332341"/>
          <geom name="//unnamed_geom_47" class="visual" rgba="0.76 0.76 0.76 1" mesh="Hip_Pitch_Right"/>
          <body name="Hip_Roll_Right" pos="-0.00399753 0.00730456 -0.0254875" quat="1 -2.44868e-05 -9.18784e-07 8.88672e-05">
            <inertial pos="0.0160754 -0.0161959 -0.0726637" quat="0.728495 -0.00188649 0.0194814 0.684771" mass="1.09023" diaginertia="0.0162814 0.00239458 0.00600283"/>
            <joint name="Right_Hip_Roll" pos="0 0 0" axis="-0.999994 -0.000429031 -0.00351652" range="-0.142734 1.57626" armature="0.00857609" damping="0" frictionloss="0.120887"/>
            <geom name="//unnamed_geom_48" class="visual" mesh="Hip_Roll_Right"/>
            <geom name="//unnamed_geom_49" class="reward_collision_sphere" size="0.0794608"/>
            <body name="Hip_Yaw_Right" pos="0.00179845 0.0105831 -0.130372" quat="0.999992 -0.00381296 0.000488839 -0.00130408">
              <inertial pos="-0.0217101 0.0104284 -0.151624" quat="0.712294 -0.0350042 -0.0335275 0.700206" mass="6.67233" diaginertia="0.222274 0.040956 0.0296246"/>
              <joint name="Right_Hip_Yaw" pos="0 0 0" axis="0.00222717 -0.00669135 -0.999975" stiffness="0.0124767" range="-0.918926 1.26096" armature="0.0265902" damping="0" frictionloss="0.0382769"/>
              <geom name="//unnamed_geom_50" class="visual" mesh="Hip_Yaw_Right"/>
              <geom name="//unnamed_geom_51" class="collision" size="0.0722371 0.115579" type="cylinder"/>
              <body name="Shank_Right" pos="-0.0293126 -0.0149462 -0.22409" quat="0.999975 0.00072241 -0.00398711 -0.00579105">
                <inertial pos="-0.0104759 -0.0123021 -0.216872" quat="0.997404 -0.00235729 -0.0719699 -0.000284002" mass="6.20798" diaginertia="0.400002 0.0581402 0.0185216"/>
                <joint name="Right_Knee_Pitch" pos="0 0 0" axis="-0.00265446 -0.997704 -0.067675" stiffness="0.00150512" range="-2.60283 0.255371" armature="0.0174525" damping="0" frictionloss="0.196395"/>
                <geom name="//unnamed_geom_52" class="visual" mesh="Shank_Right"/>
                <geom name="//unnamed_geom_53" class="collision" size="0.0722371 0.108356" pos="0 0 -0.197089" type="cylinder"/>
                <geom name="//unnamed_geom_54" class="reward_collision_sphere" size="0.0939082"/>
                <body name="Ankle_Cross_Right" pos="-0.00919938 0.0132133 -0.461367" quat="0.999964 -0.00161814 -0.0078263 -0.00275883">
                  <inertial pos="0.00118575 0.00686309 -0.0251772" quat="0.407008 0.549375 0.557349 0.471056" mass="0.21448" diaginertia="0.000273192 4.17256e-05 0.000156882"/>
                  <joint name="Right_Ankle_Pitch" pos="0 0 0" axis="-0.0252869 -0.999376 -0.0246506" stiffness="0.020026" range="-0.0880519 0.817968" armature="0.012796" damping="0.00562412" frictionloss="0.170319"/>
                  <geom name="//unnamed_geom_55" class="visual" mesh="Ankle_Cross_Right"/>
                  <body name="right_foot_link" pos="0.00620588 0.0137344 -0.0110733" quat="0.999997 4.21414e-05 0.00098508 0.00214101">
                    <inertial pos="0.00155675 -0.00671247 -0.00213546" quat="-0.0200786 0.625942 0.0159895 0.779447" mass="2.24827" diaginertia="0.0267136 0.0038611 0.0298801"/>
                    <joint name="Right_Ankle_Roll" pos="0 0 0" axis="-0.99843 -0.0519005 -0.0210483" stiffness="0.0518316" range="-0.777428 0.456461" armature="0.00438145" damping="0.0083043" frictionloss="0.225802"/>
                    <geom name="//unnamed_geom_56" class="visual" mesh="right_foot_link"/>
                    <geom name="right_foot" class="foot" size="0.166842 0.101266 0.020731" pos="0.0159006 0 -0.0246361"/>
                    <geom name="//unnamed_geom_58" class="reward_collision_sphere" size="0.0577897"/>
                    <geom name="//unnamed_geom_59" class="reward_collision_sphere" size="0.0433423" pos="0.0159006 0 -0.0246361"/>
                    <geom name="//unnamed_geom_60" class="reward_collision_sphere" size="0.0433423" pos="0.151056 0.0253404 -0.0246361"/>
                    <geom name="//unnamed_geom_61" class="reward_collision_sphere" size="0.0433423" pos="-0.111304 0.0253404 -0.0246361"/>
                    <site name="right_foot" class="foot" pos="0.0159006 0 -0.0246361" size="0.0144474"/>
                  </body>
                </body>
              </body>
            </body>
          </body>
        </body>
      </body>
    </body>
  </worldbody>

  <contact>
    <pair class="/" geom1="floor" geom2="left_foot" name="//unnamed_contact_0"/>
    <pair class="/" geom1="floor" geom2="right_foot" name="//unnamed_contact_1"/>
  </contact>

  <actuator>
    <general name="AAHead_yaw" class="/" joint="AAHead_yaw" forcerange="-13.8315 13.8315" gainprm="39.6611" biasprm="0 -39.6611 -0.935761"/>
    <general name="Head_pitch" class="/" joint="Head_pitch" forcerange="-5.9513 5.9513" gainprm="39.6611" biasprm="0 -39.6611 -0.935761"/>
    <general name="Left_Shoulder_Pitch" class="/" joint="Left_Shoulder_Pitch" forcerange="-29.5999 29.5999" gainprm="39.6611" biasprm="0 -39.6611 -0.935761"/>
    <general name="Left_Shoulder_Roll" class="/" joint="Left_Shoulder_Roll" forcerange="-12.8667 12.8667" gainprm="39.6611" biasprm="0 -39.6611 -0.935761"/>
    <general name="Left_Elbow_Pitch" class="/" joint="Left_Elbow_Pitch" forcerange="-29.0859 29.0859" gainprm="39.6611" biasprm="0 -39.6611 -0.935761"/>
    <general name="Left_Elbow_Yaw" class="/" joint="Left_Elbow_Yaw" forcerange="-26.2902 26.2902" gainprm="39.6611" biasprm="0 -39.6611 -0.935761"/>
    <general name="Right_Shoulder_Pitch" class="/" joint="Right_Shoulder_Pitch" forcerange="-26.6038 26.6038" gainprm="39.6611" biasprm="0 -39.6611 -0.935761"/>
    <general name="Right_Shoulder_Roll" class="/" joint="Right_Shoulder_Roll" forcerange="-32.7749 32.7749" gainprm="39.6611" biasprm="0 -39.6611 -0.935761"/>
    <general name="Right_Elbow_Pitch" class="/" joint="Right_Elbow_Pitch" forcerange="-21.4989 21.4989" gainprm="39.6611" biasprm="0 -39.6611 -0.935761"/>
    <general name="Right_Elbow_Yaw" class="/" joint="Right_Elbow_Yaw" forcerange="-30.735 30.735" gainprm="39.6611" biasprm="0 -39.6611 -0.935761"/>
    <general name="Waist" class="/" joint="Waist" forcerange="-65.3914 65.3914" gainprm="39.6611" biasprm="0 -39.6611 -0.935761"/>
    <general name="Left_Hip_Pitch" class="/" joint="Left_Hip_Pitch" forcerange="-80.8116 80.8116" gainprm="39.6611" biasprm="0 -39.6611 -0.935761"/>
    <general name="Left_Hip_Roll" class="/" joint="Left_Hip_Roll" forcerange="-45.0365 45.0365" gainprm="39.6611" biasprm="0 -39.6611 -0.935761"/>
    <general name="Left_Hip_Yaw" class="/" joint="Left_Hip_Yaw" forcerange="-50.8705 50.8705" gainprm="39.6611" biasprm="0 -39.6611 -0.935761"/>
    <general name="Left_Knee_Pitch" class="/" joint="Left_Knee_Pitch" forcerange="-127.988 127.988" gainprm="39.6611" biasprm="0 -39.6611 -0.935761"/>
    <general name="Left_Ankle_Pitch" class="/" joint="Left_Ankle_Pitch" forcerange="-11.5566 11.5566" gainprm="39.6611" biasprm="0 -39.6611 -0.935761"/>
    <general name="Left_Ankle_Roll" class="/" joint="Left_Ankle_Roll" forcerange="-35.3106 35.3106" gainprm="39.6611" biasprm="0 -39.6611 -0.935761"/>
    <general name="Right_Hip_Pitch" class="/" joint="Right_Hip_Pitch" forcerange="-67.98 67.98" gainprm="39.6611" biasprm="0 -39.6611 -0.935761"/>
    <general name="Right_Hip_Roll" class="/" joint="Right_Hip_Roll" forcerange="-64.097 64.097" gainprm="39.6611" biasprm="0 -39.6611 -0.935761"/>
    <general name="Right_Hip_Yaw" class="/" joint="Right_Hip_Yaw" forcerange="-19.4586 19.4586" gainprm="39.6611" biasprm="0 -39.6611 -0.935761"/>
    <general name="Right_Knee_Pitch" class="/" joint="Right_Knee_Pitch" forcerange="-68.2359 68.2359" gainprm="39.6611" biasprm="0 -39.6611 -0.935761"/>
    <general name="Right_Ankle_Pitch" class="/" joint="Right_Ankle_Pitch" forcerange="-28.3983 28.3983" gainprm="39.6611" biasprm="0 -39.6611 -0.935761"/>
    <general name="Right_Ankle_Roll" class="/" joint="Right_Ankle_Roll" forcerange="-21.5966 21.5966" gainprm="39.6611" biasprm="0 -39.6611 -0.935761"/>
  </actuator>

  <sensor>
    <gyro site="imu" name="imu_angular_velocity"/>
    <velocimeter site="imu" name="imu_linear_velocity"/>
    <framelinvel objtype="site" objname="left_foot" name="left_foot_global_linear_velocity"/>
    <framelinvel objtype="site" objname="right_foot" name="right_foot_global_linear_velocity"/>
  </sensor>

  <keyframe>
    <key name="home" qpos="0 0 0.6385 1 0 0 0 0 0 0 1.4 0 -0.4 0 -1.4 0 0.4 0 -0.4 0 0 0.8 -0.4 0 0.4 0 0 -0.8 0.4 0"/>
  </keyframe>
</mujoco>
