<mujoco model="T1">
  <compiler angle="radian" assetdir="assets" balanceinertia="true" inertiafromgeom="false"/>

  <option timestep="0.005" density="1.2" viscosity="2e-05"/>

  <size nkey="1"/>

  <visual>
    <quality shadowsize="8192"/>
    <map shadowclip="0.5"/>
  </visual>

  <default>
    <default class="/">
      <joint armature="0.01" damping="0.01" frictionloss="0.1"/>
      <geom contype="0" conaffinity="0" group="1" solref="-1000 -80"/>
      <site size="0.01 0.005 0.005" group="5"/>
      <general forcelimited="true" biastype="affine" gainprm="25" biasprm="0 -25 -0.6"/>
      <default class="t1">
        <geom rgba="0.25 0.25 0.25 1"/>
        <default class="visual">
          <geom type="mesh" group="2"/>
        </default>
        <default class="collision">
          <geom group="3"/>
        </default>
        <default class="foot">
          <geom size="0.1115 0.05 0.015" type="box" condim="6" group="4" priority="1" solimp="0.015 1 0.015"/>
        </default>
        <default class="reward_collision_sphere">
          <geom group="5" rgba="1 0 0 1"/>
        </default>
      </default>
    </default>
  </default>

  <asset>
    <texture type="skybox" colorspace="auto" name="//unnamed_texture_0" builtin="gradient" rgb1="0.95 0.95 0.95" rgb2="0.95 0.95 0.95" width="100" height="600"/>
    <texture type="2d" colorspace="auto" name="texplane" builtin="checker" rgb1="0.345 0.575 0.748" rgb2="0.345 0.575 0.748" markrgb="1 1 1" width="512" height="512"/>
    <material name="MatPlane" class="/" texture="texplane" texuniform="true" texrepeat="2 2" specular="0.9"/>
    <mesh name="Trunk" class="/" file="Trunk.stl"/>
    <mesh name="H1" class="/" file="H1.stl"/>
    <mesh name="H2" class="/" file="H2.stl"/>
    <mesh name="AL1" class="/" file="AL1.stl"/>
    <mesh name="AL2" class="/" file="AL2.stl"/>
    <mesh name="AL3" class="/" file="AL3.stl"/>
    <mesh name="left_hand_link" class="/" file="left_hand_link.stl"/>
    <mesh name="AR1" class="/" file="AR1.stl"/>
    <mesh name="AR2" class="/" file="AR2.stl"/>
    <mesh name="AR3" class="/" file="AR3.stl"/>
    <mesh name="right_hand_link" class="/" file="right_hand_link.stl"/>
    <mesh name="Waist" class="/" file="Waist.stl"/>
    <mesh name="Hip_Pitch_Left" class="/" file="Hip_Pitch_Left.stl"/>
    <mesh name="Hip_Roll_Left" class="/" file="Hip_Roll_Left.stl"/>
    <mesh name="Hip_Yaw_Left" class="/" file="Hip_Yaw_Left.stl"/>
    <mesh name="Shank_Left" class="/" file="Shank_Left.stl"/>
    <mesh name="Ankle_Cross_Left" class="/" file="Ankle_Cross_Left.stl"/>
    <mesh name="left_foot_link" class="/" file="left_foot_link.stl"/>
    <mesh name="Hip_Pitch_Right" class="/" file="Hip_Pitch_Right.stl"/>
    <mesh name="Hip_Roll_Right" class="/" file="Hip_Roll_Right.stl"/>
    <mesh name="Hip_Yaw_Right" class="/" file="Hip_Yaw_Right.stl"/>
    <mesh name="Shank_Right" class="/" file="Shank_Right.stl"/>
    <mesh name="Ankle_Cross_Right" class="/" file="Ankle_Cross_Right.stl"/>
    <mesh name="right_foot_link" class="/" file="right_foot_link.stl"/>
  </asset>

  <worldbody>
    <geom name="floor" class="/" size="100 100 0.125" type="plane" group="0" material="MatPlane"/>
    <light name="toplight_shadow" class="/" pos="0 0 5" dir="0.0990148 0.0990148 -0.990148" type="directional" ambient="0.04 0.04 0.04" diffuse="0.55 0.55 0.55" specular="0.12 0.12 0.12"/>
    <light name="toplight_fill" class="/" pos="0 0 5" dir="0.0990148 0.0990148 -0.990148" type="directional" castshadow="false" ambient="0.04 0.04 0.04" diffuse="0.3 0.3 0.3" specular="0.08 0.08 0.08"/>
    <body name="trunk" childclass="t1" pos="0.000116815 0.000460128 0.000538981" quat="1 0.000417355 -6.24489e-05 -0.000229954">
      <inertial pos="0.0510491 0.000150981 0.108299" quat="0.99992 0.00373132 -0.0120672 0.00104156" mass="10.3499" diaginertia="0.0646619 0.0543789 0.0649863"/>
      <joint name="//unnamed_joint_0" type="free" armature="0" damping="0" frictionloss="0"/>
      <geom name="//unnamed_geom_1" class="visual" rgba="0.76 0.76 0.76 1" mesh="Trunk"/>
      <geom name="//unnamed_geom_2" class="collision" size="0.0720645 0.096086 0.144129" pos="0.0553721 0 0.123222" type="box"/>
      <geom name="//unnamed_geom_3" class="reward_collision_sphere" size="0.110499" pos="0.0553721 0 0.102685"/>
      <geom name="//unnamed_geom_4" class="reward_collision_sphere" size="0.0144129" pos="0.0553721 0.0792935 0"/>
      <geom name="//unnamed_geom_5" class="reward_collision_sphere" size="0.0144129" pos="0.0553721 -0.0792935 0"/>
      <geom name="//unnamed_geom_6" class="reward_collision_sphere" size="0.0144129" pos="0.0553721 0.0998166 0.184832"/>
      <geom name="//unnamed_geom_7" class="reward_collision_sphere" size="0.0144129" pos="0.0553721 -0.0998166 0.184832"/>
      <site name="imu" pos="0.00392052 2.09539e-05 -0.00350176" size="0.0096086"/>
      <camera name="track" pos="0 -1.86573 0" quat="0.707107 0.707107 0 0" mode="trackcom"/>
      <camera name="ego_camera" pos="0.11259 0 0.431276" quat="-0.5 -0.5 0.5 0.5"/>
      <body name="H1" pos="0.0555315 -0.000375932 0.24725" quat="1 -9.08157e-05 -3.47896e-05 -8.45484e-05">
        <inertial pos="-0.000896928 -0.00202399 0.0589873" quat="0.764581 -0.0139206 0.00251295 0.644372" mass="0.394912" diaginertia="0.000161316 0.00015562 0.000171877"/>
        <joint name="AAHead_yaw" pos="0 0 0" axis="-0.000473142 0.000929908 0.999999" range="-1.55379 1.57766" armature="0.0106142" damping="0.0122549" frictionloss="0.105387"/>
        <geom name="//unnamed_geom_8" class="visual" mesh="H1"/>
        <body name="H2" pos="0.000159762 -0.00276126 0.0644304" quat="1 0.000422145 -0.000144426 0.000180082">
          <inertial pos="0.00766386 -0.00107488 0.0988966" quat="0.988607 0.101599 -0.073307 -0.0834224" mass="0.558113" diaginertia="0.00137776 0.00132753 0.0019771"/>
          <joint name="Head_pitch" pos="0 0 0" axis="-0.00279226 -0.999984 -0.00484912" range="-1.21382 0.364592" armature="0.00960199" damping="0" frictionloss="0.0971079"/>
          <geom name="//unnamed_geom_9" class="visual" mesh="H2"/>
          <geom name="//unnamed_geom_10" class="collision" size="0.0768688" pos="0.00922868 0 0.112953"/>
          <geom name="//unnamed_geom_11" class="reward_collision_sphere" size="0.0864774" pos="0.0184574 0 0.102685"/>
        </body>
      </body>
      <body name="AL1" pos="0.0536421 0.10057 0.222978" quat="0.999999 0.000697383 0.00139116 -0.000257096">
        <inertial pos="-0.00125968 0.0421969 -0.000452981" quat="0.50367 0.496262 -0.504075 0.495932" mass="0.47265" diaginertia="0.000917725 0.000891561 0.000328833"/>
        <joint name="Left_Shoulder_Pitch" pos="0 0 0" axis="-0.00324299 0.999969 -0.00715371" stiffness="0.00308276" range="-3.30298 1.26672" armature="0.00967931" damping="0" frictionloss="0.0943013"/>
        <geom name="//unnamed_geom_12" class="visual" rgba="0.76 0.76 0.76 1" mesh="AL1"/>
        <body name="AL2" pos="-0.000539327 0.043256 -0.000775497" quat="1 0.000357873 7.43167e-05 -0.00018409">
          <inertial pos="0.00434656 0.0373819 0.000200025" quat="0.488036 0.51153 -0.488088 0.511788" mass="0.141255" diaginertia="0.000269214 0.000242719 0.000202577"/>
          <joint name="Left_Shoulder_Roll" pos="0 0 0" axis="-0.999998 0.000679754 0.0020425" range="-1.58317 1.74428" armature="0.0106772" damping="0.00865579" frictionloss="0.0954756"/>
          <geom name="//unnamed_geom_13" class="visual" mesh="AL2"/>
          <body name="AL3" pos="-0.000138584 0.0569762 -0.000252802" quat="1 0.000366915 0.000303102 3.26995e-05">
            <inertial pos="0.00136751 0.0774697 -0.00124207" quat="0.706493 0.707719 -0.000121003 0.000884449" mass="0.86926" diaginertia="0.0086548 0.00894142 0.000689391"/>
            <joint name="Left_Elbow_Pitch" pos="0 0 0" axis="0.000376785 -0.999994 -0.00338287" range="-2.32001 2.28758" armature="0.0108538" damping="0.0101935" frictionloss="0.0953593"/>
            <geom name="//unnamed_geom_14" class="visual" mesh="AL3"/>
            <geom name="//unnamed_geom_15" class="collision" size="0.0288258 0.0720645" pos="0 0.0466433 0" quat="0.707105 0.707108 0 0" type="cylinder"/>
            <geom name="//unnamed_geom_16" class="reward_collision_sphere" size="0.034591"/>
            <body name="left_hand_link" pos="0.00143734 0.137037 0.00015836" quat="0.999999 -0.000112705 -0.000915456 -0.00058763">
              <inertial pos="-0.00229793 0.101499 0.000246458" quat="0.705294 0.708913 0.0014974 -0.000371882" mass="0.291485" diaginertia="0.00533532 0.00568067 0.000251195"/>
              <joint name="Left_Elbow_Yaw" pos="0 0 0" axis="-0.000462997 -0.000217324 1" stiffness="0.000560589" range="-2.44885 -0.043962" armature="0.00955802" damping="0.0094761" frictionloss="0.0950911"/>
              <geom name="//unnamed_geom_17" class="visual" mesh="left_hand_link"/>
              <geom name="//unnamed_geom_18" class="collision" size="0.0288258 0.0840753" pos="0 0.121272 0" quat="0.707105 0.707108 0 0" type="cylinder"/>
              <geom name="//unnamed_geom_19" class="reward_collision_sphere" size="0.048043"/>
              <geom name="//unnamed_geom_20" class="reward_collision_sphere" size="0.0336301" pos="0 0.102615 0"/>
              <geom name="//unnamed_geom_21" class="reward_collision_sphere" size="0.0336301" pos="0 0.200566 0"/>
            </body>
          </body>
        </body>
      </body>
      <body name="AR1" pos="0.0516699 -0.100031 0.223748" quat="1 0.000349489 0.000743837 -0.000382922">
        <inertial pos="-0.00117431 -0.044715 0.000456693" quat="0.504685 0.49572 -0.503959 0.495561" mass="0.454765" diaginertia="0.00090325 0.000889929 0.000323662"/>
        <joint name="Right_Shoulder_Pitch" pos="0 0 0" axis="0.00478153 -0.999932 0.0106614" range="-1.23207 3.31746" armature="0.010426" damping="0.0143494" frictionloss="0.0990595"/>
        <geom name="//unnamed_geom_22" class="visual" rgba="0.76 0.76 0.76 1" mesh="AR1"/>
        <body name="AR2" pos="0.00178277 -0.0422215 1.37732e-05" quat="0.999999 -0.000144348 0.000813762 -0.000784593">
          <inertial pos="0.00335147 -0.0348023 0.00126947" quat="0.511978 0.489597 -0.50858 0.489407" mass="0.13835" diaginertia="0.000268066 0.000250001 0.000203319"/>
          <joint name="Right_Shoulder_Roll" pos="0 0 0" axis="-0.999978 0.00321956 -0.00574316" range="-1.76011 1.55003" armature="0.00945285" damping="0.0038201" frictionloss="0.108022"/>
          <geom name="//unnamed_geom_23" class="visual" mesh="AR2"/>
          <body name="AR3" pos="-0.000275271 -0.0579198 -0.00255116" quat="1 5.79434e-07 -1.09098e-06 -9.41997e-07">
            <inertial pos="0.000109556 -0.0817246 0.00094318" quat="0.710402 0.703752 -0.0074278 0.00247209" mass="0.904805" diaginertia="0.00859348 0.00911863 0.000723758"/>
            <joint name="Right_Elbow_Pitch" pos="0 0 0" axis="-0.00655828 0.999965 -0.00514444" range="-2.30718 2.26915" armature="0.00856203" damping="0.00923321" frictionloss="0.0978332"/>
            <geom name="//unnamed_geom_24" class="visual" mesh="AR3"/>
            <geom name="//unnamed_geom_25" class="collision" size="0.0288258 0.0720645" pos="0 -0.0466433 0" quat="0.707105 0.707108 0 0" type="cylinder"/>
            <geom name="//unnamed_geom_26" class="reward_collision_sphere" size="0.034591"/>
            <body name="right_hand_link" pos="-0.000710221 -0.137231 -0.00100296" quat="1 0.000514435 0.000183241 0.000177141">
              <inertial pos="0.000116802 -0.101404 0.00316665" quat="0.706295 0.707918 0.000106983 -0.000110238" mass="0.292975" diaginertia="0.00546864 0.00582589 0.000246841"/>
              <joint name="Right_Elbow_Yaw" pos="0 0 0" axis="0.000978007 -0.00134576 0.999999" range="-0.00880261 2.44555" armature="0.0105428" damping="0" frictionloss="0.100398"/>
              <geom name="//unnamed_geom_27" class="visual" mesh="right_hand_link"/>
              <geom name="//unnamed_geom_28" class="collision" size="0.0288258 0.0840753" pos="0 -0.121272 0" quat="0.707105 0.707108 0 0" type="cylinder"/>
              <geom name="//unnamed_geom_29" class="reward_collision_sphere" size="0.048043"/>
              <geom name="//unnamed_geom_30" class="reward_collision_sphere" size="0.0336301" pos="0 -0.102615 0"/>
              <geom name="//unnamed_geom_31" class="reward_collision_sphere" size="0.0336301" pos="0 -0.200566 0"/>
            </body>
          </body>
        </body>
      </body>
      <body name="Waist" pos="0.058027 -0.00279728 -0.115991" quat="1 -5.05048e-05 -4.61783e-05 -0.000183736">
        <inertial pos="0.000430279 0.00019819 0.00737218" quat="0.983542 0.00852858 -0.180357 0.0065793" mass="2.2215" diaginertia="0.00348795 0.00360382 0.00525419"/>
        <joint name="Waist" pos="0 0 0" axis="-0.00468598 -0.00849516 0.999953" range="-1.57549 1.53303" armature="0.00974886" damping="0.0115427" frictionloss="0.104389"/>
        <geom name="//unnamed_geom_32" class="visual" mesh="Waist"/>
        <body name="Hip_Pitch_Left" pos="0.00132399 0.099119 -7.29769e-05" quat="1 0.000297608 -0.000178256 0.000307961">
          <inertial pos="0.000506633 -0.00685257 -0.0192632" quat="0.974968 0.221753 0.0154508 0.00485864" mass="0.904474" diaginertia="0.00121094 0.00106511 0.00142663"/>
          <joint name="Left_Hip_Pitch" pos="0 0 0" axis="-0.013873 0.999895 -0.00427207" range="-1.79686 1.61641" armature="0.00948473" damping="0.00104677" frictionloss="0.0958159"/>
          <geom name="//unnamed_geom_33" class="visual" rgba="0.76 0.76 0.76 1" mesh="Hip_Pitch_Left"/>
          <body name="Hip_Roll_Left" pos="0.00119907 0.00231959 -0.0196798" quat="0.999999 -0.00104432 -0.000454191 -0.000872017">
            <inertial pos="-0.000212511 -0.000227352 -0.0553226" quat="0.710511 -0.00561411 -0.00763797 0.703622" mass="0.333633" diaginertia="0.00116014 0.0010451 0.000569587"/>
            <joint name="Left_Hip_Roll" pos="0 0 0" axis="-0.999958 0.00819732 0.00407598" stiffness="0.00278901" range="-1.58513 0.207334" armature="0.00986278" damping="0.0105011" frictionloss="0.0979868"/>
            <geom name="//unnamed_geom_34" class="visual" mesh="Hip_Roll_Left"/>
            <geom name="//unnamed_geom_35" class="reward_collision_sphere" size="0.0528473"/>
            <body name="Hip_Yaw_Left" pos="-0.000120584 -0.000215949 -0.0839144" quat="1 1.53553e-05 -5.92407e-05 6.3991e-05">
              <inertial pos="-0.00563304 -0.00138512 -0.0917596" quat="0.694559 -0.0382409 -0.0217529 0.718089" mass="1.89372" diaginertia="0.017083 0.0174274 0.00288699"/>
              <joint name="Left_Hip_Yaw" pos="0 0 0" axis="-0.000169084 -0.00235842 -0.999997" range="-1.02826 1.00552" armature="0.00957001" damping="0.00608117" frictionloss="0.0985892"/>
              <geom name="//unnamed_geom_36" class="visual" mesh="Hip_Yaw_Left"/>
              <geom name="//unnamed_geom_37" class="collision" size="0.048043 0.0768688" type="cylinder"/>
              <body name="Shank_Left" pos="-0.0111578 -0.00156262 -0.137369" quat="1 -1.77844e-05 0.000158298 9.80088e-05">
                <inertial pos="-0.00460641 -0.000581738 -0.128277" quat="0.997625 0.00545212 -0.0179235 0.0662763" mass="1.53272" diaginertia="0.0232839 0.0244579 0.00206902"/>
                <joint name="Left_Knee_Pitch" pos="0 0 0" axis="0.00331793 0.99998 0.00538858" range="-0.0215174 2.34844" armature="0.0105433" damping="0.00290623" frictionloss="0.0999229"/>
                <geom name="//unnamed_geom_38" class="visual" mesh="Shank_Left"/>
                <geom name="//unnamed_geom_39" class="collision" size="0.048043 0.0720645" pos="0 0 -0.123222" type="cylinder"/>
                <geom name="//unnamed_geom_40" class="reward_collision_sphere" size="0.0624559"/>
                <body name="Ankle_Cross_Left" pos="0.000523941 0.00091314 -0.289329" quat="0.999999 -0.000739828 -0.000653789 -0.00026753">
                  <inertial pos="-0.00264831 -0.00220077 -0.0085322" quat="0.442431 0.553189 0.547215 0.445861" mass="0.0644705" diaginertia="1.94327e-05 1.84593e-05 1.30275e-05"/>
                  <joint name="Left_Ankle_Pitch" pos="0 0 0" axis="0.000657141 0.999994 0.00352281" range="-0.871175 0.328948" armature="0.0101937" damping="0.00669357" frictionloss="0.0986471"/>
                  <geom name="//unnamed_geom_41" class="visual" mesh="Ankle_Cross_Left"/>
                  <body name="left_foot_link" pos="-0.001665 -0.00230645 -0.0118704" quat="1 3.28237e-05 1.65476e-06 0.000157127">
                    <inertial pos="0.00161491 -0.000523201 -0.00686809" quat="-0.00339849 0.619128 -0.000766998 0.785282" mass="0.617608" diaginertia="0.00183626 0.00169676 0.00255166"/>
                    <joint name="Left_Ankle_Roll" pos="0 0 0" axis="-1 -0.000183712 0.000248283" stiffness="0.00201224" range="-0.43326 0.443446" armature="0.00862522" damping="0.00920913" frictionloss="0.0975633"/>
                    <geom name="//unnamed_geom_42" class="visual" mesh="left_foot_link"/>
                    <geom name="left_foot" class="foot" size="0.110027 0.0480609 0.013846" pos="0.00922868 0 -0.0154027"/>
                    <geom name="//unnamed_geom_44" class="reward_collision_sphere" size="0.0499647" pos="0.00922868 0 -0.0154027"/>
                    <geom name="//unnamed_geom_45" class="reward_collision_sphere" size="0.0288258" pos="0.0876725 -0.0214559 -0.0154027"/>
                    <geom name="//unnamed_geom_46" class="reward_collision_sphere" size="0.0288258" pos="-0.0646008 -0.0214559 -0.0154027"/>
                    <site name="left_foot" class="foot" pos="0.00922868 0 -0.0154027" size="0.0096086"/>
                  </body>
                </body>
              </body>
            </body>
          </body>
        </body>
        <body name="Hip_Pitch_Right" pos="-0.00181916 -0.0996816 -0.000372921" quat="0.999999 -0.000453022 0.000674701 0.00120698">
          <inertial pos="0.000558043 0.00448216 -0.0183601" quat="0.973429 -0.228474 0.0148014 -0.00406032" mass="0.883519" diaginertia="0.00117628 0.00101154 0.00140577"/>
          <joint name="Right_Hip_Pitch" pos="0 0 0" axis="-0.0037962 -0.999993 -0.000446165" range="-1.5877 1.80343" armature="0.00989961" damping="0.0128152" frictionloss="0.107229"/>
          <geom name="//unnamed_geom_47" class="visual" rgba="0.76 0.76 0.76 1" mesh="Hip_Pitch_Right"/>
          <body name="Hip_Roll_Right" pos="-0.000615088 0.00123434 -0.0192885" quat="1 7.18465e-05 0.000120702 0.000115831">
            <inertial pos="-0.000930075 0.00226746 -0.0573975" quat="0.709082 -0.00447281 -0.0080493 0.705066" mass="0.338119" diaginertia="0.00116502 0.00105882 0.000581095"/>
            <joint name="Right_Hip_Roll" pos="0 0 0" axis="-0.999997 -0.00139541 0.00200463" stiffness="0.00142385" range="-0.21074 1.56668" armature="0.0092654" damping="0.00953639" frictionloss="0.0975457"/>
            <geom name="//unnamed_geom_48" class="visual" mesh="Hip_Roll_Right"/>
            <geom name="//unnamed_geom_49" class="reward_collision_sphere" size="0.0528473"/>
            <body name="Hip_Yaw_Right" pos="-0.000257491 -0.000714367 -0.0825925" quat="1 0.00038026 0.000180537 7.46371e-05">
              <inertial pos="-0.0061847 -0.000647727 -0.0925877" quat="0.714453 -0.0315738 -0.0336253 0.698162" mass="1.8915" diaginertia="0.0173805 0.0177277 0.00300209"/>
              <joint name="Right_Hip_Yaw" pos="0 0 0" axis="-5.36805e-05 -0.00572935 -0.999984" stiffness="0.00461136" range="-0.988868 0.971593" armature="0.00840977" damping="0.0156634" frictionloss="0.106385"/>
              <geom name="//unnamed_geom_50" class="visual" mesh="Hip_Yaw_Right"/>
              <geom name="//unnamed_geom_51" class="collision" size="0.048043 0.0768688" type="cylinder"/>
              <body name="Shank_Right" pos="-0.0135452 0.00174657 -0.137695" quat="0.999999 -0.00105008 4.88014e-05 4.75941e-05">
                <inertial pos="-0.00570423 0.000998931 -0.123673" quat="0.999246 -0.00311911 -0.0262288 -0.0284579" mass="1.56307" diaginertia="0.0235523 0.0245438 0.00231602"/>
                <joint name="Right_Knee_Pitch" pos="0 0 0" axis="-0.00388089 -0.999974 -0.00607716" range="-2.30907 -0.0363331" armature="0.00963944" damping="0.0114271" frictionloss="0.100878"/>
                <geom name="//unnamed_geom_52" class="visual" mesh="Shank_Right"/>
                <geom name="//unnamed_geom_53" class="collision" size="0.048043 0.0720645" pos="0 0 -0.123222" type="cylinder"/>
                <geom name="//unnamed_geom_54" class="reward_collision_sphere" size="0.0624559"/>
                <body name="Ankle_Cross_Right" pos="0.000444776 -0.0023589 -0.287893" quat="0.999999 0.000260399 -0.000237725 0.00119839">
                  <inertial pos="-0.00241921 0.00117916 -0.00708595" quat="0.443127 0.551678 0.551339 0.441945" mass="0.0651608" diaginertia="1.92174e-05 1.81678e-05 1.27107e-05"/>
                  <joint name="Right_Ankle_Pitch" pos="0 0 0" axis="0.0071642 -0.999973 0.00187203" stiffness="0.00221042" range="-0.382883 0.878619" armature="0.00982687" damping="0.00933948" frictionloss="0.0954981"/>
                  <geom name="//unnamed_geom_55" class="visual" mesh="Ankle_Cross_Right"/>
                  <body name="right_foot_link" pos="0.000467466 -0.00287179 -0.0117352" quat="1 8.65854e-05 2.47838e-05 0.000207077">
                    <inertial pos="-0.000690759 -0.00121391 -0.0108578" quat="0.00359157 0.62192 0.00106552 0.783072" mass="0.616452" diaginertia="0.00182098 0.0016838 0.0024818"/>
                    <joint name="Right_Ankle_Roll" pos="0 0 0" axis="-0.999998 0.00199137 0.000275273" range="-0.388545 0.443409" armature="0.0104086" damping="0.00725517" frictionloss="0.0924299"/>
                    <geom name="//unnamed_geom_56" class="visual" mesh="right_foot_link"/>
                    <geom name="right_foot" class="foot" size="0.090679 0.047459 0.0137109" pos="0.00922868 0 -0.0154027"/>
                    <geom name="//unnamed_geom_58" class="reward_collision_sphere" size="0.0384344"/>
                    <geom name="//unnamed_geom_59" class="reward_collision_sphere" size="0.0288258" pos="0.00922868 0 -0.0154027"/>
                    <geom name="//unnamed_geom_60" class="reward_collision_sphere" size="0.0288258" pos="0.0876725 0.0214559 -0.0154027"/>
                    <geom name="//unnamed_geom_61" class="reward_collision_sphere" size="0.0288258" pos="-0.0646008 0.0214559 -0.0154027"/>
                    <site name="right_foot" class="foot" pos="0.00922868 0 -0.0154027" size="0.0096086"/>
                  </body>
                </body>
              </body>
            </body>
          </body>
        </body>
      </body>
    </body>
  </worldbody>

  <contact>
    <pair class="/" geom1="floor" geom2="left_foot" name="//unnamed_contact_0"/>
    <pair class="/" geom1="floor" geom2="right_foot" name="//unnamed_contact_1"/>
  </contact>

  <actuator>
    <general name="AAHead_yaw" class="/" joint="AAHead_yaw" forcerange="-6.74589 6.74589" gainprm="24.5153" biasprm="0 -24.5153 -0.585899"/>
    <general name="Head_pitch" class="/" joint="Head_pitch" forcerange="-6.88527 6.88527" gainprm="24.5153" biasprm="0 -24.5153 -0.585899"/>
    <general name="Left_Shoulder_Pitch" class="/" joint="Left_Shoulder_Pitch" forcerange="-17.4134 17.4134" gainprm="24.5153" biasprm="0 -24.5153 -0.585899"/>
    <general name="Left_Shoulder_Roll" class="/" joint="Left_Shoulder_Roll" forcerange="-18.2654 18.2654" gainprm="24.5153" biasprm="0 -24.5153 -0.585899"/>
    <general name="Left_Elbow_Pitch" class="/" joint="Left_Elbow_Pitch" forcerange="-17.0393 17.0393" gainprm="24.5153" biasprm="0 -24.5153 -0.585899"/>
    <general name="Left_Elbow_Yaw" class="/" joint="Left_Elbow_Yaw" forcerange="-17.4396 17.4396" gainprm="24.5153" biasprm="0 -24.5153 -0.585899"/>
    <general name="Right_Shoulder_Pitch" class="/" joint="Right_Shoulder_Pitch" forcerange="-17.4479 17.4479" gainprm="24.5153" biasprm="0 -24.5153 -0.585899"/>
    <general name="Right_Shoulder_Roll" class="/" joint="Right_Shoulder_Roll" forcerange="-17.9887 17.9887" gainprm="24.5153" biasprm="0 -24.5153 -0.585899"/>
    <general name="Right_Elbow_Pitch" class="/" joint="Right_Elbow_Pitch" forcerange="-16.775 16.775" gainprm="24.5153" biasprm="0 -24.5153 -0.585899"/>
    <general name="Right_Elbow_Yaw" class="/" joint="Right_Elbow_Yaw" forcerange="-17.7877 17.7877" gainprm="24.5153" biasprm="0 -24.5153 -0.585899"/>
    <general name="Waist" class="/" joint="Waist" forcerange="-27.223 27.223" gainprm="24.5153" biasprm="0 -24.5153 -0.585899"/>
    <general name="Left_Hip_Pitch" class="/" joint="Left_Hip_Pitch" forcerange="-44.8146 44.8146" gainprm="24.5153" biasprm="0 -24.5153 -0.585899"/>
    <general name="Left_Hip_Roll" class="/" joint="Left_Hip_Roll" forcerange="-28.8627 28.8627" gainprm="24.5153" biasprm="0 -24.5153 -0.585899"/>
    <general name="Left_Hip_Yaw" class="/" joint="Left_Hip_Yaw" forcerange="-29.3674 29.3674" gainprm="24.5153" biasprm="0 -24.5153 -0.585899"/>
    <general name="Left_Knee_Pitch" class="/" joint="Left_Knee_Pitch" forcerange="-53.9579 53.9579" gainprm="24.5153" biasprm="0 -24.5153 -0.585899"/>
    <general name="Left_Ankle_Pitch" class="/" joint="Left_Ankle_Pitch" forcerange="-20.9637 20.9637" gainprm="24.5153" biasprm="0 -24.5153 -0.585899"/>
    <general name="Left_Ankle_Roll" class="/" joint="Left_Ankle_Roll" forcerange="-13.0673 13.0673" gainprm="24.5153" biasprm="0 -24.5153 -0.585899"/>
    <general name="Right_Hip_Pitch" class="/" joint="Right_Hip_Pitch" forcerange="-43.6221 43.6221" gainprm="24.5153" biasprm="0 -24.5153 -0.585899"/>
    <general name="Right_Hip_Roll" class="/" joint="Right_Hip_Roll" forcerange="-27.2444 27.2444" gainprm="24.5153" biasprm="0 -24.5153 -0.585899"/>
    <general name="Right_Hip_Yaw" class="/" joint="Right_Hip_Yaw" forcerange="-31.2345 31.2345" gainprm="24.5153" biasprm="0 -24.5153 -0.585899"/>
    <general name="Right_Knee_Pitch" class="/" joint="Right_Knee_Pitch" forcerange="-55.6707 55.6707" gainprm="24.5153" biasprm="0 -24.5153 -0.585899"/>
    <general name="Right_Ankle_Pitch" class="/" joint="Right_Ankle_Pitch" forcerange="-19.1138 19.1138" gainprm="24.5153" biasprm="0 -24.5153 -0.585899"/>
    <general name="Right_Ankle_Roll" class="/" joint="Right_Ankle_Roll" forcerange="-14.5124 14.5124" gainprm="24.5153" biasprm="0 -24.5153 -0.585899"/>
  </actuator>

  <sensor>
    <gyro site="imu" name="imu_angular_velocity"/>
    <velocimeter site="imu" name="imu_linear_velocity"/>
    <framelinvel objtype="site" objname="left_foot" name="left_foot_global_linear_velocity"/>
    <framelinvel objtype="site" objname="right_foot" name="right_foot_global_linear_velocity"/>
  </sensor>

  <keyframe>
    <key name="home" qpos="0 0 0.6385 1 0 0 0 0 0 0 1.4 0 -0.4 0 -1.4 0 0.4 0 -0.4 0 0 0.8 -0.4 0 0.4 0 0 -0.8 0.4 0"/>
  </keyframe>
</mujoco>
