<mujoco model="T1">
  <compiler angle="radian" assetdir="assets" balanceinertia="true" inertiafromgeom="false"/>

  <option timestep="0.005" density="1.2" viscosity="2e-05"/>

  <size nkey="1"/>

  <visual>
    <quality shadowsize="8192"/>
    <map shadowclip="0.5"/>
  </visual>

  <default>
    <default class="/">
      <joint armature="0.01" damping="0.01" frictionloss="0.1"/>
      <geom contype="0" conaffinity="0" group="1" solref="-1000 -80"/>
      <site size="0.01 0.005 0.005" group="5"/>
      <general forcelimited="true" biastype="affine" gainprm="25" biasprm="0 -25 -0.6"/>
      <default class="t1">
        <geom rgba="0.25 0.25 0.25 1"/>
        <default class="visual">
          <geom type="mesh" group="2"/>
        </default>
        <default class="collision">
          <geom group="3"/>
        </default>
        <default class="foot">
          <geom size="0.1115 0.05 0.015" type="box" condim="6" group="4" priority="1" solimp="0.015 1 0.015"/>
        </default>
        <default class="reward_collision_sphere">
          <geom group="5" rgba="1 0 0 1"/>
        </default>
      </default>
    </default>
  </default>

  <asset>
    <texture type="skybox" colorspace="auto" name="//unnamed_texture_0" builtin="gradient" rgb1="0.95 0.95 0.95" rgb2="0.95 0.95 0.95" width="100" height="600"/>
    <texture type="2d" colorspace="auto" name="texplane" builtin="checker" rgb1="0.345 0.575 0.748" rgb2="0.345 0.575 0.748" markrgb="1 1 1" width="512" height="512"/>
    <material name="MatPlane" class="/" texture="texplane" texuniform="true" texrepeat="2 2" specular="0.9"/>
    <mesh name="Trunk" class="/" file="Trunk.stl"/>
    <mesh name="H1" class="/" file="H1.stl"/>
    <mesh name="H2" class="/" file="H2.stl"/>
    <mesh name="AL1" class="/" file="AL1.stl"/>
    <mesh name="AL2" class="/" file="AL2.stl"/>
    <mesh name="AL3" class="/" file="AL3.stl"/>
    <mesh name="left_hand_link" class="/" file="left_hand_link.stl"/>
    <mesh name="AR1" class="/" file="AR1.stl"/>
    <mesh name="AR2" class="/" file="AR2.stl"/>
    <mesh name="AR3" class="/" file="AR3.stl"/>
    <mesh name="right_hand_link" class="/" file="right_hand_link.stl"/>
    <mesh name="Waist" class="/" file="Waist.stl"/>
    <mesh name="Hip_Pitch_Left" class="/" file="Hip_Pitch_Left.stl"/>
    <mesh name="Hip_Roll_Left" class="/" file="Hip_Roll_Left.stl"/>
    <mesh name="Hip_Yaw_Left" class="/" file="Hip_Yaw_Left.stl"/>
    <mesh name="Shank_Left" class="/" file="Shank_Left.stl"/>
    <mesh name="Ankle_Cross_Left" class="/" file="Ankle_Cross_Left.stl"/>
    <mesh name="left_foot_link" class="/" file="left_foot_link.stl"/>
    <mesh name="Hip_Pitch_Right" class="/" file="Hip_Pitch_Right.stl"/>
    <mesh name="Hip_Roll_Right" class="/" file="Hip_Roll_Right.stl"/>
    <mesh name="Hip_Yaw_Right" class="/" file="Hip_Yaw_Right.stl"/>
    <mesh name="Shank_Right" class="/" file="Shank_Right.stl"/>
    <mesh name="Ankle_Cross_Right" class="/" file="Ankle_Cross_Right.stl"/>
    <mesh name="right_foot_link" class="/" file="right_foot_link.stl"/>
  </asset>

  <worldbody>
    <geom name="floor" class="/" size="100 100 0.125" type="plane" group="0" material="MatPlane"/>
    <light name="toplight_shadow" class="/" pos="0 0 5" dir="0.0990148 0.0990148 -0.990148" type="directional" ambient="0.04 0.04 0.04" diffuse="0.55 0.55 0.55" specular="0.12 0.12 0.12"/>
    <light name="toplight_fill" class="/" pos="0 0 5" dir="0.0990148 0.0990148 -0.990148" type="directional" castshadow="false" ambient="0.04 0.04 0.04" diffuse="0.3 0.3 0.3" specular="0.08 0.08 0.08"/>
    <body name="trunk" childclass="t1" pos="1.4197e-05 -0.00176063 -0.000519002" quat="0.999999 -0.000623643 -0.0011513 -0.000379106">
      <inertial pos="0.0525933 -0.00147835 0.106192" quat="0.999874 0.0121788 -0.008047 -0.00619214" mass="9.6155" diaginertia="0.0857108 0.0300168 0.0613155"/>
      <joint name="//unnamed_joint_0" type="free" armature="0" damping="0" frictionloss="0"/>
      <geom name="//unnamed_geom_1" class="visual" rgba="0.76 0.76 0.76 1" mesh="Trunk"/>
      <geom name="//unnamed_geom_2" class="collision" size="0.0705495 0.094066 0.141099" pos="0.0585881 0 0.121802" type="box"/>
      <geom name="//unnamed_geom_3" class="reward_collision_sphere" size="0.108176" pos="0.0585881 0 0.101502"/>
      <geom name="//unnamed_geom_4" class="reward_collision_sphere" size="0.0141099" pos="0.0585881 0.070592 0"/>
      <geom name="//unnamed_geom_5" class="reward_collision_sphere" size="0.0141099" pos="0.0585881 -0.070592 0"/>
      <geom name="//unnamed_geom_6" class="reward_collision_sphere" size="0.0141099" pos="0.0585881 0.0888628 0.182703"/>
      <geom name="//unnamed_geom_7" class="reward_collision_sphere" size="0.0141099" pos="0.0585881 -0.0888628 0.182703"/>
      <site name="imu" pos="0.0133367 -0.000137481 -0.0131624" size="0.0094066"/>
      <camera name="track" pos="0 -1.66099 0" quat="0.707107 0.707107 0 0" mode="trackcom"/>
      <camera name="ego_camera" pos="0.119129 0 0.426308" quat="-0.5 -0.5 0.5 0.5"/>
      <body name="H1" pos="0.0575139 -1.49064e-05 0.244149" quat="1 4.83593e-05 -3.28849e-05 -5.40161e-06">
        <inertial pos="-0.00173848 -0.000720707 0.0582841" quat="0.762812 -0.014288 -0.000196984 0.646462" mass="0.364208" diaginertia="0.00020804 8.80284e-05 0.000160458"/>
        <joint name="AAHead_yaw" pos="0 0 0" axis="-0.000167703 -0.00465566 0.999989" stiffness="0.00609672" range="-1.51479 1.56905" armature="0.0106152" damping="0.00589625" frictionloss="0.106717"/>
        <geom name="//unnamed_geom_8" class="visual" mesh="H1"/>
        <body name="H2" pos="-0.00239636 -0.00213261 0.0631648" quat="1 0.000273053 -0.000180854 -0.000328624">
          <inertial pos="0.00958086 -0.0023107 0.0978465" quat="0.990242 0.101988 -0.0643558 -0.0698359" mass="0.531236" diaginertia="0.0017751 0.000735259 0.00185317"/>
          <joint name="Head_pitch" pos="0 0 0" axis="0.000174002 -1 -5.69825e-05" range="-1.235 0.359673" armature="0.0105038" damping="0" frictionloss="0.0890413"/>
          <geom name="//unnamed_geom_9" class="visual" mesh="H2"/>
          <geom name="//unnamed_geom_10" class="collision" size="0.0752528" pos="0.00976468 0 0.111652"/>
          <geom name="//unnamed_geom_11" class="reward_collision_sphere" size="0.0846594" pos="0.0195294 0 0.101502"/>
        </body>
      </body>
      <body name="AL1" pos="0.056365 0.0882551 0.219848" quat="0.999999 0.00102508 5.33434e-05 0.000652262">
        <inertial pos="-0.00358081 0.0364994 0.000381965" quat="0.504523 0.495726 -0.503884 0.495797" mass="0.431661" diaginertia="0.0011838 0.000483726 0.000297209"/>
        <joint name="Left_Shoulder_Pitch" pos="0 0 0" axis="0.0024773 0.99986 -0.016546" range="-3.3454 1.27095" armature="0.00958448" damping="0" frictionloss="0.102798"/>
        <geom name="//unnamed_geom_12" class="visual" rgba="0.76 0.76 0.76 1" mesh="AL1"/>
        <body name="AL2" pos="-0.00143939 0.0406049 0.000356833" quat="1 0.000395545 -8.65683e-05 -0.000120874">
          <inertial pos="0.00278547 0.0342086 -0.0019514" quat="0.490036 0.50737 -0.488148 0.513957" mass="0.138435" diaginertia="0.000367367 0.000138972 0.000190905"/>
          <joint name="Left_Shoulder_Roll" pos="0 0 0" axis="-0.999997 -0.00158564 0.00167991" range="-1.54008 1.73953" armature="0.0106456" damping="0.00588551" frictionloss="0.0938782"/>
          <geom name="//unnamed_geom_13" class="visual" mesh="AL2"/>
          <body name="AL3" pos="0.00128728 0.0498877 0.00192252" quat="1 0.000185975 0.000239715 2.82058e-05">
            <inertial pos="0.00234343 0.0683129 0.000146447" quat="0.709465 0.704679 0.00782369 0.00502657" mass="0.793036" diaginertia="0.0114166 0.00489151 0.00062356"/>
            <joint name="Left_Elbow_Pitch" pos="0 0 0" axis="-0.00191522 -0.999967 0.00795628" range="-2.32149 2.24893" armature="0.0103103" damping="0.0156414" frictionloss="0.0931367"/>
            <geom name="//unnamed_geom_14" class="visual" mesh="AL3"/>
            <geom name="//unnamed_geom_15" class="collision" size="0.0282198 0.0705495" pos="0 0.0415247 0" quat="0.707105 0.707108 0 0" type="cylinder"/>
            <geom name="//unnamed_geom_16" class="reward_collision_sphere" size="0.0338638"/>
            <body name="left_hand_link" pos="0.00115884 0.121339 -0.0018308" quat="0.999999 -0.000713617 0.000750461 0.000635078">
              <inertial pos="-0.00248643 0.0923455 0.000561358" quat="0.706319 0.707893 -0.000371381 0.00120422" mass="0.271279" diaginertia="0.00701364 0.00326437 0.000240161"/>
              <joint name="Left_Elbow_Yaw" pos="0 0 0" axis="0.00384771 -0.00434259 0.999983" range="-2.44293 -0.0419633" armature="0.00991856" damping="0.019102" frictionloss="0.0963935"/>
              <geom name="//unnamed_geom_17" class="visual" mesh="left_hand_link"/>
              <geom name="//unnamed_geom_18" class="collision" size="0.0282198 0.0823077" pos="0 0.107964 0" quat="0.707105 0.707108 0 0" type="cylinder"/>
              <geom name="//unnamed_geom_19" class="reward_collision_sphere" size="0.047033"/>
              <geom name="//unnamed_geom_20" class="reward_collision_sphere" size="0.0329231" pos="0 0.0913543 0"/>
              <geom name="//unnamed_geom_21" class="reward_collision_sphere" size="0.0329231" pos="0 0.178556 0"/>
            </body>
          </body>
        </body>
      </body>
      <body name="AR1" pos="0.0565001 -0.0900321 0.220563" quat="1 -9.27257e-05 0.000652426 0.00019927">
        <inertial pos="-0.00308107 -0.0395253 0.000498084" quat="0.51029 0.492054 -0.509127 0.488135" mass="0.426362" diaginertia="0.00114783 0.000494968 0.000308012"/>
        <joint name="Right_Shoulder_Pitch" pos="0 0 0" axis="0.0126012 -0.999857 0.0112677" range="-1.21685 3.27262" armature="0.0106993" damping="0.00671872" frictionloss="0.0867674"/>
        <geom name="//unnamed_geom_22" class="visual" rgba="0.76 0.76 0.76 1" mesh="AR1"/>
        <body name="AR2" pos="0.00196845 -0.0353538 -0.00216695" quat="0.999999 -0.000870255 4.64424e-05 -0.001165">
          <inertial pos="0.00148293 -0.0320302 0.000556093" quat="0.511521 0.487913 -0.507315 0.492868" mass="0.128474" diaginertia="0.000354696 0.000140767 0.000191508"/>
          <joint name="Right_Shoulder_Roll" pos="0 0 0" axis="-0.999982 0.00485506 -0.00338711" stiffness="0.00163788" range="-1.7248 1.58154" armature="0.00947405" damping="0.0108726" frictionloss="0.103526"/>
          <geom name="//unnamed_geom_23" class="visual" mesh="AR2"/>
          <body name="AR3" pos="0.00197556 -0.0502089 -0.00188063" quat="1 -4.01779e-06 -4.10655e-06 1.36694e-05">
            <inertial pos="-0.000667907 -0.0736645 -0.00081303" quat="0.698097 0.715999 0.00150541 0.0020789" mass="0.851778" diaginertia="0.0114442 0.00510184 0.000693495"/>
            <joint name="Right_Elbow_Pitch" pos="0 0 0" axis="-0.00644184 0.999912 -0.0116082" stiffness="0.00124052" range="-2.32483 2.22558" armature="0.00803035" damping="0.00516866" frictionloss="0.105642"/>
            <geom name="//unnamed_geom_24" class="visual" mesh="AR3"/>
            <geom name="//unnamed_geom_25" class="collision" size="0.0282198 0.0705495" pos="0 -0.0415247 0" quat="0.707105 0.707108 0 0" type="cylinder"/>
            <geom name="//unnamed_geom_26" class="reward_collision_sphere" size="0.0338638"/>
            <body name="right_hand_link" pos="-0.000297974 -0.122079 0.000126409" quat="0.999999 0.00120743 0.000544661 0.000224518">
              <inertial pos="-0.000954987 -0.0925465 0.00355188" quat="0.706417 0.707796 1.27405e-05 0.000706628" mass="0.270367" diaginertia="0.00717556 0.00312704 0.000226787"/>
              <joint name="Right_Elbow_Yaw" pos="0 0 0" axis="0.00417606 -0.00726773 0.999965" range="0.0038768 2.48964" armature="0.0108319" damping="0" frictionloss="0.106787"/>
              <geom name="//unnamed_geom_27" class="visual" mesh="right_hand_link"/>
              <geom name="//unnamed_geom_28" class="collision" size="0.0282198 0.0823077" pos="0 -0.107964 0" quat="0.707105 0.707108 0 0" type="cylinder"/>
              <geom name="//unnamed_geom_29" class="reward_collision_sphere" size="0.047033"/>
              <geom name="//unnamed_geom_30" class="reward_collision_sphere" size="0.0329231" pos="0 -0.0913543 0"/>
              <geom name="//unnamed_geom_31" class="reward_collision_sphere" size="0.0329231" pos="0 -0.178556 0"/>
            </body>
          </body>
        </body>
      </body>
      <body name="Waist" pos="0.0614272 -0.0042363 -0.114668" quat="1 -0.000154205 -0.000552864 -0.00049468">
        <inertial pos="-0.000141632 -0.000125384 0.00641046" quat="0.983197 -0.0131007 -0.182074 0.000550382" mass="2.09067" diaginertia="0.00457979 0.00205664 0.00496753"/>
        <joint name="Waist" pos="0 0 0" axis="0.00101504 0.0129525 0.999916" range="-1.58975 1.51559" armature="0.00945831" damping="0.0200102" frictionloss="0.107122"/>
        <geom name="//unnamed_geom_32" class="visual" mesh="Waist"/>
        <body name="Hip_Pitch_Left" pos="0.000321089 0.0889088 0.000225687" quat="1 0.000479791 -0.000185937 -0.000246756">
          <inertial pos="0.00109852 -0.00830022 -0.0181778" quat="0.974776 0.222834 0.0120325 0.00331812" mass="0.859198" diaginertia="0.0015939 0.000591051 0.00136179"/>
          <joint name="Left_Hip_Pitch" pos="0 0 0" axis="-0.0114555 0.999933 0.00179826" range="-1.80539 1.61916" armature="0.0102358" damping="0" frictionloss="0.0927406"/>
          <geom name="//unnamed_geom_33" class="visual" rgba="0.76 0.76 0.76 1" mesh="Hip_Pitch_Left"/>
          <body name="Hip_Roll_Left" pos="0.000536999 0.00149485 -0.0183535" quat="0.999999 5.30853e-05 0.00115059 0.000470797">
            <inertial pos="-0.00174032 0.000377842 -0.0553075" quat="0.707041 -0.00530148 -0.00537858 0.707132" mass="0.314431" diaginertia="0.00155359 0.000581295 0.00053823"/>
            <joint name="Left_Hip_Roll" pos="0 0 0" axis="-0.999952 0.000197851 0.00980163" stiffness="0.00811323" range="-1.5454 0.189323" armature="0.00861301" damping="0.0165636" frictionloss="0.0984057"/>
            <geom name="//unnamed_geom_34" class="visual" mesh="Hip_Roll_Left"/>
            <geom name="//unnamed_geom_35" class="reward_collision_sphere" size="0.0517363"/>
            <body name="Hip_Yaw_Left" pos="0.00218086 -0.00117691 -0.0854958" quat="1 -0.000361196 -0.00013239 6.11715e-05">
              <inertial pos="-0.00723509 -0.00109536 -0.0903566" quat="0.693312 -0.0239862 -0.0372334 0.719275" mass="1.71778" diaginertia="0.0228565 0.00979262 0.00270185"/>
              <joint name="Left_Hip_Yaw" pos="0 0 0" axis="-0.000325591 -0.00223062 -0.999997" range="-1.06556 1.00837" armature="0.00937804" damping="0.0160275" frictionloss="0.0903917"/>
              <geom name="//unnamed_geom_36" class="visual" mesh="Hip_Yaw_Left"/>
              <geom name="//unnamed_geom_37" class="collision" size="0.047033 0.0752528" type="cylinder"/>
              <body name="Shank_Left" pos="-0.0129348 -0.00275885 -0.138335" quat="1 0.000417039 -0.000155235 -8.84496e-05">
                <inertial pos="-0.00648409 -0.00208223 -0.125452" quat="0.99751 -0.0069325 -0.0132928 0.068913" mass="1.51838" diaginertia="0.0317007 0.0139548 0.00199091"/>
                <joint name="Left_Knee_Pitch" pos="0 0 0" axis="0.00126314 0.999997 -0.0021281" range="0.00675653 2.30297" armature="0.0106636" damping="0" frictionloss="0.0966759"/>
                <geom name="//unnamed_geom_38" class="visual" mesh="Shank_Left"/>
                <geom name="//unnamed_geom_39" class="collision" size="0.047033 0.0705495" pos="0 0 -0.121802" type="cylinder"/>
                <geom name="//unnamed_geom_40" class="reward_collision_sphere" size="0.0611429"/>
                <body name="Ankle_Cross_Left" pos="0.00220153 0.00235066 -0.287567" quat="0.999999 -0.000308319 -0.000695795 -0.00112712">
                  <inertial pos="-0.00504561 -0.00194889 -0.00712609" quat="0.447881 0.545784 0.544432 0.452898" mass="0.0606781" diaginertia="2.55296e-05 1.04743e-05 1.26017e-05"/>
                  <joint name="Left_Ankle_Pitch" pos="0 0 0" axis="-0.0059221 0.999932 0.0100759" range="-0.886744 0.350783" armature="0.00913935" damping="0.00910953" frictionloss="0.0905353"/>
                  <geom name="//unnamed_geom_41" class="visual" mesh="Ankle_Cross_Left"/>
                  <body name="left_foot_link" pos="-0.00281922 -0.00272361 -0.0127868" quat="1 0.000346559 -0.000123815 -0.00020774">
                    <inertial pos="0.00240729 0.00088384 -0.00708752" quat="0.0021328 0.621637 0.00064863 0.783302" mass="0.568659" diaginertia="0.00243567 0.000936843 0.00235009"/>
                    <joint name="Left_Ankle_Roll" pos="0 0 0" axis="-0.999988 -0.00254405 0.00413122" stiffness="0.00672077" range="-0.453559 0.444165" armature="0.0079894" damping="0" frictionloss="0.0914532"/>
                    <geom name="//unnamed_geom_42" class="visual" mesh="left_foot_link"/>
                    <geom name="left_foot" class="foot" size="0.0896594 0.044487 0.0140296" pos="0.00976468 0 -0.0152253"/>
                    <geom name="//unnamed_geom_44" class="reward_collision_sphere" size="0.0489143" pos="0.00976468 0 -0.0152253"/>
                    <geom name="//unnamed_geom_45" class="reward_collision_sphere" size="0.0282198" pos="0.0927644 -0.0191014 -0.0152253"/>
                    <geom name="//unnamed_geom_46" class="reward_collision_sphere" size="0.0282198" pos="-0.0683527 -0.0191014 -0.0152253"/>
                    <site name="left_foot" class="foot" pos="0.00976468 0 -0.0152253" size="0.0094066"/>
                  </body>
                </body>
              </body>
            </body>
          </body>
        </body>
        <body name="Hip_Pitch_Right" pos="-0.00313993 -0.0854707 -0.00200067" quat="0.999999 0.00110885 0.000345941 0.000101501">
          <inertial pos="0.00146408 0.00443942 -0.0183306" quat="0.971496 -0.236435 0.012753 -0.0114878" mass="0.846637" diaginertia="0.00155092 0.000557653 0.0012971"/>
          <joint name="Right_Hip_Pitch" pos="0 0 0" axis="0.00586889 -0.999971 0.0049048" range="-1.62643 1.79242" armature="0.00864904" damping="0.00766916" frictionloss="0.105371"/>
          <geom name="//unnamed_geom_47" class="visual" rgba="0.76 0.76 0.76 1" mesh="Hip_Pitch_Right"/>
          <body name="Hip_Roll_Right" pos="-0.00108596 -0.00144298 -0.0211422" quat="1 0.00047664 -0.000324749 -6.02729e-05">
            <inertial pos="-0.00149139 0.0021628 -0.0568625" quat="0.702978 -0.00297576 -0.00538895 0.711185" mass="0.330332" diaginertia="0.00161069 0.000605113 0.000558565"/>
            <joint name="Right_Hip_Roll" pos="0 0 0" axis="-0.99999 0.00350056 -0.00279723" range="-0.189624 1.57399" armature="0.0100099" damping="0.00401162" frictionloss="0.089243"/>
            <geom name="//unnamed_geom_48" class="visual" mesh="Hip_Roll_Right"/>
            <geom name="//unnamed_geom_49" class="reward_collision_sphere" size="0.0517363"/>
            <body name="Hip_Yaw_Right" pos="-0.000381212 -0.00311476 -0.0824786" quat="1 -2.80008e-05 7.84532e-05 0.000200666">
              <inertial pos="-0.00450633 -0.00243802 -0.0912093" quat="0.713981 -0.031222 -0.0343396 0.698625" mass="1.81273" diaginertia="0.0238098 0.00998881 0.00281448"/>
              <joint name="Right_Hip_Yaw" pos="0 0 0" axis="-0.000816032 8.74937e-06 -1" stiffness="0.000935537" range="-0.9869 0.944564" armature="0.00851875" damping="0.0220502" frictionloss="0.106214"/>
              <geom name="//unnamed_geom_50" class="visual" mesh="Hip_Yaw_Right"/>
              <geom name="//unnamed_geom_51" class="collision" size="0.047033 0.0752528" type="cylinder"/>
              <body name="Shank_Right" pos="-0.011194 0.00214496 -0.135873" quat="0.999999 0.0003499 -0.000733147 0.0010647">
                <inertial pos="-0.00562891 0.00286695 -0.122139" quat="0.998801 0.00386164 -0.0358952 -0.0330594" mass="1.43989" diaginertia="0.0304004 0.0139388 0.00217357"/>
                <joint name="Right_Knee_Pitch" pos="0 0 0" axis="-0.00523501 -0.999985 0.00146396" range="-2.28235 -0.0634491" armature="0.00990036" damping="0.0195392" frictionloss="0.0906629"/>
                <geom name="//unnamed_geom_52" class="visual" mesh="Shank_Right"/>
                <geom name="//unnamed_geom_53" class="collision" size="0.047033 0.0705495" pos="0 0 -0.121802" type="cylinder"/>
                <geom name="//unnamed_geom_54" class="reward_collision_sphere" size="0.0611429"/>
                <body name="Ankle_Cross_Right" pos="0.00288098 -0.00327618 -0.284388" quat="1 0.000229829 0.000758168 -0.000565862">
                  <inertial pos="-0.00429993 -3.74513e-05 -0.00541414" quat="0.447893 0.543257 0.554642 0.443436" mass="0.0607268" diaginertia="2.56731e-05 1.01523e-05 1.18095e-05"/>
                  <joint name="Right_Ankle_Pitch" pos="0 0 0" axis="-0.000562868 -1 0.000536956" range="-0.40623 0.859095" armature="0.00918144" damping="0.00593625" frictionloss="0.0991207"/>
                  <geom name="//unnamed_geom_55" class="visual" mesh="Ankle_Cross_Right"/>
                  <body name="right_foot_link" pos="0.000490554 -0.00324807 -0.0135585" quat="1 0.000241241 4.15132e-05 -6.09146e-05">
                    <inertial pos="0.000564935 0.000184827 -0.012051" quat="-0.00137268 0.620926 0.00211024 0.783865" mass="0.568167" diaginertia="0.00237505 0.00094682 0.00228179"/>
                    <joint name="Right_Ankle_Roll" pos="0 0 0" axis="-0.999944 -0.010573 -0.000927931" range="-0.400848 0.430769" armature="0.0107508" damping="0.00936952" frictionloss="0.0815381"/>
                    <geom name="//unnamed_geom_56" class="visual" mesh="right_foot_link"/>
                    <geom name="right_foot" class="foot" size="0.0737211 0.0429789 0.0135388" pos="0.00976468 0 -0.0152253"/>
                    <geom name="//unnamed_geom_58" class="reward_collision_sphere" size="0.0376264"/>
                    <geom name="//unnamed_geom_59" class="reward_collision_sphere" size="0.0282198" pos="0.00976468 0 -0.0152253"/>
                    <geom name="//unnamed_geom_60" class="reward_collision_sphere" size="0.0282198" pos="0.0927644 0.0191014 -0.0152253"/>
                    <geom name="//unnamed_geom_61" class="reward_collision_sphere" size="0.0282198" pos="-0.0683527 0.0191014 -0.0152253"/>
                    <site name="right_foot" class="foot" pos="0.00976468 0 -0.0152253" size="0.0094066"/>
                  </body>
                </body>
              </body>
            </body>
          </body>
        </body>
      </body>
    </body>
  </worldbody>

  <contact>
    <pair class="/" geom1="floor" geom2="left_foot" name="//unnamed_contact_0"/>
    <pair class="/" geom1="floor" geom2="right_foot" name="//unnamed_contact_1"/>
  </contact>

  <actuator>
    <general name="AAHead_yaw" class="/" joint="AAHead_yaw" forcerange="-6.06289 6.06289" gainprm="23.3347" biasprm="0 -23.3347 -0.546975"/>
    <general name="Head_pitch" class="/" joint="Head_pitch" forcerange="-7.22762 7.22762" gainprm="23.3347" biasprm="0 -23.3347 -0.546975"/>
    <general name="Left_Shoulder_Pitch" class="/" joint="Left_Shoulder_Pitch" forcerange="-17.5848 17.5848" gainprm="23.3347" biasprm="0 -23.3347 -0.546975"/>
    <general name="Left_Shoulder_Roll" class="/" joint="Left_Shoulder_Roll" forcerange="-18.6092 18.6092" gainprm="23.3347" biasprm="0 -23.3347 -0.546975"/>
    <general name="Left_Elbow_Pitch" class="/" joint="Left_Elbow_Pitch" forcerange="-17.4184 17.4184" gainprm="23.3347" biasprm="0 -23.3347 -0.546975"/>
    <general name="Left_Elbow_Yaw" class="/" joint="Left_Elbow_Yaw" forcerange="-17.3372 17.3372" gainprm="23.3347" biasprm="0 -23.3347 -0.546975"/>
    <general name="Right_Shoulder_Pitch" class="/" joint="Right_Shoulder_Pitch" forcerange="-17.1313 17.1313" gainprm="23.3347" biasprm="0 -23.3347 -0.546975"/>
    <general name="Right_Shoulder_Roll" class="/" joint="Right_Shoulder_Roll" forcerange="-16.7034 16.7034" gainprm="23.3347" biasprm="0 -23.3347 -0.546975"/>
    <general name="Right_Elbow_Pitch" class="/" joint="Right_Elbow_Pitch" forcerange="-16.5861 16.5861" gainprm="23.3347" biasprm="0 -23.3347 -0.546975"/>
    <general name="Right_Elbow_Yaw" class="/" joint="Right_Elbow_Yaw" forcerange="-17.2912 17.2912" gainprm="23.3347" biasprm="0 -23.3347 -0.546975"/>
    <general name="Waist" class="/" joint="Waist" forcerange="-25.5459 25.5459" gainprm="23.3347" biasprm="0 -23.3347 -0.546975"/>
    <general name="Left_Hip_Pitch" class="/" joint="Left_Hip_Pitch" forcerange="-41.9469 41.9469" gainprm="23.3347" biasprm="0 -23.3347 -0.546975"/>
    <general name="Left_Hip_Roll" class="/" joint="Left_Hip_Roll" forcerange="-27.8293 27.8293" gainprm="23.3347" biasprm="0 -23.3347 -0.546975"/>
    <general name="Left_Hip_Yaw" class="/" joint="Left_Hip_Yaw" forcerange="-29.1503 29.1503" gainprm="23.3347" biasprm="0 -23.3347 -0.546975"/>
    <general name="Left_Knee_Pitch" class="/" joint="Left_Knee_Pitch" forcerange="-50.2504 50.2504" gainprm="23.3347" biasprm="0 -23.3347 -0.546975"/>
    <general name="Left_Ankle_Pitch" class="/" joint="Left_Ankle_Pitch" forcerange="-20.4022 20.4022" gainprm="23.3347" biasprm="0 -23.3347 -0.546975"/>
    <general name="Left_Ankle_Roll" class="/" joint="Left_Ankle_Roll" forcerange="-13.106 13.106" gainprm="23.3347" biasprm="0 -23.3347 -0.546975"/>
    <general name="Right_Hip_Pitch" class="/" joint="Right_Hip_Pitch" forcerange="-41.6706 41.6706" gainprm="23.3347" biasprm="0 -23.3347 -0.546975"/>
    <general name="Right_Hip_Roll" class="/" joint="Right_Hip_Roll" forcerange="-25.2262 25.2262" gainprm="23.3347" biasprm="0 -23.3347 -0.546975"/>
    <general name="Right_Hip_Yaw" class="/" joint="Right_Hip_Yaw" forcerange="-30.9723 30.9723" gainprm="23.3347" biasprm="0 -23.3347 -0.546975"/>
    <general name="Right_Knee_Pitch" class="/" joint="Right_Knee_Pitch" forcerange="-55.8819 55.8819" gainprm="23.3347" biasprm="0 -23.3347 -0.546975"/>
    <general name="Right_Ankle_Pitch" class="/" joint="Right_Ankle_Pitch" forcerange="-18.9641 18.9641" gainprm="23.3347" biasprm="0 -23.3347 -0.546975"/>
    <general name="Right_Ankle_Roll" class="/" joint="Right_Ankle_Roll" forcerange="-13.9815 13.9815" gainprm="23.3347" biasprm="0 -23.3347 -0.546975"/>
  </actuator>

  <sensor>
    <gyro site="imu" name="imu_angular_velocity"/>
    <velocimeter site="imu" name="imu_linear_velocity"/>
    <framelinvel objtype="site" objname="left_foot" name="left_foot_global_linear_velocity"/>
    <framelinvel objtype="site" objname="right_foot" name="right_foot_global_linear_velocity"/>
  </sensor>

  <keyframe>
    <key name="home" qpos="0 0 0.6385 1 0 0 0 0 0 0 1.4 0 -0.4 0 -1.4 0 0.4 0 -0.4 0 0 0.8 -0.4 0 0.4 0 0 -0.8 0.4 0"/>
  </keyframe>
</mujoco>
