<mujoco model="T1">
  <compiler angle="radian" assetdir="assets" balanceinertia="true" inertiafromgeom="false"/>

  <option timestep="0.005" density="1.2" viscosity="2e-05"/>

  <size nkey="1"/>

  <visual>
    <quality shadowsize="8192"/>
    <map shadowclip="0.5"/>
  </visual>

  <default>
    <default class="/">
      <joint armature="0.01" damping="0.01" frictionloss="0.1"/>
      <geom contype="0" conaffinity="0" group="1" solref="-1000 -80"/>
      <site size="0.01 0.005 0.005" group="5"/>
      <general forcelimited="true" biastype="affine" gainprm="25" biasprm="0 -25 -0.6"/>
      <default class="t1">
        <geom rgba="0.25 0.25 0.25 1"/>
        <default class="visual">
          <geom type="mesh" group="2"/>
        </default>
        <default class="collision">
          <geom group="3"/>
        </default>
        <default class="foot">
          <geom size="0.1115 0.05 0.015" type="box" condim="6" group="4" priority="1" solimp="0.015 1 0.015"/>
        </default>
        <default class="reward_collision_sphere">
          <geom group="5" rgba="1 0 0 1"/>
        </default>
      </default>
    </default>
  </default>

  <asset>
    <texture type="skybox" colorspace="auto" name="//unnamed_texture_0" builtin="gradient" rgb1="0.95 0.95 0.95" rgb2="0.95 0.95 0.95" width="100" height="600"/>
    <texture type="2d" colorspace="auto" name="texplane" builtin="checker" rgb1="0.345 0.575 0.748" rgb2="0.345 0.575 0.748" markrgb="1 1 1" width="512" height="512"/>
    <material name="MatPlane" class="/" texture="texplane" texuniform="true" texrepeat="2 2" specular="0.9"/>
    <mesh name="Trunk" class="/" file="Trunk.stl"/>
    <mesh name="H1" class="/" file="H1.stl"/>
    <mesh name="H2" class="/" file="H2.stl"/>
    <mesh name="AL1" class="/" file="AL1.stl"/>
    <mesh name="AL2" class="/" file="AL2.stl"/>
    <mesh name="AL3" class="/" file="AL3.stl"/>
    <mesh name="left_hand_link" class="/" file="left_hand_link.stl"/>
    <mesh name="AR1" class="/" file="AR1.stl"/>
    <mesh name="AR2" class="/" file="AR2.stl"/>
    <mesh name="AR3" class="/" file="AR3.stl"/>
    <mesh name="right_hand_link" class="/" file="right_hand_link.stl"/>
    <mesh name="Waist" class="/" file="Waist.stl"/>
    <mesh name="Hip_Pitch_Left" class="/" file="Hip_Pitch_Left.stl"/>
    <mesh name="Hip_Roll_Left" class="/" file="Hip_Roll_Left.stl"/>
    <mesh name="Hip_Yaw_Left" class="/" file="Hip_Yaw_Left.stl"/>
    <mesh name="Shank_Left" class="/" file="Shank_Left.stl"/>
    <mesh name="Ankle_Cross_Left" class="/" file="Ankle_Cross_Left.stl"/>
    <mesh name="left_foot_link" class="/" file="left_foot_link.stl"/>
    <mesh name="Hip_Pitch_Right" class="/" file="Hip_Pitch_Right.stl"/>
    <mesh name="Hip_Roll_Right" class="/" file="Hip_Roll_Right.stl"/>
    <mesh name="Hip_Yaw_Right" class="/" file="Hip_Yaw_Right.stl"/>
    <mesh name="Shank_Right" class="/" file="Shank_Right.stl"/>
    <mesh name="Ankle_Cross_Right" class="/" file="Ankle_Cross_Right.stl"/>
    <mesh name="right_foot_link" class="/" file="right_foot_link.stl"/>
  </asset>

  <worldbody>
    <geom name="floor" class="/" size="100 100 0.125" type="plane" group="0" material="MatPlane"/>
    <light name="toplight_shadow" class="/" pos="0 0 5" dir="0.0990148 0.0990148 -0.990148" type="directional" ambient="0.04 0.04 0.04" diffuse="0.55 0.55 0.55" specular="0.12 0.12 0.12"/>
    <light name="toplight_fill" class="/" pos="0 0 5" dir="0.0990148 0.0990148 -0.990148" type="directional" castshadow="false" ambient="0.04 0.04 0.04" diffuse="0.3 0.3 0.3" specular="0.08 0.08 0.08"/>
    <body name="trunk" childclass="t1" pos="0.000647126 0.00982122 -0.00315695" quat="0.99998 0.00223535 0.00538995 -0.00244852">
      <inertial pos="0.08549 0.00792744 0.178531" quat="0.998442 0.0326403 0.0441342 0.00999894" mass="36.1799" diaginertia="0.682447 0.111769 0.608362"/>
      <joint name="//unnamed_joint_0" type="free" armature="0" damping="0" frictionloss="0"/>
      <geom name="//unnamed_geom_1" class="visual" rgba="0.76 0.76 0.76 1" mesh="Trunk"/>
      <geom name="//unnamed_geom_2" class="collision" size="0.109932 0.146576 0.219863" pos="0.097767 0 0.201833" type="box"/>
      <geom name="//unnamed_geom_3" class="reward_collision_sphere" size="0.168562" pos="0.097767 0 0.168194"/>
      <geom name="//unnamed_geom_4" class="reward_collision_sphere" size="0.0219863" pos="0.097767 0.0922994 0"/>
      <geom name="//unnamed_geom_5" class="reward_collision_sphere" size="0.0219863" pos="0.097767 -0.0922994 0"/>
      <geom name="//unnamed_geom_6" class="reward_collision_sphere" size="0.0219863" pos="0.097767 0.116189 0.302749"/>
      <geom name="//unnamed_geom_7" class="reward_collision_sphere" size="0.0219863" pos="0.097767 -0.116189 0.302749"/>
      <site name="imu" pos="-0.0614971 -0.00154833 0.0606875" size="0.0146576"/>
      <camera name="track" pos="0 -2.17175 0" quat="0.707107 0.707107 0 0" mode="trackcom"/>
      <camera name="ego_camera" pos="0.198793 0 0.706415" quat="-0.5 -0.5 0.5 0.5"/>
      <body name="H1" pos="0.115259 -0.000627532 0.424445" quat="1 -0.000210298 -3.17561e-05 9.63758e-05">
        <inertial pos="-0.00126171 0.00167858 0.0974242" quat="0.762478 -0.0171393 -0.00449674 0.646771" mass="1.36615" diaginertia="0.00324066 0.000316945 0.00199949"/>
        <joint name="AAHead_yaw" pos="0 0 0" axis="-0.0187971 -0.0167075 0.999684" range="-1.81536 1.51863" armature="0.00315708" damping="0" frictionloss="0.0363581"/>
        <geom name="//unnamed_geom_8" class="visual" mesh="H1"/>
        <body name="H2" pos="0.00886167 0.0177462 0.110537" quat="0.999991 0.00413256 -0.000626469 -5.70492e-05">
          <inertial pos="-0.000770401 0.0152489 0.182682" quat="0.994859 0.0737006 -0.0161969 -0.0675366" mass="1.69723" diaginertia="0.0213687 0.00338965 0.0221077"/>
          <joint name="Head_pitch" pos="0 0 0" axis="-0.0375644 -0.999279 -0.00544952" range="-1.30698 0.477831" armature="0.00626275" damping="0.0812978" frictionloss="0.114401"/>
          <geom name="//unnamed_geom_9" class="visual" mesh="H2"/>
          <geom name="//unnamed_geom_10" class="collision" size="0.11726" pos="0.0162945 0 0.185013"/>
          <geom name="//unnamed_geom_11" class="reward_collision_sphere" size="0.131918" pos="0.032589 0 0.168194"/>
        </body>
      </body>
      <body name="AL1" pos="0.0881981 0.114881 0.383964" quat="0.999968 -0.00445686 -0.00202308 0.00632275">
        <inertial pos="0.0102263 0.0449771 0.00336886" quat="0.502856 0.496696 -0.504405 0.495988" mass="1.86392" diaginertia="0.017738 0.00264485 0.00521992"/>
        <joint name="Left_Shoulder_Pitch" pos="0 0 0" axis="0.00722996 0.998053 -0.0619538" range="-3.09882 0.896181" armature="0.0143093" damping="0.082342" frictionloss="0.0729271"/>
        <geom name="//unnamed_geom_12" class="visual" rgba="0.76 0.76 0.76 1" mesh="AL1"/>
        <body name="AL2" pos="0.0149849 0.0430558 -0.00776466" quat="1 -0.000165525 -9.67526e-05 0.000165254">
          <inertial pos="0.0151267 0.025725 0.00958124" quat="0.50789 0.511212 -0.478496 0.501748" mass="0.454293" diaginertia="0.00386167 0.000417493 0.00231334"/>
          <joint name="Left_Shoulder_Roll" pos="0 0 0" axis="-0.999712 0.00646119 -0.0231314" stiffness="0.0881561" range="-1.76433 1.67741" armature="0.00309026" damping="0" frictionloss="0.148285"/>
          <geom name="//unnamed_geom_13" class="visual" mesh="AL2"/>
          <body name="AL3" pos="-0.00748912 0.0687294 -0.0102257" quat="0.999995 -0.000147154 -0.00208327 -0.00218597">
            <inertial pos="-0.0146063 0.108278 -0.00851233" quat="0.722817 0.689511 -0.0182983 -0.0421215" mass="4.45425" diaginertia="0.142209 0.0217767 0.0112865"/>
            <joint name="Left_Elbow_Pitch" pos="0 0 0" axis="0.0180767 -0.998881 -0.0437046" stiffness="0.0430037" range="-1.94144 2.43968" armature="0.00213922" damping="0.0268386" frictionloss="0.162673"/>
            <geom name="//unnamed_geom_14" class="visual" mesh="AL3"/>
            <geom name="//unnamed_geom_15" class="collision" size="0.0439727 0.109932" pos="0 0.0542938 0" quat="0.707105 0.707108 0 0" type="cylinder"/>
            <geom name="//unnamed_geom_16" class="reward_collision_sphere" size="0.0527672"/>
            <body name="left_hand_link" pos="0.00621647 0.154515 0.0115152" quat="0.999968 -0.00497662 -0.0012333 0.00621899">
              <inertial pos="0.0163518 0.110262 0.000471557" quat="0.72593 0.687544 0.0154972 -0.00830114" mass="1.04517" diaginertia="0.110734 0.0109245 0.00235158"/>
              <joint name="Left_Elbow_Yaw" pos="0 0 0" axis="-0.0025091 -0.00515541 0.999984" range="-2.37808 0.333232" armature="0.0181731" damping="0" frictionloss="0.133475"/>
              <geom name="//unnamed_geom_17" class="visual" mesh="left_hand_link"/>
              <geom name="//unnamed_geom_18" class="collision" size="0.0439727 0.128254" pos="0 0.141164 0" quat="0.707105 0.707108 0 0" type="cylinder"/>
              <geom name="//unnamed_geom_19" class="reward_collision_sphere" size="0.0732878"/>
              <geom name="//unnamed_geom_20" class="reward_collision_sphere" size="0.0513014" pos="0 0.119446 0"/>
              <geom name="//unnamed_geom_21" class="reward_collision_sphere" size="0.0513014" pos="0 0.233463 0"/>
            </body>
          </body>
        </body>
      </body>
      <body name="AR1" pos="0.0855405 -0.100366 0.363596" quat="0.99999 0.00201652 0.00386727 0.00127165">
        <inertial pos="0.0101587 -0.0313326 0.00623376" quat="0.485172 0.478641 -0.491038 0.542579" mass="1.78408" diaginertia="0.0206645 0.0023792 0.00414135"/>
        <joint name="Right_Shoulder_Pitch" pos="0 0 0" axis="0.0116276 -0.997465 0.0701985" stiffness="0.0865228" range="-1.26393 3.51112" armature="0.00411887" damping="0.0532165" frictionloss="0.215779"/>
        <geom name="//unnamed_geom_22" class="visual" rgba="0.76 0.76 0.76 1" mesh="AR1"/>
        <body name="AR2" pos="-0.0166086 -0.0625645 0.0106496" quat="0.999971 -0.00377683 0.000274876 -0.00654279">
          <inertial pos="0.0176851 -0.0435794 0.00803256" quat="0.50249 0.484225 -0.487426 0.524829" mass="0.604688" diaginertia="0.00463135 0.000426344 0.00257786"/>
          <joint name="Right_Shoulder_Roll" pos="0 0 0" axis="-0.99967 0.00927659 0.0239522" stiffness="0.0171955" range="-1.90067 1.41842" armature="0.0141964" damping="0" frictionloss="0.0179904"/>
          <geom name="//unnamed_geom_23" class="visual" mesh="AR2"/>
          <body name="AR3" pos="-0.0107845 -0.0736686 0.0178163" quat="1 -0.000182848 7.16065e-05 2.29745e-05">
            <inertial pos="-0.00262671 -0.0774868 0.00877735" quat="0.659137 0.751499 0.0233962 0.0155313" mass="3.18854" diaginertia="0.14514 0.0206048 0.00677609"/>
            <joint name="Right_Elbow_Pitch" pos="0 0 0" axis="0.0590805 0.99733 0.0429154" range="-1.97717 2.48488" armature="0.0265494" damping="0" frictionloss="0.0622145"/>
            <geom name="//unnamed_geom_24" class="visual" mesh="AR3"/>
            <geom name="//unnamed_geom_25" class="collision" size="0.0439727 0.109932" pos="0 -0.0542938 0" quat="0.707105 0.707108 0 0" type="cylinder"/>
            <geom name="//unnamed_geom_26" class="reward_collision_sphere" size="0.0527672"/>
            <body name="right_hand_link" pos="-0.00135805 -0.156011 -0.000156734" quat="0.999977 0.00093174 -0.00237507 -0.00631391">
              <inertial pos="-0.00301382 -0.10961 -0.0143475" quat="0.706343 0.707868 -0.000270266 -0.00119412" mass="1.22624" diaginertia="0.10991 0.0131935 0.00324924"/>
              <joint name="Right_Elbow_Yaw" pos="0 0 0" axis="-0.0530296 -0.0169323 0.998449" range="0.0597335 2.20755" armature="0.00328659" damping="0.0956542" frictionloss="0.0547662"/>
              <geom name="//unnamed_geom_27" class="visual" mesh="right_hand_link"/>
              <geom name="//unnamed_geom_28" class="collision" size="0.0439727 0.128254" pos="0 -0.141164 0" quat="0.707105 0.707108 0 0" type="cylinder"/>
              <geom name="//unnamed_geom_29" class="reward_collision_sphere" size="0.0732878"/>
              <geom name="//unnamed_geom_30" class="reward_collision_sphere" size="0.0513014" pos="0 -0.119446 0"/>
              <geom name="//unnamed_geom_31" class="reward_collision_sphere" size="0.0513014" pos="0 -0.233463 0"/>
            </body>
          </body>
        </body>
      </body>
      <body name="Waist" pos="0.10255 0.0138973 -0.210807" quat="1 -9.05627e-05 0.000489184 -0.000359155">
        <inertial pos="0.0187268 0.00573485 0.00736088" quat="0.981223 0.0681905 -0.178758 -0.024428" mass="9.98046" diaginertia="0.0707369 0.0101475 0.0784387"/>
        <joint name="Waist" pos="0 0 0" axis="-0.0671465 0.0303211 0.997282" stiffness="0.0522079" range="-1.67869 1.87026" armature="0.0133273" damping="0" frictionloss="0.0411901"/>
        <geom name="//unnamed_geom_32" class="visual" mesh="Waist"/>
        <body name="Hip_Pitch_Left" pos="-0.00277383 0.115118 0.005397" quat="0.999988 -0.00466505 -0.000733588 -0.00121783">
          <inertial pos="0.0047599 0.00145217 -0.0272713" quat="0.971724 0.232351 0.0415904 0.00595736" mass="2.72607" diaginertia="0.0205754 0.00170558 0.0143689"/>
          <joint name="Left_Hip_Pitch" pos="0 0 0" axis="0.0505544 0.996032 0.0732485" stiffness="0.0817125" range="-1.7974 1.24494" armature="0.00774212" damping="0.0736231" frictionloss="0.162474"/>
          <geom name="//unnamed_geom_33" class="visual" rgba="0.76 0.76 0.76 1" mesh="Hip_Pitch_Left"/>
          <body name="Hip_Roll_Left" pos="0.00714331 -0.0178717 -0.0477264" quat="0.999962 -0.00739398 0.00348012 0.00298694">
            <inertial pos="0.0152605 -0.00138738 -0.0956106" quat="0.716316 0.0275181 0.00117733 0.697232" mass="1.57101" diaginertia="0.0196376 0.00267771 0.00844826"/>
            <joint name="Left_Hip_Roll" pos="0 0 0" axis="-0.99673 -0.0796999 -0.0132827" range="-1.74342 0.232025" armature="0.0218467" damping="0.0297741" frictionloss="0.186344"/>
            <geom name="//unnamed_geom_34" class="visual" mesh="Hip_Roll_Left"/>
            <geom name="//unnamed_geom_35" class="reward_collision_sphere" size="0.0806165"/>
            <body name="Hip_Yaw_Left" pos="-0.00845249 -0.00464759 -0.128961" quat="1 -0.000138532 -0.00017776 -0.000243868">
              <inertial pos="-0.0149607 -0.0065108 -0.149146" quat="0.731161 -0.00660842 0.0262176 0.681669" mass="9.0092" diaginertia="0.292252 0.048116 0.0417512"/>
              <joint name="Left_Hip_Yaw" pos="0 0 0" axis="0.00854749 0.00828647 -0.999929" stiffness="0.00451453" range="-0.75094 1.00372" armature="0.0141414" damping="0" frictionloss="0.120158"/>
              <geom name="//unnamed_geom_36" class="visual" mesh="Hip_Yaw_Left"/>
              <geom name="//unnamed_geom_37" class="collision" size="0.0732878 0.11726" type="cylinder"/>
              <body name="Shank_Left" pos="-0.0151099 0.0150943 -0.227323" quat="1 0.00010907 -0.000241226 6.63741e-05">
                <inertial pos="-0.00149558 0.0132663 -0.205774" quat="0.992889 -0.0142342 -0.0898359 0.0768017" mass="4.09586" diaginertia="0.343183 0.0461203 0.025767"/>
                <joint name="Left_Knee_Pitch" pos="0 0 0" axis="0.0241837 0.999262 0.029842" range="-0.16195 2.53564" armature="0.00438292" damping="0.0745143" frictionloss="0.192208"/>
                <geom name="//unnamed_geom_38" class="visual" mesh="Shank_Left"/>
                <geom name="//unnamed_geom_39" class="collision" size="0.0732878 0.109932" pos="0 0 -0.201833" type="cylinder"/>
                <geom name="//unnamed_geom_40" class="reward_collision_sphere" size="0.0952741"/>
                <body name="Ankle_Cross_Left" pos="-0.00127435 -0.0123389 -0.457141" quat="0.999972 -0.00597044 0.00276401 0.00367358">
                  <inertial pos="0.00336892 0.0168049 -0.00902698" quat="0.417776 0.596444 0.514767 0.452475" mass="0.237537" diaginertia="0.000349745 3.27742e-05 0.000133316"/>
                  <joint name="Left_Ankle_Pitch" pos="0 0 0" axis="0.0518508 0.99837 0.0238617" stiffness="0.0314785" range="-0.981688 0.204183" armature="0.0199337" damping="0.0240651" frictionloss="0.120431"/>
                  <geom name="//unnamed_geom_41" class="visual" mesh="Ankle_Cross_Left"/>
                  <body name="left_foot_link" pos="0.01394 0.0165071 -0.0128276" quat="1 -6.66802e-05 -0.000149157 0.000367971">
                    <inertial pos="-0.0150224 0.0030354 -0.0325819" quat="-0.0281343 0.611775 -0.00902723 0.79048" mass="2.22152" diaginertia="0.035797 0.00363233 0.0349785"/>
                    <joint name="Left_Ankle_Roll" pos="0 0 0" axis="-0.999996 -0.00259527 0.000937065" range="-0.417076 0.4299" armature="0.0262657" damping="0.0661346" frictionloss="0.157615"/>
                    <geom name="//unnamed_geom_42" class="visual" mesh="left_foot_link"/>
                    <geom name="left_foot" class="foot" size="0.135673 0.102332 0.0165702" pos="0.0162945 0 -0.0252291"/>
                    <geom name="//unnamed_geom_44" class="reward_collision_sphere" size="0.0762193" pos="0.0162945 0 -0.0252291"/>
                    <geom name="//unnamed_geom_45" class="reward_collision_sphere" size="0.0439727" pos="0.154798 -0.0249751 -0.0252291"/>
                    <geom name="//unnamed_geom_46" class="reward_collision_sphere" size="0.0439727" pos="-0.114062 -0.0249751 -0.0252291"/>
                    <site name="left_foot" class="foot" pos="0.0162945 0 -0.0252291" size="0.0146576"/>
                  </body>
                </body>
              </body>
            </body>
          </body>
        </body>
        <body name="Hip_Pitch_Right" pos="0.013285 -0.114412 0.0115768" quat="0.999963 -0.000377706 0.00793812 -0.00322942">
          <inertial pos="0.00598402 0.0260975 -0.0306012" quat="0.967061 -0.247395 0.0284863 -0.0527059" mass="3.30949" diaginertia="0.0246985 0.00254962 0.0220254"/>
          <joint name="Right_Hip_Pitch" pos="0 0 0" axis="-0.000476036 -0.999993 -0.00379405" stiffness="0.0381746" range="-1.31942 1.80074" armature="0.0216427" damping="0" frictionloss="0.0264267"/>
          <geom name="//unnamed_geom_47" class="visual" rgba="0.76 0.76 0.76 1" mesh="Hip_Pitch_Right"/>
          <body name="Hip_Roll_Right" pos="-0.00496534 0.0082937 -0.0252878" quat="1 -5.17973e-05 0.000336288 4.08842e-05">
            <inertial pos="0.0171134 -0.0171921 -0.0737935" quat="0.719586 -0.0316079 -0.0380044 0.692642" mass="1.13593" diaginertia="0.0183528 0.00222307 0.0067497"/>
            <joint name="Right_Hip_Roll" pos="0 0 0" axis="-0.999982 0.00235124 -0.00553855" range="-0.123276 1.57129" armature="0.00802099" damping="0" frictionloss="0.115501"/>
            <geom name="//unnamed_geom_48" class="visual" mesh="Hip_Roll_Right"/>
            <geom name="//unnamed_geom_49" class="reward_collision_sphere" size="0.0806165"/>
            <body name="Hip_Yaw_Right" pos="0.00274589 0.0115766 -0.132621" quat="0.99999 -0.00412621 -0.000709101 0.00179453">
              <inertial pos="-0.0229851 0.0114224 -0.156136" quat="0.715357 -0.0290379 -0.033338 0.697359" mass="6.93796" diaginertia="0.244684 0.0379343 0.0332449"/>
              <joint name="Right_Hip_Yaw" pos="0 0 0" axis="0.00492188 -0.00244715 -0.999985" stiffness="0.017321" range="-0.899199 1.28083" armature="0.0277527" damping="0" frictionloss="0.0315444"/>
              <geom name="//unnamed_geom_50" class="visual" mesh="Hip_Yaw_Right"/>
              <geom name="//unnamed_geom_51" class="collision" size="0.0732878 0.11726" type="cylinder"/>
              <body name="Shank_Right" pos="-0.030851 -0.0159398 -0.230356" quat="0.999971 -0.00626103 -0.000295556 0.00423634">
                <inertial pos="-0.0116414 -0.0132871 -0.222714" quat="0.999237 -0.0372383 0.00598 0.0101821" mass="6.6047" diaginertia="0.46069 0.0551393 0.0206961"/>
                <joint name="Right_Knee_Pitch" pos="0 0 0" axis="0.0433515 -0.997361 -0.0582447" stiffness="0.00272669" range="-2.6227 0.27527" armature="0.0184065" damping="0" frictionloss="0.206497"/>
                <geom name="//unnamed_geom_52" class="visual" mesh="Shank_Right"/>
                <geom name="//unnamed_geom_53" class="collision" size="0.0732878 0.109932" pos="0 0 -0.201833" type="cylinder"/>
                <geom name="//unnamed_geom_54" class="reward_collision_sphere" size="0.0952741"/>
                <body name="Ankle_Cross_Right" pos="-0.0101909 0.014208 -0.471579" quat="0.99996 0.00546434 -0.00634471 0.00316794">
                  <inertial pos="0.00202722 0.0078494 -0.0264858" quat="0.421506 0.535223 0.547031 0.486443" mass="0.222777" diaginertia="0.00030679 3.8747e-05 0.00017983"/>
                  <joint name="Right_Ankle_Pitch" pos="0 0 0" axis="-0.016177 -0.999187 -0.0369324" stiffness="0.0249333" range="-0.0681731 0.798697" armature="0.0122312" damping="0.0106703" frictionloss="0.179957"/>
                  <geom name="//unnamed_geom_55" class="visual" mesh="Ankle_Cross_Right"/>
                  <body name="right_foot_link" pos="0.00719293 0.0147335 -0.0105554" quat="0.999996 -0.000995937 -0.00108541 0.00243528">
                    <inertial pos="0.00251073 -0.00770106 -0.00150276" quat="0.0297486 0.612953 0.00397009 0.789549" mass="2.3538" diaginertia="0.0295524 0.00359279 0.0337231"/>
                    <joint name="Right_Ankle_Roll" pos="0 0 0" axis="-0.99814 -0.0208128 -0.0572943" stiffness="0.0567834" range="-0.797333 0.44495" armature="0.00367233" damping="0.00525049" frictionloss="0.236364"/>
                    <geom name="//unnamed_geom_56" class="visual" mesh="right_foot_link"/>
                    <geom name="right_foot" class="foot" size="0.174989 0.103449 0.0217002" pos="0.0162945 0 -0.0252291"/>
                    <geom name="//unnamed_geom_58" class="reward_collision_sphere" size="0.0586302"/>
                    <geom name="//unnamed_geom_59" class="reward_collision_sphere" size="0.0439727" pos="0.0162945 0 -0.0252291"/>
                    <geom name="//unnamed_geom_60" class="reward_collision_sphere" size="0.0439727" pos="0.154798 0.0249751 -0.0252291"/>
                    <geom name="//unnamed_geom_61" class="reward_collision_sphere" size="0.0439727" pos="-0.114062 0.0249751 -0.0252291"/>
                    <site name="right_foot" class="foot" pos="0.0162945 0 -0.0252291" size="0.0146576"/>
                  </body>
                </body>
              </body>
            </body>
          </body>
        </body>
      </body>
    </body>
  </worldbody>

  <contact>
    <pair class="/" geom1="floor" geom2="left_foot" name="//unnamed_contact_0"/>
    <pair class="/" geom1="floor" geom2="right_foot" name="//unnamed_contact_1"/>
  </contact>

  <actuator>
    <general name="AAHead_yaw" class="/" joint="AAHead_yaw" forcerange="-14.4143 14.4143" gainprm="40.081" biasprm="0 -40.081 -0.935997"/>
    <general name="Head_pitch" class="/" joint="Head_pitch" forcerange="-5.65595 5.65595" gainprm="40.081" biasprm="0 -40.081 -0.935997"/>
    <general name="Left_Shoulder_Pitch" class="/" joint="Left_Shoulder_Pitch" forcerange="-31.0046 31.0046" gainprm="40.081" biasprm="0 -40.081 -0.935997"/>
    <general name="Left_Shoulder_Roll" class="/" joint="Left_Shoulder_Roll" forcerange="-12.0706 12.0706" gainprm="40.081" biasprm="0 -40.081 -0.935997"/>
    <general name="Left_Elbow_Pitch" class="/" joint="Left_Elbow_Pitch" forcerange="-30.4714 30.4714" gainprm="40.081" biasprm="0 -40.081 -0.935997"/>
    <general name="Left_Elbow_Yaw" class="/" joint="Left_Elbow_Yaw" forcerange="-25.7571 25.7571" gainprm="40.081" biasprm="0 -40.081 -0.935997"/>
    <general name="Right_Shoulder_Pitch" class="/" joint="Right_Shoulder_Pitch" forcerange="-27.3966 27.3966" gainprm="40.081" biasprm="0 -40.081 -0.935997"/>
    <general name="Right_Shoulder_Roll" class="/" joint="Right_Shoulder_Roll" forcerange="-34.2302 34.2302" gainprm="40.081" biasprm="0 -40.081 -0.935997"/>
    <general name="Right_Elbow_Pitch" class="/" joint="Right_Elbow_Pitch" forcerange="-20.8395 20.8395" gainprm="40.081" biasprm="0 -40.081 -0.935997"/>
    <general name="Right_Elbow_Yaw" class="/" joint="Right_Elbow_Yaw" forcerange="-32.1566 32.1566" gainprm="40.081" biasprm="0 -40.081 -0.935997"/>
    <general name="Waist" class="/" joint="Waist" forcerange="-67.9811 67.9811" gainprm="40.081" biasprm="0 -40.081 -0.935997"/>
    <general name="Left_Hip_Pitch" class="/" joint="Left_Hip_Pitch" forcerange="-84.4304 84.4304" gainprm="40.081" biasprm="0 -40.081 -0.935997"/>
    <general name="Left_Hip_Roll" class="/" joint="Left_Hip_Roll" forcerange="-47.2564 47.2564" gainprm="40.081" biasprm="0 -40.081 -0.935997"/>
    <general name="Left_Hip_Yaw" class="/" joint="Left_Hip_Yaw" forcerange="-53.231 53.231" gainprm="40.081" biasprm="0 -40.081 -0.935997"/>
    <general name="Left_Knee_Pitch" class="/" joint="Left_Knee_Pitch" forcerange="-133.131 133.131" gainprm="40.081" biasprm="0 -40.081 -0.935997"/>
    <general name="Left_Ankle_Pitch" class="/" joint="Left_Ankle_Pitch" forcerange="-10.6308 10.6308" gainprm="40.081" biasprm="0 -40.081 -0.935997"/>
    <general name="Left_Ankle_Roll" class="/" joint="Left_Ankle_Roll" forcerange="-36.6449 36.6449" gainprm="40.081" biasprm="0 -40.081 -0.935997"/>
    <general name="Right_Hip_Pitch" class="/" joint="Right_Hip_Pitch" forcerange="-67.4228 67.4228" gainprm="40.081" biasprm="0 -40.081 -0.935997"/>
    <general name="Right_Hip_Roll" class="/" joint="Right_Hip_Roll" forcerange="-66.6683 66.6683" gainprm="40.081" biasprm="0 -40.081 -0.935997"/>
    <general name="Right_Hip_Yaw" class="/" joint="Right_Hip_Yaw" forcerange="-18.1015 18.1015" gainprm="40.081" biasprm="0 -40.081 -0.935997"/>
    <general name="Right_Knee_Pitch" class="/" joint="Right_Knee_Pitch" forcerange="-65.9821 65.9821" gainprm="40.081" biasprm="0 -40.081 -0.935997"/>
    <general name="Right_Ankle_Pitch" class="/" joint="Right_Ankle_Pitch" forcerange="-29.711 29.711" gainprm="40.081" biasprm="0 -40.081 -0.935997"/>
    <general name="Right_Ankle_Roll" class="/" joint="Right_Ankle_Roll" forcerange="-22.6363 22.6363" gainprm="40.081" biasprm="0 -40.081 -0.935997"/>
  </actuator>

  <sensor>
    <gyro site="imu" name="imu_angular_velocity"/>
    <velocimeter site="imu" name="imu_linear_velocity"/>
    <framelinvel objtype="site" objname="left_foot" name="left_foot_global_linear_velocity"/>
    <framelinvel objtype="site" objname="right_foot" name="right_foot_global_linear_velocity"/>
  </sensor>

  <keyframe>
    <key name="home" qpos="0 0 0.6385 1 0 0 0 0 0 0 1.4 0 -0.4 0 -1.4 0 0.4 0 -0.4 0 0 0.8 -0.4 0 0.4 0 0 -0.8 0.4 0"/>
  </keyframe>
</mujoco>
