<mujoco model="T1">
  <compiler angle="radian" assetdir="assets" balanceinertia="true" inertiafromgeom="false"/>

  <option timestep="0.005" density="1.2" viscosity="2e-05"/>

  <size nkey="1"/>

  <visual>
    <quality shadowsize="8192"/>
    <map shadowclip="0.5"/>
  </visual>

  <default>
    <default class="/">
      <joint armature="0.01" damping="0.01" frictionloss="0.1"/>
      <geom contype="0" conaffinity="0" group="1" solref="-1000 -80"/>
      <site size="0.01 0.005 0.005" group="5"/>
      <general forcelimited="true" biastype="affine" gainprm="25" biasprm="0 -25 -0.6"/>
      <default class="t1">
        <geom rgba="0.25 0.25 0.25 1"/>
        <default class="visual">
          <geom type="mesh" group="2"/>
        </default>
        <default class="collision">
          <geom group="3"/>
        </default>
        <default class="foot">
          <geom size="0.1115 0.05 0.015" type="box" condim="6" group="4" priority="1" solimp="0.015 1 0.015"/>
        </default>
        <default class="reward_collision_sphere">
          <geom group="5" rgba="1 0 0 1"/>
        </default>
      </default>
    </default>
  </default>

  <asset>
    <texture type="skybox" colorspace="auto" name="//unnamed_texture_0" builtin="gradient" rgb1="0.95 0.95 0.95" rgb2="0.95 0.95 0.95" width="100" height="600"/>
    <texture type="2d" colorspace="auto" name="texplane" builtin="checker" rgb1="0.345 0.575 0.748" rgb2="0.345 0.575 0.748" markrgb="1 1 1" width="512" height="512"/>
    <material name="MatPlane" class="/" texture="texplane" texuniform="true" texrepeat="2 2" specular="0.9"/>
    <mesh name="Trunk" class="/" file="Trunk.stl"/>
    <mesh name="H1" class="/" file="H1.stl"/>
    <mesh name="H2" class="/" file="H2.stl"/>
    <mesh name="AL1" class="/" file="AL1.stl"/>
    <mesh name="AL2" class="/" file="AL2.stl"/>
    <mesh name="AL3" class="/" file="AL3.stl"/>
    <mesh name="left_hand_link" class="/" file="left_hand_link.stl"/>
    <mesh name="AR1" class="/" file="AR1.stl"/>
    <mesh name="AR2" class="/" file="AR2.stl"/>
    <mesh name="AR3" class="/" file="AR3.stl"/>
    <mesh name="right_hand_link" class="/" file="right_hand_link.stl"/>
    <mesh name="Waist" class="/" file="Waist.stl"/>
    <mesh name="Hip_Pitch_Left" class="/" file="Hip_Pitch_Left.stl"/>
    <mesh name="Hip_Roll_Left" class="/" file="Hip_Roll_Left.stl"/>
    <mesh name="Hip_Yaw_Left" class="/" file="Hip_Yaw_Left.stl"/>
    <mesh name="Shank_Left" class="/" file="Shank_Left.stl"/>
    <mesh name="Ankle_Cross_Left" class="/" file="Ankle_Cross_Left.stl"/>
    <mesh name="left_foot_link" class="/" file="left_foot_link.stl"/>
    <mesh name="Hip_Pitch_Right" class="/" file="Hip_Pitch_Right.stl"/>
    <mesh name="Hip_Roll_Right" class="/" file="Hip_Roll_Right.stl"/>
    <mesh name="Hip_Yaw_Right" class="/" file="Hip_Yaw_Right.stl"/>
    <mesh name="Shank_Right" class="/" file="Shank_Right.stl"/>
    <mesh name="Ankle_Cross_Right" class="/" file="Ankle_Cross_Right.stl"/>
    <mesh name="right_foot_link" class="/" file="right_foot_link.stl"/>
  </asset>

  <worldbody>
    <geom name="floor" class="/" size="100 100 0.125" type="plane" group="0" material="MatPlane"/>
    <light name="toplight_shadow" class="/" pos="0 0 5" dir="0.0990148 0.0990148 -0.990148" type="directional" ambient="0.04 0.04 0.04" diffuse="0.55 0.55 0.55" specular="0.12 0.12 0.12"/>
    <light name="toplight_fill" class="/" pos="0 0 5" dir="0.0990148 0.0990148 -0.990148" type="directional" castshadow="false" ambient="0.04 0.04 0.04" diffuse="0.3 0.3 0.3" specular="0.08 0.08 0.08"/>
    <body name="trunk" childclass="t1" pos="0.00017324 0.000851216 0.00201267" quat="0.999999 0.00133197 0.000323805 -0.000974827">
      <inertial pos="0.073396 -0.000706158 0.139543" quat="0.99983 -0.0147409 -0.00787483 -0.00783443" mass="20.0111" diaginertia="0.307963 0.0521192 0.218197"/>
      <joint name="//unnamed_joint_0" type="free" armature="0" damping="0" frictionloss="0"/>
      <geom name="//unnamed_geom_1" class="visual" rgba="0.76 0.76 0.76 1" mesh="Trunk"/>
      <geom name="//unnamed_geom_2" class="collision" size="0.089474 0.119299 0.178948" pos="0.0790013 0 0.160195" type="box"/>
      <geom name="//unnamed_geom_3" class="reward_collision_sphere" size="0.137194" pos="0.0790013 0 0.133496"/>
      <geom name="//unnamed_geom_4" class="reward_collision_sphere" size="0.0178948" pos="0.0790013 0.078822 0"/>
      <geom name="//unnamed_geom_5" class="reward_collision_sphere" size="0.0178948" pos="0.0790013 -0.078822 0"/>
      <geom name="//unnamed_geom_6" class="reward_collision_sphere" size="0.0178948" pos="0.0790013 0.099223 0.240292"/>
      <geom name="//unnamed_geom_7" class="reward_collision_sphere" size="0.0178948" pos="0.0790013 -0.099223 0.240292"/>
      <site name="imu" pos="-0.0151849 0.000903961 0.0144491" size="0.0119299"/>
      <camera name="track" pos="0 -1.85463 0" quat="0.707107 0.707107 0 0" mode="trackcom"/>
      <camera name="ego_camera" pos="0.160636 0 0.560681" quat="-0.5 -0.5 0.5 0.5"/>
      <body name="H1" pos="0.0861741 -0.00103214 0.330611" quat="1 -8.99131e-05 -0.000159391 0.000393403">
        <inertial pos="-0.00275241 -0.00402145 0.0766749" quat="0.766057 -0.0128071 0.00176572 0.642643" mass="0.760696" diaginertia="0.000958419 0.000152892 0.000639021"/>
        <joint name="AAHead_yaw" pos="0 0 0" axis="0.0115717 0.000460715 0.999933" range="-1.62961 1.60632" armature="0.00824298" damping="0.0150639" frictionloss="0.0859077"/>
        <geom name="//unnamed_geom_8" class="visual" mesh="H1"/>
        <body name="H2" pos="-0.000351514 0.00816446 0.0808149" quat="1 -2.06026e-06 -0.000211678 -4.48941e-05">
          <inertial pos="0.00594448 0.00560948 0.138884" quat="0.988456 0.0976826 -0.0921624 -0.0701345" mass="1.09522" diaginertia="0.00848927 0.00147723 0.00748039"/>
          <joint name="Head_pitch" pos="0 0 0" axis="-0.0032695 -0.999991 -0.00277874" range="-1.1878 0.321695" armature="0.0108338" damping="0.0363503" frictionloss="0.132767"/>
          <geom name="//unnamed_geom_9" class="visual" mesh="H2"/>
          <geom name="//unnamed_geom_10" class="collision" size="0.095439" pos="0.0131669 0 0.146845"/>
          <geom name="//unnamed_geom_11" class="reward_collision_sphere" size="0.107369" pos="0.0263338 0 0.133496"/>
        </body>
      </body>
      <body name="AL1" pos="0.0790179 0.102103 0.298459" quat="0.999996 0.00123243 -0.00267923 -0.000195406">
        <inertial pos="0.00115864 0.0433385 -0.0020956" quat="0.5056 0.495568 -0.50493 0.493788" mass="0.908159" diaginertia="0.00549092 0.000974494 0.00133217"/>
        <joint name="Left_Shoulder_Pitch" pos="0 0 0" axis="0.0149288 0.999883 -0.00323476" range="-3.27903 1.08668" armature="0.011743" damping="0.0381436" frictionloss="0.113058"/>
        <geom name="//unnamed_geom_12" class="visual" rgba="0.76 0.76 0.76 1" mesh="AL1"/>
        <body name="AL2" pos="0.00584772 0.0444395 0.00051294" quat="1 -5.21497e-05 0.000409459 -5.5377e-06">
          <inertial pos="0.00526947 0.0291861 0.000718255" quat="0.484139 0.520297 -0.482177 0.512255" mass="0.258053" diaginertia="0.00157628 0.000236887 0.000742553"/>
          <joint name="Left_Shoulder_Roll" pos="0 0 0" axis="-0.999906 0.00922468 -0.0101568" stiffness="0.038352" range="-1.58734 1.77421" armature="0.00790476" damping="0.0148679" frictionloss="0.115763"/>
          <geom name="//unnamed_geom_13" class="visual" mesh="AL2"/>
          <body name="AL3" pos="0.00130434 0.056002 -0.00138365" quat="1 -0.000873351 0.000122797 0.000347014">
            <inertial pos="-0.00521022 0.0853083 7.8441e-05" quat="0.705065 0.709113 0.00128234 0.00642217" mass="1.94665" diaginertia="0.0503055 0.00933422 0.00287809"/>
            <joint name="Left_Elbow_Pitch" pos="0 0 0" axis="0.000997355 -0.999998 -0.00168917" range="-2.13268 2.26381" armature="0.00708407" damping="0" frictionloss="0.110675"/>
            <geom name="//unnamed_geom_14" class="visual" mesh="AL3"/>
            <geom name="//unnamed_geom_15" class="collision" size="0.0357896 0.089474" pos="0 0.0463659 0" quat="0.707105 0.707108 0 0" type="cylinder"/>
            <geom name="//unnamed_geom_16" class="reward_collision_sphere" size="0.0429475"/>
            <body name="left_hand_link" pos="-0.00144607 0.138838 0.00229031" quat="0.999994 -0.000403159 -0.00327839 -0.000370394">
              <inertial pos="0.00688109 0.101794 0.0015296" quat="0.711729 0.702426 -0.00563901 0.00279732" mass="0.55744" diaginertia="0.0347242 0.00563122 0.000857193"/>
              <joint name="Left_Elbow_Yaw" pos="0 0 0" axis="-0.00155237 -0.00247038 0.999996" stiffness="0.00434638" range="-2.46752 0.143317" armature="0.0104811" damping="0.00886287" frictionloss="0.12474"/>
              <geom name="//unnamed_geom_17" class="visual" mesh="left_hand_link"/>
              <geom name="//unnamed_geom_18" class="collision" size="0.0357896 0.104386" pos="0 0.120551 0" quat="0.707105 0.707108 0 0" type="cylinder"/>
              <geom name="//unnamed_geom_19" class="reward_collision_sphere" size="0.0596493"/>
              <geom name="//unnamed_geom_20" class="reward_collision_sphere" size="0.0417545" pos="0 0.102005 0"/>
              <geom name="//unnamed_geom_21" class="reward_collision_sphere" size="0.0417545" pos="0 0.199373 0"/>
            </body>
          </body>
        </body>
      </body>
      <body name="AR1" pos="0.0758624 -0.0925603 0.295414" quat="1 4.33035e-05 0.000412958 -0.000184285">
        <inertial pos="0.00129263 -0.0337559 -0.0014869" quat="0.50166 0.4895 -0.507195 0.501478" mass="0.965684" diaginertia="0.0057701 0.000916982 0.00131742"/>
        <joint name="Right_Shoulder_Pitch" pos="0 0 0" axis="-0.0237664 -0.999717 -0.00112767" stiffness="0.0374512" range="-1.21439 3.33019" armature="0.00893363" damping="0" frictionloss="0.122487"/>
        <geom name="//unnamed_geom_22" class="visual" rgba="0.76 0.76 0.76 1" mesh="AR1"/>
        <body name="AR2" pos="-0.00719666 -0.0455531 0.00173745" quat="0.999996 -0.00263572 0.000899855 -0.000358181">
          <inertial pos="0.00736466 -0.0330355 -0.00030088" quat="0.511869 0.488801 -0.511096 0.487693" mass="0.292406" diaginertia="0.00159705 0.00022092 0.000734919"/>
          <joint name="Right_Shoulder_Roll" pos="0 0 0" axis="-0.999978 -0.0056312 0.00349875" range="-1.72696 1.58958" armature="0.0122303" damping="0.00530518" frictionloss="0.0716234"/>
          <geom name="//unnamed_geom_23" class="visual" mesh="AR2"/>
          <body name="AR3" pos="-0.00191687 -0.0553855 0.00817918" quat="1 0.000484924 -4.14004e-05 0.000153635">
            <inertial pos="0.00188211 -0.0733965 0.000106429" quat="0.690943 0.722861 -0.00619605 0.00561679" mass="1.7244" diaginertia="0.0506996 0.00856678 0.00246061"/>
            <joint name="Right_Elbow_Pitch" pos="0 0 0" axis="-0.0244396 0.999659 -0.00925096" range="-2.16538 2.30227" armature="0.0156149" damping="0.0180525" frictionloss="0.105437"/>
            <geom name="//unnamed_geom_24" class="visual" mesh="AR3"/>
            <geom name="//unnamed_geom_25" class="collision" size="0.0357896 0.089474" pos="0 -0.0463659 0" quat="0.707105 0.707108 0 0" type="cylinder"/>
            <geom name="//unnamed_geom_26" class="reward_collision_sphere" size="0.0429475"/>
            <body name="right_hand_link" pos="-0.00121953 -0.137863 -0.00191674" quat="0.999998 0.00150673 0.00139171 -0.000548183">
              <inertial pos="0.00221134 -0.101141 -0.00505973" quat="0.706381 0.707832 0.000119063 -0.000460525" mass="0.54498" diaginertia="0.0316663 0.0057626 0.000919866"/>
              <joint name="Right_Elbow_Yaw" pos="0 0 0" axis="-0.00959322 -0.00613844 0.999935" stiffness="0.00545899" range="-0.0372929 2.39305" armature="0.00860788" damping="0.04375" frictionloss="0.0999349"/>
              <geom name="//unnamed_geom_27" class="visual" mesh="right_hand_link"/>
              <geom name="//unnamed_geom_28" class="collision" size="0.0357896 0.104386" pos="0 -0.120551 0" quat="0.707105 0.707108 0 0" type="cylinder"/>
              <geom name="//unnamed_geom_29" class="reward_collision_sphere" size="0.0596493"/>
              <geom name="//unnamed_geom_30" class="reward_collision_sphere" size="0.0417545" pos="0 -0.102005 0"/>
              <geom name="//unnamed_geom_31" class="reward_collision_sphere" size="0.0417545" pos="0 -0.199373 0"/>
            </body>
          </body>
        </body>
      </body>
      <body name="Waist" pos="0.0844444 0.00410243 -0.161198" quat="1 -0.000252982 0.000414238 0.000144282">
        <inertial pos="0.00866246 -0.0020282 0.0121449" quat="0.982737 -0.0180312 -0.182948 0.0208299" mass="4.83139" diaginertia="0.0239723 0.00388415 0.022134"/>
        <joint name="Waist" pos="0 0 0" axis="0.0250592 0.00913028 0.999644" stiffness="0.00241609" range="-1.53051 1.6804" armature="0.0127294" damping="0" frictionloss="0.0896486"/>
        <geom name="//unnamed_geom_32" class="visual" mesh="Waist"/>
        <body name="Hip_Pitch_Left" pos="0.00231997 0.0985182 -0.000891248" quat="1 -0.00012671 -5.70314e-05 -0.00037058">
          <inertial pos="-8.62152e-05 -0.00635859 -0.0264765" quat="0.973709 0.226749 0.0217308 0.0020804" mass="1.7688" diaginertia="0.00717011 0.000949595 0.00543945"/>
          <joint name="Left_Hip_Pitch" pos="0 0 0" axis="0.00219325 0.999146 0.0412571" stiffness="0.0316178" range="-1.82499 1.43509" armature="0.0113382" damping="0.0323019" frictionloss="0.111512"/>
          <geom name="//unnamed_geom_33" class="visual" rgba="0.76 0.76 0.76 1" mesh="Hip_Pitch_Left"/>
          <body name="Hip_Roll_Left" pos="-0.000722523 -0.00833557 -0.0313767" quat="0.999992 -0.00202188 0.00134564 -0.00310537">
            <inertial pos="0.00561261 0.000520247 -0.0697826" quat="0.709369 -0.00194793 -0.00590566 0.70481" mass="0.695437" diaginertia="0.00698814 0.00115924 0.00238944"/>
            <joint name="Left_Hip_Roll" pos="0 0 0" axis="-0.999431 -0.0163959 -0.0294617" range="-1.56782 0.178794" armature="0.0122879" damping="0" frictionloss="0.107004"/>
            <geom name="//unnamed_geom_34" class="visual" mesh="Hip_Roll_Left"/>
            <geom name="//unnamed_geom_35" class="reward_collision_sphere" size="0.0656143"/>
            <body name="Hip_Yaw_Left" pos="0.000659193 0.00251402 -0.10934" quat="1 -0.000437075 4.6988e-05 -7.8798e-05">
              <inertial pos="-0.00770918 0.00164817 -0.119083" quat="0.674474 -0.0345861 -0.0209465 0.737191" mass="3.94357" diaginertia="0.103464 0.0180681 0.0117675"/>
              <joint name="Left_Hip_Yaw" pos="0 0 0" axis="0.000398003 0.012092 -0.999927" range="-0.940055 1.00221" armature="0.0118087" damping="0.00529213" frictionloss="0.132004"/>
              <geom name="//unnamed_geom_36" class="visual" mesh="Hip_Yaw_Left"/>
              <geom name="//unnamed_geom_37" class="collision" size="0.0596493 0.095439" type="cylinder"/>
              <body name="Shank_Left" pos="-0.0187916 0.00560612 -0.176179" quat="1 0.000597104 -0.000510686 0.000325211">
                <inertial pos="-0.00802402 0.00405228 -0.168328" quat="0.996157 -0.00401675 -0.0418634 0.0768272" mass="2.82431" diaginertia="0.134095 0.0228406 0.00827529"/>
                <joint name="Left_Knee_Pitch" pos="0 0 0" axis="0.000883551 0.999989 -0.00450061" range="0.00838676 2.35576" armature="0.00884447" damping="0.0188821" frictionloss="0.109075"/>
                <geom name="//unnamed_geom_38" class="visual" mesh="Shank_Left"/>
                <geom name="//unnamed_geom_39" class="collision" size="0.0596493 0.089474" pos="0 0 -0.160195" type="cylinder"/>
                <geom name="//unnamed_geom_40" class="reward_collision_sphere" size="0.0775442"/>
                <body name="Ankle_Cross_Left" pos="-0.0025231 -0.00308984 -0.36946" quat="0.999996 2.28805e-05 -0.000397145 -0.00276222">
                  <inertial pos="-0.00435369 0.0073661 -0.0128271" quat="0.431187 0.54615 0.55686 0.453547" mass="0.120751" diaginertia="0.000111576 1.62146e-05 4.54699e-05"/>
                  <joint name="Left_Ankle_Pitch" pos="0 0 0" axis="0.000677267 0.999928 0.0119447" range="-0.840505 0.370466" armature="0.0113802" damping="0" frictionloss="0.131853"/>
                  <geom name="//unnamed_geom_41" class="visual" mesh="Ankle_Cross_Left"/>
                  <body name="left_foot_link" pos="0.00419441 0.00696426 -0.0159901" quat="1 9.31821e-05 0.00022149 0.000269772">
                    <inertial pos="-0.00558563 -0.00179196 -0.0198681" quat="-0.00135869 0.625576 0.0054589 0.780143" mass="1.1688" diaginertia="0.0101954 0.00164336 0.0090244"/>
                    <joint name="Left_Ankle_Roll" pos="0 0 0" axis="-0.999996 -0.00101399 0.00261074" range="-0.462726 0.43183" armature="0.015413" damping="0.0116791" frictionloss="0.11506"/>
                    <geom name="//unnamed_geom_42" class="visual" mesh="left_foot_link"/>
                    <geom name="left_foot" class="foot" size="0.0835738 0.0686246 0.0195687" pos="0.0131669 0 -0.0200243"/>
                    <geom name="//unnamed_geom_44" class="reward_collision_sphere" size="0.0620353" pos="0.0131669 0 -0.0200243"/>
                    <geom name="//unnamed_geom_45" class="reward_collision_sphere" size="0.0357896" pos="0.125085 -0.0213283 -0.0200243"/>
                    <geom name="//unnamed_geom_46" class="reward_collision_sphere" size="0.0357896" pos="-0.0921681 -0.0213283 -0.0200243"/>
                    <site name="left_foot" class="foot" pos="0.0131669 0 -0.0200243" size="0.0119299"/>
                  </body>
                </body>
              </body>
            </body>
          </body>
        </body>
        <body name="Hip_Pitch_Right" pos="0.00391521 -0.102913 0.00229251" quat="0.999993 0.00106939 0.00248616 0.00264198">
          <inertial pos="-0.00144252 0.0153798 -0.0232248" quat="0.972699 -0.230879 0.0230066 -0.00478275" mass="1.8213" diaginertia="0.00771734 0.00110631 0.00564581"/>
          <joint name="Right_Hip_Pitch" pos="0 0 0" axis="-0.000333042 -0.999982 -0.00606766" range="-1.50572 1.76752" armature="0.0123276" damping="0.0130458" frictionloss="0.0782201"/>
          <geom name="//unnamed_geom_47" class="visual" rgba="0.76 0.76 0.76 1" mesh="Hip_Pitch_Right"/>
          <body name="Hip_Roll_Right" pos="0.00212649 -0.000793769 -0.0273505" quat="1 0.000147733 -0.000858732 -0.000272987">
            <inertial pos="0.00732391 -0.00761212 -0.064657" quat="0.707012 -0.00705136 -0.00591677 0.707141" mass="0.632945" diaginertia="0.00657043 0.0010302 0.00216492"/>
            <joint name="Right_Hip_Roll" pos="0 0 0" axis="-0.999903 0.0108868 -0.00873181" stiffness="0.00100354" range="-0.240821 1.55912" armature="0.0117155" damping="0.0135184" frictionloss="0.132573"/>
            <geom name="//unnamed_geom_48" class="visual" mesh="Hip_Roll_Right"/>
            <geom name="//unnamed_geom_49" class="reward_collision_sphere" size="0.0656143"/>
            <body name="Hip_Yaw_Right" pos="0.00108276 0.00204193 -0.112702" quat="1 0.000129831 0.000116817 0.000514828">
              <inertial pos="-0.0115263 0.00238496 -0.117281" quat="0.714693 -0.030874 -0.0334859 0.697954" mass="3.83792" diaginertia="0.0982715 0.0176535 0.0107238"/>
              <joint name="Right_Hip_Yaw" pos="0 0 0" axis="-0.00399959 0.013222 -0.999905" range="-1.05942 1.0926" armature="0.0165897" damping="0" frictionloss="0.0822128"/>
              <geom name="//unnamed_geom_50" class="visual" mesh="Hip_Yaw_Right"/>
              <geom name="//unnamed_geom_51" class="collision" size="0.0596493 0.095439" type="cylinder"/>
              <body name="Shank_Right" pos="-0.0172405 -0.0068257 -0.179216" quat="0.999996 -0.000421022 -0.00107017 0.00254165">
                <inertial pos="-0.00797076 -0.00372863 -0.170695" quat="0.999632 0.00331734 -0.00904013 -0.0253553" mass="3.18321" diaginertia="0.141857 0.0232871 0.00746911"/>
                <joint name="Right_Knee_Pitch" pos="0 0 0" axis="-0.0218484 -0.999715 0.00961949" range="-2.43423 0.085569" armature="0.0107484" damping="0" frictionloss="0.11654"/>
                <geom name="//unnamed_geom_52" class="visual" mesh="Shank_Right"/>
                <geom name="//unnamed_geom_53" class="collision" size="0.0596493 0.089474" pos="0 0 -0.160195" type="cylinder"/>
                <geom name="//unnamed_geom_54" class="reward_collision_sphere" size="0.0775442"/>
                <body name="Ankle_Cross_Right" pos="-0.000716898 0.00456703 -0.373643" quat="0.999991 0.00333337 -0.00176207 -0.00176457">
                  <inertial pos="-0.00546534 -0.000363131 -0.0144338" quat="0.447466 0.552329 0.548633 0.440123" mass="0.126405" diaginertia="0.00011671 1.75494e-05 5.07092e-05"/>
                  <joint name="Right_Ankle_Pitch" pos="0 0 0" axis="0.00623063 -0.99998 -0.00053369" range="-0.25672 0.902314" armature="0.0132237" damping="0.000331408" frictionloss="0.105818"/>
                  <geom name="//unnamed_geom_55" class="visual" mesh="Ankle_Cross_Right"/>
                  <body name="right_foot_link" pos="0.000214045 0.00516114 -0.0155173" quat="1 -0.000239366 -8.68807e-05 0.00072766">
                    <inertial pos="-0.00252805 0.000962464 -0.00771679" quat="0.000401835 0.619907 0.00830209 0.784632" mass="1.14899" diaginertia="0.0109504 0.00164859 0.00957764"/>
                    <joint name="Right_Ankle_Roll" pos="0 0 0" axis="-0.999881 -0.00761977 -0.0133789" stiffness="0.00735511" range="-0.6062 0.417408" armature="0.0089629" damping="0.00212639" frictionloss="0.137133"/>
                    <geom name="//unnamed_geom_56" class="visual" mesh="right_foot_link"/>
                    <geom name="right_foot" class="foot" size="0.0969957 0.0662933 0.0184413" pos="0.0131669 0 -0.0200243"/>
                    <geom name="//unnamed_geom_58" class="reward_collision_sphere" size="0.0477195"/>
                    <geom name="//unnamed_geom_59" class="reward_collision_sphere" size="0.0357896" pos="0.0131669 0 -0.0200243"/>
                    <geom name="//unnamed_geom_60" class="reward_collision_sphere" size="0.0357896" pos="0.125085 0.0213283 -0.0200243"/>
                    <geom name="//unnamed_geom_61" class="reward_collision_sphere" size="0.0357896" pos="-0.0921681 0.0213283 -0.0200243"/>
                    <site name="right_foot" class="foot" pos="0.0131669 0 -0.0200243" size="0.0119299"/>
                  </body>
                </body>
              </body>
            </body>
          </body>
        </body>
      </body>
    </body>
  </worldbody>

  <contact>
    <pair class="/" geom1="floor" geom2="left_foot" name="//unnamed_contact_0"/>
    <pair class="/" geom1="floor" geom2="right_foot" name="//unnamed_contact_1"/>
  </contact>

  <actuator>
    <general name="AAHead_yaw" class="/" joint="AAHead_yaw" forcerange="-8.891 8.891" gainprm="31.001" biasprm="0 -31.001 -0.694955"/>
    <general name="Head_pitch" class="/" joint="Head_pitch" forcerange="-7.49171 7.49171" gainprm="31.001" biasprm="0 -31.001 -0.694955"/>
    <general name="Left_Shoulder_Pitch" class="/" joint="Left_Shoulder_Pitch" forcerange="-19.2573 19.2573" gainprm="31.001" biasprm="0 -31.001 -0.694955"/>
    <general name="Left_Shoulder_Roll" class="/" joint="Left_Shoulder_Roll" forcerange="-17.3507 17.3507" gainprm="31.001" biasprm="0 -31.001 -0.694955"/>
    <general name="Left_Elbow_Pitch" class="/" joint="Left_Elbow_Pitch" forcerange="-20.1554 20.1554" gainprm="31.001" biasprm="0 -31.001 -0.694955"/>
    <general name="Left_Elbow_Yaw" class="/" joint="Left_Elbow_Yaw" forcerange="-22.9776 22.9776" gainprm="31.001" biasprm="0 -31.001 -0.694955"/>
    <general name="Right_Shoulder_Pitch" class="/" joint="Right_Shoulder_Pitch" forcerange="-21.6429 21.6429" gainprm="31.001" biasprm="0 -31.001 -0.694955"/>
    <general name="Right_Shoulder_Roll" class="/" joint="Right_Shoulder_Roll" forcerange="-20.9412 20.9412" gainprm="31.001" biasprm="0 -31.001 -0.694955"/>
    <general name="Right_Elbow_Pitch" class="/" joint="Right_Elbow_Pitch" forcerange="-23.3269 23.3269" gainprm="31.001" biasprm="0 -31.001 -0.694955"/>
    <general name="Right_Elbow_Yaw" class="/" joint="Right_Elbow_Yaw" forcerange="-19.7354 19.7354" gainprm="31.001" biasprm="0 -31.001 -0.694955"/>
    <general name="Waist" class="/" joint="Waist" forcerange="-42.826 42.826" gainprm="31.001" biasprm="0 -31.001 -0.694955"/>
    <general name="Left_Hip_Pitch" class="/" joint="Left_Hip_Pitch" forcerange="-51.8367 51.8367" gainprm="31.001" biasprm="0 -31.001 -0.694955"/>
    <general name="Left_Hip_Roll" class="/" joint="Left_Hip_Roll" forcerange="-34.1796 34.1796" gainprm="31.001" biasprm="0 -31.001 -0.694955"/>
    <general name="Left_Hip_Yaw" class="/" joint="Left_Hip_Yaw" forcerange="-33.1866 33.1866" gainprm="31.001" biasprm="0 -31.001 -0.694955"/>
    <general name="Left_Knee_Pitch" class="/" joint="Left_Knee_Pitch" forcerange="-83.0765 83.0765" gainprm="31.001" biasprm="0 -31.001 -0.694955"/>
    <general name="Left_Ankle_Pitch" class="/" joint="Left_Ankle_Pitch" forcerange="-17.1894 17.1894" gainprm="31.001" biasprm="0 -31.001 -0.694955"/>
    <general name="Left_Ankle_Roll" class="/" joint="Left_Ankle_Roll" forcerange="-23.413 23.413" gainprm="31.001" biasprm="0 -31.001 -0.694955"/>
    <general name="Right_Hip_Pitch" class="/" joint="Right_Hip_Pitch" forcerange="-51.839 51.839" gainprm="31.001" biasprm="0 -31.001 -0.694955"/>
    <general name="Right_Hip_Roll" class="/" joint="Right_Hip_Roll" forcerange="-41.6881 41.6881" gainprm="31.001" biasprm="0 -31.001 -0.694955"/>
    <general name="Right_Hip_Yaw" class="/" joint="Right_Hip_Yaw" forcerange="-27.4899 27.4899" gainprm="31.001" biasprm="0 -31.001 -0.694955"/>
    <general name="Right_Knee_Pitch" class="/" joint="Right_Knee_Pitch" forcerange="-75.0724 75.0724" gainprm="31.001" biasprm="0 -31.001 -0.694955"/>
    <general name="Right_Ankle_Pitch" class="/" joint="Right_Ankle_Pitch" forcerange="-24.4387 24.4387" gainprm="31.001" biasprm="0 -31.001 -0.694955"/>
    <general name="Right_Ankle_Roll" class="/" joint="Right_Ankle_Roll" forcerange="-18.0204 18.0204" gainprm="31.001" biasprm="0 -31.001 -0.694955"/>
  </actuator>

  <sensor>
    <gyro site="imu" name="imu_angular_velocity"/>
    <velocimeter site="imu" name="imu_linear_velocity"/>
    <framelinvel objtype="site" objname="left_foot" name="left_foot_global_linear_velocity"/>
    <framelinvel objtype="site" objname="right_foot" name="right_foot_global_linear_velocity"/>
  </sensor>

  <keyframe>
    <key name="home" qpos="0 0 0.6385 1 0 0 0 0 0 0 1.4 0 -0.4 0 -1.4 0 0.4 0 -0.4 0 0 0.8 -0.4 0 0.4 0 0 -0.8 0.4 0"/>
  </keyframe>
</mujoco>
