<mujoco model="T1">
  <compiler angle="radian" assetdir="assets" balanceinertia="true" inertiafromgeom="false"/>

  <option timestep="0.005" density="1.2" viscosity="2e-05"/>

  <size nkey="1"/>

  <visual>
    <quality shadowsize="8192"/>
    <map shadowclip="0.5"/>
  </visual>

  <default>
    <default class="/">
      <joint armature="0.01" damping="0.01" frictionloss="0.1"/>
      <geom contype="0" conaffinity="0" group="1" solref="-1000 -80"/>
      <site size="0.01 0.005 0.005" group="5"/>
      <general forcelimited="true" biastype="affine" gainprm="25" biasprm="0 -25 -0.6"/>
      <default class="t1">
        <geom rgba="0.25 0.25 0.25 1"/>
        <default class="visual">
          <geom type="mesh" group="2"/>
        </default>
        <default class="collision">
          <geom group="3"/>
        </default>
        <default class="foot">
          <geom size="0.1115 0.05 0.015" type="box" condim="6" group="4" priority="1" solimp="0.015 1 0.015"/>
        </default>
        <default class="reward_collision_sphere">
          <geom group="5" rgba="1 0 0 1"/>
        </default>
      </default>
    </default>
  </default>

  <asset>
    <texture type="skybox" colorspace="auto" name="//unnamed_texture_0" builtin="gradient" rgb1="0.95 0.95 0.95" rgb2="0.95 0.95 0.95" width="100" height="600"/>
    <texture type="2d" colorspace="auto" name="texplane" builtin="checker" rgb1="0.345 0.575 0.748" rgb2="0.345 0.575 0.748" markrgb="1 1 1" width="512" height="512"/>
    <material name="MatPlane" class="/" texture="texplane" texuniform="true" texrepeat="2 2" specular="0.9"/>
    <mesh name="Trunk" class="/" file="Trunk.stl"/>
    <mesh name="H1" class="/" file="H1.stl"/>
    <mesh name="H2" class="/" file="H2.stl"/>
    <mesh name="AL1" class="/" file="AL1.stl"/>
    <mesh name="AL2" class="/" file="AL2.stl"/>
    <mesh name="AL3" class="/" file="AL3.stl"/>
    <mesh name="left_hand_link" class="/" file="left_hand_link.stl"/>
    <mesh name="AR1" class="/" file="AR1.stl"/>
    <mesh name="AR2" class="/" file="AR2.stl"/>
    <mesh name="AR3" class="/" file="AR3.stl"/>
    <mesh name="right_hand_link" class="/" file="right_hand_link.stl"/>
    <mesh name="Waist" class="/" file="Waist.stl"/>
    <mesh name="Hip_Pitch_Left" class="/" file="Hip_Pitch_Left.stl"/>
    <mesh name="Hip_Roll_Left" class="/" file="Hip_Roll_Left.stl"/>
    <mesh name="Hip_Yaw_Left" class="/" file="Hip_Yaw_Left.stl"/>
    <mesh name="Shank_Left" class="/" file="Shank_Left.stl"/>
    <mesh name="Ankle_Cross_Left" class="/" file="Ankle_Cross_Left.stl"/>
    <mesh name="left_foot_link" class="/" file="left_foot_link.stl"/>
    <mesh name="Hip_Pitch_Right" class="/" file="Hip_Pitch_Right.stl"/>
    <mesh name="Hip_Roll_Right" class="/" file="Hip_Roll_Right.stl"/>
    <mesh name="Hip_Yaw_Right" class="/" file="Hip_Yaw_Right.stl"/>
    <mesh name="Shank_Right" class="/" file="Shank_Right.stl"/>
    <mesh name="Ankle_Cross_Right" class="/" file="Ankle_Cross_Right.stl"/>
    <mesh name="right_foot_link" class="/" file="right_foot_link.stl"/>
  </asset>

  <worldbody>
    <geom name="floor" class="/" size="100 100 0.125" type="plane" group="0" material="MatPlane"/>
    <light name="toplight_shadow" class="/" pos="0 0 5" dir="0.0990148 0.0990148 -0.990148" type="directional" ambient="0.04 0.04 0.04" diffuse="0.55 0.55 0.55" specular="0.12 0.12 0.12"/>
    <light name="toplight_fill" class="/" pos="0 0 5" dir="0.0990148 0.0990148 -0.990148" type="directional" castshadow="false" ambient="0.04 0.04 0.04" diffuse="0.3 0.3 0.3" specular="0.08 0.08 0.08"/>
    <body name="trunk" childclass="t1" pos="-7.02448e-05 0.0108179 -0.00414562" quat="0.999977 -0.00387033 -0.00275157 0.00490448">
      <inertial pos="0.086673 0.0089215 0.183717" quat="0.99733 0.00250423 -0.0430504 -0.058933" mass="37.2819" diaginertia="0.745509 0.0977176 0.680107"/>
      <joint name="//unnamed_joint_0" type="free" armature="0" damping="0" frictionloss="0"/>
      <geom name="//unnamed_geom_1" class="visual" rgba="0.76 0.76 0.76 1" mesh="Trunk"/>
      <geom name="//unnamed_geom_2" class="collision" size="0.111225 0.1483 0.22245" pos="0.100133 0 0.206639" type="box"/>
      <geom name="//unnamed_geom_3" class="reward_collision_sphere" size="0.170545" pos="0.100133 0 0.172199"/>
      <geom name="//unnamed_geom_4" class="reward_collision_sphere" size="0.022245" pos="0.100133 0.0899405 0"/>
      <geom name="//unnamed_geom_5" class="reward_collision_sphere" size="0.022245" pos="0.100133 -0.0899405 0"/>
      <geom name="//unnamed_geom_6" class="reward_collision_sphere" size="0.022245" pos="0.100133 0.113219 0.309958"/>
      <geom name="//unnamed_geom_7" class="reward_collision_sphere" size="0.022245" pos="0.100133 -0.113219 0.309958"/>
      <site name="imu" pos="-0.0664843 -0.00326924 0.0656746" size="0.01483"/>
      <camera name="track" pos="0 -2.11625 0" quat="0.707107 0.707107 0 0" mode="trackcom"/>
      <camera name="ego_camera" pos="0.203605 0 0.723236" quat="-0.5 -0.5 0.5 0.5"/>
      <body name="H1" pos="0.118721 -0.000578441 0.435175" quat="1 -0.000549691 0.000106238 -0.000441478">
        <inertial pos="-0.000834513 0.0027071 0.0992915" quat="0.769798 -0.0214372 0.00295536 0.63792" mass="1.41319" diaginertia="0.00373656 0.000277954 0.00224688"/>
        <joint name="AAHead_yaw" pos="0 0 0" axis="-0.00883029 0.0287902 0.999546" range="-1.8353 1.49892" armature="0.00249338" damping="0" frictionloss="0.0293865"/>
        <geom name="//unnamed_geom_8" class="visual" mesh="H1"/>
        <body name="H2" pos="0.00985833 0.0187447 0.11401" quat="0.999989 0.0013505 -0.000686742 -0.00442609">
          <inertial pos="-0.00146042 0.0162116 0.187631" quat="0.986736 0.0884129 -0.0296189 -0.132884" mass="1.71093" diaginertia="0.0234637 0.00297019 0.0242495"/>
          <joint name="Head_pitch" pos="0 0 0" axis="0.0206225 -0.999078 -0.0376558" range="-1.32677 0.497708" armature="0.00555606" damping="0.0856357" frictionloss="0.108392"/>
          <geom name="//unnamed_geom_9" class="visual" mesh="H2"/>
          <geom name="//unnamed_geom_10" class="collision" size="0.11864" pos="0.0166889 0 0.189419"/>
          <geom name="//unnamed_geom_11" class="reward_collision_sphere" size="0.13347" pos="0.0333778 0 0.172199"/>
        </body>
      </body>
      <body name="AL1" pos="0.0894694 0.112683 0.393732" quat="0.999965 -0.0033246 -0.00408579 0.00653616">
        <inertial pos="0.0111967 0.0427397 0.0043566" quat="0.50339 0.497417 -0.505089 0.494024" mass="1.96509" diaginertia="0.0203962 0.0023738 0.00599963"/>
        <joint name="Left_Shoulder_Pitch" pos="0 0 0" axis="0.0544556 0.997729 0.0396434" range="-3.07888 0.876223" armature="0.0144755" damping="0.086671" frictionloss="0.0663935"/>
        <geom name="//unnamed_geom_12" class="visual" rgba="0.76 0.76 0.76 1" mesh="AL1"/>
        <body name="AL2" pos="0.0159822 0.0407562 -0.00876029" quat="1 0.000403366 0.000514474 -0.000269222">
          <inertial pos="0.0162758 0.0236732 0.0105778" quat="0.466254 0.530163 -0.493149 0.508269" mass="0.469206" diaginertia="0.00423501 0.000356663 0.0025929"/>
          <joint name="Left_Shoulder_Roll" pos="0 0 0" axis="-0.99958 -0.0285154 0.00523953" stiffness="0.0931453" range="-1.78426 1.65768" armature="0.00243365" damping="0" frictionloss="0.143374"/>
          <geom name="//unnamed_geom_13" class="visual" mesh="AL2"/>
          <body name="AL3" pos="-0.00847598 0.0680364 -0.0112219" quat="0.999994 -0.0024661 -0.00233429 0.00092967">
            <inertial pos="-0.0156042 0.106907 -0.00951202" quat="0.740144 0.671834 -0.02869 -0.00136359" mass="4.71158" diaginertia="0.159557 0.019093 0.0129697"/>
            <joint name="Left_Elbow_Pitch" pos="0 0 0" axis="-0.03724 -0.998633 0.0366845" stiffness="0.0479769" range="-1.92147 2.45961" armature="0.00146922" damping="0.0233585" frictionloss="0.171885"/>
            <geom name="//unnamed_geom_14" class="visual" mesh="AL3"/>
            <geom name="//unnamed_geom_15" class="collision" size="0.04449 0.111225" pos="0 0.0529062 0" quat="0.707105 0.707108 0 0" type="cylinder"/>
            <geom name="//unnamed_geom_16" class="reward_collision_sphere" size="0.053388"/>
            <body name="left_hand_link" pos="0.00721062 0.149439 0.0125129" quat="0.999963 -0.00636846 0.00330806 -0.00466434">
              <inertial pos="0.0173455 0.106225 0.0014331" quat="0.699683 0.713601 0.00900673 -0.0337194" mass="1.10805" diaginertia="0.127561 0.00957257 0.00263456"/>
              <joint name="Left_Elbow_Yaw" pos="0 0 0" axis="0.000804364 0.00472644 0.999989" range="-2.35838 0.353198" armature="0.0191705" damping="0" frictionloss="0.127777"/>
              <geom name="//unnamed_geom_17" class="visual" mesh="left_hand_link"/>
              <geom name="//unnamed_geom_18" class="collision" size="0.04449 0.129763" pos="0 0.137556 0" quat="0.707105 0.707108 0 0" type="cylinder"/>
              <geom name="//unnamed_geom_19" class="reward_collision_sphere" size="0.0741501"/>
              <geom name="//unnamed_geom_20" class="reward_collision_sphere" size="0.051905" pos="0 0.116394 0"/>
              <geom name="//unnamed_geom_21" class="reward_collision_sphere" size="0.051905" pos="0 0.227497 0"/>
            </body>
          </body>
        </body>
      </body>
      <body name="AR1" pos="0.0868135 -0.0964184 0.371372" quat="0.99999 4.64783e-06 -0.00169136 0.00415776">
        <inertial pos="0.0111291 -0.0290864 0.00722789" quat="0.505825 0.44899 -0.541609 0.499208" mass="1.84183" diaginertia="0.0237984 0.00213766 0.00464228"/>
        <joint name="Right_Shoulder_Pitch" pos="0 0 0" axis="-0.0493195 -0.997098 0.0579944" stiffness="0.0915091" range="-1.28349 3.53107" armature="0.00338085" damping="0.0591509" frictionloss="0.225708"/>
        <geom name="//unnamed_geom_22" class="visual" rgba="0.76 0.76 0.76 1" mesh="AR1"/>
        <body name="AR2" pos="-0.0176063 -0.062258 0.0116462" quat="0.999968 0.00369612 0.00188572 -0.00690837">
          <inertial pos="0.0188343 -0.0435119 0.00902868" quat="0.482833 0.528105 -0.503929 0.48377" mass="0.62814" diaginertia="0.00514732 0.00036607 0.00291144"/>
          <joint name="Right_Shoulder_Roll" pos="0 0 0" axis="-0.999531 0.0288091 0.0103507" stiffness="0.0221578" range="-1.92059 1.39851" armature="0.0136841" damping="0" frictionloss="0.0107995"/>
          <geom name="//unnamed_geom_23" class="visual" mesh="AR2"/>
          <body name="AR3" pos="-0.0117711 -0.072986 0.0188148" quat="1 -9.76808e-05 -3.05903e-05 -5.27266e-05">
            <inertial pos="-0.00361422 -0.0741202 0.00976965" quat="0.756114 0.653804 -0.026298 -0.011846" mass="3.27996" diaginertia="0.163037 0.0180887 0.00741462"/>
            <joint name="Right_Elbow_Pitch" pos="0 0 0" axis="-0.0342715 0.996954 0.0700627" range="-1.95721 2.50483" armature="0.0276444" damping="0" frictionloss="0.0555515"/>
            <geom name="//unnamed_geom_24" class="visual" mesh="AR3"/>
            <geom name="//unnamed_geom_25" class="collision" size="0.04449 0.111225" pos="0 -0.0529062 0" quat="0.707105 0.707108 0 0" type="cylinder"/>
            <geom name="//unnamed_geom_26" class="reward_collision_sphere" size="0.053388"/>
            <body name="right_hand_link" pos="-0.00232222 -0.15094 0.000790286" quat="0.999973 -0.00217206 -0.00344154 0.00607098">
              <inertial pos="-0.00400395 -0.105573 -0.0153218" quat="0.703964 0.710231 0.00156408 -0.00217388" mass="1.29916" diaginertia="0.12673 0.0115697 0.00372905"/>
              <joint name="Right_Elbow_Yaw" pos="0 0 0" axis="-0.0600935 -0.00812784 0.99816" range="0.079563 2.1876" armature="0.00254516" damping="0.10011" frictionloss="0.0480145"/>
              <geom name="//unnamed_geom_27" class="visual" mesh="right_hand_link"/>
              <geom name="//unnamed_geom_28" class="collision" size="0.04449 0.129763" pos="0 -0.137556 0" quat="0.707105 0.707108 0 0" type="cylinder"/>
              <geom name="//unnamed_geom_29" class="reward_collision_sphere" size="0.0741501"/>
              <geom name="//unnamed_geom_30" class="reward_collision_sphere" size="0.051905" pos="0 -0.116394 0"/>
              <geom name="//unnamed_geom_31" class="reward_collision_sphere" size="0.051905" pos="0 -0.227497 0"/>
            </body>
          </body>
        </body>
      </body>
      <body name="Waist" pos="0.104053 0.0148961 -0.21643" quat="1 0.000942769 6.39698e-05 -7.24578e-05">
        <inertial pos="0.0198148 0.00672822 0.00666022" quat="0.971115 -0.0364414 -0.232328 -0.0403884" mass="10.356" diaginertia="0.0794795 0.00911373 0.0902023"/>
        <joint name="Waist" pos="0 0 0" axis="0.0784502 0.00557567 0.996902" stiffness="0.0571778" range="-1.69855 1.89023" armature="0.0127992" damping="0" frictionloss="0.0342754"/>
        <geom name="//unnamed_geom_32" class="visual" mesh="Waist"/>
        <body name="Hip_Pitch_Left" pos="-0.00376353 0.111214 0.00639029" quat="0.999986 -0.000805275 -0.00483155 -0.00221281">
          <inertial pos="0.00576908 0.00265098 -0.0270061" quat="0.97209 0.23281 0.00332028 -0.0288024" mass="2.74777" diaginertia="0.0231633 0.00145632 0.015731"/>
          <joint name="Left_Hip_Pitch" pos="0 0 0" axis="-0.087461 0.995575 -0.0343727" stiffness="0.0867025" range="-1.81597 1.22497" armature="0.00713787" damping="0.0779169" frictionloss="0.171679"/>
          <geom name="//unnamed_geom_33" class="visual" rgba="0.76 0.76 0.76 1" mesh="Hip_Pitch_Left"/>
          <body name="Hip_Roll_Left" pos="0.00813709 -0.0188696 -0.049525" quat="0.999958 -0.00759629 -0.00386586 -0.0034633">
            <inertial pos="0.0163016 -0.00236033 -0.0987566" quat="0.696164 -0.0427352 0.00776565 0.716567" mass="1.66297" diaginertia="0.0220163 0.00234653 0.00955168"/>
            <joint name="Left_Hip_Roll" pos="0 0 0" axis="-0.996315 -0.0636178 -0.0575291" range="-1.76333 0.251712" armature="0.0228906" damping="0.0357826" frictionloss="0.195904"/>
            <geom name="//unnamed_geom_34" class="visual" mesh="Hip_Roll_Left"/>
            <geom name="//unnamed_geom_35" class="reward_collision_sphere" size="0.0815651"/>
            <body name="Hip_Yaw_Left" pos="-0.00945027 -0.00564033 -0.131243" quat="1 -5.59623e-05 -1.91233e-05 4.29067e-05">
              <inertial pos="-0.0162329 -0.00751256 -0.153411" quat="0.66499 -0.00484367 -0.100903 0.739989" mass="9.53456" diaginertia="0.327834 0.0432178 0.0474676"/>
              <joint name="Left_Hip_Yaw" pos="0 0 0" axis="0.00347613 0.0164807 -0.999858" stiffness="0.00942048" range="-0.730978 0.984582" armature="0.0144862" damping="0" frictionloss="0.114231"/>
              <geom name="//unnamed_geom_36" class="visual" mesh="Hip_Yaw_Left"/>
              <geom name="//unnamed_geom_37" class="collision" size="0.0741501 0.11864" type="cylinder"/>
              <body name="Shank_Left" pos="-0.0146677 0.0160929 -0.233676" quat="1 -2.58333e-06 -0.000409509 0.0006324">
                <inertial pos="-0.000737325 0.0142567 -0.209764" quat="0.999488 0.0187714 -0.0251043 -0.00636034" mass="4.12108" diaginertia="0.377679 0.0404145 0.0288651"/>
                <joint name="Left_Knee_Pitch" pos="0 0 0" axis="-0.0309021 0.999059 0.0304226" range="-0.181853 2.55558" armature="0.00373907" damping="0.0804918" frictionloss="0.201843"/>
                <geom name="//unnamed_geom_38" class="visual" mesh="Shank_Left"/>
                <geom name="//unnamed_geom_39" class="collision" size="0.0741501 0.111225" pos="0 0 -0.206639" type="cylinder"/>
                <geom name="//unnamed_geom_40" class="reward_collision_sphere" size="0.0963951"/>
                <body name="Ankle_Cross_Left" pos="-0.0022312 -0.0133357 -0.467358" quat="0.999968 0.00452796 0.00309799 -0.00586962">
                  <inertial pos="0.00421855 0.0178028 -0.00835493" quat="0.410319 0.561939 0.520721 0.494684" mass="0.246205" diaginertia="0.000403668 2.86969e-05 0.000149525"/>
                  <joint name="Left_Ankle_Pitch" pos="0 0 0" axis="0.049416 0.998072 -0.0375434" stiffness="0.0364486" range="-1.00154 0.184273" armature="0.0208668" damping="0.0299109" frictionloss="0.114508"/>
                  <geom name="//unnamed_geom_41" class="visual" mesh="Ankle_Cross_Left"/>
                  <body name="left_foot_link" pos="0.0149382 0.0174989 -0.0123155" quat="1 0.000239215 -0.00068818 -0.000516045">
                    <inertial pos="-0.0160303 0.00402367 -0.0339461" quat="0.00116259 0.617954 -0.0363736 0.785372" mass="2.29728" diaginertia="0.0412825 0.00318531 0.0402495"/>
                    <joint name="Left_Ankle_Roll" pos="0 0 0" axis="-0.999971 0.00732832 0.00196018" range="-0.397515 0.433086" armature="0.0273563" damping="0.0720929" frictionloss="0.166719"/>
                    <geom name="//unnamed_geom_42" class="visual" mesh="left_foot_link"/>
                    <geom name="left_foot" class="foot" size="0.136345 0.101376 0.0159349" pos="0.0166889 0 -0.0258299"/>
                    <geom name="//unnamed_geom_44" class="reward_collision_sphere" size="0.0771161" pos="0.0166889 0 -0.0258299"/>
                    <geom name="//unnamed_geom_45" class="reward_collision_sphere" size="0.04449" pos="0.158545 -0.0243368 -0.0258299"/>
                    <geom name="//unnamed_geom_46" class="reward_collision_sphere" size="0.04449" pos="-0.116822 -0.0243368 -0.0258299"/>
                    <site name="left_foot" class="foot" pos="0.0166889 0 -0.0258299" size="0.01483"/>
                  </body>
                </body>
              </body>
            </body>
          </body>
        </body>
        <body name="Hip_Pitch_Right" pos="0.0142836 -0.110486 0.0125742" quat="0.999959 -0.00127917 0.00472242 0.00764557">
          <inertial pos="0.00699789 0.0268873 -0.0305934" quat="0.960678 -0.276939 -0.0156374 -0.0125734" mass="3.41325" diaginertia="0.0280545 0.00223445 0.0253186"/>
          <joint name="Right_Hip_Pitch" pos="0 0 0" axis="0.00208164 -0.999963 0.00833344" stiffness="0.0431362" range="-1.29946 1.78235" armature="0.0226797" damping="0" frictionloss="0.019337"/>
          <geom name="//unnamed_geom_47" class="visual" rgba="0.76 0.76 0.76 1" mesh="Hip_Pitch_Right"/>
          <body name="Hip_Roll_Right" pos="-0.00595514 0.00928989 -0.0250922" quat="1 0.000472864 0.000307657 -0.000603129">
            <inertial pos="0.0181549 -0.0181913 -0.0749479" quat="0.674855 0.0168492 -0.00160238 0.737756" mass="1.17356" diaginertia="0.0206256 0.00194927 0.00757784"/>
            <joint name="Right_Hip_Roll" pos="0 0 0" axis="-0.99998 -0.00217782 0.00586215" stiffness="0.0024755" range="-0.103425 1.55622" armature="0.00742446" damping="0" frictionloss="0.109508"/>
            <geom name="//unnamed_geom_48" class="visual" mesh="Hip_Roll_Right"/>
            <geom name="//unnamed_geom_49" class="reward_collision_sphere" size="0.0815651"/>
            <body name="Hip_Yaw_Right" pos="0.00372934 0.0125744 -0.134905" quat="0.999987 -0.00270347 0.000865067 -0.00418079">
              <inertial pos="-0.0242657 0.0124233 -0.160704" quat="0.71442 -0.0308936 -0.0347263 0.698171" mass="7.15251" diaginertia="0.268302 0.0331822 0.0372479"/>
              <joint name="Right_Hip_Yaw" pos="0 0 0" axis="-0.000428662 0.00149924 -0.999999" stiffness="0.0222624" range="-0.879282 1.30078" armature="0.0288664" damping="0" frictionloss="0.0245154"/>
              <geom name="//unnamed_geom_50" class="visual" mesh="Hip_Yaw_Right"/>
              <geom name="//unnamed_geom_51" class="collision" size="0.0741501 0.11864" type="cylinder"/>
              <body name="Shank_Right" pos="-0.0323984 -0.0169372 -0.236713" quat="0.999967 0.00147533 0.00663059 -0.00434664">
                <inertial pos="-0.0128511 -0.0142698 -0.228622" quat="0.99744 -0.0421782 0.0244763 -0.0523039" mass="6.96553" diaginertia="0.528841 0.0493876 0.0230793"/>
                <joint name="Right_Knee_Pitch" pos="0 0 0" axis="-0.0272769 -0.996987 0.0726122" stiffness="0.0014546" range="-2.64265 0.295239" armature="0.0193185" damping="0" frictionloss="0.216312"/>
                <geom name="//unnamed_geom_52" class="visual" mesh="Shank_Right"/>
                <geom name="//unnamed_geom_53" class="collision" size="0.0741501 0.111225" pos="0 0 -0.206639" type="cylinder"/>
                <geom name="//unnamed_geom_54" class="reward_collision_sphere" size="0.0963951"/>
                <body name="Ankle_Cross_Right" pos="-0.0111876 0.0152061 -0.481832" quat="0.999955 -0.00505351 -0.00798584 -0.000160541">
                  <inertial pos="0.00287614 0.00884431 -0.027803" quat="0.486157 0.51513 0.549205 0.443471" mass="0.229171" diaginertia="0.000343148 3.3953e-05 0.000205676"/>
                  <joint name="Right_Ankle_Pitch" pos="0 0 0" axis="-0.038238 -0.998973 0.0243146" stiffness="0.0298946" range="-0.048218 0.778947" armature="0.0115964" damping="0.0163184" frictionloss="0.189432"/>
                  <geom name="//unnamed_geom_55" class="visual" mesh="Ankle_Cross_Right"/>
                  <body name="right_foot_link" pos="0.00818904 0.0157389 -0.0100388" quat="0.999994 0.00197109 -0.00205094 -0.00175533">
                    <inertial pos="0.00348891 -0.00869742 -0.00087096" quat="-0.010991 0.597912 -0.0197641 0.801242" mass="2.44311" diaginertia="0.0325759 0.00316427 0.037996"/>
                    <joint name="Right_Ankle_Roll" pos="0 0 0" axis="-0.997824 -0.00728085 -0.0655303" stiffness="0.0617611" range="-0.817297 0.427224" armature="0.00293057" damping="0.00173457" frictionloss="0.246541"/>
                    <geom name="//unnamed_geom_56" class="visual" mesh="right_foot_link"/>
                    <geom name="right_foot" class="foot" size="0.183183 0.102762 0.0227541" pos="0.0166889 0 -0.0258299"/>
                    <geom name="//unnamed_geom_58" class="reward_collision_sphere" size="0.0593201"/>
                    <geom name="//unnamed_geom_59" class="reward_collision_sphere" size="0.04449" pos="0.0166889 0 -0.0258299"/>
                    <geom name="//unnamed_geom_60" class="reward_collision_sphere" size="0.04449" pos="0.158545 0.0243368 -0.0258299"/>
                    <geom name="//unnamed_geom_61" class="reward_collision_sphere" size="0.04449" pos="-0.116822 0.0243368 -0.0258299"/>
                    <site name="right_foot" class="foot" pos="0.0166889 0 -0.0258299" size="0.01483"/>
                  </body>
                </body>
              </body>
            </body>
          </body>
        </body>
      </body>
    </body>
  </worldbody>

  <contact>
    <pair class="/" geom1="floor" geom2="left_foot" name="//unnamed_contact_0"/>
    <pair class="/" geom1="floor" geom2="right_foot" name="//unnamed_contact_1"/>
  </contact>

  <actuator>
    <general name="AAHead_yaw" class="/" joint="AAHead_yaw" forcerange="-14.972 14.972" gainprm="40.3401" biasprm="0 -40.3401 -0.927121"/>
    <general name="Head_pitch" class="/" joint="Head_pitch" forcerange="-5.33425 5.33425" gainprm="40.3401" biasprm="0 -40.3401 -0.927121"/>
    <general name="Left_Shoulder_Pitch" class="/" joint="Left_Shoulder_Pitch" forcerange="-32.366 32.366" gainprm="40.3401" biasprm="0 -40.3401 -0.927121"/>
    <general name="Left_Shoulder_Roll" class="/" joint="Left_Shoulder_Roll" forcerange="-11.2138 11.2138" gainprm="40.3401" biasprm="0 -40.3401 -0.927121"/>
    <general name="Left_Elbow_Pitch" class="/" joint="Left_Elbow_Pitch" forcerange="-31.8224 31.8224" gainprm="40.3401" biasprm="0 -40.3401 -0.927121"/>
    <general name="Left_Elbow_Yaw" class="/" joint="Left_Elbow_Yaw" forcerange="-25.0827 25.0827" gainprm="40.3401" biasprm="0 -40.3401 -0.927121"/>
    <general name="Right_Shoulder_Pitch" class="/" joint="Right_Shoulder_Pitch" forcerange="-27.8123 27.8123" gainprm="40.3401" biasprm="0 -40.3401 -0.927121"/>
    <general name="Right_Shoulder_Roll" class="/" joint="Right_Shoulder_Roll" forcerange="-35.6304 35.6304" gainprm="40.3401" biasprm="0 -40.3401 -0.927121"/>
    <general name="Right_Elbow_Pitch" class="/" joint="Right_Elbow_Pitch" forcerange="-20.0898 20.0898" gainprm="40.3401" biasprm="0 -40.3401 -0.927121"/>
    <general name="Right_Elbow_Yaw" class="/" joint="Right_Elbow_Yaw" forcerange="-33.5306 33.5306" gainprm="40.3401" biasprm="0 -40.3401 -0.927121"/>
    <general name="Waist" class="/" joint="Waist" forcerange="-70.4456 70.4456" gainprm="40.3401" biasprm="0 -40.3401 -0.927121"/>
    <general name="Left_Hip_Pitch" class="/" joint="Left_Hip_Pitch" forcerange="-87.916 87.916" gainprm="40.3401" biasprm="0 -40.3401 -0.927121"/>
    <general name="Left_Hip_Roll" class="/" joint="Left_Hip_Roll" forcerange="-49.4559 49.4559" gainprm="40.3401" biasprm="0 -40.3401 -0.927121"/>
    <general name="Left_Hip_Yaw" class="/" joint="Left_Hip_Yaw" forcerange="-55.5164 55.5164" gainprm="40.3401" biasprm="0 -40.3401 -0.927121"/>
    <general name="Left_Knee_Pitch" class="/" joint="Left_Knee_Pitch" forcerange="-138.028 138.028" gainprm="40.3401" biasprm="0 -40.3401 -0.927121"/>
    <general name="Left_Ankle_Pitch" class="/" joint="Left_Ankle_Pitch" forcerange="-9.64564 9.64564" gainprm="40.3401" biasprm="0 -40.3401 -0.927121"/>
    <general name="Left_Ankle_Roll" class="/" joint="Left_Ankle_Roll" forcerange="-37.9089 37.9089" gainprm="40.3401" biasprm="0 -40.3401 -0.927121"/>
    <general name="Right_Hip_Pitch" class="/" joint="Right_Hip_Pitch" forcerange="-65.9757 65.9757" gainprm="40.3401" biasprm="0 -40.3401 -0.927121"/>
    <general name="Right_Hip_Roll" class="/" joint="Right_Hip_Roll" forcerange="-69.1176 69.1176" gainprm="40.3401" biasprm="0 -40.3401 -0.927121"/>
    <general name="Right_Hip_Yaw" class="/" joint="Right_Hip_Yaw" forcerange="-16.6496 16.6496" gainprm="40.3401" biasprm="0 -40.3401 -0.927121"/>
    <general name="Right_Knee_Pitch" class="/" joint="Right_Knee_Pitch" forcerange="-63.4408 63.4408" gainprm="40.3401" biasprm="0 -40.3401 -0.927121"/>
    <general name="Right_Ankle_Pitch" class="/" joint="Right_Ankle_Pitch" forcerange="-31.1194 31.1194" gainprm="40.3401" biasprm="0 -40.3401 -0.927121"/>
    <general name="Right_Ankle_Roll" class="/" joint="Right_Ankle_Roll" forcerange="-23.7089 23.7089" gainprm="40.3401" biasprm="0 -40.3401 -0.927121"/>
  </actuator>

  <sensor>
    <gyro site="imu" name="imu_angular_velocity"/>
    <velocimeter site="imu" name="imu_linear_velocity"/>
    <framelinvel objtype="site" objname="left_foot" name="left_foot_global_linear_velocity"/>
    <framelinvel objtype="site" objname="right_foot" name="right_foot_global_linear_velocity"/>
  </sensor>

  <keyframe>
    <key name="home" qpos="0 0 0.6385 1 0 0 0 0 0 0 1.4 0 -0.4 0 -1.4 0 0.4 0 -0.4 0 0 0.8 -0.4 0 0.4 0 0 -0.8 0.4 0"/>
  </keyframe>
</mujoco>
