<mujoco model="T1">
  <compiler angle="radian" assetdir="assets" balanceinertia="true" inertiafromgeom="false"/>

  <option timestep="0.005" density="1.2" viscosity="2e-05"/>

  <size nkey="1"/>

  <visual>
    <quality shadowsize="8192"/>
    <map shadowclip="0.5"/>
  </visual>

  <default>
    <default class="/">
      <joint armature="0.01" damping="0.01" frictionloss="0.1"/>
      <geom contype="0" conaffinity="0" group="1" solref="-1000 -80"/>
      <site size="0.01 0.005 0.005" group="5"/>
      <general forcelimited="true" biastype="affine" gainprm="25" biasprm="0 -25 -0.6"/>
      <default class="t1">
        <geom rgba="0.25 0.25 0.25 1"/>
        <default class="visual">
          <geom type="mesh" group="2"/>
        </default>
        <default class="collision">
          <geom group="3"/>
        </default>
        <default class="foot">
          <geom size="0.1115 0.05 0.015" type="box" condim="6" group="4" priority="1" solimp="0.015 1 0.015"/>
        </default>
        <default class="reward_collision_sphere">
          <geom group="5" rgba="1 0 0 1"/>
        </default>
      </default>
    </default>
  </default>

  <asset>
    <texture type="skybox" colorspace="auto" name="//unnamed_texture_0" builtin="gradient" rgb1="0.95 0.95 0.95" rgb2="0.95 0.95 0.95" width="100" height="600"/>
    <texture type="2d" colorspace="auto" name="texplane" builtin="checker" rgb1="0.345 0.575 0.748" rgb2="0.345 0.575 0.748" markrgb="1 1 1" width="512" height="512"/>
    <material name="MatPlane" class="/" texture="texplane" texuniform="true" texrepeat="2 2" specular="0.9"/>
    <mesh name="Trunk" class="/" file="Trunk.stl"/>
    <mesh name="H1" class="/" file="H1.stl"/>
    <mesh name="H2" class="/" file="H2.stl"/>
    <mesh name="AL1" class="/" file="AL1.stl"/>
    <mesh name="AL2" class="/" file="AL2.stl"/>
    <mesh name="AL3" class="/" file="AL3.stl"/>
    <mesh name="left_hand_link" class="/" file="left_hand_link.stl"/>
    <mesh name="AR1" class="/" file="AR1.stl"/>
    <mesh name="AR2" class="/" file="AR2.stl"/>
    <mesh name="AR3" class="/" file="AR3.stl"/>
    <mesh name="right_hand_link" class="/" file="right_hand_link.stl"/>
    <mesh name="Waist" class="/" file="Waist.stl"/>
    <mesh name="Hip_Pitch_Left" class="/" file="Hip_Pitch_Left.stl"/>
    <mesh name="Hip_Roll_Left" class="/" file="Hip_Roll_Left.stl"/>
    <mesh name="Hip_Yaw_Left" class="/" file="Hip_Yaw_Left.stl"/>
    <mesh name="Shank_Left" class="/" file="Shank_Left.stl"/>
    <mesh name="Ankle_Cross_Left" class="/" file="Ankle_Cross_Left.stl"/>
    <mesh name="left_foot_link" class="/" file="left_foot_link.stl"/>
    <mesh name="Hip_Pitch_Right" class="/" file="Hip_Pitch_Right.stl"/>
    <mesh name="Hip_Roll_Right" class="/" file="Hip_Roll_Right.stl"/>
    <mesh name="Hip_Yaw_Right" class="/" file="Hip_Yaw_Right.stl"/>
    <mesh name="Shank_Right" class="/" file="Shank_Right.stl"/>
    <mesh name="Ankle_Cross_Right" class="/" file="Ankle_Cross_Right.stl"/>
    <mesh name="right_foot_link" class="/" file="right_foot_link.stl"/>
  </asset>

  <worldbody>
    <geom name="floor" class="/" size="100 100 0.125" type="plane" group="0" material="MatPlane"/>
    <light name="toplight_shadow" class="/" pos="0 0 5" dir="0.0990148 0.0990148 -0.990148" type="directional" ambient="0.04 0.04 0.04" diffuse="0.55 0.55 0.55" specular="0.12 0.12 0.12"/>
    <light name="toplight_fill" class="/" pos="0 0 5" dir="0.0990148 0.0990148 -0.990148" type="directional" castshadow="false" ambient="0.04 0.04 0.04" diffuse="0.3 0.3 0.3" specular="0.08 0.08 0.08"/>
    <body name="trunk" childclass="t1" pos="-0.000166347 0.00592698 0.000359578" quat="0.99999 0.00370385 0.000228062 -0.00230088">
      <inertial pos="0.0827238 0.00405058 0.16132" quat="0.998937 0.0409504 -0.0171994 0.0123438" mass="31.5207" diaginertia="0.532532 0.130311 0.426845"/>
      <joint name="//unnamed_joint_0" type="free" armature="0" damping="0" frictionloss="0"/>
      <geom name="//unnamed_geom_1" class="visual" rgba="0.76 0.76 0.76 1" mesh="Trunk"/>
      <geom name="//unnamed_geom_2" class="collision" size="0.104392 0.139189 0.208784" pos="0.0908487 0 0.185454" type="box"/>
      <geom name="//unnamed_geom_3" class="reward_collision_sphere" size="0.160067" pos="0.0908487 0 0.154545"/>
      <geom name="//unnamed_geom_4" class="reward_collision_sphere" size="0.0208784" pos="0.0908487 0.0948664 0"/>
      <geom name="//unnamed_geom_5" class="reward_collision_sphere" size="0.0208784" pos="0.0908487 -0.0948664 0"/>
      <geom name="//unnamed_geom_6" class="reward_collision_sphere" size="0.0208784" pos="0.0908487 0.11942 0.278181"/>
      <geom name="//unnamed_geom_7" class="reward_collision_sphere" size="0.0208784" pos="0.0908487 -0.11942 0.278181"/>
      <site name="imu" pos="-0.0418936 0.000578403 0.0410918" size="0.0139189"/>
      <camera name="track" pos="0 -2.23215 0" quat="0.707107 0.707107 0 0" mode="trackcom"/>
      <camera name="ego_camera" pos="0.184726 0 0.64909" quat="-0.5 -0.5 0.5 0.5"/>
      <body name="H1" pos="0.104112 -0.000486556 0.387326" quat="1 0.000441554 0.000226923 -0.000500065">
        <inertial pos="-0.000381051 -0.00191233 0.0885523" quat="0.761889 -0.0105502 -0.00372836 0.647612" mass="1.17703" diaginertia="0.00206282 0.000367338 0.00131403"/>
        <joint name="AAHead_yaw" pos="0 0 0" axis="-0.00432141 0.00450332 0.999981" range="-1.73699 1.58638" armature="0.00576782" damping="0.00965817" frictionloss="0.0619283"/>
        <geom name="//unnamed_geom_8" class="visual" mesh="H1"/>
        <body name="H2" pos="0.00496157 0.0137963 0.0982372" quat="0.999997 0.000771161 0.00204862 -0.000500622">
          <inertial pos="0.00225587 0.0113521 0.165267" quat="0.981197 0.133155 -0.0753115 -0.117687" mass="1.60223" diaginertia="0.0162202 0.00389829 0.0155752"/>
          <joint name="Head_pitch" pos="0 0 0" axis="0.0187078 -0.999823 0.00183071" range="-1.23539 0.401847" armature="0.00882015" damping="0.0638677" frictionloss="0.134312"/>
          <geom name="//unnamed_geom_9" class="visual" mesh="H2"/>
          <geom name="//unnamed_geom_10" class="collision" size="0.111351" pos="0.0151414 0 0.17"/>
          <geom name="//unnamed_geom_11" class="reward_collision_sphere" size="0.12527" pos="0.0302829 0 0.154545"/>
        </body>
      </body>
      <body name="AL1" pos="0.0853525 0.119404 0.350124" quat="0.999983 -0.00298227 -0.00427988 0.00257">
        <inertial pos="0.00638126 0.0499148 -8.04545e-05" quat="0.505874 0.495707 -0.504415 0.493894" mass="1.54825" diaginertia="0.011672 0.00278351 0.00313434"/>
        <joint name="Left_Shoulder_Pitch" pos="0 0 0" axis="0.0175839 0.999088 0.0389068" range="-3.17694 0.975011" armature="0.0132518" damping="0.064914" frictionloss="0.0963756"/>
        <geom name="//unnamed_geom_12" class="visual" rgba="0.76 0.76 0.76 1" mesh="AL1"/>
        <body name="AL2" pos="0.011056 0.0483399 -0.0039329" quat="1 -2.04431e-05 5.66317e-06 -2.45398e-05">
          <inertial pos="0.0108132 0.0308056 0.00569936" quat="0.484506 0.510054 -0.491757 0.513102" mass="0.393372" diaginertia="0.00294531 0.000531772 0.00153188"/>
          <joint name="Left_Shoulder_Roll" pos="0 0 0" axis="-0.999986 -0.00254635 0.00468671" stiffness="0.0682451" range="-1.68672 1.74441" armature="0.00550589" damping="0.0145086" frictionloss="0.143883"/>
          <geom name="//unnamed_geom_13" class="visual" mesh="AL2"/>
          <body name="AL3" pos="-0.00365124 0.0673734 -0.00637858" quat="0.999999 -0.000990851 0.000469338 -0.000174319">
            <inertial pos="-0.0106625 0.106917 -0.00463784" quat="0.714207 0.699271 0.0169732 -0.0252943" mass="3.50238" diaginertia="0.0999574 0.0249367 0.0067812"/>
            <joint name="Left_Elbow_Pitch" pos="0 0 0" axis="0.0244092 -0.999612 -0.0134093" stiffness="0.02351" range="-2.02039 2.362" armature="0.00460651" damping="0.0240884" frictionloss="0.131738"/>
            <geom name="//unnamed_geom_14" class="visual" mesh="AL3"/>
            <geom name="//unnamed_geom_15" class="collision" size="0.0417567 0.104392" pos="0 0.0558038 0" quat="0.707105 0.707108 0 0" type="cylinder"/>
            <geom name="//unnamed_geom_16" class="reward_collision_sphere" size="0.0501081"/>
            <body name="left_hand_link" pos="0.00241227 0.16274 0.00758299" quat="0.999981 0.00566483 -0.00221685 -0.000280227">
              <inertial pos="0.012428 0.117464 -0.000871366" quat="0.703256 0.710857 0.00938528 -0.00496677" mass="0.856883" diaginertia="0.0728627 0.0130911 0.00161845"/>
              <joint name="Left_Elbow_Yaw" pos="0 0 0" axis="0.000194573 -0.000951857 1" range="-2.44438 0.254236" armature="0.0145091" damping="0" frictionloss="0.147879"/>
              <geom name="//unnamed_geom_17" class="visual" mesh="left_hand_link"/>
              <geom name="//unnamed_geom_18" class="collision" size="0.0417567 0.12179" pos="0 0.14509 0" quat="0.707105 0.707108 0 0" type="cylinder"/>
              <geom name="//unnamed_geom_19" class="reward_collision_sphere" size="0.0695945"/>
              <geom name="//unnamed_geom_20" class="reward_collision_sphere" size="0.0487162" pos="0 0.122768 0"/>
              <geom name="//unnamed_geom_21" class="reward_collision_sphere" size="0.0487162" pos="0 0.239956 0"/>
            </body>
          </body>
        </body>
      </body>
      <body name="AR1" pos="0.0827584 -0.107485 0.337548" quat="0.999997 -0.0014987 0.00159742 -0.00121948">
        <inertial pos="0.00633195 -0.0366371 0.00246997" quat="0.518585 0.467478 -0.519748 0.492337" mass="1.54123" diaginertia="0.0131225 0.00250585 0.00273987"/>
        <joint name="Right_Shoulder_Pitch" pos="0 0 0" axis="-0.0465764 -0.998672 0.022028" stiffness="0.0667228" range="-1.20776 3.43317" armature="0.00670243" damping="0.0304134" frictionloss="0.177848"/>
        <geom name="//unnamed_geom_22" class="visual" rgba="0.76 0.76 0.76 1" mesh="AR1"/>
        <body name="AR2" pos="-0.0126703 -0.0600417 0.00676827" quat="0.999984 -0.00257094 -0.00494348 -0.000425508">
          <inertial pos="0.0133375 -0.0412255 0.00420346" quat="0.524913 0.500037 -0.49601 0.477915" mass="0.49004" diaginertia="0.00318312 0.000512101 0.0015933"/>
          <joint name="Right_Shoulder_Roll" pos="0 0 0" axis="-0.999963 -0.00331 0.00792394" range="-1.8235 1.49562" armature="0.0151608" damping="0" frictionloss="0.044568"/>
          <geom name="//unnamed_geom_23" class="visual" mesh="AR2"/>
          <body name="AR3" pos="-0.00692203 -0.0716201 0.013864" quat="1 -0.000297474 -6.90512e-05 -5.83806e-05">
            <inertial pos="0.000812593 -0.0839995 0.00490464" quat="0.679603 0.732724 -0.0250364 0.0250754" mass="2.79377" diaginertia="0.104447 0.0232245 0.00483669"/>
            <joint name="Right_Elbow_Pitch" pos="0 0 0" axis="-0.0524629 0.998571 -0.010181" range="-2.05594 2.40667" armature="0.0223036" damping="0.00723319" frictionloss="0.0863156"/>
            <geom name="//unnamed_geom_24" class="visual" mesh="AR3"/>
            <geom name="//unnamed_geom_25" class="collision" size="0.0417567 0.104392" pos="0 -0.0558038 0" quat="0.707105 0.707108 0 0" type="cylinder"/>
            <geom name="//unnamed_geom_26" class="reward_collision_sphere" size="0.0501081"/>
            <body name="right_hand_link" pos="0.000807042 -0.163929 -0.0013472" quat="0.999988 0.00189062 -0.00406464 0.00184558">
              <inertial pos="0.000477192 -0.116791 -0.0104849" quat="0.705883 0.708329 0.000451368 -0.000220397" mass="0.960261" diaginertia="0.0697014 0.01514 0.00202117"/>
              <joint name="Right_Elbow_Yaw" pos="0 0 0" axis="0.0217238 0.0289704 0.999344" range="-0.00901983 2.28593" armature="0.00601387" damping="0.0759902" frictionloss="0.079304"/>
              <geom name="//unnamed_geom_27" class="visual" mesh="right_hand_link"/>
              <geom name="//unnamed_geom_28" class="collision" size="0.0417567 0.12179" pos="0 -0.14509 0" quat="0.707105 0.707108 0 0" type="cylinder"/>
              <geom name="//unnamed_geom_29" class="reward_collision_sphere" size="0.0695945"/>
              <geom name="//unnamed_geom_30" class="reward_collision_sphere" size="0.0487162" pos="0 -0.122768 0"/>
              <geom name="//unnamed_geom_31" class="reward_collision_sphere" size="0.0487162" pos="0 -0.239956 0"/>
            </body>
          </body>
        </body>
      </body>
      <body name="Waist" pos="0.0979694 0.00993418 -0.1911" quat="1 -0.000224992 -6.68036e-05 -0.000395918">
        <inertial pos="0.0145283 0.00193138 0.0101006" quat="0.981206 0.0406677 -0.184894 0.0373592" mass="8.10708" diaginertia="0.0493325 0.0106909 0.0479483"/>
        <joint name="Waist" pos="0 0 0" axis="0.0209256 -0.0497529 0.998542" stiffness="0.032675" range="-1.60381 1.79149" armature="0.0147797" damping="0" frictionloss="0.0665019"/>
        <geom name="//unnamed_geom_32" class="visual" mesh="Waist"/>
        <body name="Hip_Pitch_Left" pos="0.000792976 0.120633 0.00177445" quat="0.999996 -0.0022815 0.00183954 5.72216e-05">
          <inertial pos="0.00128434 -0.00267996 -0.0282846" quat="0.975731 0.218548 0.0109365 -0.0080701" mass="2.57623" diaginertia="0.0142974 0.0021714 0.010383"/>
          <joint name="Left_Hip_Pitch" pos="0 0 0" axis="0.0671736 0.997601 -0.0167231" stiffness="0.0617674" range="-1.77097 1.32386" armature="0.00989672" damping="0.0566336" frictionloss="0.131833"/>
          <geom name="//unnamed_geom_33" class="visual" rgba="0.76 0.76 0.76 1" mesh="Hip_Pitch_Left"/>
          <body name="Hip_Roll_Left" pos="0.00338642 -0.0139279 -0.0410655" quat="0.999977 0.0047871 -0.00415267 0.00225099">
            <inertial pos="0.0112162 0.00140248 -0.0845557" quat="0.70319 -0.0224366 -0.00951988 0.710585" mass="1.23347" diaginertia="0.0138431 0.00307585 0.00523517"/>
            <joint name="Left_Hip_Roll" pos="0 0 0" axis="-0.998131 -0.0597127 0.0130255" range="-1.66576 0.170532" armature="0.017881" damping="0.00719097" frictionloss="0.150741"/>
            <geom name="//unnamed_geom_34" class="visual" mesh="Hip_Roll_Left"/>
            <geom name="//unnamed_geom_35" class="reward_collision_sphere" size="0.076554"/>
            <body name="Hip_Yaw_Left" pos="-0.0045464 -0.000935236 -0.121662" quat="1 -6.92064e-05 9.59621e-05 -0.000224743">
              <inertial pos="-0.0106845 -0.00271712 -0.137993" quat="0.695627 0.0213103 -0.056115 0.715891" mass="7.07288" diaginertia="0.205578 0.050583 0.0259666"/>
              <joint name="Left_Hip_Yaw" pos="0 0 0" axis="0.00191143 0.00350025 -0.999992" range="-0.829671 1.04547" armature="0.014241" damping="0" frictionloss="0.139063"/>
              <geom name="//unnamed_geom_36" class="visual" mesh="Hip_Yaw_Left"/>
              <geom name="//unnamed_geom_37" class="collision" size="0.0695945 0.111351" type="cylinder"/>
              <body name="Shank_Left" pos="-0.0173222 0.0111496 -0.205541" quat="1 0.00076282 0.000515972 5.08933e-05">
                <inertial pos="-0.0046646 0.0093467 -0.192367" quat="0.995725 0.0167263 0.0161297 0.089394" mass="3.91347" diaginertia="0.253117 0.0537679 0.0170951"/>
                <joint name="Left_Knee_Pitch" pos="0 0 0" axis="-0.0180833 0.999811 0.00708452" range="-0.0854807 2.45763" armature="0.00673071" damping="0.0510842" frictionloss="0.156035"/>
                <geom name="//unnamed_geom_38" class="visual" mesh="Shank_Left"/>
                <geom name="//unnamed_geom_39" class="collision" size="0.0695945 0.104392" pos="0 0 -0.185454" type="cylinder"/>
                <geom name="//unnamed_geom_40" class="reward_collision_sphere" size="0.0904729"/>
                <body name="Ankle_Cross_Left" pos="0.000927891 -0.00841923 -0.422829" quat="0.999985 0.00138405 -0.00331503 -0.00425011">
                  <inertial pos="-9.65402e-05 0.0128579 -0.0116007" quat="0.411646 0.537931 0.573651 0.460546" mass="0.195969" diaginertia="0.000224242 3.82425e-05 8.86534e-05"/>
                  <joint name="Left_Ankle_Pitch" pos="0 0 0" axis="-0.0344428 0.999295 -0.0149353" stiffness="0.011764" range="-0.907236 0.280962" armature="0.0163933" damping="0.00362648" frictionloss="0.139296"/>
                  <geom name="//unnamed_geom_41" class="visual" mesh="Ankle_Cross_Left"/>
                  <body name="left_foot_link" pos="0.010012 0.0125697 -0.0148893" quat="1 0.000143374 -0.00086352 -0.000373079">
                    <inertial pos="-0.0110566 -0.000538941 -0.0273865" quat="0.00911532 0.625661 -0.0057724 0.78002" mass="1.90359" diaginertia="0.0226606 0.00418163 0.020939"/>
                    <joint name="Left_Ankle_Roll" pos="0 0 0" axis="-0.999961 -0.000993811 0.00872503" range="-0.473556 0.448054" armature="0.0220411" damping="0.042852" frictionloss="0.129552"/>
                    <geom name="//unnamed_geom_42" class="visual" mesh="left_foot_link"/>
                    <geom name="left_foot" class="foot" size="0.123131 0.0933102 0.0187809" pos="0.0151414 0 -0.0231818"/>
                    <geom name="//unnamed_geom_44" class="reward_collision_sphere" size="0.0723783" pos="0.0151414 0 -0.0231818"/>
                    <geom name="//unnamed_geom_45" class="reward_collision_sphere" size="0.0417567" pos="0.143844 -0.0256697 -0.0231818"/>
                    <geom name="//unnamed_geom_46" class="reward_collision_sphere" size="0.0417567" pos="-0.10599 -0.0256697 -0.0231818"/>
                    <site name="left_foot" class="foot" pos="0.0151414 0 -0.0231818" size="0.0139189"/>
                  </body>
                </body>
              </body>
            </body>
          </body>
        </body>
        <body name="Hip_Pitch_Right" pos="0.0093302 -0.121027 0.00763259" quat="0.999978 -0.00108744 0.0063772 0.00136209">
          <inertial pos="0.00221671 0.0223733 -0.0285832" quat="0.976001 -0.21657 -0.00404191 0.0224162" mass="2.87163" diaginertia="0.0165227 0.00292909 0.0132238"/>
          <joint name="Right_Hip_Pitch" pos="0 0 0" axis="0.00279127 -0.999996 0.00053357" stiffness="0.0187383" range="-1.39772 1.8214" armature="0.0178438" damping="0.0169336" frictionloss="0.0525423"/>
          <geom name="//unnamed_geom_47" class="visual" rgba="0.76 0.76 0.76 1" mesh="Hip_Pitch_Right"/>
          <body name="Hip_Roll_Right" pos="-0.00139043 0.00439026 -0.0264642" quat="1 5.30671e-05 -0.000780617 -0.000207267">
            <inertial pos="0.0130429 -0.0132442 -0.0703973" quat="0.69176 -0.0130564 0.00665356 0.721978" mass="0.981038" diaginertia="0.0128428 0.00256503 0.00444565"/>
            <joint name="Right_Hip_Roll" pos="0 0 0" axis="-0.999997 -0.00261301 -0.000177109" range="-0.193395 1.55921" armature="0.0101808" damping="0.00405527" frictionloss="0.135212"/>
            <geom name="//unnamed_geom_48" class="visual" mesh="Hip_Roll_Right"/>
            <geom name="//unnamed_geom_49" class="reward_collision_sphere" size="0.076554"/>
            <body name="Hip_Yaw_Right" pos="-0.000342191 0.00764528 -0.125329" quat="0.999997 0.000540005 0.000336138 0.00254641">
              <inertial pos="-0.0182493 0.00750941 -0.140142" quat="0.715088 -0.03127 -0.0338842 0.697512" mass="6.03031" diaginertia="0.185791 0.0441257 0.0220499"/>
              <joint name="Right_Hip_Yaw" pos="0 0 0" axis="0.0046889 0.0025835 -0.999986" range="-0.975381 1.20222" armature="0.0234315" damping="0" frictionloss="0.0573813"/>
              <geom name="//unnamed_geom_50" class="visual" mesh="Hip_Yaw_Right"/>
              <geom name="//unnamed_geom_51" class="collision" size="0.0695945 0.111351" type="cylinder"/>
              <body name="Shank_Right" pos="-0.0253682 -0.0120253 -0.208639" quat="0.999984 -0.00365842 0.00405238 -0.00119807">
                <inertial pos="-0.0080981 -0.00937236 -0.202038" quat="0.997417 0.013028 -0.013132 -0.0694075" mass="5.38326" diaginertia="0.303517 0.0601713 0.0143227"/>
                <joint name="Right_Knee_Pitch" pos="0 0 0" axis="0.0387295 -0.998603 0.0359518" stiffness="0.00300304" range="-2.54418 0.196498" armature="0.0148658" damping="0" frictionloss="0.169198"/>
                <geom name="//unnamed_geom_52" class="visual" mesh="Shank_Right"/>
                <geom name="//unnamed_geom_53" class="collision" size="0.0695945 0.104392" pos="0 0 -0.185454" type="cylinder"/>
                <geom name="//unnamed_geom_54" class="reward_collision_sphere" size="0.0904729"/>
                <body name="Ankle_Cross_Right" pos="-0.00626794 0.0102509 -0.435689" quat="0.999976 0.00541937 -0.00279682 -0.00338543">
                  <inertial pos="-0.00140931 0.00399578 -0.0214716" quat="0.415316 0.564691 0.555707 0.447019" mass="0.198237" diaginertia="0.000222533 4.45123e-05 0.000112311"/>
                  <joint name="Right_Ankle_Pitch" pos="0 0 0" axis="-0.00156193 -0.999792 0.0203513" stiffness="0.00542112" range="-0.14688 0.86859" armature="0.0142126" damping="0" frictionloss="0.145116"/>
                  <geom name="//unnamed_geom_55" class="visual" mesh="Ankle_Cross_Right"/>
                  <body name="right_foot_link" pos="0.00337754 0.0107653 -0.0128489" quat="1 0.000272453 -0.000599733 0.000722103">
                    <inertial pos="-0.00100201 -0.00387375 -0.0041871" quat="0.00308678 0.619419 -0.0119543 0.784964" mass="1.94119" diaginertia="0.0215887 0.00409284 0.021303"/>
                    <joint name="Right_Ankle_Roll" pos="0 0 0" axis="-0.999142 0.0403356 0.00939227" stiffness="0.0369516" range="-0.718377 0.450766" armature="0.00639929" damping="0.0124836" frictionloss="0.197169"/>
                    <geom name="//unnamed_geom_56" class="visual" mesh="right_foot_link"/>
                    <geom name="right_foot" class="foot" size="0.145824 0.0919733 0.0191823" pos="0.0151414 0 -0.0231818"/>
                    <geom name="//unnamed_geom_58" class="reward_collision_sphere" size="0.0556756"/>
                    <geom name="//unnamed_geom_59" class="reward_collision_sphere" size="0.0417567" pos="0.0151414 0 -0.0231818"/>
                    <geom name="//unnamed_geom_60" class="reward_collision_sphere" size="0.0417567" pos="0.143844 0.0256697 -0.0231818"/>
                    <geom name="//unnamed_geom_61" class="reward_collision_sphere" size="0.0417567" pos="-0.10599 0.0256697 -0.0231818"/>
                    <site name="right_foot" class="foot" pos="0.0151414 0 -0.0231818" size="0.0139189"/>
                  </body>
                </body>
              </body>
            </body>
          </body>
        </body>
      </body>
    </body>
  </worldbody>

  <contact>
    <pair class="/" geom1="floor" geom2="left_foot" name="//unnamed_contact_0"/>
    <pair class="/" geom1="floor" geom2="right_foot" name="//unnamed_contact_1"/>
  </contact>

  <actuator>
    <general name="AAHead_yaw" class="/" joint="AAHead_yaw" forcerange="-12.262 12.262" gainprm="39.6078" biasprm="0 -39.6078 -0.903002"/>
    <general name="Head_pitch" class="/" joint="Head_pitch" forcerange="-6.80196 6.80196" gainprm="39.6078" biasprm="0 -39.6078 -0.903002"/>
    <general name="Left_Shoulder_Pitch" class="/" joint="Left_Shoulder_Pitch" forcerange="-25.8905 25.8905" gainprm="39.6078" biasprm="0 -39.6078 -0.903002"/>
    <general name="Left_Shoulder_Roll" class="/" joint="Left_Shoulder_Roll" forcerange="-15.15 15.15" gainprm="39.6078" biasprm="0 -39.6078 -0.903002"/>
    <general name="Left_Elbow_Pitch" class="/" joint="Left_Elbow_Pitch" forcerange="-25.5274 25.5274" gainprm="39.6078" biasprm="0 -39.6078 -0.903002"/>
    <general name="Left_Elbow_Yaw" class="/" joint="Left_Elbow_Yaw" forcerange="-27.3632 27.3632" gainprm="39.6078" biasprm="0 -39.6078 -0.903002"/>
    <general name="Right_Shoulder_Pitch" class="/" joint="Right_Shoulder_Pitch" forcerange="-25.7276 25.7276" gainprm="39.6078" biasprm="0 -39.6078 -0.903002"/>
    <general name="Right_Shoulder_Roll" class="/" joint="Right_Shoulder_Roll" forcerange="-28.8968 28.8968" gainprm="39.6078" biasprm="0 -39.6078 -0.903002"/>
    <general name="Right_Elbow_Pitch" class="/" joint="Right_Elbow_Pitch" forcerange="-23.3771 23.3771" gainprm="39.6078" biasprm="0 -39.6078 -0.903002"/>
    <general name="Right_Elbow_Yaw" class="/" joint="Right_Elbow_Yaw" forcerange="-26.9393 26.9393" gainprm="39.6078" biasprm="0 -39.6078 -0.903002"/>
    <general name="Waist" class="/" joint="Waist" forcerange="-58.41 58.41" gainprm="39.6078" biasprm="0 -39.6078 -0.903002"/>
    <general name="Left_Hip_Pitch" class="/" joint="Left_Hip_Pitch" forcerange="-71.1417 71.1417" gainprm="39.6078" biasprm="0 -39.6078 -0.903002"/>
    <general name="Left_Hip_Roll" class="/" joint="Left_Hip_Roll" forcerange="-39.9109 39.9109" gainprm="39.6078" biasprm="0 -39.6078 -0.903002"/>
    <general name="Left_Hip_Yaw" class="/" joint="Left_Hip_Yaw" forcerange="-44.6431 44.6431" gainprm="39.6078" biasprm="0 -39.6078 -0.903002"/>
    <general name="Left_Knee_Pitch" class="/" joint="Left_Knee_Pitch" forcerange="-114.071 114.071" gainprm="39.6078" biasprm="0 -39.6078 -0.903002"/>
    <general name="Left_Ankle_Pitch" class="/" joint="Left_Ankle_Pitch" forcerange="-14.2141 14.2141" gainprm="39.6078" biasprm="0 -39.6078 -0.903002"/>
    <general name="Left_Ankle_Roll" class="/" joint="Left_Ankle_Roll" forcerange="-31.7054 31.7054" gainprm="39.6078" biasprm="0 -39.6078 -0.903002"/>
    <general name="Right_Hip_Pitch" class="/" joint="Right_Hip_Pitch" forcerange="-65.9572 65.9572" gainprm="39.6078" biasprm="0 -39.6078 -0.903002"/>
    <general name="Right_Hip_Roll" class="/" joint="Right_Hip_Roll" forcerange="-57.1589 57.1589" gainprm="39.6078" biasprm="0 -39.6078 -0.903002"/>
    <general name="Right_Hip_Yaw" class="/" joint="Right_Hip_Yaw" forcerange="-23.3692 23.3692" gainprm="39.6078" biasprm="0 -39.6078 -0.903002"/>
    <general name="Right_Knee_Pitch" class="/" joint="Right_Knee_Pitch" forcerange="-74.6744 74.6744" gainprm="39.6078" biasprm="0 -39.6078 -0.903002"/>
    <general name="Right_Ankle_Pitch" class="/" joint="Right_Ankle_Pitch" forcerange="-26.511 26.511" gainprm="39.6078" biasprm="0 -39.6078 -0.903002"/>
    <general name="Right_Ankle_Roll" class="/" joint="Right_Ankle_Roll" forcerange="-19.7243 19.7243" gainprm="39.6078" biasprm="0 -39.6078 -0.903002"/>
  </actuator>

  <sensor>
    <gyro site="imu" name="imu_angular_velocity"/>
    <velocimeter site="imu" name="imu_linear_velocity"/>
    <framelinvel objtype="site" objname="left_foot" name="left_foot_global_linear_velocity"/>
    <framelinvel objtype="site" objname="right_foot" name="right_foot_global_linear_velocity"/>
  </sensor>

  <keyframe>
    <key name="home" qpos="0 0 0.6385 1 0 0 0 0 0 0 1.4 0 -0.4 0 -1.4 0 0.4 0 -0.4 0 0 0.8 -0.4 0 0.4 0 0 -0.8 0.4 0"/>
  </keyframe>
</mujoco>
