<mujoco model="T1">
  <compiler angle="radian" assetdir="assets" balanceinertia="true" inertiafromgeom="false"/>

  <option timestep="0.005" density="1.2" viscosity="2e-05"/>

  <size nkey="1"/>

  <visual>
    <quality shadowsize="8192"/>
    <map shadowclip="0.5"/>
  </visual>

  <default>
    <default class="/">
      <joint armature="0.01" damping="0.01" frictionloss="0.1"/>
      <geom contype="0" conaffinity="0" group="1" solref="-1000 -80"/>
      <site size="0.01 0.005 0.005" group="5"/>
      <general forcelimited="true" biastype="affine" gainprm="25" biasprm="0 -25 -0.6"/>
      <default class="t1">
        <geom rgba="0.25 0.25 0.25 1"/>
        <default class="visual">
          <geom type="mesh" group="2"/>
        </default>
        <default class="collision">
          <geom group="3"/>
        </default>
        <default class="foot">
          <geom size="0.1115 0.05 0.015" type="box" condim="6" group="4" priority="1" solimp="0.015 1 0.015"/>
        </default>
        <default class="reward_collision_sphere">
          <geom group="5" rgba="1 0 0 1"/>
        </default>
      </default>
    </default>
  </default>

  <asset>
    <texture type="skybox" colorspace="auto" name="//unnamed_texture_0" builtin="gradient" rgb1="0.95 0.95 0.95" rgb2="0.95 0.95 0.95" width="100" height="600"/>
    <texture type="2d" colorspace="auto" name="texplane" builtin="checker" rgb1="0.345 0.575 0.748" rgb2="0.345 0.575 0.748" markrgb="1 1 1" width="512" height="512"/>
    <material name="MatPlane" class="/" texture="texplane" texuniform="true" texrepeat="2 2" specular="0.9"/>
    <mesh name="Trunk" class="/" file="Trunk.stl"/>
    <mesh name="H1" class="/" file="H1.stl"/>
    <mesh name="H2" class="/" file="H2.stl"/>
    <mesh name="AL1" class="/" file="AL1.stl"/>
    <mesh name="AL2" class="/" file="AL2.stl"/>
    <mesh name="AL3" class="/" file="AL3.stl"/>
    <mesh name="left_hand_link" class="/" file="left_hand_link.stl"/>
    <mesh name="AR1" class="/" file="AR1.stl"/>
    <mesh name="AR2" class="/" file="AR2.stl"/>
    <mesh name="AR3" class="/" file="AR3.stl"/>
    <mesh name="right_hand_link" class="/" file="right_hand_link.stl"/>
    <mesh name="Waist" class="/" file="Waist.stl"/>
    <mesh name="Hip_Pitch_Left" class="/" file="Hip_Pitch_Left.stl"/>
    <mesh name="Hip_Roll_Left" class="/" file="Hip_Roll_Left.stl"/>
    <mesh name="Hip_Yaw_Left" class="/" file="Hip_Yaw_Left.stl"/>
    <mesh name="Shank_Left" class="/" file="Shank_Left.stl"/>
    <mesh name="Ankle_Cross_Left" class="/" file="Ankle_Cross_Left.stl"/>
    <mesh name="left_foot_link" class="/" file="left_foot_link.stl"/>
    <mesh name="Hip_Pitch_Right" class="/" file="Hip_Pitch_Right.stl"/>
    <mesh name="Hip_Roll_Right" class="/" file="Hip_Roll_Right.stl"/>
    <mesh name="Hip_Yaw_Right" class="/" file="Hip_Yaw_Right.stl"/>
    <mesh name="Shank_Right" class="/" file="Shank_Right.stl"/>
    <mesh name="Ankle_Cross_Right" class="/" file="Ankle_Cross_Right.stl"/>
    <mesh name="right_foot_link" class="/" file="right_foot_link.stl"/>
  </asset>

  <worldbody>
    <geom name="floor" class="/" size="100 100 0.125" type="plane" group="0" material="MatPlane"/>
    <light name="toplight_shadow" class="/" pos="0 0 5" dir="0.0990148 0.0990148 -0.990148" type="directional" ambient="0.04 0.04 0.04" diffuse="0.55 0.55 0.55" specular="0.12 0.12 0.12"/>
    <light name="toplight_fill" class="/" pos="0 0 5" dir="0.0990148 0.0990148 -0.990148" type="directional" castshadow="false" ambient="0.04 0.04 0.04" diffuse="0.3 0.3 0.3" specular="0.08 0.08 0.08"/>
    <body name="trunk" childclass="t1" pos="-0.0017602 0.000284642 -0.00363456" quat="0.999999 0.000783932 -0.00083245 -0.000155266">
      <inertial pos="0.0558462 -0.00369131 0.0622885" quat="0.999957 0.000876966 -0.00917373 0.000981354" mass="8.60542" diaginertia="0.103964 0.0915704 0.00490473"/>
      <joint name="//unnamed_joint_0" type="free" armature="0" damping="0" frictionloss="0"/>
      <geom name="//unnamed_geom_1" class="visual" rgba="0.76 0.76 0.76 1" mesh="Trunk"/>
      <geom name="//unnamed_geom_2" class="collision" size="0.0661317 0.0881756 0.132263" pos="0.0609578 0 0.0724582" type="box"/>
      <geom name="//unnamed_geom_3" class="reward_collision_sphere" size="0.101402" pos="0.0609578 0 0.0603818"/>
      <geom name="//unnamed_geom_4" class="reward_collision_sphere" size="0.0132263" pos="0.0609578 0.0871663 0"/>
      <geom name="//unnamed_geom_5" class="reward_collision_sphere" size="0.0132263" pos="0.0609578 -0.0871663 0"/>
      <geom name="//unnamed_geom_6" class="reward_collision_sphere" size="0.0132263" pos="0.0609578 0.109727 0.108687"/>
      <geom name="//unnamed_geom_7" class="reward_collision_sphere" size="0.0132263" pos="0.0609578 -0.109727 0.108687"/>
      <site name="imu" pos="-0.0348269 0.0248302 0.00252583" size="0.00881756"/>
      <camera name="track" pos="0 -2.05097 0" quat="0.707107 0.707107 0 0" mode="trackcom"/>
      <camera name="ego_camera" pos="0.123948 0 0.253604" quat="-0.5 -0.5 0.5 0.5"/>
      <body name="H1" pos="0.0622415 0.000960532 0.145334" quat="1 3.97287e-05 -0.000201344 0.000392402">
        <inertial pos="-1.36025e-05 -0.00388031 0.0325252" quat="0.763802 -0.0208815 3.84354e-05 0.645112" mass="0.293228" diaginertia="0.000246098 0.00025121 1.13134e-05"/>
        <joint name="AAHead_yaw" pos="0 0 0" axis="0.00114391 0.000646454 0.999999" range="-1.55991 1.53923" armature="0.00961314" damping="0.0103952" frictionloss="0.0804188"/>
        <geom name="//unnamed_geom_8" class="visual" mesh="H1"/>
        <body name="H2" pos="-0.000390073 0.00555075 0.0359142" quat="1 1.53989e-05 -0.00040981 5.16685e-05">
          <inertial pos="0.000529537 -0.00479674 0.0575003" quat="0.987747 0.109807 -0.0737573 -0.0828096" mass="0.403003" diaginertia="0.00226979 0.00218593 0.000136822"/>
          <joint name="Head_pitch" pos="0 0 0" axis="-0.0083973 -0.999954 -0.00465292" range="-1.22868 0.308219" armature="0.0108769" damping="0.00857736" frictionloss="0.0859452"/>
          <geom name="//unnamed_geom_9" class="visual" mesh="H2"/>
          <geom name="//unnamed_geom_10" class="collision" size="0.0705405" pos="0.0101596 0 0.06642"/>
          <geom name="//unnamed_geom_11" class="reward_collision_sphere" size="0.079358" pos="0.0203193 0 0.0603818"/>
        </body>
      </body>
      <body name="AL1" pos="0.0620698 0.112217 0.135558" quat="1 -8.97011e-05 0.000426983 4.09292e-05">
        <inertial pos="-0.000499324 0.0459363 -0.00572896" quat="0.502126 0.496691 -0.505474 0.495644" mass="0.356315" diaginertia="0.00144607 0.00147318 2.37532e-05"/>
        <joint name="Left_Shoulder_Pitch" pos="0 0 0" axis="-0.0034679 0.999979 -0.00546108" stiffness="0.0237592" range="-3.20407 1.26015" armature="0.00979444" damping="0.0144575" frictionloss="0.0913458"/>
        <geom name="//unnamed_geom_12" class="visual" rgba="0.76 0.76 0.76 1" mesh="AL1"/>
        <body name="AL2" pos="0.00454237 0.0430219 0.0020212" quat="0.999994 0.000727644 0.000939028 0.00329339">
          <inertial pos="0.00447557 0.0380885 0.00330488" quat="0.493934 0.503377 -0.493213 0.509295" mass="0.0921344" diaginertia="0.000391792 0.000347058 1.27727e-05"/>
          <joint name="Left_Shoulder_Roll" pos="0 0 0" axis="-0.999199 0.00612424 0.0395497" stiffness="0.00382294" range="-1.54147 1.74974" armature="0.00863674" damping="0.0371584" frictionloss="0.0839455"/>
          <geom name="//unnamed_geom_13" class="visual" mesh="AL2"/>
          <body name="AL3" pos="0.00104588 0.0569176 0.00202727" quat="0.999993 0.00162506 0.000661786 -0.00335608">
            <inertial pos="0.00239253 0.0895777 0.000223331" quat="0.713914 0.700023 -0.0155047 -0.00744033" mass="0.650976" diaginertia="0.0126131 0.0137634 4.6439e-05"/>
            <joint name="Left_Elbow_Pitch" pos="0 0 0" axis="0.00220218 -0.999987 0.00469628" stiffness="0.00875718" range="-2.27287 2.2781" armature="0.00933498" damping="0.00563593" frictionloss="0.0914005"/>
            <geom name="//unnamed_geom_14" class="visual" mesh="AL3"/>
            <geom name="//unnamed_geom_15" class="collision" size="0.0264527 0.0661317" pos="0 0.0512743 0" quat="0.707105 0.707108 0 0" type="cylinder"/>
            <geom name="//unnamed_geom_16" class="reward_collision_sphere" size="0.0317432"/>
            <body name="left_hand_link" pos="0.00383084 0.144261 -0.00158359" quat="0.999996 0.000852238 0.00237953 0.00146618">
              <inertial pos="-0.00162178 0.112291 0.00572691" quat="0.699907 0.713867 -0.00830255 0.0213428" mass="0.24342" diaginertia="0.00960144 0.0102448 1.89361e-05"/>
              <joint name="Left_Elbow_Yaw" pos="0 0 0" axis="0.0216063 0.00226392 0.999764" range="-2.44126 -0.0730623" armature="0.00846135" damping="0.0161254" frictionloss="0.057509"/>
              <geom name="//unnamed_geom_17" class="visual" mesh="left_hand_link"/>
              <geom name="//unnamed_geom_18" class="collision" size="0.0264527 0.0771536" pos="0 0.133313 0" quat="0.707105 0.707108 0 0" type="cylinder"/>
              <geom name="//unnamed_geom_19" class="reward_collision_sphere" size="0.0440878"/>
              <geom name="//unnamed_geom_20" class="reward_collision_sphere" size="0.0308615" pos="0 0.112803 0"/>
              <geom name="//unnamed_geom_21" class="reward_collision_sphere" size="0.0308615" pos="0 0.22048 0"/>
            </body>
          </body>
        </body>
      </body>
      <body name="AR1" pos="0.0629381 -0.111479 0.135282" quat="1 0.000278924 -0.000713335 -0.000408323">
        <inertial pos="0.000740494 -0.0481631 0.0027097" quat="0.506789 0.487467 -0.504988 0.500529" mass="0.352125" diaginertia="0.00146608 0.00139027 2.24467e-05"/>
        <joint name="Right_Shoulder_Pitch" pos="0 0 0" axis="-0.00277967 -0.999996 -0.000955874" range="-1.34391 3.25729" armature="0.00817621" damping="0" frictionloss="0.0912489"/>
        <geom name="//unnamed_geom_22" class="visual" rgba="0.76 0.76 0.76 1" mesh="AR1"/>
        <body name="AR2" pos="0.00573736 -0.0514653 0.00201453" quat="1 7.55729e-05 -5.93208e-06 0.000184335">
          <inertial pos="0.00495903 -0.0382488 0.00275444" quat="0.515827 0.4882 -0.508075 0.487281" mass="0.113954" diaginertia="0.000467154 0.000431064 1.39911e-05"/>
          <joint name="Right_Shoulder_Roll" pos="0 0 0" axis="-0.999999 -0.000290682 -0.00143704" range="-1.75062 1.68808" armature="0.0092223" damping="0.0117148" frictionloss="0.11214"/>
          <geom name="//unnamed_geom_23" class="visual" mesh="AR2"/>
          <body name="AR3" pos="0.000602882 -0.0689439 -0.00498562" quat="0.999999 0.000114429 0.000823328 0.000719229">
            <inertial pos="-0.00020555 -0.08917 -0.000902677" quat="0.714518 0.69867 -0.00732016 -0.0356406" mass="0.698406" diaginertia="0.0139273 0.0140623 4.82477e-05"/>
            <joint name="Right_Elbow_Pitch" pos="0 0 0" axis="-0.00448233 0.999989 -0.00100795" range="-2.26612 2.25974" armature="0.00776479" damping="0" frictionloss="0.0612055"/>
            <geom name="//unnamed_geom_24" class="visual" mesh="AR3"/>
            <geom name="//unnamed_geom_25" class="collision" size="0.0264527 0.0661317" pos="0 -0.0512743 0" quat="0.707105 0.707108 0 0" type="cylinder"/>
            <geom name="//unnamed_geom_26" class="reward_collision_sphere" size="0.0317432"/>
            <body name="right_hand_link" pos="0.00492692 -0.152747 0.0012985" quat="1 9.30031e-05 0.000262057 0.00011537">
              <inertial pos="0.00237672 -0.112521 -0.00527365" quat="0.702753 0.710968 -0.0227703 0.0119903" mass="0.24981" diaginertia="0.00978574 0.0100779 1.88508e-05"/>
              <joint name="Right_Elbow_Yaw" pos="0 0 0" axis="0.013281 0.00703606 0.999887" range="0.0722468 2.47897" armature="0.00549393" damping="0.0138662" frictionloss="0.0868173"/>
              <geom name="//unnamed_geom_27" class="visual" mesh="right_hand_link"/>
              <geom name="//unnamed_geom_28" class="collision" size="0.0264527 0.0771536" pos="0 -0.133313 0" quat="0.707105 0.707108 0 0" type="cylinder"/>
              <geom name="//unnamed_geom_29" class="reward_collision_sphere" size="0.0440878"/>
              <geom name="//unnamed_geom_30" class="reward_collision_sphere" size="0.0308615" pos="0 -0.112803 0"/>
              <geom name="//unnamed_geom_31" class="reward_collision_sphere" size="0.0308615" pos="0 -0.22048 0"/>
            </body>
          </body>
        </body>
      </body>
      <body name="Waist" pos="0.0620847 0.00112315 -0.0661389" quat="1 -0.000224166 -0.000116646 0.000518677">
        <inertial pos="-0.00365718 -0.00070876 0.0030503" quat="0.983663 0.000894135 -0.179989 0.00319157" mass="1.8044" diaginertia="0.00610118 0.00675836 0.00040989"/>
        <joint name="Waist" pos="0 0 0" axis="0.00341524 -0.00557353 0.999979" range="-1.71247 1.57547" armature="0.0105691" damping="0.013282" frictionloss="0.0780651"/>
        <geom name="//unnamed_geom_32" class="visual" mesh="Waist"/>
        <body name="Hip_Pitch_Left" pos="0.00558525 0.103811 1.73533e-05" quat="0.999995 0.00158141 0.000361606 -0.00260635">
          <inertial pos="0.00229328 -0.0142727 -0.0107035" quat="0.97509 0.221333 0.0143938 0.00181094" mass="0.696198" diaginertia="0.00201716 0.0015329 0.000102784"/>
          <joint name="Left_Hip_Pitch" pos="0 0 0" axis="-0.0104379 0.999875 -0.0119052" range="-1.80376 1.5319" armature="0.00863116" damping="0.0124086" frictionloss="0.0874637"/>
          <geom name="//unnamed_geom_33" class="visual" rgba="0.76 0.76 0.76 1" mesh="Hip_Pitch_Left"/>
          <body name="Hip_Roll_Left" pos="-0.000999817 0.000170697 -0.011614" quat="0.999997 -0.000108582 -0.00119047 -0.00214147">
            <inertial pos="0.00312616 -0.00050188 -0.0343064" quat="0.707306 -0.00315661 -0.00242376 0.706897" mass="0.265232" diaginertia="0.00186814 0.00185668 4.43564e-05"/>
            <joint name="Left_Hip_Roll" pos="0 0 0" axis="-0.999985 0.00437031 -0.00339177" stiffness="0.0075748" range="-1.53077 0.172564" armature="0.0084199" damping="0" frictionloss="0.0720102"/>
            <geom name="//unnamed_geom_34" class="visual" mesh="Hip_Roll_Left"/>
            <geom name="//unnamed_geom_35" class="reward_collision_sphere" size="0.0484966"/>
            <body name="Hip_Yaw_Left" pos="-0.00211039 -0.0010841 -0.0468733" quat="1 0.000710074 -0.000276423 -0.000536263">
              <inertial pos="-0.00509141 -0.000727111 -0.0555509" quat="0.681548 -0.0598566 -0.0421545 0.728102" mass="1.48612" diaginertia="0.0285949 0.0311683 0.000205636"/>
              <joint name="Left_Hip_Yaw" pos="0 0 0" axis="-0.0252677 -2.48973e-06 -0.999681" stiffness="0.00315638" range="-0.991913 1.06242" armature="0.00857033" damping="0" frictionloss="0.0886178"/>
              <geom name="//unnamed_geom_36" class="visual" mesh="Hip_Yaw_Left"/>
              <geom name="//unnamed_geom_37" class="collision" size="0.0440878 0.0705405" type="cylinder"/>
              <body name="Shank_Left" pos="-0.0141994 0.000408645 -0.0810361" quat="1 5.35725e-05 -0.000127159 0.000384018">
                <inertial pos="-0.00707069 0.00139976 -0.0744176" quat="0.996325 -0.00147713 -0.0351307 0.0781095" mass="1.16219" diaginertia="0.0369427 0.0371903 0.000145929"/>
                <joint name="Left_Knee_Pitch" pos="0 0 0" axis="-0.00563941 0.999932 -0.0102157" range="0.0120088 2.35579" armature="0.00943879" damping="0" frictionloss="0.0681578"/>
                <geom name="//unnamed_geom_38" class="visual" mesh="Shank_Left"/>
                <geom name="//unnamed_geom_39" class="collision" size="0.0440878 0.0661317" pos="0 0 -0.0724582" type="cylinder"/>
                <geom name="//unnamed_geom_40" class="reward_collision_sphere" size="0.0573141"/>
                <body name="Ankle_Cross_Left" pos="-0.000693072 0.000646401 -0.168982" quat="1 0.000159304 0.000645744 -0.000418091">
                  <inertial pos="-0.00593977 -0.000630952 0.00236077" quat="0.444247 0.55098 0.553354 0.439165" mass="0.0481257" diaginertia="2.75767e-05 2.79641e-05 8.6398e-07"/>
                  <joint name="Left_Ankle_Pitch" pos="0 0 0" axis="0.00430426 0.99999 0.00156233" range="-0.722202 0.322992" armature="0.00926986" damping="0.0147355" frictionloss="0.0665849"/>
                  <geom name="//unnamed_geom_41" class="visual" mesh="Ankle_Cross_Left"/>
                  <body name="left_foot_link" pos="-0.00533382 0.000536571 -0.000979347" quat="1 0.000125009 -0.000355978 0.000279276">
                    <inertial pos="-0.0014397 0.00585502 -0.00338944" quat="0.00161995 0.616235 0.00261451 0.787556" mass="0.475956" diaginertia="0.00286134 0.0027197 0.000180246"/>
                    <joint name="Left_Ankle_Roll" pos="0 0 0" axis="-0.999974 -0.00339766 -0.00640921" range="-0.404764 0.431288" armature="0.00835759" damping="0" frictionloss="0.0983291"/>
                    <geom name="//unnamed_geom_42" class="visual" mesh="left_foot_link"/>
                    <geom name="left_foot" class="foot" size="0.103151 0.0338148 0.0130616" pos="0.0101596 0 -0.00905727"/>
                    <geom name="//unnamed_geom_44" class="reward_collision_sphere" size="0.0458513" pos="0.0101596 0 -0.00905727"/>
                    <geom name="//unnamed_geom_45" class="reward_collision_sphere" size="0.0264527" pos="0.0965165 -0.0235862 -0.00905727"/>
                    <geom name="//unnamed_geom_46" class="reward_collision_sphere" size="0.0264527" pos="-0.0711175 -0.0235862 -0.00905727"/>
                    <site name="left_foot" class="foot" pos="0.0101596 0 -0.00905727" size="0.00881756"/>
                  </body>
                </body>
              </body>
            </body>
          </body>
        </body>
        <body name="Hip_Pitch_Right" pos="0.000438546 -0.106572 -0.00360526" quat="1 -2.62904e-05 0.000274251 0.000376445">
          <inertial pos="0.000755422 0.00926094 -0.0166891" quat="0.9776 -0.210362 0.00463382 0.0049192" mass="0.717096" diaginertia="0.00198812 0.0017101 9.77926e-05"/>
          <joint name="Right_Hip_Pitch" pos="0 0 0" axis="0.0155214 -0.99981 0.0117562" stiffness="0.00215746" range="-1.5785 1.81976" armature="0.00711821" damping="0" frictionloss="0.08352"/>
          <geom name="//unnamed_geom_47" class="visual" rgba="0.76 0.76 0.76 1" mesh="Hip_Pitch_Right"/>
          <body name="Hip_Roll_Right" pos="-0.0015612 0.000702952 -0.0129644" quat="0.999993 0.00323678 -0.00149638 0.000585009">
            <inertial pos="-0.00568309 0.000760219 -0.0300175" quat="0.705211 0.0115103 6.15087e-07 0.708904" mass="0.275015" diaginertia="0.00202004 0.00182689 4.24817e-05"/>
            <joint name="Right_Hip_Roll" pos="0 0 0" axis="-0.99997 0.00233559 0.0073576" range="-0.189941 1.4968" armature="0.00973825" damping="0.007586" frictionloss="0.0896066"/>
            <geom name="//unnamed_geom_48" class="visual" mesh="Hip_Roll_Right"/>
            <geom name="//unnamed_geom_49" class="reward_collision_sphere" size="0.0484966"/>
            <body name="Hip_Yaw_Right" pos="0.00156824 0.00341761 -0.0517771" quat="0.999997 0.00192551 -0.00172083 0.000339443">
              <inertial pos="-0.00860605 -0.0024991 -0.0529866" quat="0.708343 -0.026374 -0.0309653 0.704695" mass="1.40607" diaginertia="0.0243422 0.0243815 0.000193726"/>
              <joint name="Right_Hip_Yaw" pos="0 0 0" axis="0.00239028 -0.00662894 -0.999975" stiffness="0.00702599" range="-1.01218 1.14426" armature="0.00833828" damping="0.0117426" frictionloss="0.112227"/>
              <geom name="//unnamed_geom_50" class="visual" mesh="Hip_Yaw_Right"/>
              <geom name="//unnamed_geom_51" class="collision" size="0.0440878 0.0705405" type="cylinder"/>
              <body name="Shank_Right" pos="-0.00830148 -0.002426 -0.0817065" quat="0.999996 0.00108709 -0.00173156 0.00172657">
                <inertial pos="-0.0109214 -0.00106066 -0.0767688" quat="0.999417 0.00186985 -0.0197482 -0.0277772" mass="1.08679" diaginertia="0.0380252 0.0408061 0.000159702"/>
                <joint name="Right_Knee_Pitch" pos="0 0 0" axis="0.00501717 -0.999884 -0.0143552" range="-2.37281 0.00790908" armature="0.00991562" damping="0.00143644" frictionloss="0.0888817"/>
                <geom name="//unnamed_geom_52" class="visual" mesh="Shank_Right"/>
                <geom name="//unnamed_geom_53" class="collision" size="0.0440878 0.0661317" pos="0 0 -0.0724582" type="cylinder"/>
                <geom name="//unnamed_geom_54" class="reward_collision_sphere" size="0.0573141"/>
                <body name="Ankle_Cross_Right" pos="0.00285449 -0.000879462 -0.166285" quat="0.999997 0.0011819 -0.000856046 0.00196281">
                  <inertial pos="-0.00386434 0.000278302 -0.00458715" quat="0.44353 0.551488 0.551157 0.442005" mass="0.0549942" diaginertia="3.25535e-05 2.98569e-05 9.13442e-07"/>
                  <joint name="Right_Ankle_Pitch" pos="0 0 0" axis="-0.0366994 -0.999324 0.00229471" stiffness="0.00871938" range="-0.356388 0.924093" armature="0.00717012" damping="0.0166433" frictionloss="0.119614"/>
                  <geom name="//unnamed_geom_55" class="visual" mesh="Ankle_Cross_Right"/>
                  <body name="right_foot_link" pos="-0.00250207 -0.00264247 -0.00837233" quat="1 5.36012e-05 1.88397e-05 -0.00045506">
                    <inertial pos="0.00149421 -0.0012147 -0.000869418" quat="-0.0106252 0.623525 -0.00347063 0.781724" mass="0.447174" diaginertia="0.00302414 0.00280228 0.000176954"/>
                    <joint name="Right_Ankle_Roll" pos="0 0 0" axis="-0.999831 -0.0166176 0.00782595" range="-0.586074 0.4335" armature="0.010349" damping="0.0100184" frictionloss="0.0979399"/>
                    <geom name="//unnamed_geom_56" class="visual" mesh="right_foot_link"/>
                    <geom name="right_foot" class="foot" size="0.123086 0.0347627 0.0117137" pos="0.0101596 0 -0.00905727"/>
                    <geom name="//unnamed_geom_58" class="reward_collision_sphere" size="0.0352702"/>
                    <geom name="//unnamed_geom_59" class="reward_collision_sphere" size="0.0264527" pos="0.0101596 0 -0.00905727"/>
                    <geom name="//unnamed_geom_60" class="reward_collision_sphere" size="0.0264527" pos="0.0965165 0.0235862 -0.00905727"/>
                    <geom name="//unnamed_geom_61" class="reward_collision_sphere" size="0.0264527" pos="-0.0711175 0.0235862 -0.00905727"/>
                    <site name="right_foot" class="foot" pos="0.0101596 0 -0.00905727" size="0.00881756"/>
                  </body>
                </body>
              </body>
            </body>
          </body>
        </body>
      </body>
    </body>
  </worldbody>

  <contact>
    <pair class="/" geom1="floor" geom2="left_foot" name="//unnamed_contact_0"/>
    <pair class="/" geom1="floor" geom2="right_foot" name="//unnamed_contact_1"/>
  </contact>

  <actuator>
    <general name="AAHead_yaw" class="/" joint="AAHead_yaw" forcerange="-6.23791 6.23791" gainprm="20.2802" biasprm="0 -20.2802 -0.545907"/>
    <general name="Head_pitch" class="/" joint="Head_pitch" forcerange="-6.71395 6.71395" gainprm="20.2802" biasprm="0 -20.2802 -0.545907"/>
    <general name="Left_Shoulder_Pitch" class="/" joint="Left_Shoulder_Pitch" forcerange="-15.2765 15.2765" gainprm="20.2802" biasprm="0 -20.2802 -0.545907"/>
    <general name="Left_Shoulder_Roll" class="/" joint="Left_Shoulder_Roll" forcerange="-15.5615 15.5615" gainprm="20.2802" biasprm="0 -20.2802 -0.545907"/>
    <general name="Left_Elbow_Pitch" class="/" joint="Left_Elbow_Pitch" forcerange="-13.372 13.372" gainprm="20.2802" biasprm="0 -20.2802 -0.545907"/>
    <general name="Left_Elbow_Yaw" class="/" joint="Left_Elbow_Yaw" forcerange="-14.6294 14.6294" gainprm="20.2802" biasprm="0 -20.2802 -0.545907"/>
    <general name="Right_Shoulder_Pitch" class="/" joint="Right_Shoulder_Pitch" forcerange="-15.2693 15.2693" gainprm="20.2802" biasprm="0 -20.2802 -0.545907"/>
    <general name="Right_Shoulder_Roll" class="/" joint="Right_Shoulder_Roll" forcerange="-15.9548 15.9548" gainprm="20.2802" biasprm="0 -20.2802 -0.545907"/>
    <general name="Right_Elbow_Pitch" class="/" joint="Right_Elbow_Pitch" forcerange="-15.0646 15.0646" gainprm="20.2802" biasprm="0 -20.2802 -0.545907"/>
    <general name="Right_Elbow_Yaw" class="/" joint="Right_Elbow_Yaw" forcerange="-13.1175 13.1175" gainprm="20.2802" biasprm="0 -20.2802 -0.545907"/>
    <general name="Waist" class="/" joint="Waist" forcerange="-26.6158 26.6158" gainprm="20.2802" biasprm="0 -20.2802 -0.545907"/>
    <general name="Left_Hip_Pitch" class="/" joint="Left_Hip_Pitch" forcerange="-50.2529 50.2529" gainprm="20.2802" biasprm="0 -20.2802 -0.545907"/>
    <general name="Left_Hip_Roll" class="/" joint="Left_Hip_Roll" forcerange="-28.6695 28.6695" gainprm="20.2802" biasprm="0 -20.2802 -0.545907"/>
    <general name="Left_Hip_Yaw" class="/" joint="Left_Hip_Yaw" forcerange="-27.794 27.794" gainprm="20.2802" biasprm="0 -20.2802 -0.545907"/>
    <general name="Left_Knee_Pitch" class="/" joint="Left_Knee_Pitch" forcerange="-43.2649 43.2649" gainprm="20.2802" biasprm="0 -20.2802 -0.545907"/>
    <general name="Left_Ankle_Pitch" class="/" joint="Left_Ankle_Pitch" forcerange="-19.1556 19.1556" gainprm="20.2802" biasprm="0 -20.2802 -0.545907"/>
    <general name="Left_Ankle_Roll" class="/" joint="Left_Ankle_Roll" forcerange="-13.6137 13.6137" gainprm="20.2802" biasprm="0 -20.2802 -0.545907"/>
    <general name="Right_Hip_Pitch" class="/" joint="Right_Hip_Pitch" forcerange="-30.6609 30.6609" gainprm="20.2802" biasprm="0 -20.2802 -0.545907"/>
    <general name="Right_Hip_Roll" class="/" joint="Right_Hip_Roll" forcerange="-28.4532 28.4532" gainprm="20.2802" biasprm="0 -20.2802 -0.545907"/>
    <general name="Right_Hip_Yaw" class="/" joint="Right_Hip_Yaw" forcerange="-27.8075 27.8075" gainprm="20.2802" biasprm="0 -20.2802 -0.545907"/>
    <general name="Right_Knee_Pitch" class="/" joint="Right_Knee_Pitch" forcerange="-49.3082 49.3082" gainprm="20.2802" biasprm="0 -20.2802 -0.545907"/>
    <general name="Right_Ankle_Pitch" class="/" joint="Right_Ankle_Pitch" forcerange="-17.6984 17.6984" gainprm="20.2802" biasprm="0 -20.2802 -0.545907"/>
    <general name="Right_Ankle_Roll" class="/" joint="Right_Ankle_Roll" forcerange="-16.2673 16.2673" gainprm="20.2802" biasprm="0 -20.2802 -0.545907"/>
  </actuator>

  <sensor>
    <gyro site="imu" name="imu_angular_velocity"/>
    <velocimeter site="imu" name="imu_linear_velocity"/>
    <framelinvel objtype="site" objname="left_foot" name="left_foot_global_linear_velocity"/>
    <framelinvel objtype="site" objname="right_foot" name="right_foot_global_linear_velocity"/>
  </sensor>

  <keyframe>
    <key name="home" qpos="0 0 0.6385 1 0 0 0 0 0 0 1.4 0 -0.4 0 -1.4 0 0.4 0 -0.4 0 0 0.8 -0.4 0 0.4 0 0 -0.8 0.4 0"/>
  </keyframe>
</mujoco>
