<mujoco model="T1">
  <compiler angle="radian" assetdir="assets" balanceinertia="true" inertiafromgeom="false"/>

  <option timestep="0.005" density="1.2" viscosity="2e-05"/>

  <size nkey="1"/>

  <visual>
    <quality shadowsize="8192"/>
    <map shadowclip="0.5"/>
  </visual>

  <default>
    <default class="/">
      <joint armature="0.01" damping="0.01" frictionloss="0.1"/>
      <geom contype="0" conaffinity="0" group="1" solref="-1000 -80"/>
      <site size="0.01 0.005 0.005" group="5"/>
      <general forcelimited="true" biastype="affine" gainprm="25" biasprm="0 -25 -0.6"/>
      <default class="t1">
        <geom rgba="0.25 0.25 0.25 1"/>
        <default class="visual">
          <geom type="mesh" group="2"/>
        </default>
        <default class="collision">
          <geom group="3"/>
        </default>
        <default class="foot">
          <geom size="0.1115 0.05 0.015" type="box" condim="6" group="4" priority="1" solimp="0.015 1 0.015"/>
        </default>
        <default class="reward_collision_sphere">
          <geom group="5" rgba="1 0 0 1"/>
        </default>
      </default>
    </default>
  </default>

  <asset>
    <texture type="skybox" colorspace="auto" name="//unnamed_texture_0" builtin="gradient" rgb1="0.95 0.95 0.95" rgb2="0.95 0.95 0.95" width="100" height="600"/>
    <texture type="2d" colorspace="auto" name="texplane" builtin="checker" rgb1="0.345 0.575 0.748" rgb2="0.345 0.575 0.748" markrgb="1 1 1" width="512" height="512"/>
    <material name="MatPlane" class="/" texture="texplane" texuniform="true" texrepeat="2 2" specular="0.9"/>
    <mesh name="Trunk" class="/" file="Trunk.stl"/>
    <mesh name="H1" class="/" file="H1.stl"/>
    <mesh name="H2" class="/" file="H2.stl"/>
    <mesh name="AL1" class="/" file="AL1.stl"/>
    <mesh name="AL2" class="/" file="AL2.stl"/>
    <mesh name="AL3" class="/" file="AL3.stl"/>
    <mesh name="left_hand_link" class="/" file="left_hand_link.stl"/>
    <mesh name="AR1" class="/" file="AR1.stl"/>
    <mesh name="AR2" class="/" file="AR2.stl"/>
    <mesh name="AR3" class="/" file="AR3.stl"/>
    <mesh name="right_hand_link" class="/" file="right_hand_link.stl"/>
    <mesh name="Waist" class="/" file="Waist.stl"/>
    <mesh name="Hip_Pitch_Left" class="/" file="Hip_Pitch_Left.stl"/>
    <mesh name="Hip_Roll_Left" class="/" file="Hip_Roll_Left.stl"/>
    <mesh name="Hip_Yaw_Left" class="/" file="Hip_Yaw_Left.stl"/>
    <mesh name="Shank_Left" class="/" file="Shank_Left.stl"/>
    <mesh name="Ankle_Cross_Left" class="/" file="Ankle_Cross_Left.stl"/>
    <mesh name="left_foot_link" class="/" file="left_foot_link.stl"/>
    <mesh name="Hip_Pitch_Right" class="/" file="Hip_Pitch_Right.stl"/>
    <mesh name="Hip_Roll_Right" class="/" file="Hip_Roll_Right.stl"/>
    <mesh name="Hip_Yaw_Right" class="/" file="Hip_Yaw_Right.stl"/>
    <mesh name="Shank_Right" class="/" file="Shank_Right.stl"/>
    <mesh name="Ankle_Cross_Right" class="/" file="Ankle_Cross_Right.stl"/>
    <mesh name="right_foot_link" class="/" file="right_foot_link.stl"/>
  </asset>

  <worldbody>
    <geom name="floor" class="/" size="100 100 0.125" type="plane" group="0" material="MatPlane"/>
    <light name="toplight_shadow" class="/" pos="0 0 5" dir="0.0990148 0.0990148 -0.990148" type="directional" ambient="0.04 0.04 0.04" diffuse="0.55 0.55 0.55" specular="0.12 0.12 0.12"/>
    <light name="toplight_fill" class="/" pos="0 0 5" dir="0.0990148 0.0990148 -0.990148" type="directional" castshadow="false" ambient="0.04 0.04 0.04" diffuse="0.3 0.3 0.3" specular="0.08 0.08 0.08"/>
    <body name="trunk" childclass="t1" pos="0.00100623 6.55248e-05 0.00247892" quat="1 2.5523e-05 -0.000210337 0.000345538">
      <inertial pos="0.046353 0.000685614 0.0811141" quat="0.999897 0.00160311 -0.00619633 -0.0128155" mass="7.22316" diaginertia="0.0432367 0.0511578 0.0159721"/>
      <joint name="//unnamed_joint_0" type="free" armature="0" damping="0" frictionloss="0"/>
      <geom name="//unnamed_geom_1" class="visual" rgba="0.76 0.76 0.76 1" mesh="Trunk"/>
      <geom name="//unnamed_geom_2" class="collision" size="0.064137 0.0855159 0.128274" pos="0.0518471 0 0.0935792" type="box"/>
      <geom name="//unnamed_geom_3" class="reward_collision_sphere" size="0.0983433" pos="0.0518471 0 0.0779826"/>
      <geom name="//unnamed_geom_4" class="reward_collision_sphere" size="0.0128274" pos="0.0518471 0.0783304 0"/>
      <geom name="//unnamed_geom_5" class="reward_collision_sphere" size="0.0128274" pos="0.0518471 -0.0783304 0"/>
      <geom name="//unnamed_geom_6" class="reward_collision_sphere" size="0.0128274" pos="0.0518471 0.0986042 0.140369"/>
      <geom name="//unnamed_geom_7" class="reward_collision_sphere" size="0.0128274" pos="0.0518471 -0.0986042 0.140369"/>
      <site name="imu" pos="0.00422841 -0.00971936 0.0114498" size="0.00855159"/>
      <camera name="track" pos="0 -1.84307 0" quat="0.707107 0.707107 0 0" mode="trackcom"/>
      <camera name="ego_camera" pos="0.105422 0 0.327527" quat="-0.5 -0.5 0.5 0.5"/>
      <body name="H1" pos="0.050542 -0.00317798 0.189165" quat="0.999999 -0.000461425 0.00075781 -0.00101387">
        <inertial pos="-0.00267287 -0.00171706 0.0445322" quat="0.760742 -0.0178317 0.00327798 0.648801" mass="0.273825" diaginertia="0.000118218 0.000148134 4.40026e-05"/>
        <joint name="AAHead_yaw" pos="0 0 0" axis="-4.34692e-05 0.000224104 1" stiffness="0.00600454" range="-1.52845 1.62338" armature="0.00892323" damping="0.0135522" frictionloss="0.0806658"/>
        <geom name="//unnamed_geom_8" class="visual" mesh="H1"/>
        <body name="H2" pos="-0.00104126 -0.00168571 0.048367" quat="1 0.000125493 -0.000211545 -9.52676e-05">
          <inertial pos="0.0071123 0.00244239 0.0795888" quat="0.987707 0.107415 -0.0730755 -0.0869309" mass="0.39473" diaginertia="0.00099449 0.00123986 0.000494103"/>
          <joint name="Head_pitch" pos="0 0 0" axis="0.000845406 -0.999988 0.00489374" stiffness="0.0068529" range="-1.22181 0.403564" armature="0.00763242" damping="0" frictionloss="0.084233"/>
          <geom name="//unnamed_geom_9" class="visual" mesh="H2"/>
          <geom name="//unnamed_geom_10" class="collision" size="0.0684128" pos="0.00864118 0 0.0857809"/>
          <geom name="//unnamed_geom_11" class="reward_collision_sphere" size="0.0769644" pos="0.0172824 0 0.0779826"/>
        </body>
      </body>
      <body name="AL1" pos="0.0489947 0.0980652 0.169168" quat="0.999999 -0.00094605 0.000359156 0.000165179">
        <inertial pos="0.00182724 0.0439192 0.00150582" quat="0.496644 0.495284 -0.515048 0.492711" mass="0.328604" diaginertia="0.000658852 0.00085582 8.68223e-05"/>
        <joint name="Left_Shoulder_Pitch" pos="0 0 0" axis="0.00543386 0.999985 -0.000338576" range="-3.3453 1.16181" armature="0.00866898" damping="0.00282596" frictionloss="0.0839267"/>
        <geom name="//unnamed_geom_12" class="visual" rgba="0.76 0.76 0.76 1" mesh="AL1"/>
        <body name="AL2" pos="0.00274481 0.0456629 0.000907261" quat="1 0.000389349 0.000230031 -0.000163442">
          <inertial pos="0.00620692 0.0354968 -0.00267503" quat="0.488071 0.513014 -0.486868 0.511432" mass="0.102572" diaginertia="0.000199359 0.000241185 5.18056e-05"/>
          <joint name="Left_Shoulder_Roll" pos="0 0 0" axis="-0.999966 0.0063524 -0.0052428" range="-1.63085 1.73229" armature="0.00968424" damping="0.0027365" frictionloss="0.0771821"/>
          <geom name="//unnamed_geom_13" class="visual" mesh="AL2"/>
          <body name="AL3" pos="0.00458145 0.0579893 -0.000193568" quat="1 -2.98112e-05 0.000157329 -5.18143e-05">
            <inertial pos="-0.00127069 0.0775082 -0.000304631" quat="0.704822 0.709292 0.00873902 0.00737293" mass="0.651787" diaginertia="0.00640448 0.00856592 0.000176567"/>
            <joint name="Left_Elbow_Pitch" pos="0 0 0" axis="-0.00292565 -0.999995 0.00150784" stiffness="0.0115269" range="-2.32371 2.26192" armature="0.00820334" damping="0.00871308" frictionloss="0.0842945"/>
            <geom name="//unnamed_geom_14" class="visual" mesh="AL3"/>
            <geom name="//unnamed_geom_15" class="collision" size="0.0256548 0.064137" pos="0 0.0460767 0" quat="0.707105 0.707108 0 0" type="cylinder"/>
            <geom name="//unnamed_geom_16" class="reward_collision_sphere" size="0.0307857"/>
            <body name="left_hand_link" pos="0.00108347 0.136755 0.00381178" quat="1 -0.000441748 -0.000589674 0.000231773">
              <inertial pos="0.000495701 0.0987813 -0.00123572" quat="0.705646 0.708512 0.00293674 0.00811481" mass="0.204643" diaginertia="0.00403901 0.00532393 5.95872e-05"/>
              <joint name="Left_Elbow_Yaw" pos="0 0 0" axis="0.00633586 -0.0107371 0.999922" range="-2.44824 0.04478" armature="0.00864192" damping="0" frictionloss="0.0891454"/>
              <geom name="//unnamed_geom_17" class="visual" mesh="left_hand_link"/>
              <geom name="//unnamed_geom_18" class="collision" size="0.0256548 0.0748265" pos="0 0.119799 0" quat="0.707105 0.707108 0 0" type="cylinder"/>
              <geom name="//unnamed_geom_19" class="reward_collision_sphere" size="0.042758"/>
              <geom name="//unnamed_geom_20" class="reward_collision_sphere" size="0.0299306" pos="0 0.101369 0"/>
              <geom name="//unnamed_geom_21" class="reward_collision_sphere" size="0.0299306" pos="0 0.19813 0"/>
            </body>
          </body>
        </body>
      </body>
      <body name="AR1" pos="0.0475446 -0.0945543 0.17039" quat="1 2.01749e-05 0.000418923 -7.66516e-05">
        <inertial pos="-0.00208649 -0.0422072 -0.000617191" quat="0.500217 0.498409 -0.506201 0.495109" mass="0.346127" diaginertia="0.000658325 0.000860562 8.61875e-05"/>
        <joint name="Right_Shoulder_Pitch" pos="0 0 0" axis="-0.0092211 -0.999897 0.010998" stiffness="0.00698368" range="-1.19952 3.31535" armature="0.00889938" damping="0.0180823" frictionloss="0.0834224"/>
        <geom name="//unnamed_geom_22" class="visual" rgba="0.76 0.76 0.76 1" mesh="AR1"/>
        <body name="AR2" pos="-0.00156833 -0.0403239 -0.000452458" quat="0.999999 -0.000446774 0.000935271 0.000989171">
          <inertial pos="0.000274652 -0.0326651 -0.00259472" quat="0.509109 0.486655 -0.522982 0.480067" mass="0.102256" diaginertia="0.00019398 0.000233704 5.15787e-05"/>
          <joint name="Right_Shoulder_Roll" pos="0 0 0" axis="-0.999966 0.00374272 0.00731986" stiffness="0.0105318" range="-1.6863 1.54116" armature="0.00833383" damping="0.0132863" frictionloss="0.0781795"/>
          <geom name="//unnamed_geom_23" class="visual" mesh="AR2"/>
          <body name="AR3" pos="-0.00277175 -0.0549341 0.00185797" quat="1 -0.000374224 0.000193293 -8.31998e-05">
            <inertial pos="-0.000427366 -0.0797215 0.00121612" quat="0.7069 0.707311 -0.000564323 -0.00186729" mass="0.620374" diaginertia="0.00602863 0.00886523 0.000178517"/>
            <joint name="Right_Elbow_Pitch" pos="0 0 0" axis="-0.00225287 0.999996 0.00165477" stiffness="0.00369583" range="-2.27422 2.2663" armature="0.00860724" damping="0.0194205" frictionloss="0.0912617"/>
            <geom name="//unnamed_geom_24" class="visual" mesh="AR3"/>
            <geom name="//unnamed_geom_25" class="collision" size="0.0256548 0.064137" pos="0 -0.0460767 0" quat="0.707105 0.707108 0 0" type="cylinder"/>
            <geom name="//unnamed_geom_26" class="reward_collision_sphere" size="0.0307857"/>
            <body name="right_hand_link" pos="-0.0019852 -0.134488 0.00108728" quat="0.999999 -0.000237031 -0.000992821 0.00109091">
              <inertial pos="0.000252231 -0.100904 0.00216232" quat="0.702877 0.711272 -0.0028132 0.00699635" mass="0.201545" diaginertia="0.00374052 0.00530842 6.1049e-05"/>
              <joint name="Right_Elbow_Yaw" pos="0 0 0" axis="-0.000493091 0.000664476 1" range="-0.0490173 2.44636" armature="0.00900708" damping="0.00732819" frictionloss="0.0842786"/>
              <geom name="//unnamed_geom_27" class="visual" mesh="right_hand_link"/>
              <geom name="//unnamed_geom_28" class="collision" size="0.0256548 0.0748265" pos="0 -0.119799 0" quat="0.707105 0.707108 0 0" type="cylinder"/>
              <geom name="//unnamed_geom_29" class="reward_collision_sphere" size="0.042758"/>
              <geom name="//unnamed_geom_30" class="reward_collision_sphere" size="0.0299306" pos="0 -0.101369 0"/>
              <geom name="//unnamed_geom_31" class="reward_collision_sphere" size="0.0299306" pos="0 -0.19813 0"/>
            </body>
          </body>
        </body>
      </body>
      <body name="Waist" pos="0.0550451 0.00173749 -0.0923861" quat="1 -0.000316377 0.000107074 -0.000162898">
        <inertial pos="0.00295118 0.000208333 0.00694572" quat="0.985402 -0.0016109 -0.170184 -0.00426854" mass="1.61958" diaginertia="0.0025082 0.00335272 0.00132313"/>
        <joint name="Waist" pos="0 0 0" axis="0.00283876 -0.00437352 0.999986" stiffness="0.00300511" range="-1.55459 1.61527" armature="0.00772377" damping="0.0184019" frictionloss="0.0892064"/>
        <geom name="//unnamed_geom_32" class="visual" mesh="Waist"/>
        <body name="Hip_Pitch_Left" pos="-0.000613889 0.0992733 -0.000456472" quat="1 0.000472839 0.000273264 0.000108582">
          <inertial pos="-0.00137857 -0.00584619 -0.0147718" quat="0.975223 0.220723 0.0145475 0.00306986" mass="0.613373" diaginertia="0.000835799 0.000941144 0.000350165"/>
          <joint name="Left_Hip_Pitch" pos="0 0 0" axis="-0.00700302 0.999955 -0.00636753" stiffness="0.0108904" range="-1.81018 1.62942" armature="0.0084327" damping="0.0250772" frictionloss="0.0857433"/>
          <geom name="//unnamed_geom_33" class="visual" rgba="0.76 0.76 0.76 1" mesh="Hip_Pitch_Left"/>
          <body name="Hip_Roll_Left" pos="0.00282847 -0.00155772 -0.0187684" quat="1 -0.000303211 0.00045677 0.000581172">
            <inertial pos="-0.000124504 8.53485e-07 -0.0435564" quat="0.708444 -0.00499026 -0.00619975 0.705722" mass="0.239012" diaginertia="0.000844024 0.000976875 0.000143444"/>
            <joint name="Left_Hip_Roll" pos="0 0 0" axis="-0.999979 0.00545823 -0.00346801" range="-1.54378 0.175656" armature="0.00864414" damping="0.0141958" frictionloss="0.0960839"/>
            <geom name="//unnamed_geom_34" class="visual" mesh="Hip_Roll_Left"/>
            <geom name="//unnamed_geom_35" class="reward_collision_sphere" size="0.0470338"/>
            <body name="Hip_Yaw_Left" pos="-0.000834914 0.00122422 -0.0649101" quat="0.999999 -0.000782644 4.42625e-06 -0.00108727">
              <inertial pos="-0.0073458 0.000140369 -0.0683815" quat="0.69918 -0.0312149 -0.0296293 0.713649" mass="1.30862" diaginertia="0.0123149 0.0166422 0.000772414"/>
              <joint name="Left_Hip_Yaw" pos="0 0 0" axis="-0.00853753 -0.000628755 -0.999963" stiffness="0.00171061" range="-1.01317 0.998416" armature="0.00859704" damping="0" frictionloss="0.0859763"/>
              <geom name="//unnamed_geom_36" class="visual" mesh="Hip_Yaw_Left"/>
              <geom name="//unnamed_geom_37" class="collision" size="0.042758 0.0684128" type="cylinder"/>
              <body name="Shank_Left" pos="-0.012126 -0.00176822 -0.107134" quat="0.999999 0.00061988 -0.000353034 0.00105421">
                <inertial pos="-0.00441363 0.0021413 -0.0979279" quat="0.998024 -0.00136091 -0.0305104 0.0549038" mass="1.1154" diaginertia="0.016197 0.0238689 0.000536978"/>
                <joint name="Left_Knee_Pitch" pos="0 0 0" axis="-0.0023351 0.999987 -0.00463862" stiffness="0.00266039" range="0.0386414 2.33839" armature="0.00917857" damping="0.0148605" frictionloss="0.0947133"/>
                <geom name="//unnamed_geom_38" class="visual" mesh="Shank_Left"/>
                <geom name="//unnamed_geom_39" class="collision" size="0.042758 0.064137" pos="0 0 -0.0935792" type="cylinder"/>
                <geom name="//unnamed_geom_40" class="reward_collision_sphere" size="0.0555854"/>
                <body name="Ankle_Cross_Left" pos="-0.00208067 -0.00175011 -0.218638" quat="0.999999 0.000406996 0.00124288 -0.000423002">
                  <inertial pos="-0.00258056 0.00259905 -0.00699956" quat="0.447157 0.543835 0.556258 0.441442" mass="0.0465487" diaginertia="1.46501e-05 1.68286e-05 3.22629e-06"/>
                  <joint name="Left_Ankle_Pitch" pos="0 0 0" axis="-0.0145876 0.999891 -0.00236286" range="-0.879397 0.406075" armature="0.00731391" damping="0.0228244" frictionloss="0.0940038"/>
                  <geom name="//unnamed_geom_41" class="visual" mesh="Ankle_Cross_Left"/>
                  <body name="left_foot_link" pos="0.00189327 -0.00126128 -0.0112576" quat="1 0.000655013 -0.000669849 0.000188208">
                    <inertial pos="-0.00182636 -0.00153751 -0.00652277" quat="-0.00355002 0.621504 -0.000632818 0.783403" mass="0.413018" diaginertia="0.00134122 0.00157721 0.000641584"/>
                    <joint name="Left_Ankle_Roll" pos="0 0 0" axis="-0.99993 0.0116974 0.00152214" range="-0.495613 0.396186" armature="0.00857361" damping="0" frictionloss="0.0824065"/>
                    <geom name="//unnamed_geom_42" class="visual" mesh="left_foot_link"/>
                    <geom name="left_foot" class="foot" size="0.0989756 0.0378719 0.0143953" pos="0.00864118 0 -0.0116974"/>
                    <geom name="//unnamed_geom_44" class="reward_collision_sphere" size="0.0444683" pos="0.00864118 0 -0.0116974"/>
                    <geom name="//unnamed_geom_45" class="reward_collision_sphere" size="0.0256548" pos="0.0820912 -0.0211953 -0.0116974"/>
                    <geom name="//unnamed_geom_46" class="reward_collision_sphere" size="0.0256548" pos="-0.0604882 -0.0211953 -0.0116974"/>
                    <site name="left_foot" class="foot" pos="0.00864118 0 -0.0116974" size="0.00855159"/>
                  </body>
                </body>
              </body>
            </body>
          </body>
        </body>
        <body name="Hip_Pitch_Right" pos="-0.00374993 -0.0990128 0.00030536" quat="0.999999 -0.00057662 0.00129233 -0.000613729">
          <inertial pos="3.48576e-05 0.00869713 -0.0125136" quat="0.972657 -0.231835 0.0126654 0.00555351" mass="0.64897" diaginertia="0.000883274 0.00098585 0.000377318"/>
          <joint name="Right_Hip_Pitch" pos="0 0 0" axis="-0.00670528 -0.999923 -0.0103986" range="-1.57077 1.78534" armature="0.00942494" damping="0.00420717" frictionloss="0.097519"/>
          <geom name="//unnamed_geom_47" class="visual" rgba="0.76 0.76 0.76 1" mesh="Hip_Pitch_Right"/>
          <body name="Hip_Roll_Right" pos="-0.000338947 -0.00237564 -0.0127378" quat="1 -6.04287e-05 0.000244307 -0.000169595">
            <inertial pos="0.00214324 0.00117529 -0.0445228" quat="0.70401 -0.00777174 -0.0173401 0.709936" mass="0.233115" diaginertia="0.000783967 0.000987622 0.000143743"/>
            <joint name="Right_Hip_Roll" pos="0 0 0" axis="-0.999999 -0.00139949 0.000319231" stiffness="0.00339581" range="-0.202925 1.6227" armature="0.0080402" damping="0.0113501" frictionloss="0.0862514"/>
            <geom name="//unnamed_geom_48" class="visual" mesh="Hip_Roll_Right"/>
            <geom name="//unnamed_geom_49" class="reward_collision_sphere" size="0.0470338"/>
            <body name="Hip_Yaw_Right" pos="-0.000300198 -0.00235517 -0.0644296" quat="1 -0.000256568 0.000847656 0.00034109">
              <inertial pos="-0.00275726 -0.000597339 -0.068219" quat="0.713364 -0.0176468 -0.0339543 0.699748" mass="1.42567" diaginertia="0.0129789 0.0173445 0.0007914"/>
              <joint name="Right_Hip_Yaw" pos="0 0 0" axis="0.00636596 0.0145693 -0.999874" stiffness="0.00478225" range="-0.994911 0.992474" armature="0.00847745" damping="0.00345894" frictionloss="0.078242"/>
              <geom name="//unnamed_geom_50" class="visual" mesh="Hip_Yaw_Right"/>
              <geom name="//unnamed_geom_51" class="collision" size="0.042758 0.0684128" type="cylinder"/>
              <body name="Shank_Right" pos="-0.0138031 0.00257691 -0.106579" quat="1 -0.000124445 0.000604214 -0.000558851">
                <inertial pos="-0.00307277 0.00239817 -0.0957992" quat="0.999184 -0.00256234 -0.0247614 -0.0318174" mass="1.13463" diaginertia="0.016834 0.0227228 0.000550666"/>
                <joint name="Right_Knee_Pitch" pos="0 0 0" axis="-0.000193107 -0.999963 -0.00856386" stiffness="0.00993622" range="-2.36675 -0.0179684" armature="0.00808277" damping="0.022583" frictionloss="0.0961119"/>
                <geom name="//unnamed_geom_52" class="visual" mesh="Shank_Right"/>
                <geom name="//unnamed_geom_53" class="collision" size="0.042758 0.064137" pos="0 0 -0.0935792" type="cylinder"/>
                <geom name="//unnamed_geom_54" class="reward_collision_sphere" size="0.0555854"/>
                <body name="Ankle_Cross_Right" pos="-0.00262529 -0.000802932 -0.22066" quat="0.999999 0.000473587 0.000673409 -0.00060985">
                  <inertial pos="-0.00343791 0.000825088 -0.00711365" quat="0.448675 0.547955 0.556533 0.434404" mass="0.0430431" diaginertia="1.34963e-05 1.64275e-05 3.18273e-06"/>
                  <joint name="Right_Ankle_Pitch" pos="0 0 0" axis="0.00286907 -0.999995 0.00145568" stiffness="0.00708421" range="-0.358613 0.815765" armature="0.00959761" damping="0" frictionloss="0.0823525"/>
                  <geom name="//unnamed_geom_55" class="visual" mesh="Ankle_Cross_Right"/>
                  <body name="right_foot_link" pos="0.00198374 0.000606185 -0.00654772" quat="0.999999 0.000441388 -0.000810911 0.00105394">
                    <inertial pos="0.00102852 0.00125902 -0.00918372" quat="0.00153794 0.62066 -0.000221721 0.784078" mass="0.452841" diaginertia="0.00129018 0.00161604 0.000627771"/>
                    <joint name="Right_Ankle_Roll" pos="0 0 0" axis="-0.999922 -0.00666317 0.0106094" range="-0.425481 0.492773" armature="0.00731441" damping="0.00514552" frictionloss="0.0815399"/>
                    <geom name="//unnamed_geom_56" class="visual" mesh="right_foot_link"/>
                    <geom name="right_foot" class="foot" size="0.100858 0.0429342 0.0131019" pos="0.00864118 0 -0.0116974"/>
                    <geom name="//unnamed_geom_58" class="reward_collision_sphere" size="0.0342064"/>
                    <geom name="//unnamed_geom_59" class="reward_collision_sphere" size="0.0256548" pos="0.00864118 0 -0.0116974"/>
                    <geom name="//unnamed_geom_60" class="reward_collision_sphere" size="0.0256548" pos="0.0820912 0.0211953 -0.0116974"/>
                    <geom name="//unnamed_geom_61" class="reward_collision_sphere" size="0.0256548" pos="-0.0604882 0.0211953 -0.0116974"/>
                    <site name="right_foot" class="foot" pos="0.00864118 0 -0.0116974" size="0.00855159"/>
                  </body>
                </body>
              </body>
            </body>
          </body>
        </body>
      </body>
    </body>
  </worldbody>

  <contact>
    <pair class="/" geom1="floor" geom2="left_foot" name="//unnamed_contact_0"/>
    <pair class="/" geom1="floor" geom2="right_foot" name="//unnamed_contact_1"/>
  </contact>

  <actuator>
    <general name="AAHead_yaw" class="/" joint="AAHead_yaw" forcerange="-5.3973 5.3973" gainprm="23.1344" biasprm="0 -23.1344 -0.542731"/>
    <general name="Head_pitch" class="/" joint="Head_pitch" forcerange="-5.85138 5.85138" gainprm="23.1344" biasprm="0 -23.1344 -0.542731"/>
    <general name="Left_Shoulder_Pitch" class="/" joint="Left_Shoulder_Pitch" forcerange="-15.5443 15.5443" gainprm="23.1344" biasprm="0 -23.1344 -0.542731"/>
    <general name="Left_Shoulder_Roll" class="/" joint="Left_Shoulder_Roll" forcerange="-15.2424 15.2424" gainprm="23.1344" biasprm="0 -23.1344 -0.542731"/>
    <general name="Left_Elbow_Pitch" class="/" joint="Left_Elbow_Pitch" forcerange="-16.7501 16.7501" gainprm="23.1344" biasprm="0 -23.1344 -0.542731"/>
    <general name="Left_Elbow_Yaw" class="/" joint="Left_Elbow_Yaw" forcerange="-15.4987 15.4987" gainprm="23.1344" biasprm="0 -23.1344 -0.542731"/>
    <general name="Right_Shoulder_Pitch" class="/" joint="Right_Shoulder_Pitch" forcerange="-15.6136 15.6136" gainprm="23.1344" biasprm="0 -23.1344 -0.542731"/>
    <general name="Right_Shoulder_Roll" class="/" joint="Right_Shoulder_Roll" forcerange="-15.3633 15.3633" gainprm="23.1344" biasprm="0 -23.1344 -0.542731"/>
    <general name="Right_Elbow_Pitch" class="/" joint="Right_Elbow_Pitch" forcerange="-14.6654 14.6654" gainprm="23.1344" biasprm="0 -23.1344 -0.542731"/>
    <general name="Right_Elbow_Yaw" class="/" joint="Right_Elbow_Yaw" forcerange="-16.5647 16.5647" gainprm="23.1344" biasprm="0 -23.1344 -0.542731"/>
    <general name="Waist" class="/" joint="Waist" forcerange="-28.267 28.267" gainprm="23.1344" biasprm="0 -23.1344 -0.542731"/>
    <general name="Left_Hip_Pitch" class="/" joint="Left_Hip_Pitch" forcerange="-37.385 37.385" gainprm="23.1344" biasprm="0 -23.1344 -0.542731"/>
    <general name="Left_Hip_Roll" class="/" joint="Left_Hip_Roll" forcerange="-26.0946 26.0946" gainprm="23.1344" biasprm="0 -23.1344 -0.542731"/>
    <general name="Left_Hip_Yaw" class="/" joint="Left_Hip_Yaw" forcerange="-27.4117 27.4117" gainprm="23.1344" biasprm="0 -23.1344 -0.542731"/>
    <general name="Left_Knee_Pitch" class="/" joint="Left_Knee_Pitch" forcerange="-54.893 54.893" gainprm="23.1344" biasprm="0 -23.1344 -0.542731"/>
    <general name="Left_Ankle_Pitch" class="/" joint="Left_Ankle_Pitch" forcerange="-17.0796 17.0796" gainprm="23.1344" biasprm="0 -23.1344 -0.542731"/>
    <general name="Left_Ankle_Roll" class="/" joint="Left_Ankle_Roll" forcerange="-12.5366 12.5366" gainprm="23.1344" biasprm="0 -23.1344 -0.542731"/>
    <general name="Right_Hip_Pitch" class="/" joint="Right_Hip_Pitch" forcerange="-40.5012 40.5012" gainprm="23.1344" biasprm="0 -23.1344 -0.542731"/>
    <general name="Right_Hip_Roll" class="/" joint="Right_Hip_Roll" forcerange="-26.2773 26.2773" gainprm="23.1344" biasprm="0 -23.1344 -0.542731"/>
    <general name="Right_Hip_Yaw" class="/" joint="Right_Hip_Yaw" forcerange="-27.3398 27.3398" gainprm="23.1344" biasprm="0 -23.1344 -0.542731"/>
    <general name="Right_Knee_Pitch" class="/" joint="Right_Knee_Pitch" forcerange="-56.9991 56.9991" gainprm="23.1344" biasprm="0 -23.1344 -0.542731"/>
    <general name="Right_Ankle_Pitch" class="/" joint="Right_Ankle_Pitch" forcerange="-15.536 15.536" gainprm="23.1344" biasprm="0 -23.1344 -0.542731"/>
    <general name="Right_Ankle_Roll" class="/" joint="Right_Ankle_Roll" forcerange="-12.1946 12.1946" gainprm="23.1344" biasprm="0 -23.1344 -0.542731"/>
  </actuator>

  <sensor>
    <gyro site="imu" name="imu_angular_velocity"/>
    <velocimeter site="imu" name="imu_linear_velocity"/>
    <framelinvel objtype="site" objname="left_foot" name="left_foot_global_linear_velocity"/>
    <framelinvel objtype="site" objname="right_foot" name="right_foot_global_linear_velocity"/>
  </sensor>

  <keyframe>
    <key name="home" qpos="0 0 0.6385 1 0 0 0 0 0 0 1.4 0 -0.4 0 -1.4 0 0.4 0 -0.4 0 0 0.8 -0.4 0 0.4 0 0 -0.8 0.4 0"/>
  </keyframe>
</mujoco>
