<mujoco model="T1">
  <compiler angle="radian" assetdir="assets" balanceinertia="true" inertiafromgeom="false"/>

  <option timestep="0.005" density="1.2" viscosity="2e-05"/>

  <size nkey="1"/>

  <visual>
    <quality shadowsize="8192"/>
    <map shadowclip="0.5"/>
  </visual>

  <default>
    <default class="/">
      <joint armature="0.01" damping="0.01" frictionloss="0.1"/>
      <geom contype="0" conaffinity="0" group="1" solref="-1000 -80"/>
      <site size="0.01 0.005 0.005" group="5"/>
      <general forcelimited="true" biastype="affine" gainprm="25" biasprm="0 -25 -0.6"/>
      <default class="t1">
        <geom rgba="0.25 0.25 0.25 1"/>
        <default class="visual">
          <geom type="mesh" group="2"/>
        </default>
        <default class="collision">
          <geom group="3"/>
        </default>
        <default class="foot">
          <geom size="0.1115 0.05 0.015" type="box" condim="6" group="4" priority="1" solimp="0.015 1 0.015"/>
        </default>
        <default class="reward_collision_sphere">
          <geom group="5" rgba="1 0 0 1"/>
        </default>
      </default>
    </default>
  </default>

  <asset>
    <texture type="skybox" colorspace="auto" name="//unnamed_texture_0" builtin="gradient" rgb1="0.95 0.95 0.95" rgb2="0.95 0.95 0.95" width="100" height="600"/>
    <texture type="2d" colorspace="auto" name="texplane" builtin="checker" rgb1="0.345 0.575 0.748" rgb2="0.345 0.575 0.748" markrgb="1 1 1" width="512" height="512"/>
    <material name="MatPlane" class="/" texture="texplane" texuniform="true" texrepeat="2 2" specular="0.9"/>
    <mesh name="Trunk" class="/" file="Trunk.stl"/>
    <mesh name="H1" class="/" file="H1.stl"/>
    <mesh name="H2" class="/" file="H2.stl"/>
    <mesh name="AL1" class="/" file="AL1.stl"/>
    <mesh name="AL2" class="/" file="AL2.stl"/>
    <mesh name="AL3" class="/" file="AL3.stl"/>
    <mesh name="left_hand_link" class="/" file="left_hand_link.stl"/>
    <mesh name="AR1" class="/" file="AR1.stl"/>
    <mesh name="AR2" class="/" file="AR2.stl"/>
    <mesh name="AR3" class="/" file="AR3.stl"/>
    <mesh name="right_hand_link" class="/" file="right_hand_link.stl"/>
    <mesh name="Waist" class="/" file="Waist.stl"/>
    <mesh name="Hip_Pitch_Left" class="/" file="Hip_Pitch_Left.stl"/>
    <mesh name="Hip_Roll_Left" class="/" file="Hip_Roll_Left.stl"/>
    <mesh name="Hip_Yaw_Left" class="/" file="Hip_Yaw_Left.stl"/>
    <mesh name="Shank_Left" class="/" file="Shank_Left.stl"/>
    <mesh name="Ankle_Cross_Left" class="/" file="Ankle_Cross_Left.stl"/>
    <mesh name="left_foot_link" class="/" file="left_foot_link.stl"/>
    <mesh name="Hip_Pitch_Right" class="/" file="Hip_Pitch_Right.stl"/>
    <mesh name="Hip_Roll_Right" class="/" file="Hip_Roll_Right.stl"/>
    <mesh name="Hip_Yaw_Right" class="/" file="Hip_Yaw_Right.stl"/>
    <mesh name="Shank_Right" class="/" file="Shank_Right.stl"/>
    <mesh name="Ankle_Cross_Right" class="/" file="Ankle_Cross_Right.stl"/>
    <mesh name="right_foot_link" class="/" file="right_foot_link.stl"/>
  </asset>

  <worldbody>
    <geom name="floor" class="/" size="100 100 0.125" type="plane" group="0" material="MatPlane"/>
    <light name="toplight_shadow" class="/" pos="0 0 5" dir="0.0990148 0.0990148 -0.990148" type="directional" ambient="0.04 0.04 0.04" diffuse="0.55 0.55 0.55" specular="0.12 0.12 0.12"/>
    <light name="toplight_fill" class="/" pos="0 0 5" dir="0.0990148 0.0990148 -0.990148" type="directional" castshadow="false" ambient="0.04 0.04 0.04" diffuse="0.3 0.3 0.3" specular="0.08 0.08 0.08"/>
    <body name="trunk" childclass="t1" pos="0.000740164 2.45257e-05 0.00130268" quat="1 -0.000103342 -2.73071e-05 6.30806e-05">
      <inertial pos="0.049409 -0.000891636 0.07389" quat="0.999795 0.00530117 -0.0166866 -0.0101345" mass="7.61887" diaginertia="0.0588215 0.0614335 0.0109884"/>
      <joint name="//unnamed_joint_0" type="free" armature="0" damping="0" frictionloss="0"/>
      <geom name="//unnamed_geom_1" class="visual" rgba="0.76 0.76 0.76 1" mesh="Trunk"/>
      <geom name="//unnamed_geom_2" class="collision" size="0.0646075 0.0861433 0.129215" pos="0.054881 0 0.086178" type="box"/>
      <geom name="//unnamed_geom_3" class="reward_collision_sphere" size="0.0990648" pos="0.054881 0 0.071815"/>
      <geom name="//unnamed_geom_4" class="reward_collision_sphere" size="0.0129215" pos="0.054881 0.0808745 0"/>
      <geom name="//unnamed_geom_5" class="reward_collision_sphere" size="0.0129215" pos="0.054881 -0.0808745 0"/>
      <geom name="//unnamed_geom_6" class="reward_collision_sphere" size="0.0129215" pos="0.054881 0.101807 0.129267"/>
      <geom name="//unnamed_geom_7" class="reward_collision_sphere" size="0.0129215" pos="0.054881 -0.101807 0.129267"/>
      <site name="imu" pos="-0.00559917 -0.0020224 0.0139202" size="0.00861433"/>
      <camera name="track" pos="0 -1.90293 0" quat="0.707107 0.707107 0 0" mode="trackcom"/>
      <camera name="ego_camera" pos="0.111591 0 0.301623" quat="-0.5 -0.5 0.5 0.5"/>
      <body name="H1" pos="0.0532644 -0.00279984 0.17486" quat="0.999999 0.00128333 -0.000117165 4.97737e-05">
        <inertial pos="-0.00148719 -0.00285018 0.0397262" quat="0.763608 -0.0232237 0.00827852 0.64521" mass="0.277383" diaginertia="0.000152786 0.000173705 2.84791e-05"/>
        <joint name="AAHead_yaw" pos="0 0 0" axis="0.00282915 0.000667322 0.999996" range="-1.51946 1.61424" armature="0.00949395" damping="0.019018" frictionloss="0.0764706"/>
        <geom name="//unnamed_geom_8" class="visual" mesh="H1"/>
        <body name="H2" pos="-0.00143236 1.60175e-05 0.0431288" quat="1 -0.000108402 1.78012e-05 0.000517665">
          <inertial pos="0.00563538 0.000756022 0.0729355" quat="0.988577 0.114089 -0.070613 -0.068652" mass="0.393642" diaginertia="0.00133218 0.00143694 0.00032206"/>
          <joint name="Head_pitch" pos="0 0 0" axis="-0.00735551 -0.999943 -0.00778137" stiffness="0.0063875" range="-1.21138 0.390383" armature="0.00828739" damping="0" frictionloss="0.0872784"/>
          <geom name="//unnamed_geom_9" class="visual" mesh="H2"/>
          <geom name="//unnamed_geom_10" class="collision" size="0.0689146" pos="0.00914684 0 0.0789965"/>
          <geom name="//unnamed_geom_11" class="reward_collision_sphere" size="0.077529" pos="0.0182937 0 0.071815"/>
        </body>
      </body>
      <body name="AL1" pos="0.0519101 0.101228 0.156864" quat="0.999999 -0.000887517 -0.00026418 -0.000640387">
        <inertial pos="0.00229717 0.0455193 -0.000166239" quat="0.503363 0.499913 -0.51135 0.485009" mass="0.327405" diaginertia="0.000853062 0.000996698 5.72431e-05"/>
        <joint name="Left_Shoulder_Pitch" pos="0 0 0" axis="-0.0019335 0.999934 0.0113464" stiffness="0.00576134" range="-3.31352 1.17414" armature="0.00925031" damping="0.0123923" frictionloss="0.084424"/>
        <geom name="//unnamed_geom_12" class="visual" rgba="0.76 0.76 0.76 1" mesh="AL1"/>
        <body name="AL2" pos="0.00323686 0.0452167 0.00220618" quat="1 -0.000328938 0.000418099 -4.82171e-05">
          <inertial pos="0.00694146 0.0373248 -0.00157356" quat="0.487552 0.509104 -0.491677 0.511234" mass="0.0999784" diaginertia="0.000256965 0.000273088 3.30346e-05"/>
          <joint name="Left_Shoulder_Roll" pos="0 0 0" axis="-0.99992 -0.00961578 -0.00827384" range="-1.6208 1.71258" armature="0.00979557" damping="0.0116453" frictionloss="0.0745871"/>
          <geom name="//unnamed_geom_13" class="visual" mesh="AL2"/>
          <body name="AL3" pos="0.00400432 0.0580488 0.00107889" quat="1 0.000433144 -0.000712635 6.81175e-06">
            <inertial pos="-1.78509e-05 0.0807227 -0.000217184" quat="0.706228 0.707966 -0.00365794 0.00359335" mass="0.649288" diaginertia="0.00827404 0.00986248 0.000114316"/>
            <joint name="Left_Elbow_Pitch" pos="0 0 0" axis="-0.00393227 -0.999977 -0.00559188" stiffness="0.0189462" range="-2.32811 2.24544" armature="0.0081701" damping="0.0109422" frictionloss="0.0820409"/>
            <geom name="//unnamed_geom_14" class="visual" mesh="AL3"/>
            <geom name="//unnamed_geom_15" class="collision" size="0.025843 0.0646075" pos="0 0.0475733 0" quat="0.707105 0.707108 0 0" type="cylinder"/>
            <geom name="//unnamed_geom_16" class="reward_collision_sphere" size="0.0310116"/>
            <body name="left_hand_link" pos="0.00085609 0.139162 0.00302792" quat="1 -5.52422e-05 -8.74963e-05 -2.40089e-05">
              <inertial pos="0.000142972 0.101757 0.000366136" quat="0.706837 0.707376 0.000137306 -0.000544572" mass="0.213911" diaginertia="0.00550741 0.00638529 4.04244e-05"/>
              <joint name="Left_Elbow_Yaw" pos="0 0 0" axis="-0.00346431 0.00346592 0.999988" range="-2.44002 0.0212244" armature="0.00850179" damping="0.00163482" frictionloss="0.0813479"/>
              <geom name="//unnamed_geom_17" class="visual" mesh="left_hand_link"/>
              <geom name="//unnamed_geom_18" class="collision" size="0.025843 0.0753754" pos="0 0.12369 0" quat="0.707105 0.707108 0 0" type="cylinder"/>
              <geom name="//unnamed_geom_19" class="reward_collision_sphere" size="0.0430716"/>
              <geom name="//unnamed_geom_20" class="reward_collision_sphere" size="0.0301502" pos="0 0.104661 0"/>
              <geom name="//unnamed_geom_21" class="reward_collision_sphere" size="0.0301502" pos="0 0.204565 0"/>
            </body>
          </body>
        </body>
      </body>
      <body name="AR1" pos="0.0518937 -0.0988628 0.157983" quat="0.999999 0.000385375 0.000922841 -0.000564626">
        <inertial pos="-0.00194831 -0.0446056 0.00089469" quat="0.503055 0.494423 -0.505432 0.497011" mass="0.350159" diaginertia="0.000864903 0.000982297 5.65299e-05"/>
        <joint name="Right_Shoulder_Pitch" pos="0 0 0" axis="-0.012953 -0.999889 0.00731359" range="-1.23443 3.28731" armature="0.00900517" damping="0.0114164" frictionloss="0.0848461"/>
        <geom name="//unnamed_geom_22" class="visual" rgba="0.76 0.76 0.76 1" mesh="AR1"/>
        <body name="AR2" pos="0.000163166 -0.0430687 -0.000854893" quat="0.999999 -0.000557958 0.000673447 0.00111559">
          <inertial pos="0.000824488 -0.0332022 -0.00184301" quat="0.515857 0.491956 -0.500719 0.491072" mass="0.106957" diaginertia="0.000265082 0.000283249 3.39265e-05"/>
          <joint name="Right_Shoulder_Roll" pos="0 0 0" axis="-0.999999 0.00106352 7.82816e-05" stiffness="0.00774443" range="-1.68728 1.57592" armature="0.00818521" damping="0.0188247" frictionloss="0.0858649"/>
          <geom name="//unnamed_geom_23" class="visual" mesh="AR2"/>
          <body name="AR3" pos="-0.00273609 -0.0587682 0.000413079" quat="1 -4.46662e-05 -9.80073e-05 -1.2419e-05">
            <inertial pos="-0.000358921 -0.0834691 -6.88372e-05" quat="0.703349 0.710827 -0.000569244 -0.00495666" mass="0.631073" diaginertia="0.0079772 0.01028 0.000115884"/>
            <joint name="Right_Elbow_Pitch" pos="0 0 0" axis="0.00104837 0.999996 0.00269114" range="-2.27053 2.27717" armature="0.00807753" damping="0.0177127" frictionloss="0.0841809"/>
            <geom name="//unnamed_geom_24" class="visual" mesh="AR3"/>
            <geom name="//unnamed_geom_25" class="collision" size="0.025843 0.0646075" pos="0 -0.0475733 0" quat="0.707105 0.707108 0 0" type="cylinder"/>
            <geom name="//unnamed_geom_26" class="reward_collision_sphere" size="0.0310116"/>
            <body name="right_hand_link" pos="-0.000443345 -0.140539 0.00229941" quat="0.999999 -0.000519597 0.000122248 0.0013401">
              <inertial pos="0.00122416 -0.104335 0.000404189" quat="0.706947 0.707266 -5.18785e-05 0.000361453" mass="0.214362" diaginertia="0.00512852 0.00632789 4.12196e-05"/>
              <joint name="Right_Elbow_Yaw" pos="0 0 0" axis="0.0035779 -0.00355085 0.999987" range="-0.0250679 2.47027" armature="0.00814609" damping="0.00406974" frictionloss="0.0864474"/>
              <geom name="//unnamed_geom_27" class="visual" mesh="right_hand_link"/>
              <geom name="//unnamed_geom_28" class="collision" size="0.025843 0.0753754" pos="0 -0.12369 0" quat="0.707105 0.707108 0 0" type="cylinder"/>
              <geom name="//unnamed_geom_29" class="reward_collision_sphere" size="0.0430716"/>
              <geom name="//unnamed_geom_30" class="reward_collision_sphere" size="0.0301502" pos="0 -0.104661 0"/>
              <geom name="//unnamed_geom_31" class="reward_collision_sphere" size="0.0301502" pos="0 -0.204565 0"/>
            </body>
          </body>
        </body>
      </body>
      <body name="Waist" pos="0.0590068 0.00297873 -0.0840767" quat="1 -0.000581673 -5.78935e-05 -0.000456268">
        <inertial pos="0.00134384 -0.0002138 0.0062121" quat="0.984677 0.0119121 -0.173827 0.00734221" mass="1.66816" diaginertia="0.00338684 0.00408454 0.00090428"/>
        <joint name="Waist" pos="0 0 0" axis="-0.00609574 -0.00690478 0.999958" range="-1.59441 1.62251" armature="0.00832488" damping="0.023787" frictionloss="0.0854996"/>
        <geom name="//unnamed_geom_32" class="visual" mesh="Waist"/>
        <body name="Hip_Pitch_Left" pos="0.00087975 0.10117 0.000661021" quat="1 -0.00019068 -0.000141901 -0.000181775">
          <inertial pos="-0.00100201 -0.00794248 -0.0134045" quat="0.975414 0.220042 0.0120483 0.00212073" mass="0.621153" diaginertia="0.00110946 0.00108345 0.000231186"/>
          <joint name="Left_Hip_Pitch" pos="0 0 0" axis="0.00562534 0.999842 -0.0168407" stiffness="0.00907348" range="-1.78711 1.61732" armature="0.00867003" damping="0.0287011" frictionloss="0.0858114"/>
          <geom name="//unnamed_geom_33" class="visual" rgba="0.76 0.76 0.76 1" mesh="Hip_Pitch_Left"/>
          <body name="Hip_Roll_Left" pos="0.00308687 -0.00132524 -0.0166409" quat="1 -3.82866e-05 -7.64451e-05 4.54802e-05">
            <inertial pos="0.00193443 0.000877905 -0.0414513" quat="0.704821 -0.00967632 -0.00538152 0.709298" mass="0.244565" diaginertia="0.00111037 0.00116395 9.63616e-05"/>
            <joint name="Left_Hip_Roll" pos="0 0 0" axis="-0.999987 0.00266888 -0.00434512" range="-1.52046 0.157337" armature="0.00885498" damping="0.0105619" frictionloss="0.0916842"/>
            <geom name="//unnamed_geom_34" class="visual" mesh="Hip_Roll_Left"/>
            <geom name="//unnamed_geom_35" class="reward_collision_sphere" size="0.0473788"/>
            <body name="Hip_Yaw_Left" pos="-0.00168227 0.00136764 -0.0578624" quat="0.999999 0.000284356 3.76204e-05 -0.00101146">
              <inertial pos="-0.0067774 -0.000359303 -0.0638614" quat="0.693928 -0.0351785 -0.0287519 0.718609" mass="1.33784" diaginertia="0.0166469 0.0200503 0.000511916"/>
              <joint name="Left_Hip_Yaw" pos="0 0 0" axis="0.0011072 -0.000446571 -0.999999" stiffness="0.00865291" range="-1.01128 1.03192" armature="0.00886384" damping="0" frictionloss="0.0857766"/>
              <geom name="//unnamed_geom_36" class="visual" mesh="Hip_Yaw_Left"/>
              <geom name="//unnamed_geom_37" class="collision" size="0.0430716 0.0689146" type="cylinder"/>
              <body name="Shank_Left" pos="-0.0113139 -0.00250616 -0.0979998" quat="0.999999 -0.00109688 0.000566157 -3.41609e-05">
                <inertial pos="-0.00464928 0.00272092 -0.0887992" quat="0.997978 0.00370013 -0.0194942 0.0603786" mass="1.13088" diaginertia="0.0212545 0.0273947 0.000346988"/>
                <joint name="Left_Knee_Pitch" pos="0 0 0" axis="0.00400517 0.999986 0.00359965" range="0.0500431 2.32563" armature="0.00966151" damping="0.0119258" frictionloss="0.0892307"/>
                <geom name="//unnamed_geom_38" class="visual" mesh="Shank_Left"/>
                <geom name="//unnamed_geom_39" class="collision" size="0.0430716 0.0646075" pos="0 0 -0.086178" type="cylinder"/>
                <geom name="//unnamed_geom_40" class="reward_collision_sphere" size="0.0559931"/>
                <body name="Ankle_Cross_Left" pos="-0.0026219 -0.00170655 -0.199996" quat="0.999999 -0.000230594 0.000742036 -0.000903269">
                  <inertial pos="-0.00391845 0.00246973 -0.00448809" quat="0.448822 0.540399 0.557089 0.442921" mass="0.0473941" diaginertia="1.87382e-05 1.95383e-05 2.10372e-06"/>
                  <joint name="Left_Ankle_Pitch" pos="0 0 0" axis="-0.0111777 0.999905 -0.00801024" range="-0.83895 0.39946" armature="0.00744679" damping="0.0277985" frictionloss="0.0881367"/>
                  <geom name="//unnamed_geom_41" class="visual" mesh="Ankle_Cross_Left"/>
                  <body name="left_foot_link" pos="0.000400694 -0.001591 -0.00826608" quat="0.999999 -0.000288823 0.00116047 0.000473992">
                    <inertial pos="-0.00253509 0.000182693 -0.00475798" quat="0.0033059 0.620508 0.00353204 0.784185" mass="0.420339" diaginertia="0.00176074 0.00185504 0.000428456"/>
                    <joint name="Left_Ankle_Roll" pos="0 0 0" axis="-0.999885 -0.00884179 -0.0123486" stiffness="0.00395948" range="-0.484113 0.387157" armature="0.00880846" damping="0" frictionloss="0.087801"/>
                    <geom name="//unnamed_geom_42" class="visual" mesh="left_foot_link"/>
                    <geom name="left_foot" class="foot" size="0.105647 0.0349569 0.0143625" pos="0.00914684 0 -0.0107722"/>
                    <geom name="//unnamed_geom_44" class="reward_collision_sphere" size="0.0447945" pos="0.00914684 0 -0.0107722"/>
                    <geom name="//unnamed_geom_45" class="reward_collision_sphere" size="0.025843" pos="0.086895 -0.0218837 -0.0107722"/>
                    <geom name="//unnamed_geom_46" class="reward_collision_sphere" size="0.025843" pos="-0.0640279 -0.0218837 -0.0107722"/>
                    <site name="left_foot" class="foot" pos="0.00914684 0 -0.0107722" size="0.00861433"/>
                  </body>
                </body>
              </body>
            </body>
          </body>
        </body>
        <body name="Hip_Pitch_Right" pos="-0.00378579 -0.100452 -0.00189623" quat="0.999999 3.97405e-05 0.000785645 -0.00112891">
          <inertial pos="0.00012263 0.00996653 -0.0132094" quat="0.973628 -0.227698 0.012541 -0.00662072" mass="0.671773" diaginertia="0.00118846 0.00116677 0.000249676"/>
          <joint name="Right_Hip_Pitch" pos="0 0 0" axis="-0.00379525 -0.999978 0.00535453" range="-1.55411 1.7839" armature="0.008955" damping="0" frictionloss="0.097207"/>
          <geom name="//unnamed_geom_47" class="visual" rgba="0.76 0.76 0.76 1" mesh="Hip_Pitch_Right"/>
          <body name="Hip_Roll_Right" pos="-0.000858691 -0.00245738 -0.0126099" quat="1 -0.000187416 0.000665927 -0.000103613">
            <inertial pos="0.00025397 0.00185072 -0.0405148" quat="0.710192 -0.00850072 -0.00948665 0.703893" mass="0.240972" diaginertia="0.00106621 0.00119023 9.6884e-05"/>
            <joint name="Right_Hip_Roll" pos="0 0 0" axis="-0.999983 -0.00234936 0.0052696" range="-0.212367 1.59922" armature="0.00844901" damping="0.0170843" frictionloss="0.0857361"/>
            <geom name="//unnamed_geom_48" class="visual" mesh="Hip_Roll_Right"/>
            <geom name="//unnamed_geom_49" class="reward_collision_sphere" size="0.0473788"/>
            <body name="Hip_Yaw_Right" pos="0.000218866 -0.00123235 -0.0610303" quat="1 -0.000132708 3.32211e-05 4.77809e-05">
              <inertial pos="-0.0036182 -0.00219023 -0.0620361" quat="0.715474 -0.0289306 -0.0233318 0.69765" mass="1.44018" diaginertia="0.0165756 0.0194493 0.000514239"/>
              <joint name="Right_Hip_Yaw" pos="0 0 0" axis="-0.0165276 -0.00847122 -0.999828" stiffness="0.0128173" range="-0.970685 1.03167" armature="0.00861065" damping="0.010986" frictionloss="0.0859468"/>
              <geom name="//unnamed_geom_50" class="visual" mesh="Hip_Yaw_Right"/>
              <geom name="//unnamed_geom_51" class="collision" size="0.0430716 0.0689146" type="cylinder"/>
              <body name="Shank_Right" pos="-0.0128324 0.00194578 -0.0991064" quat="1 1.40789e-06 -4.06167e-07 -2.86302e-06">
                <inertial pos="-0.00480583 0.00219015 -0.0896117" quat="0.999168 0.0024054 -0.0220321 -0.0342458" mass="1.11354" diaginertia="0.0223172 0.026745 0.000364095"/>
                <joint name="Right_Knee_Pitch" pos="0 0 0" axis="-0.0130763 -0.99991 -0.00306063" stiffness="0.0077425" range="-2.38942 0.0133429" armature="0.00852621" damping="0.0219493" frictionloss="0.0982228"/>
                <geom name="//unnamed_geom_52" class="visual" mesh="Shank_Right"/>
                <geom name="//unnamed_geom_53" class="collision" size="0.0430716 0.0646075" pos="0 0 -0.086178" type="cylinder"/>
                <geom name="//unnamed_geom_54" class="reward_collision_sphere" size="0.0559931"/>
                <body name="Ankle_Cross_Right" pos="-0.00120447 -2.25339e-05 -0.202831" quat="1 -0.000188349 0.000167278 6.06827e-05">
                  <inertial pos="-0.00319633 -0.000425078 -0.00568277" quat="0.444335 0.557731 0.539644 0.447533" mass="0.0453834" diaginertia="1.81725e-05 1.9638e-05 2.1006e-06"/>
                  <joint name="Right_Ankle_Pitch" pos="0 0 0" axis="-0.00268566 -0.999974 -0.0066475" stiffness="0.015872" range="-0.343546 0.83357" armature="0.00914655" damping="0" frictionloss="0.0915474"/>
                  <geom name="//unnamed_geom_55" class="visual" mesh="Ankle_Cross_Right"/>
                  <body name="right_foot_link" pos="0.00133823 -0.000120934 -0.00679937" quat="0.999999 -0.000299467 0.00126797 2.48928e-06">
                    <inertial pos="0.0021662 -0.00012953 -0.00717434" quat="0.00253102 0.623921 -0.00029547 0.781483" mass="0.457945" diaginertia="0.00174143 0.0019351 0.000417304"/>
                    <joint name="Right_Ankle_Roll" pos="0 0 0" axis="-0.999981 -0.0055019 0.00287896" range="-0.466371 0.495159" armature="0.007847" damping="0.0084482" frictionloss="0.0861276"/>
                    <geom name="//unnamed_geom_56" class="visual" mesh="right_foot_link"/>
                    <geom name="right_foot" class="foot" size="0.10708 0.0404452 0.0128952" pos="0.00914684 0 -0.0107722"/>
                    <geom name="//unnamed_geom_58" class="reward_collision_sphere" size="0.0344573"/>
                    <geom name="//unnamed_geom_59" class="reward_collision_sphere" size="0.025843" pos="0.00914684 0 -0.0107722"/>
                    <geom name="//unnamed_geom_60" class="reward_collision_sphere" size="0.025843" pos="0.086895 0.0218837 -0.0107722"/>
                    <geom name="//unnamed_geom_61" class="reward_collision_sphere" size="0.025843" pos="-0.0640279 0.0218837 -0.0107722"/>
                    <site name="right_foot" class="foot" pos="0.00914684 0 -0.0107722" size="0.00861433"/>
                  </body>
                </body>
              </body>
            </body>
          </body>
        </body>
      </body>
    </body>
  </worldbody>

  <contact>
    <pair class="/" geom1="floor" geom2="left_foot" name="//unnamed_contact_0"/>
    <pair class="/" geom1="floor" geom2="right_foot" name="//unnamed_contact_1"/>
  </contact>

  <actuator>
    <general name="AAHead_yaw" class="/" joint="AAHead_yaw" forcerange="-5.405 5.405" gainprm="22.7178" biasprm="0 -22.7178 -0.559788"/>
    <general name="Head_pitch" class="/" joint="Head_pitch" forcerange="-6.15525 6.15525" gainprm="22.7178" biasprm="0 -22.7178 -0.559788"/>
    <general name="Left_Shoulder_Pitch" class="/" joint="Left_Shoulder_Pitch" forcerange="-16.1108 16.1108" gainprm="22.7178" biasprm="0 -22.7178 -0.559788"/>
    <general name="Left_Shoulder_Roll" class="/" joint="Left_Shoulder_Roll" forcerange="-15.7324 15.7324" gainprm="22.7178" biasprm="0 -22.7178 -0.559788"/>
    <general name="Left_Elbow_Pitch" class="/" joint="Left_Elbow_Pitch" forcerange="-16.0784 16.0784" gainprm="22.7178" biasprm="0 -22.7178 -0.559788"/>
    <general name="Left_Elbow_Yaw" class="/" joint="Left_Elbow_Yaw" forcerange="-14.8705 14.8705" gainprm="22.7178" biasprm="0 -22.7178 -0.559788"/>
    <general name="Right_Shoulder_Pitch" class="/" joint="Right_Shoulder_Pitch" forcerange="-16.1417 16.1417" gainprm="22.7178" biasprm="0 -22.7178 -0.559788"/>
    <general name="Right_Shoulder_Roll" class="/" joint="Right_Shoulder_Roll" forcerange="-15.2498 15.2498" gainprm="22.7178" biasprm="0 -22.7178 -0.559788"/>
    <general name="Right_Elbow_Pitch" class="/" joint="Right_Elbow_Pitch" forcerange="-14.2066 14.2066" gainprm="22.7178" biasprm="0 -22.7178 -0.559788"/>
    <general name="Right_Elbow_Yaw" class="/" joint="Right_Elbow_Yaw" forcerange="-15.865 15.865" gainprm="22.7178" biasprm="0 -22.7178 -0.559788"/>
    <general name="Waist" class="/" joint="Waist" forcerange="-28.6458 28.6458" gainprm="22.7178" biasprm="0 -22.7178 -0.559788"/>
    <general name="Left_Hip_Pitch" class="/" joint="Left_Hip_Pitch" forcerange="-40.5698 40.5698" gainprm="22.7178" biasprm="0 -22.7178 -0.559788"/>
    <general name="Left_Hip_Roll" class="/" joint="Left_Hip_Roll" forcerange="-27.57 27.57" gainprm="22.7178" biasprm="0 -22.7178 -0.559788"/>
    <general name="Left_Hip_Yaw" class="/" joint="Left_Hip_Yaw" forcerange="-28.5188 28.5188" gainprm="22.7178" biasprm="0 -22.7178 -0.559788"/>
    <general name="Left_Knee_Pitch" class="/" joint="Left_Knee_Pitch" forcerange="-52.4522 52.4522" gainprm="22.7178" biasprm="0 -22.7178 -0.559788"/>
    <general name="Left_Ankle_Pitch" class="/" joint="Left_Ankle_Pitch" forcerange="-18.057 18.057" gainprm="22.7178" biasprm="0 -22.7178 -0.559788"/>
    <general name="Left_Ankle_Roll" class="/" joint="Left_Ankle_Roll" forcerange="-12.7956 12.7956" gainprm="22.7178" biasprm="0 -22.7178 -0.559788"/>
    <general name="Right_Hip_Pitch" class="/" joint="Right_Hip_Pitch" forcerange="-38.2054 38.2054" gainprm="22.7178" biasprm="0 -22.7178 -0.559788"/>
    <general name="Right_Hip_Roll" class="/" joint="Right_Hip_Roll" forcerange="-27.6959 27.6959" gainprm="22.7178" biasprm="0 -22.7178 -0.559788"/>
    <general name="Right_Hip_Yaw" class="/" joint="Right_Hip_Yaw" forcerange="-28.4318 28.4318" gainprm="22.7178" biasprm="0 -22.7178 -0.559788"/>
    <general name="Right_Knee_Pitch" class="/" joint="Right_Knee_Pitch" forcerange="-56.4495 56.4495" gainprm="22.7178" biasprm="0 -22.7178 -0.559788"/>
    <general name="Right_Ankle_Pitch" class="/" joint="Right_Ankle_Pitch" forcerange="-15.5187 15.5187" gainprm="22.7178" biasprm="0 -22.7178 -0.559788"/>
    <general name="Right_Ankle_Roll" class="/" joint="Right_Ankle_Roll" forcerange="-13.1567 13.1567" gainprm="22.7178" biasprm="0 -22.7178 -0.559788"/>
  </actuator>

  <sensor>
    <gyro site="imu" name="imu_angular_velocity"/>
    <velocimeter site="imu" name="imu_linear_velocity"/>
    <framelinvel objtype="site" objname="left_foot" name="left_foot_global_linear_velocity"/>
    <framelinvel objtype="site" objname="right_foot" name="right_foot_global_linear_velocity"/>
  </sensor>

  <keyframe>
    <key name="home" qpos="0 0 0.6385 1 0 0 0 0 0 0 1.4 0 -0.4 0 -1.4 0 0.4 0 -0.4 0 0 0.8 -0.4 0 0.4 0 0 -0.8 0.4 0"/>
  </keyframe>
</mujoco>
