<mujoco model="T1">
  <compiler angle="radian" assetdir="assets" balanceinertia="true" inertiafromgeom="false"/>

  <option timestep="0.005" density="1.2" viscosity="2e-05"/>

  <size nkey="1"/>

  <visual>
    <quality shadowsize="8192"/>
    <map shadowclip="0.5"/>
  </visual>

  <default>
    <default class="/">
      <joint armature="0.01" damping="0.01" frictionloss="0.1"/>
      <geom contype="0" conaffinity="0" group="1" solref="-1000 -80"/>
      <site size="0.01 0.005 0.005" group="5"/>
      <general forcelimited="true" biastype="affine" gainprm="25" biasprm="0 -25 -0.6"/>
      <default class="t1">
        <geom rgba="0.25 0.25 0.25 1"/>
        <default class="visual">
          <geom type="mesh" group="2"/>
        </default>
        <default class="collision">
          <geom group="3"/>
        </default>
        <default class="foot">
          <geom size="0.1115 0.05 0.015" type="box" condim="6" group="4" priority="1" solimp="0.015 1 0.015"/>
        </default>
        <default class="reward_collision_sphere">
          <geom group="5" rgba="1 0 0 1"/>
        </default>
      </default>
    </default>
  </default>

  <asset>
    <texture type="skybox" colorspace="auto" name="//unnamed_texture_0" builtin="gradient" rgb1="0.95 0.95 0.95" rgb2="0.95 0.95 0.95" width="100" height="600"/>
    <texture type="2d" colorspace="auto" name="texplane" builtin="checker" rgb1="0.345 0.575 0.748" rgb2="0.345 0.575 0.748" markrgb="1 1 1" width="512" height="512"/>
    <material name="MatPlane" class="/" texture="texplane" texuniform="true" texrepeat="2 2" specular="0.9"/>
    <mesh name="Trunk" class="/" file="Trunk.stl"/>
    <mesh name="H1" class="/" file="H1.stl"/>
    <mesh name="H2" class="/" file="H2.stl"/>
    <mesh name="AL1" class="/" file="AL1.stl"/>
    <mesh name="AL2" class="/" file="AL2.stl"/>
    <mesh name="AL3" class="/" file="AL3.stl"/>
    <mesh name="left_hand_link" class="/" file="left_hand_link.stl"/>
    <mesh name="AR1" class="/" file="AR1.stl"/>
    <mesh name="AR2" class="/" file="AR2.stl"/>
    <mesh name="AR3" class="/" file="AR3.stl"/>
    <mesh name="right_hand_link" class="/" file="right_hand_link.stl"/>
    <mesh name="Waist" class="/" file="Waist.stl"/>
    <mesh name="Hip_Pitch_Left" class="/" file="Hip_Pitch_Left.stl"/>
    <mesh name="Hip_Roll_Left" class="/" file="Hip_Roll_Left.stl"/>
    <mesh name="Hip_Yaw_Left" class="/" file="Hip_Yaw_Left.stl"/>
    <mesh name="Shank_Left" class="/" file="Shank_Left.stl"/>
    <mesh name="Ankle_Cross_Left" class="/" file="Ankle_Cross_Left.stl"/>
    <mesh name="left_foot_link" class="/" file="left_foot_link.stl"/>
    <mesh name="Hip_Pitch_Right" class="/" file="Hip_Pitch_Right.stl"/>
    <mesh name="Hip_Roll_Right" class="/" file="Hip_Roll_Right.stl"/>
    <mesh name="Hip_Yaw_Right" class="/" file="Hip_Yaw_Right.stl"/>
    <mesh name="Shank_Right" class="/" file="Shank_Right.stl"/>
    <mesh name="Ankle_Cross_Right" class="/" file="Ankle_Cross_Right.stl"/>
    <mesh name="right_foot_link" class="/" file="right_foot_link.stl"/>
  </asset>

  <worldbody>
    <geom name="floor" class="/" size="100 100 0.125" type="plane" group="0" material="MatPlane"/>
    <light name="toplight_shadow" class="/" pos="0 0 5" dir="0.0990148 0.0990148 -0.990148" type="directional" ambient="0.04 0.04 0.04" diffuse="0.55 0.55 0.55" specular="0.12 0.12 0.12"/>
    <light name="toplight_fill" class="/" pos="0 0 5" dir="0.0990148 0.0990148 -0.990148" type="directional" castshadow="false" ambient="0.04 0.04 0.04" diffuse="0.3 0.3 0.3" specular="0.08 0.08 0.08"/>
    <body name="trunk" childclass="t1" pos="0.000687063 -0.00241159 -6.05671e-05" quat="0.999999 -0.000759929 0.00066566 -0.000269656">
      <inertial pos="0.0370162 -0.00345778 0.122707" quat="0.999973 -0.00100427 -0.00636823 0.00360334" mass="9.71339" diaginertia="0.0186489 0.0557887 0.127828"/>
      <joint name="//unnamed_joint_0" type="free" armature="0" damping="0" frictionloss="0"/>
      <geom name="//unnamed_geom_1" class="visual" rgba="0.76 0.76 0.76 1" mesh="Trunk"/>
      <geom name="//unnamed_geom_2" class="collision" size="0.0715542 0.0954056 0.143108" pos="0.0437142 0 0.142525" type="box"/>
      <geom name="//unnamed_geom_3" class="reward_collision_sphere" size="0.109716" pos="0.0437142 0 0.118771"/>
      <geom name="//unnamed_geom_4" class="reward_collision_sphere" size="0.0143108" pos="0.0437142 0.0804002 0"/>
      <geom name="//unnamed_geom_5" class="reward_collision_sphere" size="0.0143108" pos="0.0437142 -0.0804002 0"/>
      <geom name="//unnamed_geom_6" class="reward_collision_sphere" size="0.0143108" pos="0.0437142 0.10121 0.213788"/>
      <geom name="//unnamed_geom_7" class="reward_collision_sphere" size="0.0143108" pos="0.0437142 -0.10121 0.213788"/>
      <site name="imu" pos="0.0141841 0.000212358 -0.0141895" size="0.00954056"/>
      <camera name="track" pos="0 -1.89177 0" quat="0.707107 0.707107 0 0" mode="trackcom"/>
      <camera name="ego_camera" pos="0.0888856 0 0.498839" quat="-0.5 -0.5 0.5 0.5"/>
      <body name="H1" pos="0.0421359 0.00195006 0.289908" quat="1 -2.76805e-05 -0.000747607 -0.000372334">
        <inertial pos="-0.00409883 0.000309883 0.0703602" quat="0.757394 -0.0145128 -0.00252328 0.652791" mass="0.393361" diaginertia="5.06025e-05 0.000169859 0.000336936"/>
        <joint name="AAHead_yaw" pos="0 0 0" axis="0.00675478 -0.00753333 0.999949" stiffness="0.00416889" range="-1.58565 1.58332" armature="0.00820121" damping="0.011472" frictionloss="0.0937114"/>
        <geom name="//unnamed_geom_8" class="visual" mesh="H1"/>
        <body name="H2" pos="0.00192111 0.00183546 0.0717243" quat="1 2.9479e-05 2.67532e-05 0.000244217">
          <inertial pos="0.00724731 0.00315405 0.117961" quat="0.988301 0.107715 -0.0764605 -0.0762375" mass="0.556937" diaginertia="0.000436414 0.00149142 0.00411424"/>
          <joint name="Head_pitch" pos="0 0 0" axis="-0.00163503 -0.999953 -0.00953378" range="-1.22036 0.348785" armature="0.00859115" damping="0.0106568" frictionloss="0.100714"/>
          <geom name="//unnamed_geom_9" class="visual" mesh="H2"/>
          <geom name="//unnamed_geom_10" class="collision" size="0.0763245" pos="0.00728571 0 0.130648"/>
          <geom name="//unnamed_geom_11" class="reward_collision_sphere" size="0.085865" pos="0.0145714 0 0.118771"/>
        </body>
      </body>
      <body name="AL1" pos="0.0412724 0.102249 0.258566" quat="1 -0.000186661 0.000469783 -0.000167761">
        <inertial pos="-0.00258987 0.0410916 -0.00069167" quat="0.505491 0.498411 -0.504607 0.491362" mass="0.462184" diaginertia="0.000284394 0.000990971 0.000672836"/>
        <joint name="Left_Shoulder_Pitch" pos="0 0 0" axis="0.00162037 0.999953 -0.00960315" stiffness="0.00662623" range="-3.30657 1.17347" armature="0.00977833" damping="0.0102059" frictionloss="0.0978042"/>
        <geom name="//unnamed_geom_12" class="visual" rgba="0.76 0.76 0.76 1" mesh="AL1"/>
        <body name="AL2" pos="0.000526886 0.0447663 -0.00292697" quat="1 2.08548e-05 -6.73924e-05 3.5383e-05">
          <inertial pos="0.00510051 0.0334797 -0.00284185" quat="0.492426 0.503348 -0.497017 0.507081" mass="0.136873" diaginertia="8.25893e-05 0.000262346 0.000413026"/>
          <joint name="Left_Shoulder_Roll" pos="0 0 0" axis="-0.999942 -0.00382051 0.0100897" range="-1.56755 1.72205" armature="0.00945327" damping="0.00765575" frictionloss="0.0929227"/>
          <geom name="//unnamed_geom_13" class="visual" mesh="AL2"/>
          <body name="AL3" pos="0.00111634 0.05796 0.00232719" quat="1 3.70794e-05 -0.000215596 -5.92745e-05">
            <inertial pos="-0.00334369 0.0805487 -0.00081481" quat="0.702633 0.711512 -7.23845e-05 0.00759488" mass="0.896043" diaginertia="0.002736 0.00973184 0.00145537"/>
            <joint name="Left_Elbow_Pitch" pos="0 0 0" axis="-0.00176715 -0.999995 -0.0024562" range="-2.29527 2.28154" armature="0.00947837" damping="0.015126" frictionloss="0.103489"/>
            <geom name="//unnamed_geom_14" class="visual" mesh="AL3"/>
            <geom name="//unnamed_geom_15" class="collision" size="0.0286217 0.0715542" pos="0 0.0472942 0" quat="0.707105 0.707108 0 0" type="cylinder"/>
            <geom name="//unnamed_geom_16" class="reward_collision_sphere" size="0.034346"/>
            <body name="left_hand_link" pos="0.00264702 0.142242 0.0033768" quat="1 -5.53746e-06 0.000132219 -0.00024228">
              <inertial pos="0.00211842 0.100795 -0.00207163" quat="0.709761 0.704422 0.000424497 -0.00533938" mass="0.284047" diaginertia="0.00167886 0.00621553 0.000525893"/>
              <joint name="Left_Elbow_Yaw" pos="0 0 0" axis="0.00746138 -0.00451469 0.999962" range="-2.43706 -0.00299083" armature="0.0109939" damping="0.0229773" frictionloss="0.0958436"/>
              <geom name="//unnamed_geom_17" class="visual" mesh="left_hand_link"/>
              <geom name="//unnamed_geom_18" class="collision" size="0.0286217 0.0834799" pos="0 0.122965 0" quat="0.707105 0.707108 0 0" type="cylinder"/>
              <geom name="//unnamed_geom_19" class="reward_collision_sphere" size="0.0477028"/>
              <geom name="//unnamed_geom_20" class="reward_collision_sphere" size="0.033392" pos="0 0.104047 0"/>
              <geom name="//unnamed_geom_21" class="reward_collision_sphere" size="0.033392" pos="0 0.203365 0"/>
            </body>
          </body>
        </body>
      </body>
      <body name="AR1" pos="0.0434749 -0.0976031 0.260588" quat="1 -0.000257147 0.000723687 -0.000329868">
        <inertial pos="1.74271e-06 -0.044812 0.002066" quat="0.504098 0.495752 -0.504745 0.495326" mass="0.469638" diaginertia="0.000277304 0.00101529 0.000706211"/>
        <joint name="Right_Shoulder_Pitch" pos="0 0 0" axis="-0.00282703 -0.999996 -0.000691588" stiffness="0.00023642" range="-1.17063 3.31933" armature="0.00897774" damping="0.019045" frictionloss="0.0854244"/>
        <geom name="//unnamed_geom_22" class="visual" rgba="0.76 0.76 0.76 1" mesh="AR1"/>
        <body name="AR2" pos="0.000421724 -0.0453593 -0.00212746" quat="0.999999 0.000245738 -0.00126081 0.000634373">
          <inertial pos="0.000932379 -0.0346157 0.000122739" quat="0.509688 0.493429 -0.518751 0.477119" mass="0.134481" diaginertia="7.91874e-05 0.000260184 0.000399937"/>
          <joint name="Right_Shoulder_Roll" pos="0 0 0" axis="-0.999991 -0.00353229 0.00238103" range="-1.78277 1.52689" armature="0.00964222" damping="0" frictionloss="0.0999251"/>
          <geom name="//unnamed_geom_23" class="visual" mesh="AR2"/>
          <body name="AR3" pos="-0.00347666 -0.0570924 0.000861774" quat="0.999999 0.000982482 -0.000200243 -0.000701483">
            <inertial pos="0.000838371 -0.0816636 0.00218165" quat="0.707013 0.707198 -0.000534671 0.00164148" mass="0.880692" diaginertia="0.00266651 0.00954887 0.00143594"/>
            <joint name="Right_Elbow_Pitch" pos="0 0 0" axis="-0.00282922 0.99992 0.0123317" range="-2.30306 2.25122" armature="0.00947206" damping="0.00831297" frictionloss="0.106684"/>
            <geom name="//unnamed_geom_24" class="visual" mesh="AR3"/>
            <geom name="//unnamed_geom_25" class="collision" size="0.0286217 0.0715542" pos="0 -0.0472942 0" quat="0.707105 0.707108 0 0" type="cylinder"/>
            <geom name="//unnamed_geom_26" class="reward_collision_sphere" size="0.034346"/>
            <body name="right_hand_link" pos="-0.00374257 -0.141869 0.00206655" quat="0.999999 0.00029732 -0.00131173 -0.000380806">
              <inertial pos="0.00123376 -0.102069 -0.00157146" quat="0.70518 0.709025 -0.000709391 0.00196903" mass="0.282185" diaginertia="0.0016259 0.00584117 0.000512368"/>
              <joint name="Right_Elbow_Yaw" pos="0 0 0" axis="0.00125339 -0.00189013 0.999997" range="-0.000945705 2.38816" armature="0.00888491" damping="0.00992941" frictionloss="0.0959222"/>
              <geom name="//unnamed_geom_27" class="visual" mesh="right_hand_link"/>
              <geom name="//unnamed_geom_28" class="collision" size="0.0286217 0.0834799" pos="0 -0.122965 0" quat="0.707105 0.707108 0 0" type="cylinder"/>
              <geom name="//unnamed_geom_29" class="reward_collision_sphere" size="0.0477028"/>
              <geom name="//unnamed_geom_30" class="reward_collision_sphere" size="0.033392" pos="0 -0.104047 0"/>
              <geom name="//unnamed_geom_31" class="reward_collision_sphere" size="0.033392" pos="0 -0.203365 0"/>
            </body>
          </body>
        </body>
      </body>
      <body name="Waist" pos="0.0439906 -0.00203004 -0.134427" quat="1 9.15523e-05 1.49875e-05 -2.77681e-05">
        <inertial pos="0.0023627 0.00220441 0.0095469" quat="0.983545 -0.00839492 -0.180273 -0.00840444" mass="2.09259" diaginertia="0.00105308 0.00374783 0.0104445"/>
        <joint name="Waist" pos="0 0 0" axis="0.00637154 -0.000842549 0.999979" range="-1.61394 1.53262" armature="0.00891948" damping="0.00452084" frictionloss="0.108213"/>
        <geom name="//unnamed_geom_32" class="visual" mesh="Waist"/>
        <body name="Hip_Pitch_Left" pos="0.00426276 0.0985012 -0.001111" quat="1 0.000433791 0.00035312 -0.000332991">
          <inertial pos="-0.000970041 -0.00792988 -0.023943" quat="0.974361 0.224688 0.0112696 -0.00294887" mass="0.850034" diaginertia="0.000360443 0.0010756 0.00287374"/>
          <joint name="Left_Hip_Pitch" pos="0 0 0" axis="0.00185933 0.99988 0.0153895" stiffness="0.0191307" range="-1.8083 1.62213" armature="0.00930394" damping="0" frictionloss="0.0952649"/>
          <geom name="//unnamed_geom_33" class="visual" rgba="0.76 0.76 0.76 1" mesh="Hip_Pitch_Left"/>
          <body name="Hip_Roll_Left" pos="0.00225416 0.00127001 -0.0268469" quat="1 -0.000122932 -5.97016e-06 -0.00010189">
            <inertial pos="0.00150776 -0.000652237 -0.0664004" quat="0.706396 -0.009774 -0.00321403 0.707742" mass="0.340933" diaginertia="0.00037911 0.00114956 0.00122673"/>
            <joint name="Left_Hip_Roll" pos="0 0 0" axis="-0.999914 -0.012561 0.00381533" range="-1.60656 0.243427" armature="0.00909626" damping="0.0170464" frictionloss="0.0904975"/>
            <geom name="//unnamed_geom_34" class="visual" mesh="Hip_Roll_Left"/>
            <geom name="//unnamed_geom_35" class="reward_collision_sphere" size="0.0524731"/>
            <body name="Hip_Yaw_Left" pos="0.00198085 0.00183858 -0.0974815" quat="1 4.49645e-05 0.000320474 -0.000183635">
              <inertial pos="-0.00729237 -0.000787897 -0.104866" quat="0.690417 -0.0295936 -0.0395705 0.721722" mass="1.87111" diaginertia="0.00552128 0.0192979 0.00649867"/>
              <joint name="Left_Hip_Yaw" pos="0 0 0" axis="0.000146304 0.000247854 -1" stiffness="0.00227339" range="-0.992955 1.02718" armature="0.0109241" damping="0.00852035" frictionloss="0.0977438"/>
              <geom name="//unnamed_geom_36" class="visual" mesh="Hip_Yaw_Left"/>
              <geom name="//unnamed_geom_37" class="collision" size="0.0477028 0.0763245" type="cylinder"/>
              <body name="Shank_Left" pos="-0.00921698 -0.000668267 -0.161383" quat="0.999999 0.000728328 -0.000439435 -0.000728924">
                <inertial pos="-0.00380043 0.000163732 -0.150268" quat="0.997521 0.000769869 -0.0244962 0.0659688" mass="1.48807" diaginertia="0.00707782 0.0248955 0.00409461"/>
                <joint name="Left_Knee_Pitch" pos="0 0 0" axis="0.00409718 0.99999 0.00175588" stiffness="0.00580553" range="0.0534528 2.33932" armature="0.00938402" damping="0" frictionloss="0.0915317"/>
                <geom name="//unnamed_geom_38" class="visual" mesh="Shank_Left"/>
                <geom name="//unnamed_geom_39" class="collision" size="0.0477028 0.0715542" pos="0 0 -0.142525" type="cylinder"/>
                <geom name="//unnamed_geom_40" class="reward_collision_sphere" size="0.0620136"/>
                <body name="Ankle_Cross_Left" pos="-0.00242003 -0.00170085 -0.335302" quat="1 -9.58823e-05 -3.99035e-05 -0.000138344">
                  <inertial pos="-0.00462766 0.00211463 -0.00980057" quat="0.440952 0.55173 0.552126 0.443071" mass="0.0615367" diaginertia="6.17719e-06 1.90991e-05 2.69085e-05"/>
                  <joint name="Left_Ankle_Pitch" pos="0 0 0" axis="0.0115144 0.999921 0.00496129" stiffness="0.00794203" range="-0.927513 0.350884" armature="0.0083416" damping="0.0180144" frictionloss="0.108126"/>
                  <geom name="//unnamed_geom_41" class="visual" mesh="Ankle_Cross_Left"/>
                  <body name="left_foot_link" pos="-0.00130137 0.00219241 -0.0129832" quat="1 -0.000772653 -0.000314986 0.000129019">
                    <inertial pos="-0.00218596 0.000367456 -0.0123939" quat="0.00955575 0.614011 0.000871416 0.78924" mass="0.581114" diaginertia="0.000579055 0.00182855 0.0054075"/>
                    <joint name="Left_Ankle_Roll" pos="0 0 0" axis="-0.999993 -0.00299145 0.00237526" range="-0.487097 0.400497" armature="0.0109015" damping="0.0188921" frictionloss="0.0850848"/>
                    <geom name="//unnamed_geom_42" class="visual" mesh="left_foot_link"/>
                    <geom name="left_foot" class="foot" size="0.105262 0.0431778 0.0150202" pos="0.00728571 0 -0.0178157"/>
                    <geom name="//unnamed_geom_44" class="reward_collision_sphere" size="0.0496109" pos="0.00728571 0 -0.0178157"/>
                    <geom name="//unnamed_geom_45" class="reward_collision_sphere" size="0.0286217" pos="0.0692142 -0.0217553 -0.0178157"/>
                    <geom name="//unnamed_geom_46" class="reward_collision_sphere" size="0.0286217" pos="-0.0509999 -0.0217553 -0.0178157"/>
                    <site name="left_foot" class="foot" pos="0.00728571 0 -0.0178157" size="0.00954056"/>
                  </body>
                </body>
              </body>
            </body>
          </body>
        </body>
        <body name="Hip_Pitch_Right" pos="-0.000138967 -0.103195 0.000770037" quat="0.999999 -0.000679351 -0.000724955 -0.000353798">
          <inertial pos="0.00197864 0.00440359 -0.01843" quat="0.972441 -0.232631 0.0154588 -0.00173871" mass="0.887004" diaginertia="0.000373744 0.00115361 0.00305957"/>
          <joint name="Right_Hip_Pitch" pos="0 0 0" axis="0.00286986 -0.999995 -0.00155445" range="-1.60036 1.7858" armature="0.0110287" damping="0.0074004" frictionloss="0.0861435"/>
          <geom name="//unnamed_geom_47" class="visual" rgba="0.76 0.76 0.76 1" mesh="Hip_Pitch_Right"/>
          <body name="Hip_Roll_Right" pos="0.00154478 -0.00224633 -0.0255212" quat="1 -7.27467e-05 -9.49674e-05 -7.21203e-05">
            <inertial pos="0.00225106 0.0014167 -0.0608574" quat="0.709426 -0.0072051 -0.00755976 0.704703" mass="0.354346" diaginertia="0.000368437 0.00122823 0.00125241"/>
            <joint name="Right_Hip_Roll" pos="0 0 0" axis="-0.999888 0.0104581 -0.0106968" stiffness="0.00465852" range="-0.202253 1.54161" armature="0.009169" damping="0" frictionloss="0.0865895"/>
            <geom name="//unnamed_geom_48" class="visual" mesh="Hip_Roll_Right"/>
            <geom name="//unnamed_geom_49" class="reward_collision_sphere" size="0.0524731"/>
            <body name="Hip_Yaw_Right" pos="0.00192659 -0.00346606 -0.0951921" quat="0.999999 0.000168859 -0.00108228 8.75747e-05">
              <inertial pos="-0.00406712 -0.00347405 -0.10334" quat="0.717144 -0.0318492 -0.0289992 0.695592" mass="1.922" diaginertia="0.00517125 0.0197692 0.00598778"/>
              <joint name="Right_Hip_Yaw" pos="0 0 0" axis="-0.00263783 0.00417228 -0.999988" stiffness="0.0129503" range="-1.00448 1.00781" armature="0.00811852" damping="0.0150963" frictionloss="0.0904149"/>
              <geom name="//unnamed_geom_50" class="visual" mesh="Hip_Yaw_Right"/>
              <geom name="//unnamed_geom_51" class="collision" size="0.0477028 0.0763245" type="cylinder"/>
              <body name="Shank_Right" pos="-0.00836995 0.00217546 -0.160906" quat="0.999999 0.000426184 0.00122163 -0.000793378">
                <inertial pos="-0.00211387 -0.00149744 -0.14584" quat="0.998855 -0.00192127 -0.0267658 -0.0396077" mass="1.48037" diaginertia="0.00730317 0.0257171 0.00470078"/>
                <joint name="Right_Knee_Pitch" pos="0 0 0" axis="0.00206035 -0.999997 0.00092079" range="-2.3524 0.0552293" armature="0.00943876" damping="0.019351" frictionloss="0.0997188"/>
                <geom name="//unnamed_geom_52" class="visual" mesh="Shank_Right"/>
                <geom name="//unnamed_geom_53" class="collision" size="0.0477028 0.0715542" pos="0 0 -0.142525" type="cylinder"/>
                <geom name="//unnamed_geom_54" class="reward_collision_sphere" size="0.0620136"/>
                <body name="Ankle_Cross_Right" pos="0.00356694 0.00134738 -0.333666" quat="0.999999 0.000396446 -0.00074931 -0.000861178">
                  <inertial pos="-0.00152726 0.0029163 -0.00913636" quat="0.442844 0.550953 0.551246 0.443246" mass="0.063927" diaginertia="5.9028e-06 1.95402e-05 2.59626e-05"/>
                  <joint name="Right_Ankle_Pitch" pos="0 0 0" axis="0.00899253 -0.999914 0.00953988" stiffness="0.00523112" range="-0.370915 0.874073" armature="0.00900509" damping="0.0111116" frictionloss="0.0990101"/>
                  <geom name="//unnamed_geom_55" class="visual" mesh="Ankle_Cross_Right"/>
                  <body name="right_foot_link" pos="0.0033128 -0.00201069 -0.0124107" quat="1 -8.60827e-05 5.18984e-05 -0.000132376">
                    <inertial pos="-0.000264 0.00261217 -0.0109631" quat="0.00779971 0.625012 0.00702056 0.780544" mass="0.622263" diaginertia="0.000570083 0.0018634 0.00542566"/>
                    <joint name="Right_Ankle_Roll" pos="0 0 0" axis="-1 -0.000351394 0.000503219" stiffness="0.00101908" range="-0.429832 0.386109" armature="0.00918772" damping="0.00819175" frictionloss="0.0875091"/>
                    <geom name="//unnamed_geom_56" class="visual" mesh="right_foot_link"/>
                    <geom name="right_foot" class="foot" size="0.0973911 0.0493861 0.0148236" pos="0.00728571 0 -0.0178157"/>
                    <geom name="//unnamed_geom_58" class="reward_collision_sphere" size="0.0381622"/>
                    <geom name="//unnamed_geom_59" class="reward_collision_sphere" size="0.0286217" pos="0.00728571 0 -0.0178157"/>
                    <geom name="//unnamed_geom_60" class="reward_collision_sphere" size="0.0286217" pos="0.0692142 0.0217553 -0.0178157"/>
                    <geom name="//unnamed_geom_61" class="reward_collision_sphere" size="0.0286217" pos="-0.0509999 0.0217553 -0.0178157"/>
                    <site name="right_foot" class="foot" pos="0.00728571 0 -0.0178157" size="0.00954056"/>
                  </body>
                </body>
              </body>
            </body>
          </body>
        </body>
      </body>
    </body>
  </worldbody>

  <contact>
    <pair class="/" geom1="floor" geom2="left_foot" name="//unnamed_contact_0"/>
    <pair class="/" geom1="floor" geom2="right_foot" name="//unnamed_contact_1"/>
  </contact>

  <actuator>
    <general name="AAHead_yaw" class="/" joint="AAHead_yaw" forcerange="-6.44122 6.44122" gainprm="22.8681" biasprm="0 -22.8681 -0.599577"/>
    <general name="Head_pitch" class="/" joint="Head_pitch" forcerange="-6.92962 6.92962" gainprm="22.8681" biasprm="0 -22.8681 -0.599577"/>
    <general name="Left_Shoulder_Pitch" class="/" joint="Left_Shoulder_Pitch" forcerange="-16.4653 16.4653" gainprm="22.8681" biasprm="0 -22.8681 -0.599577"/>
    <general name="Left_Shoulder_Roll" class="/" joint="Left_Shoulder_Roll" forcerange="-16.7067 16.7067" gainprm="22.8681" biasprm="0 -22.8681 -0.599577"/>
    <general name="Left_Elbow_Pitch" class="/" joint="Left_Elbow_Pitch" forcerange="-15.7353 15.7353" gainprm="22.8681" biasprm="0 -22.8681 -0.599577"/>
    <general name="Left_Elbow_Yaw" class="/" joint="Left_Elbow_Yaw" forcerange="-17.1787 17.1787" gainprm="22.8681" biasprm="0 -22.8681 -0.599577"/>
    <general name="Right_Shoulder_Pitch" class="/" joint="Right_Shoulder_Pitch" forcerange="-17.4671 17.4671" gainprm="22.8681" biasprm="0 -22.8681 -0.599577"/>
    <general name="Right_Shoulder_Roll" class="/" joint="Right_Shoulder_Roll" forcerange="-16.9619 16.9619" gainprm="22.8681" biasprm="0 -22.8681 -0.599577"/>
    <general name="Right_Elbow_Pitch" class="/" joint="Right_Elbow_Pitch" forcerange="-15.5385 15.5385" gainprm="22.8681" biasprm="0 -22.8681 -0.599577"/>
    <general name="Right_Elbow_Yaw" class="/" joint="Right_Elbow_Yaw" forcerange="-15.4577 15.4577" gainprm="22.8681" biasprm="0 -22.8681 -0.599577"/>
    <general name="Waist" class="/" joint="Waist" forcerange="-26.0804 26.0804" gainprm="22.8681" biasprm="0 -22.8681 -0.599577"/>
    <general name="Left_Hip_Pitch" class="/" joint="Left_Hip_Pitch" forcerange="-44.3857 44.3857" gainprm="22.8681" biasprm="0 -22.8681 -0.599577"/>
    <general name="Left_Hip_Roll" class="/" joint="Left_Hip_Roll" forcerange="-26.0117 26.0117" gainprm="22.8681" biasprm="0 -22.8681 -0.599577"/>
    <general name="Left_Hip_Yaw" class="/" joint="Left_Hip_Yaw" forcerange="-26.0021 26.0021" gainprm="22.8681" biasprm="0 -22.8681 -0.599577"/>
    <general name="Left_Knee_Pitch" class="/" joint="Left_Knee_Pitch" forcerange="-60.5729 60.5729" gainprm="22.8681" biasprm="0 -22.8681 -0.599577"/>
    <general name="Left_Ankle_Pitch" class="/" joint="Left_Ankle_Pitch" forcerange="-20.3979 20.3979" gainprm="22.8681" biasprm="0 -22.8681 -0.599577"/>
    <general name="Left_Ankle_Roll" class="/" joint="Left_Ankle_Roll" forcerange="-13.0546 13.0546" gainprm="22.8681" biasprm="0 -22.8681 -0.599577"/>
    <general name="Right_Hip_Pitch" class="/" joint="Right_Hip_Pitch" forcerange="-41.8999 41.8999" gainprm="22.8681" biasprm="0 -22.8681 -0.599577"/>
    <general name="Right_Hip_Roll" class="/" joint="Right_Hip_Roll" forcerange="-31.0696 31.0696" gainprm="22.8681" biasprm="0 -22.8681 -0.599577"/>
    <general name="Right_Hip_Yaw" class="/" joint="Right_Hip_Yaw" forcerange="-25.6345 25.6345" gainprm="22.8681" biasprm="0 -22.8681 -0.599577"/>
    <general name="Right_Knee_Pitch" class="/" joint="Right_Knee_Pitch" forcerange="-51.0334 51.0334" gainprm="22.8681" biasprm="0 -22.8681 -0.599577"/>
    <general name="Right_Ankle_Pitch" class="/" joint="Right_Ankle_Pitch" forcerange="-19.581 19.581" gainprm="22.8681" biasprm="0 -22.8681 -0.599577"/>
    <general name="Right_Ankle_Roll" class="/" joint="Right_Ankle_Roll" forcerange="-15.7265 15.7265" gainprm="22.8681" biasprm="0 -22.8681 -0.599577"/>
  </actuator>

  <sensor>
    <gyro site="imu" name="imu_angular_velocity"/>
    <velocimeter site="imu" name="imu_linear_velocity"/>
    <framelinvel objtype="site" objname="left_foot" name="left_foot_global_linear_velocity"/>
    <framelinvel objtype="site" objname="right_foot" name="right_foot_global_linear_velocity"/>
  </sensor>

  <keyframe>
    <key name="home" qpos="0 0 0.6385 1 0 0 0 0 0 0 1.4 0 -0.4 0 -1.4 0 0.4 0 -0.4 0 0 0.8 -0.4 0 0.4 0 0 -0.8 0.4 0"/>
  </keyframe>
</mujoco>
