<mujoco model="T1">
  <compiler angle="radian" assetdir="assets" balanceinertia="true" inertiafromgeom="false"/>

  <option timestep="0.005" density="1.2" viscosity="2e-05"/>

  <size nkey="1"/>

  <visual>
    <quality shadowsize="8192"/>
    <map shadowclip="0.5"/>
  </visual>

  <default>
    <default class="/">
      <joint armature="0.01" damping="0.01" frictionloss="0.1"/>
      <geom contype="0" conaffinity="0" group="1" solref="-1000 -80"/>
      <site size="0.01 0.005 0.005" group="5"/>
      <general forcelimited="true" biastype="affine" gainprm="25" biasprm="0 -25 -0.6"/>
      <default class="t1">
        <geom rgba="0.25 0.25 0.25 1"/>
        <default class="visual">
          <geom type="mesh" group="2"/>
        </default>
        <default class="collision">
          <geom group="3"/>
        </default>
        <default class="foot">
          <geom size="0.1115 0.05 0.015" type="box" condim="6" group="4" priority="1" solimp="0.015 1 0.015"/>
        </default>
        <default class="reward_collision_sphere">
          <geom group="5" rgba="1 0 0 1"/>
        </default>
      </default>
    </default>
  </default>

  <asset>
    <texture type="skybox" colorspace="auto" name="//unnamed_texture_0" builtin="gradient" rgb1="0.95 0.95 0.95" rgb2="0.95 0.95 0.95" width="100" height="600"/>
    <texture type="2d" colorspace="auto" name="texplane" builtin="checker" rgb1="0.345 0.575 0.748" rgb2="0.345 0.575 0.748" markrgb="1 1 1" width="512" height="512"/>
    <material name="MatPlane" class="/" texture="texplane" texuniform="true" texrepeat="2 2" specular="0.9"/>
    <mesh name="Trunk" class="/" file="Trunk.stl"/>
    <mesh name="H1" class="/" file="H1.stl"/>
    <mesh name="H2" class="/" file="H2.stl"/>
    <mesh name="AL1" class="/" file="AL1.stl"/>
    <mesh name="AL2" class="/" file="AL2.stl"/>
    <mesh name="AL3" class="/" file="AL3.stl"/>
    <mesh name="left_hand_link" class="/" file="left_hand_link.stl"/>
    <mesh name="AR1" class="/" file="AR1.stl"/>
    <mesh name="AR2" class="/" file="AR2.stl"/>
    <mesh name="AR3" class="/" file="AR3.stl"/>
    <mesh name="right_hand_link" class="/" file="right_hand_link.stl"/>
    <mesh name="Waist" class="/" file="Waist.stl"/>
    <mesh name="Hip_Pitch_Left" class="/" file="Hip_Pitch_Left.stl"/>
    <mesh name="Hip_Roll_Left" class="/" file="Hip_Roll_Left.stl"/>
    <mesh name="Hip_Yaw_Left" class="/" file="Hip_Yaw_Left.stl"/>
    <mesh name="Shank_Left" class="/" file="Shank_Left.stl"/>
    <mesh name="Ankle_Cross_Left" class="/" file="Ankle_Cross_Left.stl"/>
    <mesh name="left_foot_link" class="/" file="left_foot_link.stl"/>
    <mesh name="Hip_Pitch_Right" class="/" file="Hip_Pitch_Right.stl"/>
    <mesh name="Hip_Roll_Right" class="/" file="Hip_Roll_Right.stl"/>
    <mesh name="Hip_Yaw_Right" class="/" file="Hip_Yaw_Right.stl"/>
    <mesh name="Shank_Right" class="/" file="Shank_Right.stl"/>
    <mesh name="Ankle_Cross_Right" class="/" file="Ankle_Cross_Right.stl"/>
    <mesh name="right_foot_link" class="/" file="right_foot_link.stl"/>
  </asset>

  <worldbody>
    <geom name="floor" class="/" size="100 100 0.125" type="plane" group="0" material="MatPlane"/>
    <light name="toplight_shadow" class="/" pos="0 0 5" dir="0.0990148 0.0990148 -0.990148" type="directional" ambient="0.04 0.04 0.04" diffuse="0.55 0.55 0.55" specular="0.12 0.12 0.12"/>
    <light name="toplight_fill" class="/" pos="0 0 5" dir="0.0990148 0.0990148 -0.990148" type="directional" castshadow="false" ambient="0.04 0.04 0.04" diffuse="0.3 0.3 0.3" specular="0.08 0.08 0.08"/>
    <body name="trunk" childclass="t1" pos="-0.000767217 -0.00105538 0.000143662" quat="0.999998 0.00111009 0.00135843 0.000463477">
      <inertial pos="0.0375885 0.00158542 0.0980503" quat="0.999991 0.00156821 -0.00359252 0.0013621" mass="5.3247" diaginertia="0.0114495 0.0111275 0.0451844"/>
      <joint name="//unnamed_joint_0" type="free" armature="0" damping="0" frictionloss="0"/>
      <geom name="//unnamed_geom_1" class="visual" rgba="0.76 0.76 0.76 1" mesh="Trunk"/>
      <geom name="//unnamed_geom_2" class="collision" size="0.0571839 0.0762453 0.114368" pos="0.0397432 0 0.113472" type="box"/>
      <geom name="//unnamed_geom_3" class="reward_collision_sphere" size="0.087682" pos="0.0397432 0 0.0945599"/>
      <geom name="//unnamed_geom_4" class="reward_collision_sphere" size="0.0114368" pos="0.0397432 0.0577466 0"/>
      <geom name="//unnamed_geom_5" class="reward_collision_sphere" size="0.0114368" pos="0.0397432 -0.0577466 0"/>
      <geom name="//unnamed_geom_6" class="reward_collision_sphere" size="0.0114368" pos="0.0397432 0.0726927 0.170208"/>
      <geom name="//unnamed_geom_7" class="reward_collision_sphere" size="0.0114368" pos="0.0397432 -0.0726927 0.170208"/>
      <site name="imu" pos="-0.00300376 0.0126021 0.00312075" size="0.00762453"/>
      <camera name="track" pos="0 -1.35874 0" quat="0.707107 0.707107 0 0" mode="trackcom"/>
      <camera name="ego_camera" pos="0.0808112 0 0.397152" quat="-0.5 -0.5 0.5 0.5"/>
      <body name="H1" pos="0.0383592 0.000933522 0.232883" quat="1 -0.000198996 0.000692108 -0.000407622">
        <inertial pos="-0.00156486 -0.00549091 0.0556226" quat="0.759216 -0.0265177 -0.00648433 0.650266" mass="0.20763" diaginertia="3.26486e-05 3.54259e-05 0.000121531"/>
        <joint name="AAHead_yaw" pos="0 0 0" axis="0.0164985 0.00643012 0.999843" range="-1.6153 1.5271" armature="0.00761306" damping="0.0119781" frictionloss="0.0793096"/>
        <geom name="//unnamed_geom_8" class="visual" mesh="H1"/>
        <body name="H2" pos="-0.0013389 -0.00384636 0.0597627" quat="0.999999 -0.00125209 -1.73872e-05 -0.000376933">
          <inertial pos="0.00162513 -0.0024265 0.0921748" quat="0.987443 0.105271 -0.0759887 -0.0900026" mass="0.272043" diaginertia="0.000246827 0.000281726 0.00127447"/>
          <joint name="Head_pitch" pos="0 0 0" axis="-0.0076965 -0.999964 -0.00352067" range="-1.22272 0.342926" armature="0.00909082" damping="0.00212164" frictionloss="0.0553118"/>
          <geom name="//unnamed_geom_9" class="visual" mesh="H2"/>
          <geom name="//unnamed_geom_10" class="collision" size="0.0609962" pos="0.00662387 0 0.104016"/>
          <geom name="//unnamed_geom_11" class="reward_collision_sphere" size="0.0686207" pos="0.0132477 0 0.0945599"/>
        </body>
      </body>
      <body name="AL1" pos="0.0378855 0.0781377 0.211308" quat="1 0.000101078 0.000366299 -2.96287e-05">
        <inertial pos="0.00322723 0.0322242 -0.00354075" quat="0.499503 0.49266 -0.505559 0.502189" mass="0.229112" diaginertia="0.000167885 0.000181733 0.000217957"/>
        <joint name="Left_Shoulder_Pitch" pos="0 0 0" axis="-0.00661223 0.999802 0.0187441" stiffness="0.00841547" range="-3.31492 1.20161" armature="0.00667939" damping="0.00553897" frictionloss="0.0735522"/>
        <geom name="//unnamed_geom_12" class="visual" rgba="0.76 0.76 0.76 1" mesh="AL1"/>
        <body name="AL2" pos="0.00481887 0.0368442 0.000639529" quat="1 -1.64881e-05 -3.53802e-07 -0.000106074">
          <inertial pos="0.00346259 0.0249178 0.00224969" quat="0.486618 0.506749 -0.489672 0.516361" mass="0.0752136" diaginertia="5.17196e-05 5.01339e-05 0.000137773"/>
          <joint name="Left_Shoulder_Roll" pos="0 0 0" axis="-0.999974 -0.00380198 0.00605142" range="-1.57722 1.78595" armature="0.00784926" damping="0.00908997" frictionloss="0.0789767"/>
          <geom name="//unnamed_geom_13" class="visual" mesh="AL2"/>
          <body name="AL3" pos="-0.000521062 0.0406888 0.00165953" quat="1 0.000320631 -9.69142e-05 -0.000128544">
            <inertial pos="-0.00068471 0.05756 0.000935871" quat="0.719651 0.694286 -0.00219563 -0.00809737" mass="0.435161" diaginertia="0.00161421 0.00178543 0.000485994"/>
            <joint name="Left_Elbow_Pitch" pos="0 0 0" axis="-0.00419805 -0.999991 -3.98636e-05" range="-2.31871 2.21906" armature="0.00736639" damping="0" frictionloss="0.0592752"/>
            <geom name="//unnamed_geom_14" class="visual" mesh="AL3"/>
            <geom name="//unnamed_geom_15" class="collision" size="0.0228736 0.0571839" pos="0 0.0339686 0" quat="0.707105 0.707108 0 0" type="cylinder"/>
            <geom name="//unnamed_geom_16" class="reward_collision_sphere" size="0.0274483"/>
            <body name="left_hand_link" pos="-0.00265626 0.0998583 -0.000107513" quat="0.999999 0.000874925 -0.000657155 -0.00041121">
              <inertial pos="-0.00291446 0.0750645 0.00291651" quat="0.708748 0.705374 0.00941806 -0.00602112" mass="0.145583" diaginertia="0.00105414 0.00113063 0.000158764"/>
              <joint name="Left_Elbow_Yaw" pos="0 0 0" axis="0.000737998 -0.0057898 0.999983" range="-2.45769 -0.0509142" armature="0.00763307" damping="0.0146934" frictionloss="0.0759349"/>
              <geom name="//unnamed_geom_17" class="visual" mesh="left_hand_link"/>
              <geom name="//unnamed_geom_18" class="collision" size="0.0228736 0.0667146" pos="0 0.0883183 0" quat="0.707105 0.707108 0 0" type="cylinder"/>
              <geom name="//unnamed_geom_19" class="reward_collision_sphere" size="0.0381226"/>
              <geom name="//unnamed_geom_20" class="reward_collision_sphere" size="0.0266858" pos="0 0.0747309 0"/>
              <geom name="//unnamed_geom_21" class="reward_collision_sphere" size="0.0266858" pos="0 0.146065 0"/>
            </body>
          </body>
        </body>
      </body>
      <body name="AR1" pos="0.035045 -0.0667934 0.205342" quat="0.999997 0.000516214 -0.00222095 -0.000321526">
        <inertial pos="-0.000784116 -0.0325877 0.00162423" quat="0.504657 0.494759 -0.504501 0.495998" mass="0.222559" diaginertia="0.000168148 0.000174837 0.000210847"/>
        <joint name="Right_Shoulder_Pitch" pos="0 0 0" axis="0.00466312 -0.999878 -0.0149217" range="-1.22354 3.29166" armature="0.00678841" damping="0.00251394" frictionloss="0.0704532"/>
        <geom name="//unnamed_geom_22" class="visual" rgba="0.76 0.76 0.76 1" mesh="AR1"/>
        <body name="AR2" pos="-0.000657582 -0.0286857 0.00383029" quat="1 -0.000634442 -2.80766e-05 0.000699674">
          <inertial pos="0.000514645 -0.0240622 -0.000888973" quat="0.510679 0.490303 -0.509922 0.488662" mass="0.0713344" diaginertia="5.13064e-05 5.08955e-05 0.000135874"/>
          <joint name="Right_Shoulder_Roll" pos="0 0 0" axis="-0.999901 0.0046542 -0.0132718" range="-1.76432 1.54782" armature="0.00774798" damping="0.0143334" frictionloss="0.068195"/>
          <geom name="//unnamed_geom_23" class="visual" mesh="AR2"/>
          <body name="AR3" pos="-0.000670006 -0.0416852 -0.000314987" quat="0.999999 -0.000482305 0.00104004 0.000723919">
            <inertial pos="-0.0055586 -0.0570425 0.00222121" quat="0.711381 0.702717 0.0110681 0.00167878" mass="0.445923" diaginertia="0.00157451 0.00169428 0.00043634"/>
            <joint name="Right_Elbow_Pitch" pos="0 0 0" axis="0.000221863 0.999994 -0.00334247" range="-2.30734 2.38658" armature="0.00743421" damping="0.00677198" frictionloss="0.0805787"/>
            <geom name="//unnamed_geom_24" class="visual" mesh="AR3"/>
            <geom name="//unnamed_geom_25" class="collision" size="0.0228736 0.0571839" pos="0 -0.0339686 0" quat="0.707105 0.707108 0 0" type="cylinder"/>
            <geom name="//unnamed_geom_26" class="reward_collision_sphere" size="0.0274483"/>
            <body name="right_hand_link" pos="-0.00178278 -0.0996896 -0.00324569" quat="0.999999 -0.000167439 9.56092e-05 0.000995292">
              <inertial pos="-0.00458827 -0.0722222 0.00368443" quat="0.705544 0.708656 0.000406175 -0.00371721" mass="0.158881" diaginertia="0.00118486 0.00125374 0.000164853"/>
              <joint name="Right_Elbow_Yaw" pos="0 0 0" axis="-0.0070382 0.00381081 0.999968" range="0.000316842 2.49448" armature="0.00694827" damping="0.0164964" frictionloss="0.0736133"/>
              <geom name="//unnamed_geom_27" class="visual" mesh="right_hand_link"/>
              <geom name="//unnamed_geom_28" class="collision" size="0.0228736 0.0667146" pos="0 -0.0883183 0" quat="0.707105 0.707108 0 0" type="cylinder"/>
              <geom name="//unnamed_geom_29" class="reward_collision_sphere" size="0.0381226"/>
              <geom name="//unnamed_geom_30" class="reward_collision_sphere" size="0.0266858" pos="0 -0.0747309 0"/>
              <geom name="//unnamed_geom_31" class="reward_collision_sphere" size="0.0266858" pos="0 -0.146065 0"/>
            </body>
          </body>
        </body>
      </body>
      <body name="Waist" pos="0.045187 0.0028429 -0.108005" quat="1 0.000183564 0.000263846 6.5919e-05">
        <inertial pos="0.00542885 -0.00178786 0.00493172" quat="0.983547 -0.00260499 -0.180632 -0.00103972" mass="1.17223" diaginertia="0.00066308 0.000759497 0.00363981"/>
        <joint name="Waist" pos="0 0 0" axis="0.00848479 0.00675313 0.999941" range="-1.59741 1.53604" armature="0.00819782" damping="0.0263998" frictionloss="0.0778469"/>
        <geom name="//unnamed_geom_32" class="visual" mesh="Waist"/>
        <body name="Hip_Pitch_Left" pos="0.000662029 0.0691125 5.32798e-05" quat="1 -0.000125875 -2.37447e-05 -1.78817e-05">
          <inertial pos="-0.00069069 -0.00389749 -0.0140962" quat="0.97674 0.214081 0.00945226 0.00765888" mass="0.454277" diaginertia="0.000226289 0.000208419 0.000927674"/>
          <joint name="Left_Hip_Pitch" pos="0 0 0" axis="-0.00401192 0.999963 0.00758663" stiffness="0.000654278" range="-1.75499 1.51829" armature="0.00667571" damping="0.0122232" frictionloss="0.0761423"/>
          <geom name="//unnamed_geom_33" class="visual" rgba="0.76 0.76 0.76 1" mesh="Hip_Pitch_Left"/>
          <body name="Hip_Roll_Left" pos="-0.00353364 -0.00363899 -0.0185406" quat="0.999999 -0.00113244 -0.000141992 -0.000124097">
            <inertial pos="-0.00151334 -0.00049204 -0.0486017" quat="0.709056 -0.00674308 0.00405547 0.705108" mass="0.166915" diaginertia="0.000209658 0.000219482 0.000394043"/>
            <joint name="Left_Hip_Roll" pos="0 0 0" axis="-0.99996 0.000924542 0.00887973" stiffness="0.0149489" range="-1.60223 0.127979" armature="0.00859255" damping="0.0174268" frictionloss="0.083767"/>
            <geom name="//unnamed_geom_34" class="visual" mesh="Hip_Roll_Left"/>
            <geom name="//unnamed_geom_35" class="reward_collision_sphere" size="0.0419349"/>
            <body name="Hip_Yaw_Left" pos="-0.000301046 -0.00428257 -0.0838593" quat="1 -0.000455122 -0.000163108 0.00041123">
              <inertial pos="-0.00544473 -0.000387469 -0.0822611" quat="0.702447 -0.0240774 -0.0316855 0.710623" mass="0.992885" diaginertia="0.00341856 0.0039114 0.00201359"/>
              <joint name="Left_Hip_Yaw" pos="0 0 0" axis="-0.000959563 0.00361547 -0.999993" range="-1.06904 0.894623" armature="0.0078087" damping="0.036647" frictionloss="0.0730592"/>
              <geom name="//unnamed_geom_36" class="visual" mesh="Hip_Yaw_Left"/>
              <geom name="//unnamed_geom_37" class="collision" size="0.0381226 0.0609962" type="cylinder"/>
              <body name="Shank_Left" pos="-0.00823482 -0.00345209 -0.123423" quat="1 0.000386549 0.000129502 0.000130542">
                <inertial pos="-0.00462108 0.00113106 -0.115374" quat="0.996948 0.0108317 -0.0236379 0.0736059" mass="0.738833" diaginertia="0.00430087 0.00489105 0.00140796"/>
                <joint name="Left_Knee_Pitch" pos="0 0 0" axis="0.0111943 0.999922 -0.00559867" range="0.010747 2.32787" armature="0.00781345" damping="0" frictionloss="0.0671922"/>
                <geom name="//unnamed_geom_38" class="visual" mesh="Shank_Left"/>
                <geom name="//unnamed_geom_39" class="collision" size="0.0381226 0.0571839" pos="0 0 -0.113472" type="cylinder"/>
                <geom name="//unnamed_geom_40" class="reward_collision_sphere" size="0.0495594"/>
                <body name="Ankle_Cross_Left" pos="-0.00363352 -0.00350788 -0.263128" quat="0.999999 -0.00134668 -0.000119108 -0.000342716">
                  <inertial pos="0.00120158 -0.00357936 -0.00813805" quat="0.442586 0.552368 0.548063 0.445683" mass="0.0324736" diaginertia="3.69922e-06 3.86651e-06 8.49729e-06"/>
                  <joint name="Left_Ankle_Pitch" pos="0 0 0" axis="-0.00541509 0.999955 -0.00784193" stiffness="0.00403121" range="-0.868794 0.39946" armature="0.0088067" damping="0.0171343" frictionloss="0.078061"/>
                  <geom name="//unnamed_geom_41" class="visual" mesh="Ankle_Cross_Left"/>
                  <body name="left_foot_link" pos="-0.00278029 0.000183726 -0.0147788" quat="0.999997 -0.00161085 0.000655048 -0.0015078">
                    <inertial pos="0.00335324 -6.50427e-05 -0.0104604" quat="0.00282076 0.619113 -0.00113331 0.785296" mass="0.298596" diaginertia="0.000340779 0.000350537 0.00159077"/>
                    <joint name="Left_Ankle_Roll" pos="0 0 0" axis="-0.999984 0.00564171 -0.000818613" stiffness="0.0101567" range="-0.379205 0.514987" armature="0.00792638" damping="0" frictionloss="0.0894193"/>
                    <geom name="//unnamed_geom_42" class="visual" mesh="left_foot_link"/>
                    <geom name="left_foot" class="foot" size="0.0963281 0.0377356 0.0104343" pos="0.00662387 0 -0.014184"/>
                    <geom name="//unnamed_geom_44" class="reward_collision_sphere" size="0.0396475" pos="0.00662387 0 -0.014184"/>
                    <geom name="//unnamed_geom_45" class="reward_collision_sphere" size="0.0228736" pos="0.0629268 -0.0156255 -0.014184"/>
                    <geom name="//unnamed_geom_46" class="reward_collision_sphere" size="0.0228736" pos="-0.0463671 -0.0156255 -0.014184"/>
                    <site name="left_foot" class="foot" pos="0.00662387 0 -0.014184" size="0.00762453"/>
                  </body>
                </body>
              </body>
            </body>
          </body>
        </body>
        <body name="Hip_Pitch_Right" pos="0.00562435 -0.0711574 -0.000278419" quat="0.999999 0.000537675 -0.000342985 0.00129476">
          <inertial pos="0.00172334 0.00627769 -0.0167632" quat="0.975065 -0.221361 0.0155393 0.00258436" mass="0.455597" diaginertia="0.000221415 0.000214168 0.000897561"/>
          <joint name="Right_Hip_Pitch" pos="0 0 0" axis="-0.00377163 -0.999975 -0.00600048" range="-1.60915 1.82599" armature="0.00743007" damping="0.0128128" frictionloss="0.0699059"/>
          <geom name="//unnamed_geom_47" class="visual" rgba="0.76 0.76 0.76 1" mesh="Hip_Pitch_Right"/>
          <body name="Hip_Roll_Right" pos="-0.00388879 0.00258413 -0.0170513" quat="1 -5.73636e-05 7.68691e-05 5.2304e-05">
            <inertial pos="0.00256554 0.00166188 -0.0514766" quat="0.707185 -0.00242408 -0.00322093 0.707017" mass="0.163796" diaginertia="0.000224056 0.00021705 0.000393546"/>
            <joint name="Right_Hip_Roll" pos="0 0 0" axis="-0.999941 0.00786513 -0.00746995" range="-0.198038 1.66482" armature="0.00863009" damping="0.0248557" frictionloss="0.0920619"/>
            <geom name="//unnamed_geom_48" class="visual" mesh="Hip_Roll_Right"/>
            <geom name="//unnamed_geom_49" class="reward_collision_sphere" size="0.0419349"/>
            <body name="Hip_Yaw_Right" pos="-0.00333551 -0.00144927 -0.078393" quat="1 0.000527587 7.61879e-05 -4.39864e-05">
              <inertial pos="-0.00696721 0.000144436 -0.0847458" quat="0.70825 -0.0081291 -0.024821 0.705479" mass="0.979398" diaginertia="0.00346191 0.00367112 0.00206251"/>
              <joint name="Right_Hip_Yaw" pos="0 0 0" axis="0.0212971 -0.0158127 -0.999648" range="-0.997361 1.00352" armature="0.00822813" damping="0" frictionloss="0.0823514"/>
              <geom name="//unnamed_geom_50" class="visual" mesh="Hip_Yaw_Right"/>
              <geom name="//unnamed_geom_51" class="collision" size="0.0381226 0.0609962" type="cylinder"/>
              <body name="Shank_Right" pos="-0.0127849 -0.00351627 -0.127541" quat="1 2.31412e-05 -4.47644e-05 6.21899e-05">
                <inertial pos="-0.00343934 0.00182151 -0.114118" quat="0.998919 -0.0108781 -0.0385654 -0.0235581" mass="0.760389" diaginertia="0.00429068 0.00498682 0.00145423"/>
                <joint name="Right_Knee_Pitch" pos="0 0 0" axis="-0.0161016 -0.999869 0.0018577" stiffness="0.0209915" range="-2.32124 -0.0103131" armature="0.0075563" damping="0" frictionloss="0.0719738"/>
                <geom name="//unnamed_geom_52" class="visual" mesh="Shank_Right"/>
                <geom name="//unnamed_geom_53" class="collision" size="0.0381226 0.0571839" pos="0 0 -0.113472" type="cylinder"/>
                <geom name="//unnamed_geom_54" class="reward_collision_sphere" size="0.0495594"/>
                <body name="Ankle_Cross_Right" pos="0.00403091 -0.00280211 -0.261028" quat="0.999999 -5.26664e-05 -0.00113502 -0.000617235">
                  <inertial pos="-0.00441613 -0.00151052 -0.00772039" quat="0.443138 0.550836 0.551457 0.442835" mass="0.0319831" diaginertia="3.95793e-06 3.72884e-06 8.70339e-06"/>
                  <joint name="Right_Ankle_Pitch" pos="0 0 0" axis="-0.00130569 -0.999994 0.00322039" stiffness="0.00556807" range="-0.238315 0.866514" armature="0.00824037" damping="0.00562736" frictionloss="0.0674036"/>
                  <geom name="//unnamed_geom_55" class="visual" mesh="Ankle_Cross_Right"/>
                  <body name="right_foot_link" pos="-0.000709997 -0.00415161 -0.0108885" quat="1 -4.08408e-05 1.07399e-05 6.10672e-05">
                    <inertial pos="-0.000174247 -0.00160425 -0.0091642" quat="-0.00511656 0.621221 0.00230305 0.783616" mass="0.274876" diaginertia="0.000324787 0.000334256 0.00165548"/>
                    <joint name="Right_Ankle_Roll" pos="0 0 0" axis="-0.999933 -0.00622991 -0.00978164" range="-0.487812 0.428356" armature="0.00811742" damping="0.00983344" frictionloss="0.0934715"/>
                    <geom name="//unnamed_geom_56" class="visual" mesh="right_foot_link"/>
                    <geom name="right_foot" class="foot" size="0.0940265 0.0435856 0.0107938" pos="0.00662387 0 -0.014184"/>
                    <geom name="//unnamed_geom_58" class="reward_collision_sphere" size="0.0304981"/>
                    <geom name="//unnamed_geom_59" class="reward_collision_sphere" size="0.0228736" pos="0.00662387 0 -0.014184"/>
                    <geom name="//unnamed_geom_60" class="reward_collision_sphere" size="0.0228736" pos="0.0629268 0.0156255 -0.014184"/>
                    <geom name="//unnamed_geom_61" class="reward_collision_sphere" size="0.0228736" pos="-0.0463671 0.0156255 -0.014184"/>
                    <site name="right_foot" class="foot" pos="0.00662387 0 -0.014184" size="0.00762453"/>
                  </body>
                </body>
              </body>
            </body>
          </body>
        </body>
      </body>
    </body>
  </worldbody>

  <contact>
    <pair class="/" geom1="floor" geom2="left_foot" name="//unnamed_contact_0"/>
    <pair class="/" geom1="floor" geom2="right_foot" name="//unnamed_contact_1"/>
  </contact>

  <actuator>
    <general name="AAHead_yaw" class="/" joint="AAHead_yaw" forcerange="-4.88608 4.88608" gainprm="21.3186" biasprm="0 -21.3186 -0.463418"/>
    <general name="Head_pitch" class="/" joint="Head_pitch" forcerange="-5.80429 5.80429" gainprm="21.3186" biasprm="0 -21.3186 -0.463418"/>
    <general name="Left_Shoulder_Pitch" class="/" joint="Left_Shoulder_Pitch" forcerange="-16.6122 16.6122" gainprm="21.3186" biasprm="0 -21.3186 -0.463418"/>
    <general name="Left_Shoulder_Roll" class="/" joint="Left_Shoulder_Roll" forcerange="-14.1352 14.1352" gainprm="21.3186" biasprm="0 -21.3186 -0.463418"/>
    <general name="Left_Elbow_Pitch" class="/" joint="Left_Elbow_Pitch" forcerange="-13.1857 13.1857" gainprm="21.3186" biasprm="0 -21.3186 -0.463418"/>
    <general name="Left_Elbow_Yaw" class="/" joint="Left_Elbow_Yaw" forcerange="-13.8921 13.8921" gainprm="21.3186" biasprm="0 -21.3186 -0.463418"/>
    <general name="Right_Shoulder_Pitch" class="/" joint="Right_Shoulder_Pitch" forcerange="-12.5921 12.5921" gainprm="21.3186" biasprm="0 -21.3186 -0.463418"/>
    <general name="Right_Shoulder_Roll" class="/" joint="Right_Shoulder_Roll" forcerange="-13.8691 13.8691" gainprm="21.3186" biasprm="0 -21.3186 -0.463418"/>
    <general name="Right_Elbow_Pitch" class="/" joint="Right_Elbow_Pitch" forcerange="-13.4268 13.4268" gainprm="21.3186" biasprm="0 -21.3186 -0.463418"/>
    <general name="Right_Elbow_Yaw" class="/" joint="Right_Elbow_Yaw" forcerange="-13.3706 13.3706" gainprm="21.3186" biasprm="0 -21.3186 -0.463418"/>
    <general name="Waist" class="/" joint="Waist" forcerange="-22.3297 22.3297" gainprm="21.3186" biasprm="0 -21.3186 -0.463418"/>
    <general name="Left_Hip_Pitch" class="/" joint="Left_Hip_Pitch" forcerange="-32.5012 32.5012" gainprm="21.3186" biasprm="0 -21.3186 -0.463418"/>
    <general name="Left_Hip_Roll" class="/" joint="Left_Hip_Roll" forcerange="-22.0502 22.0502" gainprm="21.3186" biasprm="0 -21.3186 -0.463418"/>
    <general name="Left_Hip_Yaw" class="/" joint="Left_Hip_Yaw" forcerange="-22.1258 22.1258" gainprm="21.3186" biasprm="0 -21.3186 -0.463418"/>
    <general name="Left_Knee_Pitch" class="/" joint="Left_Knee_Pitch" forcerange="-48.4123 48.4123" gainprm="21.3186" biasprm="0 -21.3186 -0.463418"/>
    <general name="Left_Ankle_Pitch" class="/" joint="Left_Ankle_Pitch" forcerange="-12.8729 12.8729" gainprm="21.3186" biasprm="0 -21.3186 -0.463418"/>
    <general name="Left_Ankle_Roll" class="/" joint="Left_Ankle_Roll" forcerange="-12.7227 12.7227" gainprm="21.3186" biasprm="0 -21.3186 -0.463418"/>
    <general name="Right_Hip_Pitch" class="/" joint="Right_Hip_Pitch" forcerange="-35.1377 35.1377" gainprm="21.3186" biasprm="0 -21.3186 -0.463418"/>
    <general name="Right_Hip_Roll" class="/" joint="Right_Hip_Roll" forcerange="-20.2349 20.2349" gainprm="21.3186" biasprm="0 -21.3186 -0.463418"/>
    <general name="Right_Hip_Yaw" class="/" joint="Right_Hip_Yaw" forcerange="-23.9428 23.9428" gainprm="21.3186" biasprm="0 -21.3186 -0.463418"/>
    <general name="Right_Knee_Pitch" class="/" joint="Right_Knee_Pitch" forcerange="-46.3072 46.3072" gainprm="21.3186" biasprm="0 -21.3186 -0.463418"/>
    <general name="Right_Ankle_Pitch" class="/" joint="Right_Ankle_Pitch" forcerange="-14.8582 14.8582" gainprm="21.3186" biasprm="0 -21.3186 -0.463418"/>
    <general name="Right_Ankle_Roll" class="/" joint="Right_Ankle_Roll" forcerange="-10.5191 10.5191" gainprm="21.3186" biasprm="0 -21.3186 -0.463418"/>
  </actuator>

  <sensor>
    <gyro site="imu" name="imu_angular_velocity"/>
    <velocimeter site="imu" name="imu_linear_velocity"/>
    <framelinvel objtype="site" objname="left_foot" name="left_foot_global_linear_velocity"/>
    <framelinvel objtype="site" objname="right_foot" name="right_foot_global_linear_velocity"/>
  </sensor>

  <keyframe>
    <key name="home" qpos="0 0 0.6385 1 0 0 0 0 0 0 1.4 0 -0.4 0 -1.4 0 0.4 0 -0.4 0 0 0.8 -0.4 0 0.4 0 0 -0.8 0.4 0"/>
  </keyframe>
</mujoco>
