<mujoco model="T1">
  <compiler angle="radian" assetdir="assets" balanceinertia="true" inertiafromgeom="false"/>

  <option timestep="0.005" density="1.2" viscosity="2e-05"/>

  <size nkey="1"/>

  <visual>
    <quality shadowsize="8192"/>
    <map shadowclip="0.5"/>
  </visual>

  <default>
    <default class="/">
      <joint armature="0.01" damping="0.01" frictionloss="0.1"/>
      <geom contype="0" conaffinity="0" group="1" solref="-1000 -80"/>
      <site size="0.01 0.005 0.005" group="5"/>
      <general forcelimited="true" biastype="affine" gainprm="25" biasprm="0 -25 -0.6"/>
      <default class="t1">
        <geom rgba="0.25 0.25 0.25 1"/>
        <default class="visual">
          <geom type="mesh" group="2"/>
        </default>
        <default class="collision">
          <geom group="3"/>
        </default>
        <default class="foot">
          <geom size="0.1115 0.05 0.015" type="box" condim="6" group="4" priority="1" solimp="0.015 1 0.015"/>
        </default>
        <default class="reward_collision_sphere">
          <geom group="5" rgba="1 0 0 1"/>
        </default>
      </default>
    </default>
  </default>

  <asset>
    <texture type="skybox" colorspace="auto" name="//unnamed_texture_0" builtin="gradient" rgb1="0.95 0.95 0.95" rgb2="0.95 0.95 0.95" width="100" height="600"/>
    <texture type="2d" colorspace="auto" name="texplane" builtin="checker" rgb1="0.345 0.575 0.748" rgb2="0.345 0.575 0.748" markrgb="1 1 1" width="512" height="512"/>
    <material name="MatPlane" class="/" texture="texplane" texuniform="true" texrepeat="2 2" specular="0.9"/>
    <mesh name="Trunk" class="/" file="Trunk.stl"/>
    <mesh name="H1" class="/" file="H1.stl"/>
    <mesh name="H2" class="/" file="H2.stl"/>
    <mesh name="AL1" class="/" file="AL1.stl"/>
    <mesh name="AL2" class="/" file="AL2.stl"/>
    <mesh name="AL3" class="/" file="AL3.stl"/>
    <mesh name="left_hand_link" class="/" file="left_hand_link.stl"/>
    <mesh name="AR1" class="/" file="AR1.stl"/>
    <mesh name="AR2" class="/" file="AR2.stl"/>
    <mesh name="AR3" class="/" file="AR3.stl"/>
    <mesh name="right_hand_link" class="/" file="right_hand_link.stl"/>
    <mesh name="Waist" class="/" file="Waist.stl"/>
    <mesh name="Hip_Pitch_Left" class="/" file="Hip_Pitch_Left.stl"/>
    <mesh name="Hip_Roll_Left" class="/" file="Hip_Roll_Left.stl"/>
    <mesh name="Hip_Yaw_Left" class="/" file="Hip_Yaw_Left.stl"/>
    <mesh name="Shank_Left" class="/" file="Shank_Left.stl"/>
    <mesh name="Ankle_Cross_Left" class="/" file="Ankle_Cross_Left.stl"/>
    <mesh name="left_foot_link" class="/" file="left_foot_link.stl"/>
    <mesh name="Hip_Pitch_Right" class="/" file="Hip_Pitch_Right.stl"/>
    <mesh name="Hip_Roll_Right" class="/" file="Hip_Roll_Right.stl"/>
    <mesh name="Hip_Yaw_Right" class="/" file="Hip_Yaw_Right.stl"/>
    <mesh name="Shank_Right" class="/" file="Shank_Right.stl"/>
    <mesh name="Ankle_Cross_Right" class="/" file="Ankle_Cross_Right.stl"/>
    <mesh name="right_foot_link" class="/" file="right_foot_link.stl"/>
  </asset>

  <worldbody>
    <geom name="floor" class="/" size="100 100 0.125" type="plane" group="0" material="MatPlane"/>
    <light name="toplight_shadow" class="/" pos="0 0 5" dir="0.0990148 0.0990148 -0.990148" type="directional" ambient="0.04 0.04 0.04" diffuse="0.55 0.55 0.55" specular="0.12 0.12 0.12"/>
    <light name="toplight_fill" class="/" pos="0 0 5" dir="0.0990148 0.0990148 -0.990148" type="directional" castshadow="false" ambient="0.04 0.04 0.04" diffuse="0.3 0.3 0.3" specular="0.08 0.08 0.08"/>
    <body name="trunk" childclass="t1" pos="-0.000254148 0.000644493 0.000272039" quat="1 -0.000537701 0.00012377 -0.000791542">
      <inertial pos="0.0457528 -0.00200272 0.115817" quat="0.999975 0.000538683 -0.00698618 -0.00085328" mass="11.4829" diaginertia="0.044176 0.0892171 0.0852382"/>
      <joint name="//unnamed_joint_0" type="free" armature="0" damping="0" frictionloss="0"/>
      <geom name="//unnamed_geom_1" class="visual" rgba="0.76 0.76 0.76 1" mesh="Trunk"/>
      <geom name="//unnamed_geom_2" class="collision" size="0.0746244 0.0994992 0.149249" pos="0.0517589 0 0.131323" type="box"/>
      <geom name="//unnamed_geom_3" class="reward_collision_sphere" size="0.114424" pos="0.0517589 0 0.109436"/>
      <geom name="//unnamed_geom_4" class="reward_collision_sphere" size="0.0149249" pos="0.0517589 0.0873776 0"/>
      <geom name="//unnamed_geom_5" class="reward_collision_sphere" size="0.0149249" pos="0.0517589 -0.0873776 0"/>
      <geom name="//unnamed_geom_6" class="reward_collision_sphere" size="0.0149249" pos="0.0517589 0.109993 0.196984"/>
      <geom name="//unnamed_geom_7" class="reward_collision_sphere" size="0.0149249" pos="0.0517589 -0.109993 0.196984"/>
      <site name="imu" pos="0.00200705 -0.00260899 -0.00207857" size="0.00994992"/>
      <camera name="track" pos="0 -2.05594 0" quat="0.707107 0.707107 0 0" mode="trackcom"/>
      <camera name="ego_camera" pos="0.105243 0 0.45963" quat="-0.5 -0.5 0.5 0.5"/>
      <body name="H1" pos="0.0541132 -0.000930658 0.264422" quat="1 0.000236658 0.000464282 6.80521e-05">
        <inertial pos="-0.00104567 0.000446075 0.0619829" quat="0.766014 -0.00458499 0.000765109 0.642807" mass="0.427506" diaginertia="0.000112505 0.00024575 0.000227705"/>
        <joint name="AAHead_yaw" pos="0 0 0" axis="-0.00163088 0.00920147 0.999956" stiffness="0.00625806" range="-1.55349 1.56832" armature="0.0100355" damping="0.00897397" frictionloss="0.0986257"/>
        <geom name="//unnamed_geom_8" class="visual" mesh="H1"/>
        <body name="H2" pos="-0.00077633 0.00178453 0.0683434" quat="1 -2.81078e-05 1.66867e-05 2.1842e-06">
          <inertial pos="0.00529612 0.00246756 0.10782" quat="0.988447 0.106289 -0.0744507 -0.0783106" mass="0.619144" diaginertia="0.000984052 0.00216952 0.00268879"/>
          <joint name="Head_pitch" pos="0 0 0" axis="-0.00494467 -0.999988 5.37071e-05" range="-1.21906 0.348803" armature="0.00895582" damping="0.00627553" frictionloss="0.111365"/>
          <geom name="//unnamed_geom_9" class="visual" mesh="H2"/>
          <geom name="//unnamed_geom_10" class="collision" size="0.0795994" pos="0.00862649 0 0.120379"/>
          <geom name="//unnamed_geom_11" class="reward_collision_sphere" size="0.0895493" pos="0.017253 0 0.109436"/>
        </body>
      </body>
      <body name="AL1" pos="0.051757 0.108326 0.237613" quat="1 1.08527e-05 0.00040813 -5.19332e-05">
        <inertial pos="-0.00274777 0.0466658 0.00109274" quat="0.50332 0.49783 -0.50284 0.49597" mass="0.524123" diaginertia="0.000650335 0.00148674 0.000454858"/>
        <joint name="Left_Shoulder_Pitch" pos="0 0 0" axis="-0.00508167 0.999933 0.0104396" range="-3.31584 1.23387" armature="0.00998576" damping="0.00695468" frictionloss="0.0983656"/>
        <geom name="//unnamed_geom_12" class="visual" rgba="0.76 0.76 0.76 1" mesh="AL1"/>
        <body name="AL2" pos="0.000102757 0.047929 -0.000642283" quat="1 2.95009e-06 9.0756e-06 0.00011952">
          <inertial pos="0.00292873 0.0395509 -0.00152551" quat="0.486928 0.514736 -0.489041 0.508712" mass="0.157619" diaginertia="0.000190625 0.000394967 0.00027869"/>
          <joint name="Left_Shoulder_Roll" pos="0 0 0" axis="-1 -0.000414085 0.000650935" range="-1.57021 1.74553" armature="0.010098" damping="0.00612376" frictionloss="0.100494"/>
          <geom name="//unnamed_geom_13" class="visual" mesh="AL2"/>
          <body name="AL3" pos="0.000483687 0.0619498 -0.000311489" quat="1 -3.33824e-05 -5.08514e-05 -0.000122113">
            <inertial pos="-0.000142956 0.0876603 0.000127847" quat="0.713475 0.700675 0.00155834 0.00253344" mass="1.00207" diaginertia="0.00610103 0.0147266 0.000946873"/>
            <joint name="Left_Elbow_Pitch" pos="0 0 0" axis="-0.000473248 -0.999999 -0.00131052" range="-2.25306 2.26959" armature="0.00996736" damping="0.022403" frictionloss="0.11034"/>
            <geom name="//unnamed_geom_14" class="visual" mesh="AL3"/>
            <geom name="//unnamed_geom_15" class="collision" size="0.0298498 0.0746244" pos="0 0.0513986 0" quat="0.707105 0.707108 0 0" type="cylinder"/>
            <geom name="//unnamed_geom_16" class="reward_collision_sphere" size="0.0358197"/>
            <body name="left_hand_link" pos="0.00222796 0.151805 0.00110883" quat="1 1.80571e-05 3.53249e-05 4.06322e-05">
              <inertial pos="0.00162664 0.112502 -0.00100371" quat="0.705574 0.708626 0.00369578 0.000508305" mass="0.32152" diaginertia="0.00386891 0.00955442 0.000341303"/>
              <joint name="Left_Elbow_Yaw" pos="0 0 0" axis="-0.000307085 -8.28344e-05 1" range="-2.45489 0.0156602" armature="0.00993816" damping="0.00826832" frictionloss="0.0992285"/>
              <geom name="//unnamed_geom_17" class="visual" mesh="left_hand_link"/>
              <geom name="//unnamed_geom_18" class="collision" size="0.0298498 0.0870618" pos="0 0.133636 0" quat="0.707105 0.707108 0 0" type="cylinder"/>
              <geom name="//unnamed_geom_19" class="reward_collision_sphere" size="0.0497496"/>
              <geom name="//unnamed_geom_20" class="reward_collision_sphere" size="0.0348247" pos="0 0.113077 0"/>
              <geom name="//unnamed_geom_21" class="reward_collision_sphere" size="0.0348247" pos="0 0.221014 0"/>
            </body>
          </body>
        </body>
      </body>
      <body name="AR1" pos="0.0485346 -0.110144 0.240086" quat="0.999999 -0.00103941 0.000298901 -0.000450606">
        <inertial pos="-0.00141825 -0.0454992 -0.000988398" quat="0.50506 0.49588 -0.50301 0.495983" mass="0.535015" diaginertia="0.000663213 0.00151273 0.000470668"/>
        <joint name="Right_Shoulder_Pitch" pos="0 0 0" axis="-0.000113902 -0.999998 -0.00201308" range="-1.22599 3.30763" armature="0.010445" damping="7.98768e-05" frictionloss="0.103836"/>
        <geom name="//unnamed_geom_22" class="visual" rgba="0.76 0.76 0.76 1" mesh="AR1"/>
        <body name="AR2" pos="-0.000738516 -0.0474013 -0.00196582" quat="1 -0.000120841 0.00035467 0.000703787">
          <inertial pos="0.00438137 -0.0398933 0.000622168" quat="0.512842 0.486286 -0.51166 0.488593" mass="0.157115" diaginertia="0.000190442 0.000391889 0.000276221"/>
          <joint name="Right_Shoulder_Roll" pos="0 0 0" axis="-0.999967 -0.00395906 0.00711416" range="-1.72286 1.58655" armature="0.0099785" damping="0.000757154" frictionloss="0.0976876"/>
          <geom name="//unnamed_geom_23" class="visual" mesh="AR2"/>
          <body name="AR3" pos="-0.000755245 -0.0628116 -0.00062655" quat="1 -0.000712856 0.000276299 0.0003878">
            <inertial pos="0.00200344 -0.087364 -0.000939086" quat="0.707464 0.706749 -0.000643521 -0.000329705" mass="1.00558" diaginertia="0.00631223 0.0152839 0.00100444"/>
            <joint name="Right_Elbow_Pitch" pos="0 0 0" axis="0.00162468 0.999997 -0.0015828" stiffness="0.00336475" range="-2.25162 2.22001" armature="0.0100084" damping="0.0113682" frictionloss="0.096039"/>
            <geom name="//unnamed_geom_24" class="visual" mesh="AR3"/>
            <geom name="//unnamed_geom_25" class="collision" size="0.0298498 0.0746244" pos="0 -0.0513986 0" quat="0.707105 0.707108 0 0" type="cylinder"/>
            <geom name="//unnamed_geom_26" class="reward_collision_sphere" size="0.0358197"/>
            <body name="right_hand_link" pos="-0.000477646 -0.151074 0.000903812" quat="1 -0.00064102 0.000304139 -1.88887e-05">
              <inertial pos="0.00171508 -0.113674 -0.0005584" quat="0.706727 0.707486 3.11074e-05 0.000320472" mass="0.309427" diaginertia="0.00367055 0.00905147 0.000335636"/>
              <joint name="Right_Elbow_Yaw" pos="0 0 0" axis="0.00116472 -0.000296109 0.999999" stiffness="0.0026196" range="-0.00505793 2.40659" armature="0.0104061" damping="0.00494834" frictionloss="0.100599"/>
              <geom name="//unnamed_geom_27" class="visual" mesh="right_hand_link"/>
              <geom name="//unnamed_geom_28" class="collision" size="0.0298498 0.0870618" pos="0 -0.133636 0" quat="0.707105 0.707108 0 0" type="cylinder"/>
              <geom name="//unnamed_geom_29" class="reward_collision_sphere" size="0.0497496"/>
              <geom name="//unnamed_geom_30" class="reward_collision_sphere" size="0.0348247" pos="0 -0.113077 0"/>
              <geom name="//unnamed_geom_31" class="reward_collision_sphere" size="0.0348247" pos="0 -0.221014 0"/>
            </body>
          </body>
        </body>
      </body>
      <body name="Waist" pos="0.0535567 -0.00281176 -0.126817" quat="1 5.34829e-05 -0.000196168 4.04043e-05">
        <inertial pos="0.000534548 0.000433612 0.00776539" quat="0.983764 0.00195586 -0.179458 8.49474e-05" mass="2.50433" diaginertia="0.0025953 0.00611838 0.00737127"/>
        <joint name="Waist" pos="0 0 0" axis="-0.00321261 -0.00518157 0.999981" stiffness="0.00203477" range="-1.55342 1.59045" armature="0.0102363" damping="0.000646227" frictionloss="0.0982134"/>
        <geom name="//unnamed_geom_32" class="visual" mesh="Waist"/>
        <body name="Hip_Pitch_Left" pos="0.00134809 0.109652 0.000142758" quat="1 0.000150818 -7.46908e-06 0.000175787">
          <inertial pos="0.00156812 -0.00726195 -0.0216864" quat="0.976034 0.217175 0.0131153 0.00454096" mass="1.02222" diaginertia="0.000870426 0.00169038 0.00198323"/>
          <joint name="Left_Hip_Pitch" pos="0 0 0" axis="-0.00054978 1 -0.000195877" range="-1.80286 1.60239" armature="0.0102574" damping="0.00264078" frictionloss="0.0984269"/>
          <geom name="//unnamed_geom_33" class="visual" rgba="0.76 0.76 0.76 1" mesh="Hip_Pitch_Left"/>
          <body name="Hip_Roll_Left" pos="0.00243941 0.000171435 -0.0231459" quat="1 -7.44646e-06 -1.75697e-06 -4.3635e-06">
            <inertial pos="0.00109866 0.000563622 -0.0601167" quat="0.707335 -0.00732806 -0.00731817 0.706803" mass="0.387755" diaginertia="0.000857596 0.00173935 0.000804352"/>
            <joint name="Left_Hip_Roll" pos="0 0 0" axis="-0.999997 -0.00112668 -0.00197106" range="-1.55073 0.241008" armature="0.0099235" damping="0.00465326" frictionloss="0.101823"/>
            <geom name="//unnamed_geom_34" class="visual" mesh="Hip_Roll_Left"/>
            <geom name="//unnamed_geom_35" class="reward_collision_sphere" size="0.0547246"/>
            <body name="Hip_Yaw_Left" pos="-0.000265405 0.0013812 -0.0877295" quat="1 -0.000140205 2.44609e-05 -0.000115598">
              <inertial pos="-0.00558043 -0.000370704 -0.0987108" quat="0.699588 -0.0331174 -0.0253128 0.71333" mass="2.0896" diaginertia="0.0120402 0.0280364 0.00400175"/>
              <joint name="Left_Hip_Yaw" pos="0 0 0" axis="0.000671759 -0.0017939 -0.999998" range="-1.00003 1.05402" armature="0.00978779" damping="0" frictionloss="0.0996133"/>
              <geom name="//unnamed_geom_36" class="visual" mesh="Hip_Yaw_Left"/>
              <geom name="//unnamed_geom_37" class="collision" size="0.0497496 0.0795994" type="cylinder"/>
              <body name="Shank_Left" pos="-0.0118724 0.00104744 -0.148984" quat="1 1.31598e-05 0.000201693 -0.000250427">
                <inertial pos="-0.00590129 0.000762104 -0.137382" quat="0.997684 0.00161078 -0.0237751 0.0637038" mass="1.73538" diaginertia="0.016822 0.0399279 0.0029118"/>
                <joint name="Left_Knee_Pitch" pos="0 0 0" axis="0.00401854 0.999979 0.0051097" stiffness="0.00216884" range="-0.00653923 2.34745" armature="0.00988696" damping="0.0168159" frictionloss="0.104164"/>
                <geom name="//unnamed_geom_38" class="visual" mesh="Shank_Left"/>
                <geom name="//unnamed_geom_39" class="collision" size="0.0497496 0.0746244" pos="0 0 -0.131323" type="cylinder"/>
                <geom name="//unnamed_geom_40" class="reward_collision_sphere" size="0.0646745"/>
                <body name="Ankle_Cross_Left" pos="0.00106079 0.000868472 -0.307933" quat="1 -0.000177113 0.000437617 0.000156757">
                  <inertial pos="-0.00497124 0.00208008 -0.00889832" quat="0.443112 0.551032 0.551027 0.443153" mass="0.0712909" diaginertia="1.37684e-05 2.86957e-05 1.77802e-05"/>
                  <joint name="Left_Ankle_Pitch" pos="0 0 0" axis="-0.00501438 0.999986 0.00162728" range="-0.875013 0.338267" armature="0.00917468" damping="0.00303294" frictionloss="0.0980019"/>
                  <geom name="//unnamed_geom_41" class="visual" mesh="Ankle_Cross_Left"/>
                  <body name="left_foot_link" pos="0.00067948 -0.000779507 -0.0114854" quat="0.999999 0.000215308 -0.0001754 -0.00113548">
                    <inertial pos="-0.00209887 -0.000308828 -0.00897048" quat="-0.00162681 0.61951 -0.000148818 0.784987" mass="0.671099" diaginertia="0.00127631 0.0027034 0.00346055"/>
                    <joint name="Left_Ankle_Roll" pos="0 0 0" axis="-0.999998 -0.0010273 -0.00141318" range="-0.476212 0.400865" armature="0.00973561" damping="0.00820223" frictionloss="0.0901984"/>
                    <geom name="//unnamed_geom_42" class="visual" mesh="left_foot_link"/>
                    <geom name="left_foot" class="foot" size="0.104117 0.0503039 0.0151469" pos="0.00862649 0 -0.0164153"/>
                    <geom name="//unnamed_geom_44" class="reward_collision_sphere" size="0.0517396" pos="0.00862649 0 -0.0164153"/>
                    <geom name="//unnamed_geom_45" class="reward_collision_sphere" size="0.0298498" pos="0.0819516 -0.0236433 -0.0164153"/>
                    <geom name="//unnamed_geom_46" class="reward_collision_sphere" size="0.0298498" pos="-0.0603854 -0.0236433 -0.0164153"/>
                    <site name="left_foot" class="foot" pos="0.00862649 0 -0.0164153" size="0.00994992"/>
                  </body>
                </body>
              </body>
            </body>
          </body>
        </body>
        <body name="Hip_Pitch_Right" pos="-0.00234507 -0.110604 2.62655e-06" quat="1 -0.000148305 4.96103e-05 -0.000286">
          <inertial pos="-0.000525915 0.00702444 -0.019724" quat="0.973766 -0.227119 0.0131037 -0.0050485" mass="1.00158" diaginertia="0.000882655 0.00168265 0.00199409"/>
          <joint name="Right_Hip_Pitch" pos="0 0 0" axis="0.000845673 -1 -0.000496767" stiffness="0.00541915" range="-1.55253 1.80684" armature="0.0101397" damping="0.00753829" frictionloss="0.10421"/>
          <geom name="//unnamed_geom_47" class="visual" rgba="0.76 0.76 0.76 1" mesh="Hip_Pitch_Right"/>
          <body name="Hip_Roll_Right" pos="0.00192176 -0.00195283 -0.0228533" quat="1 -5.26035e-06 1.74137e-05 -4.26598e-05">
            <inertial pos="0.00021415 -0.00107629 -0.0581438" quat="0.706352 -0.00718741 -0.00547555 0.707803" mass="0.38699" diaginertia="0.000827847 0.00175442 0.000808133"/>
            <joint name="Right_Hip_Roll" pos="0 0 0" axis="-1 -4.722e-05 -0.00010504" stiffness="0.00797982" range="-0.200087 1.52558" armature="0.00983953" damping="0" frictionloss="0.0890418"/>
            <geom name="//unnamed_geom_48" class="visual" mesh="Hip_Roll_Right"/>
            <geom name="//unnamed_geom_49" class="reward_collision_sphere" size="0.0547246"/>
            <body name="Hip_Yaw_Right" pos="0.00231872 -0.000748259 -0.0893134" quat="1 -5.76618e-05 -1.22398e-05 0.000115229">
              <inertial pos="-0.00595752 -0.000542957 -0.0974881" quat="0.717666 -0.0285038 -0.043976 0.694413" mass="2.11183" diaginertia="0.011966 0.0289796 0.00396069"/>
              <joint name="Right_Hip_Yaw" pos="0 0 0" axis="-0.0010418 0.00779895 -0.999969" stiffness="0.00118328" range="-0.994458 1.01047" armature="0.00953465" damping="0.0110341" frictionloss="0.102208"/>
              <geom name="//unnamed_geom_50" class="visual" mesh="Hip_Yaw_Right"/>
              <geom name="//unnamed_geom_51" class="collision" size="0.0497496 0.0795994" type="cylinder"/>
              <body name="Shank_Right" pos="-0.00963861 -0.000759056 -0.146562" quat="1 -4.71386e-05 4.58377e-06 -0.000108657">
                <inertial pos="-0.00594737 0.000447011 -0.134321" quat="0.999501 0.000326216 -0.0135829 -0.0285101" mass="1.80448" diaginertia="0.0172286 0.0407307 0.00312118"/>
                <joint name="Right_Knee_Pitch" pos="0 0 0" axis="-0.00552785 -0.999969 0.00563532" range="-2.34036 0.000390399" armature="0.00990744" damping="0.0182891" frictionloss="0.0973594"/>
                <geom name="//unnamed_geom_52" class="visual" mesh="Shank_Right"/>
                <geom name="//unnamed_geom_53" class="collision" size="0.0497496 0.0746244" pos="0 0 -0.131323" type="cylinder"/>
                <geom name="//unnamed_geom_54" class="reward_collision_sphere" size="0.0646745"/>
                <body name="Ankle_Cross_Right" pos="-0.000636772 -0.000814963 -0.307887" quat="1 -0.000253953 -0.000319268 0.000543823">
                  <inertial pos="-0.00369136 0.00145636 -0.00867118" quat="0.443033 0.551359 0.550779 0.443134" mass="0.0722001" diaginertia="1.34614e-05 2.94847e-05 1.7651e-05"/>
                  <joint name="Right_Ankle_Pitch" pos="0 0 0" axis="0.000481555 -1 0.000575156" range="-0.398088 0.87184" armature="0.0100738" damping="0.0075184" frictionloss="0.098757"/>
                  <geom name="//unnamed_geom_55" class="visual" mesh="Ankle_Cross_Right"/>
                  <body name="right_foot_link" pos="0.00174528 0.000328263 -0.0135063" quat="1 -1.14995e-06 2.47298e-05 4.0277e-05">
                    <inertial pos="0.000130016 0.00103764 -0.00986794" quat="0.00333985 0.620587 0.000750478 0.784131" mass="0.705878" diaginertia="0.00131984 0.00278449 0.00344172"/>
                    <joint name="Right_Ankle_Roll" pos="0 0 0" axis="-0.999987 -0.00463156 0.00225541" range="-0.436779 0.444967" armature="0.0102533" damping="0.00903758" frictionloss="0.0885623"/>
                    <geom name="//unnamed_geom_56" class="visual" mesh="right_foot_link"/>
                    <geom name="right_foot" class="foot" size="0.0995925 0.0467401 0.0149797" pos="0.00862649 0 -0.0164153"/>
                    <geom name="//unnamed_geom_58" class="reward_collision_sphere" size="0.0397997"/>
                    <geom name="//unnamed_geom_59" class="reward_collision_sphere" size="0.0298498" pos="0.00862649 0 -0.0164153"/>
                    <geom name="//unnamed_geom_60" class="reward_collision_sphere" size="0.0298498" pos="0.0819516 0.0236433 -0.0164153"/>
                    <geom name="//unnamed_geom_61" class="reward_collision_sphere" size="0.0298498" pos="-0.0603854 0.0236433 -0.0164153"/>
                    <site name="right_foot" class="foot" pos="0.00862649 0 -0.0164153" size="0.00994992"/>
                  </body>
                </body>
              </body>
            </body>
          </body>
        </body>
      </body>
    </body>
  </worldbody>

  <contact>
    <pair class="/" geom1="floor" geom2="left_foot" name="//unnamed_contact_0"/>
    <pair class="/" geom1="floor" geom2="right_foot" name="//unnamed_contact_1"/>
  </contact>

  <actuator>
    <general name="AAHead_yaw" class="/" joint="AAHead_yaw" forcerange="-7.21865 7.21865" gainprm="23.3472" biasprm="0 -23.3472 -0.571059"/>
    <general name="Head_pitch" class="/" joint="Head_pitch" forcerange="-6.70934 6.70934" gainprm="23.3472" biasprm="0 -23.3472 -0.571059"/>
    <general name="Left_Shoulder_Pitch" class="/" joint="Left_Shoulder_Pitch" forcerange="-16.1999 16.1999" gainprm="23.3472" biasprm="0 -23.3472 -0.571059"/>
    <general name="Left_Shoulder_Roll" class="/" joint="Left_Shoulder_Roll" forcerange="-17.9354 17.9354" gainprm="23.3472" biasprm="0 -23.3472 -0.571059"/>
    <general name="Left_Elbow_Pitch" class="/" joint="Left_Elbow_Pitch" forcerange="-18.4413 18.4413" gainprm="23.3472" biasprm="0 -23.3472 -0.571059"/>
    <general name="Left_Elbow_Yaw" class="/" joint="Left_Elbow_Yaw" forcerange="-18.2353 18.2353" gainprm="23.3472" biasprm="0 -23.3472 -0.571059"/>
    <general name="Right_Shoulder_Pitch" class="/" joint="Right_Shoulder_Pitch" forcerange="-18.1723 18.1723" gainprm="23.3472" biasprm="0 -23.3472 -0.571059"/>
    <general name="Right_Shoulder_Roll" class="/" joint="Right_Shoulder_Roll" forcerange="-17.8937 17.8937" gainprm="23.3472" biasprm="0 -23.3472 -0.571059"/>
    <general name="Right_Elbow_Pitch" class="/" joint="Right_Elbow_Pitch" forcerange="-18.263 18.263" gainprm="23.3472" biasprm="0 -23.3472 -0.571059"/>
    <general name="Right_Elbow_Yaw" class="/" joint="Right_Elbow_Yaw" forcerange="-18.1179 18.1179" gainprm="23.3472" biasprm="0 -23.3472 -0.571059"/>
    <general name="Waist" class="/" joint="Waist" forcerange="-30.6479 30.6479" gainprm="23.3472" biasprm="0 -23.3472 -0.571059"/>
    <general name="Left_Hip_Pitch" class="/" joint="Left_Hip_Pitch" forcerange="-43.8445 43.8445" gainprm="23.3472" biasprm="0 -23.3472 -0.571059"/>
    <general name="Left_Hip_Roll" class="/" joint="Left_Hip_Roll" forcerange="-30.5263 30.5263" gainprm="23.3472" biasprm="0 -23.3472 -0.571059"/>
    <general name="Left_Hip_Yaw" class="/" joint="Left_Hip_Yaw" forcerange="-30.4907 30.4907" gainprm="23.3472" biasprm="0 -23.3472 -0.571059"/>
    <general name="Left_Knee_Pitch" class="/" joint="Left_Knee_Pitch" forcerange="-57.2017 57.2017" gainprm="23.3472" biasprm="0 -23.3472 -0.571059"/>
    <general name="Left_Ankle_Pitch" class="/" joint="Left_Ankle_Pitch" forcerange="-21.4597 21.4597" gainprm="23.3472" biasprm="0 -23.3472 -0.571059"/>
    <general name="Left_Ankle_Roll" class="/" joint="Left_Ankle_Roll" forcerange="-13.9867 13.9867" gainprm="23.3472" biasprm="0 -23.3472 -0.571059"/>
    <general name="Right_Hip_Pitch" class="/" joint="Right_Hip_Pitch" forcerange="-45.1573 45.1573" gainprm="23.3472" biasprm="0 -23.3472 -0.571059"/>
    <general name="Right_Hip_Roll" class="/" joint="Right_Hip_Roll" forcerange="-31.7155 31.7155" gainprm="23.3472" biasprm="0 -23.3472 -0.571059"/>
    <general name="Right_Hip_Yaw" class="/" joint="Right_Hip_Yaw" forcerange="-29.0352 29.0352" gainprm="23.3472" biasprm="0 -23.3472 -0.571059"/>
    <general name="Right_Knee_Pitch" class="/" joint="Right_Knee_Pitch" forcerange="-58.862 58.862" gainprm="23.3472" biasprm="0 -23.3472 -0.571059"/>
    <general name="Right_Ankle_Pitch" class="/" joint="Right_Ankle_Pitch" forcerange="-19.7583 19.7583" gainprm="23.3472" biasprm="0 -23.3472 -0.571059"/>
    <general name="Right_Ankle_Roll" class="/" joint="Right_Ankle_Roll" forcerange="-15.651 15.651" gainprm="23.3472" biasprm="0 -23.3472 -0.571059"/>
  </actuator>

  <sensor>
    <gyro site="imu" name="imu_angular_velocity"/>
    <velocimeter site="imu" name="imu_linear_velocity"/>
    <framelinvel objtype="site" objname="left_foot" name="left_foot_global_linear_velocity"/>
    <framelinvel objtype="site" objname="right_foot" name="right_foot_global_linear_velocity"/>
  </sensor>

  <keyframe>
    <key name="home" qpos="0 0 0.6385 1 0 0 0 0 0 0 1.4 0 -0.4 0 -1.4 0 0.4 0 -0.4 0 0 0.8 -0.4 0 0.4 0 0 -0.8 0.4 0"/>
  </keyframe>
</mujoco>
