<mujoco model="T1">
  <compiler angle="radian" assetdir="assets" balanceinertia="true" inertiafromgeom="false"/>

  <option timestep="0.005" density="1.2" viscosity="2e-05"/>

  <size nkey="1"/>

  <visual>
    <quality shadowsize="8192"/>
    <map shadowclip="0.5"/>
  </visual>

  <default>
    <default class="/">
      <joint armature="0.01" damping="0.01" frictionloss="0.1"/>
      <geom contype="0" conaffinity="0" group="1" solref="-1000 -80"/>
      <site size="0.01 0.005 0.005" group="5"/>
      <general forcelimited="true" biastype="affine" gainprm="25" biasprm="0 -25 -0.6"/>
      <default class="t1">
        <geom rgba="0.25 0.25 0.25 1"/>
        <default class="visual">
          <geom type="mesh" group="2"/>
        </default>
        <default class="collision">
          <geom group="3"/>
        </default>
        <default class="foot">
          <geom size="0.1115 0.05 0.015" type="box" condim="6" group="4" priority="1" solimp="0.015 1 0.015"/>
        </default>
        <default class="reward_collision_sphere">
          <geom group="5" rgba="1 0 0 1"/>
        </default>
      </default>
    </default>
  </default>

  <asset>
    <texture type="skybox" colorspace="auto" name="//unnamed_texture_0" builtin="gradient" rgb1="0.95 0.95 0.95" rgb2="0.95 0.95 0.95" width="100" height="600"/>
    <texture type="2d" colorspace="auto" name="texplane" builtin="checker" rgb1="0.345 0.575 0.748" rgb2="0.345 0.575 0.748" markrgb="1 1 1" width="512" height="512"/>
    <material name="MatPlane" class="/" texture="texplane" texuniform="true" texrepeat="2 2" specular="0.9"/>
    <mesh name="Trunk" class="/" file="Trunk.stl"/>
    <mesh name="H1" class="/" file="H1.stl"/>
    <mesh name="H2" class="/" file="H2.stl"/>
    <mesh name="AL1" class="/" file="AL1.stl"/>
    <mesh name="AL2" class="/" file="AL2.stl"/>
    <mesh name="AL3" class="/" file="AL3.stl"/>
    <mesh name="left_hand_link" class="/" file="left_hand_link.stl"/>
    <mesh name="AR1" class="/" file="AR1.stl"/>
    <mesh name="AR2" class="/" file="AR2.stl"/>
    <mesh name="AR3" class="/" file="AR3.stl"/>
    <mesh name="right_hand_link" class="/" file="right_hand_link.stl"/>
    <mesh name="Waist" class="/" file="Waist.stl"/>
    <mesh name="Hip_Pitch_Left" class="/" file="Hip_Pitch_Left.stl"/>
    <mesh name="Hip_Roll_Left" class="/" file="Hip_Roll_Left.stl"/>
    <mesh name="Hip_Yaw_Left" class="/" file="Hip_Yaw_Left.stl"/>
    <mesh name="Shank_Left" class="/" file="Shank_Left.stl"/>
    <mesh name="Ankle_Cross_Left" class="/" file="Ankle_Cross_Left.stl"/>
    <mesh name="left_foot_link" class="/" file="left_foot_link.stl"/>
    <mesh name="Hip_Pitch_Right" class="/" file="Hip_Pitch_Right.stl"/>
    <mesh name="Hip_Roll_Right" class="/" file="Hip_Roll_Right.stl"/>
    <mesh name="Hip_Yaw_Right" class="/" file="Hip_Yaw_Right.stl"/>
    <mesh name="Shank_Right" class="/" file="Shank_Right.stl"/>
    <mesh name="Ankle_Cross_Right" class="/" file="Ankle_Cross_Right.stl"/>
    <mesh name="right_foot_link" class="/" file="right_foot_link.stl"/>
  </asset>

  <worldbody>
    <geom name="floor" class="/" size="100 100 0.125" type="plane" group="0" material="MatPlane"/>
    <light name="toplight_shadow" class="/" pos="0 0 5" dir="0.0990148 0.0990148 -0.990148" type="directional" ambient="0.04 0.04 0.04" diffuse="0.55 0.55 0.55" specular="0.12 0.12 0.12"/>
    <light name="toplight_fill" class="/" pos="0 0 5" dir="0.0990148 0.0990148 -0.990148" type="directional" castshadow="false" ambient="0.04 0.04 0.04" diffuse="0.3 0.3 0.3" specular="0.08 0.08 0.08"/>
    <body name="trunk" childclass="t1" pos="-0.00276776 -0.00118621 0.00259619" quat="0.999999 -0.000451951 -0.000828128 0.000781459">
      <inertial pos="0.0380244 -0.00328221 0.1051" quat="0.999984 0.00314732 -0.00401329 0.00244601" mass="8.84974" diaginertia="0.015247 0.0945629 0.0499351"/>
      <joint name="//unnamed_joint_0" type="free" armature="0" damping="0" frictionloss="0"/>
      <geom name="//unnamed_geom_1" class="visual" rgba="0.76 0.76 0.76 1" mesh="Trunk"/>
      <geom name="//unnamed_geom_2" class="collision" size="0.0675577 0.0900769 0.135115" pos="0.0415298 0 0.116879" type="box"/>
      <geom name="//unnamed_geom_3" class="reward_collision_sphere" size="0.103588" pos="0.0415298 0 0.0973993"/>
      <geom name="//unnamed_geom_4" class="reward_collision_sphere" size="0.0135115" pos="0.0415298 0.088073 0"/>
      <geom name="//unnamed_geom_5" class="reward_collision_sphere" size="0.0135115" pos="0.0415298 -0.088073 0"/>
      <geom name="//unnamed_geom_6" class="reward_collision_sphere" size="0.0135115" pos="0.0415298 0.110868 0.175319"/>
      <geom name="//unnamed_geom_7" class="reward_collision_sphere" size="0.0135115" pos="0.0415298 -0.110868 0.175319"/>
      <site name="imu" pos="-0.0111815 -0.00114969 -0.00419077" size="0.00900769"/>
      <camera name="track" pos="0 -2.07231 0" quat="0.707107 0.707107 0 0" mode="trackcom"/>
      <camera name="ego_camera" pos="0.0844438 0 0.409077" quat="-0.5 -0.5 0.5 0.5"/>
      <body name="H1" pos="0.0434581 -0.00100899 0.236212" quat="0.999999 0.00048541 0.000957183 -0.000651006">
        <inertial pos="0.00157071 -0.00209162 0.0583078" quat="0.767341 -0.0122694 -0.00374106 0.64111" mass="0.333949" diaginertia="3.99298e-05 0.000279886 0.0001305"/>
        <joint name="AAHead_yaw" pos="0 0 0" axis="-1.161e-06 0.00039843 1" range="-1.61353 1.59305" armature="0.0101823" damping="0.012148" frictionloss="0.0817002"/>
        <geom name="//unnamed_geom_8" class="visual" mesh="H1"/>
        <body name="H2" pos="0.000461666 -0.00133523 0.059895" quat="1 0.000146374 -6.92004e-05 1.10115e-05">
          <inertial pos="0.00468769 0.00192164 0.0963687" quat="0.989529 0.103528 -0.0707261 -0.0715026" mass="0.452396" diaginertia="0.000315114 0.00230188 0.00150129"/>
          <joint name="Head_pitch" pos="0 0 0" axis="-0.00667818 -0.999977 -0.000937844" range="-1.2458 0.402924" armature="0.0096454" damping="0.00653067" frictionloss="0.0777108"/>
          <geom name="//unnamed_geom_9" class="visual" mesh="H2"/>
          <geom name="//unnamed_geom_10" class="collision" size="0.0720616" pos="0.00692163 0 0.107139"/>
          <geom name="//unnamed_geom_11" class="reward_collision_sphere" size="0.0810692" pos="0.0138433 0 0.0973993"/>
        </body>
      </body>
      <body name="AL1" pos="0.0377615 0.108738 0.21479" quat="0.999999 -0.00090086 0.000268347 -0.000944897">
        <inertial pos="5.2081e-05 0.0486867 0.000758218" quat="0.503625 0.496697 -0.504755 0.49485" mass="0.378618" diaginertia="0.000214097 0.00150692 0.000246051"/>
        <joint name="Left_Shoulder_Pitch" pos="0 0 0" axis="0.00170946 0.999996 -0.00208036" stiffness="0.0149651" range="-3.31468 1.16646" armature="0.00791959" damping="0.00484722" frictionloss="0.0935808"/>
        <geom name="//unnamed_geom_12" class="visual" rgba="0.76 0.76 0.76 1" mesh="AL1"/>
        <body name="AL2" pos="-0.00109183 0.0480258 -0.00114208" quat="0.999999 0.000432657 -0.000674782 0.000833504">
          <inertial pos="0.00157935 0.040934 0.000210605" quat="0.487244 0.511544 -0.488077 0.512539" mass="0.117336" diaginertia="6.32895e-05 0.000401287 0.000155394"/>
          <joint name="Left_Shoulder_Roll" pos="0 0 0" axis="-0.999988 -0.0027925 -0.00394929" stiffness="0.0100678" range="-1.57303 1.69371" armature="0.00766194" damping="0.0135472" frictionloss="0.0906607"/>
          <geom name="//unnamed_geom_13" class="visual" mesh="AL2"/>
          <body name="AL3" pos="0.0022951 0.0614313 9.50066e-05" quat="1 -5.45239e-06 -0.000204641 0.000132269">
            <inertial pos="0.000328398 0.0875606 -0.00293105" quat="0.70526 0.708841 -0.00199194 0.0122553" mass="0.704199" diaginertia="0.00195282 0.0149023 0.000534155"/>
            <joint name="Left_Elbow_Pitch" pos="0 0 0" axis="0.00604805 -0.999982 -0.000403736" range="-2.3058 2.28756" armature="0.00893456" damping="0.00883214" frictionloss="0.0969703"/>
            <geom name="//unnamed_geom_14" class="visual" mesh="AL3"/>
            <geom name="//unnamed_geom_15" class="collision" size="0.0270231 0.0675577" pos="0 0.0518076 0" quat="0.707105 0.707108 0 0" type="cylinder"/>
            <geom name="//unnamed_geom_16" class="reward_collision_sphere" size="0.0324277"/>
            <body name="left_hand_link" pos="0.00295591 0.152682 0.00112723" quat="0.999999 0.000556718 0.000654204 0.000560088">
              <inertial pos="-0.000102482 0.112516 -0.000693339" quat="0.709253 0.70495 -0.00254732 -0.00041137" mass="0.246321" diaginertia="0.001338 0.00955942 0.000192624"/>
              <joint name="Left_Elbow_Yaw" pos="0 0 0" axis="-0.0123464 0.00755674 0.999895" stiffness="0.00544067" range="-2.43586 -0.0217458" armature="0.00793758" damping="0.00803563" frictionloss="0.101081"/>
              <geom name="//unnamed_geom_17" class="visual" mesh="left_hand_link"/>
              <geom name="//unnamed_geom_18" class="collision" size="0.0270231 0.0788173" pos="0 0.1347 0" quat="0.707105 0.707108 0 0" type="cylinder"/>
              <geom name="//unnamed_geom_19" class="reward_collision_sphere" size="0.0450385"/>
              <geom name="//unnamed_geom_20" class="reward_collision_sphere" size="0.0315269" pos="0 0.113977 0"/>
              <geom name="//unnamed_geom_21" class="reward_collision_sphere" size="0.0315269" pos="0 0.222773 0"/>
            </body>
          </body>
        </body>
      </body>
      <body name="AR1" pos="0.0385369 -0.106065 0.212454" quat="0.999999 -0.00093946 3.76594e-05 0.000643526">
        <inertial pos="-0.00216019 -0.0467227 -0.000158732" quat="0.504632 0.498871 -0.501298 0.495151" mass="0.387818" diaginertia="0.000218387 0.0015654 0.000267528"/>
        <joint name="Right_Shoulder_Pitch" pos="0 0 0" axis="-2.7559e-05 -1 7.82966e-05" stiffness="0.00726355" range="-1.27406 3.30356" armature="0.00797464" damping="0.0194257" frictionloss="0.0982601"/>
        <geom name="//unnamed_geom_22" class="visual" rgba="0.76 0.76 0.76 1" mesh="AR1"/>
        <body name="AR2" pos="-0.00171946 -0.047161 0.000240051" quat="1 -8.25162e-05 -0.000293915 -9.39944e-05">
          <inertial pos="0.00111529 -0.0390965 0.000666306" quat="0.505362 0.490192 -0.506766 0.497503" mass="0.124389" diaginertia="6.39798e-05 0.000427481 0.000158146"/>
          <joint name="Right_Shoulder_Roll" pos="0 0 0" axis="-1 0.000479955 -0.000584232" range="-1.78738 1.57718" armature="0.00904546" damping="0.00467801" frictionloss="0.092049"/>
          <geom name="//unnamed_geom_23" class="visual" mesh="AR2"/>
          <body name="AR3" pos="0.00153761 -0.0630197 -0.00313181" quat="1 -0.000178549 -3.64996e-05 5.37858e-05">
            <inertial pos="0.0024601 -0.0910164 -0.000980529" quat="0.708759 0.705449 -0.00146691 -0.000630756" mass="0.767171" diaginertia="0.00211967 0.016154 0.000580463"/>
            <joint name="Right_Elbow_Pitch" pos="0 0 0" axis="0.0073782 0.999912 -0.0109977" range="-2.27608 2.25793" armature="0.00888139" damping="0.00856266" frictionloss="0.0901047"/>
            <geom name="//unnamed_geom_24" class="visual" mesh="AR3"/>
            <geom name="//unnamed_geom_25" class="collision" size="0.0270231 0.0675577" pos="0 -0.0518076 0" quat="0.707105 0.707108 0 0" type="cylinder"/>
            <geom name="//unnamed_geom_26" class="reward_collision_sphere" size="0.0324277"/>
            <body name="right_hand_link" pos="-0.00113598 -0.151867 -0.00141795" quat="0.999999 -0.000862373 0.0007253 -0.000157557">
              <inertial pos="-0.00208876 -0.112938 0.00184168" quat="0.70858 0.70562 0.00377206 -0.000656553" mass="0.23391" diaginertia="0.00130216 0.00970297 0.000194963"/>
              <joint name="Right_Elbow_Yaw" pos="0 0 0" axis="-0.00233995 -0.00811273 0.999964" stiffness="0.00368104" range="0.00203985 2.41872" armature="0.00834236" damping="0" frictionloss="0.100904"/>
              <geom name="//unnamed_geom_27" class="visual" mesh="right_hand_link"/>
              <geom name="//unnamed_geom_28" class="collision" size="0.0270231 0.0788173" pos="0 -0.1347 0" quat="0.707105 0.707108 0 0" type="cylinder"/>
              <geom name="//unnamed_geom_29" class="reward_collision_sphere" size="0.0450385"/>
              <geom name="//unnamed_geom_30" class="reward_collision_sphere" size="0.0315269" pos="0 -0.113977 0"/>
              <geom name="//unnamed_geom_31" class="reward_collision_sphere" size="0.0315269" pos="0 -0.222773 0"/>
            </body>
          </body>
        </body>
      </body>
      <body name="Waist" pos="0.0469132 0.00133728 -0.111117" quat="0.999999 0.000267743 0.000775571 0.000954007">
        <inertial pos="0.00376628 -0.00171502 0.00982596" quat="0.982474 -0.00119085 -0.185851 0.0142179" mass="1.82789" diaginertia="0.000837969 0.00630847 0.00415728"/>
        <joint name="Waist" pos="0 0 0" axis="0.00270223 -0.00233682 0.999994" stiffness="0.0132671" range="-1.56342 1.57571" armature="0.0101992" damping="0.00887515" frictionloss="0.0865499"/>
        <geom name="//unnamed_geom_32" class="visual" mesh="Waist"/>
        <body name="Hip_Pitch_Left" pos="0.00146921 0.109469 -0.00303607" quat="0.999999 -0.000570941 -0.00134248 0.000764195">
          <inertial pos="-0.000423473 -0.00502988 -0.0178608" quat="0.975418 0.219544 0.0186175 0.00377262" mass="0.760642" diaginertia="0.000283292 0.00171436 0.00113043"/>
          <joint name="Left_Hip_Pitch" pos="0 0 0" axis="-0.0164203 0.999838 -0.00737977" stiffness="0.0021" range="-1.79207 1.5721" armature="0.00900979" damping="0.00835023" frictionloss="0.0838216"/>
          <geom name="//unnamed_geom_33" class="visual" rgba="0.76 0.76 0.76 1" mesh="Hip_Pitch_Left"/>
          <body name="Hip_Roll_Left" pos="-0.00123671 0.00212632 -0.0197987" quat="0.999999 -0.000643782 -0.000824706 0.000760366">
            <inertial pos="-0.00125886 0.00101054 -0.0514449" quat="0.708851 -0.0104802 0.00148793 0.705279" mass="0.297884" diaginertia="0.000280498 0.00182813 0.000462173"/>
            <joint name="Left_Hip_Roll" pos="0 0 0" axis="-0.999928 -0.00379699 0.0113669" range="-1.54671 0.25632" armature="0.00859163" damping="0.016177" frictionloss="0.0818403"/>
            <geom name="//unnamed_geom_34" class="visual" mesh="Hip_Roll_Left"/>
            <geom name="//unnamed_geom_35" class="reward_collision_sphere" size="0.0495423"/>
            <body name="Hip_Yaw_Left" pos="-0.00205471 0.000916653 -0.0788434" quat="1 -6.47375e-06 -8.32092e-05 0.000809601">
              <inertial pos="-0.00387664 0.00027313 -0.0877288" quat="0.695219 -0.0361374 -0.0308213 0.717227" mass="1.50662" diaginertia="0.00392781 0.0296714 0.00212168"/>
              <joint name="Left_Hip_Yaw" pos="0 0 0" axis="-0.000298501 3.98794e-05 -1" range="-0.951825 0.978433" armature="0.00892392" damping="0.0169438" frictionloss="0.0857001"/>
              <geom name="//unnamed_geom_36" class="visual" mesh="Hip_Yaw_Left"/>
              <geom name="//unnamed_geom_37" class="collision" size="0.0450385 0.0720616" type="cylinder"/>
              <body name="Shank_Left" pos="-0.00696342 -0.00024898 -0.131432" quat="1 -5.89263e-06 2.70823e-05 -1.66635e-05">
                <inertial pos="-0.00227503 0.00112993 -0.121463" quat="0.997328 0.000755015 -0.0260902 0.0682305" mass="1.27403" diaginertia="0.00545424 0.0413083 0.00161529"/>
                <joint name="Left_Knee_Pitch" pos="0 0 0" axis="0.00372508 0.99995 0.00924875" range="0.0508981 2.34981" armature="0.0102503" damping="0.0228456" frictionloss="0.0805731"/>
                <geom name="//unnamed_geom_38" class="visual" mesh="Shank_Left"/>
                <geom name="//unnamed_geom_39" class="collision" size="0.0450385 0.0675577" pos="0 0 -0.116879" type="cylinder"/>
                <geom name="//unnamed_geom_40" class="reward_collision_sphere" size="0.05855"/>
                <body name="Ankle_Cross_Left" pos="0.00296832 0.00163414 -0.274904" quat="1 -0.000107415 3.42858e-06 -0.000232373">
                  <inertial pos="-0.00199467 0.000335715 -0.00534545" quat="0.448331 0.550139 0.546415 0.444722" mass="0.0532673" diaginertia="4.79225e-06 3.18206e-05 1.00951e-05"/>
                  <joint name="Left_Ankle_Pitch" pos="0 0 0" axis="0.00404428 0.999992 -0.000644954" stiffness="0.00680268" range="-0.925878 0.305188" armature="0.00903605" damping="0.0151074" frictionloss="0.0778437"/>
                  <geom name="//unnamed_geom_41" class="visual" mesh="Ankle_Cross_Left"/>
                  <body name="left_foot_link" pos="-0.000135655 0.00223755 -0.0121642" quat="1 0.000274527 -0.000412364 -0.000228548">
                    <inertial pos="-0.00029299 -0.00115165 -0.0115946" quat="0.00204559 0.623684 0.0032517 0.781668" mass="0.51807" diaginertia="0.000441344 0.00295416 0.0019475"/>
                    <joint name="Left_Ankle_Roll" pos="0 0 0" axis="-0.99989 -0.00426166 -0.0141812" range="-0.423649 0.389503" armature="0.00909404" damping="6.57196e-05" frictionloss="0.102362"/>
                    <geom name="//unnamed_geom_42" class="visual" mesh="left_foot_link"/>
                    <geom name="left_foot" class="foot" size="0.104063 0.0406422 0.0144451" pos="0.00692163 0 -0.0146099"/>
                    <geom name="//unnamed_geom_44" class="reward_collision_sphere" size="0.04684" pos="0.00692163 0 -0.0146099"/>
                    <geom name="//unnamed_geom_45" class="reward_collision_sphere" size="0.0270231" pos="0.0657554 -0.0238315 -0.0146099"/>
                    <geom name="//unnamed_geom_46" class="reward_collision_sphere" size="0.0270231" pos="-0.0484514 -0.0238315 -0.0146099"/>
                    <site name="left_foot" class="foot" pos="0.00692163 0 -0.0146099" size="0.00900769"/>
                  </body>
                </body>
              </body>
            </body>
          </body>
        </body>
        <body name="Hip_Pitch_Right" pos="-0.00164885 -0.109507 -0.00177864" quat="0.999999 -0.000488144 -0.000478972 0.000957101">
          <inertial pos="-0.00218911 0.00530289 -0.0164333" quat="0.973462 -0.228484 0.0125504 -0.00310122" mass="0.740305" diaginertia="0.000296306 0.00181348 0.0011027"/>
          <joint name="Right_Hip_Pitch" pos="0 0 0" axis="0.0107486 -0.999912 0.00780352" range="-1.57479 1.80298" armature="0.00913381" damping="0.000388594" frictionloss="0.09794"/>
          <geom name="//unnamed_geom_47" class="visual" rgba="0.76 0.76 0.76 1" mesh="Hip_Pitch_Right"/>
          <body name="Hip_Roll_Right" pos="0.000409331 -0.00240307 -0.0219584" quat="1 2.22252e-05 0.000319147 3.32168e-05">
            <inertial pos="0.000327529 -0.00277433 -0.0535775" quat="0.704745 0.000841595 0.00481719 0.709444" mass="0.28621" diaginertia="0.000280262 0.00182983 0.000440129"/>
            <joint name="Right_Hip_Roll" pos="0 0 0" axis="-0.999994 -0.00345364 -0.000574434" stiffness="0.00373544" range="-0.248332 1.53773" armature="0.0102862" damping="0.0144687" frictionloss="0.0782378"/>
            <geom name="//unnamed_geom_48" class="visual" mesh="Hip_Roll_Right"/>
            <geom name="//unnamed_geom_49" class="reward_collision_sphere" size="0.0495423"/>
            <body name="Hip_Yaw_Right" pos="-0.00202742 -0.000806664 -0.0802398" quat="1 1.15347e-05 3.87198e-06 4.93918e-06">
              <inertial pos="-0.0049537 -0.000690354 -0.0877193" quat="0.71843 -0.0308999 -0.0388889 0.693823" mass="1.56316" diaginertia="0.00402489 0.0306608 0.00225491"/>
              <joint name="Right_Hip_Yaw" pos="0 0 0" axis="0.00227057 0.000142884 -0.999997" range="-1.0288 1.00284" armature="0.00947958" damping="0" frictionloss="0.0829051"/>
              <geom name="//unnamed_geom_50" class="visual" mesh="Hip_Yaw_Right"/>
              <geom name="//unnamed_geom_51" class="collision" size="0.0450385 0.0720616" type="cylinder"/>
              <body name="Shank_Right" pos="-0.0100113 -0.00134547 -0.13345" quat="1 8.26811e-05 7.14581e-05 -4.12732e-05">
                <inertial pos="-0.00512255 -0.00220387 -0.116848" quat="0.999217 0.00217429 -0.0175254 -0.0354159" mass="1.29145" diaginertia="0.00537096 0.0397814 0.00164665"/>
                <joint name="Right_Knee_Pitch" pos="0 0 0" axis="-0.00503035 -0.999974 -0.00520268" range="-2.34307 -0.00250585" armature="0.0100454" damping="0.0153525" frictionloss="0.102311"/>
                <geom name="//unnamed_geom_52" class="visual" mesh="Shank_Right"/>
                <geom name="//unnamed_geom_53" class="collision" size="0.0450385 0.0675577" pos="0 0 -0.116879" type="cylinder"/>
                <geom name="//unnamed_geom_54" class="reward_collision_sphere" size="0.05855"/>
                <body name="Ankle_Cross_Right" pos="0.00273152 0.00215037 -0.272602" quat="0.999999 -0.00116315 0.000102163 -0.000344974">
                  <inertial pos="5.51216e-05 0.00254524 -0.00755918" quat="0.44399 0.559562 0.540986 0.443957" mass="0.0522713" diaginertia="4.69039e-06 3.03107e-05 9.61445e-06"/>
                  <joint name="Right_Ankle_Pitch" pos="0 0 0" axis="-0.00542536 -0.999962 -0.00686607" range="-0.404623 0.856208" armature="0.00990221" damping="0.0161304" frictionloss="0.101494"/>
                  <geom name="//unnamed_geom_55" class="visual" mesh="Ankle_Cross_Right"/>
                  <body name="right_foot_link" pos="-0.00128673 -0.00177127 -0.0102584" quat="1 1.0848e-05 0.000267954 0.000268409">
                    <inertial pos="-0.00105554 0.000576667 -0.00671827" quat="-0.0048137 0.622937 -0.00470767 0.782243" mass="0.500206" diaginertia="0.000419147 0.00286348 0.0018529"/>
                    <joint name="Right_Ankle_Roll" pos="0 0 0" axis="-0.999987 -0.00423969 -0.00279682" range="-0.439238 0.384933" armature="0.0102966" damping="0.0150019" frictionloss="0.0915968"/>
                    <geom name="//unnamed_geom_56" class="visual" mesh="right_foot_link"/>
                    <geom name="right_foot" class="foot" size="0.102176 0.0397427 0.0124407" pos="0.00692163 0 -0.0146099"/>
                    <geom name="//unnamed_geom_58" class="reward_collision_sphere" size="0.0360308"/>
                    <geom name="//unnamed_geom_59" class="reward_collision_sphere" size="0.0270231" pos="0.00692163 0 -0.0146099"/>
                    <geom name="//unnamed_geom_60" class="reward_collision_sphere" size="0.0270231" pos="0.0657554 0.0238315 -0.0146099"/>
                    <geom name="//unnamed_geom_61" class="reward_collision_sphere" size="0.0270231" pos="-0.0484514 0.0238315 -0.0146099"/>
                    <site name="right_foot" class="foot" pos="0.00692163 0 -0.0146099" size="0.00900769"/>
                  </body>
                </body>
              </body>
            </body>
          </body>
        </body>
      </body>
    </body>
  </worldbody>

  <contact>
    <pair class="/" geom1="floor" geom2="left_foot" name="//unnamed_contact_0"/>
    <pair class="/" geom1="floor" geom2="right_foot" name="//unnamed_contact_1"/>
  </contact>

  <actuator>
    <general name="AAHead_yaw" class="/" joint="AAHead_yaw" forcerange="-6.22351 6.22351" gainprm="21.1631" biasprm="0 -21.1631 -0.54775"/>
    <general name="Head_pitch" class="/" joint="Head_pitch" forcerange="-6.95318 6.95318" gainprm="21.1631" biasprm="0 -21.1631 -0.54775"/>
    <general name="Left_Shoulder_Pitch" class="/" joint="Left_Shoulder_Pitch" forcerange="-15.6443 15.6443" gainprm="21.1631" biasprm="0 -21.1631 -0.54775"/>
    <general name="Left_Shoulder_Roll" class="/" joint="Left_Shoulder_Roll" forcerange="-17.7389 17.7389" gainprm="21.1631" biasprm="0 -21.1631 -0.54775"/>
    <general name="Left_Elbow_Pitch" class="/" joint="Left_Elbow_Pitch" forcerange="-17.0673 17.0673" gainprm="21.1631" biasprm="0 -21.1631 -0.54775"/>
    <general name="Left_Elbow_Yaw" class="/" joint="Left_Elbow_Yaw" forcerange="-15.4995 15.4995" gainprm="21.1631" biasprm="0 -21.1631 -0.54775"/>
    <general name="Right_Shoulder_Pitch" class="/" joint="Right_Shoulder_Pitch" forcerange="-16.1285 16.1285" gainprm="21.1631" biasprm="0 -21.1631 -0.54775"/>
    <general name="Right_Shoulder_Roll" class="/" joint="Right_Shoulder_Roll" forcerange="-17.0361 17.0361" gainprm="21.1631" biasprm="0 -21.1631 -0.54775"/>
    <general name="Right_Elbow_Pitch" class="/" joint="Right_Elbow_Pitch" forcerange="-17.6392 17.6392" gainprm="21.1631" biasprm="0 -21.1631 -0.54775"/>
    <general name="Right_Elbow_Yaw" class="/" joint="Right_Elbow_Yaw" forcerange="-15.2192 15.2192" gainprm="21.1631" biasprm="0 -21.1631 -0.54775"/>
    <general name="Waist" class="/" joint="Waist" forcerange="-27.1405 27.1405" gainprm="21.1631" biasprm="0 -21.1631 -0.54775"/>
    <general name="Left_Hip_Pitch" class="/" joint="Left_Hip_Pitch" forcerange="-44.1294 44.1294" gainprm="21.1631" biasprm="0 -21.1631 -0.54775"/>
    <general name="Left_Hip_Roll" class="/" joint="Left_Hip_Roll" forcerange="-26.1382 26.1382" gainprm="21.1631" biasprm="0 -21.1631 -0.54775"/>
    <general name="Left_Hip_Yaw" class="/" joint="Left_Hip_Yaw" forcerange="-29.7177 29.7177" gainprm="21.1631" biasprm="0 -21.1631 -0.54775"/>
    <general name="Left_Knee_Pitch" class="/" joint="Left_Knee_Pitch" forcerange="-53.9427 53.9427" gainprm="21.1631" biasprm="0 -21.1631 -0.54775"/>
    <general name="Left_Ankle_Pitch" class="/" joint="Left_Ankle_Pitch" forcerange="-19.5975 19.5975" gainprm="21.1631" biasprm="0 -21.1631 -0.54775"/>
    <general name="Left_Ankle_Roll" class="/" joint="Left_Ankle_Roll" forcerange="-13.4289 13.4289" gainprm="21.1631" biasprm="0 -21.1631 -0.54775"/>
    <general name="Right_Hip_Pitch" class="/" joint="Right_Hip_Pitch" forcerange="-41.3311 41.3311" gainprm="21.1631" biasprm="0 -21.1631 -0.54775"/>
    <general name="Right_Hip_Roll" class="/" joint="Right_Hip_Roll" forcerange="-27.0678 27.0678" gainprm="21.1631" biasprm="0 -21.1631 -0.54775"/>
    <general name="Right_Hip_Yaw" class="/" joint="Right_Hip_Yaw" forcerange="-26.1333 26.1333" gainprm="21.1631" biasprm="0 -21.1631 -0.54775"/>
    <general name="Right_Knee_Pitch" class="/" joint="Right_Knee_Pitch" forcerange="-48.4684 48.4684" gainprm="21.1631" biasprm="0 -21.1631 -0.54775"/>
    <general name="Right_Ankle_Pitch" class="/" joint="Right_Ankle_Pitch" forcerange="-17.0738 17.0738" gainprm="21.1631" biasprm="0 -21.1631 -0.54775"/>
    <general name="Right_Ankle_Roll" class="/" joint="Right_Ankle_Roll" forcerange="-14.7251 14.7251" gainprm="21.1631" biasprm="0 -21.1631 -0.54775"/>
  </actuator>

  <sensor>
    <gyro site="imu" name="imu_angular_velocity"/>
    <velocimeter site="imu" name="imu_linear_velocity"/>
    <framelinvel objtype="site" objname="left_foot" name="left_foot_global_linear_velocity"/>
    <framelinvel objtype="site" objname="right_foot" name="right_foot_global_linear_velocity"/>
  </sensor>

  <keyframe>
    <key name="home" qpos="0 0 0.6385 1 0 0 0 0 0 0 1.4 0 -0.4 0 -1.4 0 0.4 0 -0.4 0 0 0.8 -0.4 0 0.4 0 0 -0.8 0.4 0"/>
  </keyframe>
</mujoco>
