<mujoco model="T1">
  <compiler angle="radian" assetdir="assets" balanceinertia="true" inertiafromgeom="false"/>

  <option timestep="0.005" density="1.2" viscosity="2e-05"/>

  <size nkey="1"/>

  <visual>
    <quality shadowsize="8192"/>
    <map shadowclip="0.5"/>
  </visual>

  <default>
    <default class="/">
      <joint armature="0.01" damping="0.01" frictionloss="0.1"/>
      <geom contype="0" conaffinity="0" group="1" solref="-1000 -80"/>
      <site size="0.01 0.005 0.005" group="5"/>
      <general forcelimited="true" biastype="affine" gainprm="25" biasprm="0 -25 -0.6"/>
      <default class="t1">
        <geom rgba="0.25 0.25 0.25 1"/>
        <default class="visual">
          <geom type="mesh" group="2"/>
        </default>
        <default class="collision">
          <geom group="3"/>
        </default>
        <default class="foot">
          <geom size="0.1115 0.05 0.015" type="box" condim="6" group="4" priority="1" solimp="0.015 1 0.015"/>
        </default>
        <default class="reward_collision_sphere">
          <geom group="5" rgba="1 0 0 1"/>
        </default>
      </default>
    </default>
  </default>

  <asset>
    <texture type="skybox" colorspace="auto" name="//unnamed_texture_0" builtin="gradient" rgb1="0.95 0.95 0.95" rgb2="0.95 0.95 0.95" width="100" height="600"/>
    <texture type="2d" colorspace="auto" name="texplane" builtin="checker" rgb1="0.345 0.575 0.748" rgb2="0.345 0.575 0.748" markrgb="1 1 1" width="512" height="512"/>
    <material name="MatPlane" class="/" texture="texplane" texuniform="true" texrepeat="2 2" specular="0.9"/>
    <mesh name="Trunk" class="/" file="Trunk.stl"/>
    <mesh name="H1" class="/" file="H1.stl"/>
    <mesh name="H2" class="/" file="H2.stl"/>
    <mesh name="AL1" class="/" file="AL1.stl"/>
    <mesh name="AL2" class="/" file="AL2.stl"/>
    <mesh name="AL3" class="/" file="AL3.stl"/>
    <mesh name="left_hand_link" class="/" file="left_hand_link.stl"/>
    <mesh name="AR1" class="/" file="AR1.stl"/>
    <mesh name="AR2" class="/" file="AR2.stl"/>
    <mesh name="AR3" class="/" file="AR3.stl"/>
    <mesh name="right_hand_link" class="/" file="right_hand_link.stl"/>
    <mesh name="Waist" class="/" file="Waist.stl"/>
    <mesh name="Hip_Pitch_Left" class="/" file="Hip_Pitch_Left.stl"/>
    <mesh name="Hip_Roll_Left" class="/" file="Hip_Roll_Left.stl"/>
    <mesh name="Hip_Yaw_Left" class="/" file="Hip_Yaw_Left.stl"/>
    <mesh name="Shank_Left" class="/" file="Shank_Left.stl"/>
    <mesh name="Ankle_Cross_Left" class="/" file="Ankle_Cross_Left.stl"/>
    <mesh name="left_foot_link" class="/" file="left_foot_link.stl"/>
    <mesh name="Hip_Pitch_Right" class="/" file="Hip_Pitch_Right.stl"/>
    <mesh name="Hip_Roll_Right" class="/" file="Hip_Roll_Right.stl"/>
    <mesh name="Hip_Yaw_Right" class="/" file="Hip_Yaw_Right.stl"/>
    <mesh name="Shank_Right" class="/" file="Shank_Right.stl"/>
    <mesh name="Ankle_Cross_Right" class="/" file="Ankle_Cross_Right.stl"/>
    <mesh name="right_foot_link" class="/" file="right_foot_link.stl"/>
  </asset>

  <worldbody>
    <geom name="floor" class="/" size="100 100 0.125" type="plane" group="0" material="MatPlane"/>
    <light name="toplight_shadow" class="/" pos="0 0 5" dir="0.0990148 0.0990148 -0.990148" type="directional" ambient="0.04 0.04 0.04" diffuse="0.55 0.55 0.55" specular="0.12 0.12 0.12"/>
    <light name="toplight_fill" class="/" pos="0 0 5" dir="0.0990148 0.0990148 -0.990148" type="directional" castshadow="false" ambient="0.04 0.04 0.04" diffuse="0.3 0.3 0.3" specular="0.08 0.08 0.08"/>
    <body name="trunk" childclass="t1" pos="0.0057463 0.0103472 -0.0071681" quat="0.999993 0.000410069 -0.00171554 0.00341373">
      <inertial pos="0.0537159 0.00408674 0.124561" quat="0.999891 0.0112868 -0.00956494 7.5711e-05" mass="22.8498" diaginertia="0.083999 0.363852 0.152657"/>
      <joint name="//unnamed_joint_0" type="free" armature="0" damping="0" frictionloss="0"/>
      <geom name="//unnamed_geom_1" class="visual" rgba="0.76 0.76 0.76 1" mesh="Trunk"/>
      <geom name="//unnamed_geom_2" class="collision" size="0.091958 0.122611 0.183916" pos="0.0600084 0 0.149139" type="box"/>
      <geom name="//unnamed_geom_3" class="reward_collision_sphere" size="0.141002" pos="0.0600084 0 0.124283"/>
      <geom name="//unnamed_geom_4" class="reward_collision_sphere" size="0.0183916" pos="0.0600084 0.122005 0"/>
      <geom name="//unnamed_geom_5" class="reward_collision_sphere" size="0.0183916" pos="0.0600084 -0.122005 0"/>
      <geom name="//unnamed_geom_6" class="reward_collision_sphere" size="0.0183916" pos="0.0600084 0.153583 0.223709"/>
      <geom name="//unnamed_geom_7" class="reward_collision_sphere" size="0.0183916" pos="0.0600084 -0.153583 0.223709"/>
      <site name="imu" pos="0.0413886 0.0590798 0.000755057" size="0.0122611"/>
      <camera name="track" pos="0 -2.8707 0" quat="0.707107 0.707107 0 0" mode="trackcom"/>
      <camera name="ego_camera" pos="0.122017 0 0.521987" quat="-0.5 -0.5 0.5 0.5"/>
      <body name="H1" pos="0.0606546 0.00067443 0.301508" quat="0.999994 -0.00286117 0.00121664 0.00165839">
        <inertial pos="-0.00766562 -0.00288638 0.0635003" quat="0.792901 -0.0621237 -0.0143549 0.606005" mass="0.790657" diaginertia="0.000225875 0.00116091 0.000468507"/>
        <joint name="AAHead_yaw" pos="0 0 0" axis="-0.0586798 0.00841422 0.998241" range="-1.40075 1.53522" armature="0.00734732" damping="0.000824297" frictionloss="0.178434"/>
        <geom name="//unnamed_geom_8" class="visual" mesh="H1"/>
        <body name="H2" pos="-0.0112058 0.00158226 0.0773009" quat="1 0.00012019 1.85659e-05 -0.000469981">
          <inertial pos="0.00628141 0.0147654 0.121421" quat="0.986603 0.110604 -0.079224 -0.0900257" mass="1.31534" diaginertia="0.00228773 0.0155278 0.00568935"/>
          <joint name="Head_pitch" pos="0 0 0" axis="-0.050307 -0.998724 0.0045024" stiffness="0.0294099" range="-1.18182 0.216137" armature="0.0108017" damping="0.00640775" frictionloss="0.155089"/>
          <geom name="//unnamed_geom_9" class="visual" mesh="H2"/>
          <geom name="//unnamed_geom_10" class="collision" size="0.0980885" pos="0.0100014 0 0.136711"/>
          <geom name="//unnamed_geom_11" class="reward_collision_sphere" size="0.11035" pos="0.0200028 0 0.124283"/>
        </body>
      </body>
      <body name="AL1" pos="0.0659082 0.159798 0.270176" quat="0.999998 0.00191672 0.000313235 0.000432652">
        <inertial pos="-0.00225977 0.0603065 0.0131098" quat="0.502142 0.546507 -0.476449 0.471359" mass="0.791122" diaginertia="0.00110903 0.00647976 0.000726627"/>
        <joint name="Left_Shoulder_Pitch" pos="0 0 0" axis="0.0213738 0.99839 -0.0525461" range="-3.31285 1.33688" armature="0.0146244" damping="0.00954936" frictionloss="0.11219"/>
        <geom name="//unnamed_geom_12" class="visual" rgba="0.76 0.76 0.76 1" mesh="AL1"/>
        <body name="AL2" pos="0.00530965 0.0772099 0.0107748" quat="0.999972 0.00359596 -0.00652518 0.000178646">
          <inertial pos="0.00647962 0.068755 -1.46856e-05" quat="0.484797 0.511446 -0.490428 0.512714" mass="0.303085" diaginertia="0.00039123 0.00234886 0.000535948"/>
          <joint name="Left_Shoulder_Roll" pos="0 0 0" axis="-0.997326 -0.0316571 -0.0658614" stiffness="0.0656382" range="-1.81859 1.82432" armature="0.0160489" damping="0.0767871" frictionloss="0.0494376"/>
          <geom name="//unnamed_geom_13" class="visual" mesh="AL2"/>
          <body name="AL3" pos="-0.0083183 0.0728797 0.00118003" quat="0.99998 -0.00162673 0.00163182 0.00586835">
            <inertial pos="0.00144112 0.133414 0.00466198" quat="0.717504 0.695732 -0.00199902 -0.0337792" mass="1.67145" diaginertia="0.0141056 0.0729056 0.00234488"/>
            <joint name="Left_Elbow_Pitch" pos="0 0 0" axis="-0.00159677 -0.998652 0.0518836" stiffness="0.0521822" range="-2.55823 2.53729" armature="0.00407257" damping="0.0704377" frictionloss="0.0627963"/>
            <geom name="//unnamed_geom_14" class="visual" mesh="AL3"/>
            <geom name="//unnamed_geom_15" class="collision" size="0.0367832 0.091958" pos="0 0.0717676 0" quat="0.707105 0.707108 0 0" type="cylinder"/>
            <geom name="//unnamed_geom_16" class="reward_collision_sphere" size="0.0441398"/>
            <body name="left_hand_link" pos="-0.00646036 0.21006 0.0128316" quat="0.99999 0.000875797 -0.0017611 -0.00391871">
              <inertial pos="-0.000258857 0.158806 0.010907" quat="0.708664 0.705505 -0.00325243 -0.00687367" mass="0.551233" diaginertia="0.00755421 0.0511232 0.00061674"/>
              <joint name="Left_Elbow_Yaw" pos="0 0 0" axis="0.0298939 -0.0263594 0.999205" range="-2.42385 0.0176955" armature="0.0144813" damping="0.0152994" frictionloss="0.0754975"/>
              <geom name="//unnamed_geom_17" class="visual" mesh="left_hand_link"/>
              <geom name="//unnamed_geom_18" class="collision" size="0.0367832 0.107284" pos="0 0.186596 0" quat="0.707105 0.707108 0 0" type="cylinder"/>
              <geom name="//unnamed_geom_19" class="reward_collision_sphere" size="0.0613053"/>
              <geom name="//unnamed_geom_20" class="reward_collision_sphere" size="0.0429137" pos="0 0.157889 0"/>
              <geom name="//unnamed_geom_21" class="reward_collision_sphere" size="0.0429137" pos="0 0.308601 0"/>
            </body>
          </body>
        </body>
      </body>
      <body name="AR1" pos="0.0572675 -0.157526 0.274472" quat="0.999994 0.00119174 0.00277532 0.00161711">
        <inertial pos="0.000407316 -0.0526079 -0.0122863" quat="0.504826 0.495644 -0.504526 0.494915" mass="0.973287" diaginertia="0.00148141 0.00774113 0.000733297"/>
        <joint name="Right_Shoulder_Pitch" pos="0 0 0" axis="-0.00294382 -0.999996 -0.000230288" range="-1.14183 3.32255" armature="0.0168991" damping="0" frictionloss="0.104431"/>
        <geom name="//unnamed_geom_22" class="visual" rgba="0.76 0.76 0.76 1" mesh="AR1"/>
        <body name="AR2" pos="0.00137012 -0.0784472 5.00275e-05" quat="1 -0.000213814 -8.3955e-05 -6.12002e-05">
          <inertial pos="0.00555818 -0.0551463 0.013076" quat="0.528075 0.481995 -0.527209 0.459203" mass="0.255668" diaginertia="0.000423623 0.00232089 0.000567457"/>
          <joint name="Right_Shoulder_Roll" pos="0 0 0" axis="-0.999904 0.0126635 0.00557078" range="-1.65305 1.33708" armature="0.0132878" damping="0.0663943" frictionloss="0.130036"/>
          <geom name="//unnamed_geom_23" class="visual" mesh="AR2"/>
          <body name="AR3" pos="-0.00946678 -0.0851135 0.00827525" quat="1 0.000250246 0.000226373 -0.000249815">
            <inertial pos="-0.00503173 -0.115205 0.0021162" quat="0.710301 0.703884 0.00227277 -0.00393912" mass="1.75493" diaginertia="0.0119052 0.0647634 0.00156974"/>
            <joint name="Right_Elbow_Pitch" pos="0 0 0" axis="-0.0207658 0.999676 0.0146966" stiffness="0.0411318" range="-2.29274 2.24623" armature="0.00455529" damping="0" frictionloss="0.197139"/>
            <geom name="//unnamed_geom_24" class="visual" mesh="AR3"/>
            <geom name="//unnamed_geom_25" class="collision" size="0.0367832 0.091958" pos="0 -0.0717676 0" quat="0.707105 0.707108 0 0" type="cylinder"/>
            <geom name="//unnamed_geom_26" class="reward_collision_sphere" size="0.0441398"/>
            <body name="right_hand_link" pos="-0.000559373 -0.211453 0.00290235" quat="0.999993 -0.000231491 -0.00325984 -0.00201442">
              <inertial pos="0.00372233 -0.156816 0.0146348" quat="0.736563 0.674519 0.00309597 0.0498968" mass="0.498739" diaginertia="0.0095542 0.0495397 0.000584119"/>
              <joint name="Right_Elbow_Yaw" pos="0 0 0" axis="0.0330353 -0.0173265 0.999304" stiffness="0.0580084" range="0.246415 2.17099" armature="0.0143612" damping="0.0245679" frictionloss="0.0983313"/>
              <geom name="//unnamed_geom_27" class="visual" mesh="right_hand_link"/>
              <geom name="//unnamed_geom_28" class="collision" size="0.0367832 0.107284" pos="0 -0.186596 0" quat="0.707105 0.707108 0 0" type="cylinder"/>
              <geom name="//unnamed_geom_29" class="reward_collision_sphere" size="0.0613053"/>
              <geom name="//unnamed_geom_30" class="reward_collision_sphere" size="0.0429137" pos="0 -0.157889 0"/>
              <geom name="//unnamed_geom_31" class="reward_collision_sphere" size="0.0429137" pos="0 -0.308601 0"/>
            </body>
          </body>
        </body>
      </body>
      <body name="Waist" pos="0.055869 -0.00516862 -0.145493" quat="0.999996 0.00196829 0.00145494 -0.00115209">
        <inertial pos="0.000549703 0.000467841 0.00213672" quat="0.984758 -0.0254838 -0.170884 -0.0200142" mass="5.29662" diaginertia="0.00612556 0.032939 0.0139741"/>
        <joint name="Waist" pos="0 0 0" axis="0.0579078 0.00485 0.99831" stiffness="0.0728977" range="-1.54893 1.57939" armature="0.00912394" damping="0" frictionloss="0.189942"/>
        <geom name="//unnamed_geom_32" class="visual" mesh="Waist"/>
        <body name="Hip_Pitch_Left" pos="-0.00658649 0.140372 0.00520512" quat="0.999996 -0.000574503 0.00265925 0.000110563">
          <inertial pos="-0.0124588 -0.0170228 -0.0108246" quat="0.981509 0.185023 -0.0239112 0.0428216" mass="1.64776" diaginertia="0.001774 0.0088492 0.00340812"/>
          <joint name="Left_Hip_Pitch" pos="0 0 0" axis="-0.0265133 0.999489 0.0178407" range="-1.83767 1.32856" armature="0.0128494" damping="0.0598473" frictionloss="0.137058"/>
          <geom name="//unnamed_geom_33" class="visual" rgba="0.76 0.76 0.76 1" mesh="Hip_Pitch_Left"/>
          <body name="Hip_Roll_Left" pos="-0.00179443 -0.00309166 -0.0367788" quat="0.999998 -0.000835169 0.00172973 0.000671685">
            <inertial pos="0.00976546 -0.0105106 -0.0672235" quat="0.693768 -0.0176532 -0.0469445 0.71845" mass="0.795256" diaginertia="0.00171874 0.0123426 0.00182153"/>
            <joint name="Left_Hip_Roll" pos="0 0 0" axis="-0.999571 -0.0123254 0.026561" stiffness="0.00829724" range="-1.58558 0.0762608" armature="0.0124091" damping="0" frictionloss="0.178934"/>
            <geom name="//unnamed_geom_34" class="visual" mesh="Hip_Roll_Left"/>
            <geom name="//unnamed_geom_35" class="reward_collision_sphere" size="0.0674359"/>
            <body name="Hip_Yaw_Left" pos="0.005549 -0.00979541 -0.111436" quat="0.999999 -8.27899e-06 0.00110492 0.000236964">
              <inertial pos="-0.00720478 -0.000427503 -0.109311" quat="0.732456 0.00707932 -0.0299571 0.680118" mass="4.88555" diaginertia="0.0275363 0.162481 0.00887149"/>
              <joint name="Left_Hip_Yaw" pos="0 0 0" axis="-0.046959 0.0399813 -0.998096" stiffness="0.0106876" range="-1.14523 1.20394" armature="0.0129516" damping="0" frictionloss="0.126567"/>
              <geom name="//unnamed_geom_36" class="visual" mesh="Hip_Yaw_Left"/>
              <geom name="//unnamed_geom_37" class="collision" size="0.0613053 0.0980885" type="cylinder"/>
              <body name="Shank_Left" pos="-0.0239085 -0.0117763 -0.155223" quat="1 -4.04587e-06 -3.22178e-06 4.82895e-06">
                <inertial pos="-0.00884333 0.0138648 -0.155299" quat="0.997281 -0.00214626 -0.0194114 0.071059" mass="3.20885" diaginertia="0.0286937 0.209855 0.00456844"/>
                <joint name="Left_Knee_Pitch" pos="0 0 0" axis="0.0252516 0.999661 0.0062664" range="-0.143007 2.35437" armature="0.00927557" damping="0" frictionloss="0.0312729"/>
                <geom name="//unnamed_geom_38" class="visual" mesh="Shank_Left"/>
                <geom name="//unnamed_geom_39" class="collision" size="0.0613053 0.091958" pos="0 0 -0.149139" type="cylinder"/>
                <geom name="//unnamed_geom_40" class="reward_collision_sphere" size="0.0796969"/>
                <body name="Ankle_Cross_Left" pos="-0.00447636 -0.00282557 -0.339639" quat="1 -0.000140214 0.000489706 -0.000164235">
                  <inertial pos="-0.0032684 0.000706886 -0.0176195" quat="0.439173 0.548511 0.547989 0.453841" mass="0.176864" diaginertia="2.99687e-05 0.000216528 4.05e-05"/>
                  <joint name="Left_Ankle_Pitch" pos="0 0 0" axis="-0.067089 0.997642 -0.0144593" stiffness="0.0654204" range="-0.768461 0.417749" armature="0.0120767" damping="0.00144939" frictionloss="0.162719"/>
                  <geom name="//unnamed_geom_41" class="visual" mesh="Ankle_Cross_Left"/>
                  <body name="left_foot_link" pos="-0.000194793 -0.00720202 -0.0154875" quat="0.999977 -0.00632517 -6.34756e-05 -0.00262609">
                    <inertial pos="-0.0128126 0.000995699 -0.00572129" quat="-0.0125104 0.639916 0.0442987 0.767065" mass="1.17258" diaginertia="0.00251949 0.013353 0.00670424"/>
                    <joint name="Left_Ankle_Roll" pos="0 0 0" axis="-0.999921 -0.000605174 0.0125442" range="-0.481754 0.586765" armature="0.0123859" damping="0.0530623" frictionloss="0.0903733"/>
                    <geom name="//unnamed_geom_42" class="visual" mesh="left_foot_link"/>
                    <geom name="left_foot" class="foot" size="0.0876252 0.0737718 0.0285813" pos="0.0100014 0 -0.0186424"/>
                    <geom name="//unnamed_geom_44" class="reward_collision_sphere" size="0.0637575" pos="0.0100014 0 -0.0186424"/>
                    <geom name="//unnamed_geom_45" class="reward_collision_sphere" size="0.0367832" pos="0.0950133 -0.0330131 -0.0186424"/>
                    <geom name="//unnamed_geom_46" class="reward_collision_sphere" size="0.0367832" pos="-0.0700098 -0.0330131 -0.0186424"/>
                    <site name="left_foot" class="foot" pos="0.0100014 0 -0.0186424" size="0.0122611"/>
                  </body>
                </body>
              </body>
            </body>
          </body>
        </body>
        <body name="Hip_Pitch_Right" pos="0.0103801 -0.152269 0.00353988" quat="0.99999 0.0024655 0.00358002 -0.000740259">
          <inertial pos="0.00821115 0.0150763 -0.0329845" quat="0.973578 -0.227943 0.0131566 -0.00379056" mass="1.77845" diaginertia="0.00158317 0.00786892 0.00340668"/>
          <joint name="Right_Hip_Pitch" pos="0 0 0" axis="-0.0110941 -0.999917 0.00653157" range="-1.56746 1.80021" armature="0.0125343" damping="0.0481808" frictionloss="0.065307"/>
          <geom name="//unnamed_geom_47" class="visual" rgba="0.76 0.76 0.76 1" mesh="Hip_Pitch_Right"/>
          <body name="Hip_Roll_Right" pos="-0.0111803 0.00431084 -0.0187334" quat="1 0.000418362 -0.000696739 0.000258472">
            <inertial pos="0.0126849 0.00716927 -0.0566523" quat="0.682918 -0.0141899 -0.0106316 0.73028" mass="0.607558" diaginertia="0.00171933 0.00925306 0.00163153"/>
            <joint name="Right_Hip_Roll" pos="0 0 0" axis="-0.999784 -0.0171929 -0.0117125" range="-0.0439979 1.6148" armature="0.00754031" damping="0.00096656" frictionloss="0.165773"/>
            <geom name="//unnamed_geom_48" class="visual" mesh="Hip_Roll_Right"/>
            <geom name="//unnamed_geom_49" class="reward_collision_sphere" size="0.0674359"/>
            <body name="Hip_Yaw_Right" pos="0.00807649 0.0022973 -0.102606" quat="1 -4.15517e-05 -8.85435e-06 4.32845e-05">
              <inertial pos="-0.0087893 0.0114549 -0.124053" quat="0.714801 -0.0331283 -0.0208401 0.698232" mass="3.29769" diaginertia="0.0245678 0.114222 0.00740717"/>
              <joint name="Right_Hip_Yaw" pos="0 0 0" axis="-0.00406143 0.00992926 -0.999942" range="-0.984813 1.00933" armature="0.0206093" damping="0.0388038" frictionloss="0.138442"/>
              <geom name="//unnamed_geom_50" class="visual" mesh="Hip_Yaw_Right"/>
              <geom name="//unnamed_geom_51" class="collision" size="0.0613053 0.0980885" type="cylinder"/>
              <body name="Shank_Right" pos="-0.0264693 0.00335538 -0.161181" quat="1 3.53755e-06 -3.70211e-05 0.000101962">
                <inertial pos="-0.019579 -0.0149945 -0.157358" quat="0.998807 -0.0443611 -0.00847504 -0.0185562" mass="2.7479" diaginertia="0.0237981 0.188237 0.00529007"/>
                <joint name="Right_Knee_Pitch" pos="0 0 0" axis="-0.0495724 -0.997967 -0.0400441" stiffness="0.0198509" range="-2.34482 -0.000567379" armature="0.0101373" damping="0" frictionloss="0.0823517"/>
                <geom name="//unnamed_geom_52" class="visual" mesh="Shank_Right"/>
                <geom name="//unnamed_geom_53" class="collision" size="0.0613053 0.091958" pos="0 0 -0.149139" type="cylinder"/>
                <geom name="//unnamed_geom_54" class="reward_collision_sphere" size="0.0796969"/>
                <body name="Ankle_Cross_Right" pos="-0.00741994 -0.00440801 -0.346002" quat="0.999998 0.00111471 0.00133149 -0.0009613">
                  <inertial pos="-0.00886577 -0.00754466 -0.0112474" quat="0.473213 0.53772 0.539926 0.442048" mass="0.151933" diaginertia="2.56699e-05 0.000159138 3.70285e-05"/>
                  <joint name="Right_Ankle_Pitch" pos="0 0 0" axis="0.042454 -0.997245 -0.0608351" stiffness="0.0137272" range="-0.253068 0.867284" armature="0.0100154" damping="0" frictionloss="0.0957177"/>
                  <geom name="//unnamed_geom_55" class="visual" mesh="Ankle_Cross_Right"/>
                  <body name="right_foot_link" pos="0.00501727 0.0105633 -0.0249478" quat="1 -1.03351e-05 4.35594e-06 -4.53996e-06">
                    <inertial pos="-0.0137186 -0.000816904 -0.0197687" quat="-0.0459246 0.611683 -0.0147048 0.789632" mass="1.26068" diaginertia="0.00222991 0.0147232 0.00709289"/>
                    <joint name="Right_Ankle_Roll" pos="0 0 0" axis="-0.998602 -0.00919549 -0.0520597" stiffness="0.000683275" range="-0.428149 0.54582" armature="0.00882474" damping="0" frictionloss="0.199881"/>
                    <geom name="//unnamed_geom_56" class="visual" mesh="right_foot_link"/>
                    <geom name="right_foot" class="foot" size="0.0899647 0.0694205 0.0239787" pos="0.0100014 0 -0.0186424"/>
                    <geom name="//unnamed_geom_58" class="reward_collision_sphere" size="0.0490443"/>
                    <geom name="//unnamed_geom_59" class="reward_collision_sphere" size="0.0367832" pos="0.0100014 0 -0.0186424"/>
                    <geom name="//unnamed_geom_60" class="reward_collision_sphere" size="0.0367832" pos="0.0950133 0.0330131 -0.0186424"/>
                    <geom name="//unnamed_geom_61" class="reward_collision_sphere" size="0.0367832" pos="-0.0700098 0.0330131 -0.0186424"/>
                    <site name="right_foot" class="foot" pos="0.0100014 0 -0.0186424" size="0.0122611"/>
                  </body>
                </body>
              </body>
            </body>
          </body>
        </body>
      </body>
    </body>
  </worldbody>

  <contact>
    <pair class="/" geom1="floor" geom2="left_foot" name="//unnamed_contact_0"/>
    <pair class="/" geom1="floor" geom2="right_foot" name="//unnamed_contact_1"/>
  </contact>

  <actuator>
    <general name="AAHead_yaw" class="/" joint="AAHead_yaw" forcerange="-12.3461 12.3461" gainprm="32.9925" biasprm="0 -32.9925 -0.741389"/>
    <general name="Head_pitch" class="/" joint="Head_pitch" forcerange="-6.90517 6.90517" gainprm="32.9925" biasprm="0 -32.9925 -0.741389"/>
    <general name="Left_Shoulder_Pitch" class="/" joint="Left_Shoulder_Pitch" forcerange="-22.3013 22.3013" gainprm="32.9925" biasprm="0 -32.9925 -0.741389"/>
    <general name="Left_Shoulder_Roll" class="/" joint="Left_Shoulder_Roll" forcerange="-17.091 17.091" gainprm="32.9925" biasprm="0 -32.9925 -0.741389"/>
    <general name="Left_Elbow_Pitch" class="/" joint="Left_Elbow_Pitch" forcerange="-13.7579 13.7579" gainprm="32.9925" biasprm="0 -32.9925 -0.741389"/>
    <general name="Left_Elbow_Yaw" class="/" joint="Left_Elbow_Yaw" forcerange="-10.7244 10.7244" gainprm="32.9925" biasprm="0 -32.9925 -0.741389"/>
    <general name="Right_Shoulder_Pitch" class="/" joint="Right_Shoulder_Pitch" forcerange="-23.0977 23.0977" gainprm="32.9925" biasprm="0 -32.9925 -0.741389"/>
    <general name="Right_Shoulder_Roll" class="/" joint="Right_Shoulder_Roll" forcerange="-13.6972 13.6972" gainprm="32.9925" biasprm="0 -32.9925 -0.741389"/>
    <general name="Right_Elbow_Pitch" class="/" joint="Right_Elbow_Pitch" forcerange="-15.4478 15.4478" gainprm="32.9925" biasprm="0 -32.9925 -0.741389"/>
    <general name="Right_Elbow_Yaw" class="/" joint="Right_Elbow_Yaw" forcerange="-29.902 29.902" gainprm="32.9925" biasprm="0 -32.9925 -0.741389"/>
    <general name="Waist" class="/" joint="Waist" forcerange="-37.3796 37.3796" gainprm="32.9925" biasprm="0 -32.9925 -0.741389"/>
    <general name="Left_Hip_Pitch" class="/" joint="Left_Hip_Pitch" forcerange="-39.2381 39.2381" gainprm="32.9925" biasprm="0 -32.9925 -0.741389"/>
    <general name="Left_Hip_Roll" class="/" joint="Left_Hip_Roll" forcerange="-39.4904 39.4904" gainprm="32.9925" biasprm="0 -32.9925 -0.741389"/>
    <general name="Left_Hip_Yaw" class="/" joint="Left_Hip_Yaw" forcerange="-30.6451 30.6451" gainprm="32.9925" biasprm="0 -32.9925 -0.741389"/>
    <general name="Left_Knee_Pitch" class="/" joint="Left_Knee_Pitch" forcerange="-71.9168 71.9168" gainprm="32.9925" biasprm="0 -32.9925 -0.741389"/>
    <general name="Left_Ankle_Pitch" class="/" joint="Left_Ankle_Pitch" forcerange="-21.0497 21.0497" gainprm="32.9925" biasprm="0 -32.9925 -0.741389"/>
    <general name="Left_Ankle_Roll" class="/" joint="Left_Ankle_Roll" forcerange="-18.6719 18.6719" gainprm="32.9925" biasprm="0 -32.9925 -0.741389"/>
    <general name="Right_Hip_Pitch" class="/" joint="Right_Hip_Pitch" forcerange="-56.0265 56.0265" gainprm="32.9925" biasprm="0 -32.9925 -0.741389"/>
    <general name="Right_Hip_Roll" class="/" joint="Right_Hip_Roll" forcerange="-36.2115 36.2115" gainprm="32.9925" biasprm="0 -32.9925 -0.741389"/>
    <general name="Right_Hip_Yaw" class="/" joint="Right_Hip_Yaw" forcerange="-37.5031 37.5031" gainprm="32.9925" biasprm="0 -32.9925 -0.741389"/>
    <general name="Right_Knee_Pitch" class="/" joint="Right_Knee_Pitch" forcerange="-92.0127 92.0127" gainprm="32.9925" biasprm="0 -32.9925 -0.741389"/>
    <general name="Right_Ankle_Pitch" class="/" joint="Right_Ankle_Pitch" forcerange="-33.7011 33.7011" gainprm="32.9925" biasprm="0 -32.9925 -0.741389"/>
    <general name="Right_Ankle_Roll" class="/" joint="Right_Ankle_Roll" forcerange="-12.9579 12.9579" gainprm="32.9925" biasprm="0 -32.9925 -0.741389"/>
  </actuator>

  <sensor>
    <gyro site="imu" name="imu_angular_velocity"/>
    <velocimeter site="imu" name="imu_linear_velocity"/>
    <framelinvel objtype="site" objname="left_foot" name="left_foot_global_linear_velocity"/>
    <framelinvel objtype="site" objname="right_foot" name="right_foot_global_linear_velocity"/>
  </sensor>

  <keyframe>
    <key name="home" qpos="0 0 0.6385 1 0 0 0 0 0 0 1.4 0 -0.4 0 -1.4 0 0.4 0 -0.4 0 0 0.8 -0.4 0 0.4 0 0 -0.8 0.4 0"/>
  </keyframe>
</mujoco>
