<mujoco model="T1">
  <compiler angle="radian" assetdir="assets" balanceinertia="true" inertiafromgeom="false"/>

  <option timestep="0.005" density="1.2" viscosity="2e-05"/>

  <size nkey="1"/>

  <visual>
    <quality shadowsize="8192"/>
    <map shadowclip="0.5"/>
  </visual>

  <default>
    <default class="/">
      <joint armature="0.01" damping="0.01" frictionloss="0.1"/>
      <geom contype="0" conaffinity="0" group="1" solref="-1000 -80"/>
      <site size="0.01 0.005 0.005" group="5"/>
      <general forcelimited="true" biastype="affine" gainprm="25" biasprm="0 -25 -0.6"/>
      <default class="t1">
        <geom rgba="0.25 0.25 0.25 1"/>
        <default class="visual">
          <geom type="mesh" group="2"/>
        </default>
        <default class="collision">
          <geom group="3"/>
        </default>
        <default class="foot">
          <geom size="0.1115 0.05 0.015" type="box" condim="6" group="4" priority="1" solimp="0.015 1 0.015"/>
        </default>
        <default class="reward_collision_sphere">
          <geom group="5" rgba="1 0 0 1"/>
        </default>
      </default>
    </default>
  </default>

  <asset>
    <texture type="skybox" colorspace="auto" name="//unnamed_texture_0" builtin="gradient" rgb1="0.95 0.95 0.95" rgb2="0.95 0.95 0.95" width="100" height="600"/>
    <texture type="2d" colorspace="auto" name="texplane" builtin="checker" rgb1="0.345 0.575 0.748" rgb2="0.345 0.575 0.748" markrgb="1 1 1" width="512" height="512"/>
    <material name="MatPlane" class="/" texture="texplane" texuniform="true" texrepeat="2 2" specular="0.9"/>
    <mesh name="Trunk" class="/" file="Trunk.stl"/>
    <mesh name="H1" class="/" file="H1.stl"/>
    <mesh name="H2" class="/" file="H2.stl"/>
    <mesh name="AL1" class="/" file="AL1.stl"/>
    <mesh name="AL2" class="/" file="AL2.stl"/>
    <mesh name="AL3" class="/" file="AL3.stl"/>
    <mesh name="left_hand_link" class="/" file="left_hand_link.stl"/>
    <mesh name="AR1" class="/" file="AR1.stl"/>
    <mesh name="AR2" class="/" file="AR2.stl"/>
    <mesh name="AR3" class="/" file="AR3.stl"/>
    <mesh name="right_hand_link" class="/" file="right_hand_link.stl"/>
    <mesh name="Waist" class="/" file="Waist.stl"/>
    <mesh name="Hip_Pitch_Left" class="/" file="Hip_Pitch_Left.stl"/>
    <mesh name="Hip_Roll_Left" class="/" file="Hip_Roll_Left.stl"/>
    <mesh name="Hip_Yaw_Left" class="/" file="Hip_Yaw_Left.stl"/>
    <mesh name="Shank_Left" class="/" file="Shank_Left.stl"/>
    <mesh name="Ankle_Cross_Left" class="/" file="Ankle_Cross_Left.stl"/>
    <mesh name="left_foot_link" class="/" file="left_foot_link.stl"/>
    <mesh name="Hip_Pitch_Right" class="/" file="Hip_Pitch_Right.stl"/>
    <mesh name="Hip_Roll_Right" class="/" file="Hip_Roll_Right.stl"/>
    <mesh name="Hip_Yaw_Right" class="/" file="Hip_Yaw_Right.stl"/>
    <mesh name="Shank_Right" class="/" file="Shank_Right.stl"/>
    <mesh name="Ankle_Cross_Right" class="/" file="Ankle_Cross_Right.stl"/>
    <mesh name="right_foot_link" class="/" file="right_foot_link.stl"/>
  </asset>

  <worldbody>
    <geom name="floor" class="/" size="100 100 0.125" type="plane" group="0" material="MatPlane"/>
    <light name="toplight_shadow" class="/" pos="0 0 5" dir="0.0990148 0.0990148 -0.990148" type="directional" ambient="0.04 0.04 0.04" diffuse="0.55 0.55 0.55" specular="0.12 0.12 0.12"/>
    <light name="toplight_fill" class="/" pos="0 0 5" dir="0.0990148 0.0990148 -0.990148" type="directional" castshadow="false" ambient="0.04 0.04 0.04" diffuse="0.3 0.3 0.3" specular="0.08 0.08 0.08"/>
    <body name="trunk" childclass="t1" pos="-0.00078948 -0.00272396 0.0016557" quat="1 0.000612421 -4.15386e-07 -0.000738758">
      <inertial pos="0.0400338 -0.000985871 0.106575" quat="0.999989 -0.000886975 -0.00415166 0.00202741" mass="7.87359" diaginertia="0.0189583 0.0526778 0.0570561"/>
      <joint name="//unnamed_joint_0" type="free" armature="0" damping="0" frictionloss="0"/>
      <geom name="//unnamed_geom_1" class="visual" rgba="0.76 0.76 0.76 1" mesh="Trunk"/>
      <geom name="//unnamed_geom_2" class="collision" size="0.0663559 0.0884745 0.132712" pos="0.0438067 0 0.120439" type="box"/>
      <geom name="//unnamed_geom_3" class="reward_collision_sphere" size="0.101746" pos="0.0438067 0 0.100366"/>
      <geom name="//unnamed_geom_4" class="reward_collision_sphere" size="0.0132712" pos="0.0438067 0.0782398 0"/>
      <geom name="//unnamed_geom_5" class="reward_collision_sphere" size="0.0132712" pos="0.0438067 -0.0782398 0"/>
      <geom name="//unnamed_geom_6" class="reward_collision_sphere" size="0.0132712" pos="0.0438067 0.0984901 0.180658"/>
      <geom name="//unnamed_geom_7" class="reward_collision_sphere" size="0.0132712" pos="0.0438067 -0.0984901 0.180658"/>
      <site name="imu" pos="-0.0108942 -0.0138481 0.000913976" size="0.00884745"/>
      <camera name="track" pos="0 -1.84094 0" quat="0.707107 0.707107 0 0" mode="trackcom"/>
      <camera name="ego_camera" pos="0.0890736 0 0.421535" quat="-0.5 -0.5 0.5 0.5"/>
      <body name="H1" pos="0.0454854 0.000921237 0.244647" quat="1 -0.000380969 0.000563245 -0.000247187">
        <inertial pos="8.46557e-05 -0.00137389 0.0596044" quat="0.762191 -0.00698085 0.0112508 0.647217" mass="0.30552" diaginertia="4.89244e-05 0.000150609 0.000147454"/>
        <joint name="AAHead_yaw" pos="0 0 0" axis="-0.0134106 -0.000439686 0.99991" range="-1.61564 1.54766" armature="0.00965516" damping="0.00788869" frictionloss="0.0774997"/>
        <geom name="//unnamed_geom_8" class="visual" mesh="H1"/>
        <body name="H2" pos="0.0021997 0.000979418 0.062696" quat="1 9.28338e-05 -0.000352885 -0.000197647">
          <inertial pos="0.00485376 -0.00164579 0.0988883" quat="0.988752 0.10764 -0.0702708 -0.0764509" mass="0.422337" diaginertia="0.000407883 0.00119343 0.00168536"/>
          <joint name="Head_pitch" pos="0 0 0" axis="-0.00546948 -0.999904 -0.0127125" range="-1.20011 0.378991" armature="0.00839994" damping="0.0107018" frictionloss="0.0863014"/>
          <geom name="//unnamed_geom_9" class="visual" mesh="H2"/>
          <geom name="//unnamed_geom_10" class="collision" size="0.0707796" pos="0.00730112 0 0.110402"/>
          <geom name="//unnamed_geom_11" class="reward_collision_sphere" size="0.0796271" pos="0.0146022 0 0.100366"/>
        </body>
      </body>
      <body name="AL1" pos="0.0427901 0.0975725 0.218952" quat="1 -5.23167e-05 0.000529512 -0.000119755">
        <inertial pos="-0.00149075 0.0407149 -0.00256988" quat="0.507786 0.484515 -0.51075 0.496521" mass="0.377551" diaginertia="0.000289752 0.000883854 0.00031013"/>
        <joint name="Left_Shoulder_Pitch" pos="0 0 0" axis="0.0145155 0.999895 0.000227497" stiffness="0.00582505" range="-3.30984 1.20689" armature="0.00911163" damping="0.0148776" frictionloss="0.083889"/>
        <geom name="//unnamed_geom_12" class="visual" rgba="0.76 0.76 0.76 1" mesh="AL1"/>
        <body name="AL2" pos="0.00215777 0.0419189 -0.0027256" quat="1 -0.000219105 -0.000869813 -3.1075e-05">
          <inertial pos="0.00219736 0.0325635 -0.000343556" quat="0.487745 0.51229 -0.487414 0.511948" mass="0.108578" diaginertia="8.35713e-05 0.000221679 0.000176697"/>
          <joint name="Left_Shoulder_Roll" pos="0 0 0" axis="-0.999895 -0.00331206 -0.0140814" range="-1.51668 1.74726" armature="0.00851339" damping="0" frictionloss="0.100657"/>
          <geom name="//unnamed_geom_13" class="visual" mesh="AL2"/>
          <body name="AL3" pos="0.00317267 0.0583741 0.00205776" quat="0.999999 6.69998e-05 -0.000398871 -0.00113062">
            <inertial pos="-0.000324766 0.0757583 -0.000568442" quat="0.70805 0.706107 0.00140096 0.00875807" mass="0.712066" diaginertia="0.00263568 0.00858285 0.000601201"/>
            <joint name="Left_Elbow_Pitch" pos="0 0 0" axis="-0.0108928 -0.999906 -0.00828173" range="-2.22742 2.21761" armature="0.0101112" damping="0" frictionloss="0.100091"/>
            <geom name="//unnamed_geom_14" class="visual" mesh="AL3"/>
            <geom name="//unnamed_geom_15" class="collision" size="0.0265424 0.0663559" pos="0 0.0460234 0" quat="0.707105 0.707108 0 0" type="cylinder"/>
            <geom name="//unnamed_geom_16" class="reward_collision_sphere" size="0.0318508"/>
            <body name="left_hand_link" pos="0.00215326 0.135949 -0.00154054" quat="0.999999 -0.000952805 -0.000428725 0.000532407">
              <inertial pos="-0.000102949 0.10171 -0.00222429" quat="0.710502 0.703688 -0.00239879 0.00207727" mass="0.232067" diaginertia="0.00172258 0.00545578 0.00021705"/>
              <joint name="Left_Elbow_Yaw" pos="0 0 0" axis="0.0109585 0.0109888 0.99988" stiffness="0.00864184" range="-2.44107 0.0119553" armature="0.00902295" damping="0.0122811" frictionloss="0.096923"/>
              <geom name="//unnamed_geom_17" class="visual" mesh="left_hand_link"/>
              <geom name="//unnamed_geom_18" class="collision" size="0.0265424 0.0774152" pos="0 0.119661 0" quat="0.707105 0.707108 0 0" type="cylinder"/>
              <geom name="//unnamed_geom_19" class="reward_collision_sphere" size="0.0442373"/>
              <geom name="//unnamed_geom_20" class="reward_collision_sphere" size="0.0309661" pos="0 0.101252 0"/>
              <geom name="//unnamed_geom_21" class="reward_collision_sphere" size="0.0309661" pos="0 0.197901 0"/>
            </body>
          </body>
        </body>
      </body>
      <body name="AR1" pos="0.0417363 -0.0963713 0.220128" quat="1 0.000254817 -0.000125126 0.000365574">
        <inertial pos="-0.000505663 -0.0442572 0.0026413" quat="0.505212 0.495613 -0.503649 0.495445" mass="0.367331" diaginertia="0.000271107 0.000856028 0.000304518"/>
        <joint name="Right_Shoulder_Pitch" pos="0 0 0" axis="0.00186283 -0.999997 0.00171941" range="-1.21912 3.30601" armature="0.00792219" damping="0.00630344" frictionloss="0.0844722"/>
        <geom name="//unnamed_geom_22" class="visual" rgba="0.76 0.76 0.76 1" mesh="AR1"/>
        <body name="AR2" pos="0.00072244 -0.0394087 -0.000966857" quat="1 0.000154507 1.31547e-05 -0.000208433">
          <inertial pos="0.00350233 -0.0348804 -0.00244956" quat="0.508259 0.485145 -0.510577 0.495599" mass="0.112454" diaginertia="8.03155e-05 0.000219564 0.000172767"/>
          <joint name="Right_Shoulder_Roll" pos="0 0 0" axis="-0.999972 0.00707553 -0.00257462" stiffness="0.0110165" range="-1.73334 1.62674" armature="0.00866434" damping="0" frictionloss="0.0870629"/>
          <geom name="//unnamed_geom_23" class="visual" mesh="AR2"/>
          <body name="AR3" pos="0.00216752 -0.0552526 -0.00265104" quat="1 5.1762e-05 -0.000564429 -0.00017742">
            <inertial pos="4.38707e-05 -0.0803302 0.00102689" quat="0.707916 0.706296 0.00091632 0.000365613" mass="0.704727" diaginertia="0.00267543 0.0087452 0.000648067"/>
            <joint name="Right_Elbow_Pitch" pos="0 0 0" axis="-0.00103268 0.999999 -0.00119844" range="-2.26505 2.27697" armature="0.0100332" damping="0.00737107" frictionloss="0.0763134"/>
            <geom name="//unnamed_geom_24" class="visual" mesh="AR3"/>
            <geom name="//unnamed_geom_25" class="collision" size="0.0265424 0.0663559" pos="0 -0.0460234 0" quat="0.707105 0.707108 0 0" type="cylinder"/>
            <geom name="//unnamed_geom_26" class="reward_collision_sphere" size="0.0318508"/>
            <body name="right_hand_link" pos="3.06304e-05 -0.136123 0.00040778" quat="0.999999 0.000758904 0.00024847 -0.000753659">
              <inertial pos="0.000359639 -0.100401 -0.00176172" quat="0.714724 0.699394 -0.00153721 -0.00387364" mass="0.231606" diaginertia="0.00162781 0.00537249 0.000223427"/>
              <joint name="Right_Elbow_Yaw" pos="0 0 0" axis="-0.00207703 -0.00551314 0.999983" range="-0.0553326 2.48838" armature="0.0091677" damping="0.00791022" frictionloss="0.0868161"/>
              <geom name="//unnamed_geom_27" class="visual" mesh="right_hand_link"/>
              <geom name="//unnamed_geom_28" class="collision" size="0.0265424 0.0774152" pos="0 -0.119661 0" quat="0.707105 0.707108 0 0" type="cylinder"/>
              <geom name="//unnamed_geom_29" class="reward_collision_sphere" size="0.0442373"/>
              <geom name="//unnamed_geom_30" class="reward_collision_sphere" size="0.0309661" pos="0 -0.101252 0"/>
              <geom name="//unnamed_geom_31" class="reward_collision_sphere" size="0.0309661" pos="0 -0.197901 0"/>
            </body>
          </body>
        </body>
      </body>
      <body name="Waist" pos="0.0475128 -0.000325245 -0.116774" quat="1 -0.000146865 5.4114e-05 0.000489811">
        <inertial pos="0.000423311 3.06273e-05 0.00907645" quat="0.984421 0.00396599 -0.175755 -0.00314678" mass="1.73928" diaginertia="0.0010755 0.00353136 0.00482696"/>
        <joint name="Waist" pos="0 0 0" axis="-0.0121198 -0.0100122 0.999876" range="-1.56929 1.57893" armature="0.00907413" damping="0.0239839" frictionloss="0.0762191"/>
        <geom name="//unnamed_geom_32" class="visual" mesh="Waist"/>
        <body name="Hip_Pitch_Left" pos="0.00357783 0.0995439 -0.000976566" quat="1 -0.000100977 0.000373388 -2.52001e-05">
          <inertial pos="0.00305207 -0.0057403 -0.0210232" quat="0.975759 0.217626 0.0215725 -0.00822094" mass="0.731251" diaginertia="0.000375316 0.000974796 0.00129155"/>
          <joint name="Left_Hip_Pitch" pos="0 0 0" axis="-0.00370131 0.99997 -0.00678123" range="-1.80406 1.62688" armature="0.00916493" damping="0" frictionloss="0.093172"/>
          <geom name="//unnamed_geom_33" class="visual" rgba="0.76 0.76 0.76 1" mesh="Hip_Pitch_Left"/>
          <body name="Hip_Roll_Left" pos="0.00235178 -0.000778914 -0.0178807" quat="1 0.000127502 5.36003e-05 0.000153823">
            <inertial pos="-0.00120101 0.00273152 -0.0544055" quat="0.709884 -0.00113626 -0.0167436 0.704119" mass="0.259167" diaginertia="0.000363112 0.000943223 0.000511421"/>
            <joint name="Left_Hip_Roll" pos="0 0 0" axis="-0.999999 -0.000288953 -0.00121852" range="-1.58038 0.222958" armature="0.00875952" damping="0.00749701" frictionloss="0.0774609"/>
            <geom name="//unnamed_geom_34" class="visual" mesh="Hip_Roll_Left"/>
            <geom name="//unnamed_geom_35" class="reward_collision_sphere" size="0.048661"/>
            <body name="Hip_Yaw_Left" pos="-0.000457791 0.00182082 -0.080389" quat="1 -0.000192707 2.03878e-05 -0.000193393">
              <inertial pos="-0.00474468 -0.000785201 -0.0887229" quat="0.690487 -0.0439996 -0.0313755 0.721323" mass="1.42335" diaginertia="0.00525658 0.0161993 0.00258033"/>
              <joint name="Left_Hip_Yaw" pos="0 0 0" axis="-0.00151069 -0.0127622 -0.999917" range="-0.978803 0.953832" armature="0.00908413" damping="0.00944763" frictionloss="0.0908067"/>
              <geom name="//unnamed_geom_36" class="visual" mesh="Hip_Yaw_Left"/>
              <geom name="//unnamed_geom_37" class="collision" size="0.0442373 0.0707796" type="cylinder"/>
              <body name="Shank_Left" pos="-0.00639864 0.00214766 -0.137934" quat="1 -0.000160502 -0.000326823 0.00055974">
                <inertial pos="-0.00530148 -0.00235225 -0.125004" quat="0.997392 0.00573528 -0.0261177 0.0670408" mass="1.20185" diaginertia="0.00742792 0.0227931 0.00195446"/>
                <joint name="Left_Knee_Pitch" pos="0 0 0" axis="0.00419939 0.999973 -0.00610288" range="0.0302149 2.34001" armature="0.0088844" damping="0.0196549" frictionloss="0.0978369"/>
                <geom name="//unnamed_geom_38" class="visual" mesh="Shank_Left"/>
                <geom name="//unnamed_geom_39" class="collision" size="0.0442373 0.0663559" pos="0 0 -0.120439" type="cylinder"/>
                <geom name="//unnamed_geom_40" class="reward_collision_sphere" size="0.0575084"/>
                <body name="Ankle_Cross_Left" pos="6.66192e-05 -0.0013772 -0.283644" quat="1 5.0567e-06 0.000117534 -0.000214454">
                  <inertial pos="-0.00239117 0.000291788 -0.00611452" quat="0.440174 0.55442 0.548807 0.444607" mass="0.0476766" diaginertia="6.04737e-06 1.59782e-05 1.13695e-05"/>
                  <joint name="Left_Ankle_Pitch" pos="0 0 0" axis="-0.00788966 0.999894 -0.0122578" range="-0.879702 0.362241" armature="0.00878655" damping="0.00436879" frictionloss="0.0827049"/>
                  <geom name="//unnamed_geom_41" class="visual" mesh="Ankle_Cross_Left"/>
                  <body name="left_foot_link" pos="0.000825243 0.00152751 -0.0119853" quat="0.999999 -4.6732e-05 -5.48701e-05 -0.00128896">
                    <inertial pos="0.00267195 0.000752074 -0.00975761" quat="-0.00388131 0.611287 0.0054064 0.791381" mass="0.485634" diaginertia="0.000569385 0.00160369 0.00218677"/>
                    <joint name="Left_Ankle_Roll" pos="0 0 0" axis="-1 -0.00025952 -0.000304771" range="-0.451794 0.406428" armature="0.0089069" damping="0" frictionloss="0.0904268"/>
                    <geom name="//unnamed_geom_42" class="visual" mesh="left_foot_link"/>
                    <geom name="left_foot" class="foot" size="0.109057 0.04052 0.0122136" pos="0.00730112 0 -0.0150548"/>
                    <geom name="//unnamed_geom_44" class="reward_collision_sphere" size="0.0460068" pos="0.00730112 0 -0.0150548"/>
                    <geom name="//unnamed_geom_45" class="reward_collision_sphere" size="0.0265424" pos="0.0693606 -0.0211708 -0.0150548"/>
                    <geom name="//unnamed_geom_46" class="reward_collision_sphere" size="0.0265424" pos="-0.0511078 -0.0211708 -0.0150548"/>
                    <site name="left_foot" class="foot" pos="0.00730112 0 -0.0150548" size="0.00884745"/>
                  </body>
                </body>
              </body>
            </body>
          </body>
        </body>
        <body name="Hip_Pitch_Right" pos="-0.00336897 -0.098669 0.000552562" quat="0.999999 0.00102562 0.000577771 -0.000962969">
          <inertial pos="-0.00154028 0.00726639 -0.0151915" quat="0.973573 -0.227806 0.0157245 -0.00366346" mass="0.726464" diaginertia="0.000380797 0.000987948 0.00132605"/>
          <joint name="Right_Hip_Pitch" pos="0 0 0" axis="0.000734961 -0.999999 -0.000975393" range="-1.56975 1.8151" armature="0.00907287" damping="0" frictionloss="0.0996984"/>
          <geom name="//unnamed_geom_47" class="visual" rgba="0.76 0.76 0.76 1" mesh="Hip_Pitch_Right"/>
          <body name="Hip_Roll_Right" pos="0.00244663 0.000982712 -0.0211221" quat="1 0.000186834 -2.9719e-05 0.000116992">
            <inertial pos="-0.00174344 -0.00193254 -0.0565312" quat="0.712244 -0.00564638 -0.00828423 0.70186" mass="0.275282" diaginertia="0.000357362 0.00100015 0.000518108"/>
            <joint name="Right_Hip_Roll" pos="0 0 0" axis="-0.999979 0.0039207 0.00518254" range="-0.242015 1.59214" armature="0.009625" damping="0.00398553" frictionloss="0.0814276"/>
            <geom name="//unnamed_geom_48" class="visual" mesh="Hip_Roll_Right"/>
            <geom name="//unnamed_geom_49" class="reward_collision_sphere" size="0.048661"/>
            <body name="Hip_Yaw_Right" pos="-0.00145175 0.000774811 -0.0822392" quat="1 1.70661e-05 -1.84219e-05 6.34493e-05">
              <inertial pos="-0.00498262 -0.00321911 -0.0870918" quat="0.711359 -0.0292962 -0.0334534 0.701421" mass="1.54982" diaginertia="0.00532524 0.0178019 0.00263412"/>
              <joint name="Right_Hip_Yaw" pos="0 0 0" axis="0.000933478 0.00247842 -0.999996" stiffness="0.0102659" range="-0.976778 1.00185" armature="0.00771824" damping="0" frictionloss="0.0929325"/>
              <geom name="//unnamed_geom_50" class="visual" mesh="Hip_Yaw_Right"/>
              <geom name="//unnamed_geom_51" class="collision" size="0.0442373 0.0707796" type="cylinder"/>
              <body name="Shank_Right" pos="-0.00755332 0.000312535 -0.135677" quat="1 -8.95122e-05 -5.04796e-07 -0.000143355">
                <inertial pos="-0.00176163 0.00184098 -0.122957" quat="0.998961 -0.0100244 -0.0322625 -0.0306033" mass="1.2799" diaginertia="0.00772558 0.0236939 0.00201787"/>
                <joint name="Right_Knee_Pitch" pos="0 0 0" axis="-0.000273885 -0.999983 -0.00581237" range="-2.34326 -0.00419818" armature="0.00864086" damping="0.00387392" frictionloss="0.0943155"/>
                <geom name="//unnamed_geom_52" class="visual" mesh="Shank_Right"/>
                <geom name="//unnamed_geom_53" class="collision" size="0.0442373 0.0663559" pos="0 0 -0.120439" type="cylinder"/>
                <geom name="//unnamed_geom_54" class="reward_collision_sphere" size="0.0575084"/>
                <body name="Ankle_Cross_Right" pos="0.00245257 -0.000356885 -0.281257" quat="1 5.86741e-05 0.000116375 -0.000138903">
                  <inertial pos="-0.00262793 0.00207148 -0.00805512" quat="0.44235 0.556985 0.54635 0.442261" mass="0.0488274" diaginertia="6.20464e-06 1.70274e-05 1.12623e-05"/>
                  <joint name="Right_Ankle_Pitch" pos="0 0 0" axis="-0.00110301 -0.999921 -0.0125211" range="-0.354986 0.869797" armature="0.00857229" damping="0.0030571" frictionloss="0.0878504"/>
                  <geom name="//unnamed_geom_55" class="visual" mesh="Ankle_Cross_Right"/>
                  <body name="right_foot_link" pos="0.000391416 -0.00388489 -0.0093116" quat="1 5.3806e-06 6.58056e-05 1.7633e-07">
                    <inertial pos="0.00250112 -0.00047166 -0.00688436" quat="-0.0110439 0.61498 0.000712985 0.788465" mass="0.471971" diaginertia="0.000577049 0.00158659 0.00219338"/>
                    <joint name="Right_Ankle_Roll" pos="0 0 0" axis="-0.99989 0.000383638 0.0147937" stiffness="0.000925765" range="-0.434693 0.429751" armature="0.00905969" damping="0.00704081" frictionloss="0.0765831"/>
                    <geom name="//unnamed_geom_56" class="visual" mesh="right_foot_link"/>
                    <geom name="right_foot" class="foot" size="0.102977 0.0401799 0.0122417" pos="0.00730112 0 -0.0150548"/>
                    <geom name="//unnamed_geom_58" class="reward_collision_sphere" size="0.0353898"/>
                    <geom name="//unnamed_geom_59" class="reward_collision_sphere" size="0.0265424" pos="0.00730112 0 -0.0150548"/>
                    <geom name="//unnamed_geom_60" class="reward_collision_sphere" size="0.0265424" pos="0.0693606 0.0211708 -0.0150548"/>
                    <geom name="//unnamed_geom_61" class="reward_collision_sphere" size="0.0265424" pos="-0.0511078 0.0211708 -0.0150548"/>
                    <site name="right_foot" class="foot" pos="0.00730112 0 -0.0150548" size="0.00884745"/>
                  </body>
                </body>
              </body>
            </body>
          </body>
        </body>
      </body>
    </body>
  </worldbody>

  <contact>
    <pair class="/" geom1="floor" geom2="left_foot" name="//unnamed_contact_0"/>
    <pair class="/" geom1="floor" geom2="right_foot" name="//unnamed_contact_1"/>
  </contact>

  <actuator>
    <general name="AAHead_yaw" class="/" joint="AAHead_yaw" forcerange="-5.54807 5.54807" gainprm="22.3124" biasprm="0 -22.3124 -0.502517"/>
    <general name="Head_pitch" class="/" joint="Head_pitch" forcerange="-6.29818 6.29818" gainprm="22.3124" biasprm="0 -22.3124 -0.502517"/>
    <general name="Left_Shoulder_Pitch" class="/" joint="Left_Shoulder_Pitch" forcerange="-16.1263 16.1263" gainprm="22.3124" biasprm="0 -22.3124 -0.502517"/>
    <general name="Left_Shoulder_Roll" class="/" joint="Left_Shoulder_Roll" forcerange="-16.0992 16.0992" gainprm="22.3124" biasprm="0 -22.3124 -0.502517"/>
    <general name="Left_Elbow_Pitch" class="/" joint="Left_Elbow_Pitch" forcerange="-17.5833 17.5833" gainprm="22.3124" biasprm="0 -22.3124 -0.502517"/>
    <general name="Left_Elbow_Yaw" class="/" joint="Left_Elbow_Yaw" forcerange="-17.457 17.457" gainprm="22.3124" biasprm="0 -22.3124 -0.502517"/>
    <general name="Right_Shoulder_Pitch" class="/" joint="Right_Shoulder_Pitch" forcerange="-15.9298 15.9298" gainprm="22.3124" biasprm="0 -22.3124 -0.502517"/>
    <general name="Right_Shoulder_Roll" class="/" joint="Right_Shoulder_Roll" forcerange="-17.5497 17.5497" gainprm="22.3124" biasprm="0 -22.3124 -0.502517"/>
    <general name="Right_Elbow_Pitch" class="/" joint="Right_Elbow_Pitch" forcerange="-17.2321 17.2321" gainprm="22.3124" biasprm="0 -22.3124 -0.502517"/>
    <general name="Right_Elbow_Yaw" class="/" joint="Right_Elbow_Yaw" forcerange="-14.2756 14.2756" gainprm="22.3124" biasprm="0 -22.3124 -0.502517"/>
    <general name="Waist" class="/" joint="Waist" forcerange="-26.676 26.676" gainprm="22.3124" biasprm="0 -22.3124 -0.502517"/>
    <general name="Left_Hip_Pitch" class="/" joint="Left_Hip_Pitch" forcerange="-42.7074 42.7074" gainprm="22.3124" biasprm="0 -22.3124 -0.502517"/>
    <general name="Left_Hip_Roll" class="/" joint="Left_Hip_Roll" forcerange="-27.5742 27.5742" gainprm="22.3124" biasprm="0 -22.3124 -0.502517"/>
    <general name="Left_Hip_Yaw" class="/" joint="Left_Hip_Yaw" forcerange="-26.5821 26.5821" gainprm="22.3124" biasprm="0 -22.3124 -0.502517"/>
    <general name="Left_Knee_Pitch" class="/" joint="Left_Knee_Pitch" forcerange="-52.6395 52.6395" gainprm="22.3124" biasprm="0 -22.3124 -0.502517"/>
    <general name="Left_Ankle_Pitch" class="/" joint="Left_Ankle_Pitch" forcerange="-17.3791 17.3791" gainprm="22.3124" biasprm="0 -22.3124 -0.502517"/>
    <general name="Left_Ankle_Roll" class="/" joint="Left_Ankle_Roll" forcerange="-13.2189 13.2189" gainprm="22.3124" biasprm="0 -22.3124 -0.502517"/>
    <general name="Right_Hip_Pitch" class="/" joint="Right_Hip_Pitch" forcerange="-40.1979 40.1979" gainprm="22.3124" biasprm="0 -22.3124 -0.502517"/>
    <general name="Right_Hip_Roll" class="/" joint="Right_Hip_Roll" forcerange="-26.293 26.293" gainprm="22.3124" biasprm="0 -22.3124 -0.502517"/>
    <general name="Right_Hip_Yaw" class="/" joint="Right_Hip_Yaw" forcerange="-26.6613 26.6613" gainprm="22.3124" biasprm="0 -22.3124 -0.502517"/>
    <general name="Right_Knee_Pitch" class="/" joint="Right_Knee_Pitch" forcerange="-50.0162 50.0162" gainprm="22.3124" biasprm="0 -22.3124 -0.502517"/>
    <general name="Right_Ankle_Pitch" class="/" joint="Right_Ankle_Pitch" forcerange="-15.9511 15.9511" gainprm="22.3124" biasprm="0 -22.3124 -0.502517"/>
    <general name="Right_Ankle_Roll" class="/" joint="Right_Ankle_Roll" forcerange="-14.2812 14.2812" gainprm="22.3124" biasprm="0 -22.3124 -0.502517"/>
  </actuator>

  <sensor>
    <gyro site="imu" name="imu_angular_velocity"/>
    <velocimeter site="imu" name="imu_linear_velocity"/>
    <framelinvel objtype="site" objname="left_foot" name="left_foot_global_linear_velocity"/>
    <framelinvel objtype="site" objname="right_foot" name="right_foot_global_linear_velocity"/>
  </sensor>

  <keyframe>
    <key name="home" qpos="0 0 0.6385 1 0 0 0 0 0 0 1.4 0 -0.4 0 -1.4 0 0.4 0 -0.4 0 0 0.8 -0.4 0 0.4 0 0 -0.8 0.4 0"/>
  </keyframe>
</mujoco>
