<mujoco model="T1">
  <compiler angle="radian" assetdir="assets" balanceinertia="true" inertiafromgeom="false"/>

  <option timestep="0.005" density="1.2" viscosity="2e-05"/>

  <size nkey="1"/>

  <visual>
    <quality shadowsize="8192"/>
    <map shadowclip="0.5"/>
  </visual>

  <default>
    <default class="/">
      <joint armature="0.01" damping="0.01" frictionloss="0.1"/>
      <geom contype="0" conaffinity="0" group="1" solref="-1000 -80"/>
      <site size="0.01 0.005 0.005" group="5"/>
      <general forcelimited="true" biastype="affine" gainprm="25" biasprm="0 -25 -0.6"/>
      <default class="t1">
        <geom rgba="0.25 0.25 0.25 1"/>
        <default class="visual">
          <geom type="mesh" group="2"/>
        </default>
        <default class="collision">
          <geom group="3"/>
        </default>
        <default class="foot">
          <geom size="0.1115 0.05 0.015" type="box" condim="6" group="4" priority="1" solimp="0.015 1 0.015"/>
        </default>
        <default class="reward_collision_sphere">
          <geom group="5" rgba="1 0 0 1"/>
        </default>
      </default>
    </default>
  </default>

  <asset>
    <texture type="skybox" colorspace="auto" name="//unnamed_texture_0" builtin="gradient" rgb1="0.95 0.95 0.95" rgb2="0.95 0.95 0.95" width="100" height="600"/>
    <texture type="2d" colorspace="auto" name="texplane" builtin="checker" rgb1="0.345 0.575 0.748" rgb2="0.345 0.575 0.748" markrgb="1 1 1" width="512" height="512"/>
    <material name="MatPlane" class="/" texture="texplane" texuniform="true" texrepeat="2 2" specular="0.9"/>
    <mesh name="Trunk" class="/" file="Trunk.stl"/>
    <mesh name="H1" class="/" file="H1.stl"/>
    <mesh name="H2" class="/" file="H2.stl"/>
    <mesh name="AL1" class="/" file="AL1.stl"/>
    <mesh name="AL2" class="/" file="AL2.stl"/>
    <mesh name="AL3" class="/" file="AL3.stl"/>
    <mesh name="left_hand_link" class="/" file="left_hand_link.stl"/>
    <mesh name="AR1" class="/" file="AR1.stl"/>
    <mesh name="AR2" class="/" file="AR2.stl"/>
    <mesh name="AR3" class="/" file="AR3.stl"/>
    <mesh name="right_hand_link" class="/" file="right_hand_link.stl"/>
    <mesh name="Waist" class="/" file="Waist.stl"/>
    <mesh name="Hip_Pitch_Left" class="/" file="Hip_Pitch_Left.stl"/>
    <mesh name="Hip_Roll_Left" class="/" file="Hip_Roll_Left.stl"/>
    <mesh name="Hip_Yaw_Left" class="/" file="Hip_Yaw_Left.stl"/>
    <mesh name="Shank_Left" class="/" file="Shank_Left.stl"/>
    <mesh name="Ankle_Cross_Left" class="/" file="Ankle_Cross_Left.stl"/>
    <mesh name="left_foot_link" class="/" file="left_foot_link.stl"/>
    <mesh name="Hip_Pitch_Right" class="/" file="Hip_Pitch_Right.stl"/>
    <mesh name="Hip_Roll_Right" class="/" file="Hip_Roll_Right.stl"/>
    <mesh name="Hip_Yaw_Right" class="/" file="Hip_Yaw_Right.stl"/>
    <mesh name="Shank_Right" class="/" file="Shank_Right.stl"/>
    <mesh name="Ankle_Cross_Right" class="/" file="Ankle_Cross_Right.stl"/>
    <mesh name="right_foot_link" class="/" file="right_foot_link.stl"/>
  </asset>

  <worldbody>
    <geom name="floor" class="/" size="100 100 0.125" type="plane" group="0" material="MatPlane"/>
    <light name="toplight_shadow" class="/" pos="0 0 5" dir="0.0990148 0.0990148 -0.990148" type="directional" ambient="0.04 0.04 0.04" diffuse="0.55 0.55 0.55" specular="0.12 0.12 0.12"/>
    <light name="toplight_fill" class="/" pos="0 0 5" dir="0.0990148 0.0990148 -0.990148" type="directional" castshadow="false" ambient="0.04 0.04 0.04" diffuse="0.3 0.3 0.3" specular="0.08 0.08 0.08"/>
    <body name="trunk" childclass="t1" pos="-0.000340658 0.00891105 0.0084284" quat="0.999999 0.000216663 0.00103534 0.000930825">
      <inertial pos="0.0297428 -0.0181239 0.0629502" quat="0.998501 -0.0256173 0.0466126 0.01292" mass="16.1889" diaginertia="0.0266172 1.41224 0.0162655"/>
      <joint name="//unnamed_joint_0" type="free" armature="0" damping="0" frictionloss="0"/>
      <geom name="//unnamed_geom_1" class="visual" rgba="0.76 0.76 0.76 1" mesh="Trunk"/>
      <geom name="//unnamed_geom_2" class="collision" size="0.0813184 0.108425 0.162637" pos="0.0457893 0 0.0899924" type="box"/>
      <geom name="//unnamed_geom_3" class="reward_collision_sphere" size="0.124688" pos="0.0457893 0 0.0749937"/>
      <geom name="//unnamed_geom_4" class="reward_collision_sphere" size="0.0162637" pos="0.0457893 0.14787 0"/>
      <geom name="//unnamed_geom_5" class="reward_collision_sphere" size="0.0162637" pos="0.0457893 -0.14787 0"/>
      <geom name="//unnamed_geom_6" class="reward_collision_sphere" size="0.0162637" pos="0.0457893 0.186142 0.134989"/>
      <geom name="//unnamed_geom_7" class="reward_collision_sphere" size="0.0162637" pos="0.0457893 -0.186142 0.134989"/>
      <site name="imu" pos="0.0570538 0.0515653 -0.0368246" size="0.0108425"/>
      <camera name="track" pos="0 -3.47929 0" quat="0.707107 0.707107 0 0" mode="trackcom"/>
      <camera name="ego_camera" pos="0.093105 0 0.314974" quat="-0.5 -0.5 0.5 0.5"/>
      <body name="H1" pos="0.0561567 0.015086 0.166439" quat="1 5.78001e-05 6.66072e-05 5.02398e-05">
        <inertial pos="-0.00196769 -0.0206518 0.0492124" quat="0.772507 -0.0226174 0.0769831 0.629916" mass="0.693819" diaginertia="6.47629e-05 0.00439557 3.3676e-05"/>
        <joint name="AAHead_yaw" pos="0 0 0" axis="-0.0449757 0.0124027 0.998911" stiffness="0.0260289" range="-1.55999 1.89439" armature="0.0120844" damping="0" frictionloss="0.209622"/>
        <geom name="//unnamed_geom_8" class="visual" mesh="H1"/>
        <body name="H2" pos="-0.00729415 0.00865046 0.0611533" quat="0.999998 0.00163415 0.000532236 0.000370683">
          <inertial pos="0.0139177 0.0185861 0.0826829" quat="0.990377 0.118078 0.00736085 -0.071812" mass="0.761807" diaginertia="0.000526526 0.0291448 0.000325116"/>
          <joint name="Head_pitch" pos="0 0 0" axis="-0.0277776 -0.999399 0.0207194" range="-1.15019 0.371288" armature="0.0114681" damping="0.00555272" frictionloss="0.175665"/>
          <geom name="//unnamed_geom_9" class="visual" mesh="H2"/>
          <geom name="//unnamed_geom_10" class="collision" size="0.0867396" pos="0.00763155 0 0.0824931"/>
          <geom name="//unnamed_geom_11" class="reward_collision_sphere" size="0.0975821" pos="0.0152631 0 0.0749937"/>
        </body>
      </body>
      <body name="AL1" pos="0.0567629 0.183874 0.175182" quat="0.999966 0.00423298 0.00302779 0.00632385">
        <inertial pos="-0.00244788 0.0883002 0.00934807" quat="0.460534 0.554574 -0.519537 0.458735" mass="0.690307" diaginertia="0.000309386 0.0160766 6.46455e-05"/>
        <joint name="Left_Shoulder_Pitch" pos="0 0 0" axis="-0.0115767 0.99983 0.0143506" range="-3.43906 0.919974" armature="0.0117973" damping="0.0415277" frictionloss="0.110779"/>
        <geom name="//unnamed_geom_12" class="visual" rgba="0.76 0.76 0.76 1" mesh="AL1"/>
        <body name="AL2" pos="0.00251552 0.0670142 0.0127651" quat="0.999979 -0.00151161 -0.00543755 -0.00312789">
          <inertial pos="-0.0134292 0.0481332 -0.0112426" quat="0.540789 0.545399 -0.443397 0.462045" mass="0.169137" diaginertia="9.49884e-05 0.00525762 3.17004e-05"/>
          <joint name="Left_Shoulder_Roll" pos="0 0 0" axis="-0.999952 -0.00562365 -0.00805994" stiffness="0.00266023" range="-1.58004 1.74146" armature="0.00780115" damping="0.0130424" frictionloss="0.144121"/>
          <geom name="//unnamed_geom_13" class="visual" mesh="AL2"/>
          <body name="AL3" pos="-0.00237244 0.0868085 -0.0107293" quat="1 5.80194e-05 -0.000162374 0.000112655">
            <inertial pos="0.01695 0.144719 0.0116418" quat="0.709291 0.702153 -0.0613832 0.0109506" mass="0.879981" diaginertia="0.0029774 0.153404 0.000108578"/>
            <joint name="Left_Elbow_Pitch" pos="0 0 0" axis="-0.0453435 -0.998666 -0.0247215" range="-2.39149 1.93708" armature="0.0131941" damping="0" frictionloss="0.12319"/>
            <geom name="//unnamed_geom_14" class="visual" mesh="AL3"/>
            <geom name="//unnamed_geom_15" class="collision" size="0.0325274 0.0813184" pos="0 0.0869822 0" quat="0.707105 0.707108 0 0" type="cylinder"/>
            <geom name="//unnamed_geom_16" class="reward_collision_sphere" size="0.0390328"/>
            <body name="left_hand_link" pos="-0.0100416 0.239354 0.0174468" quat="0.999996 0.00243368 4.83117e-05 0.00156847">
              <inertial pos="-0.0044986 0.19561 -0.00362647" quat="0.68214 0.731056 -0.0134796 0.00778606" mass="0.387456" diaginertia="0.00250388 0.13475 5.4506e-05"/>
              <joint name="Left_Elbow_Yaw" pos="0 0 0" axis="0.0426295 0.00739677 0.999064" range="-2.11027 0.0833636" armature="0.0107194" damping="0.101375" frictionloss="0.0313054"/>
              <geom name="//unnamed_geom_17" class="visual" mesh="left_hand_link"/>
              <geom name="//unnamed_geom_18" class="collision" size="0.0325274 0.0948715" pos="0 0.226154 0" quat="0.707105 0.707108 0 0" type="cylinder"/>
              <geom name="//unnamed_geom_19" class="reward_collision_sphere" size="0.0542123"/>
              <geom name="//unnamed_geom_20" class="reward_collision_sphere" size="0.0379486" pos="0 0.191361 0"/>
              <geom name="//unnamed_geom_21" class="reward_collision_sphere" size="0.0379486" pos="0 0.374023 0"/>
            </body>
          </body>
        </body>
      </body>
      <body name="AR1" pos="0.0420156 -0.183595 0.167063" quat="0.999981 0.00147975 0.000500428 -0.00589403">
        <inertial pos="0.0113246 -0.0786187 0.0167893" quat="0.550717 0.461616 -0.45334 0.527356" mass="0.483602" diaginertia="0.000313526 0.0158439 5.1383e-05"/>
        <joint name="Right_Shoulder_Pitch" pos="0 0 0" axis="0.0506246 -0.998617 0.0142178" range="-1.1859 3.35494" armature="0.00730297" damping="0.0864359" frictionloss="0.202151"/>
        <geom name="//unnamed_geom_22" class="visual" rgba="0.76 0.76 0.76 1" mesh="AR1"/>
        <body name="AR2" pos="0.0167421 -0.0809313 -0.00532032" quat="1 9.30529e-05 -3.41707e-05 -9.83263e-05">
          <inertial pos="0.0144385 -0.0478562 -0.00573963" quat="0.449936 0.47136 -0.538622 0.534101" mass="0.171807" diaginertia="7.90445e-05 0.00457424 3.16397e-05"/>
          <joint name="Right_Shoulder_Roll" pos="0 0 0" axis="-0.998056 -0.0502335 0.0368945" stiffness="0.010161" range="-1.68489 1.62529" armature="0.0107246" damping="0.101439" frictionloss="0.0683066"/>
          <geom name="//unnamed_geom_23" class="visual" mesh="AR2"/>
          <body name="AR3" pos="-0.00133476 -0.111898 0.00924115" quat="0.999982 -0.00288228 -0.00173177 0.00493249">
            <inertial pos="-0.00792016 -0.143606 0.00711107" quat="0.670339 0.741254 0.00162411 -0.0344238" mass="1.10319" diaginertia="0.00285175 0.212874 0.000139425"/>
            <joint name="Right_Elbow_Pitch" pos="0 0 0" axis="0.040224 0.99905 0.0167961" range="-2.16366 2.10472" armature="0.0111294" damping="0.0047655" frictionloss="0.0740931"/>
            <geom name="//unnamed_geom_24" class="visual" mesh="AR3"/>
            <geom name="//unnamed_geom_25" class="collision" size="0.0325274 0.0813184" pos="0 -0.0869822 0" quat="0.707105 0.707108 0 0" type="cylinder"/>
            <geom name="//unnamed_geom_26" class="reward_collision_sphere" size="0.0390328"/>
            <body name="right_hand_link" pos="0.0138304 -0.267752 -0.017809" quat="0.99998 -0.00363392 -0.00308637 0.0040412">
              <inertial pos="-0.00204143 -0.203556 -0.00859404" quat="0.718522 0.694935 -0.0280467 0.00238828" mass="0.393215" diaginertia="0.00166626 0.101959 4.94562e-05"/>
              <joint name="Right_Elbow_Yaw" pos="0 0 0" axis="0.00345881 -0.00170603 0.999993" range="-0.249312 2.48393" armature="0.0129011" damping="0.0220252" frictionloss="0.0169802"/>
              <geom name="//unnamed_geom_27" class="visual" mesh="right_hand_link"/>
              <geom name="//unnamed_geom_28" class="collision" size="0.0325274 0.0948715" pos="0 -0.226154 0" quat="0.707105 0.707108 0 0" type="cylinder"/>
              <geom name="//unnamed_geom_29" class="reward_collision_sphere" size="0.0542123"/>
              <geom name="//unnamed_geom_30" class="reward_collision_sphere" size="0.0379486" pos="0 -0.191361 0"/>
              <geom name="//unnamed_geom_31" class="reward_collision_sphere" size="0.0379486" pos="0 -0.374023 0"/>
            </body>
          </body>
        </body>
      </body>
      <body name="Waist" pos="0.0613755 0.00492209 -0.0702836" quat="0.999991 0.000133405 0.00432849 0.000194168">
        <inertial pos="0.0206935 -0.00674103 -0.000233902" quat="0.980432 -0.00838426 -0.195781 0.0187889" mass="4.40875" diaginertia="0.00194742 0.100945 0.00114687"/>
        <joint name="Waist" pos="0 0 0" axis="-0.0130705 -0.0399079 0.999118" stiffness="0.0114522" range="-1.34473 1.53315" armature="0.00442313" damping="0" frictionloss="0.105047"/>
        <geom name="//unnamed_geom_32" class="visual" mesh="Waist"/>
        <body name="Hip_Pitch_Left" pos="-0.00558833 0.173355 0.0149702" quat="0.999995 1.00825e-05 0.000965558 -0.00290046">
          <inertial pos="-2.81743e-05 -0.0270365 -0.0265337" quat="0.967336 0.246791 0.0404672 -0.0414502" mass="0.999356" diaginertia="0.000449383 0.019053 0.000283645"/>
          <joint name="Left_Hip_Pitch" pos="0 0 0" axis="0.00117042 0.999996 0.00260192" range="-1.78746 1.23772" armature="0.000959449" damping="0" frictionloss="0.0609242"/>
          <geom name="//unnamed_geom_33" class="visual" rgba="0.76 0.76 0.76 1" mesh="Hip_Pitch_Left"/>
          <body name="Hip_Roll_Left" pos="-0.0165009 0.0103371 -0.00417335" quat="0.999999 0.000772891 -0.00118092 0.00024402">
            <inertial pos="0.0115667 0.000718104 -0.0505609" quat="0.671161 0.0225084 0.0611771 0.73844" mass="0.531166" diaginertia="0.000475175 0.0185959 0.00010691"/>
            <joint name="Left_Hip_Roll" pos="0 0 0" axis="-0.997146 -0.059473 0.0464958" range="-1.58134 0.0649731" armature="0.00165167" damping="0.0433615" frictionloss="0.170112"/>
            <geom name="//unnamed_geom_34" class="visual" mesh="Hip_Roll_Left"/>
            <geom name="//unnamed_geom_35" class="reward_collision_sphere" size="0.0596335"/>
            <body name="Hip_Yaw_Left" pos="0.0126528 -0.000558787 -0.0713766" quat="0.999996 0.000778336 -0.0025598 0.00105329">
              <inertial pos="0.00973052 -0.00794996 -0.060451" quat="0.712157 -0.0258489 -0.0201502 0.701255" mass="3.13001" diaginertia="0.00724979 0.504558 0.00066829"/>
              <joint name="Left_Hip_Yaw" pos="0 0 0" axis="-0.0303808 7.73376e-05 -0.999538" range="-0.775491 0.686482" armature="0.00939229" damping="0.053615" frictionloss="0.117141"/>
              <geom name="//unnamed_geom_36" class="visual" mesh="Hip_Yaw_Left"/>
              <geom name="//unnamed_geom_37" class="collision" size="0.0542123 0.0867396" type="cylinder"/>
              <body name="Shank_Left" pos="-0.0284851 -0.000211058 -0.0815885" quat="0.999998 -0.0014371 -0.000512753 0.0015268">
                <inertial pos="0.00224027 -0.0147574 -0.109134" quat="0.997573 0.00176985 -0.0237151 0.0654478" mass="2.82411" diaginertia="0.00918806 0.608806 0.000416969"/>
                <joint name="Left_Knee_Pitch" pos="0 0 0" axis="-0.0154235 0.999769 0.0149929" range="-0.210284 2.54075" armature="0.011437" damping="0.000577582" frictionloss="0.145865"/>
                <geom name="//unnamed_geom_38" class="visual" mesh="Shank_Left"/>
                <geom name="//unnamed_geom_39" class="collision" size="0.0542123 0.0813184" pos="0 0 -0.0899924" type="cylinder"/>
                <geom name="//unnamed_geom_40" class="reward_collision_sphere" size="0.0704759"/>
                <body name="Ankle_Cross_Left" pos="-0.00522569 0.000383151 -0.223156" quat="0.999997 -2.16648e-05 0.00234882 0.000703625">
                  <inertial pos="0.00707367 -0.0135634 -0.0171602" quat="0.406219 0.601479 0.549711 0.413554" mass="0.0811343" diaginertia="6.46722e-06 0.0005004 2.84213e-06"/>
                  <joint name="Left_Ankle_Pitch" pos="0 0 0" axis="-0.0113688 0.999935 -0.00102508" range="-1.20289 0.223383" armature="0.0161709" damping="0.0370271" frictionloss="0.0649339"/>
                  <geom name="//unnamed_geom_41" class="visual" mesh="Ankle_Cross_Left"/>
                  <body name="left_foot_link" pos="0.00649211 0.0128995 -0.0157384" quat="0.999987 0.000661767 -0.00360613 0.00360244">
                    <inertial pos="0.0136945 0.00103353 0.00792158" quat="0.0159962 0.638872 -0.0283621 0.768624" mass="0.989708" diaginertia="0.00100067 0.0388308 0.000476038"/>
                    <joint name="Left_Ankle_Roll" pos="0 0 0" axis="-0.999742 -0.0113127 -0.0196765" range="-0.431496 0.42917" armature="0.0107447" damping="0.0411791" frictionloss="0.108183"/>
                    <geom name="//unnamed_geom_42" class="visual" mesh="left_foot_link"/>
                    <geom name="left_foot" class="foot" size="0.0713158 0.0205556 0.0153269" pos="0.00763155 0 -0.0112491"/>
                    <geom name="//unnamed_geom_44" class="reward_collision_sphere" size="0.0563808" pos="0.00763155 0 -0.0112491"/>
                    <geom name="//unnamed_geom_45" class="reward_collision_sphere" size="0.0325274" pos="0.0724998 -0.0400118 -0.0112491"/>
                    <geom name="//unnamed_geom_46" class="reward_collision_sphere" size="0.0325274" pos="-0.0534209 -0.0400118 -0.0112491"/>
                    <site name="left_foot" class="foot" pos="0.00763155 0 -0.0112491" size="0.0108425"/>
                  </body>
                </body>
              </body>
            </body>
          </body>
        </body>
        <body name="Hip_Pitch_Right" pos="0.00239004 -0.192438 -0.00742139" quat="0.999967 0.000337044 0.00188119 0.00789826">
          <inertial pos="0.0148808 0.0212672 -0.0291062" quat="0.977144 -0.209487 0.0214249 0.0290954" mass="1.07765" diaginertia="0.000389494 0.021365 0.000305883"/>
          <joint name="Right_Hip_Pitch" pos="0 0 0" axis="-0.017226 -0.999574 0.0235687" range="-1.5591 2.1572" armature="0.0177956" damping="0.00514281" frictionloss="0.101369"/>
          <geom name="//unnamed_geom_47" class="visual" rgba="0.76 0.76 0.76 1" mesh="Hip_Pitch_Right"/>
          <body name="Hip_Roll_Right" pos="-0.0169768 -0.00255793 -0.00234625" quat="0.999986 -0.00510738 -0.00123842 0.000956839">
            <inertial pos="0.000631726 -0.00873428 -0.0525361" quat="0.715981 0.0788786 -0.0180247 0.693415" mass="0.517009" diaginertia="0.000451951 0.0185336 0.00011771"/>
            <joint name="Right_Hip_Roll" pos="0 0 0" axis="-0.99995 0.00110735 0.00991603" range="-0.568237 1.7054" armature="0.0105898" damping="0.00356986" frictionloss="0.0490676"/>
            <geom name="//unnamed_geom_48" class="visual" mesh="Hip_Roll_Right"/>
            <geom name="//unnamed_geom_49" class="reward_collision_sphere" size="0.0596335"/>
            <body name="Hip_Yaw_Right" pos="0.00940198 0.0070618 -0.0648296" quat="0.999996 -0.000649115 -0.0019259 -0.00196888">
              <inertial pos="-0.00715368 0.0108889 -0.0501238" quat="0.7048 -0.0264363 0.00575935 0.70889" mass="2.29747" diaginertia="0.00576613 0.312191 0.00063859"/>
              <joint name="Right_Hip_Yaw" pos="0 0 0" axis="0.09335 0.0120125 -0.995561" stiffness="0.0225978" range="-1.12279 0.850507" armature="0.00243075" damping="0.0885278" frictionloss="0.109245"/>
              <geom name="//unnamed_geom_50" class="visual" mesh="Hip_Yaw_Right"/>
              <geom name="//unnamed_geom_51" class="collision" size="0.0542123 0.0867396" type="cylinder"/>
              <body name="Shank_Right" pos="-0.00894797 0.00346284 -0.115025" quat="0.999983 -6.77825e-05 0.00338171 0.00475889">
                <inertial pos="-0.0049736 -0.00162246 -0.0777842" quat="0.999666 -0.0107296 -0.00321262 -0.0233108" mass="1.73678" diaginertia="0.0076831 0.490235 0.000374797"/>
                <joint name="Right_Knee_Pitch" pos="0 0 0" axis="0.0515695 -0.997372 -0.0508831" range="-2.67008 -0.184819" armature="0.000981021" damping="0" frictionloss="0.11152"/>
                <geom name="//unnamed_geom_52" class="visual" mesh="Shank_Right"/>
                <geom name="//unnamed_geom_53" class="collision" size="0.0542123 0.0813184" pos="0 0 -0.0899924" type="cylinder"/>
                <geom name="//unnamed_geom_54" class="reward_collision_sphere" size="0.0704759"/>
                <body name="Ankle_Cross_Right" pos="0.0117625 -0.00793404 -0.214504" quat="0.999999 -0.00123598 -0.000359843 0.000836917">
                  <inertial pos="-0.00059266 0.0122735 -0.00709598" quat="0.409194 0.567188 0.571026 0.429868" mass="0.0715019" diaginertia="6.95843e-06 0.000377036 2.04162e-06"/>
                  <joint name="Right_Ankle_Pitch" pos="0 0 0" axis="0.0512375 -0.99858 0.0145613" stiffness="0.074407" range="-0.0437829 1.18088" armature="0.0105761" damping="0" frictionloss="0.144987"/>
                  <geom name="//unnamed_geom_55" class="visual" mesh="Ankle_Cross_Right"/>
                  <body name="right_foot_link" pos="-0.0162739 -0.00123793 -0.000161867" quat="0.999999 -0.000228353 4.69275e-06 -0.000981955">
                    <inertial pos="0.0176358 0.00724713 -0.0076799" quat="0.00622617 0.620435 -0.0042428 0.784221" mass="0.827223" diaginertia="0.000681991 0.0428119 0.000471776"/>
                    <joint name="Right_Ankle_Roll" pos="0 0 0" axis="-0.998015 -0.00773388 0.0625015" stiffness="0.0234117" range="-0.0978927 0.424131" armature="0.00862514" damping="0.0843385" frictionloss="0.078491"/>
                    <geom name="//unnamed_geom_56" class="visual" mesh="right_foot_link"/>
                    <geom name="right_foot" class="foot" size="0.105435 0.0710457 0.0214924" pos="0.00763155 0 -0.0112491"/>
                    <geom name="//unnamed_geom_58" class="reward_collision_sphere" size="0.0433698"/>
                    <geom name="//unnamed_geom_59" class="reward_collision_sphere" size="0.0325274" pos="0.00763155 0 -0.0112491"/>
                    <geom name="//unnamed_geom_60" class="reward_collision_sphere" size="0.0325274" pos="0.0724998 0.0400118 -0.0112491"/>
                    <geom name="//unnamed_geom_61" class="reward_collision_sphere" size="0.0325274" pos="-0.0534209 0.0400118 -0.0112491"/>
                    <site name="right_foot" class="foot" pos="0.00763155 0 -0.0112491" size="0.0108425"/>
                  </body>
                </body>
              </body>
            </body>
          </body>
        </body>
      </body>
    </body>
  </worldbody>

  <contact>
    <pair class="/" geom1="floor" geom2="left_foot" name="//unnamed_contact_0"/>
    <pair class="/" geom1="floor" geom2="right_foot" name="//unnamed_contact_1"/>
  </contact>

  <actuator>
    <general name="AAHead_yaw" class="/" joint="AAHead_yaw" forcerange="-5.42467 5.42467" gainprm="36.3393" biasprm="0 -36.3393 -0.72296"/>
    <general name="Head_pitch" class="/" joint="Head_pitch" forcerange="-7.52291 7.52291" gainprm="36.3393" biasprm="0 -36.3393 -0.72296"/>
    <general name="Left_Shoulder_Pitch" class="/" joint="Left_Shoulder_Pitch" forcerange="-27.9233 27.9233" gainprm="36.3393" biasprm="0 -36.3393 -0.72296"/>
    <general name="Left_Shoulder_Roll" class="/" joint="Left_Shoulder_Roll" forcerange="-25.4084 25.4084" gainprm="36.3393" biasprm="0 -36.3393 -0.72296"/>
    <general name="Left_Elbow_Pitch" class="/" joint="Left_Elbow_Pitch" forcerange="-19.1606 19.1606" gainprm="36.3393" biasprm="0 -36.3393 -0.72296"/>
    <general name="Left_Elbow_Yaw" class="/" joint="Left_Elbow_Yaw" forcerange="-25.6283 25.6283" gainprm="36.3393" biasprm="0 -36.3393 -0.72296"/>
    <general name="Right_Shoulder_Pitch" class="/" joint="Right_Shoulder_Pitch" forcerange="-13.5761 13.5761" gainprm="36.3393" biasprm="0 -36.3393 -0.72296"/>
    <general name="Right_Shoulder_Roll" class="/" joint="Right_Shoulder_Roll" forcerange="-27.659 27.659" gainprm="36.3393" biasprm="0 -36.3393 -0.72296"/>
    <general name="Right_Elbow_Pitch" class="/" joint="Right_Elbow_Pitch" forcerange="-7.34969 7.34969" gainprm="36.3393" biasprm="0 -36.3393 -0.72296"/>
    <general name="Right_Elbow_Yaw" class="/" joint="Right_Elbow_Yaw" forcerange="-13.1373 13.1373" gainprm="36.3393" biasprm="0 -36.3393 -0.72296"/>
    <general name="Waist" class="/" joint="Waist" forcerange="-21.8583 21.8583" gainprm="36.3393" biasprm="0 -36.3393 -0.72296"/>
    <general name="Left_Hip_Pitch" class="/" joint="Left_Hip_Pitch" forcerange="-43.407 43.407" gainprm="36.3393" biasprm="0 -36.3393 -0.72296"/>
    <general name="Left_Hip_Roll" class="/" joint="Left_Hip_Roll" forcerange="-15.5159 15.5159" gainprm="36.3393" biasprm="0 -36.3393 -0.72296"/>
    <general name="Left_Hip_Yaw" class="/" joint="Left_Hip_Yaw" forcerange="-50.4122 50.4122" gainprm="36.3393" biasprm="0 -36.3393 -0.72296"/>
    <general name="Left_Knee_Pitch" class="/" joint="Left_Knee_Pitch" forcerange="-51.5054 51.5054" gainprm="36.3393" biasprm="0 -36.3393 -0.72296"/>
    <general name="Left_Ankle_Pitch" class="/" joint="Left_Ankle_Pitch" forcerange="-23.3324 23.3324" gainprm="36.3393" biasprm="0 -36.3393 -0.72296"/>
    <general name="Left_Ankle_Roll" class="/" joint="Left_Ankle_Roll" forcerange="-6.77429 6.77429" gainprm="36.3393" biasprm="0 -36.3393 -0.72296"/>
    <general name="Right_Hip_Pitch" class="/" joint="Right_Hip_Pitch" forcerange="-50.1563 50.1563" gainprm="36.3393" biasprm="0 -36.3393 -0.72296"/>
    <general name="Right_Hip_Roll" class="/" joint="Right_Hip_Roll" forcerange="-29.6184 29.6184" gainprm="36.3393" biasprm="0 -36.3393 -0.72296"/>
    <general name="Right_Hip_Yaw" class="/" joint="Right_Hip_Yaw" forcerange="-11.5891 11.5891" gainprm="36.3393" biasprm="0 -36.3393 -0.72296"/>
    <general name="Right_Knee_Pitch" class="/" joint="Right_Knee_Pitch" forcerange="-64.216 64.216" gainprm="36.3393" biasprm="0 -36.3393 -0.72296"/>
    <general name="Right_Ankle_Pitch" class="/" joint="Right_Ankle_Pitch" forcerange="-26.8588 26.8588" gainprm="36.3393" biasprm="0 -36.3393 -0.72296"/>
    <general name="Right_Ankle_Roll" class="/" joint="Right_Ankle_Roll" forcerange="-23.4019 23.4019" gainprm="36.3393" biasprm="0 -36.3393 -0.72296"/>
  </actuator>

  <sensor>
    <gyro site="imu" name="imu_angular_velocity"/>
    <velocimeter site="imu" name="imu_linear_velocity"/>
    <framelinvel objtype="site" objname="left_foot" name="left_foot_global_linear_velocity"/>
    <framelinvel objtype="site" objname="right_foot" name="right_foot_global_linear_velocity"/>
  </sensor>

  <keyframe>
    <key name="home" qpos="0 0 0.6385 1 0 0 0 0 0 0 1.4 0 -0.4 0 -1.4 0 0.4 0 -0.4 0 0 0.8 -0.4 0 0.4 0 0 -0.8 0.4 0"/>
  </keyframe>
</mujoco>
