<mujoco model="T1">
  <compiler angle="radian" assetdir="assets" balanceinertia="true" inertiafromgeom="false"/>

  <option timestep="0.005" density="1.2" viscosity="2e-05"/>

  <size nkey="1"/>

  <visual>
    <quality shadowsize="8192"/>
    <map shadowclip="0.5"/>
  </visual>

  <default>
    <default class="/">
      <joint armature="0.01" damping="0.01" frictionloss="0.1"/>
      <geom contype="0" conaffinity="0" group="1" solref="-1000 -80"/>
      <site size="0.01 0.005 0.005" group="5"/>
      <general forcelimited="true" biastype="affine" gainprm="25" biasprm="0 -25 -0.6"/>
      <default class="t1">
        <geom rgba="0.25 0.25 0.25 1"/>
        <default class="visual">
          <geom type="mesh" group="2"/>
        </default>
        <default class="collision">
          <geom group="3"/>
        </default>
        <default class="foot">
          <geom size="0.1115 0.05 0.015" type="box" condim="6" group="4" priority="1" solimp="0.015 1 0.015"/>
        </default>
        <default class="reward_collision_sphere">
          <geom group="5" rgba="1 0 0 1"/>
        </default>
      </default>
    </default>
  </default>

  <asset>
    <texture type="skybox" colorspace="auto" name="//unnamed_texture_0" builtin="gradient" rgb1="0.95 0.95 0.95" rgb2="0.95 0.95 0.95" width="100" height="600"/>
    <texture type="2d" colorspace="auto" name="texplane" builtin="checker" rgb1="0.345 0.575 0.748" rgb2="0.345 0.575 0.748" markrgb="1 1 1" width="512" height="512"/>
    <material name="MatPlane" class="/" texture="texplane" texuniform="true" texrepeat="2 2" specular="0.9"/>
    <mesh name="Trunk" class="/" file="Trunk.stl"/>
    <mesh name="H1" class="/" file="H1.stl"/>
    <mesh name="H2" class="/" file="H2.stl"/>
    <mesh name="AL1" class="/" file="AL1.stl"/>
    <mesh name="AL2" class="/" file="AL2.stl"/>
    <mesh name="AL3" class="/" file="AL3.stl"/>
    <mesh name="left_hand_link" class="/" file="left_hand_link.stl"/>
    <mesh name="AR1" class="/" file="AR1.stl"/>
    <mesh name="AR2" class="/" file="AR2.stl"/>
    <mesh name="AR3" class="/" file="AR3.stl"/>
    <mesh name="right_hand_link" class="/" file="right_hand_link.stl"/>
    <mesh name="Waist" class="/" file="Waist.stl"/>
    <mesh name="Hip_Pitch_Left" class="/" file="Hip_Pitch_Left.stl"/>
    <mesh name="Hip_Roll_Left" class="/" file="Hip_Roll_Left.stl"/>
    <mesh name="Hip_Yaw_Left" class="/" file="Hip_Yaw_Left.stl"/>
    <mesh name="Shank_Left" class="/" file="Shank_Left.stl"/>
    <mesh name="Ankle_Cross_Left" class="/" file="Ankle_Cross_Left.stl"/>
    <mesh name="left_foot_link" class="/" file="left_foot_link.stl"/>
    <mesh name="Hip_Pitch_Right" class="/" file="Hip_Pitch_Right.stl"/>
    <mesh name="Hip_Roll_Right" class="/" file="Hip_Roll_Right.stl"/>
    <mesh name="Hip_Yaw_Right" class="/" file="Hip_Yaw_Right.stl"/>
    <mesh name="Shank_Right" class="/" file="Shank_Right.stl"/>
    <mesh name="Ankle_Cross_Right" class="/" file="Ankle_Cross_Right.stl"/>
    <mesh name="right_foot_link" class="/" file="right_foot_link.stl"/>
  </asset>

  <worldbody>
    <geom name="floor" class="/" size="100 100 0.125" type="plane" group="0" material="MatPlane"/>
    <light name="toplight_shadow" class="/" pos="0 0 5" dir="0.0990148 0.0990148 -0.990148" type="directional" ambient="0.04 0.04 0.04" diffuse="0.55 0.55 0.55" specular="0.12 0.12 0.12"/>
    <light name="toplight_fill" class="/" pos="0 0 5" dir="0.0990148 0.0990148 -0.990148" type="directional" castshadow="false" ambient="0.04 0.04 0.04" diffuse="0.3 0.3 0.3" specular="0.08 0.08 0.08"/>
    <body name="trunk" childclass="t1" pos="0.000145745 -1.10577e-05 0.000287429" quat="1 6.37555e-05 -0.000254883 -8.89257e-05">
      <inertial pos="0.0400424 0.00230214 0.113049" quat="0.99984 -0.00127392 -0.0162477 -0.00738686" mass="11.9129" diaginertia="0.0162577 0.244163 0.070804"/>
      <joint name="//unnamed_joint_0" type="free" armature="0" damping="0" frictionloss="0"/>
      <geom name="//unnamed_geom_1" class="visual" rgba="0.76 0.76 0.76 1" mesh="Trunk"/>
      <geom name="//unnamed_geom_2" class="collision" size="0.0755457 0.100728 0.151091" pos="0.0425658 0 0.125984" type="box"/>
      <geom name="//unnamed_geom_3" class="reward_collision_sphere" size="0.115837" pos="0.0425658 0 0.104987"/>
      <geom name="//unnamed_geom_4" class="reward_collision_sphere" size="0.0151091" pos="0.0425658 0.107315 0"/>
      <geom name="//unnamed_geom_5" class="reward_collision_sphere" size="0.0151091" pos="0.0425658 -0.107315 0"/>
      <geom name="//unnamed_geom_6" class="reward_collision_sphere" size="0.0151091" pos="0.0425658 0.135091 0.188976"/>
      <geom name="//unnamed_geom_7" class="reward_collision_sphere" size="0.0151091" pos="0.0425658 -0.135091 0.188976"/>
      <site name="imu" pos="-0.00777704 -0.00456537 -0.00415699" size="0.0100728"/>
      <camera name="track" pos="0 -2.52507 0" quat="0.707107 0.707107 0 0" mode="trackcom"/>
      <camera name="ego_camera" pos="0.0865504 0 0.440944" quat="-0.5 -0.5 0.5 0.5"/>
      <body name="H1" pos="0.0433441 -0.00292374 0.257483" quat="1 -2.44242e-05 3.67694e-05 7.60161e-05">
        <inertial pos="-0.00117461 0.000616291 0.0613168" quat="0.766799 -0.00757916 0.0134588 0.641702" mass="0.438203" diaginertia="4.21914e-05 0.000696114 0.000191615"/>
        <joint name="AAHead_yaw" pos="0 0 0" axis="0.00126271 0.000669439 0.999999" range="-1.57031 1.5159" armature="0.0101177" damping="0.0235499" frictionloss="0.0889306"/>
        <geom name="//unnamed_geom_8" class="visual" mesh="H1"/>
        <body name="H2" pos="-0.00150258 -0.000134663 0.0619269" quat="1 -0.000167915 -9.83272e-05 -1.90074e-05">
          <inertial pos="0.00513139 -0.00134094 0.103913" quat="0.986437 0.114732 -0.0844841 -0.0814972" mass="0.647402" diaginertia="0.000365965 0.00621945 0.00227802"/>
          <joint name="Head_pitch" pos="0 0 0" axis="0.00408564 -0.999986 -0.00332192" stiffness="0.00107361" range="-1.22814 0.353094" armature="0.0101153" damping="0.0109741" frictionloss="0.0904399"/>
          <geom name="//unnamed_geom_9" class="visual" mesh="H2"/>
          <geom name="//unnamed_geom_10" class="collision" size="0.0805821" pos="0.0070943 0 0.115485"/>
          <geom name="//unnamed_geom_11" class="reward_collision_sphere" size="0.0906549" pos="0.0141886 0 0.104987"/>
        </body>
      </body>
      <body name="AL1" pos="0.0397209 0.13466 0.229088" quat="0.999999 0.000764935 0.000234042 0.00123133">
        <inertial pos="-0.000491947 0.0557315 -0.000758182" quat="0.508807 0.495231 -0.493347 0.502465" mass="0.53657" diaginertia="0.000244411 0.00427473 0.000371472"/>
        <joint name="Left_Shoulder_Pitch" pos="0 0 0" axis="-3.64749e-05 1 9.25463e-05" stiffness="0.00452015" range="-3.3294 1.27495" armature="0.0100976" damping="0.00783038" frictionloss="0.0996587"/>
        <geom name="//unnamed_geom_12" class="visual" rgba="0.76 0.76 0.76 1" mesh="AL1"/>
        <body name="AL2" pos="0.000227235 0.0626841 -0.0019902" quat="1 -0.000507919 0.000284922 -0.000742577">
          <inertial pos="0.00550809 0.0504179 0.00131159" quat="0.483643 0.522092 -0.485403 0.507832" mass="0.164907" diaginertia="7.24799e-05 0.00110539 0.000232773"/>
          <joint name="Left_Shoulder_Roll" pos="0 0 0" axis="-0.999996 0.00176837 -0.0023624" stiffness="0.000182258" range="-1.56983 1.73402" armature="0.00954124" damping="0.00931117" frictionloss="0.106039"/>
          <geom name="//unnamed_geom_13" class="visual" mesh="AL2"/>
          <body name="AL3" pos="0.000665336 0.0790702 0.0021029" quat="1 -7.49371e-06 7.28869e-05 -0.000170325">
            <inertial pos="-0.0028566 0.107859 -0.00192123" quat="0.703288 0.710841 -0.00357242 -0.008811" mass="1.11073" diaginertia="0.00241169 0.0418631 0.000811751"/>
            <joint name="Left_Elbow_Pitch" pos="0 0 0" axis="-0.00104698 -0.999991 0.00399781" range="-2.29263 2.32337" armature="0.0107369" damping="0.0216138" frictionloss="0.0979693"/>
            <geom name="//unnamed_geom_14" class="visual" mesh="AL3"/>
            <geom name="//unnamed_geom_15" class="collision" size="0.0302183 0.0755457" pos="0 0.0631266 0" quat="0.707105 0.707108 0 0" type="cylinder"/>
            <geom name="//unnamed_geom_16" class="reward_collision_sphere" size="0.036262"/>
            <body name="left_hand_link" pos="0.00102311 0.188828 -0.00213771" quat="1 -0.000415517 -0.000267604 -2.24743e-05">
              <inertial pos="-9.50235e-05 0.139266 0.000398303" quat="0.706038 0.708172 -0.00190921 -6.49013e-05" mass="0.330128" diaginertia="0.00141739 0.0259136 0.000277308"/>
              <joint name="Left_Elbow_Yaw" pos="0 0 0" axis="-0.00494741 -0.00238132 0.999985" stiffness="0.0100216" range="-2.49871 -0.00558262" armature="0.0103716" damping="0.000586082" frictionloss="0.113779"/>
              <geom name="//unnamed_geom_17" class="visual" mesh="left_hand_link"/>
              <geom name="//unnamed_geom_18" class="collision" size="0.0302183 0.0881367" pos="0 0.164129 0" quat="0.707105 0.707108 0 0" type="cylinder"/>
              <geom name="//unnamed_geom_19" class="reward_collision_sphere" size="0.0503638"/>
              <geom name="//unnamed_geom_20" class="reward_collision_sphere" size="0.0352547" pos="0 0.138879 0"/>
              <geom name="//unnamed_geom_21" class="reward_collision_sphere" size="0.0352547" pos="0 0.271445 0"/>
            </body>
          </body>
        </body>
      </body>
      <body name="AR1" pos="0.0398757 -0.133666 0.228578" quat="1 0.000777073 0.000193794 -0.000328177">
        <inertial pos="-0.00265594 -0.0571193 -0.0028468" quat="0.500756 0.507412 -0.501325 0.490357" mass="0.562163" diaginertia="0.000246372 0.00421261 0.000385264"/>
        <joint name="Right_Shoulder_Pitch" pos="0 0 0" axis="-5.95117e-05 -1 -0.000843776" stiffness="0.00557993" range="-1.22312 3.29863" armature="0.0098168" damping="0" frictionloss="0.0873482"/>
        <geom name="//unnamed_geom_22" class="visual" rgba="0.76 0.76 0.76 1" mesh="AR1"/>
        <body name="AR2" pos="-0.00181471 -0.0591659 0.000950046" quat="1 -5.91227e-05 -4.29509e-05 0.000197664">
          <inertial pos="0.00110304 -0.0503198 -0.000940857" quat="0.51847 0.494719 -0.505575 0.480454" mass="0.162675" diaginertia="7.34655e-05 0.00109387 0.000230435"/>
          <joint name="Right_Shoulder_Roll" pos="0 0 0" axis="-0.999997 -0.00254345 0.000310071" stiffness="0.00579695" range="-1.7439 1.56304" armature="0.0100208" damping="0" frictionloss="0.0966163"/>
          <geom name="//unnamed_geom_23" class="visual" mesh="AR2"/>
          <body name="AR3" pos="-0.000751102 -0.0752696 -0.000560767" quat="1 0.000843928 0.000118598 -0.000461886">
            <inertial pos="-0.000782858 -0.107282 0.000913109" quat="0.706285 0.707859 -0.00871115 0.00462335" mass="1.06674" diaginertia="0.00235835 0.0405607 0.000810467"/>
            <joint name="Right_Elbow_Pitch" pos="0 0 0" axis="-7.7409e-05 1 0.000286234" stiffness="0.000450847" range="-2.25316 2.25742" armature="0.0101204" damping="0.00861076" frictionloss="0.0952938"/>
            <geom name="//unnamed_geom_24" class="visual" mesh="AR3"/>
            <geom name="//unnamed_geom_25" class="collision" size="0.0302183 0.0755457" pos="0 -0.0631266 0" quat="0.707105 0.707108 0 0" type="cylinder"/>
            <geom name="//unnamed_geom_26" class="reward_collision_sphere" size="0.036262"/>
            <body name="right_hand_link" pos="-0.00170465 -0.183213 0.00221915" quat="0.999999 -0.000271432 -0.000811172 -0.000668891">
              <inertial pos="-8.07903e-05 -0.136027 0.000845472" quat="0.708377 0.705821 0.00114172 0.00422769" mass="0.343352" diaginertia="0.00147341 0.0262202 0.000276082"/>
              <joint name="Right_Elbow_Yaw" pos="0 0 0" axis="-0.000698588 0.00027034 1" stiffness="0.00121427" range="0.0371365 2.42797" armature="0.0102352" damping="0.00855738" frictionloss="0.114375"/>
              <geom name="//unnamed_geom_27" class="visual" mesh="right_hand_link"/>
              <geom name="//unnamed_geom_28" class="collision" size="0.0302183 0.0881367" pos="0 -0.164129 0" quat="0.707105 0.707108 0 0" type="cylinder"/>
              <geom name="//unnamed_geom_29" class="reward_collision_sphere" size="0.0503638"/>
              <geom name="//unnamed_geom_30" class="reward_collision_sphere" size="0.0352547" pos="0 -0.138879 0"/>
              <geom name="//unnamed_geom_31" class="reward_collision_sphere" size="0.0352547" pos="0 -0.271445 0"/>
            </body>
          </body>
        </body>
      </body>
      <body name="Waist" pos="0.0414105 0.000477084 -0.122887" quat="1 -0.000256388 0.000111933 7.77453e-06">
        <inertial pos="-0.000852341 -0.00148184 0.00655721" quat="0.984149 0.00179963 -0.177297 0.00353546" mass="2.5051" diaginertia="0.000915429 0.0165953 0.00592005"/>
        <joint name="Waist" pos="0 0 0" axis="3.23646e-05 -0.000687983 1" range="-1.59954 1.56977" armature="0.0111164" damping="0.0189489" frictionloss="0.10173"/>
        <geom name="//unnamed_geom_32" class="visual" mesh="Waist"/>
        <body name="Hip_Pitch_Left" pos="-0.000621121 0.134209 -0.00183425" quat="1 0.000248119 -0.000118516 -5.94457e-05">
          <inertial pos="0.000371844 -0.0068465 -0.0169671" quat="0.976111 0.216709 0.0134294 0.00799775" mass="1.08094" diaginertia="0.000324319 0.00481749 0.00159764"/>
          <joint name="Left_Hip_Pitch" pos="0 0 0" axis="0.000516809 0.999998 -0.00216299" stiffness="0.00319709" range="-1.80086 1.62566" armature="0.011386" damping="0.0179778" frictionloss="0.10037"/>
          <geom name="//unnamed_geom_33" class="visual" rgba="0.76 0.76 0.76 1" mesh="Hip_Pitch_Left"/>
          <body name="Hip_Roll_Left" pos="0.00243386 -0.00193281 -0.0230426" quat="1 5.57122e-05 -2.33217e-05 -1.33699e-05">
            <inertial pos="-0.000158397 0.000200229 -0.0554808" quat="0.704596 -0.0123707 0.00492299 0.709484" mass="0.380017" diaginertia="0.000302434 0.00493894 0.000653057"/>
            <joint name="Left_Hip_Roll" pos="0 0 0" axis="-0.999931 0.0117238 0.000717258" stiffness="0.00982964" range="-1.56587 0.182105" armature="0.0114146" damping="0.0133968" frictionloss="0.0929522"/>
            <geom name="//unnamed_geom_34" class="visual" mesh="Hip_Roll_Left"/>
            <geom name="//unnamed_geom_35" class="reward_collision_sphere" size="0.0554002"/>
            <body name="Hip_Yaw_Left" pos="-0.00219991 -0.00121869 -0.0838509" quat="1 -0.0001745 -0.00041397 -0.000338683">
              <inertial pos="-0.00763896 -0.000771345 -0.0927733" quat="0.697632 -0.0302661 -0.0318534 0.715108" mass="2.21542" diaginertia="0.00460501 0.0778698 0.00328885"/>
              <joint name="Left_Hip_Yaw" pos="0 0 0" axis="0.000830033 -0.00638609 -0.999979" stiffness="0.00316739" range="-1.04066 1.06094" armature="0.0102154" damping="0.000620072" frictionloss="0.101682"/>
              <geom name="//unnamed_geom_36" class="visual" mesh="Hip_Yaw_Left"/>
              <geom name="//unnamed_geom_37" class="collision" size="0.0503638 0.0805821" type="cylinder"/>
              <body name="Shank_Left" pos="-0.00722725 -0.000200363 -0.141278" quat="1 0.000178425 5.52824e-05 -5.37013e-05">
                <inertial pos="-0.00330896 0.00314986 -0.127849" quat="0.997534 0.00147296 -0.0245514 0.0657408" mass="1.70564" diaginertia="0.00617261 0.111287 0.00233042"/>
                <joint name="Left_Knee_Pitch" pos="0 0 0" axis="-0.00354364 0.999989 -0.0030489" range="0.0177405 2.32461" armature="0.0102245" damping="0.0142673" frictionloss="0.105802"/>
                <geom name="//unnamed_geom_38" class="visual" mesh="Shank_Left"/>
                <geom name="//unnamed_geom_39" class="collision" size="0.0503638 0.0755457" pos="0 0 -0.125984" type="cylinder"/>
                <geom name="//unnamed_geom_40" class="reward_collision_sphere" size="0.065473"/>
                <body name="Ankle_Cross_Left" pos="-0.000513667 -0.000781449 -0.291449" quat="1 -0.000231325 0.00028092 -6.53152e-05">
                  <inertial pos="-0.00309987 0.00254271 -0.0069574" quat="0.444412 0.543413 0.560327 0.439584" mass="0.0776669" diaginertia="5.43262e-06 8.09163e-05 1.46086e-05"/>
                  <joint name="Left_Ankle_Pitch" pos="0 0 0" axis="-0.000373984 1 0.000275262" range="-0.814453 0.328847" armature="0.00952377" damping="0.0116435" frictionloss="0.0980685"/>
                  <geom name="//unnamed_geom_41" class="visual" mesh="Ankle_Cross_Left"/>
                  <body name="left_foot_link" pos="0.000460532 -0.00220129 -0.0102999" quat="1 -0.000161698 -0.000237374 -0.000190282">
                    <inertial pos="-0.00275566 -2.7426e-05 -0.012225" quat="-0.00223572 0.620618 -0.00106344 0.78411" mass="0.675847" diaginertia="0.000451993 0.00753516 0.00277427"/>
                    <joint name="Left_Ankle_Roll" pos="0 0 0" axis="-0.999998 -0.00175591 0.00102018" range="-0.433315 0.442552" armature="0.0101503" damping="0.0130579" frictionloss="0.099904"/>
                    <geom name="//unnamed_geom_42" class="visual" mesh="left_foot_link"/>
                    <geom name="left_foot" class="foot" size="0.105511 0.0479151 0.0149449" pos="0.0070943 0 -0.015748"/>
                    <geom name="//unnamed_geom_44" class="reward_collision_sphere" size="0.0523784" pos="0.0070943 0 -0.015748"/>
                    <geom name="//unnamed_geom_45" class="reward_collision_sphere" size="0.0302183" pos="0.0673958 -0.0290382 -0.015748"/>
                    <geom name="//unnamed_geom_46" class="reward_collision_sphere" size="0.0302183" pos="-0.0496601 -0.0290382 -0.015748"/>
                    <site name="left_foot" class="foot" pos="0.0070943 0 -0.015748" size="0.0100728"/>
                  </body>
                </body>
              </body>
            </body>
          </body>
        </body>
        <body name="Hip_Pitch_Right" pos="-0.000268231 -0.134359 0.000740295" quat="0.999999 -0.00017635 0.00112013 0.000320171">
          <inertial pos="-0.00235782 0.00994716 -0.0159964" quat="0.97367 -0.227603 0.0117729 -0.00496624" mass="1.07086" diaginertia="0.000333562 0.00487242 0.00159011"/>
          <joint name="Right_Hip_Pitch" pos="0 0 0" axis="0.000627218 -0.999995 -0.00310822" range="-1.57241 1.74825" armature="0.00899128" damping="0.00992651" frictionloss="0.0990097"/>
          <geom name="//unnamed_geom_47" class="visual" rgba="0.76 0.76 0.76 1" mesh="Hip_Pitch_Right"/>
          <body name="Hip_Roll_Right" pos="0.00209659 0.000625981 -0.0234267" quat="1 -0.000410058 0.000615724 0.000279454">
            <inertial pos="0.0011283 -0.000310732 -0.0542494" quat="0.705975 -0.018801 -0.00367075 0.707978" mass="0.392854" diaginertia="0.000314318 0.00502633 0.000658214"/>
            <joint name="Right_Hip_Roll" pos="0 0 0" axis="-0.999995 -0.00290062 0.00100299" range="-0.153322 1.58996" armature="0.0101108" damping="0.0108765" frictionloss="0.1072"/>
            <geom name="//unnamed_geom_48" class="visual" mesh="Hip_Roll_Right"/>
            <geom name="//unnamed_geom_49" class="reward_collision_sphere" size="0.0554002"/>
            <body name="Hip_Yaw_Right" pos="-0.000172695 0.000684032 -0.0870298" quat="1 -0.000514422 0.000412237 7.82737e-06">
              <inertial pos="-0.0042342 -0.00172948 -0.0964268" quat="0.713676 -0.031129 -0.0331463 0.698999" mass="2.16843" diaginertia="0.00460426 0.082151 0.00320652"/>
              <joint name="Right_Hip_Yaw" pos="0 0 0" axis="-0.0124443 0.00541533 -0.999908" stiffness="0.000967774" range="-1.01974 0.989082" armature="0.0114398" damping="0.000503276" frictionloss="0.100659"/>
              <geom name="//unnamed_geom_50" class="visual" mesh="Hip_Yaw_Right"/>
              <geom name="//unnamed_geom_51" class="collision" size="0.0503638 0.0805821" type="cylinder"/>
              <body name="Shank_Right" pos="-0.0104933 -0.000104797 -0.138616" quat="1 0.000352115 0.000684474 -0.00025035">
                <inertial pos="-0.00360894 -0.000795564 -0.131438" quat="0.99934 -0.00224797 -0.0218531 -0.0289331" mass="1.88126" diaginertia="0.0065723 0.113317 0.00257075"/>
                <joint name="Right_Knee_Pitch" pos="0 0 0" axis="0.00839125 -0.999965 1.01697e-05" stiffness="0.00417984" range="-2.28553 -0.00252171" armature="0.011342" damping="0.0168176" frictionloss="0.0997815"/>
                <geom name="//unnamed_geom_52" class="visual" mesh="Shank_Right"/>
                <geom name="//unnamed_geom_53" class="collision" size="0.0503638 0.0755457" pos="0 0 -0.125984" type="cylinder"/>
                <geom name="//unnamed_geom_54" class="reward_collision_sphere" size="0.065473"/>
                <body name="Ankle_Cross_Right" pos="-0.00117349 -0.00121168 -0.294602" quat="1 -0.000201955 0.000207323 -9.06678e-05">
                  <inertial pos="-0.00288551 -0.00170588 -0.00831226" quat="0.443094 0.55106 0.550985 0.443189" mass="0.0756857" diaginertia="5.38931e-06 8.52051e-05 1.4772e-05"/>
                  <joint name="Right_Ankle_Pitch" pos="0 0 0" axis="0.000198933 -0.999983 -0.00582453" range="-0.40529 0.813681" armature="0.0100699" damping="0.00616517" frictionloss="0.10586"/>
                  <geom name="//unnamed_geom_55" class="visual" mesh="Ankle_Cross_Right"/>
                  <body name="right_foot_link" pos="0.00274707 -0.000768524 -0.0143341" quat="1 2.1357e-05 -1.99397e-06 -2.93314e-06">
                    <inertial pos="-0.00267232 0.000767369 -0.00977877" quat="0.00018163 0.621155 0.00134534 0.783686" mass="0.702481" diaginertia="0.000489748 0.00745319 0.00280032"/>
                    <joint name="Right_Ankle_Roll" pos="0 0 0" axis="-0.999959 -0.00715599 -0.0055084" range="-0.49224 0.441967" armature="0.00967107" damping="0" frictionloss="0.0959458"/>
                    <geom name="//unnamed_geom_56" class="visual" mesh="right_foot_link"/>
                    <geom name="right_foot" class="foot" size="0.105835 0.0450028 0.0148523" pos="0.0070943 0 -0.015748"/>
                    <geom name="//unnamed_geom_58" class="reward_collision_sphere" size="0.0402911"/>
                    <geom name="//unnamed_geom_59" class="reward_collision_sphere" size="0.0302183" pos="0.0070943 0 -0.015748"/>
                    <geom name="//unnamed_geom_60" class="reward_collision_sphere" size="0.0302183" pos="0.0673958 0.0290382 -0.015748"/>
                    <geom name="//unnamed_geom_61" class="reward_collision_sphere" size="0.0302183" pos="-0.0496601 0.0290382 -0.015748"/>
                    <site name="right_foot" class="foot" pos="0.0070943 0 -0.015748" size="0.0100728"/>
                  </body>
                </body>
              </body>
            </body>
          </body>
        </body>
      </body>
    </body>
  </worldbody>

  <contact>
    <pair class="/" geom1="floor" geom2="left_foot" name="//unnamed_contact_0"/>
    <pair class="/" geom1="floor" geom2="right_foot" name="//unnamed_contact_1"/>
  </contact>

  <actuator>
    <general name="AAHead_yaw" class="/" joint="AAHead_yaw" forcerange="-6.87633 6.87633" gainprm="23.5579" biasprm="0 -23.5579 -0.603107"/>
    <general name="Head_pitch" class="/" joint="Head_pitch" forcerange="-7.04628 7.04628" gainprm="23.5579" biasprm="0 -23.5579 -0.603107"/>
    <general name="Left_Shoulder_Pitch" class="/" joint="Left_Shoulder_Pitch" forcerange="-16.8586 16.8586" gainprm="23.5579" biasprm="0 -23.5579 -0.603107"/>
    <general name="Left_Shoulder_Roll" class="/" joint="Left_Shoulder_Roll" forcerange="-18.2813 18.2813" gainprm="23.5579" biasprm="0 -23.5579 -0.603107"/>
    <general name="Left_Elbow_Pitch" class="/" joint="Left_Elbow_Pitch" forcerange="-18.1213 18.1213" gainprm="23.5579" biasprm="0 -23.5579 -0.603107"/>
    <general name="Left_Elbow_Yaw" class="/" joint="Left_Elbow_Yaw" forcerange="-18.5379 18.5379" gainprm="23.5579" biasprm="0 -23.5579 -0.603107"/>
    <general name="Right_Shoulder_Pitch" class="/" joint="Right_Shoulder_Pitch" forcerange="-18.0966 18.0966" gainprm="23.5579" biasprm="0 -23.5579 -0.603107"/>
    <general name="Right_Shoulder_Roll" class="/" joint="Right_Shoulder_Roll" forcerange="-17.1539 17.1539" gainprm="23.5579" biasprm="0 -23.5579 -0.603107"/>
    <general name="Right_Elbow_Pitch" class="/" joint="Right_Elbow_Pitch" forcerange="-19.996 19.996" gainprm="23.5579" biasprm="0 -23.5579 -0.603107"/>
    <general name="Right_Elbow_Yaw" class="/" joint="Right_Elbow_Yaw" forcerange="-17.8806 17.8806" gainprm="23.5579" biasprm="0 -23.5579 -0.603107"/>
    <general name="Waist" class="/" joint="Waist" forcerange="-30.5899 30.5899" gainprm="23.5579" biasprm="0 -23.5579 -0.603107"/>
    <general name="Left_Hip_Pitch" class="/" joint="Left_Hip_Pitch" forcerange="-46.1777 46.1777" gainprm="23.5579" biasprm="0 -23.5579 -0.603107"/>
    <general name="Left_Hip_Roll" class="/" joint="Left_Hip_Roll" forcerange="-33.0788 33.0788" gainprm="23.5579" biasprm="0 -23.5579 -0.603107"/>
    <general name="Left_Hip_Yaw" class="/" joint="Left_Hip_Yaw" forcerange="-27.2202 27.2202" gainprm="23.5579" biasprm="0 -23.5579 -0.603107"/>
    <general name="Left_Knee_Pitch" class="/" joint="Left_Knee_Pitch" forcerange="-57.9377 57.9377" gainprm="23.5579" biasprm="0 -23.5579 -0.603107"/>
    <general name="Left_Ankle_Pitch" class="/" joint="Left_Ankle_Pitch" forcerange="-19.9731 19.9731" gainprm="23.5579" biasprm="0 -23.5579 -0.603107"/>
    <general name="Left_Ankle_Roll" class="/" joint="Left_Ankle_Roll" forcerange="-16.6814 16.6814" gainprm="23.5579" biasprm="0 -23.5579 -0.603107"/>
    <general name="Right_Hip_Pitch" class="/" joint="Right_Hip_Pitch" forcerange="-45.4416 45.4416" gainprm="23.5579" biasprm="0 -23.5579 -0.603107"/>
    <general name="Right_Hip_Roll" class="/" joint="Right_Hip_Roll" forcerange="-30.5944 30.5944" gainprm="23.5579" biasprm="0 -23.5579 -0.603107"/>
    <general name="Right_Hip_Yaw" class="/" joint="Right_Hip_Yaw" forcerange="-33.284 33.284" gainprm="23.5579" biasprm="0 -23.5579 -0.603107"/>
    <general name="Right_Knee_Pitch" class="/" joint="Right_Knee_Pitch" forcerange="-60.4682 60.4682" gainprm="23.5579" biasprm="0 -23.5579 -0.603107"/>
    <general name="Right_Ankle_Pitch" class="/" joint="Right_Ankle_Pitch" forcerange="-20.9909 20.9909" gainprm="23.5579" biasprm="0 -23.5579 -0.603107"/>
    <general name="Right_Ankle_Roll" class="/" joint="Right_Ankle_Roll" forcerange="-14.1469 14.1469" gainprm="23.5579" biasprm="0 -23.5579 -0.603107"/>
  </actuator>

  <sensor>
    <gyro site="imu" name="imu_angular_velocity"/>
    <velocimeter site="imu" name="imu_linear_velocity"/>
    <framelinvel objtype="site" objname="left_foot" name="left_foot_global_linear_velocity"/>
    <framelinvel objtype="site" objname="right_foot" name="right_foot_global_linear_velocity"/>
  </sensor>

  <keyframe>
    <key name="home" qpos="0 0 0.6385 1 0 0 0 0 0 0 1.4 0 -0.4 0 -1.4 0 0.4 0 -0.4 0 0 0.8 -0.4 0 0.4 0 0 -0.8 0.4 0"/>
  </keyframe>
</mujoco>
