<mujoco model="T1">
  <compiler angle="radian" assetdir="assets" balanceinertia="true" inertiafromgeom="false"/>

  <option timestep="0.005" density="1.2" viscosity="2e-05"/>

  <size nkey="1"/>

  <visual>
    <quality shadowsize="8192"/>
    <map shadowclip="0.5"/>
  </visual>

  <default>
    <default class="/">
      <joint armature="0.01" damping="0.01" frictionloss="0.1"/>
      <geom contype="0" conaffinity="0" group="1" solref="-1000 -80"/>
      <site size="0.01 0.005 0.005" group="5"/>
      <general forcelimited="true" biastype="affine" gainprm="25" biasprm="0 -25 -0.6"/>
      <default class="t1">
        <geom rgba="0.25 0.25 0.25 1"/>
        <default class="visual">
          <geom type="mesh" group="2"/>
        </default>
        <default class="collision">
          <geom group="3"/>
        </default>
        <default class="foot">
          <geom size="0.1115 0.05 0.015" type="box" condim="6" group="4" priority="1" solimp="0.015 1 0.015"/>
        </default>
        <default class="reward_collision_sphere">
          <geom group="5" rgba="1 0 0 1"/>
        </default>
      </default>
    </default>
  </default>

  <asset>
    <texture type="skybox" colorspace="auto" name="//unnamed_texture_0" builtin="gradient" rgb1="0.95 0.95 0.95" rgb2="0.95 0.95 0.95" width="100" height="600"/>
    <texture type="2d" colorspace="auto" name="texplane" builtin="checker" rgb1="0.345 0.575 0.748" rgb2="0.345 0.575 0.748" markrgb="1 1 1" width="512" height="512"/>
    <material name="MatPlane" class="/" texture="texplane" texuniform="true" texrepeat="2 2" specular="0.9"/>
    <mesh name="Trunk" class="/" file="Trunk.stl"/>
    <mesh name="H1" class="/" file="H1.stl"/>
    <mesh name="H2" class="/" file="H2.stl"/>
    <mesh name="AL1" class="/" file="AL1.stl"/>
    <mesh name="AL2" class="/" file="AL2.stl"/>
    <mesh name="AL3" class="/" file="AL3.stl"/>
    <mesh name="left_hand_link" class="/" file="left_hand_link.stl"/>
    <mesh name="AR1" class="/" file="AR1.stl"/>
    <mesh name="AR2" class="/" file="AR2.stl"/>
    <mesh name="AR3" class="/" file="AR3.stl"/>
    <mesh name="right_hand_link" class="/" file="right_hand_link.stl"/>
    <mesh name="Waist" class="/" file="Waist.stl"/>
    <mesh name="Hip_Pitch_Left" class="/" file="Hip_Pitch_Left.stl"/>
    <mesh name="Hip_Roll_Left" class="/" file="Hip_Roll_Left.stl"/>
    <mesh name="Hip_Yaw_Left" class="/" file="Hip_Yaw_Left.stl"/>
    <mesh name="Shank_Left" class="/" file="Shank_Left.stl"/>
    <mesh name="Ankle_Cross_Left" class="/" file="Ankle_Cross_Left.stl"/>
    <mesh name="left_foot_link" class="/" file="left_foot_link.stl"/>
    <mesh name="Hip_Pitch_Right" class="/" file="Hip_Pitch_Right.stl"/>
    <mesh name="Hip_Roll_Right" class="/" file="Hip_Roll_Right.stl"/>
    <mesh name="Hip_Yaw_Right" class="/" file="Hip_Yaw_Right.stl"/>
    <mesh name="Shank_Right" class="/" file="Shank_Right.stl"/>
    <mesh name="Ankle_Cross_Right" class="/" file="Ankle_Cross_Right.stl"/>
    <mesh name="right_foot_link" class="/" file="right_foot_link.stl"/>
  </asset>

  <worldbody>
    <geom name="floor" class="/" size="100 100 0.125" type="plane" group="0" material="MatPlane"/>
    <light name="toplight_shadow" class="/" pos="0 0 5" dir="0.0990148 0.0990148 -0.990148" type="directional" ambient="0.04 0.04 0.04" diffuse="0.55 0.55 0.55" specular="0.12 0.12 0.12"/>
    <light name="toplight_fill" class="/" pos="0 0 5" dir="0.0990148 0.0990148 -0.990148" type="directional" castshadow="false" ambient="0.04 0.04 0.04" diffuse="0.3 0.3 0.3" specular="0.08 0.08 0.08"/>
    <body name="trunk" childclass="t1" pos="0.000472239 2.97472e-05 -0.00693077" quat="1 7.49743e-05 0.000296139 -0.000227714">
      <inertial pos="0.0680006 0.00507474 0.143406" quat="0.999543 0.0147971 -0.020317 -0.016818" mass="16.4331" diaginertia="0.309962 0.0146436 0.259454"/>
      <joint name="//unnamed_joint_0" type="free" armature="0" damping="0" frictionloss="0"/>
      <geom name="//unnamed_geom_1" class="visual" rgba="0.76 0.76 0.76 1" mesh="Trunk"/>
      <geom name="//unnamed_geom_2" class="collision" size="0.0835384 0.111385 0.167077" pos="0.0770282 0 0.162106" type="box"/>
      <geom name="//unnamed_geom_3" class="reward_collision_sphere" size="0.128092" pos="0.0770282 0 0.135088"/>
      <geom name="//unnamed_geom_4" class="reward_collision_sphere" size="0.0167077" pos="0.0770282 0.0600825 0"/>
      <geom name="//unnamed_geom_5" class="reward_collision_sphere" size="0.0167077" pos="0.0770282 -0.0600825 0"/>
      <geom name="//unnamed_geom_6" class="reward_collision_sphere" size="0.0167077" pos="0.0770282 0.0756332 0.243158"/>
      <geom name="//unnamed_geom_7" class="reward_collision_sphere" size="0.0167077" pos="0.0770282 -0.0756332 0.243158"/>
      <site name="imu" pos="0.000110357 -0.0426779 0.0137115" size="0.0111385"/>
      <camera name="track" pos="0 -1.41371 0" quat="0.707107 0.707107 0 0" mode="trackcom"/>
      <camera name="ego_camera" pos="0.156624 0 0.567369" quat="-0.5 -0.5 0.5 0.5"/>
      <body name="H1" pos="0.0793407 0.00419104 0.329775" quat="0.999992 0.00253541 0.00135983 -0.00295204">
        <inertial pos="-0.00358213 -0.00239664 0.0746928" quat="0.763933 -0.00636557 0.00712682 0.645224" mass="0.692633" diaginertia="0.000899754 3.82337e-05 0.000695682"/>
        <joint name="AAHead_yaw" pos="0 0 0" axis="0.00735977 0.00563712 0.999957" range="-1.62568 1.36394" armature="0.0102366" damping="0.0377892" frictionloss="0.14117"/>
        <geom name="//unnamed_geom_8" class="visual" mesh="H1"/>
        <body name="H2" pos="-0.00162379 0.00131001 0.0953371" quat="0.999984 -0.00288574 0.00400512 -0.00287016">
          <inertial pos="0.0127749 -0.00514136 0.126376" quat="0.986574 0.103001 -0.0717711 -0.104455" mass="0.863956" diaginertia="0.00697426 0.000321141 0.00806113"/>
          <joint name="Head_pitch" pos="0 0 0" axis="-0.0313815 -0.999433 -0.0121671" stiffness="0.0255313" range="-1.23068 0.387267" armature="0.0121802" damping="0" frictionloss="0.121234"/>
          <geom name="//unnamed_geom_9" class="visual" mesh="H2"/>
          <geom name="//unnamed_geom_10" class="collision" size="0.0891076" pos="0.012838 0 0.148597"/>
          <geom name="//unnamed_geom_11" class="reward_collision_sphere" size="0.100246" pos="0.0256761 0 0.135088"/>
        </body>
      </body>
      <body name="AL1" pos="0.0795516 0.0774488 0.301581" quat="0.999999 -0.000775553 0.000563809 0.000591067">
        <inertial pos="-0.00254875 0.0364342 -0.000331653" quat="0.526173 0.46146 -0.495497 0.51447" mass="0.807806" diaginertia="0.00539216 0.000247606 0.00139568"/>
        <joint name="Left_Shoulder_Pitch" pos="0 0 0" axis="0.0204123 0.99976 -0.00790559" stiffness="0.0210149" range="-3.50354 1.24315" armature="0.0147828" damping="0.0299019" frictionloss="0.130069"/>
        <geom name="//unnamed_geom_12" class="visual" rgba="0.76 0.76 0.76 1" mesh="AL1"/>
        <body name="AL2" pos="0.00543237 0.0339427 0.00021408" quat="0.99999 0.00155874 0.00346779 0.00252336">
          <inertial pos="-0.00577661 0.0225006 -0.000391346" quat="0.497991 0.523078 -0.476288 0.501543" mass="0.240287" diaginertia="0.00152026 6.65637e-05 0.000885272"/>
          <joint name="Left_Shoulder_Roll" pos="0 0 0" axis="-0.999866 -0.0162454 0.00191214" range="-1.56727 1.74423" armature="0.00811495" damping="0" frictionloss="0.106532"/>
          <geom name="//unnamed_geom_13" class="visual" mesh="AL2"/>
          <body name="AL3" pos="0.00608946 0.0456856 -0.000106075" quat="0.999991 -7.9203e-05 0.00271073 0.00335427">
            <inertial pos="-0.00972411 0.0603282 -0.0039707" quat="0.701891 0.71011 -0.0537277 -0.0143863" mass="1.20781" diaginertia="0.0392865 0.00166511 0.0024552"/>
            <joint name="Left_Elbow_Pitch" pos="0 0 0" axis="0.00368998 -0.999988 -0.00310862" range="-2.30564 2.05768" armature="0.00704234" damping="0.0118395" frictionloss="0.0523592"/>
            <geom name="//unnamed_geom_14" class="visual" mesh="AL3"/>
            <geom name="//unnamed_geom_15" class="collision" size="0.0334154 0.0835384" pos="0 0.0353426 0" quat="0.707105 0.707108 0 0" type="cylinder"/>
            <geom name="//unnamed_geom_16" class="reward_collision_sphere" size="0.0400984"/>
            <body name="left_hand_link" pos="0.00545865 0.101182 0.00126868" quat="0.999987 -0.000676406 -0.00507421 0.000702955">
              <inertial pos="6.60919e-05 0.0710534 0.00214731" quat="0.706137 0.708072 0.00172553 -0.00126677" mass="0.480538" diaginertia="0.0252156 0.00132244 0.00108103"/>
              <joint name="Left_Elbow_Yaw" pos="0 0 0" axis="-0.0279357 0.0290805 0.999187" range="-2.3615 -0.21004" armature="0.0150563" damping="0.0474655" frictionloss="0.0885767"/>
              <geom name="//unnamed_geom_17" class="visual" mesh="left_hand_link"/>
              <geom name="//unnamed_geom_18" class="collision" size="0.0334154 0.0974614" pos="0 0.0918909 0" quat="0.707105 0.707108 0 0" type="cylinder"/>
              <geom name="//unnamed_geom_19" class="reward_collision_sphere" size="0.0556923"/>
              <geom name="//unnamed_geom_20" class="reward_collision_sphere" size="0.0389846" pos="0 0.0777538 0"/>
              <geom name="//unnamed_geom_21" class="reward_collision_sphere" size="0.0389846" pos="0 0.151973 0"/>
            </body>
          </body>
        </body>
      </body>
      <body name="AR1" pos="0.0734405 -0.0821356 0.305144" quat="1 -3.2058e-06 0.000696411 -5.91921e-05">
        <inertial pos="-5.59994e-05 -0.0235666 0.00208577" quat="0.508692 0.492683 -0.505466 0.492951" mass="0.691815" diaginertia="0.00466302 0.000239458 0.00128813"/>
        <joint name="Right_Shoulder_Pitch" pos="0 0 0" axis="0.0378605 -0.998508 0.0393592" stiffness="0.0172557" range="-1.2196 3.11805" armature="0.0111774" damping="0" frictionloss="0.167025"/>
        <geom name="//unnamed_geom_22" class="visual" rgba="0.76 0.76 0.76 1" mesh="AR1"/>
        <body name="AR2" pos="-0.0112279 -0.0236955 -0.000947161" quat="1 9.94507e-05 -0.00014506 0.000175341">
          <inertial pos="-0.00178886 -0.0260404 0.00202051" quat="0.511374 0.481666 -0.511512 0.494824" mass="0.171215" diaginertia="0.00121138 5.64068e-05 0.000685777"/>
          <joint name="Right_Shoulder_Roll" pos="0 0 0" axis="-0.999218 0.018667 -0.0348531" stiffness="0.0366226" range="-1.69985 1.43748" armature="0.0110092" damping="0.0449002" frictionloss="0.0688894"/>
          <geom name="//unnamed_geom_23" class="visual" mesh="AR2"/>
          <body name="AR3" pos="0.00818133 -0.0430489 0.00348391" quat="0.999998 -0.00128157 0.000769382 -0.00155404">
            <inertial pos="-0.0014978 -0.0675158 0.00302883" quat="0.711695 0.702328 0.0143737 -0.00430364" mass="1.09297" diaginertia="0.0380692 0.0019058 0.00234188"/>
            <joint name="Right_Elbow_Pitch" pos="0 0 0" axis="-0.00351999 0.999986 -0.00403508" stiffness="0.0582485" range="-2.12673 2.43205" armature="0.0104031" damping="0.00543662" frictionloss="0.105998"/>
            <geom name="//unnamed_geom_24" class="visual" mesh="AR3"/>
            <geom name="//unnamed_geom_25" class="collision" size="0.0334154 0.0835384" pos="0 -0.0353426 0" quat="0.707105 0.707108 0 0" type="cylinder"/>
            <geom name="//unnamed_geom_26" class="reward_collision_sphere" size="0.0400984"/>
            <body name="right_hand_link" pos="-0.00318568 -0.101613 -0.00533212" quat="1 -0.000147833 -0.000198652 7.74444e-05">
              <inertial pos="-0.00100223 -0.0760731 0.0109906" quat="0.697497 0.716153 0.021929 -0.0119033" mass="0.547289" diaginertia="0.0306987 0.00152276 0.00105535"/>
              <joint name="Right_Elbow_Yaw" pos="0 0 0" axis="-0.00652107 0.0300542 0.999527" stiffness="0.00239069" range="-0.0498133 2.27269" armature="0.0110627" damping="0.0132168" frictionloss="0.104309"/>
              <geom name="//unnamed_geom_27" class="visual" mesh="right_hand_link"/>
              <geom name="//unnamed_geom_28" class="collision" size="0.0334154 0.0974614" pos="0 -0.0918909 0" quat="0.707105 0.707108 0 0" type="cylinder"/>
              <geom name="//unnamed_geom_29" class="reward_collision_sphere" size="0.0556923"/>
              <geom name="//unnamed_geom_30" class="reward_collision_sphere" size="0.0389846" pos="0 -0.0777538 0"/>
              <geom name="//unnamed_geom_31" class="reward_collision_sphere" size="0.0389846" pos="0 -0.151973 0"/>
            </body>
          </body>
        </body>
      </body>
      <body name="Waist" pos="0.0921623 0.00808481 -0.156417" quat="0.999994 0.00114752 -0.00317337 -0.00105341">
        <inertial pos="0.0048282 0.00710622 0.0105172" quat="0.983669 -0.000146136 -0.179975 0.00187265" mass="3.72706" diaginertia="0.0211588 0.00106938 0.0250951"/>
        <joint name="Waist" pos="0 0 0" axis="0.00107822 0.0264815 0.999649" range="-1.60554 1.5435" armature="0.0101956" damping="0.0186889" frictionloss="0.165857"/>
        <geom name="//unnamed_geom_32" class="visual" mesh="Waist"/>
        <body name="Hip_Pitch_Left" pos="-0.00252979 0.0843563 -0.0073004" quat="0.999993 -0.0024159 0.00232682 0.00182621">
          <inertial pos="0.00316822 -0.00452202 -0.0252798" quat="0.97227 0.233861 -0.000116327 0.000686313" mass="1.41548" diaginertia="0.0066109 0.000233774 0.00616095"/>
          <joint name="Left_Hip_Pitch" pos="0 0 0" axis="0.001266 0.999999 -0.000133937" stiffness="0.0464343" range="-1.8173 1.53939" armature="0.011746" damping="0.0143845" frictionloss="0.0972528"/>
          <geom name="//unnamed_geom_33" class="visual" rgba="0.76 0.76 0.76 1" mesh="Hip_Pitch_Left"/>
          <body name="Hip_Roll_Left" pos="-0.00874527 -0.00115394 -0.0317445" quat="0.999984 -0.00254672 0.00406719 -0.00307258">
            <inertial pos="0.0108275 0.00759489 -0.0737086" quat="0.710769 -0.0410483 0.0353154 0.701338" mass="0.542558" diaginertia="0.00668775 0.000269274 0.00236503"/>
            <joint name="Left_Hip_Roll" pos="0 0 0" axis="-0.998406 -0.0290563 0.0483952" range="-1.43539 0.0158939" armature="0.00656706" damping="0.00764467" frictionloss="0.103816"/>
            <geom name="//unnamed_geom_34" class="visual" mesh="Hip_Roll_Left"/>
            <geom name="//unnamed_geom_35" class="reward_collision_sphere" size="0.0612615"/>
            <body name="Hip_Yaw_Left" pos="-0.0117923 -0.00136022 -0.118684" quat="0.999988 0.00240748 0.00308047 -0.00288632">
              <inertial pos="-0.00888632 -0.00144655 -0.1165" quat="0.696899 -0.0348428 -0.0329229 0.715565" mass="2.9615" diaginertia="0.0973927 0.0045268 0.0107355"/>
              <joint name="Left_Hip_Yaw" pos="0 0 0" axis="0.0151708 -0.0117668 -0.999816" range="-1.02065 1.2045" armature="0.0114995" damping="0.00183924" frictionloss="0.0909602"/>
              <geom name="//unnamed_geom_36" class="visual" mesh="Hip_Yaw_Left"/>
              <geom name="//unnamed_geom_37" class="collision" size="0.0556923 0.0891076" type="cylinder"/>
              <body name="Shank_Left" pos="-0.0208326 0.00189401 -0.170581" quat="0.999999 0.000657795 0.000153439 0.000815983">
                <inertial pos="-0.0154071 0.00860579 -0.167004" quat="0.997608 0.00101852 -0.0235974 0.0649712" mass="2.47949" diaginertia="0.122634 0.0064865 0.00828416"/>
                <joint name="Left_Knee_Pitch" pos="0 0 0" axis="-0.0305829 0.999532 0.000658336" range="-0.0916827 2.27873" armature="0.0122492" damping="0" frictionloss="0.11717"/>
                <geom name="//unnamed_geom_38" class="visual" mesh="Shank_Left"/>
                <geom name="//unnamed_geom_39" class="collision" size="0.0556923 0.0835384" pos="0 0 -0.162106" type="cylinder"/>
                <geom name="//unnamed_geom_40" class="reward_collision_sphere" size="0.0723999"/>
                <body name="Ankle_Cross_Left" pos="0.00139899 0.00410016 -0.388128" quat="0.999998 0.000406302 0.00111145 0.00182557">
                  <inertial pos="-0.0112339 -0.00178513 -0.00657337" quat="0.450248 0.548395 0.551295 0.438877" mass="0.091773" diaginertia="9.90778e-05 4.81549e-06 5.23379e-05"/>
                  <joint name="Left_Ankle_Pitch" pos="0 0 0" axis="-0.00185191 0.999849 -0.017284" range="-0.840093 0.313484" armature="0.0117475" damping="0" frictionloss="0.146712"/>
                  <geom name="//unnamed_geom_41" class="visual" mesh="Ankle_Cross_Left"/>
                  <body name="left_foot_link" pos="0.00128129 -0.00420416 -0.0111353" quat="1 -0.000111652 0.000196911 -0.000248431">
                    <inertial pos="-0.00248439 -0.0074676 -0.0139731" quat="0.0153834 0.637953 0.00281753 0.769917" mass="1.04112" diaginertia="0.0079253 0.000391246 0.00924793"/>
                    <joint name="Left_Ankle_Roll" pos="0 0 0" axis="-0.99968 -0.0200291 0.0154718" range="-0.403932 0.24445" armature="0.00560241" damping="0.00990242" frictionloss="0.0995793"/>
                    <geom name="//unnamed_geom_42" class="visual" mesh="left_foot_link"/>
                    <geom name="left_foot" class="foot" size="0.105451 0.0653611 0.0174147" pos="0.012838 0 -0.0202632"/>
                    <geom name="//unnamed_geom_44" class="reward_collision_sphere" size="0.0579199" pos="0.012838 0 -0.0202632"/>
                    <geom name="//unnamed_geom_45" class="reward_collision_sphere" size="0.0334154" pos="0.121961 -0.0162576 -0.0202632"/>
                    <geom name="//unnamed_geom_46" class="reward_collision_sphere" size="0.0334154" pos="-0.0898662 -0.0162576 -0.0202632"/>
                    <site name="left_foot" class="foot" pos="0.012838 0 -0.0202632" size="0.0111385"/>
                  </body>
                </body>
              </body>
            </body>
          </body>
        </body>
        <body name="Hip_Pitch_Right" pos="-0.008101 -0.0777854 0.0069208" quat="0.999999 -0.00039464 -0.000290462 0.000893938">
          <inertial pos="0.0093591 0.00503876 -0.0236963" quat="0.970306 -0.239727 0.0318802 0.00449197" mass="1.52675" diaginertia="0.00645085 0.000267075 0.0058814"/>
          <joint name="Right_Hip_Pitch" pos="0 0 0" axis="-0.00368029 -0.99998 0.00509106" stiffness="0.0177271" range="-1.5771 1.89233" armature="0.00488141" damping="0.00134827" frictionloss="0.132572"/>
          <geom name="//unnamed_geom_47" class="visual" rgba="0.76 0.76 0.76 1" mesh="Hip_Pitch_Right"/>
          <body name="Hip_Roll_Right" pos="-0.00137758 0.0044664 -0.0279591" quat="1 0.000632715 2.91826e-05 8.63136e-08">
            <inertial pos="0.00287819 0.00983435 -0.0658591" quat="0.674756 -0.00588939 -0.00457193 0.738003" mass="0.610616" diaginertia="0.00703001 0.000313426 0.00264075"/>
            <joint name="Right_Hip_Roll" pos="0 0 0" axis="-0.999982 -0.00016697 0.00606479" stiffness="0.00538887" range="-0.224726 1.56015" armature="0.0102269" damping="0.00810608" frictionloss="0.150854"/>
            <geom name="//unnamed_geom_48" class="visual" mesh="Hip_Roll_Right"/>
            <geom name="//unnamed_geom_49" class="reward_collision_sphere" size="0.0612615"/>
            <body name="Hip_Yaw_Right" pos="-0.00779366 -0.00411844 -0.115804" quat="0.999995 -0.00254422 -0.00198376 0.0006699">
              <inertial pos="-0.00855454 0.0111967 -0.123919" quat="0.709786 -0.0410042 -0.0322413 0.702484" mass="3.23202" diaginertia="0.101277 0.00504813 0.0135405"/>
              <joint name="Right_Hip_Yaw" pos="0 0 0" axis="0.0233778 0.00434039 -0.999717" range="-0.915283 0.845408" armature="0.0112891" damping="0" frictionloss="0.109301"/>
              <geom name="//unnamed_geom_50" class="visual" mesh="Hip_Yaw_Right"/>
              <geom name="//unnamed_geom_51" class="collision" size="0.0556923 0.0891076" type="cylinder"/>
              <body name="Shank_Right" pos="-0.018009 -0.00440946 -0.182994" quat="1 0.000285474 0.000128982 9.71641e-05">
                <inertial pos="-0.00921742 -0.00100891 -0.162544" quat="0.99927 0.000396939 -0.0230186 -0.0304772" mass="2.64257" diaginertia="0.154083 0.00694181 0.009709"/>
                <joint name="Right_Knee_Pitch" pos="0 0 0" axis="0.00991493 -0.999657 -0.0242418" stiffness="0.0408168" range="-2.42034 -0.0607758" armature="0.0111697" damping="0.00570384" frictionloss="0.121329"/>
                <geom name="//unnamed_geom_52" class="visual" mesh="Shank_Right"/>
                <geom name="//unnamed_geom_53" class="collision" size="0.0556923 0.0835384" pos="0 0 -0.162106" type="cylinder"/>
                <geom name="//unnamed_geom_54" class="reward_collision_sphere" size="0.0723999"/>
                <body name="Ankle_Cross_Right" pos="0.00207737 -0.00243862 -0.38202" quat="0.999993 -0.00106001 0.000513708 -0.0036601">
                  <inertial pos="-0.00409778 0.0017715 -0.00109898" quat="0.451514 0.508716 0.572311 0.458043" mass="0.109375" diaginertia="0.000127809 4.56809e-06 6.37971e-05"/>
                  <joint name="Right_Ankle_Pitch" pos="0 0 0" axis="0.0284267 -0.99926 0.0259249" stiffness="0.0381357" range="-0.47461 0.821738" armature="0.0114474" damping="0.0392929" frictionloss="0.152841"/>
                  <geom name="//unnamed_geom_55" class="visual" mesh="Ankle_Cross_Right"/>
                  <body name="right_foot_link" pos="-0.000530865 0.00173647 -0.0208042" quat="0.999999 -0.0010377 -0.000373246 -0.000708489">
                    <inertial pos="0.0110907 0.00626413 -0.0116964" quat="0.0163088 0.608258 -0.0218394 0.793271" mass="0.936015" diaginertia="0.00946419 0.000424821 0.0107092"/>
                    <joint name="Right_Ankle_Roll" pos="0 0 0" axis="-0.999996 -0.00168427 -0.00219197" range="-0.434751 0.4695" armature="0.00893341" damping="0" frictionloss="0.121138"/>
                    <geom name="//unnamed_geom_56" class="visual" mesh="right_foot_link"/>
                    <geom name="right_foot" class="foot" size="0.095315 0.0467395 0.0154677" pos="0.012838 0 -0.0202632"/>
                    <geom name="//unnamed_geom_58" class="reward_collision_sphere" size="0.0445538"/>
                    <geom name="//unnamed_geom_59" class="reward_collision_sphere" size="0.0334154" pos="0.012838 0 -0.0202632"/>
                    <geom name="//unnamed_geom_60" class="reward_collision_sphere" size="0.0334154" pos="0.121961 0.0162576 -0.0202632"/>
                    <geom name="//unnamed_geom_61" class="reward_collision_sphere" size="0.0334154" pos="-0.0898662 0.0162576 -0.0202632"/>
                    <site name="right_foot" class="foot" pos="0.012838 0 -0.0202632" size="0.0111385"/>
                  </body>
                </body>
              </body>
            </body>
          </body>
        </body>
      </body>
    </body>
  </worldbody>

  <contact>
    <pair class="/" geom1="floor" geom2="left_foot" name="//unnamed_contact_0"/>
    <pair class="/" geom1="floor" geom2="right_foot" name="//unnamed_contact_1"/>
  </contact>

  <actuator>
    <general name="AAHead_yaw" class="/" joint="AAHead_yaw" forcerange="-6.04092 6.04092" gainprm="28.2829" biasprm="0 -28.2829 -0.752443"/>
    <general name="Head_pitch" class="/" joint="Head_pitch" forcerange="-5.89452 5.89452" gainprm="28.2829" biasprm="0 -28.2829 -0.752443"/>
    <general name="Left_Shoulder_Pitch" class="/" joint="Left_Shoulder_Pitch" forcerange="-21.9782 21.9782" gainprm="28.2829" biasprm="0 -28.2829 -0.752443"/>
    <general name="Left_Shoulder_Roll" class="/" joint="Left_Shoulder_Roll" forcerange="-20.2196 20.2196" gainprm="28.2829" biasprm="0 -28.2829 -0.752443"/>
    <general name="Left_Elbow_Pitch" class="/" joint="Left_Elbow_Pitch" forcerange="-13.0522 13.0522" gainprm="28.2829" biasprm="0 -28.2829 -0.752443"/>
    <general name="Left_Elbow_Yaw" class="/" joint="Left_Elbow_Yaw" forcerange="-24.3488 24.3488" gainprm="28.2829" biasprm="0 -28.2829 -0.752443"/>
    <general name="Right_Shoulder_Pitch" class="/" joint="Right_Shoulder_Pitch" forcerange="-27.855 27.855" gainprm="28.2829" biasprm="0 -28.2829 -0.752443"/>
    <general name="Right_Shoulder_Roll" class="/" joint="Right_Shoulder_Roll" forcerange="-18.5977 18.5977" gainprm="28.2829" biasprm="0 -28.2829 -0.752443"/>
    <general name="Right_Elbow_Pitch" class="/" joint="Right_Elbow_Pitch" forcerange="-12.8043 12.8043" gainprm="28.2829" biasprm="0 -28.2829 -0.752443"/>
    <general name="Right_Elbow_Yaw" class="/" joint="Right_Elbow_Yaw" forcerange="-17.9548 17.9548" gainprm="28.2829" biasprm="0 -28.2829 -0.752443"/>
    <general name="Waist" class="/" joint="Waist" forcerange="-34.344 34.344" gainprm="28.2829" biasprm="0 -28.2829 -0.752443"/>
    <general name="Left_Hip_Pitch" class="/" joint="Left_Hip_Pitch" forcerange="-54.1951 54.1951" gainprm="28.2829" biasprm="0 -28.2829 -0.752443"/>
    <general name="Left_Hip_Roll" class="/" joint="Left_Hip_Roll" forcerange="-22.2984 22.2984" gainprm="28.2829" biasprm="0 -28.2829 -0.752443"/>
    <general name="Left_Hip_Yaw" class="/" joint="Left_Hip_Yaw" forcerange="-47.2065 47.2065" gainprm="28.2829" biasprm="0 -28.2829 -0.752443"/>
    <general name="Left_Knee_Pitch" class="/" joint="Left_Knee_Pitch" forcerange="-48.9918 48.9918" gainprm="28.2829" biasprm="0 -28.2829 -0.752443"/>
    <general name="Left_Ankle_Pitch" class="/" joint="Left_Ankle_Pitch" forcerange="-32.3278 32.3278" gainprm="28.2829" biasprm="0 -28.2829 -0.752443"/>
    <general name="Left_Ankle_Roll" class="/" joint="Left_Ankle_Roll" forcerange="-15.7325 15.7325" gainprm="28.2829" biasprm="0 -28.2829 -0.752443"/>
    <general name="Right_Hip_Pitch" class="/" joint="Right_Hip_Pitch" forcerange="-49.8822 49.8822" gainprm="28.2829" biasprm="0 -28.2829 -0.752443"/>
    <general name="Right_Hip_Roll" class="/" joint="Right_Hip_Roll" forcerange="-39.1886 39.1886" gainprm="28.2829" biasprm="0 -28.2829 -0.752443"/>
    <general name="Right_Hip_Yaw" class="/" joint="Right_Hip_Yaw" forcerange="-39.1441 39.1441" gainprm="28.2829" biasprm="0 -28.2829 -0.752443"/>
    <general name="Right_Knee_Pitch" class="/" joint="Right_Knee_Pitch" forcerange="-46.5225 46.5225" gainprm="28.2829" biasprm="0 -28.2829 -0.752443"/>
    <general name="Right_Ankle_Pitch" class="/" joint="Right_Ankle_Pitch" forcerange="-18.1028 18.1028" gainprm="28.2829" biasprm="0 -28.2829 -0.752443"/>
    <general name="Right_Ankle_Roll" class="/" joint="Right_Ankle_Roll" forcerange="-22.7949 22.7949" gainprm="28.2829" biasprm="0 -28.2829 -0.752443"/>
  </actuator>

  <sensor>
    <gyro site="imu" name="imu_angular_velocity"/>
    <velocimeter site="imu" name="imu_linear_velocity"/>
    <framelinvel objtype="site" objname="left_foot" name="left_foot_global_linear_velocity"/>
    <framelinvel objtype="site" objname="right_foot" name="right_foot_global_linear_velocity"/>
  </sensor>

  <keyframe>
    <key name="home" qpos="0 0 0.6385 1 0 0 0 0 0 0 1.4 0 -0.4 0 -1.4 0 0.4 0 -0.4 0 0 0.8 -0.4 0 0.4 0 0 -0.8 0.4 0"/>
  </keyframe>
</mujoco>
