<mujoco model="T1">
  <compiler angle="radian" assetdir="assets" balanceinertia="true" inertiafromgeom="false"/>

  <option timestep="0.005" density="1.2" viscosity="2e-05"/>

  <size nkey="1"/>

  <visual>
    <quality shadowsize="8192"/>
    <map shadowclip="0.5"/>
  </visual>

  <default>
    <default class="/">
      <joint armature="0.01" damping="0.01" frictionloss="0.1"/>
      <geom contype="0" conaffinity="0" group="1" solref="-1000 -80"/>
      <site size="0.01 0.005 0.005" group="5"/>
      <general forcelimited="true" biastype="affine" gainprm="25" biasprm="0 -25 -0.6"/>
      <default class="t1">
        <geom rgba="0.25 0.25 0.25 1"/>
        <default class="visual">
          <geom type="mesh" group="2"/>
        </default>
        <default class="collision">
          <geom group="3"/>
        </default>
        <default class="foot">
          <geom size="0.1115 0.05 0.015" type="box" condim="6" group="4" priority="1" solimp="0.015 1 0.015"/>
        </default>
        <default class="reward_collision_sphere">
          <geom group="5" rgba="1 0 0 1"/>
        </default>
      </default>
    </default>
  </default>

  <asset>
    <texture type="skybox" colorspace="auto" name="//unnamed_texture_0" builtin="gradient" rgb1="0.95 0.95 0.95" rgb2="0.95 0.95 0.95" width="100" height="600"/>
    <texture type="2d" colorspace="auto" name="texplane" builtin="checker" rgb1="0.345 0.575 0.748" rgb2="0.345 0.575 0.748" markrgb="1 1 1" width="512" height="512"/>
    <material name="MatPlane" class="/" texture="texplane" texuniform="true" texrepeat="2 2" specular="0.9"/>
    <mesh name="Trunk" class="/" file="Trunk.stl"/>
    <mesh name="H1" class="/" file="H1.stl"/>
    <mesh name="H2" class="/" file="H2.stl"/>
    <mesh name="AL1" class="/" file="AL1.stl"/>
    <mesh name="AL2" class="/" file="AL2.stl"/>
    <mesh name="AL3" class="/" file="AL3.stl"/>
    <mesh name="left_hand_link" class="/" file="left_hand_link.stl"/>
    <mesh name="AR1" class="/" file="AR1.stl"/>
    <mesh name="AR2" class="/" file="AR2.stl"/>
    <mesh name="AR3" class="/" file="AR3.stl"/>
    <mesh name="right_hand_link" class="/" file="right_hand_link.stl"/>
    <mesh name="Waist" class="/" file="Waist.stl"/>
    <mesh name="Hip_Pitch_Left" class="/" file="Hip_Pitch_Left.stl"/>
    <mesh name="Hip_Roll_Left" class="/" file="Hip_Roll_Left.stl"/>
    <mesh name="Hip_Yaw_Left" class="/" file="Hip_Yaw_Left.stl"/>
    <mesh name="Shank_Left" class="/" file="Shank_Left.stl"/>
    <mesh name="Ankle_Cross_Left" class="/" file="Ankle_Cross_Left.stl"/>
    <mesh name="left_foot_link" class="/" file="left_foot_link.stl"/>
    <mesh name="Hip_Pitch_Right" class="/" file="Hip_Pitch_Right.stl"/>
    <mesh name="Hip_Roll_Right" class="/" file="Hip_Roll_Right.stl"/>
    <mesh name="Hip_Yaw_Right" class="/" file="Hip_Yaw_Right.stl"/>
    <mesh name="Shank_Right" class="/" file="Shank_Right.stl"/>
    <mesh name="Ankle_Cross_Right" class="/" file="Ankle_Cross_Right.stl"/>
    <mesh name="right_foot_link" class="/" file="right_foot_link.stl"/>
  </asset>

  <worldbody>
    <geom name="floor" class="/" size="100 100 0.125" type="plane" group="0" material="MatPlane"/>
    <light name="toplight_shadow" class="/" pos="0 0 5" dir="0.0990148 0.0990148 -0.990148" type="directional" ambient="0.04 0.04 0.04" diffuse="0.55 0.55 0.55" specular="0.12 0.12 0.12"/>
    <light name="toplight_fill" class="/" pos="0 0 5" dir="0.0990148 0.0990148 -0.990148" type="directional" castshadow="false" ambient="0.04 0.04 0.04" diffuse="0.3 0.3 0.3" specular="0.08 0.08 0.08"/>
    <body name="trunk" childclass="t1" pos="-0.000836029 -0.00338348 -0.0107612" quat="1 0.000216388 -7.33963e-05 0.000450033">
      <inertial pos="0.0797334 0.00887795 0.134627" quat="0.998629 0.0033659 -0.0491769 0.0175933" mass="19.9224" diaginertia="0.543731 0.0245057 0.228156"/>
      <joint name="//unnamed_joint_0" type="free" armature="0" damping="0" frictionloss="0"/>
      <geom name="//unnamed_geom_1" class="visual" rgba="0.76 0.76 0.76 1" mesh="Trunk"/>
      <geom name="//unnamed_geom_2" class="collision" size="0.0875752 0.116767 0.17515" pos="0.0863309 0 0.155316" type="box"/>
      <geom name="//unnamed_geom_3" class="reward_collision_sphere" size="0.134282" pos="0.0863309 0 0.12943"/>
      <geom name="//unnamed_geom_4" class="reward_collision_sphere" size="0.017515" pos="0.0863309 0.0654381 0"/>
      <geom name="//unnamed_geom_5" class="reward_collision_sphere" size="0.017515" pos="0.0863309 -0.0654381 0"/>
      <geom name="//unnamed_geom_6" class="reward_collision_sphere" size="0.017515" pos="0.0863309 0.082375 0.232974"/>
      <geom name="//unnamed_geom_7" class="reward_collision_sphere" size="0.017515" pos="0.0863309 -0.082375 0.232974"/>
      <site name="imu" pos="-0.00060113 -0.0619558 0.0322067" size="0.0116767"/>
      <camera name="track" pos="0 -1.53972 0" quat="0.707107 0.707107 0 0" mode="trackcom"/>
      <camera name="ego_camera" pos="0.17554 0 0.543606" quat="-0.5 -0.5 0.5 0.5"/>
      <body name="H1" pos="0.0866231 0.00796647 0.319639" quat="0.999982 -0.00411873 -0.000313093 0.00440881">
        <inertial pos="-0.00235664 0.00092889 0.067747" quat="0.749185 -0.0207188 0.0149022 0.661869" mass="0.869283" diaginertia="0.0017355 5.81907e-05 0.000612426"/>
        <joint name="AAHead_yaw" pos="0 0 0" axis="0.0075474 0.026466 0.999621" range="-1.70002 1.28625" armature="0.0120738" damping="0.0597692" frictionloss="0.170166"/>
        <geom name="//unnamed_geom_8" class="visual" mesh="H1"/>
        <body name="H2" pos="-0.00323883 -0.00136745 0.0957199" quat="0.999971 -0.00297384 0.00610064 0.00353063">
          <inertial pos="0.0177955 -0.00884015 0.116965" quat="0.990168 0.122624 -0.0393097 -0.0546448" mass="0.982536" diaginertia="0.0121674 0.000484253 0.00644813"/>
          <joint name="Head_pitch" pos="0 0 0" axis="-0.0108189 -0.998607 -0.0516442" stiffness="0.0453508" range="-1.30003 0.355082" armature="0.0116413" damping="0" frictionloss="0.115585"/>
          <geom name="//unnamed_geom_9" class="visual" mesh="H2"/>
          <geom name="//unnamed_geom_10" class="collision" size="0.0934136" pos="0.0143885 0 0.142373"/>
          <geom name="//unnamed_geom_11" class="reward_collision_sphere" size="0.10509" pos="0.028777 0 0.12943"/>
        </body>
      </body>
      <body name="AL1" pos="0.0871155 0.0854489 0.29298" quat="1 0.000223091 0.000500858 0.000186078">
        <inertial pos="-0.00623812 0.0430517 -0.00143029" quat="0.528509 0.461475 -0.541527 0.463106" mass="0.93824" diaginertia="0.0104018 0.00039034 0.0012142"/>
        <joint name="Left_Shoulder_Pitch" pos="0 0 0" axis="0.0242104 0.999163 0.0329839" stiffness="0.0405811" range="-3.58105 1.24174" armature="0.0178954" damping="0.0497753" frictionloss="0.158121"/>
        <geom name="//unnamed_geom_12" class="visual" rgba="0.76 0.76 0.76 1" mesh="AL1"/>
        <body name="AL2" pos="0.00425119 0.0377758 0.000875704" quat="0.999979 0.00379056 0.00517019 0.0010615">
          <inertial pos="-0.00905448 0.0211181 -0.000613922" quat="0.507252 0.48543 -0.474077 0.531323" mass="0.296869" diaginertia="0.00286491 0.000110378 0.000714453"/>
          <joint name="Left_Shoulder_Roll" pos="0 0 0" axis="-0.999996 -0.00219068 0.00199562" stiffness="0.0163045" range="-1.59534 1.81313" armature="0.00617445" damping="0" frictionloss="0.13016"/>
          <geom name="//unnamed_geom_13" class="visual" mesh="AL2"/>
          <body name="AL3" pos="0.0098978 0.0531488 0.000608406" quat="0.999981 -0.00199596 0.00298547 0.005109">
            <inertial pos="-0.0135811 0.0622912 -0.00769954" quat="0.671046 0.739096 -0.0423181 0.0405393" mass="1.32614" diaginertia="0.0684596 0.00227138 0.00180994"/>
            <joint name="Left_Elbow_Pitch" pos="0 0 0" axis="0.0201828 -0.999737 0.0109165" range="-2.25265 1.98014" armature="0.0053185" damping="0.004454" frictionloss="0.0322431"/>
            <geom name="//unnamed_geom_14" class="visual" mesh="AL3"/>
            <geom name="//unnamed_geom_15" class="collision" size="0.0350301 0.0875752" pos="0 0.038493 0" quat="0.707105 0.707108 0 0" type="cylinder"/>
            <geom name="//unnamed_geom_16" class="reward_collision_sphere" size="0.0420361"/>
            <body name="left_hand_link" pos="0.00923066 0.106727 -0.00206367" quat="0.999975 0.0009232 -0.00581293 -0.00398115">
              <inertial pos="0.00350553 0.074138 -0.000538246" quat="0.722053 0.691824 -0.00282291 0.00336413" mass="0.577997" diaginertia="0.0420994 0.00191881 0.000910318"/>
              <joint name="Left_Elbow_Yaw" pos="0 0 0" axis="-0.00729806 -0.0590826 0.998226" range="-2.28623 -0.28795" armature="0.0178653" damping="0.0690597" frictionloss="0.0709134"/>
              <geom name="//unnamed_geom_17" class="visual" mesh="left_hand_link"/>
              <geom name="//unnamed_geom_18" class="collision" size="0.0350301 0.102171" pos="0 0.100082 0" quat="0.707105 0.707108 0 0" type="cylinder"/>
              <geom name="//unnamed_geom_19" class="reward_collision_sphere" size="0.0583835"/>
              <geom name="//unnamed_geom_20" class="reward_collision_sphere" size="0.0408684" pos="0 0.0846846 0"/>
              <geom name="//unnamed_geom_21" class="reward_collision_sphere" size="0.0408684" pos="0 0.16552 0"/>
            </body>
          </body>
        </body>
      </body>
      <body name="AR1" pos="0.0856957 -0.0926964 0.296638" quat="1 0.000709922 0.000613162 -0.00021767">
        <inertial pos="0.000291702 -0.0225472 3.84971e-06" quat="0.495827 0.516392 -0.496072 0.491332" mass="0.755823" diaginertia="0.00844779 0.000382663 0.00106693"/>
        <joint name="Right_Shoulder_Pitch" pos="0 0 0" axis="-0.0711685 -0.997247 -0.0208419" stiffness="0.0364844" range="-1.23506 3.04078" armature="0.0135697" damping="0" frictionloss="0.197707"/>
        <geom name="//unnamed_geom_22" class="visual" rgba="0.76 0.76 0.76 1" mesh="AR1"/>
        <body name="AR2" pos="-0.0151404 -0.0228736 -0.00449908" quat="1 -1.56881e-05 0.000107051 -1.55312e-05">
          <inertial pos="-0.00502436 -0.0288541 -0.00120925" quat="0.524353 0.478375 -0.494144 0.502029" mass="0.176172" diaginertia="0.00204015 8.5352e-05 0.000541045"/>
          <joint name="Right_Shoulder_Roll" pos="0 0 0" axis="-0.998283 -0.0384458 0.0441959" stiffness="0.0563834" range="-1.71962 1.36068" armature="0.0134552" damping="0.0672418" frictionloss="0.0497834"/>
          <geom name="//unnamed_geom_23" class="visual" mesh="AR2"/>
          <body name="AR3" pos="0.0120334 -0.0503428 0.00725431" quat="0.999992 0.00330429 0.000266189 -0.00229222">
            <inertial pos="-0.000892803 -0.0767313 0.000642717" quat="0.72336 0.689973 -0.00863343 0.0247595" mass="1.1248" diaginertia="0.0639984 0.00274211 0.00179249"/>
            <joint name="Right_Elbow_Pitch" pos="0 0 0" axis="-0.00489957 0.999965 -0.00670869" stiffness="0.0781373" range="-2.05025 2.50903" armature="0.0126445" damping="0.0209406" frictionloss="0.111333"/>
            <geom name="//unnamed_geom_24" class="visual" mesh="AR3"/>
            <geom name="//unnamed_geom_25" class="collision" size="0.0350301 0.0875752" pos="0 -0.038493 0" quat="0.707105 0.707108 0 0" type="cylinder"/>
            <geom name="//unnamed_geom_26" class="reward_collision_sphere" size="0.0420361"/>
            <body name="right_hand_link" pos="-0.00241741 -0.111956 -0.0023956" quat="1 0.000148561 -0.000597837 -6.08641e-05">
              <inertial pos="0.00209181 -0.0843653 0.0147089" quat="0.675051 0.737559 0.0118143 -0.0131849" mass="0.686732" diaginertia="0.05445 0.00253861 0.000871517"/>
              <joint name="Right_Elbow_Yaw" pos="0 0 0" axis="-0.0463537 0.0186795 0.99875" range="-0.124004 2.19591" armature="0.0136751" damping="0.0129017" frictionloss="0.12667"/>
              <geom name="//unnamed_geom_27" class="visual" mesh="right_hand_link"/>
              <geom name="//unnamed_geom_28" class="collision" size="0.0350301 0.102171" pos="0 -0.100082 0" quat="0.707105 0.707108 0 0" type="cylinder"/>
              <geom name="//unnamed_geom_29" class="reward_collision_sphere" size="0.0583835"/>
              <geom name="//unnamed_geom_30" class="reward_collision_sphere" size="0.0408684" pos="0 -0.0846846 0"/>
              <geom name="//unnamed_geom_31" class="reward_collision_sphere" size="0.0408684" pos="0 -0.16552 0"/>
            </body>
          </body>
        </body>
      </body>
      <body name="Waist" pos="0.10575 0.0119941 -0.153409" quat="0.999985 -0.00168858 -0.00465885 0.00238949">
        <inertial pos="0.00178857 0.0109467 0.00672142" quat="0.983675 0.000460596 -0.179937 0.00252698" mass="4.24171" diaginertia="0.0405696 0.00170528 0.0220651"/>
        <joint name="Waist" pos="0 0 0" axis="0.00276974 0.0452012 0.998974" range="-1.57093 1.58205" armature="0.00840515" damping="0.0356338" frictionloss="0.196467"/>
        <geom name="//unnamed_geom_32" class="visual" mesh="Waist"/>
        <body name="Hip_Pitch_Left" pos="-0.00633117 0.0949649 -0.0111263" quat="0.999983 0.0029614 0.00129796 -0.00476994">
          <inertial pos="0.000650463 -0.00138036 -0.0249882" quat="0.971334 0.233523 0.0259525 0.036111" mass="1.62099" diaginertia="0.0127418 0.00035339 0.00542933"/>
          <joint name="Left_Hip_Pitch" pos="0 0 0" axis="-0.0184231 0.999821 -0.00438854" stiffness="0.0661287" range="-1.75056 1.46724" armature="0.0142583" damping="0" frictionloss="0.080412"/>
          <geom name="//unnamed_geom_33" class="visual" rgba="0.76 0.76 0.76 1" mesh="Hip_Pitch_Left"/>
          <body name="Hip_Roll_Left" pos="-0.0126089 0.00237031 -0.0343703" quat="0.999971 0.000656654 -0.00637298 -0.00417246">
            <inertial pos="0.0148779 0.0114668 -0.0742396" quat="0.701159 0.0160021 0.0643579 0.709914" mass="0.578881" diaginertia="0.0118155 0.000378775 0.00190907"/>
            <joint name="Left_Hip_Roll" pos="0 0 0" axis="-0.997125 -0.0746996 -0.0126906" stiffness="0.00185159" range="-1.35905 -0.0613817" armature="0.0048108" damping="0" frictionloss="0.125729"/>
            <geom name="//unnamed_geom_34" class="visual" mesh="Hip_Roll_Left"/>
            <geom name="//unnamed_geom_35" class="reward_collision_sphere" size="0.0642218"/>
            <body name="Hip_Yaw_Left" pos="-0.0157058 0.00190941 -0.117873" quat="0.999977 0.00167678 0.00656883 0.000646788">
              <inertial pos="-0.0135282 0.00199921 -0.107693" quat="0.695749 -0.0321048 -0.0167065 0.717373" mass="3.68104" diaginertia="0.187719 0.00714253 0.00857147"/>
              <joint name="Left_Hip_Yaw" pos="0 0 0" axis="-0.0336732 -0.0172368 -0.999284" stiffness="0.00114196" range="-1.08955 1.28183" armature="0.0103109" damping="0.0222622" frictionloss="0.0735063"/>
              <geom name="//unnamed_geom_36" class="visual" mesh="Hip_Yaw_Left"/>
              <geom name="//unnamed_geom_37" class="collision" size="0.0583835 0.0934136" type="cylinder"/>
              <body name="Shank_Left" pos="-0.0268302 0.00541346 -0.159094" quat="1 3.21855e-05 0.00025705 0.000127364">
                <inertial pos="-0.0201908 0.0124616 -0.162848" quat="0.997979 -0.00660652 -0.00815758 0.0626638" mass="2.85252" diaginertia="0.216488 0.00992323 0.00611705"/>
                <joint name="Left_Knee_Pitch" pos="0 0 0" axis="-0.00215736 0.999619 -0.0275178" range="-0.167205 2.20456" armature="0.0119881" damping="0.00303333" frictionloss="0.1047"/>
                <geom name="//unnamed_geom_38" class="visual" mesh="Shank_Left"/>
                <geom name="//unnamed_geom_39" class="collision" size="0.0583835 0.0875752" pos="0 0 -0.155316" type="cylinder"/>
                <geom name="//unnamed_geom_40" class="reward_collision_sphere" size="0.0758985"/>
                <body name="Ankle_Cross_Left" pos="0.00133035 0.00273886 -0.376152" quat="0.999992 -0.00106741 0.00312396 0.00238474">
                  <inertial pos="-0.0156497 -0.00544283 -0.00236234" quat="0.443078 0.55106 0.551051 0.443123" mass="0.104433" diaginertia="0.000174068 8.05351e-06 4.41487e-05"/>
                  <joint name="Left_Ankle_Pitch" pos="0 0 0" axis="0.0255371 0.999352 -0.025369" range="-0.767267 0.24087" armature="0.0106166" damping="0" frictionloss="0.176105"/>
                  <geom name="//unnamed_geom_41" class="visual" mesh="Ankle_Cross_Left"/>
                  <body name="left_foot_link" pos="0.0028426 -0.00797523 -0.0100849" quat="0.999998 -0.00122642 0.000482046 0.0015938">
                    <inertial pos="-0.00616772 -0.0113216 -0.0117053" quat="0.0101009 0.654919 0.00744298 0.755595" mass="1.19423" diaginertia="0.0126163 0.000543691 0.0067773"/>
                    <joint name="Left_Ankle_Roll" pos="0 0 0" axis="-0.999014 -0.0347825 -0.0275876" range="-0.33033 0.167083" armature="0.00377652" damping="0.00363289" frictionloss="0.0830257"/>
                    <geom name="//unnamed_geom_42" class="visual" mesh="left_foot_link"/>
                    <geom name="left_foot" class="foot" size="0.101135 0.0669351 0.020507" pos="0.0143885 0 -0.0194145"/>
                    <geom name="//unnamed_geom_44" class="reward_collision_sphere" size="0.0607188" pos="0.0143885 0 -0.0194145"/>
                    <geom name="//unnamed_geom_45" class="reward_collision_sphere" size="0.0350301" pos="0.136691 -0.0177068 -0.0194145"/>
                    <geom name="//unnamed_geom_46" class="reward_collision_sphere" size="0.0350301" pos="-0.100719 -0.0177068 -0.0194145"/>
                    <site name="left_foot" class="foot" pos="0.0143885 0 -0.0194145" size="0.0116767"/>
                  </body>
                </body>
              </body>
            </body>
          </body>
        </body>
        <body name="Hip_Pitch_Right" pos="-0.011865 -0.0870909 0.0107291" quat="1 0.000183317 -0.000447472 -1.67694e-05">
          <inertial pos="0.0132998 0.00221605 -0.0234646" quat="0.980474 -0.193354 0.0356021 -0.00427425" mass="1.91981" diaginertia="0.0120918 0.000426617 0.00495396"/>
          <joint name="Right_Hip_Pitch" pos="0 0 0" axis="-0.00109495 -0.999693 0.0247342" stiffness="0.0369498" range="-1.64725 1.96833" armature="0.00302693" damping="0.00928211" frictionloss="0.160851"/>
          <geom name="//unnamed_geom_47" class="visual" rgba="0.76 0.76 0.76 1" mesh="Hip_Pitch_Right"/>
          <body name="Hip_Roll_Right" pos="-0.00331179 0.00814908 -0.0233564" quat="1 0.000659347 -0.000271003 0.000679269">
            <inertial pos="0.000919469 0.0137207 -0.0589958" quat="0.739897 -0.00596289 0.0361421 0.671722" mass="0.702353" diaginertia="0.0124435 0.000487025 0.00225321"/>
            <joint name="Right_Hip_Roll" pos="0 0 0" axis="-0.999925 0.0106178 0.00606252" stiffness="0.0239577" range="-0.166648 1.53975" armature="0.0116012" damping="0" frictionloss="0.180525"/>
            <geom name="//unnamed_geom_48" class="visual" mesh="Hip_Roll_Right"/>
            <geom name="//unnamed_geom_49" class="reward_collision_sphere" size="0.0642218"/>
            <body name="Hip_Yaw_Right" pos="-0.0116561 -0.00530331 -0.109052" quat="0.999987 -0.00212647 -0.00138622 -0.00450677">
              <inertial pos="-0.0111899 0.0150661 -0.122592" quat="0.721836 -0.0544893 -0.0181825 0.689676" mass="3.68691" diaginertia="0.187717 0.00808438 0.011899"/>
              <joint name="Right_Hip_Yaw" pos="0 0 0" axis="0.0283436 -0.0321591 -0.999081" range="-0.839228 0.768657" armature="0.0136986" damping="0" frictionloss="0.117947"/>
              <geom name="//unnamed_geom_50" class="visual" mesh="Hip_Yaw_Right"/>
              <geom name="//unnamed_geom_51" class="collision" size="0.0583835 0.0934136" type="cylinder"/>
              <body name="Shank_Right" pos="-0.0208897 -0.00827838 -0.177845" quat="1 0.000286382 0.000516136 -0.000594952">
                <inertial pos="-0.00919367 -0.0013259 -0.151862" quat="0.998826 0.00420953 -0.0147875 -0.0459293" mass="3.25535" diaginertia="0.296492 0.0116016 0.0081099"/>
                <joint name="Right_Knee_Pitch" pos="0 0 0" axis="-0.00244672 -0.999912 0.0130745" stiffness="0.0603777" range="-2.49587 -0.133664" armature="0.0120611" damping="0" frictionloss="0.115318"/>
                <geom name="//unnamed_geom_52" class="visual" mesh="Shank_Right"/>
                <geom name="//unnamed_geom_53" class="collision" size="0.0583835 0.0875752" pos="0 0 -0.155316" type="cylinder"/>
                <geom name="//unnamed_geom_54" class="reward_collision_sphere" size="0.0758985"/>
                <body name="Ankle_Cross_Right" pos="0.00597395 -0.000427976 -0.365189" quat="0.999983 -0.00330091 -0.00467054 -0.000782528">
                  <inertial pos="-0.00114478 0.000335777 0.00322117" quat="0.438184 0.602251 0.534901 0.39896" mass="0.134451" diaginertia="0.000245895 6.92062e-06 5.6059e-05"/>
                  <joint name="Right_Ankle_Pitch" pos="0 0 0" axis="-0.0563911 -0.998351 -0.010778" stiffness="0.0578755" range="-0.55103 0.748495" armature="0.0125861" damping="0.0592368" frictionloss="0.182641"/>
                  <geom name="//unnamed_geom_55" class="visual" mesh="Ankle_Cross_Right"/>
                  <body name="right_foot_link" pos="0.000839738 -0.00108116 -0.019681" quat="0.999995 0.00301 0.000713358 0.000578897">
                    <inertial pos="0.01493 0.0100682 -0.0104584" quat="-0.0465865 0.634567 0.00532026 0.771445" mass="1.07343" diaginertia="0.0177102 0.000680021 0.00942544"/>
                    <joint name="Right_Ankle_Roll" pos="0 0 0" axis="-0.999976 -0.00556222 0.00421871" range="-0.365788 0.413293" armature="0.00720301" damping="0" frictionloss="0.114666"/>
                    <geom name="//unnamed_geom_56" class="visual" mesh="right_foot_link"/>
                    <geom name="right_foot" class="foot" size="0.0911693 0.0412742 0.0166797" pos="0.0143885 0 -0.0194145"/>
                    <geom name="//unnamed_geom_58" class="reward_collision_sphere" size="0.0467068"/>
                    <geom name="//unnamed_geom_59" class="reward_collision_sphere" size="0.0350301" pos="0.0143885 0 -0.0194145"/>
                    <geom name="//unnamed_geom_60" class="reward_collision_sphere" size="0.0350301" pos="0.136691 0.0177068 -0.0194145"/>
                    <geom name="//unnamed_geom_61" class="reward_collision_sphere" size="0.0350301" pos="-0.100719 0.0177068 -0.0194145"/>
                    <site name="right_foot" class="foot" pos="0.0143885 0 -0.0194145" size="0.0116767"/>
                  </body>
                </body>
              </body>
            </body>
          </body>
        </body>
      </body>
    </body>
  </worldbody>

  <contact>
    <pair class="/" geom1="floor" geom2="left_foot" name="//unnamed_contact_0"/>
    <pair class="/" geom1="floor" geom2="right_foot" name="//unnamed_contact_1"/>
  </contact>

  <actuator>
    <general name="AAHead_yaw" class="/" joint="AAHead_yaw" forcerange="-5.16305 5.16305" gainprm="27.5097" biasprm="0 -27.5097 -0.856318"/>
    <general name="Head_pitch" class="/" joint="Head_pitch" forcerange="-5.00667 5.00667" gainprm="27.5097" biasprm="0 -27.5097 -0.856318"/>
    <general name="Left_Shoulder_Pitch" class="/" joint="Left_Shoulder_Pitch" forcerange="-25.9828 25.9828" gainprm="27.5097" biasprm="0 -27.5097 -0.856318"/>
    <general name="Left_Shoulder_Roll" class="/" joint="Left_Shoulder_Roll" forcerange="-18.7427 18.7427" gainprm="27.5097" biasprm="0 -27.5097 -0.856318"/>
    <general name="Left_Elbow_Pitch" class="/" joint="Left_Elbow_Pitch" forcerange="-10.6308 10.6308" gainprm="27.5097" biasprm="0 -27.5097 -0.856318"/>
    <general name="Left_Elbow_Yaw" class="/" joint="Left_Elbow_Yaw" forcerange="-28.5216 28.5216" gainprm="27.5097" biasprm="0 -27.5097 -0.856318"/>
    <general name="Right_Shoulder_Pitch" class="/" joint="Right_Shoulder_Pitch" forcerange="-32.2401 32.2401" gainprm="27.5097" biasprm="0 -27.5097 -0.856318"/>
    <general name="Right_Shoulder_Roll" class="/" joint="Right_Shoulder_Roll" forcerange="-20.9928 20.9928" gainprm="27.5097" biasprm="0 -27.5097 -0.856318"/>
    <general name="Right_Elbow_Pitch" class="/" joint="Right_Elbow_Pitch" forcerange="-10.3727 10.3727" gainprm="27.5097" biasprm="0 -27.5097 -0.856318"/>
    <general name="Right_Elbow_Yaw" class="/" joint="Right_Elbow_Yaw" forcerange="-15.9061 15.9061" gainprm="27.5097" biasprm="0 -27.5097 -0.856318"/>
    <general name="Waist" class="/" joint="Waist" forcerange="-40.4153 40.4153" gainprm="27.5097" biasprm="0 -27.5097 -0.856318"/>
    <general name="Left_Hip_Pitch" class="/" joint="Left_Hip_Pitch" forcerange="-64.0037 64.0037" gainprm="27.5097" biasprm="0 -27.5097 -0.856318"/>
    <general name="Left_Hip_Roll" class="/" joint="Left_Hip_Roll" forcerange="-18.3044 18.3044" gainprm="27.5097" biasprm="0 -27.5097 -0.856318"/>
    <general name="Left_Hip_Yaw" class="/" joint="Left_Hip_Yaw" forcerange="-54.5877 54.5877" gainprm="27.5097" biasprm="0 -27.5097 -0.856318"/>
    <general name="Left_Knee_Pitch" class="/" joint="Left_Knee_Pitch" forcerange="-41.2988 41.2988" gainprm="27.5097" biasprm="0 -27.5097 -0.856318"/>
    <general name="Left_Ankle_Pitch" class="/" joint="Left_Ankle_Pitch" forcerange="-37.2957 37.2957" gainprm="27.5097" biasprm="0 -27.5097 -0.856318"/>
    <general name="Left_Ankle_Roll" class="/" joint="Left_Ankle_Roll" forcerange="-18.2753 18.2753" gainprm="27.5097" biasprm="0 -27.5097 -0.856318"/>
    <general name="Right_Hip_Pitch" class="/" joint="Right_Hip_Pitch" forcerange="-55.2634 55.2634" gainprm="27.5097" biasprm="0 -27.5097 -0.856318"/>
    <general name="Right_Hip_Roll" class="/" joint="Right_Hip_Roll" forcerange="-46.0238 46.0238" gainprm="27.5097" biasprm="0 -27.5097 -0.856318"/>
    <general name="Right_Hip_Yaw" class="/" joint="Right_Hip_Yaw" forcerange="-45.9805 45.9805" gainprm="27.5097" biasprm="0 -27.5097 -0.856318"/>
    <general name="Right_Knee_Pitch" class="/" joint="Right_Knee_Pitch" forcerange="-38.6661 38.6661" gainprm="27.5097" biasprm="0 -27.5097 -0.856318"/>
    <general name="Right_Ankle_Pitch" class="/" joint="Right_Ankle_Pitch" forcerange="-15.6606 15.6606" gainprm="27.5097" biasprm="0 -27.5097 -0.856318"/>
    <general name="Right_Ankle_Roll" class="/" joint="Right_Ankle_Roll" forcerange="-26.4365 26.4365" gainprm="27.5097" biasprm="0 -27.5097 -0.856318"/>
  </actuator>

  <sensor>
    <gyro site="imu" name="imu_angular_velocity"/>
    <velocimeter site="imu" name="imu_linear_velocity"/>
    <framelinvel objtype="site" objname="left_foot" name="left_foot_global_linear_velocity"/>
    <framelinvel objtype="site" objname="right_foot" name="right_foot_global_linear_velocity"/>
  </sensor>

  <keyframe>
    <key name="home" qpos="0 0 0.6385 1 0 0 0 0 0 0 1.4 0 -0.4 0 -1.4 0 0.4 0 -0.4 0 0 0.8 -0.4 0 0.4 0 0 -0.8 0.4 0"/>
  </keyframe>
</mujoco>
