<mujoco model="T1">
  <compiler angle="radian" assetdir="assets" balanceinertia="true" inertiafromgeom="false"/>

  <option timestep="0.005" density="1.2" viscosity="2e-05"/>

  <size nkey="1"/>

  <visual>
    <quality shadowsize="8192"/>
    <map shadowclip="0.5"/>
  </visual>

  <default>
    <default class="/">
      <joint armature="0.01" damping="0.01" frictionloss="0.1"/>
      <geom contype="0" conaffinity="0" group="1" solref="-1000 -80"/>
      <site size="0.01 0.005 0.005" group="5"/>
      <general forcelimited="true" biastype="affine" gainprm="25" biasprm="0 -25 -0.6"/>
      <default class="t1">
        <geom rgba="0.25 0.25 0.25 1"/>
        <default class="visual">
          <geom type="mesh" group="2"/>
        </default>
        <default class="collision">
          <geom group="3"/>
        </default>
        <default class="foot">
          <geom size="0.1115 0.05 0.015" type="box" condim="6" group="4" priority="1" solimp="0.015 1 0.015"/>
        </default>
        <default class="reward_collision_sphere">
          <geom group="5" rgba="1 0 0 1"/>
        </default>
      </default>
    </default>
  </default>

  <asset>
    <texture type="skybox" colorspace="auto" name="//unnamed_texture_0" builtin="gradient" rgb1="0.95 0.95 0.95" rgb2="0.95 0.95 0.95" width="100" height="600"/>
    <texture type="2d" colorspace="auto" name="texplane" builtin="checker" rgb1="0.345 0.575 0.748" rgb2="0.345 0.575 0.748" markrgb="1 1 1" width="512" height="512"/>
    <material name="MatPlane" class="/" texture="texplane" texuniform="true" texrepeat="2 2" specular="0.9"/>
    <mesh name="Trunk" class="/" file="Trunk.stl"/>
    <mesh name="H1" class="/" file="H1.stl"/>
    <mesh name="H2" class="/" file="H2.stl"/>
    <mesh name="AL1" class="/" file="AL1.stl"/>
    <mesh name="AL2" class="/" file="AL2.stl"/>
    <mesh name="AL3" class="/" file="AL3.stl"/>
    <mesh name="left_hand_link" class="/" file="left_hand_link.stl"/>
    <mesh name="AR1" class="/" file="AR1.stl"/>
    <mesh name="AR2" class="/" file="AR2.stl"/>
    <mesh name="AR3" class="/" file="AR3.stl"/>
    <mesh name="right_hand_link" class="/" file="right_hand_link.stl"/>
    <mesh name="Waist" class="/" file="Waist.stl"/>
    <mesh name="Hip_Pitch_Left" class="/" file="Hip_Pitch_Left.stl"/>
    <mesh name="Hip_Roll_Left" class="/" file="Hip_Roll_Left.stl"/>
    <mesh name="Hip_Yaw_Left" class="/" file="Hip_Yaw_Left.stl"/>
    <mesh name="Shank_Left" class="/" file="Shank_Left.stl"/>
    <mesh name="Ankle_Cross_Left" class="/" file="Ankle_Cross_Left.stl"/>
    <mesh name="left_foot_link" class="/" file="left_foot_link.stl"/>
    <mesh name="Hip_Pitch_Right" class="/" file="Hip_Pitch_Right.stl"/>
    <mesh name="Hip_Roll_Right" class="/" file="Hip_Roll_Right.stl"/>
    <mesh name="Hip_Yaw_Right" class="/" file="Hip_Yaw_Right.stl"/>
    <mesh name="Shank_Right" class="/" file="Shank_Right.stl"/>
    <mesh name="Ankle_Cross_Right" class="/" file="Ankle_Cross_Right.stl"/>
    <mesh name="right_foot_link" class="/" file="right_foot_link.stl"/>
  </asset>

  <worldbody>
    <geom name="floor" class="/" size="100 100 0.125" type="plane" group="0" material="MatPlane"/>
    <light name="toplight_shadow" class="/" pos="0 0 5" dir="0.0990148 0.0990148 -0.990148" type="directional" ambient="0.04 0.04 0.04" diffuse="0.55 0.55 0.55" specular="0.12 0.12 0.12"/>
    <light name="toplight_fill" class="/" pos="0 0 5" dir="0.0990148 0.0990148 -0.990148" type="directional" castshadow="false" ambient="0.04 0.04 0.04" diffuse="0.3 0.3 0.3" specular="0.08 0.08 0.08"/>
    <body name="trunk" childclass="t1" pos="0.000119055 -0.000148834 0.00273499" quat="1 -7.68458e-05 -0.00010965 -0.00010007">
      <inertial pos="0.0491248 -0.00374317 0.118459" quat="0.999851 0.0119358 -0.0102828 0.00709334" mass="7.9666" diaginertia="0.0486441 0.00870027 0.10292"/>
      <joint name="//unnamed_joint_0" type="free" armature="0" damping="0" frictionloss="0"/>
      <geom name="//unnamed_geom_1" class="visual" rgba="0.76 0.76 0.76 1" mesh="Trunk"/>
      <geom name="//unnamed_geom_2" class="collision" size="0.066773 0.0890306 0.133546" pos="0.0528128 0 0.136368" type="box"/>
      <geom name="//unnamed_geom_3" class="reward_collision_sphere" size="0.102385" pos="0.0528128 0 0.11364"/>
      <geom name="//unnamed_geom_4" class="reward_collision_sphere" size="0.0133546" pos="0.0528128 0.055616 0"/>
      <geom name="//unnamed_geom_5" class="reward_collision_sphere" size="0.0133546" pos="0.0528128 -0.055616 0"/>
      <geom name="//unnamed_geom_6" class="reward_collision_sphere" size="0.0133546" pos="0.0528128 0.0700108 0.204552"/>
      <geom name="//unnamed_geom_7" class="reward_collision_sphere" size="0.0133546" pos="0.0528128 -0.0700108 0.204552"/>
      <site name="imu" pos="-0.000600985 0.011492 -0.0101551" size="0.00890306"/>
      <camera name="track" pos="0 -1.30861 0" quat="0.707107 0.707107 0 0" mode="trackcom"/>
      <camera name="ego_camera" pos="0.107386 0 0.477287" quat="-0.5 -0.5 0.5 0.5"/>
      <body name="H1" pos="0.0540386 -0.00328659 0.274625" quat="0.999999 -0.000906873 -0.000751981 -0.000133315">
        <inertial pos="-0.0010558 -0.00076531 0.0672602" quat="0.764022 -0.0123996 0.00857355 0.645014" mass="0.301752" diaginertia="0.000122038 2.73062e-05 0.000277216"/>
        <joint name="AAHead_yaw" pos="0 0 0" axis="-0.00239244 -0.00817617 0.999964" stiffness="0.000357124" range="-1.52867 1.59927" armature="0.00925569" damping="0" frictionloss="0.0763902"/>
        <geom name="//unnamed_geom_8" class="visual" mesh="H1"/>
        <body name="H2" pos="-0.000367247 -0.00115399 0.0695859" quat="1 -8.38195e-05 -0.000253292 0.000367195">
          <inertial pos="0.0039259 0.00307497 0.114766" quat="0.990158 0.0926235 -0.0711777 -0.0770863" mass="0.445383" diaginertia="0.00107262 0.000226261 0.00328799"/>
          <joint name="Head_pitch" pos="0 0 0" axis="-0.0101557 -0.999909 -0.00883241" range="-1.2169 0.350925" armature="0.00856411" damping="0.00764203" frictionloss="0.087291"/>
          <geom name="//unnamed_geom_9" class="visual" mesh="H2"/>
          <geom name="//unnamed_geom_10" class="collision" size="0.0712245" pos="0.00880214 0 0.125004"/>
          <geom name="//unnamed_geom_11" class="reward_collision_sphere" size="0.0801276" pos="0.0176043 0 0.11364"/>
        </body>
      </body>
      <body name="AL1" pos="0.0496378 0.0687623 0.246423" quat="1 0.000417004 0.000326935 0.000298259">
        <inertial pos="0.000523913 0.0265598 -0.000128778" quat="0.506252 0.490836 -0.499524 0.503254" mass="0.356305" diaginertia="0.000676034 0.000150302 0.000541279"/>
        <joint name="Left_Shoulder_Pitch" pos="0 0 0" axis="0.0137472 0.99989 0.00564736" range="-3.27266 1.22837" armature="0.00750134" damping="0" frictionloss="0.078558"/>
        <geom name="//unnamed_geom_12" class="visual" rgba="0.76 0.76 0.76 1" mesh="AL1"/>
        <body name="AL2" pos="-0.000757528 0.0298575 6.69408e-05" quat="1 0.000555125 -0.000682831 0.000437986">
          <inertial pos="0.00464846 0.0274719 -0.000345235" quat="0.486091 0.513541 -0.497373 0.502604" mass="0.110639" diaginertia="0.000206382 4.08264e-05 0.000324364"/>
          <joint name="Left_Shoulder_Roll" pos="0 0 0" axis="-0.999978 0.00565691 -0.00348363" range="-1.5659 1.73645" armature="0.0101465" damping="0.0209966" frictionloss="0.0928547"/>
          <geom name="//unnamed_geom_13" class="visual" mesh="AL2"/>
          <body name="AL3" pos="-0.00215258 0.0374575 0.000112129" quat="0.999999 0.000446939 0.000508377 -0.00086965">
            <inertial pos="0.00164039 0.0556659 0.00204193" quat="0.705903 0.708289 0.000673254 -0.00511597" mass="0.731207" diaginertia="0.00680559 0.00157193 0.00117851"/>
            <joint name="Left_Elbow_Pitch" pos="0 0 0" axis="0.00531196 -0.999985 0.00121106" stiffness="0.00996632" range="-2.25233 2.29648" armature="0.00999463" damping="0.0104657" frictionloss="0.0950811"/>
            <geom name="//unnamed_geom_14" class="visual" mesh="AL3"/>
            <geom name="//unnamed_geom_15" class="collision" size="0.0267092 0.066773" pos="0 0.0327153 0" quat="0.707105 0.707108 0 0" type="cylinder"/>
            <geom name="//unnamed_geom_16" class="reward_collision_sphere" size="0.032051"/>
            <body name="left_hand_link" pos="-0.00228861 0.098244 -0.0016003" quat="1 -0.000250157 -0.000512324 -0.000462655">
              <inertial pos="0.000528449 0.0745071 -0.000540782" quat="0.707499 0.70671 0.000103548 -0.00245963" mass="0.224796" diaginertia="0.00442782 0.00101382 0.000397664"/>
              <joint name="Left_Elbow_Yaw" pos="0 0 0" axis="-0.00440528 -0.012259 0.999915" stiffness="0.00751827" range="-2.4914 0.0282156" armature="0.00784681" damping="0.00135378" frictionloss="0.100597"/>
              <geom name="//unnamed_geom_17" class="visual" mesh="left_hand_link"/>
              <geom name="//unnamed_geom_18" class="collision" size="0.0267092 0.0779018" pos="0 0.0850598 0" quat="0.707105 0.707108 0 0" type="cylinder"/>
              <geom name="//unnamed_geom_19" class="reward_collision_sphere" size="0.0445153"/>
              <geom name="//unnamed_geom_20" class="reward_collision_sphere" size="0.0311607" pos="0 0.0719737 0"/>
              <geom name="//unnamed_geom_21" class="reward_collision_sphere" size="0.0311607" pos="0 0.140676 0"/>
            </body>
          </body>
        </body>
      </body>
      <body name="AR1" pos="0.0496607 -0.0662836 0.246442" quat="1 -4.76145e-05 0.000421481 -0.000128264">
        <inertial pos="-0.000314082 -0.0319334 -0.000810231" quat="0.502275 0.495798 -0.502159 0.49974" mass="0.385949" diaginertia="0.000725267 0.000149892 0.000557772"/>
        <joint name="Right_Shoulder_Pitch" pos="0 0 0" axis="-0.00290041 -0.99998 0.00558393" range="-1.22733 3.34759" armature="0.0089223" damping="0.0183212" frictionloss="0.0815449"/>
        <geom name="//unnamed_geom_22" class="visual" rgba="0.76 0.76 0.76 1" mesh="AR1"/>
        <body name="AR2" pos="0.000941954 -0.0324923 0.000372975" quat="1 -0.000161891 -3.51744e-05 -4.80959e-05">
          <inertial pos="0.00617283 -0.0243617 -0.00053612" quat="0.506148 0.48725 -0.514072 0.492069" mass="0.11822" diaginertia="0.000215476 4.10185e-05 0.000346801"/>
          <joint name="Right_Shoulder_Roll" pos="0 0 0" axis="-0.999961 -0.000809183 -0.00882851" range="-1.73254 1.62687" armature="0.00905993" damping="0" frictionloss="0.1005"/>
          <geom name="//unnamed_geom_23" class="visual" mesh="AR2"/>
          <body name="AR3" pos="-0.00251165 -0.0397158 -0.00334696" quat="0.999999 0.000447004 -0.00111666 0.000229238">
            <inertial pos="-0.000925541 -0.053236 -0.0011526" quat="0.701751 0.712383 -0.000446581 -0.00749572" mass="0.749723" diaginertia="0.00684859 0.00154105 0.00117787"/>
            <joint name="Right_Elbow_Pitch" pos="0 0 0" axis="0.00292263 0.999994 0.00197132" stiffness="0.000746684" range="-2.32539 2.22055" armature="0.0092259" damping="0.00631875" frictionloss="0.086944"/>
            <geom name="//unnamed_geom_24" class="visual" mesh="AR3"/>
            <geom name="//unnamed_geom_25" class="collision" size="0.0267092 0.066773" pos="0 -0.0327153 0" quat="0.707105 0.707108 0 0" type="cylinder"/>
            <geom name="//unnamed_geom_26" class="reward_collision_sphere" size="0.032051"/>
            <body name="right_hand_link" pos="-0.000294251 -0.0965361 0.000530995" quat="1 5.81516e-05 6.01391e-05 -4.31094e-05">
              <inertial pos="-0.000250903 -0.0718014 -0.000570514" quat="0.710205 0.703874 -0.00259688 0.0127905" mass="0.219026" diaginertia="0.0041174 0.000947327 0.000392392"/>
              <joint name="Right_Elbow_Yaw" pos="0 0 0" axis="-0.00793736 -0.013842 0.999873" range="0.0358783 2.4848" armature="0.00906833" damping="0.00695386" frictionloss="0.0936032"/>
              <geom name="//unnamed_geom_27" class="visual" mesh="right_hand_link"/>
              <geom name="//unnamed_geom_28" class="collision" size="0.0267092 0.0779018" pos="0 -0.0850598 0" quat="0.707105 0.707108 0 0" type="cylinder"/>
              <geom name="//unnamed_geom_29" class="reward_collision_sphere" size="0.0445153"/>
              <geom name="//unnamed_geom_30" class="reward_collision_sphere" size="0.0311607" pos="0 -0.0719737 0"/>
              <geom name="//unnamed_geom_31" class="reward_collision_sphere" size="0.0311607" pos="0 -0.140676 0"/>
            </body>
          </body>
        </body>
      </body>
      <body name="Waist" pos="0.0546745 -0.001785 -0.130731" quat="0.999999 0.00143427 0.000845634 -1.95188e-05">
        <inertial pos="0.000817936 -0.0035649 0.00791717" quat="0.983568 0.000351377 -0.180519 0.00259495" mass="1.86354" diaginertia="0.00283525 0.000627483 0.00869422"/>
        <joint name="Waist" pos="0 0 0" axis="-0.00934874 -0.0123726 0.99988" stiffness="0.00808363" range="-1.56431 1.5732" armature="0.00946356" damping="0" frictionloss="0.0811551"/>
        <geom name="//unnamed_geom_32" class="visual" mesh="Waist"/>
        <body name="Hip_Pitch_Left" pos="0.00387655 0.0679987 0.00228165" quat="0.999999 -0.00102437 -0.00091118 0.00050647">
          <inertial pos="-8.88992e-05 -0.00629055 -0.0209409" quat="0.975749 0.218336 0.00884308 0.0128128" mass="0.718337" diaginertia="0.000922727 0.000172533 0.00223208"/>
          <joint name="Left_Hip_Pitch" pos="0 0 0" axis="-0.00330446 0.99996 -0.00825493" range="-1.78791 1.59677" armature="0.00841217" damping="0.00611171" frictionloss="0.0976401"/>
          <geom name="//unnamed_geom_33" class="visual" rgba="0.76 0.76 0.76 1" mesh="Hip_Pitch_Left"/>
          <body name="Hip_Roll_Left" pos="0.00194439 0.00231154 -0.0202223" quat="1 -1.70918e-05 -5.56688e-05 0.000416069">
            <inertial pos="-0.000969811 -0.00290637 -0.060342" quat="0.707113 -0.00707361 -0.000179611 0.707065" mass="0.268026" diaginertia="0.000891378 0.000180486 0.000957523"/>
            <joint name="Left_Hip_Roll" pos="0 0 0" axis="-0.999991 -0.0042523 -3.04755e-05" stiffness="0.00219151" range="-1.62352 0.241192" armature="0.00977755" damping="0.0111374" frictionloss="0.0937017"/>
            <geom name="//unnamed_geom_34" class="visual" mesh="Hip_Roll_Left"/>
            <geom name="//unnamed_geom_35" class="reward_collision_sphere" size="0.0489668"/>
            <body name="Hip_Yaw_Left" pos="0.000461602 0.00224748 -0.0911879" quat="0.999999 -0.000177122 -0.000904627 0.000468313">
              <inertial pos="-0.00617429 -0.000457732 -0.104117" quat="0.698236 -0.0338806 -0.031015 0.714393" mass="1.53717" diaginertia="0.0130304 0.00300924 0.00504662"/>
              <joint name="Left_Hip_Yaw" pos="0 0 0" axis="-0.00791626 0.00704749 -0.999944" stiffness="0.00186014" range="-0.997855 0.971866" armature="0.00858072" damping="0.00643009" frictionloss="0.0999338"/>
              <geom name="//unnamed_geom_36" class="visual" mesh="Hip_Yaw_Left"/>
              <geom name="//unnamed_geom_37" class="collision" size="0.0445153 0.0712245" type="cylinder"/>
              <body name="Shank_Left" pos="-0.00856075 0.00123657 -0.154375" quat="1 0.000161518 4.18938e-05 0.000291326">
                <inertial pos="-0.00277525 -0.00229387 -0.14221" quat="0.997566 0.00143734 -0.0238786 0.0654993" mass="1.18985" diaginertia="0.0181227 0.00401537 0.00354103"/>
                <joint name="Left_Knee_Pitch" pos="0 0 0" axis="7.14244e-05 0.999982 -0.00605917" stiffness="0.00865954" range="0.0520896 2.38603" armature="0.00877435" damping="0.0127962" frictionloss="0.0849136"/>
                <geom name="//unnamed_geom_38" class="visual" mesh="Shank_Left"/>
                <geom name="//unnamed_geom_39" class="collision" size="0.0445153 0.066773" pos="0 0 -0.136368" type="cylinder"/>
                <geom name="//unnamed_geom_40" class="reward_collision_sphere" size="0.0578699"/>
                <body name="Ankle_Cross_Left" pos="-0.00085034 0.000752316 -0.317044" quat="0.999999 -9.67716e-05 -0.00129373 -0.000720101">
                  <inertial pos="-0.000374705 0.00103699 -0.0117432" quat="0.44373 0.551093 0.550745 0.44281" mass="0.0518366" diaginertia="1.54751e-05 2.93491e-06 2.11099e-05"/>
                  <joint name="Left_Ankle_Pitch" pos="0 0 0" axis="-0.00845699 0.999875 0.0133739" stiffness="0.00932825" range="-0.897579 0.378833" armature="0.00862026" damping="0.0217969" frictionloss="0.0764966"/>
                  <geom name="//unnamed_geom_41" class="visual" mesh="Ankle_Cross_Left"/>
                  <body name="left_foot_link" pos="-0.00153519 0.00448136 -0.0156015" quat="1 -2.20349e-05 -5.95847e-05 -3.3818e-05">
                    <inertial pos="0.00137067 0.00262787 -0.0101938" quat="0.00994202 0.628526 0.00133675 0.777724" mass="0.477577" diaginertia="0.00145848 0.000299377 0.0043252"/>
                    <joint name="Left_Ankle_Roll" pos="0 0 0" axis="-0.999871 -0.00322534 0.015718" stiffness="0.00300173" range="-0.473349 0.475854" armature="0.00936447" damping="0.00980008" frictionloss="0.0962791"/>
                    <geom name="//unnamed_geom_42" class="visual" mesh="left_foot_link"/>
                    <geom name="left_foot" class="foot" size="0.103605 0.0523066 0.0130891" pos="0.00880214 0 -0.017046"/>
                    <geom name="//unnamed_geom_44" class="reward_collision_sphere" size="0.0462959" pos="0.00880214 0 -0.017046"/>
                    <geom name="//unnamed_geom_45" class="reward_collision_sphere" size="0.0267092" pos="0.0836203 -0.015049 -0.017046"/>
                    <geom name="//unnamed_geom_46" class="reward_collision_sphere" size="0.0267092" pos="-0.061615 -0.015049 -0.017046"/>
                    <site name="left_foot" class="foot" pos="0.00880214 0 -0.017046" size="0.00890306"/>
                  </body>
                </body>
              </body>
            </body>
          </body>
        </body>
        <body name="Hip_Pitch_Right" pos="0.0024872 -0.0686559 -0.00229981" quat="1 -0.000116601 -2.44689e-05 1.57934e-05">
          <inertial pos="-0.00178995 0.00469515 -0.0201142" quat="0.973187 -0.228803 0.0155832 -0.0177033" mass="0.680243" diaginertia="0.000921367 0.000169333 0.00229928"/>
          <joint name="Right_Hip_Pitch" pos="0 0 0" axis="-0.00363008 -0.999955 -0.00871291" range="-1.56516 1.74162" armature="0.00914143" damping="0.00478925" frictionloss="0.0778819"/>
          <geom name="//unnamed_geom_47" class="visual" rgba="0.76 0.76 0.76 1" mesh="Hip_Pitch_Right"/>
          <body name="Hip_Roll_Right" pos="-0.00043868 -0.0024832 -0.023443" quat="1 -6.74314e-05 -0.000184142 -0.000181485">
            <inertial pos="0.00100647 -0.00206183 -0.0637701" quat="0.701203 0.000370822 -0.00377813 0.712952" mass="0.268191" diaginertia="0.000903286 0.000178785 0.000967376"/>
            <joint name="Right_Hip_Roll" pos="0 0 0" axis="-0.999988 -0.00234842 -0.00433064" range="-0.179039 1.57124" armature="0.00879544" damping="0.0127186" frictionloss="0.0769709"/>
            <geom name="//unnamed_geom_48" class="visual" mesh="Hip_Roll_Right"/>
            <geom name="//unnamed_geom_49" class="reward_collision_sphere" size="0.0489668"/>
            <body name="Hip_Yaw_Right" pos="0.00312704 0.00175279 -0.0913117" quat="0.999999 0.000229504 -0.0013839 0.000273574">
              <inertial pos="-0.00624629 -0.0012961 -0.099128" quat="0.712491 -0.0282345 -0.0412744 0.699897" mass="1.56814" diaginertia="0.0133863 0.00298817 0.00481467"/>
              <joint name="Right_Hip_Yaw" pos="0 0 0" axis="-0.00234612 -0.0171266 -0.999851" stiffness="0.00197229" range="-1.05949 1.05589" armature="0.00884447" damping="0.0177695" frictionloss="0.0893774"/>
              <geom name="//unnamed_geom_50" class="visual" mesh="Hip_Yaw_Right"/>
              <geom name="//unnamed_geom_51" class="collision" size="0.0445153 0.0712245" type="cylinder"/>
              <body name="Shank_Right" pos="-0.0129383 0.0022008 -0.153203" quat="1 0.00022246 -0.000536295 -0.000133485">
                <inertial pos="-0.00588355 -0.000705634 -0.141893" quat="0.999265 -0.000850431 -0.0234906 -0.030285" mass="1.22699" diaginertia="0.0178388 0.00396508 0.00360477"/>
                <joint name="Right_Knee_Pitch" pos="0 0 0" axis="0.000618043 -0.999999 -0.00106243" range="-2.28961 0.0380133" armature="0.00895686" damping="0.0136813" frictionloss="0.0870771"/>
                <geom name="//unnamed_geom_52" class="visual" mesh="Shank_Right"/>
                <geom name="//unnamed_geom_53" class="collision" size="0.0445153 0.066773" pos="0 0 -0.136368" type="cylinder"/>
                <geom name="//unnamed_geom_54" class="reward_collision_sphere" size="0.0578699"/>
                <body name="Ankle_Cross_Right" pos="-0.00094833 0.000887075 -0.317211" quat="0.999999 -0.000600793 0.00114455 -6.48745e-05">
                  <inertial pos="-0.00384792 0.0005224 -0.0108659" quat="0.435822 0.553722 0.552906 0.444687" mass="0.0501817" diaginertia="1.47028e-05 3.09112e-06 2.04866e-05"/>
                  <joint name="Right_Ankle_Pitch" pos="0 0 0" axis="-0.00640783 -0.999932 -0.00978724" range="-0.292004 0.904215" armature="0.00887223" damping="0" frictionloss="0.077322"/>
                  <geom name="//unnamed_geom_55" class="visual" mesh="Ankle_Cross_Right"/>
                  <body name="right_foot_link" pos="0.00178572 -0.00190518 -0.0121608" quat="1 -0.000817041 -0.000438245 0.000213892">
                    <inertial pos="-0.000962183 -0.00307366 -0.0101271" quat="-0.00972188 0.621095 0.010188 0.783609" mass="0.487745" diaginertia="0.0014165 0.000283245 0.00396712"/>
                    <joint name="Right_Ankle_Roll" pos="0 0 0" axis="-0.999999 -0.00131498 3.25281e-05" stiffness="0.00865137" range="-0.440557 0.418392" armature="0.0100064" damping="0.0138248" frictionloss="0.0867618"/>
                    <geom name="//unnamed_geom_56" class="visual" mesh="right_foot_link"/>
                    <geom name="right_foot" class="foot" size="0.101179 0.0463494 0.0135767" pos="0.00880214 0 -0.017046"/>
                    <geom name="//unnamed_geom_58" class="reward_collision_sphere" size="0.0356122"/>
                    <geom name="//unnamed_geom_59" class="reward_collision_sphere" size="0.0267092" pos="0.00880214 0 -0.017046"/>
                    <geom name="//unnamed_geom_60" class="reward_collision_sphere" size="0.0267092" pos="0.0836203 0.015049 -0.017046"/>
                    <geom name="//unnamed_geom_61" class="reward_collision_sphere" size="0.0267092" pos="-0.061615 0.015049 -0.017046"/>
                    <site name="right_foot" class="foot" pos="0.00880214 0 -0.017046" size="0.00890306"/>
                  </body>
                </body>
              </body>
            </body>
          </body>
        </body>
      </body>
    </body>
  </worldbody>

  <contact>
    <pair class="/" geom1="floor" geom2="left_foot" name="//unnamed_contact_0"/>
    <pair class="/" geom1="floor" geom2="right_foot" name="//unnamed_contact_1"/>
  </contact>

  <actuator>
    <general name="AAHead_yaw" class="/" joint="AAHead_yaw" forcerange="-6.89898 6.89898" gainprm="22.2752" biasprm="0 -22.2752 -0.483842"/>
    <general name="Head_pitch" class="/" joint="Head_pitch" forcerange="-6.88311 6.88311" gainprm="22.2752" biasprm="0 -22.2752 -0.483842"/>
    <general name="Left_Shoulder_Pitch" class="/" joint="Left_Shoulder_Pitch" forcerange="-14.7167 14.7167" gainprm="22.2752" biasprm="0 -22.2752 -0.483842"/>
    <general name="Left_Shoulder_Roll" class="/" joint="Left_Shoulder_Roll" forcerange="-15.4362 15.4362" gainprm="22.2752" biasprm="0 -22.2752 -0.483842"/>
    <general name="Left_Elbow_Pitch" class="/" joint="Left_Elbow_Pitch" forcerange="-17.2299 17.2299" gainprm="22.2752" biasprm="0 -22.2752 -0.483842"/>
    <general name="Left_Elbow_Yaw" class="/" joint="Left_Elbow_Yaw" forcerange="-14.3757 14.3757" gainprm="22.2752" biasprm="0 -22.2752 -0.483842"/>
    <general name="Right_Shoulder_Pitch" class="/" joint="Right_Shoulder_Pitch" forcerange="-15.172 15.172" gainprm="22.2752" biasprm="0 -22.2752 -0.483842"/>
    <general name="Right_Shoulder_Roll" class="/" joint="Right_Shoulder_Roll" forcerange="-16.2812 16.2812" gainprm="22.2752" biasprm="0 -22.2752 -0.483842"/>
    <general name="Right_Elbow_Pitch" class="/" joint="Right_Elbow_Pitch" forcerange="-17.1395 17.1395" gainprm="22.2752" biasprm="0 -22.2752 -0.483842"/>
    <general name="Right_Elbow_Yaw" class="/" joint="Right_Elbow_Yaw" forcerange="-17.2391 17.2391" gainprm="22.2752" biasprm="0 -22.2752 -0.483842"/>
    <general name="Waist" class="/" joint="Waist" forcerange="-26.7832 26.7832" gainprm="22.2752" biasprm="0 -22.2752 -0.483842"/>
    <general name="Left_Hip_Pitch" class="/" joint="Left_Hip_Pitch" forcerange="-37.6532 37.6532" gainprm="22.2752" biasprm="0 -22.2752 -0.483842"/>
    <general name="Left_Hip_Roll" class="/" joint="Left_Hip_Roll" forcerange="-28.9032 28.9032" gainprm="22.2752" biasprm="0 -22.2752 -0.483842"/>
    <general name="Left_Hip_Yaw" class="/" joint="Left_Hip_Yaw" forcerange="-25.6023 25.6023" gainprm="22.2752" biasprm="0 -22.2752 -0.483842"/>
    <general name="Left_Knee_Pitch" class="/" joint="Left_Knee_Pitch" forcerange="-58.6031 58.6031" gainprm="22.2752" biasprm="0 -22.2752 -0.483842"/>
    <general name="Left_Ankle_Pitch" class="/" joint="Left_Ankle_Pitch" forcerange="-17.4587 17.4587" gainprm="22.2752" biasprm="0 -22.2752 -0.483842"/>
    <general name="Left_Ankle_Roll" class="/" joint="Left_Ankle_Roll" forcerange="-13.8723 13.8723" gainprm="22.2752" biasprm="0 -22.2752 -0.483842"/>
    <general name="Right_Hip_Pitch" class="/" joint="Right_Hip_Pitch" forcerange="-39.4516 39.4516" gainprm="22.2752" biasprm="0 -22.2752 -0.483842"/>
    <general name="Right_Hip_Roll" class="/" joint="Right_Hip_Roll" forcerange="-23.9623 23.9623" gainprm="22.2752" biasprm="0 -22.2752 -0.483842"/>
    <general name="Right_Hip_Yaw" class="/" joint="Right_Hip_Yaw" forcerange="-24.0584 24.0584" gainprm="22.2752" biasprm="0 -22.2752 -0.483842"/>
    <general name="Right_Knee_Pitch" class="/" joint="Right_Knee_Pitch" forcerange="-58.2547 58.2547" gainprm="22.2752" biasprm="0 -22.2752 -0.483842"/>
    <general name="Right_Ankle_Pitch" class="/" joint="Right_Ankle_Pitch" forcerange="-19.6972 19.6972" gainprm="22.2752" biasprm="0 -22.2752 -0.483842"/>
    <general name="Right_Ankle_Roll" class="/" joint="Right_Ankle_Roll" forcerange="-12.4574 12.4574" gainprm="22.2752" biasprm="0 -22.2752 -0.483842"/>
  </actuator>

  <sensor>
    <gyro site="imu" name="imu_angular_velocity"/>
    <velocimeter site="imu" name="imu_linear_velocity"/>
    <framelinvel objtype="site" objname="left_foot" name="left_foot_global_linear_velocity"/>
    <framelinvel objtype="site" objname="right_foot" name="right_foot_global_linear_velocity"/>
  </sensor>

  <keyframe>
    <key name="home" qpos="0 0 0.6385 1 0 0 0 0 0 0 1.4 0 -0.4 0 -1.4 0 0.4 0 -0.4 0 0 0.8 -0.4 0 0.4 0 0 -0.8 0.4 0"/>
  </keyframe>
</mujoco>
