<mujoco model="T1">
  <compiler angle="radian" assetdir="assets" balanceinertia="true" inertiafromgeom="false"/>

  <option timestep="0.005" density="1.2" viscosity="2e-05"/>

  <size nkey="1"/>

  <visual>
    <quality shadowsize="8192"/>
    <map shadowclip="0.5"/>
  </visual>

  <default>
    <default class="/">
      <joint armature="0.01" damping="0.01" frictionloss="0.1"/>
      <geom contype="0" conaffinity="0" group="1" solref="-1000 -80"/>
      <site size="0.01 0.005 0.005" group="5"/>
      <general forcelimited="true" biastype="affine" gainprm="25" biasprm="0 -25 -0.6"/>
      <default class="t1">
        <geom rgba="0.25 0.25 0.25 1"/>
        <default class="visual">
          <geom type="mesh" group="2"/>
        </default>
        <default class="collision">
          <geom group="3"/>
        </default>
        <default class="foot">
          <geom size="0.1115 0.05 0.015" type="box" condim="6" group="4" priority="1" solimp="0.015 1 0.015"/>
        </default>
        <default class="reward_collision_sphere">
          <geom group="5" rgba="1 0 0 1"/>
        </default>
      </default>
    </default>
  </default>

  <asset>
    <texture type="skybox" colorspace="auto" name="//unnamed_texture_0" builtin="gradient" rgb1="0.95 0.95 0.95" rgb2="0.95 0.95 0.95" width="100" height="600"/>
    <texture type="2d" colorspace="auto" name="texplane" builtin="checker" rgb1="0.345 0.575 0.748" rgb2="0.345 0.575 0.748" markrgb="1 1 1" width="512" height="512"/>
    <material name="MatPlane" class="/" texture="texplane" texuniform="true" texrepeat="2 2" specular="0.9"/>
    <mesh name="Trunk" class="/" file="Trunk.stl"/>
    <mesh name="H1" class="/" file="H1.stl"/>
    <mesh name="H2" class="/" file="H2.stl"/>
    <mesh name="AL1" class="/" file="AL1.stl"/>
    <mesh name="AL2" class="/" file="AL2.stl"/>
    <mesh name="AL3" class="/" file="AL3.stl"/>
    <mesh name="left_hand_link" class="/" file="left_hand_link.stl"/>
    <mesh name="AR1" class="/" file="AR1.stl"/>
    <mesh name="AR2" class="/" file="AR2.stl"/>
    <mesh name="AR3" class="/" file="AR3.stl"/>
    <mesh name="right_hand_link" class="/" file="right_hand_link.stl"/>
    <mesh name="Waist" class="/" file="Waist.stl"/>
    <mesh name="Hip_Pitch_Left" class="/" file="Hip_Pitch_Left.stl"/>
    <mesh name="Hip_Roll_Left" class="/" file="Hip_Roll_Left.stl"/>
    <mesh name="Hip_Yaw_Left" class="/" file="Hip_Yaw_Left.stl"/>
    <mesh name="Shank_Left" class="/" file="Shank_Left.stl"/>
    <mesh name="Ankle_Cross_Left" class="/" file="Ankle_Cross_Left.stl"/>
    <mesh name="left_foot_link" class="/" file="left_foot_link.stl"/>
    <mesh name="Hip_Pitch_Right" class="/" file="Hip_Pitch_Right.stl"/>
    <mesh name="Hip_Roll_Right" class="/" file="Hip_Roll_Right.stl"/>
    <mesh name="Hip_Yaw_Right" class="/" file="Hip_Yaw_Right.stl"/>
    <mesh name="Shank_Right" class="/" file="Shank_Right.stl"/>
    <mesh name="Ankle_Cross_Right" class="/" file="Ankle_Cross_Right.stl"/>
    <mesh name="right_foot_link" class="/" file="right_foot_link.stl"/>
  </asset>

  <worldbody>
    <geom name="floor" class="/" size="100 100 0.125" type="plane" group="0" material="MatPlane"/>
    <light name="toplight_shadow" class="/" pos="0 0 5" dir="0.0990148 0.0990148 -0.990148" type="directional" ambient="0.04 0.04 0.04" diffuse="0.55 0.55 0.55" specular="0.12 0.12 0.12"/>
    <light name="toplight_fill" class="/" pos="0 0 5" dir="0.0990148 0.0990148 -0.990148" type="directional" castshadow="false" ambient="0.04 0.04 0.04" diffuse="0.3 0.3 0.3" specular="0.08 0.08 0.08"/>
    <body name="trunk" childclass="t1" pos="-0.000388663 0.00246274 -0.00120054" quat="1 -0.000315095 -0.000128424 -0.000139211">
      <inertial pos="0.053944 -0.000270035 0.129722" quat="0.999959 -0.00130845 -0.00885748 -0.00104695" mass="9.92726" diaginertia="0.108345 0.00512362 0.143612"/>
      <joint name="//unnamed_joint_0" type="free" armature="0" damping="0" frictionloss="0"/>
      <geom name="//unnamed_geom_1" class="visual" rgba="0.76 0.76 0.76 1" mesh="Trunk"/>
      <geom name="//unnamed_geom_2" class="collision" size="0.0711401 0.0948534 0.14228" pos="0.0622886 0 0.146499" type="box"/>
      <geom name="//unnamed_geom_3" class="reward_collision_sphere" size="0.109081" pos="0.0622886 0 0.122082"/>
      <geom name="//unnamed_geom_4" class="reward_collision_sphere" size="0.014228" pos="0.0622886 0.0498641 0"/>
      <geom name="//unnamed_geom_5" class="reward_collision_sphere" size="0.014228" pos="0.0622886 -0.0498641 0"/>
      <geom name="//unnamed_geom_6" class="reward_collision_sphere" size="0.014228" pos="0.0622886 0.0627701 0.219748"/>
      <geom name="//unnamed_geom_7" class="reward_collision_sphere" size="0.014228" pos="0.0622886 -0.0627701 0.219748"/>
      <site name="imu" pos="-0.00116792 -0.0129633 -0.00916886" size="0.00948534"/>
      <camera name="track" pos="0 -1.17327 0" quat="0.707107 0.707107 0 0" mode="trackcom"/>
      <camera name="ego_camera" pos="0.126653 0 0.512746" quat="-0.5 -0.5 0.5 0.5"/>
      <body name="H1" pos="0.0651057 -0.00100353 0.294488" quat="0.999999 -0.000125465 0.000426422 0.00109356">
        <inertial pos="-0.000356606 -0.00407044 0.0718252" quat="0.770178 -0.00819272 -0.00138667 0.637774" mass="0.381365" diaginertia="0.000279228 1.53126e-05 0.000382326"/>
        <joint name="AAHead_yaw" pos="0 0 0" axis="0.011252 -0.00117861 0.999936" range="-1.53311 1.48619" armature="0.00911977" damping="0.00779815" frictionloss="0.0944358"/>
        <geom name="//unnamed_geom_8" class="visual" mesh="H1"/>
        <body name="H2" pos="-0.000694343 0.000720648 0.0811408" quat="0.999997 -6.5631e-05 -0.0009534 -0.00243384">
          <inertial pos="0.00596817 0.000180738 0.119241" quat="0.988388 0.106655 -0.0747959 -0.0782254" mass="0.539111" diaginertia="0.00244024 0.000128707 0.00485711"/>
          <joint name="Head_pitch" pos="0 0 0" axis="-0.00327914 -0.999986 -0.00415998" range="-1.17096 0.342849" armature="0.00957084" damping="0.0107738" frictionloss="0.0953779"/>
          <geom name="//unnamed_geom_9" class="visual" mesh="H2"/>
          <geom name="//unnamed_geom_10" class="collision" size="0.0758828" pos="0.0103814 0 0.134291"/>
          <geom name="//unnamed_geom_11" class="reward_collision_sphere" size="0.0853681" pos="0.0207629 0 0.122082"/>
        </body>
      </body>
      <body name="AL1" pos="0.060915 0.0623796 0.267668" quat="1 0.00032578 0.000584298 -0.000336196">
        <inertial pos="0.00138813 0.0257034 -0.000238837" quat="0.506841 0.485538 -0.500622 0.506698" mass="0.465281" diaginertia="0.00163967 9.08059e-05 0.000794886"/>
        <joint name="Left_Shoulder_Pitch" pos="0 0 0" axis="-0.00340385 0.999991 -0.00257939" range="-3.38243 1.20504" armature="0.0097213" damping="0.00256207" frictionloss="0.0877994"/>
        <geom name="//unnamed_geom_12" class="visual" rgba="0.76 0.76 0.76 1" mesh="AL1"/>
        <body name="AL2" pos="0.000929092 0.0274929 -7.36792e-06" quat="0.999999 -0.00138277 0.000450338 0.000574806">
          <inertial pos="-0.000684894 0.0230955 -2.89338e-05" quat="0.485923 0.510079 -0.491181 0.512288" mass="0.140888" diaginertia="0.000502364 2.43943e-05 0.000511329"/>
          <joint name="Left_Shoulder_Roll" pos="0 0 0" axis="-0.999976 0.00344243 0.00606759" range="-1.57709 1.69077" armature="0.00945294" damping="0.00117475" frictionloss="0.0852364"/>
          <geom name="//unnamed_geom_13" class="visual" mesh="AL2"/>
          <body name="AL3" pos="0.000335617 0.0337893 -0.000678657" quat="0.999999 0.000248687 0.00115258 0.00064216">
            <inertial pos="-0.00373975 0.0524635 0.000970545" quat="0.696521 0.717232 -0.00257591 -0.0207403" mass="0.818251" diaginertia="0.0141265 0.000779018 0.00160171"/>
            <joint name="Left_Elbow_Pitch" pos="0 0 0" axis="0.0057062 -0.999912 0.0120135" stiffness="0.00254269" range="-2.29283 2.1806" armature="0.00856706" damping="0.00950732" frictionloss="0.0736837"/>
            <geom name="//unnamed_geom_14" class="visual" mesh="AL3"/>
            <geom name="//unnamed_geom_15" class="collision" size="0.028456 0.0711401" pos="0 0.0293318 0" quat="0.707105 0.707108 0 0" type="cylinder"/>
            <geom name="//unnamed_geom_16" class="reward_collision_sphere" size="0.0341472"/>
            <body name="left_hand_link" pos="-0.000121141 0.0881101 0.00233668" quat="0.999998 -0.000642877 -0.00198832 -0.000288782">
              <inertial pos="-0.00269158 0.0634609 0.00140819" quat="0.707333 0.706769 0.0123938 -0.00190463" mass="0.272698" diaginertia="0.00926629 0.000549442 0.00059451"/>
              <joint name="Left_Elbow_Yaw" pos="0 0 0" axis="0.00291309 0.0104964 0.999941" stiffness="0.00772095" range="-2.46421 -0.0868551" armature="0.0102518" damping="0.0183771" frictionloss="0.0995907"/>
              <geom name="//unnamed_geom_17" class="visual" mesh="left_hand_link"/>
              <geom name="//unnamed_geom_18" class="collision" size="0.028456 0.0829968" pos="0 0.0762628 0" quat="0.707105 0.707108 0 0" type="cylinder"/>
              <geom name="//unnamed_geom_19" class="reward_collision_sphere" size="0.0474267"/>
              <geom name="//unnamed_geom_20" class="reward_collision_sphere" size="0.0331987" pos="0 0.0645301 0"/>
              <geom name="//unnamed_geom_21" class="reward_collision_sphere" size="0.0331987" pos="0 0.126127 0"/>
            </body>
          </body>
        </body>
      </body>
      <body name="AR1" pos="0.0567925 -0.0636596 0.270478" quat="1 -5.00692e-05 0.000430115 -6.6326e-05">
        <inertial pos="-0.00171863 -0.0240653 0.000212465" quat="0.495352 0.493755 -0.507818 0.502945" mass="0.455151" diaginertia="0.00163884 8.83246e-05 0.000787851"/>
        <joint name="Right_Shoulder_Pitch" pos="0 0 0" axis="0.0214034 -0.999722 0.00989476" range="-1.232 3.23931" armature="0.00837675" damping="0.0131639" frictionloss="0.113356"/>
        <geom name="//unnamed_geom_22" class="visual" rgba="0.76 0.76 0.76 1" mesh="AR1"/>
        <body name="AR2" pos="-0.00492885 -0.0243023 0.00224461" quat="1 0.000136402 2.6677e-06 -1.83506e-05">
          <inertial pos="0.00294707 -0.0230546 0.00303477" quat="0.52044 0.481271 -0.509787 0.487481" mass="0.124695" diaginertia="0.000467048 2.2655e-05 0.000451882"/>
          <joint name="Right_Shoulder_Roll" pos="0 0 0" axis="-0.999953 0.00704294 -0.00659488" stiffness="0.00793334" range="-1.75265 1.55167" armature="0.00834621" damping="0.0124601" frictionloss="0.0863147"/>
          <geom name="//unnamed_geom_23" class="visual" mesh="AR2"/>
          <body name="AR3" pos="0.00238246 -0.0331386 -0.00147997" quat="1 0.000213208 -0.000273996 -0.000247092">
            <inertial pos="0.000664501 -0.0514931 0.00111653" quat="0.70686 0.707311 0.000113607 0.00775371" mass="0.794934" diaginertia="0.0144324 0.000833293 0.0015808"/>
            <joint name="Right_Elbow_Pitch" pos="0 0 0" axis="0.00423369 0.999985 0.00345287" stiffness="0.0281607" range="-2.24214 2.31471" armature="0.00887107" damping="0" frictionloss="0.0987016"/>
            <geom name="//unnamed_geom_24" class="visual" mesh="AR3"/>
            <geom name="//unnamed_geom_25" class="collision" size="0.028456 0.0711401" pos="0 -0.0293318 0" quat="0.707105 0.707108 0 0" type="cylinder"/>
            <geom name="//unnamed_geom_26" class="reward_collision_sphere" size="0.0341472"/>
            <body name="right_hand_link" pos="0.000150101 -0.0870711 -0.00435275" quat="1 3.60899e-05 0.000162789 -0.000114541">
              <inertial pos="-0.00238767 -0.0646914 0.00495411" quat="0.706313 0.7079 0.000308827 -0.000162266" mass="0.294973" diaginertia="0.0100988 0.000548722 0.000581643"/>
              <joint name="Right_Elbow_Yaw" pos="0 0 0" axis="0.00123012 -0.00241434 0.999996" range="0.0395059 2.3901" armature="0.0084504" damping="0.00164385" frictionloss="0.0870661"/>
              <geom name="//unnamed_geom_27" class="visual" mesh="right_hand_link"/>
              <geom name="//unnamed_geom_28" class="collision" size="0.028456 0.0829968" pos="0 -0.0762628 0" quat="0.707105 0.707108 0 0" type="cylinder"/>
              <geom name="//unnamed_geom_29" class="reward_collision_sphere" size="0.0474267"/>
              <geom name="//unnamed_geom_30" class="reward_collision_sphere" size="0.0331987" pos="0 -0.0645301 0"/>
              <geom name="//unnamed_geom_31" class="reward_collision_sphere" size="0.0331987" pos="0 -0.126127 0"/>
            </body>
          </body>
        </body>
      </body>
      <body name="Waist" pos="0.0706656 0.00224591 -0.138303" quat="1 0.000294946 -0.000457244 -1.13371e-06">
        <inertial pos="0.00502495 0.00118992 0.0115327" quat="0.983795 1.88424e-05 -0.179281 0.00239316" mass="2.31389" diaginertia="0.00672207 0.000391223 0.013357"/>
        <joint name="Waist" pos="0 0 0" axis="5.56401e-05 0.000430622 1" range="-1.56771 1.56911" armature="0.0106801" damping="0" frictionloss="0.112475"/>
        <geom name="//unnamed_geom_32" class="visual" mesh="Waist"/>
        <body name="Hip_Pitch_Left" pos="0.00251911 0.0654566 -0.00181464" quat="1 -0.000808916 0.000167141 -7.22837e-05">
          <inertial pos="0.00171792 -0.0073097 -0.0215016" quat="0.976212 0.216241 0.0152979 0.00406136" mass="0.873828" diaginertia="0.00207494 9.42385e-05 0.00328807"/>
          <joint name="Left_Hip_Pitch" pos="0 0 0" axis="0.0139096 0.999871 -0.00801018" stiffness="0.0188397" range="-1.8518 1.61722" armature="0.00832402" damping="0.016551" frictionloss="0.104072"/>
          <geom name="//unnamed_geom_33" class="visual" rgba="0.76 0.76 0.76 1" mesh="Hip_Pitch_Left"/>
          <body name="Hip_Roll_Left" pos="-0.00293259 -0.00233645 -0.024195" quat="0.999997 0.00194448 -0.000994585 0.00137614">
            <inertial pos="0.00437935 0.00167413 -0.0631109" quat="0.704888 -0.0140605 0.0162213 0.708994" mass="0.343216" diaginertia="0.00222506 0.000111811 0.00139782"/>
            <joint name="Left_Hip_Roll" pos="0 0 0" axis="-0.999668 0.0163186 0.0199326" range="-1.54927 0.135892" armature="0.00818921" damping="0.0207701" frictionloss="0.0878006"/>
            <geom name="//unnamed_geom_34" class="visual" mesh="Hip_Roll_Left"/>
            <geom name="//unnamed_geom_35" class="reward_collision_sphere" size="0.0521694"/>
            <body name="Hip_Yaw_Left" pos="-0.0056205 -0.00164267 -0.102459" quat="0.999998 -0.00108343 -0.000910159 -0.0011089">
              <inertial pos="-0.00475323 -0.00312302 -0.109943" quat="0.703238 -0.0403463 -0.0350789 0.708941" mass="1.76748" diaginertia="0.0302345 0.00169524 0.00670174"/>
              <joint name="Left_Hip_Yaw" pos="0 0 0" axis="-0.00538242 0.000359244 -0.999985" range="-0.959302 1.08223" armature="0.0104466" damping="0" frictionloss="0.100949"/>
              <geom name="//unnamed_geom_36" class="visual" mesh="Hip_Yaw_Left"/>
              <geom name="//unnamed_geom_37" class="collision" size="0.0474267 0.0758828" type="cylinder"/>
              <body name="Shank_Left" pos="-0.0122184 -0.00138963 -0.159589" quat="1 0.000471922 1.75773e-05 -0.000361973">
                <inertial pos="-0.00812667 0.0026935 -0.150453" quat="0.996688 0.000582224 -0.0234471 0.0778658" mass="1.49719" diaginertia="0.0419107 0.00248261 0.00536055"/>
                <joint name="Left_Knee_Pitch" pos="0 0 0" axis="0.00272777 0.999982 -0.00541764" range="0.0130462 2.3727" armature="0.00931964" damping="0.00906624" frictionloss="0.103956"/>
                <geom name="//unnamed_geom_38" class="visual" mesh="Shank_Left"/>
                <geom name="//unnamed_geom_39" class="collision" size="0.0474267 0.0711401" pos="0 0 -0.146499" type="cylinder"/>
                <geom name="//unnamed_geom_40" class="reward_collision_sphere" size="0.0616547"/>
                <body name="Ankle_Cross_Left" pos="0.000846601 0.000932434 -0.345849" quat="1 0.000163973 -0.000368818 0.000211251">
                  <inertial pos="-0.00463399 0.00236287 -0.0106779" quat="0.443684 0.551017 0.550971 0.442669" mass="0.0583186" diaginertia="3.4596e-05 1.69744e-06 3.00095e-05"/>
                  <joint name="Left_Ankle_Pitch" pos="0 0 0" axis="3.62636e-05 0.999972 -0.00743767" range="-0.918045 0.394425" armature="0.0099267" damping="0.0130509" frictionloss="0.0982234"/>
                  <geom name="//unnamed_geom_41" class="visual" mesh="Ankle_Cross_Left"/>
                  <body name="left_foot_link" pos="0.000648596 0.00104757 -0.0148685" quat="0.999999 0.000577378 -0.000250603 -0.000910453">
                    <inertial pos="0.00177659 -0.00158556 -0.0110182" quat="4.46535e-06 0.620695 1.37257e-05 0.784052" mass="0.627705" diaginertia="0.00312875 0.000172367 0.00621283"/>
                    <joint name="Left_Ankle_Roll" pos="0 0 0" axis="-0.999998 0.00144692 -0.00109177" stiffness="0.00559635" range="-0.486959 0.365647" armature="0.00745856" damping="0.00965414" frictionloss="0.104944"/>
                    <geom name="//unnamed_geom_42" class="visual" mesh="left_foot_link"/>
                    <geom name="left_foot" class="foot" size="0.0947858 0.0527915 0.013127" pos="0.0103814 0 -0.0183124"/>
                    <geom name="//unnamed_geom_44" class="reward_collision_sphere" size="0.0493238" pos="0.0103814 0 -0.0183124"/>
                    <geom name="//unnamed_geom_45" class="reward_collision_sphere" size="0.028456" pos="0.0986236 -0.0134926 -0.0183124"/>
                    <geom name="//unnamed_geom_46" class="reward_collision_sphere" size="0.028456" pos="-0.07267 -0.0134926 -0.0183124"/>
                    <site name="left_foot" class="foot" pos="0.0103814 0 -0.0183124" size="0.00948534"/>
                  </body>
                </body>
              </body>
            </body>
          </body>
        </body>
        <body name="Hip_Pitch_Right" pos="-0.00213483 -0.0606916 0.00157393" quat="0.999999 4.05718e-05 -0.00104564 -0.000964738">
          <inertial pos="0.00323138 0.0064351 -0.0220248" quat="0.972911 -0.230608 0.0147275 -0.0069367" mass="0.837761" diaginertia="0.0021567 0.000100916 0.00334076"/>
          <joint name="Right_Hip_Pitch" pos="0 0 0" axis="-0.00596717 -0.999908 -0.0121907" range="-1.51938 1.78652" armature="0.00687739" damping="0.0118099" frictionloss="0.0891689"/>
          <geom name="//unnamed_geom_47" class="visual" rgba="0.76 0.76 0.76 1" mesh="Hip_Pitch_Right"/>
          <body name="Hip_Roll_Right" pos="0.00159533 -0.00035813 -0.0277781" quat="0.999999 0.000397261 0.000335102 0.00118109">
            <inertial pos="0.00130747 0.00376835 -0.0645554" quat="0.699935 -0.00299832 -0.0165615 0.714008" mass="0.361501" diaginertia="0.00230419 0.000113186 0.0014977"/>
            <joint name="Right_Hip_Roll" pos="0 0 0" axis="-0.999798 0.00433993 -0.0196471" range="-0.23335 1.5747" armature="0.00962279" damping="0.0195388" frictionloss="0.101158"/>
            <geom name="//unnamed_geom_48" class="visual" mesh="Hip_Roll_Right"/>
            <geom name="//unnamed_geom_49" class="reward_collision_sphere" size="0.0521694"/>
            <body name="Hip_Yaw_Right" pos="-0.00161332 0.000797778 -0.10219" quat="1 -0.000425331 -8.08235e-05 -0.000316846">
              <inertial pos="-0.007992 0.00501344 -0.107466" quat="0.7094 -0.0389685 -0.0323466 0.702984" mass="1.99094" diaginertia="0.0334987 0.00189775 0.00727598"/>
              <joint name="Right_Hip_Yaw" pos="0 0 0" axis="-4.67001e-05 0.00314947 -0.999995" range="-1.01993 0.963049" armature="0.00838164" damping="0.0184632" frictionloss="0.0947561"/>
              <geom name="//unnamed_geom_50" class="visual" mesh="Hip_Yaw_Right"/>
              <geom name="//unnamed_geom_51" class="collision" size="0.0474267 0.0758828" type="cylinder"/>
              <body name="Shank_Right" pos="-0.012055 0.00105213 -0.16258" quat="1 0.000386992 -0.000334715 -0.000157059">
                <inertial pos="-0.00587363 0.000707352 -0.151377" quat="0.999239 0.0113595 -0.0254378 -0.0273155" mass="1.55904" diaginertia="0.0463688 0.00241639 0.00543724"/>
                <joint name="Right_Knee_Pitch" pos="0 0 0" axis="-0.0151733 -0.99975 0.0164519" stiffness="0.01376" range="-2.31817 0.0297742" armature="0.00965751" damping="0.01666" frictionloss="0.0957553"/>
                <geom name="//unnamed_geom_52" class="visual" mesh="Shank_Right"/>
                <geom name="//unnamed_geom_53" class="collision" size="0.0474267 0.0711401" pos="0 0 -0.146499" type="cylinder"/>
                <geom name="//unnamed_geom_54" class="reward_collision_sphere" size="0.0616547"/>
                <body name="Ankle_Cross_Right" pos="-0.00257732 -0.00120471 -0.341442" quat="1 0.000706528 -0.000484377 0.000280965">
                  <inertial pos="-0.00641765 -0.000185737 -0.00610589" quat="0.459232 0.546263 0.540604 0.445477" mass="0.064503" diaginertia="3.84307e-05 1.81067e-06 3.3446e-05"/>
                  <joint name="Right_Ankle_Pitch" pos="0 0 0" axis="0.00710753 -0.999946 -0.00753984" stiffness="0.00985747" range="-0.362129 0.908695" armature="0.00913155" damping="0.0104996" frictionloss="0.102623"/>
                  <geom name="//unnamed_geom_55" class="visual" mesh="Ankle_Cross_Right"/>
                  <body name="right_foot_link" pos="-0.00153987 4.48498e-05 -0.0145544" quat="1 -0.000140661 -0.000749392 -0.000522907">
                    <inertial pos="0.00501026 0.000726236 -0.0118642" quat="0.00274422 0.620795 -0.00180276 0.783966" mass="0.582591" diaginertia="0.00316671 0.000160062 0.00578718"/>
                    <joint name="Right_Ankle_Roll" pos="0 0 0" axis="-0.999999 4.82292e-05 0.00115713" range="-0.488845 0.466922" armature="0.0100828" damping="0" frictionloss="0.0961208"/>
                    <geom name="//unnamed_geom_56" class="visual" mesh="right_foot_link"/>
                    <geom name="right_foot" class="foot" size="0.0995102 0.0467705 0.014581" pos="0.0103814 0 -0.0183124"/>
                    <geom name="//unnamed_geom_58" class="reward_collision_sphere" size="0.0379414"/>
                    <geom name="//unnamed_geom_59" class="reward_collision_sphere" size="0.028456" pos="0.0103814 0 -0.0183124"/>
                    <geom name="//unnamed_geom_60" class="reward_collision_sphere" size="0.028456" pos="0.0986236 0.0134926 -0.0183124"/>
                    <geom name="//unnamed_geom_61" class="reward_collision_sphere" size="0.028456" pos="-0.07267 0.0134926 -0.0183124"/>
                    <site name="right_foot" class="foot" pos="0.0103814 0 -0.0183124" size="0.00948534"/>
                  </body>
                </body>
              </body>
            </body>
          </body>
        </body>
      </body>
    </body>
  </worldbody>

  <contact>
    <pair class="/" geom1="floor" geom2="left_foot" name="//unnamed_contact_0"/>
    <pair class="/" geom1="floor" geom2="right_foot" name="//unnamed_contact_1"/>
  </contact>

  <actuator>
    <general name="AAHead_yaw" class="/" joint="AAHead_yaw" forcerange="-6.53213 6.53213" gainprm="24.6805" biasprm="0 -24.6805 -0.55797"/>
    <general name="Head_pitch" class="/" joint="Head_pitch" forcerange="-6.43025 6.43025" gainprm="24.6805" biasprm="0 -24.6805 -0.55797"/>
    <general name="Left_Shoulder_Pitch" class="/" joint="Left_Shoulder_Pitch" forcerange="-15.7716 15.7716" gainprm="24.6805" biasprm="0 -24.6805 -0.55797"/>
    <general name="Left_Shoulder_Roll" class="/" joint="Left_Shoulder_Roll" forcerange="-18.1399 18.1399" gainprm="24.6805" biasprm="0 -24.6805 -0.55797"/>
    <general name="Left_Elbow_Pitch" class="/" joint="Left_Elbow_Pitch" forcerange="-14.9775 14.9775" gainprm="24.6805" biasprm="0 -24.6805 -0.55797"/>
    <general name="Left_Elbow_Yaw" class="/" joint="Left_Elbow_Yaw" forcerange="-17.2089 17.2089" gainprm="24.6805" biasprm="0 -24.6805 -0.55797"/>
    <general name="Right_Shoulder_Pitch" class="/" joint="Right_Shoulder_Pitch" forcerange="-19.8197 19.8197" gainprm="24.6805" biasprm="0 -24.6805 -0.55797"/>
    <general name="Right_Shoulder_Roll" class="/" joint="Right_Shoulder_Roll" forcerange="-17.0528 17.0528" gainprm="24.6805" biasprm="0 -24.6805 -0.55797"/>
    <general name="Right_Elbow_Pitch" class="/" joint="Right_Elbow_Pitch" forcerange="-14.7766 14.7766" gainprm="24.6805" biasprm="0 -24.6805 -0.55797"/>
    <general name="Right_Elbow_Yaw" class="/" joint="Right_Elbow_Yaw" forcerange="-18.2474 18.2474" gainprm="24.6805" biasprm="0 -24.6805 -0.55797"/>
    <general name="Waist" class="/" joint="Waist" forcerange="-26.2493 26.2493" gainprm="24.6805" biasprm="0 -24.6805 -0.55797"/>
    <general name="Left_Hip_Pitch" class="/" joint="Left_Hip_Pitch" forcerange="-39.2878 39.2878" gainprm="24.6805" biasprm="0 -24.6805 -0.55797"/>
    <general name="Left_Hip_Roll" class="/" joint="Left_Hip_Roll" forcerange="-25.3729 25.3729" gainprm="24.6805" biasprm="0 -24.6805 -0.55797"/>
    <general name="Left_Hip_Yaw" class="/" joint="Left_Hip_Yaw" forcerange="-33.6273 33.6273" gainprm="24.6805" biasprm="0 -24.6805 -0.55797"/>
    <general name="Left_Knee_Pitch" class="/" joint="Left_Knee_Pitch" forcerange="-54.0179 54.0179" gainprm="24.6805" biasprm="0 -24.6805 -0.55797"/>
    <general name="Left_Ankle_Pitch" class="/" joint="Left_Ankle_Pitch" forcerange="-23.0964 23.0964" gainprm="24.6805" biasprm="0 -24.6805 -0.55797"/>
    <general name="Left_Ankle_Roll" class="/" joint="Left_Ankle_Roll" forcerange="-13.602 13.602" gainprm="24.6805" biasprm="0 -24.6805 -0.55797"/>
    <general name="Right_Hip_Pitch" class="/" joint="Right_Hip_Pitch" forcerange="-42.7304 42.7304" gainprm="24.6805" biasprm="0 -24.6805 -0.55797"/>
    <general name="Right_Hip_Roll" class="/" joint="Right_Hip_Roll" forcerange="-27.767 27.767" gainprm="24.6805" biasprm="0 -24.6805 -0.55797"/>
    <general name="Right_Hip_Yaw" class="/" joint="Right_Hip_Yaw" forcerange="-27.7523 27.7523" gainprm="24.6805" biasprm="0 -24.6805 -0.55797"/>
    <general name="Right_Knee_Pitch" class="/" joint="Right_Knee_Pitch" forcerange="-52.1155 52.1155" gainprm="24.6805" biasprm="0 -24.6805 -0.55797"/>
    <general name="Right_Ankle_Pitch" class="/" joint="Right_Ankle_Pitch" forcerange="-19.2243 19.2243" gainprm="24.6805" biasprm="0 -24.6805 -0.55797"/>
    <general name="Right_Ankle_Roll" class="/" joint="Right_Ankle_Roll" forcerange="-16.1804 16.1804" gainprm="24.6805" biasprm="0 -24.6805 -0.55797"/>
  </actuator>

  <sensor>
    <gyro site="imu" name="imu_angular_velocity"/>
    <velocimeter site="imu" name="imu_linear_velocity"/>
    <framelinvel objtype="site" objname="left_foot" name="left_foot_global_linear_velocity"/>
    <framelinvel objtype="site" objname="right_foot" name="right_foot_global_linear_velocity"/>
  </sensor>

  <keyframe>
    <key name="home" qpos="0 0 0.6385 1 0 0 0 0 0 0 1.4 0 -0.4 0 -1.4 0 0.4 0 -0.4 0 0 0.8 -0.4 0 0.4 0 0 -0.8 0.4 0"/>
  </keyframe>
</mujoco>
