<mujoco model="GR1T2_jaw">
  <compiler angle="radian" assetdir="assets" balanceinertia="true" inertiafromgeom="false"/>

  <option timestep="0.005" density="1.2" viscosity="2e-05"/>

  <size nkey="1"/>

  <visual>
    <quality shadowsize="8192"/>
    <map shadowclip="0.5"/>
  </visual>

  <default>
    <default class="/">
      <joint armature="0.1" damping="0.01" frictionloss="0.1"/>
      <geom contype="0" conaffinity="0" group="1" solref="-1000 -80"/>
      <site size="0.01 0.005 0.005" group="5"/>
      <general forcelimited="true" biastype="affine" gainprm="80" biasprm="0 -80 -2"/>
      <default class="visual">
        <geom type="mesh" density="0" rgba="0.18 0.18 0.18 1"/>
      </default>
      <default class="collision">
        <geom group="3"/>
      </default>
      <default class="foot">
        <geom size="0.126 0.045 0.01" type="box" condim="6" group="4" priority="1" solimp="0.015 1 0.01"/>
      </default>
      <default class="reward_collision_sphere">
        <geom group="5" rgba="1 0 0 1"/>
      </default>
    </default>
  </default>

  <asset>
    <texture type="skybox" colorspace="auto" name="//unnamed_texture_0" builtin="gradient" rgb1="0.95 0.95 0.95" rgb2="0.95 0.95 0.95" width="100" height="600"/>
    <texture type="2d" colorspace="auto" name="texplane" builtin="checker" rgb1="0.345 0.575 0.748" rgb2="0.345 0.575 0.748" markrgb="1 1 1" width="512" height="512"/>
    <material name="MatPlane" class="/" texture="texplane" texuniform="true" texrepeat="2 2" specular="0.9"/>
    <mesh name="base_link" class="/" file="base_link.STL"/>
    <mesh name="left_thigh_roll_link" class="/" file="left_thigh_roll_link.STL"/>
    <mesh name="left_thigh_yaw_link" class="/" file="left_thigh_yaw_link.STL"/>
    <mesh name="left_thigh_pitch_link" class="/" file="left_thigh_pitch_link.STL"/>
    <mesh name="left_shank_pitch_link" class="/" file="left_shank_pitch_link.STL"/>
    <mesh name="left_foot_pitch_link" class="/" file="left_foot_pitch_link.STL"/>
    <mesh name="left_foot_roll_link" class="/" file="left_foot_roll_link.STL"/>
    <mesh name="right_thigh_roll_link" class="/" file="right_thigh_roll_link.STL"/>
    <mesh name="right_thigh_yaw_link" class="/" file="right_thigh_yaw_link.STL"/>
    <mesh name="right_thigh_pitch_link" class="/" file="right_thigh_pitch_link.STL"/>
    <mesh name="right_shank_pitch_link" class="/" file="right_shank_pitch_link.STL"/>
    <mesh name="right_foot_pitch_link" class="/" file="right_foot_pitch_link.STL"/>
    <mesh name="right_foot_roll_link" class="/" file="right_foot_roll_link.STL"/>
    <mesh name="waist_yaw_link" class="/" file="waist_yaw_link.STL"/>
    <mesh name="waist_pitch_link" class="/" file="waist_pitch_link.STL"/>
    <mesh name="waist_roll_link" class="/" file="waist_roll_link.STL"/>
    <mesh name="torso_link" class="/" file="torso_link.STL"/>
    <mesh name="left_upper_arm_pitch_link" class="/" file="left_upper_arm_pitch_link.STL"/>
    <mesh name="left_upper_arm_roll_link" class="/" file="left_upper_arm_roll_link.STL"/>
    <mesh name="left_upper_arm_yaw_link" class="/" file="left_upper_arm_yaw_link.STL"/>
    <mesh name="left_lower_arm_pitch_link" class="/" file="left_lower_arm_pitch_link.STL"/>
    <mesh name="left_hand_yaw_link" class="/" file="left_hand_yaw_link.STL"/>
    <mesh name="left_hand_roll_link" class="/" file="left_hand_roll_link.STL"/>
    <mesh name="left_hand_pitch" class="/" file="left_hand_pitch.STL"/>
    <mesh name="left_jaw_link" class="/" file="left_jaw_link.STL"/>
    <mesh name="right_upper_arm_pitch_link" class="/" file="right_upper_arm_pitch_link.STL"/>
    <mesh name="right_upper_arm_roll_link" class="/" file="right_upper_arm_roll_link.STL"/>
    <mesh name="right_upper_arm_yaw_link" class="/" file="right_upper_arm_yaw_link.STL"/>
    <mesh name="right_lower_arm_pitch_link" class="/" file="right_lower_arm_pitch_link.STL"/>
    <mesh name="right_hand_yaw_link" class="/" file="right_hand_yaw_link.STL"/>
    <mesh name="right_hand_roll_link" class="/" file="right_hand_roll_link.STL"/>
    <mesh name="right_hand_pitch" class="/" file="right_hand_pitch.STL"/>
    <mesh name="right_jaw_link" class="/" file="right_jaw_link.STL"/>
    <mesh name="head_roll_link" class="/" file="head_roll_link.STL"/>
    <mesh name="head_pitch_link" class="/" file="head_pitch_link.STL"/>
    <mesh name="head_yaw_link" class="/" file="head_yaw_link.STL"/>
    <mesh name="imu_link" class="/" file="imu_link.STL"/>
  </asset>

  <worldbody>
    <geom name="floor" class="/" size="100 100 0.125" type="plane" group="0" material="MatPlane"/>
    <light name="toplight_shadow" class="/" pos="0 0 5" dir="0.0990148 0.0990148 -0.990148" type="directional" ambient="0.04 0.04 0.04" diffuse="0.55 0.55 0.55" specular="0.12 0.12 0.12"/>
    <light name="toplight_fill" class="/" pos="0 0 5" dir="0.0990148 0.0990148 -0.990148" type="directional" castshadow="false" ambient="0.04 0.04 0.04" diffuse="0.3 0.3 0.3" specular="0.08 0.08 0.08"/>
    <body name="trunk" pos="0.00273406 -0.00276923 -0.000498986" quat="0.999999 0.000384097 -0.000890567 -0.00103118">
      <inertial pos="-0.0626259 0.00241417 -0.01061" quat="0.999999 0.00122021 -1.62935e-05 0.000248789" mass="1.9312" diaginertia="0.0433977 0.00138084 0.0086135"/>
      <joint name="//unnamed_joint_0" type="free"/>
      <geom name="//unnamed_geom_1" class="visual" rgba="0.12 0.12 0.12 1" mesh="base_link"/>
      <geom name="base_link.STL" class="collision" size="0.0966674 0.0541415" pos="-0.0431065 0.000234504 0.00666255" quat="0.706838 -0.707359 0.00477667 0" type="cylinder" rgba="0.752941 0.752941 0.752941 1"/>
      <geom name="//unnamed_geom_3" class="visual" pos="0 0 -0.0431144" quat="1 0 0 0" rgba="0.12 0.12 0.12 1" mesh="imu_link"/>
      <geom name="//unnamed_geom_4" class="reward_collision_sphere" size="0.0631844" pos="0 0.0633722 0.0723397"/>
      <geom name="//unnamed_geom_5" class="reward_collision_sphere" size="0.0631844" pos="0 -0.0633722 0.0723397"/>
      <site name="imu" class="/" pos="0.0142111 -0.013355 -0.0555561" size="0.00789805"/>
      <camera name="track" class="/" pos="0 -1.26744 0" quat="0.707107 0.707107 0 0" mode="trackcom"/>
      <body name="left_thigh_roll_link" pos="-0.0353834 0.0642798 -0.0192477" quat="1 -0.00021665 0.00029233 -0.000508665">
        <inertial pos="-0.000333156 0.00204413 0.00238942" quat="-0.0299704 0.704754 -0.0201851 0.708531" mass="0.690303" diaginertia="0.0026745 0.00024265 0.000295126"/>
        <joint name="left_hip_roll_joint" class="/" pos="0 0 0" axis="-0.999878 -0.0107797 -0.0113303" range="-0.777069 0.10403" armature="0.0701136" damping="0.018835" frictionloss="0.0791948"/>
        <geom name="//unnamed_geom_6" class="visual" mesh="left_thigh_roll_link"/>
        <body name="left_thigh_yaw_link" pos="0.0305305 0.00134462 0.00301746" quat="1 0.000282367 -1.37049e-05 2.09459e-05">
          <inertial pos="-0.00644499 0.0268855 -0.0795508" quat="0.570905 0.0953364 -0.19319 0.792248" mass="1.65084" diaginertia="0.0249189 0.00189735 0.0017126"/>
          <joint name="left_hip_yaw_joint" class="/" pos="0 0 0" axis="-0.00513019 -0.00709384 -0.999962" range="-0.686317 0.750512" armature="0.0869055" damping="0" frictionloss="0.0690826"/>
          <geom name="//unnamed_geom_7" class="visual" mesh="left_thigh_yaw_link"/>
          <body name="left_thigh_pitch_link" pos="-0.00195097 0.0160839 -0.0975237" quat="1 -2.29563e-05 6.59262e-05 0.000117179">
            <inertial pos="-0.00192628 -0.0188659 -0.0457184" quat="0.999843 -0.0142814 -0.00909904 0.00522792" mass="4.13142" diaginertia="0.0995256 0.00894848 0.00565896"/>
            <joint name="left_hip_pitch_joint" class="/" pos="0 0 0" axis="-0.00421301 0.999916 0.012286" stiffness="0.00109932" range="-1.76117 0.712103" armature="0.0779625" damping="0.0196305" frictionloss="0.0679914"/>
            <geom name="//unnamed_geom_8" class="visual" mesh="left_thigh_pitch_link"/>
            <geom name="left_thigh_pitch_link.STL" class="collision" size="0.064764 0.0986577" pos="0.000708659 -0.0190116 -0.120848" type="cylinder" rgba="0.752941 0.752941 0.752941 1"/>
            <geom name="//unnamed_geom_10" class="reward_collision_sphere" size="0.0789805" pos="0 -0.00633722 -0.0361698"/>
            <body name="left_shank_pitch_link" pos="-0.00222959 -0.0104847 -0.259204" quat="0.999999 0.00063446 0.000172377 0.00109861">
              <inertial pos="0.00356545 -0.00137388 -0.0827831" quat="0.999668 0.00236177 0.00652724 -0.0248061" mass="0.855063" diaginertia="0.0110911 0.00106468 0.000239197"/>
              <joint name="left_knee_pitch_joint" class="/" pos="0 0 0" axis="-0.0204158 0.999786 -0.00337513" stiffness="0.00663223" range="-0.0459119 1.92476" armature="0.0806348" damping="0.01383" frictionloss="0.0797629"/>
              <geom name="//unnamed_geom_11" class="visual" mesh="left_shank_pitch_link"/>
              <geom name="left_shank_pitch_link.STL" class="collision" size="0.0421135 0.0713865" pos="-1.67941e-05 -0.00053394 -0.126371" quat="0.00125538 -0.202712 0.979238 0" type="cylinder" rgba="0.752941 0.752941 0.752941 1"/>
              <geom name="//unnamed_geom_13" class="reward_collision_sphere" size="0.0394903"/>
              <geom name="//unnamed_geom_14" class="reward_collision_sphere" size="0.0473883" pos="0 0 -0.0795736"/>
              <body name="left_foot_pitch_link" pos="0.00111542 0.000691816 -0.246759" quat="0.999999 -0.000906378 -0.000944254 -0.00021678">
                <inertial pos="0.00261642 -0.00118115 -8.26085e-05" quat="-0.000522822 0.705963 -0.00200069 0.708245" mass="0.0279269" diaginertia="7.00333e-06 5.70301e-07 1.02883e-06"/>
                <joint name="left_ankle_pitch_joint" class="/" pos="0 0 0" axis="0.00909751 0.999958 -0.00109539" range="-1.07285 0.581921" armature="0.0910056" damping="0.0081008" frictionloss="0.0751339"/>
                <geom name="//unnamed_geom_15" class="visual" mesh="left_foot_pitch_link"/>
                <body name="left_foot_roll_link" pos="-0.0013177 -6.83171e-05 0.00338663" quat="1 -0.000197378 5.94589e-05 -0.000485578">
                  <inertial pos="0.0380327 -0.00407664 -0.02872" quat="0.00557564 0.727997 -0.0100613 0.685484" mass="0.510539" diaginertia="0.00569489 0.000512751 0.000140812"/>
                  <joint name="left_ankle_roll_joint" class="/" pos="0 0 0" axis="-0.999979 -6.75696e-05 0.00649483" range="-0.446493 0.46385" armature="0.0843517" damping="0" frictionloss="0.0757805"/>
                  <geom name="//unnamed_geom_16" class="visual" mesh="left_foot_roll_link"/>
                  <geom name="left_foot" class="foot" size="0.106806 0.0432916 0.00793201" pos="0.0455534 0 -0.0321911"/>
                  <geom name="//unnamed_geom_18" class="reward_collision_sphere" size="0.0394903" pos="0 0 -0.0217019"/>
                  <geom name="//unnamed_geom_19" class="reward_collision_sphere" size="0.0394903" pos="0.121476 0 -0.0217019"/>
                  <site name="left_foot" class="foot" pos="0.0455534 0 -0.0321911" size="0.00789805"/>
                </body>
              </body>
            </body>
          </body>
        </body>
      </body>
      <body name="right_thigh_roll_link" pos="-0.0336439 -0.0678046 -0.0230131" quat="1 0.000125865 -0.000842032 -0.000411067">
        <inertial pos="0.000844547 -0.00193032 0.00451928" quat="0.0259401 0.70647 0.0156991 0.707093" mass="0.676911" diaginertia="0.00263154 0.000242357 0.000311169"/>
        <joint name="right_hip_roll_joint" class="/" pos="0 0 0" axis="-0.99989 0.0144474 0.00341948" range="-0.100954 0.797785" armature="0.0750825" damping="0.00482463" frictionloss="0.0763763"/>
        <geom name="//unnamed_geom_20" class="visual" mesh="right_thigh_roll_link"/>
        <body name="right_thigh_yaw_link" pos="0.0295012 -0.00450957 -0.00116078" quat="1 -0.000266775 -0.000476723 -0.000544297">
          <inertial pos="-0.00588995 -0.0216449 -0.0804511" quat="0.686276 -0.151746 0.141395 0.697141" mass="1.76976" diaginertia="0.0250772 0.00190466 0.00172492"/>
          <joint name="right_hip_yaw_joint" class="/" pos="0 0 0" axis="-0.011523 -0.00124732 -0.999933" range="-0.662088 0.758479" armature="0.0688689" damping="0" frictionloss="0.0795097"/>
          <geom name="//unnamed_geom_21" class="visual" mesh="right_thigh_yaw_link"/>
          <body name="right_thigh_pitch_link" pos="0.00103564 -0.0158853 -0.102646" quat="1 -0.000108718 0.000231956 -1.31872e-05">
            <inertial pos="0.000920985 0.0157501 -0.0434974" quat="0.999812 -0.0143727 -0.0118564 0.00544965" mass="4.01916" diaginertia="0.0955961 0.00907918 0.00515682"/>
            <joint name="right_hip_pitch_joint" class="/" pos="0 0 0" axis="-0.0165815 -0.999774 0.0132911" range="-0.716628 1.7633" armature="0.0886972" damping="0.0199508" frictionloss="0.067791"/>
            <geom name="//unnamed_geom_22" class="visual" mesh="right_thigh_pitch_link"/>
            <geom name="right_thigh_pitch_link.STL" class="collision" size="0.064764 0.0986553" pos="-0.00214938 0.0190116 -0.120848" quat="0.999971 0.00269833 0.00706272 0" type="cylinder" rgba="0.752941 0.752941 0.752941 1"/>
            <geom name="//unnamed_geom_24" class="reward_collision_sphere" size="0.0789805" pos="0 0.00633722 -0.0361698"/>
            <body name="right_shank_pitch_link" pos="0.00183639 0.0115566 -0.260592" quat="1 0.00010116 0.000242985 -2.95741e-05">
              <inertial pos="0.00109611 -0.00305432 -0.0805426" quat="0.999726 0.00623954 0.00281433 0.0224049" mass="0.904951" diaginertia="0.0113062 0.00112295 0.000250303"/>
              <joint name="right_knee_pitch_joint" class="/" pos="0 0 0" axis="0.0211845 -0.999739 -0.00851177" stiffness="0.00271841" range="-1.92232 0.157733" armature="0.0668805" damping="0.00599376" frictionloss="0.0773718"/>
              <geom name="//unnamed_geom_25" class="visual" mesh="right_shank_pitch_link"/>
              <geom name="right_shank_pitch_link.STL" class="collision" size="0.0421133 0.0713858" pos="-1.67941e-05 -0.000533947 -0.126377" type="cylinder" rgba="0.752941 0.752941 0.752941 1"/>
              <geom name="//unnamed_geom_27" class="reward_collision_sphere" size="0.0394903"/>
              <geom name="//unnamed_geom_28" class="reward_collision_sphere" size="0.0473883" pos="0 0 -0.0795736"/>
              <body name="right_foot_pitch_link" pos="0.00219361 -0.000883503 -0.247654" quat="1 -0.000218977 0.000101647 0.000493276">
                <inertial pos="-0.000827832 0.000942368 -0.0016049" quat="-0.00138904 0.70745 -0.00166942 0.706761" mass="0.0266549" diaginertia="6.67834e-06 5.45569e-07 1.05328e-06"/>
                <joint name="right_ankle_pitch_joint" class="/" pos="0 0 0" axis="-0.00265225 -0.999996 -0.00128367" range="-0.513564 1.0311" armature="0.0873414" damping="0" frictionloss="0.0793799"/>
                <geom name="//unnamed_geom_29" class="visual" mesh="right_foot_pitch_link"/>
                <body name="right_foot_roll_link" pos="0.00276266 -0.000376555 -0.00179327" quat="1 3.72157e-05 -0.000105627 -9.71271e-05">
                  <inertial pos="0.0396056 -0.00110723 -0.0306195" quat="0.00115298 0.725018 0.00167001 0.688727" mass="0.528663" diaginertia="0.00602812 0.00054353 0.000156826"/>
                  <joint name="right_ankle_roll_joint" class="/" pos="0 0 0" axis="-0.99998 0.00441915 0.00458141" range="-0.391994 0.44941" armature="0.0874913" damping="0" frictionloss="0.079435"/>
                  <geom name="//unnamed_geom_30" class="visual" mesh="right_foot_roll_link"/>
                  <geom name="right_foot" class="foot" size="0.146698 0.0340031 0.00862185" pos="0.0455534 0 -0.0321911"/>
                  <geom name="//unnamed_geom_32" class="reward_collision_sphere" size="0.0394903" pos="0 0 -0.0217019"/>
                  <geom name="//unnamed_geom_33" class="reward_collision_sphere" size="0.0394903" pos="0.121476 0 -0.0217019"/>
                  <site name="right_foot" class="foot" pos="0.0455534 0 -0.0321911" size="0.00789805"/>
                </body>
              </body>
            </body>
          </body>
        </body>
      </body>
      <body name="waist_yaw_link" pos="0.000727156 0.00201767 0.00466474" quat="1 0.000244828 5.42693e-07 8.23152e-05">
        <inertial pos="-0.00253894 -0.00743098 0.0356288" quat="0.982315 0.175696 -0.0236451 0.0602414" mass="0.809771" diaginertia="0.00362852 0.000328933 0.000401084"/>
        <joint name="waist_yaw_joint" class="/" pos="0 0 0" axis="0.011465 0.00119656 0.999934" range="-1.07389 0.998501" armature="0.0713088" damping="0.00394181" frictionloss="0.0688781"/>
        <geom name="//unnamed_geom_34" class="visual" rgba="0.12 0.12 0.12 1" mesh="waist_yaw_link"/>
        <body name="waist_pitch_link" pos="0.00109687 -0.00247649 0.0643427" quat="0.999999 0.000166468 0.000837384 -0.000602551">
          <inertial pos="0.00174776 0.000902551 0.0316455" quat="0.997562 -0.0418515 0.0546316 0.0115622" mass="0.736546" diaginertia="0.00494558 0.000459888 0.000372273"/>
          <joint name="waist_pitch_joint" class="/" pos="0 0 0" axis="-0.000440285 -0.99937 0.0354928" range="-1.23951 0.495489" armature="0.0707319" damping="0" frictionloss="0.0745697"/>
          <geom name="//unnamed_geom_35" class="visual" rgba="0.12 0.12 0.12 1" mesh="waist_pitch_link"/>
          <body name="waist_roll_link" pos="0.0117058 -0.000102012 0.0608504" quat="1 -0.000492617 -0.000226578 0.000360426">
            <inertial pos="-0.0108294 -0.0024572 0.108627" quat="0.998733 -0.00238319 -0.0502512 0.000794218" mass="3.35635" diaginertia="0.0644068 0.00625436 0.00696142"/>
            <joint name="waist_roll_joint" class="/" pos="0 0 0" axis="-0.999992 -0.00387794 -0.000979305" stiffness="0.00183442" range="-0.743503 0.719417" armature="0.0695337" damping="0.0255798" frictionloss="0.0678545"/>
            <geom name="//unnamed_geom_36" class="visual" rgba="0.12 0.12 0.12 1" mesh="waist_roll_link"/>
            <geom name="//unnamed_geom_37" class="visual" pos="-0.00227767 0.000364029 0.115997" quat="1 0 0 0" mesh="torso_link"/>
            <geom name="torso_link.STL" class="collision" size="0.124337 0.0238466" pos="-0.0182881 0.00365645 0.106939" type="cylinder" rgba="0.752941 0.752941 0.752941 1"/>
            <geom name="//unnamed_geom_39" class="reward_collision_sphere" size="0.102675" pos="0 0 0.144679"/>
            <body name="left_upper_arm_pitch_link" pos="-0.000606928 0.0650165 0.14951" quat="0.976675 0.214725 -2.78759e-05 4.66606e-05">
              <inertial pos="0.00352258 0.0358991 0.000441544" quat="0.71369 0.698389 0.0080938 -0.0532272" mass="0.402764" diaginertia="0.00220531 0.000200367 9.78915e-05"/>
              <joint name="left_shoulder_pitch_joint" class="/" pos="0 0 0" axis="4.7544e-07 1 3.11284e-05" range="-2.7358 1.97719" armature="0.0918624" damping="0.0200067" frictionloss="0.0795879"/>
              <geom name="//unnamed_geom_40" class="visual" mesh="left_upper_arm_pitch_link"/>
              <body name="left_upper_arm_roll_link" pos="0.00314101 0.0577767 0.00278535" quat="0.976672 -0.214738 0.000106918 6.96863e-05">
                <inertial pos="0.00441764 0.00820905 -0.0172796" quat="0.894707 0.265362 0.118501 -0.339175" mass="0.315571" diaginertia="0.00113465 0.000106555 6.83339e-05"/>
                <joint name="left_shoulder_roll_joint" class="/" pos="0 0 0" axis="-0.999979 5.3414e-06 0.00655226" range="-2.55433 0.586099" armature="0.0761039" damping="0.00486965" frictionloss="0.0877318"/>
                <geom name="//unnamed_geom_41" class="visual" mesh="left_upper_arm_roll_link"/>
                <body name="left_upper_arm_yaw_link" pos="0.00353139 0.0223786 -0.0523447" quat="0.999999 -0.000781766 0.000714361 0.000503754">
                  <inertial pos="0.000672616 -0.00383203 -0.0610171" quat="0.99994 0.00777456 0.000293156 -0.00770379" mass="0.274846" diaginertia="0.00402031 0.000386991 5.36648e-05"/>
                  <joint name="left_shoulder_yaw_joint" class="/" pos="0 0 0" axis="0.000146633 0.00127787 0.999999" range="-2.97536 3.02729" armature="0.0781397" damping="0.00283176" frictionloss="0.0788906"/>
                  <geom name="//unnamed_geom_42" class="visual" mesh="left_upper_arm_yaw_link"/>
                  <geom name="left_upper_arm_yaw_link.STL" class="collision" size="0.0286172 0.0670876" pos="3.99709e-05 -0.000566731 -0.0573943" quat="0.00803418 -0.995528 0.0941277 0" type="cylinder" rgba="0.752941 0.752941 0.752941 1"/>
                  <body name="left_lower_arm_pitch_link" pos="0.000322218 0.00217966 -0.129244" quat="1 -2.1476e-05 0.000527105 -0.00016462">
                    <inertial pos="0.0010732 0.00606377 -0.020102" quat="0.702612 -0.0975696 0.0883244 0.699297" mass="0.158247" diaginertia="0.000320648 3.0333e-05 1.89396e-05"/>
                    <joint name="left_elbow_pitch_joint" class="/" pos="0 0 0" axis="-2.77908e-05 1 4.64123e-05" range="-2.31363 2.33159" armature="0.0824017" damping="0" frictionloss="0.0815328"/>
                    <geom name="//unnamed_geom_44" class="visual" mesh="left_lower_arm_pitch_link"/>
                    <body name="left_hand_yaw_link" pos="0.000590675 -0.000201484 -0.0414123" quat="1 -0.000118164 -0.000150264 -0.000239572">
                      <inertial pos="-3.30823e-05 0.000135095 -0.0499828" quat="0.999929 -0.00253677 0.000227465 0.0116123" mass="0.507374" diaginertia="0.00280612 0.000266161 9.99323e-05"/>
                      <joint name="left_wrist_yaw_joint" class="/" pos="0 0 0" axis="-0.00288865 -0.00119581 0.999995" range="-2.93108 2.92769" armature="0.0767739" damping="0.0206661" frictionloss="0.0784489"/>
                      <geom name="//unnamed_geom_45" class="visual" mesh="left_hand_yaw_link"/>
                      <geom name="left_hand_yaw_link.STL" class="collision" size="0.0328337 0.0549655" pos="0.00110264 -0.000976635 -0.0550092" type="cylinder" rgba="0.752941 0.752941 0.752941 1"/>
                      <geom name="//unnamed_geom_47" class="reward_collision_sphere" size="0.0394903"/>
                      <body name="left_hand_roll_link" pos="0.00250105 -0.000980977 -0.13626" quat="1 1.35861e-05 9.83767e-05 5.89728e-06">
                        <inertial pos="-0.00130598 -0.00323198 0.00017884" quat="0.500778 0.49789 0.501405 0.49992" mass="0.00254021" diaginertia="3.62858e-07 3.66073e-08 1.37653e-08"/>
                        <joint name="left_wrist_roll_joint" class="/" pos="0 0 0" axis="-0.999988 -0.000300127 0.00497524" range="-0.958722 0.816778" armature="0.0691923" damping="0" frictionloss="0.0678338"/>
                        <geom name="//unnamed_geom_48" class="visual" mesh="left_hand_roll_link"/>
                        <body name="left_hand_pitch_link" pos="-0.00269459 -0.00070154 -0.000204361" quat="0.999999 0.000734134 -0.000816554 0.000907906">
                          <inertial pos="-0.00321113 -0.00680128 -0.0382739" quat="0.725353 -0.119012 0.100747 0.670484" mass="0.106307" diaginertia="0.000298713 2.71339e-05 1.84372e-05"/>
                          <joint name="left_wrist_pitch_joint" class="/" pos="0 0 0" axis="0.00091542 0.999999 -0.0012766" range="-0.598929 0.560481" armature="0.0800112" damping="0" frictionloss="0.0899852"/>
                          <geom name="//unnamed_geom_49" class="visual" mesh="left_hand_pitch"/>
                          <body name="left_jaw_link" pos="-4.8148e-05 0.000120093 -0.0447475" quat="1 5.91501e-07 1.78536e-05 2.30615e-05">
                            <inertial pos="-0.00158726 0.00419409 -0.0279772" quat="0.707559 -0.0240617 0.0333994 0.705455" mass="0.0352666" diaginertia="8.07634e-05 5.86854e-06 6.36562e-06"/>
                            <joint name="left_jaw_joint" class="/" pos="0 0 0" axis="-0.999985 -0.00483749 -0.00244268" range="-0.930376 -0.0115875" armature="0.0914382" damping="0.0211847" frictionloss="0.0795807"/>
                            <geom name="//unnamed_geom_50" class="visual" mesh="left_jaw_link"/>
                            <geom name="//unnamed_geom_51" class="collision" size="0.028433"/>
                            <geom name="//unnamed_geom_52" class="reward_collision_sphere" size="0.0394903" pos="0 0 -0.0144679"/>
                          </body>
                        </body>
                      </body>
                    </body>
                  </body>
                </body>
              </body>
            </body>
            <body name="right_upper_arm_pitch_link" pos="-0.00341629 -0.0654536 0.149938" quat="0.976678 -0.214709 0.0001597 -7.8126e-05">
              <inertial pos="0.00243872 -0.0350097 -0.000586923" quat="0.708316 0.705013 0.0173883 0.0306967" mass="0.410766" diaginertia="0.00209538 0.000203406 9.4109e-05"/>
              <joint name="right_shoulder_pitch_joint" class="/" pos="0 0 0" axis="0.00466972 -0.999988 -0.00140242" range="-1.93839 2.79618" armature="0.0769688" damping="0" frictionloss="0.0778966"/>
              <geom name="//unnamed_geom_53" class="visual" mesh="right_upper_arm_pitch_link"/>
              <body name="right_upper_arm_roll_link" pos="-0.000649255 -0.0628951 0.00288663" quat="0.976641 0.214878 -0.000187002 0.000414348">
                <inertial pos="0.00181968 -0.0115833 -0.0175264" quat="0.888782 -0.26945 0.126949 0.34835" mass="0.29952" diaginertia="0.0011008 9.89711e-05 7.02452e-05"/>
                <joint name="right_shoulder_roll_joint" class="/" pos="0 0 0" axis="-1 0.000291156 -0.000568479" range="-0.57484 2.48628" armature="0.0722718" damping="0" frictionloss="0.0702008"/>
                <geom name="//unnamed_geom_54" class="visual" mesh="right_upper_arm_roll_link"/>
                <body name="right_upper_arm_yaw_link" pos="-0.00126057 -0.0230885 -0.0515852" quat="0.999999 0.00093955 -0.000706848 -0.00057084">
                  <inertial pos="-0.00309157 0.00154401 -0.0649067" quat="0.999955 -0.00854274 -0.00309729 -0.00259938" mass="0.270552" diaginertia="0.00378927 0.000376202 5.26155e-05"/>
                  <joint name="right_shoulder_yaw_joint" class="/" pos="0 0 0" axis="0.000335103 0.00450296 0.99999" range="-2.91201 2.92454" armature="0.0841295" damping="0" frictionloss="0.0719532"/>
                  <geom name="//unnamed_geom_55" class="visual" mesh="right_upper_arm_yaw_link"/>
                  <geom name="right_upper_arm_yaw_link.STL" class="collision" size="0.0286172 0.0670876" pos="3.99709e-05 0.000566731 -0.0573943" type="cylinder" rgba="0.752941 0.752941 0.752941 1"/>
                  <body name="right_lower_arm_pitch_link" pos="0.00294491 0.00271926 -0.130889" quat="1 6.69607e-06 4.78541e-05 -3.80928e-05">
                    <inertial pos="-0.00289163 -0.00816497 -0.0185429" quat="0.706378 0.0999199 -0.0825445 0.695868" mass="0.163484" diaginertia="0.000323895 3.00303e-05 1.91187e-05"/>
                    <joint name="right_elbow_pitch_joint" class="/" pos="0 0 0" axis="-0.00617454 -0.999957 -0.00695167" range="-2.3175 2.3125" armature="0.0693997" damping="0.00504748" frictionloss="0.0788605"/>
                    <geom name="//unnamed_geom_57" class="visual" mesh="right_lower_arm_pitch_link"/>
                    <body name="right_hand_yaw_link" pos="0.00310394 0.00046552 -0.0435936" quat="0.999999 0.000522372 0.00042928 0.0012217">
                      <inertial pos="-0.00276161 -0.000341494 -0.0532823" quat="0.999715 0.000851335 0.000227293 0.0238467" mass="0.499349" diaginertia="0.00282887 0.000246943 9.98504e-05"/>
                      <joint name="right_wrist_yaw_joint" class="/" pos="0 0 0" axis="-0.000526773 -0.00341069 0.999994" range="-2.95657 2.99329" armature="0.0891751" damping="0" frictionloss="0.0706401"/>
                      <geom name="//unnamed_geom_58" class="visual" mesh="right_hand_yaw_link"/>
                      <geom name="right_hand_yaw_link.STL" class="collision" size="0.0328337 0.0549655" pos="0.00110264 0.000406288 -0.0550092" type="cylinder" rgba="0.752941 0.752941 0.752941 1"/>
                      <geom name="//unnamed_geom_60" class="reward_collision_sphere" size="0.0394903"/>
                      <body name="right_hand_roll_link" pos="-0.000344063 0.00319014 -0.141126" quat="1 0.000247109 -6.04766e-05 9.41238e-05">
                        <inertial pos="0.00013219 -0.00101654 0.00260236" quat="0.492182 0.504189 0.500524 0.503016" mass="0.00249251" diaginertia="3.80471e-07 3.72505e-08 1.43478e-08"/>
                        <joint name="right_wrist_roll_joint" class="/" pos="0 0 0" axis="-0.999986 -0.000641241 -0.0052649" range="-0.884475 0.939216" armature="0.0715279" damping="0.0150067" frictionloss="0.0762944"/>
                        <geom name="//unnamed_geom_61" class="visual" mesh="right_hand_roll_link"/>
                        <body name="right_hand_pitch_link" pos="0.00351737 2.93452e-05 -0.00149507" quat="1 -2.2993e-05 -2.04005e-05 0.000484839">
                          <inertial pos="-6.06358e-05 0.00643218 -0.039729" quat="0.724274 0.120462 -0.112911 0.669453" mass="0.104949" diaginertia="0.000298088 2.63199e-05 1.83821e-05"/>
                          <joint name="right_wrist_pitch_joint" class="/" pos="0 0 0" axis="-0.00287208 -0.999986 -0.0044324" range="-0.572831 0.571665" armature="0.0709193" damping="0.00150115" frictionloss="0.0706024"/>
                          <geom name="//unnamed_geom_62" class="visual" mesh="right_hand_pitch"/>
                          <body name="right_jaw_link" pos="6.19846e-05 -0.000286919 -0.0447961" quat="1 0.000125793 -0.000169093 -0.000133014">
                            <inertial pos="-0.00311606 -0.000505694 -0.0252768" quat="0.70762 0.0214266 -0.0303817 0.705615" mass="0.0353365" diaginertia="8.5427e-05 5.4958e-06 6.19121e-06"/>
                            <joint name="right_jaw_joint" class="/" pos="0 0 0" axis="-0.999992 -0.00242484 -0.00306855" range="0.0127341 1.06119" armature="0.0910532" damping="0.00810976" frictionloss="0.070657"/>
                            <geom name="//unnamed_geom_63" class="visual" mesh="right_jaw_link"/>
                            <geom name="//unnamed_geom_64" class="collision" size="0.028433"/>
                            <geom name="//unnamed_geom_65" class="reward_collision_sphere" size="0.0394903" pos="0 0 -0.0144679"/>
                          </body>
                        </body>
                      </body>
                    </body>
                  </body>
                </body>
              </body>
            </body>
            <body name="head_roll_link" pos="-0.000872398 -0.002821 0.221637" quat="1 5.60666e-05 0.000120352 -5.00988e-05">
              <inertial pos="0.00109533 -0.00129564 -0.00318707" quat="-0.00160733 0.716474 -0.00154524 0.69761" mass="0.00499399" diaginertia="7.65721e-07 4.45332e-08 8.46122e-08"/>
              <joint name="head_roll_joint" class="/" pos="0 0 0" axis="-0.999997 -0.00191426 0.00176623" range="-0.384992 0.349959" armature="0.0840809" damping="0.00108894" frictionloss="0.0788146"/>
              <geom name="//unnamed_geom_66" class="visual" mesh="head_roll_link"/>
              <body name="head_pitch_link" pos="-0.00295219 0.000385777 0.00420519" quat="1 0.000736296 0.0005868 0.000104061">
                <inertial pos="-0.00241899 -0.00125396 0.0115098" quat="0.668843 0.661507 0.238447 -0.241248" mass="0.0287795" diaginertia="2.77517e-05 2.48612e-06 3.26591e-06"/>
                <joint name="head_pitch_joint" class="/" pos="0 0 0" axis="-0.00744625 -0.999959 0.00507667" stiffness="0.00439057" range="-0.808199 0.886291" armature="0.0814008" damping="0.0101529" frictionloss="0.0900718"/>
                <geom name="//unnamed_geom_67" class="visual" mesh="head_pitch_link"/>
                <body name="head_yaw_link" pos="0.000170072 0.0017305 0.0380905" quat="1 -0.000145684 2.6959e-05 0.000372384">
                  <inertial pos="0.0272199 -0.00466207 0.0674427" quat="0.709299 -0.134344 -0.145167 0.676589" mass="0.757291" diaginertia="0.010074 0.00079109 0.000991319"/>
                  <joint name="head_yaw_joint" class="/" pos="0 0 0" axis="-0.00697933 -0.00655739 0.999954" range="-2.70704 2.6883" armature="0.0769831" damping="0.0155454" frictionloss="0.0757356"/>
                  <geom name="//unnamed_geom_68" class="visual" rgba="0.12 0.12 0.12 1" mesh="head_yaw_link"/>
                  <geom name="head_yaw_link.STL" class="collision" size="0.0937396" pos="0.0185059 -0.00055769 0.0677245" rgba="0.752941 0.752941 0.752941 1"/>
                  <geom name="//unnamed_geom_70" class="reward_collision_sphere" size="0.0789805" pos="0.0303689 0 0.0723397"/>
                  <camera name="ego_camera" class="/" pos="0.111353 0 0.0795736" quat="-0.5 -0.5 0.5 0.5"/>
                </body>
              </body>
            </body>
          </body>
        </body>
      </body>
    </body>
  </worldbody>

  <contact>
    <pair class="/" geom1="floor" geom2="left_foot" name="//unnamed_contact_0"/>
    <pair class="/" geom1="floor" geom2="right_foot" name="//unnamed_contact_1"/>
  </contact>

  <actuator>
    <general name="left_hip_roll" class="/" joint="left_hip_roll_joint" forcerange="-34.7085 34.7085" gainprm="73.349" biasprm="0 -73.349 -1.24526"/>
    <general name="left_hip_yaw" class="/" joint="left_hip_yaw_joint" forcerange="-48.7091 48.7091" gainprm="73.349" biasprm="0 -73.349 -1.24526"/>
    <general name="left_hip_pitch" class="/" joint="left_hip_pitch_joint" forcerange="-191.99 191.99" gainprm="73.349" biasprm="0 -73.349 -1.24526"/>
    <general name="left_knee_pitch" class="/" joint="left_knee_pitch_joint" forcerange="-186.205 186.205" gainprm="73.349" biasprm="0 -73.349 -1.24526"/>
    <general name="left_ankle_pitch" class="/" joint="left_ankle_pitch_joint" forcerange="-11.7655 11.7655" gainprm="73.349" biasprm="0 -73.349 -1.24526"/>
    <general name="left_ankle_roll" class="/" joint="left_ankle_roll_joint" forcerange="-26.1363 26.1363" gainprm="73.349" biasprm="0 -73.349 -1.24526"/>
    <general name="right_hip_roll" class="/" joint="right_hip_roll_joint" forcerange="-36.2665 36.2665" gainprm="73.349" biasprm="0 -73.349 -1.24526"/>
    <general name="right_hip_yaw" class="/" joint="right_hip_yaw_joint" forcerange="-47.2545 47.2545" gainprm="73.349" biasprm="0 -73.349 -1.24526"/>
    <general name="right_hip_pitch" class="/" joint="right_hip_pitch_joint" forcerange="-170.042 170.042" gainprm="73.349" biasprm="0 -73.349 -1.24526"/>
    <general name="right_knee_pitch" class="/" joint="right_knee_pitch_joint" forcerange="-182.98 182.98" gainprm="73.349" biasprm="0 -73.349 -1.24526"/>
    <general name="right_ankle_pitch" class="/" joint="right_ankle_pitch_joint" forcerange="-11.9123 11.9123" gainprm="73.349" biasprm="0 -73.349 -1.24526"/>
    <general name="right_ankle_roll" class="/" joint="right_ankle_roll_joint" forcerange="-21.1583 21.1583" gainprm="73.349" biasprm="0 -73.349 -1.24526"/>
    <general name="waist_yaw" class="/" joint="waist_yaw_joint" forcerange="-53.1183 53.1183" gainprm="73.349" biasprm="0 -73.349 -1.24526"/>
    <general name="waist_pitch" class="/" joint="waist_pitch_joint" forcerange="-60.8987 60.8987" gainprm="73.349" biasprm="0 -73.349 -1.24526"/>
    <general name="waist_roll" class="/" joint="waist_roll_joint" forcerange="-47.7353 47.7353" gainprm="73.349" biasprm="0 -73.349 -1.24526"/>
    <general name="left_shoulder_pitch" class="/" joint="left_shoulder_pitch_joint" forcerange="-29.9458 29.9458" gainprm="73.349" biasprm="0 -73.349 -1.24526"/>
    <general name="left_shoulder_roll" class="/" joint="left_shoulder_roll_joint" forcerange="-27.5096 27.5096" gainprm="73.349" biasprm="0 -73.349 -1.24526"/>
    <general name="left_shoulder_yaw" class="/" joint="left_shoulder_yaw_joint" forcerange="-23.5312 23.5312" gainprm="73.349" biasprm="0 -73.349 -1.24526"/>
    <general name="left_elbow_pitch" class="/" joint="left_elbow_pitch_joint" forcerange="-26.463 26.463" gainprm="73.349" biasprm="0 -73.349 -1.24526"/>
    <general name="left_wrist_yaw" class="/" joint="left_wrist_yaw_joint" forcerange="-8.1623 8.1623" gainprm="73.349" biasprm="0 -73.349 -1.24526"/>
    <general name="left_wrist_roll" class="/" joint="left_wrist_roll_joint" forcerange="-3.06274 3.06274" gainprm="73.349" biasprm="0 -73.349 -1.24526"/>
    <general name="left_wrist_pitch" class="/" joint="left_wrist_pitch_joint" forcerange="-3.44895 3.44895" gainprm="73.349" biasprm="0 -73.349 -1.24526"/>
    <general name="left_jaw" class="/" joint="left_jaw_joint" forcerange="-3.21297 3.21297" gainprm="73.349" biasprm="0 -73.349 -1.24526"/>
    <general name="right_shoulder_pitch" class="/" joint="right_shoulder_pitch_joint" forcerange="-30.384 30.384" gainprm="73.349" biasprm="0 -73.349 -1.24526"/>
    <general name="right_shoulder_roll" class="/" joint="right_shoulder_roll_joint" forcerange="-27.8135 27.8135" gainprm="73.349" biasprm="0 -73.349 -1.24526"/>
    <general name="right_shoulder_yaw" class="/" joint="right_shoulder_yaw_joint" forcerange="-24.4359 24.4359" gainprm="73.349" biasprm="0 -73.349 -1.24526"/>
    <general name="right_elbow_pitch" class="/" joint="right_elbow_pitch_joint" forcerange="-23.3739 23.3739" gainprm="73.349" biasprm="0 -73.349 -1.24526"/>
    <general name="right_wrist_yaw" class="/" joint="right_wrist_yaw_joint" forcerange="-7.76253 7.76253" gainprm="73.349" biasprm="0 -73.349 -1.24526"/>
    <general name="right_wrist_roll" class="/" joint="right_wrist_roll_joint" forcerange="-3.1059 3.1059" gainprm="73.349" biasprm="0 -73.349 -1.24526"/>
    <general name="right_wrist_pitch" class="/" joint="right_wrist_pitch_joint" forcerange="-3.06343 3.06343" gainprm="73.349" biasprm="0 -73.349 -1.24526"/>
    <general name="right_jaw" class="/" joint="right_jaw_joint" forcerange="-2.8476 2.8476" gainprm="73.349" biasprm="0 -73.349 -1.24526"/>
    <general name="head_roll" class="/" joint="head_roll_joint" forcerange="-2.79246 2.79246" gainprm="73.349" biasprm="0 -73.349 -1.24526"/>
    <general name="head_pitch" class="/" joint="head_pitch_joint" forcerange="-3.27805 3.27805" gainprm="73.349" biasprm="0 -73.349 -1.24526"/>
    <general name="head_yaw" class="/" joint="head_yaw_joint" forcerange="-3.45099 3.45099" gainprm="73.349" biasprm="0 -73.349 -1.24526"/>
  </actuator>

  <sensor>
    <gyro site="imu" name="imu_angular_velocity"/>
    <velocimeter site="imu" name="imu_linear_velocity"/>
    <framelinvel objtype="site" objname="left_foot" name="left_foot_global_linear_velocity"/>
    <framelinvel objtype="site" objname="right_foot" name="right_foot_global_linear_velocity"/>
  </sensor>

  <keyframe>
    <key name="home" qpos="0 0 0.8665 1 0 0 0 0 0 -0.4 0.8 -0.4 0 0 0 0.4 -0.8 0.4 0 0 0 0 0 -0.2 0 -0.785 0 0 0 0 0 0.2 0 0.785 0 0 0 0 0 0 0"/>
  </keyframe>
</mujoco>
