<mujoco model="GR1T2_jaw">
  <compiler angle="radian" assetdir="assets" balanceinertia="true" inertiafromgeom="false"/>

  <option timestep="0.005" density="1.2" viscosity="2e-05"/>

  <size nkey="1"/>

  <visual>
    <quality shadowsize="8192"/>
    <map shadowclip="0.5"/>
  </visual>

  <default>
    <default class="/">
      <joint armature="0.1" damping="0.01" frictionloss="0.1"/>
      <geom contype="0" conaffinity="0" group="1" solref="-1000 -80"/>
      <site size="0.01 0.005 0.005" group="5"/>
      <general forcelimited="true" biastype="affine" gainprm="80" biasprm="0 -80 -2"/>
      <default class="visual">
        <geom type="mesh" density="0" rgba="0.18 0.18 0.18 1"/>
      </default>
      <default class="collision">
        <geom group="3"/>
      </default>
      <default class="foot">
        <geom size="0.126 0.045 0.01" type="box" condim="6" group="4" priority="1" solimp="0.015 1 0.01"/>
      </default>
      <default class="reward_collision_sphere">
        <geom group="5" rgba="1 0 0 1"/>
      </default>
    </default>
  </default>

  <asset>
    <texture type="skybox" colorspace="auto" name="//unnamed_texture_0" builtin="gradient" rgb1="0.95 0.95 0.95" rgb2="0.95 0.95 0.95" width="100" height="600"/>
    <texture type="2d" colorspace="auto" name="texplane" builtin="checker" rgb1="0.345 0.575 0.748" rgb2="0.345 0.575 0.748" markrgb="1 1 1" width="512" height="512"/>
    <material name="MatPlane" class="/" texture="texplane" texuniform="true" texrepeat="2 2" specular="0.9"/>
    <mesh name="base_link" class="/" file="base_link.STL"/>
    <mesh name="left_thigh_roll_link" class="/" file="left_thigh_roll_link.STL"/>
    <mesh name="left_thigh_yaw_link" class="/" file="left_thigh_yaw_link.STL"/>
    <mesh name="left_thigh_pitch_link" class="/" file="left_thigh_pitch_link.STL"/>
    <mesh name="left_shank_pitch_link" class="/" file="left_shank_pitch_link.STL"/>
    <mesh name="left_foot_pitch_link" class="/" file="left_foot_pitch_link.STL"/>
    <mesh name="left_foot_roll_link" class="/" file="left_foot_roll_link.STL"/>
    <mesh name="right_thigh_roll_link" class="/" file="right_thigh_roll_link.STL"/>
    <mesh name="right_thigh_yaw_link" class="/" file="right_thigh_yaw_link.STL"/>
    <mesh name="right_thigh_pitch_link" class="/" file="right_thigh_pitch_link.STL"/>
    <mesh name="right_shank_pitch_link" class="/" file="right_shank_pitch_link.STL"/>
    <mesh name="right_foot_pitch_link" class="/" file="right_foot_pitch_link.STL"/>
    <mesh name="right_foot_roll_link" class="/" file="right_foot_roll_link.STL"/>
    <mesh name="waist_yaw_link" class="/" file="waist_yaw_link.STL"/>
    <mesh name="waist_pitch_link" class="/" file="waist_pitch_link.STL"/>
    <mesh name="waist_roll_link" class="/" file="waist_roll_link.STL"/>
    <mesh name="torso_link" class="/" file="torso_link.STL"/>
    <mesh name="left_upper_arm_pitch_link" class="/" file="left_upper_arm_pitch_link.STL"/>
    <mesh name="left_upper_arm_roll_link" class="/" file="left_upper_arm_roll_link.STL"/>
    <mesh name="left_upper_arm_yaw_link" class="/" file="left_upper_arm_yaw_link.STL"/>
    <mesh name="left_lower_arm_pitch_link" class="/" file="left_lower_arm_pitch_link.STL"/>
    <mesh name="left_hand_yaw_link" class="/" file="left_hand_yaw_link.STL"/>
    <mesh name="left_hand_roll_link" class="/" file="left_hand_roll_link.STL"/>
    <mesh name="left_hand_pitch" class="/" file="left_hand_pitch.STL"/>
    <mesh name="left_jaw_link" class="/" file="left_jaw_link.STL"/>
    <mesh name="right_upper_arm_pitch_link" class="/" file="right_upper_arm_pitch_link.STL"/>
    <mesh name="right_upper_arm_roll_link" class="/" file="right_upper_arm_roll_link.STL"/>
    <mesh name="right_upper_arm_yaw_link" class="/" file="right_upper_arm_yaw_link.STL"/>
    <mesh name="right_lower_arm_pitch_link" class="/" file="right_lower_arm_pitch_link.STL"/>
    <mesh name="right_hand_yaw_link" class="/" file="right_hand_yaw_link.STL"/>
    <mesh name="right_hand_roll_link" class="/" file="right_hand_roll_link.STL"/>
    <mesh name="right_hand_pitch" class="/" file="right_hand_pitch.STL"/>
    <mesh name="right_jaw_link" class="/" file="right_jaw_link.STL"/>
    <mesh name="head_roll_link" class="/" file="head_roll_link.STL"/>
    <mesh name="head_pitch_link" class="/" file="head_pitch_link.STL"/>
    <mesh name="head_yaw_link" class="/" file="head_yaw_link.STL"/>
    <mesh name="imu_link" class="/" file="imu_link.STL"/>
  </asset>

  <worldbody>
    <geom name="floor" class="/" size="100 100 0.125" type="plane" group="0" material="MatPlane"/>
    <light name="toplight_shadow" class="/" pos="0 0 5" dir="0.0990148 0.0990148 -0.990148" type="directional" ambient="0.04 0.04 0.04" diffuse="0.55 0.55 0.55" specular="0.12 0.12 0.12"/>
    <light name="toplight_fill" class="/" pos="0 0 5" dir="0.0990148 0.0990148 -0.990148" type="directional" castshadow="false" ambient="0.04 0.04 0.04" diffuse="0.3 0.3 0.3" specular="0.08 0.08 0.08"/>
    <body name="trunk" pos="-0.0124237 -0.0129472 -0.00660787" quat="0.999999 -0.000619275 0.0004369 0.0015427">
      <inertial pos="-0.0397767 -0.00383081 -0.000296432" quat="1 0.000113704 2.17722e-06 0.000102742" mass="4.84735" diaginertia="0.0270204 0.125646 0.00365789"/>
      <joint name="//unnamed_joint_0" type="free"/>
      <geom name="//unnamed_geom_1" class="visual" rgba="0.12 0.12 0.12 1" mesh="base_link"/>
      <geom name="base_link.STL" class="collision" size="0.123565 0.0692065" pos="-0.0378894 0.000563172 0.0056828" quat="0.706838 -0.707359 0.00477667 0" type="cylinder" rgba="0.752941 0.752941 0.752941 1"/>
      <geom name="//unnamed_geom_3" class="visual" pos="0 0 -0.0367744" quat="1 0 0 0" rgba="0.12 0.12 0.12 1" mesh="imu_link"/>
      <geom name="//unnamed_geom_4" class="reward_collision_sphere" size="0.0807656" pos="0 0.152191 0.0617019"/>
      <geom name="//unnamed_geom_5" class="reward_collision_sphere" size="0.0807656" pos="0 -0.152191 0.0617019"/>
      <site name="imu" class="/" pos="-0.0747369 -0.0427954 -0.0172449" size="0.0100957"/>
      <camera name="track" class="/" pos="0 -3.04383 0" quat="0.707107 0.707107 0 0" mode="trackcom"/>
      <body name="left_thigh_roll_link" pos="-0.0376364 0.174186 -0.0319319" quat="0.999999 0.000815816 0.000855693 -0.000701366">
        <inertial pos="-0.000232935 -0.00665444 0.0123359" quat="0.034125 0.69379 -0.0508501 0.717569" mass="1.23317" diaginertia="0.00142516 0.0224394 0.00015001"/>
        <joint name="left_hip_roll_joint" class="/" pos="0 0 0" axis="-0.999612 -0.0112119 -0.025497" range="-0.529146 -0.0304445" armature="0.101835" damping="0" frictionloss="0.176601"/>
        <geom name="//unnamed_geom_6" class="visual" mesh="left_thigh_roll_link"/>
        <body name="left_thigh_yaw_link" pos="0.0290989 -0.012701 0.00136582" quat="1 -1.61256e-05 2.5285e-06 0.000137932">
          <inertial pos="-0.0149792 0.0554629 -0.0530623" quat="0.564184 0.0830234 -0.163212 0.805087" mass="3.66093" diaginertia="0.0154902 0.165406 0.000755706"/>
          <joint name="left_hip_yaw_joint" class="/" pos="0 0 0" axis="-0.017432 -0.00105455 -0.999847" range="-0.870897 0.674016" armature="0.0949946" damping="0" frictionloss="0.0851639"/>
          <geom name="//unnamed_geom_7" class="visual" mesh="left_thigh_yaw_link"/>
          <body name="left_thigh_pitch_link" pos="-0.0131442 0.0216393 -0.0983673" quat="0.999997 0.00191264 0.000116272 0.00129752">
            <inertial pos="-0.00339344 -0.0340932 -0.0398103" quat="0.999051 -0.0178532 -0.0393612 -0.00536622" mass="10.552" diaginertia="0.0612427 0.739845 0.00307541"/>
            <joint name="left_hip_pitch_joint" class="/" pos="0 0 0" axis="0.0194525 0.999799 0.00480008" range="-1.98453 0.723555" armature="0.0394246" damping="0.0589125" frictionloss="0.103711"/>
            <geom name="//unnamed_geom_8" class="visual" mesh="left_thigh_pitch_link"/>
            <geom name="left_thigh_pitch_link.STL" class="collision" size="0.0827848 0.126109" pos="0.000622891 -0.0456574 -0.103077" type="cylinder" rgba="0.752941 0.752941 0.752941 1"/>
            <geom name="//unnamed_geom_10" class="reward_collision_sphere" size="0.100957" pos="0 -0.0152191 -0.030851"/>
            <body name="left_shank_pitch_link" pos="-0.00413926 -0.0307645 -0.214833" quat="1 3.10916e-05 -0.000115963 0.000104425">
              <inertial pos="0.0086132 -0.000766245 -0.0719043" quat="0.997236 0.0266911 0.0189538 -0.0667044" mass="1.81209" diaginertia="0.00512836 0.0969971 0.00010157"/>
              <joint name="left_knee_pitch_joint" class="/" pos="0 0 0" axis="-0.0172862 0.99934 0.031949" range="-0.101175 1.89709" armature="0.102185" damping="0.000593717" frictionloss="0.102806"/>
              <geom name="//unnamed_geom_11" class="visual" mesh="left_shank_pitch_link"/>
              <geom name="left_shank_pitch_link.STL" class="collision" size="0.0538317 0.09125" pos="-1.47615e-05 -0.00128228 -0.107788" quat="0.00125538 -0.202712 0.979238 0" type="cylinder" rgba="0.752941 0.752941 0.752941 1"/>
              <geom name="//unnamed_geom_13" class="reward_collision_sphere" size="0.0504785"/>
              <geom name="//unnamed_geom_14" class="reward_collision_sphere" size="0.0605742" pos="0 0 -0.0678721"/>
              <body name="left_foot_pitch_link" pos="-0.00435374 -0.00567853 -0.201682" quat="1 -3.39686e-05 -0.000207139 -1.77964e-05">
                <inertial pos="0.00551897 -0.0139745 3.54395e-05" quat="0.00154016 0.713891 0.00109095 0.700254" mass="0.0544175" diaginertia="3.48357e-06 4.40603e-05 4.84231e-07"/>
                <joint name="left_ankle_pitch_joint" class="/" pos="0 0 0" axis="0.00628177 0.999777 -0.0201719" stiffness="0.0235364" range="-0.824501 0.710163" armature="0.127362" damping="0" frictionloss="0.11342"/>
                <geom name="//unnamed_geom_15" class="visual" mesh="left_foot_pitch_link"/>
                <body name="left_foot_roll_link" pos="0.0052676 -0.00996714 0.00735691" quat="0.99999 0.000171249 -0.000514849 0.00433131">
                  <inertial pos="0.0323276 -0.000381441 -0.0336139" quat="-0.00853255 0.730673 -0.00932999 0.68261" mass="1.00758" diaginertia="0.00231244 0.034477 4.53897e-05"/>
                  <joint name="left_ankle_roll_joint" class="/" pos="0 0 0" axis="-0.999998 0.00179262 -0.00020179" stiffness="0.0461345" range="-0.201878 0.688748" armature="0.0536413" damping="0.0438787" frictionloss="0.0677542"/>
                  <geom name="//unnamed_geom_16" class="visual" mesh="left_foot_roll_link"/>
                  <geom name="left_foot" class="foot" size="0.128325 0.0394271 0.015223" pos="0.0400401 0 -0.0274574"/>
                  <geom name="//unnamed_geom_18" class="reward_collision_sphere" size="0.0504785" pos="0 0 -0.0185106"/>
                  <geom name="//unnamed_geom_19" class="reward_collision_sphere" size="0.0504785" pos="0.106774 0 -0.0185106"/>
                  <site name="left_foot" class="foot" pos="0.0400401 0 -0.0274574" size="0.0100957"/>
                </body>
              </body>
            </body>
          </body>
        </body>
      </body>
      <body name="right_thigh_roll_link" pos="-0.0198684 -0.16774 -0.0166817" quat="0.999998 -5.50439e-05 0.00148479 -0.00139129">
        <inertial pos="-0.00504534 -0.00190926 0.00124847" quat="0.0471634 0.677679 0.0235047 0.733468" mass="1.61898" diaginertia="0.00145295 0.0220578 0.000129519"/>
        <joint name="right_hip_roll_joint" class="/" pos="0 0 0" axis="-0.99936 -0.0304167 -0.0188368" stiffness="0.0477854" range="-0.109194 0.818989" armature="0.0971454" damping="0" frictionloss="0.0974631"/>
        <geom name="//unnamed_geom_20" class="visual" mesh="right_thigh_roll_link"/>
        <body name="right_thigh_yaw_link" pos="0.0218376 -0.00532128 0.00316713" quat="1 -0.000453942 0.000478465 -0.000499949">
          <inertial pos="0.00609258 -0.0588257 -0.0586237" quat="0.652523 -0.160778 0.103947 0.733185" mass="3.54943" diaginertia="0.0132103 0.15431 0.000834066"/>
          <joint name="right_hip_yaw_joint" class="/" pos="0 0 0" axis="0.0245464 0.0468307 -0.998601" range="-0.970628 0.481189" armature="0.140303" damping="0.0338823" frictionloss="0.0955719"/>
          <geom name="//unnamed_geom_21" class="visual" mesh="right_thigh_yaw_link"/>
          <body name="right_thigh_pitch_link" pos="-0.00391476 -0.0343558 -0.0840644" quat="0.999999 0.00113738 0.00061168 -0.000385861">
            <inertial pos="0.00557808 0.0422892 -0.0430549" quat="0.996721 -0.0437506 -0.0549373 0.0401968" mass="8.9248" diaginertia="0.0515395 0.72511 0.00273077"/>
            <joint name="right_hip_pitch_joint" class="/" pos="0 0 0" axis="-0.0310865 -0.99841 0.0470154" stiffness="0.0174396" range="-0.691295 1.93574" armature="0.0639442" damping="0.0133984" frictionloss="0.108613"/>
            <geom name="//unnamed_geom_22" class="visual" mesh="right_thigh_pitch_link"/>
            <geom name="right_thigh_pitch_link.STL" class="collision" size="0.0827848 0.126106" pos="-0.00188924 0.0456574 -0.103077" quat="0.999971 0.00269833 0.00706272 0" type="cylinder" rgba="0.752941 0.752941 0.752941 1"/>
            <geom name="//unnamed_geom_24" class="reward_collision_sphere" size="0.100957" pos="0 0.0152191 -0.030851"/>
            <body name="right_shank_pitch_link" pos="-0.00666512 0.0363004 -0.226095" quat="0.999994 -0.000719975 -0.00336384 0.000795033">
              <inertial pos="0.00770057 -0.00384445 -0.0831097" quat="0.997646 -0.0596948 0.00171448 0.0337044" mass="1.73669" diaginertia="0.00653412 0.102742 0.000117707"/>
              <joint name="right_knee_pitch_joint" class="/" pos="0 0 0" axis="-0.0276575 -0.998431 -0.0486839" stiffness="0.0457138" range="-1.90446 -0.207629" armature="0.159007" damping="0" frictionloss="0.0482499"/>
              <geom name="//unnamed_geom_25" class="visual" mesh="right_shank_pitch_link"/>
              <geom name="right_shank_pitch_link.STL" class="collision" size="0.0538314 0.0912491" pos="-1.47615e-05 -0.0012823 -0.107793" type="cylinder" rgba="0.752941 0.752941 0.752941 1"/>
              <geom name="//unnamed_geom_27" class="reward_collision_sphere" size="0.0504785"/>
              <geom name="//unnamed_geom_28" class="reward_collision_sphere" size="0.0605742" pos="0 0 -0.0678721"/>
              <body name="right_foot_pitch_link" pos="0.0115445 0.000497988 -0.212802" quat="1 0.000409827 -5.26119e-05 0.000247309">
                <inertial pos="0.0135518 -0.00153645 0.00602879" quat="-0.00180698 0.710163 -0.00215665 0.704031" mass="0.0619927" diaginertia="3.37126e-06 3.97627e-05 5.42135e-07"/>
                <joint name="right_ankle_pitch_joint" class="/" pos="0 0 0" axis="0.031108 -0.998449 -0.0461737" range="-0.65146 1.15949" armature="0.171827" damping="0.013023" frictionloss="0.0505128"/>
                <geom name="//unnamed_geom_29" class="visual" mesh="right_foot_pitch_link"/>
                <body name="right_foot_roll_link" pos="-0.00815729 0.000342877 -0.000150102" quat="1 0.000205778 -0.000115253 1.41568e-05">
                  <inertial pos="0.0328262 -0.000402478 -0.0373525" quat="0.00630906 0.730994 0.0645646 0.679294" mass="1.15052" diaginertia="0.00293934 0.0395584 5.80104e-05"/>
                  <joint name="right_ankle_roll_joint" class="/" pos="0 0 0" axis="-0.999999 -0.00102686 -0.000272847" range="-0.614257 0.298474" armature="0.119317" damping="0" frictionloss="0.17189"/>
                  <geom name="//unnamed_geom_30" class="visual" mesh="right_foot_roll_link"/>
                  <geom name="right_foot" class="foot" size="0.104935 0.0516782 0.0152476" pos="0.0400401 0 -0.0274574"/>
                  <geom name="//unnamed_geom_32" class="reward_collision_sphere" size="0.0504785" pos="0 0 -0.0185106"/>
                  <geom name="//unnamed_geom_33" class="reward_collision_sphere" size="0.0504785" pos="0.106774 0 -0.0185106"/>
                  <site name="right_foot" class="foot" pos="0.0400401 0 -0.0274574" size="0.0100957"/>
                </body>
              </body>
            </body>
          </body>
        </body>
      </body>
      <body name="waist_yaw_link" pos="0.00429703 0.000767784 -0.0135747" quat="0.999988 -0.00242414 0.0042968 7.74221e-05">
        <inertial pos="-0.008955 -0.00840455 0.0313758" quat="0.980631 0.186164 -0.0236531 0.0560894" mass="1.62425" diaginertia="0.00164988 0.0253257 0.000175455"/>
        <joint name="waist_yaw_joint" class="/" pos="0 0 0" axis="0.00110727 -0.00199008 0.999997" stiffness="0.00494919" range="-1.12376 1.04364" armature="0.151137" damping="0" frictionloss="0.140872"/>
        <geom name="//unnamed_geom_34" class="visual" rgba="0.12 0.12 0.12 1" mesh="waist_yaw_link"/>
        <body name="waist_pitch_link" pos="0.00840175 -0.0129717 0.061748" quat="0.999994 0.00147745 -0.00220149 0.00237848">
          <inertial pos="-0.00464115 0.00596044 0.015985" quat="0.997808 -0.0345695 0.0474057 0.0306178" mass="1.44983" diaginertia="0.00228161 0.0377054 0.000167031"/>
          <joint name="waist_pitch_joint" class="/" pos="0 0 0" axis="-0.0124606 -0.998571 -0.0519672" range="-1.04996 0.393905" armature="0.0794983" damping="0.0601657" frictionloss="0.142126"/>
          <geom name="//unnamed_geom_35" class="visual" rgba="0.12 0.12 0.12 1" mesh="waist_pitch_link"/>
          <body name="waist_roll_link" pos="0.0123223 0.0112468 0.0551773" quat="0.999985 0.00224663 -0.00279718 0.0040752">
            <inertial pos="-0.0119224 -0.00815499 0.0945261" quat="0.996713 -0.0186034 -0.0515513 -0.0596588" mass="6.78904" diaginertia="0.0325373 0.448231 0.0028528"/>
            <joint name="waist_roll_joint" class="/" pos="0 0 0" axis="-0.999976 -0.00458029 -0.00525249" range="-0.712677 0.666336" armature="0.110812" damping="0.0570275" frictionloss="0.16355"/>
            <geom name="//unnamed_geom_36" class="visual" rgba="0.12 0.12 0.12 1" mesh="waist_roll_link"/>
            <geom name="//unnamed_geom_37" class="visual" pos="-0.002002 0.000874232 0.0989391" quat="1 0 0 0" mesh="torso_link"/>
            <geom name="torso_link.STL" class="collision" size="0.158934 0.030482" pos="-0.0160747 0.00878113 0.0912134" type="cylinder" rgba="0.752941 0.752941 0.752941 1"/>
            <geom name="//unnamed_geom_39" class="reward_collision_sphere" size="0.131244" pos="0 0 0.123404"/>
            <body name="left_upper_arm_pitch_link" pos="-0.0106317 0.154106 0.12683" quat="0.976686 0.214675 -5.79912e-05 -0.000169934">
              <inertial pos="-0.00114638 0.0719108 -0.0132601" quat="0.720131 0.692807 0.0273922 -0.026075" mass="0.721702" diaginertia="0.00119409 0.0160397 4.13434e-05"/>
              <joint name="left_shoulder_pitch_joint" class="/" pos="0 0 0" axis="0.0223427 0.999749 0.00167751" range="-2.76643 1.90449" armature="0.161979" damping="0.0179554" frictionloss="0.168896"/>
              <geom name="//unnamed_geom_40" class="visual" mesh="left_upper_arm_pitch_link"/>
              <body name="left_upper_arm_roll_link" pos="0.00493928 0.144544 0.00225174" quat="0.977474 -0.211036 -0.0013444 0.0026555">
                <inertial pos="-0.00359775 0.0190954 -0.0157464" quat="0.892105 0.257785 0.109554 -0.354533" mass="0.569378" diaginertia="0.000621358 0.00865109 2.89739e-05"/>
                <joint name="left_shoulder_roll_joint" class="/" pos="0 0 0" axis="-0.997464 -0.0708343 0.00692429" range="-2.37764 0.442783" armature="0.0337776" damping="0.0299401" frictionloss="0.102718"/>
                <geom name="//unnamed_geom_41" class="visual" mesh="left_upper_arm_roll_link"/>
                <body name="left_upper_arm_yaw_link" pos="-0.00690063 0.0597801 -0.0453323" quat="1 -0.000417192 -0.000700043 -0.000303062">
                  <inertial pos="0.00161681 0.0130202 -0.0408553" quat="0.999941 0.00940721 -0.00403658 -0.00351491" mass="0.58986" diaginertia="0.00172403 0.0262466 2.13904e-05"/>
                  <joint name="left_shoulder_yaw_joint" class="/" pos="0 0 0" axis="-0.0163253 -0.00692214 0.999843" range="-2.96373 2.74757" armature="0.140846" damping="0.0615432" frictionloss="0.127409"/>
                  <geom name="//unnamed_geom_42" class="visual" mesh="left_upper_arm_yaw_link"/>
                  <geom name="left_upper_arm_yaw_link.STL" class="collision" size="0.03658 0.0857549" pos="3.51333e-05 -0.00136103 -0.0489543" quat="0.00803418 -0.995528 0.0941277 0" type="cylinder" rgba="0.752941 0.752941 0.752941 1"/>
                  <body name="left_lower_arm_pitch_link" pos="0.00185109 -0.00853421 -0.0965149" quat="1 -3.28366e-05 -0.000401861 -0.00032949">
                    <inertial pos="0.00690887 0.0143285 -0.00672273" quat="0.702479 -0.0877219 0.0959764 0.699726" mass="0.378057" diaginertia="0.000161262 0.00236778 1.02777e-05"/>
                    <joint name="left_elbow_pitch_joint" class="/" pos="0 0 0" axis="0.0300063 0.999506 0.00938417" range="-2.26481 2.40404" armature="0.0729424" damping="0.00954265" frictionloss="0.105413"/>
                    <geom name="//unnamed_geom_44" class="visual" mesh="left_lower_arm_pitch_link"/>
                    <body name="left_hand_yaw_link" pos="0.00306167 0.00839149 -0.0382637" quat="0.999988 -0.000347593 -0.00439268 -0.00211776">
                      <inertial pos="0.012972 -0.0111441 -0.0554326" quat="0.999964 -0.00281675 -0.00383059 0.00702619" mass="1.3519" diaginertia="0.00185309 0.0265806 5.6015e-05"/>
                      <joint name="left_wrist_yaw_joint" class="/" pos="0 0 0" axis="-0.0499129 -0.0505594 0.997473" range="-2.67051 2.99577" armature="0.137163" damping="0.0249996" frictionloss="0.0944979"/>
                      <geom name="//unnamed_geom_45" class="visual" mesh="left_hand_yaw_link"/>
                      <geom name="left_hand_yaw_link.STL" class="collision" size="0.0419698 0.0702597" pos="0.000969192 -0.00234543 -0.0469199" type="cylinder" rgba="0.752941 0.752941 0.752941 1"/>
                      <geom name="//unnamed_geom_47" class="reward_collision_sphere" size="0.0504785"/>
                      <body name="left_hand_roll_link" pos="0.0128556 0.00757665 -0.103744" quat="0.999998 0.0016808 -0.000154783 0.000802367">
                        <inertial pos="-0.000838196 -0.0112906 -0.000568786" quat="0.499234 0.500478 0.504152 0.496103" mass="0.00603531" diaginertia="2.26303e-07 3.83026e-06 7.56459e-09"/>
                        <joint name="left_wrist_roll_joint" class="/" pos="0 0 0" axis="-0.999109 0.0393398 0.0152991" range="-1.02502 0.850135" armature="0.105205" damping="0.0395014" frictionloss="0.112631"/>
                        <geom name="//unnamed_geom_48" class="visual" mesh="left_hand_roll_link"/>
                        <body name="left_hand_pitch_link" pos="-0.00714139 0.000594637 -0.000842258" quat="1 -0.000454751 -0.000388433 -0.000407014">
                          <inertial pos="-0.00513899 -0.0204496 -0.0365316" quat="0.726229 -0.117202 0.115928 0.667395" mass="0.224306" diaginertia="0.000170076 0.00196149 8.78421e-06"/>
                          <joint name="left_wrist_pitch_joint" class="/" pos="0 0 0" axis="-0.00900303 0.99991 -0.00998182" range="-0.616763 0.402656" armature="0.137566" damping="0" frictionloss="0.0890482"/>
                          <geom name="//unnamed_geom_49" class="visual" mesh="left_hand_pitch"/>
                          <body name="left_jaw_link" pos="0.000722018 -0.00505962 -0.0486964" quat="1 -0.000457022 -0.000117478 0.000315344">
                            <inertial pos="-0.0110182 0.0114103 -0.0199973" quat="0.66042 -0.0367393 0.0151678 0.749844" mass="0.0578537" diaginertia="4.01291e-05 0.000395805 2.87952e-06"/>
                            <joint name="left_jaw_joint" class="/" pos="0 0 0" axis="-1 4.4742e-05 -2.33259e-05" range="-0.981557 0.140416" armature="0.104505" damping="0" frictionloss="0.149083"/>
                            <geom name="//unnamed_geom_50" class="visual" mesh="left_jaw_link"/>
                            <geom name="//unnamed_geom_51" class="collision" size="0.0363445"/>
                            <geom name="//unnamed_geom_52" class="reward_collision_sphere" size="0.0504785" pos="0 0 -0.0123404"/>
                          </body>
                        </body>
                      </body>
                    </body>
                  </body>
                </body>
              </body>
            </body>
            <body name="right_upper_arm_pitch_link" pos="-0.00123554 -0.15248 0.127773" quat="0.975804 -0.218605 0.000722953 -0.00421647">
              <inertial pos="0.00263467 -0.0953055 0.00120525" quat="0.707165 0.706208 0.0292648 0.0181936" mass="0.811722" diaginertia="0.00117544 0.0147001 4.53909e-05"/>
              <joint name="right_shoulder_pitch_joint" class="/" pos="0 0 0" axis="0.00138009 -0.999994 0.00330276" range="-1.70625 3.07311" armature="0.108221" damping="0.0309369" frictionloss="0.104775"/>
              <geom name="//unnamed_geom_53" class="visual" mesh="right_upper_arm_pitch_link"/>
              <body name="right_upper_arm_roll_link" pos="0.014523 -0.14644 -0.00318819" quat="0.976928 0.213524 -0.00351446 0.00278496">
                <inertial pos="0.00652058 -0.0352768 -0.0147159" quat="0.895266 -0.245406 0.0917193 0.360363" mass="0.587278" diaginertia="0.000512579 0.00647629 3.27934e-05"/>
                <joint name="right_shoulder_roll_joint" class="/" pos="0 0 0" axis="-0.998663 -0.0458743 -0.0238445" stiffness="0.0129055" range="-0.581094 2.42974" armature="0.162008" damping="0.0315066" frictionloss="0.054924"/>
                <geom name="//unnamed_geom_54" class="visual" mesh="right_upper_arm_roll_link"/>
                <body name="right_upper_arm_yaw_link" pos="0.00760413 -0.0614465 -0.0479814" quat="0.999995 -0.000235562 -8.47712e-05 0.00310326">
                  <inertial pos="-0.0142467 -0.0114601 -0.0604693" quat="0.998049 0.00591612 0.0292856 -0.0548246" mass="0.720735" diaginertia="0.00235322 0.0325445 3.02757e-05"/>
                  <joint name="right_shoulder_yaw_joint" class="/" pos="0 0 0" axis="-0.0265453 -0.0209414 0.999428" range="-3.18221 3.00086" armature="0.0401506" damping="0" frictionloss="0.0273034"/>
                  <geom name="//unnamed_geom_55" class="visual" mesh="right_upper_arm_yaw_link"/>
                  <geom name="right_upper_arm_yaw_link.STL" class="collision" size="0.03658 0.0857549" pos="3.51333e-05 0.00136103 -0.0489543" type="cylinder" rgba="0.752941 0.752941 0.752941 1"/>
                  <body name="right_lower_arm_pitch_link" pos="-0.00367187 0.0113261 -0.0967281" quat="0.999991 0.00160702 0.00317344 0.00222509">
                    <inertial pos="0.000921558 -0.0125291 -0.00516489" quat="0.701234 0.0917186 -0.0911687 0.701104" mass="0.324805" diaginertia="0.000147101 0.00255869 8.02713e-06"/>
                    <joint name="right_elbow_pitch_joint" class="/" pos="0 0 0" axis="0.00592592 -0.99996 0.00664254" stiffness="0.060625" range="-2.1232 2.15625" armature="0.0569521" damping="0.048526" frictionloss="0.104945"/>
                    <geom name="//unnamed_geom_57" class="visual" mesh="right_lower_arm_pitch_link"/>
                    <body name="right_hand_yaw_link" pos="0.00142641 -0.00396377 -0.0331652" quat="0.999983 -0.00167236 0.00549176 0.001008">
                      <inertial pos="-0.00207276 -0.0171578 -0.0365511" quat="0.999595 0.00954517 -0.00239106 0.026713" mass="0.81465" diaginertia="0.00126549 0.016638 4.29238e-05"/>
                      <joint name="right_wrist_yaw_joint" class="/" pos="0 0 0" axis="-0.00861707 -0.0296763 0.999522" stiffness="0.0471478" range="-2.78938 3.04156" armature="0.170634" damping="0.0447924" frictionloss="0.0716487"/>
                      <geom name="//unnamed_geom_58" class="visual" mesh="right_hand_yaw_link"/>
                      <geom name="right_hand_yaw_link.STL" class="collision" size="0.0419698 0.0702597" pos="0.000969192 0.000975719 -0.0469199" type="cylinder" rgba="0.752941 0.752941 0.752941 1"/>
                      <geom name="//unnamed_geom_60" class="reward_collision_sphere" size="0.0504785"/>
                      <body name="right_hand_roll_link" pos="-0.00642709 -0.00232052 -0.117954" quat="0.99999 -0.000372584 0.0033056 -0.00285016">
                        <inertial pos="-0.0125707 -0.0113193 0.0135624" quat="0.500313 0.50009 0.500059 0.499537" mass="0.00521079" diaginertia="1.96334e-07 3.36793e-06 6.3004e-09"/>
                        <joint name="right_wrist_roll_joint" class="/" pos="0 0 0" axis="-0.998135 0.0546251 -0.0272492" range="-1.01034 0.970711" armature="0.159365" damping="0.00854215" frictionloss="0.16797"/>
                        <geom name="//unnamed_geom_61" class="visual" mesh="right_hand_roll_link"/>
                        <body name="right_hand_pitch_link" pos="0.000761043 -0.00128495 0.0139886" quat="0.999996 -0.000799304 -0.00040081 0.00252929">
                          <inertial pos="0.00564886 0.0142465 -0.0427154" quat="0.735795 0.132868 -0.122339 0.652676" mass="0.264276" diaginertia="0.000179021 0.00236524 8.72861e-06"/>
                          <joint name="right_wrist_pitch_joint" class="/" pos="0 0 0" axis="0.0402334 -0.998759 -0.0293455" range="-0.453194 0.857043" armature="0.0546264" damping="0.00838533" frictionloss="0.0643191"/>
                          <geom name="//unnamed_geom_62" class="visual" mesh="right_hand_pitch"/>
                          <body name="right_jaw_link" pos="-0.00824827 -0.000222446 -0.0511315" quat="0.999999 -0.000416884 0.0001186 -0.00124148">
                            <inertial pos="9.32566e-05 -0.0088996 -0.0111638" quat="0.707779 0.0225328 -0.0280147 0.705518" mass="0.0837998" diaginertia="4.43784e-05 0.000527278 2.63918e-06"/>
                            <joint name="right_jaw_joint" class="/" pos="0 0 0" axis="-0.998844 0.0427637 0.0219706" stiffness="0.0289245" range="-0.171094 1.15858" armature="0.172012" damping="0" frictionloss="0.088404"/>
                            <geom name="//unnamed_geom_63" class="visual" mesh="right_jaw_link"/>
                            <geom name="//unnamed_geom_64" class="collision" size="0.0363445"/>
                            <geom name="//unnamed_geom_65" class="reward_collision_sphere" size="0.0504785" pos="0 0 -0.0123404"/>
                          </body>
                        </body>
                      </body>
                    </body>
                  </body>
                </body>
              </body>
            </body>
            <body name="head_roll_link" pos="-0.0115874 -0.00499915 0.202892" quat="1 8.94174e-06 -1.95936e-05 0.000382193">
              <inertial pos="0.00484673 -0.0117561 0.0121101" quat="0.0570063 0.726654 -0.00551439 0.684613" mass="0.0104672" diaginertia="5.44224e-07 4.39773e-06 4.3637e-08"/>
              <joint name="head_roll_joint" class="/" pos="0 0 0" axis="-0.999434 0.00828007 -0.0326121" range="-0.228083 0.243627" armature="0.0784349" damping="0.000361272" frictionloss="0.173627"/>
              <geom name="//unnamed_geom_66" class="visual" mesh="head_roll_link"/>
              <body name="head_pitch_link" pos="0.00415548 0.00976757 -0.0130498" quat="1 -0.000298485 -0.000609522 -0.000211828">
                <inertial pos="-0.00120672 -0.0103747 0.000287202" quat="0.668267 0.66296 0.240232 -0.237051" mass="0.0511701" diaginertia="1.22777e-05 0.00015971 1.26915e-06"/>
                <joint name="head_pitch_joint" class="/" pos="0 0 0" axis="0.0104718 -0.999941 0.00295086" range="-0.936518 1.13634" armature="0.154506" damping="0" frictionloss="0.102174"/>
                <geom name="//unnamed_geom_67" class="visual" mesh="head_pitch_link"/>
                <body name="head_yaw_link" pos="0.00238563 0.00142341 0.0331097" quat="0.999982 0.00226951 0.00234134 0.00508144">
                  <inertial pos="0.0242088 -0.0144903 0.0596158" quat="0.706276 -0.137166 -0.146741 0.678842" mass="1.83867" diaginertia="0.00566703 0.0529702 0.000466378"/>
                  <joint name="head_yaw_joint" class="/" pos="0 0 0" axis="-0.00106112 0.00471394 0.999988" range="-2.72497 2.63919" armature="0.15828" damping="0" frictionloss="0.161118"/>
                  <geom name="//unnamed_geom_68" class="visual" rgba="0.12 0.12 0.12 1" mesh="head_yaw_link"/>
                  <geom name="head_yaw_link.STL" class="collision" size="0.119823" pos="0.0162661 -0.00133932 0.0577655" rgba="0.752941 0.752941 0.752941 1"/>
                  <geom name="//unnamed_geom_70" class="reward_collision_sphere" size="0.100957" pos="0.0266934 0 0.0617019"/>
                  <camera name="ego_camera" class="/" pos="0.0978757 0 0.0678721" quat="-0.5 -0.5 0.5 0.5"/>
                </body>
              </body>
            </body>
          </body>
        </body>
      </body>
    </body>
  </worldbody>

  <contact>
    <pair class="/" geom1="floor" geom2="left_foot" name="//unnamed_contact_0"/>
    <pair class="/" geom1="floor" geom2="right_foot" name="//unnamed_contact_1"/>
  </contact>

  <actuator>
    <general name="left_hip_roll" class="/" joint="left_hip_roll_joint" forcerange="-22.9959 22.9959" gainprm="98.8827" biasprm="0 -98.8827 -1.00957"/>
    <general name="left_hip_yaw" class="/" joint="left_hip_yaw_joint" forcerange="-45.8165 45.8165" gainprm="98.8827" biasprm="0 -98.8827 -1.00957"/>
    <general name="left_hip_pitch" class="/" joint="left_hip_pitch_joint" forcerange="-270.404 270.404" gainprm="98.8827" biasprm="0 -98.8827 -1.00957"/>
    <general name="left_knee_pitch" class="/" joint="left_knee_pitch_joint" forcerange="-127.803 127.803" gainprm="98.8827" biasprm="0 -98.8827 -1.00957"/>
    <general name="left_ankle_pitch" class="/" joint="left_ankle_pitch_joint" forcerange="-13.6547 13.6547" gainprm="98.8827" biasprm="0 -98.8827 -1.00957"/>
    <general name="left_ankle_roll" class="/" joint="left_ankle_roll_joint" forcerange="-24.7537 24.7537" gainprm="98.8827" biasprm="0 -98.8827 -1.00957"/>
    <general name="right_hip_roll" class="/" joint="right_hip_roll_joint" forcerange="-57.4395 57.4395" gainprm="98.8827" biasprm="0 -98.8827 -1.00957"/>
    <general name="right_hip_yaw" class="/" joint="right_hip_yaw_joint" forcerange="-64.4755 64.4755" gainprm="98.8827" biasprm="0 -98.8827 -1.00957"/>
    <general name="right_hip_pitch" class="/" joint="right_hip_pitch_joint" forcerange="-128.966 128.966" gainprm="98.8827" biasprm="0 -98.8827 -1.00957"/>
    <general name="right_knee_pitch" class="/" joint="right_knee_pitch_joint" forcerange="-224.306 224.306" gainprm="98.8827" biasprm="0 -98.8827 -1.00957"/>
    <general name="right_ankle_pitch" class="/" joint="right_ankle_pitch_joint" forcerange="-13.9667 13.9667" gainprm="98.8827" biasprm="0 -98.8827 -1.00957"/>
    <general name="right_ankle_roll" class="/" joint="right_ankle_roll_joint" forcerange="-34.5843 34.5843" gainprm="98.8827" biasprm="0 -98.8827 -1.00957"/>
    <general name="waist_yaw" class="/" joint="waist_yaw_joint" forcerange="-60.7305 60.7305" gainprm="98.8827" biasprm="0 -98.8827 -1.00957"/>
    <general name="waist_pitch" class="/" joint="waist_pitch_joint" forcerange="-74.1566 74.1566" gainprm="98.8827" biasprm="0 -98.8827 -1.00957"/>
    <general name="waist_roll" class="/" joint="waist_roll_joint" forcerange="-68.5246 68.5246" gainprm="98.8827" biasprm="0 -98.8827 -1.00957"/>
    <general name="left_shoulder_pitch" class="/" joint="left_shoulder_pitch_joint" forcerange="-53.5494 53.5494" gainprm="98.8827" biasprm="0 -98.8827 -1.00957"/>
    <general name="left_shoulder_roll" class="/" joint="left_shoulder_roll_joint" forcerange="-44.7182 44.7182" gainprm="98.8827" biasprm="0 -98.8827 -1.00957"/>
    <general name="left_shoulder_yaw" class="/" joint="left_shoulder_yaw_joint" forcerange="-31.2177 31.2177" gainprm="98.8827" biasprm="0 -98.8827 -1.00957"/>
    <general name="left_elbow_pitch" class="/" joint="left_elbow_pitch_joint" forcerange="-30.0456 30.0456" gainprm="98.8827" biasprm="0 -98.8827 -1.00957"/>
    <general name="left_wrist_yaw" class="/" joint="left_wrist_yaw_joint" forcerange="-10.4466 10.4466" gainprm="98.8827" biasprm="0 -98.8827 -1.00957"/>
    <general name="left_wrist_roll" class="/" joint="left_wrist_roll_joint" forcerange="-5.47007 5.47007" gainprm="98.8827" biasprm="0 -98.8827 -1.00957"/>
    <general name="left_wrist_pitch" class="/" joint="left_wrist_pitch_joint" forcerange="-2.5635 2.5635" gainprm="98.8827" biasprm="0 -98.8827 -1.00957"/>
    <general name="left_jaw" class="/" joint="left_jaw_joint" forcerange="-4.16183 4.16183" gainprm="98.8827" biasprm="0 -98.8827 -1.00957"/>
    <general name="right_shoulder_pitch" class="/" joint="right_shoulder_pitch_joint" forcerange="-39.1862 39.1862" gainprm="98.8827" biasprm="0 -98.8827 -1.00957"/>
    <general name="right_shoulder_roll" class="/" joint="right_shoulder_roll_joint" forcerange="-40.3941 40.3941" gainprm="98.8827" biasprm="0 -98.8827 -1.00957"/>
    <general name="right_shoulder_yaw" class="/" joint="right_shoulder_yaw_joint" forcerange="-29.5403 29.5403" gainprm="98.8827" biasprm="0 -98.8827 -1.00957"/>
    <general name="right_elbow_pitch" class="/" joint="right_elbow_pitch_joint" forcerange="-30.7856 30.7856" gainprm="98.8827" biasprm="0 -98.8827 -1.00957"/>
    <general name="right_wrist_yaw" class="/" joint="right_wrist_yaw_joint" forcerange="-10.6438 10.6438" gainprm="98.8827" biasprm="0 -98.8827 -1.00957"/>
    <general name="right_wrist_roll" class="/" joint="right_wrist_roll_joint" forcerange="-4.37704 4.37704" gainprm="98.8827" biasprm="0 -98.8827 -1.00957"/>
    <general name="right_wrist_pitch" class="/" joint="right_wrist_pitch_joint" forcerange="-3.69197 3.69197" gainprm="98.8827" biasprm="0 -98.8827 -1.00957"/>
    <general name="right_jaw" class="/" joint="right_jaw_joint" forcerange="-3.93683 3.93683" gainprm="98.8827" biasprm="0 -98.8827 -1.00957"/>
    <general name="head_roll" class="/" joint="head_roll_joint" forcerange="-4.62115 4.62115" gainprm="98.8827" biasprm="0 -98.8827 -1.00957"/>
    <general name="head_pitch" class="/" joint="head_pitch_joint" forcerange="-2.51946 2.51946" gainprm="98.8827" biasprm="0 -98.8827 -1.00957"/>
    <general name="head_yaw" class="/" joint="head_yaw_joint" forcerange="-3.67524 3.67524" gainprm="98.8827" biasprm="0 -98.8827 -1.00957"/>
  </actuator>

  <sensor>
    <gyro site="imu" name="imu_angular_velocity"/>
    <velocimeter site="imu" name="imu_linear_velocity"/>
    <framelinvel objtype="site" objname="left_foot" name="left_foot_global_linear_velocity"/>
    <framelinvel objtype="site" objname="right_foot" name="right_foot_global_linear_velocity"/>
  </sensor>

  <keyframe>
    <key name="home" qpos="0 0 0.8665 1 0 0 0 0 0 -0.4 0.8 -0.4 0 0 0 0.4 -0.8 0.4 0 0 0 0 0 -0.2 0 -0.785 0 0 0 0 0 0.2 0 0.785 0 0 0 0 0 0 0"/>
  </keyframe>
</mujoco>
