<mujoco model="GR1T2_jaw">
  <compiler angle="radian" assetdir="assets" balanceinertia="true" inertiafromgeom="false"/>

  <option timestep="0.005" density="1.2" viscosity="2e-05"/>

  <size nkey="1"/>

  <visual>
    <quality shadowsize="8192"/>
    <map shadowclip="0.5"/>
  </visual>

  <default>
    <default class="/">
      <joint armature="0.1" damping="0.01" frictionloss="0.1"/>
      <geom contype="0" conaffinity="0" group="1" solref="-1000 -80"/>
      <site size="0.01 0.005 0.005" group="5"/>
      <general forcelimited="true" biastype="affine" gainprm="80" biasprm="0 -80 -2"/>
      <default class="visual">
        <geom type="mesh" density="0" rgba="0.18 0.18 0.18 1"/>
      </default>
      <default class="collision">
        <geom group="3"/>
      </default>
      <default class="foot">
        <geom size="0.126 0.045 0.01" type="box" condim="6" group="4" priority="1" solimp="0.015 1 0.01"/>
      </default>
      <default class="reward_collision_sphere">
        <geom group="5" rgba="1 0 0 1"/>
      </default>
    </default>
  </default>

  <asset>
    <texture type="skybox" colorspace="auto" name="//unnamed_texture_0" builtin="gradient" rgb1="0.95 0.95 0.95" rgb2="0.95 0.95 0.95" width="100" height="600"/>
    <texture type="2d" colorspace="auto" name="texplane" builtin="checker" rgb1="0.345 0.575 0.748" rgb2="0.345 0.575 0.748" markrgb="1 1 1" width="512" height="512"/>
    <material name="MatPlane" class="/" texture="texplane" texuniform="true" texrepeat="2 2" specular="0.9"/>
    <mesh name="base_link" class="/" file="base_link.STL"/>
    <mesh name="left_thigh_roll_link" class="/" file="left_thigh_roll_link.STL"/>
    <mesh name="left_thigh_yaw_link" class="/" file="left_thigh_yaw_link.STL"/>
    <mesh name="left_thigh_pitch_link" class="/" file="left_thigh_pitch_link.STL"/>
    <mesh name="left_shank_pitch_link" class="/" file="left_shank_pitch_link.STL"/>
    <mesh name="left_foot_pitch_link" class="/" file="left_foot_pitch_link.STL"/>
    <mesh name="left_foot_roll_link" class="/" file="left_foot_roll_link.STL"/>
    <mesh name="right_thigh_roll_link" class="/" file="right_thigh_roll_link.STL"/>
    <mesh name="right_thigh_yaw_link" class="/" file="right_thigh_yaw_link.STL"/>
    <mesh name="right_thigh_pitch_link" class="/" file="right_thigh_pitch_link.STL"/>
    <mesh name="right_shank_pitch_link" class="/" file="right_shank_pitch_link.STL"/>
    <mesh name="right_foot_pitch_link" class="/" file="right_foot_pitch_link.STL"/>
    <mesh name="right_foot_roll_link" class="/" file="right_foot_roll_link.STL"/>
    <mesh name="waist_yaw_link" class="/" file="waist_yaw_link.STL"/>
    <mesh name="waist_pitch_link" class="/" file="waist_pitch_link.STL"/>
    <mesh name="waist_roll_link" class="/" file="waist_roll_link.STL"/>
    <mesh name="torso_link" class="/" file="torso_link.STL"/>
    <mesh name="left_upper_arm_pitch_link" class="/" file="left_upper_arm_pitch_link.STL"/>
    <mesh name="left_upper_arm_roll_link" class="/" file="left_upper_arm_roll_link.STL"/>
    <mesh name="left_upper_arm_yaw_link" class="/" file="left_upper_arm_yaw_link.STL"/>
    <mesh name="left_lower_arm_pitch_link" class="/" file="left_lower_arm_pitch_link.STL"/>
    <mesh name="left_hand_yaw_link" class="/" file="left_hand_yaw_link.STL"/>
    <mesh name="left_hand_roll_link" class="/" file="left_hand_roll_link.STL"/>
    <mesh name="left_hand_pitch" class="/" file="left_hand_pitch.STL"/>
    <mesh name="left_jaw_link" class="/" file="left_jaw_link.STL"/>
    <mesh name="right_upper_arm_pitch_link" class="/" file="right_upper_arm_pitch_link.STL"/>
    <mesh name="right_upper_arm_roll_link" class="/" file="right_upper_arm_roll_link.STL"/>
    <mesh name="right_upper_arm_yaw_link" class="/" file="right_upper_arm_yaw_link.STL"/>
    <mesh name="right_lower_arm_pitch_link" class="/" file="right_lower_arm_pitch_link.STL"/>
    <mesh name="right_hand_yaw_link" class="/" file="right_hand_yaw_link.STL"/>
    <mesh name="right_hand_roll_link" class="/" file="right_hand_roll_link.STL"/>
    <mesh name="right_hand_pitch" class="/" file="right_hand_pitch.STL"/>
    <mesh name="right_jaw_link" class="/" file="right_jaw_link.STL"/>
    <mesh name="head_roll_link" class="/" file="head_roll_link.STL"/>
    <mesh name="head_pitch_link" class="/" file="head_pitch_link.STL"/>
    <mesh name="head_yaw_link" class="/" file="head_yaw_link.STL"/>
    <mesh name="imu_link" class="/" file="imu_link.STL"/>
  </asset>

  <worldbody>
    <geom name="floor" class="/" size="100 100 0.125" type="plane" group="0" material="MatPlane"/>
    <light name="toplight_shadow" class="/" pos="0 0 5" dir="0.0990148 0.0990148 -0.990148" type="directional" ambient="0.04 0.04 0.04" diffuse="0.55 0.55 0.55" specular="0.12 0.12 0.12"/>
    <light name="toplight_fill" class="/" pos="0 0 5" dir="0.0990148 0.0990148 -0.990148" type="directional" castshadow="false" ambient="0.04 0.04 0.04" diffuse="0.3 0.3 0.3" specular="0.08 0.08 0.08"/>
    <body name="trunk" pos="0.00238204 0.00247993 -0.000213427" quat="1 0.000320156 8.72992e-05 -0.000377701">
      <inertial pos="-0.068753 0.00112827 -0.00765898" quat="0.999997 0.0014985 0.000964113 -0.00174115" mass="3.15682" diaginertia="0.0670887 0.0127956 0.00683946"/>
      <joint name="//unnamed_joint_0" type="free"/>
      <geom name="//unnamed_geom_1" class="visual" rgba="0.12 0.12 0.12 1" mesh="base_link"/>
      <geom name="base_link.STL" class="collision" size="0.114001 0.0638497" pos="-0.0471812 0.000368044 0.0063706" quat="0.706838 -0.707359 0.00477667 0" type="cylinder" rgba="0.752941 0.752941 0.752941 1"/>
      <geom name="//unnamed_geom_3" class="visual" pos="0 0 -0.0412252" quat="1 0 0 0" rgba="0.12 0.12 0.12 1" mesh="imu_link"/>
      <geom name="//unnamed_geom_4" class="reward_collision_sphere" size="0.0745142" pos="0 0.09946 0.0691698"/>
      <geom name="//unnamed_geom_5" class="reward_collision_sphere" size="0.0745142" pos="0 -0.09946 0.0691698"/>
      <site name="imu" class="/" pos="0.0129945 0.004281 -0.0359446" size="0.00931428"/>
      <camera name="track" class="/" pos="0 -1.9892 0" quat="0.707107 0.707107 0 0" mode="trackcom"/>
      <body name="left_thigh_roll_link" pos="-0.0367822 0.102293 -0.0157362" quat="1 0.00051386 -0.000654578 -0.000231991">
        <inertial pos="0.000592769 -0.00103025 -0.000520667" quat="-0.0230615 0.705928 -0.0240555 0.707499" mass="1.21208" diaginertia="0.00428454 0.00232182 0.00024511"/>
        <joint name="left_hip_roll_joint" class="/" pos="0 0 0" axis="-1 -0.000902304 -8.57009e-05" range="-0.846923 0.0910593" armature="0.0918628" damping="0.0225167" frictionloss="0.0811761"/>
        <geom name="//unnamed_geom_6" class="visual" mesh="left_thigh_roll_link"/>
        <body name="left_thigh_yaw_link" pos="0.0315008 0.00275431 0.000330225" quat="1 -0.000177352 -0.000291509 0.000226021">
          <inertial pos="-0.00125696 0.0374222 -0.0785713" quat="0.572081 0.0935652 -0.195 0.791167" mass="2.77976" diaginertia="0.0393793 0.0190161 0.00139166"/>
          <joint name="left_hip_yaw_joint" class="/" pos="0 0 0" axis="0.00198972 -0.00734552 -0.999971" range="-0.69164 0.694302" armature="0.0964725" damping="0.000693789" frictionloss="0.0887358"/>
          <geom name="//unnamed_geom_7" class="visual" mesh="left_thigh_yaw_link"/>
          <body name="left_thigh_pitch_link" pos="-0.000426165 0.0254991 -0.0942442" quat="1 -6.13095e-05 -0.000742199 0.000329033">
            <inertial pos="-0.00115268 -0.0296384 -0.0434303" quat="0.999789 -0.016172 -0.00988621 0.00789991" mass="6.58873" diaginertia="0.154961 0.0862265 0.00439822"/>
            <joint name="left_hip_pitch_joint" class="/" pos="0 0 0" axis="0.000948258 0.999999 -0.000831846" range="-1.72032 0.696619" armature="0.103111" damping="0.00175479" frictionloss="0.0925351"/>
            <geom name="//unnamed_geom_8" class="visual" mesh="left_thigh_pitch_link"/>
            <geom name="left_thigh_pitch_link.STL" class="collision" size="0.0763771 0.116348" pos="0.000775646 -0.029838 -0.115552" type="cylinder" rgba="0.752941 0.752941 0.752941 1"/>
            <geom name="//unnamed_geom_10" class="reward_collision_sphere" size="0.0931428" pos="0 -0.009946 -0.0345849"/>
            <body name="left_shank_pitch_link" pos="-0.00309051 -0.0188432 -0.24821" quat="1 0.000424602 0.000146634 0.000121092">
              <inertial pos="0.00130662 -0.00180827 -0.0786823" quat="0.999728 0.0029001 0.00637429 -0.0222393" mass="1.42081" diaginertia="0.0185492 0.0103121 0.000200961"/>
              <joint name="left_knee_pitch_joint" class="/" pos="0 0 0" axis="-0.000267455 1 0.000323595" range="-0.0904219 1.91565" armature="0.0875116" damping="0.011082" frictionloss="0.090677"/>
              <geom name="//unnamed_geom_11" class="visual" mesh="left_shank_pitch_link"/>
              <geom name="left_shank_pitch_link.STL" class="collision" size="0.049665 0.0841871" pos="-1.83816e-05 -0.000837997 -0.120833" quat="0.00125538 -0.202712 0.979238 0" type="cylinder" rgba="0.752941 0.752941 0.752941 1"/>
              <geom name="//unnamed_geom_13" class="reward_collision_sphere" size="0.0465714"/>
              <geom name="//unnamed_geom_14" class="reward_collision_sphere" size="0.0558857" pos="0 0 -0.0760868"/>
              <body name="left_foot_pitch_link" pos="-0.00186289 -0.00222338 -0.235433" quat="1 -8.35826e-05 0.000119933 -0.000166678">
                <inertial pos="0.00171136 0.00161642 -0.000130852" quat="0.00154746 0.707774 -0.00037219 0.706437" mass="0.0453682" diaginertia="1.06627e-05 5.43815e-06 8.46849e-07"/>
                <joint name="left_ankle_pitch_joint" class="/" pos="0 0 0" axis="0.00709511 0.999975 0.000512215" range="-1.11049 0.509761" armature="0.098634" damping="0.00394043" frictionloss="0.0962236"/>
                <geom name="//unnamed_geom_15" class="visual" mesh="left_foot_pitch_link"/>
                <body name="left_foot_roll_link" pos="0.00010403 0.00146118 0.000239823" quat="1 -0.000415226 -8.00442e-05 -0.000189548">
                  <inertial pos="0.0417579 -0.00101007 -0.0249137" quat="-0.00443125 0.725281 -0.00283275 0.688433" mass="0.882431" diaginertia="0.00966403 0.00512941 0.000127257"/>
                  <joint name="left_ankle_roll_joint" class="/" pos="0 0 0" axis="-0.99997 0.00753641 -0.00154131" range="-0.49952 0.400896" armature="0.100071" damping="0.00587158" frictionloss="0.0919826"/>
                  <geom name="//unnamed_geom_16" class="visual" mesh="left_foot_roll_link"/>
                  <geom name="left_foot" class="foot" size="0.150405 0.0417242 0.00839053" pos="0.0498593 0 -0.0307806"/>
                  <geom name="//unnamed_geom_18" class="reward_collision_sphere" size="0.0465714" pos="0 0 -0.0207509"/>
                  <geom name="//unnamed_geom_19" class="reward_collision_sphere" size="0.0465714" pos="0.132958 0 -0.0207509"/>
                  <site name="left_foot" class="foot" pos="0.0498593 0 -0.0307806" size="0.00931428"/>
                </body>
              </body>
            </body>
          </body>
        </body>
      </body>
      <body name="right_thigh_roll_link" pos="-0.0394063 -0.110257 -0.0182446" quat="0.999998 -0.00161223 -0.000450983 0.000749929">
        <inertial pos="-0.000159099 -0.00126539 0.00229219" quat="0.0271147 0.702557 0.0161541 0.710927" mass="1.19914" diaginertia="0.0043232 0.00245079 0.000257472"/>
        <joint name="right_hip_roll_joint" class="/" pos="0 0 0" axis="-0.999998 0.000897999 -0.00198641" range="-0.102244 0.817981" armature="0.085496" damping="0.00192047" frictionloss="0.0928237"/>
        <geom name="//unnamed_geom_20" class="visual" mesh="right_thigh_roll_link"/>
        <body name="right_thigh_yaw_link" pos="0.0335596 -0.00571225 0.00191692" quat="1 -0.000139661 -0.000552501 -0.000544552">
          <inertial pos="-0.00500543 -0.0383113 -0.0784966" quat="0.695532 -0.143416 0.145489 0.688839" mass="2.80422" diaginertia="0.0394945 0.0187587 0.00143967"/>
          <joint name="right_hip_yaw_joint" class="/" pos="0 0 0" axis="0.000706246 0.000536871 -1" range="-0.657792 0.742627" armature="0.0921104" damping="0.0111421" frictionloss="0.0923551"/>
          <geom name="//unnamed_geom_21" class="visual" mesh="right_thigh_yaw_link"/>
          <body name="right_thigh_pitch_link" pos="-0.00180537 -0.0258824 -0.095079" quat="1 2.00854e-05 8.00718e-05 -0.000116297">
            <inertial pos="0.00119313 0.0261528 -0.044171" quat="0.999519 -0.0259972 -0.0130431 0.0107593" mass="6.77719" diaginertia="0.154565 0.0863581 0.00431344"/>
            <joint name="right_hip_pitch_joint" class="/" pos="0 0 0" axis="0.0187563 -0.999767 -0.010672" range="-0.689508 1.73385" armature="0.088273" damping="0.0256315" frictionloss="0.0935988"/>
            <geom name="//unnamed_geom_22" class="visual" mesh="right_thigh_pitch_link"/>
            <geom name="right_thigh_pitch_link.STL" class="collision" size="0.0763771 0.116346" pos="-0.00235255 0.029838 -0.115552" quat="0.999971 0.00269833 0.00706272 0" type="cylinder" rgba="0.752941 0.752941 0.752941 1"/>
            <geom name="//unnamed_geom_24" class="reward_collision_sphere" size="0.0931428" pos="0 0.009946 -0.0345849"/>
            <body name="right_shank_pitch_link" pos="-0.00146714 0.0160502 -0.248248" quat="1 -0.000158322 -0.000500048 0.000278346">
              <inertial pos="0.00102061 -0.00194243 -0.0774905" quat="0.999763 0.011364 0.0118469 0.0142686" mass="1.447" diaginertia="0.0178926 0.0103438 0.0001966"/>
              <joint name="right_knee_pitch_joint" class="/" pos="0 0 0" axis="0.0231258 -0.99969 0.00919188" range="-1.92568 0.162649" armature="0.0803834" damping="0.0140455" frictionloss="0.101331"/>
              <geom name="//unnamed_geom_25" class="visual" mesh="right_shank_pitch_link"/>
              <geom name="right_shank_pitch_link.STL" class="collision" size="0.0496648 0.0841863" pos="-1.83816e-05 -0.000838007 -0.120839" type="cylinder" rgba="0.752941 0.752941 0.752941 1"/>
              <geom name="//unnamed_geom_27" class="reward_collision_sphere" size="0.0465714"/>
              <geom name="//unnamed_geom_28" class="reward_collision_sphere" size="0.0558857" pos="0 0 -0.0760868"/>
              <body name="right_foot_pitch_link" pos="-0.00343692 -0.000164841 -0.23598" quat="1 -7.62034e-05 9.1617e-05 1.57411e-05">
                <inertial pos="-0.00216054 -0.00160837 0.000279341" quat="0.000593577 0.706402 0.00041864 0.707811" mass="0.0452851" diaginertia="1.04873e-05 5.35875e-06 8.04368e-07"/>
                <joint name="right_ankle_pitch_joint" class="/" pos="0 0 0" axis="-0.0036026 -0.999919 0.0121707" range="-0.530768 1.08054" armature="0.0814105" damping="0.00077864" frictionloss="0.100332"/>
                <geom name="//unnamed_geom_29" class="visual" mesh="right_foot_pitch_link"/>
                <body name="right_foot_roll_link" pos="-0.00072549 -0.00200774 -0.000294674" quat="1 0.000113657 1.12913e-05 -0.000285931">
                  <inertial pos="0.0411084 -0.00148778 -0.0239784" quat="-0.0115604 0.723906 -0.000386536 0.689801" mass="0.873844" diaginertia="0.00923423 0.00490229 0.000123129"/>
                  <joint name="right_ankle_roll_joint" class="/" pos="0 0 0" axis="-0.999986 -0.00260455 0.00460224" range="-0.439588 0.451367" armature="0.0972697" damping="0.00461572" frictionloss="0.0809976"/>
                  <geom name="//unnamed_geom_30" class="visual" mesh="right_foot_roll_link"/>
                  <geom name="right_foot" class="foot" size="0.150883 0.0415899 0.00849249" pos="0.0498593 0 -0.0307806"/>
                  <geom name="//unnamed_geom_32" class="reward_collision_sphere" size="0.0465714" pos="0 0 -0.0207509"/>
                  <geom name="//unnamed_geom_33" class="reward_collision_sphere" size="0.0465714" pos="0.132958 0 -0.0207509"/>
                  <site name="right_foot" class="foot" pos="0.0498593 0 -0.0307806" size="0.00931428"/>
                </body>
              </body>
            </body>
          </body>
        </body>
      </body>
      <body name="waist_yaw_link" pos="0.00468544 0.00239122 0.00442521" quat="1 0.000221245 3.68852e-05 -4.98822e-05">
        <inertial pos="-0.00193316 -0.00716494 0.0358315" quat="0.97996 0.187893 -0.0284719 0.0596958" mass="1.36974" diaginertia="0.00601092 0.00329581 0.000350526"/>
        <joint name="waist_yaw_joint" class="/" pos="0 0 0" axis="0.00850182 -0.00234597 0.999961" stiffness="0.000164418" range="-1.07409 1.0276" armature="0.0891815" damping="0.0184024" frictionloss="0.0907924"/>
        <geom name="//unnamed_geom_34" class="visual" rgba="0.12 0.12 0.12 1" mesh="waist_yaw_link"/>
        <body name="waist_pitch_link" pos="0.00471674 0.00517594 0.0626439" quat="1 -0.000494656 -0.000549505 -0.000246404">
          <inertial pos="0.00376122 -0.00438821 0.0340807" quat="0.99801 -0.0454251 0.043397 0.00540063" mass="1.25046" diaginertia="0.0078939 0.00451016 0.000288752"/>
          <joint name="waist_pitch_joint" class="/" pos="0 0 0" axis="-0.024892 -0.999108 -0.034119" range="-1.20884 0.460567" armature="0.0858038" damping="0" frictionloss="0.0892461"/>
          <geom name="//unnamed_geom_35" class="visual" rgba="0.12 0.12 0.12 1" mesh="waist_pitch_link"/>
          <body name="waist_roll_link" pos="0.0100059 -0.00317497 0.0580746" quat="1 0.000451027 -0.000426346 -9.0467e-05">
            <inertial pos="-0.0143455 0.00189939 0.103412" quat="0.998701 -0.013279 -0.0489445 -0.00488075" mass="5.35521" diaginertia="0.104662 0.0578503 0.00560584"/>
            <joint name="waist_roll_joint" class="/" pos="0 0 0" axis="-0.999954 -0.00955635 -0.00128376" range="-0.727766 0.685788" armature="0.0962772" damping="0.00918558" frictionloss="0.0822525"/>
            <geom name="//unnamed_geom_36" class="visual" rgba="0.12 0.12 0.12 1" mesh="waist_roll_link"/>
            <geom name="//unnamed_geom_37" class="visual" pos="-0.00249297 0.000571328 0.110914" quat="1 0 0 0" mesh="torso_link"/>
            <geom name="torso_link.STL" class="collision" size="0.146632 0.0281226" pos="-0.0200167 0.00573864 0.102253" type="cylinder" rgba="0.752941 0.752941 0.752941 1"/>
            <geom name="//unnamed_geom_39" class="reward_collision_sphere" size="0.121086" pos="0 0 0.13834"/>
            <body name="left_upper_arm_pitch_link" pos="0.00142183 0.0993528 0.144133" quat="0.97668 0.214698 -1.51368e-05 5.26384e-05">
              <inertial pos="0.00333126 0.0536832 0.00235862" quat="0.70437 0.707549 0.00362502 -0.0567868" mass="0.656388" diaginertia="0.00334326 0.00192969 7.77564e-05"/>
              <joint name="left_shoulder_pitch_joint" class="/" pos="0 0 0" axis="0.000681368 0.999989 -0.00468592" range="-2.79218 1.93368" armature="0.0867512" damping="0.00177465" frictionloss="0.0813047"/>
              <geom name="//unnamed_geom_40" class="visual" mesh="left_upper_arm_pitch_link"/>
              <body name="left_upper_arm_roll_link" pos="0.00135981 0.0935246 0.00193009" quat="0.976681 -0.214696 -6.40829e-05 -0.000397928">
                <inertial pos="0.00617825 0.0159862 -0.0164855" quat="0.888551 0.269851 0.120293 -0.350981" mass="0.512178" diaginertia="0.00174673 0.000992799 5.75399e-05"/>
                <joint name="left_shoulder_roll_joint" class="/" pos="0 0 0" axis="-0.999956 -0.00916342 -0.00212644" range="-2.53547 0.573935" armature="0.109242" damping="0.000366394" frictionloss="0.094895"/>
                <geom name="//unnamed_geom_41" class="visual" mesh="left_upper_arm_roll_link"/>
                <body name="left_upper_arm_yaw_link" pos="0.00197194 0.0391543 -0.0480852" quat="1 0.000109387 1.87973e-05 -4.82255e-05">
                  <inertial pos="-0.000357648 -0.00345799 -0.0632651" quat="0.999958 0.00592085 0.000600881 -0.00700315" mass="0.424048" diaginertia="0.00585867 0.00336014 4.02196e-05"/>
                  <joint name="left_shoulder_yaw_joint" class="/" pos="0 0 0" axis="-0.00675603 0.00209746 0.999975" stiffness="1.46228e-05" range="-2.96702 3.0175" armature="0.094056" damping="0" frictionloss="0.0967971"/>
                  <geom name="//unnamed_geom_42" class="visual" mesh="left_upper_arm_yaw_link"/>
                  <geom name="left_upper_arm_yaw_link.STL" class="collision" size="0.0337486 0.0791173" pos="4.37492e-05 -0.000889461 -0.0548793" quat="0.00803418 -0.995528 0.0941277 0" type="cylinder" rgba="0.752941 0.752941 0.752941 1"/>
                  <body name="left_lower_arm_pitch_link" pos="0.000904347 0.00138916 -0.1253" quat="1 7.38152e-05 -2.60275e-05 0.000187105">
                    <inertial pos="0.000155779 0.00768035 -0.0179515" quat="0.701297 -0.0915688 0.0910942 0.70107" mass="0.262286" diaginertia="0.000497029 0.000288961 1.50774e-05"/>
                    <joint name="left_elbow_pitch_joint" class="/" pos="0 0 0" axis="-0.00202498 0.999998 6.06227e-05" range="-2.27669 2.2838" armature="0.0966185" damping="0.000724639" frictionloss="0.0917062"/>
                    <geom name="//unnamed_geom_44" class="visual" mesh="left_lower_arm_pitch_link"/>
                    <body name="left_hand_yaw_link" pos="-0.000132086 -0.00151792 -0.0418414" quat="1 -0.000115787 -3.2577e-05 0.000795517">
                      <inertial pos="-0.00212677 0.003719 -0.0490476" quat="0.999955 -0.00421621 -0.00126008 0.00844869" mass="0.758391" diaginertia="0.00426119 0.00240531 7.69579e-05"/>
                      <joint name="left_wrist_yaw_joint" class="/" pos="0 0 0" axis="0.00314818 -0.0115262 0.999929" range="-3.0164 2.97983" armature="0.0981549" damping="0.00973041" frictionloss="0.0931028"/>
                      <geom name="//unnamed_geom_45" class="visual" mesh="left_hand_yaw_link"/>
                      <geom name="left_hand_yaw_link.STL" class="collision" size="0.0387212 0.0648215" pos="0.00120687 -0.00153279 -0.0525987" type="cylinder" rgba="0.752941 0.752941 0.752941 1"/>
                      <geom name="//unnamed_geom_47" class="reward_collision_sphere" size="0.0465714"/>
                      <body name="left_hand_roll_link" pos="-0.00255461 -0.000574723 -0.135146" quat="1 0.000295575 0.000161268 0.000295418">
                        <inertial pos="0.000228216 0.00156494 -0.000396333" quat="0.499979 0.498627 0.500735 0.500656" mass="0.00391278" diaginertia="5.64846e-07 3.20655e-07 1.08344e-08"/>
                        <joint name="left_wrist_roll_joint" class="/" pos="0 0 0" axis="-0.99998 -0.00625573 -0.000862551" range="-0.964723 0.869136" armature="0.0939166" damping="0.00647422" frictionloss="0.0957406"/>
                        <geom name="//unnamed_geom_48" class="visual" mesh="left_hand_roll_link"/>
                        <body name="left_hand_pitch_link" pos="0.000393222 0.000458456 -0.000471451" quat="1 -1.23049e-05 1.05893e-05 6.86658e-06">
                          <inertial pos="-0.00140194 -0.0125278 -0.0382213" quat="0.72429 -0.120528 0.115293 0.669017" mass="0.176689" diaginertia="0.00048716 0.000272492 1.50785e-05"/>
                          <joint name="left_wrist_pitch_joint" class="/" pos="0 0 0" axis="-0.00355758 0.999976 0.00586768" range="-0.591257 0.639375" armature="0.0965482" damping="0.0127996" frictionloss="0.0902711"/>
                          <geom name="//unnamed_geom_49" class="visual" mesh="left_hand_pitch"/>
                          <body name="left_jaw_link" pos="-0.000300391 0.000242399 -0.0396781" quat="1 8.35413e-05 -5.14988e-05 -0.0001302">
                            <inertial pos="0.00308979 0.00421854 -0.024354" quat="0.716588 -0.0222772 0.0328297 0.696368" mass="0.0581779" diaginertia="0.00013197 5.53269e-05 5.12846e-06"/>
                            <joint name="left_jaw_joint" class="/" pos="0 0 0" axis="-0.999999 -0.000990875 -0.000901027" range="-0.972651 -0.0284016" armature="0.0987427" damping="0.0158199" frictionloss="0.0866258"/>
                            <geom name="//unnamed_geom_50" class="visual" mesh="left_jaw_link"/>
                            <geom name="//unnamed_geom_51" class="collision" size="0.0335314"/>
                            <geom name="//unnamed_geom_52" class="reward_collision_sphere" size="0.0465714" pos="0 0 -0.013834"/>
                          </body>
                        </body>
                      </body>
                    </body>
                  </body>
                </body>
              </body>
            </body>
            <body name="right_upper_arm_pitch_link" pos="-0.000849588 -0.097567 0.141599" quat="0.976635 -0.214904 0.000147504 -0.000829935">
              <inertial pos="0.00253454 -0.0509593 -0.000341873" quat="0.706024 0.70727 0.0282089 0.022452" mass="0.65179" diaginertia="0.00339496 0.00187594 7.84084e-05"/>
              <joint name="right_shoulder_pitch_joint" class="/" pos="0 0 0" axis="0.0012806 -0.999999 0.000609202" range="-1.95474 2.74822" armature="0.0966759" damping="0.00722544" frictionloss="0.0930063"/>
              <geom name="//unnamed_geom_53" class="visual" mesh="right_upper_arm_pitch_link"/>
              <body name="right_upper_arm_roll_link" pos="-0.00135531 -0.092796 -0.000198945" quat="0.976743 0.214412 0.000732494 0.000112032">
                <inertial pos="0.00550367 -0.0169455 -0.0164612" quat="0.887541 -0.269696 0.122074 0.353033" mass="0.504944" diaginertia="0.00174004 0.00100102 5.44166e-05"/>
                <joint name="right_shoulder_roll_joint" class="/" pos="0 0 0" axis="-0.999932 -0.010068 -0.00588391" range="-0.56147 2.52354" armature="0.0871387" damping="0.012556" frictionloss="0.0984585"/>
                <geom name="//unnamed_geom_54" class="visual" mesh="right_upper_arm_roll_link"/>
                <body name="right_upper_arm_yaw_link" pos="0.000459659 -0.0383925 -0.0486573" quat="1 -0.000157078 0.000142021 -0.000130018">
                  <inertial pos="0.00245899 0.00150074 -0.0615046" quat="0.999848 -0.0138017 -0.00417814 0.00983926" mass="0.418044" diaginertia="0.00578272 0.00329805 3.92647e-05"/>
                  <joint name="right_shoulder_yaw_joint" class="/" pos="0 0 0" axis="0.00407892 0.00013203 0.999992" range="-2.93175 2.9719" armature="0.106547" damping="0" frictionloss="0.105215"/>
                  <geom name="//unnamed_geom_55" class="visual" mesh="right_upper_arm_yaw_link"/>
                  <geom name="right_upper_arm_yaw_link.STL" class="collision" size="0.0337486 0.0791173" pos="4.37492e-05 0.000889461 -0.0548793" type="cylinder" rgba="0.752941 0.752941 0.752941 1"/>
                  <body name="right_lower_arm_pitch_link" pos="-0.000684478 -0.00293044 -0.125195" quat="1 0.000151062 -0.000130254 -0.000497654">
                    <inertial pos="-0.000640326 -0.0081234 -0.0190605" quat="0.702296 0.0918653 -0.0934892 0.699715" mass="0.263252" diaginertia="0.000511771 0.000291468 1.56843e-05"/>
                    <joint name="right_elbow_pitch_joint" class="/" pos="0 0 0" axis="0.00135283 -0.999997 -0.00212749" range="-2.26919 2.26204" armature="0.10147" damping="0.00623085" frictionloss="0.0911597"/>
                    <geom name="//unnamed_geom_57" class="visual" mesh="right_lower_arm_pitch_link"/>
                    <body name="right_hand_yaw_link" pos="0.000901405 0.000348184 -0.03968" quat="0.999999 -0.00071461 0.000799375 9.13474e-05">
                      <inertial pos="-0.000482257 -1.32373e-05 -0.0509977" quat="0.999704 0.00394659 -0.00084037 0.0240125" mass="0.814733" diaginertia="0.00445624 0.00249309 7.95881e-05"/>
                      <joint name="right_wrist_yaw_joint" class="/" pos="0 0 0" axis="-0.00274947 -0.000678235 0.999996" range="-2.99297 2.9949" armature="0.0851444" damping="0.00605208" frictionloss="0.0903142"/>
                      <geom name="//unnamed_geom_58" class="visual" mesh="right_hand_yaw_link"/>
                      <geom name="right_hand_yaw_link.STL" class="collision" size="0.0387212 0.0648215" pos="0.00120687 0.000637652 -0.0525987" type="cylinder" rgba="0.752941 0.752941 0.752941 1"/>
                      <geom name="//unnamed_geom_60" class="reward_collision_sphere" size="0.0465714"/>
                      <body name="right_hand_roll_link" pos="0.00120635 0.000863946 -0.131461" quat="1 0.000119562 -6.39381e-05 0.000547786">
                        <inertial pos="0.00139064 0.00189509 -0.00222386" quat="0.498085 0.501993 0.499959 0.499955" mass="0.00399335" diaginertia="5.83658e-07 3.27324e-07 1.09314e-08"/>
                        <joint name="right_wrist_roll_joint" class="/" pos="0 0 0" axis="-0.99996 0.00840621 -0.00303014" stiffness="0.000451699" range="-0.876541 0.950934" armature="0.0877842" damping="0.00676418" frictionloss="0.0812602"/>
                        <geom name="//unnamed_geom_61" class="visual" mesh="right_hand_roll_link"/>
                        <body name="right_hand_pitch_link" pos="0.00108805 0.00118815 -0.00198653" quat="1 0.000157137 0.000229694 0.000132375">
                          <inertial pos="0.00110043 0.0100002 -0.0354897" quat="0.721857 0.121234 -0.11854 0.67095" mass="0.177416" diaginertia="0.000488419 0.000262865 1.48013e-05"/>
                          <joint name="right_wrist_pitch_joint" class="/" pos="0 0 0" axis="0.0080037 -0.999965 0.00234608" range="-0.640666 0.578787" armature="0.101484" damping="0.003194" frictionloss="0.0938638"/>
                          <geom name="//unnamed_geom_62" class="visual" mesh="right_hand_pitch"/>
                          <body name="right_jaw_link" pos="0.00147202 0.00126825 -0.039632" quat="1 -0.000309854 -0.000140054 -0.000152022">
                            <inertial pos="-0.000345895 -0.00448786 -0.0255091" quat="0.708176 0.0207873 -0.0300154 0.705091" mass="0.0542128" diaginertia="0.000132142 5.23731e-05 5.09867e-06"/>
                            <joint name="right_jaw_joint" class="/" pos="0 0 0" axis="-0.999985 0.00542216 -0.000506137" range="0.00585436 1.00861" armature="0.0829812" damping="0.00564205" frictionloss="0.0899685"/>
                            <geom name="//unnamed_geom_63" class="visual" mesh="right_jaw_link"/>
                            <geom name="//unnamed_geom_64" class="collision" size="0.0335314"/>
                            <geom name="//unnamed_geom_65" class="reward_collision_sphere" size="0.0465714" pos="0 0 -0.013834"/>
                          </body>
                        </body>
                      </body>
                    </body>
                  </body>
                </body>
              </body>
            </body>
            <body name="head_roll_link" pos="0.0020887 0.000728716 0.209213" quat="1 0.000225816 -0.000196055 -0.00017586">
              <inertial pos="0.00489149 0.00136581 -0.00258288" quat="-0.00328992 0.707827 -0.0118771 0.706278" mass="0.00796603" diaginertia="1.13095e-06 4.20392e-07 6.65048e-08"/>
              <joint name="head_roll_joint" class="/" pos="0 0 0" axis="-0.99999 0.00350938 0.00270062" range="-0.34706 0.347624" armature="0.0924904" damping="0.000578032" frictionloss="0.0809906"/>
              <geom name="//unnamed_geom_66" class="visual" mesh="head_roll_link"/>
              <body name="head_pitch_link" pos="0.000444101 -0.00176567 0.00341849" quat="1 2.0595e-05 5.28238e-06 -3.08989e-05">
                <inertial pos="-0.00089351 0.00125029 0.0144596" quat="0.664939 0.664885 0.240345 -0.24087" mass="0.0499708" diaginertia="4.49128e-05 2.37975e-05 2.80801e-06"/>
                <joint name="head_pitch_joint" class="/" pos="0 0 0" axis="0.00576168 -0.999982 0.00147974" range="-0.873704 0.818815" armature="0.086885" damping="0.0156938" frictionloss="0.0933711"/>
                <geom name="//unnamed_geom_67" class="visual" mesh="head_pitch_link"/>
                <body name="head_yaw_link" pos="0.00102736 -0.000148206 0.0361931" quat="0.999999 0.000179867 -0.000958883 0.000751649">
                  <inertial pos="0.0303291 -0.000791818 0.0654921" quat="0.706084 -0.133894 -0.142842 0.680525" mass="1.24598" diaginertia="0.0169462 0.0079764 0.0008335"/>
                  <joint name="head_yaw_joint" class="/" pos="0 0 0" axis="-0.000327971 -0.00221705 0.999997" range="-2.70242 2.69522" armature="0.0862662" damping="0" frictionloss="0.0825011"/>
                  <geom name="//unnamed_geom_68" class="visual" rgba="0.12 0.12 0.12 1" mesh="head_yaw_link"/>
                  <geom name="head_yaw_link.STL" class="collision" size="0.110548" pos="0.0202552 -0.000875272 0.0647569" rgba="0.752941 0.752941 0.752941 1"/>
                  <geom name="//unnamed_geom_70" class="reward_collision_sphere" size="0.0931428" pos="0.0332396 0 0.0691698"/>
                  <camera name="ego_camera" class="/" pos="0.121878 0 0.0760868" quat="-0.5 -0.5 0.5 0.5"/>
                </body>
              </body>
            </body>
          </body>
        </body>
      </body>
    </body>
  </worldbody>

  <contact>
    <pair class="/" geom1="floor" geom2="left_foot" name="//unnamed_contact_0"/>
    <pair class="/" geom1="floor" geom2="right_foot" name="//unnamed_contact_1"/>
  </contact>

  <actuator>
    <general name="left_hip_roll" class="/" joint="left_hip_roll_joint" forcerange="-50.4028 50.4028" gainprm="111.771" biasprm="0 -111.771 -0.931428"/>
    <general name="left_hip_yaw" class="/" joint="left_hip_yaw_joint" forcerange="-61.294 61.294" gainprm="111.771" biasprm="0 -111.771 -0.931428"/>
    <general name="left_hip_pitch" class="/" joint="left_hip_pitch_joint" forcerange="-224.41 224.41" gainprm="111.771" biasprm="0 -111.771 -0.931428"/>
    <general name="left_knee_pitch" class="/" joint="left_knee_pitch_joint" forcerange="-231.835 231.835" gainprm="111.771" biasprm="0 -111.771 -0.931428"/>
    <general name="left_ankle_pitch" class="/" joint="left_ankle_pitch_joint" forcerange="-13.5602 13.5602" gainprm="111.771" biasprm="0 -111.771 -0.931428"/>
    <general name="left_ankle_roll" class="/" joint="left_ankle_roll_joint" forcerange="-26.9029 26.9029" gainprm="111.771" biasprm="0 -111.771 -0.931428"/>
    <general name="right_hip_roll" class="/" joint="right_hip_roll_joint" forcerange="-45.3874 45.3874" gainprm="111.771" biasprm="0 -111.771 -0.931428"/>
    <general name="right_hip_yaw" class="/" joint="right_hip_yaw_joint" forcerange="-61.6923 61.6923" gainprm="111.771" biasprm="0 -111.771 -0.931428"/>
    <general name="right_hip_pitch" class="/" joint="right_hip_pitch_joint" forcerange="-241.647 241.647" gainprm="111.771" biasprm="0 -111.771 -0.931428"/>
    <general name="right_knee_pitch" class="/" joint="right_knee_pitch_joint" forcerange="-208.911 208.911" gainprm="111.771" biasprm="0 -111.771 -0.931428"/>
    <general name="right_ankle_pitch" class="/" joint="right_ankle_pitch_joint" forcerange="-13.7544 13.7544" gainprm="111.771" biasprm="0 -111.771 -0.931428"/>
    <general name="right_ankle_roll" class="/" joint="right_ankle_roll_joint" forcerange="-29.0227 29.0227" gainprm="111.771" biasprm="0 -111.771 -0.931428"/>
    <general name="waist_yaw" class="/" joint="waist_yaw_joint" forcerange="-59.8126 59.8126" gainprm="111.771" biasprm="0 -111.771 -0.931428"/>
    <general name="waist_pitch" class="/" joint="waist_pitch_joint" forcerange="-69.5125 69.5125" gainprm="111.771" biasprm="0 -111.771 -0.931428"/>
    <general name="waist_roll" class="/" joint="waist_roll_joint" forcerange="-58.8575 58.8575" gainprm="111.771" biasprm="0 -111.771 -0.931428"/>
    <general name="left_shoulder_pitch" class="/" joint="left_shoulder_pitch_joint" forcerange="-31.392 31.392" gainprm="111.771" biasprm="0 -111.771 -0.931428"/>
    <general name="left_shoulder_roll" class="/" joint="left_shoulder_roll_joint" forcerange="-36.3623 36.3623" gainprm="111.771" biasprm="0 -111.771 -0.931428"/>
    <general name="left_shoulder_yaw" class="/" joint="left_shoulder_yaw_joint" forcerange="-27.8724 27.8724" gainprm="111.771" biasprm="0 -111.771 -0.931428"/>
    <general name="left_elbow_pitch" class="/" joint="left_elbow_pitch_joint" forcerange="-27.5716 27.5716" gainprm="111.771" biasprm="0 -111.771 -0.931428"/>
    <general name="left_wrist_yaw" class="/" joint="left_wrist_yaw_joint" forcerange="-9.40475 9.40475" gainprm="111.771" biasprm="0 -111.771 -0.931428"/>
    <general name="left_wrist_roll" class="/" joint="left_wrist_roll_joint" forcerange="-3.46301 3.46301" gainprm="111.771" biasprm="0 -111.771 -0.931428"/>
    <general name="left_wrist_pitch" class="/" joint="left_wrist_pitch_joint" forcerange="-3.86771 3.86771" gainprm="111.771" biasprm="0 -111.771 -0.931428"/>
    <general name="left_jaw" class="/" joint="left_jaw_joint" forcerange="-3.63227 3.63227" gainprm="111.771" biasprm="0 -111.771 -0.931428"/>
    <general name="right_shoulder_pitch" class="/" joint="right_shoulder_pitch_joint" forcerange="-35.5855 35.5855" gainprm="111.771" biasprm="0 -111.771 -0.931428"/>
    <general name="right_shoulder_roll" class="/" joint="right_shoulder_roll_joint" forcerange="-35.2986 35.2986" gainprm="111.771" biasprm="0 -111.771 -0.931428"/>
    <general name="right_shoulder_yaw" class="/" joint="right_shoulder_yaw_joint" forcerange="-27.3371 27.3371" gainprm="111.771" biasprm="0 -111.771 -0.931428"/>
    <general name="right_elbow_pitch" class="/" joint="right_elbow_pitch_joint" forcerange="-27.955 27.955" gainprm="111.771" biasprm="0 -111.771 -0.931428"/>
    <general name="right_wrist_yaw" class="/" joint="right_wrist_yaw_joint" forcerange="-9.38101 9.38101" gainprm="111.771" biasprm="0 -111.771 -0.931428"/>
    <general name="right_wrist_roll" class="/" joint="right_wrist_roll_joint" forcerange="-3.78396 3.78396" gainprm="111.771" biasprm="0 -111.771 -0.931428"/>
    <general name="right_wrist_pitch" class="/" joint="right_wrist_pitch_joint" forcerange="-3.62215 3.62215" gainprm="111.771" biasprm="0 -111.771 -0.931428"/>
    <general name="right_jaw" class="/" joint="right_jaw_joint" forcerange="-3.62266 3.62266" gainprm="111.771" biasprm="0 -111.771 -0.931428"/>
    <general name="head_roll" class="/" joint="head_roll_joint" forcerange="-3.82597 3.82597" gainprm="111.771" biasprm="0 -111.771 -0.931428"/>
    <general name="head_pitch" class="/" joint="head_pitch_joint" forcerange="-3.83546 3.83546" gainprm="111.771" biasprm="0 -111.771 -0.931428"/>
    <general name="head_yaw" class="/" joint="head_yaw_joint" forcerange="-3.6161 3.6161" gainprm="111.771" biasprm="0 -111.771 -0.931428"/>
  </actuator>

  <sensor>
    <gyro site="imu" name="imu_angular_velocity"/>
    <velocimeter site="imu" name="imu_linear_velocity"/>
    <framelinvel objtype="site" objname="left_foot" name="left_foot_global_linear_velocity"/>
    <framelinvel objtype="site" objname="right_foot" name="right_foot_global_linear_velocity"/>
  </sensor>

  <keyframe>
    <key name="home" qpos="0 0 0.8665 1 0 0 0 0 0 -0.4 0.8 -0.4 0 0 0 0.4 -0.8 0.4 0 0 0 0 0 -0.2 0 -0.785 0 0 0 0 0 0.2 0 0.785 0 0 0 0 0 0 0"/>
  </keyframe>
</mujoco>
