<mujoco model="GR1T2_jaw">
  <compiler angle="radian" assetdir="assets" balanceinertia="true" inertiafromgeom="false"/>

  <option timestep="0.005" density="1.2" viscosity="2e-05"/>

  <size nkey="1"/>

  <visual>
    <quality shadowsize="8192"/>
    <map shadowclip="0.5"/>
  </visual>

  <default>
    <default class="/">
      <joint armature="0.1" damping="0.01" frictionloss="0.1"/>
      <geom contype="0" conaffinity="0" group="1" solref="-1000 -80"/>
      <site size="0.01 0.005 0.005" group="5"/>
      <general forcelimited="true" biastype="affine" gainprm="80" biasprm="0 -80 -2"/>
      <default class="visual">
        <geom type="mesh" density="0" rgba="0.18 0.18 0.18 1"/>
      </default>
      <default class="collision">
        <geom group="3"/>
      </default>
      <default class="foot">
        <geom size="0.126 0.045 0.01" type="box" condim="6" group="4" priority="1" solimp="0.015 1 0.01"/>
      </default>
      <default class="reward_collision_sphere">
        <geom group="5" rgba="1 0 0 1"/>
      </default>
    </default>
  </default>

  <asset>
    <texture type="skybox" colorspace="auto" name="//unnamed_texture_0" builtin="gradient" rgb1="0.95 0.95 0.95" rgb2="0.95 0.95 0.95" width="100" height="600"/>
    <texture type="2d" colorspace="auto" name="texplane" builtin="checker" rgb1="0.345 0.575 0.748" rgb2="0.345 0.575 0.748" markrgb="1 1 1" width="512" height="512"/>
    <material name="MatPlane" class="/" texture="texplane" texuniform="true" texrepeat="2 2" specular="0.9"/>
    <mesh name="base_link" class="/" file="base_link.STL"/>
    <mesh name="left_thigh_roll_link" class="/" file="left_thigh_roll_link.STL"/>
    <mesh name="left_thigh_yaw_link" class="/" file="left_thigh_yaw_link.STL"/>
    <mesh name="left_thigh_pitch_link" class="/" file="left_thigh_pitch_link.STL"/>
    <mesh name="left_shank_pitch_link" class="/" file="left_shank_pitch_link.STL"/>
    <mesh name="left_foot_pitch_link" class="/" file="left_foot_pitch_link.STL"/>
    <mesh name="left_foot_roll_link" class="/" file="left_foot_roll_link.STL"/>
    <mesh name="right_thigh_roll_link" class="/" file="right_thigh_roll_link.STL"/>
    <mesh name="right_thigh_yaw_link" class="/" file="right_thigh_yaw_link.STL"/>
    <mesh name="right_thigh_pitch_link" class="/" file="right_thigh_pitch_link.STL"/>
    <mesh name="right_shank_pitch_link" class="/" file="right_shank_pitch_link.STL"/>
    <mesh name="right_foot_pitch_link" class="/" file="right_foot_pitch_link.STL"/>
    <mesh name="right_foot_roll_link" class="/" file="right_foot_roll_link.STL"/>
    <mesh name="waist_yaw_link" class="/" file="waist_yaw_link.STL"/>
    <mesh name="waist_pitch_link" class="/" file="waist_pitch_link.STL"/>
    <mesh name="waist_roll_link" class="/" file="waist_roll_link.STL"/>
    <mesh name="torso_link" class="/" file="torso_link.STL"/>
    <mesh name="left_upper_arm_pitch_link" class="/" file="left_upper_arm_pitch_link.STL"/>
    <mesh name="left_upper_arm_roll_link" class="/" file="left_upper_arm_roll_link.STL"/>
    <mesh name="left_upper_arm_yaw_link" class="/" file="left_upper_arm_yaw_link.STL"/>
    <mesh name="left_lower_arm_pitch_link" class="/" file="left_lower_arm_pitch_link.STL"/>
    <mesh name="left_hand_yaw_link" class="/" file="left_hand_yaw_link.STL"/>
    <mesh name="left_hand_roll_link" class="/" file="left_hand_roll_link.STL"/>
    <mesh name="left_hand_pitch" class="/" file="left_hand_pitch.STL"/>
    <mesh name="left_jaw_link" class="/" file="left_jaw_link.STL"/>
    <mesh name="right_upper_arm_pitch_link" class="/" file="right_upper_arm_pitch_link.STL"/>
    <mesh name="right_upper_arm_roll_link" class="/" file="right_upper_arm_roll_link.STL"/>
    <mesh name="right_upper_arm_yaw_link" class="/" file="right_upper_arm_yaw_link.STL"/>
    <mesh name="right_lower_arm_pitch_link" class="/" file="right_lower_arm_pitch_link.STL"/>
    <mesh name="right_hand_yaw_link" class="/" file="right_hand_yaw_link.STL"/>
    <mesh name="right_hand_roll_link" class="/" file="right_hand_roll_link.STL"/>
    <mesh name="right_hand_pitch" class="/" file="right_hand_pitch.STL"/>
    <mesh name="right_jaw_link" class="/" file="right_jaw_link.STL"/>
    <mesh name="head_roll_link" class="/" file="head_roll_link.STL"/>
    <mesh name="head_pitch_link" class="/" file="head_pitch_link.STL"/>
    <mesh name="head_yaw_link" class="/" file="head_yaw_link.STL"/>
    <mesh name="imu_link" class="/" file="imu_link.STL"/>
  </asset>

  <worldbody>
    <geom name="floor" class="/" size="100 100 0.125" type="plane" group="0" material="MatPlane"/>
    <light name="toplight_shadow" class="/" pos="0 0 5" dir="0.0990148 0.0990148 -0.990148" type="directional" ambient="0.04 0.04 0.04" diffuse="0.55 0.55 0.55" specular="0.12 0.12 0.12"/>
    <light name="toplight_fill" class="/" pos="0 0 5" dir="0.0990148 0.0990148 -0.990148" type="directional" castshadow="false" ambient="0.04 0.04 0.04" diffuse="0.3 0.3 0.3" specular="0.08 0.08 0.08"/>
    <body name="trunk" pos="-0.0143955 -0.0149201 -0.00855699" quat="0.999996 -0.00159404 0.00207754 0.000548909">
      <inertial pos="-0.0406013 -0.00575936 0.00226646" quat="0.999963 -0.00594807 0.00253109 0.00559026" mass="5.17089" diaginertia="0.0349833 0.168277 0.00195253"/>
      <joint name="//unnamed_joint_0" type="free"/>
      <geom name="//unnamed_geom_1" class="visual" rgba="0.12 0.12 0.12 1" mesh="base_link"/>
      <geom name="base_link.STL" class="collision" size="0.12576 0.0704358" pos="-0.0398663 0.000592462 0.00502173" quat="0.706838 -0.707359 0.00477667 0" type="cylinder" rgba="0.752941 0.752941 0.752941 1"/>
      <geom name="//unnamed_geom_3" class="visual" pos="0 0 -0.0324964" quat="1 0 0 0" rgba="0.12 0.12 0.12 1" mesh="imu_link"/>
      <geom name="//unnamed_geom_4" class="reward_collision_sphere" size="0.0822003" pos="0 0.160107 0.0545242"/>
      <geom name="//unnamed_geom_5" class="reward_collision_sphere" size="0.0822003" pos="0 -0.160107 0.0545242"/>
      <site name="imu" class="/" pos="-0.0846201 -0.0525945 -0.00335914" size="0.010275"/>
      <camera name="track" class="/" pos="0 -3.20213 0" quat="0.707107 0.707107 0 0" mode="trackcom"/>
      <body name="left_thigh_roll_link" pos="-0.0411014 0.184467 -0.0319405" quat="0.999997 0.00105755 -0.00193248 0.000790378">
        <inertial pos="-0.000395274 -0.00860332 0.0141711" quat="-0.108007 0.701418 -0.0187606 0.704269" mass="1.2311" diaginertia="0.00183381 0.0288104 8.05996e-05"/>
        <joint name="left_hip_roll_joint" class="/" pos="0 0 0" axis="-0.999293 -0.0358856 -0.0111768" range="-0.489604 -0.0693102" armature="0.112347" damping="0" frictionloss="0.189894"/>
        <geom name="//unnamed_geom_6" class="visual" mesh="left_thigh_roll_link"/>
        <body name="left_thigh_yaw_link" pos="0.0286571 -0.0146742 0.00306862" quat="1 -0.000102362 -9.90847e-05 -6.99441e-07">
          <inertial pos="-0.016991 0.0565957 -0.0431721" quat="0.572929 0.139647 -0.187418 0.785573" mass="3.88162" diaginertia="0.0200747 0.214417 0.000390129"/>
          <joint name="left_hip_yaw_joint" class="/" pos="0 0 0" axis="0.0266192 0.00449584 -0.999636" range="-0.910097 0.637415" armature="0.103818" damping="0" frictionloss="0.0768769"/>
          <geom name="//unnamed_geom_7" class="visual" mesh="left_thigh_yaw_link"/>
          <body name="left_thigh_pitch_link" pos="-0.0151381 0.0214305 -0.0902859" quat="0.999995 -0.000473765 -0.00320813 -0.000560424">
            <inertial pos="-0.00523706 -0.0343714 -0.033597" quat="0.999736 0.0197349 0.0085625 -0.00813123" mass="11.6216" diaginertia="0.0825571 0.948607 0.00173149"/>
            <joint name="left_hip_pitch_joint" class="/" pos="0 0 0" axis="0.0185944 0.999558 -0.023197" range="-2.02395 0.76051" armature="0.0299016" damping="0.0687412" frictionloss="0.107388"/>
            <geom name="//unnamed_geom_8" class="visual" mesh="left_thigh_pitch_link"/>
            <geom name="left_thigh_pitch_link.STL" class="collision" size="0.0842553 0.12835" pos="0.00065539 -0.048032 -0.0910859" type="cylinder" rgba="0.752941 0.752941 0.752941 1"/>
            <geom name="//unnamed_geom_10" class="reward_collision_sphere" size="0.10275" pos="0 -0.0160107 -0.0272621"/>
            <body name="left_shank_pitch_link" pos="-0.00612757 -0.0310898 -0.187053" quat="1 7.74223e-05 -0.000601456 0.000355507">
              <inertial pos="0.0106405 0.000972559 -0.0654503" quat="0.997528 0.02974 -0.0428058 -0.0471388" mass="1.91101" diaginertia="0.0062979 0.125333 5.22175e-05"/>
              <joint name="left_knee_pitch_joint" class="/" pos="0 0 0" axis="-0.0452539 0.998937 0.00875372" range="-0.136176 1.91453" armature="0.113297" damping="0" frictionloss="0.113771"/>
              <geom name="//unnamed_geom_11" class="visual" mesh="left_shank_pitch_link"/>
              <geom name="left_shank_pitch_link.STL" class="collision" size="0.054788 0.0928709" pos="-1.55317e-05 -0.00134897 -0.0952488" quat="0.00125538 -0.202712 0.979238 0" type="cylinder" rgba="0.752941 0.752941 0.752941 1"/>
              <geom name="//unnamed_geom_13" class="reward_collision_sphere" size="0.0513752"/>
              <geom name="//unnamed_geom_14" class="reward_collision_sphere" size="0.0616502" pos="0 0 -0.0599766"/>
              <body name="left_foot_pitch_link" pos="-0.00631872 -0.00769882 -0.175375" quat="1 -0.000227011 0.000332328 -7.18952e-05">
                <inertial pos="0.00745014 -0.0159481 0.000159669" quat="0.0159749 0.713817 -0.00447197 0.700136" mass="0.0562389" diaginertia="4.41933e-06 5.57266e-05 2.68534e-07"/>
                <joint name="left_ankle_pitch_joint" class="/" pos="0 0 0" axis="0.0265919 0.999525 0.0155716" stiffness="0.0333383" range="-0.78515 0.749456" armature="0.139678" damping="0" frictionloss="0.125157"/>
                <geom name="//unnamed_geom_15" class="visual" mesh="left_foot_pitch_link"/>
                <body name="left_foot_roll_link" pos="0.00692718 -0.0119364 0.00927554" quat="0.999986 -0.00494492 0.00120023 -0.00164278">
                  <inertial pos="0.0322014 0.000444502 -0.0328254" quat="-0.00683189 0.740284 0.00104547 0.672259" mass="1.05327" diaginertia="0.00281436 0.0422095 2.30072e-05"/>
                  <joint name="left_ankle_roll_joint" class="/" pos="0 0 0" axis="-0.999944 0.00856469 0.00619436" stiffness="0.0559732" range="-0.162491 0.728199" armature="0.0444314" damping="0.0546324" frictionloss="0.0589444"/>
                  <geom name="//unnamed_geom_16" class="visual" mesh="left_foot_roll_link"/>
                  <geom name="left_foot" class="foot" size="0.123055 0.0367219 0.0162554" pos="0.0421292 0 -0.0242633"/>
                  <geom name="//unnamed_geom_18" class="reward_collision_sphere" size="0.0513752" pos="0 0 -0.0163573"/>
                  <geom name="//unnamed_geom_19" class="reward_collision_sphere" size="0.0513752" pos="0.112344 0 -0.0163573"/>
                  <site name="left_foot" class="foot" pos="0.0421292 0 -0.0242633" size="0.010275"/>
                </body>
              </body>
            </body>
          </body>
        </body>
      </body>
      <body name="right_thigh_roll_link" pos="-0.0193537 -0.178012 -0.0129144" quat="0.999996 -0.00201163 0.000509085 0.00214929">
        <inertial pos="-0.00688882 -0.00056425 -0.000587059" quat="0.0590983 0.679272 -0.00477184 0.731488" mass="1.73965" diaginertia="0.00186721 0.0285775 6.93456e-05"/>
        <joint name="right_hip_roll_joint" class="/" pos="0 0 0" axis="-0.998959 0.0316165 -0.0328694" stiffness="0.0574734" range="-0.0765336 0.830632" armature="0.107809" damping="0" frictionloss="0.107345"/>
        <geom name="//unnamed_geom_20" class="visual" mesh="right_thigh_roll_link"/>
        <body name="right_thigh_yaw_link" pos="0.0218877 -0.0072739 0.00275308" quat="1 -8.36636e-05 7.00702e-05 3.70242e-05">
          <inertial pos="0.00801608 -0.060226 -0.0487347" quat="0.662195 -0.0803177 0.146975 0.730373" mass="3.72274" diaginertia="0.0174043 0.194358 0.000459404"/>
          <joint name="right_hip_yaw_joint" class="/" pos="0 0 0" axis="0.0357163 0.0514837 -0.998035" range="-1.01006 0.441803" armature="0.152732" damping="0.0431317" frictionloss="0.0985829"/>
          <geom name="//unnamed_geom_21" class="visual" mesh="right_thigh_yaw_link"/>
          <body name="right_thigh_pitch_link" pos="-0.002033 -0.0365454 -0.0731519" quat="1 -0.000215275 0.000433327 -0.000642377">
            <inertial pos="0.00760258 0.0462075 -0.0404011" quat="0.996003 -0.0402499 -0.0785834 0.0134791" mass="9.39232" diaginertia="0.066345 0.898564 0.0014676"/>
            <joint name="right_hip_pitch_joint" class="/" pos="0 0 0" axis="0.0125948 -0.997809 0.06495" stiffness="0.0270105" range="-0.704712 1.97499" armature="0.0549772" damping="0.00540126" frictionloss="0.12009"/>
            <geom name="//unnamed_geom_22" class="visual" mesh="right_thigh_pitch_link"/>
            <geom name="right_thigh_pitch_link.STL" class="collision" size="0.0842553 0.128347" pos="-0.00198781 0.048032 -0.0910859" quat="0.999971 0.00269833 0.00706272 0" type="cylinder" rgba="0.752941 0.752941 0.752941 1"/>
            <geom name="//unnamed_geom_24" class="reward_collision_sphere" size="0.10275" pos="0 0.0160107 -0.0272621"/>
            <body name="right_shank_pitch_link" pos="-0.00847765 0.0397977 -0.202198" quat="0.99999 0.000175939 0.00285373 -0.00348296">
              <inertial pos="0.00971692 -0.00571086 -0.076811" quat="0.996068 0.0708577 -0.0393083 0.0358115" mass="1.82027" diaginertia="0.00880784 0.138392 6.3317e-05"/>
              <joint name="right_knee_pitch_joint" class="/" pos="0 0 0" axis="0.00623212 -0.997835 -0.0654756" stiffness="0.0555051" range="-1.91867 -0.247147" armature="0.171863" damping="0" frictionloss="0.0390039"/>
              <geom name="//unnamed_geom_25" class="visual" mesh="right_shank_pitch_link"/>
              <geom name="right_shank_pitch_link.STL" class="collision" size="0.0547876 0.09287" pos="-1.55317e-05 -0.00134899 -0.0952532" type="cylinder" rgba="0.752941 0.752941 0.752941 1"/>
              <geom name="//unnamed_geom_27" class="reward_collision_sphere" size="0.0513752"/>
              <geom name="//unnamed_geom_28" class="reward_collision_sphere" size="0.0616502" pos="0 0 -0.0599766"/>
              <body name="right_foot_pitch_link" pos="0.0135219 0.00025824 -0.190257" quat="0.999999 -0.00118373 0.000167399 -0.000692777">
                <inertial pos="0.0155232 -0.00107794 0.00797075" quat="0.0119864 0.703102 0.00554485 0.710967" mass="0.0651587" diaginertia="4.25091e-06 4.86282e-05 2.90829e-07"/>
                <joint name="right_ankle_pitch_joint" class="/" pos="0 0 0" axis="-0.0540821 -0.997854 -0.0369086" range="-0.690415 1.19828" armature="0.185117" damping="0.00831398" frictionloss="0.0413122"/>
                <geom name="//unnamed_geom_29" class="visual" mesh="right_foot_pitch_link"/>
                <body name="right_foot_roll_link" pos="-0.0100271 -0.000912912 -0.00198855" quat="1 9.56622e-05 -5.33138e-05 -5.95698e-05">
                  <inertial pos="0.0339239 0.00134927 -0.0365724" quat="0.0558349 0.688761 0.00768084 0.722795" mass="1.2355" diaginertia="0.00367636 0.0494519 3.02218e-05"/>
                  <joint name="right_ankle_roll_joint" class="/" pos="0 0 0" axis="-0.999951 0.0054162 0.00830753" range="-0.653467 0.259426" armature="0.131388" damping="0" frictionloss="0.185089"/>
                  <geom name="//unnamed_geom_30" class="visual" mesh="right_foot_roll_link"/>
                  <geom name="right_foot" class="foot" size="0.0979816 0.0559456 0.0162771" pos="0.0421292 0 -0.0242633"/>
                  <geom name="//unnamed_geom_32" class="reward_collision_sphere" size="0.0513752" pos="0 0 -0.0163573"/>
                  <geom name="//unnamed_geom_33" class="reward_collision_sphere" size="0.0513752" pos="0.112344 0 -0.0163573"/>
                  <site name="right_foot" class="foot" pos="0.0421292 0 -0.0242633" size="0.010275"/>
                </body>
              </body>
            </body>
          </body>
        </body>
      </body>
      <body name="waist_yaw_link" pos="0.00522689 0.000472212 -0.0155345" quat="0.999983 0.000853508 0.00459583 0.00360535">
        <inertial pos="-0.0109666 -0.007053 0.0285286" quat="0.980598 0.185078 -0.014152 0.0630288" mass="1.702" diaginertia="0.00201503 0.032441 9.40084e-05"/>
        <joint name="waist_yaw_joint" class="/" pos="0 0 0" axis="0.00287878 -0.00071184 0.999996" stiffness="0.0146674" range="-1.16198 1.0785" armature="0.163891" damping="0" frictionloss="0.153428"/>
        <geom name="//unnamed_geom_34" class="visual" rgba="0.12 0.12 0.12 1" mesh="waist_yaw_link"/>
        <body name="waist_pitch_link" pos="0.0103198 -0.0149377 0.0574869" quat="0.99999 0.00155273 -0.00428223 -2.06275e-05">
          <inertial pos="-0.00638254 0.00756578 0.0111504" quat="0.996256 -0.07833 0.0350976 0.0102984" mass="1.45781" diaginertia="0.002803 0.0465663 8.67219e-05"/>
          <joint name="waist_pitch_joint" class="/" pos="0 0 0" axis="-0.00641594 -0.997994 -0.0629793" range="-1.01067 0.354906" armature="0.0708668" damping="0.0695911" frictionloss="0.154709"/>
          <geom name="//unnamed_geom_35" class="visual" rgba="0.12 0.12 0.12 1" mesh="waist_pitch_link"/>
          <body name="waist_roll_link" pos="0.0144201 0.0131735 0.0508986" quat="0.999979 0.00304323 -0.00161189 -0.00541956">
            <inertial pos="-0.0113489 -0.0100547 0.0858903" quat="0.994483 0.0104809 -0.0837104 0.0623335" mass="7.12231" diaginertia="0.0417718 0.561272 0.00152425"/>
            <joint name="waist_roll_joint" class="/" pos="0 0 0" axis="-0.999999 0.000261902 0.00136245" range="-0.678846 0.672838" armature="0.122243" damping="0.0660066" frictionloss="0.176585"/>
            <geom name="//unnamed_geom_36" class="visual" rgba="0.12 0.12 0.12 1" mesh="waist_roll_link"/>
            <geom name="//unnamed_geom_37" class="visual" pos="-0.00210646 0.000919701 0.0874295" quat="1 0 0 0" mesh="torso_link"/>
            <geom name="torso_link.STL" class="collision" size="0.161757 0.0310234" pos="-0.0169134 0.00923783 0.0806026" type="cylinder" rgba="0.752941 0.752941 0.752941 1"/>
            <geom name="//unnamed_geom_39" class="reward_collision_sphere" size="0.133576" pos="0 0 0.109048"/>
            <body name="left_upper_arm_pitch_link" pos="-0.0127024 0.162418 0.110461" quat="0.976821 0.214058 8.96044e-05 3.79303e-05">
              <inertial pos="-0.00289005 0.0741898 -0.0152269" quat="0.713359 0.699017 -0.0406242 -0.0290435" mass="0.721413" diaginertia="0.0015336 0.0205994 2.12132e-05"/>
              <joint name="left_shoulder_pitch_joint" class="/" pos="0 0 0" axis="0.00296515 0.999485 0.0319477" range="-2.77938 1.92761" armature="0.174893" damping="0.0172554" frictionloss="0.182036"/>
              <geom name="//unnamed_geom_40" class="visual" mesh="left_upper_arm_pitch_link"/>
              <body name="left_upper_arm_roll_link" pos="0.00547512 0.150567 0.00406667" quat="0.975862 -0.218346 -0.00161099 0.00406862">
                <inertial pos="-0.00531492 0.0185195 -0.01402" quat="0.896129 0.27689 0.131551 -0.320903" mass="0.596191" diaginertia="0.000813768 0.0111432 1.55143e-05"/>
                <joint name="left_shoulder_roll_joint" class="/" pos="0 0 0" axis="-0.996716 -0.0804392 -0.00930765" range="-2.33848 0.403752" armature="0.024142" damping="0.0407592" frictionloss="0.0959323"/>
                <geom name="//unnamed_geom_41" class="visual" mesh="left_upper_arm_roll_link"/>
                <body name="left_upper_arm_yaw_link" pos="-0.00886699 0.0611601 -0.0396378" quat="1 7.05681e-05 -0.000194619 -0.000203095">
                  <inertial pos="0.000801223 0.0149785 -0.0325947" quat="0.999931 0.00916402 -0.00230233 -0.00694148" mass="0.619491" diaginertia="0.00210925 0.0321368 1.09601e-05"/>
                  <joint name="left_shoulder_yaw_joint" class="/" pos="0 0 0" axis="-0.0267915 -0.00548397 0.999626" stiffness="0.00164456" range="-2.9656 2.70818" armature="0.153319" damping="0.0725857" frictionloss="0.139629"/>
                  <geom name="//unnamed_geom_42" class="visual" mesh="left_upper_arm_yaw_link"/>
                  <geom name="left_upper_arm_yaw_link.STL" class="collision" size="0.0372298 0.0872782" pos="3.69664e-05 -0.00143182 -0.0432595" quat="0.00803418 -0.995528 0.0941277 0" type="cylinder" rgba="0.752941 0.752941 0.752941 1"/>
                  <body name="left_lower_arm_pitch_link" pos="-2.86192e-06 -0.0104222 -0.0817357" quat="1 2.02071e-05 3.5473e-06 4.38784e-05">
                    <inertial pos="0.00886987 0.0168614 -0.00296472" quat="0.701451 -0.0928553 0.0894374 0.70096" mass="0.410515" diaginertia="0.00020446 0.00312678 5.6989e-06"/>
                    <joint name="left_elbow_pitch_joint" class="/" pos="0 0 0" axis="0.0410061 0.99915 -0.00409855" range="-2.28099 2.44305" armature="0.064323" damping="0.000224496" frictionloss="0.116651"/>
                    <geom name="//unnamed_geom_44" class="visual" mesh="left_lower_arm_pitch_link"/>
                    <body name="left_hand_yaw_link" pos="0.00465918 0.0103376 -0.0351453" quat="0.999983 -0.00537942 0.00165006 0.00168165">
                      <inertial pos="0.0149685 -0.0129638 -0.0521561" quat="0.999937 -0.00405733 -0.000173211 0.0104505" mass="1.48684" diaginertia="0.00249489 0.0357542 3.15147e-05"/>
                      <joint name="left_wrist_yaw_joint" class="/" pos="0 0 0" axis="-0.038266 -0.0712846 0.996722" range="-2.63101 2.99785" armature="0.14968" damping="0.0337116" frictionloss="0.100753"/>
                      <geom name="//unnamed_geom_45" class="visual" mesh="left_hand_yaw_link"/>
                      <geom name="left_hand_yaw_link.STL" class="collision" size="0.0427153 0.0715078" pos="0.00101976 -0.00246742 -0.0414618" type="cylinder" rgba="0.752941 0.752941 0.752941 1"/>
                      <geom name="//unnamed_geom_47" class="reward_collision_sphere" size="0.0513752"/>
                      <body name="left_hand_roll_link" pos="0.0147988 0.00951527 -0.0880352" quat="0.999996 -0.000636994 0.000323764 -0.00273915">
                        <inertial pos="-0.00263345 -0.0132635 0.00106084" quat="0.499929 0.499812 0.500633 0.499626" mass="0.0065395" diaginertia="3.04005e-07 5.14788e-06 4.25759e-09"/>
                        <joint name="left_wrist_roll_joint" class="/" pos="0 0 0" axis="-0.998646 0.0109955 0.0508471" range="-1.06315 0.876249" armature="0.116181" damping="0.0503943" frictionloss="0.124329"/>
                        <geom name="//unnamed_geom_48" class="visual" mesh="left_hand_roll_link"/>
                        <body name="left_hand_pitch_link" pos="-0.00912077 -0.000360453 -0.00165873" quat="1 9.98848e-05 0.000206133 -0.000123863">
                          <inertial pos="-0.00708572 -0.023197 -0.0346176" quat="0.723013 -0.121819 0.114824 0.670244" mass="0.235748" diaginertia="0.000223809 0.00251041 4.86541e-06"/>
                          <joint name="left_wrist_pitch_joint" class="/" pos="0 0 0" axis="0.00206514 0.999736 0.0228963" range="-0.653316 0.363404" armature="0.15011" damping="0" frictionloss="0.0809307"/>
                          <geom name="//unnamed_geom_49" class="visual" mesh="left_hand_pitch"/>
                          <body name="left_jaw_link" pos="0.00160838 -0.00700064 -0.0462493" quat="1 -7.07819e-05 -4.97647e-05 4.75501e-05">
                            <inertial pos="-0.0129794 0.0136756 -0.0156848" quat="0.747674 0.00507691 -0.0109151 0.663957" mass="0.0592085" diaginertia="5.04299e-05 0.000496287 1.55108e-06"/>
                            <joint name="left_jaw_joint" class="/" pos="0 0 0" axis="-0.999995 0.00149079 -0.00264696" range="-0.984518 0.179544" armature="0.0976914" damping="0" frictionloss="0.161821"/>
                            <geom name="//unnamed_geom_50" class="visual" mesh="left_jaw_link"/>
                            <geom name="//unnamed_geom_51" class="collision" size="0.0369901"/>
                            <geom name="//unnamed_geom_52" class="reward_collision_sphere" size="0.0513752" pos="0 0 -0.0109048"/>
                          </body>
                        </body>
                      </body>
                    </body>
                  </body>
                </body>
              </body>
            </body>
            <body name="right_upper_arm_pitch_link" pos="-0.00118073 -0.15861 0.111159" quat="0.976965 -0.213294 -0.0017232 -0.00647739">
              <inertial pos="0.00449871 -0.101526 0.000120753" quat="0.707005 0.706487 0.024838 0.020104" mass="0.852955" diaginertia="0.00151072 0.0180023 2.43787e-05"/>
              <joint name="right_shoulder_pitch_joint" class="/" pos="0 0 0" axis="-0.00877665 -0.99992 0.00906166" stiffness="0.000626395" range="-1.66691 3.11262" armature="0.105885" damping="0.0397135" frictionloss="0.098625"/>
              <geom name="//unnamed_geom_53" class="visual" mesh="right_upper_arm_pitch_link"/>
              <body name="right_upper_arm_roll_link" pos="0.0165009 -0.155564 -0.00504638" quat="0.976603 0.214978 -0.00234561 0.00510144">
                <inertial pos="0.00864289 -0.0386148 -0.0147064" quat="0.897008 -0.261859 0.163611 0.316289" mass="0.61592" diaginertia="0.000637893 0.00789127 1.75472e-05"/>
                <joint name="right_shoulder_roll_joint" class="/" pos="0 0 0" axis="-0.998105 0.0111039 0.0605204" stiffness="0.0226422" range="-0.616712 2.39102" armature="0.175096" damping="0.0424135" frictionloss="0.0458203"/>
                <geom name="//unnamed_geom_54" class="visual" mesh="right_upper_arm_roll_link"/>
                <body name="right_upper_arm_yaw_link" pos="0.00956172 -0.0654624 -0.044766" quat="0.999992 -0.000826493 -0.00383432 0.00115013">
                  <inertial pos="-0.016223 -0.0134138 -0.0561248" quat="0.997623 0.0436142 0.03388 -0.0412022" mass="0.793003" diaginertia="0.00303642 0.0417507 1.70242e-05"/>
                  <joint name="right_shoulder_yaw_joint" class="/" pos="0 0 0" axis="-0.019358 -0.0390138 0.999051" range="-3.22152 2.97605" armature="0.0308085" damping="0" frictionloss="0.0176379"/>
                  <geom name="//unnamed_geom_55" class="visual" mesh="right_upper_arm_yaw_link"/>
                  <geom name="right_upper_arm_yaw_link.STL" class="collision" size="0.0372298 0.0872782" pos="3.69664e-05 0.00143182 -0.0432595" type="cylinder" rgba="0.752941 0.752941 0.752941 1"/>
                  <body name="right_lower_arm_pitch_link" pos="-0.0055714 0.0132139 -0.0819123" quat="0.999987 -0.00429534 -0.00274876 0.000873338">
                    <inertial pos="-0.000537503 -0.0126271 -0.0013904" quat="0.700721 0.083976 -0.0903558 0.70269" mass="0.330999" diaginertia="0.00018282 0.00334406 4.17334e-06"/>
                    <joint name="right_elbow_pitch_joint" class="/" pos="0 0 0" axis="0.00200694 -0.999998 0.000492028" stiffness="0.0704768" range="-2.08414 2.11742" armature="0.0479804" damping="0.0575226" frictionloss="0.116145"/>
                    <geom name="//unnamed_geom_57" class="visual" mesh="right_lower_arm_pitch_link"/>
                    <body name="right_hand_yaw_link" pos="0.00285734 -0.00586601 -0.0269507" quat="0.999977 -0.00496209 -0.00325437 0.00335035">
                      <inertial pos="-0.00392338 -0.0192867 -0.0294074" quat="0.999733 0.00411677 -0.00189369 0.0226397" mass="0.812464" diaginertia="0.00155257 0.0202875 2.29718e-05"/>
                      <joint name="right_wrist_yaw_joint" class="/" pos="0 0 0" axis="-0.0183278 -0.0362526 0.999175" stiffness="0.0569959" range="-2.75014 3.07981" armature="0.18371" damping="0.0538161" frictionloss="0.0629403"/>
                      <geom name="//unnamed_geom_58" class="visual" mesh="right_hand_yaw_link"/>
                      <geom name="right_hand_yaw_link.STL" class="collision" size="0.0427153 0.0715078" pos="0.00101976 0.00102647 -0.0414618" type="cylinder" rgba="0.752941 0.752941 0.752941 1"/>
                      <geom name="//unnamed_geom_60" class="reward_collision_sphere" size="0.0513752"/>
                      <body name="right_hand_roll_link" pos="-0.00835202 -0.00414769 -0.104492" quat="0.999986 -0.000213925 0.00494522 0.00205657">
                        <inertial pos="-0.0145354 -0.0132884 0.0155345" quat="0.506893 0.495017 0.496488 0.501515" mass="0.00574049" diaginertia="2.53277e-07 4.52833e-06 3.54608e-09"/>
                        <joint name="right_wrist_roll_joint" class="/" pos="0 0 0" axis="-0.997484 -0.0697842 -0.0125128" range="-1.04945 1.00636" armature="0.17234" damping="0.000279531" frictionloss="0.181094"/>
                        <geom name="//unnamed_geom_61" class="visual" mesh="right_hand_roll_link"/>
                        <body name="right_hand_pitch_link" pos="-0.00100948 -0.00300787 0.0159695" quat="0.999993 -0.00164459 0.00189726 0.00265155">
                          <inertial pos="0.00762914 0.0132374 -0.0408484" quat="0.702035 0.139915 -0.126622 0.686686" mass="0.291282" diaginertia="0.00024149 0.00308848 4.69121e-06"/>
                          <joint name="right_wrist_pitch_joint" class="/" pos="0 0 0" axis="0.059471 -0.998217 -0.005045" range="-0.414017 0.896455" armature="0.0455769" damping="0.00100583" frictionloss="0.0554288"/>
                          <geom name="//unnamed_geom_62" class="visual" mesh="right_hand_pitch"/>
                          <body name="right_jaw_link" pos="-0.0102033 0.00159011 -0.0487254" quat="0.999997 -0.000697139 -0.00173769 0.00126945">
                            <inertial pos="-0.00168936 -0.010952 -0.00673625" quat="0.710269 0.025599 -0.0294112 0.70285" mass="0.0921467" diaginertia="5.72494e-05 0.000708784 1.41377e-06"/>
                            <joint name="right_jaw_joint" class="/" pos="0 0 0" axis="-0.998321 0.0235427 -0.0529205" stiffness="0.0387006" range="-0.210393 1.19781" armature="0.185295" damping="0" frictionloss="0.0802518"/>
                            <geom name="//unnamed_geom_63" class="visual" mesh="right_jaw_link"/>
                            <geom name="//unnamed_geom_64" class="collision" size="0.0369901"/>
                            <geom name="//unnamed_geom_65" class="reward_collision_sphere" size="0.0513752" pos="0 0 -0.0109048"/>
                          </body>
                        </body>
                      </body>
                    </body>
                  </body>
                </body>
              </body>
            </body>
            <body name="head_roll_link" pos="-0.0135712 -0.00686221 0.182971" quat="0.999999 -0.000902887 0.000921006 -0.000128555">
              <inertial pos="0.00362027 -0.0137261 0.0140804" quat="-0.0562187 0.733917 -0.0267373 0.67638" mass="0.0109604" diaginertia="7.3186e-07 5.91981e-06 2.34662e-08"/>
              <joint name="head_roll_joint" class="/" pos="0 0 0" axis="-0.999057 0.00672256 0.0428838" range="-0.189055 0.204713" armature="0.0698939" damping="0.001148" frictionloss="0.186861"/>
              <geom name="//unnamed_geom_66" class="visual" mesh="head_roll_link"/>
              <body name="head_pitch_link" pos="0.00607927 0.0117315 -0.015028" quat="1 0.000270709 2.40543e-05 0.000141674">
                <inertial pos="1.33305e-05 -0.0123409 -0.00293597" quat="0.656559 0.671147 0.250582 -0.236009" mass="0.0528242" diaginertia="1.57093e-05 0.000195329 6.49107e-07"/>
                <joint name="head_pitch_joint" class="/" pos="0 0 0" axis="0.000414339 -0.999796 0.0202043" range="-0.974768 1.17581" armature="0.167265" damping="0" frictionloss="0.100225"/>
                <geom name="//unnamed_geom_67" class="visual" mesh="head_pitch_link"/>
                <body name="head_yaw_link" pos="0.00428185 0.000417226 0.0275902" quat="0.999975 0.000581551 0.000798007 0.00695332">
                  <inertial pos="0.0259862 -0.0166227 0.0545351" quat="0.70483 -0.13433 -0.142805 0.681745" mass="1.96773" diaginertia="0.00725147 0.0657762 0.000250062"/>
                  <joint name="head_yaw_joint" class="/" pos="0 0 0" axis="0.00139696 -4.87421e-05 0.999999" stiffness="0.00103014" range="-2.76117 2.60079" armature="0.171281" damping="0" frictionloss="0.174104"/>
                  <geom name="//unnamed_geom_68" class="visual" rgba="0.12 0.12 0.12 1" mesh="head_yaw_link"/>
                  <geom name="head_yaw_link.STL" class="collision" size="0.121951" pos="0.0171148 -0.00140898 0.0510457" rgba="0.752941 0.752941 0.752941 1"/>
                  <geom name="//unnamed_geom_70" class="reward_collision_sphere" size="0.10275" pos="0.0280861 0 0.0545242"/>
                  <camera name="ego_camera" class="/" pos="0.102982 0 0.0599766" quat="-0.5 -0.5 0.5 0.5"/>
                </body>
              </body>
            </body>
          </body>
        </body>
      </body>
    </body>
  </worldbody>

  <contact>
    <pair class="/" geom1="floor" geom2="left_foot" name="//unnamed_contact_0"/>
    <pair class="/" geom1="floor" geom2="right_foot" name="//unnamed_contact_1"/>
  </contact>

  <actuator>
    <general name="left_hip_roll" class="/" joint="left_hip_roll_joint" forcerange="-19.755 19.755" gainprm="96.6529" biasprm="0 -96.6529 -1.07516"/>
    <general name="left_hip_yaw" class="/" joint="left_hip_yaw_joint" forcerange="-41.6457 41.6457" gainprm="96.6529" biasprm="0 -96.6529 -1.07516"/>
    <general name="left_hip_pitch" class="/" joint="left_hip_pitch_joint" forcerange="-291.856 291.856" gainprm="96.6529" biasprm="0 -96.6529 -1.07516"/>
    <general name="left_knee_pitch" class="/" joint="left_knee_pitch_joint" forcerange="-112.904 112.904" gainprm="96.6529" biasprm="0 -96.6529 -1.07516"/>
    <general name="left_ankle_pitch" class="/" joint="left_ankle_pitch_joint" forcerange="-12.8012 12.8012" gainprm="96.6529" biasprm="0 -96.6529 -1.07516"/>
    <general name="left_ankle_roll" class="/" joint="left_ankle_roll_joint" forcerange="-22.9562 22.9562" gainprm="96.6529" biasprm="0 -96.6529 -1.07516"/>
    <general name="right_hip_roll" class="/" joint="right_hip_roll_joint" forcerange="-62.0143 62.0143" gainprm="96.6529" biasprm="0 -96.6529 -1.07516"/>
    <general name="right_hip_yaw" class="/" joint="right_hip_yaw_joint" forcerange="-61.0007 61.0007" gainprm="96.6529" biasprm="0 -96.6529 -1.07516"/>
    <general name="right_hip_pitch" class="/" joint="right_hip_pitch_joint" forcerange="-114.019 114.019" gainprm="96.6529" biasprm="0 -96.6529 -1.07516"/>
    <general name="right_knee_pitch" class="/" joint="right_knee_pitch_joint" forcerange="-212.001 212.001" gainprm="96.6529" biasprm="0 -96.6529 -1.07516"/>
    <general name="right_ankle_pitch" class="/" joint="right_ankle_pitch_joint" forcerange="-13.1273 13.1273" gainprm="96.6529" biasprm="0 -96.6529 -1.07516"/>
    <general name="right_ankle_roll" class="/" joint="right_ankle_roll_joint" forcerange="-37.4154 37.4154" gainprm="96.6529" biasprm="0 -96.6529 -1.07516"/>
    <general name="waist_yaw" class="/" joint="waist_yaw_joint" forcerange="-57.0629 57.0629" gainprm="96.6529" biasprm="0 -96.6529 -1.07516"/>
    <general name="waist_pitch" class="/" joint="waist_pitch_joint" forcerange="-79.9086 79.9086" gainprm="96.6529" biasprm="0 -96.6529 -1.07516"/>
    <general name="waist_roll" class="/" joint="waist_roll_joint" forcerange="-67.9088 67.9088" gainprm="96.6529" biasprm="0 -96.6529 -1.07516"/>
    <general name="left_shoulder_pitch" class="/" joint="left_shoulder_pitch_joint" forcerange="-57.3771 57.3771" gainprm="96.6529" biasprm="0 -96.6529 -1.07516"/>
    <general name="left_shoulder_roll" class="/" joint="left_shoulder_roll_joint" forcerange="-48.3438 48.3438" gainprm="96.6529" biasprm="0 -96.6529 -1.07516"/>
    <general name="left_shoulder_yaw" class="/" joint="left_shoulder_yaw_joint" forcerange="-29.9439 29.9439" gainprm="96.6529" biasprm="0 -96.6529 -1.07516"/>
    <general name="left_elbow_pitch" class="/" joint="left_elbow_pitch_joint" forcerange="-30.1391 30.1391" gainprm="96.6529" biasprm="0 -96.6529 -1.07516"/>
    <general name="left_wrist_yaw" class="/" joint="left_wrist_yaw_joint" forcerange="-10.823 10.823" gainprm="96.6529" biasprm="0 -96.6529 -1.07516"/>
    <general name="left_wrist_roll" class="/" joint="left_wrist_roll_joint" forcerange="-5.86635 5.86635" gainprm="96.6529" biasprm="0 -96.6529 -1.07516"/>
    <general name="left_wrist_pitch" class="/" joint="left_wrist_pitch_joint" forcerange="-2.31017 2.31017" gainprm="96.6529" biasprm="0 -96.6529 -1.07516"/>
    <general name="left_jaw" class="/" joint="left_jaw_joint" forcerange="-4.03455 4.03455" gainprm="96.6529" biasprm="0 -96.6529 -1.07516"/>
    <general name="right_shoulder_pitch" class="/" joint="right_shoulder_pitch_joint" forcerange="-38.9159 38.9159" gainprm="96.6529" biasprm="0 -96.6529 -1.07516"/>
    <general name="right_shoulder_roll" class="/" joint="right_shoulder_roll_joint" forcerange="-39.4676 39.4676" gainprm="96.6529" biasprm="0 -96.6529 -1.07516"/>
    <general name="right_shoulder_yaw" class="/" joint="right_shoulder_yaw_joint" forcerange="-31.9733 31.9733" gainprm="96.6529" biasprm="0 -96.6529 -1.07516"/>
    <general name="right_elbow_pitch" class="/" joint="right_elbow_pitch_joint" forcerange="-30.4104 30.4104" gainprm="96.6529" biasprm="0 -96.6529 -1.07516"/>
    <general name="right_wrist_yaw" class="/" joint="right_wrist_yaw_joint" forcerange="-10.2625 10.2625" gainprm="96.6529" biasprm="0 -96.6529 -1.07516"/>
    <general name="right_wrist_roll" class="/" joint="right_wrist_roll_joint" forcerange="-4.74316 4.74316" gainprm="96.6529" biasprm="0 -96.6529 -1.07516"/>
    <general name="right_wrist_pitch" class="/" joint="right_wrist_pitch_joint" forcerange="-3.47189 3.47189" gainprm="96.6529" biasprm="0 -96.6529 -1.07516"/>
    <general name="right_jaw" class="/" joint="right_jaw_joint" forcerange="-4.26268 4.26268" gainprm="96.6529" biasprm="0 -96.6529 -1.07516"/>
    <general name="head_roll" class="/" joint="head_roll_joint" forcerange="-4.99628 4.99628" gainprm="96.6529" biasprm="0 -96.6529 -1.07516"/>
    <general name="head_pitch" class="/" joint="head_pitch_joint" forcerange="-2.26523 2.26523" gainprm="96.6529" biasprm="0 -96.6529 -1.07516"/>
    <general name="head_yaw" class="/" joint="head_yaw_joint" forcerange="-3.45444 3.45444" gainprm="96.6529" biasprm="0 -96.6529 -1.07516"/>
  </actuator>

  <sensor>
    <gyro site="imu" name="imu_angular_velocity"/>
    <velocimeter site="imu" name="imu_linear_velocity"/>
    <framelinvel objtype="site" objname="left_foot" name="left_foot_global_linear_velocity"/>
    <framelinvel objtype="site" objname="right_foot" name="right_foot_global_linear_velocity"/>
  </sensor>

  <keyframe>
    <key name="home" qpos="0 0 0.8665 1 0 0 0 0 0 -0.4 0.8 -0.4 0 0 0 0.4 -0.8 0.4 0 0 0 0 0 -0.2 0 -0.785 0 0 0 0 0 0.2 0 0.785 0 0 0 0 0 0 0"/>
  </keyframe>
</mujoco>
