<mujoco model="GR1T2_jaw">
  <compiler angle="radian" assetdir="assets" balanceinertia="true" inertiafromgeom="false"/>

  <option timestep="0.005" density="1.2" viscosity="2e-05"/>

  <size nkey="1"/>

  <visual>
    <quality shadowsize="8192"/>
    <map shadowclip="0.5"/>
  </visual>

  <default>
    <default class="/">
      <joint armature="0.1" damping="0.01" frictionloss="0.1"/>
      <geom contype="0" conaffinity="0" group="1" solref="-1000 -80"/>
      <site size="0.01 0.005 0.005" group="5"/>
      <general forcelimited="true" biastype="affine" gainprm="80" biasprm="0 -80 -2"/>
      <default class="visual">
        <geom type="mesh" density="0" rgba="0.18 0.18 0.18 1"/>
      </default>
      <default class="collision">
        <geom group="3"/>
      </default>
      <default class="foot">
        <geom size="0.126 0.045 0.01" type="box" condim="6" group="4" priority="1" solimp="0.015 1 0.01"/>
      </default>
      <default class="reward_collision_sphere">
        <geom group="5" rgba="1 0 0 1"/>
      </default>
    </default>
  </default>

  <asset>
    <texture type="skybox" colorspace="auto" name="//unnamed_texture_0" builtin="gradient" rgb1="0.95 0.95 0.95" rgb2="0.95 0.95 0.95" width="100" height="600"/>
    <texture type="2d" colorspace="auto" name="texplane" builtin="checker" rgb1="0.345 0.575 0.748" rgb2="0.345 0.575 0.748" markrgb="1 1 1" width="512" height="512"/>
    <material name="MatPlane" class="/" texture="texplane" texuniform="true" texrepeat="2 2" specular="0.9"/>
    <mesh name="base_link" class="/" file="base_link.STL"/>
    <mesh name="left_thigh_roll_link" class="/" file="left_thigh_roll_link.STL"/>
    <mesh name="left_thigh_yaw_link" class="/" file="left_thigh_yaw_link.STL"/>
    <mesh name="left_thigh_pitch_link" class="/" file="left_thigh_pitch_link.STL"/>
    <mesh name="left_shank_pitch_link" class="/" file="left_shank_pitch_link.STL"/>
    <mesh name="left_foot_pitch_link" class="/" file="left_foot_pitch_link.STL"/>
    <mesh name="left_foot_roll_link" class="/" file="left_foot_roll_link.STL"/>
    <mesh name="right_thigh_roll_link" class="/" file="right_thigh_roll_link.STL"/>
    <mesh name="right_thigh_yaw_link" class="/" file="right_thigh_yaw_link.STL"/>
    <mesh name="right_thigh_pitch_link" class="/" file="right_thigh_pitch_link.STL"/>
    <mesh name="right_shank_pitch_link" class="/" file="right_shank_pitch_link.STL"/>
    <mesh name="right_foot_pitch_link" class="/" file="right_foot_pitch_link.STL"/>
    <mesh name="right_foot_roll_link" class="/" file="right_foot_roll_link.STL"/>
    <mesh name="waist_yaw_link" class="/" file="waist_yaw_link.STL"/>
    <mesh name="waist_pitch_link" class="/" file="waist_pitch_link.STL"/>
    <mesh name="waist_roll_link" class="/" file="waist_roll_link.STL"/>
    <mesh name="torso_link" class="/" file="torso_link.STL"/>
    <mesh name="left_upper_arm_pitch_link" class="/" file="left_upper_arm_pitch_link.STL"/>
    <mesh name="left_upper_arm_roll_link" class="/" file="left_upper_arm_roll_link.STL"/>
    <mesh name="left_upper_arm_yaw_link" class="/" file="left_upper_arm_yaw_link.STL"/>
    <mesh name="left_lower_arm_pitch_link" class="/" file="left_lower_arm_pitch_link.STL"/>
    <mesh name="left_hand_yaw_link" class="/" file="left_hand_yaw_link.STL"/>
    <mesh name="left_hand_roll_link" class="/" file="left_hand_roll_link.STL"/>
    <mesh name="left_hand_pitch" class="/" file="left_hand_pitch.STL"/>
    <mesh name="left_jaw_link" class="/" file="left_jaw_link.STL"/>
    <mesh name="right_upper_arm_pitch_link" class="/" file="right_upper_arm_pitch_link.STL"/>
    <mesh name="right_upper_arm_roll_link" class="/" file="right_upper_arm_roll_link.STL"/>
    <mesh name="right_upper_arm_yaw_link" class="/" file="right_upper_arm_yaw_link.STL"/>
    <mesh name="right_lower_arm_pitch_link" class="/" file="right_lower_arm_pitch_link.STL"/>
    <mesh name="right_hand_yaw_link" class="/" file="right_hand_yaw_link.STL"/>
    <mesh name="right_hand_roll_link" class="/" file="right_hand_roll_link.STL"/>
    <mesh name="right_hand_pitch" class="/" file="right_hand_pitch.STL"/>
    <mesh name="right_jaw_link" class="/" file="right_jaw_link.STL"/>
    <mesh name="head_roll_link" class="/" file="head_roll_link.STL"/>
    <mesh name="head_pitch_link" class="/" file="head_pitch_link.STL"/>
    <mesh name="head_yaw_link" class="/" file="head_yaw_link.STL"/>
    <mesh name="imu_link" class="/" file="imu_link.STL"/>
  </asset>

  <worldbody>
    <geom name="floor" class="/" size="100 100 0.125" type="plane" group="0" material="MatPlane"/>
    <light name="toplight_shadow" class="/" pos="0 0 5" dir="0.0990148 0.0990148 -0.990148" type="directional" ambient="0.04 0.04 0.04" diffuse="0.55 0.55 0.55" specular="0.12 0.12 0.12"/>
    <light name="toplight_fill" class="/" pos="0 0 5" dir="0.0990148 0.0990148 -0.990148" type="directional" castshadow="false" ambient="0.04 0.04 0.04" diffuse="0.3 0.3 0.3" specular="0.08 0.08 0.08"/>
    <body name="trunk" pos="0.000882197 9.95798e-05 0.000889179" quat="1 1.51136e-06 1.99358e-06 -2.57611e-06">
      <inertial pos="-0.0651324 0.00194556 -0.00848208" quat="0.999999 -0.000699821 -0.00125891 -0.000285347" mass="2.8824" diaginertia="0.066042 0.00415223 0.0134262"/>
      <joint name="//unnamed_joint_0" type="free"/>
      <geom name="//unnamed_geom_1" class="visual" rgba="0.12 0.12 0.12 1" mesh="base_link"/>
      <geom name="base_link.STL" class="collision" size="0.109367 0.0612543" pos="-0.0467634 0.00029238 0.00729806" quat="0.706838 -0.707359 0.00477667 0" type="cylinder" rgba="0.752941 0.752941 0.752941 1"/>
      <geom name="//unnamed_geom_3" class="visual" pos="0 0 -0.0472269" quat="1 0 0 0" rgba="0.12 0.12 0.12 1" mesh="imu_link"/>
      <geom name="//unnamed_geom_4" class="reward_collision_sphere" size="0.0714853" pos="0 0.0790127 0.0792398"/>
      <geom name="//unnamed_geom_5" class="reward_collision_sphere" size="0.0714853" pos="0 -0.0790127 0.0792398"/>
      <site name="imu" class="/" pos="-0.0040487 -0.000190862 -0.0460831" size="0.00893566"/>
      <camera name="track" class="/" pos="0 -1.58025 0" quat="0.707107 0.707107 0 0" mode="trackcom"/>
      <body name="left_thigh_roll_link" pos="-0.0388885 0.0824025 -0.0213059" quat="1 8.46213e-05 2.68353e-05 1.89105e-06">
        <inertial pos="0.000496292 -0.00136344 0.00105787" quat="-0.0307945 0.705402 -0.035359 0.707255" mass="1.04691" diaginertia="0.00408344 0.000757744 0.000489013"/>
        <joint name="left_hip_roll_joint" class="/" pos="0 0 0" axis="-0.99999 0.00448741 0.000516035" range="-0.798027 0.0957985" armature="0.0849141" damping="0.00473144" frictionloss="0.0900248"/>
        <geom name="//unnamed_geom_6" class="visual" mesh="left_thigh_roll_link"/>
        <body name="left_thigh_yaw_link" pos="0.0343174 -0.000444023 0.00213041" quat="1 0.000182222 -0.000145898 -6.75664e-05">
          <inertial pos="-0.00350571 0.0306421 -0.0879543" quat="0.57135 0.0941194 -0.1948 0.791677" mass="2.4847" diaginertia="0.0386427 0.00605722 0.00279589"/>
          <joint name="left_hip_yaw_joint" class="/" pos="0 0 0" axis="0.00286913 -0.00630021 -0.999976" range="-0.719669 0.716644" armature="0.0868233" damping="0" frictionloss="0.0922391"/>
          <geom name="//unnamed_geom_7" class="visual" mesh="left_thigh_yaw_link"/>
          <body name="left_thigh_pitch_link" pos="-0.000925967 0.0177146 -0.109555" quat="1 0.000115497 -0.000100658 -0.000437227">
            <inertial pos="0.00105877 -0.0221011 -0.0502472" quat="0.999799 -0.0152295 -0.0099806 0.00838746" mass="5.91123" diaginertia="0.146677 0.0275254 0.00883605"/>
            <joint name="left_hip_pitch_joint" class="/" pos="0 0 0" axis="0.000736793 0.999998 -0.00178022" range="-1.75412 0.694178" armature="0.0878878" damping="0.00781815" frictionloss="0.0855558"/>
            <geom name="//unnamed_geom_8" class="visual" mesh="left_thigh_pitch_link"/>
            <geom name="left_thigh_pitch_link.STL" class="collision" size="0.0732724 0.111619" pos="0.000768777 -0.0237038 -0.132375" type="cylinder" rgba="0.752941 0.752941 0.752941 1"/>
            <geom name="//unnamed_geom_10" class="reward_collision_sphere" size="0.0893566" pos="0 -0.00790127 -0.0396199"/>
            <body name="left_shank_pitch_link" pos="-0.00043638 -0.01569 -0.283009" quat="1 8.13659e-06 -0.000155335 0.000372304">
              <inertial pos="0.00236991 -0.00117914 -0.0910103" quat="0.999686 -0.0067408 0.007494 -0.0229422" mass="1.27453" diaginertia="0.0174003 0.00334176 0.00039873"/>
              <joint name="left_knee_pitch_joint" class="/" pos="0 0 0" axis="-0.00393529 0.99998 -0.00487276" range="-0.103577 1.91966" armature="0.0856797" damping="0.0141742" frictionloss="0.0897325"/>
              <geom name="//unnamed_geom_11" class="visual" mesh="left_shank_pitch_link"/>
              <geom name="left_shank_pitch_link.STL" class="collision" size="0.0476462 0.0807649" pos="-1.82188e-05 -0.000665719 -0.138425" quat="0.00125538 -0.202712 0.979238 0" type="cylinder" rgba="0.752941 0.752941 0.752941 1"/>
              <geom name="//unnamed_geom_13" class="reward_collision_sphere" size="0.0446783"/>
              <geom name="//unnamed_geom_14" class="reward_collision_sphere" size="0.0536139" pos="0 0 -0.0871638"/>
              <body name="left_foot_pitch_link" pos="-0.000165886 -0.00135085 -0.26754" quat="1 -0.000228229 -0.000144261 0.000130047">
                <inertial pos="0.000466448 -0.0016381 -0.000144473" quat="0.000350403 0.707409 -0.000121795 0.706805" mass="0.0407486" diaginertia="1.01251e-05 1.7504e-06 1.64561e-06"/>
                <joint name="left_ankle_pitch_joint" class="/" pos="0 0 0" axis="0.00444268 0.999989 0.00145291" range="-1.05948 0.538352" armature="0.0945697" damping="0.00105347" frictionloss="0.0887635"/>
                <geom name="//unnamed_geom_15" class="visual" mesh="left_foot_pitch_link"/>
                <body name="left_foot_roll_link" pos="0.000448163 0.000159989 0.00125345" quat="1 8.20227e-05 3.49391e-05 -0.000158831">
                  <inertial pos="0.0421894 -0.00153643 -0.0301194" quat="-0.000618781 0.724785 -0.00129501 0.688974" mass="0.757178" diaginertia="0.00887409 0.00157194 0.000236244"/>
                  <joint name="left_ankle_roll_joint" class="/" pos="0 0 0" axis="-0.999979 -0.00512261 0.00398677" range="-0.462183 0.462934" armature="0.0912551" damping="0.00376911" frictionloss="0.0852337"/>
                  <geom name="//unnamed_geom_16" class="visual" mesh="left_foot_roll_link"/>
                  <geom name="left_foot" class="foot" size="0.143725 0.0417087 0.00913282" pos="0.0494178 0 -0.0352617"/>
                  <geom name="//unnamed_geom_18" class="reward_collision_sphere" size="0.0446783" pos="0 0 -0.0237719"/>
                  <geom name="//unnamed_geom_19" class="reward_collision_sphere" size="0.0446783" pos="0.131781 0 -0.0237719"/>
                  <site name="left_foot" class="foot" pos="0.0494178 0 -0.0352617" size="0.00893566"/>
                </body>
              </body>
            </body>
          </body>
        </body>
      </body>
      <body name="right_thigh_roll_link" pos="-0.0346228 -0.0871959 -0.022258" quat="1 -0.000254386 -0.000657379 0.000119821">
        <inertial pos="0.000940553 -0.00116475 0.00171019" quat="0.0271733 0.705336 0.0182096 0.708118" mass="1.05382" diaginertia="0.00414127 0.000769597 0.000491933"/>
        <joint name="right_hip_roll_joint" class="/" pos="0 0 0" axis="-0.999989 -0.004112 -0.00232614" range="-0.0829498 0.800199" armature="0.0798649" damping="0.00332304" frictionloss="0.0873479"/>
        <geom name="//unnamed_geom_20" class="visual" mesh="right_thigh_roll_link"/>
        <body name="right_thigh_yaw_link" pos="0.0360323 -0.00288232 -0.000269907" quat="1 3.34247e-06 2.63261e-05 -4.09027e-06">
          <inertial pos="-0.00327493 -0.0306414 -0.0888334" quat="0.686971 -0.145733 0.151359 0.695646" mass="2.44924" diaginertia="0.0380355 0.00576668 0.0027459"/>
          <joint name="right_hip_yaw_joint" class="/" pos="0 0 0" axis="0.0022252 -0.000482512 -0.999997" range="-0.714459 0.711099" armature="0.0907072" damping="0.00698296" frictionloss="0.0896081"/>
          <geom name="//unnamed_geom_21" class="visual" mesh="right_thigh_yaw_link"/>
          <body name="right_thigh_pitch_link" pos="-0.00111996 -0.0204015 -0.111772" quat="1 -9.31785e-05 -1.82083e-05 0.000268143">
            <inertial pos="0.000758271 0.0197455 -0.049127" quat="0.999811 -0.0144814 -0.0109804 0.00689794" mass="5.90031" diaginertia="0.148323 0.0277233 0.00873393"/>
            <joint name="right_hip_pitch_joint" class="/" pos="0 0 0" axis="0.000760721 -0.999898 0.0142419" range="-0.69282 1.77341" armature="0.0840299" damping="0.0226268" frictionloss="0.0867133"/>
            <geom name="//unnamed_geom_22" class="visual" mesh="right_thigh_pitch_link"/>
            <geom name="right_thigh_pitch_link.STL" class="collision" size="0.0732724 0.111616" pos="-0.00233172 0.0237038 -0.132375" quat="0.999971 0.00269833 0.00706272 0" type="cylinder" rgba="0.752941 0.752941 0.752941 1"/>
            <geom name="//unnamed_geom_24" class="reward_collision_sphere" size="0.0893566" pos="0 0.00790127 -0.0396199"/>
            <body name="right_shank_pitch_link" pos="-0.000111769 0.0130504 -0.284837" quat="1 -0.000448282 -0.000485182 -0.000389444">
              <inertial pos="0.00202458 -0.000392445 -0.0919425" quat="0.999665 0.0076267 0.00647354 0.0238536" mass="1.24498" diaginertia="0.0171729 0.00326871 0.000382764"/>
              <joint name="right_knee_pitch_joint" class="/" pos="0 0 0" axis="-0.0110454 -0.999938 -0.00123714" range="-1.92428 0.128681" armature="0.0889371" damping="0.0170283" frictionloss="0.087642"/>
              <geom name="//unnamed_geom_25" class="visual" mesh="right_shank_pitch_link"/>
              <geom name="right_shank_pitch_link.STL" class="collision" size="0.0476459 0.0807641" pos="-1.82188e-05 -0.000665727 -0.138431" type="cylinder" rgba="0.752941 0.752941 0.752941 1"/>
              <geom name="//unnamed_geom_27" class="reward_collision_sphere" size="0.0446783"/>
              <geom name="//unnamed_geom_28" class="reward_collision_sphere" size="0.0536139" pos="0 0 -0.0871638"/>
              <body name="right_foot_pitch_link" pos="-0.000520924 -0.00151716 -0.268487" quat="1 0.000368911 5.96845e-05 -1.23342e-05">
                <inertial pos="0.000816654 -0.00198262 -0.000260277" quat="-0.00021925 0.707084 -5.6109e-06 0.707129" mass="0.0410215" diaginertia="1.02066e-05 1.69942e-06 1.66478e-06"/>
                <joint name="right_ankle_pitch_joint" class="/" pos="0 0 0" axis="0.00189471 -0.999995 -0.00239413" range="-0.528428 1.08344" armature="0.0904469" damping="0.00659399" frictionloss="0.0864223"/>
                <geom name="//unnamed_geom_29" class="visual" mesh="right_foot_pitch_link"/>
                <body name="right_foot_roll_link" pos="0.000102956 -0.000974929 0.000660584" quat="1 0.000159223 -0.000145936 9.96451e-05">
                  <inertial pos="0.0408897 -0.00040303 -0.0300588" quat="0.00137208 0.725976 0.00206623 0.687715" mass="0.761411" diaginertia="0.00898288 0.00157422 0.00023368"/>
                  <joint name="right_ankle_roll_joint" class="/" pos="0 0 0" axis="-0.999989 -0.00205296 0.00423487" stiffness="0.000160245" range="-0.440214 0.456981" armature="0.091459" damping="0.00285385" frictionloss="0.0898077"/>
                  <geom name="//unnamed_geom_30" class="visual" mesh="right_foot_roll_link"/>
                  <geom name="right_foot" class="foot" size="0.146302 0.0396095 0.00870376" pos="0.0494178 0 -0.0352617"/>
                  <geom name="//unnamed_geom_32" class="reward_collision_sphere" size="0.0446783" pos="0 0 -0.0237719"/>
                  <geom name="//unnamed_geom_33" class="reward_collision_sphere" size="0.0446783" pos="0.131781 0 -0.0237719"/>
                  <site name="right_foot" class="foot" pos="0.0494178 0 -0.0352617" size="0.00893566"/>
                </body>
              </body>
            </body>
          </body>
        </body>
      </body>
      <body name="waist_yaw_link" pos="0.00443976 0.00298949 0.0023409" quat="1 -2.31216e-05 0.000271509 -0.000275849">
        <inertial pos="-0.00331743 -0.00745611 0.0403897" quat="0.980592 0.183953 -0.0300847 0.0607852" mass="1.17674" diaginertia="0.00567849 0.00100337 0.000668993"/>
        <joint name="waist_yaw_joint" class="/" pos="0 0 0" axis="-0.00509808 -0.00805712 0.999955" range="-1.05947 1.03454" armature="0.0912999" damping="0.012198" frictionloss="0.089526"/>
        <geom name="//unnamed_geom_34" class="visual" rgba="0.12 0.12 0.12 1" mesh="waist_yaw_link"/>
        <body name="waist_pitch_link" pos="0.00330431 0.00232537 0.0718357" quat="1 0.00010864 -6.62957e-05 -0.000392567">
          <inertial pos="0.00494602 -0.00272834 0.0324501" quat="0.997681 -0.0469283 0.0487558 0.00730814" mass="1.09789" diaginertia="0.00741999 0.00142033 0.000570193"/>
          <joint name="waist_pitch_joint" class="/" pos="0 0 0" axis="0.0171888 -0.999734 0.0153722" range="-1.1981 0.498517" armature="0.0868868" damping="0" frictionloss="0.0852025"/>
          <geom name="//unnamed_geom_35" class="visual" rgba="0.12 0.12 0.12 1" mesh="waist_pitch_link"/>
          <body name="waist_roll_link" pos="0.00987004 4.34381e-05 0.0670275" quat="1 -0.000226793 -0.0002079 0.000112934">
            <inertial pos="-0.016019 -0.000535312 0.116879" quat="0.998813 -0.00659848 -0.0482566 -4.05811e-05" mass="4.77912" diaginertia="0.0987221 0.0183471 0.0110024"/>
            <joint name="waist_roll_joint" class="/" pos="0 0 0" axis="-0.999992 -0.00382571 0.000790919" range="-0.744829 0.681579" armature="0.0923911" damping="0.0108641" frictionloss="0.0903445"/>
            <geom name="//unnamed_geom_36" class="visual" rgba="0.12 0.12 0.12 1" mesh="waist_roll_link"/>
            <geom name="//unnamed_geom_37" class="visual" pos="-0.00247089 0.000453873 0.127061" quat="1 0 0 0" mesh="torso_link"/>
            <geom name="torso_link.STL" class="collision" size="0.140671 0.0269794" pos="-0.0198395 0.00455887 0.117139" type="cylinder" rgba="0.752941 0.752941 0.752941 1"/>
            <geom name="//unnamed_geom_39" class="reward_collision_sphere" size="0.116164" pos="0 0 0.15848"/>
            <body name="left_upper_arm_pitch_link" pos="-0.000142861 0.0789857 0.164404" quat="0.976688 0.214662 2.71901e-05 5.83164e-05">
              <inertial pos="0.00400444 0.0415193 -0.00059933" quat="0.702765 0.709461 0.00260274 -0.0527332" mass="0.576751" diaginertia="0.00323427 0.000605784 0.000152268"/>
              <joint name="left_shoulder_pitch_joint" class="/" pos="0 0 0" axis="0.000248672 0.999999 -0.00151451" range="-2.7911 1.92745" armature="0.089341" damping="0.00569884" frictionloss="0.0903408"/>
              <geom name="//unnamed_geom_40" class="visual" mesh="left_upper_arm_pitch_link"/>
              <body name="left_upper_arm_roll_link" pos="0.00120992 0.0728446 0.00154198" quat="0.976673 -0.21473 1.15905e-06 3.51901e-05">
                <inertial pos="0.00517621 0.011728 -0.0189055" quat="0.889588 0.267828 0.124516 -0.348421" mass="0.431774" diaginertia="0.00164936 0.000312468 0.000111138"/>
                <joint name="left_shoulder_roll_joint" class="/" pos="0 0 0" axis="-0.999995 0.0021717 0.00211017" range="-2.52938 0.57157" armature="0.09461" damping="0.00317867" frictionloss="0.0891575"/>
                <geom name="//unnamed_geom_41" class="visual" mesh="left_upper_arm_roll_link"/>
                <body name="left_upper_arm_yaw_link" pos="5.03799e-05 0.029845 -0.0549167" quat="1 5.52032e-07 -1.90947e-07 -3.70984e-07">
                  <inertial pos="-0.000190842 -0.0019269 -0.0689783" quat="0.999951 0.00644763 -5.91127e-05 -0.00746603" mass="0.384771" diaginertia="0.005677 0.00110247 8.12997e-05"/>
                  <joint name="left_shoulder_yaw_joint" class="/" pos="0 0 0" axis="0.00348467 0.000245851 0.999994" range="-2.97863 2.97707" armature="0.0928232" damping="0.00516052" frictionloss="0.0932603"/>
                  <geom name="//unnamed_geom_42" class="visual" mesh="left_upper_arm_yaw_link"/>
                  <geom name="left_upper_arm_yaw_link.STL" class="collision" size="0.0323767 0.0759013" pos="4.33618e-05 -0.000706603 -0.0628689" quat="0.00803418 -0.995528 0.0941277 0" type="cylinder" rgba="0.752941 0.752941 0.752941 1"/>
                  <body name="left_lower_arm_pitch_link" pos="0.000694715 0.000878238 -0.141409" quat="1 0.000163783 -0.000132245 0.000139862">
                    <inertial pos="0.000161243 0.00516283 -0.0197461" quat="0.701032 -0.0924443 0.0917999 0.701129" mass="0.238078" diaginertia="0.000477917 9.16651e-05 3.06602e-05"/>
                    <joint name="left_elbow_pitch_joint" class="/" pos="0 0 0" axis="0.00257322 0.999997 -0.000468572" range="-2.26636 2.25955" armature="0.0935631" damping="0" frictionloss="0.0891533"/>
                    <geom name="//unnamed_geom_44" class="visual" mesh="left_lower_arm_pitch_link"/>
                    <body name="left_hand_yaw_link" pos="0.000129223 -0.000731657 -0.0475034" quat="1 -3.78439e-05 3.48276e-05 -4.33339e-05">
                      <inertial pos="0.000447006 0.000621091 -0.0580668" quat="0.999953 -0.00423687 -0.00162282 0.00859983" mass="0.712655" diaginertia="0.00424186 0.000796099 0.000156884"/>
                      <joint name="left_wrist_yaw_joint" class="/" pos="0 0 0" axis="-0.00042267 -0.000288494 1" range="-2.98599 2.9831" armature="0.089097" damping="0.00729951" frictionloss="0.0853091"/>
                      <geom name="//unnamed_geom_45" class="visual" mesh="left_hand_yaw_link"/>
                      <geom name="left_hand_yaw_link.STL" class="collision" size="0.0371472 0.0621865" pos="0.00119618 -0.00121767 -0.0602563" type="cylinder" rgba="0.752941 0.752941 0.752941 1"/>
                      <geom name="//unnamed_geom_47" class="reward_collision_sphere" size="0.0446783"/>
                      <body name="left_hand_roll_link" pos="-0.000716131 0.00145814 -0.152965" quat="1 2.90167e-05 -4.33819e-05 1.51535e-05">
                        <inertial pos="-0.000326735 -0.000494947 -4.02435e-05" quat="0.500031 0.499564 0.499981 0.500423" mass="0.00355076" diaginertia="5.59754e-07 1.07255e-07 2.19754e-08"/>
                        <joint name="left_wrist_roll_joint" class="/" pos="0 0 0" axis="-0.999998 0.00164232 0.00145734" range="-0.968971 0.869674" armature="0.0946041" damping="0" frictionloss="0.090055"/>
                        <geom name="//unnamed_geom_48" class="visual" mesh="left_hand_roll_link"/>
                        <body name="left_hand_pitch_link" pos="0.00110822 0.000159735 -0.000863636" quat="1 0.000267499 0.000211548 5.59195e-05">
                          <inertial pos="-0.00131414 -0.00992512 -0.0422518" quat="0.723162 -0.121432 0.114601 0.670192" mass="0.154282" diaginertia="0.000461941 8.23296e-05 2.97248e-05"/>
                          <joint name="left_wrist_pitch_joint" class="/" pos="0 0 0" axis="-0.00132529 0.999996 0.00243966" range="-0.598095 0.601465" armature="0.0922063" damping="0.00591986" frictionloss="0.0863242"/>
                          <geom name="//unnamed_geom_49" class="visual" mesh="left_hand_pitch"/>
                          <body name="left_jaw_link" pos="-0.00103207 0.000363863 -0.0490214" quat="1 1.1939e-06 -3.08181e-05 2.61073e-05">
                            <inertial pos="-0.000387102 0.00232643 -0.0282877" quat="0.707642 -0.0245304 0.0332746 0.705361" mass="0.0492184" diaginertia="0.00012708 1.71237e-05 1.00286e-05"/>
                            <joint name="left_jaw_joint" class="/" pos="0 0 0" axis="-0.999994 -0.00286214 0.00195015" range="-0.969977 -0.0124629" armature="0.0908459" damping="0.010012" frictionloss="0.0860827"/>
                            <geom name="//unnamed_geom_50" class="visual" mesh="left_jaw_link"/>
                            <geom name="//unnamed_geom_51" class="collision" size="0.0321684"/>
                            <geom name="//unnamed_geom_52" class="reward_collision_sphere" size="0.0446783" pos="0 0 -0.015848"/>
                          </body>
                        </body>
                      </body>
                    </body>
                  </body>
                </body>
              </body>
            </body>
            <body name="right_upper_arm_pitch_link" pos="0.000110317 -0.0791831 0.164853" quat="0.976761 -0.21433 7.50695e-05 -0.000506041">
              <inertial pos="0.00219195 -0.0423121 0.000801255" quat="0.705922 0.707387 0.0272791 0.0231042" mass="0.581994" diaginertia="0.00325643 0.000604519 0.000156383"/>
              <joint name="right_shoulder_pitch_joint" class="/" pos="0 0 0" axis="-0.00150646 -0.999986 0.00505135" range="-1.92543 2.79794" armature="0.0909084" damping="0.00640897" frictionloss="0.0871014"/>
              <geom name="//unnamed_geom_53" class="visual" mesh="right_upper_arm_pitch_link"/>
              <body name="right_upper_arm_roll_link" pos="0.0018997 -0.0744487 0.000573314" quat="0.976581 0.215151 3.70756e-05 -0.000356353">
                <inertial pos="0.00485755 -0.0138028 -0.0193266" quat="0.888166 -0.269246 0.125621 0.350554" mass="0.430176" diaginertia="0.00162804 0.00030471 0.000108715"/>
                <joint name="right_shoulder_roll_joint" class="/" pos="0 0 0" axis="-0.999987 0.00484272 0.00133854" range="-0.593191 2.54031" armature="0.0924797" damping="0.00177879" frictionloss="0.0886199"/>
                <geom name="//unnamed_geom_54" class="visual" mesh="right_upper_arm_roll_link"/>
                <body name="right_upper_arm_yaw_link" pos="0.00126722 -0.0302846 -0.0566119" quat="1 -0.000458389 -0.000213516 2.41291e-05">
                  <inertial pos="-0.000306781 -0.000349602 -0.0697286" quat="0.99999 -0.00447771 0.000254416 0.000440831" mass="0.387325" diaginertia="0.00565515 0.00108817 8.05554e-05"/>
                  <joint name="right_shoulder_yaw_joint" class="/" pos="0 0 0" axis="0.00322277 -0.00624813 0.999975" range="-2.95431 2.96572" armature="0.0903094" damping="0.00277812" frictionloss="0.0896089"/>
                  <geom name="//unnamed_geom_55" class="visual" mesh="right_upper_arm_yaw_link"/>
                  <geom name="right_upper_arm_yaw_link.STL" class="collision" size="0.0323767 0.0759013" pos="4.33618e-05 0.000706603 -0.0628689" type="cylinder" rgba="0.752941 0.752941 0.752941 1"/>
                  <body name="right_lower_arm_pitch_link" pos="0.00171053 -0.000523547 -0.140801" quat="1 0.000120634 -0.000114094 0.000402447">
                    <inertial pos="-0.000134898 -0.0066179 -0.0207585" quat="0.701123 0.0923989 -0.091508 0.701081" mass="0.235698" diaginertia="0.000472037 8.99311e-05 3.05102e-05"/>
                    <joint name="right_elbow_pitch_joint" class="/" pos="0 0 0" axis="-4.32978e-05 -1 -5.8994e-05" stiffness="0.000522165" range="-2.26873 2.2724" armature="0.0920225" damping="0.00959224" frictionloss="0.0892179"/>
                    <geom name="//unnamed_geom_57" class="visual" mesh="right_lower_arm_pitch_link"/>
                    <body name="right_hand_yaw_link" pos="0.0013501 -7.09351e-05 -0.0483721" quat="1 4.94621e-05 -7.31946e-05 -0.000257045">
                      <inertial pos="0.000139817 -0.00305565 -0.0568437" quat="0.999679 0.00344949 -0.00149887 0.0250671" mass="0.708186" diaginertia="0.0041674 0.000785911 0.000155538"/>
                      <joint name="right_wrist_yaw_joint" class="/" pos="0 0 0" axis="-0.000133508 -0.00105997 0.999999" stiffness="2.57744e-05" range="-2.96187 2.97136" armature="0.0920182" damping="0.00327211" frictionloss="0.0886337"/>
                      <geom name="//unnamed_geom_58" class="visual" mesh="right_hand_yaw_link"/>
                      <geom name="right_hand_yaw_link.STL" class="collision" size="0.0371472 0.0621865" pos="0.00119618 0.000506561 -0.0602563" type="cylinder" rgba="0.752941 0.752941 0.752941 1"/>
                      <geom name="//unnamed_geom_60" class="reward_collision_sphere" size="0.0446783"/>
                      <body name="right_hand_roll_link" pos="-0.000228548 -0.000195037 -0.152323" quat="1 -2.73439e-05 -3.57525e-05 -0.000118497">
                        <inertial pos="-0.000448577 0.00016149 -0.000128041" quat="0.499984 0.50008 0.500012 0.499924" mass="0.00354979" diaginertia="5.58953e-07 1.0673e-07 2.15134e-08"/>
                        <joint name="right_wrist_roll_joint" class="/" pos="0 0 0" axis="-1 5.42081e-06 -0.000632052" range="-0.873799 0.968846" armature="0.0931103" damping="0.00868334" frictionloss="0.0898353"/>
                        <geom name="//unnamed_geom_61" class="visual" mesh="right_hand_roll_link"/>
                        <body name="right_hand_pitch_link" pos="0.000858717 -0.000468864 0.00010329" quat="1 0.000167205 6.49221e-05 0.000118948">
                          <inertial pos="-8.01523e-05 0.00734768 -0.0413275" quat="0.724175 0.121817 -0.114669 0.669016" mass="0.157577" diaginertia="0.000463403 8.36606e-05 2.94403e-05"/>
                          <joint name="right_wrist_pitch_joint" class="/" pos="0 0 0" axis="-0.00604706 -0.999982 -0.00061402" range="-0.613821 0.60809" armature="0.0916356" damping="0.00835354" frictionloss="0.0899291"/>
                          <geom name="//unnamed_geom_62" class="visual" mesh="right_hand_pitch"/>
                          <body name="right_jaw_link" pos="0.000993809 0.000103521 -0.0487587" quat="1 -4.26757e-05 5.06531e-05 4.69599e-05">
                            <inertial pos="-0.000511294 -0.00504653 -0.0263754" quat="0.707789 0.0215202 -0.0305291 0.705436" mass="0.049999" diaginertia="0.000126157 1.72145e-05 1.00419e-05"/>
                            <joint name="right_jaw_joint" class="/" pos="0 0 0" axis="-0.999991 0.00330255 -0.00259509" range="-0.0151613 0.994475" armature="0.0915467" damping="0.00232852" frictionloss="0.0891456"/>
                            <geom name="//unnamed_geom_63" class="visual" mesh="right_jaw_link"/>
                            <geom name="//unnamed_geom_64" class="collision" size="0.0321684"/>
                            <geom name="//unnamed_geom_65" class="reward_collision_sphere" size="0.0446783" pos="0 0 -0.015848"/>
                          </body>
                        </body>
                      </body>
                    </body>
                  </body>
                </body>
              </body>
            </body>
            <body name="head_roll_link" pos="1.00472e-05 0.00140752 0.244314" quat="1 -4.69297e-05 0.000270083 0.000104891">
              <inertial pos="0.00472602 -6.6264e-05 0.00016511" quat="-0.00183638 0.70692 -0.00103883 0.70729" mass="0.00714289" diaginertia="1.15328e-06 1.35663e-07 1.34797e-07"/>
              <joint name="head_roll_joint" class="/" pos="0 0 0" axis="-1 -0.000986447 -1.47839e-05" range="-0.350634 0.365328" armature="0.0886709" damping="0" frictionloss="0.0929459"/>
              <geom name="//unnamed_geom_66" class="visual" mesh="head_roll_link"/>
              <body name="head_pitch_link" pos="-0.00063336 0.000596544 0.00262569" quat="1 8.13507e-05 -0.000184261 0.000497759">
                <inertial pos="-0.00144268 0.000116711 0.0138909" quat="0.662669 0.665988 0.241821 -0.242595" mass="0.0426815" diaginertia="4.20149e-05 7.23929e-06 5.30247e-06"/>
                <joint name="head_pitch_joint" class="/" pos="0 0 0" axis="0.00150186 -0.999979 0.00633878" range="-0.861066 0.866491" armature="0.0876708" damping="0.00876947" frictionloss="0.0901659"/>
                <geom name="//unnamed_geom_67" class="visual" mesh="head_pitch_link"/>
                <body name="head_yaw_link" pos="-0.000446426 0.000265809 0.0421029" quat="1 6.29433e-05 0.000184173 0.000122816">
                  <inertial pos="0.028841 -0.00229626 0.076149" quat="0.706643 -0.136252 -0.13974 0.68012" mass="1.12817" diaginertia="0.0159937 0.00244013 0.00163239"/>
                  <joint name="head_yaw_joint" class="/" pos="0 0 0" axis="0.000519081 0.00429432 0.999991" range="-2.70421 2.70211" armature="0.0922649" damping="0" frictionloss="0.0890238"/>
                  <geom name="//unnamed_geom_68" class="visual" rgba="0.12 0.12 0.12 1" mesh="head_yaw_link"/>
                  <geom name="head_yaw_link.STL" class="collision" size="0.106055" pos="0.0200758 -0.000695331 0.0741845" rgba="0.752941 0.752941 0.752941 1"/>
                  <geom name="//unnamed_geom_70" class="reward_collision_sphere" size="0.0893566" pos="0.0329452 0 0.0792398"/>
                  <camera name="ego_camera" class="/" pos="0.120799 0 0.0871638" quat="-0.5 -0.5 0.5 0.5"/>
                </body>
              </body>
            </body>
          </body>
        </body>
      </body>
    </body>
  </worldbody>

  <contact>
    <pair class="/" geom1="floor" geom2="left_foot" name="//unnamed_contact_0"/>
    <pair class="/" geom1="floor" geom2="right_foot" name="//unnamed_contact_1"/>
  </contact>

  <actuator>
    <general name="left_hip_roll" class="/" joint="left_hip_roll_joint" forcerange="-43.0374 43.0374" gainprm="107.228" biasprm="0 -107.228 -0.893566"/>
    <general name="left_hip_yaw" class="/" joint="left_hip_yaw_joint" forcerange="-57.7254 57.7254" gainprm="107.228" biasprm="0 -107.228 -0.893566"/>
    <general name="left_hip_pitch" class="/" joint="left_hip_pitch_joint" forcerange="-210.458 210.458" gainprm="107.228" biasprm="0 -107.228 -0.893566"/>
    <general name="left_knee_pitch" class="/" joint="left_knee_pitch_joint" forcerange="-202.623 202.623" gainprm="107.228" biasprm="0 -107.228 -0.893566"/>
    <general name="left_ankle_pitch" class="/" joint="left_ankle_pitch_joint" forcerange="-13.4941 13.4941" gainprm="107.228" biasprm="0 -107.228 -0.893566"/>
    <general name="left_ankle_roll" class="/" joint="left_ankle_roll_joint" forcerange="-26.7122 26.7122" gainprm="107.228" biasprm="0 -107.228 -0.893566"/>
    <general name="right_hip_roll" class="/" joint="right_hip_roll_joint" forcerange="-42.1868 42.1868" gainprm="107.228" biasprm="0 -107.228 -0.893566"/>
    <general name="right_hip_yaw" class="/" joint="right_hip_yaw_joint" forcerange="-58.9517 58.9517" gainprm="107.228" biasprm="0 -107.228 -0.893566"/>
    <general name="right_hip_pitch" class="/" joint="right_hip_pitch_joint" forcerange="-203.723 203.723" gainprm="107.228" biasprm="0 -107.228 -0.893566"/>
    <general name="right_knee_pitch" class="/" joint="right_knee_pitch_joint" forcerange="-198.002 198.002" gainprm="107.228" biasprm="0 -107.228 -0.893566"/>
    <general name="right_ankle_pitch" class="/" joint="right_ankle_pitch_joint" forcerange="-13.457 13.457" gainprm="107.228" biasprm="0 -107.228 -0.893566"/>
    <general name="right_ankle_roll" class="/" joint="right_ankle_roll_joint" forcerange="-26.9866 26.9866" gainprm="107.228" biasprm="0 -107.228 -0.893566"/>
    <general name="waist_yaw" class="/" joint="waist_yaw_joint" forcerange="-57.4922 57.4922" gainprm="107.228" biasprm="0 -107.228 -0.893566"/>
    <general name="waist_pitch" class="/" joint="waist_pitch_joint" forcerange="-59.6841 59.6841" gainprm="107.228" biasprm="0 -107.228 -0.893566"/>
    <general name="waist_roll" class="/" joint="waist_roll_joint" forcerange="-56.1017 56.1017" gainprm="107.228" biasprm="0 -107.228 -0.893566"/>
    <general name="left_shoulder_pitch" class="/" joint="left_shoulder_pitch_joint" forcerange="-33.346 33.346" gainprm="107.228" biasprm="0 -107.228 -0.893566"/>
    <general name="left_shoulder_roll" class="/" joint="left_shoulder_roll_joint" forcerange="-33.6475 33.6475" gainprm="107.228" biasprm="0 -107.228 -0.893566"/>
    <general name="left_shoulder_yaw" class="/" joint="left_shoulder_yaw_joint" forcerange="-26.7963 26.7963" gainprm="107.228" biasprm="0 -107.228 -0.893566"/>
    <general name="left_elbow_pitch" class="/" joint="left_elbow_pitch_joint" forcerange="-25.926 25.926" gainprm="107.228" biasprm="0 -107.228 -0.893566"/>
    <general name="left_wrist_yaw" class="/" joint="left_wrist_yaw_joint" forcerange="-9.37568 9.37568" gainprm="107.228" biasprm="0 -107.228 -0.893566"/>
    <general name="left_wrist_roll" class="/" joint="left_wrist_roll_joint" forcerange="-3.52322 3.52322" gainprm="107.228" biasprm="0 -107.228 -0.893566"/>
    <general name="left_wrist_pitch" class="/" joint="left_wrist_pitch_joint" forcerange="-3.62596 3.62596" gainprm="107.228" biasprm="0 -107.228 -0.893566"/>
    <general name="left_jaw" class="/" joint="left_jaw_joint" forcerange="-3.61903 3.61903" gainprm="107.228" biasprm="0 -107.228 -0.893566"/>
    <general name="right_shoulder_pitch" class="/" joint="right_shoulder_pitch_joint" forcerange="-33.8217 33.8217" gainprm="107.228" biasprm="0 -107.228 -0.893566"/>
    <general name="right_shoulder_roll" class="/" joint="right_shoulder_roll_joint" forcerange="-33.8474 33.8474" gainprm="107.228" biasprm="0 -107.228 -0.893566"/>
    <general name="right_shoulder_yaw" class="/" joint="right_shoulder_yaw_joint" forcerange="-27.541 27.541" gainprm="107.228" biasprm="0 -107.228 -0.893566"/>
    <general name="right_elbow_pitch" class="/" joint="right_elbow_pitch_joint" forcerange="-26.196 26.196" gainprm="107.228" biasprm="0 -107.228 -0.893566"/>
    <general name="right_wrist_yaw" class="/" joint="right_wrist_yaw_joint" forcerange="-9.08231 9.08231" gainprm="107.228" biasprm="0 -107.228 -0.893566"/>
    <general name="right_wrist_roll" class="/" joint="right_wrist_roll_joint" forcerange="-3.41292 3.41292" gainprm="107.228" biasprm="0 -107.228 -0.893566"/>
    <general name="right_wrist_pitch" class="/" joint="right_wrist_pitch_joint" forcerange="-3.46444 3.46444" gainprm="107.228" biasprm="0 -107.228 -0.893566"/>
    <general name="right_jaw" class="/" joint="right_jaw_joint" forcerange="-3.58068 3.58068" gainprm="107.228" biasprm="0 -107.228 -0.893566"/>
    <general name="head_roll" class="/" joint="head_roll_joint" forcerange="-3.60572 3.60572" gainprm="107.228" biasprm="0 -107.228 -0.893566"/>
    <general name="head_pitch" class="/" joint="head_pitch_joint" forcerange="-3.4208 3.4208" gainprm="107.228" biasprm="0 -107.228 -0.893566"/>
    <general name="head_yaw" class="/" joint="head_yaw_joint" forcerange="-3.50644 3.50644" gainprm="107.228" biasprm="0 -107.228 -0.893566"/>
  </actuator>

  <sensor>
    <gyro site="imu" name="imu_angular_velocity"/>
    <velocimeter site="imu" name="imu_linear_velocity"/>
    <framelinvel objtype="site" objname="left_foot" name="left_foot_global_linear_velocity"/>
    <framelinvel objtype="site" objname="right_foot" name="right_foot_global_linear_velocity"/>
  </sensor>

  <keyframe>
    <key name="home" qpos="0 0 0.8665 1 0 0 0 0 0 -0.4 0.8 -0.4 0 0 0 0.4 -0.8 0.4 0 0 0 0 0 -0.2 0 -0.785 0 0 0 0 0 0.2 0 0.785 0 0 0 0 0 0 0"/>
  </keyframe>
</mujoco>
