<mujoco model="GR1T2_jaw">
  <compiler angle="radian" assetdir="assets" balanceinertia="true" inertiafromgeom="false"/>

  <option timestep="0.005" density="1.2" viscosity="2e-05"/>

  <size nkey="1"/>

  <visual>
    <quality shadowsize="8192"/>
    <map shadowclip="0.5"/>
  </visual>

  <default>
    <default class="/">
      <joint armature="0.1" damping="0.01" frictionloss="0.1"/>
      <geom contype="0" conaffinity="0" group="1" solref="-1000 -80"/>
      <site size="0.01 0.005 0.005" group="5"/>
      <general forcelimited="true" biastype="affine" gainprm="80" biasprm="0 -80 -2"/>
      <default class="visual">
        <geom type="mesh" density="0" rgba="0.18 0.18 0.18 1"/>
      </default>
      <default class="collision">
        <geom group="3"/>
      </default>
      <default class="foot">
        <geom size="0.126 0.045 0.01" type="box" condim="6" group="4" priority="1" solimp="0.015 1 0.01"/>
      </default>
      <default class="reward_collision_sphere">
        <geom group="5" rgba="1 0 0 1"/>
      </default>
    </default>
  </default>

  <asset>
    <texture type="skybox" colorspace="auto" name="//unnamed_texture_0" builtin="gradient" rgb1="0.95 0.95 0.95" rgb2="0.95 0.95 0.95" width="100" height="600"/>
    <texture type="2d" colorspace="auto" name="texplane" builtin="checker" rgb1="0.345 0.575 0.748" rgb2="0.345 0.575 0.748" markrgb="1 1 1" width="512" height="512"/>
    <material name="MatPlane" class="/" texture="texplane" texuniform="true" texrepeat="2 2" specular="0.9"/>
    <mesh name="base_link" class="/" file="base_link.STL"/>
    <mesh name="left_thigh_roll_link" class="/" file="left_thigh_roll_link.STL"/>
    <mesh name="left_thigh_yaw_link" class="/" file="left_thigh_yaw_link.STL"/>
    <mesh name="left_thigh_pitch_link" class="/" file="left_thigh_pitch_link.STL"/>
    <mesh name="left_shank_pitch_link" class="/" file="left_shank_pitch_link.STL"/>
    <mesh name="left_foot_pitch_link" class="/" file="left_foot_pitch_link.STL"/>
    <mesh name="left_foot_roll_link" class="/" file="left_foot_roll_link.STL"/>
    <mesh name="right_thigh_roll_link" class="/" file="right_thigh_roll_link.STL"/>
    <mesh name="right_thigh_yaw_link" class="/" file="right_thigh_yaw_link.STL"/>
    <mesh name="right_thigh_pitch_link" class="/" file="right_thigh_pitch_link.STL"/>
    <mesh name="right_shank_pitch_link" class="/" file="right_shank_pitch_link.STL"/>
    <mesh name="right_foot_pitch_link" class="/" file="right_foot_pitch_link.STL"/>
    <mesh name="right_foot_roll_link" class="/" file="right_foot_roll_link.STL"/>
    <mesh name="waist_yaw_link" class="/" file="waist_yaw_link.STL"/>
    <mesh name="waist_pitch_link" class="/" file="waist_pitch_link.STL"/>
    <mesh name="waist_roll_link" class="/" file="waist_roll_link.STL"/>
    <mesh name="torso_link" class="/" file="torso_link.STL"/>
    <mesh name="left_upper_arm_pitch_link" class="/" file="left_upper_arm_pitch_link.STL"/>
    <mesh name="left_upper_arm_roll_link" class="/" file="left_upper_arm_roll_link.STL"/>
    <mesh name="left_upper_arm_yaw_link" class="/" file="left_upper_arm_yaw_link.STL"/>
    <mesh name="left_lower_arm_pitch_link" class="/" file="left_lower_arm_pitch_link.STL"/>
    <mesh name="left_hand_yaw_link" class="/" file="left_hand_yaw_link.STL"/>
    <mesh name="left_hand_roll_link" class="/" file="left_hand_roll_link.STL"/>
    <mesh name="left_hand_pitch" class="/" file="left_hand_pitch.STL"/>
    <mesh name="left_jaw_link" class="/" file="left_jaw_link.STL"/>
    <mesh name="right_upper_arm_pitch_link" class="/" file="right_upper_arm_pitch_link.STL"/>
    <mesh name="right_upper_arm_roll_link" class="/" file="right_upper_arm_roll_link.STL"/>
    <mesh name="right_upper_arm_yaw_link" class="/" file="right_upper_arm_yaw_link.STL"/>
    <mesh name="right_lower_arm_pitch_link" class="/" file="right_lower_arm_pitch_link.STL"/>
    <mesh name="right_hand_yaw_link" class="/" file="right_hand_yaw_link.STL"/>
    <mesh name="right_hand_roll_link" class="/" file="right_hand_roll_link.STL"/>
    <mesh name="right_hand_pitch" class="/" file="right_hand_pitch.STL"/>
    <mesh name="right_jaw_link" class="/" file="right_jaw_link.STL"/>
    <mesh name="head_roll_link" class="/" file="head_roll_link.STL"/>
    <mesh name="head_pitch_link" class="/" file="head_pitch_link.STL"/>
    <mesh name="head_yaw_link" class="/" file="head_yaw_link.STL"/>
    <mesh name="imu_link" class="/" file="imu_link.STL"/>
  </asset>

  <worldbody>
    <geom name="floor" class="/" size="100 100 0.125" type="plane" group="0" material="MatPlane"/>
    <light name="toplight_shadow" class="/" pos="0 0 5" dir="0.0990148 0.0990148 -0.990148" type="directional" ambient="0.04 0.04 0.04" diffuse="0.55 0.55 0.55" specular="0.12 0.12 0.12"/>
    <light name="toplight_fill" class="/" pos="0 0 5" dir="0.0990148 0.0990148 -0.990148" type="directional" castshadow="false" ambient="0.04 0.04 0.04" diffuse="0.3 0.3 0.3" specular="0.08 0.08 0.08"/>
    <body name="trunk" pos="0.00481111 0.00886252 0.00490987" quat="0.99999 0.00275804 0.000900564 -0.00351462">
      <inertial pos="-0.0265283 0.00860288 -0.0085759" quat="0.99876 0.0156475 -0.0463463 -0.00921872" mass="1.41203" diaginertia="0.000533275 0.000349657 0.104501"/>
      <joint name="//unnamed_joint_0" type="free"/>
      <geom name="//unnamed_geom_1" class="visual" rgba="0.12 0.12 0.12 1" mesh="base_link"/>
      <geom name="base_link.STL" class="collision" size="0.0877496 0.0491468" pos="-0.0183318 0.00018343 0.011279" quat="0.706838 -0.707359 0.00477667 0" type="cylinder" rgba="0.752941 0.752941 0.752941 1"/>
      <geom name="//unnamed_geom_3" class="visual" pos="0 0 -0.0729882" quat="1 0 0 0" rgba="0.12 0.12 0.12 1" mesh="imu_link"/>
      <geom name="//unnamed_geom_4" class="reward_collision_sphere" size="0.0573555" pos="0 0.0495699 0.122463"/>
      <geom name="//unnamed_geom_5" class="reward_collision_sphere" size="0.0573555" pos="0 -0.0495699 0.122463"/>
      <site name="imu" class="/" pos="-0.0211824 0.000642152 -0.0816148" size="0.00716943"/>
      <camera name="track" class="/" pos="0 -0.991398 0" quat="0.707107 0.707107 0 0" mode="trackcom"/>
      <body name="left_thigh_roll_link" pos="-0.0124165 0.0537853 -0.0364411" quat="1 -0.000336179 0.00039072 -0.00014161">
        <inertial pos="0.00795806 -0.00768874 -0.00226605" quat="0.00264803 0.717671 -0.0271354 0.695848" mass="0.53586" diaginertia="4.22376e-05 6.95575e-05 0.00425121"/>
        <joint name="left_hip_roll_joint" class="/" pos="0 0 0" axis="-0.99867 -0.0388645 -0.0338876" range="-0.805761 0.0572086" armature="0.0511036" damping="0" frictionloss="0.0658344"/>
        <geom name="//unnamed_geom_6" class="visual" mesh="left_thigh_roll_link"/>
        <body name="left_thigh_yaw_link" pos="0.00435215 -0.0003172 0.00712738" quat="0.999991 -0.00331499 -0.000945031 -0.00228665">
          <inertial pos="-0.00978009 0.0243929 -0.124427" quat="0.572483 0.0952472 -0.188739 0.792192" mass="1.43199" diaginertia="0.00036226 0.000519536 0.0248298"/>
          <joint name="left_hip_yaw_joint" class="/" pos="0 0 0" axis="0.000156466 -0.0029413 -0.999996" stiffness="0.0116768" range="-0.853075 0.801805" armature="0.0557606" damping="0.00485024" frictionloss="0.0846927"/>
          <geom name="//unnamed_geom_7" class="visual" mesh="left_thigh_yaw_link"/>
          <body name="left_thigh_pitch_link" pos="0.00321525 0.0106538 -0.165712" quat="0.999997 0.00190971 0.00130341 -3.33387e-05">
            <inertial pos="-0.0109472 -0.010196 -0.0768559" quat="0.999828 -0.0160523 -0.00650824 0.00669257" mass="2.83277" diaginertia="0.00144158 0.00263926 0.0626266"/>
            <joint name="left_hip_pitch_joint" class="/" pos="0 0 0" axis="-0.017517 0.999822 0.00701688" stiffness="0.00336677" range="-1.7869 0.901628" armature="0.0661831" damping="0.00916295" frictionloss="0.0499847"/>
            <geom name="//unnamed_geom_8" class="visual" mesh="left_thigh_pitch_link"/>
            <geom name="left_thigh_pitch_link.STL" class="collision" size="0.0587894 0.0895563" pos="0.00030137 -0.014871 -0.204582" type="cylinder" rgba="0.752941 0.752941 0.752941 1"/>
            <geom name="//unnamed_geom_10" class="reward_collision_sphere" size="0.0716943" pos="0 -0.00495699 -0.0612317"/>
            <body name="left_shank_pitch_link" pos="0.00033713 -0.0128317 -0.436523" quat="0.999996 0.00203709 0.00140191 -0.00114057">
              <inertial pos="0.00914666 -0.00198723 -0.140231" quat="0.999644 -0.00528705 0.00845514 -0.0247363" mass="0.60636" diaginertia="0.000138588 0.000238913 0.00323519"/>
              <joint name="left_knee_pitch_joint" class="/" pos="0 0 0" axis="0.0506023 0.998568 -0.0173791" stiffness="0.00604107" range="0.100429 2.10832" armature="0.0772288" damping="0.0219902" frictionloss="0.0731419"/>
              <geom name="//unnamed_geom_11" class="visual" mesh="left_shank_pitch_link"/>
              <geom name="left_shank_pitch_link.STL" class="collision" size="0.0382284 0.0648009" pos="-7.14198e-06 -0.00041765 -0.213933" quat="0.00125538 -0.202712 0.979238 0" type="cylinder" rgba="0.752941 0.752941 0.752941 1"/>
              <geom name="//unnamed_geom_13" class="reward_collision_sphere" size="0.0358472"/>
              <geom name="//unnamed_geom_14" class="reward_collision_sphere" size="0.0430166" pos="0 0 -0.13471"/>
              <body name="left_foot_pitch_link" pos="0.00197449 0.00725734 -0.415982" quat="1 0.000405919 0.000326145 0.000594586">
                <inertial pos="-0.0028194 -0.00908664 0.00218043" quat="0.00332814 0.709024 -0.00109725 0.705175" mass="0.0207254" diaginertia="8.33864e-08 1.45613e-07 1.64105e-05"/>
                <joint name="left_ankle_pitch_joint" class="/" pos="0 0 0" axis="-0.0227914 0.998353 0.0526558" range="-1.06313 0.581836" armature="0.0880488" damping="0" frictionloss="0.0742059"/>
                <geom name="//unnamed_geom_15" class="visual" mesh="left_foot_pitch_link"/>
                <body name="left_foot_roll_link" pos="-0.00847265 0.00166417 -0.00791667" quat="0.999999 0.000585937 0.000786681 -0.000272694">
                  <inertial pos="0.00534642 0.000600729 -0.0481167" quat="2.84951e-05 0.724278 0.000102615 0.689508" mass="0.391694" diaginertia="8.21189e-05 0.000150772 0.00179396"/>
                  <joint name="left_ankle_roll_joint" class="/" pos="0 0 0" axis="-0.999227 0.0288801 0.0266742" range="-0.601919 0.232796" armature="0.0666453" damping="0" frictionloss="0.113183"/>
                  <geom name="//unnamed_geom_16" class="visual" mesh="left_foot_roll_link"/>
                  <geom name="left_foot" class="foot" size="0.113437 0.0324609 0.00476192" pos="0.0193723 0 -0.0544962"/>
                  <geom name="//unnamed_geom_18" class="reward_collision_sphere" size="0.0358472" pos="0 0 -0.036739"/>
                  <geom name="//unnamed_geom_19" class="reward_collision_sphere" size="0.0358472" pos="0.0516596 0 -0.036739"/>
                  <site name="left_foot" class="foot" pos="0.0193723 0 -0.0544962" size="0.00716943"/>
                </body>
              </body>
            </body>
          </body>
        </body>
      </body>
      <body name="right_thigh_roll_link" pos="-0.00655289 -0.0505374 -0.0302526" quat="0.999984 0.00234156 -0.00260065 0.00434193">
        <inertial pos="7.65591e-05 0.00781474 -0.000450226" quat="0.0582869 0.702216 0.0529072 0.707599" mass="0.540004" diaginertia="3.87248e-05 7.52727e-05 0.00430361"/>
        <joint name="right_hip_roll_joint" class="/" pos="0 0 0" axis="-0.999209 -0.0367186 0.0152789" stiffness="0.0221169" range="-0.0151708 0.781473" armature="0.0693203" damping="0" frictionloss="0.0438563"/>
        <geom name="//unnamed_geom_20" class="visual" mesh="right_thigh_roll_link"/>
        <body name="right_thigh_yaw_link" pos="0.0042646 -0.00213023 0.000806797" quat="1 0.000191015 4.03282e-05 -0.000145817">
          <inertial pos="6.11293e-05 -0.0178676 -0.139834" quat="0.68712 -0.147925 0.151392 0.695029" mass="1.18662" diaginertia="0.000276117 0.000486351 0.0216703"/>
          <joint name="right_hip_yaw_joint" class="/" pos="0 0 0" axis="0.025351 0.00685444 -0.999655" range="-0.499324 0.691507" armature="0.0658732" damping="0" frictionloss="0.0675918"/>
          <geom name="//unnamed_geom_21" class="visual" mesh="right_thigh_yaw_link"/>
          <body name="right_thigh_pitch_link" pos="-0.00696673 -0.012895 -0.178244" quat="0.999999 0.000135574 0.00116073 -0.000715235">
            <inertial pos="0.000565094 0.00899585 -0.0741413" quat="0.999872 -0.00779266 -0.0127586 0.00572576" mass="2.97671" diaginertia="0.00141095 0.00270238 0.0762347"/>
            <joint name="right_hip_pitch_joint" class="/" pos="0 0 0" axis="0.0453501 -0.99896 0.00474182" range="-0.709469 1.82473" armature="0.0435474" damping="0" frictionloss="0.0593974"/>
            <geom name="//unnamed_geom_22" class="visual" mesh="right_thigh_pitch_link"/>
            <geom name="right_thigh_pitch_link.STL" class="collision" size="0.0587894 0.0895541" pos="-0.00091406 0.014871 -0.204582" quat="0.999971 0.00269833 0.00706272 0" type="cylinder" rgba="0.752941 0.752941 0.752941 1"/>
            <geom name="//unnamed_geom_24" class="reward_collision_sphere" size="0.0716943" pos="0 0.00495699 -0.0612317"/>
            <body name="right_shank_pitch_link" pos="-0.000223941 0.0108803 -0.44273" quat="0.999996 -0.00177436 0.00125389 0.00193066">
              <inertial pos="-0.00118562 -0.000735135 -0.130021" quat="0.998435 0.0339321 0.0335748 0.0291421" mass="0.579179" diaginertia="0.000155941 0.00035015 0.00384331"/>
              <joint name="right_knee_pitch_joint" class="/" pos="0 0 0" axis="0.00227327 -0.999976 -0.0065087" stiffness="0.00036134" range="-1.96029 0.212725" armature="0.0667396" damping="0" frictionloss="0.108122"/>
              <geom name="//unnamed_geom_25" class="visual" mesh="right_shank_pitch_link"/>
              <geom name="right_shank_pitch_link.STL" class="collision" size="0.0382282 0.0648003" pos="-7.14198e-06 -0.000417655 -0.213942" type="cylinder" rgba="0.752941 0.752941 0.752941 1"/>
              <geom name="//unnamed_geom_27" class="reward_collision_sphere" size="0.0358472"/>
              <geom name="//unnamed_geom_28" class="reward_collision_sphere" size="0.0430166" pos="0 0 -0.13471"/>
              <body name="right_foot_pitch_link" pos="-0.00695946 -0.00420408 -0.412731" quat="0.999996 0.000312465 -0.000815187 0.00257322">
                <inertial pos="0.000926201 -0.000420824 0.00174488" quat="0.000466769 0.706144 -0.000297571 0.708068" mass="0.0185575" diaginertia="8.4066e-08 1.61155e-07 1.47107e-05"/>
                <joint name="right_ankle_pitch_joint" class="/" pos="0 0 0" axis="-0.000116983 -1 -0.000291334" range="-0.48634 1.17021" armature="0.0757565" damping="0.00347933" frictionloss="0.046038"/>
                <geom name="//unnamed_geom_29" class="visual" mesh="right_foot_pitch_link"/>
                <body name="right_foot_roll_link" pos="0.00140345 -0.000432886 -0.00110477" quat="0.999999 -0.000936918 1.03817e-06 0.000788337">
                  <inertial pos="0.014009 -0.0117005 -0.0391092" quat="0.00909262 0.716959 0.00365541 0.697047" mass="0.390296" diaginertia="8.40956e-05 0.000131572 0.00191624"/>
                  <joint name="right_ankle_roll_joint" class="/" pos="0 0 0" axis="-0.999993 -0.00347641 0.00123512" range="-0.306725 0.605715" armature="0.0699555" damping="0" frictionloss="0.103304"/>
                  <geom name="//unnamed_geom_30" class="visual" mesh="right_foot_roll_link"/>
                  <geom name="right_foot" class="foot" size="0.121532 0.0332565 0.00734085" pos="0.0193723 0 -0.0544962"/>
                  <geom name="//unnamed_geom_32" class="reward_collision_sphere" size="0.0358472" pos="0 0 -0.036739"/>
                  <geom name="//unnamed_geom_33" class="reward_collision_sphere" size="0.0358472" pos="0.0516596 0 -0.036739"/>
                  <site name="right_foot" class="foot" pos="0.0193723 0 -0.0544962" size="0.00716943"/>
                </body>
              </body>
            </body>
          </body>
        </body>
      </body>
      <body name="waist_yaw_link" pos="2.16033e-05 -0.00120453 -0.000244289" quat="0.999996 -0.00162881 0.00191534 -0.000831563">
        <inertial pos="0.00974166 -0.00884156 0.0578833" quat="0.974631 0.20697 -0.0346939 0.0778115" mass="0.694881" diaginertia="6.00857e-05 0.000111397 0.00742342"/>
        <joint name="waist_yaw_joint" class="/" pos="0 0 0" axis="0.00123971 0.00173455 0.999998" range="-1.01454 1.22046" armature="0.0406824" damping="0.0163279" frictionloss="0.0676167"/>
        <geom name="//unnamed_geom_34" class="visual" rgba="0.12 0.12 0.12 1" mesh="waist_yaw_link"/>
        <body name="waist_pitch_link" pos="0.00714239 -0.00435556 0.1108" quat="0.999997 -0.0016188 0.00105302 0.00170511">
          <inertial pos="0.00200076 -0.00418496 0.0610725" quat="0.997349 -0.0443778 0.0395269 0.0419961" mass="0.624643" diaginertia="7.43341e-05 0.000144381 0.00440164"/>
          <joint name="waist_pitch_joint" class="/" pos="0 0 0" axis="0.0316142 -0.999286 -0.0206868" stiffness="0.0337612" range="-1.22557 0.469851" armature="0.0610484" damping="0" frictionloss="0.0551244"/>
          <geom name="//unnamed_geom_35" class="visual" rgba="0.12 0.12 0.12 1" mesh="waist_pitch_link"/>
          <body name="waist_roll_link" pos="0.000122591 -0.00185301 0.0993695" quat="0.999999 -0.000960287 -0.000392381 -0.000349987">
            <inertial pos="0.00547433 0.012024 0.177564" quat="0.999527 -0.0103981 -0.0282003 0.00648485" mass="2.67212" diaginertia="0.00107622 0.00177926 0.088597"/>
            <joint name="waist_roll_joint" class="/" pos="0 0 0" axis="-0.999973 6.76267e-05 -0.00736285" range="-0.472858 0.675002" armature="0.0703965" damping="0.0216669" frictionloss="0.07763"/>
            <geom name="//unnamed_geom_36" class="visual" rgba="0.12 0.12 0.12 1" mesh="waist_roll_link"/>
            <geom name="//unnamed_geom_37" class="visual" pos="-0.000968617 0.000284745 0.19637" quat="1 0 0 0" mesh="torso_link"/>
            <geom name="torso_link.STL" class="collision" size="0.112866 0.0216467" pos="-0.00777731 0.00286009 0.181036" type="cylinder" rgba="0.752941 0.752941 0.752941 1"/>
            <geom name="//unnamed_geom_39" class="reward_collision_sphere" size="0.0932026" pos="0 0 0.244927"/>
            <body name="left_upper_arm_pitch_link" pos="0.00136183 0.0578838 0.262433" quat="0.97674 0.214428 9.57932e-05 0.000267734">
              <inertial pos="-0.000523065 0.0260393 -0.00318678" quat="0.704272 0.707977 0.00341616 -0.052515" mass="0.290262" diaginertia="2.77336e-05 5.46331e-05 0.00130813"/>
              <joint name="left_shoulder_pitch_joint" class="/" pos="0 0 0" axis="-0.0291167 0.998878 -0.0373467" range="-2.82552 1.94553" armature="0.0600006" damping="0.053698" frictionloss="0.0666369"/>
              <geom name="//unnamed_geom_40" class="visual" mesh="left_upper_arm_pitch_link"/>
              <body name="left_upper_arm_roll_link" pos="-0.00214781 0.0414256 0.00799066" quat="0.976503 -0.215446 -0.0022448 -0.00453874">
                <inertial pos="-0.00739031 0.00315702 -0.0280932" quat="0.888612 0.2763 0.125392 -0.343954" mass="0.25885" diaginertia="1.55357e-05 3.2044e-05 0.00104243"/>
                <joint name="left_shoulder_roll_joint" class="/" pos="0 0 0" axis="-0.999966 0.00818365 0.000413765" range="-2.52136 0.568401" armature="0.0678751" damping="0.0560448" frictionloss="0.0700971"/>
                <geom name="//unnamed_geom_41" class="visual" mesh="left_upper_arm_roll_link"/>
                <body name="left_upper_arm_yaw_link" pos="-0.00408944 0.0163104 -0.082417" quat="1 0.000253572 -0.000159711 -0.000531659">
                  <inertial pos="-0.0086588 -0.00626197 -0.117645" quat="0.999917 0.000856162 0.00268385 -0.0125982" mass="0.194072" diaginertia="5.2301e-05 0.000110995 0.000728528"/>
                  <joint name="left_shoulder_yaw_joint" class="/" pos="0 0 0" axis="-0.0221792 -0.0400674 0.998951" stiffness="0.0417417" range="-2.97407 2.97195" armature="0.0775271" damping="0.00767299" frictionloss="0.090419"/>
                  <geom name="//unnamed_geom_42" class="visual" mesh="left_upper_arm_yaw_link"/>
                  <geom name="left_upper_arm_yaw_link.STL" class="collision" size="0.0259772 0.0608986" pos="1.69983e-05 -0.000443299 -0.0971625" quat="0.00803418 -0.995528 0.0941277 0" type="cylinder" rgba="0.752941 0.752941 0.752941 1"/>
                  <body name="left_lower_arm_pitch_link" pos="0.0108063 0.00647701 -0.219724" quat="0.999985 -1.34963e-05 -0.0034241 -0.00437147">
                    <inertial pos="-0.00179048 0.00389634 -0.0335192" quat="0.70552 -0.0906544 0.0958154 0.696307" mass="0.138443" diaginertia="5.55204e-06 9.49703e-06 0.000337808"/>
                    <joint name="left_elbow_pitch_joint" class="/" pos="0 0 0" axis="0.000504938 0.999864 0.0165028" stiffness="0.0387796" range="-2.26863 2.17765" armature="0.0763136" damping="0" frictionloss="0.0704741"/>
                    <geom name="//unnamed_geom_44" class="visual" mesh="left_lower_arm_pitch_link"/>
                    <body name="left_hand_yaw_link" pos="0.001036 0.0116461 -0.0710203" quat="0.99999 -0.000594856 -0.00210751 -0.00377744">
                      <inertial pos="0.000649989 0.0019024 -0.0902795" quat="0.999912 0.00194488 -0.00778024 0.0105477" mass="0.388254" diaginertia="3.51358e-05 8.69091e-05 0.00141321"/>
                      <joint name="left_wrist_yaw_joint" class="/" pos="0 0 0" axis="-0.000601154 -0.000502911 1" stiffness="0.00268709" range="-2.73753 2.93712" armature="0.0574693" damping="0.00718571" frictionloss="0.113042"/>
                      <geom name="//unnamed_geom_45" class="visual" mesh="left_hand_yaw_link"/>
                      <geom name="left_hand_yaw_link.STL" class="collision" size="0.0298047 0.0498947" pos="0.000468918 -0.000763927 -0.0931247" type="cylinder" rgba="0.752941 0.752941 0.752941 1"/>
                      <geom name="//unnamed_geom_47" class="reward_collision_sphere" size="0.0358472"/>
                      <body name="left_hand_roll_link" pos="-0.00180113 -0.0116427 -0.238598" quat="1 -0.000352602 0.000237447 -0.000798292">
                        <inertial pos="0.00947353 0.000866413 -0.001218" quat="0.497233 0.476888 0.535505 0.488438" mass="0.00174236" diaginertia="5.24594e-09 9.8873e-09 1.92273e-07"/>
                        <joint name="left_wrist_roll_joint" class="/" pos="0 0 0" axis="-0.999989 0.00308316 0.00363747" range="-1.0661 0.883202" armature="0.0849321" damping="0" frictionloss="0.102625"/>
                        <geom name="//unnamed_geom_48" class="visual" mesh="left_hand_roll_link"/>
                        <body name="left_hand_pitch_link" pos="-0.0116057 0.00854365 -0.0029296" quat="0.999993 0.000908251 0.00151689 -0.00322164">
                          <inertial pos="-0.00380223 0.00455925 -0.0672224" quat="0.723557 -0.126768 0.0704669 0.674855" mass="0.0837676" diaginertia="4.686e-06 8.06871e-06 0.000244944"/>
                          <joint name="left_wrist_pitch_joint" class="/" pos="0 0 0" axis="0.0535779 0.998223 -0.0260753" stiffness="0.0527255" range="-0.630942 0.554654" armature="0.038677" damping="0" frictionloss="0.0586388"/>
                          <geom name="//unnamed_geom_49" class="visual" mesh="left_hand_pitch"/>
                          <body name="left_jaw_link" pos="-0.0053904 -5.6362e-05 -0.0789195" quat="1 -3.33239e-05 1.72999e-05 0.000130136">
                            <inertial pos="-0.00580627 2.68868e-05 -0.04795" quat="0.707343 -0.0250586 0.0337349 0.705621" mass="0.0239315" diaginertia="1.28721e-06 1.65126e-06 8.41326e-05"/>
                            <joint name="left_jaw_joint" class="/" pos="0 0 0" axis="-0.999886 0.0124595 -0.00852758" stiffness="0.00976436" range="-0.840458 -0.0214278" armature="0.107271" damping="0.0536161" frictionloss="0.0470076"/>
                            <geom name="//unnamed_geom_50" class="visual" mesh="left_jaw_link"/>
                            <geom name="//unnamed_geom_51" class="collision" size="0.02581"/>
                            <geom name="//unnamed_geom_52" class="reward_collision_sphere" size="0.0358472" pos="0 0 -0.0244927"/>
                          </body>
                        </body>
                      </body>
                    </body>
                  </body>
                </body>
              </body>
            </body>
            <body name="right_upper_arm_pitch_link" pos="-0.00188404 -0.0398001 0.260291" quat="0.976341 -0.216222 0.0011335 -0.00246172">
              <inertial pos="-0.00363642 -0.0269937 0.00542132" quat="0.70549 0.707742 0.0266048 0.0260271" mass="0.296734" diaginertia="2.96946e-05 5.91191e-05 0.00146348"/>
              <joint name="right_shoulder_pitch_joint" class="/" pos="0 0 0" axis="-0.000978362 -0.999446 -0.0332741" range="-1.92147 2.77705" armature="0.0666681" damping="0.0410509" frictionloss="0.0717105"/>
              <geom name="//unnamed_geom_53" class="visual" mesh="right_upper_arm_pitch_link"/>
              <body name="right_upper_arm_roll_link" pos="-0.00254525 -0.0383862 0.00244325" quat="0.976643 0.214853 0.00261131 5.43978e-05">
                <inertial pos="0.00151699 -0.0100874 -0.0280342" quat="0.888332 -0.269364 0.125185 0.350199" mass="0.1832" diaginertia="1.24696e-05 3.07267e-05 0.000979812"/>
                <joint name="right_shoulder_roll_joint" class="/" pos="0 0 0" axis="-0.998766 0.0303665 -0.0392976" range="-0.684804 2.71849" armature="0.107147" damping="0" frictionloss="0.0762383"/>
                <geom name="//unnamed_geom_54" class="visual" mesh="right_upper_arm_roll_link"/>
                <body name="right_upper_arm_yaw_link" pos="2.70393e-05 -0.0195896 -0.0746936" quat="0.999998 -0.000724287 -0.00141205 -0.00138412">
                  <inertial pos="-0.00175808 0.00184055 -0.117084" quat="0.999979 -0.00639766 -0.000597485 0.00112423" mass="0.153743" diaginertia="4.59985e-05 9.39976e-05 0.000654013"/>
                  <joint name="right_shoulder_yaw_joint" class="/" pos="0 0 0" axis="0.0240226 0.046018 0.998652" stiffness="0.0347697" range="-2.84888 2.84235" armature="0.0714598" damping="0" frictionloss="0.0652844"/>
                  <geom name="//unnamed_geom_55" class="visual" mesh="right_upper_arm_yaw_link"/>
                  <geom name="right_upper_arm_yaw_link.STL" class="collision" size="0.0259772 0.0608986" pos="1.69983e-05 0.000443299 -0.0971625" type="cylinder" rgba="0.752941 0.752941 0.752941 1"/>
                  <body name="right_lower_arm_pitch_link" pos="-0.00031715 0.00144197 -0.21921" quat="0.999982 0.0048709 -0.00333854 -0.0011184">
                    <inertial pos="-0.000907032 -0.00397955 -0.0359312" quat="0.701728 0.0913753 -0.0914118 0.700622" mass="0.123224" diaginertia="4.23213e-06 7.47271e-06 0.000255765"/>
                    <joint name="right_elbow_pitch_joint" class="/" pos="0 0 0" axis="0.0044942 -0.999977 0.00513041" range="-2.27025 2.26949" armature="0.0754735" damping="0.014447" frictionloss="0.104585"/>
                    <geom name="//unnamed_geom_57" class="visual" mesh="right_lower_arm_pitch_link"/>
                    <body name="right_hand_yaw_link" pos="0.00036875 -0.00801813 -0.0720908" quat="0.999986 0.00200243 0.00460287 -0.00176691">
                      <inertial pos="0.0021049 -0.00601556 -0.0891678" quat="0.999735 0.00701357 -0.00571664 0.0211617" mass="0.358403" diaginertia="4.11589e-05 8.11278e-05 0.00150579"/>
                      <joint name="right_wrist_yaw_joint" class="/" pos="0 0 0" axis="-0.011096 -0.0106342 0.999882" stiffness="0.0276666" range="-2.97402 3.00372" armature="0.0769526" damping="0.0104056" frictionloss="0.0663384"/>
                      <geom name="//unnamed_geom_58" class="visual" mesh="right_hand_yaw_link"/>
                      <geom name="right_hand_yaw_link.STL" class="collision" size="0.0298047 0.0498947" pos="0.000468918 0.0003178 -0.0931247" type="cylinder" rgba="0.752941 0.752941 0.752941 1"/>
                      <geom name="//unnamed_geom_60" class="reward_collision_sphere" size="0.0358472"/>
                      <body name="right_hand_roll_link" pos="0.0120125 0.00182809 -0.238459" quat="1 -0.000402051 0.000445749 0.000715922">
                        <inertial pos="-0.00989857 0.00249058 0.00128587" quat="0.501275 0.499022 0.501187 0.498509" mass="0.00184704" diaginertia="5.67219e-09 1.01059e-08 1.77853e-07"/>
                        <joint name="right_wrist_roll_joint" class="/" pos="0 0 0" axis="-1 -0.000173696 -0.000159271" stiffness="0.0227134" range="-0.91047 0.934294" armature="0.104687" damping="0.00645511" frictionloss="0.065687"/>
                        <geom name="//unnamed_geom_61" class="visual" mesh="right_hand_roll_link"/>
                        <body name="right_hand_pitch_link" pos="-0.0100188 0.000701301 0.00223956" quat="1 -0.00037232 -9.31193e-05 0.000102121">
                          <inertial pos="-0.000601137 0.00153732 -0.0766746" quat="0.726656 0.117779 -0.109632 0.667892" mass="0.0870792" diaginertia="4.68443e-06 8.53241e-06 0.000315373"/>
                          <joint name="right_wrist_pitch_joint" class="/" pos="0 0 0" axis="0.0381796 -0.999147 0.0157606" range="-0.576746 0.447264" armature="0.0729471" damping="0.0155087" frictionloss="0.0680301"/>
                          <geom name="//unnamed_geom_62" class="visual" mesh="right_hand_pitch"/>
                          <body name="right_jaw_link" pos="-0.0111456 -0.01019 -0.0753435" quat="1 -0.000329719 0.000754801 0.00017905">
                            <inertial pos="7.09241e-05 0.00111205 -0.0363248" quat="0.707876 0.0220046 -0.0313087 0.7053" mass="0.024807" diaginertia="1.16863e-06 1.68679e-06 0.000100086"/>
                            <joint name="right_jaw_joint" class="/" pos="0 0 0" axis="-0.999722 -0.012388 0.0200505" stiffness="0.00373238" range="-0.06615 0.877681" armature="0.0779376" damping="0" frictionloss="0.0703737"/>
                            <geom name="//unnamed_geom_63" class="visual" mesh="right_jaw_link"/>
                            <geom name="//unnamed_geom_64" class="collision" size="0.02581"/>
                            <geom name="//unnamed_geom_65" class="reward_collision_sphere" size="0.0358472" pos="0 0 -0.0244927"/>
                          </body>
                        </body>
                      </body>
                    </body>
                  </body>
                </body>
              </body>
            </body>
            <body name="head_roll_link" pos="0.00734021 -0.00065249 0.372662" quat="1 0.000163734 0.000402532 -0.000463891">
              <inertial pos="0.00271895 0.00610038 -0.0101283" quat="0.0116124 0.679164 -0.0321811 0.733189" mass="0.00374673" diaginertia="1.06453e-08 1.31166e-08 1.23239e-06"/>
              <joint name="head_roll_joint" class="/" pos="0 0 0" axis="-1 0.000250006 0.000514263" stiffness="0.000384272" range="-0.377859 0.351292" armature="0.0498439" damping="0" frictionloss="0.0868877"/>
              <geom name="//unnamed_geom_66" class="visual" mesh="head_roll_link"/>
              <body name="head_pitch_link" pos="-0.00210682 -0.00163691 0.00144117" quat="0.999997 -0.00107702 -0.00195732 0.000573292">
                <inertial pos="-0.000382138 -0.00210147 0.0221982" quat="0.667488 0.666619 0.243933 -0.224891" mass="0.0247992" diaginertia="3.83975e-07 6.96253e-07 5.30691e-05"/>
                <joint name="head_pitch_joint" class="/" pos="0 0 0" axis="-0.001225 -0.99999 0.00433308" range="-0.825222 0.867303" armature="0.0496495" damping="0.00487878" frictionloss="0.0776209"/>
                <geom name="//unnamed_geom_67" class="visual" mesh="head_pitch_link"/>
                <body name="head_yaw_link" pos="-0.00352997 -0.0012798 0.0565517" quat="1 0.000535314 -0.000281308 -0.000284576">
                  <inertial pos="0.00820977 0.00689772 0.116802" quat="0.705989 -0.105977 -0.125279 0.688951" mass="0.586545" diaginertia="0.000135516 0.000232964 0.0141445"/>
                  <joint name="head_yaw_joint" class="/" pos="0 0 0" axis="0.000679518 0.000719855 1" range="-2.74048 2.63688" armature="0.0768384" damping="0.00737287" frictionloss="0.0703118"/>
                  <geom name="//unnamed_geom_68" class="visual" rgba="0.12 0.12 0.12 1" mesh="head_yaw_link"/>
                  <geom name="head_yaw_link.STL" class="collision" size="0.0850919" pos="0.00786995 -0.000436227 0.11465" rgba="0.752941 0.752941 0.752941 1"/>
                  <geom name="//unnamed_geom_70" class="reward_collision_sphere" size="0.0716943" pos="0.0129149 0 0.122463"/>
                  <camera name="ego_camera" class="/" pos="0.0473546 0 0.13471" quat="-0.5 -0.5 0.5 0.5"/>
                </body>
              </body>
            </body>
          </body>
        </body>
      </body>
    </body>
  </worldbody>

  <contact>
    <pair class="/" geom1="floor" geom2="left_foot" name="//unnamed_contact_0"/>
    <pair class="/" geom1="floor" geom2="right_foot" name="//unnamed_contact_1"/>
  </contact>

  <actuator>
    <general name="left_hip_roll" class="/" joint="left_hip_roll_joint" forcerange="-48.6005 48.6005" gainprm="71.4775" biasprm="0 -71.4775 -1.78092"/>
    <general name="left_hip_yaw" class="/" joint="left_hip_yaw_joint" forcerange="-32.5643 32.5643" gainprm="71.4775" biasprm="0 -71.4775 -1.78092"/>
    <general name="left_hip_pitch" class="/" joint="left_hip_pitch_joint" forcerange="-173.383 173.383" gainprm="71.4775" biasprm="0 -71.4775 -1.78092"/>
    <general name="left_knee_pitch" class="/" joint="left_knee_pitch_joint" forcerange="-159.342 159.342" gainprm="71.4775" biasprm="0 -71.4775 -1.78092"/>
    <general name="left_ankle_pitch" class="/" joint="left_ankle_pitch_joint" forcerange="-10.2034 10.2034" gainprm="71.4775" biasprm="0 -71.4775 -1.78092"/>
    <general name="left_ankle_roll" class="/" joint="left_ankle_roll_joint" forcerange="-28.8948 28.8948" gainprm="71.4775" biasprm="0 -71.4775 -1.78092"/>
    <general name="right_hip_roll" class="/" joint="right_hip_roll_joint" forcerange="-32.7203 32.7203" gainprm="71.4775" biasprm="0 -71.4775 -1.78092"/>
    <general name="right_hip_yaw" class="/" joint="right_hip_yaw_joint" forcerange="-31.1235 31.1235" gainprm="71.4775" biasprm="0 -71.4775 -1.78092"/>
    <general name="right_hip_pitch" class="/" joint="right_hip_pitch_joint" forcerange="-124.815 124.815" gainprm="71.4775" biasprm="0 -71.4775 -1.78092"/>
    <general name="right_knee_pitch" class="/" joint="right_knee_pitch_joint" forcerange="-121.962 121.962" gainprm="71.4775" biasprm="0 -71.4775 -1.78092"/>
    <general name="right_ankle_pitch" class="/" joint="right_ankle_pitch_joint" forcerange="-10.7524 10.7524" gainprm="71.4775" biasprm="0 -71.4775 -1.78092"/>
    <general name="right_ankle_roll" class="/" joint="right_ankle_roll_joint" forcerange="-28.4229 28.4229" gainprm="71.4775" biasprm="0 -71.4775 -1.78092"/>
    <general name="waist_yaw" class="/" joint="waist_yaw_joint" forcerange="-33.6153 33.6153" gainprm="71.4775" biasprm="0 -71.4775 -1.78092"/>
    <general name="waist_pitch" class="/" joint="waist_pitch_joint" forcerange="-36.247 36.247" gainprm="71.4775" biasprm="0 -71.4775 -1.78092"/>
    <general name="waist_roll" class="/" joint="waist_roll_joint" forcerange="-40.4443 40.4443" gainprm="71.4775" biasprm="0 -71.4775 -1.78092"/>
    <general name="left_shoulder_pitch" class="/" joint="left_shoulder_pitch_joint" forcerange="-25.731 25.731" gainprm="71.4775" biasprm="0 -71.4775 -1.78092"/>
    <general name="left_shoulder_roll" class="/" joint="left_shoulder_roll_joint" forcerange="-28.5551 28.5551" gainprm="71.4775" biasprm="0 -71.4775 -1.78092"/>
    <general name="left_shoulder_yaw" class="/" joint="left_shoulder_yaw_joint" forcerange="-22.8849 22.8849" gainprm="71.4775" biasprm="0 -71.4775 -1.78092"/>
    <general name="left_elbow_pitch" class="/" joint="left_elbow_pitch_joint" forcerange="-16.3787 16.3787" gainprm="71.4775" biasprm="0 -71.4775 -1.78092"/>
    <general name="left_wrist_yaw" class="/" joint="left_wrist_yaw_joint" forcerange="-8.74109 8.74109" gainprm="71.4775" biasprm="0 -71.4775 -1.78092"/>
    <general name="left_wrist_roll" class="/" joint="left_wrist_roll_joint" forcerange="-2.78748 2.78748" gainprm="71.4775" biasprm="0 -71.4775 -1.78092"/>
    <general name="left_wrist_pitch" class="/" joint="left_wrist_pitch_joint" forcerange="-3.55684 3.55684" gainprm="71.4775" biasprm="0 -71.4775 -1.78092"/>
    <general name="left_jaw" class="/" joint="left_jaw_joint" forcerange="-1.67114 1.67114" gainprm="71.4775" biasprm="0 -71.4775 -1.78092"/>
    <general name="right_shoulder_pitch" class="/" joint="right_shoulder_pitch_joint" forcerange="-27.5995 27.5995" gainprm="71.4775" biasprm="0 -71.4775 -1.78092"/>
    <general name="right_shoulder_roll" class="/" joint="right_shoulder_roll_joint" forcerange="-28.7596 28.7596" gainprm="71.4775" biasprm="0 -71.4775 -1.78092"/>
    <general name="right_shoulder_yaw" class="/" joint="right_shoulder_yaw_joint" forcerange="-26.2419 26.2419" gainprm="71.4775" biasprm="0 -71.4775 -1.78092"/>
    <general name="right_elbow_pitch" class="/" joint="right_elbow_pitch_joint" forcerange="-21.6839 21.6839" gainprm="71.4775" biasprm="0 -71.4775 -1.78092"/>
    <general name="right_wrist_yaw" class="/" joint="right_wrist_yaw_joint" forcerange="-7.41531 7.41531" gainprm="71.4775" biasprm="0 -71.4775 -1.78092"/>
    <general name="right_wrist_roll" class="/" joint="right_wrist_roll_joint" forcerange="-2.21931 2.21931" gainprm="71.4775" biasprm="0 -71.4775 -1.78092"/>
    <general name="right_wrist_pitch" class="/" joint="right_wrist_pitch_joint" forcerange="-2.82559 2.82559" gainprm="71.4775" biasprm="0 -71.4775 -1.78092"/>
    <general name="right_jaw" class="/" joint="right_jaw_joint" forcerange="-3.68263 3.68263" gainprm="71.4775" biasprm="0 -71.4775 -1.78092"/>
    <general name="head_roll" class="/" joint="head_roll_joint" forcerange="-3.18958 3.18958" gainprm="71.4775" biasprm="0 -71.4775 -1.78092"/>
    <general name="head_pitch" class="/" joint="head_pitch_joint" forcerange="-3.98133 3.98133" gainprm="71.4775" biasprm="0 -71.4775 -1.78092"/>
    <general name="head_yaw" class="/" joint="head_yaw_joint" forcerange="-2.65056 2.65056" gainprm="71.4775" biasprm="0 -71.4775 -1.78092"/>
  </actuator>

  <sensor>
    <gyro site="imu" name="imu_angular_velocity"/>
    <velocimeter site="imu" name="imu_linear_velocity"/>
    <framelinvel objtype="site" objname="left_foot" name="left_foot_global_linear_velocity"/>
    <framelinvel objtype="site" objname="right_foot" name="right_foot_global_linear_velocity"/>
  </sensor>

  <keyframe>
    <key name="home" qpos="0 0 0.8665 1 0 0 0 0 0 -0.4 0.8 -0.4 0 0 0 0.4 -0.8 0.4 0 0 0 0 0 -0.2 0 -0.785 0 0 0 0 0 0.2 0 0.785 0 0 0 0 0 0 0"/>
  </keyframe>
</mujoco>
