<mujoco model="GR1T2_jaw">
  <compiler angle="radian" assetdir="assets" balanceinertia="true" inertiafromgeom="false"/>

  <option timestep="0.005" density="1.2" viscosity="2e-05"/>

  <size nkey="1"/>

  <visual>
    <quality shadowsize="8192"/>
    <map shadowclip="0.5"/>
  </visual>

  <default>
    <default class="/">
      <joint armature="0.1" damping="0.01" frictionloss="0.1"/>
      <geom contype="0" conaffinity="0" group="1" solref="-1000 -80"/>
      <site size="0.01 0.005 0.005" group="5"/>
      <general forcelimited="true" biastype="affine" gainprm="80" biasprm="0 -80 -2"/>
      <default class="visual">
        <geom type="mesh" density="0" rgba="0.18 0.18 0.18 1"/>
      </default>
      <default class="collision">
        <geom group="3"/>
      </default>
      <default class="foot">
        <geom size="0.126 0.045 0.01" type="box" condim="6" group="4" priority="1" solimp="0.015 1 0.01"/>
      </default>
      <default class="reward_collision_sphere">
        <geom group="5" rgba="1 0 0 1"/>
      </default>
    </default>
  </default>

  <asset>
    <texture type="skybox" colorspace="auto" name="//unnamed_texture_0" builtin="gradient" rgb1="0.95 0.95 0.95" rgb2="0.95 0.95 0.95" width="100" height="600"/>
    <texture type="2d" colorspace="auto" name="texplane" builtin="checker" rgb1="0.345 0.575 0.748" rgb2="0.345 0.575 0.748" markrgb="1 1 1" width="512" height="512"/>
    <material name="MatPlane" class="/" texture="texplane" texuniform="true" texrepeat="2 2" specular="0.9"/>
    <mesh name="base_link" class="/" file="base_link.STL"/>
    <mesh name="left_thigh_roll_link" class="/" file="left_thigh_roll_link.STL"/>
    <mesh name="left_thigh_yaw_link" class="/" file="left_thigh_yaw_link.STL"/>
    <mesh name="left_thigh_pitch_link" class="/" file="left_thigh_pitch_link.STL"/>
    <mesh name="left_shank_pitch_link" class="/" file="left_shank_pitch_link.STL"/>
    <mesh name="left_foot_pitch_link" class="/" file="left_foot_pitch_link.STL"/>
    <mesh name="left_foot_roll_link" class="/" file="left_foot_roll_link.STL"/>
    <mesh name="right_thigh_roll_link" class="/" file="right_thigh_roll_link.STL"/>
    <mesh name="right_thigh_yaw_link" class="/" file="right_thigh_yaw_link.STL"/>
    <mesh name="right_thigh_pitch_link" class="/" file="right_thigh_pitch_link.STL"/>
    <mesh name="right_shank_pitch_link" class="/" file="right_shank_pitch_link.STL"/>
    <mesh name="right_foot_pitch_link" class="/" file="right_foot_pitch_link.STL"/>
    <mesh name="right_foot_roll_link" class="/" file="right_foot_roll_link.STL"/>
    <mesh name="waist_yaw_link" class="/" file="waist_yaw_link.STL"/>
    <mesh name="waist_pitch_link" class="/" file="waist_pitch_link.STL"/>
    <mesh name="waist_roll_link" class="/" file="waist_roll_link.STL"/>
    <mesh name="torso_link" class="/" file="torso_link.STL"/>
    <mesh name="left_upper_arm_pitch_link" class="/" file="left_upper_arm_pitch_link.STL"/>
    <mesh name="left_upper_arm_roll_link" class="/" file="left_upper_arm_roll_link.STL"/>
    <mesh name="left_upper_arm_yaw_link" class="/" file="left_upper_arm_yaw_link.STL"/>
    <mesh name="left_lower_arm_pitch_link" class="/" file="left_lower_arm_pitch_link.STL"/>
    <mesh name="left_hand_yaw_link" class="/" file="left_hand_yaw_link.STL"/>
    <mesh name="left_hand_roll_link" class="/" file="left_hand_roll_link.STL"/>
    <mesh name="left_hand_pitch" class="/" file="left_hand_pitch.STL"/>
    <mesh name="left_jaw_link" class="/" file="left_jaw_link.STL"/>
    <mesh name="right_upper_arm_pitch_link" class="/" file="right_upper_arm_pitch_link.STL"/>
    <mesh name="right_upper_arm_roll_link" class="/" file="right_upper_arm_roll_link.STL"/>
    <mesh name="right_upper_arm_yaw_link" class="/" file="right_upper_arm_yaw_link.STL"/>
    <mesh name="right_lower_arm_pitch_link" class="/" file="right_lower_arm_pitch_link.STL"/>
    <mesh name="right_hand_yaw_link" class="/" file="right_hand_yaw_link.STL"/>
    <mesh name="right_hand_roll_link" class="/" file="right_hand_roll_link.STL"/>
    <mesh name="right_hand_pitch" class="/" file="right_hand_pitch.STL"/>
    <mesh name="right_jaw_link" class="/" file="right_jaw_link.STL"/>
    <mesh name="head_roll_link" class="/" file="head_roll_link.STL"/>
    <mesh name="head_pitch_link" class="/" file="head_pitch_link.STL"/>
    <mesh name="head_yaw_link" class="/" file="head_yaw_link.STL"/>
    <mesh name="imu_link" class="/" file="imu_link.STL"/>
  </asset>

  <worldbody>
    <geom name="floor" class="/" size="100 100 0.125" type="plane" group="0" material="MatPlane"/>
    <light name="toplight_shadow" class="/" pos="0 0 5" dir="0.0990148 0.0990148 -0.990148" type="directional" ambient="0.04 0.04 0.04" diffuse="0.55 0.55 0.55" specular="0.12 0.12 0.12"/>
    <light name="toplight_fill" class="/" pos="0 0 5" dir="0.0990148 0.0990148 -0.990148" type="directional" castshadow="false" ambient="0.04 0.04 0.04" diffuse="0.3 0.3 0.3" specular="0.08 0.08 0.08"/>
    <body name="trunk" pos="-0.00137684 -0.00271022 -0.00143239" quat="0.999999 0.0012648 -0.000259752 0.000436965">
      <inertial pos="-0.0490843 -0.000973648 -0.00907259" quat="0.999907 0.00637478 0.0120364 -0.000846737" mass="2.00066" diaginertia="0.0157255 0.00303505 0.0165922"/>
      <joint name="//unnamed_joint_0" type="free"/>
      <geom name="//unnamed_geom_1" class="visual" rgba="0.12 0.12 0.12 1" mesh="base_link"/>
      <geom name="base_link.STL" class="collision" size="0.0970838 0.0543747" pos="-0.0348759 0.000273354 0.00756976" quat="0.706838 -0.707359 0.00477667 0" type="cylinder" rgba="0.752941 0.752941 0.752941 1"/>
      <geom name="//unnamed_geom_3" class="visual" pos="0 0 -0.0489851" quat="1 0 0 0" rgba="0.12 0.12 0.12 1" mesh="imu_link"/>
      <geom name="//unnamed_geom_4" class="reward_collision_sphere" size="0.0634566" pos="0 0.0738712 0.0821898"/>
      <geom name="//unnamed_geom_5" class="reward_collision_sphere" size="0.0634566" pos="0 -0.0738712 0.0821898"/>
      <site name="imu" class="/" pos="0.00517661 -0.000340625 -0.0512732" size="0.00793207"/>
      <camera name="track" class="/" pos="0 -1.47742 0" quat="0.707107 0.707107 0 0" mode="trackcom"/>
      <body name="left_thigh_roll_link" pos="-0.0299921 0.0784494 -0.0211638" quat="1 0.000193822 0.000306954 0.000369419">
        <inertial pos="-0.0028979 0.00185435 0.00304938" quat="-0.023709 0.696864 -0.033502 0.716028" mass="0.725493" diaginertia="0.000911325 0.000543833 0.00059447"/>
        <joint name="left_hip_roll_joint" class="/" pos="0 0 0" axis="-0.99987 0.0160186 0.00188315" range="-0.780677 0.0868664" armature="0.0859677" damping="0.0186793" frictionloss="0.0769887"/>
        <geom name="//unnamed_geom_6" class="visual" mesh="left_thigh_roll_link"/>
        <body name="left_thigh_yaw_link" pos="0.027602 0.000745251 -0.000250465" quat="0.999999 -0.000874967 0.000719393 -0.000634687">
          <inertial pos="0.000187784 0.0260358 -0.0933459" quat="0.570822 0.0937239 -0.195381 0.791962" mass="1.68994" diaginertia="0.00902546 0.00448972 0.00332937"/>
          <joint name="left_hip_yaw_joint" class="/" pos="0 0 0" axis="-0.00117781 -0.00487962 -0.999987" range="-0.654282 0.668012" armature="0.0853653" damping="0" frictionloss="0.0766295"/>
          <geom name="//unnamed_geom_7" class="visual" mesh="left_thigh_yaw_link"/>
          <body name="left_thigh_pitch_link" pos="-0.00322313 0.0183073 -0.1159" quat="1 -0.000330654 -0.000567562 0.000349185">
            <inertial pos="0.00274177 -0.0220564 -0.0506856" quat="0.999834 -0.0137824 -0.00890036 0.00790832" mass="4.21434" diaginertia="0.0336148 0.0198712 0.0111167"/>
            <joint name="left_hip_pitch_joint" class="/" pos="0 0 0" axis="0.00357338 0.999993 -0.00113766" range="-1.76039 0.645526" armature="0.0794115" damping="0.00942116" frictionloss="0.0872694"/>
            <geom name="//unnamed_geom_8" class="visual" mesh="left_thigh_pitch_link"/>
            <geom name="left_thigh_pitch_link.STL" class="collision" size="0.065043 0.0990827" pos="0.000573349 -0.0221614 -0.137303" type="cylinder" rgba="0.752941 0.752941 0.752941 1"/>
            <geom name="//unnamed_geom_10" class="reward_collision_sphere" size="0.0793207" pos="0 -0.00738712 -0.0410949"/>
            <body name="left_shank_pitch_link" pos="-0.00201035 -0.0146422 -0.294933" quat="0.999999 -0.000992495 -0.000246008 -8.74442e-05">
              <inertial pos="-0.00109078 -0.00251966 -0.0931156" quat="0.999611 -0.0112058 0.00683697 -0.0246264" mass="0.889025" diaginertia="0.00406071 0.00250519 0.000477558"/>
              <joint name="left_knee_pitch_joint" class="/" pos="0 0 0" axis="-0.0109046 0.999938 0.00218857" stiffness="0.000757626" range="-0.148621 1.867" armature="0.0793911" damping="0.00488874" frictionloss="0.079228"/>
              <geom name="//unnamed_geom_11" class="visual" mesh="left_shank_pitch_link"/>
              <geom name="left_shank_pitch_link.STL" class="collision" size="0.0422949 0.071694" pos="-1.35875e-05 -0.000622399 -0.143578" quat="0.00125538 -0.202712 0.979238 0" type="cylinder" rgba="0.752941 0.752941 0.752941 1"/>
              <geom name="//unnamed_geom_13" class="reward_collision_sphere" size="0.0396603"/>
              <geom name="//unnamed_geom_14" class="reward_collision_sphere" size="0.0475924" pos="0 0 -0.0904088"/>
              <body name="left_foot_pitch_link" pos="-0.00335767 -0.00391049 -0.278967" quat="1 0.000262783 0.000446156 -0.000244351">
                <inertial pos="0.00162713 0.00142733 2.27493e-05" quat="-0.00190012 0.708002 0.00251482 0.706204" mass="0.028245" diaginertia="2.39683e-06 1.27382e-06 1.91085e-06"/>
                <joint name="left_ankle_pitch_joint" class="/" pos="0 0 0" axis="0.0149066 0.999886 -0.00224702" range="-1.05394 0.536254" armature="0.075708" damping="0.00142693" frictionloss="0.0781241"/>
                <geom name="//unnamed_geom_15" class="visual" mesh="left_foot_pitch_link"/>
                <body name="left_foot_roll_link" pos="0.00244877 -0.000818732 0.00399399" quat="1 7.58508e-05 1.40264e-05 4.55635e-05">
                  <inertial pos="0.0335243 -0.000993554 -0.0324178" quat="-0.000741274 0.725105 -0.000985244 0.688637" mass="0.546125" diaginertia="0.00206623 0.00111395 0.000295066"/>
                  <joint name="left_ankle_roll_joint" class="/" pos="0 0 0" axis="-0.99984 -0.0134386 -0.0118119" range="-0.398978 0.50382" armature="0.0773171" damping="0.00547029" frictionloss="0.069334"/>
                  <geom name="//unnamed_geom_16" class="visual" mesh="left_foot_roll_link"/>
                  <geom name="left_foot" class="foot" size="0.142445 0.0419372 0.00874357" pos="0.0368555 0 -0.0365745"/>
                  <geom name="//unnamed_geom_18" class="reward_collision_sphere" size="0.0396603" pos="0 0 -0.024657"/>
                  <geom name="//unnamed_geom_19" class="reward_collision_sphere" size="0.0396603" pos="0.0982813 0 -0.024657"/>
                  <site name="left_foot" class="foot" pos="0.0368555 0 -0.0365745" size="0.00793207"/>
                </body>
              </body>
            </body>
          </body>
        </body>
      </body>
      <body name="right_thigh_roll_link" pos="-0.0289383 -0.0801519 -0.0242542" quat="1 0.000239094 0.000598087 -0.000173231">
        <inertial pos="0.000625125 -0.00351373 0.00187878" quat="0.0142917 0.707358 0.0208682 0.706403" mass="0.729427" diaginertia="0.000966053 0.000552 0.000592558"/>
        <joint name="right_hip_roll_joint" class="/" pos="0 0 0" axis="-0.999926 -0.00310248 -0.0117871" range="-0.109542 0.822468" armature="0.0767298" damping="0.0133371" frictionloss="0.0894849"/>
        <geom name="//unnamed_geom_20" class="visual" mesh="right_thigh_roll_link"/>
        <body name="right_thigh_yaw_link" pos="0.0292452 -0.00367427 0.000621497" quat="1 0.000657893 -0.000299957 -0.000111969">
          <inertial pos="-0.00288313 -0.0293825 -0.0899683" quat="0.690556 -0.145884 0.149876 0.692378" mass="1.77788" diaginertia="0.00925879 0.004427 0.00348381"/>
          <joint name="right_hip_yaw_joint" class="/" pos="0 0 0" axis="-0.0141409 -0.00408401 -0.999892" range="-0.759239 0.684279" armature="0.0774621" damping="0.0101736" frictionloss="0.0803123"/>
          <geom name="//unnamed_geom_21" class="visual" mesh="right_thigh_yaw_link"/>
          <body name="right_thigh_pitch_link" pos="0.00200278 -0.0191896 -0.112914" quat="1 0.000614253 -0.000482868 0.000167734">
            <inertial pos="0.000302921 0.020893 -0.0527769" quat="0.999792 -0.0161194 -0.00920359 0.00850496" mass="4.18555" diaginertia="0.0340655 0.0193788 0.0103708"/>
            <joint name="right_hip_pitch_joint" class="/" pos="0 0 0" axis="-0.00415224 -0.999779 -0.0206111" range="-0.691502 1.74102" armature="0.0875862" damping="0.0296314" frictionloss="0.0814261"/>
            <geom name="//unnamed_geom_22" class="visual" mesh="right_thigh_pitch_link"/>
            <geom name="right_thigh_pitch_link.STL" class="collision" size="0.065043 0.0990803" pos="-0.00173898 0.0221614 -0.137303" quat="0.999971 0.00269833 0.00706272 0" type="cylinder" rgba="0.752941 0.752941 0.752941 1"/>
            <geom name="//unnamed_geom_24" class="reward_collision_sphere" size="0.0793207" pos="0 0.00738712 -0.0410949"/>
            <body name="right_shank_pitch_link" pos="-0.000413163 0.0131752 -0.295696" quat="1 0.000464861 0.000371782 6.54239e-05">
              <inertial pos="0.00099172 -0.00202662 -0.0972297" quat="0.999567 0.00289623 -0.00677288 0.0285028" mass="0.917962" diaginertia="0.00396467 0.00228722 0.000454538"/>
              <joint name="right_knee_pitch_joint" class="/" pos="0 0 0" axis="-0.00747908 -0.999967 0.0030426" range="-1.9337 0.0758742" armature="0.0749314" damping="0.0240149" frictionloss="0.068589"/>
              <geom name="//unnamed_geom_25" class="visual" mesh="right_shank_pitch_link"/>
              <geom name="right_shank_pitch_link.STL" class="collision" size="0.0422947 0.0716933" pos="-1.35875e-05 -0.000622407 -0.143585" type="cylinder" rgba="0.752941 0.752941 0.752941 1"/>
              <geom name="//unnamed_geom_27" class="reward_collision_sphere" size="0.0396603"/>
              <geom name="//unnamed_geom_28" class="reward_collision_sphere" size="0.0475924" pos="0 0 -0.0904088"/>
              <body name="right_foot_pitch_link" pos="0.00215125 0.000660462 -0.279893" quat="1 -0.000759093 0.000594934 -0.000108262">
                <inertial pos="-0.000388312 -0.000858314 0.000336885" quat="-0.000384531 0.707669 -0.000457962 0.706543" mass="0.0294126" diaginertia="2.425e-06 1.23645e-06 2.00077e-06"/>
                <joint name="right_ankle_pitch_joint" class="/" pos="0 0 0" axis="-0.000138895 -1 -0.000139888" stiffness="0.00134053" range="-0.51468 1.03017" armature="0.0776002" damping="0.000104786" frictionloss="0.088789"/>
                <geom name="//unnamed_geom_29" class="visual" mesh="right_foot_pitch_link"/>
                <body name="right_foot_roll_link" pos="0.000314531 -1.71586e-05 -0.000791599" quat="1 -2.81838e-05 -0.000119637 -4.40143e-05">
                  <inertial pos="0.0302381 0.001518 -0.0341554" quat="0.00105999 0.724465 0.00105812 0.68931" mass="0.54137" diaginertia="0.00204669 0.00115798 0.000288021"/>
                  <joint name="right_ankle_roll_joint" class="/" pos="0 0 0" axis="-1 0.000565922 0.000582872" range="-0.49785 0.397748" armature="0.0752813" damping="0.00735985" frictionloss="0.0685616"/>
                  <geom name="//unnamed_geom_30" class="visual" mesh="right_foot_roll_link"/>
                  <geom name="right_foot" class="foot" size="0.146763 0.03453 0.00835196" pos="0.0368555 0 -0.0365745"/>
                  <geom name="//unnamed_geom_32" class="reward_collision_sphere" size="0.0396603" pos="0 0 -0.024657"/>
                  <geom name="//unnamed_geom_33" class="reward_collision_sphere" size="0.0396603" pos="0.0982813 0 -0.024657"/>
                  <site name="right_foot" class="foot" pos="0.0368555 0 -0.0365745" size="0.00793207"/>
                </body>
              </body>
            </body>
          </body>
        </body>
      </body>
      <body name="waist_yaw_link" pos="0.00238011 0.00179683 0.000851213" quat="1 7.5297e-06 0.000281726 -1.61319e-05">
        <inertial pos="-0.0048122 -0.00512831 0.0448773" quat="0.978487 0.19602 -0.030627 0.0565779" mass="0.802758" diaginertia="0.00127828 0.000709753 0.000754119"/>
        <joint name="waist_yaw_joint" class="/" pos="0 0 0" axis="0.00450002 0.00982807 0.999942" range="-1.0469 0.983108" armature="0.0917457" damping="0.0145423" frictionloss="0.0811174"/>
        <geom name="//unnamed_geom_34" class="visual" rgba="0.12 0.12 0.12 1" mesh="waist_yaw_link"/>
        <body name="waist_pitch_link" pos="0.000401247 0.00125287 0.0724022" quat="1 -9.10793e-05 7.76808e-06 0.000109474">
          <inertial pos="0.00406217 -0.00308921 0.030835" quat="0.997801 -0.0357926 0.0555935 0.00453261" mass="0.753441" diaginertia="0.00167946 0.00101258 0.000718306"/>
          <joint name="waist_pitch_joint" class="/" pos="0 0 0" axis="0.0098948 -0.999812 0.0167048" range="-1.23317 0.487164" armature="0.0802801" damping="0.0160514" frictionloss="0.0841044"/>
          <geom name="//unnamed_geom_35" class="visual" rgba="0.12 0.12 0.12 1" mesh="waist_pitch_link"/>
          <body name="waist_roll_link" pos="0.00948567 0.000504301 0.0696807" quat="1 -0.000133371 -5.86746e-05 0.000115655">
            <inertial pos="-0.0138911 -0.00221941 0.121431" quat="0.998925 -0.00790492 -0.0456799 0.000385653" mass="3.25865" diaginertia="0.0224471 0.0131062 0.0137977"/>
            <joint name="waist_roll_joint" class="/" pos="0 0 0" axis="-0.999995 -0.000759883 -0.00317971" range="-0.765527 0.699946" armature="0.0822067" damping="0.0220639" frictionloss="0.0806866"/>
            <geom name="//unnamed_geom_36" class="visual" rgba="0.12 0.12 0.12 1" mesh="waist_roll_link"/>
            <geom name="//unnamed_geom_37" class="visual" pos="-0.00184277 0.000424338 0.131791" quat="1 0 0 0" mesh="torso_link"/>
            <geom name="torso_link.STL" class="collision" size="0.124872 0.0239493" pos="-0.0147962 0.00426222 0.1215" type="cylinder" rgba="0.752941 0.752941 0.752941 1"/>
            <geom name="//unnamed_geom_39" class="reward_collision_sphere" size="0.103117" pos="0 0 0.16438"/>
            <body name="left_upper_arm_pitch_link" pos="0.000735969 0.0709661 0.167656" quat="0.976643 0.214868 -0.000176565 0.000350221">
              <inertial pos="0.00233325 0.0388961 0.000448986" quat="0.70235 0.709908 0.00794589 -0.0516992" mass="0.418262" diaginertia="0.000765376 0.000441668 0.000189541"/>
              <joint name="left_shoulder_pitch_joint" class="/" pos="0 0 0" axis="-0.0114285 0.999934 -0.000880591" range="-2.79858 1.91933" armature="0.0838472" damping="0" frictionloss="0.0764121"/>
              <geom name="//unnamed_geom_40" class="visual" mesh="left_upper_arm_pitch_link"/>
              <body name="left_upper_arm_roll_link" pos="0.00206091 0.0707018 -0.00162821" quat="0.976504 -0.215499 -0.000365238 0.000680303">
                <inertial pos="0.0065263 0.0132374 -0.0199176" quat="0.888948 0.269673 0.125511 -0.348275" mass="0.292094" diaginertia="0.000376225 0.000215623 0.000128104"/>
                <joint name="left_shoulder_roll_joint" class="/" pos="0 0 0" axis="-0.999993 0.0036478 -0.000249739" range="-2.52697 0.568302" armature="0.0803567" damping="0" frictionloss="0.079311"/>
                <geom name="//unnamed_geom_41" class="visual" mesh="left_upper_arm_roll_link"/>
                <body name="left_upper_arm_yaw_link" pos="0.00276056 0.029365 -0.0591506" quat="1 1.72031e-06 2.14521e-05 3.27558e-06">
                  <inertial pos="0.00259783 0.000825847 -0.0692903" quat="0.999926 0.00821099 0.000842911 -0.00894374" mass="0.268194" diaginertia="0.0013112 0.00077205 9.81218e-05"/>
                  <joint name="left_shoulder_yaw_joint" class="/" pos="0 0 0" axis="-0.00119614 -0.0147565 0.99989" range="-2.94721 2.97308" armature="0.0821183" damping="0.00146028" frictionloss="0.0728544"/>
                  <geom name="//unnamed_geom_42" class="visual" mesh="left_upper_arm_yaw_link"/>
                  <geom name="left_upper_arm_yaw_link.STL" class="collision" size="0.0287404 0.0673766" pos="3.2339e-05 -0.000660622 -0.0652094" quat="0.00803418 -0.995528 0.0941277 0" type="cylinder" rgba="0.752941 0.752941 0.752941 1"/>
                  <body name="left_lower_arm_pitch_link" pos="-0.00127921 -0.00189941 -0.146166" quat="0.999999 0.000570386 -0.000159695 0.00105847">
                    <inertial pos="-0.000656139 0.00492057 -0.0199483" quat="0.702108 -0.0936055 0.0890765 0.700248" mass="0.159006" diaginertia="0.000103645 6.25094e-05 3.45363e-05"/>
                    <joint name="left_elbow_pitch_joint" class="/" pos="0 0 0" axis="0.00270678 0.999989 -0.00380205" range="-2.29327 2.30708" armature="0.0810765" damping="0.0141409" frictionloss="0.0796304"/>
                    <geom name="//unnamed_geom_44" class="visual" mesh="left_lower_arm_pitch_link"/>
                    <body name="left_hand_yaw_link" pos="0.000271116 -0.0024868 -0.0493192" quat="0.999999 -0.0008367 -0.00082595 -0.000732057">
                      <inertial pos="4.45591e-05 0.000552659 -0.0590291" quat="0.999928 -0.00473466 -0.000339853 0.0109886" mass="0.494332" diaginertia="0.000993051 0.000540297 0.000186382"/>
                      <joint name="left_wrist_yaw_joint" class="/" pos="0 0 0" axis="-0.00103367 0.000772997 0.999999" range="-3.02001 2.96555" armature="0.0856568" damping="0.00258814" frictionloss="0.0693003"/>
                      <geom name="//unnamed_geom_45" class="visual" mesh="left_hand_yaw_link"/>
                      <geom name="left_hand_yaw_link.STL" class="collision" size="0.0329751 0.0552022" pos="0.000892108 -0.00113844 -0.0624995" type="cylinder" rgba="0.752941 0.752941 0.752941 1"/>
                      <geom name="//unnamed_geom_47" class="reward_collision_sphere" size="0.0396603"/>
                      <body name="left_hand_roll_link" pos="0.00150631 0.00249544 -0.15687" quat="1 0.000128761 -8.66327e-05 -1.29997e-05">
                        <inertial pos="-0.00282383 -0.000510126 0.000594822" quat="0.488555 0.503286 0.501826 0.506151" mass="0.00249757" diaginertia="1.28698e-07 7.71387e-08 2.59116e-08"/>
                        <joint name="left_wrist_roll_joint" class="/" pos="0 0 0" axis="-0.999996 0.0027741 -9.29168e-05" range="-0.918082 0.841482" armature="0.0781049" damping="0.0194858" frictionloss="0.0685924"/>
                        <geom name="//unnamed_geom_48" class="visual" mesh="left_hand_roll_link"/>
                        <body name="left_hand_pitch_link" pos="0.00294954 -0.00238221 -0.000491503" quat="0.999999 0.000437038 -0.0010753 -0.000169543">
                          <inertial pos="0.000512175 -0.0112834 -0.0436004" quat="0.722604 -0.134067 0.118293 0.66774" mass="0.107625" diaginertia="0.000101248 5.89429e-05 3.50471e-05"/>
                          <joint name="left_wrist_pitch_joint" class="/" pos="0 0 0" axis="-0.00359161 0.999947 0.00963986" range="-0.594497 0.603149" armature="0.0916587" damping="0.00278362" frictionloss="0.0818568"/>
                          <geom name="//unnamed_geom_49" class="visual" mesh="left_hand_pitch"/>
                          <body name="left_jaw_link" pos="0.00194556 -0.000325661 -0.049257" quat="1 -5.66587e-05 -2.94501e-05 -6.77219e-06">
                            <inertial pos="0.00259517 0.00241736 -0.0264237" quat="0.707443 -0.0242553 0.033664 0.705552" mass="0.0353901" diaginertia="2.81996e-05 1.24118e-05 1.22751e-05"/>
                            <joint name="left_jaw_joint" class="/" pos="0 0 0" axis="-0.999998 -0.00172387 0.000849528" range="-1.03145 -0.00632386" armature="0.0698366" damping="0" frictionloss="0.0884149"/>
                            <geom name="//unnamed_geom_50" class="visual" mesh="left_jaw_link"/>
                            <geom name="//unnamed_geom_51" class="collision" size="0.0285555"/>
                            <geom name="//unnamed_geom_52" class="reward_collision_sphere" size="0.0396603" pos="0 0 -0.016438"/>
                          </body>
                        </body>
                      </body>
                    </body>
                  </body>
                </body>
              </body>
            </body>
            <body name="right_upper_arm_pitch_link" pos="0.00106251 -0.0771006 0.167655" quat="0.976592 -0.215098 0.000276855 -0.000618767">
              <inertial pos="0.00425059 -0.0406279 -0.00189698" quat="0.708111 0.705149 0.0299257 0.0211606" mass="0.411824" diaginertia="0.000763196 0.00044133 0.000185848"/>
              <joint name="right_shoulder_pitch_joint" class="/" pos="0 0 0" axis="0.00641598 -0.999961 0.00613281" stiffness="0.00132753" range="-1.89834 2.80839" armature="0.0794002" damping="0" frictionloss="0.0834896"/>
              <geom name="//unnamed_geom_53" class="visual" mesh="right_upper_arm_pitch_link"/>
              <body name="right_upper_arm_roll_link" pos="0.0026943 -0.0729917 -0.00030593" quat="0.976726 0.214491 -6.44048e-05 0.000543396">
                <inertial pos="0.00336644 -0.0144275 -0.0199437" quat="0.888676 -0.268509 0.124958 0.350062" mass="0.324179" diaginertia="0.000404744 0.000220205 0.000131306"/>
                <joint name="right_shoulder_roll_joint" class="/" pos="0 0 0" axis="-0.999866 0.0163822 0.000771994" range="-0.539342 2.48759" armature="0.0710343" damping="0.00380131" frictionloss="0.0782635"/>
                <geom name="//unnamed_geom_54" class="visual" mesh="right_upper_arm_roll_link"/>
                <body name="right_upper_arm_yaw_link" pos="0.00185061 -0.0303398 -0.0606239" quat="1 0.000164484 -0.000434828 -0.000417141">
                  <inertial pos="-0.00148772 -0.000922054 -0.0696257" quat="0.999962 -0.00712441 0.00354544 -0.00346186" mass="0.287161" diaginertia="0.00135761 0.000808132 0.000100196"/>
                  <joint name="right_shoulder_yaw_joint" class="/" pos="0 0 0" axis="0.00437147 0.0145768 0.999884" range="-3.01265 3.02644" armature="0.0803172" damping="0.00196244" frictionloss="0.0771254"/>
                  <geom name="//unnamed_geom_55" class="visual" mesh="right_upper_arm_yaw_link"/>
                  <geom name="right_upper_arm_yaw_link.STL" class="collision" size="0.0287404 0.0673766" pos="3.2339e-05 0.000660622 -0.0652094" type="cylinder" rgba="0.752941 0.752941 0.752941 1"/>
                  <body name="right_lower_arm_pitch_link" pos="0.000635546 -0.000539328 -0.14665" quat="0.999999 -0.00110347 -0.000588221 6.31565e-05">
                    <inertial pos="-0.00135923 -0.00690151 -0.019568" quat="0.701044 0.0921397 -0.091464 0.701201" mass="0.163091" diaginertia="0.000113551 6.80584e-05 3.74192e-05"/>
                    <joint name="right_elbow_pitch_joint" class="/" pos="0 0 0" axis="-0.00119571 -0.999998 0.00151943" range="-2.26818 2.26355" armature="0.0790302" damping="0.00905651" frictionloss="0.0684838"/>
                    <geom name="//unnamed_geom_57" class="visual" mesh="right_lower_arm_pitch_link"/>
                    <body name="right_hand_yaw_link" pos="0.00250687 0.00241987 -0.0490002" quat="0.999999 -0.00104812 -0.000763574 -0.000153261">
                      <inertial pos="0.0002276 -0.00128446 -0.060453" quat="0.999713 0.000725993 0.00138883 0.0239133" mass="0.494419" diaginertia="0.000922919 0.00053739 0.000183225"/>
                      <joint name="right_wrist_yaw_joint" class="/" pos="0 0 0" axis="0.00049525 8.33763e-05 1" range="-2.99185 2.97185" armature="0.081805" damping="0.0106904" frictionloss="0.0789876"/>
                      <geom name="//unnamed_geom_58" class="visual" mesh="right_hand_yaw_link"/>
                      <geom name="right_hand_yaw_link.STL" class="collision" size="0.0329751 0.0552022" pos="0.000892108 0.000473598 -0.0624995" type="cylinder" rgba="0.752941 0.752941 0.752941 1"/>
                      <geom name="//unnamed_geom_60" class="reward_collision_sphere" size="0.0396603"/>
                      <body name="right_hand_roll_link" pos="-0.0022578 -0.000461337 -0.155846" quat="1 0.000139192 -0.00010392 8.80196e-06">
                        <inertial pos="0.00207326 -0.000627222 0.000367721" quat="0.500572 0.500262 0.499516 0.499649" mass="0.00252653" diaginertia="1.26477e-07 7.80285e-08 2.72658e-08"/>
                        <joint name="right_wrist_roll_joint" class="/" pos="0 0 0" axis="-1 -0.000938197 -3.42567e-05" range="-0.873742 0.958479" armature="0.0705649" damping="0.0195096" frictionloss="0.0770146"/>
                        <geom name="//unnamed_geom_61" class="visual" mesh="right_hand_roll_link"/>
                        <body name="right_hand_pitch_link" pos="0.00280153 -0.000868175 0.000475939" quat="1 0.000377087 -0.000243843 -0.000133804">
                          <inertial pos="0.00067586 0.0069639 -0.0411878" quat="0.723302 0.121475 -0.114721 0.670013" mass="0.106229" diaginertia="0.000103992 5.77619e-05 3.31635e-05"/>
                          <joint name="right_wrist_pitch_joint" class="/" pos="0 0 0" axis="-0.00806653 -0.999966 0.00171757" range="-0.605096 0.669547" armature="0.080083" damping="0.00661552" frictionloss="0.0806192"/>
                          <geom name="//unnamed_geom_62" class="visual" mesh="right_hand_pitch"/>
                          <body name="right_jaw_link" pos="0.0025455 0.00241289 -0.0500378" quat="1 0.000200322 -0.000143172 -9.76473e-05">
                            <inertial pos="-0.00212327 -0.00589012 -0.0299287" quat="0.707687 0.0215587 -0.0309918 0.705516" mass="0.0348573" diaginertia="2.9714e-05 1.24158e-05 1.18151e-05"/>
                            <joint name="right_jaw_joint" class="/" pos="0 0 0" axis="-0.999975 -0.00675191 0.00230331" range="0.0106493 1.05436" armature="0.0823953" damping="0.000265242" frictionloss="0.0796166"/>
                            <geom name="//unnamed_geom_63" class="visual" mesh="right_jaw_link"/>
                            <geom name="//unnamed_geom_64" class="collision" size="0.0285555"/>
                            <geom name="//unnamed_geom_65" class="reward_collision_sphere" size="0.0396603" pos="0 0 -0.016438"/>
                          </body>
                        </body>
                      </body>
                    </body>
                  </body>
                </body>
              </body>
            </body>
            <body name="head_roll_link" pos="-0.00259702 0.00124388 0.252405" quat="1 0.000204374 0.000210195 -1.39645e-05">
              <inertial pos="0.00276415 -0.00298018 0.00262495" quat="0.00367262 0.714896 0.00680906 0.699188" mass="0.00501884" diaginertia="2.65051e-07 9.69031e-08 1.6237e-07"/>
              <joint name="head_roll_joint" class="/" pos="0 0 0" axis="-0.999981 0.00105093 0.00606023" range="-0.358935 0.355841" armature="0.0898714" damping="0.0122601" frictionloss="0.0751793"/>
              <geom name="//unnamed_geom_66" class="visual" mesh="head_roll_link"/>
              <body name="head_pitch_link" pos="-0.00109194 -0.000367552 0.00206781" quat="1 -0.000421555 -2.08596e-06 -0.000258327">
                <inertial pos="-0.000316209 -0.000813387 0.0142018" quat="0.665972 0.664426 0.240323 -0.239301" mass="0.0289058" diaginertia="9.52089e-06 5.21226e-06 6.18209e-06"/>
                <joint name="head_pitch_joint" class="/" pos="0 0 0" axis="0.00121692 -0.999999 0.00110736" range="-0.859925 0.866818" armature="0.0892139" damping="0.00917128" frictionloss="0.0806853"/>
                <geom name="//unnamed_geom_67" class="visual" mesh="head_pitch_link"/>
                <body name="head_yaw_link" pos="0.000661077 0.000617467 0.0466719" quat="1 2.77589e-05 -3.76258e-05 -1.99379e-05">
                  <inertial pos="0.0219685 -0.00496971 0.0774727" quat="0.704458 -0.139553 -0.153137 0.678832" mass="0.785328" diaginertia="0.00380579 0.00173299 0.00198677"/>
                  <joint name="head_yaw_joint" class="/" pos="0 0 0" axis="0.00222257 0.00146557 0.999996" range="-2.70732 2.73396" armature="0.081571" damping="0.00762714" frictionloss="0.0792581"/>
                  <geom name="//unnamed_geom_68" class="visual" rgba="0.12 0.12 0.12 1" mesh="head_yaw_link"/>
                  <geom name="head_yaw_link.STL" class="collision" size="0.0941434" pos="0.0149724 -0.000650084 0.0769463" rgba="0.752941 0.752941 0.752941 1"/>
                  <geom name="//unnamed_geom_70" class="reward_collision_sphere" size="0.0793207" pos="0.0245703 0 0.0821898"/>
                  <camera name="ego_camera" class="/" pos="0.0900912 0 0.0904088" quat="-0.5 -0.5 0.5 0.5"/>
                </body>
              </body>
            </body>
          </body>
        </body>
      </body>
    </body>
  </worldbody>

  <contact>
    <pair class="/" geom1="floor" geom2="left_foot" name="//unnamed_contact_0"/>
    <pair class="/" geom1="floor" geom2="right_foot" name="//unnamed_contact_1"/>
  </contact>

  <actuator>
    <general name="left_hip_roll" class="/" joint="left_hip_roll_joint" forcerange="-35.0594 35.0594" gainprm="92.31" biasprm="0 -92.31 -1.17041"/>
    <general name="left_hip_yaw" class="/" joint="left_hip_yaw_joint" forcerange="-57.3363 57.3363" gainprm="92.31" biasprm="0 -92.31 -1.17041"/>
    <general name="left_hip_pitch" class="/" joint="left_hip_pitch_joint" forcerange="-185.591 185.591" gainprm="92.31" biasprm="0 -92.31 -1.17041"/>
    <general name="left_knee_pitch" class="/" joint="left_knee_pitch_joint" forcerange="-183.704 183.704" gainprm="92.31" biasprm="0 -92.31 -1.17041"/>
    <general name="left_ankle_pitch" class="/" joint="left_ankle_pitch_joint" forcerange="-11.5349 11.5349" gainprm="92.31" biasprm="0 -92.31 -1.17041"/>
    <general name="left_ankle_roll" class="/" joint="left_ankle_roll_joint" forcerange="-21.3234 21.3234" gainprm="92.31" biasprm="0 -92.31 -1.17041"/>
    <general name="right_hip_roll" class="/" joint="right_hip_roll_joint" forcerange="-37.0853 37.0853" gainprm="92.31" biasprm="0 -92.31 -1.17041"/>
    <general name="right_hip_yaw" class="/" joint="right_hip_yaw_joint" forcerange="-57.6995 57.6995" gainprm="92.31" biasprm="0 -92.31 -1.17041"/>
    <general name="right_hip_pitch" class="/" joint="right_hip_pitch_joint" forcerange="-197.622 197.622" gainprm="92.31" biasprm="0 -92.31 -1.17041"/>
    <general name="right_knee_pitch" class="/" joint="right_knee_pitch_joint" forcerange="-194.081 194.081" gainprm="92.31" biasprm="0 -92.31 -1.17041"/>
    <general name="right_ankle_pitch" class="/" joint="right_ankle_pitch_joint" forcerange="-11.973 11.973" gainprm="92.31" biasprm="0 -92.31 -1.17041"/>
    <general name="right_ankle_roll" class="/" joint="right_ankle_roll_joint" forcerange="-21.3931 21.3931" gainprm="92.31" biasprm="0 -92.31 -1.17041"/>
    <general name="waist_yaw" class="/" joint="waist_yaw_joint" forcerange="-56.8325 56.8325" gainprm="92.31" biasprm="0 -92.31 -1.17041"/>
    <general name="waist_pitch" class="/" joint="waist_pitch_joint" forcerange="-60.3242 60.3242" gainprm="92.31" biasprm="0 -92.31 -1.17041"/>
    <general name="waist_roll" class="/" joint="waist_roll_joint" forcerange="-53.6887 53.6887" gainprm="92.31" biasprm="0 -92.31 -1.17041"/>
    <general name="left_shoulder_pitch" class="/" joint="left_shoulder_pitch_joint" forcerange="-29.7975 29.7975" gainprm="92.31" biasprm="0 -92.31 -1.17041"/>
    <general name="left_shoulder_roll" class="/" joint="left_shoulder_roll_joint" forcerange="-29.6231 29.6231" gainprm="92.31" biasprm="0 -92.31 -1.17041"/>
    <general name="left_shoulder_yaw" class="/" joint="left_shoulder_yaw_joint" forcerange="-23.9121 23.9121" gainprm="92.31" biasprm="0 -92.31 -1.17041"/>
    <general name="left_elbow_pitch" class="/" joint="left_elbow_pitch_joint" forcerange="-25.8248 25.8248" gainprm="92.31" biasprm="0 -92.31 -1.17041"/>
    <general name="left_wrist_yaw" class="/" joint="left_wrist_yaw_joint" forcerange="-7.57031 7.57031" gainprm="92.31" biasprm="0 -92.31 -1.17041"/>
    <general name="left_wrist_roll" class="/" joint="left_wrist_roll_joint" forcerange="-3.13504 3.13504" gainprm="92.31" biasprm="0 -92.31 -1.17041"/>
    <general name="left_wrist_pitch" class="/" joint="left_wrist_pitch_joint" forcerange="-2.86626 2.86626" gainprm="92.31" biasprm="0 -92.31 -1.17041"/>
    <general name="left_jaw" class="/" joint="left_jaw_joint" forcerange="-3.44206 3.44206" gainprm="92.31" biasprm="0 -92.31 -1.17041"/>
    <general name="right_shoulder_pitch" class="/" joint="right_shoulder_pitch_joint" forcerange="-29.848 29.848" gainprm="92.31" biasprm="0 -92.31 -1.17041"/>
    <general name="right_shoulder_roll" class="/" joint="right_shoulder_roll_joint" forcerange="-29.478 29.478" gainprm="92.31" biasprm="0 -92.31 -1.17041"/>
    <general name="right_shoulder_yaw" class="/" joint="right_shoulder_yaw_joint" forcerange="-21.9945 21.9945" gainprm="92.31" biasprm="0 -92.31 -1.17041"/>
    <general name="right_elbow_pitch" class="/" joint="right_elbow_pitch_joint" forcerange="-24.6825 24.6825" gainprm="92.31" biasprm="0 -92.31 -1.17041"/>
    <general name="right_wrist_yaw" class="/" joint="right_wrist_yaw_joint" forcerange="-8.05495 8.05495" gainprm="92.31" biasprm="0 -92.31 -1.17041"/>
    <general name="right_wrist_roll" class="/" joint="right_wrist_roll_joint" forcerange="-3.35375 3.35375" gainprm="92.31" biasprm="0 -92.31 -1.17041"/>
    <general name="right_wrist_pitch" class="/" joint="right_wrist_pitch_joint" forcerange="-3.25698 3.25698" gainprm="92.31" biasprm="0 -92.31 -1.17041"/>
    <general name="right_jaw" class="/" joint="right_jaw_joint" forcerange="-2.82749 2.82749" gainprm="92.31" biasprm="0 -92.31 -1.17041"/>
    <general name="head_roll" class="/" joint="head_roll_joint" forcerange="-3.07739 3.07739" gainprm="92.31" biasprm="0 -92.31 -1.17041"/>
    <general name="head_pitch" class="/" joint="head_pitch_joint" forcerange="-2.81485 2.81485" gainprm="92.31" biasprm="0 -92.31 -1.17041"/>
    <general name="head_yaw" class="/" joint="head_yaw_joint" forcerange="-3.0793 3.0793" gainprm="92.31" biasprm="0 -92.31 -1.17041"/>
  </actuator>

  <sensor>
    <gyro site="imu" name="imu_angular_velocity"/>
    <velocimeter site="imu" name="imu_linear_velocity"/>
    <framelinvel objtype="site" objname="left_foot" name="left_foot_global_linear_velocity"/>
    <framelinvel objtype="site" objname="right_foot" name="right_foot_global_linear_velocity"/>
  </sensor>

  <keyframe>
    <key name="home" qpos="0 0 0.8665 1 0 0 0 0 0 -0.4 0.8 -0.4 0 0 0 0.4 -0.8 0.4 0 0 0 0 0 -0.2 0 -0.785 0 0 0 0 0 0.2 0 0.785 0 0 0 0 0 0 0"/>
  </keyframe>
</mujoco>
