<mujoco model="GR1T2_jaw">
  <compiler angle="radian" assetdir="assets" balanceinertia="true" inertiafromgeom="false"/>

  <option timestep="0.005" density="1.2" viscosity="2e-05"/>

  <size nkey="1"/>

  <visual>
    <quality shadowsize="8192"/>
    <map shadowclip="0.5"/>
  </visual>

  <default>
    <default class="/">
      <joint armature="0.1" damping="0.01" frictionloss="0.1"/>
      <geom contype="0" conaffinity="0" group="1" solref="-1000 -80"/>
      <site size="0.01 0.005 0.005" group="5"/>
      <general forcelimited="true" biastype="affine" gainprm="80" biasprm="0 -80 -2"/>
      <default class="visual">
        <geom type="mesh" density="0" rgba="0.18 0.18 0.18 1"/>
      </default>
      <default class="collision">
        <geom group="3"/>
      </default>
      <default class="foot">
        <geom size="0.126 0.045 0.01" type="box" condim="6" group="4" priority="1" solimp="0.015 1 0.01"/>
      </default>
      <default class="reward_collision_sphere">
        <geom group="5" rgba="1 0 0 1"/>
      </default>
    </default>
  </default>

  <asset>
    <texture type="skybox" colorspace="auto" name="//unnamed_texture_0" builtin="gradient" rgb1="0.95 0.95 0.95" rgb2="0.95 0.95 0.95" width="100" height="600"/>
    <texture type="2d" colorspace="auto" name="texplane" builtin="checker" rgb1="0.345 0.575 0.748" rgb2="0.345 0.575 0.748" markrgb="1 1 1" width="512" height="512"/>
    <material name="MatPlane" class="/" texture="texplane" texuniform="true" texrepeat="2 2" specular="0.9"/>
    <mesh name="base_link" class="/" file="base_link.STL"/>
    <mesh name="left_thigh_roll_link" class="/" file="left_thigh_roll_link.STL"/>
    <mesh name="left_thigh_yaw_link" class="/" file="left_thigh_yaw_link.STL"/>
    <mesh name="left_thigh_pitch_link" class="/" file="left_thigh_pitch_link.STL"/>
    <mesh name="left_shank_pitch_link" class="/" file="left_shank_pitch_link.STL"/>
    <mesh name="left_foot_pitch_link" class="/" file="left_foot_pitch_link.STL"/>
    <mesh name="left_foot_roll_link" class="/" file="left_foot_roll_link.STL"/>
    <mesh name="right_thigh_roll_link" class="/" file="right_thigh_roll_link.STL"/>
    <mesh name="right_thigh_yaw_link" class="/" file="right_thigh_yaw_link.STL"/>
    <mesh name="right_thigh_pitch_link" class="/" file="right_thigh_pitch_link.STL"/>
    <mesh name="right_shank_pitch_link" class="/" file="right_shank_pitch_link.STL"/>
    <mesh name="right_foot_pitch_link" class="/" file="right_foot_pitch_link.STL"/>
    <mesh name="right_foot_roll_link" class="/" file="right_foot_roll_link.STL"/>
    <mesh name="waist_yaw_link" class="/" file="waist_yaw_link.STL"/>
    <mesh name="waist_pitch_link" class="/" file="waist_pitch_link.STL"/>
    <mesh name="waist_roll_link" class="/" file="waist_roll_link.STL"/>
    <mesh name="torso_link" class="/" file="torso_link.STL"/>
    <mesh name="left_upper_arm_pitch_link" class="/" file="left_upper_arm_pitch_link.STL"/>
    <mesh name="left_upper_arm_roll_link" class="/" file="left_upper_arm_roll_link.STL"/>
    <mesh name="left_upper_arm_yaw_link" class="/" file="left_upper_arm_yaw_link.STL"/>
    <mesh name="left_lower_arm_pitch_link" class="/" file="left_lower_arm_pitch_link.STL"/>
    <mesh name="left_hand_yaw_link" class="/" file="left_hand_yaw_link.STL"/>
    <mesh name="left_hand_roll_link" class="/" file="left_hand_roll_link.STL"/>
    <mesh name="left_hand_pitch" class="/" file="left_hand_pitch.STL"/>
    <mesh name="left_jaw_link" class="/" file="left_jaw_link.STL"/>
    <mesh name="right_upper_arm_pitch_link" class="/" file="right_upper_arm_pitch_link.STL"/>
    <mesh name="right_upper_arm_roll_link" class="/" file="right_upper_arm_roll_link.STL"/>
    <mesh name="right_upper_arm_yaw_link" class="/" file="right_upper_arm_yaw_link.STL"/>
    <mesh name="right_lower_arm_pitch_link" class="/" file="right_lower_arm_pitch_link.STL"/>
    <mesh name="right_hand_yaw_link" class="/" file="right_hand_yaw_link.STL"/>
    <mesh name="right_hand_roll_link" class="/" file="right_hand_roll_link.STL"/>
    <mesh name="right_hand_pitch" class="/" file="right_hand_pitch.STL"/>
    <mesh name="right_jaw_link" class="/" file="right_jaw_link.STL"/>
    <mesh name="head_roll_link" class="/" file="head_roll_link.STL"/>
    <mesh name="head_pitch_link" class="/" file="head_pitch_link.STL"/>
    <mesh name="head_yaw_link" class="/" file="head_yaw_link.STL"/>
    <mesh name="imu_link" class="/" file="imu_link.STL"/>
  </asset>

  <worldbody>
    <geom name="floor" class="/" size="100 100 0.125" type="plane" group="0" material="MatPlane"/>
    <light name="toplight_shadow" class="/" pos="0 0 5" dir="0.0990148 0.0990148 -0.990148" type="directional" ambient="0.04 0.04 0.04" diffuse="0.55 0.55 0.55" specular="0.12 0.12 0.12"/>
    <light name="toplight_fill" class="/" pos="0 0 5" dir="0.0990148 0.0990148 -0.990148" type="directional" castshadow="false" ambient="0.04 0.04 0.04" diffuse="0.3 0.3 0.3" specular="0.08 0.08 0.08"/>
    <body name="trunk" pos="0.000259803 -0.00206395 -0.000927607" quat="1 -3.05724e-06 0.000231473 -0.000311925">
      <inertial pos="-0.0556673 -0.00178344 -0.00895885" quat="0.999937 0.005135 0.00786629 -0.0062077" mass="2.95611" diaginertia="0.0271702 0.013086 0.0151945"/>
      <joint name="//unnamed_joint_0" type="free"/>
      <geom name="//unnamed_geom_1" class="visual" rgba="0.12 0.12 0.12 1" mesh="base_link"/>
      <geom name="base_link.STL" class="collision" size="0.111573 0.0624899" pos="-0.0394569 0.000367821 0.00749868" quat="0.706838 -0.707359 0.00477667 0" type="cylinder" rgba="0.752941 0.752941 0.752941 1"/>
      <geom name="//unnamed_geom_3" class="visual" pos="0 0 -0.0485252" quat="1 0 0 0" rgba="0.12 0.12 0.12 1" mesh="imu_link"/>
      <geom name="//unnamed_geom_4" class="reward_collision_sphere" size="0.0729272" pos="0 0.0993998 0.0814181"/>
      <geom name="//unnamed_geom_5" class="reward_collision_sphere" size="0.0729272" pos="0 -0.0993998 0.0814181"/>
      <site name="imu" class="/" pos="-0.013998 0.000516989 -0.0346236" size="0.0091159"/>
      <camera name="track" class="/" pos="0 -1.988 0" quat="0.707107 0.707107 0 0" mode="trackcom"/>
      <body name="left_thigh_roll_link" pos="-0.0335949 0.103265 -0.0204044" quat="1 3.02766e-05 0.000200034 -0.000143936">
        <inertial pos="0.00257571 -2.3276e-05 -0.000375561" quat="-0.0304251 0.707811 -0.0235078 0.705355" mass="1.17341" diaginertia="0.00181983 0.0025335 0.000593874"/>
        <joint name="left_hip_roll_joint" class="/" pos="0 0 0" axis="-1 -0.000119348 -0.000234304" range="-0.793478 0.0467157" armature="0.099228" damping="0" frictionloss="0.092941"/>
        <geom name="//unnamed_geom_6" class="visual" mesh="left_thigh_roll_link"/>
        <body name="left_thigh_yaw_link" pos="0.0264332 0.00243353 0.000964439" quat="1 -0.000364472 -0.000692238 -0.000430522">
          <inertial pos="-0.00212552 0.0380734 -0.0907532" quat="0.573401 0.0834199 -0.186031 0.793501" mass="2.55058" diaginertia="0.0161185 0.0195765 0.00326007"/>
          <joint name="left_hip_yaw_joint" class="/" pos="0 0 0" axis="0.0148965 -0.0110692 -0.999828" range="-0.75908 0.647872" armature="0.0950069" damping="0.00385172" frictionloss="0.0817279"/>
          <geom name="//unnamed_geom_7" class="visual" mesh="left_thigh_yaw_link"/>
          <body name="left_thigh_pitch_link" pos="-0.00111985 0.0220357 -0.11609" quat="0.999999 0.000109728 -0.000927647 0.000988386">
            <inertial pos="-0.000110303 -0.0311322 -0.0517799" quat="0.999816 -0.0147518 -0.00905741 0.0083098" mass="6.34102" diaginertia="0.0634519 0.0844256 0.0101328"/>
            <joint name="left_hip_pitch_joint" class="/" pos="0 0 0" axis="-0.00846149 0.999958 0.00365209" stiffness="0.00681009" range="-1.76202 0.692762" armature="0.0855146" damping="0.0180615" frictionloss="0.0823241"/>
            <geom name="//unnamed_geom_8" class="visual" mesh="left_thigh_pitch_link"/>
            <geom name="left_thigh_pitch_link.STL" class="collision" size="0.0747504 0.11387" pos="0.000648661 -0.0298199 -0.136014" type="cylinder" rgba="0.752941 0.752941 0.752941 1"/>
            <geom name="//unnamed_geom_10" class="reward_collision_sphere" size="0.091159" pos="0 -0.00993998 -0.040709"/>
            <body name="left_shank_pitch_link" pos="-0.00188726 -0.0168529 -0.289232" quat="1 0.000361833 0.000173364 -0.000472534">
              <inertial pos="0.001578 -0.00219628 -0.0955761" quat="0.999716 -0.00868412 0.00778331 -0.0207761" mass="1.36212" diaginertia="0.00745685 0.0110719 0.000462966"/>
              <joint name="left_knee_pitch_joint" class="/" pos="0 0 0" axis="0.00360676 0.999993 -0.000838552" stiffness="0.00814162" range="-0.0451105 1.92913" armature="0.0877207" damping="0.0103044" frictionloss="0.0991118"/>
              <geom name="//unnamed_geom_11" class="visual" mesh="left_shank_pitch_link"/>
              <geom name="left_shank_pitch_link.STL" class="collision" size="0.0486073 0.0823941" pos="-1.53722e-05 -0.00083749 -0.14223" quat="0.00125538 -0.202712 0.979238 0" type="cylinder" rgba="0.752941 0.752941 0.752941 1"/>
              <geom name="//unnamed_geom_13" class="reward_collision_sphere" size="0.0455795"/>
              <geom name="//unnamed_geom_14" class="reward_collision_sphere" size="0.0546954" pos="0 0 -0.0895599"/>
              <body name="left_foot_pitch_link" pos="-0.00021036 -0.00101115 -0.272913" quat="1 -9.33764e-05 0.000201296 0.000161307">
                <inertial pos="0.000682774 -0.00148152 -0.000562216" quat="-0.000967177 0.710475 -0.00115734 0.703721" mass="0.0405425" diaginertia="4.14292e-06 5.35994e-06 1.83081e-06"/>
                <joint name="left_ankle_pitch_joint" class="/" pos="0 0 0" axis="-0.00490228 0.999888 0.0141529" range="-1.05026 0.530586" armature="0.0961824" damping="0.0138705" frictionloss="0.0932422"/>
                <geom name="//unnamed_geom_15" class="visual" mesh="left_foot_pitch_link"/>
                <body name="left_foot_roll_link" pos="0.0025143 0.00172262 -0.000842577" quat="1 9.63815e-05 -0.000151701 -0.000137077">
                  <inertial pos="0.0352085 -0.00152013 -0.0316252" quat="4.26946e-06 0.724538 -0.00125793 0.689233" mass="0.830686" diaginertia="0.00385533 0.00508837 0.000274847"/>
                  <joint name="left_ankle_roll_joint" class="/" pos="0 0 0" axis="-0.999974 -0.00330245 -0.00645951" range="-0.394953 0.44596" armature="0.0896876" damping="0.016084" frictionloss="0.0793069"/>
                  <geom name="//unnamed_geom_16" class="visual" mesh="left_foot_roll_link"/>
                  <geom name="left_foot" class="foot" size="0.142981 0.0424949 0.00990291" pos="0.0416966 0 -0.036231"/>
                  <geom name="//unnamed_geom_18" class="reward_collision_sphere" size="0.0455795" pos="0 0 -0.0244254"/>
                  <geom name="//unnamed_geom_19" class="reward_collision_sphere" size="0.0455795" pos="0.111191 0 -0.0244254"/>
                  <site name="left_foot" class="foot" pos="0.0416966 0 -0.036231" size="0.0091159"/>
                </body>
              </body>
            </body>
          </body>
        </body>
      </body>
      <body name="right_thigh_roll_link" pos="-0.0296425 -0.107465 -0.0247671" quat="1 0.0002057 -0.000120359 -0.000316332">
        <inertial pos="0.00185991 -0.00370373 0.00200306" quat="0.015346 0.703259 0.0130263 0.710649" mass="1.06423" diaginertia="0.00174281 0.00239574 0.000551896"/>
        <joint name="right_hip_roll_joint" class="/" pos="0 0 0" axis="-0.999917 -0.0123884 -0.0036303" range="-0.0432642 0.776591" armature="0.0694203" damping="0.00376932" frictionloss="0.0889881"/>
        <geom name="//unnamed_geom_20" class="visual" mesh="right_thigh_roll_link"/>
        <body name="right_thigh_yaw_link" pos="0.0303903 -0.00216188 0.00250095" quat="1 -0.000189329 7.47993e-05 -3.30532e-05">
          <inertial pos="-0.00175411 -0.0388119 -0.092535" quat="0.680616 -0.149477 0.143367 0.702755" mass="2.55917" diaginertia="0.0167827 0.0185228 0.0032864"/>
          <joint name="right_hip_yaw_joint" class="/" pos="0 0 0" axis="-9.90968e-05 0.00062715 -1" range="-0.711712 0.70865" armature="0.0866722" damping="0.0227269" frictionloss="0.0939434"/>
          <geom name="//unnamed_geom_21" class="visual" mesh="right_thigh_yaw_link"/>
          <body name="right_thigh_pitch_link" pos="0.00114963 -0.0248585 -0.115904" quat="0.999999 -0.000239836 -0.00113218 0.00026523">
            <inertial pos="0.000626877 0.0268663 -0.051973" quat="0.999765 -0.0148704 -0.0120487 0.0101476" mass="6.47157" diaginertia="0.0639681 0.0873991 0.00966701"/>
            <joint name="right_hip_pitch_joint" class="/" pos="0 0 0" axis="-0.000216806 -1 -0.000147642" range="-0.693179 1.79471" armature="0.0908161" damping="0.0262938" frictionloss="0.0791517"/>
            <geom name="//unnamed_geom_22" class="visual" mesh="right_thigh_pitch_link"/>
            <geom name="right_thigh_pitch_link.STL" class="collision" size="0.0747504 0.113868" pos="-0.0019674 0.0298199 -0.136014" quat="0.999971 0.00269833 0.00706272 0" type="cylinder" rgba="0.752941 0.752941 0.752941 1"/>
            <geom name="//unnamed_geom_24" class="reward_collision_sphere" size="0.091159" pos="0 0.00993998 -0.040709"/>
            <body name="right_shank_pitch_link" pos="0.00120507 0.0168865 -0.295191" quat="1 0.000579824 -0.000281657 0.000701484">
              <inertial pos="0.000706052 -0.00269351 -0.0926349" quat="0.999377 0.0194162 -0.000698836 0.0294541" mass="1.30098" diaginertia="0.00730125 0.010327 0.000447434"/>
              <joint name="right_knee_pitch_joint" class="/" pos="0 0 0" axis="0.000946853 -0.999944 0.0105009" stiffness="0.00126776" range="-1.94139 0.150821" armature="0.0894139" damping="0.0231983" frictionloss="0.0883419"/>
              <geom name="//unnamed_geom_25" class="visual" mesh="right_shank_pitch_link"/>
              <geom name="right_shank_pitch_link.STL" class="collision" size="0.048607 0.0823932" pos="-1.53722e-05 -0.0008375 -0.142237" type="cylinder" rgba="0.752941 0.752941 0.752941 1"/>
              <geom name="//unnamed_geom_27" class="reward_collision_sphere" size="0.0455795"/>
              <geom name="//unnamed_geom_28" class="reward_collision_sphere" size="0.0546954" pos="0 0 -0.0895599"/>
              <body name="right_foot_pitch_link" pos="-0.000322764 0.00186645 -0.275541" quat="1 -5.22634e-05 -0.000126694 -5.93915e-05">
                <inertial pos="-0.00187022 -0.00288481 -0.000112354" quat="-0.00668529 0.710947 0.00674035 0.703182" mass="0.0414338" diaginertia="4.36857e-06 5.08749e-06 1.82226e-06"/>
                <joint name="right_ankle_pitch_joint" class="/" pos="0 0 0" axis="-0.00316238 -0.999983 0.00496775" range="-0.4991 1.04673" armature="0.0985264" damping="0.0108005" frictionloss="0.103732"/>
                <geom name="//unnamed_geom_29" class="visual" mesh="right_foot_pitch_link"/>
                <body name="right_foot_roll_link" pos="-0.00290791 -0.00196008 -0.000501993" quat="1 -2.36299e-06 4.94309e-07 -1.06172e-05">
                  <inertial pos="0.0365872 0.00125117 -0.0329627" quat="0.000537858 0.724412 0.00151622 0.689365" mass="0.810153" diaginertia="0.00374804 0.00483491 0.000265671"/>
                  <joint name="right_ankle_roll_joint" class="/" pos="0 0 0" axis="-0.99999 0.00327847 -0.00288423" range="-0.465362 0.48255" armature="0.0940324" damping="0.015423" frictionloss="0.0899938"/>
                  <geom name="//unnamed_geom_30" class="visual" mesh="right_foot_roll_link"/>
                  <geom name="right_foot" class="foot" size="0.150974 0.0403908 0.00929639" pos="0.0416966 0 -0.036231"/>
                  <geom name="//unnamed_geom_32" class="reward_collision_sphere" size="0.0455795" pos="0 0 -0.0244254"/>
                  <geom name="//unnamed_geom_33" class="reward_collision_sphere" size="0.0455795" pos="0.111191 0 -0.0244254"/>
                  <site name="right_foot" class="foot" pos="0.0416966 0 -0.036231" size="0.0091159"/>
                </body>
              </body>
            </body>
          </body>
        </body>
      </body>
      <body name="waist_yaw_link" pos="0.00310309 -0.00142127 0.00155618" quat="0.999999 -0.000782826 -0.000169711 -0.000960716">
        <inertial pos="-0.00303764 -0.00655451 0.0414344" quat="0.980052 0.18763 -0.0287681 0.0588685" mass="1.32457" diaginertia="0.00249136 0.00326258 0.000788736"/>
        <joint name="waist_yaw_joint" class="/" pos="0 0 0" axis="-0.00333507 0.00172902 0.999993" stiffness="0.000299488" range="-1.0963 0.982891" armature="0.0834254" damping="0.0202735" frictionloss="0.0987378"/>
        <geom name="//unnamed_geom_34" class="visual" rgba="0.12 0.12 0.12 1" mesh="waist_yaw_link"/>
        <body name="waist_pitch_link" pos="0.00129768 0.000603694 0.0719852" quat="1 -0.000235447 -0.00025776 2.41717e-06">
          <inertial pos="0.00403407 -0.00121994 0.0335316" quat="0.998542 -0.0333936 0.0424046 -0.000180637" mass="1.15349" diaginertia="0.0032356 0.00446214 0.000647897"/>
          <joint name="waist_pitch_joint" class="/" pos="0 0 0" axis="0.0184742 -0.999828 0.00187566" stiffness="0.00340075" range="-1.22917 0.532833" armature="0.0775583" damping="0.0133303" frictionloss="0.0877678"/>
          <geom name="//unnamed_geom_35" class="visual" rgba="0.12 0.12 0.12 1" mesh="waist_pitch_link"/>
          <body name="waist_roll_link" pos="0.00950334 0.0013359 0.0683242" quat="0.999999 0.000848986 -0.000751843 0.000869436">
            <inertial pos="-0.0139869 -0.00163706 0.119343" quat="0.998678 -0.00471563 -0.0511442 -0.00181949" mass="5.04761" diaginertia="0.0418183 0.0551273 0.0123783"/>
            <joint name="waist_roll_joint" class="/" pos="0 0 0" axis="-0.99992 0.00545368 0.0114394" range="-0.689237 0.696358" armature="0.101916" damping="0.00420799" frictionloss="0.0886453"/>
            <geom name="//unnamed_geom_36" class="visual" rgba="0.12 0.12 0.12 1" mesh="waist_roll_link"/>
            <geom name="//unnamed_geom_37" class="visual" pos="-0.00208483 0.000570982 0.130554" quat="1 0 0 0" mesh="torso_link"/>
            <geom name="torso_link.STL" class="collision" size="0.143509 0.0275236" pos="-0.0167397 0.00573517 0.12036" type="cylinder" rgba="0.752941 0.752941 0.752941 1"/>
            <geom name="//unnamed_geom_39" class="reward_collision_sphere" size="0.118507" pos="0 0 0.162836"/>
            <body name="left_upper_arm_pitch_link" pos="0.00211672 0.0987872 0.167153" quat="0.976599 0.215068 -0.000238761 -0.000148851">
              <inertial pos="0.000501951 0.0528731 0.000155583" quat="0.699314 0.712437 0.0111691 -0.0571787" mass="0.616451" diaginertia="0.00138232 0.00190165 0.000174086"/>
              <joint name="left_shoulder_pitch_joint" class="/" pos="0 0 0" axis="0.00120719 0.999999 -0.000329926" range="-2.79183 1.92324" armature="0.0946765" damping="0" frictionloss="0.0955941"/>
              <geom name="//unnamed_geom_40" class="visual" mesh="left_upper_arm_pitch_link"/>
              <body name="left_upper_arm_roll_link" pos="0.00242619 0.0906441 0.00353357" quat="0.976602 -0.215052 3.16995e-05 -0.000529018">
                <inertial pos="0.00392764 0.0179582 -0.0213369" quat="0.889216 0.269089 0.123516 -0.348754" mass="0.46794" diaginertia="0.000672423 0.000990475 0.000124463"/>
                <joint name="left_shoulder_roll_joint" class="/" pos="0 0 0" axis="-0.999957 0.00640354 -0.00671273" stiffness="0.000167353" range="-2.5073 0.613645" armature="0.0821613" damping="0.0170558" frictionloss="0.101451"/>
                <geom name="//unnamed_geom_41" class="visual" mesh="left_upper_arm_roll_link"/>
                <body name="left_upper_arm_yaw_link" pos="-0.00109981 0.0407261 -0.05474" quat="1 -0.000540396 -0.000210973 -9.8535e-05">
                  <inertial pos="0.00276303 -0.00146757 -0.0687743" quat="0.999746 0.014109 -0.00624547 -0.0164046" mass="0.408056" diaginertia="0.00243495 0.00354893 9.30663e-05"/>
                  <joint name="left_shoulder_yaw_joint" class="/" pos="0 0 0" axis="0.00916326 0.00808316 0.999925" stiffness="0.00496337" range="-2.91895 2.92893" armature="0.0807204" damping="0.0133183" frictionloss="0.0912079"/>
                  <geom name="//unnamed_geom_42" class="visual" mesh="left_upper_arm_yaw_link"/>
                  <geom name="left_upper_arm_yaw_link.STL" class="collision" size="0.0330298 0.0774323" pos="3.65868e-05 -0.000888922 -0.0645971" quat="0.00803418 -0.995528 0.0941277 0" type="cylinder" rgba="0.752941 0.752941 0.752941 1"/>
                  <body name="left_lower_arm_pitch_link" pos="-0.000844214 0.00238583 -0.143303" quat="1 6.23955e-05 3.93292e-05 -7.22759e-05">
                    <inertial pos="0.000813839 0.00608954 -0.0221056" quat="0.710135 -0.0957305 0.0874611 0.692022" mass="0.251517" diaginertia="0.000210748 0.000295435 3.59686e-05"/>
                    <joint name="left_elbow_pitch_joint" class="/" pos="0 0 0" axis="-0.0118046 0.999912 -0.00609924" range="-2.29556 2.31267" armature="0.0950347" damping="0.018799" frictionloss="0.0972715"/>
                    <geom name="//unnamed_geom_44" class="visual" mesh="left_lower_arm_pitch_link"/>
                    <body name="left_hand_yaw_link" pos="0.00159946 -0.00291801 -0.049066" quat="1 -0.000311499 -0.00038951 -0.000285071">
                      <inertial pos="0.00239585 0.00195935 -0.0611764" quat="0.999952 -0.00125374 -0.00460948 0.00851944" mass="0.768192" diaginertia="0.00184929 0.00251779 0.000177849"/>
                      <joint name="left_wrist_yaw_joint" class="/" pos="0 0 0" axis="-0.014446 -0.00773867 0.999866" range="-3.01062 3.01917" armature="0.10552" damping="0.0107074" frictionloss="0.0910738"/>
                      <geom name="//unnamed_geom_45" class="visual" mesh="left_hand_yaw_link"/>
                      <geom name="left_hand_yaw_link.STL" class="collision" size="0.0378965 0.0634409" pos="0.00100929 -0.00153186 -0.0619127" type="cylinder" rgba="0.752941 0.752941 0.752941 1"/>
                      <geom name="//unnamed_geom_47" class="reward_collision_sphere" size="0.0455795"/>
                      <body name="left_hand_roll_link" pos="0.000911111 -0.00129641 -0.159108" quat="1 2.19015e-05 6.52442e-05 8.90709e-06">
                        <inertial pos="0.00281034 -0.00100548 -0.00177343" quat="0.50258 0.500434 0.497741 0.499232" mass="0.00383437" diaginertia="2.29285e-07 3.37681e-07 2.53065e-08"/>
                        <joint name="left_wrist_roll_joint" class="/" pos="0 0 0" axis="-0.999997 -0.00240464 -0.000174877" range="-0.966237 0.845406" armature="0.0907017" damping="0.0124601" frictionloss="0.0912707"/>
                        <geom name="//unnamed_geom_48" class="visual" mesh="left_hand_roll_link"/>
                        <body name="left_hand_pitch_link" pos="0.000396358 0.00248662 -0.00261367" quat="1 0.000693107 -0.000168418 -0.000415652">
                          <inertial pos="-0.00291971 -0.0115554 -0.0431659" quat="0.721496 -0.118185 0.111983 0.673005" mass="0.172322" diaginertia="0.000197996 0.000259651 3.37034e-05"/>
                          <joint name="left_wrist_pitch_joint" class="/" pos="0 0 0" axis="0.0174723 0.999843 0.0029988" range="-0.60618 0.597775" armature="0.102818" damping="0" frictionloss="0.08269"/>
                          <geom name="//unnamed_geom_49" class="visual" mesh="left_hand_pitch"/>
                          <body name="left_jaw_link" pos="-0.00248014 -0.00103348 -0.0478536" quat="1 0.000153823 -8.20482e-05 -0.000102611">
                            <inertial pos="0.000552598 0.00316595 -0.0280325" quat="0.70098 -0.0271487 0.0351795 0.711796" mass="0.0510606" diaginertia="5.41684e-05 5.59157e-05 1.14329e-05"/>
                            <joint name="left_jaw_joint" class="/" pos="0 0 0" axis="-0.999998 -0.000700339 0.00202701" range="-0.983495 0.0357331" armature="0.0812962" damping="0.0219558" frictionloss="0.103744"/>
                            <geom name="//unnamed_geom_50" class="visual" mesh="left_jaw_link"/>
                            <geom name="//unnamed_geom_51" class="collision" size="0.0328172"/>
                            <geom name="//unnamed_geom_52" class="reward_collision_sphere" size="0.0455795" pos="0 0 -0.0162836"/>
                          </body>
                        </body>
                      </body>
                    </body>
                  </body>
                </body>
              </body>
            </body>
            <body name="right_upper_arm_pitch_link" pos="0.000708994 -0.099711 0.168665" quat="0.976711 -0.214558 0.000129967 -4.40908e-05">
              <inertial pos="0.00225687 -0.0551003 6.98561e-05" quat="0.709452 0.703122 0.0351969 0.0325198" mass="0.580999" diaginertia="0.0013978 0.00190902 0.00017621"/>
              <joint name="right_shoulder_pitch_joint" class="/" pos="0 0 0" axis="-0.00279471 -0.999975 0.00645115" range="-1.90637 2.78204" armature="0.0975952" damping="0.00196648" frictionloss="0.0953753"/>
              <geom name="//unnamed_geom_53" class="visual" mesh="right_upper_arm_pitch_link"/>
              <body name="right_upper_arm_roll_link" pos="0.00207285 -0.0936584 0.000401443" quat="0.976738 0.214434 -4.87095e-06 0.000204348">
                <inertial pos="0.00417378 -0.0176521 -0.0208576" quat="0.888842 -0.268532 0.123559 0.35012" mass="0.459599" diaginertia="0.000703939 0.00100486 0.000125736"/>
                <joint name="right_shoulder_roll_joint" class="/" pos="0 0 0" axis="-0.999988 0.0043461 0.00222793" range="-0.632435 2.5711" armature="0.0841235" damping="0.00208038" frictionloss="0.0866845"/>
                <geom name="//unnamed_geom_54" class="visual" mesh="right_upper_arm_roll_link"/>
                <body name="right_upper_arm_yaw_link" pos="-0.00104819 -0.038863 -0.0598063" quat="1 -9.86766e-05 -0.00014571 7.29866e-05">
                  <inertial pos="0.00219493 0.00205433 -0.0721295" quat="0.999996 -0.00260828 -0.000698605 -0.000584866" mass="0.395522" diaginertia="0.00236962 0.003461 9.05913e-05"/>
                  <joint name="right_shoulder_yaw_joint" class="/" pos="0 0 0" axis="-0.0059277 -0.0147557 0.999874" range="-2.93716 3.02601" armature="0.0974316" damping="0.00579608" frictionloss="0.0934703"/>
                  <geom name="//unnamed_geom_55" class="visual" mesh="right_upper_arm_yaw_link"/>
                  <geom name="right_upper_arm_yaw_link.STL" class="collision" size="0.0330298 0.0774323" pos="3.65868e-05 0.000888922 -0.0645971" type="cylinder" rgba="0.752941 0.752941 0.752941 1"/>
                  <body name="right_lower_arm_pitch_link" pos="0.00291216 -0.00166354 -0.142834" quat="1 0.000185719 1.27936e-06 2.04652e-05">
                    <inertial pos="-0.00274941 -0.0073814 -0.0179767" quat="0.701127 0.0911749 -0.0932675 0.701006" mass="0.255844" diaginertia="0.000202062 0.000276846 3.53372e-05"/>
                    <joint name="right_elbow_pitch_joint" class="/" pos="0 0 0" axis="-0.00259818 -0.999988 -0.00417973" range="-2.32198 2.24118" armature="0.0882741" damping="0" frictionloss="0.0919579"/>
                    <geom name="//unnamed_geom_57" class="visual" mesh="right_lower_arm_pitch_link"/>
                    <body name="right_hand_yaw_link" pos="0.00120059 0.0018446 -0.051246" quat="0.999999 0.000493807 -0.00110887 -0.000659681">
                      <inertial pos="0.00200254 0.000121861 -0.0579873" quat="0.999711 0.00350247 -0.000807776 0.0237884" mass="0.739842" diaginertia="0.00185894 0.0024985 0.000176706"/>
                      <joint name="right_wrist_yaw_joint" class="/" pos="0 0 0" axis="0.00425439 -0.0043199 0.999982" range="-2.91532 2.99088" armature="0.0842155" damping="0.00729993" frictionloss="0.0964493"/>
                      <geom name="//unnamed_geom_58" class="visual" mesh="right_hand_yaw_link"/>
                      <geom name="right_hand_yaw_link.STL" class="collision" size="0.0378965 0.0634409" pos="0.00100929 0.000637266 -0.0619127" type="cylinder" rgba="0.752941 0.752941 0.752941 1"/>
                      <geom name="//unnamed_geom_60" class="reward_collision_sphere" size="0.0455795"/>
                      <body name="right_hand_roll_link" pos="0.00240093 0.00203634 -0.15722" quat="1 -8.88797e-05 4.74356e-05 0.000161624">
                        <inertial pos="-0.00134874 -0.00310519 0.00305934" quat="0.499926 0.500228 0.499745 0.500101" mass="0.00391161" diaginertia="2.40369e-07 3.41889e-07 2.58764e-08"/>
                        <joint name="right_wrist_roll_joint" class="/" pos="0 0 0" axis="-0.999993 0.00177398 0.00343431" range="-0.914805 0.97407" armature="0.106832" damping="0.0207718" frictionloss="0.0791282"/>
                        <geom name="//unnamed_geom_61" class="visual" mesh="right_hand_roll_link"/>
                        <body name="right_hand_pitch_link" pos="-0.000625169 0.0011421 0.000202135" quat="1 -6.31166e-05 3.40995e-05 4.99827e-06">
                          <inertial pos="-0.00181804 0.0099005 -0.0461094" quat="0.724346 0.12368 -0.115087 0.668417" mass="0.163848" diaginertia="0.000187905 0.000255604 3.32768e-05"/>
                          <joint name="right_wrist_pitch_joint" class="/" pos="0 0 0" axis="0.000927981 -0.999999 -0.000542573" range="-0.605408 0.664345" armature="0.0859091" damping="0.00445457" frictionloss="0.102799"/>
                          <geom name="//unnamed_geom_62" class="visual" mesh="right_hand_pitch"/>
                          <body name="right_jaw_link" pos="-0.00188011 0.00232662 -0.0473592" quat="1 -0.000502994 -0.000214207 -0.000308506">
                            <inertial pos="-0.00380722 -0.0068062 -0.0283595" quat="0.711616 0.0289696 -0.0336345 0.701165" mass="0.0553281" diaginertia="5.55378e-05 5.66283e-05 1.19364e-05"/>
                            <joint name="right_jaw_joint" class="/" pos="0 0 0" axis="-0.999965 0.0023789 0.00807849" stiffness="0.00104647" range="-0.00114363 1.06704" armature="0.0877674" damping="0.00179041" frictionloss="0.0803383"/>
                            <geom name="//unnamed_geom_63" class="visual" mesh="right_jaw_link"/>
                            <geom name="//unnamed_geom_64" class="collision" size="0.0328172"/>
                            <geom name="//unnamed_geom_65" class="reward_collision_sphere" size="0.0455795" pos="0 0 -0.0162836"/>
                          </body>
                        </body>
                      </body>
                    </body>
                  </body>
                </body>
              </body>
            </body>
            <body name="head_roll_link" pos="-0.00031313 0.0032636 0.251537" quat="0.999999 -0.00106249 -0.000501275 0.00055865">
              <inertial pos="0.00441504 -0.000266977 0.00261486" quat="0.00275206 0.706957 -4.82604e-05 0.707251" mass="0.00774819" diaginertia="4.81455e-07 4.4567e-07 1.5479e-07"/>
              <joint name="head_roll_joint" class="/" pos="0 0 0" axis="-0.999971 -0.00720733 -0.0022767" range="-0.300889 0.412765" armature="0.0828195" damping="0" frictionloss="0.0821385"/>
              <geom name="//unnamed_geom_66" class="visual" mesh="head_roll_link"/>
              <body name="head_pitch_link" pos="0.000209852 -0.00121973 -0.00061329" quat="1 0.000303814 2.60897e-05 0.000292573">
                <inertial pos="-0.0011172 -0.000964192 0.0128832" quat="0.665475 0.66416 0.241567 -0.240168" mass="0.0463469" diaginertia="1.80185e-05 2.38846e-05 6.10073e-06"/>
                <joint name="head_pitch_joint" class="/" pos="0 0 0" axis="0.00524297 -0.999985 -0.00138583" range="-0.899217 0.868178" armature="0.0889918" damping="0.00631154" frictionloss="0.10374"/>
                <geom name="//unnamed_geom_67" class="visual" mesh="head_pitch_link"/>
                <body name="head_yaw_link" pos="0.00257158 0.000331654 0.0432351" quat="1 0.000411092 -0.000221539 2.83439e-05">
                  <inertial pos="0.0245247 -0.00348324 0.0780654" quat="0.705439 -0.137847 -0.143728 0.680217" mass="1.12095" diaginertia="0.00681244 0.0073949 0.00176637"/>
                  <joint name="head_yaw_joint" class="/" pos="0 0 0" axis="-0.00154596 0.00421738 0.99999" range="-2.73101 2.7264" armature="0.0833213" damping="0" frictionloss="0.094611"/>
                  <geom name="//unnamed_geom_68" class="visual" rgba="0.12 0.12 0.12 1" mesh="head_yaw_link"/>
                  <geom name="head_yaw_link.STL" class="collision" size="0.108194" pos="0.0169391 -0.000874742 0.0762238" rgba="0.752941 0.752941 0.752941 1"/>
                  <geom name="//unnamed_geom_70" class="reward_collision_sphere" size="0.091159" pos="0.0277977 0 0.0814181"/>
                  <camera name="ego_camera" class="/" pos="0.101925 0 0.0895599" quat="-0.5 -0.5 0.5 0.5"/>
                </body>
              </body>
            </body>
          </body>
        </body>
      </body>
    </body>
  </worldbody>

  <contact>
    <pair class="/" geom1="floor" geom2="left_foot" name="//unnamed_contact_0"/>
    <pair class="/" geom1="floor" geom2="right_foot" name="//unnamed_contact_1"/>
  </contact>

  <actuator>
    <general name="left_hip_roll" class="/" joint="left_hip_roll_joint" forcerange="-43.5308 43.5308" gainprm="109.391" biasprm="0 -109.391 -0.91159"/>
    <general name="left_hip_yaw" class="/" joint="left_hip_yaw_joint" forcerange="-57.1522 57.1522" gainprm="109.391" biasprm="0 -109.391 -0.91159"/>
    <general name="left_hip_pitch" class="/" joint="left_hip_pitch_joint" forcerange="-206.321 206.321" gainprm="109.391" biasprm="0 -109.391 -0.91159"/>
    <general name="left_knee_pitch" class="/" joint="left_knee_pitch_joint" forcerange="-198.039 198.039" gainprm="109.391" biasprm="0 -109.391 -0.91159"/>
    <general name="left_ankle_pitch" class="/" joint="left_ankle_pitch_joint" forcerange="-12.2102 12.2102" gainprm="109.391" biasprm="0 -109.391 -0.91159"/>
    <general name="left_ankle_roll" class="/" joint="left_ankle_roll_joint" forcerange="-29.2561 29.2561" gainprm="109.391" biasprm="0 -109.391 -0.91159"/>
    <general name="right_hip_roll" class="/" joint="right_hip_roll_joint" forcerange="-44.3031 44.3031" gainprm="109.391" biasprm="0 -109.391 -0.91159"/>
    <general name="right_hip_yaw" class="/" joint="right_hip_yaw_joint" forcerange="-61.3544 61.3544" gainprm="109.391" biasprm="0 -109.391 -0.91159"/>
    <general name="right_hip_pitch" class="/" joint="right_hip_pitch_joint" forcerange="-234.973 234.973" gainprm="109.391" biasprm="0 -109.391 -0.91159"/>
    <general name="right_knee_pitch" class="/" joint="right_knee_pitch_joint" forcerange="-185.829 185.829" gainprm="109.391" biasprm="0 -109.391 -0.91159"/>
    <general name="right_ankle_pitch" class="/" joint="right_ankle_pitch_joint" forcerange="-13.2882 13.2882" gainprm="109.391" biasprm="0 -109.391 -0.91159"/>
    <general name="right_ankle_roll" class="/" joint="right_ankle_roll_joint" forcerange="-27.792 27.792" gainprm="109.391" biasprm="0 -109.391 -0.91159"/>
    <general name="waist_yaw" class="/" joint="waist_yaw_joint" forcerange="-61.7263 61.7263" gainprm="109.391" biasprm="0 -109.391 -0.91159"/>
    <general name="waist_pitch" class="/" joint="waist_pitch_joint" forcerange="-62.428 62.428" gainprm="109.391" biasprm="0 -109.391 -0.91159"/>
    <general name="waist_roll" class="/" joint="waist_roll_joint" forcerange="-53.9384 53.9384" gainprm="109.391" biasprm="0 -109.391 -0.91159"/>
    <general name="left_shoulder_pitch" class="/" joint="left_shoulder_pitch_joint" forcerange="-33.8159 33.8159" gainprm="109.391" biasprm="0 -109.391 -0.91159"/>
    <general name="left_shoulder_roll" class="/" joint="left_shoulder_roll_joint" forcerange="-33.8331 33.8331" gainprm="109.391" biasprm="0 -109.391 -0.91159"/>
    <general name="left_shoulder_yaw" class="/" joint="left_shoulder_yaw_joint" forcerange="-24.3693 24.3693" gainprm="109.391" biasprm="0 -109.391 -0.91159"/>
    <general name="left_elbow_pitch" class="/" joint="left_elbow_pitch_joint" forcerange="-25.2148 25.2148" gainprm="109.391" biasprm="0 -109.391 -0.91159"/>
    <general name="left_wrist_yaw" class="/" joint="left_wrist_yaw_joint" forcerange="-10.0997 10.0997" gainprm="109.391" biasprm="0 -109.391 -0.91159"/>
    <general name="left_wrist_roll" class="/" joint="left_wrist_roll_joint" forcerange="-3.57996 3.57996" gainprm="109.391" biasprm="0 -109.391 -0.91159"/>
    <general name="left_wrist_pitch" class="/" joint="left_wrist_pitch_joint" forcerange="-3.93075 3.93075" gainprm="109.391" biasprm="0 -109.391 -0.91159"/>
    <general name="left_jaw" class="/" joint="left_jaw_joint" forcerange="-3.97021 3.97021" gainprm="109.391" biasprm="0 -109.391 -0.91159"/>
    <general name="right_shoulder_pitch" class="/" joint="right_shoulder_pitch_joint" forcerange="-35.0298 35.0298" gainprm="109.391" biasprm="0 -109.391 -0.91159"/>
    <general name="right_shoulder_roll" class="/" joint="right_shoulder_roll_joint" forcerange="-37.8892 37.8892" gainprm="109.391" biasprm="0 -109.391 -0.91159"/>
    <general name="right_shoulder_yaw" class="/" joint="right_shoulder_yaw_joint" forcerange="-24.3464 24.3464" gainprm="109.391" biasprm="0 -109.391 -0.91159"/>
    <general name="right_elbow_pitch" class="/" joint="right_elbow_pitch_joint" forcerange="-26.4468 26.4468" gainprm="109.391" biasprm="0 -109.391 -0.91159"/>
    <general name="right_wrist_yaw" class="/" joint="right_wrist_yaw_joint" forcerange="-10.2235 10.2235" gainprm="109.391" biasprm="0 -109.391 -0.91159"/>
    <general name="right_wrist_roll" class="/" joint="right_wrist_roll_joint" forcerange="-3.71567 3.71567" gainprm="109.391" biasprm="0 -109.391 -0.91159"/>
    <general name="right_wrist_pitch" class="/" joint="right_wrist_pitch_joint" forcerange="-3.90282 3.90282" gainprm="109.391" biasprm="0 -109.391 -0.91159"/>
    <general name="right_jaw" class="/" joint="right_jaw_joint" forcerange="-3.71077 3.71077" gainprm="109.391" biasprm="0 -109.391 -0.91159"/>
    <general name="head_roll" class="/" joint="head_roll_joint" forcerange="-3.73533 3.73533" gainprm="109.391" biasprm="0 -109.391 -0.91159"/>
    <general name="head_pitch" class="/" joint="head_pitch_joint" forcerange="-3.9539 3.9539" gainprm="109.391" biasprm="0 -109.391 -0.91159"/>
    <general name="head_yaw" class="/" joint="head_yaw_joint" forcerange="-3.89441 3.89441" gainprm="109.391" biasprm="0 -109.391 -0.91159"/>
  </actuator>

  <sensor>
    <gyro site="imu" name="imu_angular_velocity"/>
    <velocimeter site="imu" name="imu_linear_velocity"/>
    <framelinvel objtype="site" objname="left_foot" name="left_foot_global_linear_velocity"/>
    <framelinvel objtype="site" objname="right_foot" name="right_foot_global_linear_velocity"/>
  </sensor>

  <keyframe>
    <key name="home" qpos="0 0 0.8665 1 0 0 0 0 0 -0.4 0.8 -0.4 0 0 0 0.4 -0.8 0.4 0 0 0 0 0 -0.2 0 -0.785 0 0 0 0 0 0.2 0 0.785 0 0 0 0 0 0 0"/>
  </keyframe>
</mujoco>
