<mujoco model="GR1T2_jaw">
  <compiler angle="radian" assetdir="assets" balanceinertia="true" inertiafromgeom="false"/>

  <option timestep="0.005" density="1.2" viscosity="2e-05"/>

  <size nkey="1"/>

  <visual>
    <quality shadowsize="8192"/>
    <map shadowclip="0.5"/>
  </visual>

  <default>
    <default class="/">
      <joint armature="0.1" damping="0.01" frictionloss="0.1"/>
      <geom contype="0" conaffinity="0" group="1" solref="-1000 -80"/>
      <site size="0.01 0.005 0.005" group="5"/>
      <general forcelimited="true" biastype="affine" gainprm="80" biasprm="0 -80 -2"/>
      <default class="visual">
        <geom type="mesh" density="0" rgba="0.18 0.18 0.18 1"/>
      </default>
      <default class="collision">
        <geom group="3"/>
      </default>
      <default class="foot">
        <geom size="0.126 0.045 0.01" type="box" condim="6" group="4" priority="1" solimp="0.015 1 0.01"/>
      </default>
      <default class="reward_collision_sphere">
        <geom group="5" rgba="1 0 0 1"/>
      </default>
    </default>
  </default>

  <asset>
    <texture type="skybox" colorspace="auto" name="//unnamed_texture_0" builtin="gradient" rgb1="0.95 0.95 0.95" rgb2="0.95 0.95 0.95" width="100" height="600"/>
    <texture type="2d" colorspace="auto" name="texplane" builtin="checker" rgb1="0.345 0.575 0.748" rgb2="0.345 0.575 0.748" markrgb="1 1 1" width="512" height="512"/>
    <material name="MatPlane" class="/" texture="texplane" texuniform="true" texrepeat="2 2" specular="0.9"/>
    <mesh name="base_link" class="/" file="base_link.STL"/>
    <mesh name="left_thigh_roll_link" class="/" file="left_thigh_roll_link.STL"/>
    <mesh name="left_thigh_yaw_link" class="/" file="left_thigh_yaw_link.STL"/>
    <mesh name="left_thigh_pitch_link" class="/" file="left_thigh_pitch_link.STL"/>
    <mesh name="left_shank_pitch_link" class="/" file="left_shank_pitch_link.STL"/>
    <mesh name="left_foot_pitch_link" class="/" file="left_foot_pitch_link.STL"/>
    <mesh name="left_foot_roll_link" class="/" file="left_foot_roll_link.STL"/>
    <mesh name="right_thigh_roll_link" class="/" file="right_thigh_roll_link.STL"/>
    <mesh name="right_thigh_yaw_link" class="/" file="right_thigh_yaw_link.STL"/>
    <mesh name="right_thigh_pitch_link" class="/" file="right_thigh_pitch_link.STL"/>
    <mesh name="right_shank_pitch_link" class="/" file="right_shank_pitch_link.STL"/>
    <mesh name="right_foot_pitch_link" class="/" file="right_foot_pitch_link.STL"/>
    <mesh name="right_foot_roll_link" class="/" file="right_foot_roll_link.STL"/>
    <mesh name="waist_yaw_link" class="/" file="waist_yaw_link.STL"/>
    <mesh name="waist_pitch_link" class="/" file="waist_pitch_link.STL"/>
    <mesh name="waist_roll_link" class="/" file="waist_roll_link.STL"/>
    <mesh name="torso_link" class="/" file="torso_link.STL"/>
    <mesh name="left_upper_arm_pitch_link" class="/" file="left_upper_arm_pitch_link.STL"/>
    <mesh name="left_upper_arm_roll_link" class="/" file="left_upper_arm_roll_link.STL"/>
    <mesh name="left_upper_arm_yaw_link" class="/" file="left_upper_arm_yaw_link.STL"/>
    <mesh name="left_lower_arm_pitch_link" class="/" file="left_lower_arm_pitch_link.STL"/>
    <mesh name="left_hand_yaw_link" class="/" file="left_hand_yaw_link.STL"/>
    <mesh name="left_hand_roll_link" class="/" file="left_hand_roll_link.STL"/>
    <mesh name="left_hand_pitch" class="/" file="left_hand_pitch.STL"/>
    <mesh name="left_jaw_link" class="/" file="left_jaw_link.STL"/>
    <mesh name="right_upper_arm_pitch_link" class="/" file="right_upper_arm_pitch_link.STL"/>
    <mesh name="right_upper_arm_roll_link" class="/" file="right_upper_arm_roll_link.STL"/>
    <mesh name="right_upper_arm_yaw_link" class="/" file="right_upper_arm_yaw_link.STL"/>
    <mesh name="right_lower_arm_pitch_link" class="/" file="right_lower_arm_pitch_link.STL"/>
    <mesh name="right_hand_yaw_link" class="/" file="right_hand_yaw_link.STL"/>
    <mesh name="right_hand_roll_link" class="/" file="right_hand_roll_link.STL"/>
    <mesh name="right_hand_pitch" class="/" file="right_hand_pitch.STL"/>
    <mesh name="right_jaw_link" class="/" file="right_jaw_link.STL"/>
    <mesh name="head_roll_link" class="/" file="head_roll_link.STL"/>
    <mesh name="head_pitch_link" class="/" file="head_pitch_link.STL"/>
    <mesh name="head_yaw_link" class="/" file="head_yaw_link.STL"/>
    <mesh name="imu_link" class="/" file="imu_link.STL"/>
  </asset>

  <worldbody>
    <geom name="floor" class="/" size="100 100 0.125" type="plane" group="0" material="MatPlane"/>
    <light name="toplight_shadow" class="/" pos="0 0 5" dir="0.0990148 0.0990148 -0.990148" type="directional" ambient="0.04 0.04 0.04" diffuse="0.55 0.55 0.55" specular="0.12 0.12 0.12"/>
    <light name="toplight_fill" class="/" pos="0 0 5" dir="0.0990148 0.0990148 -0.990148" type="directional" castshadow="false" ambient="0.04 0.04 0.04" diffuse="0.3 0.3 0.3" specular="0.08 0.08 0.08"/>
    <body name="trunk" pos="-0.000461748 0.00101389 0.00260731" quat="0.999999 0.000415104 -0.000634719 0.00100292">
      <inertial pos="-0.0658663 0.00140457 -0.00891963" quat="0.999966 -0.00746082 -0.00260947 -0.00227265" mass="3.40165" diaginertia="0.0687727 0.0097936 0.0129233"/>
      <joint name="//unnamed_joint_0" type="free"/>
      <geom name="//unnamed_geom_1" class="visual" rgba="0.12 0.12 0.12 1" mesh="base_link"/>
      <geom name="base_link.STL" class="collision" size="0.11511 0.0644709" pos="-0.0470703 0.00034463 0.00722769" quat="0.706838 -0.707359 0.00477667 0" type="cylinder" rgba="0.752941 0.752941 0.752941 1"/>
      <geom name="//unnamed_geom_3" class="visual" pos="0 0 -0.0467715" quat="1 0 0 0" rgba="0.12 0.12 0.12 1" mesh="imu_link"/>
      <geom name="//unnamed_geom_4" class="reward_collision_sphere" size="0.0752391" pos="0 0.0931327 0.0784757"/>
      <geom name="//unnamed_geom_5" class="reward_collision_sphere" size="0.0752391" pos="0 -0.0931327 0.0784757"/>
      <site name="imu" class="/" pos="0.000344006 0.013133 -0.0440133" size="0.00940488"/>
      <camera name="track" class="/" pos="0 -1.86265 0" quat="0.707107 0.707107 0 0" mode="trackcom"/>
      <body name="left_thigh_roll_link" pos="-0.0367679 0.0982224 -0.020815" quat="0.999999 -0.00054312 0.000404834 -0.000940054">
        <inertial pos="0.0010234 -0.000350612 0.00014888" quat="-0.0279267 0.705717 -0.0407344 0.706771" mass="1.25481" diaginertia="0.00449874 0.00179371 0.000481639"/>
        <joint name="left_hip_roll_joint" class="/" pos="0 0 0" axis="-0.999909 -0.00844218 0.0105628" range="-0.791165 0.071478" armature="0.102214" damping="0.0119248" frictionloss="0.0817449"/>
        <geom name="//unnamed_geom_6" class="visual" mesh="left_thigh_roll_link"/>
        <body name="left_thigh_yaw_link" pos="0.0333279 0.000950499 0.00176029" quat="0.999999 -0.000850115 -4.5261e-05 0.000537064">
          <inertial pos="-0.0031398 0.0326289 -0.0838219" quat="0.571813 0.0942066 -0.19412 0.7915" mass="2.84244" diaginertia="0.0390557 0.0139771 0.00261005"/>
          <joint name="left_hip_yaw_joint" class="/" pos="0 0 0" axis="0.00210924 -0.00076378 -0.999997" range="-0.720404 0.671862" armature="0.0940696" damping="0.000756547" frictionloss="0.0852699"/>
          <geom name="//unnamed_geom_7" class="visual" mesh="left_thigh_yaw_link"/>
          <body name="left_thigh_pitch_link" pos="-0.00134958 0.0236595 -0.110055" quat="1 3.19677e-06 -3.68549e-05 1.5282e-05">
            <inertial pos="0.000417697 -0.0264085 -0.0488238" quat="0.999631 -0.0174892 -0.0207535 0.00138291" mass="6.97399" diaginertia="0.153546 0.0618185 0.00814861"/>
            <joint name="left_hip_pitch_joint" class="/" pos="0 0 0" axis="0.00458656 0.999982 0.00377875" range="-1.76514 0.696527" armature="0.0936817" damping="0.00334791" frictionloss="0.0989154"/>
            <geom name="//unnamed_geom_8" class="visual" mesh="left_thigh_pitch_link"/>
            <geom name="left_thigh_pitch_link.STL" class="collision" size="0.07712 0.11748" pos="0.000773823 -0.0279398 -0.131098" type="cylinder" rgba="0.752941 0.752941 0.752941 1"/>
            <geom name="//unnamed_geom_10" class="reward_collision_sphere" size="0.0940488" pos="0 -0.00931327 -0.0392379"/>
            <body name="left_shank_pitch_link" pos="-0.000268226 -0.0191218 -0.28063" quat="1 -3.67804e-05 6.54746e-05 0.000294401">
              <inertial pos="0.00231701 -0.000770238 -0.0914518" quat="0.999707 -0.00806696 0.00771979 -0.0214724" mass="1.49997" diaginertia="0.0183064 0.00758862 0.000378665"/>
              <joint name="left_knee_pitch_joint" class="/" pos="0 0 0" axis="0.000517177 1 0.000327982" range="-0.0802581 1.92118" armature="0.0781523" damping="0.0128626" frictionloss="0.103974"/>
              <geom name="//unnamed_geom_11" class="visual" mesh="left_shank_pitch_link"/>
              <geom name="left_shank_pitch_link.STL" class="collision" size="0.0501482 0.085006" pos="-1.83384e-05 -0.000784687 -0.13709" quat="0.00125538 -0.202712 0.979238 0" type="cylinder" rgba="0.752941 0.752941 0.752941 1"/>
              <geom name="//unnamed_geom_13" class="reward_collision_sphere" size="0.0470244"/>
              <geom name="//unnamed_geom_14" class="reward_collision_sphere" size="0.0564293" pos="0 0 -0.0863233"/>
              <body name="left_foot_pitch_link" pos="-0.0011465 0.000925984 -0.265553" quat="1 2.17475e-08 -5.56107e-07 3.22891e-06">
                <inertial pos="0.00160548 -0.00103097 8.74545e-05" quat="-0.000314584 0.707115 0.00276472 0.707093" mass="0.047547" diaginertia="1.07593e-05 4.13527e-06 1.61404e-06"/>
                <joint name="left_ankle_pitch_joint" class="/" pos="0 0 0" axis="0.00134399 0.999999 0.00102897" stiffness="0.000710774" range="-1.01209 0.530341" armature="0.107217" damping="0.0114022" frictionloss="0.0946737"/>
                <geom name="//unnamed_geom_15" class="visual" mesh="left_foot_pitch_link"/>
                <body name="left_foot_roll_link" pos="-0.00123119 -0.00135511 0.00255557" quat="1 2.67119e-05 -7.62405e-05 6.37099e-05">
                  <inertial pos="0.0418517 -0.00116912 -0.0295658" quat="-0.000805706 0.724898 -0.00101046 0.688855" mass="0.908439" diaginertia="0.00947206 0.00364974 0.000231507"/>
                  <joint name="left_ankle_roll_joint" class="/" pos="0 0 0" axis="-0.999982 0.00591352 0.000724989" range="-0.434905 0.447209" armature="0.0957307" damping="0.0156483" frictionloss="0.0969274"/>
                  <geom name="//unnamed_geom_16" class="visual" mesh="left_foot_roll_link"/>
                  <geom name="left_foot" class="foot" size="0.140317 0.0480449 0.010084" pos="0.0497421 0 -0.0349217"/>
                  <geom name="//unnamed_geom_18" class="reward_collision_sphere" size="0.0470244" pos="0 0 -0.0235427"/>
                  <geom name="//unnamed_geom_19" class="reward_collision_sphere" size="0.0470244" pos="0.132646 0 -0.0235427"/>
                  <site name="left_foot" class="foot" pos="0.0497421 0 -0.0349217" size="0.00940488"/>
                </body>
              </body>
            </body>
          </body>
        </body>
      </body>
      <body name="right_thigh_roll_link" pos="-0.036422 -0.104206 -0.021787" quat="0.999999 -0.000893133 0.000296464 -0.000457683">
        <inertial pos="0.000138022 -0.00142498 0.00185951" quat="0.031156 0.706828 0.0188194 0.706448" mass="1.24027" diaginertia="0.00433691 0.00176155 0.00047041"/>
        <joint name="right_hip_roll_joint" class="/" pos="0 0 0" axis="-0.999999 0.00136254 0.000260636" stiffness="6.27459e-05" range="-0.0872931 0.858231" armature="0.0834098" damping="0.0112133" frictionloss="0.0936519"/>
        <geom name="//unnamed_geom_20" class="visual" mesh="right_thigh_roll_link"/>
        <body name="right_thigh_yaw_link" pos="0.0349093 -0.00403573 0.00198877" quat="0.999999 -0.00113449 -6.84575e-05 -0.000946387">
          <inertial pos="-0.000668221 -0.0362828 -0.0887713" quat="0.686229 -0.147023 0.154537 0.695408" mass="2.82169" diaginertia="0.0394148 0.0133932 0.00273141"/>
          <joint name="right_hip_yaw_joint" class="/" pos="0 0 0" axis="0.000596421 -0.00480105 -0.999988" range="-0.710912 0.695499" armature="0.0975493" damping="0.00968995" frictionloss="0.105885"/>
          <geom name="//unnamed_geom_21" class="visual" mesh="right_thigh_yaw_link"/>
          <body name="right_thigh_pitch_link" pos="-0.00145779 -0.0231812 -0.109192" quat="1 -0.000199876 -7.36701e-05 8.07776e-05">
            <inertial pos="0.000570675 0.0249914 -0.0489823" quat="0.999651 -0.0121978 -0.0233508 0.0019924" mass="7.10394" diaginertia="0.153104 0.0625994 0.00830335"/>
            <joint name="right_hip_pitch_joint" class="/" pos="0 0 0" axis="-0.0010411 -0.999999 0.000142821" range="-0.69487 1.79575" armature="0.0900061" damping="0.0263431" frictionloss="0.0965285"/>
            <geom name="//unnamed_geom_22" class="visual" mesh="right_thigh_pitch_link"/>
            <geom name="right_thigh_pitch_link.STL" class="collision" size="0.07712 0.117477" pos="-0.00234702 0.0279398 -0.131098" quat="0.999971 0.00269833 0.00706272 0" type="cylinder" rgba="0.752941 0.752941 0.752941 1"/>
            <geom name="//unnamed_geom_24" class="reward_collision_sphere" size="0.0940488" pos="0 0.00931327 -0.0392379"/>
            <body name="right_shank_pitch_link" pos="-0.000963841 0.0162426 -0.282562" quat="1 0.000224992 0.000153607 -0.000141717">
              <inertial pos="0.00179089 0.000472999 -0.0879348" quat="0.999673 0.00757907 0.00435101 0.0240447" mass="1.44043" diaginertia="0.0178598 0.00770057 0.000369207"/>
              <joint name="right_knee_pitch_joint" class="/" pos="0 0 0" axis="0.0071772 -0.999965 -0.00426834" range="-1.93654 0.0880245" armature="0.0902906" damping="0.0220266" frictionloss="0.0942396"/>
              <geom name="//unnamed_geom_25" class="visual" mesh="right_shank_pitch_link"/>
              <geom name="right_shank_pitch_link.STL" class="collision" size="0.0501479 0.0850052" pos="-1.83384e-05 -0.000784696 -0.137096" type="cylinder" rgba="0.752941 0.752941 0.752941 1"/>
              <geom name="//unnamed_geom_27" class="reward_collision_sphere" size="0.0470244"/>
              <geom name="//unnamed_geom_28" class="reward_collision_sphere" size="0.0564293" pos="0 0 -0.0863233"/>
              <body name="right_foot_pitch_link" pos="-0.00277702 0.00168944 -0.264084" quat="1 -4.84391e-05 3.48725e-05 -0.000122866">
                <inertial pos="-0.000993937 -0.0036479 -0.00279322" quat="0.00664339 0.710556 -0.00185072 0.703607" mass="0.0482414" diaginertia="1.06354e-05 3.98344e-06 1.60918e-06"/>
                <joint name="right_ankle_pitch_joint" class="/" pos="0 0 0" axis="-0.000768478 -0.999962 -0.00870031" range="-0.48012 1.07229" armature="0.10536" damping="0.00198974" frictionloss="0.0930299"/>
                <geom name="//unnamed_geom_29" class="visual" mesh="right_foot_pitch_link"/>
                <body name="right_foot_roll_link" pos="0.000689668 -0.000979135 0.000413654" quat="1 -5.13013e-05 -2.47185e-05 -3.90426e-06">
                  <inertial pos="0.0429338 0.000722716 -0.0322618" quat="0.000612545 0.724829 0.00129115 0.688927" mass="0.861556" diaginertia="0.00895527 0.00334781 0.000218393"/>
                  <joint name="right_ankle_roll_joint" class="/" pos="0 0 0" axis="-0.999953 0.00845797 0.00483104" range="-0.437987 0.425901" armature="0.0902345" damping="0" frictionloss="0.0936575"/>
                  <geom name="//unnamed_geom_30" class="visual" mesh="right_foot_roll_link"/>
                  <geom name="right_foot" class="foot" size="0.147507 0.0373754 0.00935986" pos="0.0497421 0 -0.0349217"/>
                  <geom name="//unnamed_geom_32" class="reward_collision_sphere" size="0.0470244" pos="0 0 -0.0235427"/>
                  <geom name="//unnamed_geom_33" class="reward_collision_sphere" size="0.0470244" pos="0.132646 0 -0.0235427"/>
                  <site name="right_foot" class="foot" pos="0.0497421 0 -0.0349217" size="0.00940488"/>
                </body>
              </body>
            </body>
          </body>
        </body>
      </body>
      <body name="waist_yaw_link" pos="0.0035722 0.00359451 0.00431854" quat="1 0.000154835 -4.08294e-05 0.000127152">
        <inertial pos="-0.00216537 -0.0082764 0.0413874" quat="0.979818 0.188812 -0.0283201 0.0591998" mass="1.38734" diaginertia="0.0058254 0.0022785 0.00063157"/>
        <joint name="waist_yaw_joint" class="/" pos="0 0 0" axis="-0.00512527 -0.0128074 0.999905" range="-1.03682 1.03052" armature="0.088957" damping="0.00579661" frictionloss="0.104018"/>
        <geom name="//unnamed_geom_34" class="visual" rgba="0.12 0.12 0.12 1" mesh="waist_yaw_link"/>
        <body name="waist_pitch_link" pos="0.000276829 4.86718e-05 0.0700032" quat="1 0.000280066 0.000366521 -0.000722214">
          <inertial pos="0.00516936 -0.00183149 0.0322063" quat="0.997827 -0.0455372 0.0471073 0.00690696" mass="1.29726" diaginertia="0.00785814 0.00320993 0.000527606"/>
          <joint name="waist_pitch_joint" class="/" pos="0 0 0" axis="0.0238462 -0.999672 0.00939081" range="-1.15721 0.478183" armature="0.0956641" damping="0" frictionloss="0.0951297"/>
          <geom name="//unnamed_geom_35" class="visual" rgba="0.12 0.12 0.12 1" mesh="waist_pitch_link"/>
          <body name="waist_roll_link" pos="0.00814297 0.000332456 0.0661864" quat="1 0.00021003 0.0001951 2.77364e-05">
            <inertial pos="-0.0144627 0.00134935 0.118706" quat="0.998759 -0.00351904 -0.0496724 -0.000537421" mass="5.51839" diaginertia="0.104752 0.0426572 0.0103104"/>
            <joint name="waist_roll_joint" class="/" pos="0 0 0" axis="-0.999851 0.00981218 0.014202" range="-0.742108 0.686651" armature="0.0918139" damping="0.0215889" frictionloss="0.106553"/>
            <geom name="//unnamed_geom_36" class="visual" rgba="0.12 0.12 0.12 1" mesh="waist_roll_link"/>
            <geom name="//unnamed_geom_37" class="visual" pos="-0.00248711 0.000534982 0.125836" quat="1 0 0 0" mesh="torso_link"/>
            <geom name="torso_link.STL" class="collision" size="0.148058 0.0283962" pos="-0.0199697 0.00537357 0.11601" type="cylinder" rgba="0.752941 0.752941 0.752941 1"/>
            <geom name="//unnamed_geom_39" class="reward_collision_sphere" size="0.122263" pos="0 0 0.156951"/>
            <body name="left_upper_arm_pitch_link" pos="0.000318632 0.093915 0.160705" quat="0.976714 0.214547 8.0248e-05 7.18584e-05">
              <inertial pos="0.00367226 0.0494439 -0.000416335" quat="0.70212 0.71021 0.000441236 -0.05128" mass="0.658518" diaginertia="0.00328889 0.00138448 0.000144195"/>
              <joint name="left_shoulder_pitch_joint" class="/" pos="0 0 0" axis="-0.00163341 0.999998 0.00100564" range="-2.79124 1.9348" armature="0.0981563" damping="0.0108941" frictionloss="0.0818112"/>
              <geom name="//unnamed_geom_40" class="visual" mesh="left_upper_arm_pitch_link"/>
              <body name="left_upper_arm_roll_link" pos="0.00128382 0.0870151 0.001775" quat="0.97669 -0.214657 -3.36612e-05 3.94319e-06">
                <inertial pos="0.0054181 0.0141142 -0.0206528" quat="0.889793 0.2686 0.124878 -0.347172" mass="0.517244" diaginertia="0.00174252 0.000718235 0.000107888"/>
                <joint name="left_shoulder_roll_joint" class="/" pos="0 0 0" axis="-0.999961 0.00813227 -0.00345613" range="-2.47797 0.554894" armature="0.0989663" damping="0.0041064" frictionloss="0.1016"/>
                <geom name="//unnamed_geom_41" class="visual" mesh="left_upper_arm_roll_link"/>
                <body name="left_upper_arm_yaw_link" pos="-0.000689734 0.0385489 -0.0552232" quat="1 -1.51643e-05 0.000183178 -4.17147e-06">
                  <inertial pos="6.32667e-05 -0.000792566 -0.0679316" quat="0.999944 0.00788289 -0.00148373 -0.00685729" mass="0.43533" diaginertia="0.00566129 0.0023742 7.50594e-05"/>
                  <joint name="left_shoulder_yaw_joint" class="/" pos="0 0 0" axis="-0.0114178 -0.00380561 0.999928" range="-2.94749 2.99297" armature="0.0965717" damping="0.000109891" frictionloss="0.0925196"/>
                  <geom name="//unnamed_geom_42" class="visual" mesh="left_upper_arm_yaw_link"/>
                  <geom name="left_upper_arm_yaw_link.STL" class="collision" size="0.0340769 0.079887" pos="4.36464e-05 -0.000832877 -0.0622627" quat="0.00803418 -0.995528 0.0941277 0" type="cylinder" rgba="0.752941 0.752941 0.752941 1"/>
                  <body name="left_lower_arm_pitch_link" pos="0.00226713 -0.000280569 -0.137896" quat="1 -1.24242e-05 -2.28605e-05 -6.27922e-06">
                    <inertial pos="-0.000520634 0.00418024 -0.0211426" quat="0.703219 -0.0913005 0.0913319 0.699146" mass="0.272224" diaginertia="0.00048454 0.000203055 2.8973e-05"/>
                    <joint name="left_elbow_pitch_joint" class="/" pos="0 0 0" axis="0.00275892 0.999994 -0.0021133" range="-2.25378 2.25309" armature="0.110883" damping="0.00911356" frictionloss="0.0893426"/>
                    <geom name="//unnamed_geom_44" class="visual" mesh="left_lower_arm_pitch_link"/>
                    <body name="left_hand_yaw_link" pos="0.00243314 0.00104528 -0.0445541" quat="1 -0.000174933 -1.93099e-05 1.9093e-05">
                      <inertial pos="0.00172225 0.000664126 -0.0593593" quat="0.999936 -0.0109927 -0.00120558 -0.00238595" mass="0.809344" diaginertia="0.00439401 0.00176659 0.000147517"/>
                      <joint name="left_wrist_yaw_joint" class="/" pos="0 0 0" axis="0.00162406 -0.000551868 0.999999" range="-3.00423 3.01233" armature="0.104083" damping="0.0048437" frictionloss="0.094347"/>
                      <geom name="//unnamed_geom_45" class="visual" mesh="left_hand_yaw_link"/>
                      <geom name="left_hand_yaw_link.STL" class="collision" size="0.0390979 0.0654521" pos="0.00120404 -0.00143528 -0.0596752" type="cylinder" rgba="0.752941 0.752941 0.752941 1"/>
                      <geom name="//unnamed_geom_47" class="reward_collision_sphere" size="0.0470244"/>
                      <body name="left_hand_roll_link" pos="0.00265383 -0.00219497 -0.150685" quat="1 6.65768e-06 3.82254e-06 4.05154e-05">
                        <inertial pos="2.7044e-05 -0.000215045 0.000959424" quat="0.500407 0.489943 0.501105 0.508373" mass="0.00406905" diaginertia="5.70018e-07 2.45802e-07 2.05399e-08"/>
                        <joint name="left_wrist_roll_joint" class="/" pos="0 0 0" axis="-0.999994 0.00315424 -0.0010824" range="-0.897673 0.868992" armature="0.0843892" damping="0" frictionloss="0.0924937"/>
                        <geom name="//unnamed_geom_48" class="visual" mesh="left_hand_roll_link"/>
                        <body name="left_hand_pitch_link" pos="0.000754757 0.000863481 -0.00216564" quat="0.999999 0.000417388 0.00107804 0.000180407">
                          <inertial pos="0.000436033 -0.0108268 -0.0420381" quat="0.724826 -0.121592 0.110279 0.669089" mass="0.183773" diaginertia="0.000475227 0.000189023 2.81306e-05"/>
                          <joint name="left_wrist_pitch_joint" class="/" pos="0 0 0" axis="-0.00418697 0.999985 0.00347344" range="-0.594257 0.554774" armature="0.092254" damping="0" frictionloss="0.0845026"/>
                          <geom name="//unnamed_geom_49" class="visual" mesh="left_hand_pitch"/>
                          <body name="left_jaw_link" pos="-0.000179097 0.000746209 -0.0483257" quat="0.999999 0.000555771 0.000436513 -0.00110128">
                            <inertial pos="0.000630803 0.00364855 -0.0270702" quat="0.709228 -0.0260883 0.024093 0.704084" mass="0.0585403" diaginertia="0.000129971 3.92516e-05 9.33539e-06"/>
                            <joint name="left_jaw_joint" class="/" pos="0 0 0" axis="-0.999919 -0.00707387 -0.010566" range="-0.979919 0.0117149" armature="0.0992666" damping="0.00609889" frictionloss="0.0965125"/>
                            <geom name="//unnamed_geom_50" class="visual" mesh="left_jaw_link"/>
                            <geom name="//unnamed_geom_51" class="collision" size="0.0338576"/>
                            <geom name="//unnamed_geom_52" class="reward_collision_sphere" size="0.0470244" pos="0 0 -0.0156951"/>
                          </body>
                        </body>
                      </body>
                    </body>
                  </body>
                </body>
              </body>
            </body>
            <body name="right_upper_arm_pitch_link" pos="-0.000539698 -0.0955838 0.162" quat="0.976984 -0.21331 8.80253e-05 -0.000267544">
              <inertial pos="0.00366858 -0.0489935 -5.24516e-05" quat="0.705416 0.707944 0.0279171 0.0205686" mass="0.690988" diaginertia="0.00337406 0.00141581 0.000146906"/>
              <joint name="right_shoulder_pitch_joint" class="/" pos="0 0 0" axis="0.001505 -0.999999 -0.000334974" stiffness="0.000199101" range="-1.91792 2.85046" armature="0.0942853" damping="0.00752464" frictionloss="0.0816798"/>
              <geom name="//unnamed_geom_53" class="visual" mesh="right_upper_arm_pitch_link"/>
              <body name="right_upper_arm_roll_link" pos="0.00465399 -0.0855172 0.000133776" quat="0.976678 0.21471 -2.58986e-05 -8.05368e-05">
                <inertial pos="0.00419418 -0.0164298 -0.0217695" quat="0.886924 -0.277801 0.115715 0.350432" mass="0.526166" diaginertia="0.00175294 0.000723281 0.000108085"/>
                <joint name="right_shoulder_roll_joint" class="/" pos="0 0 0" axis="-0.999994 0.00242207 -0.00246788" stiffness="0.000509357" range="-0.591111 2.51604" armature="0.0909757" damping="0.0131035" frictionloss="0.0963048"/>
                <geom name="//unnamed_geom_54" class="visual" mesh="right_upper_arm_roll_link"/>
                <body name="right_upper_arm_yaw_link" pos="0.00200346 -0.036982 -0.0539598" quat="0.999999 -0.000320557 -8.28837e-05 -0.00136845">
                  <inertial pos="-0.000121641 0.000406462 -0.0665252" quat="0.999975 -0.00668352 0.00157634 0.00139212" mass="0.441451" diaginertia="0.00578151 0.00257298 7.81925e-05"/>
                  <joint name="right_shoulder_yaw_joint" class="/" pos="0 0 0" axis="-0.00795028 -0.0067879 0.999945" range="-2.92767 3.01165" armature="0.108228" damping="0" frictionloss="0.0815636"/>
                  <geom name="//unnamed_geom_55" class="visual" mesh="right_upper_arm_yaw_link"/>
                  <geom name="right_upper_arm_yaw_link.STL" class="collision" size="0.0340769 0.079887" pos="4.36464e-05 0.000832877 -0.0622627" type="cylinder" rgba="0.752941 0.752941 0.752941 1"/>
                  <body name="right_lower_arm_pitch_link" pos="-0.000137784 -0.000969224 -0.140157" quat="1 6.83574e-05 -0.000103873 7.92754e-05">
                    <inertial pos="-0.00202418 -0.0103432 -0.0203695" quat="0.702365 0.0908131 -0.0895537 0.700297" mass="0.276696" diaginertia="0.000501813 0.000203266 2.85864e-05"/>
                    <joint name="right_elbow_pitch_joint" class="/" pos="0 0 0" axis="0.0032462 -0.999954 0.00902588" range="-2.28425 2.22709" armature="0.0852297" damping="0.0126417" frictionloss="0.0920255"/>
                    <geom name="//unnamed_geom_57" class="visual" mesh="right_lower_arm_pitch_link"/>
                    <body name="right_hand_yaw_link" pos="0.000952092 -0.000681698 -0.0477528" quat="1 9.61725e-05 0.000177945 -2.17013e-05">
                      <inertial pos="-0.00102725 -0.00254883 -0.0569903" quat="0.999702 0.00396495 -0.000738149 0.0240843" mass="0.83265" diaginertia="0.00449245 0.00182145 0.000148706"/>
                      <joint name="right_wrist_yaw_joint" class="/" pos="0 0 0" axis="0.00269123 -0.00138944 0.999995" range="-2.95883 2.92274" armature="0.09012" damping="0" frictionloss="0.105287"/>
                      <geom name="//unnamed_geom_58" class="visual" mesh="right_hand_yaw_link"/>
                      <geom name="right_hand_yaw_link.STL" class="collision" size="0.0390979 0.0654521" pos="0.00120404 0.000597087 -0.0596752" type="cylinder" rgba="0.752941 0.752941 0.752941 1"/>
                      <geom name="//unnamed_geom_60" class="reward_collision_sphere" size="0.0470244"/>
                      <body name="right_hand_roll_link" pos="0.00247588 7.78147e-05 -0.148549" quat="1 9.59317e-05 0.000227814 3.61293e-05">
                        <inertial pos="-0.000766868 -0.00125735 0.000460674" quat="0.499344 0.501362 0.499255 0.500037" mass="0.00422522" diaginertia="5.98442e-07 2.4615e-07 2.11356e-08"/>
                        <joint name="right_wrist_roll_joint" class="/" pos="0 0 0" axis="-0.999906 0.000387144 -0.0137109" range="-0.901493 0.951406" armature="0.0965438" damping="0.0120434" frictionloss="0.0892322"/>
                        <geom name="//unnamed_geom_61" class="visual" mesh="right_hand_roll_link"/>
                        <body name="right_hand_pitch_link" pos="0.000913358 -0.00184495 -0.00249697" quat="1 -7.67979e-05 9.55416e-05 -7.6354e-05">
                          <inertial pos="-0.00161991 0.0092066 -0.0423554" quat="0.721537 0.132495 -0.10882 0.670811" mass="0.170463" diaginertia="0.000462708 0.000176652 2.70809e-05"/>
                          <joint name="right_wrist_pitch_joint" class="/" pos="0 0 0" axis="0.00311648 -0.999994 -0.00144441" range="-0.565194 0.644477" armature="0.101151" damping="0.0214825" frictionloss="0.0996761"/>
                          <geom name="//unnamed_geom_62" class="visual" mesh="right_hand_pitch"/>
                          <body name="right_jaw_link" pos="-0.00184427 -0.000252251 -0.0465667" quat="0.999999 -0.000467003 -0.000953025 -0.000410769">
                            <inertial pos="-0.00157572 -0.00874928 -0.0270898" quat="0.702017 0.0240696 -0.0354494 0.71087" mass="0.0577092" diaginertia="0.000135324 4.04108e-05 9.64084e-06"/>
                            <joint name="right_jaw_joint" class="/" pos="0 0 0" axis="-0.999955 0.00551465 0.00777339" range="-0.00809498 1.0168" armature="0.108405" damping="0.00592326" frictionloss="0.0980967"/>
                            <geom name="//unnamed_geom_63" class="visual" mesh="right_jaw_link"/>
                            <geom name="//unnamed_geom_64" class="collision" size="0.0338576"/>
                            <geom name="//unnamed_geom_65" class="reward_collision_sphere" size="0.0470244" pos="0 0 -0.0156951"/>
                          </body>
                        </body>
                      </body>
                    </body>
                  </body>
                </body>
              </body>
            </body>
            <body name="head_roll_link" pos="-0.000296731 0.00113774 0.24019" quat="1 2.70253e-05 -8.32133e-06 -4.88537e-05">
              <inertial pos="0.00448146 -0.000389013 0.000248006" quat="-0.0074612 0.700033 -0.00323945 0.714064" mass="0.0082232" diaginertia="1.16234e-06 3.04588e-07 1.28093e-07"/>
              <joint name="head_roll_joint" class="/" pos="0 0 0" axis="-0.999997 0.00229642 0.000448138" range="-0.346056 0.345462" armature="0.0905289" damping="0.00644386" frictionloss="0.0850554"/>
              <geom name="//unnamed_geom_66" class="visual" mesh="head_roll_link"/>
              <body name="head_pitch_link" pos="-0.00117986 0.00147635 0.00212299" quat="1 -7.50692e-05 3.8552e-05 1.7249e-05">
                <inertial pos="-0.00187619 -0.0027 0.0116649" quat="0.664906 0.661131 0.238026 -0.253279" mass="0.0476485" diaginertia="4.27514e-05 1.60858e-05 5.08056e-06"/>
                <joint name="head_pitch_joint" class="/" pos="0 0 0" axis="0.0068609 -0.999943 -0.00816149" range="-0.886401 0.918906" armature="0.0980622" damping="0.0106916" frictionloss="0.0933352"/>
                <geom name="//unnamed_geom_67" class="visual" mesh="head_pitch_link"/>
                <body name="head_yaw_link" pos="-0.000312644 0.000556224 0.0447026" quat="1 0.000466456 -0.00012999 -0.000209648">
                  <inertial pos="0.0321737 -0.00178557 0.0743967" quat="0.715023 -0.136628 -0.141831 0.670789" mass="1.32906" diaginertia="0.0167153 0.00565534 0.00159288"/>
                  <joint name="head_yaw_joint" class="/" pos="0 0 0" axis="0.0150224 0.00352926 0.999881" range="-2.75742 2.72048" armature="0.100857" damping="0.00800317" frictionloss="0.090266"/>
                  <geom name="//unnamed_geom_68" class="visual" rgba="0.12 0.12 0.12 1" mesh="head_yaw_link"/>
                  <geom name="head_yaw_link.STL" class="collision" size="0.111624" pos="0.0202076 -0.00081959 0.0734692" rgba="0.752941 0.752941 0.752941 1"/>
                  <geom name="//unnamed_geom_70" class="reward_collision_sphere" size="0.0940488" pos="0.0331614 0 0.0784757"/>
                  <camera name="ego_camera" class="/" pos="0.121592 0 0.0863233" quat="-0.5 -0.5 0.5 0.5"/>
                </body>
              </body>
            </body>
          </body>
        </body>
      </body>
    </body>
  </worldbody>

  <contact>
    <pair class="/" geom1="floor" geom2="left_foot" name="//unnamed_contact_0"/>
    <pair class="/" geom1="floor" geom2="right_foot" name="//unnamed_contact_1"/>
  </contact>

  <actuator>
    <general name="left_hip_roll" class="/" joint="left_hip_roll_joint" forcerange="-46.7011 46.7011" gainprm="112.859" biasprm="0 -112.859 -0.940488"/>
    <general name="left_hip_yaw" class="/" joint="left_hip_yaw_joint" forcerange="-62.3112 62.3112" gainprm="112.859" biasprm="0 -112.859 -0.940488"/>
    <general name="left_hip_pitch" class="/" joint="left_hip_pitch_joint" forcerange="-222.189 222.189" gainprm="112.859" biasprm="0 -112.859 -0.940488"/>
    <general name="left_knee_pitch" class="/" joint="left_knee_pitch_joint" forcerange="-222.9 222.9" gainprm="112.859" biasprm="0 -112.859 -0.940488"/>
    <general name="left_ankle_pitch" class="/" joint="left_ankle_pitch_joint" forcerange="-14.071 14.071" gainprm="112.859" biasprm="0 -112.859 -0.940488"/>
    <general name="left_ankle_roll" class="/" joint="left_ankle_roll_joint" forcerange="-30.2082 30.2082" gainprm="112.859" biasprm="0 -112.859 -0.940488"/>
    <general name="right_hip_roll" class="/" joint="right_hip_roll_joint" forcerange="-43.6445 43.6445" gainprm="112.859" biasprm="0 -112.859 -0.940488"/>
    <general name="right_hip_yaw" class="/" joint="right_hip_yaw_joint" forcerange="-68.0516 68.0516" gainprm="112.859" biasprm="0 -112.859 -0.940488"/>
    <general name="right_hip_pitch" class="/" joint="right_hip_pitch_joint" forcerange="-220.715 220.715" gainprm="112.859" biasprm="0 -112.859 -0.940488"/>
    <general name="right_knee_pitch" class="/" joint="right_knee_pitch_joint" forcerange="-225.213 225.213" gainprm="112.859" biasprm="0 -112.859 -0.940488"/>
    <general name="right_ankle_pitch" class="/" joint="right_ankle_pitch_joint" forcerange="-12.761 12.761" gainprm="112.859" biasprm="0 -112.859 -0.940488"/>
    <general name="right_ankle_roll" class="/" joint="right_ankle_roll_joint" forcerange="-25.4015 25.4015" gainprm="112.859" biasprm="0 -112.859 -0.940488"/>
    <general name="waist_yaw" class="/" joint="waist_yaw_joint" forcerange="-67.3471 67.3471" gainprm="112.859" biasprm="0 -112.859 -0.940488"/>
    <general name="waist_pitch" class="/" joint="waist_pitch_joint" forcerange="-64.2751 64.2751" gainprm="112.859" biasprm="0 -112.859 -0.940488"/>
    <general name="waist_roll" class="/" joint="waist_roll_joint" forcerange="-56.5761 56.5761" gainprm="112.859" biasprm="0 -112.859 -0.940488"/>
    <general name="left_shoulder_pitch" class="/" joint="left_shoulder_pitch_joint" forcerange="-35.2125 35.2125" gainprm="112.859" biasprm="0 -112.859 -0.940488"/>
    <general name="left_shoulder_roll" class="/" joint="left_shoulder_roll_joint" forcerange="-35.3988 35.3988" gainprm="112.859" biasprm="0 -112.859 -0.940488"/>
    <general name="left_shoulder_yaw" class="/" joint="left_shoulder_yaw_joint" forcerange="-28.129 28.129" gainprm="112.859" biasprm="0 -112.859 -0.940488"/>
    <general name="left_elbow_pitch" class="/" joint="left_elbow_pitch_joint" forcerange="-26.3208 26.3208" gainprm="112.859" biasprm="0 -112.859 -0.940488"/>
    <general name="left_wrist_yaw" class="/" joint="left_wrist_yaw_joint" forcerange="-10.0383 10.0383" gainprm="112.859" biasprm="0 -112.859 -0.940488"/>
    <general name="left_wrist_roll" class="/" joint="left_wrist_roll_joint" forcerange="-3.7278 3.7278" gainprm="112.859" biasprm="0 -112.859 -0.940488"/>
    <general name="left_wrist_pitch" class="/" joint="left_wrist_pitch_joint" forcerange="-3.91592 3.91592" gainprm="112.859" biasprm="0 -112.859 -0.940488"/>
    <general name="left_jaw" class="/" joint="left_jaw_joint" forcerange="-3.81378 3.81378" gainprm="112.859" biasprm="0 -112.859 -0.940488"/>
    <general name="right_shoulder_pitch" class="/" joint="right_shoulder_pitch_joint" forcerange="-35.7939 35.7939" gainprm="112.859" biasprm="0 -112.859 -0.940488"/>
    <general name="right_shoulder_roll" class="/" joint="right_shoulder_roll_joint" forcerange="-34.7896 34.7896" gainprm="112.859" biasprm="0 -112.859 -0.940488"/>
    <general name="right_shoulder_yaw" class="/" joint="right_shoulder_yaw_joint" forcerange="-27.6187 27.6187" gainprm="112.859" biasprm="0 -112.859 -0.940488"/>
    <general name="right_elbow_pitch" class="/" joint="right_elbow_pitch_joint" forcerange="-28.6207 28.6207" gainprm="112.859" biasprm="0 -112.859 -0.940488"/>
    <general name="right_wrist_yaw" class="/" joint="right_wrist_yaw_joint" forcerange="-9.8005 9.8005" gainprm="112.859" biasprm="0 -112.859 -0.940488"/>
    <general name="right_wrist_roll" class="/" joint="right_wrist_roll_joint" forcerange="-3.65314 3.65314" gainprm="112.859" biasprm="0 -112.859 -0.940488"/>
    <general name="right_wrist_pitch" class="/" joint="right_wrist_pitch_joint" forcerange="-3.58071 3.58071" gainprm="112.859" biasprm="0 -112.859 -0.940488"/>
    <general name="right_jaw" class="/" joint="right_jaw_joint" forcerange="-4.06218 4.06218" gainprm="112.859" biasprm="0 -112.859 -0.940488"/>
    <general name="head_roll" class="/" joint="head_roll_joint" forcerange="-3.35319 3.35319" gainprm="112.859" biasprm="0 -112.859 -0.940488"/>
    <general name="head_pitch" class="/" joint="head_pitch_joint" forcerange="-3.76219 3.76219" gainprm="112.859" biasprm="0 -112.859 -0.940488"/>
    <general name="head_yaw" class="/" joint="head_yaw_joint" forcerange="-3.95232 3.95232" gainprm="112.859" biasprm="0 -112.859 -0.940488"/>
  </actuator>

  <sensor>
    <gyro site="imu" name="imu_angular_velocity"/>
    <velocimeter site="imu" name="imu_linear_velocity"/>
    <framelinvel objtype="site" objname="left_foot" name="left_foot_global_linear_velocity"/>
    <framelinvel objtype="site" objname="right_foot" name="right_foot_global_linear_velocity"/>
  </sensor>

  <keyframe>
    <key name="home" qpos="0 0 0.8665 1 0 0 0 0 0 -0.4 0.8 -0.4 0 0 0 0.4 -0.8 0.4 0 0 0 0 0 -0.2 0 -0.785 0 0 0 0 0 0.2 0 0.785 0 0 0 0 0 0 0"/>
  </keyframe>
</mujoco>
