<mujoco model="GR1T2_jaw">
  <compiler angle="radian" assetdir="assets" balanceinertia="true" inertiafromgeom="false"/>

  <option timestep="0.005" density="1.2" viscosity="2e-05"/>

  <size nkey="1"/>

  <visual>
    <quality shadowsize="8192"/>
    <map shadowclip="0.5"/>
  </visual>

  <default>
    <default class="/">
      <joint armature="0.1" damping="0.01" frictionloss="0.1"/>
      <geom contype="0" conaffinity="0" group="1" solref="-1000 -80"/>
      <site size="0.01 0.005 0.005" group="5"/>
      <general forcelimited="true" biastype="affine" gainprm="80" biasprm="0 -80 -2"/>
      <default class="visual">
        <geom type="mesh" density="0" rgba="0.18 0.18 0.18 1"/>
      </default>
      <default class="collision">
        <geom group="3"/>
      </default>
      <default class="foot">
        <geom size="0.126 0.045 0.01" type="box" condim="6" group="4" priority="1" solimp="0.015 1 0.01"/>
      </default>
      <default class="reward_collision_sphere">
        <geom group="5" rgba="1 0 0 1"/>
      </default>
    </default>
  </default>

  <asset>
    <texture type="skybox" colorspace="auto" name="//unnamed_texture_0" builtin="gradient" rgb1="0.95 0.95 0.95" rgb2="0.95 0.95 0.95" width="100" height="600"/>
    <texture type="2d" colorspace="auto" name="texplane" builtin="checker" rgb1="0.345 0.575 0.748" rgb2="0.345 0.575 0.748" markrgb="1 1 1" width="512" height="512"/>
    <material name="MatPlane" class="/" texture="texplane" texuniform="true" texrepeat="2 2" specular="0.9"/>
    <mesh name="base_link" class="/" file="base_link.STL"/>
    <mesh name="left_thigh_roll_link" class="/" file="left_thigh_roll_link.STL"/>
    <mesh name="left_thigh_yaw_link" class="/" file="left_thigh_yaw_link.STL"/>
    <mesh name="left_thigh_pitch_link" class="/" file="left_thigh_pitch_link.STL"/>
    <mesh name="left_shank_pitch_link" class="/" file="left_shank_pitch_link.STL"/>
    <mesh name="left_foot_pitch_link" class="/" file="left_foot_pitch_link.STL"/>
    <mesh name="left_foot_roll_link" class="/" file="left_foot_roll_link.STL"/>
    <mesh name="right_thigh_roll_link" class="/" file="right_thigh_roll_link.STL"/>
    <mesh name="right_thigh_yaw_link" class="/" file="right_thigh_yaw_link.STL"/>
    <mesh name="right_thigh_pitch_link" class="/" file="right_thigh_pitch_link.STL"/>
    <mesh name="right_shank_pitch_link" class="/" file="right_shank_pitch_link.STL"/>
    <mesh name="right_foot_pitch_link" class="/" file="right_foot_pitch_link.STL"/>
    <mesh name="right_foot_roll_link" class="/" file="right_foot_roll_link.STL"/>
    <mesh name="waist_yaw_link" class="/" file="waist_yaw_link.STL"/>
    <mesh name="waist_pitch_link" class="/" file="waist_pitch_link.STL"/>
    <mesh name="waist_roll_link" class="/" file="waist_roll_link.STL"/>
    <mesh name="torso_link" class="/" file="torso_link.STL"/>
    <mesh name="left_upper_arm_pitch_link" class="/" file="left_upper_arm_pitch_link.STL"/>
    <mesh name="left_upper_arm_roll_link" class="/" file="left_upper_arm_roll_link.STL"/>
    <mesh name="left_upper_arm_yaw_link" class="/" file="left_upper_arm_yaw_link.STL"/>
    <mesh name="left_lower_arm_pitch_link" class="/" file="left_lower_arm_pitch_link.STL"/>
    <mesh name="left_hand_yaw_link" class="/" file="left_hand_yaw_link.STL"/>
    <mesh name="left_hand_roll_link" class="/" file="left_hand_roll_link.STL"/>
    <mesh name="left_hand_pitch" class="/" file="left_hand_pitch.STL"/>
    <mesh name="left_jaw_link" class="/" file="left_jaw_link.STL"/>
    <mesh name="right_upper_arm_pitch_link" class="/" file="right_upper_arm_pitch_link.STL"/>
    <mesh name="right_upper_arm_roll_link" class="/" file="right_upper_arm_roll_link.STL"/>
    <mesh name="right_upper_arm_yaw_link" class="/" file="right_upper_arm_yaw_link.STL"/>
    <mesh name="right_lower_arm_pitch_link" class="/" file="right_lower_arm_pitch_link.STL"/>
    <mesh name="right_hand_yaw_link" class="/" file="right_hand_yaw_link.STL"/>
    <mesh name="right_hand_roll_link" class="/" file="right_hand_roll_link.STL"/>
    <mesh name="right_hand_pitch" class="/" file="right_hand_pitch.STL"/>
    <mesh name="right_jaw_link" class="/" file="right_jaw_link.STL"/>
    <mesh name="head_roll_link" class="/" file="head_roll_link.STL"/>
    <mesh name="head_pitch_link" class="/" file="head_pitch_link.STL"/>
    <mesh name="head_yaw_link" class="/" file="head_yaw_link.STL"/>
    <mesh name="imu_link" class="/" file="imu_link.STL"/>
  </asset>

  <worldbody>
    <geom name="floor" class="/" size="100 100 0.125" type="plane" group="0" material="MatPlane"/>
    <light name="toplight_shadow" class="/" pos="0 0 5" dir="0.0990148 0.0990148 -0.990148" type="directional" ambient="0.04 0.04 0.04" diffuse="0.55 0.55 0.55" specular="0.12 0.12 0.12"/>
    <light name="toplight_fill" class="/" pos="0 0 5" dir="0.0990148 0.0990148 -0.990148" type="directional" castshadow="false" ambient="0.04 0.04 0.04" diffuse="0.3 0.3 0.3" specular="0.08 0.08 0.08"/>
    <body name="trunk" pos="0.000433518 0.00101877 -0.000981487" quat="1 -0.000196261 0.00017173 9.15144e-05">
      <inertial pos="-0.0641767 0.00156185 -0.0115657" quat="0.999927 0.0102559 -0.00387199 0.00516418" mass="2.74911" diaginertia="0.0510518 0.00201778 0.0266163"/>
      <joint name="//unnamed_joint_0" type="free"/>
      <geom name="//unnamed_geom_1" class="visual" rgba="0.12 0.12 0.12 1" mesh="base_link"/>
      <geom name="base_link.STL" class="collision" size="0.106833 0.0598349" pos="-0.044111 0.000252012 0.00830436" quat="0.706838 -0.707359 0.00477667 0" type="cylinder" rgba="0.752941 0.752941 0.752941 1"/>
      <geom name="//unnamed_geom_3" class="visual" pos="0 0 -0.0537389" quat="1 0 0 0" rgba="0.12 0.12 0.12 1" mesh="imu_link"/>
      <geom name="//unnamed_geom_4" class="reward_collision_sphere" size="0.0698288" pos="0 0.0681036 0.0901659"/>
      <geom name="//unnamed_geom_5" class="reward_collision_sphere" size="0.0698288" pos="0 -0.0681036 0.0901659"/>
      <site name="imu" class="/" pos="-0.00908629 0.00234698 -0.040895" size="0.0087286"/>
      <camera name="track" class="/" pos="0 -1.36207 0" quat="0.707107 0.707107 0 0" mode="trackcom"/>
      <body name="left_thigh_roll_link" pos="-0.0339234 0.0722756 -0.0238682" quat="0.999999 -0.000799063 0.000830528 -0.000655283">
        <inertial pos="0.00235651 -0.00334176 0.00240213" quat="-0.0301004 0.703434 -0.0336644 0.709325" mass="0.967812" diaginertia="0.0031439 0.000365289 0.000933727"/>
        <joint name="left_hip_roll_joint" class="/" pos="0 0 0" axis="-0.999996 0.00101376 0.00276024" range="-0.789586 0.095477" armature="0.0787234" damping="0.00591263" frictionloss="0.0890047"/>
        <geom name="//unnamed_geom_6" class="visual" mesh="left_thigh_roll_link"/>
        <body name="left_thigh_yaw_link" pos="0.0318683 0.000964555 0.00247093" quat="1 6.67986e-05 0.000340882 -0.000144631">
          <inertial pos="-0.00437283 0.024663 -0.0991941" quat="0.571286 0.0940014 -0.195233 0.791631" mass="2.34313" diaginertia="0.0294026 0.00295985 0.00532483"/>
          <joint name="left_hip_yaw_joint" class="/" pos="0 0 0" axis="0.00211091 0.00500028 -0.999985" range="-0.70421 0.710182" armature="0.0977685" damping="0" frictionloss="0.0878559"/>
          <geom name="//unnamed_geom_7" class="visual" mesh="left_thigh_yaw_link"/>
          <body name="left_thigh_pitch_link" pos="-0.00176339 0.0164059 -0.125437" quat="1 -4.57983e-05 0.00043893 -0.000164896">
            <inertial pos="0.00162266 -0.01724 -0.0560032" quat="0.999794 -0.0161765 -0.012231 -0.00090822" mass="5.61977" diaginertia="0.11184 0.0131468 0.0168789"/>
            <joint name="left_hip_pitch_joint" class="/" pos="0 0 0" axis="-0.00391346 0.999991 -0.00163366" range="-1.70957 0.71216" armature="0.0870937" damping="0.0159164" frictionloss="0.0912513"/>
            <geom name="//unnamed_geom_8" class="visual" mesh="left_thigh_pitch_link"/>
            <geom name="left_thigh_pitch_link.STL" class="collision" size="0.0715745 0.109032" pos="0.000725172 -0.0204311 -0.150628" type="cylinder" rgba="0.752941 0.752941 0.752941 1"/>
            <geom name="//unnamed_geom_10" class="reward_collision_sphere" size="0.087286" pos="0 -0.00681036 -0.0450829"/>
            <body name="left_shank_pitch_link" pos="0.00141455 -0.0126448 -0.325143" quat="0.999999 -0.00125119 0.000407055 -0.000561331">
              <inertial pos="0.00290498 -0.000306551 -0.10384" quat="0.999714 -0.00802197 0.00718283 -0.0213647" mass="1.17569" diaginertia="0.0128448 0.00157537 0.000748134"/>
              <joint name="left_knee_pitch_joint" class="/" pos="0 0 0" axis="-0.000784868 0.999998 -0.00176262" range="-0.0793496 1.96216" armature="0.0754322" damping="0" frictionloss="0.0979416"/>
              <geom name="//unnamed_geom_11" class="visual" mesh="left_shank_pitch_link"/>
              <geom name="left_shank_pitch_link.STL" class="collision" size="0.0465421 0.0788935" pos="-1.71854e-05 -0.000573805 -0.157512" quat="0.00125538 -0.202712 0.979238 0" type="cylinder" rgba="0.752941 0.752941 0.752941 1"/>
              <geom name="//unnamed_geom_13" class="reward_collision_sphere" size="0.043643"/>
              <geom name="//unnamed_geom_14" class="reward_collision_sphere" size="0.0523716" pos="0 0 -0.0991825"/>
              <body name="left_foot_pitch_link" pos="0.000277737 -0.00387105 -0.302954" quat="1 -0.000316315 8.26296e-05 -6.32541e-06">
                <inertial pos="3.56414e-05 -0.00318811 0.000953137" quat="-0.00170322 0.703733 0.00133551 0.710461" mass="0.0372434" diaginertia="7.67277e-06 8.07704e-07 3.19717e-06"/>
                <joint name="left_ankle_pitch_joint" class="/" pos="0 0 0" axis="-1.96222e-06 1 -0.000758575" stiffness="0.000370649" range="-1.07102 0.539536" armature="0.084173" damping="0.00230962" frictionloss="0.0947989"/>
                <geom name="//unnamed_geom_15" class="visual" mesh="left_foot_pitch_link"/>
                <body name="left_foot_roll_link" pos="-0.00194822 -0.00107791 0.000874257" quat="1 -2.95589e-05 8.63906e-05 -0.000181032">
                  <inertial pos="0.0394419 -0.0035307 -0.0345988" quat="0.000759632 0.731885 0.000897619 0.681427" mass="0.716053" diaginertia="0.00668728 0.000744309 0.000458396"/>
                  <joint name="left_ankle_roll_joint" class="/" pos="0 0 0" axis="-0.999969 0.00354481 -0.00709552" range="-0.439987 0.464986" armature="0.0932942" damping="0.0154572" frictionloss="0.0971289"/>
                  <geom name="//unnamed_geom_16" class="visual" mesh="left_foot_roll_link"/>
                  <geom name="left_foot" class="foot" size="0.144009 0.0398736 0.00897037" pos="0.0466148 0 -0.0401238"/>
                  <geom name="//unnamed_geom_18" class="reward_collision_sphere" size="0.043643" pos="0 0 -0.0270498"/>
                  <geom name="//unnamed_geom_19" class="reward_collision_sphere" size="0.043643" pos="0.124306 0 -0.0270498"/>
                  <site name="left_foot" class="foot" pos="0.0466148 0 -0.0401238" size="0.0087286"/>
                </body>
              </body>
            </body>
          </body>
        </body>
      </body>
      <body name="right_thigh_roll_link" pos="-0.0322862 -0.0745765 -0.0253993" quat="0.999999 0.000574027 0.000621988 0.000872952">
        <inertial pos="0.00106225 -0.00115571 0.00287834" quat="0.0258657 0.70436 0.0181426 0.70914" mass="0.961318" diaginertia="0.0030299 0.000358576 0.000916857"/>
        <joint name="right_hip_roll_joint" class="/" pos="0 0 0" axis="-0.99996 0.00518975 0.00731282" range="-0.0863948 0.810034" armature="0.0838064" damping="0.00110964" frictionloss="0.082814"/>
        <geom name="//unnamed_geom_20" class="visual" mesh="right_thigh_roll_link"/>
        <body name="right_thigh_yaw_link" pos="0.0337081 -0.00319559 0.002266" quat="1 0.000243348 3.9849e-05 -0.000114321">
          <inertial pos="-0.00413705 -0.0271378 -0.101739" quat="0.686186 -0.146478 0.145385 0.697536" mass="2.29018" diaginertia="0.0283251 0.00272219 0.00535554"/>
          <joint name="right_hip_yaw_joint" class="/" pos="0 0 0" axis="0.00637368 0.000174081 -0.99998" range="-0.655725 0.705662" armature="0.0864175" damping="0" frictionloss="0.0981681"/>
          <geom name="//unnamed_geom_21" class="visual" mesh="right_thigh_yaw_link"/>
          <body name="right_thigh_pitch_link" pos="-0.00100141 -0.0164913 -0.126885" quat="0.999999 -0.000156889 0.00103666 -0.000801016">
            <inertial pos="0.000986243 0.0158795 -0.0564246" quat="0.999803 -0.0148003 -0.0115892 0.00629548" mass="5.36294" diaginertia="0.11328 0.0132321 0.0167209"/>
            <joint name="right_hip_pitch_joint" class="/" pos="0 0 0" axis="0.0157285 -0.999876 0.000525951" range="-0.643774 1.77711" armature="0.0770195" damping="0.012624" frictionloss="0.0913966"/>
            <geom name="//unnamed_geom_22" class="visual" mesh="right_thigh_pitch_link"/>
            <geom name="right_thigh_pitch_link.STL" class="collision" size="0.0715745 0.10903" pos="-0.00219946 0.0204311 -0.150628" quat="0.999971 0.00269833 0.00706272 0" type="cylinder" rgba="0.752941 0.752941 0.752941 1"/>
            <geom name="//unnamed_geom_24" class="reward_collision_sphere" size="0.087286" pos="0 0.00681036 -0.0450829"/>
            <body name="right_shank_pitch_link" pos="0.00139243 0.0122911 -0.323" quat="1 0.000196822 0.000310673 0.000124951">
              <inertial pos="0.00271089 -0.00339825 -0.10218" quat="0.999624 0.0118761 0.00498463 0.0242029" mass="1.15446" diaginertia="0.0128313 0.00158371 0.00074201"/>
              <joint name="right_knee_pitch_joint" class="/" pos="0 0 0" axis="-0.0191733 -0.999815 0.00159862" range="-1.92514 0.0995089" armature="0.0860689" damping="0.0222811" frictionloss="0.0830833"/>
              <geom name="//unnamed_geom_25" class="visual" mesh="right_shank_pitch_link"/>
              <geom name="right_shank_pitch_link.STL" class="collision" size="0.0465419 0.0788927" pos="-1.71854e-05 -0.000573812 -0.157519" type="cylinder" rgba="0.752941 0.752941 0.752941 1"/>
              <geom name="//unnamed_geom_27" class="reward_collision_sphere" size="0.043643"/>
              <geom name="//unnamed_geom_28" class="reward_collision_sphere" size="0.0523716" pos="0 0 -0.0991825"/>
              <body name="right_foot_pitch_link" pos="-0.000249626 -0.000679902 -0.307383" quat="1 -5.49963e-05 8.95202e-05 0.00016364">
                <inertial pos="-0.000835361 -0.00244581 -0.00047761" quat="-0.00187351 0.708961 -0.0116123 0.70515" mass="0.0369237" diaginertia="7.39205e-06 7.98731e-07 3.07015e-06"/>
                <joint name="right_ankle_pitch_joint" class="/" pos="0 0 0" axis="-8.7402e-05 -1 0.00011974" range="-0.557247 1.06725" armature="0.086399" damping="0.00590035" frictionloss="0.090486"/>
                <geom name="//unnamed_geom_29" class="visual" mesh="right_foot_pitch_link"/>
                <body name="right_foot_roll_link" pos="0.00110336 -0.00129573 -0.000102403" quat="1 0.000321954 0.000383803 0.000380721">
                  <inertial pos="0.0379283 -0.000780284 -0.0335491" quat="0.000838951 0.724944 0.00162707 0.688806" mass="0.725645" diaginertia="0.00660771 0.000741381 0.000450746"/>
                  <joint name="right_ankle_roll_joint" class="/" pos="0 0 0" axis="-0.999969 -0.00734666 -0.00281896" range="-0.436258 0.431807" armature="0.0983427" damping="0.00393873" frictionloss="0.0826622"/>
                  <geom name="//unnamed_geom_30" class="visual" mesh="right_foot_roll_link"/>
                  <geom name="right_foot" class="foot" size="0.142948 0.0389612 0.00811274" pos="0.0466148 0 -0.0401238"/>
                  <geom name="//unnamed_geom_32" class="reward_collision_sphere" size="0.043643" pos="0 0 -0.0270498"/>
                  <geom name="//unnamed_geom_33" class="reward_collision_sphere" size="0.043643" pos="0.124306 0 -0.0270498"/>
                  <site name="right_foot" class="foot" pos="0.0466148 0 -0.0401238" size="0.0087286"/>
                </body>
              </body>
            </body>
          </body>
        </body>
      </body>
      <body name="waist_yaw_link" pos="0.000539378 0.000810695 0.00129283" quat="1 -0.000180566 -0.000240862 0.000632037">
        <inertial pos="-0.00263601 -0.00678846 0.0468708" quat="0.979935 0.187778 -0.0327794 0.0582477" mass="1.10233" diaginertia="0.0040388 0.000467776 0.00123769"/>
        <joint name="waist_yaw_joint" class="/" pos="0 0 0" axis="-0.00535253 0.00430684 0.999976" range="-1.06304 1.05292" armature="0.0896557" damping="0.0124656" frictionloss="0.0857894"/>
        <geom name="//unnamed_geom_34" class="visual" rgba="0.12 0.12 0.12 1" mesh="waist_yaw_link"/>
        <body name="waist_pitch_link" pos="0.0032255 -0.00227651 0.0824756" quat="1 -0.000255951 -0.000397963 -6.14862e-05">
          <inertial pos="0.00534404 -0.00195618 0.0358835" quat="0.998456 -0.0375347 0.0409441 -0.00104607" mass="0.972363" diaginertia="0.00534038 0.000676157 0.00104727"/>
          <joint name="waist_pitch_joint" class="/" pos="0 0 0" axis="-0.0149773 -0.999787 0.0142139" range="-1.1938 0.520689" armature="0.0905739" damping="0.00160963" frictionloss="0.0867569"/>
          <geom name="//unnamed_geom_35" class="visual" rgba="0.12 0.12 0.12 1" mesh="waist_pitch_link"/>
          <body name="waist_roll_link" pos="0.00655559 0.000683749 0.0740892" quat="1 -0.000309364 -0.000116631 0.000219281">
            <inertial pos="-0.0144786 -0.00219963 0.134045" quat="0.998711 0.00119649 -0.0506865 0.00244124" mass="4.43893" diaginertia="0.0749172 0.00856943 0.0213131"/>
            <joint name="waist_roll_joint" class="/" pos="0 0 0" axis="-0.999994 0.000927486 -0.00342794" range="-0.700508 0.710051" armature="0.0875143" damping="0.01257" frictionloss="0.0887624"/>
            <geom name="//unnamed_geom_36" class="visual" rgba="0.12 0.12 0.12 1" mesh="waist_roll_link"/>
            <geom name="//unnamed_geom_37" class="visual" pos="-0.00233074 0.000391208 0.144581" quat="1 0 0 0" mesh="torso_link"/>
            <geom name="torso_link.STL" class="collision" size="0.137412 0.0263543" pos="-0.0187142 0.00392944 0.133291" type="cylinder" rgba="0.752941 0.752941 0.752941 1"/>
            <geom name="//unnamed_geom_39" class="reward_collision_sphere" size="0.113472" pos="0 0 0.180332"/>
            <body name="left_upper_arm_pitch_link" pos="0.00164253 0.0675817 0.18707" quat="0.976714 0.214541 0.000311295 0.00105255">
              <inertial pos="0.00085025 0.0367463 -0.000672314" quat="0.707592 0.705032 -0.00445902 -0.0471592" mass="0.541478" diaginertia="0.00242861 0.000286042 0.000293757"/>
              <joint name="left_shoulder_pitch_joint" class="/" pos="0 0 0" axis="0.00141334 0.999909 0.0134317" range="-2.74878 1.93584" armature="0.0930587" damping="0.00428943" frictionloss="0.0859388"/>
              <geom name="//unnamed_geom_40" class="visual" mesh="left_upper_arm_pitch_link"/>
              <body name="left_upper_arm_roll_link" pos="0.00214963 0.061031 -0.00024438" quat="0.976679 -0.214702 0.000565807 -0.000337482">
                <inertial pos="0.00485019 0.00843536 -0.0234939" quat="0.889236 0.269609 0.124365 -0.347999" mass="0.404841" diaginertia="0.00125965 0.000148653 0.000211398"/>
                <joint name="left_shoulder_roll_joint" class="/" pos="0 0 0" axis="-1 -0.000196677 -0.000855433" range="-2.5282 0.577165" armature="0.0917331" damping="0" frictionloss="0.0907338"/>
                <geom name="//unnamed_geom_41" class="visual" mesh="left_upper_arm_roll_link"/>
                <body name="left_upper_arm_yaw_link" pos="0.000208112 0.0269569 -0.0629391" quat="1 -0.000135958 -2.78511e-05 0.000108512">
                  <inertial pos="-0.000998449 -0.00200163 -0.0799498" quat="0.999905 0.00328477 0.00459456 -0.012608" mass="0.351144" diaginertia="0.00409221 0.000504689 0.000153273"/>
                  <joint name="left_shoulder_yaw_joint" class="/" pos="0 0 0" axis="-0.00158791 0.00266641 0.999995" range="-2.93158 2.99647" armature="0.0882369" damping="0" frictionloss="0.0868634"/>
                  <geom name="//unnamed_geom_42" class="visual" mesh="left_upper_arm_yaw_link"/>
                  <geom name="left_upper_arm_yaw_link.STL" class="collision" size="0.0316265 0.0741425" pos="4.09023e-05 -0.000609044 -0.0715376" quat="0.00803418 -0.995528 0.0941277 0" type="cylinder" rgba="0.752941 0.752941 0.752941 1"/>
                  <body name="left_lower_arm_pitch_link" pos="-0.00105017 -0.000706852 -0.158433" quat="1 0.000635554 -0.00042985 0.00022989">
                    <inertial pos="-0.000752431 0.0039668 -0.021393" quat="0.701175 -0.0917342 0.0915214 0.701115" mass="0.22036" diaginertia="0.000350809 4.19972e-05 5.83143e-05"/>
                    <joint name="left_elbow_pitch_joint" class="/" pos="0 0 0" axis="0.00127394 0.999959 -0.0089524" stiffness="0.000127817" range="-2.27582 2.28171" armature="0.080665" damping="0.0169815" frictionloss="0.0887109"/>
                    <geom name="//unnamed_geom_44" class="visual" mesh="left_lower_arm_pitch_link"/>
                    <body name="left_hand_yaw_link" pos="-0.000154623 -0.000190671 -0.055706" quat="1 -6.38619e-06 1.92611e-05 -0.000101166">
                      <inertial pos="-0.000438904 -0.000274054 -0.0667701" quat="0.99994 -0.00440593 -0.00232062 0.00974278" mass="0.647656" diaginertia="0.00318933 0.000376736 0.000303867"/>
                      <joint name="left_wrist_yaw_joint" class="/" pos="0 0 0" axis="-0.0111078 -0.00027698 0.999938" range="-2.9569 2.96699" armature="0.0929897" damping="0.00628844" frictionloss="0.0841715"/>
                      <geom name="//unnamed_geom_45" class="visual" mesh="left_hand_yaw_link"/>
                      <geom name="left_hand_yaw_link.STL" class="collision" size="0.0362864 0.0607456" pos="0.00112834 -0.00104955 -0.0685648" type="cylinder" rgba="0.752941 0.752941 0.752941 1"/>
                      <geom name="//unnamed_geom_47" class="reward_collision_sphere" size="0.043643"/>
                      <body name="left_hand_roll_link" pos="0.0012987 -0.00064806 -0.17339" quat="1 7.36162e-05 -0.00038599 0.000427001">
                        <inertial pos="-0.00215194 -0.000313369 0.00241221" quat="0.505068 0.489673 0.499603 0.505493" mass="0.00331048" diaginertia="4.28651e-07 5.14535e-08 4.26984e-08"/>
                        <joint name="left_wrist_roll_joint" class="/" pos="0 0 0" axis="-0.999948 -0.00444761 0.00917253" range="-0.933403 0.873064" armature="0.0883381" damping="0.00590241" frictionloss="0.0884287"/>
                        <geom name="//unnamed_geom_48" class="visual" mesh="left_hand_roll_link"/>
                        <body name="left_hand_pitch_link" pos="-0.000210558 0.00276253 -0.00080491" quat="1 3.92484e-05 -1.42962e-05 -5.4343e-05">
                          <inertial pos="0.000430283 -0.00864748 -0.0479202" quat="0.723212 -0.121059 0.114449 0.670232" mass="0.145373" diaginertia="0.000333852 3.89792e-05 5.43007e-05"/>
                          <joint name="left_wrist_pitch_joint" class="/" pos="0 0 0" axis="0.000834352 0.999998 -0.00154943" range="-0.586373 0.59454" armature="0.0889426" damping="0.00882985" frictionloss="0.0852386"/>
                          <geom name="//unnamed_geom_49" class="visual" mesh="left_hand_pitch"/>
                          <body name="left_jaw_link" pos="0.000722288 0.00304694 -0.0563381" quat="1 0.000241841 0.000254515 2.57672e-05">
                            <inertial pos="-0.000296555 0.000735291 -0.0304967" quat="0.707672 -0.0244275 0.033261 0.705335" mass="0.0450324" diaginertia="9.37974e-05 8.20707e-06 1.92187e-05"/>
                            <joint name="left_jaw_joint" class="/" pos="0 0 0" axis="-0.999999 0.000366927 0.00166529" range="-0.983281 -0.0127284" armature="0.0792678" damping="0.00964651" frictionloss="0.085765"/>
                            <geom name="//unnamed_geom_50" class="visual" mesh="left_jaw_link"/>
                            <geom name="//unnamed_geom_51" class="collision" size="0.031423"/>
                            <geom name="//unnamed_geom_52" class="reward_collision_sphere" size="0.043643" pos="0 0 -0.0180332"/>
                          </body>
                        </body>
                      </body>
                    </body>
                  </body>
                </body>
              </body>
            </body>
            <body name="right_upper_arm_pitch_link" pos="-0.000703552 -0.0663859 0.189466" quat="0.976668 -0.214753 -3.39289e-05 -0.000184628">
              <inertial pos="0.00299795 -0.0367705 0.000447397" quat="0.705699 0.707631 0.0328545 0.0129457" mass="0.516618" diaginertia="0.00229858 0.000284052 0.000285874"/>
              <joint name="right_shoulder_pitch_joint" class="/" pos="0 0 0" axis="0.00132091 -0.999989 0.00453885" range="-1.88822 2.79162" armature="0.0901539" damping="0.00577126" frictionloss="0.0868446"/>
              <geom name="//unnamed_geom_53" class="visual" mesh="right_upper_arm_pitch_link"/>
              <body name="right_upper_arm_roll_link" pos="0.00116141 -0.0663272 0.000961072" quat="0.976673 0.214732 -4.34243e-05 6.79975e-05">
                <inertial pos="0.00277091 -0.0102292 -0.0216302" quat="0.888542 -0.26842 0.124406 0.350666" mass="0.408281" diaginertia="0.0012402 0.00014922 0.000211221"/>
                <joint name="right_shoulder_roll_joint" class="/" pos="0 0 0" axis="-0.999999 0.000938908 -0.000452498" range="-0.561513 2.54658" armature="0.0933186" damping="0.00352022" frictionloss="0.0869841"/>
                <geom name="//unnamed_geom_54" class="visual" mesh="right_upper_arm_roll_link"/>
                <body name="right_upper_arm_yaw_link" pos="0.000901166 -0.0272845 -0.0638349" quat="1 -0.000294103 -0.000213398 -0.000213627">
                  <inertial pos="-0.000323677 -0.000123162 -0.0784096" quat="0.999831 -0.0161743 -0.00861619 0.00148315" mass="0.353221" diaginertia="0.00411076 0.000519602 0.000154544"/>
                  <joint name="right_shoulder_yaw_joint" class="/" pos="0 0 0" axis="-0.00368312 -0.000885303 0.999993" range="-2.97509 3.01211" armature="0.0884764" damping="0" frictionloss="0.079088"/>
                  <geom name="//unnamed_geom_55" class="visual" mesh="right_upper_arm_yaw_link"/>
                  <geom name="right_upper_arm_yaw_link.STL" class="collision" size="0.0316265 0.0741425" pos="4.09023e-05 0.000609044 -0.0715376" type="cylinder" rgba="0.752941 0.752941 0.752941 1"/>
                  <body name="right_lower_arm_pitch_link" pos="0.00203394 -0.0013237 -0.159512" quat="1 -0.0005805 0.00010764 0.00013131">
                    <inertial pos="0.0024312 -0.00434094 -0.0238114" quat="0.70103 0.0923991 -0.0916402 0.701157" mass="0.219471" diaginertia="0.000360267 4.44839e-05 5.72027e-05"/>
                    <joint name="right_elbow_pitch_joint" class="/" pos="0 0 0" axis="0.00252879 -0.999978 -0.00609798" range="-2.27704 2.29216" armature="0.0898727" damping="0.00197943" frictionloss="0.0852147"/>
                    <geom name="//unnamed_geom_57" class="visual" mesh="right_lower_arm_pitch_link"/>
                    <body name="right_hand_yaw_link" pos="0.00162671 -4.55443e-05 -0.0528487" quat="1 -1.84079e-05 -4.83952e-05 0.000174686">
                      <inertial pos="0.000258211 -0.00182577 -0.06432" quat="0.99974 0.00315874 0.00167526 0.0225231" mass="0.66851" diaginertia="0.0031091 0.00036677 0.000293657"/>
                      <joint name="right_wrist_yaw_joint" class="/" pos="0 0 0" axis="0.00327586 0.0131832 0.999908" range="-2.98042 2.97982" armature="0.0791383" damping="0" frictionloss="0.0909994"/>
                      <geom name="//unnamed_geom_58" class="visual" mesh="right_hand_yaw_link"/>
                      <geom name="right_hand_yaw_link.STL" class="collision" size="0.0362864 0.0607456" pos="0.00112834 0.000436622 -0.0685648" type="cylinder" rgba="0.752941 0.752941 0.752941 1"/>
                      <geom name="//unnamed_geom_60" class="reward_collision_sphere" size="0.043643"/>
                      <body name="right_hand_roll_link" pos="0.00368959 -0.000323296 -0.173518" quat="1 -2.85974e-05 -4.12634e-05 0.00012265">
                        <inertial pos="-0.00251948 -0.000314395 0.000262863" quat="0.500108 0.507445 0.500165 0.492166" mass="0.00324276" diaginertia="4.08073e-07 4.94743e-08 3.97356e-08"/>
                        <joint name="right_wrist_roll_joint" class="/" pos="0 0 0" axis="-0.999998 0.00174148 -0.00126052" range="-0.857921 0.973347" armature="0.0941548" damping="0.00716173" frictionloss="0.0861231"/>
                        <geom name="//unnamed_geom_61" class="visual" mesh="right_hand_roll_link"/>
                        <body name="right_hand_pitch_link" pos="0.000369732 -0.0013888 -0.00196271" quat="1 -8.53384e-06 -2.84061e-05 -8.94504e-06">
                          <inertial pos="0.00144178 0.00428672 -0.049935" quat="0.715514 0.127891 -0.118598 0.676475" mass="0.143492" diaginertia="0.000343424 3.93139e-05 5.65708e-05"/>
                          <joint name="right_wrist_pitch_joint" class="/" pos="0 0 0" axis="0.0107808 -0.999928 0.00532567" range="-0.622032 0.611139" armature="0.0904281" damping="0.00369389" frictionloss="0.0896955"/>
                          <geom name="//unnamed_geom_62" class="visual" mesh="right_hand_pitch"/>
                          <body name="right_jaw_link" pos="0.00261627 0.000457719 -0.0546078" quat="1 -5.63836e-05 -7.57608e-05 -0.000160694">
                            <inertial pos="-0.00280921 -0.00283849 -0.0324142" quat="0.708906 0.0186598 -0.0304078 0.7044" mass="0.0446092" diaginertia="9.21677e-05 8.06955e-06 1.92687e-05"/>
                            <joint name="right_jaw_joint" class="/" pos="0 0 0" axis="-1 -0.000496502 0.000514702" range="0.0202091 1.05195" armature="0.0891287" damping="2.23327e-05" frictionloss="0.0984531"/>
                            <geom name="//unnamed_geom_63" class="visual" mesh="right_jaw_link"/>
                            <geom name="//unnamed_geom_64" class="collision" size="0.031423"/>
                            <geom name="//unnamed_geom_65" class="reward_collision_sphere" size="0.043643" pos="0 0 -0.0180332"/>
                          </body>
                        </body>
                      </body>
                    </body>
                  </body>
                </body>
              </body>
            </body>
            <body name="head_roll_link" pos="-0.000432407 -0.00178265 0.277898" quat="1 -0.000721747 7.2891e-05 -0.000341795">
              <inertial pos="0.0047785 -0.00192396 -0.000396906" quat="0.00266243 0.706259 0.00419819 0.707936" mass="0.00640654" diaginertia="8.21264e-07 6.22861e-08 2.50717e-07"/>
              <joint name="head_roll_joint" class="/" pos="0 0 0" axis="-0.999998 0.000508546 -0.00166964" stiffness="0.000313256" range="-0.355585 0.410424" armature="0.0878332" damping="0" frictionloss="0.0872321"/>
              <geom name="//unnamed_geom_66" class="visual" mesh="head_roll_link"/>
              <body name="head_pitch_link" pos="-0.000114191 0.000716344 0.00305727" quat="1 0.000816166 -0.000386134 0.000391555">
                <inertial pos="-0.000569344 0.000463635 0.0153385" quat="0.664949 0.664587 0.240925 -0.241085" mass="0.0409773" diaginertia="3.02757e-05 3.44821e-06 1.04375e-05"/>
                <joint name="head_pitch_joint" class="/" pos="0 0 0" axis="-0.00185639 -0.999971 0.00739702" range="-0.868667 0.816951" armature="0.0902636" damping="0.00883231" frictionloss="0.0911968"/>
                <geom name="//unnamed_geom_67" class="visual" mesh="head_pitch_link"/>
                <body name="head_yaw_link" pos="9.49914e-05 0.0024123 0.0479621" quat="1 -0.000372691 1.76145e-06 0.000865603">
                  <inertial pos="0.0269163 -0.00161473 0.0852054" quat="0.708461 -0.132137 -0.145505 0.677829" mass="1.06078" diaginertia="0.0120601 0.00120497 0.00316449"/>
                  <joint name="head_yaw_joint" class="/" pos="0 0 0" axis="-0.000967151 -0.00010503 1" range="-2.72262 2.72365" armature="0.0909229" damping="0.00293568" frictionloss="0.0923722"/>
                  <geom name="//unnamed_geom_68" class="visual" rgba="0.12 0.12 0.12 1" mesh="head_yaw_link"/>
                  <geom name="head_yaw_link.STL" class="collision" size="0.103597" pos="0.0189371 -0.000599328 0.0844135" rgba="0.752941 0.752941 0.752941 1"/>
                  <geom name="//unnamed_geom_70" class="reward_collision_sphere" size="0.087286" pos="0.0310766 0 0.0901659"/>
                  <camera name="ego_camera" class="/" pos="0.113947 0 0.0991825" quat="-0.5 -0.5 0.5 0.5"/>
                </body>
              </body>
            </body>
          </body>
        </body>
      </body>
    </body>
  </worldbody>

  <contact>
    <pair class="/" geom1="floor" geom2="left_foot" name="//unnamed_contact_0"/>
    <pair class="/" geom1="floor" geom2="right_foot" name="//unnamed_contact_1"/>
  </contact>

  <actuator>
    <general name="left_hip_roll" class="/" joint="left_hip_roll_joint" forcerange="-44.277 44.277" gainprm="89.1453" biasprm="0 -89.1453 -0.87286"/>
    <general name="left_hip_yaw" class="/" joint="left_hip_yaw_joint" forcerange="-58.2598 58.2598" gainprm="89.1453" biasprm="0 -89.1453 -0.87286"/>
    <general name="left_hip_pitch" class="/" joint="left_hip_pitch_joint" forcerange="-194.252 194.252" gainprm="89.1453" biasprm="0 -89.1453 -0.87286"/>
    <general name="left_knee_pitch" class="/" joint="left_knee_pitch_joint" forcerange="-210.915 210.915" gainprm="89.1453" biasprm="0 -89.1453 -0.87286"/>
    <general name="left_ankle_pitch" class="/" joint="left_ankle_pitch_joint" forcerange="-13.7104 13.7104" gainprm="89.1453" biasprm="0 -89.1453 -0.87286"/>
    <general name="left_ankle_roll" class="/" joint="left_ankle_roll_joint" forcerange="-25.888 25.888" gainprm="89.1453" biasprm="0 -89.1453 -0.87286"/>
    <general name="right_hip_roll" class="/" joint="right_hip_roll_joint" forcerange="-41.6263 41.6263" gainprm="89.1453" biasprm="0 -89.1453 -0.87286"/>
    <general name="right_hip_yaw" class="/" joint="right_hip_yaw_joint" forcerange="-62.1542 62.1542" gainprm="89.1453" biasprm="0 -89.1453 -0.87286"/>
    <general name="right_hip_pitch" class="/" joint="right_hip_pitch_joint" forcerange="-215.658 215.658" gainprm="89.1453" biasprm="0 -89.1453 -0.87286"/>
    <general name="right_knee_pitch" class="/" joint="right_knee_pitch_joint" forcerange="-204.17 204.17" gainprm="89.1453" biasprm="0 -89.1453 -0.87286"/>
    <general name="right_ankle_pitch" class="/" joint="right_ankle_pitch_joint" forcerange="-14.2612 14.2612" gainprm="89.1453" biasprm="0 -89.1453 -0.87286"/>
    <general name="right_ankle_roll" class="/" joint="right_ankle_roll_joint" forcerange="-28.6863 28.6863" gainprm="89.1453" biasprm="0 -89.1453 -0.87286"/>
    <general name="waist_yaw" class="/" joint="waist_yaw_joint" forcerange="-56.9288 56.9288" gainprm="89.1453" biasprm="0 -89.1453 -0.87286"/>
    <general name="waist_pitch" class="/" joint="waist_pitch_joint" forcerange="-63.2459 63.2459" gainprm="89.1453" biasprm="0 -89.1453 -0.87286"/>
    <general name="waist_roll" class="/" joint="waist_roll_joint" forcerange="-57.7367 57.7367" gainprm="89.1453" biasprm="0 -89.1453 -0.87286"/>
    <general name="left_shoulder_pitch" class="/" joint="left_shoulder_pitch_joint" forcerange="-30.1414 30.1414" gainprm="89.1453" biasprm="0 -89.1453 -0.87286"/>
    <general name="left_shoulder_roll" class="/" joint="left_shoulder_roll_joint" forcerange="-35.2924 35.2924" gainprm="89.1453" biasprm="0 -89.1453 -0.87286"/>
    <general name="left_shoulder_yaw" class="/" joint="left_shoulder_yaw_joint" forcerange="-26.0093 26.0093" gainprm="89.1453" biasprm="0 -89.1453 -0.87286"/>
    <general name="left_elbow_pitch" class="/" joint="left_elbow_pitch_joint" forcerange="-26.5616 26.5616" gainprm="89.1453" biasprm="0 -89.1453 -0.87286"/>
    <general name="left_wrist_yaw" class="/" joint="left_wrist_yaw_joint" forcerange="-8.91947 8.91947" gainprm="89.1453" biasprm="0 -89.1453 -0.87286"/>
    <general name="left_wrist_roll" class="/" joint="left_wrist_roll_joint" forcerange="-3.44093 3.44093" gainprm="89.1453" biasprm="0 -89.1453 -0.87286"/>
    <general name="left_wrist_pitch" class="/" joint="left_wrist_pitch_joint" forcerange="-3.71119 3.71119" gainprm="89.1453" biasprm="0 -89.1453 -0.87286"/>
    <general name="left_jaw" class="/" joint="left_jaw_joint" forcerange="-3.56196 3.56196" gainprm="89.1453" biasprm="0 -89.1453 -0.87286"/>
    <general name="right_shoulder_pitch" class="/" joint="right_shoulder_pitch_joint" forcerange="-30.6681 30.6681" gainprm="89.1453" biasprm="0 -89.1453 -0.87286"/>
    <general name="right_shoulder_roll" class="/" joint="right_shoulder_roll_joint" forcerange="-33.722 33.722" gainprm="89.1453" biasprm="0 -89.1453 -0.87286"/>
    <general name="right_shoulder_yaw" class="/" joint="right_shoulder_yaw_joint" forcerange="-25.4981 25.4981" gainprm="89.1453" biasprm="0 -89.1453 -0.87286"/>
    <general name="right_elbow_pitch" class="/" joint="right_elbow_pitch_joint" forcerange="-23.3488 23.3488" gainprm="89.1453" biasprm="0 -89.1453 -0.87286"/>
    <general name="right_wrist_yaw" class="/" joint="right_wrist_yaw_joint" forcerange="-8.96375 8.96375" gainprm="89.1453" biasprm="0 -89.1453 -0.87286"/>
    <general name="right_wrist_roll" class="/" joint="right_wrist_roll_joint" forcerange="-3.52054 3.52054" gainprm="89.1453" biasprm="0 -89.1453 -0.87286"/>
    <general name="right_wrist_pitch" class="/" joint="right_wrist_pitch_joint" forcerange="-3.69428 3.69428" gainprm="89.1453" biasprm="0 -89.1453 -0.87286"/>
    <general name="right_jaw" class="/" joint="right_jaw_joint" forcerange="-3.43713 3.43713" gainprm="89.1453" biasprm="0 -89.1453 -0.87286"/>
    <general name="head_roll" class="/" joint="head_roll_joint" forcerange="-3.71329 3.71329" gainprm="89.1453" biasprm="0 -89.1453 -0.87286"/>
    <general name="head_pitch" class="/" joint="head_pitch_joint" forcerange="-3.58705 3.58705" gainprm="89.1453" biasprm="0 -89.1453 -0.87286"/>
    <general name="head_yaw" class="/" joint="head_yaw_joint" forcerange="-3.41591 3.41591" gainprm="89.1453" biasprm="0 -89.1453 -0.87286"/>
  </actuator>

  <sensor>
    <gyro site="imu" name="imu_angular_velocity"/>
    <velocimeter site="imu" name="imu_linear_velocity"/>
    <framelinvel objtype="site" objname="left_foot" name="left_foot_global_linear_velocity"/>
    <framelinvel objtype="site" objname="right_foot" name="right_foot_global_linear_velocity"/>
  </sensor>

  <keyframe>
    <key name="home" qpos="0 0 0.8665 1 0 0 0 0 0 -0.4 0.8 -0.4 0 0 0 0.4 -0.8 0.4 0 0 0 0 0 -0.2 0 -0.785 0 0 0 0 0 0.2 0 0.785 0 0 0 0 0 0 0"/>
  </keyframe>
</mujoco>
