<mujoco model="GR1T2_jaw">
  <compiler angle="radian" assetdir="assets" balanceinertia="true" inertiafromgeom="false"/>

  <option timestep="0.005" density="1.2" viscosity="2e-05"/>

  <size nkey="1"/>

  <visual>
    <quality shadowsize="8192"/>
    <map shadowclip="0.5"/>
  </visual>

  <default>
    <default class="/">
      <joint armature="0.1" damping="0.01" frictionloss="0.1"/>
      <geom contype="0" conaffinity="0" group="1" solref="-1000 -80"/>
      <site size="0.01 0.005 0.005" group="5"/>
      <general forcelimited="true" biastype="affine" gainprm="80" biasprm="0 -80 -2"/>
      <default class="visual">
        <geom type="mesh" density="0" rgba="0.18 0.18 0.18 1"/>
      </default>
      <default class="collision">
        <geom group="3"/>
      </default>
      <default class="foot">
        <geom size="0.126 0.045 0.01" type="box" condim="6" group="4" priority="1" solimp="0.015 1 0.01"/>
      </default>
      <default class="reward_collision_sphere">
        <geom group="5" rgba="1 0 0 1"/>
      </default>
    </default>
  </default>

  <asset>
    <texture type="skybox" colorspace="auto" name="//unnamed_texture_0" builtin="gradient" rgb1="0.95 0.95 0.95" rgb2="0.95 0.95 0.95" width="100" height="600"/>
    <texture type="2d" colorspace="auto" name="texplane" builtin="checker" rgb1="0.345 0.575 0.748" rgb2="0.345 0.575 0.748" markrgb="1 1 1" width="512" height="512"/>
    <material name="MatPlane" class="/" texture="texplane" texuniform="true" texrepeat="2 2" specular="0.9"/>
    <mesh name="base_link" class="/" file="base_link.STL"/>
    <mesh name="left_thigh_roll_link" class="/" file="left_thigh_roll_link.STL"/>
    <mesh name="left_thigh_yaw_link" class="/" file="left_thigh_yaw_link.STL"/>
    <mesh name="left_thigh_pitch_link" class="/" file="left_thigh_pitch_link.STL"/>
    <mesh name="left_shank_pitch_link" class="/" file="left_shank_pitch_link.STL"/>
    <mesh name="left_foot_pitch_link" class="/" file="left_foot_pitch_link.STL"/>
    <mesh name="left_foot_roll_link" class="/" file="left_foot_roll_link.STL"/>
    <mesh name="right_thigh_roll_link" class="/" file="right_thigh_roll_link.STL"/>
    <mesh name="right_thigh_yaw_link" class="/" file="right_thigh_yaw_link.STL"/>
    <mesh name="right_thigh_pitch_link" class="/" file="right_thigh_pitch_link.STL"/>
    <mesh name="right_shank_pitch_link" class="/" file="right_shank_pitch_link.STL"/>
    <mesh name="right_foot_pitch_link" class="/" file="right_foot_pitch_link.STL"/>
    <mesh name="right_foot_roll_link" class="/" file="right_foot_roll_link.STL"/>
    <mesh name="waist_yaw_link" class="/" file="waist_yaw_link.STL"/>
    <mesh name="waist_pitch_link" class="/" file="waist_pitch_link.STL"/>
    <mesh name="waist_roll_link" class="/" file="waist_roll_link.STL"/>
    <mesh name="torso_link" class="/" file="torso_link.STL"/>
    <mesh name="left_upper_arm_pitch_link" class="/" file="left_upper_arm_pitch_link.STL"/>
    <mesh name="left_upper_arm_roll_link" class="/" file="left_upper_arm_roll_link.STL"/>
    <mesh name="left_upper_arm_yaw_link" class="/" file="left_upper_arm_yaw_link.STL"/>
    <mesh name="left_lower_arm_pitch_link" class="/" file="left_lower_arm_pitch_link.STL"/>
    <mesh name="left_hand_yaw_link" class="/" file="left_hand_yaw_link.STL"/>
    <mesh name="left_hand_roll_link" class="/" file="left_hand_roll_link.STL"/>
    <mesh name="left_hand_pitch" class="/" file="left_hand_pitch.STL"/>
    <mesh name="left_jaw_link" class="/" file="left_jaw_link.STL"/>
    <mesh name="right_upper_arm_pitch_link" class="/" file="right_upper_arm_pitch_link.STL"/>
    <mesh name="right_upper_arm_roll_link" class="/" file="right_upper_arm_roll_link.STL"/>
    <mesh name="right_upper_arm_yaw_link" class="/" file="right_upper_arm_yaw_link.STL"/>
    <mesh name="right_lower_arm_pitch_link" class="/" file="right_lower_arm_pitch_link.STL"/>
    <mesh name="right_hand_yaw_link" class="/" file="right_hand_yaw_link.STL"/>
    <mesh name="right_hand_roll_link" class="/" file="right_hand_roll_link.STL"/>
    <mesh name="right_hand_pitch" class="/" file="right_hand_pitch.STL"/>
    <mesh name="right_jaw_link" class="/" file="right_jaw_link.STL"/>
    <mesh name="head_roll_link" class="/" file="head_roll_link.STL"/>
    <mesh name="head_pitch_link" class="/" file="head_pitch_link.STL"/>
    <mesh name="head_yaw_link" class="/" file="head_yaw_link.STL"/>
    <mesh name="imu_link" class="/" file="imu_link.STL"/>
  </asset>

  <worldbody>
    <geom name="floor" class="/" size="100 100 0.125" type="plane" group="0" material="MatPlane"/>
    <light name="toplight_shadow" class="/" pos="0 0 5" dir="0.0990148 0.0990148 -0.990148" type="directional" ambient="0.04 0.04 0.04" diffuse="0.55 0.55 0.55" specular="0.12 0.12 0.12"/>
    <light name="toplight_fill" class="/" pos="0 0 5" dir="0.0990148 0.0990148 -0.990148" type="directional" castshadow="false" ambient="0.04 0.04 0.04" diffuse="0.3 0.3 0.3" specular="0.08 0.08 0.08"/>
    <body name="trunk" pos="2.91166e-05 0.00100954 -0.00104497" quat="1 -6.01377e-05 -7.28607e-05 -0.000162394">
      <inertial pos="-0.0632157 0.00179152 -0.0120999" quat="0.999908 0.00310518 -0.00113089 -0.0131469" mass="2.80623" diaginertia="0.0467638 0.00190643 0.0336182"/>
      <joint name="//unnamed_joint_0" type="free"/>
      <geom name="//unnamed_geom_1" class="visual" rgba="0.12 0.12 0.12 1" mesh="base_link"/>
      <geom name="base_link.STL" class="collision" size="0.1075 0.0602085" pos="-0.043355 0.000248708 0.00870068" quat="0.706838 -0.707359 0.00477667 0" type="cylinder" rgba="0.752941 0.752941 0.752941 1"/>
      <geom name="//unnamed_geom_3" class="visual" pos="0 0 -0.0563035" quat="1 0 0 0" rgba="0.12 0.12 0.12 1" mesh="imu_link"/>
      <geom name="//unnamed_geom_4" class="reward_collision_sphere" size="0.0702648" pos="0 0.0672108 0.094469"/>
      <geom name="//unnamed_geom_5" class="reward_collision_sphere" size="0.0702648" pos="0 -0.0672108 0.094469"/>
      <site name="imu" class="/" pos="-0.011865 0.000550505 -0.0434038" size="0.0087831"/>
      <camera name="track" class="/" pos="0 -1.34422 0" quat="0.707107 0.707107 0 0" mode="trackcom"/>
      <body name="left_thigh_roll_link" pos="-0.0337315 0.071728 -0.02514" quat="0.999999 -0.000227719 -0.00142192 -0.000451421">
        <inertial pos="0.00256881 -0.00346424 0.00316815" quat="-0.03405 0.702372 -0.0335728 0.710202" mass="0.990658" diaginertia="0.00288911 0.000341886 0.00117757"/>
        <joint name="left_hip_roll_joint" class="/" pos="0 0 0" axis="-0.999997 -0.000851757 -0.0023723" range="-0.797355 0.0887172" armature="0.0770124" damping="0.00728366" frictionloss="0.0866443"/>
        <geom name="//unnamed_geom_6" class="visual" mesh="left_thigh_roll_link"/>
        <body name="left_thigh_yaw_link" pos="0.0307807 0.000948523 0.00289331" quat="1 -0.000178987 -9.18562e-05 5.13636e-05">
          <inertial pos="-0.00504751 0.0240759 -0.103701" quat="0.573062 0.0955029 -0.196197 0.789928" mass="2.39294" diaginertia="0.0269815 0.00278285 0.00674686"/>
          <joint name="left_hip_yaw_joint" class="/" pos="0 0 0" axis="-0.000724216 -0.00819874 -0.999966" range="-0.697858 0.698543" armature="0.10094" damping="0.000952204" frictionloss="0.0892223"/>
          <geom name="//unnamed_geom_7" class="visual" mesh="left_thigh_yaw_link"/>
          <body name="left_thigh_pitch_link" pos="-0.00223532 0.0156696 -0.131721" quat="1 0.000405664 -0.000186868 -0.000435711">
            <inertial pos="0.00235015 -0.0167326 -0.0590297" quat="0.999879 -0.00461377 -0.0068321 0.0131795" mass="5.63758" diaginertia="0.101349 0.0122321 0.0209853"/>
            <joint name="left_hip_pitch_joint" class="/" pos="0 0 0" axis="-0.00282768 0.999994 -0.00208602" range="-1.70698 0.727578" armature="0.086658" damping="0.0184801" frictionloss="0.0925089"/>
            <geom name="//unnamed_geom_8" class="visual" mesh="left_thigh_pitch_link"/>
            <geom name="left_thigh_pitch_link.STL" class="collision" size="0.0720214 0.109713" pos="0.000712745 -0.0201632 -0.157816" type="cylinder" rgba="0.752941 0.752941 0.752941 1"/>
            <geom name="//unnamed_geom_10" class="reward_collision_sphere" size="0.087831" pos="0 -0.00672108 -0.0472345"/>
            <body name="left_shank_pitch_link" pos="0.00153117 -0.0122401 -0.341242" quat="0.999999 -2.61331e-05 0.00062522 0.00140939">
              <inertial pos="0.00243908 0.00042779 -0.108941" quat="0.999724 -0.00806362 0.00781485 -0.0206546" mass="1.22014" diaginertia="0.011935 0.0014916 0.000952754"/>
              <joint name="left_knee_pitch_joint" class="/" pos="0 0 0" axis="-0.00241907 0.999994 0.00228198" range="-0.0653052 1.97296" armature="0.0732893" damping="0" frictionloss="0.0996472"/>
              <geom name="//unnamed_geom_11" class="visual" mesh="left_shank_pitch_link"/>
              <geom name="left_shank_pitch_link.STL" class="collision" size="0.0468327 0.0793861" pos="-1.68909e-05 -0.000566282 -0.165029" quat="0.00125538 -0.202712 0.979238 0" type="cylinder" rgba="0.752941 0.752941 0.752941 1"/>
              <geom name="//unnamed_geom_13" class="reward_collision_sphere" size="0.0439155"/>
              <geom name="//unnamed_geom_14" class="reward_collision_sphere" size="0.0526986" pos="0 0 -0.103916"/>
              <body name="left_foot_pitch_link" pos="0.00077656 -0.00425553 -0.317943" quat="1 -6.88634e-06 1.32539e-05 0.000119592">
                <inertial pos="0.000333058 -0.00361505 0.00166914" quat="0.000227858 0.703927 0.000758959 0.710272" mass="0.0377356" diaginertia="7.00837e-06 7.55041e-07 4.02214e-06"/>
                <joint name="left_ankle_pitch_joint" class="/" pos="0 0 0" axis="-0.000839749 1 -0.000468989" range="-1.07291 0.549624" armature="0.084886" damping="0.000910144" frictionloss="0.0979331"/>
                <geom name="//unnamed_geom_15" class="visual" mesh="left_foot_pitch_link"/>
                <body name="left_foot_roll_link" pos="-0.00263963 -0.000858342 0.000875301" quat="1 -0.000157639 3.68354e-05 -7.04447e-05">
                  <inertial pos="0.0384591 -0.00395282 -0.0362036" quat="0.0121713 0.725287 -0.00109706 0.688338" mass="0.724265" diaginertia="0.00612076 0.000696079 0.000581507"/>
                  <joint name="left_ankle_roll_joint" class="/" pos="0 0 0" axis="-0.999951 0.00532927 0.00834264" range="-0.447537 0.471662" armature="0.0968221" damping="0.0175734" frictionloss="0.0993227"/>
                  <geom name="//unnamed_geom_16" class="visual" mesh="left_foot_roll_link"/>
                  <geom name="left_foot" class="foot" size="0.143531 0.0386167 0.00925632" pos="0.045816 0 -0.0420387"/>
                  <geom name="//unnamed_geom_18" class="reward_collision_sphere" size="0.0439155" pos="0 0 -0.0283407"/>
                  <geom name="//unnamed_geom_19" class="reward_collision_sphere" size="0.0439155" pos="0.122176 0 -0.0283407"/>
                  <site name="left_foot" class="foot" pos="0.045816 0 -0.0420387" size="0.0087831"/>
                </body>
              </body>
            </body>
          </body>
        </body>
      </body>
      <body name="right_thigh_roll_link" pos="-0.0310335 -0.0736632 -0.0265309" quat="0.999999 -0.000612315 -0.000886045 1.88748e-05">
        <inertial pos="0.00152241 -0.00179025 0.00314182" quat="0.0270563 0.704255 0.0189073 0.709179" mass="0.981487" diaginertia="0.00277673 0.000333004 0.00114615"/>
        <joint name="right_hip_roll_joint" class="/" pos="0 0 0" axis="-0.999926 -0.00745802 -0.00962881" range="-0.0838001 0.805839" armature="0.0851483" damping="0.00496196" frictionloss="0.0842572"/>
        <geom name="//unnamed_geom_20" class="visual" mesh="right_thigh_roll_link"/>
        <body name="right_thigh_yaw_link" pos="0.0330859 -0.0023061 0.00291083" quat="1 -0.00016873 0.000126105 0.000168068">
          <inertial pos="-0.00482097 -0.0261458 -0.106964" quat="0.684738 -0.140367 0.147953 0.699672" mass="2.35572" diaginertia="0.0259101 0.0025408 0.006744"/>
          <joint name="right_hip_yaw_joint" class="/" pos="0 0 0" axis="0.0025042 -0.00669207 -0.999974" range="-0.651336 0.696079" armature="0.0838062" damping="0" frictionloss="0.0993741"/>
          <geom name="//unnamed_geom_21" class="visual" mesh="right_thigh_yaw_link"/>
          <body name="right_thigh_pitch_link" pos="-0.000315648 -0.0154701 -0.133534" quat="0.999999 -0.00099732 0.000824561 0.000874295">
            <inertial pos="0.000504136 0.0152644 -0.0588726" quat="0.999778 -0.0152787 -0.0126165 0.00722914" mass="5.44617" diaginertia="0.104541 0.0124944 0.0211818"/>
            <joint name="right_hip_pitch_joint" class="/" pos="0 0 0" axis="-0.00189691 -0.999879 -0.0154368" range="-0.638516 1.76737" armature="0.0753773" damping="0.0107081" frictionloss="0.0902375"/>
            <geom name="//unnamed_geom_22" class="visual" mesh="right_thigh_pitch_link"/>
            <geom name="right_thigh_pitch_link.STL" class="collision" size="0.0720214 0.109711" pos="-0.00216177 0.0201632 -0.157816" quat="0.999971 0.00269833 0.00706272 0" type="cylinder" rgba="0.752941 0.752941 0.752941 1"/>
            <geom name="//unnamed_geom_24" class="reward_collision_sphere" size="0.087831" pos="0 0.00672108 -0.0472345"/>
            <body name="right_shank_pitch_link" pos="0.00211146 0.0125644 -0.337917" quat="1 2.01383e-05 8.23805e-05 2.04614e-06">
              <inertial pos="0.00236663 -0.003538 -0.106552" quat="0.999657 0.00632483 0.00322086 0.0252105" mass="1.1572" diaginertia="0.0116057 0.00146297 0.000929329"/>
              <joint name="right_knee_pitch_joint" class="/" pos="0 0 0" axis="0.0194561 -0.999723 0.0132554" range="-1.91645 0.0842982" armature="0.0851448" damping="0.0193352" frictionloss="0.0804207"/>
              <geom name="//unnamed_geom_25" class="visual" mesh="right_shank_pitch_link"/>
              <geom name="right_shank_pitch_link.STL" class="collision" size="0.0468325 0.0793853" pos="-1.68909e-05 -0.000566289 -0.165036" type="cylinder" rgba="0.752941 0.752941 0.752941 1"/>
              <geom name="//unnamed_geom_27" class="reward_collision_sphere" size="0.0439155"/>
              <geom name="//unnamed_geom_28" class="reward_collision_sphere" size="0.0526986" pos="0 0 -0.103916"/>
              <body name="right_foot_pitch_link" pos="0.0001325 -0.000278464 -0.322053" quat="1 -0.00018779 3.91299e-05 -1.85741e-05">
                <inertial pos="-0.00159153 -0.00275864 -0.00119684" quat="0.00463939 0.71139 0.0109307 0.702697" mass="0.0375946" diaginertia="6.77076e-06 7.44573e-07 3.90763e-06"/>
                <joint name="right_ankle_pitch_joint" class="/" pos="0 0 0" axis="-2.24891e-05 -1 0.000394296" range="-0.569937 1.06029" armature="0.0898807" damping="0.00597564" frictionloss="0.0887188"/>
                <geom name="//unnamed_geom_29" class="visual" mesh="right_foot_pitch_link"/>
                <body name="right_foot_roll_link" pos="0.00109681 -0.00158497 0.000334289" quat="0.999999 0.000747066 0.000572453 -0.000392756">
                  <inertial pos="0.0378227 -0.00106808 -0.0344692" quat="-2.46783e-05 0.72543 0.00118601 0.688295" mass="0.734871" diaginertia="0.00603883 0.000690729 0.000569569"/>
                  <joint name="right_ankle_roll_joint" class="/" pos="0 0 0" axis="-0.999969 0.00781308 0.00127339" range="-0.421423 0.427829" armature="0.0994391" damping="0.00206247" frictionloss="0.0838149"/>
                  <geom name="//unnamed_geom_30" class="visual" mesh="right_foot_roll_link"/>
                  <geom name="right_foot" class="foot" size="0.141362 0.0386714 0.00799296" pos="0.045816 0 -0.0420387"/>
                  <geom name="//unnamed_geom_32" class="reward_collision_sphere" size="0.0439155" pos="0 0 -0.0283407"/>
                  <geom name="//unnamed_geom_33" class="reward_collision_sphere" size="0.0439155" pos="0.122176 0 -0.0283407"/>
                  <site name="right_foot" class="foot" pos="0.045816 0 -0.0420387" size="0.0087831"/>
                </body>
              </body>
            </body>
          </body>
        </body>
      </body>
      <body name="waist_yaw_link" pos="0.000345783 -0.000576909 0.000872601" quat="1 7.301e-05 0.000522251 0.00019105">
        <inertial pos="-0.00330294 -0.0070621 0.0491789" quat="0.98026 0.186613 -0.0238028 0.0608245" mass="1.12371" diaginertia="0.00367039 0.000432832 0.00154421"/>
        <joint name="waist_yaw_joint" class="/" pos="0 0 0" axis="-0.0059732 0.00431228 0.999973" stiffness="7.88462e-05" range="-1.05328 1.05712" armature="0.0913291" damping="0.00885237" frictionloss="0.0872467"/>
        <geom name="//unnamed_geom_34" class="visual" rgba="0.12 0.12 0.12 1" mesh="waist_yaw_link"/>
        <body name="waist_pitch_link" pos="0.00306177 -0.00305668 0.0861738" quat="1 0.000677299 0.000320083 -7.06898e-05">
          <inertial pos="0.00454861 -0.0021852 0.0370088" quat="0.998137 -0.0496327 0.0353851 0.00282747" mass="0.979426" diaginertia="0.00488883 0.00063 0.00131417"/>
          <joint name="waist_pitch_joint" class="/" pos="0 0 0" axis="-0.00849992 -0.99986 0.0143872" range="-1.1882 0.53283" armature="0.0941902" damping="0.000332755" frictionloss="0.0895597"/>
          <geom name="//unnamed_geom_35" class="visual" rgba="0.12 0.12 0.12 1" mesh="waist_pitch_link"/>
          <body name="waist_roll_link" pos="0.00650938 -3.9457e-06 0.0767987" quat="1 0.000423131 0.000210342 -3.49337e-05">
            <inertial pos="-0.0150034 -0.0024302 0.1399" quat="0.998655 -0.00327197 -0.0517317 -0.000825007" mass="4.56344" diaginertia="0.0693985 0.00803863 0.0270523"/>
            <joint name="waist_roll_joint" class="/" pos="0 0 0" axis="-0.999991 -0.00367285 -0.00202398" range="-0.685761 0.708641" armature="0.0876749" damping="0.0114546" frictionloss="0.0926282"/>
            <geom name="//unnamed_geom_36" class="visual" rgba="0.12 0.12 0.12 1" mesh="waist_roll_link"/>
            <geom name="//unnamed_geom_37" class="visual" pos="-0.0022908 0.000386079 0.151481" quat="1 0 0 0" mesh="torso_link"/>
            <geom name="torso_link.STL" class="collision" size="0.13827 0.0265188" pos="-0.0183935 0.00387793 0.139653" type="cylinder" rgba="0.752941 0.752941 0.752941 1"/>
            <geom name="//unnamed_geom_39" class="reward_collision_sphere" size="0.11418" pos="0 0 0.188938"/>
            <body name="left_upper_arm_pitch_link" pos="0.0017157 0.066052 0.196165" quat="0.976611 0.21501 -0.00117149 -0.000165039">
              <inertial pos="0.000749269 0.0361407 -0.000923714" quat="0.698127 0.71405 -0.00587129 -0.0521262" mass="0.54499" diaginertia="0.00222415 0.000264541 0.000367448"/>
              <joint name="left_shoulder_pitch_joint" class="/" pos="0 0 0" axis="0.00439956 0.999881 0.0148148" range="-2.7392 1.92758" armature="0.0952535" damping="0.00751354" frictionloss="0.084363"/>
              <geom name="//unnamed_geom_40" class="visual" mesh="left_upper_arm_pitch_link"/>
              <body name="left_upper_arm_roll_link" pos="0.00093358 0.0600486 -0.000345578" quat="0.976751 -0.214378 9.81233e-05 -0.000242275">
                <inertial pos="0.00532965 0.00807605 -0.0249906" quat="0.889356 0.269149 0.124578 -0.347972" mass="0.413781" diaginertia="0.00115307 0.000138803 0.000267887"/>
                <joint name="left_shoulder_roll_joint" class="/" pos="0 0 0" axis="-0.999992 0.00356525 0.00169864" range="-2.53523 0.563162" armature="0.0948408" damping="0" frictionloss="0.0923975"/>
                <geom name="//unnamed_geom_41" class="visual" mesh="left_upper_arm_roll_link"/>
                <body name="left_upper_arm_yaw_link" pos="0.000833501 0.026729 -0.0652838" quat="1 0.000161348 -6.35085e-05 0.000103127">
                  <inertial pos="-0.00061241 -0.00188721 -0.0833733" quat="0.999984 0.00153117 -0.00523581 0.00139853" mass="0.355757" diaginertia="0.00374687 0.000469536 0.000194135"/>
                  <joint name="left_shoulder_yaw_joint" class="/" pos="0 0 0" axis="-0.00304302 -0.00299132 0.999991" range="-2.92148 2.99302" armature="0.0915763" damping="0.000823307" frictionloss="0.0881101"/>
                  <geom name="//unnamed_geom_42" class="visual" mesh="left_upper_arm_yaw_link"/>
                  <geom name="left_upper_arm_yaw_link.STL" class="collision" size="0.031824 0.0746054" pos="4.02014e-05 -0.000601059 -0.0749517" quat="0.00803418 -0.995528 0.0941277 0" type="cylinder" rgba="0.752941 0.752941 0.752941 1"/>
                  <body name="left_lower_arm_pitch_link" pos="-0.00174039 -0.000157219 -0.166135" quat="0.999999 0.000571857 -0.000956289 -5.0986e-05">
                    <inertial pos="-0.000777104 0.00455534 -0.0221241" quat="0.701217 -0.0913204 0.0918524 0.701083" mass="0.224573" diaginertia="0.000321434 3.94786e-05 7.33954e-05"/>
                    <joint name="left_elbow_pitch_joint" class="/" pos="0 0 0" axis="-0.0130276 0.999915 1.53706e-05" range="-2.28679 2.29257" armature="0.0804545" damping="0.019977" frictionloss="0.0902502"/>
                    <geom name="//unnamed_geom_44" class="visual" mesh="left_lower_arm_pitch_link"/>
                    <body name="left_hand_yaw_link" pos="-0.00130128 0.000570432 -0.0586684" quat="1 0.000177007 -3.64431e-05 -0.00017749">
                      <inertial pos="-0.000720742 -0.00100669 -0.0695834" quat="0.999947 -0.00494072 -0.00291279 0.00850828" mass="0.66406" diaginertia="0.00293353 0.000356963 0.000384272"/>
                      <joint name="left_wrist_yaw_joint" class="/" pos="0 0 0" axis="-0.00964979 -0.0096899 0.999906" range="-2.94257 2.96376" armature="0.0910801" damping="0.00666901" frictionloss="0.0871122"/>
                      <geom name="//unnamed_geom_45" class="visual" mesh="left_hand_yaw_link"/>
                      <geom name="left_hand_yaw_link.STL" class="collision" size="0.036513 0.0611249" pos="0.001109 -0.00103579 -0.071837" type="cylinder" rgba="0.752941 0.752941 0.752941 1"/>
                      <geom name="//unnamed_geom_47" class="reward_collision_sphere" size="0.0439155"/>
                      <body name="left_hand_roll_link" pos="0.00175832 -0.000461811 -0.180702" quat="1 0.000185657 -0.000173882 0.000230824">
                        <inertial pos="-0.00254117 -0.000831254 0.00260809" quat="0.491447 0.498713 0.509926 0.49974" mass="0.00337394" diaginertia="3.95499e-07 4.78427e-08 5.43106e-08"/>
                        <joint name="left_wrist_roll_joint" class="/" pos="0 0 0" axis="-0.999918 0.0062538 -0.0112148" range="-0.941562 0.880625" armature="0.0913823" damping="0.00492135" frictionloss="0.0859586"/>
                        <geom name="//unnamed_geom_48" class="visual" mesh="left_hand_roll_link"/>
                        <body name="left_hand_pitch_link" pos="-0.000804314 0.00315302 2.11358e-05" quat="1 0.000185458 8.58874e-05 -0.000133384">
                          <inertial pos="0.00115817 -0.00929148 -0.049486" quat="0.723693 -0.121028 0.114962 0.669631" mass="0.148217" diaginertia="0.000304293 3.66342e-05 6.82481e-05"/>
                          <joint name="left_wrist_pitch_joint" class="/" pos="0 0 0" axis="0.00355018 0.999991 0.00226805" stiffness="0.00064158" range="-0.598107 0.595937" armature="0.0858733" damping="0.00706318" frictionloss="0.0838396"/>
                          <geom name="//unnamed_geom_49" class="visual" mesh="left_hand_pitch"/>
                          <body name="left_jaw_link" pos="0.00129424 0.00330143 -0.05952" quat="1 0.000186118 -0.000112942 0.000492597">
                            <inertial pos="0.000132468 0.00120122 -0.0319161" quat="0.707112 -0.0232778 0.0334306 0.705927" mass="0.0456034" diaginertia="8.63673e-05 7.65156e-06 2.3969e-05"/>
                            <joint name="left_jaw_joint" class="/" pos="0 0 0" axis="-1 0.0002322 6.57146e-05" range="-0.98355 -0.00405554" armature="0.0783542" damping="0.0128096" frictionloss="0.0867271"/>
                            <geom name="//unnamed_geom_50" class="visual" mesh="left_jaw_link"/>
                            <geom name="//unnamed_geom_51" class="collision" size="0.0316192"/>
                            <geom name="//unnamed_geom_52" class="reward_collision_sphere" size="0.0439155" pos="0 0 -0.0188938"/>
                          </body>
                        </body>
                      </body>
                    </body>
                  </body>
                </body>
              </body>
            </body>
            <body name="right_upper_arm_pitch_link" pos="0.000194833 -0.0651854 0.198505" quat="0.976706 -0.214583 0.000124728 4.07067e-06">
              <inertial pos="0.00341379 -0.0361259 -0.000244683" quat="0.700963 0.71246 0.0301376 0.0120276" mass="0.520989" diaginertia="0.00209976 0.000265632 0.000356373"/>
              <joint name="right_shoulder_pitch_joint" class="/" pos="0 0 0" axis="-0.0018125 -0.999998 -8.87462e-05" range="-1.87578 2.80178" armature="0.088626" damping="0.00543181" frictionloss="0.0887255"/>
              <geom name="//unnamed_geom_53" class="visual" mesh="right_upper_arm_pitch_link"/>
              <body name="right_upper_arm_roll_link" pos="0.0005816 -0.0662805 0.000809102" quat="0.97669 0.214656 2.91091e-05 3.87337e-05">
                <inertial pos="0.00213986 -0.00977556 -0.0226941" quat="0.888776 -0.269715 0.124983 0.34887" mass="0.414994" diaginertia="0.00113401 0.000138216 0.000265367"/>
                <joint name="right_shoulder_roll_joint" class="/" pos="0 0 0" axis="-0.999996 0.000283823 -0.00273704" range="-0.546577 2.54511" armature="0.0912719" damping="0.00740895" frictionloss="0.0906968"/>
                <geom name="//unnamed_geom_54" class="visual" mesh="right_upper_arm_roll_link"/>
                <body name="right_upper_arm_yaw_link" pos="0.000366369 -0.0273362 -0.0667367" quat="1 0.000137959 -0.000325067 -5.32657e-05">
                  <inertial pos="-0.000473236 3.92955e-05 -0.0823568" quat="0.999961 0.00367401 0.00789139 0.00164239" mass="0.36107" diaginertia="0.0037782 0.000486581 0.000196501"/>
                  <joint name="right_shoulder_yaw_joint" class="/" pos="0 0 0" axis="0.000679683 0.00726616 0.999973" range="-2.9753 3.02334" armature="0.0881672" damping="0" frictionloss="0.0771982"/>
                  <geom name="//unnamed_geom_55" class="visual" mesh="right_upper_arm_yaw_link"/>
                  <geom name="right_upper_arm_yaw_link.STL" class="collision" size="0.031824 0.0746054" pos="4.02014e-05 0.000601059 -0.0749517" type="cylinder" rgba="0.752941 0.752941 0.752941 1"/>
                  <body name="right_lower_arm_pitch_link" pos="0.00168889 -0.00117296 -0.167048" quat="1 0.000267048 0.000267364 -0.000836568">
                    <inertial pos="0.00250985 -0.0036879 -0.0245763" quat="0.700373 0.0930232 -0.0921697 0.701662" mass="0.221383" diaginertia="0.000327534 4.18034e-05 7.17469e-05"/>
                    <joint name="right_elbow_pitch_joint" class="/" pos="0 0 0" axis="-0.00222362 -0.999942 0.0105758" range="-2.26308 2.29095" armature="0.0920058" damping="0.00300198" frictionloss="0.0838274"/>
                    <geom name="//unnamed_geom_57" class="visual" mesh="right_lower_arm_pitch_link"/>
                    <body name="right_hand_yaw_link" pos="0.00115646 0.000228864 -0.0561233" quat="1 -0.000153196 -1.01544e-06 5.31674e-05">
                      <inertial pos="-0.000209919 -0.00243315 -0.0677403" quat="0.999701 0.00398409 -0.000735329 0.0240981" mass="0.689564" diaginertia="0.00287733 0.000342953 0.000374746"/>
                      <joint name="right_wrist_yaw_joint" class="/" pos="0 0 0" axis="0.0147828 -0.000878162 0.99989" range="-2.97233 2.98304" armature="0.0790822" damping="0" frictionloss="0.0895033"/>
                      <geom name="//unnamed_geom_58" class="visual" mesh="right_hand_yaw_link"/>
                      <geom name="right_hand_yaw_link.STL" class="collision" size="0.036513 0.0611249" pos="0.001109 0.000430898 -0.071837" type="cylinder" rgba="0.752941 0.752941 0.752941 1"/>
                      <geom name="//unnamed_geom_60" class="reward_collision_sphere" size="0.0439155"/>
                      <body name="right_hand_roll_link" pos="0.00397017 -0.000432134 -0.181934" quat="1 1.33566e-05 -2.89204e-05 9.71095e-05">
                        <inertial pos="-0.00279804 0.000111493 0.000500565" quat="0.500521 0.498633 0.509407 0.491272" mass="0.00329855" diaginertia="3.69617e-07 4.62084e-08 4.95368e-08"/>
                        <joint name="right_wrist_roll_joint" class="/" pos="0 0 0" axis="-0.999987 0.00419628 0.00278849" range="-0.848567 0.972121" armature="0.0979688" damping="0.00953091" frictionloss="0.0888104"/>
                        <geom name="//unnamed_geom_61" class="visual" mesh="right_hand_roll_link"/>
                        <body name="right_hand_pitch_link" pos="0.00116008 -0.00161356 -0.00247441" quat="1 1.00813e-05 1.38351e-05 4.53363e-05">
                          <inertial pos="0.00224331 0.00367642 -0.0528288" quat="0.719446 0.132028 -0.120336 0.671182" mass="0.144507" diaginertia="0.000315211 3.64829e-05 7.10202e-05"/>
                          <joint name="right_wrist_pitch_joint" class="/" pos="0 0 0" axis="0.0142776 -0.999896 0.00204821" range="-0.613704 0.615438" armature="0.0887592" damping="0.000880073" frictionloss="0.0935564"/>
                          <geom name="//unnamed_geom_62" class="visual" mesh="right_hand_pitch"/>
                          <body name="right_jaw_link" pos="0.0031242 0.00116072 -0.0565294" quat="1 0.000230544 -0.000221679 -0.00027216">
                            <inertial pos="-0.00291795 -0.00277687 -0.0345692" quat="0.708656 0.0239048 -0.0261516 0.704664" mass="0.0452653" diaginertia="8.47012e-05 7.58585e-06 2.42461e-05"/>
                            <joint name="right_jaw_joint" class="/" pos="0 0 0" axis="-0.999997 -0.00091271 -0.00231099" range="0.0153454 1.05785" armature="0.0862961" damping="0" frictionloss="0.0992828"/>
                            <geom name="//unnamed_geom_63" class="visual" mesh="right_jaw_link"/>
                            <geom name="//unnamed_geom_64" class="collision" size="0.0316192"/>
                            <geom name="//unnamed_geom_65" class="reward_collision_sphere" size="0.0439155" pos="0 0 -0.0188938"/>
                          </body>
                        </body>
                      </body>
                    </body>
                  </body>
                </body>
              </body>
            </body>
            <body name="head_roll_link" pos="0.000145365 -0.00205321 0.29137" quat="0.999999 0.000543961 -0.000492864 -0.000788424">
              <inertial pos="0.00476477 -0.00265918 -0.000856116" quat="0.00836876 0.705492 0.000879893 0.708668" mass="0.0065349" diaginertia="7.42886e-07 5.81952e-08 3.12342e-07"/>
              <joint name="head_roll_joint" class="/" pos="0 0 0" axis="-0.999997 -0.00171815 -0.00165561" range="-0.36945 0.409361" armature="0.0902339" damping="0" frictionloss="0.0870849"/>
              <geom name="//unnamed_geom_66" class="visual" mesh="head_roll_link"/>
              <body name="head_pitch_link" pos="0.000215794 0.000210581 0.00284904" quat="0.999999 -6.77102e-05 0.000698961 -0.00102182">
                <inertial pos="-0.000794558 -0.00019189 0.0160799" quat="0.664724 0.664723 0.241125 -0.241129" mass="0.0419399" diaginertia="2.76777e-05 3.24564e-06 1.32426e-05"/>
                <joint name="head_pitch_joint" class="/" pos="0 0 0" axis="-0.00382546 -0.999988 -0.00304571" range="-0.87495 0.814013" armature="0.0918007" damping="0.006592" frictionloss="0.0899796"/>
                <geom name="//unnamed_geom_67" class="visual" mesh="head_pitch_link"/>
                <body name="head_yaw_link" pos="-0.000631901 0.00261178 0.0504885" quat="0.999999 -2.13041e-05 9.3823e-05 0.00122091">
                  <inertial pos="0.0257418 -0.00129044 0.0896923" quat="0.707865 -0.140889 -0.137651 0.678329" mass="1.0783" diaginertia="0.0111449 0.00113619 0.0040417"/>
                  <joint name="head_yaw_joint" class="/" pos="0 0 0" axis="0.00118111 0.000804022 0.999999" stiffness="0.000486153" range="-2.71164 2.71535" armature="0.0884323" damping="0.000629109" frictionloss="0.0960127"/>
                  <geom name="//unnamed_geom_68" class="visual" rgba="0.12 0.12 0.12 1" mesh="head_yaw_link"/>
                  <geom name="head_yaw_link.STL" class="collision" size="0.104244" pos="0.0186126 -0.000591471 0.0884421" rgba="0.752941 0.752941 0.752941 1"/>
                  <geom name="//unnamed_geom_70" class="reward_collision_sphere" size="0.087831" pos="0.030544 0 0.094469"/>
                  <camera name="ego_camera" class="/" pos="0.111995 0 0.103916" quat="-0.5 -0.5 0.5 0.5"/>
                </body>
              </body>
            </body>
          </body>
        </body>
      </body>
    </body>
  </worldbody>

  <contact>
    <pair class="/" geom1="floor" geom2="left_foot" name="//unnamed_contact_0"/>
    <pair class="/" geom1="floor" geom2="right_foot" name="//unnamed_contact_1"/>
  </contact>

  <actuator>
    <general name="left_hip_roll" class="/" joint="left_hip_roll_joint" forcerange="-44.0477 44.0477" gainprm="86.6707" biasprm="0 -86.6707 -0.87831"/>
    <general name="left_hip_yaw" class="/" joint="left_hip_yaw_joint" forcerange="-58.2761 58.2761" gainprm="86.6707" biasprm="0 -86.6707 -0.87831"/>
    <general name="left_hip_pitch" class="/" joint="left_hip_pitch_joint" forcerange="-196.398 196.398" gainprm="86.6707" biasprm="0 -86.6707 -0.87831"/>
    <general name="left_knee_pitch" class="/" joint="left_knee_pitch_joint" forcerange="-215.301 215.301" gainprm="86.6707" biasprm="0 -86.6707 -0.87831"/>
    <general name="left_ankle_pitch" class="/" joint="left_ankle_pitch_joint" forcerange="-14.131 14.131" gainprm="86.6707" biasprm="0 -86.6707 -0.87831"/>
    <general name="left_ankle_roll" class="/" joint="left_ankle_roll_joint" forcerange="-26.4474 26.4474" gainprm="86.6707" biasprm="0 -86.6707 -0.87831"/>
    <general name="right_hip_roll" class="/" joint="right_hip_roll_joint" forcerange="-42.2002 42.2002" gainprm="86.6707" biasprm="0 -86.6707 -0.87831"/>
    <general name="right_hip_yaw" class="/" joint="right_hip_yaw_joint" forcerange="-63.2284 63.2284" gainprm="86.6707" biasprm="0 -86.6707 -0.87831"/>
    <general name="right_hip_pitch" class="/" joint="right_hip_pitch_joint" forcerange="-221.839 221.839" gainprm="86.6707" biasprm="0 -86.6707 -0.87831"/>
    <general name="right_knee_pitch" class="/" joint="right_knee_pitch_joint" forcerange="-204.83 204.83" gainprm="86.6707" biasprm="0 -86.6707 -0.87831"/>
    <general name="right_ankle_pitch" class="/" joint="right_ankle_pitch_joint" forcerange="-14.4893 14.4893" gainprm="86.6707" biasprm="0 -86.6707 -0.87831"/>
    <general name="right_ankle_roll" class="/" joint="right_ankle_roll_joint" forcerange="-28.8991 28.8991" gainprm="86.6707" biasprm="0 -86.6707 -0.87831"/>
    <general name="waist_yaw" class="/" joint="waist_yaw_joint" forcerange="-58.1956 58.1956" gainprm="86.6707" biasprm="0 -86.6707 -0.87831"/>
    <general name="waist_pitch" class="/" joint="waist_pitch_joint" forcerange="-64.0622 64.0622" gainprm="86.6707" biasprm="0 -86.6707 -0.87831"/>
    <general name="waist_roll" class="/" joint="waist_roll_joint" forcerange="-59.1138 59.1138" gainprm="86.6707" biasprm="0 -86.6707 -0.87831"/>
    <general name="left_shoulder_pitch" class="/" joint="left_shoulder_pitch_joint" forcerange="-29.8516 29.8516" gainprm="86.6707" biasprm="0 -86.6707 -0.87831"/>
    <general name="left_shoulder_roll" class="/" joint="left_shoulder_roll_joint" forcerange="-36.259 36.259" gainprm="86.6707" biasprm="0 -86.6707 -0.87831"/>
    <general name="left_shoulder_yaw" class="/" joint="left_shoulder_yaw_joint" forcerange="-26.5887 26.5887" gainprm="86.6707" biasprm="0 -86.6707 -0.87831"/>
    <general name="left_elbow_pitch" class="/" joint="left_elbow_pitch_joint" forcerange="-27.5532 27.5532" gainprm="86.6707" biasprm="0 -86.6707 -0.87831"/>
    <general name="left_wrist_yaw" class="/" joint="left_wrist_yaw_joint" forcerange="-8.74143 8.74143" gainprm="86.6707" biasprm="0 -86.6707 -0.87831"/>
    <general name="left_wrist_roll" class="/" joint="left_wrist_roll_joint" forcerange="-3.48273 3.48273" gainprm="86.6707" biasprm="0 -86.6707 -0.87831"/>
    <general name="left_wrist_pitch" class="/" joint="left_wrist_pitch_joint" forcerange="-3.79872 3.79872" gainprm="86.6707" biasprm="0 -86.6707 -0.87831"/>
    <general name="left_jaw" class="/" joint="left_jaw_joint" forcerange="-3.52725 3.52725" gainprm="86.6707" biasprm="0 -86.6707 -0.87831"/>
    <general name="right_shoulder_pitch" class="/" joint="right_shoulder_pitch_joint" forcerange="-30.3483 30.3483" gainprm="86.6707" biasprm="0 -86.6707 -0.87831"/>
    <general name="right_shoulder_roll" class="/" joint="right_shoulder_roll_joint" forcerange="-33.1194 33.1194" gainprm="86.6707" biasprm="0 -86.6707 -0.87831"/>
    <general name="right_shoulder_yaw" class="/" joint="right_shoulder_yaw_joint" forcerange="-26.2218 26.2218" gainprm="86.6707" biasprm="0 -86.6707 -0.87831"/>
    <general name="right_elbow_pitch" class="/" joint="right_elbow_pitch_joint" forcerange="-23.4183 23.4183" gainprm="86.6707" biasprm="0 -86.6707 -0.87831"/>
    <general name="right_wrist_yaw" class="/" joint="right_wrist_yaw_joint" forcerange="-9.17347 9.17347" gainprm="86.6707" biasprm="0 -86.6707 -0.87831"/>
    <general name="right_wrist_roll" class="/" joint="right_wrist_roll_joint" forcerange="-3.5266 3.5266" gainprm="86.6707" biasprm="0 -86.6707 -0.87831"/>
    <general name="right_wrist_pitch" class="/" joint="right_wrist_pitch_joint" forcerange="-3.78354 3.78354" gainprm="86.6707" biasprm="0 -86.6707 -0.87831"/>
    <general name="right_jaw" class="/" joint="right_jaw_joint" forcerange="-3.48819 3.48819" gainprm="86.6707" biasprm="0 -86.6707 -0.87831"/>
    <general name="head_roll" class="/" joint="head_roll_joint" forcerange="-3.79681 3.79681" gainprm="86.6707" biasprm="0 -86.6707 -0.87831"/>
    <general name="head_pitch" class="/" joint="head_pitch_joint" forcerange="-3.69953 3.69953" gainprm="86.6707" biasprm="0 -86.6707 -0.87831"/>
    <general name="head_yaw" class="/" joint="head_yaw_joint" forcerange="-3.50168 3.50168" gainprm="86.6707" biasprm="0 -86.6707 -0.87831"/>
  </actuator>

  <sensor>
    <gyro site="imu" name="imu_angular_velocity"/>
    <velocimeter site="imu" name="imu_linear_velocity"/>
    <framelinvel objtype="site" objname="left_foot" name="left_foot_global_linear_velocity"/>
    <framelinvel objtype="site" objname="right_foot" name="right_foot_global_linear_velocity"/>
  </sensor>

  <keyframe>
    <key name="home" qpos="0 0 0.8665 1 0 0 0 0 0 -0.4 0.8 -0.4 0 0 0 0.4 -0.8 0.4 0 0 0 0 0 -0.2 0 -0.785 0 0 0 0 0 0.2 0 0.785 0 0 0 0 0 0 0"/>
  </keyframe>
</mujoco>
