<mujoco model="GR1T2_jaw">
  <compiler angle="radian" assetdir="assets" balanceinertia="true" inertiafromgeom="false"/>

  <option timestep="0.005" density="1.2" viscosity="2e-05"/>

  <size nkey="1"/>

  <visual>
    <quality shadowsize="8192"/>
    <map shadowclip="0.5"/>
  </visual>

  <default>
    <default class="/">
      <joint armature="0.1" damping="0.01" frictionloss="0.1"/>
      <geom contype="0" conaffinity="0" group="1" solref="-1000 -80"/>
      <site size="0.01 0.005 0.005" group="5"/>
      <general forcelimited="true" biastype="affine" gainprm="80" biasprm="0 -80 -2"/>
      <default class="visual">
        <geom type="mesh" density="0" rgba="0.18 0.18 0.18 1"/>
      </default>
      <default class="collision">
        <geom group="3"/>
      </default>
      <default class="foot">
        <geom size="0.126 0.045 0.01" type="box" condim="6" group="4" priority="1" solimp="0.015 1 0.01"/>
      </default>
      <default class="reward_collision_sphere">
        <geom group="5" rgba="1 0 0 1"/>
      </default>
    </default>
  </default>

  <asset>
    <texture type="skybox" colorspace="auto" name="//unnamed_texture_0" builtin="gradient" rgb1="0.95 0.95 0.95" rgb2="0.95 0.95 0.95" width="100" height="600"/>
    <texture type="2d" colorspace="auto" name="texplane" builtin="checker" rgb1="0.345 0.575 0.748" rgb2="0.345 0.575 0.748" markrgb="1 1 1" width="512" height="512"/>
    <material name="MatPlane" class="/" texture="texplane" texuniform="true" texrepeat="2 2" specular="0.9"/>
    <mesh name="base_link" class="/" file="base_link.STL"/>
    <mesh name="left_thigh_roll_link" class="/" file="left_thigh_roll_link.STL"/>
    <mesh name="left_thigh_yaw_link" class="/" file="left_thigh_yaw_link.STL"/>
    <mesh name="left_thigh_pitch_link" class="/" file="left_thigh_pitch_link.STL"/>
    <mesh name="left_shank_pitch_link" class="/" file="left_shank_pitch_link.STL"/>
    <mesh name="left_foot_pitch_link" class="/" file="left_foot_pitch_link.STL"/>
    <mesh name="left_foot_roll_link" class="/" file="left_foot_roll_link.STL"/>
    <mesh name="right_thigh_roll_link" class="/" file="right_thigh_roll_link.STL"/>
    <mesh name="right_thigh_yaw_link" class="/" file="right_thigh_yaw_link.STL"/>
    <mesh name="right_thigh_pitch_link" class="/" file="right_thigh_pitch_link.STL"/>
    <mesh name="right_shank_pitch_link" class="/" file="right_shank_pitch_link.STL"/>
    <mesh name="right_foot_pitch_link" class="/" file="right_foot_pitch_link.STL"/>
    <mesh name="right_foot_roll_link" class="/" file="right_foot_roll_link.STL"/>
    <mesh name="waist_yaw_link" class="/" file="waist_yaw_link.STL"/>
    <mesh name="waist_pitch_link" class="/" file="waist_pitch_link.STL"/>
    <mesh name="waist_roll_link" class="/" file="waist_roll_link.STL"/>
    <mesh name="torso_link" class="/" file="torso_link.STL"/>
    <mesh name="left_upper_arm_pitch_link" class="/" file="left_upper_arm_pitch_link.STL"/>
    <mesh name="left_upper_arm_roll_link" class="/" file="left_upper_arm_roll_link.STL"/>
    <mesh name="left_upper_arm_yaw_link" class="/" file="left_upper_arm_yaw_link.STL"/>
    <mesh name="left_lower_arm_pitch_link" class="/" file="left_lower_arm_pitch_link.STL"/>
    <mesh name="left_hand_yaw_link" class="/" file="left_hand_yaw_link.STL"/>
    <mesh name="left_hand_roll_link" class="/" file="left_hand_roll_link.STL"/>
    <mesh name="left_hand_pitch" class="/" file="left_hand_pitch.STL"/>
    <mesh name="left_jaw_link" class="/" file="left_jaw_link.STL"/>
    <mesh name="right_upper_arm_pitch_link" class="/" file="right_upper_arm_pitch_link.STL"/>
    <mesh name="right_upper_arm_roll_link" class="/" file="right_upper_arm_roll_link.STL"/>
    <mesh name="right_upper_arm_yaw_link" class="/" file="right_upper_arm_yaw_link.STL"/>
    <mesh name="right_lower_arm_pitch_link" class="/" file="right_lower_arm_pitch_link.STL"/>
    <mesh name="right_hand_yaw_link" class="/" file="right_hand_yaw_link.STL"/>
    <mesh name="right_hand_roll_link" class="/" file="right_hand_roll_link.STL"/>
    <mesh name="right_hand_pitch" class="/" file="right_hand_pitch.STL"/>
    <mesh name="right_jaw_link" class="/" file="right_jaw_link.STL"/>
    <mesh name="head_roll_link" class="/" file="head_roll_link.STL"/>
    <mesh name="head_pitch_link" class="/" file="head_pitch_link.STL"/>
    <mesh name="head_yaw_link" class="/" file="head_yaw_link.STL"/>
    <mesh name="imu_link" class="/" file="imu_link.STL"/>
  </asset>

  <worldbody>
    <geom name="floor" class="/" size="100 100 0.125" type="plane" group="0" material="MatPlane"/>
    <light name="toplight_shadow" class="/" pos="0 0 5" dir="0.0990148 0.0990148 -0.990148" type="directional" ambient="0.04 0.04 0.04" diffuse="0.55 0.55 0.55" specular="0.12 0.12 0.12"/>
    <light name="toplight_fill" class="/" pos="0 0 5" dir="0.0990148 0.0990148 -0.990148" type="directional" castshadow="false" ambient="0.04 0.04 0.04" diffuse="0.3 0.3 0.3" specular="0.08 0.08 0.08"/>
    <body name="trunk" pos="-0.000923428 -0.00130455 0.00113766" quat="1 2.36527e-05 -0.000480338 0.000195789">
      <inertial pos="-0.0650863 0.000986625 -0.0118606" quat="0.99998 -0.00507829 0.00371321 -0.00105548" mass="3.64558" diaginertia="0.063616 0.00183163 0.0814171"/>
      <joint name="//unnamed_joint_0" type="free"/>
      <geom name="//unnamed_geom_1" class="visual" rgba="0.12 0.12 0.12 1" mesh="base_link"/>
      <geom name="base_link.STL" class="collision" size="0.117471 0.0657932" pos="-0.0461439 0.000245998 0.0104159" quat="0.706838 -0.707359 0.00477667 0" type="cylinder" rgba="0.752941 0.752941 0.752941 1"/>
      <geom name="//unnamed_geom_3" class="visual" pos="0 0 -0.0674032" quat="1 0 0 0" rgba="0.12 0.12 0.12 1" mesh="imu_link"/>
      <geom name="//unnamed_geom_4" class="reward_collision_sphere" size="0.0767823" pos="0 0.0664783 0.113093"/>
      <geom name="//unnamed_geom_5" class="reward_collision_sphere" size="0.0767823" pos="0 -0.0664783 0.113093"/>
      <site name="imu" class="/" pos="-0.0108272 -0.00483094 -0.0668788" size="0.00959779"/>
      <camera name="track" class="/" pos="0 -1.32957 0" quat="0.707107 0.707107 0 0" mode="trackcom"/>
      <body name="left_thigh_roll_link" pos="-0.0384162 0.0696299 -0.0309322" quat="1 -0.000649677 -1.97028e-05 0.000275299">
        <inertial pos="0.00115664 -0.00129877 0.00487404" quat="-0.0306478 0.704026 -0.0343712 0.70868" mass="1.3553" diaginertia="0.00396972 0.000322003 0.00293886"/>
        <joint name="left_hip_roll_joint" class="/" pos="0 0 0" axis="-0.999995 0.00149086 0.00280534" range="-0.78564 0.104976" armature="0.0858787" damping="0.00887593" frictionloss="0.0832438"/>
        <geom name="//unnamed_geom_6" class="visual" mesh="left_thigh_roll_link"/>
        <body name="left_thigh_yaw_link" pos="0.0338635 -0.0012433 0.00312926" quat="0.999999 -0.000444242 -0.000950758 -0.000254512">
          <inertial pos="-0.00535959 0.0257095 -0.125482" quat="0.570591 0.086262 -0.206124 0.790251" mass="3.01234" diaginertia="0.0353464 0.00257311 0.016462"/>
          <joint name="left_hip_yaw_joint" class="/" pos="0 0 0" axis="0.00685944 -7.11577e-05 -0.999976" range="-0.716055 0.650268" armature="0.108736" damping="0.000397229" frictionloss="0.0934022"/>
          <geom name="//unnamed_geom_7" class="visual" mesh="left_thigh_yaw_link"/>
          <body name="left_thigh_pitch_link" pos="-0.0012398 0.0128061 -0.157956" quat="1 -0.000407501 0.000360672 0.000216203">
            <inertial pos="0.00354002 -0.0180899 -0.073578" quat="0.999904 -0.0135742 -0.000720464 0.00253005" mass="6.91151" diaginertia="0.132322 0.0112381 0.0502365"/>
            <joint name="left_hip_pitch_joint" class="/" pos="0 0 0" axis="0.00188211 0.999954 -0.00936589" range="-1.74724 0.758133" armature="0.0890072" damping="0.0177902" frictionloss="0.0916045"/>
            <geom name="//unnamed_geom_8" class="visual" mesh="left_thigh_pitch_link"/>
            <geom name="left_thigh_pitch_link.STL" class="collision" size="0.0787018 0.11989" pos="0.000758593 -0.0199435 -0.188928" type="cylinder" rgba="0.752941 0.752941 0.752941 1"/>
            <geom name="//unnamed_geom_10" class="reward_collision_sphere" size="0.0959779" pos="0 -0.00664783 -0.0565463"/>
            <body name="left_shank_pitch_link" pos="0.000586186 -0.0140077 -0.408361" quat="1 0.000445462 0.000216651 -0.000382762">
              <inertial pos="-0.000454023 0.00133547 -0.129046" quat="0.999685 -0.00797937 0.0080116 -0.0224127" mass="1.66793" diaginertia="0.0169101 0.00142726 0.00243823"/>
              <joint name="left_knee_pitch_joint" class="/" pos="0 0 0" axis="-0.00479864 0.999955 -0.00815494" stiffness="0.00117022" range="-0.044288 1.96489" armature="0.0806258" damping="0.00785812" frictionloss="0.101179"/>
              <geom name="//unnamed_geom_11" class="visual" mesh="left_shank_pitch_link"/>
              <geom name="left_shank_pitch_link.STL" class="collision" size="0.0511767 0.0867496" pos="-1.79775e-05 -0.000560111 -0.197563" quat="0.00125538 -0.202712 0.979238 0" type="cylinder" rgba="0.752941 0.752941 0.752941 1"/>
              <geom name="//unnamed_geom_13" class="reward_collision_sphere" size="0.0479889"/>
              <geom name="//unnamed_geom_14" class="reward_collision_sphere" size="0.0575867" pos="0 0 -0.124402"/>
              <body name="left_foot_pitch_link" pos="0.00185092 -0.00323451 -0.384564" quat="1 -0.000319935 0.000306657 0.000219646">
                <inertial pos="0.00268857 -0.00285176 0.00251923" quat="0.00774967 0.707636 -0.00133177 0.706533" mass="0.0486038" diaginertia="9.37326e-06 7.32167e-07 9.70996e-06"/>
                <joint name="left_ankle_pitch_joint" class="/" pos="0 0 0" axis="-0.000139395 0.999997 0.0023545" range="-1.04717 0.536857" armature="0.103707" damping="0.00258522" frictionloss="0.106644"/>
                <geom name="//unnamed_geom_15" class="visual" mesh="left_foot_pitch_link"/>
                <body name="left_foot_roll_link" pos="-0.00191148 -1.86558e-06 0.00216718" quat="0.999999 0.000290129 0.000893562 -0.00105212">
                  <inertial pos="0.0403017 -0.00311256 -0.0432474" quat="-0.00140984 0.729247 -0.00724278 0.684211" mass="0.936805" diaginertia="0.00824278 0.000662401 0.00143985"/>
                  <joint name="left_ankle_roll_joint" class="/" pos="0 0 0" axis="-0.999982 -0.00599694 -0.000626161" range="-0.474204 0.441145" armature="0.108835" damping="0.014398" frictionloss="0.103055"/>
                  <geom name="//unnamed_geom_16" class="visual" mesh="left_foot_roll_link"/>
                  <geom name="left_foot" class="foot" size="0.142648 0.0367961 0.0106649" pos="0.0487632 0 -0.0503262"/>
                  <geom name="//unnamed_geom_18" class="reward_collision_sphere" size="0.0479889" pos="0 0 -0.0339278"/>
                  <geom name="//unnamed_geom_19" class="reward_collision_sphere" size="0.0479889" pos="0.130035 0 -0.0339278"/>
                  <site name="left_foot" class="foot" pos="0.0487632 0 -0.0503262" size="0.00959779"/>
                </body>
              </body>
            </body>
          </body>
        </body>
      </body>
      <body name="right_thigh_roll_link" pos="-0.0319544 -0.0727273 -0.0319511" quat="1 -4.051e-05 -8.6278e-05 1.43935e-05">
        <inertial pos="0.000967249 -0.00348304 0.00147093" quat="0.0363359 0.701304 0.00959161 0.711872" mass="1.30921" diaginertia="0.00378693 0.000315567 0.00282763"/>
        <joint name="right_hip_roll_joint" class="/" pos="0 0 0" axis="-0.99992 0.00386224 -0.0120091" range="-0.11776 0.794314" armature="0.0856555" damping="0.0207193" frictionloss="0.104429"/>
        <geom name="//unnamed_geom_20" class="visual" mesh="right_thigh_roll_link"/>
        <body name="right_thigh_yaw_link" pos="0.0348974 -0.00149657 0.00289704" quat="1 -0.000233938 -0.000468784 -0.000175399">
          <inertial pos="-0.00547954 -0.02321 -0.126995" quat="0.680088 -0.145147 0.144032 0.704037" mass="3.17444" diaginertia="0.0358442 0.00244027 0.0166627"/>
          <joint name="right_hip_yaw_joint" class="/" pos="0 0 0" axis="-0.00228507 -0.000772114 -0.999997" range="-0.68419 0.688802" armature="0.0836794" damping="0.00283556" frictionloss="0.0988063"/>
          <geom name="//unnamed_geom_21" class="visual" mesh="right_thigh_yaw_link"/>
          <body name="right_thigh_pitch_link" pos="0.00259475 -0.0139284 -0.161117" quat="0.999999 -0.000565473 -0.000835286 -0.000677424">
            <inertial pos="0.00083337 0.0161218 -0.0723058" quat="0.999764 -0.0164111 -0.0133203 0.0050121" mass="7.33594" diaginertia="0.143668 0.0121039 0.0515795"/>
            <joint name="right_hip_pitch_joint" class="/" pos="0 0 0" axis="-0.0112061 -0.999937 0.000566526" range="-0.668308 1.70918" armature="0.0848201" damping="0.016216" frictionloss="0.0858256"/>
            <geom name="//unnamed_geom_22" class="visual" mesh="right_thigh_pitch_link"/>
            <geom name="right_thigh_pitch_link.STL" class="collision" size="0.0787018 0.119887" pos="-0.00230083 0.0199435 -0.188928" quat="0.999971 0.00269833 0.00706272 0" type="cylinder" rgba="0.752941 0.752941 0.752941 1"/>
            <geom name="//unnamed_geom_24" class="reward_collision_sphere" size="0.0959779" pos="0 0.00664783 -0.0565463"/>
            <body name="right_shank_pitch_link" pos="0.00297224 0.0107337 -0.405124" quat="1 0.000112093 -0.000836843 -5.37868e-05">
              <inertial pos="-0.000275276 -0.00144222 -0.127995" quat="0.99939 0.0101242 0.0128613 0.0308641" mass="1.459" diaginertia="0.0155286 0.00129846 0.0022185"/>
              <joint name="right_knee_pitch_joint" class="/" pos="0 0 0" axis="-0.00035897 -0.999594 0.0284763" range="-1.92558 0.0527546" armature="0.0936301" damping="0.0118138" frictionloss="0.0829311"/>
              <geom name="//unnamed_geom_25" class="visual" mesh="right_shank_pitch_link"/>
              <geom name="right_shank_pitch_link.STL" class="collision" size="0.0511764 0.0867487" pos="-1.79775e-05 -0.000560118 -0.197572" type="cylinder" rgba="0.752941 0.752941 0.752941 1"/>
              <geom name="//unnamed_geom_27" class="reward_collision_sphere" size="0.0479889"/>
              <geom name="//unnamed_geom_28" class="reward_collision_sphere" size="0.0575867" pos="0 0 -0.124402"/>
              <body name="right_foot_pitch_link" pos="0.00113069 -0.000554356 -0.38368" quat="1 -0.000123962 0.000555854 -0.000179768">
                <inertial pos="-0.00243477 -0.00116282 -0.00291336" quat="-0.00250871 0.708358 -0.004646 0.705833" mass="0.0495072" diaginertia="9.33238e-06 7.01617e-07 1.01163e-05"/>
                <joint name="right_ankle_pitch_joint" class="/" pos="0 0 0" axis="-0.00561786 -0.999977 0.00377135" stiffness="0.00220954" range="-0.573904 1.06286" armature="0.109376" damping="0" frictionloss="0.0843365"/>
                <geom name="//unnamed_geom_29" class="visual" mesh="right_foot_pitch_link"/>
                <body name="right_foot_roll_link" pos="-0.000772622 -0.000759765 0.000270607" quat="0.999999 0.000364555 -0.00133883 -0.000827731">
                  <inertial pos="0.0426207 -0.000831116 -0.0407081" quat="-0.00103966 0.725947 0.000567802 0.68775" mass="0.912641" diaginertia="0.00833842 0.000659516 0.00137698"/>
                  <joint name="right_ankle_roll_joint" class="/" pos="0 0 0" axis="-1 -0.0001957 -0.00059189" stiffness="0.00747613" range="-0.395669 0.463844" armature="0.0980562" damping="0.00290719" frictionloss="0.103622"/>
                  <geom name="//unnamed_geom_30" class="visual" mesh="right_foot_roll_link"/>
                  <geom name="right_foot" class="foot" size="0.142348 0.0393777 0.00884173" pos="0.0487632 0 -0.0503262"/>
                  <geom name="//unnamed_geom_32" class="reward_collision_sphere" size="0.0479889" pos="0 0 -0.0339278"/>
                  <geom name="//unnamed_geom_33" class="reward_collision_sphere" size="0.0479889" pos="0.130035 0 -0.0339278"/>
                  <site name="right_foot" class="foot" pos="0.0487632 0 -0.0503262" size="0.00959779"/>
                </body>
              </body>
            </body>
          </body>
        </body>
      </body>
      <body name="waist_yaw_link" pos="0.000795181 -0.00395189 0.00198074" quat="0.999999 -0.00011616 -0.00123797 -0.000158155">
        <inertial pos="-0.00507249 -0.00525267 0.0589402" quat="0.979421 0.189865 -0.0309266 0.0610752" mass="1.47194" diaginertia="0.00515546 0.000408941 0.00379842"/>
        <joint name="waist_yaw_joint" class="/" pos="0 0 0" axis="0.00913629 0.00849157 0.999922" range="-1.04353 1.02067" armature="0.0967227" damping="0.00851341" frictionloss="0.0966976"/>
        <geom name="//unnamed_geom_34" class="visual" rgba="0.12 0.12 0.12 1" mesh="waist_yaw_link"/>
        <body name="waist_pitch_link" pos="0.000624809 -0.00267105 0.0995992" quat="1 3.65557e-05 -0.000309257 -0.000546828">
          <inertial pos="0.00228254 -0.00336748 0.0440118" quat="0.997699 -0.042603 0.0525469 0.00444467" mass="1.30222" diaginertia="0.00686606 0.000586108 0.00335939"/>
          <joint name="waist_pitch_joint" class="/" pos="0 0 0" axis="-0.00855105 -0.999955 -0.004116" range="-1.22156 0.542148" armature="0.10801" damping="0" frictionloss="0.0982502"/>
          <geom name="//unnamed_geom_35" class="visual" rgba="0.12 0.12 0.12 1" mesh="waist_pitch_link"/>
          <body name="waist_roll_link" pos="0.00838732 -0.00198248 0.0906883" quat="1 -0.000201266 -1.52554e-05 6.97012e-05">
            <inertial pos="-0.015546 -0.000812055 0.16448" quat="0.998537 -0.0106345 -0.0524601 0.00761852" mass="6.08193" diaginertia="0.0968273 0.00777983 0.0669277"/>
            <joint name="waist_roll_joint" class="/" pos="0 0 0" axis="-0.999903 -0.00628139 0.0124439" range="-0.66448 0.656227" armature="0.102796" damping="0.0197825" frictionloss="0.10974"/>
            <geom name="//unnamed_geom_36" class="visual" rgba="0.12 0.12 0.12 1" mesh="waist_roll_link"/>
            <geom name="//unnamed_geom_37" class="visual" pos="-0.00243816 0.000381871 0.181344" quat="1 0 0 0" mesh="torso_link"/>
            <geom name="torso_link.STL" class="collision" size="0.151095 0.0289786" pos="-0.0195767 0.00383567 0.167184" type="cylinder" rgba="0.752941 0.752941 0.752941 1"/>
            <geom name="//unnamed_geom_39" class="reward_collision_sphere" size="0.124771" pos="0 0 0.226185"/>
            <body name="left_upper_arm_pitch_link" pos="-0.000414991 0.0656996 0.234411" quat="0.976654 0.214816 8.40648e-05 -0.000493188">
              <inertial pos="0.00340165 0.0333772 0.000663274" quat="0.698748 0.71348 0.000511445 -0.0519449" mass="0.706668" diaginertia="0.00308839 0.000250959 0.000917555"/>
              <joint name="left_shoulder_pitch_joint" class="/" pos="0 0 0" axis="0.00143967 0.999946 -0.0103019" range="-2.75148 1.93513" armature="0.09678" damping="0.0174567" frictionloss="0.0954273"/>
              <geom name="//unnamed_geom_40" class="visual" mesh="left_upper_arm_pitch_link"/>
              <body name="left_upper_arm_roll_link" pos="0.00139621 0.0614399 0.00181296" quat="0.976783 -0.214231 0.000762339 -0.000474483">
                <inertial pos="0.00539418 0.00971469 -0.0288051" quat="0.889508 0.268962 0.124049 -0.347918" mass="0.543249" diaginertia="0.00148708 0.000129501 0.000641936"/>
                <joint name="left_shoulder_roll_joint" class="/" pos="0 0 0" axis="-0.999991 -0.0038422 -0.00159508" stiffness="0.00588742" range="-2.51925 0.5222" armature="0.101604" damping="0.00361973" frictionloss="0.0927488"/>
                <geom name="//unnamed_geom_41" class="visual" mesh="left_upper_arm_roll_link"/>
                <body name="left_upper_arm_yaw_link" pos="0.00382911 0.0256106 -0.0772446" quat="1 -1.89314e-05 -0.000225725 4.5205e-05">
                  <inertial pos="0.0021177 0.00062974 -0.097024" quat="0.999808 0.013305 0.00887267 -0.0113606" mass="0.462996" diaginertia="0.00528911 0.000451327 0.000486122"/>
                  <joint name="left_shoulder_yaw_joint" class="/" pos="0 0 0" axis="-0.00159342 0.00100951 0.999998" range="-2.92992 2.94231" armature="0.110564" damping="0.0159914" frictionloss="0.0959355"/>
                  <geom name="//unnamed_geom_42" class="visual" mesh="left_upper_arm_yaw_link"/>
                  <geom name="left_upper_arm_yaw_link.STL" class="collision" size="0.0347758 0.0815255" pos="4.27874e-05 -0.000594509 -0.0897277" quat="0.00803418 -0.995528 0.0941277 0" type="cylinder" rgba="0.752941 0.752941 0.752941 1"/>
                  <body name="left_lower_arm_pitch_link" pos="-0.00142579 0.00259965 -0.201935" quat="0.999999 0.00107231 -0.000698404 5.74687e-05">
                    <inertial pos="0.000515932 0.00704522 -0.028413" quat="0.701072 -0.0909604 0.0908796 0.701402" mass="0.290452" diaginertia="0.000438201 3.81803e-05 0.00017641"/>
                    <joint name="left_elbow_pitch_joint" class="/" pos="0 0 0" axis="-0.00969628 0.999801 0.0174267" range="-2.28488 2.28703" armature="0.0967598" damping="0.0186225" frictionloss="0.0919948"/>
                    <geom name="//unnamed_geom_44" class="visual" mesh="left_lower_arm_pitch_link"/>
                    <body name="left_hand_yaw_link" pos="0.000573062 0.0032112 -0.0692978" quat="1 0.000132291 -5.2661e-05 -8.98175e-05">
                      <inertial pos="0.000981012 -0.00209157 -0.0806554" quat="0.99998 0.00456293 -0.00397424 -0.00169999" mass="0.895711" diaginertia="0.00400252 0.000346159 0.000921877"/>
                      <joint name="left_wrist_yaw_joint" class="/" pos="0 0 0" axis="0.00126998 0.010416 0.999945" range="-2.91519 2.99418" armature="0.087059" damping="0.00816067" frictionloss="0.107688"/>
                      <geom name="//unnamed_geom_45" class="visual" mesh="left_hand_yaw_link"/>
                      <geom name="left_hand_yaw_link.STL" class="collision" size="0.0398998 0.0667945" pos="0.00118034 -0.0010245 -0.0859989" type="cylinder" rgba="0.752941 0.752941 0.752941 1"/>
                      <geom name="//unnamed_geom_47" class="reward_collision_sphere" size="0.0479889"/>
                      <body name="left_hand_roll_link" pos="0.00186883 0.00156422 -0.214885" quat="0.999999 -0.000281645 -0.000837033 -0.000698158">
                        <inertial pos="-0.00162575 -0.000911372 0.000833621" quat="0.498536 0.499559 0.500859 0.501042" mass="0.00444065" diaginertia="5.32179e-07 4.3871e-08 1.32493e-07"/>
                        <joint name="left_wrist_roll_joint" class="/" pos="0 0 0" axis="-0.999954 0.00946883 -0.00153533" stiffness="0.000818085" range="-0.997922 0.860695" armature="0.101946" damping="0.00104654" frictionloss="0.0827678"/>
                        <geom name="//unnamed_geom_48" class="visual" mesh="left_hand_roll_link"/>
                        <body name="left_hand_pitch_link" pos="-0.000269617 0.00196891 0.000454932" quat="0.999999 -0.000834504 0.000209167 0.000968753">
                          <inertial pos="0.00232917 -0.0106905 -0.0577505" quat="0.723445 -0.121214 0.114527 0.669938" mass="0.192967" diaginertia="0.000421418 3.58033e-05 0.000171379"/>
                          <joint name="left_wrist_pitch_joint" class="/" pos="0 0 0" axis="-0.00136836 0.999981 -0.00601229" range="-0.65592 0.627408" armature="0.0828429" damping="0" frictionloss="0.0962794"/>
                          <geom name="//unnamed_geom_49" class="visual" mesh="left_hand_pitch"/>
                          <body name="left_jaw_link" pos="0.00222084 0.0016089 -0.0711412" quat="1 -1.48203e-05 -0.000156182 -0.000105473">
                            <inertial pos="0.00248209 0.00504929 -0.0401755" quat="0.708782 -0.024332 0.0311838 0.704318" mass="0.0607683" diaginertia="0.00012196 7.27384e-06 5.77955e-05"/>
                            <joint name="left_jaw_joint" class="/" pos="0 0 0" axis="-0.999997 -0.00221934 0.000977153" range="-0.98942 -0.010501" armature="0.0917809" damping="0.0236517" frictionloss="0.097259"/>
                            <geom name="//unnamed_geom_50" class="visual" mesh="left_jaw_link"/>
                            <geom name="//unnamed_geom_51" class="collision" size="0.034552"/>
                            <geom name="//unnamed_geom_52" class="reward_collision_sphere" size="0.0479889" pos="0 0 -0.0226185"/>
                          </body>
                        </body>
                      </body>
                    </body>
                  </body>
                </body>
              </body>
            </body>
            <body name="right_upper_arm_pitch_link" pos="0.00168251 -0.065253 0.23473" quat="0.976626 -0.214944 0.000242527 0.000716892">
              <inertial pos="0.00459265 -0.0366487 0.000220012" quat="0.704409 0.708998 0.0206725 0.0265201" mass="0.696156" diaginertia="0.00301423 0.000250581 0.000877317"/>
              <joint name="right_shoulder_pitch_joint" class="/" pos="0 0 0" axis="0.00834111 -0.999946 0.00623368" range="-1.87054 2.81355" armature="0.0951699" damping="0" frictionloss="0.093532"/>
              <geom name="//unnamed_geom_53" class="visual" mesh="right_upper_arm_pitch_link"/>
              <body name="right_upper_arm_roll_link" pos="-0.000989958 -0.0660714 -0.00109601" quat="0.976814 0.214087 -0.000490176 -0.000492346">
                <inertial pos="0.00261027 -0.0109636 -0.0285952" quat="0.888735 -0.267662 0.127045 0.349809" mass="0.52917" diaginertia="0.00151139 0.000125596 0.000635641"/>
                <joint name="right_shoulder_roll_joint" class="/" pos="0 0 0" axis="-0.999928 -0.0120327 -0.000118438" range="-0.520571 2.54389" armature="0.0875346" damping="0.0182331" frictionloss="0.109386"/>
                <geom name="//unnamed_geom_54" class="visual" mesh="right_upper_arm_roll_link"/>
                <body name="right_upper_arm_yaw_link" pos="-0.00204382 -0.0259608 -0.0786787" quat="1 -4.81241e-05 0.000105937 -0.000484702">
                  <inertial pos="0.000104988 -0.00169637 -0.101128" quat="0.999968 -0.00730547 -0.000867388 0.00322375" mass="0.495423" diaginertia="0.00538876 0.000460055 0.000489283"/>
                  <joint name="right_shoulder_yaw_joint" class="/" pos="0 0 0" axis="-0.00751656 0.014232 0.99987" range="-2.97902 3.02189" armature="0.0996945" damping="0" frictionloss="0.0856982"/>
                  <geom name="//unnamed_geom_55" class="visual" mesh="right_upper_arm_yaw_link"/>
                  <geom name="right_upper_arm_yaw_link.STL" class="collision" size="0.0347758 0.0815255" pos="4.27874e-05 0.000594509 -0.0897277" type="cylinder" rgba="0.752941 0.752941 0.752941 1"/>
                  <body name="right_lower_arm_pitch_link" pos="-0.00156869 0.0010529 -0.202115" quat="0.999999 -0.000424416 0.00104777 0.000287312">
                    <inertial pos="0.000159683 -0.00354226 -0.0267217" quat="0.701444 0.0943654 -0.091818 0.700458" mass="0.280832" diaginertia="0.000432923 3.90401e-05 0.000178007"/>
                    <joint name="right_elbow_pitch_joint" class="/" pos="0 0 0" axis="-0.0155153 -0.999849 0.00782761" range="-2.21103 2.24075" armature="0.0953475" damping="0.0157461" frictionloss="0.0963577"/>
                    <geom name="//unnamed_geom_57" class="visual" mesh="right_lower_arm_pitch_link"/>
                    <body name="right_hand_yaw_link" pos="-0.00125923 0.00149209 -0.0679152" quat="1 2.17626e-05 -0.00014896 -2.56171e-06">
                      <inertial pos="-0.000393836 -0.00469368 -0.0838504" quat="0.999681 0.0139868 0.00598465 0.020153" mass="0.911363" diaginertia="0.00390447 0.000331082 0.000941306"/>
                      <joint name="right_wrist_yaw_joint" class="/" pos="0 0 0" axis="0.00493986 0.00418135 0.999979" stiffness="0.00207023" range="-2.9522 2.9611" armature="0.096272" damping="0.00474803" frictionloss="0.0850367"/>
                      <geom name="//unnamed_geom_58" class="visual" mesh="right_hand_yaw_link"/>
                      <geom name="right_hand_yaw_link.STL" class="collision" size="0.0398998 0.0667945" pos="0.00118034 0.000426202 -0.0859989" type="cylinder" rgba="0.752941 0.752941 0.752941 1"/>
                      <geom name="//unnamed_geom_60" class="reward_collision_sphere" size="0.0479889"/>
                      <body name="right_hand_roll_link" pos="0.00157239 0.000914759 -0.214766" quat="1 -0.000329273 8.68412e-05 0.000228294">
                        <inertial pos="-0.00165402 -0.000804696 -0.000269056" quat="0.49991 0.493975 0.506019 0.500024" mass="0.00429494" diaginertia="4.96457e-07 4.51798e-08 1.23294e-07"/>
                        <joint name="right_wrist_roll_joint" class="/" pos="0 0 0" axis="-0.999942 0.0107023 -0.000752329" stiffness="0.00498193" range="-0.870763 0.941514" armature="0.111949" damping="0.0230751" frictionloss="0.0995735"/>
                        <geom name="//unnamed_geom_61" class="visual" mesh="right_hand_roll_link"/>
                        <body name="right_hand_pitch_link" pos="0.000514055 -0.000596075 -0.00144654" quat="1 -1.4884e-06 -0.000128699 7.80576e-05">
                          <inertial pos="0.00334701 0.00415194 -0.0627032" quat="0.723375 0.121613 -0.114808 0.669895" mass="0.187015" diaginertia="0.000429491 3.48673e-05 0.000171231"/>
                          <joint name="right_wrist_pitch_joint" class="/" pos="0 0 0" axis="-0.00796406 -0.999926 0.00919241" range="-0.615053 0.607724" armature="0.0982341" damping="0.00488453" frictionloss="0.109539"/>
                          <geom name="//unnamed_geom_62" class="visual" mesh="right_hand_pitch"/>
                          <body name="right_jaw_link" pos="0.00187718 0.00171913 -0.0658079" quat="1 1.60449e-06 5.08519e-06 4.37813e-08">
                            <inertial pos="-0.00112503 -0.0048947 -0.041381" quat="0.706844 0.0234886 -0.0300468 0.706341" mass="0.0614302" diaginertia="0.000122822 7.41609e-06 5.94815e-05"/>
                            <joint name="right_jaw_joint" class="/" pos="0 0 0" axis="-1 -0.000583043 0.000694362" stiffness="0.00366901" range="-0.0349244 1.03204" armature="0.083484" damping="0.00901977" frictionloss="0.0972507"/>
                            <geom name="//unnamed_geom_63" class="visual" mesh="right_jaw_link"/>
                            <geom name="//unnamed_geom_64" class="collision" size="0.034552"/>
                            <geom name="//unnamed_geom_65" class="reward_collision_sphere" size="0.0479889" pos="0 0 -0.0226185"/>
                          </body>
                        </body>
                      </body>
                    </body>
                  </body>
                </body>
              </body>
            </body>
            <body name="head_roll_link" pos="0.00074375 -0.000203856 0.34791" quat="1 -0.000918264 -0.000372522 7.72281e-05">
              <inertial pos="0.00439126 -0.00351959 -0.000151725" quat="-0.0016532 0.714746 0.00784847 0.699338" mass="0.00891349" diaginertia="1.01981e-06 5.66482e-08 7.53206e-07"/>
              <joint name="head_roll_joint" class="/" pos="0 0 0" axis="-0.999892 -0.0136376 0.00544989" range="-0.406496 0.356371" armature="0.103603" damping="0.00315553" frictionloss="0.0952662"/>
              <geom name="//unnamed_geom_66" class="visual" mesh="head_roll_link"/>
              <body name="head_pitch_link" pos="-0.00106297 -0.00099264 -0.000228919" quat="0.999999 0.000889456 0.000579003 -0.00014983">
                <inertial pos="-0.00349157 -0.00297473 0.02095" quat="0.66471 0.664767 0.240752 -0.241419" mass="0.054197" diaginertia="3.86804e-05 3.07258e-06 3.23061e-05"/>
                <joint name="head_pitch_joint" class="/" pos="0 0 0" axis="-0.0053805 -0.999982 -0.00275052" range="-0.847068 0.854402" armature="0.0945366" damping="0" frictionloss="0.0855358"/>
                <geom name="//unnamed_geom_67" class="visual" mesh="head_pitch_link"/>
                <body name="head_yaw_link" pos="-0.00265486 0.000984878 0.0609932" quat="0.999999 -0.000716741 0.000637979 0.000669819">
                  <inertial pos="0.0264088 -0.00261983 0.110235" quat="0.711438 -0.122675 -0.145455 0.676498" mass="1.35171" diaginertia="0.0153568 0.00103837 0.00974623"/>
                  <joint name="head_yaw_joint" class="/" pos="0 0 0" axis="0.0015047 -0.00127448 0.999998" range="-2.66086 2.69898" armature="0.0841028" damping="0.00343006" frictionloss="0.108516"/>
                  <geom name="//unnamed_geom_68" class="visual" rgba="0.12 0.12 0.12 1" mesh="head_yaw_link"/>
                  <geom name="head_yaw_link.STL" class="collision" size="0.113913" pos="0.0198099 -0.000585025 0.105878" rgba="0.752941 0.752941 0.752941 1"/>
                  <geom name="//unnamed_geom_70" class="reward_collision_sphere" size="0.0959779" pos="0.0325088 0 0.113093"/>
                  <camera name="ego_camera" class="/" pos="0.119199 0 0.124402" quat="-0.5 -0.5 0.5 0.5"/>
                </body>
              </body>
            </body>
          </body>
        </body>
      </body>
    </body>
  </worldbody>

  <contact>
    <pair class="/" geom1="floor" geom2="left_foot" name="//unnamed_contact_0"/>
    <pair class="/" geom1="floor" geom2="right_foot" name="//unnamed_contact_1"/>
  </contact>

  <actuator>
    <general name="left_hip_roll" class="/" joint="left_hip_roll_joint" forcerange="-43.8774 43.8774" gainprm="81.1712" biasprm="0 -81.1712 -0.959779"/>
    <general name="left_hip_yaw" class="/" joint="left_hip_yaw_joint" forcerange="-60.1857 60.1857" gainprm="81.1712" biasprm="0 -81.1712 -0.959779"/>
    <general name="left_hip_pitch" class="/" joint="left_hip_pitch_joint" forcerange="-232.844 232.844" gainprm="81.1712" biasprm="0 -81.1712 -0.959779"/>
    <general name="left_knee_pitch" class="/" joint="left_knee_pitch_joint" forcerange="-231.828 231.828" gainprm="81.1712" biasprm="0 -81.1712 -0.959779"/>
    <general name="left_ankle_pitch" class="/" joint="left_ankle_pitch_joint" forcerange="-15.7593 15.7593" gainprm="81.1712" biasprm="0 -81.1712 -0.959779"/>
    <general name="left_ankle_roll" class="/" joint="left_ankle_roll_joint" forcerange="-28.7943 28.7943" gainprm="81.1712" biasprm="0 -81.1712 -0.959779"/>
    <general name="right_hip_roll" class="/" joint="right_hip_roll_joint" forcerange="-45.0965 45.0965" gainprm="81.1712" biasprm="0 -81.1712 -0.959779"/>
    <general name="right_hip_yaw" class="/" joint="right_hip_yaw_joint" forcerange="-66.2549 66.2549" gainprm="81.1712" biasprm="0 -81.1712 -0.959779"/>
    <general name="right_hip_pitch" class="/" joint="right_hip_pitch_joint" forcerange="-246.683 246.683" gainprm="81.1712" biasprm="0 -81.1712 -0.959779"/>
    <general name="right_knee_pitch" class="/" joint="right_knee_pitch_joint" forcerange="-206.574 206.574" gainprm="81.1712" biasprm="0 -81.1712 -0.959779"/>
    <general name="right_ankle_pitch" class="/" joint="right_ankle_pitch_joint" forcerange="-15.0417 15.0417" gainprm="81.1712" biasprm="0 -81.1712 -0.959779"/>
    <general name="right_ankle_roll" class="/" joint="right_ankle_roll_joint" forcerange="-29.0198 29.0198" gainprm="81.1712" biasprm="0 -81.1712 -0.959779"/>
    <general name="waist_yaw" class="/" joint="waist_yaw_joint" forcerange="-63.8068 63.8068" gainprm="81.1712" biasprm="0 -81.1712 -0.959779"/>
    <general name="waist_pitch" class="/" joint="waist_pitch_joint" forcerange="-67.2175 67.2175" gainprm="81.1712" biasprm="0 -81.1712 -0.959779"/>
    <general name="waist_roll" class="/" joint="waist_roll_joint" forcerange="-61.8711 61.8711" gainprm="81.1712" biasprm="0 -81.1712 -0.959779"/>
    <general name="left_shoulder_pitch" class="/" joint="left_shoulder_pitch_joint" forcerange="-34.0827 34.0827" gainprm="81.1712" biasprm="0 -81.1712 -0.959779"/>
    <general name="left_shoulder_roll" class="/" joint="left_shoulder_roll_joint" forcerange="-39.4582 39.4582" gainprm="81.1712" biasprm="0 -81.1712 -0.959779"/>
    <general name="left_shoulder_yaw" class="/" joint="left_shoulder_yaw_joint" forcerange="-28.0634 28.0634" gainprm="81.1712" biasprm="0 -81.1712 -0.959779"/>
    <general name="left_elbow_pitch" class="/" joint="left_elbow_pitch_joint" forcerange="-32.3863 32.3863" gainprm="81.1712" biasprm="0 -81.1712 -0.959779"/>
    <general name="left_wrist_yaw" class="/" joint="left_wrist_yaw_joint" forcerange="-8.73611 8.73611" gainprm="81.1712" biasprm="0 -81.1712 -0.959779"/>
    <general name="left_wrist_roll" class="/" joint="left_wrist_roll_joint" forcerange="-3.81456 3.81456" gainprm="81.1712" biasprm="0 -81.1712 -0.959779"/>
    <general name="left_wrist_pitch" class="/" joint="left_wrist_pitch_joint" forcerange="-4.07239 4.07239" gainprm="81.1712" biasprm="0 -81.1712 -0.959779"/>
    <general name="left_jaw" class="/" joint="left_jaw_joint" forcerange="-3.47558 3.47558" gainprm="81.1712" biasprm="0 -81.1712 -0.959779"/>
    <general name="right_shoulder_pitch" class="/" joint="right_shoulder_pitch_joint" forcerange="-34.2523 34.2523" gainprm="81.1712" biasprm="0 -81.1712 -0.959779"/>
    <general name="right_shoulder_roll" class="/" joint="right_shoulder_roll_joint" forcerange="-32.7101 32.7101" gainprm="81.1712" biasprm="0 -81.1712 -0.959779"/>
    <general name="right_shoulder_yaw" class="/" joint="right_shoulder_yaw_joint" forcerange="-31.3513 31.3513" gainprm="81.1712" biasprm="0 -81.1712 -0.959779"/>
    <general name="right_elbow_pitch" class="/" joint="right_elbow_pitch_joint" forcerange="-28.0974 28.0974" gainprm="81.1712" biasprm="0 -81.1712 -0.959779"/>
    <general name="right_wrist_yaw" class="/" joint="right_wrist_yaw_joint" forcerange="-9.7694 9.7694" gainprm="81.1712" biasprm="0 -81.1712 -0.959779"/>
    <general name="right_wrist_roll" class="/" joint="right_wrist_roll_joint" forcerange="-3.64106 3.64106" gainprm="81.1712" biasprm="0 -81.1712 -0.959779"/>
    <general name="right_wrist_pitch" class="/" joint="right_wrist_pitch_joint" forcerange="-4.07278 4.07278" gainprm="81.1712" biasprm="0 -81.1712 -0.959779"/>
    <general name="right_jaw" class="/" joint="right_jaw_joint" forcerange="-3.7955 3.7955" gainprm="81.1712" biasprm="0 -81.1712 -0.959779"/>
    <general name="head_roll" class="/" joint="head_roll_joint" forcerange="-4.05286 4.05286" gainprm="81.1712" biasprm="0 -81.1712 -0.959779"/>
    <general name="head_pitch" class="/" joint="head_pitch_joint" forcerange="-4.14489 4.14489" gainprm="81.1712" biasprm="0 -81.1712 -0.959779"/>
    <general name="head_yaw" class="/" joint="head_yaw_joint" forcerange="-3.89418 3.89418" gainprm="81.1712" biasprm="0 -81.1712 -0.959779"/>
  </actuator>

  <sensor>
    <gyro site="imu" name="imu_angular_velocity"/>
    <velocimeter site="imu" name="imu_linear_velocity"/>
    <framelinvel objtype="site" objname="left_foot" name="left_foot_global_linear_velocity"/>
    <framelinvel objtype="site" objname="right_foot" name="right_foot_global_linear_velocity"/>
  </sensor>

  <keyframe>
    <key name="home" qpos="0 0 0.8665 1 0 0 0 0 0 -0.4 0.8 -0.4 0 0 0 0.4 -0.8 0.4 0 0 0 0 0 -0.2 0 -0.785 0 0 0 0 0 0.2 0 0.785 0 0 0 0 0 0 0"/>
  </keyframe>
</mujoco>
