<mujoco model="GR1T2_jaw">
  <compiler angle="radian" assetdir="assets" balanceinertia="true" inertiafromgeom="false"/>

  <option timestep="0.005" density="1.2" viscosity="2e-05"/>

  <size nkey="1"/>

  <visual>
    <quality shadowsize="8192"/>
    <map shadowclip="0.5"/>
  </visual>

  <default>
    <default class="/">
      <joint armature="0.1" damping="0.01" frictionloss="0.1"/>
      <geom contype="0" conaffinity="0" group="1" solref="-1000 -80"/>
      <site size="0.01 0.005 0.005" group="5"/>
      <general forcelimited="true" biastype="affine" gainprm="80" biasprm="0 -80 -2"/>
      <default class="visual">
        <geom type="mesh" density="0" rgba="0.18 0.18 0.18 1"/>
      </default>
      <default class="collision">
        <geom group="3"/>
      </default>
      <default class="foot">
        <geom size="0.126 0.045 0.01" type="box" condim="6" group="4" priority="1" solimp="0.015 1 0.01"/>
      </default>
      <default class="reward_collision_sphere">
        <geom group="5" rgba="1 0 0 1"/>
      </default>
    </default>
  </default>

  <asset>
    <texture type="skybox" colorspace="auto" name="//unnamed_texture_0" builtin="gradient" rgb1="0.95 0.95 0.95" rgb2="0.95 0.95 0.95" width="100" height="600"/>
    <texture type="2d" colorspace="auto" name="texplane" builtin="checker" rgb1="0.345 0.575 0.748" rgb2="0.345 0.575 0.748" markrgb="1 1 1" width="512" height="512"/>
    <material name="MatPlane" class="/" texture="texplane" texuniform="true" texrepeat="2 2" specular="0.9"/>
    <mesh name="base_link" class="/" file="base_link.STL"/>
    <mesh name="left_thigh_roll_link" class="/" file="left_thigh_roll_link.STL"/>
    <mesh name="left_thigh_yaw_link" class="/" file="left_thigh_yaw_link.STL"/>
    <mesh name="left_thigh_pitch_link" class="/" file="left_thigh_pitch_link.STL"/>
    <mesh name="left_shank_pitch_link" class="/" file="left_shank_pitch_link.STL"/>
    <mesh name="left_foot_pitch_link" class="/" file="left_foot_pitch_link.STL"/>
    <mesh name="left_foot_roll_link" class="/" file="left_foot_roll_link.STL"/>
    <mesh name="right_thigh_roll_link" class="/" file="right_thigh_roll_link.STL"/>
    <mesh name="right_thigh_yaw_link" class="/" file="right_thigh_yaw_link.STL"/>
    <mesh name="right_thigh_pitch_link" class="/" file="right_thigh_pitch_link.STL"/>
    <mesh name="right_shank_pitch_link" class="/" file="right_shank_pitch_link.STL"/>
    <mesh name="right_foot_pitch_link" class="/" file="right_foot_pitch_link.STL"/>
    <mesh name="right_foot_roll_link" class="/" file="right_foot_roll_link.STL"/>
    <mesh name="waist_yaw_link" class="/" file="waist_yaw_link.STL"/>
    <mesh name="waist_pitch_link" class="/" file="waist_pitch_link.STL"/>
    <mesh name="waist_roll_link" class="/" file="waist_roll_link.STL"/>
    <mesh name="torso_link" class="/" file="torso_link.STL"/>
    <mesh name="left_upper_arm_pitch_link" class="/" file="left_upper_arm_pitch_link.STL"/>
    <mesh name="left_upper_arm_roll_link" class="/" file="left_upper_arm_roll_link.STL"/>
    <mesh name="left_upper_arm_yaw_link" class="/" file="left_upper_arm_yaw_link.STL"/>
    <mesh name="left_lower_arm_pitch_link" class="/" file="left_lower_arm_pitch_link.STL"/>
    <mesh name="left_hand_yaw_link" class="/" file="left_hand_yaw_link.STL"/>
    <mesh name="left_hand_roll_link" class="/" file="left_hand_roll_link.STL"/>
    <mesh name="left_hand_pitch" class="/" file="left_hand_pitch.STL"/>
    <mesh name="left_jaw_link" class="/" file="left_jaw_link.STL"/>
    <mesh name="right_upper_arm_pitch_link" class="/" file="right_upper_arm_pitch_link.STL"/>
    <mesh name="right_upper_arm_roll_link" class="/" file="right_upper_arm_roll_link.STL"/>
    <mesh name="right_upper_arm_yaw_link" class="/" file="right_upper_arm_yaw_link.STL"/>
    <mesh name="right_lower_arm_pitch_link" class="/" file="right_lower_arm_pitch_link.STL"/>
    <mesh name="right_hand_yaw_link" class="/" file="right_hand_yaw_link.STL"/>
    <mesh name="right_hand_roll_link" class="/" file="right_hand_roll_link.STL"/>
    <mesh name="right_hand_pitch" class="/" file="right_hand_pitch.STL"/>
    <mesh name="right_jaw_link" class="/" file="right_jaw_link.STL"/>
    <mesh name="head_roll_link" class="/" file="head_roll_link.STL"/>
    <mesh name="head_pitch_link" class="/" file="head_pitch_link.STL"/>
    <mesh name="head_yaw_link" class="/" file="head_yaw_link.STL"/>
    <mesh name="imu_link" class="/" file="imu_link.STL"/>
  </asset>

  <worldbody>
    <geom name="floor" class="/" size="100 100 0.125" type="plane" group="0" material="MatPlane"/>
    <light name="toplight_shadow" class="/" pos="0 0 5" dir="0.0990148 0.0990148 -0.990148" type="directional" ambient="0.04 0.04 0.04" diffuse="0.55 0.55 0.55" specular="0.12 0.12 0.12"/>
    <light name="toplight_fill" class="/" pos="0 0 5" dir="0.0990148 0.0990148 -0.990148" type="directional" castshadow="false" ambient="0.04 0.04 0.04" diffuse="0.3 0.3 0.3" specular="0.08 0.08 0.08"/>
    <body name="trunk" pos="0.00243619 0.000627184 0.00277137" quat="1 -0.000103394 -0.000354468 -6.81038e-05">
      <inertial pos="-0.0493502 0.000487533 -0.00562548" quat="0.999948 -0.00844826 0.00494002 0.00271166" mass="1.55078" diaginertia="0.0206947 0.00654307 0.000571702"/>
      <joint name="//unnamed_joint_0" type="free"/>
      <geom name="//unnamed_geom_1" class="visual" rgba="0.12 0.12 0.12 1" mesh="base_link"/>
      <geom name="base_link.STL" class="collision" size="0.0875901 0.0490574" pos="-0.0370163 0.000317694 0.00386005" quat="0.706838 -0.707359 0.00477667 0" type="cylinder" rgba="0.752941 0.752941 0.752941 1"/>
      <geom name="//unnamed_geom_3" class="visual" pos="0 0 -0.024979" quat="1 0 0 0" rgba="0.12 0.12 0.12 1" mesh="imu_link"/>
      <geom name="//unnamed_geom_4" class="reward_collision_sphere" size="0.0572512" pos="0 0.0858534 0.0419111"/>
      <geom name="//unnamed_geom_5" class="reward_collision_sphere" size="0.0572512" pos="0 -0.0858534 0.0419111"/>
      <site name="imu" class="/" pos="0.00215028 -0.00926323 -0.0320096" size="0.0071564"/>
      <camera name="track" class="/" pos="0 -1.71707 0" quat="0.707107 0.707107 0 0" mode="trackcom"/>
      <body name="left_thigh_roll_link" pos="-0.0270051 0.0882934 -0.0123186" quat="0.999999 0.00106632 -0.000250142 -9.47528e-05">
        <inertial pos="0.000822136 -0.00237839 0.00323322" quat="-0.0285424 0.694813 -0.0305021 0.717977" mass="0.527844" diaginertia="0.00130008 0.00112338 1.96814e-05"/>
        <joint name="left_hip_roll_joint" class="/" pos="0 0 0" axis="-0.999998 -0.00175097 -0.000467617" range="-0.835981 0.0772052" armature="0.0643252" damping="0.011834" frictionloss="0.0694065"/>
        <geom name="//unnamed_geom_6" class="visual" mesh="left_thigh_roll_link"/>
        <body name="left_thigh_yaw_link" pos="0.0283049 0.000392617 -0.0013168" quat="1 0.000416707 0.000267108 -0.000228305">
          <inertial pos="-0.00655844 0.0354481 -0.0460479" quat="0.570802 0.0936247 -0.195562 0.791943" mass="1.2652" diaginertia="0.0122157 0.00880452 0.000110788"/>
          <joint name="left_hip_yaw_joint" class="/" pos="0 0 0" axis="-0.00591857 0.00675226 -0.99996" range="-0.72413 0.687394" armature="0.0640487" damping="0.0136586" frictionloss="0.0682818"/>
          <geom name="//unnamed_geom_7" class="visual" mesh="left_thigh_yaw_link"/>
          <body name="left_thigh_pitch_link" pos="0.00142399 0.0200178 -0.0579535" quat="1 0.000172522 0.000106705 6.97374e-06">
            <inertial pos="0.00224428 -0.0251158 -0.0253694" quat="0.999789 -0.0154035 -0.0101819 0.00895634" mass="2.92027" diaginertia="0.0450308 0.0410701 0.000361799"/>
            <joint name="left_hip_pitch_joint" class="/" pos="0 0 0" axis="-0.00321947 0.999983 0.004867" stiffness="0.00643502" range="-1.75591 0.69076" armature="0.0706784" damping="0.0196539" frictionloss="0.0743599"/>
            <geom name="//unnamed_geom_8" class="visual" mesh="left_thigh_pitch_link"/>
            <geom name="left_thigh_pitch_link.STL" class="collision" size="0.0586825 0.0893935" pos="0.000608537 -0.025756 -0.0700151" type="cylinder" rgba="0.752941 0.752941 0.752941 1"/>
            <geom name="//unnamed_geom_10" class="reward_collision_sphere" size="0.071564" pos="0 -0.00858534 -0.0209556"/>
            <body name="left_shank_pitch_link" pos="-0.00317904 -0.019566 -0.152075" quat="1 -0.000284889 0.000280544 0.000450914">
              <inertial pos="0.000459008 -0.000929314 -0.045511" quat="0.999793 -0.00555488 8.27153e-05 -0.019577" mass="0.665134" diaginertia="0.00536401 0.00503786 1.60198e-05"/>
              <joint name="left_knee_pitch_joint" class="/" pos="0 0 0" axis="0.00259592 0.999995 -0.00175305" stiffness="0.00036843" range="-0.092534 1.92149" armature="0.0673868" damping="0.0143463" frictionloss="0.0714636"/>
              <geom name="//unnamed_geom_11" class="visual" mesh="left_shank_pitch_link"/>
              <geom name="left_shank_pitch_link.STL" class="collision" size="0.0381589 0.0646831" pos="-1.44214e-05 -0.000723355 -0.073215" quat="0.00125538 -0.202712 0.979238 0" type="cylinder" rgba="0.752941 0.752941 0.752941 1"/>
              <geom name="//unnamed_geom_13" class="reward_collision_sphere" size="0.035782"/>
              <geom name="//unnamed_geom_14" class="reward_collision_sphere" size="0.0429384" pos="0 0 -0.0461023"/>
              <body name="left_foot_pitch_link" pos="-0.0019871 -0.000754482 -0.13934" quat="1 -0.000106702 -0.000136638 -2.20709e-05">
                <inertial pos="0.000715235 -0.000882856 0.0024304" quat="0.000186901 0.709486 -0.00865178 0.704666" mass="0.0211286" diaginertia="3.08931e-06 2.61567e-06 6.90561e-08"/>
                <joint name="left_ankle_pitch_joint" class="/" pos="0 0 0" axis="-0.000890457 0.999999 -0.00126585" range="-1.05293 0.551041" armature="0.0749543" damping="0.00163796" frictionloss="0.0722842"/>
                <geom name="//unnamed_geom_15" class="visual" mesh="left_foot_pitch_link"/>
                <body name="left_foot_roll_link" pos="0.00252255 -0.000462278 -0.000184469" quat="1 0.000103043 1.01115e-05 0.000404473">
                  <inertial pos="0.0301177 0.00151323 -0.0133602" quat="-0.000840169 0.724855 -0.000934958 0.688901" mass="0.386124" diaginertia="0.00280879 0.00239999 1.0041e-05"/>
                  <joint name="left_ankle_roll_joint" class="/" pos="0 0 0" axis="-0.999998 0.00204319 -0.000442625" range="-0.445233 0.457569" armature="0.0689858" damping="0.00333143" frictionloss="0.0626204"/>
                  <geom name="//unnamed_geom_16" class="visual" mesh="left_foot_roll_link"/>
                  <geom name="left_foot" class="foot" size="0.114261 0.0335035 0.0072529" pos="0.0391174 0 -0.0186505"/>
                  <geom name="//unnamed_geom_18" class="reward_collision_sphere" size="0.035782" pos="0 0 -0.0125733"/>
                  <geom name="//unnamed_geom_19" class="reward_collision_sphere" size="0.035782" pos="0.104313 0 -0.0125733"/>
                  <site name="left_foot" class="foot" pos="0.0391174 0 -0.0186505" size="0.0071564"/>
                </body>
              </body>
            </body>
          </body>
        </body>
      </body>
      <body name="right_thigh_roll_link" pos="-0.0267009 -0.0900783 -0.0127634" quat="1 0.000185893 -0.000610165 4.69381e-05">
        <inertial pos="0.000737987 0.000653031 0.000614838" quat="0.0308194 0.701055 0.00678677 0.712409" mass="0.538463" diaginertia="0.00130639 0.00120442 1.96506e-05"/>
        <joint name="right_hip_roll_joint" class="/" pos="0 0 0" axis="-1 7.60164e-05 0.000396116" range="-0.0813683 0.817307" armature="0.0636627" damping="0.0151755" frictionloss="0.0744117"/>
        <geom name="//unnamed_geom_20" class="visual" mesh="right_thigh_roll_link"/>
        <body name="right_thigh_yaw_link" pos="0.0248832 -0.000208197 -0.000949629" quat="1 0.000249459 0.000302893 -0.00016627">
          <inertial pos="-0.00589818 -0.0302884 -0.0480811" quat="0.686195 -0.149053 0.150809 0.695828" mass="1.31558" diaginertia="0.0125525 0.00911951 0.000120686"/>
          <joint name="right_hip_yaw_joint" class="/" pos="0 0 0" axis="-0.00824012 0.00163801 -0.999965" range="-0.6573 0.689888" armature="0.0721595" damping="0.0111051" frictionloss="0.0811945"/>
          <geom name="//unnamed_geom_21" class="visual" mesh="right_thigh_yaw_link"/>
          <body name="right_thigh_pitch_link" pos="0.00098785 -0.0213181 -0.0606159" quat="1 -4.01195e-05 0.000106394 -2.72351e-05">
            <inertial pos="0.000620327 0.02668 -0.0252919" quat="0.999564 -0.0137645 -0.0209899 0.0155777" mass="3.17031" diaginertia="0.0451386 0.0405625 0.000370786"/>
            <joint name="right_hip_pitch_joint" class="/" pos="0 0 0" axis="0.0150463 -0.999811 0.0122956" range="-0.697536 1.80192" armature="0.0800182" damping="0.0126838" frictionloss="0.0730505"/>
            <geom name="//unnamed_geom_22" class="visual" mesh="right_thigh_pitch_link"/>
            <geom name="right_thigh_pitch_link.STL" class="collision" size="0.0586825 0.0893913" pos="-0.00184571 0.025756 -0.0700151" quat="0.999971 0.00269833 0.00706272 0" type="cylinder" rgba="0.752941 0.752941 0.752941 1"/>
            <geom name="//unnamed_geom_24" class="reward_collision_sphere" size="0.071564" pos="0 0.00858534 -0.0209556"/>
            <body name="right_shank_pitch_link" pos="0.00162242 0.0149643 -0.148265" quat="1 -0.000138024 0.000308583 -0.000179814">
              <inertial pos="0.00160073 0.00134897 -0.0496648" quat="0.999742 0.00964491 0.00163049 0.0205036" mass="0.642276" diaginertia="0.00540897 0.00516776 1.61728e-05"/>
              <joint name="right_knee_pitch_joint" class="/" pos="0 0 0" axis="-0.00920753 -0.999954 0.0026621" stiffness="0.00784477" range="-1.8962 0.107039" armature="0.0660325" damping="0.0176449" frictionloss="0.0694096"/>
              <geom name="//unnamed_geom_25" class="visual" mesh="right_shank_pitch_link"/>
              <geom name="right_shank_pitch_link.STL" class="collision" size="0.0381587 0.0646825" pos="-1.44214e-05 -0.000723364 -0.0732183" type="cylinder" rgba="0.752941 0.752941 0.752941 1"/>
              <geom name="//unnamed_geom_27" class="reward_collision_sphere" size="0.035782"/>
              <geom name="//unnamed_geom_28" class="reward_collision_sphere" size="0.0429384" pos="0 0 -0.0461023"/>
              <body name="right_foot_pitch_link" pos="8.43049e-05 -0.00300448 -0.139729" quat="1 0.000550695 0.000256987 -0.000173404">
                <inertial pos="0.00301974 -0.000577304 -0.000721161" quat="-0.00810632 0.699076 0.00165479 0.714999" mass="0.0204711" diaginertia="3.08813e-06 2.59561e-06 6.5938e-08"/>
                <joint name="right_ankle_pitch_joint" class="/" pos="0 0 0" axis="0.0118346 -0.99992 0.00435433" range="-0.569425 1.06948" armature="0.0688723" damping="0.00868719" frictionloss="0.0663001"/>
                <geom name="//unnamed_geom_29" class="visual" mesh="right_foot_pitch_link"/>
                <body name="right_foot_roll_link" pos="-0.000999246 -0.00428421 0.00142664" quat="0.999999 0.000727675 -0.000731385 -0.000138355">
                  <inertial pos="0.0332979 -0.00263717 -0.0171228" quat="-0.00131348 0.72099 0.00199842 0.692942" mass="0.384986" diaginertia="0.00275918 0.00231799 9.48228e-06"/>
                  <joint name="right_ankle_roll_joint" class="/" pos="0 0 0" axis="-0.99996 0.0089841 0.000441642" range="-0.502808 0.404916" armature="0.0621858" damping="0.00719176" frictionloss="0.0776051"/>
                  <geom name="//unnamed_geom_30" class="visual" mesh="right_foot_roll_link"/>
                  <geom name="right_foot" class="foot" size="0.0950067 0.0309205 0.00704687" pos="0.0391174 0 -0.0186505"/>
                  <geom name="//unnamed_geom_32" class="reward_collision_sphere" size="0.035782" pos="0 0 -0.0125733"/>
                  <geom name="//unnamed_geom_33" class="reward_collision_sphere" size="0.035782" pos="0.104313 0 -0.0125733"/>
                  <site name="right_foot" class="foot" pos="0.0391174 0 -0.0186505" size="0.0071564"/>
                </body>
              </body>
            </body>
          </body>
        </body>
      </body>
      <body name="waist_yaw_link" pos="0.00461929 0.0017728 0.00518267" quat="1 -0.000254102 0.000286327 -0.000124347">
        <inertial pos="-0.00463802 -0.00615623 0.0225635" quat="0.9811 0.181471 -0.0332591 0.0583482" mass="0.583693" diaginertia="0.00172108 0.00157087 2.75613e-05"/>
        <joint name="waist_yaw_joint" class="/" pos="0 0 0" axis="0.00264585 -0.00155715 0.999995" range="-1.09908 1.08413" armature="0.0716682" damping="0.0204499" frictionloss="0.0734858"/>
        <geom name="//unnamed_geom_34" class="visual" rgba="0.12 0.12 0.12 1" mesh="waist_yaw_link"/>
        <body name="waist_pitch_link" pos="0.00518958 0.000919679 0.0417099" quat="0.999998 0.00107135 0.00124146 -0.00144437">
          <inertial pos="0.00202898 -0.0017216 0.018258" quat="0.997787 -0.0456088 0.0480228 0.00585095" mass="0.561609" diaginertia="0.00228825 0.00210814 2.37197e-05"/>
          <joint name="waist_pitch_joint" class="/" pos="0 0 0" axis="-0.0386606 -0.999064 -0.0193957" range="-1.24049 0.52567" armature="0.0635485" damping="0.00545891" frictionloss="0.0658917"/>
          <geom name="//unnamed_geom_35" class="visual" rgba="0.12 0.12 0.12 1" mesh="waist_pitch_link"/>
          <body name="waist_roll_link" pos="0.00682047 -0.00139422 0.0404445" quat="1 1.22585e-05 -7.10248e-06 4.78364e-05">
            <inertial pos="-0.0124484 0.000584393 0.0625458" quat="0.998931 0.000148643 -0.0462134 -0.000781451" mass="2.39574" diaginertia="0.030631 0.027036 0.00043767"/>
            <joint name="waist_roll_joint" class="/" pos="0 0 0" axis="-0.999873 0.0155891 0.00328158" range="-0.782793 0.694238" armature="0.06843" damping="0.0206492" frictionloss="0.0790395"/>
            <geom name="//unnamed_geom_36" class="visual" rgba="0.12 0.12 0.12 1" mesh="waist_roll_link"/>
            <geom name="//unnamed_geom_37" class="visual" pos="-0.00195587 0.000493168 0.0672045" quat="1 0 0 0" mesh="torso_link"/>
            <geom name="torso_link.STL" class="collision" size="0.112661 0.0216073" pos="-0.0157042 0.00495357 0.0619568" type="cylinder" rgba="0.752941 0.752941 0.752941 1"/>
            <geom name="//unnamed_geom_39" class="reward_collision_sphere" size="0.0930332" pos="0 0 0.0838223"/>
            <body name="left_upper_arm_pitch_link" pos="0.00277429 0.0891563 0.0846727" quat="0.976545 0.215314 -0.00066083 0.000526138">
              <inertial pos="0.00307117 0.044536 -0.00172716" quat="0.708169 0.703156 -0.00218044 -0.0637426" mass="0.297618" diaginertia="0.00102578 0.00089429 6.33097e-06"/>
              <joint name="left_shoulder_pitch_joint" class="/" pos="0 0 0" axis="-0.00631065 0.999964 0.00571975" range="-2.75705 1.96464" armature="0.0656047" damping="0.00477306" frictionloss="0.0722882"/>
              <geom name="//unnamed_geom_40" class="visual" mesh="left_upper_arm_pitch_link"/>
              <body name="left_upper_arm_roll_link" pos="0.00124245 0.0807226 0.00132055" quat="0.976863 -0.213864 0.000349514 -0.000832978">
                <inertial pos="0.00344966 0.0129262 -0.0102447" quat="0.889305 0.26886 0.123627 -0.348665" mass="0.221507" diaginertia="0.000514835 0.000450699 4.50159e-06"/>
                <joint name="left_shoulder_roll_joint" class="/" pos="0 0 0" axis="-1 -0.000186784 0.000676918" range="-2.51142 0.605164" armature="0.0640681" damping="0.0125434" frictionloss="0.0718464"/>
                <geom name="//unnamed_geom_41" class="visual" mesh="left_upper_arm_roll_link"/>
                <body name="left_upper_arm_yaw_link" pos="0.00076082 0.0353548 -0.0275824" quat="0.999999 -0.000907039 -0.000912269 -8.62798e-05">
                  <inertial pos="0.000195361 0.00125575 -0.0341523" quat="0.999795 0.0174075 0.00853436 -0.00577508" mass="0.202481" diaginertia="0.00178525 0.00166759 3.39427e-06"/>
                  <joint name="left_shoulder_yaw_joint" class="/" pos="0 0 0" axis="0.00347205 -0.0100336 0.999944" range="-2.96578 3.03223" armature="0.067617" damping="0" frictionloss="0.0614971"/>
                  <geom name="//unnamed_geom_42" class="visual" mesh="left_upper_arm_yaw_link"/>
                  <geom name="left_upper_arm_yaw_link.STL" class="collision" size="0.0259299 0.0607879" pos="3.43237e-05 -0.000767778 -0.0332523" quat="0.00803418 -0.995528 0.0941277 0" type="cylinder" rgba="0.752941 0.752941 0.752941 1"/>
                  <body name="left_lower_arm_pitch_link" pos="0.000775165 -0.000216307 -0.0768264" quat="1 -0.000206509 0.000155804 0.000172249">
                    <inertial pos="0.000150728 0.0055878 -0.0109427" quat="0.701562 -0.0918219 0.0949508 0.70026" mass="0.12247" diaginertia="0.000145226 0.000138715 1.28943e-06"/>
                    <joint name="left_elbow_pitch_joint" class="/" pos="0 0 0" axis="-0.0162324 0.999814 0.0104093" stiffness="0.00591714" range="-2.29133 2.25216" armature="0.0750625" damping="0" frictionloss="0.0702045"/>
                    <geom name="//unnamed_geom_44" class="visual" mesh="left_lower_arm_pitch_link"/>
                    <body name="left_hand_yaw_link" pos="-0.00120162 0.000938194 -0.0228805" quat="1 -7.0459e-05 3.07458e-05 2.45432e-05">
                      <inertial pos="-0.00046282 0.00358153 -0.0315566" quat="0.999974 -0.00337922 5.8727e-05 0.0064022" mass="0.352703" diaginertia="0.00135107 0.00119135 6.68502e-06"/>
                      <joint name="left_wrist_yaw_joint" class="/" pos="0 0 0" axis="-0.00458456 -0.0122683 0.999914" range="-2.9434 2.98477" armature="0.0753313" damping="0.000144672" frictionloss="0.0718515"/>
                      <geom name="//unnamed_geom_45" class="visual" mesh="left_hand_yaw_link"/>
                      <geom name="left_hand_yaw_link.STL" class="collision" size="0.0297505 0.0498041" pos="0.000946858 -0.0013231 -0.0318704" type="cylinder" rgba="0.752941 0.752941 0.752941 1"/>
                      <geom name="//unnamed_geom_47" class="reward_collision_sphere" size="0.035782"/>
                      <body name="left_hand_roll_link" pos="-0.00094305 -0.000305261 -0.0785729" quat="0.999999 0.00132435 -0.000158301 -0.000481642">
                        <inertial pos="0.00200416 -0.00141105 2.97249e-05" quat="0.498542 0.5003 0.499522 0.50163" mass="0.00178994" diaginertia="1.73605e-07 1.58123e-07 8.93848e-10"/>
                        <joint name="left_wrist_roll_joint" class="/" pos="0 0 0" axis="-0.999999 -0.00167125 0.000249286" range="-0.995995 0.898089" armature="0.0794893" damping="0.000800313" frictionloss="0.0732068"/>
                        <geom name="//unnamed_geom_48" class="visual" mesh="left_hand_roll_link"/>
                        <body name="left_hand_pitch_link" pos="0.00251436 0.00261392 -0.00266206" quat="1 2.66114e-06 4.42123e-06 9.82685e-06">
                          <inertial pos="0.00106543 -0.0107038 -0.0253394" quat="0.730623 -0.12417 0.110926 0.662168" mass="0.0771466" diaginertia="0.000138622 0.000121543 1.17066e-06"/>
                          <joint name="left_wrist_pitch_joint" class="/" pos="0 0 0" axis="0.000126057 0.999999 -0.0011026" range="-0.580087 0.639068" armature="0.062591" damping="0.0049662" frictionloss="0.0630537"/>
                          <geom name="//unnamed_geom_49" class="visual" mesh="left_hand_pitch"/>
                          <body name="left_jaw_link" pos="0.000146997 -0.000169713 -0.022726" quat="1 -5.88084e-05 -0.00059997 -0.000411065">
                            <inertial pos="-0.000647112 0.00389014 -0.0150851" quat="0.705309 -0.0277888 0.0456096 0.706885" mass="0.0264251" diaginertia="3.93021e-05 2.69024e-05 4.29417e-07"/>
                            <joint name="left_jaw_joint" class="/" pos="0 0 0" axis="-0.999988 -0.00418252 -0.00267156" stiffness="0.00315611" range="-0.923854 0.0391224" armature="0.0746556" damping="0.00491659" frictionloss="0.0810596"/>
                            <geom name="//unnamed_geom_50" class="visual" mesh="left_jaw_link"/>
                            <geom name="//unnamed_geom_51" class="collision" size="0.025763"/>
                            <geom name="//unnamed_geom_52" class="reward_collision_sphere" size="0.035782" pos="0 0 -0.00838223"/>
                          </body>
                        </body>
                      </body>
                    </body>
                  </body>
                </body>
              </body>
            </body>
            <body name="right_upper_arm_pitch_link" pos="-0.00173051 -0.0864726 0.0837739" quat="0.976901 -0.21369 0.000533573 -0.000533873">
              <inertial pos="0.00103555 -0.0439598 -0.000258441" quat="0.700057 0.713356 0.020102 0.0252935" mass="0.305926" diaginertia="0.000979341 0.000910572 6.13381e-06"/>
              <joint name="right_shoulder_pitch_joint" class="/" pos="0 0 0" axis="-0.0139721 -0.999902 -0.00110589" range="-1.93534 2.75296" armature="0.0620836" damping="0" frictionloss="0.0670588"/>
              <geom name="//unnamed_geom_53" class="visual" mesh="right_upper_arm_pitch_link"/>
              <body name="right_upper_arm_roll_link" pos="0.00181007 -0.080578 0.00280831" quat="0.976457 0.215711 0.000466335 0.000315359">
                <inertial pos="0.00684461 -0.0165028 -0.0101704" quat="0.889293 -0.259782 0.134811 0.351422" mass="0.219379" diaginertia="0.000518024 0.000446813 4.43393e-06"/>
                <joint name="right_shoulder_roll_joint" class="/" pos="0 0 0" axis="-0.999997 0.00233186 -0.00034064" range="-0.626229 2.563" armature="0.0768577" damping="0" frictionloss="0.0631405"/>
                <geom name="//unnamed_geom_54" class="visual" mesh="right_upper_arm_roll_link"/>
                <body name="right_upper_arm_yaw_link" pos="0.00061991 -0.0337422 -0.0295487" quat="0.999999 6.25608e-05 0.000408633 0.00143049">
                  <inertial pos="0.000207834 -0.000558558 -0.034329" quat="0.999896 -0.00585743 0.00654094 0.0114056" mass="0.198701" diaginertia="0.00170009 0.00163485 3.36308e-06"/>
                  <joint name="right_shoulder_yaw_joint" class="/" pos="0 0 0" axis="0.00219432 0.00455746 0.999987" range="-2.9212 2.97412" armature="0.0624812" damping="0.0119659" frictionloss="0.0683508"/>
                  <geom name="//unnamed_geom_55" class="visual" mesh="right_upper_arm_yaw_link"/>
                  <geom name="right_upper_arm_yaw_link.STL" class="collision" size="0.0259299 0.0607879" pos="3.43237e-05 0.000767778 -0.0332523" type="cylinder" rgba="0.752941 0.752941 0.752941 1"/>
                  <body name="right_lower_arm_pitch_link" pos="0.00286068 0.00103718 -0.0754653" quat="1 0.000453509 0.000255519 -7.59325e-05">
                    <inertial pos="-0.00145195 -0.0094041 -0.0128117" quat="0.703017 0.0977471 -0.0890142 0.698777" mass="0.11601" diaginertia="0.000145693 0.000134504 1.24128e-06"/>
                    <joint name="right_elbow_pitch_joint" class="/" pos="0 0 0" axis="0.0092521 -0.999921 -0.00855304" range="-2.31361 2.27085" armature="0.0714937" damping="0.00148596" frictionloss="0.0720596"/>
                    <geom name="//unnamed_geom_57" class="visual" mesh="right_lower_arm_pitch_link"/>
                    <body name="right_hand_yaw_link" pos="0.00272585 7.37602e-06 -0.0224137" quat="1 -7.15601e-05 5.94091e-05 1.87749e-05">
                      <inertial pos="0.00275319 -0.00166791 -0.0306565" quat="0.999692 0.00384006 -0.0011544 0.0244974" mass="0.357915" diaginertia="0.00126899 0.00115404 6.11606e-06"/>
                      <joint name="right_wrist_yaw_joint" class="/" pos="0 0 0" axis="-0.00111608 -0.00509401 0.999986" range="-2.96824 3.01647" armature="0.0730973" damping="0.00354817" frictionloss="0.0615547"/>
                      <geom name="//unnamed_geom_58" class="visual" mesh="right_hand_yaw_link"/>
                      <geom name="right_hand_yaw_link.STL" class="collision" size="0.0297505 0.0498041" pos="0.000946858 0.000550418 -0.0318704" type="cylinder" rgba="0.752941 0.752941 0.752941 1"/>
                      <geom name="//unnamed_geom_60" class="reward_collision_sphere" size="0.035782"/>
                      <body name="right_hand_roll_link" pos="-0.000402018 -0.00234861 -0.0812293" quat="1 2.13808e-05 7.70252e-05 -0.000109511">
                        <inertial pos="-0.00160843 -0.00121197 -0.00283606" quat="0.500168 0.499302 0.499854 0.500676" mass="0.00181008" diaginertia="1.71179e-07 1.6195e-07 9.02053e-10"/>
                        <joint name="right_wrist_roll_joint" class="/" pos="0 0 0" axis="-0.999993 -0.0022275 0.00288696" stiffness="0.004948" range="-0.867281 0.985999" armature="0.0757792" damping="0.000990171" frictionloss="0.0783643"/>
                        <geom name="//unnamed_geom_61" class="visual" mesh="right_hand_roll_link"/>
                        <body name="right_hand_pitch_link" pos="-0.000951412 0.0010619 0.000519254" quat="1 0.000604282 4.07298e-05 -0.000115849">
                          <inertial pos="9.63349e-05 0.00880798 -0.0219852" quat="0.72352 0.119799 -0.115935 0.66987" mass="0.0776328" diaginertia="0.000144999 0.000122056 1.22068e-06"/>
                          <joint name="right_wrist_pitch_joint" class="/" pos="0 0 0" axis="-0.00978025 -0.999947 0.0031785" stiffness="0.00504288" range="-0.61304 0.627911" armature="0.0717983" damping="0" frictionloss="0.068536"/>
                          <geom name="//unnamed_geom_62" class="visual" mesh="right_hand_pitch"/>
                          <body name="right_jaw_link" pos="-0.000794235 -0.000738083 -0.0231257" quat="1 -4.16851e-05 9.09221e-08 1.08986e-05">
                            <inertial pos="-0.00128392 -0.0042172 -0.0139789" quat="0.709907 0.0312987 -0.038663 0.702537" mass="0.0273422" diaginertia="4.05858e-05 2.6925e-05 4.38528e-07"/>
                            <joint name="right_jaw_joint" class="/" pos="0 0 0" axis="-0.999999 -0.000680265 0.00156475" range="-0.0505512 1.01781" armature="0.0759968" damping="0.00211369" frictionloss="0.0619644"/>
                            <geom name="//unnamed_geom_63" class="visual" mesh="right_jaw_link"/>
                            <geom name="//unnamed_geom_64" class="collision" size="0.025763"/>
                            <geom name="//unnamed_geom_65" class="reward_collision_sphere" size="0.035782" pos="0 0 -0.00838223"/>
                          </body>
                        </body>
                      </body>
                    </body>
                  </body>
                </body>
              </body>
            </body>
            <body name="head_roll_link" pos="-0.00358323 -0.00190423 0.132532" quat="1 -0.000675486 0.000141282 -0.000244994">
              <inertial pos="0.00407295 0.000134425 -0.000856661" quat="-0.00553336 0.707337 0.000754133 0.706855" mass="0.00365973" diaginertia="3.7324e-07 2.06195e-07 5.56632e-09"/>
              <joint name="head_roll_joint" class="/" pos="0 0 0" axis="-0.99996 0.00891096 -0.00124447" range="-0.376562 0.393682" armature="0.069356" damping="0" frictionloss="0.0705618"/>
              <geom name="//unnamed_geom_66" class="visual" mesh="head_roll_link"/>
              <body name="head_pitch_link" pos="0.00155949 0.000334223 0.00345845" quat="0.999999 -0.000395363 0.000532011 0.000921136">
                <inertial pos="-0.00316055 0.00190343 0.0091859" quat="0.663874 0.664864 0.241247 -0.242955" mass="0.0205119" diaginertia="1.29748e-05 1.07772e-05 2.06356e-07"/>
                <joint name="head_pitch_joint" class="/" pos="0 0 0" axis="0.00228089 -0.999942 -0.0105569" stiffness="0.00330786" range="-0.79936 0.864288" armature="0.0721155" damping="0" frictionloss="0.0756789"/>
                <geom name="//unnamed_geom_67" class="visual" mesh="head_pitch_link"/>
                <body name="head_yaw_link" pos="-0.00013379 -0.0023086 0.0208285" quat="1 -3.32856e-05 -9.63701e-05 0.000173016">
                  <inertial pos="0.0218361 -0.00228072 0.041116" quat="0.698377 -0.132242 -0.151267 0.68695" mass="0.581088" diaginertia="0.00512104 0.00384159 6.94295e-05"/>
                  <joint name="head_yaw_joint" class="/" pos="0 0 0" axis="0.00369484 -0.0119038 0.999922" stiffness="0.00015933" range="-2.70826 2.7295" armature="0.0785984" damping="0.00884947" frictionloss="0.0744898"/>
                  <geom name="//unnamed_geom_68" class="visual" rgba="0.12 0.12 0.12 1" mesh="head_yaw_link"/>
                  <geom name="head_yaw_link.STL" class="collision" size="0.0849372" pos="0.0158913 -0.00075553 0.0392373" rgba="0.752941 0.752941 0.752941 1"/>
                  <geom name="//unnamed_geom_70" class="reward_collision_sphere" size="0.071564" pos="0.0260783 0 0.0419111"/>
                  <camera name="ego_camera" class="/" pos="0.0956203 0 0.0461023" quat="-0.5 -0.5 0.5 0.5"/>
                </body>
              </body>
            </body>
          </body>
        </body>
      </body>
    </body>
  </worldbody>

  <contact>
    <pair class="/" geom1="floor" geom2="left_foot" name="//unnamed_contact_0"/>
    <pair class="/" geom1="floor" geom2="right_foot" name="//unnamed_contact_1"/>
  </contact>

  <actuator>
    <general name="left_hip_roll" class="/" joint="left_hip_roll_joint" forcerange="-33.2673 33.2673" gainprm="62.5728" biasprm="0 -62.5728 -0.71564"/>
    <general name="left_hip_yaw" class="/" joint="left_hip_yaw_joint" forcerange="-43.4927 43.4927" gainprm="62.5728" biasprm="0 -62.5728 -0.71564"/>
    <general name="left_hip_pitch" class="/" joint="left_hip_pitch_joint" forcerange="-169.27 169.27" gainprm="62.5728" biasprm="0 -62.5728 -0.71564"/>
    <general name="left_knee_pitch" class="/" joint="left_knee_pitch_joint" forcerange="-168.652 168.652" gainprm="62.5728" biasprm="0 -62.5728 -0.71564"/>
    <general name="left_ankle_pitch" class="/" joint="left_ankle_pitch_joint" forcerange="-11.7469 11.7469" gainprm="62.5728" biasprm="0 -62.5728 -0.71564"/>
    <general name="left_ankle_roll" class="/" joint="left_ankle_roll_joint" forcerange="-19.5117 19.5117" gainprm="62.5728" biasprm="0 -62.5728 -0.71564"/>
    <general name="right_hip_roll" class="/" joint="right_hip_roll_joint" forcerange="-34.1236 34.1236" gainprm="62.5728" biasprm="0 -62.5728 -0.71564"/>
    <general name="right_hip_yaw" class="/" joint="right_hip_yaw_joint" forcerange="-50.3919 50.3919" gainprm="62.5728" biasprm="0 -62.5728 -0.71564"/>
    <general name="right_hip_pitch" class="/" joint="right_hip_pitch_joint" forcerange="-159.934 159.934" gainprm="62.5728" biasprm="0 -62.5728 -0.71564"/>
    <general name="right_knee_pitch" class="/" joint="right_knee_pitch_joint" forcerange="-169.09 169.09" gainprm="62.5728" biasprm="0 -62.5728 -0.71564"/>
    <general name="right_ankle_pitch" class="/" joint="right_ankle_pitch_joint" forcerange="-11.8373 11.8373" gainprm="62.5728" biasprm="0 -62.5728 -0.71564"/>
    <general name="right_ankle_roll" class="/" joint="right_ankle_roll_joint" forcerange="-20.7276 20.7276" gainprm="62.5728" biasprm="0 -62.5728 -0.71564"/>
    <general name="waist_yaw" class="/" joint="waist_yaw_joint" forcerange="-46.7287 46.7287" gainprm="62.5728" biasprm="0 -62.5728 -0.71564"/>
    <general name="waist_pitch" class="/" joint="waist_pitch_joint" forcerange="-53.3538 53.3538" gainprm="62.5728" biasprm="0 -62.5728 -0.71564"/>
    <general name="waist_roll" class="/" joint="waist_roll_joint" forcerange="-43.9381 43.9381" gainprm="62.5728" biasprm="0 -62.5728 -0.71564"/>
    <general name="left_shoulder_pitch" class="/" joint="left_shoulder_pitch_joint" forcerange="-24.9737 24.9737" gainprm="62.5728" biasprm="0 -62.5728 -0.71564"/>
    <general name="left_shoulder_roll" class="/" joint="left_shoulder_roll_joint" forcerange="-26.2775 26.2775" gainprm="62.5728" biasprm="0 -62.5728 -0.71564"/>
    <general name="left_shoulder_yaw" class="/" joint="left_shoulder_yaw_joint" forcerange="-21.0933 21.0933" gainprm="62.5728" biasprm="0 -62.5728 -0.71564"/>
    <general name="left_elbow_pitch" class="/" joint="left_elbow_pitch_joint" forcerange="-20.955 20.955" gainprm="62.5728" biasprm="0 -62.5728 -0.71564"/>
    <general name="left_wrist_yaw" class="/" joint="left_wrist_yaw_joint" forcerange="-7.38095 7.38095" gainprm="62.5728" biasprm="0 -62.5728 -0.71564"/>
    <general name="left_wrist_roll" class="/" joint="left_wrist_roll_joint" forcerange="-2.87745 2.87745" gainprm="62.5728" biasprm="0 -62.5728 -0.71564"/>
    <general name="left_wrist_pitch" class="/" joint="left_wrist_pitch_joint" forcerange="-3.0649 3.0649" gainprm="62.5728" biasprm="0 -62.5728 -0.71564"/>
    <general name="left_jaw" class="/" joint="left_jaw_joint" forcerange="-2.54619 2.54619" gainprm="62.5728" biasprm="0 -62.5728 -0.71564"/>
    <general name="right_shoulder_pitch" class="/" joint="right_shoulder_pitch_joint" forcerange="-27.834 27.834" gainprm="62.5728" biasprm="0 -62.5728 -0.71564"/>
    <general name="right_shoulder_roll" class="/" joint="right_shoulder_roll_joint" forcerange="-28.3093 28.3093" gainprm="62.5728" biasprm="0 -62.5728 -0.71564"/>
    <general name="right_shoulder_yaw" class="/" joint="right_shoulder_yaw_joint" forcerange="-21.1639 21.1639" gainprm="62.5728" biasprm="0 -62.5728 -0.71564"/>
    <general name="right_elbow_pitch" class="/" joint="right_elbow_pitch_joint" forcerange="-21.3393 21.3393" gainprm="62.5728" biasprm="0 -62.5728 -0.71564"/>
    <general name="right_wrist_yaw" class="/" joint="right_wrist_yaw_joint" forcerange="-7.19331 7.19331" gainprm="62.5728" biasprm="0 -62.5728 -0.71564"/>
    <general name="right_wrist_roll" class="/" joint="right_wrist_roll_joint" forcerange="-2.96034 2.96034" gainprm="62.5728" biasprm="0 -62.5728 -0.71564"/>
    <general name="right_wrist_pitch" class="/" joint="right_wrist_pitch_joint" forcerange="-2.67222 2.67222" gainprm="62.5728" biasprm="0 -62.5728 -0.71564"/>
    <general name="right_jaw" class="/" joint="right_jaw_joint" forcerange="-3.06245 3.06245" gainprm="62.5728" biasprm="0 -62.5728 -0.71564"/>
    <general name="head_roll" class="/" joint="head_roll_joint" forcerange="-2.58599 2.58599" gainprm="62.5728" biasprm="0 -62.5728 -0.71564"/>
    <general name="head_pitch" class="/" joint="head_pitch_joint" forcerange="-2.78481 2.78481" gainprm="62.5728" biasprm="0 -62.5728 -0.71564"/>
    <general name="head_yaw" class="/" joint="head_yaw_joint" forcerange="-2.8381 2.8381" gainprm="62.5728" biasprm="0 -62.5728 -0.71564"/>
  </actuator>

  <sensor>
    <gyro site="imu" name="imu_angular_velocity"/>
    <velocimeter site="imu" name="imu_linear_velocity"/>
    <framelinvel objtype="site" objname="left_foot" name="left_foot_global_linear_velocity"/>
    <framelinvel objtype="site" objname="right_foot" name="right_foot_global_linear_velocity"/>
  </sensor>

  <keyframe>
    <key name="home" qpos="0 0 0.8665 1 0 0 0 0 0 -0.4 0.8 -0.4 0 0 0 0.4 -0.8 0.4 0 0 0 0 0 -0.2 0 -0.785 0 0 0 0 0 0.2 0 0.785 0 0 0 0 0 0 0"/>
  </keyframe>
</mujoco>
