<mujoco model="GR1T2_jaw">
  <compiler angle="radian" assetdir="assets" balanceinertia="true" inertiafromgeom="false"/>

  <option timestep="0.005" density="1.2" viscosity="2e-05"/>

  <size nkey="1"/>

  <visual>
    <quality shadowsize="8192"/>
    <map shadowclip="0.5"/>
  </visual>

  <default>
    <default class="/">
      <joint armature="0.1" damping="0.01" frictionloss="0.1"/>
      <geom contype="0" conaffinity="0" group="1" solref="-1000 -80"/>
      <site size="0.01 0.005 0.005" group="5"/>
      <general forcelimited="true" biastype="affine" gainprm="80" biasprm="0 -80 -2"/>
      <default class="visual">
        <geom type="mesh" density="0" rgba="0.18 0.18 0.18 1"/>
      </default>
      <default class="collision">
        <geom group="3"/>
      </default>
      <default class="foot">
        <geom size="0.126 0.045 0.01" type="box" condim="6" group="4" priority="1" solimp="0.015 1 0.01"/>
      </default>
      <default class="reward_collision_sphere">
        <geom group="5" rgba="1 0 0 1"/>
      </default>
    </default>
  </default>

  <asset>
    <texture type="skybox" colorspace="auto" name="//unnamed_texture_0" builtin="gradient" rgb1="0.95 0.95 0.95" rgb2="0.95 0.95 0.95" width="100" height="600"/>
    <texture type="2d" colorspace="auto" name="texplane" builtin="checker" rgb1="0.345 0.575 0.748" rgb2="0.345 0.575 0.748" markrgb="1 1 1" width="512" height="512"/>
    <material name="MatPlane" class="/" texture="texplane" texuniform="true" texrepeat="2 2" specular="0.9"/>
    <mesh name="base_link" class="/" file="base_link.STL"/>
    <mesh name="left_thigh_roll_link" class="/" file="left_thigh_roll_link.STL"/>
    <mesh name="left_thigh_yaw_link" class="/" file="left_thigh_yaw_link.STL"/>
    <mesh name="left_thigh_pitch_link" class="/" file="left_thigh_pitch_link.STL"/>
    <mesh name="left_shank_pitch_link" class="/" file="left_shank_pitch_link.STL"/>
    <mesh name="left_foot_pitch_link" class="/" file="left_foot_pitch_link.STL"/>
    <mesh name="left_foot_roll_link" class="/" file="left_foot_roll_link.STL"/>
    <mesh name="right_thigh_roll_link" class="/" file="right_thigh_roll_link.STL"/>
    <mesh name="right_thigh_yaw_link" class="/" file="right_thigh_yaw_link.STL"/>
    <mesh name="right_thigh_pitch_link" class="/" file="right_thigh_pitch_link.STL"/>
    <mesh name="right_shank_pitch_link" class="/" file="right_shank_pitch_link.STL"/>
    <mesh name="right_foot_pitch_link" class="/" file="right_foot_pitch_link.STL"/>
    <mesh name="right_foot_roll_link" class="/" file="right_foot_roll_link.STL"/>
    <mesh name="waist_yaw_link" class="/" file="waist_yaw_link.STL"/>
    <mesh name="waist_pitch_link" class="/" file="waist_pitch_link.STL"/>
    <mesh name="waist_roll_link" class="/" file="waist_roll_link.STL"/>
    <mesh name="torso_link" class="/" file="torso_link.STL"/>
    <mesh name="left_upper_arm_pitch_link" class="/" file="left_upper_arm_pitch_link.STL"/>
    <mesh name="left_upper_arm_roll_link" class="/" file="left_upper_arm_roll_link.STL"/>
    <mesh name="left_upper_arm_yaw_link" class="/" file="left_upper_arm_yaw_link.STL"/>
    <mesh name="left_lower_arm_pitch_link" class="/" file="left_lower_arm_pitch_link.STL"/>
    <mesh name="left_hand_yaw_link" class="/" file="left_hand_yaw_link.STL"/>
    <mesh name="left_hand_roll_link" class="/" file="left_hand_roll_link.STL"/>
    <mesh name="left_hand_pitch" class="/" file="left_hand_pitch.STL"/>
    <mesh name="left_jaw_link" class="/" file="left_jaw_link.STL"/>
    <mesh name="right_upper_arm_pitch_link" class="/" file="right_upper_arm_pitch_link.STL"/>
    <mesh name="right_upper_arm_roll_link" class="/" file="right_upper_arm_roll_link.STL"/>
    <mesh name="right_upper_arm_yaw_link" class="/" file="right_upper_arm_yaw_link.STL"/>
    <mesh name="right_lower_arm_pitch_link" class="/" file="right_lower_arm_pitch_link.STL"/>
    <mesh name="right_hand_yaw_link" class="/" file="right_hand_yaw_link.STL"/>
    <mesh name="right_hand_roll_link" class="/" file="right_hand_roll_link.STL"/>
    <mesh name="right_hand_pitch" class="/" file="right_hand_pitch.STL"/>
    <mesh name="right_jaw_link" class="/" file="right_jaw_link.STL"/>
    <mesh name="head_roll_link" class="/" file="head_roll_link.STL"/>
    <mesh name="head_pitch_link" class="/" file="head_pitch_link.STL"/>
    <mesh name="head_yaw_link" class="/" file="head_yaw_link.STL"/>
    <mesh name="imu_link" class="/" file="imu_link.STL"/>
  </asset>

  <worldbody>
    <geom name="floor" class="/" size="100 100 0.125" type="plane" group="0" material="MatPlane"/>
    <light name="toplight_shadow" class="/" pos="0 0 5" dir="0.0990148 0.0990148 -0.990148" type="directional" ambient="0.04 0.04 0.04" diffuse="0.55 0.55 0.55" specular="0.12 0.12 0.12"/>
    <light name="toplight_fill" class="/" pos="0 0 5" dir="0.0990148 0.0990148 -0.990148" type="directional" castshadow="false" ambient="0.04 0.04 0.04" diffuse="0.3 0.3 0.3" specular="0.08 0.08 0.08"/>
    <body name="trunk" pos="-0.00941867 0.00337547 -0.01181" quat="0.999998 0.00167309 -0.000420122 0.000385213">
      <inertial pos="-0.0992989 -0.0182801 -0.0281172" quat="0.997394 0.045039 -0.0501453 0.0257369" mass="6.93774" diaginertia="0.296185 0.0933792 0.0525135"/>
      <joint name="//unnamed_joint_0" type="free"/>
      <geom name="//unnamed_geom_1" class="visual" rgba="0.12 0.12 0.12 1" mesh="base_link"/>
      <geom name="base_link.STL" class="collision" size="0.163405 0.0915201" pos="-0.0633636 0.000552364 0.00943593" quat="0.706838 -0.707359 0.00477667 0" type="cylinder" rgba="0.752941 0.752941 0.752941 1"/>
      <geom name="//unnamed_geom_3" class="visual" pos="0 0 -0.0610614" quat="1 0 0 0" rgba="0.12 0.12 0.12 1" mesh="imu_link"/>
      <geom name="//unnamed_geom_4" class="reward_collision_sphere" size="0.106806" pos="0 0.149271 0.102452"/>
      <geom name="//unnamed_geom_5" class="reward_collision_sphere" size="0.106806" pos="0 -0.149271 0.102452"/>
      <site name="imu" class="/" pos="-0.0114381 0.0739565 -0.159807" size="0.0133508"/>
      <camera name="track" class="/" pos="0 -2.98541 0" quat="0.707107 0.707107 0 0" mode="trackcom"/>
      <body name="left_thigh_roll_link" pos="-0.0280759 0.151384 -0.0254344" quat="0.999984 0.00372484 0.00321002 0.00295441">
        <inertial pos="-0.00850072 0.0144863 -0.0116481" quat="-0.0624149 0.679361 -0.000848439 0.731145" mass="2.9877" diaginertia="0.018189 0.0158589 0.00159455"/>
        <joint name="left_hip_roll_joint" class="/" pos="0 0 0" axis="-0.999974 0.0038515 0.00613678" stiffness="0.0641406" range="-0.584439 0.0121422" armature="0.208357" damping="0.036108" frictionloss="0.0987757"/>
        <geom name="//unnamed_geom_6" class="visual" mesh="left_thigh_roll_link"/>
        <body name="left_thigh_yaw_link" pos="0.0522049 -0.00873366 0.0101519" quat="0.999998 0.000954198 0.000358388 0.00191032">
          <inertial pos="0.00653586 0.0472952 -0.130381" quat="0.567504 0.0929488 -0.19349 0.794897" mass="7.5759" diaginertia="0.137485 0.151233 0.0111259"/>
          <joint name="left_hip_yaw_joint" class="/" pos="0 0 0" axis="0.00736958 -0.0248923 -0.999663" stiffness="0.0867708" range="-1.08731 0.749208" armature="0.218329" damping="0" frictionloss="0.00593939"/>
          <geom name="//unnamed_geom_7" class="visual" mesh="left_thigh_yaw_link"/>
          <body name="left_thigh_pitch_link" pos="0.0196911 0.0371141 -0.160359" quat="1 0.00025012 -0.000743611 0.000307984">
            <inertial pos="-0.0102367 -0.0351564 -0.0655031" quat="0.999821 -0.0114043 -0.0133353 0.00709448" mass="21.7951" diaginertia="0.614718 0.6506 0.0301381"/>
            <joint name="left_hip_pitch_joint" class="/" pos="0 0 0" axis="-0.0671671 0.996614 0.0474221" range="-1.39474 0.330331" armature="0.24998" damping="0" frictionloss="0.16668"/>
            <geom name="//unnamed_geom_8" class="visual" mesh="left_thigh_pitch_link"/>
            <geom name="left_thigh_pitch_link.STL" class="collision" size="0.109476 0.16677" pos="0.00104168 -0.0447812 -0.171152" type="cylinder" rgba="0.752941 0.752941 0.752941 1"/>
            <geom name="//unnamed_geom_10" class="reward_collision_sphere" size="0.133508" pos="0 -0.0149271 -0.051226"/>
            <body name="left_shank_pitch_link" pos="0.0123222 -0.022454 -0.369235" quat="0.999969 -0.00515638 0.000699853 0.00591305">
              <inertial pos="0.00416646 -0.00306759 -0.127256" quat="0.998632 0.0178218 -0.0117155 0.0477355" mass="2.80806" diaginertia="0.0747762 0.0555769 0.00104293"/>
              <joint name="left_knee_pitch_joint" class="/" pos="0 0 0" axis="-0.00332191 0.999993 0.00198848" range="-0.119761 2.04357" armature="0.102449" damping="0.0381461" frictionloss="0.123681"/>
              <geom name="//unnamed_geom_11" class="visual" mesh="left_shank_pitch_link"/>
              <geom name="left_shank_pitch_link.STL" class="collision" size="0.0711882 0.120671" pos="-2.46861e-05 -0.00125767 -0.178975" quat="0.00125538 -0.202712 0.979238 0" type="cylinder" rgba="0.752941 0.752941 0.752941 1"/>
              <geom name="//unnamed_geom_13" class="reward_collision_sphere" size="0.0667538"/>
              <geom name="//unnamed_geom_14" class="reward_collision_sphere" size="0.0801046" pos="0 0 -0.112697"/>
              <body name="left_foot_pitch_link" pos="0.00617216 -0.0114118 -0.356184" quat="0.999957 0.000342972 -0.00129926 -0.00915337">
                <inertial pos="-0.000466087 0.0168978 -0.0119402" quat="0.0338706 0.740696 0.0421521 0.669661" mass="0.0955734" diaginertia="2.69625e-05 3.11304e-05 4.94646e-06"/>
                <joint name="left_ankle_pitch_joint" class="/" pos="0 0 0" axis="0.0171997 0.996083 -0.086737" stiffness="0.0503052" range="-1.05877 0.202789" armature="0.0919781" damping="0" frictionloss="0.128792"/>
                <geom name="//unnamed_geom_15" class="visual" mesh="left_foot_pitch_link"/>
                <body name="left_foot_roll_link" pos="0.000612762 -0.0172633 0.00351941" quat="0.999994 0.00196087 0.000157571 -0.00278314">
                  <inertial pos="0.0639191 -0.00980554 -0.0515742" quat="0.000853966 0.723547 0.000352913 0.690275" mass="3.65885" diaginertia="0.0618322 0.0570654 0.000971699"/>
                  <joint name="left_ankle_roll_joint" class="/" pos="0 0 0" axis="-0.996169 -0.00658508 -0.0871967" range="-0.428966 0.103838" armature="0.00744076" damping="0" frictionloss="0.221595"/>
                  <geom name="//unnamed_geom_16" class="visual" mesh="left_foot_roll_link"/>
                  <geom name="left_foot" class="foot" size="0.0925089 0.101306 0.0164257" pos="0.0669602 0 -0.0455912"/>
                  <geom name="//unnamed_geom_18" class="reward_collision_sphere" size="0.0667538" pos="0 0 -0.0307356"/>
                  <geom name="//unnamed_geom_19" class="reward_collision_sphere" size="0.0667538" pos="0.178561 0 -0.0307356"/>
                  <site name="left_foot" class="foot" pos="0.0669602 0 -0.0455912" size="0.0133508"/>
                </body>
              </body>
            </body>
          </body>
        </body>
      </body>
      <body name="right_thigh_roll_link" pos="-0.0597775 -0.166579 -0.0122793" quat="0.999981 0.00374026 -0.00113413 -0.00472877">
        <inertial pos="-0.00508351 -0.0164351 0.0192099" quat="0.0253988 0.739487 0.0230156 0.672297" mass="3.77794" diaginertia="0.0253465 0.0168369 0.00221799"/>
        <joint name="right_hip_roll_joint" class="/" pos="0 0 0" axis="-0.995883 0.0193802 0.0885505" range="-0.433776 0.660498" armature="0.121823" damping="0" frictionloss="0.166337"/>
        <geom name="//unnamed_geom_20" class="visual" mesh="right_thigh_roll_link"/>
        <body name="right_thigh_yaw_link" pos="0.0528207 -0.0102447 0.00872935" quat="0.999958 -0.000632334 0.00909497 0.000456306">
          <inertial pos="-0.00644368 -0.0703013 -0.133107" quat="0.699406 -0.159844 0.126559 0.685028" mass="7.18422" diaginertia="0.124592 0.117051 0.00690404"/>
          <joint name="right_hip_yaw_joint" class="/" pos="0 0 0" axis="-0.0107916 0.0785589 -0.996851" stiffness="0.00603423" range="-0.958134 0.703489" armature="0.0153359" damping="0.0399807" frictionloss="0.0640971"/>
          <geom name="//unnamed_geom_21" class="visual" mesh="right_thigh_yaw_link"/>
          <body name="right_thigh_pitch_link" pos="0.0198648 -0.0173838 -0.131757" quat="0.999999 -0.000385032 -0.000807064 0.00094369">
            <inertial pos="-0.0155205 0.0306057 -0.0688529" quat="0.996793 -0.0710369 -0.00928427 0.0356413" mass="16.6883" diaginertia="0.775423 0.748143 0.0249889"/>
            <joint name="right_hip_pitch_joint" class="/" pos="0 0 0" axis="0.0282419 -0.999337 -0.0229722" range="-0.344357 1.52203" armature="0.0576109" damping="0.100366" frictionloss="0.25652"/>
            <geom name="//unnamed_geom_22" class="visual" mesh="right_thigh_pitch_link"/>
            <geom name="right_thigh_pitch_link.STL" class="collision" size="0.109476 0.166766" pos="-0.00315944 0.0447812 -0.171152" quat="0.999971 0.00269833 0.00706272 0" type="cylinder" rgba="0.752941 0.752941 0.752941 1"/>
            <geom name="//unnamed_geom_24" class="reward_collision_sphere" size="0.133508" pos="0 0.0149271 -0.051226"/>
            <body name="right_shank_pitch_link" pos="-0.00669749 0.0328232 -0.365428" quat="0.999999 -0.000777518 -0.00130412 -0.000184419">
              <inertial pos="0.00627398 0.020413 -0.102406" quat="0.999553 0.0249802 0.00832479 0.0141716" mass="3.92359" diaginertia="0.0983384 0.0856847 0.00172318"/>
              <joint name="right_knee_pitch_joint" class="/" pos="0 0 0" axis="0.078499 -0.996914 -0.0008727" range="-1.529 -0.0305334" armature="0.109241" damping="0" frictionloss="0.246797"/>
              <geom name="//unnamed_geom_25" class="visual" mesh="right_shank_pitch_link"/>
              <geom name="right_shank_pitch_link.STL" class="collision" size="0.0711878 0.12067" pos="-2.46861e-05 -0.00125769 -0.178983" type="cylinder" rgba="0.752941 0.752941 0.752941 1"/>
              <geom name="//unnamed_geom_27" class="reward_collision_sphere" size="0.0667538"/>
              <geom name="//unnamed_geom_28" class="reward_collision_sphere" size="0.0801046" pos="0 0 -0.112697"/>
              <body name="right_foot_pitch_link" pos="-0.016461 0.00957346 -0.347493" quat="0.999969 -0.00421575 0.00403615 0.00530925">
                <inertial pos="-0.0103098 0.00446181 0.0168617" quat="-0.0547708 0.716512 -0.00312061 0.695414" mass="0.197837" diaginertia="5.71008e-05 3.96727e-05 8.49466e-06"/>
                <joint name="right_ankle_pitch_joint" class="/" pos="0 0 0" axis="-0.0536673 -0.997638 0.042885" stiffness="0.0329591" range="-0.251501 1.06819" armature="0.110268" damping="0" frictionloss="0.184958"/>
                <geom name="//unnamed_geom_29" class="visual" mesh="right_foot_pitch_link"/>
                <body name="right_foot_roll_link" pos="0.000877686 0.00949084 -0.0169036" quat="0.999992 0.00216326 -0.00335438 -0.000682024">
                  <inertial pos="0.0386739 0.0140123 -0.043468" quat="-0.0837004 0.754571 -0.00242054 0.650854" mass="2.36646" diaginertia="0.042367 0.0430026 0.000776738"/>
                  <joint name="right_ankle_roll_joint" class="/" pos="0 0 0" axis="-0.997624 0.00157338 0.068872" stiffness="0.0468404" range="-0.215533 0.732253" armature="0.205063" damping="0.0918696" frictionloss="0.0327035"/>
                  <geom name="//unnamed_geom_30" class="visual" mesh="right_foot_roll_link"/>
                  <geom name="right_foot" class="foot" size="0.250904 0.0631244 0.00416297" pos="0.0669602 0 -0.0455912"/>
                  <geom name="//unnamed_geom_32" class="reward_collision_sphere" size="0.0667538" pos="0 0 -0.0307356"/>
                  <geom name="//unnamed_geom_33" class="reward_collision_sphere" size="0.0667538" pos="0.178561 0 -0.0307356"/>
                  <site name="right_foot" class="foot" pos="0.0669602 0 -0.0455912" size="0.0133508"/>
                </body>
              </body>
            </body>
          </body>
        </body>
      </body>
      <body name="waist_yaw_link" pos="-0.0114965 0.0195111 -0.00801007" quat="0.999952 -0.000738148 0.00833614 0.00506909">
        <inertial pos="0.00900573 -0.0174107 0.0585396" quat="0.965748 0.22088 -0.12174 0.0610052" mass="4.38238" diaginertia="0.0185627 0.0196021 0.00211502"/>
        <joint name="waist_yaw_joint" class="/" pos="0 0 0" axis="-0.021857 0.0510902 0.998455" range="-0.776486 0.768101" armature="0.123064" damping="0" frictionloss="0.169033"/>
        <geom name="//unnamed_geom_34" class="visual" rgba="0.12 0.12 0.12 1" mesh="waist_yaw_link"/>
        <body name="waist_pitch_link" pos="-0.00978942 -0.0171273 0.0815287" quat="0.999984 -0.0052606 -0.000210194 -0.00192432">
          <inertial pos="0.00709718 -0.0228344 0.0517213" quat="0.995741 -0.0857733 -0.033755 0.0018224" mass="3.41068" diaginertia="0.040872 0.0405417 0.00203591"/>
          <joint name="waist_pitch_joint" class="/" pos="0 0 0" axis="0.00692751 -0.999971 0.00324897" stiffness="0.0331785" range="-0.907024 0.215844" armature="0.189233" damping="0.0201213" frictionloss="0.000420811"/>
          <geom name="//unnamed_geom_35" class="visual" rgba="0.12 0.12 0.12 1" mesh="waist_pitch_link"/>
          <body name="waist_roll_link" pos="0.0102321 -0.0191819 0.0745473" quat="1 0.000495796 -0.000603393 -0.000319243">
            <inertial pos="-0.00503352 0.000434096 0.146174" quat="0.997808 0.0320568 -0.0577715 -0.00369138" mass="21.0434" diaginertia="0.484928 0.519569 0.0511883"/>
            <joint name="waist_roll_joint" class="/" pos="0 0 0" axis="-0.998609 0.0491331 -0.019145" range="-0.512489 0.336619" armature="0.00665641" damping="0" frictionloss="0.0764598"/>
            <geom name="//unnamed_geom_36" class="visual" rgba="0.12 0.12 0.12 1" mesh="waist_roll_link"/>
            <geom name="//unnamed_geom_37" class="visual" pos="-0.00334801 0.000857455 0.164282" quat="1 0 0 0" mesh="torso_link"/>
            <geom name="torso_link.STL" class="collision" size="0.210177 0.04031" pos="-0.0268821 0.00861261 0.151454" type="cylinder" rgba="0.752941 0.752941 0.752941 1"/>
            <geom name="//unnamed_geom_39" class="reward_collision_sphere" size="0.17356" pos="0 0 0.204904"/>
            <body name="left_upper_arm_pitch_link" pos="-0.0130934 0.138197 0.223753" quat="0.97797 0.208717 -0.00130536 0.0030676">
              <inertial pos="0.0228101 0.0749963 0.0150721" quat="0.720896 0.685064 0.0265433 -0.101449" mass="1.44625" diaginertia="0.0107219 0.0131414 0.00041351"/>
              <joint name="left_shoulder_pitch_joint" class="/" pos="0 0 0" axis="-5.13597e-05 0.997078 -0.0763914" stiffness="0.0771074" range="-2.94983 1.62552" armature="0.191721" damping="0" frictionloss="0.116184"/>
              <geom name="//unnamed_geom_40" class="visual" mesh="left_upper_arm_pitch_link"/>
              <body name="left_upper_arm_roll_link" pos="0.0184902 0.158652 -0.00236763" quat="0.976293 -0.216415 0.0010181 0.00388224">
                <inertial pos="0.00422167 0.0209137 -0.0301109" quat="0.877816 0.290977 0.14315 -0.352533" mass="1.81753" diaginertia="0.00810113 0.0085459 0.000407911"/>
                <joint name="left_shoulder_roll_joint" class="/" pos="0 0 0" axis="-0.99999 -0.00380731 -0.00245225" range="-2.4327 0.421921" armature="0.203567" damping="0" frictionloss="0.12314"/>
                <geom name="//unnamed_geom_41" class="visual" mesh="left_upper_arm_roll_link"/>
                <body name="left_upper_arm_yaw_link" pos="-0.0173466 0.0536676 -0.0716565" quat="0.999989 0.00409513 0.0019799 0.00137913">
                  <inertial pos="-0.0176254 -0.0092058 -0.100579" quat="0.997808 0.057299 -0.0313744 0.0105847" mass="1.17014" diaginertia="0.0251759 0.0255625 0.000195479"/>
                  <joint name="left_shoulder_yaw_joint" class="/" pos="0 0 0" axis="-0.0181317 0.0709783 0.997313" range="-2.91695 2.74476" armature="0.0029759" damping="0" frictionloss="0.210535"/>
                  <geom name="//unnamed_geom_42" class="visual" mesh="left_upper_arm_yaw_link"/>
                  <geom name="left_upper_arm_yaw_link.STL" class="collision" size="0.0483741 0.113404" pos="5.87545e-05 -0.00133491 -0.0812855" quat="0.00803418 -0.995528 0.0941277 0" type="cylinder" rgba="0.752941 0.752941 0.752941 1"/>
                  <body name="left_lower_arm_pitch_link" pos="-0.00478995 0.010814 -0.173254" quat="0.999997 -0.00154142 -0.00059034 -0.00182588">
                    <inertial pos="-0.0175062 0.0137566 -0.0282118" quat="0.699933 -0.11561 0.0991334 0.697783" mass="0.81296" diaginertia="0.00200599 0.00214897 0.000113211"/>
                    <joint name="left_elbow_pitch_joint" class="/" pos="0 0 0" axis="0.0253436 0.999579 -0.0141023" range="-2.35063 2.59114" armature="0.0934471" damping="0.0775595" frictionloss="0.149201"/>
                    <geom name="//unnamed_geom_44" class="visual" mesh="left_lower_arm_pitch_link"/>
                    <body name="left_hand_yaw_link" pos="0.0158667 -0.00123377 -0.0713699" quat="0.999995 0.0021387 -0.00219967 0.000794401">
                      <inertial pos="-0.0183409 -0.0108375 -0.0581749" quat="0.99651 0.0331845 0.0251564 -0.0723509" mass="2.06497" diaginertia="0.0127375 0.0114433 0.000377252"/>
                      <joint name="left_wrist_yaw_joint" class="/" pos="0 0 0" axis="-0.057559 -0.0148677 0.998231" range="-2.89206 2.95938" armature="0.170901" damping="0" frictionloss="0.172909"/>
                      <geom name="//unnamed_geom_45" class="visual" mesh="left_hand_yaw_link"/>
                      <geom name="left_hand_yaw_link.STL" class="collision" size="0.0555017 0.0929129" pos="0.00162081 -0.00230042 -0.0779075" type="cylinder" rgba="0.752941 0.752941 0.752941 1"/>
                      <geom name="//unnamed_geom_47" class="reward_collision_sphere" size="0.0667538"/>
                      <body name="left_hand_roll_link" pos="0.016446 0.0153722 -0.210765" quat="0.999986 -0.00201835 -0.00115059 0.00479507">
                        <inertial pos="-0.0146558 -0.00506687 0.0180311" quat="0.512628 0.430151 0.548406 0.501431" mass="0.0140948" diaginertia="2.92239e-06 3.37175e-06 7.96142e-08"/>
                        <joint name="left_wrist_roll_joint" class="/" pos="0 0 0" axis="-0.999958 0.00375374 -0.00831716" range="-0.779309 1.264" armature="0.0368533" damping="0.0489001" frictionloss="0.120101"/>
                        <geom name="//unnamed_geom_48" class="visual" mesh="left_hand_roll_link"/>
                        <body name="left_hand_pitch_link" pos="-0.0115434 0.00640281 0.0128312" quat="1 0.00017203 -0.000262104 0.000547776">
                          <inertial pos="-0.0162347 -0.0192235 -0.0426874" quat="0.695077 -0.0931668 0.0748108 0.708936" mass="0.67351" diaginertia="0.00232181 0.00226165 0.000136938"/>
                          <joint name="left_wrist_pitch_joint" class="/" pos="0 0 0" axis="-0.0847499 0.996071 0.0256955" stiffness="0.0567637" range="-0.742861 0.297757" armature="0.215174" damping="0" frictionloss="0.195246"/>
                          <geom name="//unnamed_geom_49" class="visual" mesh="left_hand_pitch"/>
                          <body name="left_jaw_link" pos="0.0184072 -0.0191546 -0.0749284" quat="0.999951 -0.00264251 -0.0063946 0.00709191">
                            <inertial pos="-0.0190452 -0.0107468 -0.0180208" quat="0.678827 -0.0566307 -0.00499866 0.732094" mass="0.14074" diaginertia="0.000570822 0.000436231 2.96269e-05"/>
                            <joint name="left_jaw_joint" class="/" pos="0 0 0" axis="-0.999802 -0.0182453 0.00792264" range="-1.20728 -0.274807" armature="0.260295" damping="0.0239388" frictionloss="0.0499884"/>
                            <geom name="//unnamed_geom_50" class="visual" mesh="left_jaw_link"/>
                            <geom name="//unnamed_geom_51" class="collision" size="0.0480628"/>
                            <geom name="//unnamed_geom_52" class="reward_collision_sphere" size="0.0667538" pos="0 0 -0.0204904"/>
                          </body>
                        </body>
                      </body>
                    </body>
                  </body>
                </body>
              </body>
            </body>
            <body name="right_upper_arm_pitch_link" pos="-0.00642771 -0.14829 0.223214" quat="0.977699 -0.209961 -0.00212444 -0.00398519">
              <inertial pos="0.0123987 -0.0896272 -0.000575282" quat="0.687261 0.719938 0.090903 0.0331344" mass="2.01217" diaginertia="0.0197934 0.0161628 0.000782573"/>
              <joint name="right_shoulder_pitch_joint" class="/" pos="0 0 0" axis="-0.0249105 -0.997918 -0.0594893" stiffness="0.00676718" range="-1.99576 2.98373" armature="0.208989" damping="0.0800602" frictionloss="0.239763"/>
              <geom name="//unnamed_geom_53" class="visual" mesh="right_upper_arm_pitch_link"/>
              <body name="right_upper_arm_roll_link" pos="0.00226857 -0.141286 -0.0104295" quat="0.976918 0.213506 0.00561681 -0.00376856">
                <inertial pos="-0.0033416 -0.0102755 -0.0065757" quat="0.880862 -0.259587 0.090004 0.385482" mass="1.84308" diaginertia="0.00772697 0.0104513 0.000471337"/>
                <joint name="right_shoulder_roll_joint" class="/" pos="0 0 0" axis="-0.996401 -0.0552069 0.0643269" range="-0.356963 2.21635" armature="0.164706" damping="0" frictionloss="0.224226"/>
                <geom name="//unnamed_geom_54" class="visual" mesh="right_upper_arm_roll_link"/>
                <body name="right_upper_arm_yaw_link" pos="0.00600532 -0.0564135 -0.0548122" quat="0.999985 -0.0028765 0.00465747 0.000502307">
                  <inertial pos="-0.0171738 0.00126191 -0.102397" quat="0.998006 0.00932222 0.00738169 -0.0619836" mass="0.783993" diaginertia="0.0220049 0.0202944 0.000202074"/>
                  <joint name="right_shoulder_yaw_joint" class="/" pos="0 0 0" axis="-0.0178471 0.0268004 0.999481" stiffness="0.0825408" range="-3.24033 2.85812" armature="0.210203" damping="0" frictionloss="0.243668"/>
                  <geom name="//unnamed_geom_55" class="visual" mesh="right_upper_arm_yaw_link"/>
                  <geom name="right_upper_arm_yaw_link.STL" class="collision" size="0.0483741 0.113404" pos="5.87545e-05 0.00133491 -0.0812855" type="cylinder" rgba="0.752941 0.752941 0.752941 1"/>
                  <body name="right_lower_arm_pitch_link" pos="-0.0124098 -0.0165772 -0.188839" quat="0.999998 -0.000853347 0.000836728 -0.00162883">
                    <inertial pos="-0.00382471 -0.00244612 -0.0173668" quat="0.683908 0.183908 -0.0604435 0.703416" mass="0.950074" diaginertia="0.00241144 0.00187432 9.48232e-05"/>
                    <joint name="right_elbow_pitch_joint" class="/" pos="0 0 0" axis="0.0690985 -0.99749 -0.0154669" stiffness="0.0309295" range="-1.99452 2.25707" armature="0.249899" damping="0.0491687" frictionloss="0.254033"/>
                    <geom name="//unnamed_geom_57" class="visual" mesh="right_lower_arm_pitch_link"/>
                    <body name="right_hand_yaw_link" pos="-0.00697516 -0.00187842 -0.0740466" quat="1 0.000106484 0.000750625 -0.00040375">
                      <inertial pos="-0.011708 -0.0096346 -0.0771544" quat="0.996314 -0.0690271 -0.049243 0.0129756" mass="1.88803" diaginertia="0.0144391 0.0138878 0.000491843"/>
                      <joint name="right_wrist_yaw_joint" class="/" pos="0 0 0" axis="-0.0079602 0.0175255 0.999815" stiffness="0.0125649" range="-2.93869 2.8029" armature="0.255915" damping="0" frictionloss="0.209077"/>
                      <geom name="//unnamed_geom_58" class="visual" mesh="right_hand_yaw_link"/>
                      <geom name="right_hand_yaw_link.STL" class="collision" size="0.0555017 0.0929129" pos="0.00162081 0.000956994 -0.0779075" type="cylinder" rgba="0.752941 0.752941 0.752941 1"/>
                      <geom name="//unnamed_geom_60" class="reward_collision_sphere" size="0.0667538"/>
                      <body name="right_hand_roll_link" pos="0.00827282 0.012906 -0.215586" quat="1 0.000295217 0.000261855 -6.74642e-05">
                        <inertial pos="-0.00454859 0.00728567 0.0115341" quat="0.569443 0.460778 0.498751 0.463321" mass="0.0111825" diaginertia="1.94387e-06 2.67207e-06 7.8776e-08"/>
                        <joint name="right_wrist_roll_joint" class="/" pos="0 0 0" axis="-0.999821 0.0091084 -0.0166017" range="-0.830074 1.04415" armature="0.0897671" damping="0.0183491" frictionloss="0.077557"/>
                        <geom name="//unnamed_geom_61" class="visual" mesh="right_hand_roll_link"/>
                        <body name="right_hand_pitch_link" pos="0.0164106 -0.0163772 -0.00774907" quat="0.999968 0.00789099 -0.000780695 0.00047783">
                          <inertial pos="-0.00581214 0.0132758 -0.0720377" quat="0.71871 0.203374 -0.133169 0.65143" mass="0.579148" diaginertia="0.00213272 0.00214968 0.000103898"/>
                          <joint name="right_wrist_pitch_joint" class="/" pos="0 0 0" axis="0.00965067 -0.99865 0.0510332" range="-0.740977 0.691205" armature="0.172778" damping="0" frictionloss="0.2442"/>
                          <geom name="//unnamed_geom_62" class="visual" mesh="right_hand_pitch"/>
                          <body name="right_jaw_link" pos="-0.000545926 -0.00304153 -0.0738821" quat="0.999999 0.00080493 0.000930096 0.000623114">
                            <inertial pos="-0.00551794 0.0109301 -0.0350939" quat="0.739386 0.0624026 -0.037785 0.669318" mass="0.119713" diaginertia="0.000508155 0.000350998 3.29408e-05"/>
                            <joint name="right_jaw_joint" class="/" pos="0 0 0" axis="-0.999869 0.00234799 -0.0160268" stiffness="0.0210375" range="0.203317 0.883218" armature="0.0244172" damping="0" frictionloss="0.216536"/>
                            <geom name="//unnamed_geom_63" class="visual" mesh="right_jaw_link"/>
                            <geom name="//unnamed_geom_64" class="collision" size="0.0480628"/>
                            <geom name="//unnamed_geom_65" class="reward_collision_sphere" size="0.0667538" pos="0 0 -0.0204904"/>
                          </body>
                        </body>
                      </body>
                    </body>
                  </body>
                </body>
              </body>
            </body>
            <body name="head_roll_link" pos="0.00880217 0.0151969 0.301581" quat="0.999952 -0.00130395 0.00928658 -0.00277789">
              <inertial pos="0.00861164 0.00424466 0.00268716" quat="-0.00644662 0.771517 -0.0119108 0.636064" mass="0.0205246" diaginertia="4.18906e-06 3.05365e-06 4.8106e-07"/>
              <joint name="head_roll_joint" class="/" pos="0 0 0" axis="-0.99934 0.0186099 0.0311888" stiffness="0.0840864" range="-0.385217 0.0542461" armature="0.244326" damping="0.0717297" frictionloss="0.126141"/>
              <geom name="//unnamed_geom_66" class="visual" mesh="head_roll_link"/>
              <body name="head_pitch_link" pos="-0.0134092 0.000760636 -0.0140563" quat="0.999989 -0.00420624 -0.000383323 0.0017782">
                <inertial pos="0.00893962 -0.00961757 0.0106016" quat="0.711424 0.639288 0.234709 -0.173487" mass="0.189168" diaginertia="0.000186183 0.000250419 2.49561e-05"/>
                <joint name="head_pitch_joint" class="/" pos="0 0 0" axis="-0.0152304 -0.99988 0.00293947" range="-1.06248 0.502518" armature="0.0155717" damping="0.0865755" frictionloss="0.0262097"/>
                <geom name="//unnamed_geom_67" class="visual" mesh="head_pitch_link"/>
                <body name="head_yaw_link" pos="0.0175838 0.0140499 0.0659509" quat="1 0.000404769 0.000331078 -0.000416473">
                  <inertial pos="0.0557979 -0.00307773 0.116512" quat="0.691208 -0.18371 -0.161501 0.68" mass="3.21076" diaginertia="0.0824592 0.0479247 0.00524267"/>
                  <joint name="head_yaw_joint" class="/" pos="0 0 0" axis="-0.0500915 0.0110356 0.998684" range="-3.06494 2.3774" armature="0.0772998" damping="0.108917" frictionloss="0.260217"/>
                  <geom name="//unnamed_geom_68" class="visual" rgba="0.12 0.12 0.12 1" mesh="head_yaw_link"/>
                  <geom name="head_yaw_link.STL" class="collision" size="0.158456" pos="0.0272024 -0.00131362 0.0959159" rgba="0.752941 0.752941 0.752941 1"/>
                  <geom name="//unnamed_geom_70" class="reward_collision_sphere" size="0.133508" pos="0.0446401 0 0.102452"/>
                  <camera name="ego_camera" class="/" pos="0.163681 0 0.112697" quat="-0.5 -0.5 0.5 0.5"/>
                </body>
              </body>
            </body>
          </body>
        </body>
      </body>
    </body>
  </worldbody>

  <contact>
    <pair class="/" geom1="floor" geom2="left_foot" name="//unnamed_contact_0"/>
    <pair class="/" geom1="floor" geom2="right_foot" name="//unnamed_contact_1"/>
  </contact>

  <actuator>
    <general name="left_hip_roll" class="/" joint="left_hip_roll_joint" forcerange="-84.3994 84.3994" gainprm="64.103" biasprm="0 -64.103 -1.51804"/>
    <general name="left_hip_yaw" class="/" joint="left_hip_yaw_joint" forcerange="-115.717 115.717" gainprm="64.103" biasprm="0 -64.103 -1.51804"/>
    <general name="left_hip_pitch" class="/" joint="left_hip_pitch_joint" forcerange="-265.167 265.167" gainprm="64.103" biasprm="0 -64.103 -1.51804"/>
    <general name="left_knee_pitch" class="/" joint="left_knee_pitch_joint" forcerange="-282.108 282.108" gainprm="64.103" biasprm="0 -64.103 -1.51804"/>
    <general name="left_ankle_pitch" class="/" joint="left_ankle_pitch_joint" forcerange="-10.2084 10.2084" gainprm="64.103" biasprm="0 -64.103 -1.51804"/>
    <general name="left_ankle_roll" class="/" joint="left_ankle_roll_joint" forcerange="-60.1613 60.1613" gainprm="64.103" biasprm="0 -64.103 -1.51804"/>
    <general name="right_hip_roll" class="/" joint="right_hip_roll_joint" forcerange="-50.3039 50.3039" gainprm="64.103" biasprm="0 -64.103 -1.51804"/>
    <general name="right_hip_yaw" class="/" joint="right_hip_yaw_joint" forcerange="-60.7526 60.7526" gainprm="64.103" biasprm="0 -64.103 -1.51804"/>
    <general name="right_hip_pitch" class="/" joint="right_hip_pitch_joint" forcerange="-493.546 493.546" gainprm="64.103" biasprm="0 -64.103 -1.51804"/>
    <general name="right_knee_pitch" class="/" joint="right_knee_pitch_joint" forcerange="-212.724 212.724" gainprm="64.103" biasprm="0 -64.103 -1.51804"/>
    <general name="right_ankle_pitch" class="/" joint="right_ankle_pitch_joint" forcerange="-10.9535 10.9535" gainprm="64.103" biasprm="0 -64.103 -1.51804"/>
    <general name="right_ankle_roll" class="/" joint="right_ankle_roll_joint" forcerange="-32.9884 32.9884" gainprm="64.103" biasprm="0 -64.103 -1.51804"/>
    <general name="waist_yaw" class="/" joint="waist_yaw_joint" forcerange="-90.1877 90.1877" gainprm="64.103" biasprm="0 -64.103 -1.51804"/>
    <general name="waist_pitch" class="/" joint="waist_pitch_joint" forcerange="-103.203 103.203" gainprm="64.103" biasprm="0 -64.103 -1.51804"/>
    <general name="waist_roll" class="/" joint="waist_roll_joint" forcerange="-74.69 74.69" gainprm="64.103" biasprm="0 -64.103 -1.51804"/>
    <general name="left_shoulder_pitch" class="/" joint="left_shoulder_pitch_joint" forcerange="-64.7505 64.7505" gainprm="64.103" biasprm="0 -64.103 -1.51804"/>
    <general name="left_shoulder_roll" class="/" joint="left_shoulder_roll_joint" forcerange="-14.4317 14.4317" gainprm="64.103" biasprm="0 -64.103 -1.51804"/>
    <general name="left_shoulder_yaw" class="/" joint="left_shoulder_yaw_joint" forcerange="-65.6803 65.6803" gainprm="64.103" biasprm="0 -64.103 -1.51804"/>
    <general name="left_elbow_pitch" class="/" joint="left_elbow_pitch_joint" forcerange="-37.7236 37.7236" gainprm="64.103" biasprm="0 -64.103 -1.51804"/>
    <general name="left_wrist_yaw" class="/" joint="left_wrist_yaw_joint" forcerange="-12.5687 12.5687" gainprm="64.103" biasprm="0 -64.103 -1.51804"/>
    <general name="left_wrist_roll" class="/" joint="left_wrist_roll_joint" forcerange="-4.85202 4.85202" gainprm="64.103" biasprm="0 -64.103 -1.51804"/>
    <general name="left_wrist_pitch" class="/" joint="left_wrist_pitch_joint" forcerange="-3.49997 3.49997" gainprm="64.103" biasprm="0 -64.103 -1.51804"/>
    <general name="left_jaw" class="/" joint="left_jaw_joint" forcerange="-7.76433 7.76433" gainprm="64.103" biasprm="0 -64.103 -1.51804"/>
    <general name="right_shoulder_pitch" class="/" joint="right_shoulder_pitch_joint" forcerange="-47.1461 47.1461" gainprm="64.103" biasprm="0 -64.103 -1.51804"/>
    <general name="right_shoulder_roll" class="/" joint="right_shoulder_roll_joint" forcerange="-19.9584 19.9584" gainprm="64.103" biasprm="0 -64.103 -1.51804"/>
    <general name="right_shoulder_yaw" class="/" joint="right_shoulder_yaw_joint" forcerange="-31.0493 31.0493" gainprm="64.103" biasprm="0 -64.103 -1.51804"/>
    <general name="right_elbow_pitch" class="/" joint="right_elbow_pitch_joint" forcerange="-39.1524 39.1524" gainprm="64.103" biasprm="0 -64.103 -1.51804"/>
    <general name="right_wrist_yaw" class="/" joint="right_wrist_yaw_joint" forcerange="-10.7488 10.7488" gainprm="64.103" biasprm="0 -64.103 -1.51804"/>
    <general name="right_wrist_roll" class="/" joint="right_wrist_roll_joint" forcerange="-2.12931 2.12931" gainprm="64.103" biasprm="0 -64.103 -1.51804"/>
    <general name="right_wrist_pitch" class="/" joint="right_wrist_pitch_joint" forcerange="-8.34941 8.34941" gainprm="64.103" biasprm="0 -64.103 -1.51804"/>
    <general name="right_jaw" class="/" joint="right_jaw_joint" forcerange="-2.51272 2.51272" gainprm="64.103" biasprm="0 -64.103 -1.51804"/>
    <general name="head_roll" class="/" joint="head_roll_joint" forcerange="-7.08532 7.08532" gainprm="64.103" biasprm="0 -64.103 -1.51804"/>
    <general name="head_pitch" class="/" joint="head_pitch_joint" forcerange="-4.67534 4.67534" gainprm="64.103" biasprm="0 -64.103 -1.51804"/>
    <general name="head_yaw" class="/" joint="head_yaw_joint" forcerange="-5.23754 5.23754" gainprm="64.103" biasprm="0 -64.103 -1.51804"/>
  </actuator>

  <sensor>
    <gyro site="imu" name="imu_angular_velocity"/>
    <velocimeter site="imu" name="imu_linear_velocity"/>
    <framelinvel objtype="site" objname="left_foot" name="left_foot_global_linear_velocity"/>
    <framelinvel objtype="site" objname="right_foot" name="right_foot_global_linear_velocity"/>
  </sensor>

  <keyframe>
    <key name="home" qpos="0 0 0.8665 1 0 0 0 0 0 -0.4 0.8 -0.4 0 0 0 0.4 -0.8 0.4 0 0 0 0 0 -0.2 0 -0.785 0 0 0 0 0 0.2 0 0.785 0 0 0 0 0 0 0"/>
  </keyframe>
</mujoco>
