<mujoco model="GR1T2_jaw">
  <compiler angle="radian" assetdir="assets" balanceinertia="true" inertiafromgeom="false"/>

  <option timestep="0.005" density="1.2" viscosity="2e-05"/>

  <size nkey="1"/>

  <visual>
    <quality shadowsize="8192"/>
    <map shadowclip="0.5"/>
  </visual>

  <default>
    <default class="/">
      <joint armature="0.1" damping="0.01" frictionloss="0.1"/>
      <geom contype="0" conaffinity="0" group="1" solref="-1000 -80"/>
      <site size="0.01 0.005 0.005" group="5"/>
      <general forcelimited="true" biastype="affine" gainprm="80" biasprm="0 -80 -2"/>
      <default class="visual">
        <geom type="mesh" density="0" rgba="0.18 0.18 0.18 1"/>
      </default>
      <default class="collision">
        <geom group="3"/>
      </default>
      <default class="foot">
        <geom size="0.126 0.045 0.01" type="box" condim="6" group="4" priority="1" solimp="0.015 1 0.01"/>
      </default>
      <default class="reward_collision_sphere">
        <geom group="5" rgba="1 0 0 1"/>
      </default>
    </default>
  </default>

  <asset>
    <texture type="skybox" colorspace="auto" name="//unnamed_texture_0" builtin="gradient" rgb1="0.95 0.95 0.95" rgb2="0.95 0.95 0.95" width="100" height="600"/>
    <texture type="2d" colorspace="auto" name="texplane" builtin="checker" rgb1="0.345 0.575 0.748" rgb2="0.345 0.575 0.748" markrgb="1 1 1" width="512" height="512"/>
    <material name="MatPlane" class="/" texture="texplane" texuniform="true" texrepeat="2 2" specular="0.9"/>
    <mesh name="base_link" class="/" file="base_link.STL"/>
    <mesh name="left_thigh_roll_link" class="/" file="left_thigh_roll_link.STL"/>
    <mesh name="left_thigh_yaw_link" class="/" file="left_thigh_yaw_link.STL"/>
    <mesh name="left_thigh_pitch_link" class="/" file="left_thigh_pitch_link.STL"/>
    <mesh name="left_shank_pitch_link" class="/" file="left_shank_pitch_link.STL"/>
    <mesh name="left_foot_pitch_link" class="/" file="left_foot_pitch_link.STL"/>
    <mesh name="left_foot_roll_link" class="/" file="left_foot_roll_link.STL"/>
    <mesh name="right_thigh_roll_link" class="/" file="right_thigh_roll_link.STL"/>
    <mesh name="right_thigh_yaw_link" class="/" file="right_thigh_yaw_link.STL"/>
    <mesh name="right_thigh_pitch_link" class="/" file="right_thigh_pitch_link.STL"/>
    <mesh name="right_shank_pitch_link" class="/" file="right_shank_pitch_link.STL"/>
    <mesh name="right_foot_pitch_link" class="/" file="right_foot_pitch_link.STL"/>
    <mesh name="right_foot_roll_link" class="/" file="right_foot_roll_link.STL"/>
    <mesh name="waist_yaw_link" class="/" file="waist_yaw_link.STL"/>
    <mesh name="waist_pitch_link" class="/" file="waist_pitch_link.STL"/>
    <mesh name="waist_roll_link" class="/" file="waist_roll_link.STL"/>
    <mesh name="torso_link" class="/" file="torso_link.STL"/>
    <mesh name="left_upper_arm_pitch_link" class="/" file="left_upper_arm_pitch_link.STL"/>
    <mesh name="left_upper_arm_roll_link" class="/" file="left_upper_arm_roll_link.STL"/>
    <mesh name="left_upper_arm_yaw_link" class="/" file="left_upper_arm_yaw_link.STL"/>
    <mesh name="left_lower_arm_pitch_link" class="/" file="left_lower_arm_pitch_link.STL"/>
    <mesh name="left_hand_yaw_link" class="/" file="left_hand_yaw_link.STL"/>
    <mesh name="left_hand_roll_link" class="/" file="left_hand_roll_link.STL"/>
    <mesh name="left_hand_pitch" class="/" file="left_hand_pitch.STL"/>
    <mesh name="left_jaw_link" class="/" file="left_jaw_link.STL"/>
    <mesh name="right_upper_arm_pitch_link" class="/" file="right_upper_arm_pitch_link.STL"/>
    <mesh name="right_upper_arm_roll_link" class="/" file="right_upper_arm_roll_link.STL"/>
    <mesh name="right_upper_arm_yaw_link" class="/" file="right_upper_arm_yaw_link.STL"/>
    <mesh name="right_lower_arm_pitch_link" class="/" file="right_lower_arm_pitch_link.STL"/>
    <mesh name="right_hand_yaw_link" class="/" file="right_hand_yaw_link.STL"/>
    <mesh name="right_hand_roll_link" class="/" file="right_hand_roll_link.STL"/>
    <mesh name="right_hand_pitch" class="/" file="right_hand_pitch.STL"/>
    <mesh name="right_jaw_link" class="/" file="right_jaw_link.STL"/>
    <mesh name="head_roll_link" class="/" file="head_roll_link.STL"/>
    <mesh name="head_pitch_link" class="/" file="head_pitch_link.STL"/>
    <mesh name="head_yaw_link" class="/" file="head_yaw_link.STL"/>
    <mesh name="imu_link" class="/" file="imu_link.STL"/>
  </asset>

  <worldbody>
    <geom name="floor" class="/" size="100 100 0.125" type="plane" group="0" material="MatPlane"/>
    <light name="toplight_shadow" class="/" pos="0 0 5" dir="0.0990148 0.0990148 -0.990148" type="directional" ambient="0.04 0.04 0.04" diffuse="0.55 0.55 0.55" specular="0.12 0.12 0.12"/>
    <light name="toplight_fill" class="/" pos="0 0 5" dir="0.0990148 0.0990148 -0.990148" type="directional" castshadow="false" ambient="0.04 0.04 0.04" diffuse="0.3 0.3 0.3" specular="0.08 0.08 0.08"/>
    <body name="trunk" pos="-0.00267846 -0.00161009 -0.00498792" quat="1 0.00071618 0.000134515 0.000352206">
      <inertial pos="-0.0758047 -0.011294 -0.0189513" quat="0.999285 -0.033346 -0.00875162 0.0155395" mass="4.18667" diaginertia="0.106764 0.0337316 0.0114983"/>
      <joint name="//unnamed_joint_0" type="free"/>
      <geom name="//unnamed_geom_1" class="visual" rgba="0.12 0.12 0.12 1" mesh="base_link"/>
      <geom name="base_link.STL" class="collision" size="0.129582 0.0725763" pos="-0.0515291 0.000448745 0.006939" quat="0.706838 -0.707359 0.00477667 0" type="cylinder" rgba="0.752941 0.752941 0.752941 1"/>
      <geom name="//unnamed_geom_3" class="visual" pos="0 0 -0.0449034" quat="1 0 0 0" rgba="0.12 0.12 0.12 1" mesh="imu_link"/>
      <geom name="//unnamed_geom_4" class="reward_collision_sphere" size="0.0846984" pos="0 0.121269 0.0753412"/>
      <geom name="//unnamed_geom_5" class="reward_collision_sphere" size="0.0846984" pos="0 -0.121269 0.0753412"/>
      <site name="imu" class="/" pos="0.00517402 0.039586 -0.109067" size="0.0105873"/>
      <camera name="track" class="/" pos="0 -2.42537 0" quat="0.707107 0.707107 0 0" mode="trackcom"/>
      <body name="left_thigh_roll_link" pos="-0.0262211 0.127527 -0.0175175" quat="0.999997 -0.000155997 0.00176571 0.00158078">
        <inertial pos="-0.00228524 0.00759725 -0.00530484" quat="-0.0450936 0.716136 -0.0355828 0.695593" mass="1.53031" diaginertia="0.00668934 0.00576494 0.000352816"/>
        <joint name="left_hip_roll_joint" class="/" pos="0 0 0" axis="-0.999876 -0.0115223 -0.0107586" stiffness="0.0290525" range="-0.717871 0.131475" armature="0.130254" damping="0" frictionloss="0.111102"/>
        <geom name="//unnamed_geom_6" class="visual" mesh="left_thigh_roll_link"/>
        <body name="left_thigh_yaw_link" pos="0.0371053 -0.00219424 0.00394552" quat="1 0.000122381 0.00020599 -0.000306733">
          <inertial pos="-0.000119324 0.0433245 -0.0935896" quat="0.571086 0.0956812 -0.193122 0.792092" mass="4.23413" diaginertia="0.0582652 0.0534068 0.00239409"/>
          <joint name="left_hip_yaw_joint" class="/" pos="0 0 0" axis="0.00175486 0.000720362 -0.999998" stiffness="0.0515512" range="-0.94951 0.68836" armature="0.137345" damping="0" frictionloss="0.0413064"/>
          <geom name="//unnamed_geom_7" class="visual" mesh="left_thigh_yaw_link"/>
          <body name="left_thigh_pitch_link" pos="0.0127583 0.0247303 -0.115333" quat="1 -2.26738e-05 0.000129937 -1.52306e-06">
            <inertial pos="-0.00386862 -0.0336788 -0.0469448" quat="0.999813 -0.0147198 -0.0110373 0.00601854" mass="10.769" diaginertia="0.251064 0.237336 0.00696591"/>
            <joint name="left_hip_pitch_joint" class="/" pos="0 0 0" axis="-0.00787982 0.998877 -0.0467293" range="-1.53321 0.46853" armature="0.162036" damping="0" frictionloss="0.0999796"/>
            <geom name="//unnamed_geom_8" class="visual" mesh="left_thigh_pitch_link"/>
            <geom name="left_thigh_pitch_link.STL" class="collision" size="0.0868158 0.13225" pos="0.000847124 -0.0363806 -0.125862" type="cylinder" rgba="0.752941 0.752941 0.752941 1"/>
            <geom name="//unnamed_geom_10" class="reward_collision_sphere" size="0.105873" pos="0 -0.0121269 -0.0376706"/>
            <body name="left_shank_pitch_link" pos="0.00549027 -0.0237638 -0.265312" quat="0.99999 0.00393348 -0.00161718 -0.0013311">
              <inertial pos="0.000246602 -0.000530319 -0.0892616" quat="0.99893 -0.0437796 -0.0107939 -0.0102955" mass="1.70901" diaginertia="0.0274916 0.0238466 0.000267355"/>
              <joint name="left_knee_pitch_joint" class="/" pos="0 0 0" axis="-0.0172877 0.999614 -0.0217392" range="-0.0985967 1.91619" armature="0.108966" damping="0.00490497" frictionloss="0.106153"/>
              <geom name="//unnamed_geom_11" class="visual" mesh="left_shank_pitch_link"/>
              <geom name="left_shank_pitch_link.STL" class="collision" size="0.0564529 0.0956933" pos="-2.00755e-05 -0.00102175 -0.131614" quat="0.00125538 -0.202712 0.979238 0" type="cylinder" rgba="0.752941 0.752941 0.752941 1"/>
              <geom name="//unnamed_geom_13" class="reward_collision_sphere" size="0.0529365"/>
              <geom name="//unnamed_geom_14" class="reward_collision_sphere" size="0.0635238" pos="0 0 -0.0828754"/>
              <body name="left_foot_pitch_link" pos="-0.000713562 -0.00451531 -0.257093" quat="0.999983 0.00323064 -0.00416354 0.00240587">
                <inertial pos="0.000590459 0.0100005 -0.00513923" quat="-0.0384024 0.709367 0.00830356 0.703743" mass="0.0577597" diaginertia="1.18874e-05 1.30055e-05 1.09653e-06"/>
                <joint name="left_ankle_pitch_joint" class="/" pos="0 0 0" axis="0.0495378 0.998547 -0.0212237" stiffness="0.0151211" range="-1.06044 0.340959" armature="0.107645" damping="0" frictionloss="0.103686"/>
                <geom name="//unnamed_geom_15" class="visual" mesh="left_foot_pitch_link"/>
                <body name="left_foot_roll_link" pos="-0.00381939 -0.0104268 0.00223496" quat="1 6.69807e-05 -2.87933e-05 7.85322e-05">
                  <inertial pos="0.0469609 -0.00310632 -0.0343389" quat="-0.00133879 0.724837 -0.000835925 0.688918" mass="1.57236" diaginertia="0.0190206 0.0174603 0.000211909"/>
                  <joint name="left_ankle_roll_joint" class="/" pos="0 0 0" axis="-0.998589 0.0123265 0.0516463" range="-0.445343 0.241964" armature="0.0424917" damping="0" frictionloss="0.139459"/>
                  <geom name="//unnamed_geom_16" class="visual" mesh="left_foot_roll_link"/>
                  <geom name="left_foot" class="foot" size="0.108201 0.0678109 0.0103907" pos="0.054454 0 -0.0335269"/>
                  <geom name="//unnamed_geom_18" class="reward_collision_sphere" size="0.0529365" pos="0 0 -0.0226024"/>
                  <geom name="//unnamed_geom_19" class="reward_collision_sphere" size="0.0529365" pos="0.145211 0 -0.0226024"/>
                  <site name="left_foot" class="foot" pos="0.054454 0 -0.0335269" size="0.0105873"/>
                </body>
              </body>
            </body>
          </body>
        </body>
      </body>
      <body name="right_thigh_roll_link" pos="-0.0447544 -0.130466 -0.0117633" quat="0.999996 9.10894e-05 -0.0028193 8.28313e-05">
        <inertial pos="0.000928446 -0.00951207 0.0118267" quat="0.02116 0.715112 0.0125475 0.698577" mass="1.73504" diaginertia="0.00776531 0.00607401 0.000409006"/>
        <joint name="right_hip_roll_joint" class="/" pos="0 0 0" axis="-0.998433 0.0521858 -0.0201942" range="-0.295992 0.792284" armature="0.0867519" damping="0.0116333" frictionloss="0.0997223"/>
        <geom name="//unnamed_geom_20" class="visual" mesh="right_thigh_roll_link"/>
        <body name="right_thigh_yaw_link" pos="0.0419722 -0.00361958 0.00169377" quat="0.999983 0.00253881 0.00303658 -0.00419201">
          <inertial pos="-0.00120526 -0.0526729 -0.0962664" quat="0.68647 -0.148642 0.151107 0.69558" mass="3.91229" diaginertia="0.0536864 0.0486919 0.00180873"/>
          <joint name="right_hip_yaw_joint" class="/" pos="0 0 0" axis="0.0387786 -0.0227982 -0.998988" range="-0.822021 0.701956" armature="0.0485137" damping="0.00794415" frictionloss="0.0867157"/>
          <geom name="//unnamed_geom_21" class="visual" mesh="right_thigh_yaw_link"/>
          <body name="right_thigh_pitch_link" pos="0.0128528 -0.0180582 -0.100636" quat="1 6.04659e-05 -0.000462199 -0.000383536">
            <inertial pos="-0.00903113 0.0295922 -0.04629" quat="0.999842 0.0015054 -0.00506938 -0.0169481" mass="9.59673" diaginertia="0.268617 0.257658 0.00623633"/>
            <joint name="right_hip_pitch_joint" class="/" pos="0 0 0" axis="0.000855706 -0.999997 0.00233316" range="-0.482362 1.65733" armature="0.0810851" damping="0.0620269" frictionloss="0.166853"/>
            <geom name="//unnamed_geom_22" class="visual" mesh="right_thigh_pitch_link"/>
            <geom name="right_thigh_pitch_link.STL" class="collision" size="0.0868158 0.132247" pos="-0.00256935 0.0363806 -0.125862" quat="0.999971 0.00269833 0.00706272 0" type="cylinder" rgba="0.752941 0.752941 0.752941 1"/>
            <geom name="//unnamed_geom_24" class="reward_collision_sphere" size="0.105873" pos="0 0.0121269 -0.0376706"/>
            <body name="right_shank_pitch_link" pos="-0.00155702 0.0209659 -0.273259" quat="1 -0.000438647 1.93151e-05 0.000230873">
              <inertial pos="-2.1831e-05 0.0132779 -0.0780608" quat="0.999703 0.00907061 0.0107455 0.0199109" mass="2.02775" diaginertia="0.0322745 0.0309134 0.000346815"/>
              <joint name="right_knee_pitch_joint" class="/" pos="0 0 0" axis="-0.00377365 -0.999033 0.0438004" range="-1.6673 0.0978435" armature="0.1155" damping="0.0103873" frictionloss="0.159199"/>
              <geom name="//unnamed_geom_25" class="visual" mesh="right_shank_pitch_link"/>
              <geom name="right_shank_pitch_link.STL" class="collision" size="0.0564526 0.0956923" pos="-2.00755e-05 -0.00102176 -0.13162" type="cylinder" rgba="0.752941 0.752941 0.752941 1"/>
              <geom name="//unnamed_geom_27" class="reward_collision_sphere" size="0.0529365"/>
              <geom name="//unnamed_geom_28" class="reward_collision_sphere" size="0.0635238" pos="0 0 -0.0828754"/>
              <body name="right_foot_pitch_link" pos="-0.00981813 0.00241656 -0.25856" quat="0.99999 -0.000132236 -0.00358715 -0.00262091">
                <inertial pos="-0.00353159 -0.00154568 0.00996109" quat="-0.0211393 0.712656 0.00289521 0.701189" mass="0.0850836" diaginertia="1.81622e-05 1.44282e-05 1.57248e-06"/>
                <joint name="right_ankle_pitch_joint" class="/" pos="0 0 0" axis="-0.0115733 -0.999407 0.0324434" range="-0.388746 1.06866" armature="0.11702" damping="0" frictionloss="0.111573"/>
                <geom name="//unnamed_geom_29" class="visual" mesh="right_foot_pitch_link"/>
                <body name="right_foot_roll_link" pos="0.000704111 0.0026487 -0.0101104" quat="1 -0.000433669 0.000539522 -4.28484e-05">
                  <inertial pos="0.0353609 0.00716638 -0.0273993" quat="0.0325619 0.730941 -0.0515313 0.679713" mass="1.21268" diaginertia="0.0152843 0.014643 0.000171983"/>
                  <joint name="right_ankle_roll_joint" class="/" pos="0 0 0" axis="-0.999399 -0.0346144 -0.00180142" stiffness="0.0117646" range="-0.35195 0.595035" armature="0.126598" damping="0.0606195" frictionloss="0.0623375"/>
                  <geom name="//unnamed_geom_30" class="visual" mesh="right_foot_roll_link"/>
                  <geom name="right_foot" class="foot" size="0.164164 0.038286 0.00605801" pos="0.054454 0 -0.0335269"/>
                  <geom name="//unnamed_geom_32" class="reward_collision_sphere" size="0.0529365" pos="0 0 -0.0226024"/>
                  <geom name="//unnamed_geom_33" class="reward_collision_sphere" size="0.0529365" pos="0.145211 0 -0.0226024"/>
                  <site name="right_foot" class="foot" pos="0.054454 0 -0.0335269" size="0.0105873"/>
                </body>
              </body>
            </body>
          </body>
        </body>
      </body>
      <body name="waist_yaw_link" pos="-0.00458025 0.0125861 -0.00113512" quat="0.99998 0.00128309 -0.00346497 0.00508694">
        <inertial pos="0.00258326 -0.00904923 0.0384417" quat="0.976266 0.216435 -0.000517712 0.00776971" mass="2.18078" diaginertia="0.007926 0.00822061 0.000532557"/>
        <joint name="waist_yaw_joint" class="/" pos="0 0 0" axis="-0.00257806 0.0220044 0.999755" range="-0.913871 0.904673" armature="0.10076" damping="0.00556981" frictionloss="0.101188"/>
        <geom name="//unnamed_geom_34" class="visual" rgba="0.12 0.12 0.12 1" mesh="waist_yaw_link"/>
        <body name="waist_pitch_link" pos="-0.00293875 -0.0102414 0.0648438" quat="0.999998 0.000477676 0.000277987 0.0020417">
          <inertial pos="0.00451258 -0.0145879 0.0341546" quat="0.992781 -0.0942916 0.0732925 0.0111107" mass="1.84992" diaginertia="0.0135632 0.0133717 0.000441549"/>
          <joint name="waist_pitch_joint" class="/" pos="0 0 0" axis="-8.04907e-05 -0.999997 0.00227445" range="-1.04455 0.352384" armature="0.114384" damping="0.0103352" frictionloss="0.036943"/>
          <geom name="//unnamed_geom_35" class="visual" rgba="0.12 0.12 0.12 1" mesh="waist_pitch_link"/>
          <body name="waist_roll_link" pos="0.00923344 -0.0121707 0.0595519" quat="1 -0.000304766 0.000640212 0.000493732">
            <inertial pos="-0.00829584 0.00223489 0.111085" quat="0.99863 -0.00449701 -0.0521376 -0.000230848" mass="9.01143" diaginertia="0.163946 0.157066 0.00942912"/>
            <joint name="waist_roll_joint" class="/" pos="0 0 0" axis="-0.999833 -0.00222854 -0.0181473" range="-0.650663 0.47404" armature="0.0418361" damping="0" frictionloss="0.0961028"/>
            <geom name="//unnamed_geom_36" class="visual" rgba="0.12 0.12 0.12 1" mesh="waist_roll_link"/>
            <geom name="//unnamed_geom_37" class="visual" pos="-0.0027227 0.000696603 0.12081" quat="1 0 0 0" mesh="torso_link"/>
            <geom name="torso_link.STL" class="collision" size="0.166673 0.0319662" pos="-0.0218614 0.00699696 0.111376" type="cylinder" rgba="0.752941 0.752941 0.752941 1"/>
            <geom name="//unnamed_geom_39" class="reward_collision_sphere" size="0.137635" pos="0 0 0.150682"/>
            <body name="left_upper_arm_pitch_link" pos="-0.0054949 0.116538 0.160854" quat="0.977417 0.21132 0.0001875 -0.000660255">
              <inertial pos="0.0149909 0.0661404 0.00822831" quat="0.709629 0.70232 0.0285468 -0.0485586" mass="0.859834" diaginertia="0.0046086 0.00478086 0.000106024"/>
              <joint name="left_shoulder_pitch_joint" class="/" pos="0 0 0" axis="-0.0360792 0.999118 -0.0214826" stiffness="0.0421335" range="-2.816 1.7636" armature="0.116985" damping="0" frictionloss="0.112666"/>
              <geom name="//unnamed_geom_40" class="visual" mesh="left_upper_arm_pitch_link"/>
              <body name="left_upper_arm_roll_link" pos="0.0117098 0.125133 0.00181221" quat="0.976556 -0.215263 0.000773476 0.000245485">
                <inertial pos="0.00782246 0.0220438 -0.0172962" quat="0.88953 0.269299 0.123548 -0.347778" mass="0.80955" diaginertia="0.00259226 0.00268797 8.41883e-05"/>
                <joint name="left_shoulder_roll_joint" class="/" pos="0 0 0" axis="-0.999922 -0.00960286 -0.00799538" stiffness="0.00349637" range="-2.55131 0.555439" armature="0.125662" damping="0" frictionloss="0.106889"/>
                <geom name="//unnamed_geom_41" class="visual" mesh="left_upper_arm_roll_link"/>
                <body name="left_upper_arm_yaw_link" pos="-0.0103577 0.0490752 -0.0530411" quat="0.999999 -0.000428148 -0.000403891 -0.00121766">
                  <inertial pos="-0.0107296 -0.00246737 -0.070029" quat="0.999477 0.00200144 -0.019772 -0.0255152" mass="0.61378" diaginertia="0.0090642 0.00915653 5.13164e-05"/>
                  <joint name="left_shoulder_yaw_joint" class="/" pos="0 0 0" axis="-0.0128085 -0.0365785 0.999249" range="-3.00869 2.88171" armature="0.0392312" damping="0" frictionloss="0.130873"/>
                  <geom name="//unnamed_geom_42" class="visual" mesh="left_upper_arm_yaw_link"/>
                  <geom name="left_upper_arm_yaw_link.STL" class="collision" size="0.0383612 0.0899306" pos="4.77809e-05 -0.00108449 -0.0597757" quat="0.00803418 -0.995528 0.0941277 0" type="cylinder" rgba="0.752941 0.752941 0.752941 1"/>
                  <body name="left_lower_arm_pitch_link" pos="0.00208648 0.00396675 -0.131596" quat="1 0.000672812 0.000128577 0.000278683">
                    <inertial pos="-0.0106048 0.00924305 -0.0163404" quat="0.698814 -0.0922769 0.0957916 0.702829" mass="0.412762" diaginertia="0.000736218 0.000778962 2.48327e-05"/>
                    <joint name="left_elbow_pitch_joint" class="/" pos="0 0 0" axis="-0.00427759 0.999984 0.00382873" range="-2.23705 2.45399" armature="0.108967" damping="0.0360043" frictionloss="0.100081"/>
                    <geom name="//unnamed_geom_44" class="visual" mesh="left_lower_arm_pitch_link"/>
                    <body name="left_hand_yaw_link" pos="0.00905872 0.00311239 -0.0487327" quat="1 4.20794e-05 8.87019e-06 8.19447e-05">
                      <inertial pos="-0.0115576 -0.00452736 -0.0452346" quat="0.998193 0.0380894 -0.0372097 0.0278441" mass="1.05731" diaginertia="0.00553409 0.00499754 9.90109e-05"/>
                      <joint name="left_wrist_yaw_joint" class="/" pos="0 0 0" axis="-0.0222562 0.0117911 0.999683" range="-3.003 2.99247" armature="0.103401" damping="0.0144192" frictionloss="0.103451"/>
                      <geom name="//unnamed_geom_45" class="visual" mesh="left_hand_yaw_link"/>
                      <geom name="left_hand_yaw_link.STL" class="collision" size="0.0440134 0.0736809" pos="0.00131809 -0.00186888 -0.0572917" type="cylinder" rgba="0.752941 0.752941 0.752941 1"/>
                      <geom name="//unnamed_geom_47" class="reward_collision_sphere" size="0.0529365"/>
                      <body name="left_hand_roll_link" pos="0.00960838 0.00859267 -0.152194" quat="0.999998 -0.00103288 0.000474655 0.00156572">
                        <inertial pos="-0.00780283 0.00112258 0.0111325" quat="0.468334 0.522187 0.527177 0.479654" mass="0.00601009" diaginertia="8.97248e-07 1.02375e-06 1.71987e-08"/>
                        <joint name="left_wrist_roll_joint" class="/" pos="0 0 0" axis="-0.99992 0.0124731 0.00193005" range="-0.912887 1.12579" armature="0.065486" damping="0.0176089" frictionloss="0.109449"/>
                        <geom name="//unnamed_geom_48" class="visual" mesh="left_hand_roll_link"/>
                        <body name="left_hand_pitch_link" pos="-0.0046206 0.000880875 0.00589645" quat="1 -2.34206e-05 0.000125373 0.000119555">
                          <inertial pos="-0.0091591 -0.011193 -0.0350809" quat="0.717415 -0.0895308 0.11734 0.680831" mass="0.288022" diaginertia="0.000829737 0.000790125 2.52552e-05"/>
                          <joint name="left_wrist_pitch_joint" class="/" pos="0 0 0" axis="0.0243542 0.998529 -0.0484442" stiffness="0.0216037" range="-0.608591 0.435208" armature="0.134721" damping="0.0139655" frictionloss="0.119199"/>
                          <geom name="//unnamed_geom_49" class="visual" mesh="left_hand_pitch"/>
                          <body name="left_jaw_link" pos="0.0115136 -0.0122279 -0.0515802" quat="0.999979 0.00282984 0.000855686 -0.00573234">
                            <inertial pos="-0.0121581 -0.00507051 -0.0156034" quat="0.688896 -0.0321935 0.0226221 0.723791" mass="0.0785022" diaginertia="0.00020639 0.00015758 7.56621e-06"/>
                            <joint name="left_jaw_joint" class="/" pos="0 0 0" axis="-0.999972 0.00680314 -0.00310534" range="-1.07031 -0.137804" armature="0.16966" damping="0.0319041" frictionloss="0.0758372"/>
                            <geom name="//unnamed_geom_50" class="visual" mesh="left_jaw_link"/>
                            <geom name="//unnamed_geom_51" class="collision" size="0.0381143"/>
                            <geom name="//unnamed_geom_52" class="reward_collision_sphere" size="0.0529365" pos="0 0 -0.0150682"/>
                          </body>
                        </body>
                      </body>
                    </body>
                  </body>
                </body>
              </body>
            </body>
            <body name="right_upper_arm_pitch_link" pos="-0.000686066 -0.122539 0.160256" quat="0.977018 -0.213137 0.00144126 0.00237111">
              <inertial pos="0.00485434 -0.0678759 -0.000574442" quat="0.718757 0.695014 -3.45848e-05 0.0185582" mass="1.02335" diaginertia="0.00604037 0.00577364 0.000144701"/>
              <joint name="right_shoulder_pitch_joint" class="/" pos="0 0 0" axis="-0.0130465 -0.999542 -0.0273096" range="-1.88402 2.85029" armature="0.12998" damping="0.0471885" frictionloss="0.15367"/>
              <geom name="//unnamed_geom_53" class="visual" mesh="right_upper_arm_pitch_link"/>
              <body name="right_upper_arm_roll_link" pos="9.76867e-05 -0.114963 -0.00366663" quat="0.976004 0.217747 0.000156683 -0.00139966">
                <inertial pos="0.00220684 -0.0122881 -0.0069856" quat="0.887134 -0.268258 0.110271 0.358986" mass="0.789856" diaginertia="0.00279941 0.00318197 9.35795e-05"/>
                <joint name="right_shoulder_roll_joint" class="/" pos="0 0 0" axis="-0.998728 0.0224433 0.0451562" stiffness="0.00158226" range="-0.492202 2.35443" armature="0.100543" damping="0.019769" frictionloss="0.141516"/>
                <geom name="//unnamed_geom_54" class="visual" mesh="right_upper_arm_roll_link"/>
                <body name="right_upper_arm_yaw_link" pos="-0.000347708 -0.0492449 -0.0424986" quat="0.999998 -0.00173881 -0.00112501 0.000213322">
                  <inertial pos="-0.0102833 0.00010769 -0.0718008" quat="0.999462 -0.0133454 0.0281948 -0.0101557" mass="0.482119" diaginertia="0.00805965 0.0078697 5.27961e-05"/>
                  <joint name="right_shoulder_yaw_joint" class="/" pos="0 0 0" axis="0.000446493 2.18243e-05 1" stiffness="0.0474318" range="-3.10324 2.98747" armature="0.130592" damping="0" frictionloss="0.156742"/>
                  <geom name="//unnamed_geom_55" class="visual" mesh="right_upper_arm_yaw_link"/>
                  <geom name="right_upper_arm_yaw_link.STL" class="collision" size="0.0383612 0.0899306" pos="4.77809e-05 0.00108449 -0.0597757" type="cylinder" rgba="0.752941 0.752941 0.752941 1"/>
                  <body name="right_lower_arm_pitch_link" pos="-0.00560726 -0.0093825 -0.134269" quat="1 0.000452499 -0.000165883 -0.000412415">
                    <inertial pos="0.00141856 -0.00689083 -0.0172279" quat="0.691826 0.13941 -0.13332 0.695821" mass="0.404896" diaginertia="0.000796912 0.000681439 2.09609e-05"/>
                    <joint name="right_elbow_pitch_joint" class="/" pos="0 0 0" axis="0.00450689 -0.999341 -0.0360101" range="-2.13155 2.27657" armature="0.161879" damping="0.00965505" frictionloss="0.164894"/>
                    <geom name="//unnamed_geom_57" class="visual" mesh="right_lower_arm_pitch_link"/>
                    <body name="right_hand_yaw_link" pos="-0.00034827 0.00155725 -0.0510587" quat="1 -0.000174611 -0.000101448 9.17791e-06">
                      <inertial pos="-0.005023 -0.0026094 -0.0525866" quat="0.999068 -0.0135196 -0.040127 -0.00832425" mass="0.973374" diaginertia="0.00566615 0.00550918 0.0001093"/>
                      <joint name="right_wrist_yaw_joint" class="/" pos="0 0 0" axis="-0.00891196 -6.55515e-05 0.99996" range="-2.96685 2.93805" armature="0.166296" damping="0" frictionloss="0.129749"/>
                      <geom name="//unnamed_geom_58" class="visual" mesh="right_hand_yaw_link"/>
                      <geom name="right_hand_yaw_link.STL" class="collision" size="0.0440134 0.0736809" pos="0.00131809 0.00077747 -0.0572917" type="cylinder" rgba="0.752941 0.752941 0.752941 1"/>
                      <geom name="//unnamed_geom_60" class="reward_collision_sphere" size="0.0529365"/>
                      <body name="right_hand_roll_link" pos="0.00172856 0.00610321 -0.156834" quat="1 2.24003e-05 8.70023e-05 -0.000114443">
                        <inertial pos="0.00139918 0.000771915 0.00472697" quat="0.466512 0.483973 0.537012 0.509661" mass="0.00600728" diaginertia="7.67375e-07 9.0455e-07 1.69901e-08"/>
                        <joint name="right_wrist_roll_joint" class="/" pos="0 0 0" axis="-0.999945 -0.00957762 -0.00423401" range="-0.858833 0.935316" armature="0.106291" damping="0.0291506" frictionloss="0.0968649"/>
                        <geom name="//unnamed_geom_61" class="visual" mesh="right_hand_roll_link"/>
                        <body name="right_hand_pitch_link" pos="0.00952235 -0.00946285 -0.00119758" quat="0.99999 0.00197846 0.002453 0.00321174">
                          <inertial pos="0.000370731 0.0134697 -0.0506439" quat="0.727198 0.13775 -0.0655984 0.669257" mass="0.280444" diaginertia="0.000743543 0.00073773 2.32919e-05"/>
                          <joint name="right_wrist_pitch_joint" class="/" pos="0 0 0" axis="0.00135184 -0.999835 -0.0181087" range="-0.612386 0.597262" armature="0.103347" damping="0.00940341" frictionloss="0.15716"/>
                          <geom name="//unnamed_geom_62" class="visual" mesh="right_hand_pitch"/>
                          <body name="right_jaw_link" pos="0.00332673 0.0018117 -0.0505288" quat="1 -0.000665145 -0.000127781 -8.04592e-06">
                            <inertial pos="0.000717177 0.00532095 -0.0259987" quat="0.70244 0.00589369 -0.0542287 0.70965" mass="0.072302" diaginertia="0.000189773 0.000137493 7.24783e-06"/>
                            <joint name="right_jaw_joint" class="/" pos="0 0 0" axis="-0.999988 -0.00366522 -0.00316818" range="0.0693001 1.01425" armature="0.056166" damping="0.0148593" frictionloss="0.135528"/>
                            <geom name="//unnamed_geom_63" class="visual" mesh="right_jaw_link"/>
                            <geom name="//unnamed_geom_64" class="collision" size="0.0381143"/>
                            <geom name="//unnamed_geom_65" class="reward_collision_sphere" size="0.0529365" pos="0 0 -0.0150682"/>
                          </body>
                        </body>
                      </body>
                    </body>
                  </body>
                </body>
              </body>
            </body>
            <body name="head_roll_link" pos="0.00207522 0.00797555 0.225875" quat="0.99998 -0.0024572 0.005102 0.00282174">
              <inertial pos="0.00282097 -0.0018456 -0.000786274" quat="0.0429996 0.678312 -0.02291 0.733157" mass="0.0120103" diaginertia="1.78085e-06 1.13527e-06 1.0426e-07"/>
              <joint name="head_roll_joint" class="/" pos="0 0 0" axis="-0.999996 0.00272754 0.000994059" stiffness="0.0489327" range="-0.375105 0.192625" armature="0.157541" damping="0.0283901" frictionloss="0.103874"/>
              <geom name="//unnamed_geom_66" class="visual" mesh="head_roll_link"/>
              <body name="head_pitch_link" pos="-0.00658163 -0.000590604 -0.00706735" quat="0.999999 6.71921e-05 0.000589107 -0.00108665">
                <inertial pos="0.00271735 -0.00289867 0.012501" quat="0.685437 0.649344 0.261101 -0.200887" mass="0.0808652" diaginertia="6.75132e-05 7.63612e-05 4.59571e-06"/>
                <joint name="head_pitch_joint" class="/" pos="0 0 0" axis="0.0044446 -0.999981 0.00437425" range="-0.926595 0.641131" armature="0.0488548" damping="0.0442045" frictionloss="0.0572491"/>
                <geom name="//unnamed_geom_67" class="visual" mesh="head_pitch_link"/>
                <body name="head_yaw_link" pos="0.0106857 0.00717418 0.0454339" quat="1 9.33015e-05 0.000124596 -0.000107834">
                  <inertial pos="0.0413719 -0.00274917 0.0837353" quat="0.707651 -0.153032 -0.133879 0.676675" mass="1.88602" diaginertia="0.0297403 0.020218 0.00128153"/>
                  <joint name="head_yaw_joint" class="/" pos="0 0 0" axis="0.0171293 0.00460648 0.999843" range="-2.92678 2.51567" armature="0.0964162" damping="0.0673525" frictionloss="0.169767"/>
                  <geom name="//unnamed_geom_68" class="visual" rgba="0.12 0.12 0.12 1" mesh="head_yaw_link"/>
                  <geom name="head_yaw_link.STL" class="collision" size="0.125657" pos="0.0221218 -0.00106719 0.0705346" rgba="0.752941 0.752941 0.752941 1"/>
                  <geom name="//unnamed_geom_70" class="reward_collision_sphere" size="0.105873" pos="0.0363027 0 0.0753412"/>
                  <camera name="ego_camera" class="/" pos="0.13311 0 0.0828754" quat="-0.5 -0.5 0.5 0.5"/>
                </body>
              </body>
            </body>
          </body>
        </body>
      </body>
    </body>
  </worldbody>

  <contact>
    <pair class="/" geom1="floor" geom2="left_foot" name="//unnamed_contact_0"/>
    <pair class="/" geom1="floor" geom2="right_foot" name="//unnamed_contact_1"/>
  </contact>

  <actuator>
    <general name="left_hip_roll" class="/" joint="left_hip_roll_joint" forcerange="-54.7439 54.7439" gainprm="65.5615" biasprm="0 -65.5615 -1.05873"/>
    <general name="left_hip_yaw" class="/" joint="left_hip_yaw_joint" forcerange="-74.2719 74.2719" gainprm="65.5615" biasprm="0 -65.5615 -1.05873"/>
    <general name="left_hip_pitch" class="/" joint="left_hip_pitch_joint" forcerange="-241.34 241.34" gainprm="65.5615" biasprm="0 -65.5615 -1.05873"/>
    <general name="left_knee_pitch" class="/" joint="left_knee_pitch_joint" forcerange="-250.388 250.388" gainprm="65.5615" biasprm="0 -65.5615 -1.05873"/>
    <general name="left_ankle_pitch" class="/" joint="left_ankle_pitch_joint" forcerange="-12.1748 12.1748" gainprm="65.5615" biasprm="0 -65.5615 -1.05873"/>
    <general name="left_ankle_roll" class="/" joint="left_ankle_roll_joint" forcerange="-39.5458 39.5458" gainprm="65.5615" biasprm="0 -65.5615 -1.05873"/>
    <general name="right_hip_roll" class="/" joint="right_hip_roll_joint" forcerange="-52.0922 52.0922" gainprm="65.5615" biasprm="0 -65.5615 -1.05873"/>
    <general name="right_hip_yaw" class="/" joint="right_hip_yaw_joint" forcerange="-65.7173 65.7173" gainprm="65.5615" biasprm="0 -65.5615 -1.05873"/>
    <general name="right_hip_pitch" class="/" joint="right_hip_pitch_joint" forcerange="-330.342 330.342" gainprm="65.5615" biasprm="0 -65.5615 -1.05873"/>
    <general name="right_knee_pitch" class="/" joint="right_knee_pitch_joint" forcerange="-227.388 227.388" gainprm="65.5615" biasprm="0 -65.5615 -1.05873"/>
    <general name="right_ankle_pitch" class="/" joint="right_ankle_pitch_joint" forcerange="-12.7537 12.7537" gainprm="65.5615" biasprm="0 -65.5615 -1.05873"/>
    <general name="right_ankle_roll" class="/" joint="right_ankle_roll_joint" forcerange="-33.2735 33.2735" gainprm="65.5615" biasprm="0 -65.5615 -1.05873"/>
    <general name="waist_yaw" class="/" joint="waist_yaw_joint" forcerange="-70.9532 70.9532" gainprm="65.5615" biasprm="0 -65.5615 -1.05873"/>
    <general name="waist_pitch" class="/" joint="waist_pitch_joint" forcerange="-72.6187 72.6187" gainprm="65.5615" biasprm="0 -65.5615 -1.05873"/>
    <general name="waist_roll" class="/" joint="waist_roll_joint" forcerange="-75.1699 75.1699" gainprm="65.5615" biasprm="0 -65.5615 -1.05873"/>
    <general name="left_shoulder_pitch" class="/" joint="left_shoulder_pitch_joint" forcerange="-41.3091 41.3091" gainprm="65.5615" biasprm="0 -65.5615 -1.05873"/>
    <general name="left_shoulder_roll" class="/" joint="left_shoulder_roll_joint" forcerange="-21.8661 21.8661" gainprm="65.5615" biasprm="0 -65.5615 -1.05873"/>
    <general name="left_shoulder_yaw" class="/" joint="left_shoulder_yaw_joint" forcerange="-43.8828 43.8828" gainprm="65.5615" biasprm="0 -65.5615 -1.05873"/>
    <general name="left_elbow_pitch" class="/" joint="left_elbow_pitch_joint" forcerange="-32.4766 32.4766" gainprm="65.5615" biasprm="0 -65.5615 -1.05873"/>
    <general name="left_wrist_yaw" class="/" joint="left_wrist_yaw_joint" forcerange="-10.9918 10.9918" gainprm="65.5615" biasprm="0 -65.5615 -1.05873"/>
    <general name="left_wrist_roll" class="/" joint="left_wrist_roll_joint" forcerange="-4.35067 4.35067" gainprm="65.5615" biasprm="0 -65.5615 -1.05873"/>
    <general name="left_wrist_pitch" class="/" joint="left_wrist_pitch_joint" forcerange="-3.82833 3.82833" gainprm="65.5615" biasprm="0 -65.5615 -1.05873"/>
    <general name="left_jaw" class="/" joint="left_jaw_joint" forcerange="-5.08479 5.08479" gainprm="65.5615" biasprm="0 -65.5615 -1.05873"/>
    <general name="right_shoulder_pitch" class="/" joint="right_shoulder_pitch_joint" forcerange="-42.0805 42.0805" gainprm="65.5615" biasprm="0 -65.5615 -1.05873"/>
    <general name="right_shoulder_roll" class="/" joint="right_shoulder_roll_joint" forcerange="-26.2241 26.2241" gainprm="65.5615" biasprm="0 -65.5615 -1.05873"/>
    <general name="right_shoulder_yaw" class="/" joint="right_shoulder_yaw_joint" forcerange="-32.2142 32.2142" gainprm="65.5615" biasprm="0 -65.5615 -1.05873"/>
    <general name="right_elbow_pitch" class="/" joint="right_elbow_pitch_joint" forcerange="-32.3857 32.3857" gainprm="65.5615" biasprm="0 -65.5615 -1.05873"/>
    <general name="right_wrist_yaw" class="/" joint="right_wrist_yaw_joint" forcerange="-11.0795 11.0795" gainprm="65.5615" biasprm="0 -65.5615 -1.05873"/>
    <general name="right_wrist_roll" class="/" joint="right_wrist_roll_joint" forcerange="-2.76859 2.76859" gainprm="65.5615" biasprm="0 -65.5615 -1.05873"/>
    <general name="right_wrist_pitch" class="/" joint="right_wrist_pitch_joint" forcerange="-5.54184 5.54184" gainprm="65.5615" biasprm="0 -65.5615 -1.05873"/>
    <general name="right_jaw" class="/" joint="right_jaw_joint" forcerange="-3.06893 3.06893" gainprm="65.5615" biasprm="0 -65.5615 -1.05873"/>
    <general name="head_roll" class="/" joint="head_roll_joint" forcerange="-4.56404 4.56404" gainprm="65.5615" biasprm="0 -65.5615 -1.05873"/>
    <general name="head_pitch" class="/" joint="head_pitch_joint" forcerange="-4.4009 4.4009" gainprm="65.5615" biasprm="0 -65.5615 -1.05873"/>
    <general name="head_yaw" class="/" joint="head_yaw_joint" forcerange="-4.21566 4.21566" gainprm="65.5615" biasprm="0 -65.5615 -1.05873"/>
  </actuator>

  <sensor>
    <gyro site="imu" name="imu_angular_velocity"/>
    <velocimeter site="imu" name="imu_linear_velocity"/>
    <framelinvel objtype="site" objname="left_foot" name="left_foot_global_linear_velocity"/>
    <framelinvel objtype="site" objname="right_foot" name="right_foot_global_linear_velocity"/>
  </sensor>

  <keyframe>
    <key name="home" qpos="0 0 0.8665 1 0 0 0 0 0 -0.4 0.8 -0.4 0 0 0 0.4 -0.8 0.4 0 0 0 0 0 -0.2 0 -0.785 0 0 0 0 0 0.2 0 0.785 0 0 0 0 0 0 0"/>
  </keyframe>
</mujoco>
