<mujoco model="GR1T2_jaw">
  <compiler angle="radian" assetdir="assets" balanceinertia="true" inertiafromgeom="false"/>

  <option timestep="0.005" density="1.2" viscosity="2e-05"/>

  <size nkey="1"/>

  <visual>
    <quality shadowsize="8192"/>
    <map shadowclip="0.5"/>
  </visual>

  <default>
    <default class="/">
      <joint armature="0.1" damping="0.01" frictionloss="0.1"/>
      <geom contype="0" conaffinity="0" group="1" solref="-1000 -80"/>
      <site size="0.01 0.005 0.005" group="5"/>
      <general forcelimited="true" biastype="affine" gainprm="80" biasprm="0 -80 -2"/>
      <default class="visual">
        <geom type="mesh" density="0" rgba="0.18 0.18 0.18 1"/>
      </default>
      <default class="collision">
        <geom group="3"/>
      </default>
      <default class="foot">
        <geom size="0.126 0.045 0.01" type="box" condim="6" group="4" priority="1" solimp="0.015 1 0.01"/>
      </default>
      <default class="reward_collision_sphere">
        <geom group="5" rgba="1 0 0 1"/>
      </default>
    </default>
  </default>

  <asset>
    <texture type="skybox" colorspace="auto" name="//unnamed_texture_0" builtin="gradient" rgb1="0.95 0.95 0.95" rgb2="0.95 0.95 0.95" width="100" height="600"/>
    <texture type="2d" colorspace="auto" name="texplane" builtin="checker" rgb1="0.345 0.575 0.748" rgb2="0.345 0.575 0.748" markrgb="1 1 1" width="512" height="512"/>
    <material name="MatPlane" class="/" texture="texplane" texuniform="true" texrepeat="2 2" specular="0.9"/>
    <mesh name="base_link" class="/" file="base_link.STL"/>
    <mesh name="left_thigh_roll_link" class="/" file="left_thigh_roll_link.STL"/>
    <mesh name="left_thigh_yaw_link" class="/" file="left_thigh_yaw_link.STL"/>
    <mesh name="left_thigh_pitch_link" class="/" file="left_thigh_pitch_link.STL"/>
    <mesh name="left_shank_pitch_link" class="/" file="left_shank_pitch_link.STL"/>
    <mesh name="left_foot_pitch_link" class="/" file="left_foot_pitch_link.STL"/>
    <mesh name="left_foot_roll_link" class="/" file="left_foot_roll_link.STL"/>
    <mesh name="right_thigh_roll_link" class="/" file="right_thigh_roll_link.STL"/>
    <mesh name="right_thigh_yaw_link" class="/" file="right_thigh_yaw_link.STL"/>
    <mesh name="right_thigh_pitch_link" class="/" file="right_thigh_pitch_link.STL"/>
    <mesh name="right_shank_pitch_link" class="/" file="right_shank_pitch_link.STL"/>
    <mesh name="right_foot_pitch_link" class="/" file="right_foot_pitch_link.STL"/>
    <mesh name="right_foot_roll_link" class="/" file="right_foot_roll_link.STL"/>
    <mesh name="waist_yaw_link" class="/" file="waist_yaw_link.STL"/>
    <mesh name="waist_pitch_link" class="/" file="waist_pitch_link.STL"/>
    <mesh name="waist_roll_link" class="/" file="waist_roll_link.STL"/>
    <mesh name="torso_link" class="/" file="torso_link.STL"/>
    <mesh name="left_upper_arm_pitch_link" class="/" file="left_upper_arm_pitch_link.STL"/>
    <mesh name="left_upper_arm_roll_link" class="/" file="left_upper_arm_roll_link.STL"/>
    <mesh name="left_upper_arm_yaw_link" class="/" file="left_upper_arm_yaw_link.STL"/>
    <mesh name="left_lower_arm_pitch_link" class="/" file="left_lower_arm_pitch_link.STL"/>
    <mesh name="left_hand_yaw_link" class="/" file="left_hand_yaw_link.STL"/>
    <mesh name="left_hand_roll_link" class="/" file="left_hand_roll_link.STL"/>
    <mesh name="left_hand_pitch" class="/" file="left_hand_pitch.STL"/>
    <mesh name="left_jaw_link" class="/" file="left_jaw_link.STL"/>
    <mesh name="right_upper_arm_pitch_link" class="/" file="right_upper_arm_pitch_link.STL"/>
    <mesh name="right_upper_arm_roll_link" class="/" file="right_upper_arm_roll_link.STL"/>
    <mesh name="right_upper_arm_yaw_link" class="/" file="right_upper_arm_yaw_link.STL"/>
    <mesh name="right_lower_arm_pitch_link" class="/" file="right_lower_arm_pitch_link.STL"/>
    <mesh name="right_hand_yaw_link" class="/" file="right_hand_yaw_link.STL"/>
    <mesh name="right_hand_roll_link" class="/" file="right_hand_roll_link.STL"/>
    <mesh name="right_hand_pitch" class="/" file="right_hand_pitch.STL"/>
    <mesh name="right_jaw_link" class="/" file="right_jaw_link.STL"/>
    <mesh name="head_roll_link" class="/" file="head_roll_link.STL"/>
    <mesh name="head_pitch_link" class="/" file="head_pitch_link.STL"/>
    <mesh name="head_yaw_link" class="/" file="head_yaw_link.STL"/>
    <mesh name="imu_link" class="/" file="imu_link.STL"/>
  </asset>

  <worldbody>
    <geom name="floor" class="/" size="100 100 0.125" type="plane" group="0" material="MatPlane"/>
    <light name="toplight_shadow" class="/" pos="0 0 5" dir="0.0990148 0.0990148 -0.990148" type="directional" ambient="0.04 0.04 0.04" diffuse="0.55 0.55 0.55" specular="0.12 0.12 0.12"/>
    <light name="toplight_fill" class="/" pos="0 0 5" dir="0.0990148 0.0990148 -0.990148" type="directional" castshadow="false" ambient="0.04 0.04 0.04" diffuse="0.3 0.3 0.3" specular="0.08 0.08 0.08"/>
    <body name="trunk" pos="0.000822386 -0.000483205 0.00223628" quat="1 -4.40131e-05 0.000139021 0.00013741">
      <inertial pos="-0.0486961 0.00333627 -0.00382424" quat="0.999898 -0.00173809 0.00323033 -0.0138085" mass="1.36315" diaginertia="0.0173366 0.00512929 0.000453294"/>
      <joint name="//unnamed_joint_0" type="free"/>
      <geom name="//unnamed_geom_1" class="visual" rgba="0.12 0.12 0.12 1" mesh="base_link"/>
      <geom name="base_link.STL" class="collision" size="0.0842828 0.0472051" pos="-0.0357276 0.000304456 0.00372163" quat="0.706838 -0.707359 0.00477667 0" type="cylinder" rgba="0.752941 0.752941 0.752941 1"/>
      <geom name="//unnamed_geom_3" class="visual" pos="0 0 -0.0240833" quat="1 0 0 0" rgba="0.12 0.12 0.12 1" mesh="imu_link"/>
      <geom name="//unnamed_geom_4" class="reward_collision_sphere" size="0.0550895" pos="0 0.0822761 0.0404081"/>
      <geom name="//unnamed_geom_5" class="reward_collision_sphere" size="0.0550895" pos="0 -0.0822761 0.0404081"/>
      <site name="imu" class="/" pos="-0.000100569 -0.0141564 -0.0172487" size="0.00688619"/>
      <camera name="track" class="/" pos="0 -1.64552 0" quat="0.707107 0.707107 0 0" mode="trackcom"/>
      <body name="left_thigh_roll_link" pos="-0.0298396 0.0873259 -0.00989803" quat="0.999999 -0.000522617 0.000350562 0.00082012">
        <inertial pos="-0.00115751 -0.00342915 0.00388315" quat="-0.0276836 0.701521 -0.0254181 0.711657" mass="0.494753" diaginertia="0.00108112 0.000953988 1.69021e-05"/>
        <joint name="left_hip_roll_joint" class="/" pos="0 0 0" axis="-0.999957 -0.00647341 0.00671366" range="-0.811697 0.0882522" armature="0.0650894" damping="0.0118294" frictionloss="0.0658487"/>
        <geom name="//unnamed_geom_6" class="visual" mesh="left_thigh_roll_link"/>
        <body name="left_thigh_yaw_link" pos="0.0244793 0.000276497 0.000747204" quat="1 -0.000137847 0.000100103 0.000305102">
          <inertial pos="-0.00602824 0.0327252 -0.0423929" quat="0.570994 0.0939427 -0.195411 0.791805" mass="1.12262" diaginertia="0.0103449 0.00731557 9.2048e-05"/>
          <joint name="left_hip_yaw_joint" class="/" pos="0 0 0" axis="0.00289486 0.00323698 -0.999991" range="-0.673053 0.698401" armature="0.0624582" damping="0.00194119" frictionloss="0.0746188"/>
          <geom name="//unnamed_geom_7" class="visual" mesh="left_thigh_yaw_link"/>
          <body name="left_thigh_pitch_link" pos="-0.00216003 0.0208713 -0.0535981" quat="1 5.13577e-05 -0.000839739 0.000288893">
            <inertial pos="0.00102409 -0.0227148 -0.0246277" quat="0.999821 -0.0142368 -0.00976649 0.00768429" mass="2.65713" diaginertia="0.0387952 0.0339703 0.000305221"/>
            <joint name="left_hip_pitch_joint" class="/" pos="0 0 0" axis="0.00845007 0.999911 0.0103353" stiffness="0.00718799" range="-1.80219 0.738778" armature="0.0607888" damping="0.0211715" frictionloss="0.0714399"/>
            <geom name="//unnamed_geom_8" class="visual" mesh="left_thigh_pitch_link"/>
            <geom name="left_thigh_pitch_link.STL" class="collision" size="0.0564667 0.0860181" pos="0.000587353 -0.0246828 -0.0675042" type="cylinder" rgba="0.752941 0.752941 0.752941 1"/>
            <geom name="//unnamed_geom_10" class="reward_collision_sphere" size="0.0688619" pos="0 -0.00822761 -0.0202041"/>
            <body name="left_shank_pitch_link" pos="-0.00446837 -0.0157285 -0.144326" quat="0.999999 -0.000713625 -0.000730808 0.00081406">
              <inertial pos="0.000852282 -0.00118344 -0.0452246" quat="0.999845 -0.00323596 -0.00471883 -0.0166272" mass="0.601338" diaginertia="0.00448748 0.00409833 1.39168e-05"/>
              <joint name="left_knee_pitch_joint" class="/" pos="0 0 0" axis="0.000650724 0.999973 -0.00728843" stiffness="0.00634618" range="-0.101987 1.94266" armature="0.0696971" damping="0.00353352" frictionloss="0.0686393"/>
              <geom name="//unnamed_geom_11" class="visual" mesh="left_shank_pitch_link"/>
              <geom name="left_shank_pitch_link.STL" class="collision" size="0.0367181 0.0622408" pos="-1.39193e-05 -0.000693215 -0.0705894" quat="0.00125538 -0.202712 0.979238 0" type="cylinder" rgba="0.752941 0.752941 0.752941 1"/>
              <geom name="//unnamed_geom_13" class="reward_collision_sphere" size="0.0344309"/>
              <geom name="//unnamed_geom_14" class="reward_collision_sphere" size="0.0413171" pos="0 0 -0.044449"/>
              <body name="left_foot_pitch_link" pos="-0.0019077 -0.00138517 -0.135557" quat="0.999999 0.000532972 -0.000863528 0.000115851">
                <inertial pos="0.000883173 -0.00302483 0.00176663" quat="-0.00473293 0.713978 -0.0090182 0.700094" mass="0.0189406" diaginertia="2.75725e-06 2.20155e-06 5.93932e-08"/>
                <joint name="left_ankle_pitch_joint" class="/" pos="0 0 0" axis="0.0121858 0.999926 0.000144755" range="-1.06927 0.584088" armature="0.0669488" damping="0.0131528" frictionloss="0.0682208"/>
                <geom name="//unnamed_geom_15" class="visual" mesh="left_foot_pitch_link"/>
                <body name="left_foot_roll_link" pos="-0.00100359 0.001421 0.00219079" quat="1 -0.000361324 0.00010073 0.000211962">
                  <inertial pos="0.0309276 -0.00030371 -0.0130995" quat="-0.000866668 0.724778 -0.00132611 0.68898" mass="0.333968" diaginertia="0.0022128 0.00182824 7.91067e-06"/>
                  <joint name="left_ankle_roll_joint" class="/" pos="0 0 0" axis="-0.999977 -0.0067669 0.000279252" range="-0.453004 0.496838" armature="0.0754416" damping="0.0141695" frictionloss="0.0595777"/>
                  <geom name="//unnamed_geom_16" class="visual" mesh="left_foot_roll_link"/>
                  <geom name="left_foot" class="foot" size="0.121433 0.0304771 0.00714332" pos="0.0377556 0 -0.0179816"/>
                  <geom name="//unnamed_geom_18" class="reward_collision_sphere" size="0.0344309" pos="0 0 -0.0121224"/>
                  <geom name="//unnamed_geom_19" class="reward_collision_sphere" size="0.0344309" pos="0.100682 0 -0.0121224"/>
                  <site name="left_foot" class="foot" pos="0.0377556 0 -0.0179816" size="0.00688619"/>
                </body>
              </body>
            </body>
          </body>
        </body>
      </body>
      <body name="right_thigh_roll_link" pos="-0.024895 -0.0890932 -0.0144509" quat="1 0.000357796 7.94162e-05 0.000103724">
        <inertial pos="-0.00139589 0.00189331 -0.00104709" quat="0.0305738 0.708409 0.0157145 0.704965" mass="0.485683" diaginertia="0.00107302 0.000985587 1.65977e-05"/>
        <joint name="right_hip_roll_joint" class="/" pos="0 0 0" axis="-0.99992 -0.00951772 0.00834496" stiffness="0.00427864" range="-0.0452563 0.789322" armature="0.0628329" damping="0.000949448" frictionloss="0.0714713"/>
        <geom name="//unnamed_geom_20" class="visual" mesh="right_thigh_roll_link"/>
        <body name="right_thigh_yaw_link" pos="0.0258955 -0.00241048 0.000417195" quat="1 -0.000305353 0.000122398 0.000740266">
          <inertial pos="-0.00597761 -0.0288669 -0.0437965" quat="0.689375 -0.145168 0.147492 0.694215" mass="1.15377" diaginertia="0.0104263 0.00737225 0.000101526"/>
          <joint name="right_hip_yaw_joint" class="/" pos="0 0 0" axis="0.00992131 0.0144797 -0.999846" range="-0.657114 0.708941" armature="0.0771866" damping="0.00425113" frictionloss="0.0738417"/>
          <geom name="//unnamed_geom_21" class="visual" mesh="right_thigh_yaw_link"/>
          <body name="right_thigh_pitch_link" pos="-0.00179936 -0.0228771 -0.0581555" quat="1 2.1506e-05 0.000279185 -7.54505e-05">
            <inertial pos="0.00200407 0.0244612 -0.0231951" quat="0.999741 -0.018536 -0.00164506 0.0130685" mass="2.79204" diaginertia="0.0375414 0.0328054 0.00031271"/>
            <joint name="right_hip_pitch_joint" class="/" pos="0 0 0" axis="0.00498439 -0.999948 0.00893597" range="-0.737484 1.79034" armature="0.0739072" damping="0.00820258" frictionloss="0.0620633"/>
            <geom name="//unnamed_geom_22" class="visual" mesh="right_thigh_pitch_link"/>
            <geom name="right_thigh_pitch_link.STL" class="collision" size="0.0564667 0.0860161" pos="-0.00178145 0.0246828 -0.0675042" quat="0.999971 0.00269833 0.00706272 0" type="cylinder" rgba="0.752941 0.752941 0.752941 1"/>
            <geom name="//unnamed_geom_24" class="reward_collision_sphere" size="0.0688619" pos="0 0.00822761 -0.0202041"/>
            <body name="right_shank_pitch_link" pos="0.00201282 0.0146531 -0.143671" quat="1 9.75901e-05 8.5996e-05 -6.15841e-05">
              <inertial pos="0.000191305 -0.00162307 -0.0492675" quat="0.999677 0.00746686 0.00442639 0.0239" mass="0.573012" diaginertia="0.00436168 0.00397045 1.308e-05"/>
              <joint name="right_knee_pitch_joint" class="/" pos="0 0 0" axis="0.0137946 -0.999834 -0.0119339" range="-1.95247 0.0852962" armature="0.0675626" damping="0.00994047" frictionloss="0.0602627"/>
              <geom name="//unnamed_geom_25" class="visual" mesh="right_shank_pitch_link"/>
              <geom name="right_shank_pitch_link.STL" class="collision" size="0.0367179 0.0622402" pos="-1.39193e-05 -0.000693223 -0.0705926" type="cylinder" rgba="0.752941 0.752941 0.752941 1"/>
              <geom name="//unnamed_geom_27" class="reward_collision_sphere" size="0.0344309"/>
              <geom name="//unnamed_geom_28" class="reward_collision_sphere" size="0.0413171" pos="0 0 -0.044449"/>
              <body name="right_foot_pitch_link" pos="0.00238365 -0.00127941 -0.133665" quat="0.999999 -0.0011281 -0.000357039 0.000572821">
                <inertial pos="0.00188904 -0.00107952 -0.00265428" quat="-0.0034487 0.713833 0.000549388 0.700307" mass="0.0174434" diaginertia="2.55952e-06 2.09443e-06 5.3302e-08"/>
                <joint name="right_ankle_pitch_joint" class="/" pos="0 0 0" axis="-0.00703119 -0.999877 0.0140264" range="-0.577317 1.05528" armature="0.0701042" damping="0" frictionloss="0.070182"/>
                <geom name="//unnamed_geom_29" class="visual" mesh="right_foot_pitch_link"/>
                <body name="right_foot_roll_link" pos="0.00206416 -0.0030695 0.00367663" quat="1 -9.10129e-06 7.13448e-05 -5.75091e-05">
                  <inertial pos="0.0337667 -0.00370826 -0.0157042" quat="-0.00261101 0.720859 0.00502892 0.693058" mass="0.348203" diaginertia="0.00224742 0.00184642 8.06199e-06"/>
                  <joint name="right_ankle_roll_joint" class="/" pos="0 0 0" axis="-0.999941 0.00027392 0.010905" range="-0.490549 0.390063" armature="0.0641675" damping="0" frictionloss="0.0785077"/>
                  <geom name="//unnamed_geom_30" class="visual" mesh="right_foot_roll_link"/>
                  <geom name="right_foot" class="foot" size="0.0957787 0.0335841 0.00736599" pos="0.0377556 0 -0.0179816"/>
                  <geom name="//unnamed_geom_32" class="reward_collision_sphere" size="0.0344309" pos="0 0 -0.0121224"/>
                  <geom name="//unnamed_geom_33" class="reward_collision_sphere" size="0.0344309" pos="0.100682 0 -0.0121224"/>
                  <site name="right_foot" class="foot" pos="0.0377556 0 -0.0179816" size="0.00688619"/>
                </body>
              </body>
            </body>
          </body>
        </body>
      </body>
      <body name="waist_yaw_link" pos="0.00587181 -0.000677119 0.00421981" quat="0.999999 -0.000183737 -0.000962455 -0.000287206">
        <inertial pos="-0.00407923 -0.00776056 0.0212892" quat="0.979904 0.186496 -0.0277086 0.06511" mass="0.521482" diaginertia="0.00150695 0.00127623 2.27906e-05"/>
        <joint name="waist_yaw_joint" class="/" pos="0 0 0" axis="-0.00323961 -0.00345528 0.999989" range="-1.11085 1.09273" armature="0.0718434" damping="0.00510284" frictionloss="0.0720284"/>
        <geom name="//unnamed_geom_34" class="visual" rgba="0.12 0.12 0.12 1" mesh="waist_yaw_link"/>
        <body name="waist_pitch_link" pos="0.00564874 0.00298862 0.0394031" quat="0.999998 0.000180928 -0.00132658 0.00139741">
          <inertial pos="0.000933894 0.000731464 0.0197917" quat="0.998345 -0.0436393 0.03723 0.00407719" mass="0.496993" diaginertia="0.00186659 0.00167224 1.9654e-05"/>
          <joint name="waist_pitch_joint" class="/" pos="0 0 0" axis="-0.0199662 -0.999099 0.0374373" range="-1.26287 0.536393" armature="0.06834" damping="0.0028072" frictionloss="0.0730549"/>
          <geom name="//unnamed_geom_35" class="visual" rgba="0.12 0.12 0.12 1" mesh="waist_pitch_link"/>
          <body name="waist_roll_link" pos="0.00624768 0.000237508 0.0393273" quat="1 0.000344754 0.000488003 0.000221663">
            <inertial pos="-0.0131258 -0.000462649 0.0606353" quat="0.998737 -0.00459499 -0.0499098 0.00346718" mass="2.12321" diaginertia="0.02605 0.0228198 0.000369577"/>
            <joint name="waist_roll_joint" class="/" pos="0 0 0" axis="-0.999947 0.00947463 -0.00392989" range="-0.757423 0.737268" armature="0.0752483" damping="0.00861042" frictionloss="0.0697249"/>
            <geom name="//unnamed_geom_36" class="visual" rgba="0.12 0.12 0.12 1" mesh="waist_roll_link"/>
            <geom name="//unnamed_geom_37" class="visual" pos="-0.00188778 0.000472619 0.0647945" quat="1 0 0 0" mesh="torso_link"/>
            <geom name="torso_link.STL" class="collision" size="0.108407 0.0207915" pos="-0.0151575 0.00474717 0.059735" type="cylinder" rgba="0.752941 0.752941 0.752941 1"/>
            <geom name="//unnamed_geom_39" class="reward_collision_sphere" size="0.0895204" pos="0 0 0.0808163"/>
            <body name="left_upper_arm_pitch_link" pos="0.00281141 0.0850054 0.0824181" quat="0.976817 0.214074 0.000984733 0.000675889">
              <inertial pos="0.000843001 0.0419762 -0.00294235" quat="0.706684 0.70609 0.0105543 -0.0438588" mass="0.275516" diaginertia="0.000866067 0.000747325 5.47995e-06"/>
              <joint name="left_shoulder_pitch_joint" class="/" pos="0 0 0" axis="0.00895853 0.999893 -0.0115843" range="-2.79752 1.98864" armature="0.069969" damping="0.0150336" frictionloss="0.0698591"/>
              <geom name="//unnamed_geom_40" class="visual" mesh="left_upper_arm_pitch_link"/>
              <body name="left_upper_arm_roll_link" pos="-0.000312205 0.0748706 0.00251619" quat="0.976715 -0.21454 -0.00012426 0.000150168">
                <inertial pos="0.00411542 0.0119336 -0.0107847" quat="0.887611 0.27398 0.124069 -0.34884" mass="0.193543" diaginertia="0.000428155 0.000374302 3.79803e-06"/>
                <joint name="left_shoulder_roll_joint" class="/" pos="0 0 0" axis="-0.999979 0.00108627 0.00645051" range="-2.51374 0.571136" armature="0.0665131" damping="0.0153863" frictionloss="0.068243"/>
                <geom name="//unnamed_geom_41" class="visual" mesh="left_upper_arm_roll_link"/>
                <body name="left_upper_arm_yaw_link" pos="0.00343194 0.0308435 -0.0281511" quat="1 0.00045611 0.000111816 0.000321097">
                  <inertial pos="0.00225756 -0.00083338 -0.034044" quat="0.999952 -0.00525604 -0.000394301 -0.00826368" mass="0.177825" diaginertia="0.00149892 0.00135158 2.86743e-06"/>
                  <joint name="left_shoulder_yaw_joint" class="/" pos="0 0 0" axis="0.0122953 0.0108067 0.999866" range="-2.97958 3.01936" armature="0.0747362" damping="0.0118104" frictionloss="0.0614628"/>
                  <geom name="//unnamed_geom_42" class="visual" mesh="left_upper_arm_yaw_link"/>
                  <geom name="left_upper_arm_yaw_link.STL" class="collision" size="0.0249509 0.0584927" pos="3.31288e-05 -0.000735787 -0.0320598" quat="0.00803418 -0.995528 0.0941277 0" type="cylinder" rgba="0.752941 0.752941 0.752941 1"/>
                  <body name="left_lower_arm_pitch_link" pos="0.000766197 3.57804e-05 -0.0723247" quat="1 -0.000394279 0.000357771 0.000262933">
                    <inertial pos="0.0021999 0.00588886 -0.00930121" quat="0.699024 -0.0922242 0.0891658 0.703498" mass="0.105905" diaginertia="0.000123456 0.000111297 1.04918e-06"/>
                    <joint name="left_elbow_pitch_joint" class="/" pos="0 0 0" axis="0.000931493 0.999998 0.00179479" range="-2.27378 2.22456" armature="0.068464" damping="0" frictionloss="0.0685845"/>
                    <geom name="//unnamed_geom_44" class="visual" mesh="left_lower_arm_pitch_link"/>
                    <body name="left_hand_yaw_link" pos="-0.00238905 -0.000797694 -0.0235995" quat="1 0.000306338 -0.000257522 -0.000121518">
                      <inertial pos="0.00194183 0.0035936 -0.0323261" quat="0.999999 -0.00144661 0.00024672 -0.000472265" mass="0.328674" diaginertia="0.00115369 0.00101572 5.65759e-06"/>
                      <joint name="left_wrist_yaw_joint" class="/" pos="0 0 0" axis="0.00493684 0.0102003 0.999936" range="-2.9682 2.97214" armature="0.0749969" damping="0.00141642" frictionloss="0.0724849"/>
                      <geom name="//unnamed_geom_45" class="visual" mesh="left_hand_yaw_link"/>
                      <geom name="left_hand_yaw_link.STL" class="collision" size="0.0286272 0.0479235" pos="0.000913896 -0.00126797 -0.0307275" type="cylinder" rgba="0.752941 0.752941 0.752941 1"/>
                      <geom name="//unnamed_geom_47" class="reward_collision_sphere" size="0.0344309"/>
                      <body name="left_hand_roll_link" pos="-0.00248862 -0.00159396 -0.0751296" quat="1 -0.000656531 0.000411878 0.000124861">
                        <inertial pos="0.00254298 -0.0012 -0.00217061" quat="0.505861 0.494611 0.506147 0.493234" mass="0.00166434" diaginertia="1.46824e-07 1.28513e-07 7.50817e-10"/>
                        <joint name="left_wrist_roll_joint" class="/" pos="0 0 0" axis="-0.999966 -0.00784766 0.00262024" range="-0.960336 0.842779" armature="0.0802266" damping="0.0033124" frictionloss="0.0678399"/>
                        <geom name="//unnamed_geom_48" class="visual" mesh="left_hand_roll_link"/>
                        <body name="left_hand_pitch_link" pos="0.00239207 0.000770011 -0.00310558" quat="1 -2.21664e-06 -3.8024e-05 -7.24795e-05">
                          <inertial pos="0.00235665 -0.00922546 -0.0241103" quat="0.71538 -0.129914 0.117918 0.67635" mass="0.0694153" diaginertia="0.000114069 9.83402e-05 9.84425e-07"/>
                          <joint name="left_wrist_pitch_joint" class="/" pos="0 0 0" axis="-0.00651355 0.999917 0.0111175" range="-0.617082 0.66497" armature="0.0623279" damping="0.00123893" frictionloss="0.0664117"/>
                          <geom name="//unnamed_geom_49" class="visual" mesh="left_hand_pitch"/>
                          <body name="left_jaw_link" pos="-0.00220754 0.00254113 -0.0220705" quat="1 -0.000583325 6.66767e-05 0.000310366">
                            <inertial pos="0.0020789 0.00569863 -0.0166866" quat="0.702116 -0.0150211 0.0369715 0.710943" mass="0.0232704" diaginertia="3.28389e-05 2.09119e-05 3.53552e-07"/>
                            <joint name="left_jaw_joint" class="/" pos="0 0 0" axis="-1 0.000770648 -0.000239318" range="-0.941641 0.0435416" armature="0.0637453" damping="0.00716802" frictionloss="0.0773992"/>
                            <geom name="//unnamed_geom_50" class="visual" mesh="left_jaw_link"/>
                            <geom name="//unnamed_geom_51" class="collision" size="0.0247903"/>
                            <geom name="//unnamed_geom_52" class="reward_collision_sphere" size="0.0344309" pos="0 0 -0.00808163"/>
                          </body>
                        </body>
                      </body>
                    </body>
                  </body>
                </body>
              </body>
            </body>
            <body name="right_upper_arm_pitch_link" pos="0.000797558 -0.0834686 0.0817161" quat="0.976402 -0.21596 0.000222356 0.000813073">
              <inertial pos="0.00221976 -0.0436723 -0.000494528" quat="0.699811 0.713075 0.0262353 0.0331736" mass="0.264729" diaginertia="0.000824524 0.000710717 5.01257e-06"/>
              <joint name="right_shoulder_pitch_joint" class="/" pos="0 0 0" axis="-0.0126251 -0.999898 0.00672225" range="-1.91303 2.78572" armature="0.0629936" damping="0" frictionloss="0.0594214"/>
              <geom name="//unnamed_geom_53" class="visual" mesh="right_upper_arm_pitch_link"/>
              <body name="right_upper_arm_roll_link" pos="0.00368032 -0.0792382 0.00188282" quat="0.97664 0.214879 -0.00106044 -0.00106469">
                <inertial pos="0.00521564 -0.0174821 -0.0122279" quat="0.886932 -0.266978 0.130811 0.353502" mass="0.194623" diaginertia="0.000422786 0.000351885 3.64821e-06"/>
                <joint name="right_shoulder_roll_joint" class="/" pos="0 0 0" axis="-0.999936 0.0102161 -0.00483742" range="-0.604292 2.59422" armature="0.0742597" damping="0" frictionloss="0.059419"/>
                <geom name="//unnamed_geom_54" class="visual" mesh="right_upper_arm_roll_link"/>
                <body name="right_upper_arm_yaw_link" pos="0.00256025 -0.034195 -0.0305121" quat="1 0.000179507 0.000836938 0.000429844">
                  <inertial pos="0.00197356 -0.000792156 -0.0333811" quat="0.999971 0.00509769 0.00526707 0.00181173" mass="0.186074" diaginertia="0.00150443 0.00136296 2.83144e-06"/>
                  <joint name="right_shoulder_yaw_joint" class="/" pos="0 0 0" axis="-0.000403937 0.00066213 1" range="-2.91348 2.96337" armature="0.0631405" damping="0.0170965" frictionloss="0.0598545"/>
                  <geom name="//unnamed_geom_55" class="visual" mesh="right_upper_arm_yaw_link"/>
                  <geom name="right_upper_arm_yaw_link.STL" class="collision" size="0.0249509 0.0584927" pos="3.31288e-05 0.000735787 -0.0320598" type="cylinder" rgba="0.752941 0.752941 0.752941 1"/>
                  <body name="right_lower_arm_pitch_link" pos="0.00352801 0.00195917 -0.0723801" quat="1 -1.09132e-06 -2.42316e-05 2.56326e-05">
                    <inertial pos="-0.000752831 -0.00763647 -0.0104484" quat="0.699059 0.0922475 -0.0979268 0.702295" mass="0.108305" diaginertia="0.000124958 0.000114433 1.08979e-06"/>
                    <joint name="right_elbow_pitch_joint" class="/" pos="0 0 0" axis="0.00471911 -0.999888 0.0141859" range="-2.32212 2.27304" armature="0.0621456" damping="0.00778785" frictionloss="0.061498"/>
                    <geom name="//unnamed_geom_57" class="visual" mesh="right_lower_arm_pitch_link"/>
                    <body name="right_hand_yaw_link" pos="0.00181373 -0.00103634 -0.0219056" quat="1 9.40146e-05 6.85937e-05 3.76547e-05">
                      <inertial pos="0.00215774 -0.00339197 -0.028224" quat="0.999411 0.00587784 0.00541425 0.0333631" mass="0.332346" diaginertia="0.00109435 0.000967181 5.26142e-06"/>
                      <joint name="right_wrist_yaw_joint" class="/" pos="0 0 0" axis="-0.000632113 -7.80803e-05 1" range="-2.97003 2.98134" armature="0.0629192" damping="0.0144153" frictionloss="0.0619339"/>
                      <geom name="//unnamed_geom_58" class="visual" mesh="right_hand_yaw_link"/>
                      <geom name="right_hand_yaw_link.STL" class="collision" size="0.0286272 0.0479235" pos="0.000913896 0.000527484 -0.0307275" type="cylinder" rgba="0.752941 0.752941 0.752941 1"/>
                      <geom name="//unnamed_geom_60" class="reward_collision_sphere" size="0.0344309"/>
                      <body name="right_hand_roll_link" pos="0.0021776 -0.00286276 -0.0755749" quat="1 -5.89784e-05 -2.61182e-05 -9.86239e-06">
                        <inertial pos="-0.00182233 0.00045197 -0.00199195" quat="0.498651 0.491258 0.506559 0.503399" mass="0.00161958" diaginertia="1.48665e-07 1.32136e-07 7.5617e-10"/>
                        <joint name="right_wrist_roll_joint" class="/" pos="0 0 0" axis="-1 -6.38745e-05 -0.000260814" range="-0.866706 0.962954" armature="0.0686366" damping="0.0135976" frictionloss="0.0690487"/>
                        <geom name="//unnamed_geom_61" class="visual" mesh="right_hand_roll_link"/>
                        <body name="right_hand_pitch_link" pos="-0.00212695 0.00253365 -0.000472783" quat="0.999999 -0.00108207 0.000713442 0.000217151">
                          <inertial pos="-0.00103044 0.00786459 -0.0191294" quat="0.715891 0.11758 -0.116235 0.678354" mass="0.0695855" diaginertia="0.000119876 0.000100802 1.01337e-06"/>
                          <joint name="right_wrist_pitch_joint" class="/" pos="0 0 0" axis="0.000895212 -0.999993 0.00373031" stiffness="0.000140963" range="-0.638693 0.610842" armature="0.0742639" damping="0.00244098" frictionloss="0.0599477"/>
                          <geom name="//unnamed_geom_62" class="visual" mesh="right_hand_pitch"/>
                          <body name="right_jaw_link" pos="0.00149593 -0.000436467 -0.0235678" quat="1 1.85129e-05 -0.000198084 5.85368e-05">
                            <inertial pos="-0.00233609 -0.00649582 -0.0138038" quat="0.703495 0.0198724 -0.0195597 0.710153" mass="0.0241212" diaginertia="3.37976e-05 2.16846e-05 3.61141e-07"/>
                            <joint name="right_jaw_joint" class="/" pos="0 0 0" axis="-1 5.86475e-05 0.00026147" range="-0.0233457 0.99115" armature="0.0793835" damping="0.00729185" frictionloss="0.0603404"/>
                            <geom name="//unnamed_geom_63" class="visual" mesh="right_jaw_link"/>
                            <geom name="//unnamed_geom_64" class="collision" size="0.0247903"/>
                            <geom name="//unnamed_geom_65" class="reward_collision_sphere" size="0.0344309" pos="0 0 -0.00808163"/>
                          </body>
                        </body>
                      </body>
                    </body>
                  </body>
                </body>
              </body>
            </body>
            <body name="head_roll_link" pos="-0.00168882 -0.00249304 0.128382" quat="1 0.000165207 0.000335353 0.000433501">
              <inertial pos="0.00239977 -0.000701624 -0.000666345" quat="-0.000394036 0.710603 0.00594186 0.703568" mass="0.0032203" diaginertia="3.01065e-07 1.64607e-07 4.63476e-09"/>
              <joint name="head_roll_joint" class="/" pos="0 0 0" axis="-0.999995 -0.00228203 0.00220246" range="-0.353374 0.422491" armature="0.0614072" damping="0.000740535" frictionloss="0.0695118"/>
              <geom name="//unnamed_geom_66" class="visual" mesh="head_roll_link"/>
              <body name="head_pitch_link" pos="0.00134507 -0.0012119 0.00547359" quat="1 0.000315447 -2.30759e-05 -0.000128189">
                <inertial pos="-0.00194069 0.000225351 0.00714165" quat="0.671282 0.655937 0.242168 -0.24593" mass="0.0184613" diaginertia="1.08784e-05 8.45154e-06 1.75842e-07"/>
                <joint name="head_pitch_joint" class="/" pos="0 0 0" axis="-0.00116308 -0.999997 0.00213073" stiffness="0.00124907" range="-0.826241 0.911987" armature="0.0772073" damping="0" frictionloss="0.0781029"/>
                <geom name="//unnamed_geom_67" class="visual" mesh="head_pitch_link"/>
                <body name="head_yaw_link" pos="-0.00214709 -0.00289228 0.0207829" quat="1 4.03564e-06 -1.19948e-06 -3.77229e-07">
                  <inertial pos="0.0194423 -0.00279283 0.0371186" quat="0.707459 -0.141907 -0.146922 0.676593" mass="0.507849" diaginertia="0.00407364 0.00296775 5.62238e-05"/>
                  <joint name="head_yaw_joint" class="/" pos="0 0 0" axis="0.00274173 -0.0035235 0.99999" range="-2.66437 2.76816" armature="0.0702256" damping="0" frictionloss="0.0628548"/>
                  <geom name="//unnamed_geom_68" class="visual" rgba="0.12 0.12 0.12 1" mesh="head_yaw_link"/>
                  <geom name="head_yaw_link.STL" class="collision" size="0.0817301" pos="0.0153381 -0.000724049 0.0378302" rgba="0.752941 0.752941 0.752941 1"/>
                  <geom name="//unnamed_geom_70" class="reward_collision_sphere" size="0.0688619" pos="0.0251704 0 0.0404081"/>
                  <camera name="ego_camera" class="/" pos="0.0922915 0 0.044449" quat="-0.5 -0.5 0.5 0.5"/>
                </body>
              </body>
            </body>
          </body>
        </body>
      </body>
    </body>
  </worldbody>

  <contact>
    <pair class="/" geom1="floor" geom2="left_foot" name="//unnamed_contact_0"/>
    <pair class="/" geom1="floor" geom2="right_foot" name="//unnamed_contact_1"/>
  </contact>

  <actuator>
    <general name="left_hip_roll" class="/" joint="left_hip_roll_joint" forcerange="-33.9726 33.9726" gainprm="66.3836" biasprm="0 -66.3836 -0.688619"/>
    <general name="left_hip_yaw" class="/" joint="left_hip_yaw_joint" forcerange="-44.6505 44.6505" gainprm="66.3836" biasprm="0 -66.3836 -0.688619"/>
    <general name="left_hip_pitch" class="/" joint="left_hip_pitch_joint" forcerange="-163.734 163.734" gainprm="66.3836" biasprm="0 -66.3836 -0.688619"/>
    <general name="left_knee_pitch" class="/" joint="left_knee_pitch_joint" forcerange="-156.924 156.924" gainprm="66.3836" biasprm="0 -66.3836 -0.688619"/>
    <general name="left_ankle_pitch" class="/" joint="left_ankle_pitch_joint" forcerange="-11.3438 11.3438" gainprm="66.3836" biasprm="0 -66.3836 -0.688619"/>
    <general name="left_ankle_roll" class="/" joint="left_ankle_roll_joint" forcerange="-18.5182 18.5182" gainprm="66.3836" biasprm="0 -66.3836 -0.688619"/>
    <general name="right_hip_roll" class="/" joint="right_hip_roll_joint" forcerange="-31.3888 31.3888" gainprm="66.3836" biasprm="0 -66.3836 -0.688619"/>
    <general name="right_hip_yaw" class="/" joint="right_hip_yaw_joint" forcerange="-45.3977 45.3977" gainprm="66.3836" biasprm="0 -66.3836 -0.688619"/>
    <general name="right_hip_pitch" class="/" joint="right_hip_pitch_joint" forcerange="-145.163 145.163" gainprm="66.3836" biasprm="0 -66.3836 -0.688619"/>
    <general name="right_knee_pitch" class="/" joint="right_knee_pitch_joint" forcerange="-154.338 154.338" gainprm="66.3836" biasprm="0 -66.3836 -0.688619"/>
    <general name="right_ankle_pitch" class="/" joint="right_ankle_pitch_joint" forcerange="-11.2327 11.2327" gainprm="66.3836" biasprm="0 -66.3836 -0.688619"/>
    <general name="right_ankle_roll" class="/" joint="right_ankle_roll_joint" forcerange="-20.1969 20.1969" gainprm="66.3836" biasprm="0 -66.3836 -0.688619"/>
    <general name="waist_yaw" class="/" joint="waist_yaw_joint" forcerange="-46.3851 46.3851" gainprm="66.3836" biasprm="0 -66.3836 -0.688619"/>
    <general name="waist_pitch" class="/" joint="waist_pitch_joint" forcerange="-51.0669 51.0669" gainprm="66.3836" biasprm="0 -66.3836 -0.688619"/>
    <general name="waist_roll" class="/" joint="waist_roll_joint" forcerange="-43.8736 43.8736" gainprm="66.3836" biasprm="0 -66.3836 -0.688619"/>
    <general name="left_shoulder_pitch" class="/" joint="left_shoulder_pitch_joint" forcerange="-26.046 26.046" gainprm="66.3836" biasprm="0 -66.3836 -0.688619"/>
    <general name="left_shoulder_roll" class="/" joint="left_shoulder_roll_joint" forcerange="-27.8107 27.8107" gainprm="66.3836" biasprm="0 -66.3836 -0.688619"/>
    <general name="left_shoulder_yaw" class="/" joint="left_shoulder_yaw_joint" forcerange="-18.7868 18.7868" gainprm="66.3836" biasprm="0 -66.3836 -0.688619"/>
    <general name="left_elbow_pitch" class="/" joint="left_elbow_pitch_joint" forcerange="-20.6844 20.6844" gainprm="66.3836" biasprm="0 -66.3836 -0.688619"/>
    <general name="left_wrist_yaw" class="/" joint="left_wrist_yaw_joint" forcerange="-6.92108 6.92108" gainprm="66.3836" biasprm="0 -66.3836 -0.688619"/>
    <general name="left_wrist_roll" class="/" joint="left_wrist_roll_joint" forcerange="-2.71332 2.71332" gainprm="66.3836" biasprm="0 -66.3836 -0.688619"/>
    <general name="left_wrist_pitch" class="/" joint="left_wrist_pitch_joint" forcerange="-2.76976 2.76976" gainprm="66.3836" biasprm="0 -66.3836 -0.688619"/>
    <general name="left_jaw" class="/" joint="left_jaw_joint" forcerange="-2.46277 2.46277" gainprm="66.3836" biasprm="0 -66.3836 -0.688619"/>
    <general name="right_shoulder_pitch" class="/" joint="right_shoulder_pitch_joint" forcerange="-26.2432 26.2432" gainprm="66.3836" biasprm="0 -66.3836 -0.688619"/>
    <general name="right_shoulder_roll" class="/" joint="right_shoulder_roll_joint" forcerange="-28.8006 28.8006" gainprm="66.3836" biasprm="0 -66.3836 -0.688619"/>
    <general name="right_shoulder_yaw" class="/" joint="right_shoulder_yaw_joint" forcerange="-19.7298 19.7298" gainprm="66.3836" biasprm="0 -66.3836 -0.688619"/>
    <general name="right_elbow_pitch" class="/" joint="right_elbow_pitch_joint" forcerange="-20.7554 20.7554" gainprm="66.3836" biasprm="0 -66.3836 -0.688619"/>
    <general name="right_wrist_yaw" class="/" joint="right_wrist_yaw_joint" forcerange="-6.73905 6.73905" gainprm="66.3836" biasprm="0 -66.3836 -0.688619"/>
    <general name="right_wrist_roll" class="/" joint="right_wrist_roll_joint" forcerange="-2.99834 2.99834" gainprm="66.3836" biasprm="0 -66.3836 -0.688619"/>
    <general name="right_wrist_pitch" class="/" joint="right_wrist_pitch_joint" forcerange="-2.4357 2.4357" gainprm="66.3836" biasprm="0 -66.3836 -0.688619"/>
    <general name="right_jaw" class="/" joint="right_jaw_joint" forcerange="-3.00562 3.00562" gainprm="66.3836" biasprm="0 -66.3836 -0.688619"/>
    <general name="head_roll" class="/" joint="head_roll_joint" forcerange="-2.66242 2.66242" gainprm="66.3836" biasprm="0 -66.3836 -0.688619"/>
    <general name="head_pitch" class="/" joint="head_pitch_joint" forcerange="-2.75721 2.75721" gainprm="66.3836" biasprm="0 -66.3836 -0.688619"/>
    <general name="head_yaw" class="/" joint="head_yaw_joint" forcerange="-2.71984 2.71984" gainprm="66.3836" biasprm="0 -66.3836 -0.688619"/>
  </actuator>

  <sensor>
    <gyro site="imu" name="imu_angular_velocity"/>
    <velocimeter site="imu" name="imu_linear_velocity"/>
    <framelinvel objtype="site" objname="left_foot" name="left_foot_global_linear_velocity"/>
    <framelinvel objtype="site" objname="right_foot" name="right_foot_global_linear_velocity"/>
  </sensor>

  <keyframe>
    <key name="home" qpos="0 0 0.8665 1 0 0 0 0 0 -0.4 0.8 -0.4 0 0 0 0.4 -0.8 0.4 0 0 0 0 0 -0.2 0 -0.785 0 0 0 0 0 0.2 0 0.785 0 0 0 0 0 0 0"/>
  </keyframe>
</mujoco>
