<mujoco model="GR1T2_jaw">
  <compiler angle="radian" assetdir="assets" balanceinertia="true" inertiafromgeom="false"/>

  <option timestep="0.005" density="1.2" viscosity="2e-05"/>

  <size nkey="1"/>

  <visual>
    <quality shadowsize="8192"/>
    <map shadowclip="0.5"/>
  </visual>

  <default>
    <default class="/">
      <joint armature="0.1" damping="0.01" frictionloss="0.1"/>
      <geom contype="0" conaffinity="0" group="1" solref="-1000 -80"/>
      <site size="0.01 0.005 0.005" group="5"/>
      <general forcelimited="true" biastype="affine" gainprm="80" biasprm="0 -80 -2"/>
      <default class="visual">
        <geom type="mesh" density="0" rgba="0.18 0.18 0.18 1"/>
      </default>
      <default class="collision">
        <geom group="3"/>
      </default>
      <default class="foot">
        <geom size="0.126 0.045 0.01" type="box" condim="6" group="4" priority="1" solimp="0.015 1 0.01"/>
      </default>
      <default class="reward_collision_sphere">
        <geom group="5" rgba="1 0 0 1"/>
      </default>
    </default>
  </default>

  <asset>
    <texture type="skybox" colorspace="auto" name="//unnamed_texture_0" builtin="gradient" rgb1="0.95 0.95 0.95" rgb2="0.95 0.95 0.95" width="100" height="600"/>
    <texture type="2d" colorspace="auto" name="texplane" builtin="checker" rgb1="0.345 0.575 0.748" rgb2="0.345 0.575 0.748" markrgb="1 1 1" width="512" height="512"/>
    <material name="MatPlane" class="/" texture="texplane" texuniform="true" texrepeat="2 2" specular="0.9"/>
    <mesh name="base_link" class="/" file="base_link.STL"/>
    <mesh name="left_thigh_roll_link" class="/" file="left_thigh_roll_link.STL"/>
    <mesh name="left_thigh_yaw_link" class="/" file="left_thigh_yaw_link.STL"/>
    <mesh name="left_thigh_pitch_link" class="/" file="left_thigh_pitch_link.STL"/>
    <mesh name="left_shank_pitch_link" class="/" file="left_shank_pitch_link.STL"/>
    <mesh name="left_foot_pitch_link" class="/" file="left_foot_pitch_link.STL"/>
    <mesh name="left_foot_roll_link" class="/" file="left_foot_roll_link.STL"/>
    <mesh name="right_thigh_roll_link" class="/" file="right_thigh_roll_link.STL"/>
    <mesh name="right_thigh_yaw_link" class="/" file="right_thigh_yaw_link.STL"/>
    <mesh name="right_thigh_pitch_link" class="/" file="right_thigh_pitch_link.STL"/>
    <mesh name="right_shank_pitch_link" class="/" file="right_shank_pitch_link.STL"/>
    <mesh name="right_foot_pitch_link" class="/" file="right_foot_pitch_link.STL"/>
    <mesh name="right_foot_roll_link" class="/" file="right_foot_roll_link.STL"/>
    <mesh name="waist_yaw_link" class="/" file="waist_yaw_link.STL"/>
    <mesh name="waist_pitch_link" class="/" file="waist_pitch_link.STL"/>
    <mesh name="waist_roll_link" class="/" file="waist_roll_link.STL"/>
    <mesh name="torso_link" class="/" file="torso_link.STL"/>
    <mesh name="left_upper_arm_pitch_link" class="/" file="left_upper_arm_pitch_link.STL"/>
    <mesh name="left_upper_arm_roll_link" class="/" file="left_upper_arm_roll_link.STL"/>
    <mesh name="left_upper_arm_yaw_link" class="/" file="left_upper_arm_yaw_link.STL"/>
    <mesh name="left_lower_arm_pitch_link" class="/" file="left_lower_arm_pitch_link.STL"/>
    <mesh name="left_hand_yaw_link" class="/" file="left_hand_yaw_link.STL"/>
    <mesh name="left_hand_roll_link" class="/" file="left_hand_roll_link.STL"/>
    <mesh name="left_hand_pitch" class="/" file="left_hand_pitch.STL"/>
    <mesh name="left_jaw_link" class="/" file="left_jaw_link.STL"/>
    <mesh name="right_upper_arm_pitch_link" class="/" file="right_upper_arm_pitch_link.STL"/>
    <mesh name="right_upper_arm_roll_link" class="/" file="right_upper_arm_roll_link.STL"/>
    <mesh name="right_upper_arm_yaw_link" class="/" file="right_upper_arm_yaw_link.STL"/>
    <mesh name="right_lower_arm_pitch_link" class="/" file="right_lower_arm_pitch_link.STL"/>
    <mesh name="right_hand_yaw_link" class="/" file="right_hand_yaw_link.STL"/>
    <mesh name="right_hand_roll_link" class="/" file="right_hand_roll_link.STL"/>
    <mesh name="right_hand_pitch" class="/" file="right_hand_pitch.STL"/>
    <mesh name="right_jaw_link" class="/" file="right_jaw_link.STL"/>
    <mesh name="head_roll_link" class="/" file="head_roll_link.STL"/>
    <mesh name="head_pitch_link" class="/" file="head_pitch_link.STL"/>
    <mesh name="head_yaw_link" class="/" file="head_yaw_link.STL"/>
    <mesh name="imu_link" class="/" file="imu_link.STL"/>
  </asset>

  <worldbody>
    <geom name="floor" class="/" size="100 100 0.125" type="plane" group="0" material="MatPlane"/>
    <light name="toplight_shadow" class="/" pos="0 0 5" dir="0.0990148 0.0990148 -0.990148" type="directional" ambient="0.04 0.04 0.04" diffuse="0.55 0.55 0.55" specular="0.12 0.12 0.12"/>
    <light name="toplight_fill" class="/" pos="0 0 5" dir="0.0990148 0.0990148 -0.990148" type="directional" castshadow="false" ambient="0.04 0.04 0.04" diffuse="0.3 0.3 0.3" specular="0.08 0.08 0.08"/>
    <body name="trunk" pos="-0.00357601 -0.00140457 -0.00591918" quat="1 -0.000624399 0.000258536 -6.23168e-05">
      <inertial pos="-0.0791114 -0.0122816 -0.0202284" quat="0.999093 -0.0173915 0.000972594 -0.0388485" mass="4.5597" diaginertia="0.125377 0.0394859 0.0147842"/>
      <joint name="//unnamed_joint_0" type="free"/>
      <geom name="//unnamed_geom_1" class="visual" rgba="0.12 0.12 0.12 1" mesh="base_link"/>
      <geom name="base_link.STL" class="collision" size="0.134444 0.0752993" pos="-0.0532279 0.000463627 0.00729871" quat="0.706838 -0.707359 0.00477667 0" type="cylinder" rgba="0.752941 0.752941 0.752941 1"/>
      <geom name="//unnamed_geom_3" class="visual" pos="0 0 -0.0472311" quat="1 0 0 0" rgba="0.12 0.12 0.12 1" mesh="imu_link"/>
      <geom name="//unnamed_geom_4" class="reward_collision_sphere" size="0.0878762" pos="0 0.12529 0.0792469"/>
      <geom name="//unnamed_geom_5" class="reward_collision_sphere" size="0.0878762" pos="0 -0.12529 0.0792469"/>
      <site name="imu" class="/" pos="0.00618553 0.0443472 -0.116238" size="0.0109845"/>
      <camera name="track" class="/" pos="0 -2.50581 0" quat="0.707107 0.707107 0 0" mode="trackcom"/>
      <body name="left_thigh_roll_link" pos="-0.0265178 0.131418 -0.0192628" quat="0.999996 -0.001058 -0.00201599 0.00166056">
        <inertial pos="-0.00306492 0.00855365 -0.00617016" quat="-0.0492966 0.717157 -0.0394105 0.694048" mass="1.70304" diaginertia="0.00783836 0.0067639 0.000452813"/>
        <joint name="left_hip_roll_joint" class="/" pos="0 0 0" axis="-0.99986 -0.0160803 0.00467781" stiffness="0.0340678" range="-0.700226 0.120418" armature="0.139843" damping="0.00160875" frictionloss="0.111639"/>
        <geom name="//unnamed_geom_6" class="visual" mesh="left_thigh_roll_link"/>
        <body name="left_thigh_yaw_link" pos="0.0388037 -0.00298258 0.00460804" quat="1 -0.000258131 6.63709e-05 -3.83118e-05">
          <inertial pos="0.000788774 0.0439585 -0.0988557" quat="0.571353 0.0948509 -0.195487 0.791419" mass="4.71064" diaginertia="0.0671572 0.0630944 0.00309394"/>
          <joint name="left_hip_yaw_joint" class="/" pos="0 0 0" axis="-0.000579425 -0.00298801 -0.999995" stiffness="0.056599" range="-0.968718 0.683096" armature="0.147555" damping="0" frictionloss="0.0375429"/>
          <geom name="//unnamed_geom_7" class="visual" mesh="left_thigh_yaw_link"/>
          <body name="left_thigh_pitch_link" pos="0.013723 0.0263387 -0.121805" quat="1 -6.38014e-06 0.0001625 0.000154142">
            <inertial pos="-0.00472148 -0.0340317 -0.0497777" quat="0.999812 -0.0149884 -0.0101441 0.00697131" mass="12.1105" diaginertia="0.292644 0.277391 0.0089396"/>
            <joint name="left_hip_pitch_joint" class="/" pos="0 0 0" axis="-0.0313166 0.99863 0.0419313" range="-1.51378 0.449204" armature="0.173359" damping="0" frictionloss="0.107116"/>
            <geom name="//unnamed_geom_8" class="visual" mesh="left_thigh_pitch_link"/>
            <geom name="left_thigh_pitch_link.STL" class="collision" size="0.0900731 0.137212" pos="0.000875052 -0.0375871 -0.132387" type="cylinder" rgba="0.752941 0.752941 0.752941 1"/>
            <geom name="//unnamed_geom_10" class="reward_collision_sphere" size="0.109845" pos="0 -0.012529 -0.0396234"/>
            <body name="left_shank_pitch_link" pos="0.00640995 -0.0236274 -0.279851" quat="0.999988 0.000418385 -0.00344069 -0.00350352">
              <inertial pos="7.52332e-05 -0.000192131 -0.0946612" quat="0.997573 -0.030644 0.00874372 -0.0619019" mass="1.85925" diaginertia="0.0322147 0.0273874 0.000337796"/>
              <joint name="left_knee_pitch_joint" class="/" pos="0 0 0" axis="-0.00530948 0.99969 0.0243265" range="-0.0894647 1.93121" armature="0.11161" damping="0.00699528" frictionloss="0.112238"/>
              <geom name="//unnamed_geom_11" class="visual" mesh="left_shank_pitch_link"/>
              <geom name="left_shank_pitch_link.STL" class="collision" size="0.058571 0.0992836" pos="-2.07374e-05 -0.00105563 -0.138437" quat="0.00125538 -0.202712 0.979238 0" type="cylinder" rgba="0.752941 0.752941 0.752941 1"/>
              <geom name="//unnamed_geom_13" class="reward_collision_sphere" size="0.0549226"/>
              <geom name="//unnamed_geom_14" class="reward_collision_sphere" size="0.0659071" pos="0 0 -0.0871716"/>
              <body name="left_foot_pitch_link" pos="0.000197701 -0.00537148 -0.271336" quat="0.99998 0.00577123 0.000723918 -0.0023629">
                <inertial pos="0.000328453 0.0109625 -0.00606412" quat="-0.0101318 0.67609 0.00400427 0.736738" mass="0.0629413" diaginertia="1.3585e-05 1.50699e-05 1.40367e-06"/>
                <joint name="left_ankle_pitch_joint" class="/" pos="0 0 0" axis="-0.0478798 0.998273 -0.0340427" stiffness="0.0201768" range="-1.06697 0.321673" armature="0.107187" damping="0" frictionloss="0.107139"/>
                <geom name="//unnamed_geom_15" class="visual" mesh="left_foot_pitch_link"/>
                <body name="left_foot_roll_link" pos="-0.00414049 -0.0113607 0.00169124" quat="1 0.000242111 -0.00025647 -0.000385431">
                  <inertial pos="0.0493256 -0.00399292 -0.0367737" quat="-0.000834202 0.725792 -0.00244023 0.68791" mass="1.7938" diaginertia="0.022843 0.0209898 0.000272865"/>
                  <joint name="left_ankle_roll_joint" class="/" pos="0 0 0" axis="-0.998325 0.0345151 0.0464399" stiffness="0.00191168" range="-0.442288 0.222676" armature="0.0387764" damping="0" frictionloss="0.14987"/>
                  <geom name="//unnamed_geom_16" class="visual" mesh="left_foot_roll_link"/>
                  <geom name="left_foot" class="foot" size="0.107062 0.0721933 0.0111122" pos="0.0562493 0 -0.0352649"/>
                  <geom name="//unnamed_geom_18" class="reward_collision_sphere" size="0.0549226" pos="0 0 -0.0237741"/>
                  <geom name="//unnamed_geom_19" class="reward_collision_sphere" size="0.0549226" pos="0.149998 0 -0.0237741"/>
                  <site name="left_foot" class="foot" pos="0.0562493 0 -0.0352649" size="0.0109845"/>
                </body>
              </body>
            </body>
          </body>
        </body>
      </body>
      <body name="right_thigh_roll_link" pos="-0.0467597 -0.13558 -0.0118587" quat="0.999995 -0.00151197 0.00188885 -0.00218181">
        <inertial pos="0.000226771 -0.0104752 0.0128597" quat="0.021324 0.719154 0.0163544 0.694331" mass="1.96308" diaginertia="0.00931534 0.0071269 0.000537386"/>
        <joint name="right_hip_roll_joint" class="/" pos="0 0 0" axis="-0.998147 -0.016729 0.0584986" range="-0.315202 0.775649" armature="0.0889617" damping="0.00755163" frictionloss="0.106841"/>
        <geom name="//unnamed_geom_20" class="visual" mesh="right_thigh_roll_link"/>
        <body name="right_thigh_yaw_link" pos="0.0441734 -0.004488 0.00264884" quat="0.999981 0.000728242 -0.00344274 0.00513071">
          <inertial pos="-0.0014584 -0.0551703 -0.101544" quat="0.686782 -0.147311 0.153671 0.694993" mass="4.33282" diaginertia="0.0615716 0.0563907 0.002269"/>
          <joint name="right_hip_yaw_joint" class="/" pos="0 0 0" axis="0.0177837 0.0464705 -0.998761" range="-0.84048 0.709217" armature="0.0450581" damping="0.00957237" frictionloss="0.0849492"/>
          <geom name="//unnamed_geom_21" class="visual" mesh="right_thigh_yaw_link"/>
          <body name="right_thigh_pitch_link" pos="0.0138578 -0.0179879 -0.105156" quat="1 0.000622382 4.17324e-05 -0.000101579">
            <inertial pos="-0.00992816 0.0297794 -0.049111" quat="0.999488 -0.00406755 0.00985541 0.030174" mass="10.6011" diaginertia="0.319713 0.30698 0.00793308"/>
            <joint name="right_hip_pitch_joint" class="/" pos="0 0 0" axis="-0.00687093 -0.999975 0.00161604" range="-0.463124 1.63911" armature="0.0792179" damping="0.0669411" frictionloss="0.178416"/>
            <geom name="//unnamed_geom_22" class="visual" mesh="right_thigh_pitch_link"/>
            <geom name="right_thigh_pitch_link.STL" class="collision" size="0.0900731 0.137209" pos="-0.00265405 0.0375871 -0.132387" quat="0.999971 0.00269833 0.00706272 0" type="cylinder" rgba="0.752941 0.752941 0.752941 1"/>
            <geom name="//unnamed_geom_24" class="reward_collision_sphere" size="0.109845" pos="0 0.012529 -0.0396234"/>
            <body name="right_shank_pitch_link" pos="-0.00194386 0.0224433 -0.286906" quat="1 -0.000301671 0.000176355 0.000369376">
              <inertial pos="0.000572595 0.0142791 -0.0816031" quat="0.999758 0.00666924 0.00760442 0.0195328" mass="2.25563" diaginertia="0.0382169 0.0363426 0.000449603"/>
              <joint name="right_knee_pitch_joint" class="/" pos="0 0 0" axis="0.0487789 -0.998809 0.00116032" range="-1.64793 0.0822314" armature="0.11795" damping="0.0102902" frictionloss="0.170452"/>
              <geom name="//unnamed_geom_25" class="visual" mesh="right_shank_pitch_link"/>
              <geom name="right_shank_pitch_link.STL" class="collision" size="0.0585707 0.0992826" pos="-2.07374e-05 -0.00105564 -0.138443" type="cylinder" rgba="0.752941 0.752941 0.752941 1"/>
              <geom name="//unnamed_geom_27" class="reward_collision_sphere" size="0.0549226"/>
              <geom name="//unnamed_geom_28" class="reward_collision_sphere" size="0.0659071" pos="0 0 -0.0871716"/>
              <body name="right_foot_pitch_link" pos="-0.0107063 0.00337976 -0.271021" quat="0.999988 -0.000110916 0.00313547 0.00379419">
                <inertial pos="-0.00444545 -0.000945639 0.010923" quat="-0.0109916 0.691146 0.0118527 0.722534" mass="0.0970681" diaginertia="2.152e-05 1.69366e-05 2.06852e-06"/>
                <joint name="right_ankle_pitch_joint" class="/" pos="0 0 0" axis="-0.0363564 -0.999232 0.0145823" stiffness="0.0028603" range="-0.369805 1.06035" armature="0.119224" damping="0" frictionloss="0.120433"/>
                <geom name="//unnamed_geom_29" class="visual" mesh="right_foot_pitch_link"/>
                <body name="right_foot_roll_link" pos="0.00141668 0.00358127 -0.0110434" quat="0.999999 0.000690984 0.000435266 -0.000790545">
                  <inertial pos="0.0358674 0.00811495 -0.0293571" quat="-0.010848 0.688334 0.0446077 0.72394" mass="1.35042" diaginertia="0.0179646 0.0174815 0.000220722"/>
                  <joint name="right_ankle_roll_joint" class="/" pos="0 0 0" axis="-0.999225 0.0359382 -0.0160674" stiffness="0.0167948" range="-0.333343 0.613989" armature="0.136395" damping="0.065126" frictionloss="0.0594403"/>
                  <geom name="//unnamed_geom_30" class="visual" mesh="right_foot_roll_link"/>
                  <geom name="right_foot" class="foot" size="0.175425 0.0414052 0.00588464" pos="0.0562493 0 -0.0352649"/>
                  <geom name="//unnamed_geom_32" class="reward_collision_sphere" size="0.0549226" pos="0 0 -0.0237741"/>
                  <geom name="//unnamed_geom_33" class="reward_collision_sphere" size="0.0549226" pos="0.149998 0 -0.0237741"/>
                  <site name="right_foot" class="foot" pos="0.0562493 0 -0.0352649" size="0.0109845"/>
                </body>
              </body>
            </body>
          </body>
        </body>
      </body>
      <body name="waist_yaw_link" pos="-0.00556599 0.0135547 -0.00208285" quat="0.999977 -0.00389847 0.00372847 -0.0041131">
        <inertial pos="0.00346074 -0.0100979 0.0410383" quat="0.968841 0.213402 -0.0248347 0.123251" mass="2.44704" diaginertia="0.00913068 0.00949763 0.000674897"/>
        <joint name="waist_yaw_joint" class="/" pos="0 0 0" axis="0.0113996 -0.0239669 0.999648" range="-0.894867 0.885976" armature="0.105402" damping="0.00184744" frictionloss="0.108662"/>
        <geom name="//unnamed_geom_34" class="visual" rgba="0.12 0.12 0.12 1" mesh="waist_yaw_link"/>
        <body name="waist_pitch_link" pos="-0.00391653 -0.0112023 0.0672925" quat="0.999997 -0.000826319 0.0024704 5.01997e-05">
          <inertial pos="0.00510644 -0.0157501 0.0365834" quat="0.998831 -0.00878744 0.0268524 -0.0392094" mass="2.04082" diaginertia="0.0160572 0.0158473 0.000566298"/>
          <joint name="waist_pitch_joint" class="/" pos="0 0 0" axis="-0.000790104 -1 0.000543316" stiffness="0.00305562" range="-1.0255 0.333773" armature="0.123586" damping="0.014252" frictionloss="0.0330109"/>
          <geom name="//unnamed_geom_35" class="visual" rgba="0.12 0.12 0.12 1" mesh="waist_pitch_link"/>
          <body name="waist_roll_link" pos="0.00874244 -0.0131428 0.0617306" quat="1 -0.000185704 -0.000432392 0.000753095">
            <inertial pos="-0.00792753 0.00228574 0.116645" quat="0.998729 0.00446555 -0.0501929 0.000613164" mass="10.277" diaginertia="0.195634 0.188703 0.0124001"/>
            <joint name="waist_roll_joint" class="/" pos="0 0 0" axis="-0.999735 0.013835 -0.018382" range="-0.631517 0.45492" armature="0.0380814" damping="0" frictionloss="0.0948722"/>
            <geom name="//unnamed_geom_36" class="visual" rgba="0.12 0.12 0.12 1" mesh="waist_roll_link"/>
            <geom name="//unnamed_geom_37" class="visual" pos="-0.00281246 0.000719706 0.127072" quat="1 0 0 0" mesh="torso_link"/>
            <geom name="torso_link.STL" class="collision" size="0.172926 0.0331656" pos="-0.0225821 0.007229 0.11715" type="cylinder" rgba="0.752941 0.752941 0.752941 1"/>
            <geom name="//unnamed_geom_39" class="reward_collision_sphere" size="0.142799" pos="0 0 0.158494"/>
            <body name="left_upper_arm_pitch_link" pos="-0.00656919 0.119691 0.16985" quat="0.976667 0.214722 -0.00168339 0.00362218">
              <inertial pos="0.0160845 0.0676559 0.00917719" quat="0.688924 0.722303 -0.0188835 -0.0574912" mass="0.942114" diaginertia="0.0052922 0.00561061 0.00013392"/>
              <joint name="left_shoulder_pitch_joint" class="/" pos="0 0 0" axis="0.0112897 0.998906 -0.0453899" stiffness="0.0471134" range="-2.83352 1.74436" armature="0.126103" damping="0" frictionloss="0.117409"/>
              <geom name="//unnamed_geom_40" class="visual" mesh="left_upper_arm_pitch_link"/>
              <body name="left_upper_arm_roll_link" pos="0.0126316 0.129916 0.00174218" quat="0.976758 -0.214339 -0.00140209 -9.85202e-05">
                <inertial pos="0.00781015 0.0221616 -0.0189438" quat="0.89069 0.268603 0.122952 -0.345552" mass="0.911127" diaginertia="0.00305297 0.00318947 0.000108578"/>
                <joint name="left_shoulder_roll_joint" class="/" pos="0 0 0" axis="-0.999955 -0.00714886 0.00627278" stiffness="0.00367955" range="-2.54015 0.538141" armature="0.135298" damping="0" frictionloss="0.112982"/>
                <geom name="//unnamed_geom_41" class="visual" mesh="left_upper_arm_roll_link"/>
                <body name="left_upper_arm_yaw_link" pos="-0.0113502 0.0498679 -0.0559626" quat="0.999998 0.00120081 -0.000914768 0.00100157">
                  <inertial pos="-0.0116912 -0.00335097 -0.0743716" quat="0.999711 -0.00988053 -0.0131205 0.0175719" mass="0.675744" diaginertia="0.0106477 0.0107674 6.43681e-05"/>
                  <joint name="left_shoulder_yaw_joint" class="/" pos="0 0 0" axis="-0.0419606 -0.0117284 0.99905" range="-3.00744 2.86296" armature="0.0353463" damping="0" frictionloss="0.140885"/>
                  <geom name="//unnamed_geom_42" class="visual" mesh="left_upper_arm_yaw_link"/>
                  <geom name="left_upper_arm_yaw_link.STL" class="collision" size="0.0398004 0.0933047" pos="4.93561e-05 -0.00112046 -0.0628745" quat="0.00803418 -0.995528 0.0941277 0" type="cylinder" rgba="0.752941 0.752941 0.752941 1"/>
                  <body name="left_lower_arm_pitch_link" pos="0.00115003 0.0048522 -0.137676" quat="1 -0.00021914 -7.6275e-05 -0.000300605">
                    <inertial pos="-0.0115674 0.00922171 -0.017524" quat="0.699816 -0.0911857 0.091485 0.702548" mass="0.460389" diaginertia="0.000862859 0.000914827 3.19197e-05"/>
                    <joint name="left_elbow_pitch_joint" class="/" pos="0 0 0" axis="0.000132053 1 -0.000920547" range="-2.246 2.47293" armature="0.108604" damping="0.0415378" frictionloss="0.10284"/>
                    <geom name="//unnamed_geom_44" class="visual" mesh="left_lower_arm_pitch_link"/>
                    <body name="left_hand_yaw_link" pos="0.00998806 0.00327108 -0.0518868" quat="1 -0.000285819 0.000103243 5.38611e-06">
                      <inertial pos="-0.0125062 -0.00539433 -0.0471319" quat="0.998407 0.0280336 -0.0340308 -0.0352124" mass="1.17713" diaginertia="0.00633849 0.00572027 0.000124168"/>
                      <joint name="left_wrist_yaw_joint" class="/" pos="0 0 0" axis="-0.0238822 0.0179597 0.999553" range="-2.9955 2.99142" armature="0.110771" damping="0.0127095" frictionloss="0.111374"/>
                      <geom name="//unnamed_geom_45" class="visual" mesh="left_hand_yaw_link"/>
                      <geom name="left_hand_yaw_link.STL" class="collision" size="0.0456647 0.0764453" pos="0.00136154 -0.00193086 -0.0602616" type="cylinder" rgba="0.752941 0.752941 0.752941 1"/>
                      <geom name="//unnamed_geom_47" class="reward_collision_sphere" size="0.0549226"/>
                      <body name="left_hand_roll_link" pos="0.0105479 0.00951816 -0.160576" quat="0.999997 1.9724e-05 -0.00184875 0.00152157">
                        <inertial pos="-0.00875434 0.000487024 0.0120978" quat="0.46953 0.544998 0.496427 0.48588" mass="0.00684975" diaginertia="1.0717e-06 1.23062e-06 2.21619e-08"/>
                        <joint name="left_wrist_roll_joint" class="/" pos="0 0 0" axis="-0.999912 -0.00122945 -0.0132271" range="-0.895386 1.14512" armature="0.0627112" damping="0.0212685" frictionloss="0.115183"/>
                        <geom name="//unnamed_geom_48" class="visual" mesh="left_hand_roll_link"/>
                        <body name="left_hand_pitch_link" pos="-0.00558273 0.00133954 0.0068627" quat="1 1.85262e-05 -4.68534e-06 -1.40048e-05">
                          <inertial pos="-0.010149 -0.0118442 -0.0362172" quat="0.749206 -0.119233 0.103169 0.643296" mass="0.328516" diaginertia="0.00097818 0.00093802 3.32055e-05"/>
                          <joint name="left_wrist_pitch_joint" class="/" pos="0 0 0" axis="0.0492469 0.998257 -0.0325293" stiffness="0.0266232" range="-0.626044 0.416136" armature="0.144869" damping="0.0146819" frictionloss="0.128581"/>
                          <geom name="//unnamed_geom_49" class="visual" mesh="left_hand_pitch"/>
                          <body name="left_jaw_link" pos="0.0124727 -0.0132063 -0.0548878" quat="0.999976 0.00169777 0.0040633 0.00535636">
                            <inertial pos="-0.0131263 -0.00585632 -0.0159807" quat="0.707168 -0.00639541 0.0622004 0.704275" mass="0.0870285" diaginertia="0.000242411 0.000185195 9.54979e-06"/>
                            <joint name="left_jaw_joint" class="/" pos="0 0 0" axis="-0.999983 -0.00557292 0.00152608" range="-1.08911 -0.156632" armature="0.181363" damping="0.0313189" frictionloss="0.0735332"/>
                            <geom name="//unnamed_geom_50" class="visual" mesh="left_jaw_link"/>
                            <geom name="//unnamed_geom_51" class="collision" size="0.0395443"/>
                            <geom name="//unnamed_geom_52" class="reward_collision_sphere" size="0.0549226" pos="0 0 -0.0158494"/>
                          </body>
                        </body>
                      </body>
                    </body>
                  </body>
                </body>
              </body>
            </body>
            <body name="right_upper_arm_pitch_link" pos="-0.000971908 -0.126754 0.169276" quat="0.977345 -0.211644 0.00187688 0.000443038">
              <inertial pos="0.00583333 -0.0709269 -0.000296205" quat="0.720863 0.69252 -0.00342461 0.0275984" mass="1.14111" diaginertia="0.00725681 0.00680346 0.000190365"/>
              <joint name="right_shoulder_pitch_joint" class="/" pos="0 0 0" axis="-0.0349763 -0.999388 -0.000431337" range="-1.8921 2.86774" armature="0.139909" damping="0.0520047" frictionloss="0.164695"/>
              <geom name="//unnamed_geom_53" class="visual" mesh="right_upper_arm_pitch_link"/>
              <body name="right_upper_arm_roll_link" pos="0.000751096 -0.118236 -0.00457228" quat="0.976538 0.215311 0.000211043 -0.00384709">
                <inertial pos="0.0014672 -0.0120318 -0.00695527" quat="0.895144 -0.248333 0.123723 0.348913" mass="0.899646" diaginertia="0.00328768 0.00382732 0.000122283"/>
                <joint name="right_shoulder_roll_joint" class="/" pos="0 0 0" axis="-0.998475 0.0421901 -0.0356048" stiffness="0.00315169" range="-0.474 2.33517" armature="0.107013" damping="0.015949" frictionloss="0.152017"/>
                <geom name="//unnamed_geom_54" class="visual" mesh="right_upper_arm_roll_link"/>
                <body name="right_upper_arm_yaw_link" pos="0.000462739 -0.0507527 -0.0443028" quat="0.999997 0.0025094 -0.000252711 -0.000349136">
                  <inertial pos="-0.0112405 0.000139977 -0.0761617" quat="0.999547 0.0205881 -0.00279029 -0.0217703" mass="0.523612" diaginertia="0.00944406 0.00908772 6.62971e-05"/>
                  <joint name="right_shoulder_yaw_joint" class="/" pos="0 0 0" axis="-0.00335266 -0.00119564 0.999994" stiffness="0.0524556" range="-3.12213 2.97226" armature="0.140576" damping="0" frictionloss="0.167893"/>
                  <geom name="//unnamed_geom_55" class="visual" mesh="right_upper_arm_yaw_link"/>
                  <geom name="right_upper_arm_yaw_link.STL" class="collision" size="0.0398004 0.0933047" pos="4.93561e-05 0.00112046 -0.0628745" type="cylinder" rgba="0.752941 0.752941 0.752941 1"/>
                  <body name="right_lower_arm_pitch_link" pos="-0.00652669 -0.0103806 -0.141877" quat="1 6.67699e-06 0.000404184 -0.000223044">
                    <inertial pos="0.00112385 -0.00632858 -0.0173276" quat="0.705079 0.0429661 -0.0433543 0.706497" mass="0.461806" diaginertia="0.00094347 0.000799389 2.68912e-05"/>
                    <joint name="right_elbow_pitch_joint" class="/" pos="0 0 0" axis="-0.0377994 -0.999157 -0.0160095" stiffness="0.00135159" range="-2.11267 2.2738" armature="0.173199" damping="0.014556" frictionloss="0.176379"/>
                    <geom name="//unnamed_geom_57" class="visual" mesh="right_lower_arm_pitch_link"/>
                    <body name="right_hand_yaw_link" pos="-0.00118402 0.00190534 -0.0543342" quat="1 6.65349e-05 -7.87899e-05 0.000383776">
                      <inertial pos="-0.00593349 -0.00347576 -0.0555522" quat="0.999354 -0.00991974 -0.0148407 -0.0312054" mass="1.08059" diaginertia="0.00653931 0.00640374 0.0001402"/>
                      <joint name="right_wrist_yaw_joint" class="/" pos="0 0 0" axis="-0.0066864 -0.00154274 0.999976" range="-2.97445 2.92011" armature="0.177844" damping="0" frictionloss="0.139705"/>
                      <geom name="//unnamed_geom_58" class="visual" mesh="right_hand_yaw_link"/>
                      <geom name="right_hand_yaw_link.STL" class="collision" size="0.0456647 0.0764453" pos="0.00136154 0.000803254 -0.0602616" type="cylinder" rgba="0.752941 0.752941 0.752941 1"/>
                      <geom name="//unnamed_geom_60" class="reward_collision_sphere" size="0.0549226"/>
                      <body name="right_hand_roll_link" pos="0.00257457 0.00704161 -0.165274" quat="1 -6.10264e-05 -9.23275e-05 -0.000184604">
                        <inertial pos="0.000839942 0.00158396 0.00565655" quat="0.471278 0.484664 0.547637 0.493043" mass="0.00668734" diaginertia="8.93462e-07 1.06665e-06 2.18943e-08"/>
                        <joint name="right_wrist_roll_joint" class="/" pos="0 0 0" axis="-0.99997 -0.000872734 -0.00765284" range="-0.867262 0.942287" armature="0.105704" damping="0.0297472" frictionloss="0.0957087"/>
                        <geom name="//unnamed_geom_61" class="visual" mesh="right_hand_roll_link"/>
                        <body name="right_hand_pitch_link" pos="0.010486 -0.0104205 -0.00201426" quat="0.999988 0.00366536 -0.00127627 -0.00311722">
                          <inertial pos="-0.000339259 0.0141396 -0.0536954" quat="0.726092 0.118421 -0.169299 0.655824" mass="0.317086" diaginertia="0.000879969 0.000879083 2.9948e-05"/>
                          <joint name="right_wrist_pitch_joint" class="/" pos="0 0 0" axis="0.00576218 -0.999744 -0.021897" range="-0.627654 0.600312" armature="0.111377" damping="0.00653814" frictionloss="0.168328"/>
                          <geom name="//unnamed_geom_62" class="visual" mesh="right_hand_pitch"/>
                          <body name="right_jaw_link" pos="0.00356616 0.00190216 -0.0538392" quat="1 0.000465597 0.00030442 -0.000415983">
                            <inertial pos="4.22186e-05 0.00610094 -0.026891" quat="0.71146 0.0467476 -0.0522005 0.699224" mass="0.0787456" diaginertia="0.000220081 0.000159272 9.28027e-06"/>
                            <joint name="right_jaw_joint" class="/" pos="0 0 0" axis="-0.999986 -0.00232545 -0.00464823" range="0.0871157 0.997973" armature="0.0529454" damping="0.0143654" frictionloss="0.145759"/>
                            <geom name="//unnamed_geom_63" class="visual" mesh="right_jaw_link"/>
                            <geom name="//unnamed_geom_64" class="collision" size="0.0395443"/>
                            <geom name="//unnamed_geom_65" class="reward_collision_sphere" size="0.0549226" pos="0 0 -0.0158494"/>
                          </body>
                        </body>
                      </body>
                    </body>
                  </body>
                </body>
              </body>
            </body>
            <body name="head_roll_link" pos="0.00298738 0.00898117 0.236803" quat="0.999977 0.00223501 0.00258882 -0.00588766">
              <inertial pos="0.00304353 -0.0012496 -0.000924695" quat="-0.0491171 0.724652 0.0368451 0.686375" mass="0.0131937" diaginertia="2.04832e-06 1.31831e-06 1.34196e-07"/>
              <joint name="head_roll_joint" class="/" pos="0 0 0" axis="-0.999974 0.00261984 -0.00671275" stiffness="0.0539518" range="-0.376978 0.173333" armature="0.168678" damping="0.0341458" frictionloss="0.109478"/>
              <geom name="//unnamed_geom_66" class="visual" mesh="head_roll_link"/>
              <body name="head_pitch_link" pos="-0.00751233 -0.000721153 -0.00805712" quat="0.999999 -0.000655182 -0.000544865 -0.0014471">
                <inertial pos="0.003556 -0.00378525 0.0123301" quat="0.670218 0.633804 0.26268 -0.283017" mass="0.0923021" diaginertia="7.92608e-05 9.18254e-05 6.04695e-06"/>
                <joint name="head_pitch_joint" class="/" pos="0 0 0" axis="-0.0056967 -0.99998 -0.00280075" range="-0.945051 0.621682" armature="0.0453715" damping="0.050043" frictionloss="0.0541365"/>
                <geom name="//unnamed_geom_67" class="visual" mesh="head_pitch_link"/>
                <body name="head_yaw_link" pos="0.0116483 0.0081262 0.0482992" quat="1 -8.89408e-06 -9.24849e-06 -9.32199e-06">
                  <inertial pos="0.043412 -0.00317819 0.0883998" quat="0.689666 -0.137079 -0.15527 0.693874" mass="2.06914" diaginertia="0.0349744 0.0232893 0.00163688"/>
                  <joint name="head_yaw_joint" class="/" pos="0 0 0" axis="0.0173947 -0.0138426 0.999753" range="-2.94607 2.49635" armature="0.0953051" damping="0.0729833" frictionloss="0.181447"/>
                  <geom name="//unnamed_geom_68" class="visual" rgba="0.12 0.12 0.12 1" mesh="head_yaw_link"/>
                  <geom name="head_yaw_link.STL" class="collision" size="0.130372" pos="0.0228511 -0.00110259 0.0741911" rgba="0.752941 0.752941 0.752941 1"/>
                  <geom name="//unnamed_geom_70" class="reward_collision_sphere" size="0.109845" pos="0.0374995 0 0.0792469"/>
                  <camera name="ego_camera" class="/" pos="0.137498 0 0.0871716" quat="-0.5 -0.5 0.5 0.5"/>
                </body>
              </body>
            </body>
          </body>
        </body>
      </body>
    </body>
  </worldbody>

  <contact>
    <pair class="/" geom1="floor" geom2="left_foot" name="//unnamed_contact_0"/>
    <pair class="/" geom1="floor" geom2="right_foot" name="//unnamed_contact_1"/>
  </contact>

  <actuator>
    <general name="left_hip_roll" class="/" joint="left_hip_roll_joint" forcerange="-58.35 58.35" gainprm="65.8199" biasprm="0 -65.8199 -1.09845"/>
    <general name="left_hip_yaw" class="/" joint="left_hip_yaw_joint" forcerange="-79.4104 79.4104" gainprm="65.8199" biasprm="0 -65.8199 -1.09845"/>
    <general name="left_hip_pitch" class="/" joint="left_hip_pitch_joint" forcerange="-252.387 252.387" gainprm="65.8199" biasprm="0 -65.8199 -1.09845"/>
    <general name="left_knee_pitch" class="/" joint="left_knee_pitch_joint" forcerange="-260.39 260.39" gainprm="65.8199" biasprm="0 -65.8199 -1.09845"/>
    <general name="left_ankle_pitch" class="/" joint="left_ankle_pitch_joint" forcerange="-12.0492 12.0492" gainprm="65.8199" biasprm="0 -65.8199 -1.09845"/>
    <general name="left_ankle_roll" class="/" joint="left_ankle_roll_joint" forcerange="-42.195 42.195" gainprm="65.8199" biasprm="0 -65.8199 -1.09845"/>
    <general name="right_hip_roll" class="/" joint="right_hip_roll_joint" forcerange="-52.563 52.563" gainprm="65.8199" biasprm="0 -65.8199 -1.09845"/>
    <general name="right_hip_yaw" class="/" joint="right_hip_yaw_joint" forcerange="-65.7942 65.7942" gainprm="65.8199" biasprm="0 -65.8199 -1.09845"/>
    <general name="right_hip_pitch" class="/" joint="right_hip_pitch_joint" forcerange="-351.454 351.454" gainprm="65.8199" biasprm="0 -65.8199 -1.09845"/>
    <general name="right_knee_pitch" class="/" joint="right_knee_pitch_joint" forcerange="-228.07 228.07" gainprm="65.8199" biasprm="0 -65.8199 -1.09845"/>
    <general name="right_ankle_pitch" class="/" joint="right_ankle_pitch_joint" forcerange="-12.6547 12.6547" gainprm="65.8199" biasprm="0 -65.8199 -1.09845"/>
    <general name="right_ankle_roll" class="/" joint="right_ankle_roll_joint" forcerange="-33.8083 33.8083" gainprm="65.8199" biasprm="0 -65.8199 -1.09845"/>
    <general name="waist_yaw" class="/" joint="waist_yaw_joint" forcerange="-74.3337 74.3337" gainprm="65.8199" biasprm="0 -65.8199 -1.09845"/>
    <general name="waist_pitch" class="/" joint="waist_pitch_joint" forcerange="-74.9972 74.9972" gainprm="65.8199" biasprm="0 -65.8199 -1.09845"/>
    <general name="waist_roll" class="/" joint="waist_roll_joint" forcerange="-76.6517 76.6517" gainprm="65.8199" biasprm="0 -65.8199 -1.09845"/>
    <general name="left_shoulder_pitch" class="/" joint="left_shoulder_pitch_joint" forcerange="-44.2244 44.2244" gainprm="65.8199" biasprm="0 -65.8199 -1.09845"/>
    <general name="left_shoulder_roll" class="/" joint="left_shoulder_roll_joint" forcerange="-21.1749 21.1749" gainprm="65.8199" biasprm="0 -65.8199 -1.09845"/>
    <general name="left_shoulder_yaw" class="/" joint="left_shoulder_yaw_joint" forcerange="-46.7123 46.7123" gainprm="65.8199" biasprm="0 -65.8199 -1.09845"/>
    <general name="left_elbow_pitch" class="/" joint="left_elbow_pitch_joint" forcerange="-33.9457 33.9457" gainprm="65.8199" biasprm="0 -65.8199 -1.09845"/>
    <general name="left_wrist_yaw" class="/" joint="left_wrist_yaw_joint" forcerange="-11.5353 11.5353" gainprm="65.8199" biasprm="0 -65.8199 -1.09845"/>
    <general name="left_wrist_roll" class="/" joint="left_wrist_roll_joint" forcerange="-4.55173 4.55173" gainprm="65.8199" biasprm="0 -65.8199 -1.09845"/>
    <general name="left_wrist_pitch" class="/" joint="left_wrist_pitch_joint" forcerange="-3.82754 3.82754" gainprm="65.8199" biasprm="0 -65.8199 -1.09845"/>
    <general name="left_jaw" class="/" joint="left_jaw_joint" forcerange="-5.42818 5.42818" gainprm="65.8199" biasprm="0 -65.8199 -1.09845"/>
    <general name="right_shoulder_pitch" class="/" joint="right_shoulder_pitch_joint" forcerange="-43.8505 43.8505" gainprm="65.8199" biasprm="0 -65.8199 -1.09845"/>
    <general name="right_shoulder_roll" class="/" joint="right_shoulder_roll_joint" forcerange="-25.7049 25.7049" gainprm="65.8199" biasprm="0 -65.8199 -1.09845"/>
    <general name="right_shoulder_yaw" class="/" joint="right_shoulder_yaw_joint" forcerange="-32.5196 32.5196" gainprm="65.8199" biasprm="0 -65.8199 -1.09845"/>
    <general name="right_elbow_pitch" class="/" joint="right_elbow_pitch_joint" forcerange="-33.8775 33.8775" gainprm="65.8199" biasprm="0 -65.8199 -1.09845"/>
    <general name="right_wrist_yaw" class="/" joint="right_wrist_yaw_joint" forcerange="-11.1961 11.1961" gainprm="65.8199" biasprm="0 -65.8199 -1.09845"/>
    <general name="right_wrist_roll" class="/" joint="right_wrist_roll_joint" forcerange="-2.7167 2.7167" gainprm="65.8199" biasprm="0 -65.8199 -1.09845"/>
    <general name="right_wrist_pitch" class="/" joint="right_wrist_pitch_joint" forcerange="-5.90522 5.90522" gainprm="65.8199" biasprm="0 -65.8199 -1.09845"/>
    <general name="right_jaw" class="/" joint="right_jaw_joint" forcerange="-3.02984 3.02984" gainprm="65.8199" biasprm="0 -65.8199 -1.09845"/>
    <general name="head_roll" class="/" joint="head_roll_joint" forcerange="-4.88025 4.88025" gainprm="65.8199" biasprm="0 -65.8199 -1.09845"/>
    <general name="head_pitch" class="/" joint="head_pitch_joint" forcerange="-4.56129 4.56129" gainprm="65.8199" biasprm="0 -65.8199 -1.09845"/>
    <general name="head_yaw" class="/" joint="head_yaw_joint" forcerange="-4.31993 4.31993" gainprm="65.8199" biasprm="0 -65.8199 -1.09845"/>
  </actuator>

  <sensor>
    <gyro site="imu" name="imu_angular_velocity"/>
    <velocimeter site="imu" name="imu_linear_velocity"/>
    <framelinvel objtype="site" objname="left_foot" name="left_foot_global_linear_velocity"/>
    <framelinvel objtype="site" objname="right_foot" name="right_foot_global_linear_velocity"/>
  </sensor>

  <keyframe>
    <key name="home" qpos="0 0 0.8665 1 0 0 0 0 0 -0.4 0.8 -0.4 0 0 0 0.4 -0.8 0.4 0 0 0 0 0 -0.2 0 -0.785 0 0 0 0 0 0.2 0 0.785 0 0 0 0 0 0 0"/>
  </keyframe>
</mujoco>
