<mujoco model="GR1T2_jaw">
  <compiler angle="radian" assetdir="assets" balanceinertia="true" inertiafromgeom="false"/>

  <option timestep="0.005" density="1.2" viscosity="2e-05"/>

  <size nkey="1"/>

  <visual>
    <quality shadowsize="8192"/>
    <map shadowclip="0.5"/>
  </visual>

  <default>
    <default class="/">
      <joint armature="0.1" damping="0.01" frictionloss="0.1"/>
      <geom contype="0" conaffinity="0" group="1" solref="-1000 -80"/>
      <site size="0.01 0.005 0.005" group="5"/>
      <general forcelimited="true" biastype="affine" gainprm="80" biasprm="0 -80 -2"/>
      <default class="visual">
        <geom type="mesh" density="0" rgba="0.18 0.18 0.18 1"/>
      </default>
      <default class="collision">
        <geom group="3"/>
      </default>
      <default class="foot">
        <geom size="0.126 0.045 0.01" type="box" condim="6" group="4" priority="1" solimp="0.015 1 0.01"/>
      </default>
      <default class="reward_collision_sphere">
        <geom group="5" rgba="1 0 0 1"/>
      </default>
    </default>
  </default>

  <asset>
    <texture type="skybox" colorspace="auto" name="//unnamed_texture_0" builtin="gradient" rgb1="0.95 0.95 0.95" rgb2="0.95 0.95 0.95" width="100" height="600"/>
    <texture type="2d" colorspace="auto" name="texplane" builtin="checker" rgb1="0.345 0.575 0.748" rgb2="0.345 0.575 0.748" markrgb="1 1 1" width="512" height="512"/>
    <material name="MatPlane" class="/" texture="texplane" texuniform="true" texrepeat="2 2" specular="0.9"/>
    <mesh name="base_link" class="/" file="base_link.STL"/>
    <mesh name="left_thigh_roll_link" class="/" file="left_thigh_roll_link.STL"/>
    <mesh name="left_thigh_yaw_link" class="/" file="left_thigh_yaw_link.STL"/>
    <mesh name="left_thigh_pitch_link" class="/" file="left_thigh_pitch_link.STL"/>
    <mesh name="left_shank_pitch_link" class="/" file="left_shank_pitch_link.STL"/>
    <mesh name="left_foot_pitch_link" class="/" file="left_foot_pitch_link.STL"/>
    <mesh name="left_foot_roll_link" class="/" file="left_foot_roll_link.STL"/>
    <mesh name="right_thigh_roll_link" class="/" file="right_thigh_roll_link.STL"/>
    <mesh name="right_thigh_yaw_link" class="/" file="right_thigh_yaw_link.STL"/>
    <mesh name="right_thigh_pitch_link" class="/" file="right_thigh_pitch_link.STL"/>
    <mesh name="right_shank_pitch_link" class="/" file="right_shank_pitch_link.STL"/>
    <mesh name="right_foot_pitch_link" class="/" file="right_foot_pitch_link.STL"/>
    <mesh name="right_foot_roll_link" class="/" file="right_foot_roll_link.STL"/>
    <mesh name="waist_yaw_link" class="/" file="waist_yaw_link.STL"/>
    <mesh name="waist_pitch_link" class="/" file="waist_pitch_link.STL"/>
    <mesh name="waist_roll_link" class="/" file="waist_roll_link.STL"/>
    <mesh name="torso_link" class="/" file="torso_link.STL"/>
    <mesh name="left_upper_arm_pitch_link" class="/" file="left_upper_arm_pitch_link.STL"/>
    <mesh name="left_upper_arm_roll_link" class="/" file="left_upper_arm_roll_link.STL"/>
    <mesh name="left_upper_arm_yaw_link" class="/" file="left_upper_arm_yaw_link.STL"/>
    <mesh name="left_lower_arm_pitch_link" class="/" file="left_lower_arm_pitch_link.STL"/>
    <mesh name="left_hand_yaw_link" class="/" file="left_hand_yaw_link.STL"/>
    <mesh name="left_hand_roll_link" class="/" file="left_hand_roll_link.STL"/>
    <mesh name="left_hand_pitch" class="/" file="left_hand_pitch.STL"/>
    <mesh name="left_jaw_link" class="/" file="left_jaw_link.STL"/>
    <mesh name="right_upper_arm_pitch_link" class="/" file="right_upper_arm_pitch_link.STL"/>
    <mesh name="right_upper_arm_roll_link" class="/" file="right_upper_arm_roll_link.STL"/>
    <mesh name="right_upper_arm_yaw_link" class="/" file="right_upper_arm_yaw_link.STL"/>
    <mesh name="right_lower_arm_pitch_link" class="/" file="right_lower_arm_pitch_link.STL"/>
    <mesh name="right_hand_yaw_link" class="/" file="right_hand_yaw_link.STL"/>
    <mesh name="right_hand_roll_link" class="/" file="right_hand_roll_link.STL"/>
    <mesh name="right_hand_pitch" class="/" file="right_hand_pitch.STL"/>
    <mesh name="right_jaw_link" class="/" file="right_jaw_link.STL"/>
    <mesh name="head_roll_link" class="/" file="head_roll_link.STL"/>
    <mesh name="head_pitch_link" class="/" file="head_pitch_link.STL"/>
    <mesh name="head_yaw_link" class="/" file="head_yaw_link.STL"/>
    <mesh name="imu_link" class="/" file="imu_link.STL"/>
  </asset>

  <worldbody>
    <geom name="floor" class="/" size="100 100 0.125" type="plane" group="0" material="MatPlane"/>
    <light name="toplight_shadow" class="/" pos="0 0 5" dir="0.0990148 0.0990148 -0.990148" type="directional" ambient="0.04 0.04 0.04" diffuse="0.55 0.55 0.55" specular="0.12 0.12 0.12"/>
    <light name="toplight_fill" class="/" pos="0 0 5" dir="0.0990148 0.0990148 -0.990148" type="directional" castshadow="false" ambient="0.04 0.04 0.04" diffuse="0.3 0.3 0.3" specular="0.08 0.08 0.08"/>
    <body name="trunk" pos="-0.000251388 -0.00184965 -0.00054689" quat="1 0.000250827 -0.000102904 0.000292209">
      <inertial pos="-0.062819 0.00340297 -0.00983092" quat="0.999996 0.00257736 0.000404125 0.00123794" mass="2.87825" diaginertia="0.0466722 0.00600941 0.0182507"/>
      <joint name="//unnamed_joint_0" type="free"/>
      <geom name="//unnamed_geom_1" class="visual" rgba="0.12 0.12 0.12 1" mesh="base_link"/>
      <geom name="base_link.STL" class="collision" size="0.110842 0.0620804" pos="-0.0436244 0.000314574 0.00775755" quat="0.706838 -0.707359 0.00477667 0" type="cylinder" rgba="0.752941 0.752941 0.752941 1"/>
      <geom name="//unnamed_geom_3" class="visual" pos="0 0 -0.0502004" quat="1 0 0 0" rgba="0.12 0.12 0.12 1" mesh="imu_link"/>
      <geom name="//unnamed_geom_4" class="reward_collision_sphere" size="0.0724493" pos="0 0.0850103 0.0842289"/>
      <geom name="//unnamed_geom_5" class="reward_collision_sphere" size="0.0724493" pos="0 -0.0850103 0.0842289"/>
      <site name="imu" class="/" pos="-0.0123353 -0.00235947 -0.0449849" size="0.00905617"/>
      <camera name="track" class="/" pos="0 -1.70021 0" quat="0.707107 0.707107 0 0" mode="trackcom"/>
      <body name="left_thigh_roll_link" pos="-0.0380352 0.0889007 -0.0228756" quat="1 3.42246e-05 7.26047e-05 6.08341e-06">
        <inertial pos="-0.000406058 0.00117913 0.00268038" quat="-0.0269183 0.704879 -0.0313579 0.708123" mass="1.05463" diaginertia="0.00285389 0.00106688 0.00063811"/>
        <joint name="left_hip_roll_joint" class="/" pos="0 0 0" axis="-0.999988 0.00219736 -0.00427098" range="-0.791811 0.150959" armature="0.0863353" damping="0.0118187" frictionloss="0.0886421"/>
        <geom name="//unnamed_geom_6" class="visual" mesh="left_thigh_roll_link"/>
        <body name="left_thigh_yaw_link" pos="0.029049 -0.000352861 0.00338707" quat="1 0.000201194 0.000666124 0.000351773">
          <inertial pos="-0.00591821 0.0337791 -0.0918198" quat="0.571585 0.0911439 -0.195253 0.791745" mass="2.54511" diaginertia="0.0271458 0.00852253 0.00366784"/>
          <joint name="left_hip_yaw_joint" class="/" pos="0 0 0" axis="-0.00755174 -0.00160632 -0.99997" range="-0.703972 0.692083" armature="0.0942259" damping="0" frictionloss="0.0785616"/>
          <geom name="//unnamed_geom_7" class="visual" mesh="left_thigh_yaw_link"/>
          <body name="left_thigh_pitch_link" pos="-0.00107392 0.0195358 -0.117839" quat="1 0.000150188 0.000237882 0.000336435">
            <inertial pos="0.00028922 -0.0255395 -0.0536483" quat="0.999784 -0.0159867 -0.0103767 0.00833764" mass="6.08552" diaginertia="0.103753 0.0416617 0.0122455"/>
            <joint name="left_hip_pitch_joint" class="/" pos="0 0 0" axis="-0.000675985 1 0.000403334" range="-1.7444 0.71711" armature="0.0910641" damping="0.00967409" frictionloss="0.0902632"/>
            <geom name="//unnamed_geom_8" class="visual" mesh="left_thigh_pitch_link"/>
            <geom name="left_thigh_pitch_link.STL" class="collision" size="0.0742606 0.113124" pos="0.000717173 -0.0255031 -0.140709" type="cylinder" rgba="0.752941 0.752941 0.752941 1"/>
            <geom name="//unnamed_geom_10" class="reward_collision_sphere" size="0.0905617" pos="0 -0.00850103 -0.0421144"/>
            <body name="left_shank_pitch_link" pos="-0.00139709 -0.0190132 -0.302107" quat="1 -0.000187814 6.29889e-05 0.000389535">
              <inertial pos="0.00428402 -0.00171259 -0.0960985" quat="0.999601 -0.0154203 0.0130868 -0.0196968" mass="1.33573" diaginertia="0.0118459 0.00454686 0.000526008"/>
              <joint name="left_knee_pitch_joint" class="/" pos="0 0 0" axis="-0.00621553 0.999959 0.00655435" range="-0.0987202 1.95272" armature="0.0884043" damping="0" frictionloss="0.0972517"/>
              <geom name="//unnamed_geom_11" class="visual" mesh="left_shank_pitch_link"/>
              <geom name="left_shank_pitch_link.STL" class="collision" size="0.0482888 0.0818542" pos="-1.69959e-05 -0.000716252 -0.14714" quat="0.00125538 -0.202712 0.979238 0" type="cylinder" rgba="0.752941 0.752941 0.752941 1"/>
              <geom name="//unnamed_geom_13" class="reward_collision_sphere" size="0.0452808"/>
              <geom name="//unnamed_geom_14" class="reward_collision_sphere" size="0.054337" pos="0 0 -0.0926517"/>
              <body name="left_foot_pitch_link" pos="-0.000478056 -0.00192227 -0.284006" quat="1 0.000882099 0.000346201 -0.000153292">
                <inertial pos="0.00363503 -0.00172423 0.000214666" quat="0.00609182 0.706531 -0.0105694 0.707577" mass="0.0416541" diaginertia="7.2621e-06 2.54349e-06 2.3371e-06"/>
                <joint name="left_ankle_pitch_joint" class="/" pos="0 0 0" axis="0.00913248 0.999957 0.00149608" stiffness="0.00184586" range="-1.05743 0.514406" armature="0.093939" damping="0.000204826" frictionloss="0.088155"/>
                <geom name="//unnamed_geom_15" class="visual" mesh="left_foot_pitch_link"/>
                <body name="left_foot_roll_link" pos="0.000964118 -0.000408587 0.00119847" quat="1 -2.11754e-05 1.51931e-05 -5.07689e-05">
                  <inertial pos="0.0413264 -0.00167629 -0.031787" quat="-0.00198036 0.724423 -0.0012212 0.689351" mass="0.801816" diaginertia="0.00625957 0.0022532 0.000327387"/>
                  <joint name="left_ankle_roll_joint" class="/" pos="0 0 0" axis="-0.99978 -0.01788 -0.0109415" stiffness="0.000489147" range="-0.45704 0.467554" armature="0.0796353" damping="0.017899" frictionloss="0.0897194"/>
                  <geom name="//unnamed_geom_16" class="visual" mesh="left_foot_roll_link"/>
                  <geom name="left_foot" class="foot" size="0.138143 0.040749 0.00900834" pos="0.0461006 0 -0.0374818"/>
                  <geom name="//unnamed_geom_18" class="reward_collision_sphere" size="0.0452808" pos="0 0 -0.0252687"/>
                  <geom name="//unnamed_geom_19" class="reward_collision_sphere" size="0.0452808" pos="0.122935 0 -0.0252687"/>
                  <site name="left_foot" class="foot" pos="0.0461006 0 -0.0374818" size="0.00905617"/>
                </body>
              </body>
            </body>
          </body>
        </body>
      </body>
      <body name="right_thigh_roll_link" pos="-0.0355604 -0.0938113 -0.0241987" quat="0.999999 -0.00157247 0.000249524 9.4241e-05">
        <inertial pos="-0.00150938 -0.00383263 0.00275235" quat="0.0323105 0.703968 0.016799 0.709297" mass="1.09266" diaginertia="0.00292562 0.00116092 0.000712373"/>
        <joint name="right_hip_roll_joint" class="/" pos="0 0 0" axis="-0.999987 -0.00392997 -0.00335032" range="-0.0736125 0.751212" armature="0.0857418" damping="0.00540291" frictionloss="0.0887582"/>
        <geom name="//unnamed_geom_20" class="visual" mesh="right_thigh_roll_link"/>
        <body name="right_thigh_yaw_link" pos="0.0336096 -0.00436421 0.00033808" quat="1 0.000110451 -9.58463e-05 -2.06783e-05">
          <inertial pos="-0.00262 -0.0309584 -0.0922849" quat="0.685672 -0.138729 0.142118 0.700293" mass="2.59635" diaginertia="0.0263132 0.00812138 0.00375114"/>
          <joint name="right_hip_yaw_joint" class="/" pos="0 0 0" axis="0.00468039 0.00518715 -0.999976" range="-0.71138 0.648936" armature="0.0883083" damping="0.00887953" frictionloss="0.0914649"/>
          <geom name="//unnamed_geom_21" class="visual" mesh="right_thigh_yaw_link"/>
          <body name="right_thigh_pitch_link" pos="0.00127689 -0.0213281 -0.117398" quat="1 -0.000117531 -3.5666e-05 -3.5591e-05">
            <inertial pos="0.000379814 0.0202067 -0.0531692" quat="0.999805 -0.0143453 -0.0117614 0.00684343" mass="6.40155" diaginertia="0.104728 0.0412988 0.0124069"/>
            <joint name="right_hip_pitch_joint" class="/" pos="0 0 0" axis="0.0176109 -0.999625 0.0209533" range="-0.705174 1.75383" armature="0.0799123" damping="0.0243746" frictionloss="0.0876777"/>
            <geom name="//unnamed_geom_22" class="visual" mesh="right_thigh_pitch_link"/>
            <geom name="right_thigh_pitch_link.STL" class="collision" size="0.0742606 0.113121" pos="-0.0021752 0.0255031 -0.140709" quat="0.999971 0.00269833 0.00706272 0" type="cylinder" rgba="0.752941 0.752941 0.752941 1"/>
            <geom name="//unnamed_geom_24" class="reward_collision_sphere" size="0.0905617" pos="0 0.00850103 -0.0421144"/>
            <body name="right_shank_pitch_link" pos="0.000256454 0.0129194 -0.303231" quat="1 -0.000605766 -0.00060679 0.000189934">
              <inertial pos="0.00197667 0.00170584 -0.0981169" quat="0.999658 0.00477893 0.00855939 0.0242601" mass="1.25842" diaginertia="0.0115902 0.00471328 0.00050619"/>
              <joint name="right_knee_pitch_joint" class="/" pos="0 0 0" axis="-0.00124202 -0.99999 0.00426954" stiffness="0.000172517" range="-1.91436 0.0571164" armature="0.0861201" damping="0.0251002" frictionloss="0.0916721"/>
              <geom name="//unnamed_geom_25" class="visual" mesh="right_shank_pitch_link"/>
              <geom name="right_shank_pitch_link.STL" class="collision" size="0.0482885 0.0818534" pos="-1.69959e-05 -0.00071626 -0.147147" type="cylinder" rgba="0.752941 0.752941 0.752941 1"/>
              <geom name="//unnamed_geom_27" class="reward_collision_sphere" size="0.0452808"/>
              <geom name="//unnamed_geom_28" class="reward_collision_sphere" size="0.054337" pos="0 0 -0.0926517"/>
              <body name="right_foot_pitch_link" pos="-0.0011272 0.00107151 -0.284528" quat="1 0.000123514 -0.000182734 -0.000181016">
                <inertial pos="0.000926313 -0.00349491 -0.00055876" quat="-0.000365552 0.706656 -0.000825081 0.707557" mass="0.0412923" diaginertia="6.95152e-06 2.44993e-06 2.21089e-06"/>
                <joint name="right_ankle_pitch_joint" class="/" pos="0 0 0" axis="-0.00577783 -0.999983 0.000338978" range="-0.507625 1.06062" armature="0.0908791" damping="0.00616812" frictionloss="0.100769"/>
                <geom name="//unnamed_geom_29" class="visual" mesh="right_foot_pitch_link"/>
                <body name="right_foot_roll_link" pos="0.000951502 -0.00301997 -0.00072678" quat="0.999999 0.000609664 0.000882519 -0.000364912">
                  <inertial pos="0.0377236 -0.003437 -0.0350955" quat="0.000700411 0.724796 0.00144656 0.688962" mass="0.811872" diaginertia="0.00641991 0.00222786 0.000306401"/>
                  <joint name="right_ankle_roll_joint" class="/" pos="0 0 0" axis="-0.999862 0.00841715 0.0143205" range="-0.415734 0.440031" armature="0.101395" damping="0.00160699" frictionloss="0.0906704"/>
                  <geom name="//unnamed_geom_30" class="visual" mesh="right_foot_roll_link"/>
                  <geom name="right_foot" class="foot" size="0.149202 0.0407372 0.00911362" pos="0.0461006 0 -0.0374818"/>
                  <geom name="//unnamed_geom_32" class="reward_collision_sphere" size="0.0452808" pos="0 0 -0.0252687"/>
                  <geom name="//unnamed_geom_33" class="reward_collision_sphere" size="0.0452808" pos="0.122935 0 -0.0252687"/>
                  <site name="right_foot" class="foot" pos="0.0461006 0 -0.0374818" size="0.00905617"/>
                </body>
              </body>
            </body>
          </body>
        </body>
      </body>
      <body name="waist_yaw_link" pos="0.00189315 0.00285305 0.00134576" quat="1 -6.13706e-05 1.82981e-05 -2.98699e-05">
        <inertial pos="-0.0023114 -0.00681149 0.043482" quat="0.980255 0.186458 -0.0304586 0.0583535" mass="1.29195" diaginertia="0.00424892 0.00146348 0.000971853"/>
        <joint name="waist_yaw_joint" class="/" pos="0 0 0" axis="0.00483431 0.0220609 0.999745" range="-1.11289 1.0515" armature="0.0899182" damping="0.0231775" frictionloss="0.0877629"/>
        <geom name="//unnamed_geom_34" class="visual" rgba="0.12 0.12 0.12 1" mesh="waist_yaw_link"/>
        <body name="waist_pitch_link" pos="0.00199706 0.00227676 0.0776414" quat="1 0.000477546 -0.00014069 -0.000180483">
          <inertial pos="0.00336682 -0.00278809 0.0358524" quat="0.997793 -0.0460452 0.0465239 0.0111577" mass="1.14191" diaginertia="0.00528392 0.00210499 0.000759842"/>
          <joint name="waist_pitch_joint" class="/" pos="0 0 0" axis="0.0165203 -0.999837 0.00733096" range="-1.20422 0.54652" armature="0.0893466" damping="0" frictionloss="0.0916342"/>
          <geom name="//unnamed_geom_35" class="visual" rgba="0.12 0.12 0.12 1" mesh="waist_pitch_link"/>
          <body name="waist_roll_link" pos="0.00658359 -0.000219795 0.0735724" quat="0.999999 -1.33041e-05 -0.00049739 0.000980824">
            <inertial pos="-0.014594 -0.000625377 0.126719" quat="0.998743 0.00894828 -0.0490823 0.00476295" mass="4.64782" diaginertia="0.0688203 0.0249738 0.0147793"/>
            <joint name="waist_roll_joint" class="/" pos="0 0 0" axis="-0.999971 0.00651396 0.00383057" range="-0.762585 0.648418" armature="0.0886873" damping="0.0133547" frictionloss="0.0927149"/>
            <geom name="//unnamed_geom_36" class="visual" rgba="0.12 0.12 0.12 1" mesh="waist_roll_link"/>
            <geom name="//unnamed_geom_37" class="visual" pos="-0.00230503 0.000488325 0.135061" quat="1 0 0 0" mesh="torso_link"/>
            <geom name="torso_link.STL" class="collision" size="0.142569 0.0273433" pos="-0.0185078 0.00490493 0.124515" type="cylinder" rgba="0.752941 0.752941 0.752941 1"/>
            <geom name="//unnamed_geom_39" class="reward_collision_sphere" size="0.11773" pos="0 0 0.168458"/>
            <body name="left_upper_arm_pitch_link" pos="-0.00192284 0.082742 0.1746" quat="0.976895 0.213719 -8.34994e-05 -0.000814325">
              <inertial pos="0.00634434 0.0449336 -0.000346898" quat="0.7091 0.702674 0.0134922 -0.0569637" mass="0.622654" diaginertia="0.00230219 0.000872369 0.000202714"/>
              <joint name="left_shoulder_pitch_joint" class="/" pos="0 0 0" axis="-0.000491819 1 -1.4316e-05" range="-2.78569 1.93252" armature="0.102289" damping="0" frictionloss="0.0896137"/>
              <geom name="//unnamed_geom_40" class="visual" mesh="left_upper_arm_pitch_link"/>
              <body name="left_upper_arm_roll_link" pos="0.00435793 0.0771062 0.000637311" quat="0.976622 -0.214963 -4.58391e-05 -0.000198858">
                <inertial pos="0.00480056 0.0111517 -0.0204609" quat="0.885387 0.267486 0.121468 -0.36026" mass="0.451289" diaginertia="0.00112665 0.00044106 0.000146532"/>
                <joint name="left_shoulder_roll_joint" class="/" pos="0 0 0" axis="-0.999998 0.00175134 0.0012947" range="-2.50978 0.535672" armature="0.0818668" damping="0.0158669" frictionloss="0.0919032"/>
                <geom name="//unnamed_geom_41" class="visual" mesh="left_upper_arm_roll_link"/>
                <body name="left_upper_arm_yaw_link" pos="0.00383039 0.034887 -0.0573527" quat="0.999999 0.000734022 7.21402e-05 0.0010556">
                  <inertial pos="0.000234055 -0.00336595 -0.07302" quat="0.999925 0.000553241 0.0111529 -0.00512731" mass="0.403391" diaginertia="0.0042752 0.0016336 0.000113787"/>
                  <joint name="left_shoulder_yaw_joint" class="/" pos="0 0 0" axis="0.000856838 0.000248767 1" stiffness="0.000560884" range="-2.97703 3.0183" armature="0.0825918" damping="0.00236225" frictionloss="0.0788236"/>
                  <geom name="//unnamed_geom_42" class="visual" mesh="left_upper_arm_yaw_link"/>
                  <geom name="left_upper_arm_yaw_link.STL" class="collision" size="0.0328134 0.0769249" pos="4.04511e-05 -0.000760239 -0.0668272" quat="0.00803418 -0.995528 0.0941277 0" type="cylinder" rgba="0.752941 0.752941 0.752941 1"/>
                  <body name="left_lower_arm_pitch_link" pos="-0.000865837 -0.00230509 -0.152997" quat="1 -6.02061e-05 0.000104379 -0.000101016">
                    <inertial pos="-3.7475e-05 0.00551949 -0.0178033" quat="0.701447 -0.0910743 0.0906651 0.701041" mass="0.257624" diaginertia="0.000356415 0.000132744 4.09772e-05"/>
                    <joint name="left_elbow_pitch_joint" class="/" pos="0 0 0" axis="0.00135507 0.999999 0.000138786" range="-2.27591 2.32885" armature="0.105951" damping="0.00687587" frictionloss="0.0980155"/>
                    <geom name="//unnamed_geom_44" class="visual" mesh="left_lower_arm_pitch_link"/>
                    <body name="left_hand_yaw_link" pos="-0.00172554 -0.0011926 -0.0482887" quat="0.999999 -0.000246875 0.000294444 -0.00121614">
                      <inertial pos="0.00209439 0.00244063 -0.0614597" quat="0.999951 -0.00348408 -0.000500087 0.00929832" mass="0.729955" diaginertia="0.00294541 0.00114859 0.000213958"/>
                      <joint name="left_wrist_yaw_joint" class="/" pos="0 0 0" axis="-2.79547e-05 0.00148452 0.999999" range="-2.9638 2.9837" armature="0.0930762" damping="0.0206154" frictionloss="0.0911526"/>
                      <geom name="//unnamed_geom_45" class="visual" mesh="left_hand_yaw_link"/>
                      <geom name="left_hand_yaw_link.STL" class="collision" size="0.0376482 0.0630252" pos="0.00111589 -0.0013101 -0.0640501" type="cylinder" rgba="0.752941 0.752941 0.752941 1"/>
                      <geom name="//unnamed_geom_47" class="reward_collision_sphere" size="0.0452808"/>
                      <body name="left_hand_roll_link" pos="-0.00167683 0.00225679 -0.158846" quat="1 -0.000166888 -0.000413541 0.000358579">
                        <inertial pos="-0.00134297 -0.000551036 -0.000287481" quat="0.500678 0.499558 0.497394 0.502358" mass="0.00371158" diaginertia="3.89923e-07 1.50245e-07 2.91383e-08"/>
                        <joint name="left_wrist_roll_joint" class="/" pos="0 0 0" axis="-0.999994 0.00331669 -0.000492607" range="-0.942933 0.85864" armature="0.081075" damping="0.000614934" frictionloss="0.0929416"/>
                        <geom name="//unnamed_geom_48" class="visual" mesh="left_hand_roll_link"/>
                        <body name="left_hand_pitch_link" pos="0.00271897 -0.00150336 0.00116015" quat="1 -7.61173e-05 4.76506e-05 -6.65722e-05">
                          <inertial pos="0.000677354 -0.0121872 -0.0469898" quat="0.723369 -0.121241 0.114555 0.670012" mass="0.162363" diaginertia="0.000322522 0.000118068 4.10407e-05"/>
                          <joint name="left_wrist_pitch_joint" class="/" pos="0 0 0" axis="0.00498869 0.999985 0.00246824" stiffness="8.26828e-05" range="-0.567028 0.553731" armature="0.0805024" damping="0.00413817" frictionloss="0.0911877"/>
                          <geom name="//unnamed_geom_49" class="visual" mesh="left_hand_pitch"/>
                          <body name="left_jaw_link" pos="0.00254733 0.00268924 -0.0499433" quat="1 0.000594619 -0.000552242 0.000406671">
                            <inertial pos="0.000285584 0.00307947 -0.0300649" quat="0.70653 -0.0239709 0.0306368 0.706613" mass="0.0533385" diaginertia="9.00132e-05 2.47444e-05 1.42368e-05"/>
                            <joint name="left_jaw_joint" class="/" pos="0 0 0" axis="-0.999918 -0.0126902 0.00177646" stiffness="0.0001539" range="-0.953107 -0.0652591" armature="0.0914653" damping="0.00944136" frictionloss="0.0887324"/>
                            <geom name="//unnamed_geom_50" class="visual" mesh="left_jaw_link"/>
                            <geom name="//unnamed_geom_51" class="collision" size="0.0326022"/>
                            <geom name="//unnamed_geom_52" class="reward_collision_sphere" size="0.0452808" pos="0 0 -0.0168458"/>
                          </body>
                        </body>
                      </body>
                    </body>
                  </body>
                </body>
              </body>
            </body>
            <body name="right_upper_arm_pitch_link" pos="0.000838456 -0.0846328 0.174602" quat="0.976701 -0.214605 -0.000203118 6.09946e-05">
              <inertial pos="0.00121329 -0.0432436 -0.00226749" quat="0.703374 0.709954 0.029303 0.0192711" mass="0.57428" diaginertia="0.00224553 0.000856602 0.000205209"/>
              <joint name="right_shoulder_pitch_joint" class="/" pos="0 0 0" axis="-1.98692e-05 -1 0.000184384" range="-1.92236 2.74854" armature="0.0991417" damping="0.00449176" frictionloss="0.088253"/>
              <geom name="//unnamed_geom_53" class="visual" mesh="right_upper_arm_pitch_link"/>
              <body name="right_upper_arm_roll_link" pos="0.00322459 -0.0779183 0.00304542" quat="0.976829 0.214017 1.25352e-05 -0.00124319">
                <inertial pos="0.00154578 -0.0147091 -0.0194485" quat="0.888098 -0.278867 0.128525 0.342047" mass="0.465759" diaginertia="0.00119423 0.000461291 0.000157779"/>
                <joint name="right_shoulder_roll_joint" class="/" pos="0 0 0" axis="-0.999999 0.00107862 0.00028606" range="-0.536345 2.52665" armature="0.0991952" damping="0" frictionloss="0.101909"/>
                <geom name="//unnamed_geom_54" class="visual" mesh="right_upper_arm_roll_link"/>
                <body name="right_upper_arm_yaw_link" pos="0.000948769 -0.0336274 -0.0611489" quat="0.999999 4.96567e-05 -0.00116772 -0.000545866">
                  <inertial pos="-0.000186568 -0.000964691 -0.071566" quat="0.99997 0.00557635 0.00348379 0.00410349" mass="0.402698" diaginertia="0.00403254 0.00156931 0.000113298"/>
                  <joint name="right_shoulder_yaw_joint" class="/" pos="0 0 0" axis="-0.00761272 -0.00370867 0.999964" range="-2.97755 3.02315" armature="0.103465" damping="0.00323562" frictionloss="0.0926903"/>
                  <geom name="//unnamed_geom_55" class="visual" mesh="right_upper_arm_yaw_link"/>
                  <geom name="right_upper_arm_yaw_link.STL" class="collision" size="0.0328134 0.0769249" pos="4.04511e-05 0.000760239 -0.0668272" type="cylinder" rgba="0.752941 0.752941 0.752941 1"/>
                  <body name="right_lower_arm_pitch_link" pos="-0.00121375 -0.0036821 -0.151646" quat="1 -4.19816e-05 0.000173178 -0.000124886">
                    <inertial pos="-0.000302843 -0.00900448 -0.0206978" quat="0.699733 0.0929514 -0.095479 0.701867" mass="0.242564" diaginertia="0.000335728 0.000126217 4.10899e-05"/>
                    <joint name="right_elbow_pitch_joint" class="/" pos="0 0 0" axis="-0.000695822 -0.999999 -0.00110179" range="-2.27768 2.27252" armature="0.0876787" damping="0.00724709" frictionloss="0.0929261"/>
                    <geom name="//unnamed_geom_57" class="visual" mesh="right_lower_arm_pitch_link"/>
                    <body name="right_hand_yaw_link" pos="0.00126698 0.000400432 -0.0474252" quat="1 -0.000103021 -0.000271399 0.000334129">
                      <inertial pos="0.00272366 0.000284722 -0.06058" quat="0.999678 -0.00173217 0.00809664 0.023985" mass="0.732957" diaginertia="0.00298369 0.00111915 0.000207248"/>
                      <joint name="right_wrist_yaw_joint" class="/" pos="0 0 0" axis="-0.00205904 0.00482013 0.999986" range="-3.02128 3.0292" armature="0.0829156" damping="0.00388796" frictionloss="0.0802338"/>
                      <geom name="//unnamed_geom_58" class="visual" mesh="right_hand_yaw_link"/>
                      <geom name="right_hand_yaw_link.STL" class="collision" size="0.0376482 0.0630252" pos="0.00111589 0.000545013 -0.0640501" type="cylinder" rgba="0.752941 0.752941 0.752941 1"/>
                      <geom name="//unnamed_geom_60" class="reward_collision_sphere" size="0.0452808"/>
                      <body name="right_hand_roll_link" pos="-0.00205342 -2.98002e-05 -0.15812" quat="1 7.00387e-05 -2.38768e-05 -1.23604e-07">
                        <inertial pos="0.000430508 -0.00303965 0.0012749" quat="0.494549 0.49946 0.500012 0.505914" mass="0.00371928" diaginertia="3.92567e-07 1.50483e-07 3.01434e-08"/>
                        <joint name="right_wrist_roll_joint" class="/" pos="0 0 0" axis="-0.999909 -0.00852876 -0.0104711" range="-0.876672 1.01405" armature="0.104857" damping="0.00769581" frictionloss="0.0783246"/>
                        <geom name="//unnamed_geom_61" class="visual" mesh="right_hand_roll_link"/>
                        <body name="right_hand_pitch_link" pos="-0.00164405 7.25074e-06 -0.00225909" quat="0.999999 0.000409073 -0.000772579 0.00100627">
                          <inertial pos="0.00156262 0.00556003 -0.0445347" quat="0.725328 0.133752 -0.113026 0.665759" mass="0.15238" diaginertia="0.000313734 0.000111775 3.79407e-05"/>
                          <joint name="right_wrist_pitch_joint" class="/" pos="0 0 0" axis="-0.0131916 -0.999898 -0.00539654" range="-0.653323 0.670666" armature="0.080086" damping="0.00664347" frictionloss="0.0842439"/>
                          <geom name="//unnamed_geom_62" class="visual" mesh="right_hand_pitch"/>
                          <body name="right_jaw_link" pos="0.00272254 -0.00274455 -0.0487938" quat="1 2.16403e-05 7.88321e-05 0.000108074">
                            <inertial pos="0.000760585 -0.00254463 -0.0297259" quat="0.707953 0.0189811 -0.0298667 0.705372" mass="0.050126" diaginertia="8.89721e-05 2.47576e-05 1.37553e-05"/>
                            <joint name="right_jaw_joint" class="/" pos="0 0 0" axis="-0.999997 0.000906346 -0.00239588" range="-0.0440664 1.02533" armature="0.0890714" damping="0.00422654" frictionloss="0.0817502"/>
                            <geom name="//unnamed_geom_63" class="visual" mesh="right_jaw_link"/>
                            <geom name="//unnamed_geom_64" class="collision" size="0.0326022"/>
                            <geom name="//unnamed_geom_65" class="reward_collision_sphere" size="0.0452808" pos="0 0 -0.0168458"/>
                          </body>
                        </body>
                      </body>
                    </body>
                  </body>
                </body>
              </body>
            </body>
            <body name="head_roll_link" pos="-0.00274577 0.00303485 0.259664" quat="1 -1.48363e-05 7.99098e-05 -1.85008e-06">
              <inertial pos="0.00210064 -0.000449052 0.00256704" quat="-0.00429154 0.713526 -0.00217637 0.700612" mass="0.00738363" diaginertia="8.07357e-07 1.88457e-07 1.7557e-07"/>
              <joint name="head_roll_joint" class="/" pos="0 0 0" axis="-0.999906 -0.00878583 -0.010545" range="-0.409308 0.367893" armature="0.0899271" damping="0.00102577" frictionloss="0.0792821"/>
              <geom name="//unnamed_geom_66" class="visual" mesh="head_roll_link"/>
              <body name="head_pitch_link" pos="0.000678079 0.00122562 0.00187363" quat="1 0.000127351 0.00015121 -6.0099e-05">
                <inertial pos="-0.00378152 -0.00202885 0.0176324" quat="0.663597 0.6667 0.236838 -0.243018" mass="0.043068" diaginertia="2.95447e-05 1.01258e-05 6.75972e-06"/>
                <joint name="head_pitch_joint" class="/" pos="0 0 0" axis="-0.00599799 -0.999943 -0.00884559" range="-0.801355 0.880066" armature="0.0976202" damping="0.00792271" frictionloss="0.0794139"/>
                <geom name="//unnamed_geom_67" class="visual" mesh="head_pitch_link"/>
                <body name="head_yaw_link" pos="-0.000114982 -0.000947851 0.0444406" quat="1 0.000649365 0.000454886 0.000336755">
                  <inertial pos="0.0262978 -0.00150718 0.0831628" quat="0.701685 -0.128808 -0.140304 0.686558" mass="1.12887" diaginertia="0.0113026 0.003496 0.0022194"/>
                  <joint name="head_yaw_joint" class="/" pos="0 0 0" axis="-0.00396031 0.00311317 0.999987" range="-2.65492 2.7683" armature="0.104717" damping="0.000131499" frictionloss="0.0913375"/>
                  <geom name="//unnamed_geom_68" class="visual" rgba="0.12 0.12 0.12 1" mesh="head_yaw_link"/>
                  <geom name="head_yaw_link.STL" class="collision" size="0.107485" pos="0.0187282 -0.000748111 0.0788552" rgba="0.752941 0.752941 0.752941 1"/>
                  <geom name="//unnamed_geom_70" class="reward_collision_sphere" size="0.0905617" pos="0.0307338 0 0.0842289"/>
                  <camera name="ego_camera" class="/" pos="0.11269 0 0.0926517" quat="-0.5 -0.5 0.5 0.5"/>
                </body>
              </body>
            </body>
          </body>
        </body>
      </body>
    </body>
  </worldbody>

  <contact>
    <pair class="/" geom1="floor" geom2="left_foot" name="//unnamed_contact_0"/>
    <pair class="/" geom1="floor" geom2="right_foot" name="//unnamed_contact_1"/>
  </contact>

  <actuator>
    <general name="left_hip_roll" class="/" joint="left_hip_roll_joint" forcerange="-43.7303 43.7303" gainprm="108.674" biasprm="0 -108.674 -0.905617"/>
    <general name="left_hip_yaw" class="/" joint="left_hip_yaw_joint" forcerange="-56.7714 56.7714" gainprm="108.674" biasprm="0 -108.674 -0.905617"/>
    <general name="left_hip_pitch" class="/" joint="left_hip_pitch_joint" forcerange="-190.248 190.248" gainprm="108.674" biasprm="0 -108.674 -0.905617"/>
    <general name="left_knee_pitch" class="/" joint="left_knee_pitch_joint" forcerange="-199.669 199.669" gainprm="108.674" biasprm="0 -108.674 -0.905617"/>
    <general name="left_ankle_pitch" class="/" joint="left_ankle_pitch_joint" forcerange="-14.9423 14.9423" gainprm="108.674" biasprm="0 -108.674 -0.905617"/>
    <general name="left_ankle_roll" class="/" joint="left_ankle_roll_joint" forcerange="-26.9871 26.9871" gainprm="108.674" biasprm="0 -108.674 -0.905617"/>
    <general name="right_hip_roll" class="/" joint="right_hip_roll_joint" forcerange="-42.8493 42.8493" gainprm="108.674" biasprm="0 -108.674 -0.905617"/>
    <general name="right_hip_yaw" class="/" joint="right_hip_yaw_joint" forcerange="-56.2322 56.2322" gainprm="108.674" biasprm="0 -108.674 -0.905617"/>
    <general name="right_hip_pitch" class="/" joint="right_hip_pitch_joint" forcerange="-190.355 190.355" gainprm="108.674" biasprm="0 -108.674 -0.905617"/>
    <general name="right_knee_pitch" class="/" joint="right_knee_pitch_joint" forcerange="-216.404 216.404" gainprm="108.674" biasprm="0 -108.674 -0.905617"/>
    <general name="right_ankle_pitch" class="/" joint="right_ankle_pitch_joint" forcerange="-13.4849 13.4849" gainprm="108.674" biasprm="0 -108.674 -0.905617"/>
    <general name="right_ankle_roll" class="/" joint="right_ankle_roll_joint" forcerange="-27.1065 27.1065" gainprm="108.674" biasprm="0 -108.674 -0.905617"/>
    <general name="waist_yaw" class="/" joint="waist_yaw_joint" forcerange="-63.1241 63.1241" gainprm="108.674" biasprm="0 -108.674 -0.905617"/>
    <general name="waist_pitch" class="/" joint="waist_pitch_joint" forcerange="-64.692 64.692" gainprm="108.674" biasprm="0 -108.674 -0.905617"/>
    <general name="waist_roll" class="/" joint="waist_roll_joint" forcerange="-58.7765 58.7765" gainprm="108.674" biasprm="0 -108.674 -0.905617"/>
    <general name="left_shoulder_pitch" class="/" joint="left_shoulder_pitch_joint" forcerange="-34.8022 34.8022" gainprm="108.674" biasprm="0 -108.674 -0.905617"/>
    <general name="left_shoulder_roll" class="/" joint="left_shoulder_roll_joint" forcerange="-34.1935 34.1935" gainprm="108.674" biasprm="0 -108.674 -0.905617"/>
    <general name="left_shoulder_yaw" class="/" joint="left_shoulder_yaw_joint" forcerange="-26.6539 26.6539" gainprm="108.674" biasprm="0 -108.674 -0.905617"/>
    <general name="left_elbow_pitch" class="/" joint="left_elbow_pitch_joint" forcerange="-28.2678 28.2678" gainprm="108.674" biasprm="0 -108.674 -0.905617"/>
    <general name="left_wrist_yaw" class="/" joint="left_wrist_yaw_joint" forcerange="-8.86417 8.86417" gainprm="108.674" biasprm="0 -108.674 -0.905617"/>
    <general name="left_wrist_roll" class="/" joint="left_wrist_roll_joint" forcerange="-3.75014 3.75014" gainprm="108.674" biasprm="0 -108.674 -0.905617"/>
    <general name="left_wrist_pitch" class="/" joint="left_wrist_pitch_joint" forcerange="-3.61609 3.61609" gainprm="108.674" biasprm="0 -108.674 -0.905617"/>
    <general name="left_jaw" class="/" joint="left_jaw_joint" forcerange="-3.21369 3.21369" gainprm="108.674" biasprm="0 -108.674 -0.905617"/>
    <general name="right_shoulder_pitch" class="/" joint="right_shoulder_pitch_joint" forcerange="-36.258 36.258" gainprm="108.674" biasprm="0 -108.674 -0.905617"/>
    <general name="right_shoulder_roll" class="/" joint="right_shoulder_roll_joint" forcerange="-37.0598 37.0598" gainprm="108.674" biasprm="0 -108.674 -0.905617"/>
    <general name="right_shoulder_yaw" class="/" joint="right_shoulder_yaw_joint" forcerange="-25.9145 25.9145" gainprm="108.674" biasprm="0 -108.674 -0.905617"/>
    <general name="right_elbow_pitch" class="/" joint="right_elbow_pitch_joint" forcerange="-24.7185 24.7185" gainprm="108.674" biasprm="0 -108.674 -0.905617"/>
    <general name="right_wrist_yaw" class="/" joint="right_wrist_yaw_joint" forcerange="-9.2647 9.2647" gainprm="108.674" biasprm="0 -108.674 -0.905617"/>
    <general name="right_wrist_roll" class="/" joint="right_wrist_roll_joint" forcerange="-3.60368 3.60368" gainprm="108.674" biasprm="0 -108.674 -0.905617"/>
    <general name="right_wrist_pitch" class="/" joint="right_wrist_pitch_joint" forcerange="-3.57177 3.57177" gainprm="108.674" biasprm="0 -108.674 -0.905617"/>
    <general name="right_jaw" class="/" joint="right_jaw_joint" forcerange="-3.44455 3.44455" gainprm="108.674" biasprm="0 -108.674 -0.905617"/>
    <general name="head_roll" class="/" joint="head_roll_joint" forcerange="-3.57279 3.57279" gainprm="108.674" biasprm="0 -108.674 -0.905617"/>
    <general name="head_pitch" class="/" joint="head_pitch_joint" forcerange="-3.60895 3.60895" gainprm="108.674" biasprm="0 -108.674 -0.905617"/>
    <general name="head_yaw" class="/" joint="head_yaw_joint" forcerange="-3.85661 3.85661" gainprm="108.674" biasprm="0 -108.674 -0.905617"/>
  </actuator>

  <sensor>
    <gyro site="imu" name="imu_angular_velocity"/>
    <velocimeter site="imu" name="imu_linear_velocity"/>
    <framelinvel objtype="site" objname="left_foot" name="left_foot_global_linear_velocity"/>
    <framelinvel objtype="site" objname="right_foot" name="right_foot_global_linear_velocity"/>
  </sensor>

  <keyframe>
    <key name="home" qpos="0 0 0.8665 1 0 0 0 0 0 -0.4 0.8 -0.4 0 0 0 0.4 -0.8 0.4 0 0 0 0 0 -0.2 0 -0.785 0 0 0 0 0 0.2 0 0.785 0 0 0 0 0 0 0"/>
  </keyframe>
</mujoco>
