<mujoco model="GR1T2_jaw">
  <compiler angle="radian" assetdir="assets" balanceinertia="true" inertiafromgeom="false"/>

  <option timestep="0.005" density="1.2" viscosity="2e-05"/>

  <size nkey="1"/>

  <visual>
    <quality shadowsize="8192"/>
    <map shadowclip="0.5"/>
  </visual>

  <default>
    <default class="/">
      <joint armature="0.1" damping="0.01" frictionloss="0.1"/>
      <geom contype="0" conaffinity="0" group="1" solref="-1000 -80"/>
      <site size="0.01 0.005 0.005" group="5"/>
      <general forcelimited="true" biastype="affine" gainprm="80" biasprm="0 -80 -2"/>
      <default class="visual">
        <geom type="mesh" density="0" rgba="0.18 0.18 0.18 1"/>
      </default>
      <default class="collision">
        <geom group="3"/>
      </default>
      <default class="foot">
        <geom size="0.126 0.045 0.01" type="box" condim="6" group="4" priority="1" solimp="0.015 1 0.01"/>
      </default>
      <default class="reward_collision_sphere">
        <geom group="5" rgba="1 0 0 1"/>
      </default>
    </default>
  </default>

  <asset>
    <texture type="skybox" colorspace="auto" name="//unnamed_texture_0" builtin="gradient" rgb1="0.95 0.95 0.95" rgb2="0.95 0.95 0.95" width="100" height="600"/>
    <texture type="2d" colorspace="auto" name="texplane" builtin="checker" rgb1="0.345 0.575 0.748" rgb2="0.345 0.575 0.748" markrgb="1 1 1" width="512" height="512"/>
    <material name="MatPlane" class="/" texture="texplane" texuniform="true" texrepeat="2 2" specular="0.9"/>
    <mesh name="base_link" class="/" file="base_link.STL"/>
    <mesh name="left_thigh_roll_link" class="/" file="left_thigh_roll_link.STL"/>
    <mesh name="left_thigh_yaw_link" class="/" file="left_thigh_yaw_link.STL"/>
    <mesh name="left_thigh_pitch_link" class="/" file="left_thigh_pitch_link.STL"/>
    <mesh name="left_shank_pitch_link" class="/" file="left_shank_pitch_link.STL"/>
    <mesh name="left_foot_pitch_link" class="/" file="left_foot_pitch_link.STL"/>
    <mesh name="left_foot_roll_link" class="/" file="left_foot_roll_link.STL"/>
    <mesh name="right_thigh_roll_link" class="/" file="right_thigh_roll_link.STL"/>
    <mesh name="right_thigh_yaw_link" class="/" file="right_thigh_yaw_link.STL"/>
    <mesh name="right_thigh_pitch_link" class="/" file="right_thigh_pitch_link.STL"/>
    <mesh name="right_shank_pitch_link" class="/" file="right_shank_pitch_link.STL"/>
    <mesh name="right_foot_pitch_link" class="/" file="right_foot_pitch_link.STL"/>
    <mesh name="right_foot_roll_link" class="/" file="right_foot_roll_link.STL"/>
    <mesh name="waist_yaw_link" class="/" file="waist_yaw_link.STL"/>
    <mesh name="waist_pitch_link" class="/" file="waist_pitch_link.STL"/>
    <mesh name="waist_roll_link" class="/" file="waist_roll_link.STL"/>
    <mesh name="torso_link" class="/" file="torso_link.STL"/>
    <mesh name="left_upper_arm_pitch_link" class="/" file="left_upper_arm_pitch_link.STL"/>
    <mesh name="left_upper_arm_roll_link" class="/" file="left_upper_arm_roll_link.STL"/>
    <mesh name="left_upper_arm_yaw_link" class="/" file="left_upper_arm_yaw_link.STL"/>
    <mesh name="left_lower_arm_pitch_link" class="/" file="left_lower_arm_pitch_link.STL"/>
    <mesh name="left_hand_yaw_link" class="/" file="left_hand_yaw_link.STL"/>
    <mesh name="left_hand_roll_link" class="/" file="left_hand_roll_link.STL"/>
    <mesh name="left_hand_pitch" class="/" file="left_hand_pitch.STL"/>
    <mesh name="left_jaw_link" class="/" file="left_jaw_link.STL"/>
    <mesh name="right_upper_arm_pitch_link" class="/" file="right_upper_arm_pitch_link.STL"/>
    <mesh name="right_upper_arm_roll_link" class="/" file="right_upper_arm_roll_link.STL"/>
    <mesh name="right_upper_arm_yaw_link" class="/" file="right_upper_arm_yaw_link.STL"/>
    <mesh name="right_lower_arm_pitch_link" class="/" file="right_lower_arm_pitch_link.STL"/>
    <mesh name="right_hand_yaw_link" class="/" file="right_hand_yaw_link.STL"/>
    <mesh name="right_hand_roll_link" class="/" file="right_hand_roll_link.STL"/>
    <mesh name="right_hand_pitch" class="/" file="right_hand_pitch.STL"/>
    <mesh name="right_jaw_link" class="/" file="right_jaw_link.STL"/>
    <mesh name="head_roll_link" class="/" file="head_roll_link.STL"/>
    <mesh name="head_pitch_link" class="/" file="head_pitch_link.STL"/>
    <mesh name="head_yaw_link" class="/" file="head_yaw_link.STL"/>
    <mesh name="imu_link" class="/" file="imu_link.STL"/>
  </asset>

  <worldbody>
    <geom name="floor" class="/" size="100 100 0.125" type="plane" group="0" material="MatPlane"/>
    <light name="toplight_shadow" class="/" pos="0 0 5" dir="0.0990148 0.0990148 -0.990148" type="directional" ambient="0.04 0.04 0.04" diffuse="0.55 0.55 0.55" specular="0.12 0.12 0.12"/>
    <light name="toplight_fill" class="/" pos="0 0 5" dir="0.0990148 0.0990148 -0.990148" type="directional" castshadow="false" ambient="0.04 0.04 0.04" diffuse="0.3 0.3 0.3" specular="0.08 0.08 0.08"/>
    <body name="trunk" pos="0.00096024 -0.0025952 0.000964925" quat="1 3.86325e-06 -1.0193e-05 1.54368e-05">
      <inertial pos="-0.0583982 0.00371482 -0.00823175" quat="0.999989 -0.00211347 0.00284267 0.00314033" mass="2.55975" diaginertia="0.0314415 0.00491184 0.0185309"/>
      <joint name="//unnamed_joint_0" type="free"/>
      <geom name="//unnamed_geom_1" class="visual" rgba="0.12 0.12 0.12 1" mesh="base_link"/>
      <geom name="base_link.STL" class="collision" size="0.10665 0.0597326" pos="-0.0403012 0.000303852 0.00779689" quat="0.706838 -0.707359 0.00477667 0" type="cylinder" rgba="0.752941 0.752941 0.752941 1"/>
      <geom name="//unnamed_geom_3" class="visual" pos="0 0 -0.0504549" quat="1 0 0 0" rgba="0.12 0.12 0.12 1" mesh="imu_link"/>
      <geom name="//unnamed_geom_4" class="reward_collision_sphere" size="0.0697094" pos="0 0.0821127 0.0846559"/>
      <geom name="//unnamed_geom_5" class="reward_collision_sphere" size="0.0697094" pos="0 -0.0821127 0.0846559"/>
      <site name="imu" class="/" pos="0.0038486 0.00346889 -0.0537915" size="0.00871368"/>
      <camera name="track" class="/" pos="0 -1.64225 0" quat="0.707107 0.707107 0 0" mode="trackcom"/>
      <body name="left_thigh_roll_link" pos="-0.0325444 0.0886395 -0.0242975" quat="0.999999 -8.97783e-05 0.000251865 0.00107511">
        <inertial pos="0.00103597 0.0017376 0.00187805" quat="-0.0316665 0.709387 -0.0352371 0.703225" mass="0.972502" diaginertia="0.00204099 0.000931478 0.00069826"/>
        <joint name="left_hip_roll_joint" class="/" pos="0 0 0" axis="-0.999998 -0.00138184 -0.0011331" stiffness="0.00350762" range="-0.802466 0.0956722" armature="0.0949806" damping="0.0191521" frictionloss="0.0752518"/>
        <geom name="//unnamed_geom_6" class="visual" mesh="left_thigh_roll_link"/>
        <body name="left_thigh_yaw_link" pos="0.029857 -0.00274211 0.000759757" quat="1 0.000350928 -0.000128507 -0.000233446">
          <inertial pos="-0.00496593 0.033569 -0.090621" quat="0.56926 0.0852718 -0.19039 0.79525" mass="2.3465" diaginertia="0.0179218 0.00713463 0.00395583"/>
          <joint name="left_hip_yaw_joint" class="/" pos="0 0 0" axis="0.000901643 -0.000775449 -0.999999" range="-0.721907 0.648099" armature="0.0887753" damping="0.015069" frictionloss="0.0801533"/>
          <geom name="//unnamed_geom_7" class="visual" mesh="left_thigh_yaw_link"/>
          <body name="left_thigh_pitch_link" pos="0.000622738 0.0188821 -0.118762" quat="1 -8.19987e-05 -0.000286528 0.00030711">
            <inertial pos="0.000632474 -0.0221232 -0.0524369" quat="0.999812 -0.0155549 -0.00850867 0.00786361" mass="5.35485" diaginertia="0.0677896 0.0335031 0.0119077"/>
            <joint name="left_hip_pitch_joint" class="/" pos="0 0 0" axis="-0.000196671 0.999999 0.00114325" stiffness="0.00256585" range="-1.76438 0.756451" armature="0.0810323" damping="0.00276512" frictionloss="0.0871777"/>
            <geom name="//unnamed_geom_8" class="visual" mesh="left_thigh_pitch_link"/>
            <geom name="left_thigh_pitch_link.STL" class="collision" size="0.0714522 0.108846" pos="0.000662541 -0.0246338 -0.141423" type="cylinder" rgba="0.752941 0.752941 0.752941 1"/>
            <geom name="//unnamed_geom_10" class="reward_collision_sphere" size="0.0871368" pos="0 -0.00821127 -0.042328"/>
            <body name="left_shank_pitch_link" pos="0.000674433 -0.0189446 -0.305714" quat="0.999999 0.000485889 0.000334945 0.000896685">
              <inertial pos="0.00328774 -0.00118701 -0.0971425" quat="0.999742 -0.0169807 0.000984178 -0.0150303" mass="1.18131" diaginertia="0.00794409 0.00389951 0.000548153"/>
              <joint name="left_knee_pitch_joint" class="/" pos="0 0 0" axis="0.0172253 0.999831 -0.00641835" range="-0.0922438 1.97996" armature="0.0961732" damping="0.00136233" frictionloss="0.0991836"/>
              <geom name="//unnamed_geom_11" class="visual" mesh="left_shank_pitch_link"/>
              <geom name="left_shank_pitch_link.STL" class="collision" size="0.0464626 0.0787586" pos="-1.57012e-05 -0.000691838 -0.147886" quat="0.00125538 -0.202712 0.979238 0" type="cylinder" rgba="0.752941 0.752941 0.752941 1"/>
              <geom name="//unnamed_geom_13" class="reward_collision_sphere" size="0.0435684"/>
              <geom name="//unnamed_geom_14" class="reward_collision_sphere" size="0.0522821" pos="0 0 -0.0931215"/>
              <body name="left_foot_pitch_link" pos="-0.0015036 -0.000371432 -0.283908" quat="0.999999 0.000402556 0.000631931 -0.00110113">
                <inertial pos="0.00235948 -0.000440556 -0.0010481" quat="0.00783024 0.711443 0.00116415 0.7027" mass="0.0363477" diaginertia="4.78636e-06 2.09836e-06 2.36032e-06"/>
                <joint name="left_ankle_pitch_joint" class="/" pos="0 0 0" axis="0.00645002 0.99993 0.0099234" range="-1.07314 0.53843" armature="0.0898144" damping="0.00237932" frictionloss="0.0968009"/>
                <geom name="//unnamed_geom_15" class="visual" mesh="left_foot_pitch_link"/>
                <body name="left_foot_roll_link" pos="0.00277582 -0.000689759 0.000493439" quat="1 -2.44004e-05 -6.85991e-05 2.8025e-05">
                  <inertial pos="0.0359527 -0.00197716 -0.0320414" quat="-0.00200332 0.725118 -0.00385581 0.688611" mass="0.701579" diaginertia="0.00432663 0.00196197 0.000345708"/>
                  <joint name="left_ankle_roll_joint" class="/" pos="0 0 0" axis="-0.999863 -0.0165021 -0.00121673" range="-0.444304 0.419636" armature="0.0804682" damping="0.0128671" frictionloss="0.084073"/>
                  <geom name="//unnamed_geom_16" class="visual" mesh="left_foot_roll_link"/>
                  <geom name="left_foot" class="foot" size="0.147843 0.0442099 0.00942825" pos="0.0425888 0 -0.0376719"/>
                  <geom name="//unnamed_geom_18" class="reward_collision_sphere" size="0.0435684" pos="0 0 -0.0253968"/>
                  <geom name="//unnamed_geom_19" class="reward_collision_sphere" size="0.0435684" pos="0.11357 0 -0.0253968"/>
                  <site name="left_foot" class="foot" pos="0.0425888 0 -0.0376719" size="0.00871368"/>
                </body>
              </body>
            </body>
          </body>
        </body>
      </body>
      <body name="right_thigh_roll_link" pos="-0.0320416 -0.0879055 -0.0224935" quat="0.999997 -0.000209196 -0.000840306 -0.00209411">
        <inertial pos="-0.000935435 -0.000881335 5.88578e-05" quat="0.0315407 0.704966 0.0193032 0.708277" mass="0.957267" diaginertia="0.00197597 0.000972109 0.000698012"/>
        <joint name="right_hip_roll_joint" class="/" pos="0 0 0" axis="-0.99997 -0.00600369 -0.00491546" range="-0.0417002 0.781189" armature="0.0786378" damping="0.000544435" frictionloss="0.0851888"/>
        <geom name="//unnamed_geom_20" class="visual" mesh="right_thigh_roll_link"/>
        <body name="right_thigh_yaw_link" pos="0.03216 -0.000289951 0.000854502" quat="0.999999 -0.000903887 -0.000334366 -0.000593039">
          <inertial pos="-0.00292438 -0.0293729 -0.0948123" quat="0.684886 -0.147938 0.149025 0.697738" mass="2.24356" diaginertia="0.0170182 0.00667984 0.00391124"/>
          <joint name="right_hip_yaw_joint" class="/" pos="0 0 0" axis="0.00276037 -0.00170574 -0.999995" range="-0.757966 0.696" armature="0.0916638" damping="0.00717236" frictionloss="0.0867758"/>
          <geom name="//unnamed_geom_21" class="visual" mesh="right_thigh_yaw_link"/>
          <body name="right_thigh_pitch_link" pos="0.00124825 -0.0210304 -0.120479" quat="0.999999 0.000564874 -0.000421531 -0.00128191">
            <inertial pos="0.00097242 0.0200674 -0.0507684" quat="0.999937 -0.00183757 -0.00988829 0.00498313" mass="5.65232" diaginertia="0.0698292 0.032765 0.0124369"/>
            <joint name="right_hip_pitch_joint" class="/" pos="0 0 0" axis="0.012697 -0.999841 0.0125303" range="-0.69153 1.77604" armature="0.073923" damping="0.0126349" frictionloss="0.0962997"/>
            <geom name="//unnamed_geom_22" class="visual" mesh="right_thigh_pitch_link"/>
            <geom name="right_thigh_pitch_link.STL" class="collision" size="0.0714522 0.108843" pos="-0.0020095 0.0246338 -0.141423" quat="0.999971 0.00269833 0.00706272 0" type="cylinder" rgba="0.752941 0.752941 0.752941 1"/>
            <geom name="//unnamed_geom_24" class="reward_collision_sphere" size="0.0871368" pos="0 0.00821127 -0.042328"/>
            <body name="right_shank_pitch_link" pos="0.00171351 0.0163357 -0.303075" quat="1 0.000348194 -0.000466331 0.000204268">
              <inertial pos="0.00153314 0.00114897 -0.0964309" quat="0.999621 0.00656561 0.00450989 0.0263349" mass="1.13014" diaginertia="0.00834099 0.0040808 0.000523017"/>
              <joint name="right_knee_pitch_joint" class="/" pos="0 0 0" axis="0.00979752 -0.999818 0.0163624" range="-1.93723 0.0983988" armature="0.0894469" damping="0.0132744" frictionloss="0.086096"/>
              <geom name="//unnamed_geom_25" class="visual" mesh="right_shank_pitch_link"/>
              <geom name="right_shank_pitch_link.STL" class="collision" size="0.0464623 0.0787578" pos="-1.57012e-05 -0.000691846 -0.147893" type="cylinder" rgba="0.752941 0.752941 0.752941 1"/>
              <geom name="//unnamed_geom_27" class="reward_collision_sphere" size="0.0435684"/>
              <geom name="//unnamed_geom_28" class="reward_collision_sphere" size="0.0522821" pos="0 0 -0.0931215"/>
              <body name="right_foot_pitch_link" pos="-0.00340371 -0.000493332 -0.28928" quat="1 0.000118452 -0.000368899 0.000177923">
                <inertial pos="-0.000318864 -0.00435522 -0.000637654" quat="0.000278398 0.707322 -0.000172549 0.706892" mass="0.0366302" diaginertia="4.76967e-06 1.97704e-06 2.22895e-06"/>
                <joint name="right_ankle_pitch_joint" class="/" pos="0 0 0" axis="-0.0029715 -0.999863 -0.0163114" range="-0.548608 1.05453" armature="0.0990222" damping="0.000662313" frictionloss="0.0968928"/>
                <geom name="//unnamed_geom_29" class="visual" mesh="right_foot_pitch_link"/>
                <body name="right_foot_roll_link" pos="-0.000137338 -0.00391484 -0.00233434" quat="1 4.80448e-05 0.000523802 0.000279061">
                  <inertial pos="0.0357533 0.000140038 -0.0329914" quat="0.00169738 0.724132 0.00111438 0.689659" mass="0.675832" diaginertia="0.00418821 0.0018441 0.000316655"/>
                  <joint name="right_ankle_roll_joint" class="/" pos="0 0 0" axis="-1 -0.000203025 0.000835008" stiffness="0.00142391" range="-0.398191 0.395776" armature="0.0959777" damping="0.00404124" frictionloss="0.0872258"/>
                  <geom name="//unnamed_geom_30" class="visual" mesh="right_foot_roll_link"/>
                  <geom name="right_foot" class="foot" size="0.151735 0.0431568 0.00819613" pos="0.0425888 0 -0.0376719"/>
                  <geom name="//unnamed_geom_32" class="reward_collision_sphere" size="0.0435684" pos="0 0 -0.0253968"/>
                  <geom name="//unnamed_geom_33" class="reward_collision_sphere" size="0.0435684" pos="0.11357 0 -0.0253968"/>
                  <site name="right_foot" class="foot" pos="0.0425888 0 -0.0376719" size="0.00871368"/>
                </body>
              </body>
            </body>
          </body>
        </body>
      </body>
      <body name="waist_yaw_link" pos="0.00131009 0.00221813 -0.000973988" quat="1 -5.82942e-05 0.000737245 -0.000533712">
        <inertial pos="-0.00263285 -0.00423532 0.0450105" quat="0.980365 0.185467 -0.0253058 0.0620248" mass="1.0877" diaginertia="0.00282388 0.00123563 0.000961956"/>
        <joint name="waist_yaw_joint" class="/" pos="0 0 0" axis="0.00212143 -0.00833392 0.999963" range="-1.07742 1.03833" armature="0.0973052" damping="0.0180638" frictionloss="0.0964246"/>
        <geom name="//unnamed_geom_34" class="visual" rgba="0.12 0.12 0.12 1" mesh="waist_yaw_link"/>
        <body name="waist_pitch_link" pos="0.00126237 0.00375991 0.074702" quat="1 -0.000579008 -1.22385e-06 -8.16633e-06">
          <inertial pos="0.00122597 -0.00274859 0.0337886" quat="0.997974 -0.0414192 0.04804 0.0049261" mass="1.01799" diaginertia="0.00364488 0.00183553 0.000832064"/>
          <joint name="waist_pitch_joint" class="/" pos="0 0 0" axis="-0.00919351 -0.999948 0.00436468" range="-1.21049 0.498875" armature="0.0856251" damping="0.0109842" frictionloss="0.0852671"/>
          <geom name="//unnamed_geom_35" class="visual" rgba="0.12 0.12 0.12 1" mesh="waist_pitch_link"/>
          <body name="waist_roll_link" pos="0.00734847 -0.00126898 0.0708604" quat="1 2.43877e-05 1.58818e-06 9.67711e-06">
            <inertial pos="-0.010278 0.00204572 0.127702" quat="0.998599 -0.00469378 -0.0526872 0.00168718" mass="4.26974" diaginertia="0.0457747 0.0209548 0.0146072"/>
            <joint name="waist_roll_joint" class="/" pos="0 0 0" axis="-0.999892 0.0144637 -0.00276399" range="-0.688477 0.645214" armature="0.0960947" damping="0.014999" frictionloss="0.0992427"/>
            <geom name="//unnamed_geom_36" class="visual" rgba="0.12 0.12 0.12 1" mesh="waist_roll_link"/>
            <geom name="//unnamed_geom_37" class="visual" pos="-0.00212944 0.00047168 0.135746" quat="1 0 0 0" mesh="torso_link"/>
            <geom name="torso_link.STL" class="collision" size="0.137177 0.0263092" pos="-0.0170979 0.00473774 0.125146" type="cylinder" rgba="0.752941 0.752941 0.752941 1"/>
            <geom name="//unnamed_geom_39" class="reward_collision_sphere" size="0.113278" pos="0 0 0.169312"/>
            <body name="left_upper_arm_pitch_link" pos="-0.00111163 0.0798772 0.176499" quat="0.976822 0.214052 -0.000227353 -0.000149411">
              <inertial pos="0.00385448 0.0432906 -0.00270413" quat="0.703258 0.709469 -0.000987583 -0.045614" mass="0.561127" diaginertia="0.0015709 0.00076377 0.000209979"/>
              <joint name="left_shoulder_pitch_joint" class="/" pos="0 0 0" axis="0.00191289 0.999988 -0.00461265" range="-2.775 1.91676" armature="0.100534" damping="0" frictionloss="0.0885354"/>
              <geom name="//unnamed_geom_40" class="visual" mesh="left_upper_arm_pitch_link"/>
              <body name="left_upper_arm_roll_link" pos="0.00261581 0.07524 0.000346662" quat="0.976984 -0.213312 0.000160741 7.90812e-05">
                <inertial pos="0.00339547 0.0135522 -0.020492" quat="0.890634 0.27209 0.124665 -0.342341" mass="0.420567" diaginertia="0.000773528 0.000365285 0.000149049"/>
                <joint name="left_shoulder_roll_joint" class="/" pos="0 0 0" axis="-0.999853 0.00559193 0.0161853" range="-2.56126 0.528996" armature="0.0852175" damping="0.00540597" frictionloss="0.0851172"/>
                <geom name="//unnamed_geom_41" class="visual" mesh="left_upper_arm_roll_link"/>
                <body name="left_upper_arm_yaw_link" pos="0.00207705 0.0348928 -0.0573" quat="1 0.000140079 0.000134821 -0.000233886">
                  <inertial pos="-0.000942416 -0.00319557 -0.0743428" quat="0.999991 -0.000231759 -0.00319806 -0.00294023" mass="0.354619" diaginertia="0.00277531 0.00140382 0.000115053"/>
                  <joint name="left_shoulder_yaw_joint" class="/" pos="0 0 0" axis="0.00137298 -0.00455556 0.999989" range="-2.97744 3.02464" armature="0.0791515" damping="0.00218854" frictionloss="0.0793746"/>
                  <geom name="//unnamed_geom_42" class="visual" mesh="left_upper_arm_yaw_link"/>
                  <geom name="left_upper_arm_yaw_link.STL" class="collision" size="0.0315725 0.0740158" pos="3.73697e-05 -0.000734326 -0.067166" quat="0.00803418 -0.995528 0.0941277 0" type="cylinder" rgba="0.752941 0.752941 0.752941 1"/>
                  <body name="left_lower_arm_pitch_link" pos="-0.000139497 -0.00119375 -0.151806" quat="1 0.000110061 2.28973e-06 2.53569e-05">
                    <inertial pos="-0.000737303 0.00794297 -0.0197644" quat="0.699539 -0.0923646 0.0911118 0.702718" mass="0.229901" diaginertia="0.00023923 0.000115077 4.40009e-05"/>
                    <joint name="left_elbow_pitch_joint" class="/" pos="0 0 0" axis="-0.0027164 0.999824 0.0185697" range="-2.28853 2.3187" armature="0.0987849" damping="0.00441721" frictionloss="0.0988667"/>
                    <geom name="//unnamed_geom_44" class="visual" mesh="left_lower_arm_pitch_link"/>
                    <body name="left_hand_yaw_link" pos="0.0019883 -0.000191526 -0.0520861" quat="1 0.000123737 -0.000176236 -0.000148732">
                      <inertial pos="0.00295071 0.00357506 -0.061886" quat="0.99995 -0.00258259 -0.0025318 0.00936268" mass="0.672611" diaginertia="0.0019827 0.000940378 0.000224314"/>
                      <joint name="left_wrist_yaw_joint" class="/" pos="0 0 0" axis="0.00344414 -0.0016067 0.999993" stiffness="0.00498953" range="-2.97381 2.93151" armature="0.0928583" damping="0.015749" frictionloss="0.0831331"/>
                      <geom name="//unnamed_geom_45" class="visual" mesh="left_hand_yaw_link"/>
                      <geom name="left_hand_yaw_link.STL" class="collision" size="0.0362244 0.0606417" pos="0.00103089 -0.00126545 -0.0643748" type="cylinder" rgba="0.752941 0.752941 0.752941 1"/>
                      <geom name="//unnamed_geom_47" class="reward_collision_sphere" size="0.0435684"/>
                      <body name="left_hand_roll_link" pos="0.000201545 -0.000843255 -0.161753" quat="0.999999 -0.000948101 -0.000791863 -0.000479393">
                        <inertial pos="0.000140751 -0.000186898 0.00231432" quat="0.500215 0.500103 0.499648 0.500034" mass="0.00321473" diaginertia="2.48044e-07 1.23764e-07 2.84249e-08"/>
                        <joint name="left_wrist_roll_joint" class="/" pos="0 0 0" axis="-0.999996 0.000937785 0.00267932" range="-0.974164 0.875034" armature="0.0912462" damping="0.00557616" frictionloss="0.083174"/>
                        <geom name="//unnamed_geom_48" class="visual" mesh="left_hand_roll_link"/>
                        <body name="left_hand_pitch_link" pos="0.00148031 0.00214688 -0.000422244" quat="1 0.000222843 0.000147512 6.69391e-05">
                          <inertial pos="-0.00149134 -0.00791077 -0.0485137" quat="0.723348 -0.121666 0.114754 0.669923" mass="0.144186" diaginertia="0.000219961 0.000100041 4.14784e-05"/>
                          <joint name="left_wrist_pitch_joint" class="/" pos="0 0 0" axis="0.000743356 0.999999 0.000953907" range="-0.547679 0.611597" armature="0.0824035" damping="0" frictionloss="0.083099"/>
                          <geom name="//unnamed_geom_49" class="visual" mesh="left_hand_pitch"/>
                          <body name="left_jaw_link" pos="-1.69339e-05 0.000279393 -0.0530569" quat="0.999999 -0.00118723 -0.000254019 -0.000512574">
                            <inertial pos="0.000507829 0.00518661 -0.0319811" quat="0.715905 -0.0205081 0.0263769 0.697398" mass="0.0470734" diaginertia="5.9606e-05 2.08956e-05 1.43054e-05"/>
                            <joint name="left_jaw_joint" class="/" pos="0 0 0" axis="-0.999995 -0.00310443 0.000845226" range="-0.936426 -0.03462" armature="0.0992143" damping="0.00684274" frictionloss="0.0848092"/>
                            <geom name="//unnamed_geom_50" class="visual" mesh="left_jaw_link"/>
                            <geom name="//unnamed_geom_51" class="collision" size="0.0313693"/>
                            <geom name="//unnamed_geom_52" class="reward_collision_sphere" size="0.0435684" pos="0 0 -0.0169312"/>
                          </body>
                        </body>
                      </body>
                    </body>
                  </body>
                </body>
              </body>
            </body>
            <body name="right_upper_arm_pitch_link" pos="0.000725724 -0.0823537 0.172472" quat="0.976525 -0.215402 -9.07407e-05 -0.000799797">
              <inertial pos="0.000432704 -0.0427177 -0.0025768" quat="0.707338 0.70578 0.0264083 0.0291691" mass="0.513119" diaginertia="0.00146535 0.000742188 0.000203832"/>
              <joint name="right_shoulder_pitch_joint" class="/" pos="0 0 0" axis="-0.00897935 -0.999933 0.00725358" range="-1.86544 2.76049" armature="0.10108" damping="0" frictionloss="0.0914294"/>
              <geom name="//unnamed_geom_53" class="visual" mesh="right_upper_arm_pitch_link"/>
              <body name="right_upper_arm_roll_link" pos="0.00154241 -0.0767089 0.0016622" quat="0.97659 0.215107 0.000233587 -0.000140076">
                <inertial pos="0.0030732 -0.012154 -0.0180435" quat="0.888378 -0.269008 0.125151 0.350366" mass="0.419415" diaginertia="0.0008313 0.000375046 0.000155779"/>
                <joint name="right_shoulder_roll_joint" class="/" pos="0 0 0" axis="-0.999975 0.00479075 0.00517097" range="-0.522677 2.56041" armature="0.102293" damping="0" frictionloss="0.0843581"/>
                <geom name="//unnamed_geom_54" class="visual" mesh="right_upper_arm_roll_link"/>
                <body name="right_upper_arm_yaw_link" pos="0.000520347 -0.0331181 -0.06197" quat="1 0.000298363 -4.07807e-05 6.27197e-06">
                  <inertial pos="-0.00291753 -0.0010175 -0.0734396" quat="0.999913 -0.013027 -0.00202136 -0.000857758" mass="0.360193" diaginertia="0.00269285 0.00137486 0.000113762"/>
                  <joint name="right_shoulder_yaw_joint" class="/" pos="0 0 0" axis="0.00580729 0.00426682 0.999974" range="-2.9618 3.02799" armature="0.0842821" damping="0" frictionloss="0.0826861"/>
                  <geom name="//unnamed_geom_55" class="visual" mesh="right_upper_arm_yaw_link"/>
                  <geom name="right_upper_arm_yaw_link.STL" class="collision" size="0.0315725 0.0740158" pos="3.73697e-05 0.000734326 -0.067166" type="cylinder" rgba="0.752941 0.752941 0.752941 1"/>
                  <body name="right_lower_arm_pitch_link" pos="-0.00187389 -0.00103365 -0.153202" quat="0.999999 -0.000485219 -0.000391282 -0.00081715">
                    <inertial pos="0.00053191 -0.00955537 -0.0236275" quat="0.700657 0.0916594 -0.0912296 0.70168" mass="0.221683" diaginertia="0.000236233 0.000109421 4.38605e-05"/>
                    <joint name="right_elbow_pitch_joint" class="/" pos="0 0 0" axis="0.000829616 -1 0.000481504" range="-2.25142 2.27622" armature="0.0767681" damping="0.00982607" frictionloss="0.0835468"/>
                    <geom name="//unnamed_geom_57" class="visual" mesh="right_lower_arm_pitch_link"/>
                    <body name="right_hand_yaw_link" pos="0.000560454 -0.00142083 -0.0496083" quat="1 -1.19834e-05 6.09241e-05 0.000108962">
                      <inertial pos="0.000644109 -0.00173701 -0.0615742" quat="0.999429 -0.00338618 -0.00213358 0.0335406" mass="0.684278" diaginertia="0.00203866 0.000948446 0.000210919"/>
                      <joint name="right_wrist_yaw_joint" class="/" pos="0 0 0" axis="-0.00829511 -0.00398487 0.999958" range="-3.00667 2.9999" armature="0.0801555" damping="0.00249874" frictionloss="0.0773819"/>
                      <geom name="//unnamed_geom_58" class="visual" mesh="right_hand_yaw_link"/>
                      <geom name="right_hand_yaw_link.STL" class="collision" size="0.0362244 0.0606417" pos="0.00103089 0.000526436 -0.0643748" type="cylinder" rgba="0.752941 0.752941 0.752941 1"/>
                      <geom name="//unnamed_geom_60" class="reward_collision_sphere" size="0.0435684"/>
                      <body name="right_hand_roll_link" pos="-0.000856744 -0.00165744 -0.161433" quat="1 -2.1766e-05 -0.000180558 -8.97822e-05">
                        <inertial pos="-0.00161657 -0.00124573 -0.000946306" quat="0.488934 0.506904 0.500438 0.503541" mass="0.00331219" diaginertia="2.64207e-07 1.28379e-07 2.98325e-08"/>
                        <joint name="right_wrist_roll_joint" class="/" pos="0 0 0" axis="-0.999996 -0.00179838 0.00237844" range="-0.866966 0.953529" armature="0.0865956" damping="0" frictionloss="0.0861162"/>
                        <geom name="//unnamed_geom_61" class="visual" mesh="right_hand_roll_link"/>
                        <body name="right_hand_pitch_link" pos="-0.0020066 -0.000963945 0.000828726" quat="1 -3.19494e-05 -1.68331e-05 6.99836e-05">
                          <inertial pos="-0.00121647 0.00604032 -0.0456371" quat="0.719024 0.12304 -0.118125 0.673731" mass="0.142489" diaginertia="0.000213886 9.59514e-05 3.84873e-05"/>
                          <joint name="right_wrist_pitch_joint" class="/" pos="0 0 0" axis="-0.00642751 -0.999903 -0.0123799" range="-0.668541 0.6257" armature="0.0810666" damping="0" frictionloss="0.0750904"/>
                          <geom name="//unnamed_geom_62" class="visual" mesh="right_hand_pitch"/>
                          <body name="right_jaw_link" pos="0.00115033 0.000313166 -0.0498658" quat="1 0.000138293 -1.83165e-05 0.000140962">
                            <inertial pos="0.00183519 -0.00301566 -0.0289764" quat="0.706613 0.0229433 -0.0346713 0.706378" mass="0.0454907" diaginertia="6.11341e-05 2.15608e-05 1.41189e-05"/>
                            <joint name="right_jaw_joint" class="/" pos="0 0 0" axis="-0.999952 0.00663591 -0.00714309" range="-0.0482216 0.979265" armature="0.0969648" damping="0.000886276" frictionloss="0.0760739"/>
                            <geom name="//unnamed_geom_63" class="visual" mesh="right_jaw_link"/>
                            <geom name="//unnamed_geom_64" class="collision" size="0.0313693"/>
                            <geom name="//unnamed_geom_65" class="reward_collision_sphere" size="0.0435684" pos="0 0 -0.0169312"/>
                          </body>
                        </body>
                      </body>
                    </body>
                  </body>
                </body>
              </body>
            </body>
            <body name="head_roll_link" pos="-0.000730879 0.0034092 0.259788" quat="1 -0.000245037 -0.000231548 0.000148619">
              <inertial pos="0.00167748 -0.00127828 0.000136473" quat="0.011334 0.706736 -0.00462952 0.707371" mass="0.00639934" diaginertia="5.53825e-07 1.60992e-07 1.85527e-07"/>
              <joint name="head_roll_joint" class="/" pos="0 0 0" axis="-0.999996 0.00120696 0.00266878" range="-0.36994 0.348755" armature="0.0900749" damping="0" frictionloss="0.0902054"/>
              <geom name="//unnamed_geom_66" class="visual" mesh="head_roll_link"/>
              <body name="head_pitch_link" pos="-0.00177704 0.000729625 0.00126313" quat="1 6.04938e-05 4.76939e-05 -0.000112096">
                <inertial pos="-0.00292855 -0.00300141 0.0154587" quat="0.66762 0.660201 0.241712 -0.244937" mass="0.0399198" diaginertia="2.0088e-05 8.82099e-06 7.36953e-06"/>
                <joint name="head_pitch_joint" class="/" pos="0 0 0" axis="0.00166145 -0.999994 0.00304053" range="-0.827433 0.827176" armature="0.0863618" damping="0.00400224" frictionloss="0.0908043"/>
                <geom name="//unnamed_geom_67" class="visual" mesh="head_pitch_link"/>
                <body name="head_yaw_link" pos="0.000599878 -0.00282334 0.0458057" quat="0.999999 -0.000595734 0.000924757 0.000540923">
                  <inertial pos="0.0223747 0.000256595 0.0813753" quat="0.703781 -0.130485 -0.153841 0.681174" mass="1.04229" diaginertia="0.00791114 0.00294078 0.00242476"/>
                  <joint name="head_yaw_joint" class="/" pos="0 0 0" axis="0.00684306 -0.00424914 0.999968" range="-2.70603 2.75284" armature="0.0926215" damping="0.0164316" frictionloss="0.0899824"/>
                  <geom name="//unnamed_geom_68" class="visual" rgba="0.12 0.12 0.12 1" mesh="head_yaw_link"/>
                  <geom name="head_yaw_link.STL" class="collision" size="0.10342" pos="0.0173016 -0.000722612 0.079255" rgba="0.752941 0.752941 0.752941 1"/>
                  <geom name="//unnamed_geom_70" class="reward_collision_sphere" size="0.0871368" pos="0.0283925 0 0.0846559"/>
                  <camera name="ego_camera" class="/" pos="0.104106 0 0.0931215" quat="-0.5 -0.5 0.5 0.5"/>
                </body>
              </body>
            </body>
          </body>
        </body>
      </body>
    </body>
  </worldbody>

  <contact>
    <pair class="/" geom1="floor" geom2="left_foot" name="//unnamed_contact_0"/>
    <pair class="/" geom1="floor" geom2="right_foot" name="//unnamed_contact_1"/>
  </contact>

  <actuator>
    <general name="left_hip_roll" class="/" joint="left_hip_roll_joint" forcerange="-43.9599 43.9599" gainprm="95.8928" biasprm="0 -95.8928 -0.871368"/>
    <general name="left_hip_yaw" class="/" joint="left_hip_yaw_joint" forcerange="-57.9116 57.9116" gainprm="95.8928" biasprm="0 -95.8928 -0.871368"/>
    <general name="left_hip_pitch" class="/" joint="left_hip_pitch_joint" forcerange="-190.61 190.61" gainprm="95.8928" biasprm="0 -95.8928 -0.871368"/>
    <general name="left_knee_pitch" class="/" joint="left_knee_pitch_joint" forcerange="-206.177 206.177" gainprm="95.8928" biasprm="0 -95.8928 -0.871368"/>
    <general name="left_ankle_pitch" class="/" joint="left_ankle_pitch_joint" forcerange="-13.2678 13.2678" gainprm="95.8928" biasprm="0 -95.8928 -0.871368"/>
    <general name="left_ankle_roll" class="/" joint="left_ankle_roll_joint" forcerange="-26.0253 26.0253" gainprm="95.8928" biasprm="0 -95.8928 -0.871368"/>
    <general name="right_hip_roll" class="/" joint="right_hip_roll_joint" forcerange="-40.8198 40.8198" gainprm="95.8928" biasprm="0 -95.8928 -0.871368"/>
    <general name="right_hip_yaw" class="/" joint="right_hip_yaw_joint" forcerange="-51.4158 51.4158" gainprm="95.8928" biasprm="0 -95.8928 -0.871368"/>
    <general name="right_hip_pitch" class="/" joint="right_hip_pitch_joint" forcerange="-193.834 193.834" gainprm="95.8928" biasprm="0 -95.8928 -0.871368"/>
    <general name="right_knee_pitch" class="/" joint="right_knee_pitch_joint" forcerange="-192.219 192.219" gainprm="95.8928" biasprm="0 -95.8928 -0.871368"/>
    <general name="right_ankle_pitch" class="/" joint="right_ankle_pitch_joint" forcerange="-13.2158 13.2158" gainprm="95.8928" biasprm="0 -95.8928 -0.871368"/>
    <general name="right_ankle_roll" class="/" joint="right_ankle_roll_joint" forcerange="-26.5901 26.5901" gainprm="95.8928" biasprm="0 -95.8928 -0.871368"/>
    <general name="waist_yaw" class="/" joint="waist_yaw_joint" forcerange="-62.9911 62.9911" gainprm="95.8928" biasprm="0 -95.8928 -0.871368"/>
    <general name="waist_pitch" class="/" joint="waist_pitch_joint" forcerange="-55.5934 55.5934" gainprm="95.8928" biasprm="0 -95.8928 -0.871368"/>
    <general name="waist_roll" class="/" joint="waist_roll_joint" forcerange="-57.9907 57.9907" gainprm="95.8928" biasprm="0 -95.8928 -0.871368"/>
    <general name="left_shoulder_pitch" class="/" joint="left_shoulder_pitch_joint" forcerange="-31.7119 31.7119" gainprm="95.8928" biasprm="0 -95.8928 -0.871368"/>
    <general name="left_shoulder_roll" class="/" joint="left_shoulder_roll_joint" forcerange="-29.8072 29.8072" gainprm="95.8928" biasprm="0 -95.8928 -0.871368"/>
    <general name="left_shoulder_yaw" class="/" joint="left_shoulder_yaw_joint" forcerange="-25.4221 25.4221" gainprm="95.8928" biasprm="0 -95.8928 -0.871368"/>
    <general name="left_elbow_pitch" class="/" joint="left_elbow_pitch_joint" forcerange="-25.0589 25.0589" gainprm="95.8928" biasprm="0 -95.8928 -0.871368"/>
    <general name="left_wrist_yaw" class="/" joint="left_wrist_yaw_joint" forcerange="-8.96924 8.96924" gainprm="95.8928" biasprm="0 -95.8928 -0.871368"/>
    <general name="left_wrist_roll" class="/" joint="left_wrist_roll_joint" forcerange="-3.80191 3.80191" gainprm="95.8928" biasprm="0 -95.8928 -0.871368"/>
    <general name="left_wrist_pitch" class="/" joint="left_wrist_pitch_joint" forcerange="-3.37818 3.37818" gainprm="95.8928" biasprm="0 -95.8928 -0.871368"/>
    <general name="left_jaw" class="/" joint="left_jaw_joint" forcerange="-3.2831 3.2831" gainprm="95.8928" biasprm="0 -95.8928 -0.871368"/>
    <general name="right_shoulder_pitch" class="/" joint="right_shoulder_pitch_joint" forcerange="-36.6494 36.6494" gainprm="95.8928" biasprm="0 -95.8928 -0.871368"/>
    <general name="right_shoulder_roll" class="/" joint="right_shoulder_roll_joint" forcerange="-36.1265 36.1265" gainprm="95.8928" biasprm="0 -95.8928 -0.871368"/>
    <general name="right_shoulder_yaw" class="/" joint="right_shoulder_yaw_joint" forcerange="-26.7177 26.7177" gainprm="95.8928" biasprm="0 -95.8928 -0.871368"/>
    <general name="right_elbow_pitch" class="/" joint="right_elbow_pitch_joint" forcerange="-23.8031 23.8031" gainprm="95.8928" biasprm="0 -95.8928 -0.871368"/>
    <general name="right_wrist_yaw" class="/" joint="right_wrist_yaw_joint" forcerange="-8.89761 8.89761" gainprm="95.8928" biasprm="0 -95.8928 -0.871368"/>
    <general name="right_wrist_roll" class="/" joint="right_wrist_roll_joint" forcerange="-3.32181 3.32181" gainprm="95.8928" biasprm="0 -95.8928 -0.871368"/>
    <general name="right_wrist_pitch" class="/" joint="right_wrist_pitch_joint" forcerange="-3.33251 3.33251" gainprm="95.8928" biasprm="0 -95.8928 -0.871368"/>
    <general name="right_jaw" class="/" joint="right_jaw_joint" forcerange="-3.49551 3.49551" gainprm="95.8928" biasprm="0 -95.8928 -0.871368"/>
    <general name="head_roll" class="/" joint="head_roll_joint" forcerange="-3.39237 3.39237" gainprm="95.8928" biasprm="0 -95.8928 -0.871368"/>
    <general name="head_pitch" class="/" joint="head_pitch_joint" forcerange="-3.35198 3.35198" gainprm="95.8928" biasprm="0 -95.8928 -0.871368"/>
    <general name="head_yaw" class="/" joint="head_yaw_joint" forcerange="-3.75522 3.75522" gainprm="95.8928" biasprm="0 -95.8928 -0.871368"/>
  </actuator>

  <sensor>
    <gyro site="imu" name="imu_angular_velocity"/>
    <velocimeter site="imu" name="imu_linear_velocity"/>
    <framelinvel objtype="site" objname="left_foot" name="left_foot_global_linear_velocity"/>
    <framelinvel objtype="site" objname="right_foot" name="right_foot_global_linear_velocity"/>
  </sensor>

  <keyframe>
    <key name="home" qpos="0 0 0.8665 1 0 0 0 0 0 -0.4 0.8 -0.4 0 0 0 0.4 -0.8 0.4 0 0 0 0 0 -0.2 0 -0.785 0 0 0 0 0 0.2 0 0.785 0 0 0 0 0 0 0"/>
  </keyframe>
</mujoco>
