<mujoco model="GR1T2_jaw">
  <compiler angle="radian" assetdir="assets" balanceinertia="true" inertiafromgeom="false"/>

  <option timestep="0.005" density="1.2" viscosity="2e-05"/>

  <size nkey="1"/>

  <visual>
    <quality shadowsize="8192"/>
    <map shadowclip="0.5"/>
  </visual>

  <default>
    <default class="/">
      <joint armature="0.1" damping="0.01" frictionloss="0.1"/>
      <geom contype="0" conaffinity="0" group="1" solref="-1000 -80"/>
      <site size="0.01 0.005 0.005" group="5"/>
      <general forcelimited="true" biastype="affine" gainprm="80" biasprm="0 -80 -2"/>
      <default class="visual">
        <geom type="mesh" density="0" rgba="0.18 0.18 0.18 1"/>
      </default>
      <default class="collision">
        <geom group="3"/>
      </default>
      <default class="foot">
        <geom size="0.126 0.045 0.01" type="box" condim="6" group="4" priority="1" solimp="0.015 1 0.01"/>
      </default>
      <default class="reward_collision_sphere">
        <geom group="5" rgba="1 0 0 1"/>
      </default>
    </default>
  </default>

  <asset>
    <texture type="skybox" colorspace="auto" name="//unnamed_texture_0" builtin="gradient" rgb1="0.95 0.95 0.95" rgb2="0.95 0.95 0.95" width="100" height="600"/>
    <texture type="2d" colorspace="auto" name="texplane" builtin="checker" rgb1="0.345 0.575 0.748" rgb2="0.345 0.575 0.748" markrgb="1 1 1" width="512" height="512"/>
    <material name="MatPlane" class="/" texture="texplane" texuniform="true" texrepeat="2 2" specular="0.9"/>
    <mesh name="base_link" class="/" file="base_link.STL"/>
    <mesh name="left_thigh_roll_link" class="/" file="left_thigh_roll_link.STL"/>
    <mesh name="left_thigh_yaw_link" class="/" file="left_thigh_yaw_link.STL"/>
    <mesh name="left_thigh_pitch_link" class="/" file="left_thigh_pitch_link.STL"/>
    <mesh name="left_shank_pitch_link" class="/" file="left_shank_pitch_link.STL"/>
    <mesh name="left_foot_pitch_link" class="/" file="left_foot_pitch_link.STL"/>
    <mesh name="left_foot_roll_link" class="/" file="left_foot_roll_link.STL"/>
    <mesh name="right_thigh_roll_link" class="/" file="right_thigh_roll_link.STL"/>
    <mesh name="right_thigh_yaw_link" class="/" file="right_thigh_yaw_link.STL"/>
    <mesh name="right_thigh_pitch_link" class="/" file="right_thigh_pitch_link.STL"/>
    <mesh name="right_shank_pitch_link" class="/" file="right_shank_pitch_link.STL"/>
    <mesh name="right_foot_pitch_link" class="/" file="right_foot_pitch_link.STL"/>
    <mesh name="right_foot_roll_link" class="/" file="right_foot_roll_link.STL"/>
    <mesh name="waist_yaw_link" class="/" file="waist_yaw_link.STL"/>
    <mesh name="waist_pitch_link" class="/" file="waist_pitch_link.STL"/>
    <mesh name="waist_roll_link" class="/" file="waist_roll_link.STL"/>
    <mesh name="torso_link" class="/" file="torso_link.STL"/>
    <mesh name="left_upper_arm_pitch_link" class="/" file="left_upper_arm_pitch_link.STL"/>
    <mesh name="left_upper_arm_roll_link" class="/" file="left_upper_arm_roll_link.STL"/>
    <mesh name="left_upper_arm_yaw_link" class="/" file="left_upper_arm_yaw_link.STL"/>
    <mesh name="left_lower_arm_pitch_link" class="/" file="left_lower_arm_pitch_link.STL"/>
    <mesh name="left_hand_yaw_link" class="/" file="left_hand_yaw_link.STL"/>
    <mesh name="left_hand_roll_link" class="/" file="left_hand_roll_link.STL"/>
    <mesh name="left_hand_pitch" class="/" file="left_hand_pitch.STL"/>
    <mesh name="left_jaw_link" class="/" file="left_jaw_link.STL"/>
    <mesh name="right_upper_arm_pitch_link" class="/" file="right_upper_arm_pitch_link.STL"/>
    <mesh name="right_upper_arm_roll_link" class="/" file="right_upper_arm_roll_link.STL"/>
    <mesh name="right_upper_arm_yaw_link" class="/" file="right_upper_arm_yaw_link.STL"/>
    <mesh name="right_lower_arm_pitch_link" class="/" file="right_lower_arm_pitch_link.STL"/>
    <mesh name="right_hand_yaw_link" class="/" file="right_hand_yaw_link.STL"/>
    <mesh name="right_hand_roll_link" class="/" file="right_hand_roll_link.STL"/>
    <mesh name="right_hand_pitch" class="/" file="right_hand_pitch.STL"/>
    <mesh name="right_jaw_link" class="/" file="right_jaw_link.STL"/>
    <mesh name="head_roll_link" class="/" file="head_roll_link.STL"/>
    <mesh name="head_pitch_link" class="/" file="head_pitch_link.STL"/>
    <mesh name="head_yaw_link" class="/" file="head_yaw_link.STL"/>
    <mesh name="imu_link" class="/" file="imu_link.STL"/>
  </asset>

  <worldbody>
    <geom name="floor" class="/" size="100 100 0.125" type="plane" group="0" material="MatPlane"/>
    <light name="toplight_shadow" class="/" pos="0 0 5" dir="0.0990148 0.0990148 -0.990148" type="directional" ambient="0.04 0.04 0.04" diffuse="0.55 0.55 0.55" specular="0.12 0.12 0.12"/>
    <light name="toplight_fill" class="/" pos="0 0 5" dir="0.0990148 0.0990148 -0.990148" type="directional" castshadow="false" ambient="0.04 0.04 0.04" diffuse="0.3 0.3 0.3" specular="0.08 0.08 0.08"/>
    <body name="trunk" pos="-0.000483529 -0.00135854 -0.000520027" quat="1 -0.000118352 0.000204547 2.11886e-05">
      <inertial pos="-0.0640577 0.00298348 -0.00981818" quat="0.999996 -0.0011989 1.70624e-05 -0.002558" mass="3.02856" diaginertia="0.0533189 0.00630235 0.01868"/>
      <joint name="//unnamed_joint_0" type="free"/>
      <geom name="//unnamed_geom_1" class="visual" rgba="0.12 0.12 0.12 1" mesh="base_link"/>
      <geom name="base_link.STL" class="collision" size="0.112418 0.0629628" pos="-0.0447979 0.00031737 0.00778983" quat="0.706838 -0.707359 0.00477667 0" type="cylinder" rgba="0.752941 0.752941 0.752941 1"/>
      <geom name="//unnamed_geom_3" class="visual" pos="0 0 -0.0504092" quat="1 0 0 0" rgba="0.12 0.12 0.12 1" mesh="imu_link"/>
      <geom name="//unnamed_geom_4" class="reward_collision_sphere" size="0.0734791" pos="0 0.0857659 0.0845793"/>
      <geom name="//unnamed_geom_5" class="reward_collision_sphere" size="0.0734791" pos="0 -0.0857659 0.0845793"/>
      <site name="imu" class="/" pos="-0.0130277 -0.00127 -0.0461115" size="0.00918489"/>
      <camera name="track" class="/" pos="0 -1.71532 0" quat="0.707107 0.707107 0 0" mode="trackcom"/>
      <body name="left_thigh_roll_link" pos="-0.0389372 0.0891943 -0.0223698" quat="1 -1.10821e-06 -1.01621e-05 -0.000262422">
        <inertial pos="-0.000381314 0.000716506 0.0023476" quat="-0.0342156 0.707041 -0.034943 0.705479" mass="1.10348" diaginertia="0.00323234 0.00111603 0.000651401"/>
        <joint name="left_hip_roll_joint" class="/" pos="0 0 0" axis="-0.999993 -0.00328767 0.00159099" range="-0.789933 0.151489" armature="0.086602" damping="0.00966428" frictionloss="0.0922334"/>
        <geom name="//unnamed_geom_6" class="visual" mesh="left_thigh_roll_link"/>
        <body name="left_thigh_yaw_link" pos="0.0298521 5.84058e-05 0.00350499" quat="1 -4.083e-05 0.000198931 -0.000641766">
          <inertial pos="-0.00560248 0.03359 -0.0927254" quat="0.571001 0.0985397 -0.19529 0.791271" mass="2.64738" diaginertia="0.0310719 0.00892899 0.00372206"/>
          <joint name="left_hip_yaw_joint" class="/" pos="0 0 0" axis="0.00493771 -0.00424303 -0.999979" range="-0.710745 0.701346" armature="0.092732" damping="0" frictionloss="0.0809321"/>
          <geom name="//unnamed_geom_7" class="visual" mesh="left_thigh_yaw_link"/>
          <body name="left_thigh_pitch_link" pos="-0.00136867 0.0194202 -0.117987" quat="1 -0.000214373 -0.000179129 -0.000148981">
            <inertial pos="9.64661e-05 -0.0258382 -0.0538945" quat="0.999784 -0.0159591 -0.0109802 0.0074682" mass="6.35987" diaginertia="0.118905 0.0433781 0.0125055"/>
            <joint name="left_hip_pitch_joint" class="/" pos="0 0 0" axis="0.000280372 1 -0.000378817" range="-1.75022 0.706493" armature="0.091459" damping="0.01176" frictionloss="0.0905737"/>
            <geom name="//unnamed_geom_8" class="visual" mesh="left_thigh_pitch_link"/>
            <geom name="left_thigh_pitch_link.STL" class="collision" size="0.0753161 0.114732" pos="0.000736465 -0.0257298 -0.141295" type="cylinder" rgba="0.752941 0.752941 0.752941 1"/>
            <geom name="//unnamed_geom_10" class="reward_collision_sphere" size="0.0918489" pos="0 -0.00857659 -0.0422896"/>
            <body name="left_shank_pitch_link" pos="-0.00148916 -0.0187312 -0.302959" quat="1 0.000499905 7.36821e-05 0.000207074">
              <inertial pos="0.00404755 -0.00149865 -0.096503" quat="0.999818 -0.00789651 0.00943536 -0.0145724" mass="1.396" diaginertia="0.0136635 0.00479171 0.000539422"/>
              <joint name="left_knee_pitch_joint" class="/" pos="0 0 0" axis="0.00575968 0.999981 0.0021236" stiffness="0.000672485" range="-0.0943822 1.94162" armature="0.0873941" damping="0" frictionloss="0.0962182"/>
              <geom name="//unnamed_geom_11" class="visual" mesh="left_shank_pitch_link"/>
              <geom name="left_shank_pitch_link.STL" class="collision" size="0.0489751 0.0830176" pos="-1.7453e-05 -0.000722618 -0.147752" quat="0.00125538 -0.202712 0.979238 0" type="cylinder" rgba="0.752941 0.752941 0.752941 1"/>
              <geom name="//unnamed_geom_13" class="reward_collision_sphere" size="0.0459245"/>
              <geom name="//unnamed_geom_14" class="reward_collision_sphere" size="0.0551094" pos="0 0 -0.0930372"/>
              <body name="left_foot_pitch_link" pos="-0.000158968 -0.00212517 -0.285606" quat="1 0.000277146 -0.00011898 0.000657391">
                <inertial pos="0.0034006 -0.00142285 0.000268528" quat="-0.00400863 0.712527 0.00572703 0.70161" mass="0.0435891" diaginertia="8.29123e-06 2.65598e-06 2.36732e-06"/>
                <joint name="left_ankle_pitch_joint" class="/" pos="0 0 0" axis="-0.00394433 0.999976 0.00572072" range="-1.06228 0.520217" armature="0.0937463" damping="0.000985432" frictionloss="0.0879118"/>
                <geom name="//unnamed_geom_15" class="visual" mesh="left_foot_pitch_link"/>
                <body name="left_foot_roll_link" pos="0.000568634 -0.000571305 0.00143123" quat="1 1.56253e-05 9.63331e-06 1.43701e-05">
                  <inertial pos="0.0423264 -0.0013156 -0.0323161" quat="-0.000931187 0.724814 -0.00112129 0.688943" mass="0.838202" diaginertia="0.00711781 0.00234106 0.000331355"/>
                  <joint name="left_ankle_roll_joint" class="/" pos="0 0 0" axis="-0.999814 -0.0109274 0.0158767" range="-0.454848 0.469568" armature="0.0821882" damping="0.0166722" frictionloss="0.092612"/>
                  <geom name="//unnamed_geom_16" class="visual" mesh="left_foot_roll_link"/>
                  <geom name="left_foot" class="foot" size="0.140735 0.0418695 0.00906163" pos="0.0473407 0 -0.0376378"/>
                  <geom name="//unnamed_geom_18" class="reward_collision_sphere" size="0.0459245" pos="0 0 -0.0253738"/>
                  <geom name="//unnamed_geom_19" class="reward_collision_sphere" size="0.0459245" pos="0.126242 0 -0.0253738"/>
                  <site name="left_foot" class="foot" pos="0.0473407 0 -0.0376378" size="0.00918489"/>
                </body>
              </body>
            </body>
          </body>
        </body>
      </body>
      <body name="right_thigh_roll_link" pos="-0.0362889 -0.0949519 -0.0247556" quat="0.999999 -0.000146305 0.000886935 -0.00100826">
        <inertial pos="-0.00115119 -0.00390977 0.00299611" quat="0.0226535 0.705521 0.0182368 0.708092" mass="1.1435" diaginertia="0.00333925 0.0012046 0.000724981"/>
        <joint name="right_hip_roll_joint" class="/" pos="0 0 0" axis="-0.999979 0.000185325 0.00652404" range="-0.0841384 0.75509" armature="0.0856402" damping="0.00761745" frictionloss="0.0917094"/>
        <geom name="//unnamed_geom_20" class="visual" mesh="right_thigh_roll_link"/>
        <body name="right_thigh_yaw_link" pos="0.0340285 -0.00473134 -0.000150952" quat="1 1.54767e-05 -0.000142173 -5.03735e-06">
          <inertial pos="-0.00301439 -0.0317063 -0.092799" quat="0.681635 -0.146863 0.141191 0.70276" mass="2.72139" diaginertia="0.0303381 0.00859598 0.00382679"/>
          <joint name="right_hip_yaw_joint" class="/" pos="0 0 0" axis="0.00495308 -0.00205907 -0.999986" range="-0.702083 0.649724" armature="0.0897353" damping="0.00871439" frictionloss="0.0923296"/>
          <geom name="//unnamed_geom_21" class="visual" mesh="right_thigh_yaw_link"/>
          <body name="right_thigh_pitch_link" pos="0.000791123 -0.0215508 -0.117698" quat="1 -6.88255e-05 -5.51625e-05 7.0039e-05">
            <inertial pos="0.00066019 0.0207404 -0.0538558" quat="0.999809 -0.0151069 -0.0102887 0.00696047" mass="6.65101" diaginertia="0.119839 0.0431829 0.0126054"/>
            <joint name="right_hip_pitch_joint" class="/" pos="0 0 0" axis="0.00551501 -0.999651 0.0258438" range="-0.698082 1.74925" armature="0.0830843" damping="0.0263519" frictionloss="0.0876573"/>
            <geom name="//unnamed_geom_22" class="visual" mesh="right_thigh_pitch_link"/>
            <geom name="right_thigh_pitch_link.STL" class="collision" size="0.0753161 0.114729" pos="-0.00223371 0.0257298 -0.141295" quat="0.999971 0.00269833 0.00706272 0" type="cylinder" rgba="0.752941 0.752941 0.752941 1"/>
            <geom name="//unnamed_geom_24" class="reward_collision_sphere" size="0.0918489" pos="0 0.00857659 -0.0422896"/>
            <body name="right_shank_pitch_link" pos="-0.000227217 0.0127345 -0.304648" quat="1 0.000470457 0.000665417 0.000439883">
              <inertial pos="0.00171212 0.00137917 -0.0984413" quat="0.999703 0.00501112 0.00710345 0.0227873" mass="1.31985" diaginertia="0.0132186 0.00490183 0.000519502"/>
              <joint name="right_knee_pitch_joint" class="/" pos="0 0 0" axis="0.00315149 -0.999992 -0.00263097" range="-1.91885 0.0586749" armature="0.0875516" damping="0.0247409" frictionloss="0.0934139"/>
              <geom name="//unnamed_geom_25" class="visual" mesh="right_shank_pitch_link"/>
              <geom name="right_shank_pitch_link.STL" class="collision" size="0.0489749 0.0830168" pos="-1.7453e-05 -0.000722627 -0.147759" type="cylinder" rgba="0.752941 0.752941 0.752941 1"/>
              <geom name="//unnamed_geom_27" class="reward_collision_sphere" size="0.0459245"/>
              <geom name="//unnamed_geom_28" class="reward_collision_sphere" size="0.0551094" pos="0 0 -0.0930372"/>
              <body name="right_foot_pitch_link" pos="-0.000610137 0.000561566 -0.285699" quat="1 1.48485e-05 -0.000140761 -0.000334573">
                <inertial pos="0.000692995 -0.0029556 -0.000194919" quat="0.00021181 0.706884 0.000348002 0.707329" mass="0.0433817" diaginertia="7.97383e-06 2.57613e-06 2.26889e-06"/>
                <joint name="right_ankle_pitch_joint" class="/" pos="0 0 0" axis="0.00117733 -0.999996 0.00274691" range="-0.508361 1.05738" armature="0.0901773" damping="0.0068219" frictionloss="0.100298"/>
                <geom name="//unnamed_geom_29" class="visual" mesh="right_foot_pitch_link"/>
                <body name="right_foot_roll_link" pos="0.000587552 -0.0025394 -0.000274902" quat="0.999999 -0.000904424 0.000403657 -0.000161427">
                  <inertial pos="0.0389036 -0.00363794 -0.0351725" quat="9.93982e-05 0.725078 0.00125458 0.688666" mass="0.854183" diaginertia="0.00734614 0.00235188 0.000314786"/>
                  <joint name="right_ankle_roll_joint" class="/" pos="0 0 0" axis="-0.999852 0.00669889 -0.0158547" range="-0.425964 0.449688" armature="0.101183" damping="0.00327626" frictionloss="0.0929933"/>
                  <geom name="//unnamed_geom_30" class="visual" mesh="right_foot_roll_link"/>
                  <geom name="right_foot" class="foot" size="0.149705 0.0403408 0.00935547" pos="0.0473407 0 -0.0376378"/>
                  <geom name="//unnamed_geom_32" class="reward_collision_sphere" size="0.0459245" pos="0 0 -0.0253738"/>
                  <geom name="//unnamed_geom_33" class="reward_collision_sphere" size="0.0459245" pos="0.126242 0 -0.0253738"/>
                  <site name="right_foot" class="foot" pos="0.0473407 0 -0.0376378" size="0.00918489"/>
                </body>
              </body>
            </body>
          </body>
        </body>
      </body>
      <body name="waist_yaw_link" pos="0.0021778 0.00290316 0.00183956" quat="1 -3.8545e-05 -7.03259e-05 4.92774e-05">
        <inertial pos="-0.00261692 -0.00730998 0.0435845" quat="0.979807 0.189261 -0.0299579 0.05711" mass="1.34631" diaginertia="0.00481804 0.00152878 0.000987559"/>
        <joint name="waist_yaw_joint" class="/" pos="0 0 0" axis="0.0136206 0.018227 0.999741" range="-1.10962 1.04451" armature="0.0903319" damping="0.0213065" frictionloss="0.0876652"/>
        <geom name="//unnamed_geom_34" class="visual" rgba="0.12 0.12 0.12 1" mesh="waist_yaw_link"/>
        <body name="waist_pitch_link" pos="0.00227369 0.00204231 0.078081" quat="1 -0.000129435 -0.000137892 -0.00060351">
          <inertial pos="0.00402453 -0.00258839 0.0362818" quat="0.997715 -0.0436197 0.0508916 0.00844418" mass="1.19152" diaginertia="0.00601226 0.00217199 0.000769101"/>
          <joint name="waist_pitch_joint" class="/" pos="0 0 0" axis="0.00538773 -0.999789 -0.0198397" range="-1.21194 0.545267" armature="0.0913468" damping="0" frictionloss="0.0929822"/>
          <geom name="//unnamed_geom_35" class="visual" rgba="0.12 0.12 0.12 1" mesh="waist_pitch_link"/>
          <body name="waist_roll_link" pos="0.00685872 0.00035132 0.0739158" quat="1 8.12352e-05 -0.000357747 0.00091925">
            <inertial pos="-0.0154163 -0.000730922 0.126721" quat="0.999077 -0.0121597 -0.0411918 -0.000158112" mass="4.87345" diaginertia="0.0788344 0.0263865 0.0151949"/>
            <joint name="waist_roll_joint" class="/" pos="0 0 0" axis="-0.999993 0.00129822 -0.00348934" range="-0.767864 0.655842" armature="0.0896612" damping="0.0141933" frictionloss="0.0916886"/>
            <geom name="//unnamed_geom_36" class="visual" rgba="0.12 0.12 0.12 1" mesh="waist_roll_link"/>
            <geom name="//unnamed_geom_37" class="visual" pos="-0.00236704 0.000492665 0.135623" quat="1 0 0 0" mesh="torso_link"/>
            <geom name="torso_link.STL" class="collision" size="0.144595 0.0277319" pos="-0.0190056 0.00494852 0.125033" type="cylinder" rgba="0.752941 0.752941 0.752941 1"/>
            <geom name="//unnamed_geom_39" class="reward_collision_sphere" size="0.119404" pos="0 0 0.169159"/>
            <body name="left_upper_arm_pitch_link" pos="-0.00189518 0.0839692 0.174972" quat="0.976481 0.215601 0.000421533 -0.0005503">
              <inertial pos="0.00636274 0.0454906 0.000148592" quat="0.702045 0.710747 -0.0026771 -0.0443119" mass="0.64535" diaginertia="0.00263375 0.000906895 0.000207803"/>
              <joint name="left_shoulder_pitch_joint" class="/" pos="0 0 0" axis="-0.00126267 0.999999 -0.000173009" range="-2.79292 1.92672" armature="0.101573" damping="0" frictionloss="0.092168"/>
              <geom name="//unnamed_geom_40" class="visual" mesh="left_upper_arm_pitch_link"/>
              <body name="left_upper_arm_roll_link" pos="0.00416356 0.0781654 0.000585486" quat="0.976673 -0.214732 -7.41191e-05 5.53298e-05">
                <inertial pos="0.00525988 0.0112214 -0.0201897" quat="0.884539 0.280065 0.125183 -0.351403" mass="0.466709" diaginertia="0.00128738 0.000462357 0.000150069"/>
                <joint name="left_shoulder_roll_joint" class="/" pos="0 0 0" axis="-1 -0.000159293 0.000306781" range="-2.50737 0.544527" armature="0.0839474" damping="0.0149862" frictionloss="0.0919475"/>
                <geom name="//unnamed_geom_41" class="visual" mesh="left_upper_arm_roll_link"/>
                <body name="left_upper_arm_yaw_link" pos="0.00363111 0.0347254 -0.0580948" quat="0.999999 -0.00113289 0.000366123 -0.000311925">
                  <inertial pos="0.000468964 -0.00296212 -0.073629" quat="0.999905 0.0133795 -0.0028403 0.00195648" mass="0.421563" diaginertia="0.00485969 0.001689 0.000115355"/>
                  <joint name="left_shoulder_yaw_joint" class="/" pos="0 0 0" axis="0.00013722 0.000587702 1" range="-2.96971 3.00914" armature="0.0857267" damping="0.00238827" frictionloss="0.0813608"/>
                  <geom name="//unnamed_geom_42" class="visual" mesh="left_upper_arm_yaw_link"/>
                  <geom name="left_upper_arm_yaw_link.STL" class="collision" size="0.0332798 0.0780183" pos="4.15393e-05 -0.000766996 -0.0671052" quat="0.00803418 -0.995528 0.0941277 0" type="cylinder" rgba="0.752941 0.752941 0.752941 1"/>
                  <body name="left_lower_arm_pitch_link" pos="-0.000716583 -0.00197587 -0.153547" quat="1 -2.38345e-05 1.50484e-06 1.81202e-05">
                    <inertial pos="6.79929e-05 0.00519902 -0.0180281" quat="0.701225 -0.0917242 0.0914589 0.701074" mass="0.266242" diaginertia="0.000403465 0.000138262 4.15976e-05"/>
                    <joint name="left_elbow_pitch_joint" class="/" pos="0 0 0" axis="-0.000943421 0.999999 -0.000539322" range="-2.26922 2.32173" armature="0.105953" damping="0.00538221" frictionloss="0.0970503"/>
                    <geom name="//unnamed_geom_44" class="visual" mesh="left_lower_arm_pitch_link"/>
                    <body name="left_hand_yaw_link" pos="-0.00197602 -0.000798992 -0.0485108" quat="0.999999 -0.000552462 0.00119924 -0.000100834">
                      <inertial pos="0.00158754 0.00192989 -0.0618362" quat="0.999955 -0.0037038 -0.00143283 0.0086295" mass="0.757569" diaginertia="0.00337239 0.0011971 0.00021657"/>
                      <joint name="left_wrist_yaw_joint" class="/" pos="0 0 0" axis="0.000147813 0.000239545 1" range="-2.96811 2.9908" armature="0.0958779" damping="0.0191005" frictionloss="0.0937162"/>
                      <geom name="//unnamed_geom_45" class="visual" mesh="left_hand_yaw_link"/>
                      <geom name="left_hand_yaw_link.STL" class="collision" size="0.0381833 0.0639211" pos="0.00114591 -0.00132175 -0.0643165" type="cylinder" rgba="0.752941 0.752941 0.752941 1"/>
                      <geom name="//unnamed_geom_47" class="reward_collision_sphere" size="0.0459245"/>
                      <body name="left_hand_roll_link" pos="-0.00140367 0.00248301 -0.159584" quat="1 -2.66624e-05 0.000271348 0.000138658">
                        <inertial pos="-0.001048 -0.000356314 -0.000649196" quat="0.499633 0.499531 0.501622 0.49921" mass="0.00390312" diaginertia="4.50846e-07 1.5853e-07 3.01209e-08"/>
                        <joint name="left_wrist_roll_joint" class="/" pos="0 0 0" axis="-0.999998 0.000717044 -0.00185239" range="-0.940744 0.861209" armature="0.081833" damping="0.000279898" frictionloss="0.0937594"/>
                        <geom name="//unnamed_geom_48" class="visual" mesh="left_hand_roll_link"/>
                        <body name="left_hand_pitch_link" pos="0.00239579 -0.00163518 0.000784556" quat="1 -3.09147e-06 1.83314e-06 3.00004e-06">
                          <inertial pos="0.000579412 -0.0124692 -0.0466104" quat="0.723246 -0.121529 0.115005 0.670014" mass="0.168983" diaginertia="0.00036932 0.000124103 4.18434e-05"/>
                          <joint name="left_wrist_pitch_joint" class="/" pos="0 0 0" axis="0.00126822 0.999991 0.00399949" range="-0.577453 0.552702" armature="0.082913" damping="0.00580115" frictionloss="0.093727"/>
                          <geom name="//unnamed_geom_49" class="visual" mesh="left_hand_pitch"/>
                          <body name="left_jaw_link" pos="0.00250884 0.00271368 -0.0498415" quat="1 9.71712e-06 8.70304e-05 0.000652906">
                            <inertial pos="0.000530994 0.0027847 -0.0296816" quat="0.707963 -0.0242442 0.0335391 0.705036" mass="0.0554285" diaginertia="0.000103021 2.58548e-05 1.44547e-05"/>
                            <joint name="left_jaw_joint" class="/" pos="0 0 0" axis="-0.999909 -0.00547747 -0.0123174" range="-0.96193 -0.0616206" armature="0.0912579" damping="0.0117304" frictionloss="0.091692"/>
                            <geom name="//unnamed_geom_50" class="visual" mesh="left_jaw_link"/>
                            <geom name="//unnamed_geom_51" class="collision" size="0.0330656"/>
                            <geom name="//unnamed_geom_52" class="reward_collision_sphere" size="0.0459245" pos="0 0 -0.0169159"/>
                          </body>
                        </body>
                      </body>
                    </body>
                  </body>
                </body>
              </body>
            </body>
            <body name="right_upper_arm_pitch_link" pos="0.000623465 -0.0849946 0.175824" quat="0.97668 -0.214699 -0.000165027 -0.00025978">
              <inertial pos="0.00176578 -0.0439255 -0.00180715" quat="0.70884 0.704285 0.0310332 0.023778" mass="0.605335" diaginertia="0.00259297 0.000894443 0.000211772"/>
              <joint name="right_shoulder_pitch_joint" class="/" pos="0 0 0" axis="0.00146988 -0.999998 0.00167528" range="-1.93103 2.75526" armature="0.0981623" damping="0.00447265" frictionloss="0.0891949"/>
              <geom name="//unnamed_geom_53" class="visual" mesh="right_upper_arm_pitch_link"/>
              <body name="right_upper_arm_roll_link" pos="0.00371545 -0.0787525 0.00286243" quat="0.976491 0.215557 -0.00086935 0.000596001">
                <inertial pos="0.00181079 -0.0153407 -0.0200494" quat="0.892491 -0.270675 0.11601 0.341667" mass="0.481431" diaginertia="0.00134961 0.000481326 0.000160492"/>
                <joint name="right_shoulder_roll_joint" class="/" pos="0 0 0" axis="-0.999999 0.00146695 -0.000814872" range="-0.546086 2.52763" armature="0.098229" damping="0" frictionloss="0.103903"/>
                <geom name="//unnamed_geom_54" class="visual" mesh="right_upper_arm_roll_link"/>
                <body name="right_upper_arm_yaw_link" pos="0.00147023 -0.0334325 -0.0609151" quat="0.999999 -0.000988846 0.000699437 -0.000264334">
                  <inertial pos="0.000195093 -0.00049994 -0.0720598" quat="0.99997 0.00324343 0.00697297 0.00132284" mass="0.418849" diaginertia="0.00461954 0.001633 0.000115824"/>
                  <joint name="right_shoulder_yaw_joint" class="/" pos="0 0 0" axis="0.00663266 0.000247599 0.999978" stiffness="0.00158676" range="-2.97155 3.01414" armature="0.105789" damping="0.00277943" frictionloss="0.0943228"/>
                  <geom name="//unnamed_geom_55" class="visual" mesh="right_upper_arm_yaw_link"/>
                  <geom name="right_upper_arm_yaw_link.STL" class="collision" size="0.0332798 0.0780183" pos="4.15393e-05 0.000766996 -0.0671052" type="cylinder" rgba="0.752941 0.752941 0.752941 1"/>
                  <body name="right_lower_arm_pitch_link" pos="-0.000592825 -0.00361136 -0.151757" quat="1 0.000375492 -2.32089e-05 -3.47371e-05">
                    <inertial pos="-0.000690511 -0.00856345 -0.020461" quat="0.701936 0.0931517 -0.0891509 0.700472" mass="0.2546" diaginertia="0.000382923 0.000132699 4.20934e-05"/>
                    <joint name="right_elbow_pitch_joint" class="/" pos="0 0 0" axis="0.000463591 -1 0.000240864" range="-2.27434 2.27435" armature="0.0914525" damping="0.00734756" frictionloss="0.0934736"/>
                    <geom name="//unnamed_geom_57" class="visual" mesh="right_lower_arm_pitch_link"/>
                    <body name="right_hand_yaw_link" pos="0.0018247 0.000655375 -0.0478014" quat="1 -4.81615e-05 -0.000251213 -1.83995e-05">
                      <inertial pos="0.0026424 0.00018344 -0.0606941" quat="0.999786 -0.000833631 0.00469885 0.0201117" mass="0.76122" diaginertia="0.0034001 0.00116812 0.000213366"/>
                      <joint name="right_wrist_yaw_joint" class="/" pos="0 0 0" axis="-0.00640296 0.000441764 0.999979" range="-3.01492 3.02509" armature="0.0860229" damping="0.00590985" frictionloss="0.0832641"/>
                      <geom name="//unnamed_geom_58" class="visual" mesh="right_hand_yaw_link"/>
                      <geom name="right_hand_yaw_link.STL" class="collision" size="0.0381833 0.0639211" pos="0.00114591 0.000549857 -0.0643165" type="cylinder" rgba="0.752941 0.752941 0.752941 1"/>
                      <geom name="//unnamed_geom_60" class="reward_collision_sphere" size="0.0459245"/>
                      <body name="right_hand_roll_link" pos="-0.00170863 0.000272044 -0.158845" quat="1 -5.27004e-06 1.19305e-05 -1.92307e-06">
                        <inertial pos="0.000372725 -0.00288534 0.00125742" quat="0.503704 0.501359 0.49658 0.498327" mass="0.00387699" diaginertia="4.48697e-07 1.57096e-07 3.0667e-08"/>
                        <joint name="right_wrist_roll_joint" class="/" pos="0 0 0" axis="-0.999916 0.0105348 -0.00761501" range="-0.872171 1.0161" armature="0.107054" damping="0.0105688" frictionloss="0.0795375"/>
                        <geom name="//unnamed_geom_61" class="visual" mesh="right_hand_roll_link"/>
                        <body name="right_hand_pitch_link" pos="-0.00109648 7.9778e-05 -0.00240549" quat="0.999999 0.000692356 -0.00116893 6.85601e-05">
                          <inertial pos="0.00155168 0.00596878 -0.0448537" quat="0.719877 0.112601 -0.121148 0.674107" mass="0.159396" diaginertia="0.000360469 0.000117764 3.91647e-05"/>
                          <joint name="right_wrist_pitch_joint" class="/" pos="0 0 0" axis="-0.0121692 -0.999924 -0.00171009" range="-0.643175 0.669271" armature="0.0825961" damping="0.00915619" frictionloss="0.0878682"/>
                          <geom name="//unnamed_geom_62" class="visual" mesh="right_hand_pitch"/>
                          <body name="right_jaw_link" pos="0.00262556 -0.00262453 -0.0493538" quat="1 -4.44185e-05 9.18905e-05 -9.1968e-05">
                            <inertial pos="0.000289749 -0.00280369 -0.0295292" quat="0.707929 0.0196209 -0.0294562 0.705396" mass="0.0525344" diaginertia="0.000101805 2.57858e-05 1.40433e-05"/>
                            <joint name="right_jaw_joint" class="/" pos="0 0 0" axis="-0.999993 0.00066364 0.0036645" range="-0.0352541 1.02719" armature="0.0895462" damping="0.00467549" frictionloss="0.0851103"/>
                            <geom name="//unnamed_geom_63" class="visual" mesh="right_jaw_link"/>
                            <geom name="//unnamed_geom_64" class="collision" size="0.0330656"/>
                            <geom name="//unnamed_geom_65" class="reward_collision_sphere" size="0.0459245" pos="0 0 -0.0169159"/>
                          </body>
                        </body>
                      </body>
                    </body>
                  </body>
                </body>
              </body>
            </body>
            <body name="head_roll_link" pos="-0.00265489 0.00257809 0.260504" quat="1 -3.59372e-05 -6.01225e-06 -9.03062e-06">
              <inertial pos="0.00266038 -0.000532111 0.00254156" quat="-0.00608914 0.71014 -0.00295373 0.704028" mass="0.00776024" diaginertia="9.20645e-07 1.97979e-07 1.79726e-07"/>
              <joint name="head_roll_joint" class="/" pos="0 0 0" axis="-0.999895 0.00308168 -0.0141561" range="-0.406867 0.363709" armature="0.0926702" damping="0" frictionloss="0.0798138"/>
              <geom name="//unnamed_geom_66" class="visual" mesh="head_roll_link"/>
              <body name="head_pitch_link" pos="0.000664066 0.000769809 0.00202053" quat="1 -0.000161923 -7.28639e-05 -2.58421e-05">
                <inertial pos="-0.00353152 -0.00150941 0.0176354" quat="0.66481 0.667015 0.237228 -0.238416" mass="0.0450029" diaginertia="3.36772e-05 1.05652e-05 6.90733e-06"/>
                <joint name="head_pitch_joint" class="/" pos="0 0 0" axis="0.00727483 -0.999953 0.00635938" range="-0.806109 0.885298" armature="0.0980898" damping="0.00787835" frictionloss="0.0798415"/>
                <geom name="//unnamed_geom_67" class="visual" mesh="head_pitch_link"/>
                <body name="head_yaw_link" pos="-0.000101306 -0.00038751 0.0445019" quat="1 0.00014133 0.000433402 -0.000413688">
                  <inertial pos="0.0275939 -0.00203733 0.0834296" quat="0.708842 -0.141444 -0.141336 0.676433" mass="1.18012" diaginertia="0.0128499 0.0036627 0.00224515"/>
                  <joint name="head_yaw_joint" class="/" pos="0 0 0" axis="-0.00541825 -0.00340595 0.99998" range="-2.65509 2.76195" armature="0.105582" damping="0" frictionloss="0.09101"/>
                  <geom name="//unnamed_geom_68" class="visual" rgba="0.12 0.12 0.12 1" mesh="head_yaw_link"/>
                  <geom name="head_yaw_link.STL" class="collision" size="0.109013" pos="0.019232 -0.000754761 0.0791833" rgba="0.752941 0.752941 0.752941 1"/>
                  <geom name="//unnamed_geom_70" class="reward_collision_sphere" size="0.0918489" pos="0.0315605 0 0.0845793"/>
                  <camera name="ego_camera" class="/" pos="0.115722 0 0.0930372" quat="-0.5 -0.5 0.5 0.5"/>
                </body>
              </body>
            </body>
          </body>
        </body>
      </body>
    </body>
  </worldbody>

  <contact>
    <pair class="/" geom1="floor" geom2="left_foot" name="//unnamed_contact_0"/>
    <pair class="/" geom1="floor" geom2="right_foot" name="//unnamed_contact_1"/>
  </contact>

  <actuator>
    <general name="left_hip_roll" class="/" joint="left_hip_roll_joint" forcerange="-44.6379 44.6379" gainprm="110.219" biasprm="0 -110.219 -0.918489"/>
    <general name="left_hip_yaw" class="/" joint="left_hip_yaw_joint" forcerange="-58.1015 58.1015" gainprm="110.219" biasprm="0 -110.219 -0.918489"/>
    <general name="left_hip_pitch" class="/" joint="left_hip_pitch_joint" forcerange="-195.155 195.155" gainprm="110.219" biasprm="0 -110.219 -0.918489"/>
    <general name="left_knee_pitch" class="/" joint="left_knee_pitch_joint" forcerange="-201.85 201.85" gainprm="110.219" biasprm="0 -110.219 -0.918489"/>
    <general name="left_ankle_pitch" class="/" joint="left_ankle_pitch_joint" forcerange="-15.1226 15.1226" gainprm="110.219" biasprm="0 -110.219 -0.918489"/>
    <general name="left_ankle_roll" class="/" joint="left_ankle_roll_joint" forcerange="-27.383 27.383" gainprm="110.219" biasprm="0 -110.219 -0.918489"/>
    <general name="right_hip_roll" class="/" joint="right_hip_roll_joint" forcerange="-43.5644 43.5644" gainprm="110.219" biasprm="0 -110.219 -0.918489"/>
    <general name="right_hip_yaw" class="/" joint="right_hip_yaw_joint" forcerange="-58.2453 58.2453" gainprm="110.219" biasprm="0 -110.219 -0.918489"/>
    <general name="right_hip_pitch" class="/" joint="right_hip_pitch_joint" forcerange="-194.837 194.837" gainprm="110.219" biasprm="0 -110.219 -0.918489"/>
    <general name="right_knee_pitch" class="/" joint="right_knee_pitch_joint" forcerange="-218.139 218.139" gainprm="110.219" biasprm="0 -110.219 -0.918489"/>
    <general name="right_ankle_pitch" class="/" joint="right_ankle_pitch_joint" forcerange="-13.8157 13.8157" gainprm="110.219" biasprm="0 -110.219 -0.918489"/>
    <general name="right_ankle_roll" class="/" joint="right_ankle_roll_joint" forcerange="-27.7164 27.7164" gainprm="110.219" biasprm="0 -110.219 -0.918489"/>
    <general name="waist_yaw" class="/" joint="waist_yaw_joint" forcerange="-62.8948 62.8948" gainprm="110.219" biasprm="0 -110.219 -0.918489"/>
    <general name="waist_pitch" class="/" joint="waist_pitch_joint" forcerange="-66.0113 66.0113" gainprm="110.219" biasprm="0 -110.219 -0.918489"/>
    <general name="waist_roll" class="/" joint="waist_roll_joint" forcerange="-60.3619 60.3619" gainprm="110.219" biasprm="0 -110.219 -0.918489"/>
    <general name="left_shoulder_pitch" class="/" joint="left_shoulder_pitch_joint" forcerange="-35.0725 35.0725" gainprm="110.219" biasprm="0 -110.219 -0.918489"/>
    <general name="left_shoulder_roll" class="/" joint="left_shoulder_roll_joint" forcerange="-35.2478 35.2478" gainprm="110.219" biasprm="0 -110.219 -0.918489"/>
    <general name="left_shoulder_yaw" class="/" joint="left_shoulder_yaw_joint" forcerange="-27.4187 27.4187" gainprm="110.219" biasprm="0 -110.219 -0.918489"/>
    <general name="left_elbow_pitch" class="/" joint="left_elbow_pitch_joint" forcerange="-28.6187 28.6187" gainprm="110.219" biasprm="0 -110.219 -0.918489"/>
    <general name="left_wrist_yaw" class="/" joint="left_wrist_yaw_joint" forcerange="-9.08093 9.08093" gainprm="110.219" biasprm="0 -110.219 -0.918489"/>
    <general name="left_wrist_roll" class="/" joint="left_wrist_roll_joint" forcerange="-3.73079 3.73079" gainprm="110.219" biasprm="0 -110.219 -0.918489"/>
    <general name="left_wrist_pitch" class="/" joint="left_wrist_pitch_joint" forcerange="-3.64151 3.64151" gainprm="110.219" biasprm="0 -110.219 -0.918489"/>
    <general name="left_jaw" class="/" joint="left_jaw_joint" forcerange="-3.28699 3.28699" gainprm="110.219" biasprm="0 -110.219 -0.918489"/>
    <general name="right_shoulder_pitch" class="/" joint="right_shoulder_pitch_joint" forcerange="-36.0873 36.0873" gainprm="110.219" biasprm="0 -110.219 -0.918489"/>
    <general name="right_shoulder_roll" class="/" joint="right_shoulder_roll_joint" forcerange="-36.9792 36.9792" gainprm="110.219" biasprm="0 -110.219 -0.918489"/>
    <general name="right_shoulder_yaw" class="/" joint="right_shoulder_yaw_joint" forcerange="-26.462 26.462" gainprm="110.219" biasprm="0 -110.219 -0.918489"/>
    <general name="right_elbow_pitch" class="/" joint="right_elbow_pitch_joint" forcerange="-25.5052 25.5052" gainprm="110.219" biasprm="0 -110.219 -0.918489"/>
    <general name="right_wrist_yaw" class="/" joint="right_wrist_yaw_joint" forcerange="-9.40986 9.40986" gainprm="110.219" biasprm="0 -110.219 -0.918489"/>
    <general name="right_wrist_roll" class="/" joint="right_wrist_roll_joint" forcerange="-3.68911 3.68911" gainprm="110.219" biasprm="0 -110.219 -0.918489"/>
    <general name="right_wrist_pitch" class="/" joint="right_wrist_pitch_joint" forcerange="-3.66711 3.66711" gainprm="110.219" biasprm="0 -110.219 -0.918489"/>
    <general name="right_jaw" class="/" joint="right_jaw_joint" forcerange="-3.52676 3.52676" gainprm="110.219" biasprm="0 -110.219 -0.918489"/>
    <general name="head_roll" class="/" joint="head_roll_joint" forcerange="-3.5992 3.5992" gainprm="110.219" biasprm="0 -110.219 -0.918489"/>
    <general name="head_pitch" class="/" joint="head_pitch_joint" forcerange="-3.62463 3.62463" gainprm="110.219" biasprm="0 -110.219 -0.918489"/>
    <general name="head_yaw" class="/" joint="head_yaw_joint" forcerange="-3.84957 3.84957" gainprm="110.219" biasprm="0 -110.219 -0.918489"/>
  </actuator>

  <sensor>
    <gyro site="imu" name="imu_angular_velocity"/>
    <velocimeter site="imu" name="imu_linear_velocity"/>
    <framelinvel objtype="site" objname="left_foot" name="left_foot_global_linear_velocity"/>
    <framelinvel objtype="site" objname="right_foot" name="right_foot_global_linear_velocity"/>
  </sensor>

  <keyframe>
    <key name="home" qpos="0 0 0.8665 1 0 0 0 0 0 -0.4 0.8 -0.4 0 0 0 0.4 -0.8 0.4 0 0 0 0 0 -0.2 0 -0.785 0 0 0 0 0 0.2 0 0.785 0 0 0 0 0 0 0"/>
  </keyframe>
</mujoco>
