<mujoco model="GR1T2_jaw">
  <compiler angle="radian" assetdir="assets" balanceinertia="true" inertiafromgeom="false"/>

  <option timestep="0.005" density="1.2" viscosity="2e-05"/>

  <size nkey="1"/>

  <visual>
    <quality shadowsize="8192"/>
    <map shadowclip="0.5"/>
  </visual>

  <default>
    <default class="/">
      <joint armature="0.1" damping="0.01" frictionloss="0.1"/>
      <geom contype="0" conaffinity="0" group="1" solref="-1000 -80"/>
      <site size="0.01 0.005 0.005" group="5"/>
      <general forcelimited="true" biastype="affine" gainprm="80" biasprm="0 -80 -2"/>
      <default class="visual">
        <geom type="mesh" density="0" rgba="0.18 0.18 0.18 1"/>
      </default>
      <default class="collision">
        <geom group="3"/>
      </default>
      <default class="foot">
        <geom size="0.126 0.045 0.01" type="box" condim="6" group="4" priority="1" solimp="0.015 1 0.01"/>
      </default>
      <default class="reward_collision_sphere">
        <geom group="5" rgba="1 0 0 1"/>
      </default>
    </default>
  </default>

  <asset>
    <texture type="skybox" colorspace="auto" name="//unnamed_texture_0" builtin="gradient" rgb1="0.95 0.95 0.95" rgb2="0.95 0.95 0.95" width="100" height="600"/>
    <texture type="2d" colorspace="auto" name="texplane" builtin="checker" rgb1="0.345 0.575 0.748" rgb2="0.345 0.575 0.748" markrgb="1 1 1" width="512" height="512"/>
    <material name="MatPlane" class="/" texture="texplane" texuniform="true" texrepeat="2 2" specular="0.9"/>
    <mesh name="base_link" class="/" file="base_link.STL"/>
    <mesh name="left_thigh_roll_link" class="/" file="left_thigh_roll_link.STL"/>
    <mesh name="left_thigh_yaw_link" class="/" file="left_thigh_yaw_link.STL"/>
    <mesh name="left_thigh_pitch_link" class="/" file="left_thigh_pitch_link.STL"/>
    <mesh name="left_shank_pitch_link" class="/" file="left_shank_pitch_link.STL"/>
    <mesh name="left_foot_pitch_link" class="/" file="left_foot_pitch_link.STL"/>
    <mesh name="left_foot_roll_link" class="/" file="left_foot_roll_link.STL"/>
    <mesh name="right_thigh_roll_link" class="/" file="right_thigh_roll_link.STL"/>
    <mesh name="right_thigh_yaw_link" class="/" file="right_thigh_yaw_link.STL"/>
    <mesh name="right_thigh_pitch_link" class="/" file="right_thigh_pitch_link.STL"/>
    <mesh name="right_shank_pitch_link" class="/" file="right_shank_pitch_link.STL"/>
    <mesh name="right_foot_pitch_link" class="/" file="right_foot_pitch_link.STL"/>
    <mesh name="right_foot_roll_link" class="/" file="right_foot_roll_link.STL"/>
    <mesh name="waist_yaw_link" class="/" file="waist_yaw_link.STL"/>
    <mesh name="waist_pitch_link" class="/" file="waist_pitch_link.STL"/>
    <mesh name="waist_roll_link" class="/" file="waist_roll_link.STL"/>
    <mesh name="torso_link" class="/" file="torso_link.STL"/>
    <mesh name="left_upper_arm_pitch_link" class="/" file="left_upper_arm_pitch_link.STL"/>
    <mesh name="left_upper_arm_roll_link" class="/" file="left_upper_arm_roll_link.STL"/>
    <mesh name="left_upper_arm_yaw_link" class="/" file="left_upper_arm_yaw_link.STL"/>
    <mesh name="left_lower_arm_pitch_link" class="/" file="left_lower_arm_pitch_link.STL"/>
    <mesh name="left_hand_yaw_link" class="/" file="left_hand_yaw_link.STL"/>
    <mesh name="left_hand_roll_link" class="/" file="left_hand_roll_link.STL"/>
    <mesh name="left_hand_pitch" class="/" file="left_hand_pitch.STL"/>
    <mesh name="left_jaw_link" class="/" file="left_jaw_link.STL"/>
    <mesh name="right_upper_arm_pitch_link" class="/" file="right_upper_arm_pitch_link.STL"/>
    <mesh name="right_upper_arm_roll_link" class="/" file="right_upper_arm_roll_link.STL"/>
    <mesh name="right_upper_arm_yaw_link" class="/" file="right_upper_arm_yaw_link.STL"/>
    <mesh name="right_lower_arm_pitch_link" class="/" file="right_lower_arm_pitch_link.STL"/>
    <mesh name="right_hand_yaw_link" class="/" file="right_hand_yaw_link.STL"/>
    <mesh name="right_hand_roll_link" class="/" file="right_hand_roll_link.STL"/>
    <mesh name="right_hand_pitch" class="/" file="right_hand_pitch.STL"/>
    <mesh name="right_jaw_link" class="/" file="right_jaw_link.STL"/>
    <mesh name="head_roll_link" class="/" file="head_roll_link.STL"/>
    <mesh name="head_pitch_link" class="/" file="head_pitch_link.STL"/>
    <mesh name="head_yaw_link" class="/" file="head_yaw_link.STL"/>
    <mesh name="imu_link" class="/" file="imu_link.STL"/>
  </asset>

  <worldbody>
    <geom name="floor" class="/" size="100 100 0.125" type="plane" group="0" material="MatPlane"/>
    <light name="toplight_shadow" class="/" pos="0 0 5" dir="0.0990148 0.0990148 -0.990148" type="directional" ambient="0.04 0.04 0.04" diffuse="0.55 0.55 0.55" specular="0.12 0.12 0.12"/>
    <light name="toplight_fill" class="/" pos="0 0 5" dir="0.0990148 0.0990148 -0.990148" type="directional" castshadow="false" ambient="0.04 0.04 0.04" diffuse="0.3 0.3 0.3" specular="0.08 0.08 0.08"/>
    <body name="trunk" pos="0.000307796 0.000863202 0.000178781" quat="1 -1.78253e-05 -0.000143639 -4.78376e-05">
      <inertial pos="-0.0693807 0.000626577 -0.00847931" quat="1 -0.000183991 0.000350156 -0.000169951" mass="3.34553" diaginertia="0.0946905 0.00523895 0.0151861"/>
      <joint name="//unnamed_joint_0" type="free"/>
      <geom name="//unnamed_geom_1" class="visual" rgba="0.12 0.12 0.12 1" mesh="base_link"/>
      <geom name="base_link.STL" class="collision" size="0.11501 0.0644148" pos="-0.0501879 0.000306498 0.00747987" quat="0.706838 -0.707359 0.00477667 0" type="cylinder" rgba="0.752941 0.752941 0.752941 1"/>
      <geom name="//unnamed_geom_3" class="visual" pos="0 0 -0.0484035" quat="1 0 0 0" rgba="0.12 0.12 0.12 1" mesh="imu_link"/>
      <geom name="//unnamed_geom_4" class="reward_collision_sphere" size="0.0751736" pos="0 0.0828279 0.0812139"/>
      <geom name="//unnamed_geom_5" class="reward_collision_sphere" size="0.0751736" pos="0 -0.0828279 0.0812139"/>
      <site name="imu" class="/" pos="-0.00578915 -0.000449685 -0.0508775" size="0.0093967"/>
      <camera name="track" class="/" pos="0 -1.65656 0" quat="0.707107 0.707107 0 0" mode="trackcom"/>
      <body name="left_thigh_roll_link" pos="-0.0411183 0.0866289 -0.0212315" quat="1 -0.0001104 -5.3336e-05 0.000144099">
        <inertial pos="0.000643918 -0.00152572 0.00143418" quat="-0.0320358 0.703157 -0.0331603 0.709538" mass="1.20118" diaginertia="0.0057131 0.000950969 0.000552196"/>
        <joint name="left_hip_roll_joint" class="/" pos="0 0 0" axis="-0.999998 -0.000231985 0.00196264" range="-0.795339 0.11311" armature="0.0940937" damping="0.0034055" frictionloss="0.0972581"/>
        <geom name="//unnamed_geom_6" class="visual" mesh="left_thigh_roll_link"/>
        <body name="left_thigh_yaw_link" pos="0.0356147 0.000576709 0.0022445" quat="1 -0.000198277 6.56358e-05 -8.07121e-05">
          <inertial pos="-0.00265781 0.0305135 -0.0903273" quat="0.571443 0.0941199 -0.19476 0.79162" mass="2.90493" diaginertia="0.0557269 0.0077412 0.00311165"/>
          <joint name="left_hip_yaw_joint" class="/" pos="0 0 0" axis="-0.00540061 -0.00253288 -0.999982" range="-0.705618 0.709266" armature="0.0941298" damping="0.00285251" frictionloss="0.0948043"/>
          <geom name="//unnamed_geom_7" class="visual" mesh="left_thigh_yaw_link"/>
          <body name="left_thigh_pitch_link" pos="-0.00200474 0.0191217 -0.11296" quat="1 5.10095e-07 -2.13043e-07 -3.09043e-07">
            <inertial pos="0.00080063 -0.0235166 -0.0509858" quat="0.999808 -0.0150679 -0.00966688 0.00793203" mass="6.92815" diaginertia="0.212373 0.0349152 0.00991666"/>
            <joint name="left_hip_pitch_joint" class="/" pos="0 0 0" axis="7.73707e-06 1 1.18122e-05" stiffness="0.000745148" range="-1.76742 0.682993" armature="0.0931649" damping="0.00794504" frictionloss="0.0946338"/>
            <geom name="//unnamed_geom_8" class="visual" mesh="left_thigh_pitch_link"/>
            <geom name="left_thigh_pitch_link.STL" class="collision" size="0.077053 0.117378" pos="0.000825075 -0.0248484 -0.135673" type="cylinder" rgba="0.752941 0.752941 0.752941 1"/>
            <geom name="//unnamed_geom_10" class="reward_collision_sphere" size="0.093967" pos="0 -0.00828279 -0.040607"/>
            <body name="left_shank_pitch_link" pos="-0.000819963 -0.0156344 -0.290605" quat="1 -2.93922e-05 -9.20296e-05 -7.93352e-05">
              <inertial pos="0.00186976 -0.00166789 -0.0927698" quat="0.99966 -0.00562989 0.0107979 -0.0230764" mass="1.47377" diaginertia="0.0249539 0.00421612 0.000446614"/>
              <joint name="left_knee_pitch_joint" class="/" pos="0 0 0" axis="-0.00149943 0.999991 -0.00388947" range="-0.0991449 1.9007" armature="0.0874023" damping="0.0101035" frictionloss="0.089726"/>
              <geom name="//unnamed_geom_11" class="visual" mesh="left_shank_pitch_link"/>
              <geom name="left_shank_pitch_link.STL" class="collision" size="0.0501045 0.0849321" pos="-1.9553e-05 -0.000697864 -0.141873" quat="0.00125538 -0.202712 0.979238 0" type="cylinder" rgba="0.752941 0.752941 0.752941 1"/>
              <geom name="//unnamed_geom_13" class="reward_collision_sphere" size="0.0469835"/>
              <geom name="//unnamed_geom_14" class="reward_collision_sphere" size="0.0563802" pos="0 0 -0.0893353"/>
              <body name="left_foot_pitch_link" pos="-0.00108832 -0.00127864 -0.27553" quat="1 -7.90825e-05 0.000143275 -0.000284592">
                <inertial pos="0.000943067 -0.00139276 -0.000463855" quat="-0.0011364 0.708632 -0.000347405 0.705577" mass="0.0473711" diaginertia="1.43856e-05 2.19083e-06 1.8454e-06"/>
                <joint name="left_ankle_pitch_joint" class="/" pos="0 0 0" axis="0.00237488 0.999992 -0.00320482" range="-1.05901 0.539225" armature="0.0952875" damping="0.000333323" frictionloss="0.093547"/>
                <geom name="//unnamed_geom_15" class="visual" mesh="left_foot_pitch_link"/>
                <body name="left_foot_roll_link" pos="-0.000546997 -0.000429743 0.00146258" quat="1 9.38665e-07 3.16773e-06 2.72648e-06">
                  <inertial pos="0.0449782 -0.00119224 -0.031276" quat="-0.000506274 0.725031 -0.0013405 0.688714" mass="0.892049" diaginertia="0.0124849 0.00194259 0.000264368"/>
                  <joint name="left_ankle_roll_joint" class="/" pos="0 0 0" axis="-0.999988 0.000917609 0.00475177" range="-0.453214 0.442212" armature="0.0965093" damping="0.00495032" frictionloss="0.093246"/>
                  <geom name="//unnamed_geom_16" class="visual" mesh="left_foot_roll_link"/>
                  <geom name="left_foot" class="foot" size="0.14386 0.0442833 0.00944044" pos="0.0530367 0 -0.0361402"/>
                  <geom name="//unnamed_geom_18" class="reward_collision_sphere" size="0.0469835" pos="0 0 -0.0243642"/>
                  <geom name="//unnamed_geom_19" class="reward_collision_sphere" size="0.0469835" pos="0.141431 0 -0.0243642"/>
                  <site name="left_foot" class="foot" pos="0.0530367 0 -0.0361402" size="0.0093967"/>
                </body>
              </body>
            </body>
          </body>
        </body>
      </body>
      <body name="right_thigh_roll_link" pos="-0.0381454 -0.0905245 -0.0230858" quat="1 2.55395e-05 -0.000472142 9.29593e-06">
        <inertial pos="0.0015065 -0.00223619 0.0018296" quat="0.0282629 0.704032 0.0163246 0.709418" mass="1.23238" diaginertia="0.00589042 0.000971706 0.000559224"/>
        <joint name="right_hip_roll_joint" class="/" pos="0 0 0" axis="-1 5.39062e-05 -6.94998e-05" range="-0.114002 0.804037" armature="0.0840177" damping="0.00649811" frictionloss="0.0941167"/>
        <geom name="//unnamed_geom_20" class="visual" mesh="right_thigh_roll_link"/>
        <body name="right_thigh_yaw_link" pos="0.0375256 -0.00452147 0.000400111" quat="1 0.000441608 0.000360269 -4.03058e-05">
          <inertial pos="-0.00271061 -0.0328313 -0.0907196" quat="0.686738 -0.149344 0.149304 0.695554" mass="2.92142" diaginertia="0.0545839 0.0076118 0.00316278"/>
          <joint name="right_hip_yaw_joint" class="/" pos="0 0 0" axis="0.00650067 -0.00474196 -0.999968" range="-0.695738 0.690857" armature="0.095574" damping="0.0103054" frictionloss="0.0941462"/>
          <geom name="//unnamed_geom_21" class="visual" mesh="right_thigh_yaw_link"/>
          <body name="right_thigh_pitch_link" pos="-0.00157211 -0.0214392 -0.113632" quat="1 4.7475e-05 -3.3528e-06 4.11169e-05">
            <inertial pos="0.000583992 0.0223181 -0.0516361" quat="0.999809 -0.0134798 -0.0113134 0.00853012" mass="6.98662" diaginertia="0.213269 0.0353964 0.00988736"/>
            <joint name="right_hip_pitch_joint" class="/" pos="0 0 0" axis="-0.00240832 -0.999927 -0.0118282" range="-0.683772 1.76463" armature="0.0941196" damping="0.0263639" frictionloss="0.0942526"/>
            <geom name="//unnamed_geom_22" class="visual" mesh="right_thigh_pitch_link"/>
            <geom name="right_thigh_pitch_link.STL" class="collision" size="0.077053 0.117375" pos="-0.00250247 0.0248484 -0.135673" quat="0.999971 0.00269833 0.00706272 0" type="cylinder" rgba="0.752941 0.752941 0.752941 1"/>
            <geom name="//unnamed_geom_24" class="reward_collision_sphere" size="0.093967" pos="0 0.00828279 -0.040607"/>
            <body name="right_shank_pitch_link" pos="-0.000250906 0.0125558 -0.291709" quat="1 -3.83369e-05 -0.000173445 -1.51694e-05">
              <inertial pos="0.00170866 -0.00114987 -0.0929786" quat="0.999671 0.0096773 0.00358049 0.0234792" mass="1.45482" diaginertia="0.0242858 0.00407464 0.00043589"/>
              <joint name="right_knee_pitch_joint" class="/" pos="0 0 0" axis="0.0119848 -0.999919 0.00437744" range="-1.93586 0.100477" armature="0.0927105" damping="0.0174905" frictionloss="0.0939122"/>
              <geom name="//unnamed_geom_25" class="visual" mesh="right_shank_pitch_link"/>
              <geom name="right_shank_pitch_link.STL" class="collision" size="0.0501042 0.0849312" pos="-1.9553e-05 -0.000697872 -0.14188" type="cylinder" rgba="0.752941 0.752941 0.752941 1"/>
              <geom name="//unnamed_geom_27" class="reward_collision_sphere" size="0.0469835"/>
              <geom name="//unnamed_geom_28" class="reward_collision_sphere" size="0.0563802" pos="0 0 -0.0893353"/>
              <body name="right_foot_pitch_link" pos="0.000620853 -0.00123238 -0.276188" quat="1 -4.46623e-05 -3.57535e-05 -7.74729e-05">
                <inertial pos="0.000649426 -0.000513924 -0.000171683" quat="0.000215647 0.70716 3.81618e-05 0.707054" mass="0.0477635" diaginertia="1.46755e-05 2.17877e-06 1.8985e-06"/>
                <joint name="right_ankle_pitch_joint" class="/" pos="0 0 0" axis="-0.000988581 -0.999997 0.00213243" range="-0.53568 1.06132" armature="0.0929162" damping="0.00401401" frictionloss="0.0908128"/>
                <geom name="//unnamed_geom_29" class="visual" mesh="right_foot_pitch_link"/>
                <body name="right_foot_roll_link" pos="-0.000285264 -0.0003124 0.00128752" quat="1 -0.000154917 -6.69726e-05 0.000124407">
                  <inertial pos="0.0437701 -0.00237103 -0.0317685" quat="0.000681312 0.725129 0.00130598 0.688612" mass="0.909912" diaginertia="0.0127078 0.00199729 0.000266242"/>
                  <joint name="right_ankle_roll_joint" class="/" pos="0 0 0" axis="-0.99996 -0.00883732 0.00160294" range="-0.470164 0.460668" armature="0.0916892" damping="0.0055949" frictionloss="0.0931551"/>
                  <geom name="//unnamed_geom_30" class="visual" mesh="right_foot_roll_link"/>
                  <geom name="right_foot" class="foot" size="0.145499 0.0384139 0.00923115" pos="0.0530367 0 -0.0361402"/>
                  <geom name="//unnamed_geom_32" class="reward_collision_sphere" size="0.0469835" pos="0 0 -0.0243642"/>
                  <geom name="//unnamed_geom_33" class="reward_collision_sphere" size="0.0469835" pos="0.141431 0 -0.0243642"/>
                  <site name="right_foot" class="foot" pos="0.0530367 0 -0.0361402" size="0.0093967"/>
                </body>
              </body>
            </body>
          </body>
        </body>
      </body>
      <body name="waist_yaw_link" pos="0.00307017 0.00245936 0.00246655" quat="1 0.000255001 9.37089e-05 3.09673e-05">
        <inertial pos="-0.00231701 -0.00719986 0.0425412" quat="0.979926 0.188465 -0.0274813 0.0589081" mass="1.37926" diaginertia="0.00810598 0.00128319 0.000761117"/>
        <joint name="waist_yaw_joint" class="/" pos="0 0 0" axis="-0.0120119 -0.00613536 0.999909" range="-1.06084 1.02965" armature="0.0979597" damping="0.00895078" frictionloss="0.0939705"/>
        <geom name="//unnamed_geom_34" class="visual" rgba="0.12 0.12 0.12 1" mesh="waist_yaw_link"/>
        <body name="waist_pitch_link" pos="0.00300841 0.00200448 0.073616" quat="1 -1.83862e-05 6.26061e-05 0.000268828">
          <inertial pos="0.00630443 -0.00298913 0.033937" quat="0.997994 -0.0422366 0.0467252 0.00639321" mass="1.27907" diaginertia="0.010402 0.00175292 0.000629508"/>
          <joint name="waist_pitch_joint" class="/" pos="0 0 0" axis="0.00765687 -0.99971 0.0228393" range="-1.21439 0.499809" armature="0.0943371" damping="0.00342971" frictionloss="0.0939507"/>
          <geom name="//unnamed_geom_35" class="visual" rgba="0.12 0.12 0.12 1" mesh="waist_pitch_link"/>
          <body name="waist_roll_link" pos="0.00928943 0.000348617 0.0692477" quat="1 -3.17765e-06 3.55699e-06 -4.68719e-06">
            <inertial pos="-0.0168387 0.000580678 0.119145" quat="0.998953 -0.00113973 -0.0455942 0.00366792" mass="5.4972" diaginertia="0.14359 0.0235832 0.0125532"/>
            <joint name="waist_roll_joint" class="/" pos="0 0 0" axis="-0.999986 0.00410748 0.00337972" range="-0.751674 0.697332" armature="0.0985943" damping="0.0171939" frictionloss="0.0908424"/>
            <geom name="//unnamed_geom_36" class="visual" rgba="0.12 0.12 0.12 1" mesh="waist_roll_link"/>
            <geom name="//unnamed_geom_37" class="visual" pos="-0.00265183 0.000475788 0.130227" quat="1 0 0 0" mesh="torso_link"/>
            <geom name="torso_link.STL" class="collision" size="0.147929 0.0283715" pos="-0.0212923 0.004779 0.120058" type="cylinder" rgba="0.752941 0.752941 0.752941 1"/>
            <geom name="//unnamed_geom_39" class="reward_collision_sphere" size="0.122157" pos="0 0 0.162428"/>
            <body name="left_upper_arm_pitch_link" pos="-0.000904978 0.083529 0.168658" quat="0.976683 0.214689 -3.27474e-05 9.80084e-05">
              <inertial pos="0.00465599 0.0436853 0.000560916" quat="0.703303 0.708927 0.0029088 -0.052722" mass="0.673637" diaginertia="0.00465911 0.000770838 0.000175901"/>
              <joint name="left_shoulder_pitch_joint" class="/" pos="0 0 0" axis="-0.000122961 1 -0.000650658" range="-2.78802 1.92928" armature="0.0931137" damping="0.00966712" frictionloss="0.0929506"/>
              <geom name="//unnamed_geom_40" class="visual" mesh="left_upper_arm_pitch_link"/>
              <body name="left_upper_arm_roll_link" pos="0.00167291 0.0780561 0.000704535" quat="0.976674 -0.214728 -1.89846e-05 -6.02543e-05">
                <inertial pos="0.00536545 0.0124882 -0.0192375" quat="0.889457 0.269167 0.124382 -0.347772" mass="0.506039" diaginertia="0.00236672 0.000396033 0.000125963"/>
                <joint name="left_shoulder_roll_joint" class="/" pos="0 0 0" axis="-1 -0.000811612 -0.000379219" stiffness="0.000310545" range="-2.53556 0.590719" armature="0.0976434" damping="0" frictionloss="0.0948364"/>
                <geom name="//unnamed_geom_41" class="visual" mesh="left_upper_arm_roll_link"/>
                <body name="left_upper_arm_yaw_link" pos="0.00109509 0.0314631 -0.058016" quat="1 8.88743e-06 -7.99933e-05 -1.26168e-05">
                  <inertial pos="-0.000330001 -0.000291401 -0.071556" quat="0.999959 0.00560894 0.00103071 -0.00708697" mass="0.449934" diaginertia="0.00810732 0.00136054 9.13167e-05"/>
                  <joint name="left_shoulder_yaw_joint" class="/" pos="0 0 0" axis="0.000723404 0.000449216 1" range="-2.9683 2.95965" armature="0.0999146" damping="0.00443085" frictionloss="0.09535"/>
                  <geom name="//unnamed_geom_42" class="visual" mesh="left_upper_arm_yaw_link"/>
                  <geom name="left_upper_arm_yaw_link.STL" class="collision" size="0.0340473 0.0798175" pos="4.65372e-05 -0.000740721 -0.0644351" quat="0.00803418 -0.995528 0.0941277 0" type="cylinder" rgba="0.752941 0.752941 0.752941 1"/>
                  <body name="left_lower_arm_pitch_link" pos="0.00109178 0.000564479 -0.145414" quat="1 -0.000137334 0.000120692 0.00010056">
                    <inertial pos="-5.34787e-05 0.00546548 -0.0196555" quat="0.701233 -0.0916843 0.0919755 0.701004" mass="0.270397" diaginertia="0.000676166 0.000113735 3.41419e-05"/>
                    <joint name="left_elbow_pitch_joint" class="/" pos="0 0 0" axis="-0.00364272 0.999992 -0.00147858" range="-2.27784 2.26882" armature="0.0965214" damping="0.0022978" frictionloss="0.089716"/>
                    <geom name="//unnamed_geom_44" class="visual" mesh="left_lower_arm_pitch_link"/>
                    <body name="left_hand_yaw_link" pos="0.000363152 0.000685563 -0.0492969" quat="1 -0.00044414 -0.000154558 0.000259437">
                      <inertial pos="-0.000725402 -9.98742e-05 -0.0592487" quat="0.999954 -0.00379234 -0.00244494 0.00850281" mass="0.821935" diaginertia="0.00596176 0.000987063 0.000173834"/>
                      <joint name="left_wrist_yaw_joint" class="/" pos="0 0 0" axis="-0.000899497 -0.000560257 0.999999" range="-2.96788 2.97974" armature="0.097326" damping="0.00521076" frictionloss="0.0925815"/>
                      <geom name="//unnamed_geom_45" class="visual" mesh="left_hand_yaw_link"/>
                      <geom name="left_hand_yaw_link.STL" class="collision" size="0.0390639 0.0653951" pos="0.00128378 -0.00127647 -0.0617574" type="cylinder" rgba="0.752941 0.752941 0.752941 1"/>
                      <geom name="//unnamed_geom_47" class="reward_collision_sphere" size="0.0469835"/>
                      <body name="left_hand_roll_link" pos="5.38916e-05 0.00171008 -0.155374" quat="1 -2.71427e-06 0.000419658 -0.000343435">
                        <inertial pos="0.000365214 -0.000428184 -0.000258856" quat="0.500331 0.500828 0.499541 0.499299" mass="0.00417474" diaginertia="8.09164e-07 1.37675e-07 2.516e-08"/>
                        <joint name="left_wrist_roll_joint" class="/" pos="0 0 0" axis="-0.999994 0.00330412 -0.000877166" range="-0.955197 0.858687" armature="0.0916508" damping="0.00617586" frictionloss="0.0934756"/>
                        <geom name="//unnamed_geom_48" class="visual" mesh="left_hand_roll_link"/>
                        <body name="left_hand_pitch_link" pos="-0.00033615 -0.000156469 -0.000520125" quat="1 7.16309e-06 -6.47968e-05 4.69048e-05">
                          <inertial pos="-0.00101333 -0.0104974 -0.0424543" quat="0.723352 -0.121252 0.114501 0.670037" mass="0.181765" diaginertia="0.000652676 0.000104858 3.31617e-05"/>
                          <joint name="left_wrist_pitch_joint" class="/" pos="0 0 0" axis="-0.00261876 0.999996 0.000686154" range="-0.620653 0.58875" armature="0.0975579" damping="0.00534745" frictionloss="0.0925328"/>
                          <geom name="//unnamed_geom_49" class="visual" mesh="left_hand_pitch"/>
                          <body name="left_jaw_link" pos="0.000463715 0.00074241 -0.0499782" quat="1 -1.82673e-05 8.19016e-05 -0.000420546">
                            <inertial pos="0.000337353 0.00278527 -0.0273543" quat="0.70948 -0.0240701 0.0358969 0.703399" mass="0.0575633" diaginertia="0.000181432 2.17284e-05 1.14273e-05"/>
                            <joint name="left_jaw_joint" class="/" pos="0 0 0" axis="-0.99998 0.00337465 -0.00531721" range="-0.994936 -0.0158714" armature="0.09631" damping="0.0106888" frictionloss="0.0937651"/>
                            <geom name="//unnamed_geom_50" class="visual" mesh="left_jaw_link"/>
                            <geom name="//unnamed_geom_51" class="collision" size="0.0338281"/>
                            <geom name="//unnamed_geom_52" class="reward_collision_sphere" size="0.0469835" pos="0 0 -0.0162428"/>
                          </body>
                        </body>
                      </body>
                    </body>
                  </body>
                </body>
              </body>
            </body>
            <body name="right_upper_arm_pitch_link" pos="-0.000758007 -0.0824728 0.168217" quat="0.9767 -0.214607 4.18654e-05 -0.000234654">
              <inertial pos="0.00437754 -0.0448395 0.000697431" quat="0.705956 0.707383 0.0261694 0.0234416" mass="0.690902" diaginertia="0.00473721 0.000770785 0.000178298"/>
              <joint name="right_shoulder_pitch_joint" class="/" pos="0 0 0" axis="0.000320619 -0.999989 -0.00476332" stiffness="9.4943e-05" range="-1.92439 2.80598" armature="0.0922773" damping="0.000970116" frictionloss="0.0950816"/>
              <geom name="//unnamed_geom_53" class="visual" mesh="right_upper_arm_pitch_link"/>
              <body name="right_upper_arm_roll_link" pos="0.00135806 -0.0777699 0.000270053" quat="0.976736 0.214444 0.000251512 0.000141465">
                <inertial pos="0.00480767 -0.0156319 -0.020787" quat="0.889861 -0.267505 0.126435 0.34728" mass="0.503114" diaginertia="0.00231732 0.000387404 0.000124701"/>
                <joint name="right_shoulder_roll_joint" class="/" pos="0 0 0" axis="-0.999995 -0.00209217 -0.00228273" range="-0.592499 2.54409" armature="0.0939958" damping="0.00732162" frictionloss="0.0991285"/>
                <geom name="//unnamed_geom_54" class="visual" mesh="right_upper_arm_roll_link"/>
                <body name="right_upper_arm_yaw_link" pos="0.0012202 -0.0323582 -0.0564959" quat="1 0.000181417 5.85034e-06 -6.90464e-05">
                  <inertial pos="-0.000269336 -0.000365748 -0.0714788" quat="0.999976 -0.006932 -9.04699e-05 0.000618423" mass="0.446176" diaginertia="0.00807493 0.00137081 9.23796e-05"/>
                  <joint name="right_shoulder_yaw_joint" class="/" pos="0 0 0" axis="0.00248403 0.00498958 0.999984" range="-2.97585 2.96514" armature="0.102333" damping="0.0047383" frictionloss="0.0926393"/>
                  <geom name="//unnamed_geom_55" class="visual" mesh="right_upper_arm_yaw_link"/>
                  <geom name="right_upper_arm_yaw_link.STL" class="collision" size="0.0340473 0.0798175" pos="4.65372e-05 0.000740721 -0.0644351" type="cylinder" rgba="0.752941 0.752941 0.752941 1"/>
                  <body name="right_lower_arm_pitch_link" pos="0.00228574 -0.00103692 -0.143778" quat="1 -3.33205e-05 -3.93171e-05 -1.39647e-06">
                    <inertial pos="-0.000363785 -0.00609568 -0.0204325" quat="0.700714 0.093093 -0.0928516 0.701222" mass="0.272895" diaginertia="0.000680185 0.000114872 3.49754e-05"/>
                    <joint name="right_elbow_pitch_joint" class="/" pos="0 0 0" axis="0.00139904 -0.999997 0.00219866" range="-2.26882 2.27304" armature="0.100967" damping="0.0105822" frictionloss="0.0938756"/>
                    <geom name="//unnamed_geom_57" class="visual" mesh="right_lower_arm_pitch_link"/>
                    <body name="right_hand_yaw_link" pos="0.00152803 -2.71268e-05 -0.0483419" quat="1 -8.72098e-05 -3.8811e-05 2.24801e-05">
                      <inertial pos="0.00046071 -0.00191165 -0.0586989" quat="0.999762 0.00139403 -0.00212355 0.0216461" mass="0.818276" diaginertia="0.00591356 0.000985842 0.000178333"/>
                      <joint name="right_wrist_yaw_joint" class="/" pos="0 0 0" axis="0.000361003 2.38356e-05 1" range="-2.964 2.97579" armature="0.100611" damping="0.00595035" frictionloss="0.0970114"/>
                      <geom name="//unnamed_geom_58" class="visual" mesh="right_hand_yaw_link"/>
                      <geom name="right_hand_yaw_link.STL" class="collision" size="0.0390639 0.0653951" pos="0.00128378 0.000531021 -0.0617574" type="cylinder" rgba="0.752941 0.752941 0.752941 1"/>
                      <geom name="//unnamed_geom_60" class="reward_collision_sphere" size="0.0469835"/>
                      <body name="right_hand_roll_link" pos="0.00114817 -0.000196984 -0.154626" quat="1 3.71003e-05 -6.06778e-06 5.98418e-06">
                        <inertial pos="-0.00111853 -0.000470721 -0.000233071" quat="0.500025 0.498743 0.497582 0.503629" mass="0.00415861" diaginertia="8.00216e-07 1.36562e-07 2.46548e-08"/>
                        <joint name="right_wrist_roll_joint" class="/" pos="0 0 0" axis="-0.999999 0.000136801 0.00169187" range="-0.871919 0.984587" armature="0.103198" damping="0.0175182" frictionloss="0.0908871"/>
                        <geom name="//unnamed_geom_61" class="visual" mesh="right_hand_roll_link"/>
                        <body name="right_hand_pitch_link" pos="0.00153351 -9.848e-05 -0.00108451" quat="1 0.000146126 8.18998e-05 0.000446592">
                          <inertial pos="-0.000377257 0.00842245 -0.0432452" quat="0.723423 0.121176 -0.114213 0.670024" mass="0.179808" diaginertia="0.00065764 0.000105594 3.37121e-05"/>
                          <joint name="right_wrist_pitch_joint" class="/" pos="0 0 0" axis="-9.77829e-06 -1 -2.81265e-05" stiffness="0.00112857" range="-0.597347 0.625725" armature="0.0971334" damping="0.00737013" frictionloss="0.0982542"/>
                          <geom name="//unnamed_geom_62" class="visual" mesh="right_hand_pitch"/>
                          <body name="right_jaw_link" pos="0.000723163 0.000123683 -0.0501241" quat="1 1.36934e-05 -2.50339e-06 -3.44838e-06">
                            <inertial pos="-0.00161825 -0.0048497 -0.0273908" quat="0.70744 0.0213644 -0.0303935 0.705796" mass="0.0579827" diaginertia="0.000180917 2.17146e-05 1.14582e-05"/>
                            <joint name="right_jaw_joint" class="/" pos="0 0 0" axis="-1 -0.000928958 -0.000199979" range="0.0142007 1.00078" armature="0.0975858" damping="0.00272314" frictionloss="0.0978937"/>
                            <geom name="//unnamed_geom_63" class="visual" mesh="right_jaw_link"/>
                            <geom name="//unnamed_geom_64" class="collision" size="0.0338281"/>
                            <geom name="//unnamed_geom_65" class="reward_collision_sphere" size="0.0469835" pos="0 0 -0.0162428"/>
                          </body>
                        </body>
                      </body>
                    </body>
                  </body>
                </body>
              </body>
            </body>
            <body name="head_roll_link" pos="-0.000627736 0.000651018 0.249469" quat="1 -6.15378e-05 1.31082e-05 5.43524e-05">
              <inertial pos="0.00576817 -0.000590377 0.000494922" quat="0.00381178 0.706494 0.000233959 0.707708" mass="0.0083511" diaginertia="1.64259e-06 1.71942e-07 1.51086e-07"/>
              <joint name="head_roll_joint" class="/" pos="0 0 0" axis="-0.999968 0.00290352 -0.00745973" range="-0.361955 0.368166" armature="0.0987966" damping="0.000883326" frictionloss="0.0886216"/>
              <geom name="//unnamed_geom_66" class="visual" mesh="head_roll_link"/>
              <body name="head_pitch_link" pos="-0.00111336 -0.000126788 0.00227019" quat="1 0.00016602 4.51186e-05 2.10132e-05">
                <inertial pos="-0.00143693 0.000722125 0.0149186" quat="0.663716 0.666324 0.240301 -0.240309" mass="0.0492997" diaginertia="5.91659e-05 9.06938e-06 5.93926e-06"/>
                <joint name="head_pitch_joint" class="/" pos="0 0 0" axis="1.31265e-05 -0.999994 -0.00335985" range="-0.857196 0.864917" armature="0.0939043" damping="0.00898903" frictionloss="0.0882142"/>
                <geom name="//unnamed_geom_67" class="visual" mesh="head_pitch_link"/>
                <body name="head_yaw_link" pos="6.35716e-05 0.00124051 0.0440178" quat="1 -0.000273089 -0.000444461 -1.57098e-05">
                  <inertial pos="0.032479 -0.00323365 0.0780548" quat="0.705886 -0.134227 -0.146589 0.679867" mass="1.32284" diaginertia="0.023097 0.00311381 0.0018478"/>
                  <joint name="head_yaw_joint" class="/" pos="0 0 0" axis="0.00101927 0.00187938 0.999998" range="-2.69548 2.71002" armature="0.0972707" damping="0.00461373" frictionloss="0.0944631"/>
                  <geom name="//unnamed_geom_68" class="visual" rgba="0.12 0.12 0.12 1" mesh="head_yaw_link"/>
                  <geom name="head_yaw_link.STL" class="collision" size="0.111527" pos="0.021546 -0.000728905 0.0760326" rgba="0.752941 0.752941 0.752941 1"/>
                  <geom name="//unnamed_geom_70" class="reward_collision_sphere" size="0.093967" pos="0.0353578 0 0.0812139"/>
                  <camera name="ego_camera" class="/" pos="0.129645 0 0.0893353" quat="-0.5 -0.5 0.5 0.5"/>
                </body>
              </body>
            </body>
          </body>
        </body>
      </body>
    </body>
  </worldbody>

  <contact>
    <pair class="/" geom1="floor" geom2="left_foot" name="//unnamed_contact_0"/>
    <pair class="/" geom1="floor" geom2="right_foot" name="//unnamed_contact_1"/>
  </contact>

  <actuator>
    <general name="left_hip_roll" class="/" joint="left_hip_roll_joint" forcerange="-46.1001 46.1001" gainprm="112.76" biasprm="0 -112.76 -0.93967"/>
    <general name="left_hip_yaw" class="/" joint="left_hip_yaw_joint" forcerange="-62.3201 62.3201" gainprm="112.76" biasprm="0 -112.76 -0.93967"/>
    <general name="left_hip_pitch" class="/" joint="left_hip_pitch_joint" forcerange="-220.58 220.58" gainprm="112.76" biasprm="0 -112.76 -0.93967"/>
    <general name="left_knee_pitch" class="/" joint="left_knee_pitch_joint" forcerange="-217.193 217.193" gainprm="112.76" biasprm="0 -112.76 -0.93967"/>
    <general name="left_ankle_pitch" class="/" joint="left_ankle_pitch_joint" forcerange="-14.3359 14.3359" gainprm="112.76" biasprm="0 -112.76 -0.93967"/>
    <general name="left_ankle_roll" class="/" joint="left_ankle_roll_joint" forcerange="-28.0873 28.0873" gainprm="112.76" biasprm="0 -112.76 -0.93967"/>
    <general name="right_hip_roll" class="/" joint="right_hip_roll_joint" forcerange="-44.661 44.661" gainprm="112.76" biasprm="0 -112.76 -0.93967"/>
    <general name="right_hip_yaw" class="/" joint="right_hip_yaw_joint" forcerange="-64.1254 64.1254" gainprm="112.76" biasprm="0 -112.76 -0.93967"/>
    <general name="right_hip_pitch" class="/" joint="right_hip_pitch_joint" forcerange="-220.391 220.391" gainprm="112.76" biasprm="0 -112.76 -0.93967"/>
    <general name="right_knee_pitch" class="/" joint="right_knee_pitch_joint" forcerange="-210.246 210.246" gainprm="112.76" biasprm="0 -112.76 -0.93967"/>
    <general name="right_ankle_pitch" class="/" joint="right_ankle_pitch_joint" forcerange="-13.9755 13.9755" gainprm="112.76" biasprm="0 -112.76 -0.93967"/>
    <general name="right_ankle_roll" class="/" joint="right_ankle_roll_joint" forcerange="-28.2688 28.2688" gainprm="112.76" biasprm="0 -112.76 -0.93967"/>
    <general name="waist_yaw" class="/" joint="waist_yaw_joint" forcerange="-59.4498 59.4498" gainprm="112.76" biasprm="0 -112.76 -0.93967"/>
    <general name="waist_pitch" class="/" joint="waist_pitch_joint" forcerange="-62.8212 62.8212" gainprm="112.76" biasprm="0 -112.76 -0.93967"/>
    <general name="waist_roll" class="/" joint="waist_roll_joint" forcerange="-60.7663 60.7663" gainprm="112.76" biasprm="0 -112.76 -0.93967"/>
    <general name="left_shoulder_pitch" class="/" joint="left_shoulder_pitch_joint" forcerange="-35.035 35.035" gainprm="112.76" biasprm="0 -112.76 -0.93967"/>
    <general name="left_shoulder_roll" class="/" joint="left_shoulder_roll_joint" forcerange="-36.0232 36.0232" gainprm="112.76" biasprm="0 -112.76 -0.93967"/>
    <general name="left_shoulder_yaw" class="/" joint="left_shoulder_yaw_joint" forcerange="-27.8897 27.8897" gainprm="112.76" biasprm="0 -112.76 -0.93967"/>
    <general name="left_elbow_pitch" class="/" joint="left_elbow_pitch_joint" forcerange="-27.5123 27.5123" gainprm="112.76" biasprm="0 -112.76 -0.93967"/>
    <general name="left_wrist_yaw" class="/" joint="left_wrist_yaw_joint" forcerange="-9.68426 9.68426" gainprm="112.76" biasprm="0 -112.76 -0.93967"/>
    <general name="left_wrist_roll" class="/" joint="left_wrist_roll_joint" forcerange="-3.58378 3.58378" gainprm="112.76" biasprm="0 -112.76 -0.93967"/>
    <general name="left_wrist_pitch" class="/" joint="left_wrist_pitch_joint" forcerange="-3.73292 3.73292" gainprm="112.76" biasprm="0 -112.76 -0.93967"/>
    <general name="left_jaw" class="/" joint="left_jaw_joint" forcerange="-3.70624 3.70624" gainprm="112.76" biasprm="0 -112.76 -0.93967"/>
    <general name="right_shoulder_pitch" class="/" joint="right_shoulder_pitch_joint" forcerange="-34.6539 34.6539" gainprm="112.76" biasprm="0 -112.76 -0.93967"/>
    <general name="right_shoulder_roll" class="/" joint="right_shoulder_roll_joint" forcerange="-34.5866 34.5866" gainprm="112.76" biasprm="0 -112.76 -0.93967"/>
    <general name="right_shoulder_yaw" class="/" joint="right_shoulder_yaw_joint" forcerange="-28.594 28.594" gainprm="112.76" biasprm="0 -112.76 -0.93967"/>
    <general name="right_elbow_pitch" class="/" joint="right_elbow_pitch_joint" forcerange="-28.8738 28.8738" gainprm="112.76" biasprm="0 -112.76 -0.93967"/>
    <general name="right_wrist_yaw" class="/" joint="right_wrist_yaw_joint" forcerange="-9.58879 9.58879" gainprm="112.76" biasprm="0 -112.76 -0.93967"/>
    <general name="right_wrist_roll" class="/" joint="right_wrist_roll_joint" forcerange="-3.67098 3.67098" gainprm="112.76" biasprm="0 -112.76 -0.93967"/>
    <general name="right_wrist_pitch" class="/" joint="right_wrist_pitch_joint" forcerange="-3.67732 3.67732" gainprm="112.76" biasprm="0 -112.76 -0.93967"/>
    <general name="right_jaw" class="/" joint="right_jaw_joint" forcerange="-3.77168 3.77168" gainprm="112.76" biasprm="0 -112.76 -0.93967"/>
    <general name="head_roll" class="/" joint="head_roll_joint" forcerange="-3.70462 3.70462" gainprm="112.76" biasprm="0 -112.76 -0.93967"/>
    <general name="head_pitch" class="/" joint="head_pitch_joint" forcerange="-3.71071 3.71071" gainprm="112.76" biasprm="0 -112.76 -0.93967"/>
    <general name="head_yaw" class="/" joint="head_yaw_joint" forcerange="-3.60289 3.60289" gainprm="112.76" biasprm="0 -112.76 -0.93967"/>
  </actuator>

  <sensor>
    <gyro site="imu" name="imu_angular_velocity"/>
    <velocimeter site="imu" name="imu_linear_velocity"/>
    <framelinvel objtype="site" objname="left_foot" name="left_foot_global_linear_velocity"/>
    <framelinvel objtype="site" objname="right_foot" name="right_foot_global_linear_velocity"/>
  </sensor>

  <keyframe>
    <key name="home" qpos="0 0 0.8665 1 0 0 0 0 0 -0.4 0.8 -0.4 0 0 0 0.4 -0.8 0.4 0 0 0 0 0 -0.2 0 -0.785 0 0 0 0 0 0.2 0 0.785 0 0 0 0 0 0 0"/>
  </keyframe>
</mujoco>
