<mujoco model="GR1T2_jaw">
  <compiler angle="radian" assetdir="assets" balanceinertia="true" inertiafromgeom="false"/>

  <option timestep="0.005" density="1.2" viscosity="2e-05"/>

  <size nkey="1"/>

  <visual>
    <quality shadowsize="8192"/>
    <map shadowclip="0.5"/>
  </visual>

  <default>
    <default class="/">
      <joint armature="0.1" damping="0.01" frictionloss="0.1"/>
      <geom contype="0" conaffinity="0" group="1" solref="-1000 -80"/>
      <site size="0.01 0.005 0.005" group="5"/>
      <general forcelimited="true" biastype="affine" gainprm="80" biasprm="0 -80 -2"/>
      <default class="visual">
        <geom type="mesh" density="0" rgba="0.18 0.18 0.18 1"/>
      </default>
      <default class="collision">
        <geom group="3"/>
      </default>
      <default class="foot">
        <geom size="0.126 0.045 0.01" type="box" condim="6" group="4" priority="1" solimp="0.015 1 0.01"/>
      </default>
      <default class="reward_collision_sphere">
        <geom group="5" rgba="1 0 0 1"/>
      </default>
    </default>
  </default>

  <asset>
    <texture type="skybox" colorspace="auto" name="//unnamed_texture_0" builtin="gradient" rgb1="0.95 0.95 0.95" rgb2="0.95 0.95 0.95" width="100" height="600"/>
    <texture type="2d" colorspace="auto" name="texplane" builtin="checker" rgb1="0.345 0.575 0.748" rgb2="0.345 0.575 0.748" markrgb="1 1 1" width="512" height="512"/>
    <material name="MatPlane" class="/" texture="texplane" texuniform="true" texrepeat="2 2" specular="0.9"/>
    <mesh name="base_link" class="/" file="base_link.STL"/>
    <mesh name="left_thigh_roll_link" class="/" file="left_thigh_roll_link.STL"/>
    <mesh name="left_thigh_yaw_link" class="/" file="left_thigh_yaw_link.STL"/>
    <mesh name="left_thigh_pitch_link" class="/" file="left_thigh_pitch_link.STL"/>
    <mesh name="left_shank_pitch_link" class="/" file="left_shank_pitch_link.STL"/>
    <mesh name="left_foot_pitch_link" class="/" file="left_foot_pitch_link.STL"/>
    <mesh name="left_foot_roll_link" class="/" file="left_foot_roll_link.STL"/>
    <mesh name="right_thigh_roll_link" class="/" file="right_thigh_roll_link.STL"/>
    <mesh name="right_thigh_yaw_link" class="/" file="right_thigh_yaw_link.STL"/>
    <mesh name="right_thigh_pitch_link" class="/" file="right_thigh_pitch_link.STL"/>
    <mesh name="right_shank_pitch_link" class="/" file="right_shank_pitch_link.STL"/>
    <mesh name="right_foot_pitch_link" class="/" file="right_foot_pitch_link.STL"/>
    <mesh name="right_foot_roll_link" class="/" file="right_foot_roll_link.STL"/>
    <mesh name="waist_yaw_link" class="/" file="waist_yaw_link.STL"/>
    <mesh name="waist_pitch_link" class="/" file="waist_pitch_link.STL"/>
    <mesh name="waist_roll_link" class="/" file="waist_roll_link.STL"/>
    <mesh name="torso_link" class="/" file="torso_link.STL"/>
    <mesh name="left_upper_arm_pitch_link" class="/" file="left_upper_arm_pitch_link.STL"/>
    <mesh name="left_upper_arm_roll_link" class="/" file="left_upper_arm_roll_link.STL"/>
    <mesh name="left_upper_arm_yaw_link" class="/" file="left_upper_arm_yaw_link.STL"/>
    <mesh name="left_lower_arm_pitch_link" class="/" file="left_lower_arm_pitch_link.STL"/>
    <mesh name="left_hand_yaw_link" class="/" file="left_hand_yaw_link.STL"/>
    <mesh name="left_hand_roll_link" class="/" file="left_hand_roll_link.STL"/>
    <mesh name="left_hand_pitch" class="/" file="left_hand_pitch.STL"/>
    <mesh name="left_jaw_link" class="/" file="left_jaw_link.STL"/>
    <mesh name="right_upper_arm_pitch_link" class="/" file="right_upper_arm_pitch_link.STL"/>
    <mesh name="right_upper_arm_roll_link" class="/" file="right_upper_arm_roll_link.STL"/>
    <mesh name="right_upper_arm_yaw_link" class="/" file="right_upper_arm_yaw_link.STL"/>
    <mesh name="right_lower_arm_pitch_link" class="/" file="right_lower_arm_pitch_link.STL"/>
    <mesh name="right_hand_yaw_link" class="/" file="right_hand_yaw_link.STL"/>
    <mesh name="right_hand_roll_link" class="/" file="right_hand_roll_link.STL"/>
    <mesh name="right_hand_pitch" class="/" file="right_hand_pitch.STL"/>
    <mesh name="right_jaw_link" class="/" file="right_jaw_link.STL"/>
    <mesh name="head_roll_link" class="/" file="head_roll_link.STL"/>
    <mesh name="head_pitch_link" class="/" file="head_pitch_link.STL"/>
    <mesh name="head_yaw_link" class="/" file="head_yaw_link.STL"/>
    <mesh name="imu_link" class="/" file="imu_link.STL"/>
  </asset>

  <worldbody>
    <geom name="floor" class="/" size="100 100 0.125" type="plane" group="0" material="MatPlane"/>
    <light name="toplight_shadow" class="/" pos="0 0 5" dir="0.0990148 0.0990148 -0.990148" type="directional" ambient="0.04 0.04 0.04" diffuse="0.55 0.55 0.55" specular="0.12 0.12 0.12"/>
    <light name="toplight_fill" class="/" pos="0 0 5" dir="0.0990148 0.0990148 -0.990148" type="directional" castshadow="false" ambient="0.04 0.04 0.04" diffuse="0.3 0.3 0.3" specular="0.08 0.08 0.08"/>
    <body name="trunk" pos="0.000161114 0.00855142 -0.000403923" quat="1 -0.0004613 0.000642997 8.00647e-05">
      <inertial pos="-0.043854 -0.00810581 -0.00992003" quat="0.999998 -0.000328982 -0.00115849 0.00173468" mass="1.53503" diaginertia="0.0231407 0.00103287 0.00356132"/>
      <joint name="//unnamed_joint_0" type="free"/>
      <geom name="//unnamed_geom_1" class="visual" rgba="0.12 0.12 0.12 1" mesh="base_link"/>
      <geom name="base_link.STL" class="collision" size="0.0856432 0.047967" pos="-0.0379433 0.000221658 0.00561029" quat="0.706838 -0.707359 0.00477667 0" type="cylinder" rgba="0.752941 0.752941 0.752941 1"/>
      <geom name="//unnamed_geom_3" class="visual" pos="0 0 -0.0363051" quat="1 0 0 0" rgba="0.12 0.12 0.12 1" mesh="imu_link"/>
      <geom name="//unnamed_geom_4" class="reward_collision_sphere" size="0.0559787" pos="0 0.0599008 0.0609146"/>
      <geom name="//unnamed_geom_5" class="reward_collision_sphere" size="0.0559787" pos="0 -0.0599008 0.0609146"/>
      <site name="imu" class="/" pos="0.0734636 -0.00389278 -0.0248456" size="0.00699733"/>
      <camera name="track" class="/" pos="0 -1.19802 0" quat="0.707107 0.707107 0 0" mode="trackcom"/>
      <body name="left_thigh_roll_link" pos="-0.016929 0.0587795 -0.0129817" quat="0.999998 0.000858213 -0.00031759 -0.00199723">
        <inertial pos="-0.00428784 -0.00934017 0.00305215" quat="-0.0374911 0.714554 -0.0299266 0.697934" mass="0.589495" diaginertia="0.00155752 0.000222364 0.000151037"/>
        <joint name="left_hip_roll_joint" class="/" pos="0 0 0" axis="-0.999863 0.0070624 0.0149399" range="-0.810921 -0.179659" armature="0.0565275" damping="0" frictionloss="0.0913166"/>
        <geom name="//unnamed_geom_6" class="visual" mesh="left_thigh_roll_link"/>
        <body name="left_thigh_yaw_link" pos="0.0420537 0.0056815 -0.0125385" quat="1 -0.000820053 -0.000169407 -0.000481788">
          <inertial pos="0.00811074 0.0142659 -0.0742775" quat="0.562693 0.0815386 -0.209569 0.795493" mass="1.15751" diaginertia="0.0147795 0.00167596 0.00089223"/>
          <joint name="left_hip_yaw_joint" class="/" pos="0 0 0" axis="0.0102656 -0.00342997 -0.999941" stiffness="0.0252415" range="-0.70347 0.821006" armature="0.0719566" damping="0" frictionloss="0.108589"/>
          <geom name="//unnamed_geom_7" class="visual" mesh="left_thigh_yaw_link"/>
          <body name="left_thigh_pitch_link" pos="-0.006574 0.0129043 -0.0827944" quat="0.999999 -0.000736252 -0.000726039 6.80607e-06">
            <inertial pos="0.00103631 -0.0200261 -0.0380142" quat="0.999693 -0.0171471 -0.01179 0.0134219" mass="3.31444" diaginertia="0.0592184 0.00597105 0.00255763"/>
            <joint name="left_hip_pitch_joint" class="/" pos="0 0 0" axis="0.000741926 0.999999 0.00109595" range="-1.7207 0.566301" armature="0.0646262" damping="0.000102453" frictionloss="0.0740948"/>
            <geom name="//unnamed_geom_8" class="visual" mesh="left_thigh_pitch_link"/>
            <geom name="left_thigh_pitch_link.STL" class="collision" size="0.0573781 0.0874065" pos="0.000623777 -0.0179703 -0.101762" type="cylinder" rgba="0.752941 0.752941 0.752941 1"/>
            <geom name="//unnamed_geom_10" class="reward_collision_sphere" size="0.0699733" pos="0 -0.00599008 -0.0304573"/>
            <body name="left_shank_pitch_link" pos="-0.00339585 -0.00306991 -0.211931" quat="0.999999 0.00074431 0.00141451 -7.07262e-05">
              <inertial pos="-0.00904056 -0.00135971 -0.0691426" quat="0.998939 -0.00136023 0.0459621 -0.00270423" mass="0.496959" diaginertia="0.00645985 0.000903461 0.000102388"/>
              <joint name="left_knee_pitch_joint" class="/" pos="0 0 0" axis="-0.0129993 0.999523 -0.0280243" range="-0.0779594 1.76561" armature="0.0479037" damping="0.0626722" frictionloss="0.0428011"/>
              <geom name="//unnamed_geom_11" class="visual" mesh="left_shank_pitch_link"/>
              <geom name="left_shank_pitch_link.STL" class="collision" size="0.0373108 0.0632454" pos="-1.47825e-05 -0.000504693 -0.106412" quat="0.00125538 -0.202712 0.979238 0" type="cylinder" rgba="0.752941 0.752941 0.752941 1"/>
              <geom name="//unnamed_geom_13" class="reward_collision_sphere" size="0.0349867"/>
              <geom name="//unnamed_geom_14" class="reward_collision_sphere" size="0.041984" pos="0 0 -0.0670061"/>
              <body name="left_foot_pitch_link" pos="-0.001395 -0.00576479 -0.212667" quat="0.999991 -0.00305326 -0.00250157 -0.00146252">
                <inertial pos="-0.0103381 0.000698445 -0.000332564" quat="0.0404085 0.719748 0.0243002 0.692632" mass="0.0225385" diaginertia="3.67905e-06 4.45912e-07 4.07636e-07"/>
                <joint name="left_ankle_pitch_joint" class="/" pos="0 0 0" axis="0.0442278 0.99901 0.0048197" range="-1.04148 0.496505" armature="0.0745401" damping="0.00595836" frictionloss="0.0541519"/>
                <geom name="//unnamed_geom_15" class="visual" mesh="left_foot_pitch_link"/>
                <body name="left_foot_roll_link" pos="-0.00593104 -0.0028512 0.00432923" quat="1 8.03493e-05 -0.000261435 -0.000448213">
                  <inertial pos="0.0203713 -0.00213906 -0.0224634" quat="0.00329307 0.724136 -0.000201462 0.689649" mass="0.352871" diaginertia="0.00318818 0.000404653 5.20813e-05"/>
                  <joint name="left_ankle_roll_joint" class="/" pos="0 0 0" axis="-0.998855 0.013725 0.045837" range="-0.423967 0.522549" armature="0.108545" damping="0" frictionloss="0.0674961"/>
                  <geom name="//unnamed_geom_16" class="visual" mesh="left_foot_roll_link"/>
                  <geom name="left_foot" class="foot" size="0.118983 0.0291958 0.00564983" pos="0.040097 0 -0.027107"/>
                  <geom name="//unnamed_geom_18" class="reward_collision_sphere" size="0.0349867" pos="0 0 -0.0182744"/>
                  <geom name="//unnamed_geom_19" class="reward_collision_sphere" size="0.0349867" pos="0.106925 0 -0.0182744"/>
                  <site name="left_foot" class="foot" pos="0.040097 0 -0.027107" size="0.00699733"/>
                </body>
              </body>
            </body>
          </body>
        </body>
      </body>
      <body name="right_thigh_roll_link" pos="-0.0174779 -0.0658397 -0.0189339" quat="0.999995 -0.00265096 -0.00167731 0.000342937">
        <inertial pos="0.0112244 0.0130801 0.00562887" quat="0.036828 0.707789 0.0107161 0.705382" mass="0.47914" diaginertia="0.00142451 0.00014806 9.43808e-05"/>
        <joint name="right_hip_roll_joint" class="/" pos="0 0 0" axis="-0.999953 -0.0095139 -0.00207243" range="-0.242758 1.03772" armature="0.0715061" damping="0.00623409" frictionloss="0.0664667"/>
        <geom name="//unnamed_geom_20" class="visual" mesh="right_thigh_roll_link"/>
        <body name="right_thigh_yaw_link" pos="0.0234832 0.0142998 -0.000405782" quat="0.999994 -0.000921869 0.000197935 -0.00318079">
          <inertial pos="-0.00144208 -0.0321018 -0.0648026" quat="0.649534 -0.179219 0.127436 0.727837" mass="1.11425" diaginertia="0.0156738 0.00179961 0.000762981"/>
          <joint name="right_hip_yaw_joint" class="/" pos="0 0 0" axis="-0.016621 -0.0560915 -0.998287" range="-0.584094 0.962988" armature="0.0687393" damping="0.0105763" frictionloss="0.0730032"/>
          <geom name="//unnamed_geom_21" class="visual" mesh="right_thigh_yaw_link"/>
          <body name="right_thigh_pitch_link" pos="-0.00906467 -0.017031 -0.0811221" quat="0.999997 0.00136622 0.00162894 0.00148502">
            <inertial pos="-0.000212785 0.0263544 -0.0438021" quat="0.999602 -0.0130074 0.011179 0.0223948" mass="2.17481" diaginertia="0.0497854 0.00568181 0.0017293"/>
            <joint name="right_hip_pitch_joint" class="/" pos="0 0 0" axis="-0.0472535 -0.998797 -0.0130902" range="-0.714368 1.75647" armature="0.0983075" damping="0.0465739" frictionloss="0.0551673"/>
            <geom name="//unnamed_geom_22" class="visual" mesh="right_thigh_pitch_link"/>
            <geom name="right_thigh_pitch_link.STL" class="collision" size="0.0573781 0.0874044" pos="-0.00189193 0.0179703 -0.101762" quat="0.999971 0.00269833 0.00706272 0" type="cylinder" rgba="0.752941 0.752941 0.752941 1"/>
            <geom name="//unnamed_geom_24" class="reward_collision_sphere" size="0.0699733" pos="0 0.00599008 -0.0304573"/>
            <body name="right_shank_pitch_link" pos="-0.00440137 0.0265691 -0.221014" quat="0.999972 0.00730458 -0.0015569 -0.000365109">
              <inertial pos="0.00277223 -0.010834 -0.0729199" quat="0.999538 0.0181504 0.00378238 0.0240686" mass="0.763792" diaginertia="0.00683451 0.000838227 0.000131438"/>
              <joint name="right_knee_pitch_joint" class="/" pos="0 0 0" axis="-0.00458269 -0.999986 0.00279712" range="-1.88237 0.361177" armature="0.0687512" damping="0.0245923" frictionloss="0.0656355"/>
              <geom name="//unnamed_geom_25" class="visual" mesh="right_shank_pitch_link"/>
              <geom name="right_shank_pitch_link.STL" class="collision" size="0.0373105 0.0632448" pos="-1.47825e-05 -0.000504699 -0.106417" type="cylinder" rgba="0.752941 0.752941 0.752941 1"/>
              <geom name="//unnamed_geom_27" class="reward_collision_sphere" size="0.0349867"/>
              <geom name="//unnamed_geom_28" class="reward_collision_sphere" size="0.041984" pos="0 0 -0.0670061"/>
              <body name="right_foot_pitch_link" pos="0.00669488 -5.03127e-05 -0.204568" quat="1 -4.06731e-05 0.000120336 -3.93221e-05">
                <inertial pos="0.00176925 0.00725678 -0.00131913" quat="0.00123531 0.709923 0.000430198 0.704278" mass="0.0218569" diaginertia="3.75404e-06 4.89229e-07 4.95838e-07"/>
                <joint name="right_ankle_pitch_joint" class="/" pos="0 0 0" axis="0.0285218 -0.999558 -0.00838589" range="-0.462829 1.07895" armature="0.0524696" damping="0" frictionloss="0.0363256"/>
                <geom name="//unnamed_geom_29" class="visual" mesh="right_foot_pitch_link"/>
                <body name="right_foot_roll_link" pos="0.000116323 0.00741591 0.00732327" quat="0.999983 0.0023107 0.00518004 -0.00117435">
                  <inertial pos="0.0329904 0.0144063 -0.0104888" quat="-0.00131527 0.725332 0.00325185 0.688391" mass="0.322861" diaginertia="0.00295792 0.000419073 8.00773e-05"/>
                  <joint name="right_ankle_roll_joint" class="/" pos="0 0 0" axis="-0.997627 -0.068832 0.00186384" range="-0.619519 0.57014" armature="0.034456" damping="0" frictionloss="0.0658571"/>
                  <geom name="//unnamed_geom_30" class="visual" mesh="right_foot_roll_link"/>
                  <geom name="right_foot" class="foot" size="0.130633 0.0221298 0.00689464" pos="0.040097 0 -0.027107"/>
                  <geom name="//unnamed_geom_32" class="reward_collision_sphere" size="0.0349867" pos="0 0 -0.0182744"/>
                  <geom name="//unnamed_geom_33" class="reward_collision_sphere" size="0.0349867" pos="0.106925 0 -0.0182744"/>
                  <site name="right_foot" class="foot" pos="0.040097 0 -0.027107" size="0.00699733"/>
                </body>
              </body>
            </body>
          </body>
        </body>
      </body>
      <body name="waist_yaw_link" pos="0.00722837 0.00046266 0.0069198" quat="0.999995 -0.00206344 0.00095211 0.00205285">
        <inertial pos="-0.00271695 -0.0108553 0.0317634" quat="0.979837 0.188561 -0.0289877 0.0593623" mass="0.492334" diaginertia="0.00151994 0.00024865 0.000131353"/>
        <joint name="waist_yaw_joint" class="/" pos="0 0 0" axis="-0.0243529 -0.056411 0.998111" range="-0.814213 1.07227" armature="0.0565931" damping="0" frictionloss="0.0548208"/>
        <geom name="//unnamed_geom_34" class="visual" rgba="0.12 0.12 0.12 1" mesh="waist_yaw_link"/>
        <body name="waist_pitch_link" pos="0.00706506 -0.00581448 0.0397856" quat="0.999996 -0.002162 -0.00100394 0.00142568">
          <inertial pos="0.0108614 -0.00298432 0.0296542" quat="0.997647 -0.0541157 0.0411163 0.00903496" mass="0.525573" diaginertia="0.0023474 0.000291476 0.000166417"/>
          <joint name="waist_pitch_joint" class="/" pos="0 0 0" axis="-0.0386947 -0.998147 0.0469625" range="-1.1834 0.231351" armature="0.0719091" damping="0" frictionloss="0.0653893"/>
          <geom name="//unnamed_geom_35" class="visual" rgba="0.12 0.12 0.12 1" mesh="waist_pitch_link"/>
          <body name="waist_roll_link" pos="0.0165145 -0.00070865 0.0373776" quat="0.999999 0.000934058 0.000553804 0.000330269">
            <inertial pos="-0.0172606 -0.0032092 0.0807731" quat="0.99697 0.0632589 -0.0350155 0.028672" mass="2.97002" diaginertia="0.0384922 0.00573576 0.00343866"/>
            <joint name="waist_roll_joint" class="/" pos="0 0 0" axis="-0.999999 -0.000426515 0.00142442" range="-0.405707 0.87434" armature="0.060279" damping="0.000822898" frictionloss="0.0486753"/>
            <geom name="//unnamed_geom_36" class="visual" rgba="0.12 0.12 0.12 1" mesh="waist_roll_link"/>
            <geom name="//unnamed_geom_37" class="visual" pos="-0.00200485 0.000344088 0.0976766" quat="1 0 0 0" mesh="torso_link"/>
            <geom name="torso_link.STL" class="collision" size="0.110157 0.021127" pos="-0.0160975 0.00345616 0.0900495" type="cylinder" rgba="0.752941 0.752941 0.752941 1"/>
            <geom name="//unnamed_geom_39" class="reward_collision_sphere" size="0.0909653" pos="0 0 0.121829"/>
            <body name="left_upper_arm_pitch_link" pos="0.00781983 0.069727 0.125813" quat="0.97546 0.220177 -0.000805422 -0.000439217">
              <inertial pos="-0.00979352 0.0328394 0.00592305" quat="0.732848 0.678359 0.0349914 -0.0392331" mass="0.25316" diaginertia="0.00118706 0.000146074 4.73407e-05"/>
              <joint name="left_shoulder_pitch_joint" class="/" pos="0 0 0" axis="0.00119474 0.999998 0.00136597" range="-2.77976 1.94454" armature="0.0409694" damping="0.0556884" frictionloss="0.0663528"/>
              <geom name="//unnamed_geom_40" class="visual" mesh="left_upper_arm_pitch_link"/>
              <body name="left_upper_arm_roll_link" pos="-0.0109189 0.0667811 -0.00152672" quat="0.976305 -0.216384 0.000201722 -0.00233728">
                <inertial pos="0.00416019 0.0235823 -0.0157534" quat="0.912748 0.224052 0.119835 -0.319894" mass="0.196819" diaginertia="0.000658374 8.39381e-05 3.23175e-05"/>
                <joint name="left_shoulder_roll_joint" class="/" pos="0 0 0" axis="-0.999752 -0.0219094 0.00394367" range="-2.45913 0.757382" armature="0.113667" damping="0" frictionloss="0.0733766"/>
                <geom name="//unnamed_geom_41" class="visual" mesh="left_upper_arm_roll_link"/>
                <body name="left_upper_arm_yaw_link" pos="-0.0115281 0.0159296 -0.0525969" quat="0.99998 0.00391529 0.00411026 -0.00265149">
                  <inertial pos="-0.000122665 0.00901872 -0.0517874" quat="0.998656 0.0165423 0.0429446 0.0238358" mass="0.179106" diaginertia="0.00145305 0.00021986 1.87231e-05"/>
                  <joint name="left_shoulder_yaw_joint" class="/" pos="0 0 0" axis="0.000295431 -0.00159323 0.999999" stiffness="0.00253597" range="-2.99425 2.79184" armature="0.104663" damping="0.00983139" frictionloss="0.107371"/>
                  <geom name="//unnamed_geom_42" class="visual" mesh="left_upper_arm_yaw_link"/>
                  <geom name="left_upper_arm_yaw_link.STL" class="collision" size="0.0253536 0.0594367" pos="3.51833e-05 -0.000535687 -0.0483297" quat="0.00803418 -0.995528 0.0941277 0" type="cylinder" rgba="0.752941 0.752941 0.752941 1"/>
                  <body name="left_lower_arm_pitch_link" pos="0.00978339 0.0111538 -0.0965151" quat="1 0.000208517 0.000580997 -0.000438761">
                    <inertial pos="-0.00222008 -0.000780712 -0.0269307" quat="0.700427 -0.0962152 0.0955952 0.700719" mass="0.0877788" diaginertia="0.000129962 2.04143e-05 8.67347e-06"/>
                    <joint name="left_elbow_pitch_joint" class="/" pos="0 0 0" axis="-0.0107882 0.99993 0.00481361" range="-2.28661 2.07217" armature="0.0359106" damping="0.018297" frictionloss="0.0415193"/>
                    <geom name="//unnamed_geom_44" class="visual" mesh="left_lower_arm_pitch_link"/>
                    <body name="left_hand_yaw_link" pos="-0.00236704 0.0024882 -0.0363875" quat="0.999974 -0.00571102 -0.00176274 0.00402088">
                      <inertial pos="-0.00810809 -0.00726725 -0.0436344" quat="0.999975 -0.00389551 -0.00401751 0.00429873" mass="0.319594" diaginertia="0.00144361 0.000201995 3.78481e-05"/>
                      <joint name="left_wrist_yaw_joint" class="/" pos="0 0 0" axis="0.00520353 -0.00384532 0.999979" range="-2.9587 3.07321" armature="0.0764471" damping="0" frictionloss="0.0689443"/>
                      <geom name="//unnamed_geom_45" class="visual" mesh="left_hand_yaw_link"/>
                      <geom name="left_hand_yaw_link.STL" class="collision" size="0.0290892 0.048697" pos="0.000970571 -0.000923138 -0.0463213" type="cylinder" rgba="0.752941 0.752941 0.752941 1"/>
                      <geom name="//unnamed_geom_47" class="reward_collision_sphere" size="0.0349867"/>
                      <body name="left_hand_roll_link" pos="-0.00135784 -0.0143607 -0.129051" quat="0.999993 -0.000608562 0.00332593 -0.00178785">
                        <inertial pos="-0.00205637 -0.0008742 -0.00467413" quat="0.502682 0.496927 0.504411 0.495927" mass="0.00185577" diaginertia="2.28159e-07 3.27596e-08 6.87204e-09"/>
                        <joint name="left_wrist_roll_joint" class="/" pos="0 0 0" axis="-0.999981 -0.00593778 0.00177551" stiffness="0.0553049" range="-0.960601 0.892903" armature="0.121604" damping="0.0139758" frictionloss="0.0719225"/>
                        <geom name="//unnamed_geom_48" class="visual" mesh="left_hand_roll_link"/>
                        <body name="left_hand_pitch_link" pos="-0.0118427 0.00228354 0.000194911" quat="1 -7.37975e-05 -0.000165444 0.000475562">
                          <inertial pos="0.00193884 0.00661064 -0.0247586" quat="0.723308 -0.121429 0.114679 0.670022" mass="0.0750605" diaginertia="0.000162421 2.01721e-05 6.65121e-06"/>
                          <joint name="left_wrist_pitch_joint" class="/" pos="0 0 0" axis="-0.00640649 0.999915 -0.0113923" range="-0.768033 0.886707" armature="0.110528" damping="0.038837" frictionloss="0.0688992"/>
                          <geom name="//unnamed_geom_49" class="visual" mesh="left_hand_pitch"/>
                          <body name="left_jaw_link" pos="-0.0139373 -0.0125952 -0.037243" quat="0.999991 -0.00195126 -0.00224746 0.00298855">
                            <inertial pos="-0.00131313 -0.00210721 -0.0142244" quat="0.719928 -0.0480632 0.0218849 0.692036" mass="0.0204244" diaginertia="4.28648e-05 4.24852e-06 2.31472e-06"/>
                            <joint name="left_jaw_joint" class="/" pos="0 0 0" axis="-0.997378 0.00224655 0.0723379" range="-1.14906 0.220451" armature="0.0546377" damping="0.00266842" frictionloss="0.0666584"/>
                            <geom name="//unnamed_geom_50" class="visual" mesh="left_jaw_link"/>
                            <geom name="//unnamed_geom_51" class="collision" size="0.0251904"/>
                            <geom name="//unnamed_geom_52" class="reward_collision_sphere" size="0.0349867" pos="0 0 -0.0121829"/>
                          </body>
                        </body>
                      </body>
                    </body>
                  </body>
                </body>
              </body>
            </body>
            <body name="right_upper_arm_pitch_link" pos="-0.000901249 -0.0608644 0.1313" quat="0.976945 -0.213488 -0.000193242 -0.000930042">
              <inertial pos="0.0115141 -0.0434059 0.00903284" quat="0.700828 0.712969 0.0199677 0.0107988" mass="0.35353" diaginertia="0.00138406 0.000158255 4.99536e-05"/>
              <joint name="right_shoulder_pitch_joint" class="/" pos="0 0 0" axis="-0.000620447 -0.999536 -0.0304412" range="-2.01465 3.00643" armature="0.0440869" damping="0.000382661" frictionloss="0.0691587"/>
              <geom name="//unnamed_geom_53" class="visual" mesh="right_upper_arm_pitch_link"/>
              <body name="right_upper_arm_roll_link" pos="0.000695568 -0.06851 -0.0108081" quat="0.976255 0.216551 0.00237737 0.00512761">
                <inertial pos="0.0158613 -0.0173916 -0.0223303" quat="0.895048 -0.213439 0.163704 0.355718" mass="0.185436" diaginertia="0.000478618 7.18272e-05 2.12454e-05"/>
                <joint name="right_shoulder_roll_joint" class="/" pos="0 0 0" axis="-0.999992 -0.00387178 -0.00130051" stiffness="0.0263877" range="-0.746507 2.52969" armature="0.0474619" damping="0.0642841" frictionloss="0.0191877"/>
                <geom name="//unnamed_geom_54" class="visual" mesh="right_upper_arm_roll_link"/>
                <body name="right_upper_arm_yaw_link" pos="-0.00099382 -0.0235718 -0.0335383" quat="0.99998 -0.00284667 0.00505238 0.00258075">
                  <inertial pos="0.0041289 -0.00122989 -0.0654481" quat="0.998023 -0.0500986 -0.0318347 -0.0206671" mass="0.191119" diaginertia="0.00203908 0.000258475 1.84147e-05"/>
                  <joint name="right_shoulder_yaw_joint" class="/" pos="0 0 0" axis="0.0317659 -0.0415171 0.998633" stiffness="0.0122251" range="-2.99035 2.79383" armature="0.017873" damping="0" frictionloss="0.0706959"/>
                  <geom name="//unnamed_geom_55" class="visual" mesh="right_upper_arm_yaw_link"/>
                  <geom name="right_upper_arm_yaw_link.STL" class="collision" size="0.0253536 0.0594367" pos="3.51833e-05 0.000535687 -0.0483297" type="cylinder" rgba="0.752941 0.752941 0.752941 1"/>
                  <body name="right_lower_arm_pitch_link" pos="0.0101607 0.0128213 -0.0993489" quat="0.999997 4.82833e-06 -0.00192579 0.00170173">
                    <inertial pos="-0.000245264 0.00336627 -0.0111279" quat="0.695616 0.0926056 -0.0962733 0.705885" mass="0.110675" diaginertia="0.000156958 2.58513e-05 7.87066e-06"/>
                    <joint name="right_elbow_pitch_joint" class="/" pos="0 0 0" axis="0.00216572 -0.999781 -0.02082" range="-2.27856 2.27944" armature="0.0966194" damping="0.00105382" frictionloss="0.0722324"/>
                    <geom name="//unnamed_geom_57" class="visual" mesh="right_lower_arm_pitch_link"/>
                    <body name="right_hand_yaw_link" pos="0.00077672 0.00333205 -0.0488259" quat="1 0.00040926 -0.000444668 0.000178922">
                      <inertial pos="-0.0125841 -0.0145048 -0.0433878" quat="0.99931 0.0153109 0.0336018 -0.0039895" mass="0.301851" diaginertia="0.00123224 0.000193316 4.35167e-05"/>
                      <joint name="right_wrist_yaw_joint" class="/" pos="0 0 0" axis="0.00470778 0.0187411 0.999813" stiffness="0.00382105" range="-2.75886 2.74146" armature="0.106083" damping="0" frictionloss="0.1037"/>
                      <geom name="//unnamed_geom_58" class="visual" mesh="right_hand_yaw_link"/>
                      <geom name="right_hand_yaw_link.STL" class="collision" size="0.0290892 0.048697" pos="0.000970571 0.000384033 -0.0463213" type="cylinder" rgba="0.752941 0.752941 0.752941 1"/>
                      <geom name="//unnamed_geom_60" class="reward_collision_sphere" size="0.0349867"/>
                      <body name="right_hand_roll_link" pos="0.0126403 0.00374055 -0.129722" quat="1 -0.000680779 0.000356468 8.84334e-05">
                        <inertial pos="0.0013583 0.011862 0.00361928" quat="0.513245 0.509707 0.464764 0.51066" mass="0.00176066" diaginertia="1.95666e-07 3.14291e-08 6.16983e-09"/>
                        <joint name="right_wrist_roll_joint" class="/" pos="0 0 0" axis="-0.997967 0.0339776 -0.0539233" stiffness="0.00137985" range="-0.896786 0.678471" armature="0.0202536" damping="0.0343846" frictionloss="0.116447"/>
                        <geom name="//unnamed_geom_61" class="visual" mesh="right_hand_roll_link"/>
                        <body name="right_hand_pitch_link" pos="0.0105015 0.0041089 0.0144463" quat="0.999976 -0.00651956 -0.00113422 0.00201497">
                          <inertial pos="0.00267785 0.016321 -0.03177" quat="0.761464 0.111184 -0.109282 0.629181" mass="0.100177" diaginertia="0.000181127 2.6644e-05 9.73672e-06"/>
                          <joint name="right_wrist_pitch_joint" class="/" pos="0 0 0" axis="-0.0256183 -0.998931 0.0384907" stiffness="0.0373913" range="-0.44228 0.356499" armature="0.109195" damping="0" frictionloss="0.0967753"/>
                          <geom name="//unnamed_geom_62" class="visual" mesh="right_hand_pitch"/>
                          <body name="right_jaw_link" pos="-0.0111268 0.00188396 -0.047894" quat="1 0.000395892 1.30883e-05 0.00044855">
                            <inertial pos="-0.00831971 -0.0132034 -0.0217299" quat="0.707726 0.019212 -0.0296523 0.705603" mass="0.0276682" diaginertia="4.49008e-05 4.09022e-06 2.75559e-06"/>
                            <joint name="right_jaw_joint" class="/" pos="0 0 0" axis="-0.999764 0.0073729 0.0204252" stiffness="0.0713734" range="0.185775 1.08399" armature="0.0579217" damping="0.00248761" frictionloss="0.100648"/>
                            <geom name="//unnamed_geom_63" class="visual" mesh="right_jaw_link"/>
                            <geom name="//unnamed_geom_64" class="collision" size="0.0251904"/>
                            <geom name="//unnamed_geom_65" class="reward_collision_sphere" size="0.0349867" pos="0 0 -0.0121829"/>
                          </body>
                        </body>
                      </body>
                    </body>
                  </body>
                </body>
              </body>
            </body>
            <body name="head_roll_link" pos="0.0124289 -0.00839057 0.189927" quat="1 -3.48279e-05 -8.93396e-05 -0.000320717">
              <inertial pos="0.0134057 -0.00172471 -0.0132936" quat="0.00735807 0.693859 -0.0409624 0.718907" mass="0.00363389" diaginertia="4.00706e-07 3.81502e-08 4.12937e-08"/>
              <joint name="head_roll_joint" class="/" pos="0 0 0" axis="-0.997288 -0.0541513 -0.049851" stiffness="0.0694557" range="-0.102935 0.335409" armature="0.0663195" damping="0.00508866" frictionloss="0.121073"/>
              <geom name="//unnamed_geom_66" class="visual" mesh="head_roll_link"/>
              <body name="head_pitch_link" pos="0.00215535 -0.000741209 0.00370615" quat="1 -0.000380976 -0.000431094 0.000370257">
                <inertial pos="0.00937969 0.00800108 -0.00213354" quat="0.663259 0.66454 0.253795 -0.232515" mass="0.0239345" diaginertia="1.45365e-05 2.12346e-06 1.94247e-06"/>
                <joint name="head_pitch_joint" class="/" pos="0 0 0" axis="-0.0052867 -0.999888 0.0139831" stiffness="0.0127048" range="-1.08574 0.956111" armature="0.0786904" damping="0.00976491" frictionloss="0.121764"/>
                <geom name="//unnamed_geom_67" class="visual" mesh="head_pitch_link"/>
                <body name="head_yaw_link" pos="0.000698458 0.00691212 0.0332101" quat="0.99999 -0.00264976 0.00284447 0.00200115">
                  <inertial pos="0.0306434 -0.00899356 0.0453133" quat="0.675175 -0.127821 -0.144426 0.711999" mass="0.576823" diaginertia="0.00548939 0.000619137 0.000388202"/>
                  <joint name="head_yaw_joint" class="/" pos="0 0 0" axis="-0.0193051 -0.0137292 0.999719" range="-2.97772 2.50301" armature="0.0284497" damping="0" frictionloss="0.0724617"/>
                  <geom name="//unnamed_geom_68" class="visual" rgba="0.12 0.12 0.12 1" mesh="head_yaw_link"/>
                  <geom name="head_yaw_link.STL" class="collision" size="0.0830492" pos="0.0162893 -0.000527142 0.0570284" rgba="0.752941 0.752941 0.752941 1"/>
                  <geom name="//unnamed_geom_70" class="reward_collision_sphere" size="0.0699733" pos="0.0267313 0 0.0609146"/>
                  <camera name="ego_camera" class="/" pos="0.0980149 0 0.0670061" quat="-0.5 -0.5 0.5 0.5"/>
                </body>
              </body>
            </body>
          </body>
        </body>
      </body>
    </body>
  </worldbody>

  <contact>
    <pair class="/" geom1="floor" geom2="left_foot" name="//unnamed_contact_0"/>
    <pair class="/" geom1="floor" geom2="right_foot" name="//unnamed_contact_1"/>
  </contact>

  <actuator>
    <general name="left_hip_roll" class="/" joint="left_hip_roll_joint" forcerange="-33.5736 33.5736" gainprm="55.9505" biasprm="0 -55.9505 -1.07316"/>
    <general name="left_hip_yaw" class="/" joint="left_hip_yaw_joint" forcerange="-42.6068 42.6068" gainprm="55.9505" biasprm="0 -55.9505 -1.07316"/>
    <general name="left_hip_pitch" class="/" joint="left_hip_pitch_joint" forcerange="-228.259 228.259" gainprm="55.9505" biasprm="0 -55.9505 -1.07316"/>
    <general name="left_knee_pitch" class="/" joint="left_knee_pitch_joint" forcerange="-156.698 156.698" gainprm="55.9505" biasprm="0 -55.9505 -1.07316"/>
    <general name="left_ankle_pitch" class="/" joint="left_ankle_pitch_joint" forcerange="-5.37865 5.37865" gainprm="55.9505" biasprm="0 -55.9505 -1.07316"/>
    <general name="left_ankle_roll" class="/" joint="left_ankle_roll_joint" forcerange="-21.1237 21.1237" gainprm="55.9505" biasprm="0 -55.9505 -1.07316"/>
    <general name="right_hip_roll" class="/" joint="right_hip_roll_joint" forcerange="-32.6789 32.6789" gainprm="55.9505" biasprm="0 -55.9505 -1.07316"/>
    <general name="right_hip_yaw" class="/" joint="right_hip_yaw_joint" forcerange="-59.7537 59.7537" gainprm="55.9505" biasprm="0 -55.9505 -1.07316"/>
    <general name="right_hip_pitch" class="/" joint="right_hip_pitch_joint" forcerange="-232.876 232.876" gainprm="55.9505" biasprm="0 -55.9505 -1.07316"/>
    <general name="right_knee_pitch" class="/" joint="right_knee_pitch_joint" forcerange="-170.989 170.989" gainprm="55.9505" biasprm="0 -55.9505 -1.07316"/>
    <general name="right_ankle_pitch" class="/" joint="right_ankle_pitch_joint" forcerange="-10.0608 10.0608" gainprm="55.9505" biasprm="0 -55.9505 -1.07316"/>
    <general name="right_ankle_roll" class="/" joint="right_ankle_roll_joint" forcerange="-20.5156 20.5156" gainprm="55.9505" biasprm="0 -55.9505 -1.07316"/>
    <general name="waist_yaw" class="/" joint="waist_yaw_joint" forcerange="-32.0325 32.0325" gainprm="55.9505" biasprm="0 -55.9505 -1.07316"/>
    <general name="waist_pitch" class="/" joint="waist_pitch_joint" forcerange="-54.1917 54.1917" gainprm="55.9505" biasprm="0 -55.9505 -1.07316"/>
    <general name="waist_roll" class="/" joint="waist_roll_joint" forcerange="-47.3643 47.3643" gainprm="55.9505" biasprm="0 -55.9505 -1.07316"/>
    <general name="left_shoulder_pitch" class="/" joint="left_shoulder_pitch_joint" forcerange="-27.0556 27.0556" gainprm="55.9505" biasprm="0 -55.9505 -1.07316"/>
    <general name="left_shoulder_roll" class="/" joint="left_shoulder_roll_joint" forcerange="-31.673 31.673" gainprm="55.9505" biasprm="0 -55.9505 -1.07316"/>
    <general name="left_shoulder_yaw" class="/" joint="left_shoulder_yaw_joint" forcerange="-20.2482 20.2482" gainprm="55.9505" biasprm="0 -55.9505 -1.07316"/>
    <general name="left_elbow_pitch" class="/" joint="left_elbow_pitch_joint" forcerange="-23.572 23.572" gainprm="55.9505" biasprm="0 -55.9505 -1.07316"/>
    <general name="left_wrist_yaw" class="/" joint="left_wrist_yaw_joint" forcerange="-6.57405 6.57405" gainprm="55.9505" biasprm="0 -55.9505 -1.07316"/>
    <general name="left_wrist_roll" class="/" joint="left_wrist_roll_joint" forcerange="-1.99069 1.99069" gainprm="55.9505" biasprm="0 -55.9505 -1.07316"/>
    <general name="left_wrist_pitch" class="/" joint="left_wrist_pitch_joint" forcerange="-2.6418 2.6418" gainprm="55.9505" biasprm="0 -55.9505 -1.07316"/>
    <general name="left_jaw" class="/" joint="left_jaw_joint" forcerange="-3.97643 3.97643" gainprm="55.9505" biasprm="0 -55.9505 -1.07316"/>
    <general name="right_shoulder_pitch" class="/" joint="right_shoulder_pitch_joint" forcerange="-19.1118 19.1118" gainprm="55.9505" biasprm="0 -55.9505 -1.07316"/>
    <general name="right_shoulder_roll" class="/" joint="right_shoulder_roll_joint" forcerange="-17.5716 17.5716" gainprm="55.9505" biasprm="0 -55.9505 -1.07316"/>
    <general name="right_shoulder_yaw" class="/" joint="right_shoulder_yaw_joint" forcerange="-19.1308 19.1308" gainprm="55.9505" biasprm="0 -55.9505 -1.07316"/>
    <general name="right_elbow_pitch" class="/" joint="right_elbow_pitch_joint" forcerange="-28.4148 28.4148" gainprm="55.9505" biasprm="0 -55.9505 -1.07316"/>
    <general name="right_wrist_yaw" class="/" joint="right_wrist_yaw_joint" forcerange="-7.39606 7.39606" gainprm="55.9505" biasprm="0 -55.9505 -1.07316"/>
    <general name="right_wrist_roll" class="/" joint="right_wrist_roll_joint" forcerange="-2.74331 2.74331" gainprm="55.9505" biasprm="0 -55.9505 -1.07316"/>
    <general name="right_wrist_pitch" class="/" joint="right_wrist_pitch_joint" forcerange="-2.71279 2.71279" gainprm="55.9505" biasprm="0 -55.9505 -1.07316"/>
    <general name="right_jaw" class="/" joint="right_jaw_joint" forcerange="-2.55552 2.55552" gainprm="55.9505" biasprm="0 -55.9505 -1.07316"/>
    <general name="head_roll" class="/" joint="head_roll_joint" forcerange="-2.64886 2.64886" gainprm="55.9505" biasprm="0 -55.9505 -1.07316"/>
    <general name="head_pitch" class="/" joint="head_pitch_joint" forcerange="-2.83955 2.83955" gainprm="55.9505" biasprm="0 -55.9505 -1.07316"/>
    <general name="head_yaw" class="/" joint="head_yaw_joint" forcerange="-1.819 1.819" gainprm="55.9505" biasprm="0 -55.9505 -1.07316"/>
  </actuator>

  <sensor>
    <gyro site="imu" name="imu_angular_velocity"/>
    <velocimeter site="imu" name="imu_linear_velocity"/>
    <framelinvel objtype="site" objname="left_foot" name="left_foot_global_linear_velocity"/>
    <framelinvel objtype="site" objname="right_foot" name="right_foot_global_linear_velocity"/>
  </sensor>

  <keyframe>
    <key name="home" qpos="0 0 0.8665 1 0 0 0 0 0 -0.4 0.8 -0.4 0 0 0 0.4 -0.8 0.4 0 0 0 0 0 -0.2 0 -0.785 0 0 0 0 0 0.2 0 0.785 0 0 0 0 0 0 0"/>
  </keyframe>
</mujoco>
