<mujoco model="GR1T2_jaw">
  <compiler angle="radian" assetdir="assets" balanceinertia="true" inertiafromgeom="false"/>

  <option timestep="0.005" density="1.2" viscosity="2e-05"/>

  <size nkey="1"/>

  <visual>
    <quality shadowsize="8192"/>
    <map shadowclip="0.5"/>
  </visual>

  <default>
    <default class="/">
      <joint armature="0.1" damping="0.01" frictionloss="0.1"/>
      <geom contype="0" conaffinity="0" group="1" solref="-1000 -80"/>
      <site size="0.01 0.005 0.005" group="5"/>
      <general forcelimited="true" biastype="affine" gainprm="80" biasprm="0 -80 -2"/>
      <default class="visual">
        <geom type="mesh" density="0" rgba="0.18 0.18 0.18 1"/>
      </default>
      <default class="collision">
        <geom group="3"/>
      </default>
      <default class="foot">
        <geom size="0.126 0.045 0.01" type="box" condim="6" group="4" priority="1" solimp="0.015 1 0.01"/>
      </default>
      <default class="reward_collision_sphere">
        <geom group="5" rgba="1 0 0 1"/>
      </default>
    </default>
  </default>

  <asset>
    <texture type="skybox" colorspace="auto" name="//unnamed_texture_0" builtin="gradient" rgb1="0.95 0.95 0.95" rgb2="0.95 0.95 0.95" width="100" height="600"/>
    <texture type="2d" colorspace="auto" name="texplane" builtin="checker" rgb1="0.345 0.575 0.748" rgb2="0.345 0.575 0.748" markrgb="1 1 1" width="512" height="512"/>
    <material name="MatPlane" class="/" texture="texplane" texuniform="true" texrepeat="2 2" specular="0.9"/>
    <mesh name="base_link" class="/" file="base_link.STL"/>
    <mesh name="left_thigh_roll_link" class="/" file="left_thigh_roll_link.STL"/>
    <mesh name="left_thigh_yaw_link" class="/" file="left_thigh_yaw_link.STL"/>
    <mesh name="left_thigh_pitch_link" class="/" file="left_thigh_pitch_link.STL"/>
    <mesh name="left_shank_pitch_link" class="/" file="left_shank_pitch_link.STL"/>
    <mesh name="left_foot_pitch_link" class="/" file="left_foot_pitch_link.STL"/>
    <mesh name="left_foot_roll_link" class="/" file="left_foot_roll_link.STL"/>
    <mesh name="right_thigh_roll_link" class="/" file="right_thigh_roll_link.STL"/>
    <mesh name="right_thigh_yaw_link" class="/" file="right_thigh_yaw_link.STL"/>
    <mesh name="right_thigh_pitch_link" class="/" file="right_thigh_pitch_link.STL"/>
    <mesh name="right_shank_pitch_link" class="/" file="right_shank_pitch_link.STL"/>
    <mesh name="right_foot_pitch_link" class="/" file="right_foot_pitch_link.STL"/>
    <mesh name="right_foot_roll_link" class="/" file="right_foot_roll_link.STL"/>
    <mesh name="waist_yaw_link" class="/" file="waist_yaw_link.STL"/>
    <mesh name="waist_pitch_link" class="/" file="waist_pitch_link.STL"/>
    <mesh name="waist_roll_link" class="/" file="waist_roll_link.STL"/>
    <mesh name="torso_link" class="/" file="torso_link.STL"/>
    <mesh name="left_upper_arm_pitch_link" class="/" file="left_upper_arm_pitch_link.STL"/>
    <mesh name="left_upper_arm_roll_link" class="/" file="left_upper_arm_roll_link.STL"/>
    <mesh name="left_upper_arm_yaw_link" class="/" file="left_upper_arm_yaw_link.STL"/>
    <mesh name="left_lower_arm_pitch_link" class="/" file="left_lower_arm_pitch_link.STL"/>
    <mesh name="left_hand_yaw_link" class="/" file="left_hand_yaw_link.STL"/>
    <mesh name="left_hand_roll_link" class="/" file="left_hand_roll_link.STL"/>
    <mesh name="left_hand_pitch" class="/" file="left_hand_pitch.STL"/>
    <mesh name="left_jaw_link" class="/" file="left_jaw_link.STL"/>
    <mesh name="right_upper_arm_pitch_link" class="/" file="right_upper_arm_pitch_link.STL"/>
    <mesh name="right_upper_arm_roll_link" class="/" file="right_upper_arm_roll_link.STL"/>
    <mesh name="right_upper_arm_yaw_link" class="/" file="right_upper_arm_yaw_link.STL"/>
    <mesh name="right_lower_arm_pitch_link" class="/" file="right_lower_arm_pitch_link.STL"/>
    <mesh name="right_hand_yaw_link" class="/" file="right_hand_yaw_link.STL"/>
    <mesh name="right_hand_roll_link" class="/" file="right_hand_roll_link.STL"/>
    <mesh name="right_hand_pitch" class="/" file="right_hand_pitch.STL"/>
    <mesh name="right_jaw_link" class="/" file="right_jaw_link.STL"/>
    <mesh name="head_roll_link" class="/" file="head_roll_link.STL"/>
    <mesh name="head_pitch_link" class="/" file="head_pitch_link.STL"/>
    <mesh name="head_yaw_link" class="/" file="head_yaw_link.STL"/>
    <mesh name="imu_link" class="/" file="imu_link.STL"/>
  </asset>

  <worldbody>
    <geom name="floor" class="/" size="100 100 0.125" type="plane" group="0" material="MatPlane"/>
    <light name="toplight_shadow" class="/" pos="0 0 5" dir="0.0990148 0.0990148 -0.990148" type="directional" ambient="0.04 0.04 0.04" diffuse="0.55 0.55 0.55" specular="0.12 0.12 0.12"/>
    <light name="toplight_fill" class="/" pos="0 0 5" dir="0.0990148 0.0990148 -0.990148" type="directional" castshadow="false" ambient="0.04 0.04 0.04" diffuse="0.3 0.3 0.3" specular="0.08 0.08 0.08"/>
    <body name="trunk" pos="-0.000748343 0.000353854 -0.00100287" quat="1 4.03814e-05 2.58517e-05 7.05551e-05">
      <inertial pos="-0.0632858 0.000817074 -0.00933193" quat="1 0.000360848 -0.000254733 0.000287318" mass="3.43894" diaginertia="0.0538937 0.0100227 0.01848"/>
      <joint name="//unnamed_joint_0" type="free"/>
      <geom name="//unnamed_geom_1" class="visual" rgba="0.12 0.12 0.12 1" mesh="base_link"/>
      <geom name="base_link.STL" class="collision" size="0.116102 0.0650267" pos="-0.0449702 0.000349968 0.00777308" quat="0.706838 -0.707359 0.00477667 0" type="cylinder" rgba="0.752941 0.752941 0.752941 1"/>
      <geom name="//unnamed_geom_3" class="visual" pos="0 0 -0.0503009" quat="1 0 0 0" rgba="0.12 0.12 0.12 1" mesh="imu_link"/>
      <geom name="//unnamed_geom_4" class="reward_collision_sphere" size="0.0758877" pos="0 0.0945753 0.0843974"/>
      <geom name="//unnamed_geom_5" class="reward_collision_sphere" size="0.0758877" pos="0 -0.0945753 0.0843974"/>
      <site name="imu" class="/" pos="0.000486465 -0.00149082 -0.0507029" size="0.00948596"/>
      <camera name="track" class="/" pos="0 -1.89151 0" quat="0.707107 0.707107 0 0" mode="trackcom"/>
      <body name="left_thigh_roll_link" pos="-0.0364263 0.0983856 -0.0215013" quat="1 0.000228729 -9.80856e-05 0.000182015">
        <inertial pos="0.00128213 -5.61289e-05 0.00202537" quat="-0.0298161 0.704805 -0.0342172 0.707947" mass="1.2487" diaginertia="0.00339046 0.00189222 0.000678557"/>
        <joint name="left_hip_roll_joint" class="/" pos="0 0 0" axis="-0.999996 0.00282324 0.000573843" range="-0.79818 0.0817696" armature="0.0898627" damping="0.00426879" frictionloss="0.0912531"/>
        <geom name="//unnamed_geom_6" class="visual" mesh="left_thigh_roll_link"/>
        <body name="left_thigh_yaw_link" pos="0.0327045 -0.000795536 0.00119362" quat="1 0.000169073 0.00015615 -1.62787e-05">
          <inertial pos="-0.0032612 0.0362329 -0.0922782" quat="0.572475 0.093162 -0.190686 0.79198" mass="2.98994" diaginertia="0.0317465 0.0147794 0.00384676"/>
          <joint name="left_hip_yaw_joint" class="/" pos="0 0 0" axis="-0.00270637 -0.0061225 -0.999978" range="-0.721955 0.706208" armature="0.0972071" damping="0" frictionloss="0.0927997"/>
          <geom name="//unnamed_geom_7" class="visual" mesh="left_thigh_yaw_link"/>
          <body name="left_thigh_pitch_link" pos="-0.0022803 0.0210137 -0.118467" quat="1 9.66555e-05 -3.98386e-05 0.000111283">
            <inertial pos="0.000982749 -0.0273117 -0.0536546" quat="0.999817 -0.0146707 -0.00947917 0.00779173" mass="7.26734" diaginertia="0.123569 0.0678921 0.0123387"/>
            <joint name="left_hip_pitch_joint" class="/" pos="0 0 0" axis="-0.00065983 0.999998 -0.00212945" stiffness="0.000725953" range="-1.76 0.698848" armature="0.0884558" damping="0.0118562" frictionloss="0.0994759"/>
            <geom name="//unnamed_geom_8" class="visual" mesh="left_thigh_pitch_link"/>
            <geom name="left_thigh_pitch_link.STL" class="collision" size="0.0777849 0.118493" pos="0.000739297 -0.0283726 -0.140991" type="cylinder" rgba="0.752941 0.752941 0.752941 1"/>
            <geom name="//unnamed_geom_10" class="reward_collision_sphere" size="0.0948596" pos="0 -0.00945753 -0.0421987"/>
            <body name="left_shank_pitch_link" pos="5.08389e-06 -0.0180957 -0.302488" quat="1 -1.396e-05 2.24951e-05 -4.39494e-05">
              <inertial pos="0.00108241 -0.00151919 -0.095962" quat="0.999717 -0.00777186 0.00732386 -0.0212656" mass="1.51975" diaginertia="0.014359 0.00817431 0.000542341"/>
              <joint name="left_knee_pitch_joint" class="/" pos="0 0 0" axis="-0.00319549 0.999969 0.00714524" range="-0.088733 1.92742" armature="0.0939073" damping="0.00770138" frictionloss="0.0936221"/>
              <geom name="//unnamed_geom_11" class="visual" mesh="left_shank_pitch_link"/>
              <geom name="left_shank_pitch_link.STL" class="collision" size="0.0505805 0.0857389" pos="-1.75202e-05 -0.000796841 -0.147435" quat="0.00125538 -0.202712 0.979238 0" type="cylinder" rgba="0.752941 0.752941 0.752941 1"/>
              <geom name="//unnamed_geom_13" class="reward_collision_sphere" size="0.0474298"/>
              <geom name="//unnamed_geom_14" class="reward_collision_sphere" size="0.0569158" pos="0 0 -0.0928372"/>
              <body name="left_foot_pitch_link" pos="-0.00127574 -0.00160957 -0.286297" quat="1 -1.47971e-05 -2.75907e-05 5.94389e-05">
                <inertial pos="0.00100461 -0.00179235 -0.000670071" quat="0.000220209 0.707093 0.000771552 0.70712" mass="0.0496549" diaginertia="8.45662e-06 4.29807e-06 2.31227e-06"/>
                <joint name="left_ankle_pitch_joint" class="/" pos="0 0 0" axis="0.000349014 1 0.0004183" range="-1.07155 0.549851" armature="0.0946548" damping="0.00282192" frictionloss="0.0921315"/>
                <geom name="//unnamed_geom_15" class="visual" mesh="left_foot_pitch_link"/>
                <body name="left_foot_roll_link" pos="0.00103602 -0.000406469 0.00186278" quat="1 4.03508e-06 1.7679e-05 7.39806e-06">
                  <inertial pos="0.0408915 -0.000780276 -0.0326279" quat="0.00108124 0.725301 -0.00183644 0.688428" mass="0.914583" diaginertia="0.00737049 0.003842 0.000322279"/>
                  <joint name="left_ankle_roll_joint" class="/" pos="0 0 0" axis="-0.999988 0.00376538 -0.00314324" stiffness="4.92779e-05" range="-0.451376 0.473061" armature="0.100008" damping="0.0101741" frictionloss="0.0965111"/>
                  <geom name="//unnamed_geom_16" class="visual" mesh="left_foot_roll_link"/>
                  <geom name="left_foot" class="foot" size="0.139409 0.0431638 0.00959798" pos="0.0475228 0 -0.0375569"/>
                  <geom name="//unnamed_geom_18" class="reward_collision_sphere" size="0.0474298" pos="0 0 -0.0253192"/>
                  <geom name="//unnamed_geom_19" class="reward_collision_sphere" size="0.0474298" pos="0.126727 0 -0.0253192"/>
                  <site name="left_foot" class="foot" pos="0.0475228 0 -0.0375569" size="0.00948596"/>
                </body>
              </body>
            </body>
          </body>
        </body>
      </body>
      <body name="right_thigh_roll_link" pos="-0.0344636 -0.102411 -0.0243506" quat="1 0.000538022 0.00022003 0.000283535">
        <inertial pos="0.000663912 -0.00031831 0.00204148" quat="0.0297433 0.706523 0.01754 0.706847" mass="1.26339" diaginertia="0.00344791 0.00190962 0.000683552"/>
        <joint name="right_hip_roll_joint" class="/" pos="0 0 0" axis="-0.999999 0.00131824 -0.000532334" range="-0.0786733 0.795901" armature="0.0859539" damping="0.0034563" frictionloss="0.09596"/>
        <geom name="//unnamed_geom_20" class="visual" mesh="right_thigh_roll_link"/>
        <body name="right_thigh_yaw_link" pos="0.0340521 -0.00298718 0.000664685" quat="1 0.000170194 -0.000344741 -0.000190094">
          <inertial pos="-0.00328016 -0.0373264 -0.0937724" quat="0.687776 -0.148689 0.146438 0.695278" mass="2.96247" diaginertia="0.0312038 0.0146349 0.00382159"/>
          <joint name="right_hip_yaw_joint" class="/" pos="0 0 0" axis="-0.0028792 -0.00580032 -0.999979" stiffness="0.000218006" range="-0.725019 0.717102" armature="0.0989361" damping="0.0122291" frictionloss="0.0934468"/>
          <geom name="//unnamed_geom_21" class="visual" mesh="right_thigh_yaw_link"/>
          <body name="right_thigh_pitch_link" pos="-0.00210687 -0.0234461 -0.117995" quat="1 1.73436e-05 -6.79965e-06 1.31539e-05">
            <inertial pos="0.0010198 0.026194 -0.0535675" quat="0.999802 -0.0155666 -0.0121275 0.00236703" mass="7.1206" diaginertia="0.121222 0.0675356 0.0119333"/>
            <joint name="right_hip_pitch_joint" class="/" pos="0 0 0" axis="0.00546028 -0.999978 -0.00387846" range="-0.693319 1.74379" armature="0.0939381" damping="0.0236667" frictionloss="0.0971672"/>
            <geom name="//unnamed_geom_22" class="visual" mesh="right_thigh_pitch_link"/>
            <geom name="right_thigh_pitch_link.STL" class="collision" size="0.0777849 0.11849" pos="-0.0022423 0.0283726 -0.140991" quat="0.999971 0.00269833 0.00706272 0" type="cylinder" rgba="0.752941 0.752941 0.752941 1"/>
            <geom name="//unnamed_geom_24" class="reward_collision_sphere" size="0.0948596" pos="0 0.00945753 -0.0421987"/>
            <body name="right_shank_pitch_link" pos="-0.000378067 0.0168206 -0.303816" quat="1 0.000144447 -0.000172231 2.61983e-05">
              <inertial pos="0.00246067 -0.000307571 -0.0968494" quat="0.999668 0.00728172 0.00450986 0.0242868" mass="1.49969" diaginertia="0.0140997 0.00809915 0.000530722"/>
              <joint name="right_knee_pitch_joint" class="/" pos="0 0 0" axis="-0.00942712 -0.999943 0.0049385" range="-1.92194 0.112779" armature="0.094451" damping="0.0215307" frictionloss="0.098231"/>
              <geom name="//unnamed_geom_25" class="visual" mesh="right_shank_pitch_link"/>
              <geom name="right_shank_pitch_link.STL" class="collision" size="0.0505802 0.085738" pos="-1.75202e-05 -0.000796851 -0.147441" type="cylinder" rgba="0.752941 0.752941 0.752941 1"/>
              <geom name="//unnamed_geom_27" class="reward_collision_sphere" size="0.0474298"/>
              <geom name="//unnamed_geom_28" class="reward_collision_sphere" size="0.0569158" pos="0 0 -0.0928372"/>
              <body name="right_foot_pitch_link" pos="-0.00144058 2.26403e-05 -0.287216" quat="1 5.09411e-05 -4.44968e-06 -2.61647e-05">
                <inertial pos="0.0010386 -0.00198108 0.000105753" quat="4.16155e-05 0.707561 -0.00118157 0.706651" mass="0.049029" diaginertia="8.3306e-06 4.17906e-06 2.26999e-06"/>
                <joint name="right_ankle_pitch_joint" class="/" pos="0 0 0" axis="-0.000225075 -0.999999 -0.00165408" stiffness="0.00049187" range="-0.521981 1.055" armature="0.091654" damping="0.00636252" frictionloss="0.0918411"/>
                <geom name="//unnamed_geom_29" class="visual" mesh="right_foot_pitch_link"/>
                <body name="right_foot_roll_link" pos="-0.00110257 -0.00179133 0.00143846" quat="1 6.10516e-05 -0.00020029 0.000434126">
                  <inertial pos="0.0400682 -0.000473279 -0.03171" quat="-0.000972722 0.727354 -0.00211333 0.686259" mass="0.911788" diaginertia="0.00732449 0.00386989 0.000323889"/>
                  <joint name="right_ankle_roll_joint" class="/" pos="0 0 0" axis="-1 -0.000756543 -0.000286663" range="-0.468424 0.465372" armature="0.0956535" damping="0.00475115" frictionloss="0.0982913"/>
                  <geom name="//unnamed_geom_30" class="visual" mesh="right_foot_roll_link"/>
                  <geom name="right_foot" class="foot" size="0.144744 0.0390358 0.00966065" pos="0.0475228 0 -0.0375569"/>
                  <geom name="//unnamed_geom_32" class="reward_collision_sphere" size="0.0474298" pos="0 0 -0.0253192"/>
                  <geom name="//unnamed_geom_33" class="reward_collision_sphere" size="0.0474298" pos="0.126727 0 -0.0253192"/>
                  <site name="right_foot" class="foot" pos="0.0475228 0 -0.0375569" size="0.00948596"/>
                </body>
              </body>
            </body>
          </body>
        </body>
      </body>
      <body name="waist_yaw_link" pos="0.00314373 0.00179978 0.00164688" quat="1 -0.000203162 0.000110803 -0.00026315">
        <inertial pos="-0.00146917 -0.00819919 0.044401" quat="0.980223 0.186742 -0.0288572 0.0587966" mass="1.39799" diaginertia="0.00459273 0.00245959 0.000920762"/>
        <joint name="waist_yaw_joint" class="/" pos="0 0 0" axis="-0.00783928 0.0111253 0.999907" range="-1.07134 1.03707" armature="0.0965586" damping="0.0143128" frictionloss="0.0917424"/>
        <geom name="//unnamed_geom_34" class="visual" rgba="0.12 0.12 0.12 1" mesh="waist_yaw_link"/>
        <body name="waist_pitch_link" pos="0.00205614 0.00231046 0.0747169" quat="1 1.57897e-05 -3.05666e-05 -1.19883e-05">
          <inertial pos="0.00560777 -0.00427906 0.0350283" quat="0.997717 -0.0434994 0.0513903 0.00534026" mass="1.33218" diaginertia="0.0061606 0.00354837 0.000782977"/>
          <joint name="waist_pitch_joint" class="/" pos="0 0 0" axis="0.00518312 -0.999856 0.0161377" range="-1.19242 0.488233" armature="0.0946567" damping="0.00238237" frictionloss="0.0957219"/>
          <geom name="//unnamed_geom_35" class="visual" rgba="0.12 0.12 0.12 1" mesh="waist_pitch_link"/>
          <body name="waist_roll_link" pos="0.00881577 0.000640049 0.0709075" quat="1 -0.000477555 -9.27379e-05 0.000354458">
            <inertial pos="-0.0140763 0.000424798 0.124509" quat="0.998786 -0.000187401 -0.049225 0.00180743" mass="5.67601" diaginertia="0.0825487 0.0456431 0.0153499"/>
            <joint name="waist_roll_joint" class="/" pos="0 0 0" axis="-0.999972 0.00367988 -0.00644723" range="-0.708093 0.677872" armature="0.0942414" damping="0.0186575" frictionloss="0.0933535"/>
            <geom name="//unnamed_geom_36" class="visual" rgba="0.12 0.12 0.12 1" mesh="waist_roll_link"/>
            <geom name="//unnamed_geom_37" class="visual" pos="-0.00237614 0.000543269 0.135331" quat="1 0 0 0" mesh="torso_link"/>
            <geom name="torso_link.STL" class="collision" size="0.149335 0.028641" pos="-0.0190787 0.0054568 0.124764" type="cylinder" rgba="0.752941 0.752941 0.752941 1"/>
            <geom name="//unnamed_geom_39" class="reward_collision_sphere" size="0.123318" pos="0 0 0.168795"/>
            <body name="left_upper_arm_pitch_link" pos="-0.000951902 0.096128 0.17591" quat="0.976664 0.214771 -2.77105e-05 -1.82115e-05">
              <inertial pos="0.00370518 0.0501714 0.000758683" quat="0.704398 0.707859 0.00350161 -0.0524182" mass="0.695526" diaginertia="0.00267101 0.00149556 0.000209303"/>
              <joint name="left_shoulder_pitch_joint" class="/" pos="0 0 0" axis="-0.000900771 1 -0.000265662" range="-2.78668 1.93371" armature="0.0953468" damping="0.00475596" frictionloss="0.0907755"/>
              <geom name="//unnamed_geom_40" class="visual" mesh="left_upper_arm_pitch_link"/>
              <body name="left_upper_arm_roll_link" pos="0.000633447 0.0883523 0.0006994" quat="0.976668 -0.214757 -5.07866e-05 0.00024716">
                <inertial pos="0.00576399 0.015816 -0.0203698" quat="0.889265 0.269804 0.124637 -0.347677" mass="0.510932" diaginertia="0.00134065 0.000747264 0.000147645"/>
                <joint name="left_shoulder_roll_joint" class="/" pos="0 0 0" axis="-0.999949 -0.01009 -0.000247003" range="-2.52153 0.583504" armature="0.0984221" damping="0.00222522" frictionloss="0.0962921"/>
                <geom name="//unnamed_geom_41" class="visual" mesh="left_upper_arm_roll_link"/>
                <body name="left_upper_arm_yaw_link" pos="0.000227788 0.0366783 -0.0599181" quat="1 0.000273606 0.000203276 -7.182e-05">
                  <inertial pos="0.000748348 -0.000513314 -0.074916" quat="0.999968 0.00664234 -0.00272119 -0.00345031" mass="0.46096" diaginertia="0.00460952 0.00262293 0.000110119"/>
                  <joint name="left_shoulder_yaw_joint" class="/" pos="0 0 0" axis="-0.0011935 0.00192054 0.999997" range="-2.96374 2.97145" armature="0.0999312" damping="0.00434301" frictionloss="0.0959504"/>
                  <geom name="//unnamed_geom_42" class="visual" mesh="left_upper_arm_yaw_link"/>
                  <geom name="left_upper_arm_yaw_link.STL" class="collision" size="0.0343707 0.0805757" pos="4.1699e-05 -0.000845777 -0.0669609" quat="0.00803418 -0.995528 0.0941277 0" type="cylinder" rgba="0.752941 0.752941 0.752941 1"/>
                  <body name="left_lower_arm_pitch_link" pos="0.000466324 -6.07024e-05 -0.150541" quat="1 0.000139668 0.000424864 -4.76749e-05">
                    <inertial pos="0.0006361 0.00655844 -0.0218286" quat="0.701005 -0.0919346 0.0898351 0.701477" mass="0.281442" diaginertia="0.000393916 0.000224128 4.23576e-05"/>
                    <joint name="left_elbow_pitch_joint" class="/" pos="0 0 0" axis="-0.000891991 0.999999 0.00138216" range="-2.26048 2.28295" armature="0.0957288" damping="0.00206925" frictionloss="0.0964138"/>
                    <geom name="//unnamed_geom_44" class="visual" mesh="left_lower_arm_pitch_link"/>
                    <body name="left_hand_yaw_link" pos="-0.000267014 -7.84748e-05 -0.04999" quat="1 0.000166843 0.000260736 -0.000195948">
                      <inertial pos="0.00024016 0.000756416 -0.0617233" quat="0.999944 -0.0049733 -0.000606461 0.00935559" mass="0.841736" diaginertia="0.00347139 0.00193056 0.000214161"/>
                      <joint name="left_wrist_yaw_joint" class="/" pos="0 0 0" axis="0.000112016 0.000148409 1" range="-2.96082 2.98169" armature="0.0965011" damping="0.00710069" frictionloss="0.0940435"/>
                      <geom name="//unnamed_geom_45" class="visual" mesh="left_hand_yaw_link"/>
                      <geom name="left_hand_yaw_link.STL" class="collision" size="0.039435 0.0660163" pos="0.00115032 -0.00145751 -0.0641782" type="cylinder" rgba="0.752941 0.752941 0.752941 1"/>
                      <geom name="//unnamed_geom_47" class="reward_collision_sphere" size="0.0474298"/>
                      <body name="left_hand_roll_link" pos="0.000587125 -0.000494576 -0.161708" quat="1 0.000472199 -9.47993e-05 -1.56916e-05">
                        <inertial pos="-0.000157218 -0.000353333 -0.00034242" quat="0.499139 0.50069 0.500595 0.499574" mass="0.00429005" diaginertia="4.58365e-07 2.66672e-07 3.02177e-08"/>
                        <joint name="left_wrist_roll_joint" class="/" pos="0 0 0" axis="-0.999999 0.00164747 -0.000399443" range="-0.9489 0.854676" armature="0.0965873" damping="0.000828355" frictionloss="0.0984444"/>
                        <geom name="//unnamed_geom_48" class="visual" mesh="left_hand_roll_link"/>
                        <body name="left_hand_pitch_link" pos="-0.00020754 -0.000938849 0.000327708" quat="1 3.86797e-06 -1.30305e-05 1.60213e-06">
                          <inertial pos="-0.000764333 -0.0109613 -0.045928" quat="0.723514 -0.121031 0.114181 0.669957" mass="0.18684" diaginertia="0.000379707 0.000203407 4.0098e-05"/>
                          <joint name="left_wrist_pitch_joint" class="/" pos="0 0 0" axis="-0.00388288 0.999989 0.00252558" range="-0.606579 0.599075" armature="0.0975033" damping="0.00871178" frictionloss="0.0927643"/>
                          <geom name="//unnamed_geom_49" class="visual" mesh="left_hand_pitch"/>
                          <body name="left_jaw_link" pos="0.000348719 0.000599763 -0.0512189" quat="1 8.53455e-05 3.26589e-05 -4.55946e-05">
                            <inertial pos="0.00059422 0.00391623 -0.0292812" quat="0.707533 -0.0230801 0.0325715 0.705552" mass="0.0596043" diaginertia="0.000104122 4.25233e-05 1.3894e-05"/>
                            <joint name="left_jaw_joint" class="/" pos="0 0 0" axis="-0.999996 0.00244807 0.00129119" range="-0.985329 -0.00615117" armature="0.0972299" damping="0.0107213" frictionloss="0.0942589"/>
                            <geom name="//unnamed_geom_50" class="visual" mesh="left_jaw_link"/>
                            <geom name="//unnamed_geom_51" class="collision" size="0.0341495"/>
                            <geom name="//unnamed_geom_52" class="reward_collision_sphere" size="0.0474298" pos="0 0 -0.0168795"/>
                          </body>
                        </body>
                      </body>
                    </body>
                  </body>
                </body>
              </body>
            </body>
            <body name="right_upper_arm_pitch_link" pos="-0.000463878 -0.0936268 0.174419" quat="0.976687 -0.214667 -4.26085e-06 -7.05815e-06">
              <inertial pos="0.00278646 -0.0508565 -0.000693719" quat="0.706383 0.706895 0.0286852 0.0223346" mass="0.696909" diaginertia="0.00270088 0.00149986 0.000213515"/>
              <joint name="right_shoulder_pitch_joint" class="/" pos="0 0 0" axis="-0.00261569 -0.999996 -0.000753676" range="-1.92804 2.78785" armature="0.0977357" damping="0.00267579" frictionloss="0.0961844"/>
              <geom name="//unnamed_geom_53" class="visual" mesh="right_upper_arm_pitch_link"/>
              <body name="right_upper_arm_roll_link" pos="0.00171043 -0.0888851 -0.000659929" quat="0.976647 0.214852 0.000199515 -3.31162e-05">
                <inertial pos="0.00421707 -0.0167694 -0.0206708" quat="0.887457 -0.268105 0.126052 0.353059" mass="0.517119" diaginertia="0.00136126 0.000757857 0.000150585"/>
                <joint name="right_shoulder_roll_joint" class="/" pos="0 0 0" axis="-0.999996 9.38068e-05 -0.00276354" range="-0.590431 2.53462" armature="0.103628" damping="0.00700185" frictionloss="0.0932453"/>
                <geom name="//unnamed_geom_54" class="visual" mesh="right_upper_arm_roll_link"/>
                <body name="right_upper_arm_yaw_link" pos="0.000972828 -0.0380583 -0.0591395" quat="1 2.87423e-05 -0.000249417 0.000145143">
                  <inertial pos="-0.000706957 -4.81015e-05 -0.0744684" quat="0.999958 -0.00844125 0.000694992 -0.0033981" mass="0.460123" diaginertia="0.00474031 0.00266794 0.00011075"/>
                  <joint name="right_shoulder_yaw_joint" class="/" pos="0 0 0" axis="0.00629677 -0.00306299 0.999975" range="-2.96581 2.97978" armature="0.0989699" damping="0.00260309" frictionloss="0.0947279"/>
                  <geom name="//unnamed_geom_55" class="visual" mesh="right_upper_arm_yaw_link"/>
                  <geom name="right_upper_arm_yaw_link.STL" class="collision" size="0.0343707 0.0805757" pos="4.1699e-05 0.000845777 -0.0669609" type="cylinder" rgba="0.752941 0.752941 0.752941 1"/>
                  <body name="right_lower_arm_pitch_link" pos="0.000973571 -0.000657473 -0.150275" quat="1 3.28972e-05 -2.92473e-05 2.61545e-05">
                    <inertial pos="-0.000150122 -0.0079793 -0.0207574" quat="0.701335 0.0914661 -0.0915213 0.70099" mass="0.28049" diaginertia="0.000396037 0.00022175 4.24237e-05"/>
                    <joint name="right_elbow_pitch_joint" class="/" pos="0 0 0" axis="0.0020314 -0.999998 0.000555291" range="-2.25164 2.26805" armature="0.0977283" damping="0.0121963" frictionloss="0.0938115"/>
                    <geom name="//unnamed_geom_57" class="visual" mesh="right_lower_arm_pitch_link"/>
                    <body name="right_hand_yaw_link" pos="0.000884103 -0.000527979 -0.0507846" quat="1 -7.5278e-05 9.93844e-06 8.74888e-05">
                      <inertial pos="-0.00057482 -0.00347054 -0.0617996" quat="0.999696 0.00346865 -0.00179249 0.0243628" mass="0.843223" diaginertia="0.00340161 0.00188668 0.000213471"/>
                      <joint name="right_wrist_yaw_joint" class="/" pos="0 0 0" axis="-0.00120268 -0.00083474 0.999999" range="-2.96386 2.98388" armature="0.0978767" damping="0.00389795" frictionloss="0.0928939"/>
                      <geom name="//unnamed_geom_58" class="visual" mesh="right_hand_yaw_link"/>
                      <geom name="right_hand_yaw_link.STL" class="collision" size="0.039435 0.0660163" pos="0.00115032 0.000606335 -0.0641782" type="cylinder" rgba="0.752941 0.752941 0.752941 1"/>
                      <geom name="//unnamed_geom_60" class="reward_collision_sphere" size="0.0474298"/>
                      <body name="right_hand_roll_link" pos="0.000450087 -0.000677113 -0.16053" quat="1 0.000223353 -0.000412787 2.09565e-05">
                        <inertial pos="-0.000981138 -6.21589e-05 0.000411807" quat="0.4998 0.499792 0.500328 0.500081" mass="0.00430188" diaginertia="4.61048e-07 2.68362e-07 3.06572e-08"/>
                        <joint name="right_wrist_roll_joint" class="/" pos="0 0 0" axis="-0.999998 -0.00158061 -0.0012247" range="-0.874851 0.948758" armature="0.097139" damping="0.0159668" frictionloss="0.0990487"/>
                        <geom name="//unnamed_geom_61" class="visual" mesh="right_hand_roll_link"/>
                        <body name="right_hand_pitch_link" pos="0.000490062 0.000764696 -0.000602196" quat="1 -0.000229387 0.000135789 -6.07661e-05">
                          <inertial pos="0.00070745 0.0102501 -0.0446731" quat="0.723542 0.122457 -0.114976 0.669532" mass="0.183185" diaginertia="0.000371697 0.000201343 3.97457e-05"/>
                          <joint name="right_wrist_pitch_joint" class="/" pos="0 0 0" axis="3.82557e-05 -1 -0.000933976" range="-0.609371 0.59586" armature="0.0980418" damping="0.00304902" frictionloss="0.0956079"/>
                          <geom name="//unnamed_geom_62" class="visual" mesh="right_hand_pitch"/>
                          <body name="right_jaw_link" pos="0.000302883 -0.000814414 -0.0518685" quat="1 3.08385e-05 -2.56471e-05 8.89428e-06">
                            <inertial pos="-0.00170547 -0.00619659 -0.0284431" quat="0.708099 0.0229964 -0.0307969 0.705066" mass="0.0586571" diaginertia="0.000103376 4.18917e-05 1.38734e-05"/>
                            <joint name="right_jaw_joint" class="/" pos="0 0 0" axis="-1 -0.000373231 0.000159994" range="0.00297157 1.00887" armature="0.0968463" damping="0.0044267" frictionloss="0.0950506"/>
                            <geom name="//unnamed_geom_63" class="visual" mesh="right_jaw_link"/>
                            <geom name="//unnamed_geom_64" class="collision" size="0.0341495"/>
                            <geom name="//unnamed_geom_65" class="reward_collision_sphere" size="0.0474298" pos="0 0 -0.0168795"/>
                          </body>
                        </body>
                      </body>
                    </body>
                  </body>
                </body>
              </body>
            </body>
            <body name="head_roll_link" pos="-0.000476496 0.00121837 0.260391" quat="1 9.66996e-06 9.36439e-05 9.51842e-06">
              <inertial pos="0.00424889 -0.000736013 -0.000480429" quat="0.0020446 0.706447 0.00388677 0.707753" mass="0.00840962" diaginertia="9.29764e-07 3.2919e-07 1.82937e-07"/>
              <joint name="head_roll_joint" class="/" pos="0 0 0" axis="-0.999998 -0.00170061 -0.00135946" range="-0.368708 0.358414" armature="0.101507" damping="0.000964506" frictionloss="0.0990677"/>
              <geom name="//unnamed_geom_66" class="visual" mesh="head_roll_link"/>
              <body name="head_pitch_link" pos="-0.00077298 -0.000128924 0.00136185" quat="1 2.65925e-05 8.01141e-05 8.41965e-05">
                <inertial pos="-0.00181261 0.000572168 0.0158326" quat="0.664531 0.664763 0.241391 -0.241286" mass="0.0513426" diaginertia="3.43626e-05 1.75485e-05 7.30265e-06"/>
                <joint name="head_pitch_joint" class="/" pos="0 0 0" axis="0.00110347 -0.999999 0.000762485" range="-0.849847 0.865294" armature="0.0984584" damping="0.0119576" frictionloss="0.0969342"/>
                <geom name="//unnamed_geom_67" class="visual" mesh="head_pitch_link"/>
                <body name="head_yaw_link" pos="0.000352148 0.000751416 0.0454201" quat="1 -2.08547e-05 -3.81716e-05 7.95141e-05">
                  <inertial pos="0.0277643 -0.00286003 0.0807456" quat="0.705857 -0.135236 -0.142352 0.680597" mass="1.37723" diaginertia="0.0135231 0.00611602 0.00230816"/>
                  <joint name="head_yaw_joint" class="/" pos="0 0 0" axis="-0.00220575 -0.00173749 0.999996" range="-2.70699 2.7203" armature="0.0992736" damping="0.00441899" frictionloss="0.0953149"/>
                  <geom name="//unnamed_geom_68" class="visual" rgba="0.12 0.12 0.12 1" mesh="head_yaw_link"/>
                  <geom name="head_yaw_link.STL" class="collision" size="0.112586" pos="0.019306 -0.000832285 0.079013" rgba="0.752941 0.752941 0.752941 1"/>
                  <geom name="//unnamed_geom_70" class="reward_collision_sphere" size="0.0948596" pos="0.0316819 0 0.0843974"/>
                  <camera name="ego_camera" class="/" pos="0.116167 0 0.0928372" quat="-0.5 -0.5 0.5 0.5"/>
                </body>
              </body>
            </body>
          </body>
        </body>
      </body>
    </body>
  </worldbody>

  <contact>
    <pair class="/" geom1="floor" geom2="left_foot" name="//unnamed_contact_0"/>
    <pair class="/" geom1="floor" geom2="right_foot" name="//unnamed_contact_1"/>
  </contact>

  <actuator>
    <general name="left_hip_roll" class="/" joint="left_hip_roll_joint" forcerange="-48.0523 48.0523" gainprm="113.832" biasprm="0 -113.832 -0.948596"/>
    <general name="left_hip_yaw" class="/" joint="left_hip_yaw_joint" forcerange="-63.8007 63.8007" gainprm="113.832" biasprm="0 -113.832 -0.948596"/>
    <general name="left_hip_pitch" class="/" joint="left_hip_pitch_joint" forcerange="-218.649 218.649" gainprm="113.832" biasprm="0 -113.832 -0.948596"/>
    <general name="left_knee_pitch" class="/" joint="left_knee_pitch_joint" forcerange="-216.6 216.6" gainprm="113.832" biasprm="0 -113.832 -0.948596"/>
    <general name="left_ankle_pitch" class="/" joint="left_ankle_pitch_joint" forcerange="-14.1512 14.1512" gainprm="113.832" biasprm="0 -113.832 -0.948596"/>
    <general name="left_ankle_roll" class="/" joint="left_ankle_roll_joint" forcerange="-28.0366 28.0366" gainprm="113.832" biasprm="0 -113.832 -0.948596"/>
    <general name="right_hip_roll" class="/" joint="right_hip_roll_joint" forcerange="-45.4544 45.4544" gainprm="113.832" biasprm="0 -113.832 -0.948596"/>
    <general name="right_hip_yaw" class="/" joint="right_hip_yaw_joint" forcerange="-60.5228 60.5228" gainprm="113.832" biasprm="0 -113.832 -0.948596"/>
    <general name="right_hip_pitch" class="/" joint="right_hip_pitch_joint" forcerange="-224.793 224.793" gainprm="113.832" biasprm="0 -113.832 -0.948596"/>
    <general name="right_knee_pitch" class="/" joint="right_knee_pitch_joint" forcerange="-212.432 212.432" gainprm="113.832" biasprm="0 -113.832 -0.948596"/>
    <general name="right_ankle_pitch" class="/" joint="right_ankle_pitch_joint" forcerange="-14.4843 14.4843" gainprm="113.832" biasprm="0 -113.832 -0.948596"/>
    <general name="right_ankle_roll" class="/" joint="right_ankle_roll_joint" forcerange="-28.7098 28.7098" gainprm="113.832" biasprm="0 -113.832 -0.948596"/>
    <general name="waist_yaw" class="/" joint="waist_yaw_joint" forcerange="-61.4052 61.4052" gainprm="113.832" biasprm="0 -113.832 -0.948596"/>
    <general name="waist_pitch" class="/" joint="waist_pitch_joint" forcerange="-66.0619 66.0619" gainprm="113.832" biasprm="0 -113.832 -0.948596"/>
    <general name="waist_roll" class="/" joint="waist_roll_joint" forcerange="-60.3419 60.3419" gainprm="113.832" biasprm="0 -113.832 -0.948596"/>
    <general name="left_shoulder_pitch" class="/" joint="left_shoulder_pitch_joint" forcerange="-35.4922 35.4922" gainprm="113.832" biasprm="0 -113.832 -0.948596"/>
    <general name="left_shoulder_roll" class="/" joint="left_shoulder_roll_joint" forcerange="-35.3425 35.3425" gainprm="113.832" biasprm="0 -113.832 -0.948596"/>
    <general name="left_shoulder_yaw" class="/" joint="left_shoulder_yaw_joint" forcerange="-27.9603 27.9603" gainprm="113.832" biasprm="0 -113.832 -0.948596"/>
    <general name="left_elbow_pitch" class="/" joint="left_elbow_pitch_joint" forcerange="-28.3002 28.3002" gainprm="113.832" biasprm="0 -113.832 -0.948596"/>
    <general name="left_wrist_yaw" class="/" joint="left_wrist_yaw_joint" forcerange="-9.52623 9.52623" gainprm="113.832" biasprm="0 -113.832 -0.948596"/>
    <general name="left_wrist_roll" class="/" joint="left_wrist_roll_joint" forcerange="-3.77537 3.77537" gainprm="113.832" biasprm="0 -113.832 -0.948596"/>
    <general name="left_wrist_pitch" class="/" joint="left_wrist_pitch_joint" forcerange="-3.73724 3.73724" gainprm="113.832" biasprm="0 -113.832 -0.948596"/>
    <general name="left_jaw" class="/" joint="left_jaw_joint" forcerange="-3.75274 3.75274" gainprm="113.832" biasprm="0 -113.832 -0.948596"/>
    <general name="right_shoulder_pitch" class="/" joint="right_shoulder_pitch_joint" forcerange="-36.0155 36.0155" gainprm="113.832" biasprm="0 -113.832 -0.948596"/>
    <general name="right_shoulder_roll" class="/" joint="right_shoulder_roll_joint" forcerange="-36.1158 36.1158" gainprm="113.832" biasprm="0 -113.832 -0.948596"/>
    <general name="right_shoulder_yaw" class="/" joint="right_shoulder_yaw_joint" forcerange="-27.4182 27.4182" gainprm="113.832" biasprm="0 -113.832 -0.948596"/>
    <general name="right_elbow_pitch" class="/" joint="right_elbow_pitch_joint" forcerange="-27.6971 27.6971" gainprm="113.832" biasprm="0 -113.832 -0.948596"/>
    <general name="right_wrist_yaw" class="/" joint="right_wrist_yaw_joint" forcerange="-9.77661 9.77661" gainprm="113.832" biasprm="0 -113.832 -0.948596"/>
    <general name="right_wrist_roll" class="/" joint="right_wrist_roll_joint" forcerange="-3.81793 3.81793" gainprm="113.832" biasprm="0 -113.832 -0.948596"/>
    <general name="right_wrist_pitch" class="/" joint="right_wrist_pitch_joint" forcerange="-3.73723 3.73723" gainprm="113.832" biasprm="0 -113.832 -0.948596"/>
    <general name="right_jaw" class="/" joint="right_jaw_joint" forcerange="-3.76158 3.76158" gainprm="113.832" biasprm="0 -113.832 -0.948596"/>
    <general name="head_roll" class="/" joint="head_roll_joint" forcerange="-3.76358 3.76358" gainprm="113.832" biasprm="0 -113.832 -0.948596"/>
    <general name="head_pitch" class="/" joint="head_pitch_joint" forcerange="-3.80601 3.80601" gainprm="113.832" biasprm="0 -113.832 -0.948596"/>
    <general name="head_yaw" class="/" joint="head_yaw_joint" forcerange="-3.68935 3.68935" gainprm="113.832" biasprm="0 -113.832 -0.948596"/>
  </actuator>

  <sensor>
    <gyro site="imu" name="imu_angular_velocity"/>
    <velocimeter site="imu" name="imu_linear_velocity"/>
    <framelinvel objtype="site" objname="left_foot" name="left_foot_global_linear_velocity"/>
    <framelinvel objtype="site" objname="right_foot" name="right_foot_global_linear_velocity"/>
  </sensor>

  <keyframe>
    <key name="home" qpos="0 0 0.8665 1 0 0 0 0 0 -0.4 0.8 -0.4 0 0 0 0.4 -0.8 0.4 0 0 0 0 0 -0.2 0 -0.785 0 0 0 0 0 0.2 0 0.785 0 0 0 0 0 0 0"/>
  </keyframe>
</mujoco>
