<mujoco model="GR1T2_jaw">
  <compiler angle="radian" assetdir="assets" balanceinertia="true" inertiafromgeom="false"/>

  <option timestep="0.005" density="1.2" viscosity="2e-05"/>

  <size nkey="1"/>

  <visual>
    <quality shadowsize="8192"/>
    <map shadowclip="0.5"/>
  </visual>

  <default>
    <default class="/">
      <joint armature="0.1" damping="0.01" frictionloss="0.1"/>
      <geom contype="0" conaffinity="0" group="1" solref="-1000 -80"/>
      <site size="0.01 0.005 0.005" group="5"/>
      <general forcelimited="true" biastype="affine" gainprm="80" biasprm="0 -80 -2"/>
      <default class="visual">
        <geom type="mesh" density="0" rgba="0.18 0.18 0.18 1"/>
      </default>
      <default class="collision">
        <geom group="3"/>
      </default>
      <default class="foot">
        <geom size="0.126 0.045 0.01" type="box" condim="6" group="4" priority="1" solimp="0.015 1 0.01"/>
      </default>
      <default class="reward_collision_sphere">
        <geom group="5" rgba="1 0 0 1"/>
      </default>
    </default>
  </default>

  <asset>
    <texture type="skybox" colorspace="auto" name="//unnamed_texture_0" builtin="gradient" rgb1="0.95 0.95 0.95" rgb2="0.95 0.95 0.95" width="100" height="600"/>
    <texture type="2d" colorspace="auto" name="texplane" builtin="checker" rgb1="0.345 0.575 0.748" rgb2="0.345 0.575 0.748" markrgb="1 1 1" width="512" height="512"/>
    <material name="MatPlane" class="/" texture="texplane" texuniform="true" texrepeat="2 2" specular="0.9"/>
    <mesh name="base_link" class="/" file="base_link.STL"/>
    <mesh name="left_thigh_roll_link" class="/" file="left_thigh_roll_link.STL"/>
    <mesh name="left_thigh_yaw_link" class="/" file="left_thigh_yaw_link.STL"/>
    <mesh name="left_thigh_pitch_link" class="/" file="left_thigh_pitch_link.STL"/>
    <mesh name="left_shank_pitch_link" class="/" file="left_shank_pitch_link.STL"/>
    <mesh name="left_foot_pitch_link" class="/" file="left_foot_pitch_link.STL"/>
    <mesh name="left_foot_roll_link" class="/" file="left_foot_roll_link.STL"/>
    <mesh name="right_thigh_roll_link" class="/" file="right_thigh_roll_link.STL"/>
    <mesh name="right_thigh_yaw_link" class="/" file="right_thigh_yaw_link.STL"/>
    <mesh name="right_thigh_pitch_link" class="/" file="right_thigh_pitch_link.STL"/>
    <mesh name="right_shank_pitch_link" class="/" file="right_shank_pitch_link.STL"/>
    <mesh name="right_foot_pitch_link" class="/" file="right_foot_pitch_link.STL"/>
    <mesh name="right_foot_roll_link" class="/" file="right_foot_roll_link.STL"/>
    <mesh name="waist_yaw_link" class="/" file="waist_yaw_link.STL"/>
    <mesh name="waist_pitch_link" class="/" file="waist_pitch_link.STL"/>
    <mesh name="waist_roll_link" class="/" file="waist_roll_link.STL"/>
    <mesh name="torso_link" class="/" file="torso_link.STL"/>
    <mesh name="left_upper_arm_pitch_link" class="/" file="left_upper_arm_pitch_link.STL"/>
    <mesh name="left_upper_arm_roll_link" class="/" file="left_upper_arm_roll_link.STL"/>
    <mesh name="left_upper_arm_yaw_link" class="/" file="left_upper_arm_yaw_link.STL"/>
    <mesh name="left_lower_arm_pitch_link" class="/" file="left_lower_arm_pitch_link.STL"/>
    <mesh name="left_hand_yaw_link" class="/" file="left_hand_yaw_link.STL"/>
    <mesh name="left_hand_roll_link" class="/" file="left_hand_roll_link.STL"/>
    <mesh name="left_hand_pitch" class="/" file="left_hand_pitch.STL"/>
    <mesh name="left_jaw_link" class="/" file="left_jaw_link.STL"/>
    <mesh name="right_upper_arm_pitch_link" class="/" file="right_upper_arm_pitch_link.STL"/>
    <mesh name="right_upper_arm_roll_link" class="/" file="right_upper_arm_roll_link.STL"/>
    <mesh name="right_upper_arm_yaw_link" class="/" file="right_upper_arm_yaw_link.STL"/>
    <mesh name="right_lower_arm_pitch_link" class="/" file="right_lower_arm_pitch_link.STL"/>
    <mesh name="right_hand_yaw_link" class="/" file="right_hand_yaw_link.STL"/>
    <mesh name="right_hand_roll_link" class="/" file="right_hand_roll_link.STL"/>
    <mesh name="right_hand_pitch" class="/" file="right_hand_pitch.STL"/>
    <mesh name="right_jaw_link" class="/" file="right_jaw_link.STL"/>
    <mesh name="head_roll_link" class="/" file="head_roll_link.STL"/>
    <mesh name="head_pitch_link" class="/" file="head_pitch_link.STL"/>
    <mesh name="head_yaw_link" class="/" file="head_yaw_link.STL"/>
    <mesh name="imu_link" class="/" file="imu_link.STL"/>
  </asset>

  <worldbody>
    <geom name="floor" class="/" size="100 100 0.125" type="plane" group="0" material="MatPlane"/>
    <light name="toplight_shadow" class="/" pos="0 0 5" dir="0.0990148 0.0990148 -0.990148" type="directional" ambient="0.04 0.04 0.04" diffuse="0.55 0.55 0.55" specular="0.12 0.12 0.12"/>
    <light name="toplight_fill" class="/" pos="0 0 5" dir="0.0990148 0.0990148 -0.990148" type="directional" castshadow="false" ambient="0.04 0.04 0.04" diffuse="0.3 0.3 0.3" specular="0.08 0.08 0.08"/>
    <body name="trunk" pos="0.00135724 0.000731905 -0.00260709" quat="1 -6.50363e-05 -0.00039623 0.000334297">
      <inertial pos="-0.0599519 0.00288038 -0.0120573" quat="1 0.000159623 -0.000151563 -3.66511e-05" mass="4.23368" diaginertia="0.0472119 0.0221326 0.029202"/>
      <joint name="//unnamed_joint_0" type="free"/>
      <geom name="//unnamed_geom_1" class="visual" rgba="0.12 0.12 0.12 1" mesh="base_link"/>
      <geom name="base_link.STL" class="collision" size="0.124468 0.0697121" pos="-0.0436539 0.000406736 0.00853342" quat="0.706838 -0.707359 0.00477667 0" type="cylinder" rgba="0.752941 0.752941 0.752941 1"/>
      <geom name="//unnamed_geom_3" class="visual" pos="0 0 -0.0552211" quat="1 0 0 0" rgba="0.12 0.12 0.12 1" mesh="imu_link"/>
      <geom name="//unnamed_geom_4" class="reward_collision_sphere" size="0.0813557" pos="0 0.109916 0.0926529"/>
      <geom name="//unnamed_geom_5" class="reward_collision_sphere" size="0.0813557" pos="0 -0.109916 0.0926529"/>
      <site name="imu" class="/" pos="0.00468895 0.0027596 -0.0559766" size="0.0101695"/>
      <camera name="track" class="/" pos="0 -2.19832 0" quat="0.707107 0.707107 0 0" mode="trackcom"/>
      <body name="left_thigh_roll_link" pos="-0.0343736 0.116528 -0.0253647" quat="0.999999 0.000470484 0.000376339 0.000947724">
        <inertial pos="-6.02414e-05 -0.00231095 0.0022203" quat="-0.0299091 0.706819 -0.0342237 0.705932" mass="1.54773" diaginertia="0.00279415 0.00382818 0.00106682"/>
        <joint name="left_hip_roll_joint" class="/" pos="0 0 0" axis="-1 1.09353e-05 0.000704973" range="-0.752169 0.129368" armature="0.107437" damping="0.00644039" frictionloss="0.101541"/>
        <geom name="//unnamed_geom_6" class="visual" mesh="left_thigh_roll_link"/>
        <body name="left_thigh_yaw_link" pos="0.0296181 0.00160748 0.00360255" quat="0.999999 -0.00102133 -0.000517286 -7.93851e-05">
          <inertial pos="-0.00516553 0.0442971 -0.0995342" quat="0.570572 0.0939631 -0.195283 0.792138" mass="3.5326" diaginertia="0.0272882 0.0308744 0.00579608"/>
          <joint name="left_hip_yaw_joint" class="/" pos="0 0 0" axis="-0.00339225 -0.00281951 -0.99999" stiffness="0.000604318" range="-0.702595 0.67657" armature="0.102246" damping="0" frictionloss="0.106701"/>
          <geom name="//unnamed_geom_7" class="visual" mesh="left_thigh_yaw_link"/>
          <body name="left_thigh_pitch_link" pos="-0.0036309 0.0268133 -0.128842" quat="1 -0.000347861 -0.0004083 0.000250256">
            <inertial pos="0.00288463 -0.0323675 -0.0592328" quat="0.999839 -0.0141707 -0.00496405 0.00983445" mass="8.8747" diaginertia="0.108334 0.149276 0.0194967"/>
            <joint name="left_hip_pitch_joint" class="/" pos="0 0 0" axis="-0.000884107 1 0.000157172" range="-1.75823 0.652939" armature="0.086297" damping="0.0111722" frictionloss="0.114961"/>
            <geom name="//unnamed_geom_8" class="visual" mesh="left_thigh_pitch_link"/>
            <geom name="left_thigh_pitch_link.STL" class="collision" size="0.0833896 0.127031" pos="0.000717658 -0.0329748 -0.154782" type="cylinder" rgba="0.752941 0.752941 0.752941 1"/>
            <geom name="//unnamed_geom_10" class="reward_collision_sphere" size="0.101695" pos="0 -0.0109916 -0.0463265"/>
            <body name="left_shank_pitch_link" pos="-0.000954536 -0.0223002 -0.331706" quat="1 4.63073e-05 4.64778e-05 -0.000243283">
              <inertial pos="0.00215603 -0.00139009 -0.103705" quat="0.999728 -0.0073896 0.0073913 -0.0208608" mass="1.83761" diaginertia="0.0120909 0.0170923 0.000858993"/>
              <joint name="left_knee_pitch_joint" class="/" pos="0 0 0" axis="-0.00577183 0.9999 -0.0129297" range="-0.115081 1.88177" armature="0.0992881" damping="0.0165528" frictionloss="0.0977006"/>
              <geom name="//unnamed_geom_11" class="visual" mesh="left_shank_pitch_link"/>
              <geom name="left_shank_pitch_link.STL" class="collision" size="0.054225 0.0919167" pos="-1.70074e-05 -0.000926094 -0.161856" quat="0.00125538 -0.202712 0.979238 0" type="cylinder" rgba="0.752941 0.752941 0.752941 1"/>
              <geom name="//unnamed_geom_13" class="reward_collision_sphere" size="0.0508473"/>
              <geom name="//unnamed_geom_14" class="reward_collision_sphere" size="0.0610168" pos="0 0 -0.101918"/>
              <body name="left_foot_pitch_link" pos="-0.000484428 -0.00397677 -0.314354" quat="1 0.000267599 -0.000278367 -0.000494158">
                <inertial pos="0.00125312 -0.000477742 0.000343879" quat="0.00115517 0.704543 -0.0023575 0.709656" mass="0.0591804" diaginertia="7.19467e-06 8.98584e-06 3.74304e-06"/>
                <joint name="left_ankle_pitch_joint" class="/" pos="0 0 0" axis="-0.00111139 0.999996 0.00278568" range="-1.04315 0.51493" armature="0.112635" damping="0.00307475" frictionloss="0.0886195"/>
                <geom name="//unnamed_geom_15" class="visual" mesh="left_foot_pitch_link"/>
                <body name="left_foot_roll_link" pos="0.000645551 0.00202357 0.000879275" quat="1 2.73045e-06 7.28848e-06 5.34227e-06">
                  <inertial pos="0.0411504 -0.0012647 -0.037952" quat="-0.00417186 0.719972 -0.00703908 0.693955" mass="1.11854" diaginertia="0.00617188 0.00813279 0.000512722"/>
                  <joint name="left_ankle_roll_joint" class="/" pos="0 0 0" axis="-0.999873 -0.0156655 0.00275269" range="-0.454779 0.500574" armature="0.102092" damping="0.00560474" frictionloss="0.0916446"/>
                  <geom name="//unnamed_geom_16" class="visual" mesh="left_foot_roll_link"/>
                  <geom name="left_foot" class="foot" size="0.150821 0.0510083 0.0101694" pos="0.0461318 0 -0.0412305"/>
                  <geom name="//unnamed_geom_18" class="reward_collision_sphere" size="0.0508473" pos="0 0 -0.0277959"/>
                  <geom name="//unnamed_geom_19" class="reward_collision_sphere" size="0.0508473" pos="0.123018 0 -0.0277959"/>
                  <site name="left_foot" class="foot" pos="0.0461318 0 -0.0412305" size="0.0101695"/>
                </body>
              </body>
            </body>
          </body>
        </body>
      </body>
      <body name="right_thigh_roll_link" pos="-0.0304499 -0.119521 -0.0263226" quat="1 0.000305695 8.86636e-05 -0.000411729">
        <inertial pos="0.000438271 -0.00160393 0.00183081" quat="0.0274002 0.709515 0.0228285 0.703787" mass="1.54732" diaginertia="0.0028849 0.0040117 0.0010957"/>
        <joint name="right_hip_roll_joint" class="/" pos="0 0 0" axis="-0.999999 0.00143799 -0.000215058" range="-0.0986049 0.795911" armature="0.0901692" damping="0.0162871" frictionloss="0.0995821"/>
        <geom name="//unnamed_geom_20" class="visual" mesh="right_thigh_roll_link"/>
        <body name="right_thigh_yaw_link" pos="0.0340624 -0.00258324 0.00292582" quat="0.999999 -0.000452583 -0.000901481 0.000483533">
          <inertial pos="-0.00244419 -0.0422346 -0.102397" quat="0.687992 -0.146938 0.150695 0.694527" mass="3.6949" diaginertia="0.0267286 0.0312422 0.00616242"/>
          <joint name="right_hip_yaw_joint" class="/" pos="0 0 0" axis="0.000809801 -0.00854319 -0.999963" range="-0.682656 0.701735" armature="0.104447" damping="0.00997861" frictionloss="0.112052"/>
          <geom name="//unnamed_geom_21" class="visual" mesh="right_thigh_yaw_link"/>
          <body name="right_thigh_pitch_link" pos="-0.00248638 -0.0289024 -0.131917" quat="1 0.000207096 0.000535036 -0.000182646">
            <inertial pos="0.0031248 0.0295231 -0.0610411" quat="0.999802 -0.0147374 -0.0118328 0.00627956" mass="8.68995" diaginertia="0.100907 0.14219 0.0187581"/>
            <joint name="right_hip_pitch_joint" class="/" pos="0 0 0" axis="-0.006433 -0.999974 -0.00320877" range="-0.680849 1.7545" armature="0.111028" damping="0.0306065" frictionloss="0.0985059"/>
            <geom name="//unnamed_geom_22" class="visual" mesh="right_thigh_pitch_link"/>
            <geom name="right_thigh_pitch_link.STL" class="collision" size="0.0833896 0.127028" pos="-0.00217667 0.0329748 -0.154782" quat="0.999971 0.00269833 0.00706272 0" type="cylinder" rgba="0.752941 0.752941 0.752941 1"/>
            <geom name="//unnamed_geom_24" class="reward_collision_sphere" size="0.101695" pos="0 0.0109916 -0.0463265"/>
            <body name="right_shank_pitch_link" pos="-0.000536364 0.0200113 -0.333163" quat="1 -0.000128706 0.000266234 -7.07538e-05">
              <inertial pos="0.000301115 0.00216459 -0.106913" quat="0.999662 0.00781396 0.00319342 0.0246054" mass="1.85321" diaginertia="0.0121726 0.0167499 0.000847305"/>
              <joint name="right_knee_pitch_joint" class="/" pos="0 0 0" axis="0.000302737 -0.999997 0.00262569" range="-1.95081 0.0656424" armature="0.0900597" damping="0.0250673" frictionloss="0.11488"/>
              <geom name="//unnamed_geom_25" class="visual" mesh="right_shank_pitch_link"/>
              <geom name="right_shank_pitch_link.STL" class="collision" size="0.0542247 0.0919158" pos="-1.70074e-05 -0.000926105 -0.161864" type="cylinder" rgba="0.752941 0.752941 0.752941 1"/>
              <geom name="//unnamed_geom_27" class="reward_collision_sphere" size="0.0508473"/>
              <geom name="//unnamed_geom_28" class="reward_collision_sphere" size="0.0610168" pos="0 0 -0.101918"/>
              <body name="right_foot_pitch_link" pos="0.0015557 0.00256894 -0.314614" quat="0.999999 -0.000279845 0.0010564 -0.000158708">
                <inertial pos="-0.00023955 0.000232431 -0.000658883" quat="0.00244398 0.708696 0.00408182 0.705498" mass="0.0588526" diaginertia="7.21338e-06 9.00266e-06 3.6411e-06"/>
                <joint name="right_ankle_pitch_joint" class="/" pos="0 0 0" axis="-8.83902e-06 -1 5.45871e-05" range="-0.547986 1.07874" armature="0.107204" damping="0.00249307" frictionloss="0.0996608"/>
                <geom name="//unnamed_geom_29" class="visual" mesh="right_foot_pitch_link"/>
                <body name="right_foot_roll_link" pos="0.00208685 -0.000854935 -0.000586543" quat="0.999999 0.000689215 0.000491355 -0.00115053">
                  <inertial pos="0.0384248 -0.00143222 -0.0369767" quat="0.00473513 0.726944 -0.0106403 0.686598" mass="1.12817" diaginertia="0.00629913 0.00820561 0.000500064"/>
                  <joint name="right_ankle_roll_joint" class="/" pos="0 0 0" axis="-0.999982 0.00586934 0.00146055" range="-0.428146 0.445154" armature="0.102479" damping="0.00701811" frictionloss="0.114828"/>
                  <geom name="//unnamed_geom_30" class="visual" mesh="right_foot_roll_link"/>
                  <geom name="right_foot" class="foot" size="0.156224 0.0429454 0.00965793" pos="0.0461318 0 -0.0412305"/>
                  <geom name="//unnamed_geom_32" class="reward_collision_sphere" size="0.0508473" pos="0 0 -0.0277959"/>
                  <geom name="//unnamed_geom_33" class="reward_collision_sphere" size="0.0508473" pos="0.123018 0 -0.0277959"/>
                  <site name="right_foot" class="foot" pos="0.0461318 0 -0.0412305" size="0.0101695"/>
                </body>
              </body>
            </body>
          </body>
        </body>
      </body>
      <body name="waist_yaw_link" pos="0.00241197 0.00272762 0.0014494" quat="1 -0.000191295 0.000102495 -0.00023781">
        <inertial pos="-0.00236733 -0.0071411 0.0489132" quat="0.978016 0.196929 -0.0232856 0.0645161" mass="1.6864" diaginertia="0.00397457 0.00496813 0.00146702"/>
        <joint name="waist_yaw_joint" class="/" pos="0 0 0" axis="0.0101615 0.000664973 0.999948" range="-1.02794 1.03623" armature="0.106375" damping="0.0148905" frictionloss="0.10962"/>
        <geom name="//unnamed_geom_34" class="visual" rgba="0.12 0.12 0.12 1" mesh="waist_yaw_link"/>
        <body name="waist_pitch_link" pos="0.00211087 0.0019666 0.0814135" quat="1 -0.000266884 -0.000833507 0.000185996">
          <inertial pos="0.00345433 -0.00358075 0.0383489" quat="0.997803 -0.0416955 0.0511301 0.0060684" mass="1.67333" diaginertia="0.00531055 0.00736445 0.00127245"/>
          <joint name="waist_pitch_joint" class="/" pos="0 0 0" axis="0.0173984 -0.99973 0.0154264" range="-1.15643 0.477048" armature="0.102894" damping="0.00163526" frictionloss="0.098841"/>
          <geom name="//unnamed_geom_35" class="visual" rgba="0.12 0.12 0.12 1" mesh="waist_pitch_link"/>
          <body name="waist_roll_link" pos="0.00854462 0.00172561 0.0773783" quat="1 4.34527e-05 -3.2401e-05 0.000329543">
            <inertial pos="-0.014786 0.00024639 0.138979" quat="0.998806 -0.00265609 -0.0487399 0.0021327" mass="6.97862" diaginertia="0.070168 0.0945078 0.0247969"/>
            <joint name="waist_roll_joint" class="/" pos="0 0 0" axis="-0.999999 -0.00061399 -0.00127278" range="-0.751275 0.725296" armature="0.111206" damping="0.014017" frictionloss="0.111913"/>
            <geom name="//unnamed_geom_36" class="visual" rgba="0.12 0.12 0.12 1" mesh="waist_roll_link"/>
            <geom name="//unnamed_geom_37" class="visual" pos="-0.00230659 0.000631391 0.148569" quat="1 0 0 0" mesh="torso_link"/>
            <geom name="torso_link.STL" class="collision" size="0.160095 0.0307047" pos="-0.0185203 0.00634194 0.136968" type="cylinder" rgba="0.752941 0.752941 0.752941 1"/>
            <geom name="//unnamed_geom_39" class="reward_collision_sphere" size="0.132203" pos="0 0 0.185306"/>
            <body name="left_upper_arm_pitch_link" pos="-0.00050404 0.110238 0.190635" quat="0.976736 0.214444 -0.000206226 0.00100661">
              <inertial pos="0.00378469 0.057986 -0.000631512" quat="0.705173 0.706955 0.00352936 -0.0541622" mass="0.828776" diaginertia="0.0022308 0.0030799 0.000326276"/>
              <joint name="left_shoulder_pitch_joint" class="/" pos="0 0 0" axis="0.000381009 1 0.00064817" range="-2.81201 1.94483" armature="0.113644" damping="0.0155487" frictionloss="0.106727"/>
              <geom name="//unnamed_geom_40" class="visual" mesh="left_upper_arm_pitch_link"/>
              <body name="left_upper_arm_roll_link" pos="0.00222184 0.104855 0.00276837" quat="0.976662 -0.214783 -0.000160816 -4.17753e-05">
                <inertial pos="0.00497303 0.018195 -0.0210417" quat="0.890069 0.268821 0.124762 -0.346334" mass="0.648252" diaginertia="0.00117958 0.00159317 0.000239253"/>
                <joint name="left_shoulder_roll_joint" class="/" pos="0 0 0" axis="-0.999857 0.010731 0.0130595" range="-2.54128 0.559035" armature="0.101475" damping="0.0034693" frictionloss="0.0913373"/>
                <geom name="//unnamed_geom_41" class="visual" mesh="left_upper_arm_roll_link"/>
                <body name="left_upper_arm_yaw_link" pos="-0.00182675 0.041274 -0.0657464" quat="1 0.000126925 0.000222744 -0.000149076">
                  <inertial pos="-0.00135757 -0.00292271 -0.0804626" quat="0.999957 0.0059994 0.00176226 -0.00681201" mass="0.571562" diaginertia="0.00409455 0.00578594 0.000179441"/>
                  <joint name="left_shoulder_yaw_joint" class="/" pos="0 0 0" axis="0.000348902 0.000256878 1" range="-2.97895 2.97279" armature="0.117657" damping="0" frictionloss="0.100551"/>
                  <geom name="//unnamed_geom_42" class="visual" mesh="left_upper_arm_yaw_link"/>
                  <geom name="left_upper_arm_yaw_link.STL" class="collision" size="0.0368472 0.0863815" pos="4.04785e-05 -0.000982968 -0.0735108" quat="0.00803418 -0.995528 0.0941277 0" type="cylinder" rgba="0.752941 0.752941 0.752941 1"/>
                  <body name="left_lower_arm_pitch_link" pos="-0.00176061 0.000603478 -0.164917" quat="1 2.3047e-05 7.71312e-05 9.28067e-05">
                    <inertial pos="0.00246889 0.00837251 -0.0229476" quat="0.702995 -0.0916196 0.0884793 0.699697" mass="0.347375" diaginertia="0.000327506 0.000473316 6.66809e-05"/>
                    <joint name="left_elbow_pitch_joint" class="/" pos="0 0 0" axis="-0.00678687 0.999937 -0.0089883" range="-2.30275 2.2569" armature="0.108358" damping="0.0119125" frictionloss="0.10023"/>
                    <geom name="//unnamed_geom_44" class="visual" mesh="left_lower_arm_pitch_link"/>
                    <body name="left_hand_yaw_link" pos="6.59572e-07 -0.00167275 -0.0528288" quat="1 -0.000114796 0.000766188 0.000241667">
                      <inertial pos="0.000382726 -0.00101771 -0.0673003" quat="0.999983 -0.00288907 -0.00125016 0.00486636" mass="1.03933" diaginertia="0.00302235 0.00408733 0.000351208"/>
                      <joint name="left_wrist_yaw_joint" class="/" pos="0 0 0" axis="-0.000194492 -0.000253494 1" range="-2.95285 2.96492" armature="0.115127" damping="0.00264723" frictionloss="0.11263"/>
                      <geom name="//unnamed_geom_45" class="visual" mesh="left_hand_yaw_link"/>
                      <geom name="left_hand_yaw_link.STL" class="collision" size="0.0422764 0.0707731" pos="0.00111665 -0.00169393 -0.070456" type="cylinder" rgba="0.752941 0.752941 0.752941 1"/>
                      <geom name="//unnamed_geom_47" class="reward_collision_sphere" size="0.0508473"/>
                      <body name="left_hand_roll_link" pos="-0.000969333 0.00176883 -0.175204" quat="1 -3.80336e-05 -4.90057e-05 7.90011e-05">
                        <inertial pos="-0.0011121 7.868e-05 -1.6641e-05" quat="0.496731 0.499693 0.504085 0.499464" mass="0.00543232" diaginertia="3.95673e-07 5.79628e-07 4.93113e-08"/>
                        <joint name="left_wrist_roll_joint" class="/" pos="0 0 0" axis="-1 -0.00030362 -0.00024165" stiffness="0.000388145" range="-0.930547 0.870994" armature="0.105284" damping="0.00888724" frictionloss="0.101837"/>
                        <geom name="//unnamed_geom_48" class="visual" mesh="left_hand_roll_link"/>
                        <body name="left_hand_pitch_link" pos="-0.000437794 0.00108982 -0.00189768" quat="1 2.45723e-05 -3.83381e-05 5.29895e-05">
                          <inertial pos="0.00155312 -0.01187 -0.0482073" quat="0.72371 -0.120936 0.113967 0.669799" mass="0.229012" diaginertia="0.00031799 0.000436285 6.43625e-05"/>
                          <joint name="left_wrist_pitch_joint" class="/" pos="0 0 0" axis="-0.0106372 0.999889 -0.0104342" range="-0.578757 0.617699" armature="0.106386" damping="0.000873676" frictionloss="0.104232"/>
                          <geom name="//unnamed_geom_49" class="visual" mesh="left_hand_pitch"/>
                          <body name="left_jaw_link" pos="0.000411021 -0.000480664 -0.0553896" quat="1 -0.000332521 -9.26883e-05 -0.000224275">
                            <inertial pos="0.000148581 0.00342863 -0.0317112" quat="0.708625 -0.0219921 0.0331983 0.704461" mass="0.07283" diaginertia="8.92251e-05 8.75716e-05 2.20473e-05"/>
                            <joint name="left_jaw_joint" class="/" pos="0 0 0" axis="-0.999969 0.00646308 0.0045799" range="-0.971058 0.0361879" armature="0.106341" damping="0.0004795" frictionloss="0.100529"/>
                            <geom name="//unnamed_geom_50" class="visual" mesh="left_jaw_link"/>
                            <geom name="//unnamed_geom_51" class="collision" size="0.0366101"/>
                            <geom name="//unnamed_geom_52" class="reward_collision_sphere" size="0.0508473" pos="0 0 -0.0185306"/>
                          </body>
                        </body>
                      </body>
                    </body>
                  </body>
                </body>
              </body>
            </body>
            <body name="right_upper_arm_pitch_link" pos="-6.71311e-05 -0.111163 0.191298" quat="0.976752 -0.214371 0.000138475 -0.00018836">
              <inertial pos="0.00369065 -0.0592361 -0.000412995" quat="0.706162 0.707203 0.0274791 0.0210876" mass="0.844074" diaginertia="0.00219618 0.0031755 0.000329503"/>
              <joint name="right_shoulder_pitch_joint" class="/" pos="0 0 0" axis="0.000754612 -1 0.000383766" range="-1.96918 2.81615" armature="0.0994276" damping="0.0169143" frictionloss="0.0987152"/>
              <geom name="//unnamed_geom_53" class="visual" mesh="right_upper_arm_pitch_link"/>
              <body name="right_upper_arm_roll_link" pos="0.0026433 -0.1042 0.00115321" quat="0.976699 0.214613 7.26892e-05 5.90732e-05">
                <inertial pos="0.00364626 -0.0194899 -0.0224312" quat="0.893408 -0.25893 0.120052 0.346935" mass="0.646107" diaginertia="0.00116163 0.00154859 0.000235557"/>
                <joint name="right_shoulder_roll_joint" class="/" pos="0 0 0" axis="-0.999965 0.0053789 0.00641544" range="-0.580276 2.56186" armature="0.119298" damping="0.0082416" frictionloss="0.111813"/>
                <geom name="//unnamed_geom_54" class="visual" mesh="right_upper_arm_roll_link"/>
                <body name="right_upper_arm_yaw_link" pos="0.00177848 -0.0426212 -0.0675516" quat="1 -3.07748e-05 5.04582e-06 1.84124e-05">
                  <inertial pos="0.00167858 0.000255568 -0.0812414" quat="0.999933 -0.0110324 0.000482506 0.0033702" mass="0.567671" diaginertia="0.00403267 0.00572097 0.000179529"/>
                  <joint name="right_shoulder_yaw_joint" class="/" pos="0 0 0" axis="0.000412283 0.00502359 0.999987" range="-2.99372 2.98722" armature="0.102878" damping="0.00276038" frictionloss="0.0965926"/>
                  <geom name="//unnamed_geom_55" class="visual" mesh="right_upper_arm_yaw_link"/>
                  <geom name="right_upper_arm_yaw_link.STL" class="collision" size="0.0368472 0.0863815" pos="4.04785e-05 0.000982968 -0.0735108" type="cylinder" rgba="0.752941 0.752941 0.752941 1"/>
                  <body name="right_lower_arm_pitch_link" pos="0.00151389 -0.00111797 -0.167516" quat="1 -4.8241e-05 -5.21623e-05 -0.000168219">
                    <inertial pos="-0.00163424 -0.0068353 -0.0227568" quat="0.701124 0.0921599 -0.091517 0.70111" mass="0.343443" diaginertia="0.000337414 0.000458281 6.7022e-05"/>
                    <joint name="right_elbow_pitch_joint" class="/" pos="0 0 0" axis="-0.00252591 -0.999995 0.00167371" range="-2.29405 2.27551" armature="0.109512" damping="0.00910089" frictionloss="0.10284"/>
                    <geom name="//unnamed_geom_57" class="visual" mesh="right_lower_arm_pitch_link"/>
                    <body name="right_hand_yaw_link" pos="0.00258988 0.000388495 -0.0530012" quat="1 2.96215e-05 0.000205684 -0.000185171">
                      <inertial pos="0.0014557 -0.00197189 -0.0656167" quat="0.999693 0.00516121 0.00136721 0.0242076" mass="1.03255" diaginertia="0.00292079 0.00400796 0.000346709"/>
                      <joint name="right_wrist_yaw_joint" class="/" pos="0 0 0" axis="-0.00277159 -0.00108891 0.999996" range="-2.99284 2.95667" armature="0.101987" damping="0" frictionloss="0.08895"/>
                      <geom name="//unnamed_geom_58" class="visual" mesh="right_hand_yaw_link"/>
                      <geom name="right_hand_yaw_link.STL" class="collision" size="0.0422764 0.0707731" pos="0.00111665 0.000704687 -0.070456" type="cylinder" rgba="0.752941 0.752941 0.752941 1"/>
                      <geom name="//unnamed_geom_60" class="reward_collision_sphere" size="0.0508473"/>
                      <body name="right_hand_roll_link" pos="-0.00225583 0.000633879 -0.176944" quat="1 -9.16815e-05 -9.93969e-05 9.2002e-05">
                        <inertial pos="0.00140122 -0.00229419 -0.000629286" quat="0.500044 0.500475 0.499102 0.500378" mass="0.00556814" diaginertia="4.07955e-07 5.6398e-07 4.87931e-08"/>
                        <joint name="right_wrist_roll_joint" class="/" pos="0 0 0" axis="-0.999936 -0.0112482 0.00142884" range="-0.825508 0.961167" armature="0.109121" damping="0.0258328" frictionloss="0.0996566"/>
                        <geom name="//unnamed_geom_61" class="visual" mesh="right_hand_roll_link"/>
                        <body name="right_hand_pitch_link" pos="-0.000628853 0.000243048 0.00102994" quat="1 0.000258833 0.000177782 0.000182926">
                          <inertial pos="-0.000967209 0.0101171 -0.0500277" quat="0.724824 0.117085 -0.117176 0.668723" mass="0.223153" diaginertia="0.000334062 0.000430461 6.42792e-05"/>
                          <joint name="right_wrist_pitch_joint" class="/" pos="0 0 0" axis="0.0052616 -0.999944 0.00919688" range="-0.638416 0.627856" armature="0.108315" damping="0.0109639" frictionloss="0.099832"/>
                          <geom name="//unnamed_geom_62" class="visual" mesh="right_hand_pitch"/>
                          <body name="right_jaw_link" pos="0.000345903 -0.00293659 -0.0565477" quat="1 -3.97944e-05 0.000167172 -4.94769e-05">
                            <inertial pos="-0.000492261 -0.00623931 -0.0335164" quat="0.707632 0.0221333 -0.0332215 0.705453" mass="0.0738313" diaginertia="9.06277e-05 9.06112e-05 2.21153e-05"/>
                            <joint name="right_jaw_joint" class="/" pos="0 0 0" axis="-1 -0.000388334 -9.37607e-05" range="0.0489046 0.998483" armature="0.105965" damping="0.00426393" frictionloss="0.102118"/>
                            <geom name="//unnamed_geom_63" class="visual" mesh="right_jaw_link"/>
                            <geom name="//unnamed_geom_64" class="collision" size="0.0366101"/>
                            <geom name="//unnamed_geom_65" class="reward_collision_sphere" size="0.0508473" pos="0 0 -0.0185306"/>
                          </body>
                        </body>
                      </body>
                    </body>
                  </body>
                </body>
              </body>
            </body>
            <body name="head_roll_link" pos="-0.000215104 0.00243547 0.283992" quat="1 -2.35022e-05 0.000271977 -0.000228771">
              <inertial pos="0.00495661 0.000552815 0.00186473" quat="0.000928272 0.709277 -0.00144997 0.704928" mass="0.0105725" diaginertia="7.89369e-07 7.04634e-07 2.91713e-07"/>
              <joint name="head_roll_joint" class="/" pos="0 0 0" axis="-0.999993 0.0010334 0.0035615" range="-0.364561 0.384011" armature="0.0978083" damping="0.00505595" frictionloss="0.114916"/>
              <geom name="//unnamed_geom_66" class="visual" mesh="head_roll_link"/>
              <body name="head_pitch_link" pos="-0.000424493 0.000777371 0.00211862" quat="1 0.000113205 -6.2551e-05 0.000238761">
                <inertial pos="-0.000906443 0.000105904 0.0157325" quat="0.666056 0.66851 0.232314 -0.235572" mass="0.0627721" diaginertia="2.96595e-05 3.81808e-05 1.20833e-05"/>
                <joint name="head_pitch_joint" class="/" pos="0 0 0" axis="-0.00124035 -0.99995 -0.00996431" range="-0.898468 0.846202" armature="0.0939798" damping="0.0134717" frictionloss="0.0921414"/>
                <geom name="//unnamed_geom_67" class="visual" mesh="head_pitch_link"/>
                <body name="head_yaw_link" pos="0.00022084 0.000706266 0.0519547" quat="1 5.54166e-06 4.81375e-07 7.362e-06">
                  <inertial pos="0.0281204 -0.00228426 0.0908863" quat="0.706779 -0.136715 -0.143762 0.679047" mass="1.68196" diaginertia="0.011834 0.0132606 0.00369331"/>
                  <joint name="head_yaw_joint" class="/" pos="0 0 0" axis="0.00291306 0.000945554 0.999995" range="-2.70701 2.72282" armature="0.100157" damping="0.00098355" frictionloss="0.113602"/>
                  <geom name="//unnamed_geom_68" class="visual" rgba="0.12 0.12 0.12 1" mesh="head_yaw_link"/>
                  <geom name="head_yaw_link.STL" class="collision" size="0.120698" pos="0.0187409 -0.000967288 0.0867418" rgba="0.752941 0.752941 0.752941 1"/>
                  <geom name="//unnamed_geom_70" class="reward_collision_sphere" size="0.101695" pos="0.0307545 0 0.0926529"/>
                  <camera name="ego_camera" class="/" pos="0.112767 0 0.101918" quat="-0.5 -0.5 0.5 0.5"/>
                </body>
              </body>
            </body>
          </body>
        </body>
      </body>
    </body>
  </worldbody>

  <contact>
    <pair class="/" geom1="floor" geom2="left_foot" name="//unnamed_contact_0"/>
    <pair class="/" geom1="floor" geom2="right_foot" name="//unnamed_contact_1"/>
  </contact>

  <actuator>
    <general name="left_hip_roll" class="/" joint="left_hip_roll_joint" forcerange="-49.9327 49.9327" gainprm="122.034" biasprm="0 -122.034 -1.01695"/>
    <general name="left_hip_yaw" class="/" joint="left_hip_yaw_joint" forcerange="-64.1158 64.1158" gainprm="122.034" biasprm="0 -122.034 -1.01695"/>
    <general name="left_hip_pitch" class="/" joint="left_hip_pitch_joint" forcerange="-237.634 237.634" gainprm="122.034" biasprm="0 -122.034 -1.01695"/>
    <general name="left_knee_pitch" class="/" joint="left_knee_pitch_joint" forcerange="-239.737 239.737" gainprm="122.034" biasprm="0 -122.034 -1.01695"/>
    <general name="left_ankle_pitch" class="/" joint="left_ankle_pitch_joint" forcerange="-15.1292 15.1292" gainprm="122.034" biasprm="0 -122.034 -1.01695"/>
    <general name="left_ankle_roll" class="/" joint="left_ankle_roll_joint" forcerange="-31.0727 31.0727" gainprm="122.034" biasprm="0 -122.034 -1.01695"/>
    <general name="right_hip_roll" class="/" joint="right_hip_roll_joint" forcerange="-47.7572 47.7572" gainprm="122.034" biasprm="0 -122.034 -1.01695"/>
    <general name="right_hip_yaw" class="/" joint="right_hip_yaw_joint" forcerange="-67.3005 67.3005" gainprm="122.034" biasprm="0 -122.034 -1.01695"/>
    <general name="right_hip_pitch" class="/" joint="right_hip_pitch_joint" forcerange="-231.392 231.392" gainprm="122.034" biasprm="0 -122.034 -1.01695"/>
    <general name="right_knee_pitch" class="/" joint="right_knee_pitch_joint" forcerange="-240.202 240.202" gainprm="122.034" biasprm="0 -122.034 -1.01695"/>
    <general name="right_ankle_pitch" class="/" joint="right_ankle_pitch_joint" forcerange="-15.5626 15.5626" gainprm="122.034" biasprm="0 -122.034 -1.01695"/>
    <general name="right_ankle_roll" class="/" joint="right_ankle_roll_joint" forcerange="-33.3064 33.3064" gainprm="122.034" biasprm="0 -122.034 -1.01695"/>
    <general name="waist_yaw" class="/" joint="waist_yaw_joint" forcerange="-68.9007 68.9007" gainprm="122.034" biasprm="0 -122.034 -1.01695"/>
    <general name="waist_pitch" class="/" joint="waist_pitch_joint" forcerange="-69.0382 69.0382" gainprm="122.034" biasprm="0 -122.034 -1.01695"/>
    <general name="waist_roll" class="/" joint="waist_roll_joint" forcerange="-68.3197 68.3197" gainprm="122.034" biasprm="0 -122.034 -1.01695"/>
    <general name="left_shoulder_pitch" class="/" joint="left_shoulder_pitch_joint" forcerange="-41.4975 41.4975" gainprm="122.034" biasprm="0 -122.034 -1.01695"/>
    <general name="left_shoulder_roll" class="/" joint="left_shoulder_roll_joint" forcerange="-39.7664 39.7664" gainprm="122.034" biasprm="0 -122.034 -1.01695"/>
    <general name="left_shoulder_yaw" class="/" joint="left_shoulder_yaw_joint" forcerange="-29.2771 29.2771" gainprm="122.034" biasprm="0 -122.034 -1.01695"/>
    <general name="left_elbow_pitch" class="/" joint="left_elbow_pitch_joint" forcerange="-30.0387 30.0387" gainprm="122.034" biasprm="0 -122.034 -1.01695"/>
    <general name="left_wrist_yaw" class="/" joint="left_wrist_yaw_joint" forcerange="-10.5128 10.5128" gainprm="122.034" biasprm="0 -122.034 -1.01695"/>
    <general name="left_wrist_roll" class="/" joint="left_wrist_roll_joint" forcerange="-3.95088 3.95088" gainprm="122.034" biasprm="0 -122.034 -1.01695"/>
    <general name="left_wrist_pitch" class="/" joint="left_wrist_pitch_joint" forcerange="-3.87282 3.87282" gainprm="122.034" biasprm="0 -122.034 -1.01695"/>
    <general name="left_jaw" class="/" joint="left_jaw_joint" forcerange="-4.0358 4.0358" gainprm="122.034" biasprm="0 -122.034 -1.01695"/>
    <general name="right_shoulder_pitch" class="/" joint="right_shoulder_pitch_joint" forcerange="-38.913 38.913" gainprm="122.034" biasprm="0 -122.034 -1.01695"/>
    <general name="right_shoulder_roll" class="/" joint="right_shoulder_roll_joint" forcerange="-38.3038 38.3038" gainprm="122.034" biasprm="0 -122.034 -1.01695"/>
    <general name="right_shoulder_yaw" class="/" joint="right_shoulder_yaw_joint" forcerange="-30.2936 30.2936" gainprm="122.034" biasprm="0 -122.034 -1.01695"/>
    <general name="right_elbow_pitch" class="/" joint="right_elbow_pitch_joint" forcerange="-27.6822 27.6822" gainprm="122.034" biasprm="0 -122.034 -1.01695"/>
    <general name="right_wrist_yaw" class="/" joint="right_wrist_yaw_joint" forcerange="-9.93328 9.93328" gainprm="122.034" biasprm="0 -122.034 -1.01695"/>
    <general name="right_wrist_roll" class="/" joint="right_wrist_roll_joint" forcerange="-3.89236 3.89236" gainprm="122.034" biasprm="0 -122.034 -1.01695"/>
    <general name="right_wrist_pitch" class="/" joint="right_wrist_pitch_joint" forcerange="-3.86986 3.86986" gainprm="122.034" biasprm="0 -122.034 -1.01695"/>
    <general name="right_jaw" class="/" joint="right_jaw_joint" forcerange="-4.37067 4.37067" gainprm="122.034" biasprm="0 -122.034 -1.01695"/>
    <general name="head_roll" class="/" joint="head_roll_joint" forcerange="-3.96412 3.96412" gainprm="122.034" biasprm="0 -122.034 -1.01695"/>
    <general name="head_pitch" class="/" joint="head_pitch_joint" forcerange="-4.06003 4.06003" gainprm="122.034" biasprm="0 -122.034 -1.01695"/>
    <general name="head_yaw" class="/" joint="head_yaw_joint" forcerange="-4.16826 4.16826" gainprm="122.034" biasprm="0 -122.034 -1.01695"/>
  </actuator>

  <sensor>
    <gyro site="imu" name="imu_angular_velocity"/>
    <velocimeter site="imu" name="imu_linear_velocity"/>
    <framelinvel objtype="site" objname="left_foot" name="left_foot_global_linear_velocity"/>
    <framelinvel objtype="site" objname="right_foot" name="right_foot_global_linear_velocity"/>
  </sensor>

  <keyframe>
    <key name="home" qpos="0 0 0.8665 1 0 0 0 0 0 -0.4 0.8 -0.4 0 0 0 0.4 -0.8 0.4 0 0 0 0 0 -0.2 0 -0.785 0 0 0 0 0 0.2 0 0.785 0 0 0 0 0 0 0"/>
  </keyframe>
</mujoco>
