<mujoco model="GR1T2_jaw">
  <compiler angle="radian" assetdir="assets" balanceinertia="true" inertiafromgeom="false"/>

  <option timestep="0.005" density="1.2" viscosity="2e-05"/>

  <size nkey="1"/>

  <visual>
    <quality shadowsize="8192"/>
    <map shadowclip="0.5"/>
  </visual>

  <default>
    <default class="/">
      <joint armature="0.1" damping="0.01" frictionloss="0.1"/>
      <geom contype="0" conaffinity="0" group="1" solref="-1000 -80"/>
      <site size="0.01 0.005 0.005" group="5"/>
      <general forcelimited="true" biastype="affine" gainprm="80" biasprm="0 -80 -2"/>
      <default class="visual">
        <geom type="mesh" density="0" rgba="0.18 0.18 0.18 1"/>
      </default>
      <default class="collision">
        <geom group="3"/>
      </default>
      <default class="foot">
        <geom size="0.126 0.045 0.01" type="box" condim="6" group="4" priority="1" solimp="0.015 1 0.01"/>
      </default>
      <default class="reward_collision_sphere">
        <geom group="5" rgba="1 0 0 1"/>
      </default>
    </default>
  </default>

  <asset>
    <texture type="skybox" colorspace="auto" name="//unnamed_texture_0" builtin="gradient" rgb1="0.95 0.95 0.95" rgb2="0.95 0.95 0.95" width="100" height="600"/>
    <texture type="2d" colorspace="auto" name="texplane" builtin="checker" rgb1="0.345 0.575 0.748" rgb2="0.345 0.575 0.748" markrgb="1 1 1" width="512" height="512"/>
    <material name="MatPlane" class="/" texture="texplane" texuniform="true" texrepeat="2 2" specular="0.9"/>
    <mesh name="base_link" class="/" file="base_link.STL"/>
    <mesh name="left_thigh_roll_link" class="/" file="left_thigh_roll_link.STL"/>
    <mesh name="left_thigh_yaw_link" class="/" file="left_thigh_yaw_link.STL"/>
    <mesh name="left_thigh_pitch_link" class="/" file="left_thigh_pitch_link.STL"/>
    <mesh name="left_shank_pitch_link" class="/" file="left_shank_pitch_link.STL"/>
    <mesh name="left_foot_pitch_link" class="/" file="left_foot_pitch_link.STL"/>
    <mesh name="left_foot_roll_link" class="/" file="left_foot_roll_link.STL"/>
    <mesh name="right_thigh_roll_link" class="/" file="right_thigh_roll_link.STL"/>
    <mesh name="right_thigh_yaw_link" class="/" file="right_thigh_yaw_link.STL"/>
    <mesh name="right_thigh_pitch_link" class="/" file="right_thigh_pitch_link.STL"/>
    <mesh name="right_shank_pitch_link" class="/" file="right_shank_pitch_link.STL"/>
    <mesh name="right_foot_pitch_link" class="/" file="right_foot_pitch_link.STL"/>
    <mesh name="right_foot_roll_link" class="/" file="right_foot_roll_link.STL"/>
    <mesh name="waist_yaw_link" class="/" file="waist_yaw_link.STL"/>
    <mesh name="waist_pitch_link" class="/" file="waist_pitch_link.STL"/>
    <mesh name="waist_roll_link" class="/" file="waist_roll_link.STL"/>
    <mesh name="torso_link" class="/" file="torso_link.STL"/>
    <mesh name="left_upper_arm_pitch_link" class="/" file="left_upper_arm_pitch_link.STL"/>
    <mesh name="left_upper_arm_roll_link" class="/" file="left_upper_arm_roll_link.STL"/>
    <mesh name="left_upper_arm_yaw_link" class="/" file="left_upper_arm_yaw_link.STL"/>
    <mesh name="left_lower_arm_pitch_link" class="/" file="left_lower_arm_pitch_link.STL"/>
    <mesh name="left_hand_yaw_link" class="/" file="left_hand_yaw_link.STL"/>
    <mesh name="left_hand_roll_link" class="/" file="left_hand_roll_link.STL"/>
    <mesh name="left_hand_pitch" class="/" file="left_hand_pitch.STL"/>
    <mesh name="left_jaw_link" class="/" file="left_jaw_link.STL"/>
    <mesh name="right_upper_arm_pitch_link" class="/" file="right_upper_arm_pitch_link.STL"/>
    <mesh name="right_upper_arm_roll_link" class="/" file="right_upper_arm_roll_link.STL"/>
    <mesh name="right_upper_arm_yaw_link" class="/" file="right_upper_arm_yaw_link.STL"/>
    <mesh name="right_lower_arm_pitch_link" class="/" file="right_lower_arm_pitch_link.STL"/>
    <mesh name="right_hand_yaw_link" class="/" file="right_hand_yaw_link.STL"/>
    <mesh name="right_hand_roll_link" class="/" file="right_hand_roll_link.STL"/>
    <mesh name="right_hand_pitch" class="/" file="right_hand_pitch.STL"/>
    <mesh name="right_jaw_link" class="/" file="right_jaw_link.STL"/>
    <mesh name="head_roll_link" class="/" file="head_roll_link.STL"/>
    <mesh name="head_pitch_link" class="/" file="head_pitch_link.STL"/>
    <mesh name="head_yaw_link" class="/" file="head_yaw_link.STL"/>
    <mesh name="imu_link" class="/" file="imu_link.STL"/>
  </asset>

  <worldbody>
    <geom name="floor" class="/" size="100 100 0.125" type="plane" group="0" material="MatPlane"/>
    <light name="toplight_shadow" class="/" pos="0 0 5" dir="0.0990148 0.0990148 -0.990148" type="directional" ambient="0.04 0.04 0.04" diffuse="0.55 0.55 0.55" specular="0.12 0.12 0.12"/>
    <light name="toplight_fill" class="/" pos="0 0 5" dir="0.0990148 0.0990148 -0.990148" type="directional" castshadow="false" ambient="0.04 0.04 0.04" diffuse="0.3 0.3 0.3" specular="0.08 0.08 0.08"/>
    <body name="trunk" pos="-0.0114968 0.0074299 0.0167243" quat="0.999995 0.00293552 -0.000875584 -0.000126908">
      <inertial pos="-0.0591175 -0.0126313 0.00219036" quat="0.999995 0.00144402 -0.000716857 0.0027605" mass="9.00192" diaginertia="0.0575381 0.082774 0.177422"/>
      <joint name="//unnamed_joint_0" type="free"/>
      <geom name="//unnamed_geom_1" class="visual" rgba="0.12 0.12 0.12 1" mesh="base_link"/>
      <geom name="base_link.STL" class="collision" size="0.160154 0.0896988" pos="-0.0461224 0.000561864 0.0121944" quat="0.706838 -0.707359 0.00477667 0" type="cylinder" rgba="0.752941 0.752941 0.752941 1"/>
      <geom name="//unnamed_geom_3" class="visual" pos="0 0 -0.078912" quat="1 0 0 0" rgba="0.12 0.12 0.12 1" mesh="imu_link"/>
      <geom name="//unnamed_geom_4" class="reward_collision_sphere" size="0.104681" pos="0 0.151838 0.132403"/>
      <geom name="//unnamed_geom_5" class="reward_collision_sphere" size="0.104681" pos="0 -0.151838 0.132403"/>
      <site name="imu" class="/" pos="0.0339407 -0.00917865 -0.0744776" size="0.0130851"/>
      <camera name="track" class="/" pos="0 -3.03676 0" quat="0.707107 0.707107 0 0" mode="trackcom"/>
      <body name="left_thigh_roll_link" pos="-0.0453685 0.16497 -0.0265214" quat="0.999966 -0.00391378 -0.00344708 -0.00632391">
        <inertial pos="0.0102808 0.0121532 0.0019248" quat="-0.0555151 0.70781 -0.0600004 0.701657" mass="2.66897" diaginertia="0.0042651 0.0218224 0.00600244"/>
        <joint name="left_hip_roll_joint" class="/" pos="0 0 0" axis="-0.999113 0.0356295 -0.0224539" range="-1.06817 -0.144423" armature="0.0567679" damping="0" frictionloss="0.0731607"/>
        <geom name="//unnamed_geom_6" class="visual" mesh="left_thigh_roll_link"/>
        <body name="left_thigh_yaw_link" pos="0.0497145 -0.012073 -0.0123482" quat="0.999971 0.00577415 -0.00504202 0.000320587">
          <inertial pos="0.01287 0.0431633 -0.161835" quat="0.570469 0.118814 -0.23246 0.778724" mass="8.23039" diaginertia="0.0356881 0.160531 0.0490666"/>
          <joint name="left_hip_yaw_joint" class="/" pos="0 0 0" axis="0.00344474 -0.00115232 -0.999993" stiffness="0.000826803" range="-0.892779 0.602699" armature="0.11159" damping="0.00692168" frictionloss="0.165917"/>
          <geom name="//unnamed_geom_7" class="visual" mesh="left_thigh_yaw_link"/>
          <body name="left_thigh_pitch_link" pos="0.0165177 0.0215257 -0.195671" quat="1 -0.000245872 4.5207e-05 0.000112777">
            <inertial pos="-0.0146946 -0.0499046 -0.0918122" quat="0.999105 -0.0306959 -0.0247836 -0.0152658" mass="17.038" diaginertia="0.108569 0.501471 0.104935"/>
            <joint name="left_hip_pitch_joint" class="/" pos="0 0 0" axis="-0.0279952 0.999607 -0.00141135" range="-1.74066 0.982527" armature="0.23684" damping="0.00837554" frictionloss="0.0220631"/>
            <geom name="//unnamed_geom_8" class="visual" mesh="left_thigh_pitch_link"/>
            <geom name="left_thigh_pitch_link.STL" class="collision" size="0.107298 0.163451" pos="0.000758239 -0.0455514 -0.221187" type="cylinder" rgba="0.752941 0.752941 0.752941 1"/>
            <geom name="//unnamed_geom_10" class="reward_collision_sphere" size="0.130851" pos="0 -0.0151838 -0.0662013"/>
            <body name="left_shank_pitch_link" pos="2.9399e-05 -0.0291397 -0.469617" quat="1 -1.60703e-05 -0.000410082 0.000134171">
              <inertial pos="-0.00791062 -0.00135444 -0.168242" quat="0.999698 -0.0109882 0.004441 -0.0215357" mass="4.43372" diaginertia="0.0186813 0.0967642 0.0056034"/>
              <joint name="left_knee_pitch_joint" class="/" pos="0 0 0" axis="-0.0764551 0.996949 -0.0156988" range="-0.207863 2.1791" armature="0.177031" damping="0" frictionloss="0.0836539"/>
              <geom name="//unnamed_geom_11" class="visual" mesh="left_shank_pitch_link"/>
              <geom name="left_shank_pitch_link.STL" class="collision" size="0.0697715 0.11827" pos="-1.79691e-05 -0.00127931 -0.231295" quat="0.00125538 -0.202712 0.979238 0" type="cylinder" rgba="0.752941 0.752941 0.752941 1"/>
              <geom name="//unnamed_geom_13" class="reward_collision_sphere" size="0.0654254"/>
              <geom name="//unnamed_geom_14" class="reward_collision_sphere" size="0.0785105" pos="0 0 -0.145643"/>
              <body name="left_foot_pitch_link" pos="-0.00939526 0.011689 -0.458516" quat="0.999996 -0.00179964 -0.00196227 0.0011949">
                <inertial pos="0.000770754 -0.0103695 0.00414031" quat="0.0120762 0.683985 0.00555461 0.729375" mass="0.161231" diaginertia="1.04486e-05 4.59592e-05 1.93615e-05"/>
                <joint name="left_ankle_pitch_joint" class="/" pos="0 0 0" axis="0.000568217 0.99997 -0.00775414" stiffness="0.00714383" range="-0.965144 0.742998" armature="0.0500598" damping="0.0280674" frictionloss="0.231848"/>
                <geom name="//unnamed_geom_15" class="visual" mesh="left_foot_pitch_link"/>
                <body name="left_foot_roll_link" pos="0.00777152 -0.0143035 -0.00140842" quat="1 0.000574896 -0.00029128 0.000378499">
                  <inertial pos="0.0235876 -0.00444874 -0.0362621" quat="-0.0483951 0.745723 -0.0294522 0.663844" mass="2.50252" diaginertia="0.00965918 0.0419306 0.00307259"/>
                  <joint name="left_ankle_roll_joint" class="/" pos="0 0 0" axis="-0.998371 -0.0292253 -0.0490125" stiffness="0.00316092" range="-0.460247 0.102518" armature="0.192673" damping="0.0521508" frictionloss="0.215349"/>
                  <geom name="//unnamed_geom_16" class="visual" mesh="left_foot_roll_link"/>
                  <geom name="left_foot" class="foot" size="0.209874 0.0528035 0.011332" pos="0.0487404 0 -0.0589192"/>
                  <geom name="//unnamed_geom_18" class="reward_collision_sphere" size="0.0654254" pos="0 0 -0.0397208"/>
                  <geom name="//unnamed_geom_19" class="reward_collision_sphere" size="0.0654254" pos="0.129974 0 -0.0397208"/>
                  <site name="left_foot" class="foot" pos="0.0487404 0 -0.0589192" size="0.0130851"/>
                </body>
              </body>
            </body>
          </body>
        </body>
      </body>
      <body name="right_thigh_roll_link" pos="-0.0499822 -0.163899 -0.0410604" quat="0.999995 -0.000255728 0.0030158 -0.000768626">
        <inertial pos="0.00126942 0.0093273 0.00567704" quat="0.0137603 0.663164 0.0270178 0.74786" mass="3.35009" diaginertia="0.00344259 0.0206283 0.00480315"/>
        <joint name="right_hip_roll_joint" class="/" pos="0 0 0" axis="-0.999999 0.000306322 0.0013608" range="0.0799062 0.646001" armature="0.099587" damping="0" frictionloss="0.147063"/>
        <geom name="//unnamed_geom_20" class="visual" mesh="right_thigh_roll_link"/>
        <body name="right_thigh_yaw_link" pos="0.0416933 0.000693462 -0.0137383" quat="0.999977 -0.00617285 0.000157161 -0.00286079">
          <inertial pos="0.000702954 -0.067681 -0.14605" quat="0.708931 -0.115553 0.125167 0.684396" mass="6.00095" diaginertia="0.0319372 0.114737 0.0286858"/>
          <joint name="right_hip_yaw_joint" class="/" pos="0 0 0" axis="0.000138441 -3.44413e-05 -1" stiffness="0.0264899" range="-0.926227 0.879877" armature="0.185193" damping="0.017563" frictionloss="0.0439715"/>
          <geom name="//unnamed_geom_21" class="visual" mesh="right_thigh_yaw_link"/>
          <body name="right_thigh_pitch_link" pos="0.0168175 -0.0213061 -0.17205" quat="1 0.000161273 -0.000129429 0.000358972">
            <inertial pos="-0.0139189 0.051822 -0.0693134" quat="0.999148 0.019118 -0.0343656 -0.0124971" mass="16.9405" diaginertia="0.15199 0.689177 0.103851"/>
            <joint name="right_hip_pitch_joint" class="/" pos="0 0 0" axis="-5.51958e-06 -0.999837 0.0180565" range="-0.610551 1.57968" armature="0.0229539" damping="0.0525268" frictionloss="0.102706"/>
            <geom name="//unnamed_geom_22" class="visual" mesh="right_thigh_pitch_link"/>
            <geom name="right_thigh_pitch_link.STL" class="collision" size="0.107298 0.163447" pos="-0.00229976 0.0455514 -0.221187" quat="0.999971 0.00269833 0.00706272 0" type="cylinder" rgba="0.752941 0.752941 0.752941 1"/>
            <geom name="//unnamed_geom_24" class="reward_collision_sphere" size="0.130851" pos="0 0.0151838 -0.0662013"/>
            <body name="right_shank_pitch_link" pos="-0.00718403 0.0286438 -0.484566" quat="1 0.0001014 0.000380698 -0.000134823">
              <inertial pos="0.0127755 -0.0137858 -0.156015" quat="0.999633 0.00784576 0.0176055 0.0190611" mass="3.98832" diaginertia="0.0159945 0.0992636 0.00486919"/>
              <joint name="right_knee_pitch_joint" class="/" pos="0 0 0" axis="-0.0164012 -0.999789 0.0124069" stiffness="0.0789503" range="-2.0464 0.381597" armature="0.207868" damping="0" frictionloss="0.0268901"/>
              <geom name="//unnamed_geom_25" class="visual" mesh="right_shank_pitch_link"/>
              <geom name="right_shank_pitch_link.STL" class="collision" size="0.0697711 0.118268" pos="-1.79691e-05 -0.00127932 -0.231306" type="cylinder" rgba="0.752941 0.752941 0.752941 1"/>
              <geom name="//unnamed_geom_27" class="reward_collision_sphere" size="0.0654254"/>
              <geom name="//unnamed_geom_28" class="reward_collision_sphere" size="0.0785105" pos="0 0 -0.145643"/>
              <body name="right_foot_pitch_link" pos="-0.0120381 -0.0137901 -0.450513" quat="0.999974 -0.00128804 0.00515746 -0.00477714">
                <inertial pos="-0.00430376 -0.0125011 0.0021109" quat="-0.0267681 0.709366 -0.0113135 0.704241" mass="0.147317" diaginertia="9.60799e-06 4.75429e-05 2.09403e-05"/>
                <joint name="right_ankle_pitch_joint" class="/" pos="0 0 0" axis="-0.00218311 -0.999996 -0.0019239" range="-0.64558 1.15262" armature="0.0628246" damping="0" frictionloss="0.0769089"/>
                <geom name="//unnamed_geom_29" class="visual" mesh="right_foot_pitch_link"/>
                <body name="right_foot_roll_link" pos="-0.0121016 -0.00996218 0.0114412" quat="0.99997 0.0026345 -0.00305965 -0.00656939">
                  <inertial pos="0.0486607 -0.00462888 -0.0392814" quat="0.0245646 0.678937 -0.0494298 0.732119" mass="2.30298" diaginertia="0.00819372 0.0446266 0.00355517"/>
                  <joint name="right_ankle_roll_joint" class="/" pos="0 0 0" axis="-0.999999 0.00105868 -0.000680311" range="-0.676531 0.632347" armature="0.13517" damping="0.000812003" frictionloss="0.0262397"/>
                  <geom name="//unnamed_geom_30" class="visual" mesh="right_foot_roll_link"/>
                  <geom name="right_foot" class="foot" size="0.22748 0.0433761 0.0183797" pos="0.0487404 0 -0.0589192"/>
                  <geom name="//unnamed_geom_32" class="reward_collision_sphere" size="0.0654254" pos="0 0 -0.0397208"/>
                  <geom name="//unnamed_geom_33" class="reward_collision_sphere" size="0.0654254" pos="0.129974 0 -0.0397208"/>
                  <site name="right_foot" class="foot" pos="0.0487404 0 -0.0589192" size="0.0130851"/>
                </body>
              </body>
            </body>
          </body>
        </body>
      </body>
      <body name="waist_yaw_link" pos="0.00222713 -0.00967443 0.00383135" quat="1 -0.000125502 -3.01717e-05 0.000102087">
        <inertial pos="0.00725413 -0.0223362 0.0768436" quat="0.967991 0.23571 0.0186033 0.0841906" mass="4.55801" diaginertia="0.00557225 0.0379925 0.00836688"/>
        <joint name="waist_yaw_joint" class="/" pos="0 0 0" axis="0.0414149 0.0249365 0.998831" range="-1.2961 1.01942" armature="0.153151" damping="0.0141772" frictionloss="0.0525834"/>
        <geom name="//unnamed_geom_34" class="visual" rgba="0.12 0.12 0.12 1" mesh="waist_yaw_link"/>
        <body name="waist_pitch_link" pos="-0.00637165 -0.00180476 0.109347" quat="0.999999 0.00084683 0.000636426 -0.000400201">
          <inertial pos="0.017272 -0.0162543 0.0541698" quat="0.998845 -0.0064201 0.0279898 0.0385133" mass="3.12611" diaginertia="0.00833847 0.045968 0.00705802"/>
          <joint name="waist_pitch_joint" class="/" pos="0 0 0" axis="0.00634244 -0.999648 -0.0257451" stiffness="0.0834018" range="-1.53202 0.506263" armature="0.133473" damping="0.0264721" frictionloss="0.146365"/>
          <geom name="//unnamed_geom_35" class="visual" rgba="0.12 0.12 0.12 1" mesh="waist_pitch_link"/>
          <body name="waist_roll_link" pos="0.00616524 0.00140815 0.109145" quat="1 0.000364842 7.3742e-05 -0.000258486">
            <inertial pos="-0.0105101 0.00256913 0.181538" quat="0.996026 -0.0103355 -0.087592 -0.0123721" mass="14.9183" diaginertia="0.094982 0.550537 0.116987"/>
            <joint name="waist_roll_joint" class="/" pos="0 0 0" axis="-0.999651 -0.011787 0.0236466" range="-0.482326 0.427431" armature="0.0622056" damping="0.00779505" frictionloss="0.0458486"/>
            <geom name="//unnamed_geom_36" class="visual" rgba="0.12 0.12 0.12 1" mesh="waist_roll_link"/>
            <geom name="//unnamed_geom_37" class="visual" pos="-0.00243702 0.000872202 0.212308" quat="1 0 0 0" mesh="torso_link"/>
            <geom name="torso_link.STL" class="collision" size="0.205995 0.0395078" pos="-0.0195675 0.00876074 0.19573" type="cylinder" rgba="0.752941 0.752941 0.752941 1"/>
            <geom name="//unnamed_geom_39" class="reward_collision_sphere" size="0.170106" pos="0 0 0.264805"/>
            <body name="left_upper_arm_pitch_link" pos="-0.00361353 0.163292 0.286017" quat="0.975453 0.220169 0.00416451 0.000664991">
              <inertial pos="0.0070519 0.0837133 0.00982121" quat="0.707644 0.704887 0.00444739 -0.0485166" mass="2.10373" diaginertia="0.00378961 0.0214084 0.00242489"/>
              <joint name="left_shoulder_pitch_joint" class="/" pos="0 0 0" axis="6.06363e-05 1 0.000777315" stiffness="0.00619268" range="-2.91095 2.07216" armature="0.0553106" damping="0" frictionloss="0.0603254"/>
              <geom name="//unnamed_geom_40" class="visual" mesh="left_upper_arm_pitch_link"/>
              <body name="left_upper_arm_roll_link" pos="-0.00982491 0.1329 -0.0124807" quat="0.976722 -0.214507 -0.000149406 -0.000282491">
                <inertial pos="0.0145987 0.0224762 -0.0258517" quat="0.891627 0.272958 0.11248 -0.343284" mass="1.05493" diaginertia="0.00148092 0.0065234 0.00113447"/>
                <joint name="left_shoulder_roll_joint" class="/" pos="0 0 0" axis="-0.996403 0.0245131 -0.0811146" stiffness="0.0831521" range="-2.50256 0.479912" armature="0.0937947" damping="0.0621024" frictionloss="0.216688"/>
                <geom name="//unnamed_geom_41" class="visual" mesh="left_upper_arm_roll_link"/>
                <body name="left_upper_arm_yaw_link" pos="0.0161984 0.0753997 -0.101659" quat="0.999992 -0.00216714 0.00155348 0.00306626">
                  <inertial pos="0.0116827 0.0124225 -0.126548" quat="0.998879 0.0128145 0.0437336 0.0128106" mass="1.17629" diaginertia="0.00445509 0.0217651 0.000880124"/>
                  <joint name="left_shoulder_yaw_joint" class="/" pos="0 0 0" axis="-0.00888134 -0.0117121 0.999892" stiffness="0.0750385" range="-2.926 2.98795" armature="0.0340135" damping="0.0830889" frictionloss="0.107221"/>
                  <geom name="//unnamed_geom_42" class="visual" mesh="left_upper_arm_yaw_link"/>
                  <geom name="left_upper_arm_yaw_link.STL" class="collision" size="0.0474114 0.111147" pos="4.27674e-05 -0.00135787 -0.105048" quat="0.00803418 -0.995528 0.0941277 0" type="cylinder" rgba="0.752941 0.752941 0.752941 1"/>
                  <body name="left_lower_arm_pitch_link" pos="0.0158106 -0.00714462 -0.235888" quat="0.999989 -0.00244641 0.00368165 -0.00127395">
                    <inertial pos="-0.0159399 0.0153658 -0.0418958" quat="0.71159 -0.117218 0.109387 0.684057" mass="0.736099" diaginertia="0.000541618 0.00243422 0.000390625"/>
                    <joint name="left_elbow_pitch_joint" class="/" pos="0 0 0" axis="-0.00103908 0.999924 -0.0122552" range="-2.0399 2.16402" armature="0.0754186" damping="0" frictionloss="0.106579"/>
                    <geom name="//unnamed_geom_44" class="visual" mesh="left_lower_arm_pitch_link"/>
                    <body name="left_hand_yaw_link" pos="0.00201108 0.0135975 -0.0941013" quat="0.999982 0.00163268 0.00566081 -0.00150142">
                      <inertial pos="0.000258143 0.0177758 -0.0987108" quat="0.999451 0.00974604 0.0316653 0.00080833" mass="2.15778" diaginertia="0.00291952 0.0197924 0.00164977"/>
                      <joint name="left_wrist_yaw_joint" class="/" pos="0 0 0" axis="0.0108683 0.00124729 0.99994" range="-2.82348 3.01965" armature="0.0542875" damping="0" frictionloss="0.0422288"/>
                      <geom name="//unnamed_geom_45" class="visual" mesh="left_hand_yaw_link"/>
                      <geom name="left_hand_yaw_link.STL" class="collision" size="0.0543972 0.0910639" pos="0.00117979 -0.00233999 -0.100683" type="cylinder" rgba="0.752941 0.752941 0.752941 1"/>
                      <geom name="//unnamed_geom_47" class="reward_collision_sphere" size="0.0654254"/>
                      <body name="left_hand_roll_link" pos="-0.00438659 0.00100706 -0.267441" quat="0.99999 -0.00263418 2.48544e-05 0.00371069">
                        <inertial pos="-0.00690249 0.000571023 0.00331913" quat="0.495984 0.524457 0.486152 0.492546" mass="0.00909843" diaginertia="5.05324e-07 2.2665e-06 2.2763e-07"/>
                        <joint name="left_wrist_roll_joint" class="/" pos="0 0 0" axis="-0.999997 -0.00212859 0.00083463" stiffness="0.00552706" range="-0.827311 0.831934" armature="0.138364" damping="0" frictionloss="0.188759"/>
                        <geom name="//unnamed_geom_48" class="visual" mesh="left_hand_roll_link"/>
                        <body name="left_hand_pitch_link" pos="-0.00754023 -0.00176956 0.012242" quat="1 0.000169978 0.000119005 -5.56274e-05">
                          <inertial pos="-0.013526 -0.0177313 -0.0823928" quat="0.723695 -0.119323 0.112753 0.670309" mass="0.496176" diaginertia="0.000496483 0.00234366 0.000382522"/>
                          <joint name="left_wrist_pitch_joint" class="/" pos="0 0 0" axis="-0.0552825 0.99722 -0.0499683" stiffness="0.0255917" range="-0.489887 0.709637" armature="0.111821" damping="0.0670346" frictionloss="0.157558"/>
                          <geom name="//unnamed_geom_49" class="visual" mesh="left_hand_pitch"/>
                          <body name="left_jaw_link" pos="0.00748333 0.0101567 -0.0733092" quat="0.999994 -0.00274811 0.00122838 0.00181028">
                            <inertial pos="0.00372441 0.0168717 -0.0474554" quat="0.703333 -0.0173755 0.0354088 0.709765" mass="0.163036" diaginertia="0.000119398 0.000524809 0.000132266"/>
                            <joint name="left_jaw_joint" class="/" pos="0 0 0" axis="-0.998027 -0.0336864 -0.0529828" range="-1.03156 -0.318904" armature="0.134468" damping="0.0730387" frictionloss="0.12602"/>
                            <geom name="//unnamed_geom_50" class="visual" mesh="left_jaw_link"/>
                            <geom name="//unnamed_geom_51" class="collision" size="0.0471063"/>
                            <geom name="//unnamed_geom_52" class="reward_collision_sphere" size="0.0654254" pos="0 0 -0.0264805"/>
                          </body>
                        </body>
                      </body>
                    </body>
                  </body>
                </body>
              </body>
            </body>
            <body name="right_upper_arm_pitch_link" pos="0.00290328 -0.14192 0.278511" quat="0.976191 -0.216909 0.00128405 0.000579657">
              <inertial pos="0.00146993 -0.0825786 -0.00813352" quat="0.705297 0.708031 0.0268088 0.0230168" mass="2.26153" diaginertia="0.00420806 0.0153599 0.00237528"/>
              <joint name="right_shoulder_pitch_joint" class="/" pos="0 0 0" axis="-0.00964163 -0.999949 -0.0028903" range="-1.60952 2.90144" armature="0.0930725" damping="0" frictionloss="0.14245"/>
              <geom name="//unnamed_geom_53" class="visual" mesh="right_upper_arm_pitch_link"/>
              <body name="right_upper_arm_roll_link" pos="0.00644806 -0.149607 -0.0103075" quat="0.976668 0.214753 -9.64741e-05 4.76437e-05">
                <inertial pos="-0.00224149 -0.0302645 -0.0308327" quat="0.881921 -0.335492 0.114049 0.310891" mass="1.21177" diaginertia="0.00157066 0.00988276 0.00134037"/>
                <joint name="right_shoulder_roll_joint" class="/" pos="0 0 0" axis="-0.999498 -0.0287918 -0.0132105" range="-0.746395 2.65511" armature="0.0284513" damping="0" frictionloss="0.0458441"/>
                <geom name="//unnamed_geom_54" class="visual" mesh="right_upper_arm_roll_link"/>
                <body name="right_upper_arm_yaw_link" pos="0.00727912 -0.071147 -0.0800866" quat="0.999989 -0.000211079 -0.00421587 -0.00195739">
                  <inertial pos="-0.013759 0.00742564 -0.115723" quat="0.998817 0.0327161 0.0123623 -0.033785" mass="1.21308" diaginertia="0.00592489 0.0300012 0.00112931"/>
                  <joint name="right_shoulder_yaw_joint" class="/" pos="0 0 0" axis="0.00686999 -0.0615224 0.998082" range="-3.08738 2.99321" armature="0.106458" damping="0" frictionloss="0.0876347"/>
                  <geom name="//unnamed_geom_55" class="visual" mesh="right_upper_arm_yaw_link"/>
                  <geom name="right_upper_arm_yaw_link.STL" class="collision" size="0.0474114 0.111147" pos="4.27674e-05 0.00135787 -0.105048" type="cylinder" rgba="0.752941 0.752941 0.752941 1"/>
                  <body name="right_lower_arm_pitch_link" pos="0.00116219 -0.00565601 -0.221999" quat="1 -5.95066e-05 0.000600205 -7.37393e-05">
                    <inertial pos="-0.00503069 -0.0262082 -0.0259293" quat="0.70047 0.0897447 -0.0950138 0.701613" mass="0.667493" diaginertia="0.000458037 0.00284521 0.000380932"/>
                    <joint name="right_elbow_pitch_joint" class="/" pos="0 0 0" axis="0.00505615 -0.999876 -0.0148807" range="-2.04185 2.2834" armature="0.178317" damping="0" frictionloss="0.133812"/>
                    <geom name="//unnamed_geom_57" class="visual" mesh="right_lower_arm_pitch_link"/>
                    <body name="right_hand_yaw_link" pos="-0.0108084 -0.00228383 -0.0920621" quat="1 -0.000314621 0.00057376 -0.000676621">
                      <inertial pos="-0.0112587 -0.0147413 -0.107632" quat="0.999849 0.00366063 -0.00313619 0.0166669" mass="1.99609" diaginertia="0.00347814 0.0165042 0.00149934"/>
                      <joint name="right_wrist_yaw_joint" class="/" pos="0 0 0" axis="0.0116705 0.0190241 0.999751" range="-3.07993 2.87412" armature="0.0873024" damping="0.0843693" frictionloss="0.229628"/>
                      <geom name="//unnamed_geom_58" class="visual" mesh="right_hand_yaw_link"/>
                      <geom name="right_hand_yaw_link.STL" class="collision" size="0.0543972 0.0910639" pos="0.00117979 0.000973454 -0.100683" type="cylinder" rgba="0.752941 0.752941 0.752941 1"/>
                      <geom name="//unnamed_geom_60" class="reward_collision_sphere" size="0.0654254"/>
                      <body name="right_hand_roll_link" pos="0.015624 0.000638417 -0.243929" quat="0.999988 0.000208716 -0.0048568 0.000487349">
                        <inertial pos="-0.0137633 0.0132608 -0.00624326" quat="0.498927 0.501973 0.497611 0.501476" mass="0.00742715" diaginertia="3.69942e-07 2.62255e-06 2.55946e-07"/>
                        <joint name="right_wrist_roll_joint" class="/" pos="0 0 0" axis="-0.997527 0.0702494 -0.00241223" range="-1.14856 0.795445" armature="0.124267" damping="0" frictionloss="0.194288"/>
                        <geom name="//unnamed_geom_61" class="visual" mesh="right_hand_roll_link"/>
                        <body name="right_hand_pitch_link" pos="-0.00573092 0.00909271 0.00512861" quat="0.999998 -0.00120713 -0.000683628 0.00153863">
                          <inertial pos="-0.00419406 0.026217 -0.0688833" quat="0.740269 0.121674 -0.0963435 0.654153" mass="0.517967" diaginertia="0.000319788 0.00194532 0.00034004"/>
                          <joint name="right_wrist_pitch_joint" class="/" pos="0 0 0" axis="0.05519 -0.998299 -0.0188162" range="-0.733297 0.408151" armature="0.178513" damping="0" frictionloss="0.148306"/>
                          <geom name="//unnamed_geom_62" class="visual" mesh="right_hand_pitch"/>
                          <body name="right_jaw_link" pos="0.00278814 0.015031 -0.0806396" quat="0.999999 -0.00133231 -0.000222649 0.000122911">
                            <inertial pos="-0.00966593 -0.00705088 -0.0331004" quat="0.709003 0.015664 -0.0369132 0.704065" mass="0.148039" diaginertia="0.000126516 0.000497491 0.000131291"/>
                            <joint name="right_jaw_joint" class="/" pos="0 0 0" axis="-0.999741 0.019739 -0.0113335" range="-0.289688 1.0278" armature="0.125362" damping="0.0151293" frictionloss="0.127827"/>
                            <geom name="//unnamed_geom_63" class="visual" mesh="right_jaw_link"/>
                            <geom name="//unnamed_geom_64" class="collision" size="0.0471063"/>
                            <geom name="//unnamed_geom_65" class="reward_collision_sphere" size="0.0654254" pos="0 0 -0.0264805"/>
                          </body>
                        </body>
                      </body>
                    </body>
                  </body>
                </body>
              </body>
            </body>
            <body name="head_roll_link" pos="-0.000990652 0.00638487 0.414248" quat="1 -0.000247968 -0.000170168 -0.000301562">
              <inertial pos="0.00256018 0.00545184 -0.0131365" quat="-0.0107702 0.671045 -0.00567279 0.741317" mass="0.0208563" diaginertia="1.13682e-06 3.18698e-06 1.59522e-06"/>
              <joint name="head_roll_joint" class="/" pos="0 0 0" axis="-0.999998 0.000553331 -0.00191517" range="-0.518747 0.481528" armature="0.21302" damping="0.00421708" frictionloss="0.0235452"/>
              <geom name="//unnamed_geom_66" class="visual" mesh="head_roll_link"/>
              <body name="head_pitch_link" pos="-0.00364669 0.00382696 -0.00864266" quat="1 -0.000209015 -6.34149e-05 -0.000103496">
                <inertial pos="0.00376324 0.00806952 0.0332229" quat="0.672648 0.643267 0.210983 -0.298729" mass="0.122449" diaginertia="3.90778e-05 0.000162281 5.52313e-05"/>
                <joint name="head_pitch_joint" class="/" pos="0 0 0" axis="0.0329348 -0.998967 0.0313057" stiffness="0.0704314" range="-0.591825 0.748089" armature="0.221308" damping="0.053142" frictionloss="0.21353"/>
                <geom name="//unnamed_geom_67" class="visual" mesh="head_pitch_link"/>
                <body name="head_yaw_link" pos="-0.000648571 0.00778707 0.0535351" quat="1 -0.000463172 -0.000104195 0.000395898">
                  <inertial pos="0.0333455 -0.00535791 0.112363" quat="0.705933 -0.133499 -0.135447 0.682269" mass="3.21211" diaginertia="0.0118334 0.0553539 0.0189338"/>
                  <joint name="head_yaw_joint" class="/" pos="0 0 0" axis="-0.00221388 -0.000814993 0.999997" stiffness="0.00112822" range="-2.70849 2.72334" armature="0.101588" damping="0.00242994" frictionloss="0.0370827"/>
                  <geom name="//unnamed_geom_68" class="visual" rgba="0.12 0.12 0.12 1" mesh="head_yaw_link"/>
                  <geom name="head_yaw_link.STL" class="collision" size="0.155303" pos="0.0198006 -0.00133621 0.123956" rgba="0.752941 0.752941 0.752941 1"/>
                  <geom name="//unnamed_geom_70" class="reward_collision_sphere" size="0.130851" pos="0.0324936 0 0.132403"/>
                  <camera name="ego_camera" class="/" pos="0.119143 0 0.145643" quat="-0.5 -0.5 0.5 0.5"/>
                </body>
              </body>
            </body>
          </body>
        </body>
      </body>
    </body>
  </worldbody>

  <contact>
    <pair class="/" geom1="floor" geom2="left_foot" name="//unnamed_contact_0"/>
    <pair class="/" geom1="floor" geom2="right_foot" name="//unnamed_contact_1"/>
  </contact>

  <actuator>
    <general name="left_hip_roll" class="/" joint="left_hip_roll_joint" forcerange="-86.673 86.673" gainprm="157.021" biasprm="0 -157.021 -1.50933"/>
    <general name="left_hip_yaw" class="/" joint="left_hip_yaw_joint" forcerange="-119.126 119.126" gainprm="157.021" biasprm="0 -157.021 -1.50933"/>
    <general name="left_hip_pitch" class="/" joint="left_hip_pitch_joint" forcerange="-314.854 314.854" gainprm="157.021" biasprm="0 -157.021 -1.50933"/>
    <general name="left_knee_pitch" class="/" joint="left_knee_pitch_joint" forcerange="-379.983 379.983" gainprm="157.021" biasprm="0 -157.021 -1.50933"/>
    <general name="left_ankle_pitch" class="/" joint="left_ankle_pitch_joint" forcerange="-20.1444 20.1444" gainprm="157.021" biasprm="0 -157.021 -1.50933"/>
    <general name="left_ankle_roll" class="/" joint="left_ankle_roll_joint" forcerange="-36.1353 36.1353" gainprm="157.021" biasprm="0 -157.021 -1.50933"/>
    <general name="right_hip_roll" class="/" joint="right_hip_roll_joint" forcerange="-61.0893 61.0893" gainprm="157.021" biasprm="0 -157.021 -1.50933"/>
    <general name="right_hip_yaw" class="/" joint="right_hip_yaw_joint" forcerange="-57.361 57.361" gainprm="157.021" biasprm="0 -157.021 -1.50933"/>
    <general name="right_hip_pitch" class="/" joint="right_hip_pitch_joint" forcerange="-246.365 246.365" gainprm="157.021" biasprm="0 -157.021 -1.50933"/>
    <general name="right_knee_pitch" class="/" joint="right_knee_pitch_joint" forcerange="-352.737 352.737" gainprm="157.021" biasprm="0 -157.021 -1.50933"/>
    <general name="right_ankle_pitch" class="/" joint="right_ankle_pitch_joint" forcerange="-25.3943 25.3943" gainprm="157.021" biasprm="0 -157.021 -1.50933"/>
    <general name="right_ankle_roll" class="/" joint="right_ankle_roll_joint" forcerange="-17.559 17.559" gainprm="157.021" biasprm="0 -157.021 -1.50933"/>
    <general name="waist_yaw" class="/" joint="waist_yaw_joint" forcerange="-106.896 106.896" gainprm="157.021" biasprm="0 -157.021 -1.50933"/>
    <general name="waist_pitch" class="/" joint="waist_pitch_joint" forcerange="-118.345 118.345" gainprm="157.021" biasprm="0 -157.021 -1.50933"/>
    <general name="waist_roll" class="/" joint="waist_roll_joint" forcerange="-88.9027 88.9027" gainprm="157.021" biasprm="0 -157.021 -1.50933"/>
    <general name="left_shoulder_pitch" class="/" joint="left_shoulder_pitch_joint" forcerange="-22.6757 22.6757" gainprm="157.021" biasprm="0 -157.021 -1.50933"/>
    <general name="left_shoulder_roll" class="/" joint="left_shoulder_roll_joint" forcerange="-57.8054 57.8054" gainprm="157.021" biasprm="0 -157.021 -1.50933"/>
    <general name="left_shoulder_yaw" class="/" joint="left_shoulder_yaw_joint" forcerange="-28.7058 28.7058" gainprm="157.021" biasprm="0 -157.021 -1.50933"/>
    <general name="left_elbow_pitch" class="/" joint="left_elbow_pitch_joint" forcerange="-43.3843 43.3843" gainprm="157.021" biasprm="0 -157.021 -1.50933"/>
    <general name="left_wrist_yaw" class="/" joint="left_wrist_yaw_joint" forcerange="-12.3545 12.3545" gainprm="157.021" biasprm="0 -157.021 -1.50933"/>
    <general name="left_wrist_roll" class="/" joint="left_wrist_roll_joint" forcerange="-5.65849 5.65849" gainprm="157.021" biasprm="0 -157.021 -1.50933"/>
    <general name="left_wrist_pitch" class="/" joint="left_wrist_pitch_joint" forcerange="-3.8718 3.8718" gainprm="157.021" biasprm="0 -157.021 -1.50933"/>
    <general name="left_jaw" class="/" joint="left_jaw_joint" forcerange="-5.31208 5.31208" gainprm="157.021" biasprm="0 -157.021 -1.50933"/>
    <general name="right_shoulder_pitch" class="/" joint="right_shoulder_pitch_joint" forcerange="-53.3769 53.3769" gainprm="157.021" biasprm="0 -157.021 -1.50933"/>
    <general name="right_shoulder_roll" class="/" joint="right_shoulder_roll_joint" forcerange="-53.9645 53.9645" gainprm="157.021" biasprm="0 -157.021 -1.50933"/>
    <general name="right_shoulder_yaw" class="/" joint="right_shoulder_yaw_joint" forcerange="-26.1734 26.1734" gainprm="157.021" biasprm="0 -157.021 -1.50933"/>
    <general name="right_elbow_pitch" class="/" joint="right_elbow_pitch_joint" forcerange="-62.0531 62.0531" gainprm="157.021" biasprm="0 -157.021 -1.50933"/>
    <general name="right_wrist_yaw" class="/" joint="right_wrist_yaw_joint" forcerange="-10.6167 10.6167" gainprm="157.021" biasprm="0 -157.021 -1.50933"/>
    <general name="right_wrist_roll" class="/" joint="right_wrist_roll_joint" forcerange="-4.24189 4.24189" gainprm="157.021" biasprm="0 -157.021 -1.50933"/>
    <general name="right_wrist_pitch" class="/" joint="right_wrist_pitch_joint" forcerange="-3.85725 3.85725" gainprm="157.021" biasprm="0 -157.021 -1.50933"/>
    <general name="right_jaw" class="/" joint="right_jaw_joint" forcerange="-2.39532 2.39532" gainprm="157.021" biasprm="0 -157.021 -1.50933"/>
    <general name="head_roll" class="/" joint="head_roll_joint" forcerange="-5.12878 5.12878" gainprm="157.021" biasprm="0 -157.021 -1.50933"/>
    <general name="head_pitch" class="/" joint="head_pitch_joint" forcerange="-6.69731 6.69731" gainprm="157.021" biasprm="0 -157.021 -1.50933"/>
    <general name="head_yaw" class="/" joint="head_yaw_joint" forcerange="-6.21586 6.21586" gainprm="157.021" biasprm="0 -157.021 -1.50933"/>
  </actuator>

  <sensor>
    <gyro site="imu" name="imu_angular_velocity"/>
    <velocimeter site="imu" name="imu_linear_velocity"/>
    <framelinvel objtype="site" objname="left_foot" name="left_foot_global_linear_velocity"/>
    <framelinvel objtype="site" objname="right_foot" name="right_foot_global_linear_velocity"/>
  </sensor>

  <keyframe>
    <key name="home" qpos="0 0 0.8665 1 0 0 0 0 0 -0.4 0.8 -0.4 0 0 0 0.4 -0.8 0.4 0 0 0 0 0 -0.2 0 -0.785 0 0 0 0 0 0.2 0 0.785 0 0 0 0 0 0 0"/>
  </keyframe>
</mujoco>
