<mujoco model="GR1T2_jaw">
  <compiler angle="radian" assetdir="assets" balanceinertia="true" inertiafromgeom="false"/>

  <option timestep="0.005" density="1.2" viscosity="2e-05"/>

  <size nkey="1"/>

  <visual>
    <quality shadowsize="8192"/>
    <map shadowclip="0.5"/>
  </visual>

  <default>
    <default class="/">
      <joint armature="0.1" damping="0.01" frictionloss="0.1"/>
      <geom contype="0" conaffinity="0" group="1" solref="-1000 -80"/>
      <site size="0.01 0.005 0.005" group="5"/>
      <general forcelimited="true" biastype="affine" gainprm="80" biasprm="0 -80 -2"/>
      <default class="visual">
        <geom type="mesh" density="0" rgba="0.18 0.18 0.18 1"/>
      </default>
      <default class="collision">
        <geom group="3"/>
      </default>
      <default class="foot">
        <geom size="0.126 0.045 0.01" type="box" condim="6" group="4" priority="1" solimp="0.015 1 0.01"/>
      </default>
      <default class="reward_collision_sphere">
        <geom group="5" rgba="1 0 0 1"/>
      </default>
    </default>
  </default>

  <asset>
    <texture type="skybox" colorspace="auto" name="//unnamed_texture_0" builtin="gradient" rgb1="0.95 0.95 0.95" rgb2="0.95 0.95 0.95" width="100" height="600"/>
    <texture type="2d" colorspace="auto" name="texplane" builtin="checker" rgb1="0.345 0.575 0.748" rgb2="0.345 0.575 0.748" markrgb="1 1 1" width="512" height="512"/>
    <material name="MatPlane" class="/" texture="texplane" texuniform="true" texrepeat="2 2" specular="0.9"/>
    <mesh name="base_link" class="/" file="base_link.STL"/>
    <mesh name="left_thigh_roll_link" class="/" file="left_thigh_roll_link.STL"/>
    <mesh name="left_thigh_yaw_link" class="/" file="left_thigh_yaw_link.STL"/>
    <mesh name="left_thigh_pitch_link" class="/" file="left_thigh_pitch_link.STL"/>
    <mesh name="left_shank_pitch_link" class="/" file="left_shank_pitch_link.STL"/>
    <mesh name="left_foot_pitch_link" class="/" file="left_foot_pitch_link.STL"/>
    <mesh name="left_foot_roll_link" class="/" file="left_foot_roll_link.STL"/>
    <mesh name="right_thigh_roll_link" class="/" file="right_thigh_roll_link.STL"/>
    <mesh name="right_thigh_yaw_link" class="/" file="right_thigh_yaw_link.STL"/>
    <mesh name="right_thigh_pitch_link" class="/" file="right_thigh_pitch_link.STL"/>
    <mesh name="right_shank_pitch_link" class="/" file="right_shank_pitch_link.STL"/>
    <mesh name="right_foot_pitch_link" class="/" file="right_foot_pitch_link.STL"/>
    <mesh name="right_foot_roll_link" class="/" file="right_foot_roll_link.STL"/>
    <mesh name="waist_yaw_link" class="/" file="waist_yaw_link.STL"/>
    <mesh name="waist_pitch_link" class="/" file="waist_pitch_link.STL"/>
    <mesh name="waist_roll_link" class="/" file="waist_roll_link.STL"/>
    <mesh name="torso_link" class="/" file="torso_link.STL"/>
    <mesh name="left_upper_arm_pitch_link" class="/" file="left_upper_arm_pitch_link.STL"/>
    <mesh name="left_upper_arm_roll_link" class="/" file="left_upper_arm_roll_link.STL"/>
    <mesh name="left_upper_arm_yaw_link" class="/" file="left_upper_arm_yaw_link.STL"/>
    <mesh name="left_lower_arm_pitch_link" class="/" file="left_lower_arm_pitch_link.STL"/>
    <mesh name="left_hand_yaw_link" class="/" file="left_hand_yaw_link.STL"/>
    <mesh name="left_hand_roll_link" class="/" file="left_hand_roll_link.STL"/>
    <mesh name="left_hand_pitch" class="/" file="left_hand_pitch.STL"/>
    <mesh name="left_jaw_link" class="/" file="left_jaw_link.STL"/>
    <mesh name="right_upper_arm_pitch_link" class="/" file="right_upper_arm_pitch_link.STL"/>
    <mesh name="right_upper_arm_roll_link" class="/" file="right_upper_arm_roll_link.STL"/>
    <mesh name="right_upper_arm_yaw_link" class="/" file="right_upper_arm_yaw_link.STL"/>
    <mesh name="right_lower_arm_pitch_link" class="/" file="right_lower_arm_pitch_link.STL"/>
    <mesh name="right_hand_yaw_link" class="/" file="right_hand_yaw_link.STL"/>
    <mesh name="right_hand_roll_link" class="/" file="right_hand_roll_link.STL"/>
    <mesh name="right_hand_pitch" class="/" file="right_hand_pitch.STL"/>
    <mesh name="right_jaw_link" class="/" file="right_jaw_link.STL"/>
    <mesh name="head_roll_link" class="/" file="head_roll_link.STL"/>
    <mesh name="head_pitch_link" class="/" file="head_pitch_link.STL"/>
    <mesh name="head_yaw_link" class="/" file="head_yaw_link.STL"/>
    <mesh name="imu_link" class="/" file="imu_link.STL"/>
  </asset>

  <worldbody>
    <geom name="floor" class="/" size="100 100 0.125" type="plane" group="0" material="MatPlane"/>
    <light name="toplight_shadow" class="/" pos="0 0 5" dir="0.0990148 0.0990148 -0.990148" type="directional" ambient="0.04 0.04 0.04" diffuse="0.55 0.55 0.55" specular="0.12 0.12 0.12"/>
    <light name="toplight_fill" class="/" pos="0 0 5" dir="0.0990148 0.0990148 -0.990148" type="directional" castshadow="false" ambient="0.04 0.04 0.04" diffuse="0.3 0.3 0.3" specular="0.08 0.08 0.08"/>
    <body name="trunk" pos="0.00282624 -0.00177669 -0.00103459" quat="1 -2.44155e-05 -0.000409329 0.000199199">
      <inertial pos="-0.0542074 0.00322842 -0.011564" quat="1 -7.33696e-05 8.12284e-06 -0.000200858" mass="3.95823" diaginertia="0.0259618 0.0277546 0.032086"/>
      <joint name="//unnamed_joint_0" type="free"/>
      <geom name="//unnamed_geom_1" class="visual" rgba="0.12 0.12 0.12 1" mesh="base_link"/>
      <geom name="base_link.STL" class="collision" size="0.121848 0.0682448" pos="-0.0384466 0.000421926 0.00869017" quat="0.706838 -0.707359 0.00477667 0" type="cylinder" rgba="0.752941 0.752941 0.752941 1"/>
      <geom name="//unnamed_geom_3" class="visual" pos="0 0 -0.0562355" quat="1 0 0 0" rgba="0.12 0.12 0.12 1" mesh="imu_link"/>
      <geom name="//unnamed_geom_4" class="reward_collision_sphere" size="0.0796434" pos="0 0.114021 0.0943549"/>
      <geom name="//unnamed_geom_5" class="reward_collision_sphere" size="0.0796434" pos="0 -0.114021 0.0943549"/>
      <site name="imu" class="/" pos="-0.00686633 -0.00395693 -0.0563281" size="0.00995542"/>
      <camera name="track" class="/" pos="0 -2.28042 0" quat="0.707107 0.707107 0 0" mode="trackcom"/>
      <body name="left_thigh_roll_link" pos="-0.0280606 0.119303 -0.0274794" quat="1 0.000428559 -0.000286924 0.000175811">
        <inertial pos="-0.00254905 -0.00325528 0.00153308" quat="-0.0287218 0.70778 -0.0402332 0.704701" mass="1.50304" diaginertia="0.00150833 0.00462563 0.00117119"/>
        <joint name="left_hip_roll_joint" class="/" pos="0 0 0" axis="-0.999935 -0.00348883 0.0108663" range="-0.747493 0.155886" armature="0.113864" damping="0.018287" frictionloss="0.111894"/>
        <geom name="//unnamed_geom_6" class="visual" mesh="left_thigh_roll_link"/>
        <body name="left_thigh_yaw_link" pos="0.0265104 0.00255029 0.00421668" quat="1 0.000269762 0.000731596 0.000207517">
          <inertial pos="-0.00420303 0.0453632 -0.102532" quat="0.574071 0.0892988 -0.183001 0.793082" mass="3.34837" diaginertia="0.0145207 0.0376084 0.00625554"/>
          <joint name="left_hip_yaw_joint" class="/" pos="0 0 0" axis="0.00779944 -0.00103931 -0.999969" range="-0.654583 0.700567" armature="0.0954785" damping="0.00578039" frictionloss="0.0977307"/>
          <geom name="//unnamed_geom_7" class="visual" mesh="left_thigh_yaw_link"/>
          <body name="left_thigh_pitch_link" pos="-0.00157613 0.0283151 -0.128476" quat="1 0.000512364 0.000592983 4.99628e-05">
            <inertial pos="0.00194535 -0.0312196 -0.0578454" quat="0.999866 -0.0100789 -0.0110845 0.00659157" mass="8.05696" diaginertia="0.0564992 0.180804 0.0206828"/>
            <joint name="left_hip_pitch_joint" class="/" pos="0 0 0" axis="-0.00148603 0.999998 0.00114348" range="-1.76488 0.654914" armature="0.0924606" damping="0.00493009" frictionloss="0.104971"/>
            <geom name="//unnamed_geom_8" class="visual" mesh="left_thigh_pitch_link"/>
            <geom name="left_thigh_pitch_link.STL" class="collision" size="0.0816345 0.124357" pos="0.000632052 -0.0342064 -0.157626" type="cylinder" rgba="0.752941 0.752941 0.752941 1"/>
            <geom name="//unnamed_geom_10" class="reward_collision_sphere" size="0.0995542" pos="0 -0.0114021 -0.0471775"/>
            <body name="left_shank_pitch_link" pos="7.1626e-05 -0.0208955 -0.339301" quat="1 -0.000245763 0.000137768 -0.000102341">
              <inertial pos="0.00417784 -0.00183782 -0.10687" quat="0.999711 -0.00862361 0.00793542 -0.0209734" mass="1.67465" diaginertia="0.00633667 0.0197521 0.000898258"/>
              <joint name="left_knee_pitch_joint" class="/" pos="0 0 0" axis="0.00640248 0.999974 -0.00319293" range="-0.0941017 1.86968" armature="0.0844206" damping="0.0258186" frictionloss="0.107915"/>
              <geom name="//unnamed_geom_11" class="visual" mesh="left_shank_pitch_link"/>
              <geom name="left_shank_pitch_link.STL" class="collision" size="0.0530837 0.0899821" pos="-1.49786e-05 -0.000960682 -0.16483" quat="0.00125538 -0.202712 0.979238 0" type="cylinder" rgba="0.752941 0.752941 0.752941 1"/>
              <geom name="//unnamed_geom_13" class="reward_collision_sphere" size="0.0497771"/>
              <geom name="//unnamed_geom_14" class="reward_collision_sphere" size="0.0597325" pos="0 0 -0.10379"/>
              <body name="left_foot_pitch_link" pos="0.00184375 -0.00406899 -0.316943" quat="1 2.98624e-05 -0.000184426 0.000102292">
                <inertial pos="0.000538893 0.0017331 0.000212366" quat="0.00359123 0.710767 -0.00384833 0.703408" mass="0.0525784" diaginertia="3.70884e-06 1.07883e-05 3.92971e-06"/>
                <joint name="left_ankle_pitch_joint" class="/" pos="0 0 0" axis="-0.000790172 0.999997 0.00211505" range="-1.06619 0.476336" armature="0.113833" damping="0.00891662" frictionloss="0.0910543"/>
                <geom name="//unnamed_geom_15" class="visual" mesh="left_foot_pitch_link"/>
                <body name="left_foot_roll_link" pos="-0.00172825 0.00205664 0.000240916" quat="1 -4.60305e-05 8.1099e-05 -2.74315e-06">
                  <inertial pos="0.0348798 -0.00158608 -0.0382634" quat="0.000980704 0.732076 -0.008831 0.681165" mass="1.07075" diaginertia="0.00322975 0.00981426 0.000566142"/>
                  <joint name="left_ankle_roll_joint" class="/" pos="0 0 0" axis="-0.99981 -0.0129615 -0.0145644" stiffness="0.000547759" range="-0.446431 0.462945" armature="0.0874734" damping="0" frictionloss="0.0865144"/>
                  <geom name="//unnamed_geom_16" class="visual" mesh="left_foot_roll_link"/>
                  <geom name="left_foot" class="foot" size="0.138853 0.0470247 0.00989768" pos="0.0406289 0 -0.0419879"/>
                  <geom name="//unnamed_geom_18" class="reward_collision_sphere" size="0.0497771" pos="0 0 -0.0283065"/>
                  <geom name="//unnamed_geom_19" class="reward_collision_sphere" size="0.0497771" pos="0.108344 0 -0.0283065"/>
                  <site name="left_foot" class="foot" pos="0.0406289 0 -0.0419879" size="0.00995542"/>
                </body>
              </body>
            </body>
          </body>
        </body>
      </body>
      <body name="right_thigh_roll_link" pos="-0.0267508 -0.123165 -0.0274793" quat="0.999998 -0.000329248 -0.000188648 0.00171591">
        <inertial pos="0.000764406 -0.00360702 0.00298871" quat="0.0150322 0.708396 0.0227853 0.705287" mass="1.42717" diaginertia="0.00154596 0.004728 0.00119651"/>
        <joint name="right_hip_roll_joint" class="/" pos="0 0 0" axis="-1 -0.000203092 0.000540611" range="-0.150492 0.847185" armature="0.0924705" damping="0.0249135" frictionloss="0.10479"/>
        <geom name="//unnamed_geom_20" class="visual" mesh="right_thigh_roll_link"/>
        <body name="right_thigh_yaw_link" pos="0.0280153 -0.00170827 0.00222022" quat="1 -0.000639154 -0.000521387 -0.000359372">
          <inertial pos="-0.0015719 -0.0414754 -0.105135" quat="0.679126 -0.154877 0.145847 0.702516" mass="3.56174" diaginertia="0.0142124 0.0378808 0.00699687"/>
          <joint name="right_hip_yaw_joint" class="/" pos="0 0 0" axis="-0.00379048 0.000989264 -0.999992" range="-0.646989 0.653199" armature="0.088743" damping="0.00700973" frictionloss="0.112006"/>
          <geom name="//unnamed_geom_21" class="visual" mesh="right_thigh_yaw_link"/>
          <body name="right_thigh_pitch_link" pos="-0.000412247 -0.0297225 -0.135048" quat="1 0.000323114 -0.000123648 0.000311849">
            <inertial pos="0.00247568 0.028542 -0.0616773" quat="0.999927 -0.00354258 -0.00769104 0.00861128" mass="8.41156" diaginertia="0.0557613 0.177777 0.0213758"/>
            <joint name="right_hip_pitch_joint" class="/" pos="0 0 0" axis="-0.021119 -0.999761 -0.0056835" stiffness="0.00484242" range="-0.679635 1.80375" armature="0.103774" damping="0.027228" frictionloss="0.0974222"/>
            <geom name="//unnamed_geom_22" class="visual" mesh="right_thigh_pitch_link"/>
            <geom name="right_thigh_pitch_link.STL" class="collision" size="0.0816345 0.124354" pos="-0.00191703 0.0342064 -0.157626" quat="0.999971 0.00269833 0.00706272 0" type="cylinder" rgba="0.752941 0.752941 0.752941 1"/>
            <geom name="//unnamed_geom_24" class="reward_collision_sphere" size="0.0995542" pos="0 0.0114021 -0.0471775"/>
            <body name="right_shank_pitch_link" pos="0.00193027 0.021194 -0.337816" quat="1 0.000196743 -0.000193163 0.000504962">
              <inertial pos="-0.00155569 0.00207448 -0.109457" quat="0.999747 0.00317877 0.00591865 0.0214567" mass="1.73972" diaginertia="0.00644962 0.0198099 0.000917061"/>
              <joint name="right_knee_pitch_joint" class="/" pos="0 0 0" axis="0.0107571 -0.999907 0.00842312" range="-1.91735 0.0614095" armature="0.0841494" damping="0.0199487" frictionloss="0.106949"/>
              <geom name="//unnamed_geom_25" class="visual" mesh="right_shank_pitch_link"/>
              <geom name="right_shank_pitch_link.STL" class="collision" size="0.0530834 0.0899812" pos="-1.49786e-05 -0.000960694 -0.164837" type="cylinder" rgba="0.752941 0.752941 0.752941 1"/>
              <geom name="//unnamed_geom_27" class="reward_collision_sphere" size="0.0497771"/>
              <geom name="//unnamed_geom_28" class="reward_collision_sphere" size="0.0597325" pos="0 0 -0.10379"/>
              <body name="right_foot_pitch_link" pos="0.00349689 0.00232036 -0.320135" quat="0.999999 0.000920554 -0.000524183 0.000181864">
                <inertial pos="0.000182317 0.00164818 0.000928762" quat="-0.00330435 0.706817 -0.00120278 0.707387" mass="0.0543511" diaginertia="3.81205e-06 1.07833e-05 3.92424e-06"/>
                <joint name="right_ankle_pitch_joint" class="/" pos="0 0 0" axis="-0.00230973 -0.999997 -0.000122142" range="-0.51114 1.07115" armature="0.114144" damping="0.010285" frictionloss="0.110376"/>
                <geom name="//unnamed_geom_29" class="visual" mesh="right_foot_pitch_link"/>
                <body name="right_foot_roll_link" pos="0.0037156 0.00161047 -0.00288331" quat="1 0.00046176 0.000219857 -0.000724217">
                  <inertial pos="0.0312823 -0.00139381 -0.039063" quat="0.00446402 0.725202 0.0040255 0.68851" mass="1.04221" diaginertia="0.0033485 0.00957157 0.000546473"/>
                  <joint name="right_ankle_roll_joint" class="/" pos="0 0 0" axis="-0.999993 0.00184902 -0.00335974" range="-0.395765 0.397231" armature="0.0968981" damping="0.00548243" frictionloss="0.106667"/>
                  <geom name="//unnamed_geom_30" class="visual" mesh="right_foot_roll_link"/>
                  <geom name="right_foot" class="foot" size="0.141119 0.0443882 0.00894772" pos="0.0406289 0 -0.0419879"/>
                  <geom name="//unnamed_geom_32" class="reward_collision_sphere" size="0.0497771" pos="0 0 -0.0283065"/>
                  <geom name="//unnamed_geom_33" class="reward_collision_sphere" size="0.0497771" pos="0.108344 0 -0.0283065"/>
                  <site name="right_foot" class="foot" pos="0.0406289 0 -0.0419879" size="0.00995542"/>
                </body>
              </body>
            </body>
          </body>
        </body>
      </body>
      <body name="waist_yaw_link" pos="0.000420483 0.00482461 0.00165712" quat="1 -0.000407985 0.000301562 -0.000136518">
        <inertial pos="-0.00458175 -0.00579889 0.0473118" quat="0.978025 0.197233 -0.0264301 0.0621843" mass="1.61957" diaginertia="0.00219636 0.00610843 0.00160843"/>
        <joint name="waist_yaw_joint" class="/" pos="0 0 0" axis="-0.00126943 0.00329843 0.999994" range="-1.00178 1.03696" armature="0.10712" damping="0.0102278" frictionloss="0.113388"/>
        <geom name="//unnamed_geom_34" class="visual" rgba="0.12 0.12 0.12 1" mesh="waist_yaw_link"/>
        <body name="waist_pitch_link" pos="0.00367531 0.00377852 0.0852456" quat="0.999999 -0.00109147 0.000276154 4.84914e-05">
          <inertial pos="0.00143724 -0.00172676 0.0396966" quat="0.998215 -0.0429874 0.0379642 0.0166639" mass="1.51262" diaginertia="0.00264257 0.00831143 0.00137345"/>
          <joint name="waist_pitch_joint" class="/" pos="0 0 0" axis="0.0211394 -0.999302 0.0308125" range="-1.18091 0.492096" armature="0.098291" damping="0.00424229" frictionloss="0.104473"/>
          <geom name="//unnamed_geom_35" class="visual" rgba="0.12 0.12 0.12 1" mesh="waist_pitch_link"/>
          <body name="waist_roll_link" pos="0.00571755 -0.000723548 0.0781133" quat="1 8.66091e-05 -0.000188513 0.000756583">
            <inertial pos="-0.0122664 0.000491695 0.141706" quat="0.998507 0.00620491 -0.054116 -0.00411572" mass="6.60569" diaginertia="0.0382234 0.112312 0.027188"/>
            <joint name="waist_roll_joint" class="/" pos="0 0 0" axis="-0.999968 0.00793413 -0.000600468" range="-0.775624 0.739304" armature="0.116948" damping="0.0189947" frictionloss="0.11255"/>
            <geom name="//unnamed_geom_36" class="visual" rgba="0.12 0.12 0.12 1" mesh="waist_roll_link"/>
            <geom name="//unnamed_geom_37" class="visual" pos="-0.00203145 0.000654972 0.151298" quat="1 0 0 0" mesh="torso_link"/>
            <geom name="torso_link.STL" class="collision" size="0.156725 0.0300584" pos="-0.0163111 0.0065788 0.139484" type="cylinder" rgba="0.752941 0.752941 0.752941 1"/>
            <geom name="//unnamed_geom_39" class="reward_collision_sphere" size="0.12942" pos="0 0 0.18871"/>
            <body name="left_upper_arm_pitch_link" pos="-0.00128155 0.112373 0.192754" quat="0.9765 0.215518 0.000662057 -0.00024137">
              <inertial pos="0.00424742 0.0615237 -0.00278024" quat="0.704134 0.70798 0.00475461 -0.0541982" mass="0.79215" diaginertia="0.00122729 0.00365165 0.000364344"/>
              <joint name="left_shoulder_pitch_joint" class="/" pos="0 0 0" axis="0.00171957 0.999997 -0.00183174" range="-2.7713 1.89537" armature="0.116596" damping="0.0209228" frictionloss="0.113617"/>
              <geom name="//unnamed_geom_40" class="visual" mesh="left_upper_arm_pitch_link"/>
              <body name="left_upper_arm_roll_link" pos="0.00374198 0.110668 0.00315117" quat="0.976611 -0.215013 -0.000295205 -0.000341294">
                <inertial pos="0.00188538 0.0180618 -0.023051" quat="0.889902 0.270258 0.119204 -0.3476" mass="0.641017" diaginertia="0.000629972 0.00203914 0.00027878"/>
                <joint name="left_shoulder_roll_joint" class="/" pos="0 0 0" axis="-0.999978 8.26906e-06 0.00669535" range="-2.51598 0.57525" armature="0.110132" damping="0" frictionloss="0.0867187"/>
                <geom name="//unnamed_geom_41" class="visual" mesh="left_upper_arm_roll_link"/>
                <body name="left_upper_arm_yaw_link" pos="-0.000911652 0.0438461 -0.06458" quat="0.999999 -0.000321283 -0.000510746 -0.000820585">
                  <inertial pos="-0.00281466 -0.00341623 -0.0799699" quat="0.999939 -0.00516666 0.005743 -0.00785227" mass="0.533114" diaginertia="0.00218046 0.00731224 0.000198578"/>
                  <joint name="left_shoulder_yaw_joint" class="/" pos="0 0 0" axis="0.00348835 0.00169896 0.999992" range="-2.94879 2.98333" armature="0.111001" damping="0" frictionloss="0.0951728"/>
                  <geom name="//unnamed_geom_42" class="visual" mesh="left_upper_arm_yaw_link"/>
                  <geom name="left_upper_arm_yaw_link.STL" class="collision" size="0.0360717 0.0845633" pos="3.565e-05 -0.00101968 -0.0748612" quat="0.00803418 -0.995528 0.0941277 0" type="cylinder" rgba="0.752941 0.752941 0.752941 1"/>
                  <body name="left_lower_arm_pitch_link" pos="-0.00111077 0.0032697 -0.168588" quat="0.999999 0.000233424 0.00022794 0.00113104">
                    <inertial pos="0.00138434 0.00924138 -0.0207036" quat="0.701442 -0.0877053 0.0992172 0.700316" mass="0.324674" diaginertia="0.000177144 0.000570035 7.32767e-05"/>
                    <joint name="left_elbow_pitch_joint" class="/" pos="0 0 0" axis="-0.00266877 0.999962 -0.00832603" stiffness="0.00569687" range="-2.32855 2.2906" armature="0.117292" damping="0.0180834" frictionloss="0.0956089"/>
                    <geom name="//unnamed_geom_44" class="visual" mesh="left_lower_arm_pitch_link"/>
                    <body name="left_hand_yaw_link" pos="-0.000523151 -0.00150045 -0.0545642" quat="0.999999 -0.00021236 -0.00138275 -0.000368957">
                      <inertial pos="-0.000324809 -0.000187666 -0.0694528" quat="0.999992 -0.00228758 -0.00319309 0.000373235" mass="0.981902" diaginertia="0.00162666 0.00490577 0.000380909"/>
                      <joint name="left_wrist_yaw_joint" class="/" pos="0 0 0" axis="0.00109049 -0.000576893 0.999999" range="-3.00151 2.99507" armature="0.116693" damping="0.0141346" frictionloss="0.111677"/>
                      <geom name="//unnamed_geom_45" class="visual" mesh="left_hand_yaw_link"/>
                      <geom name="left_hand_yaw_link.STL" class="collision" size="0.0413866 0.0692835" pos="0.000983446 -0.00175719 -0.0717502" type="cylinder" rgba="0.752941 0.752941 0.752941 1"/>
                      <geom name="//unnamed_geom_47" class="reward_collision_sphere" size="0.0497771"/>
                      <body name="left_hand_roll_link" pos="-0.000456717 0.00179424 -0.178519" quat="0.999999 -0.000477854 -0.000681457 -0.0008744">
                        <inertial pos="0.00126758 -0.000421431 0.000991219" quat="0.50105 0.496911 0.50072 0.501306" mass="0.00502172" diaginertia="2.10767e-07 6.89113e-07 5.34184e-08"/>
                        <joint name="left_wrist_roll_joint" class="/" pos="0 0 0" axis="-0.999992 -0.00218851 0.00335702" range="-0.973932 0.836292" armature="0.103301" damping="0.0212803" frictionloss="0.0872415"/>
                        <geom name="//unnamed_geom_48" class="visual" mesh="left_hand_roll_link"/>
                        <body name="left_hand_pitch_link" pos="0.00174186 0.00261371 -0.00292385" quat="1 5.28799e-05 -5.01849e-05 -5.6097e-05">
                          <inertial pos="0.00214576 -0.0130664 -0.0476546" quat="0.723208 -0.121426 0.114462 0.670168" mass="0.216965" diaginertia="0.000167182 0.000509788 6.99021e-05"/>
                          <joint name="left_wrist_pitch_joint" class="/" pos="0 0 0" axis="-0.00227069 0.999939 0.0107897" range="-0.622351 0.609069" armature="0.0987193" damping="0" frictionloss="0.102347"/>
                          <geom name="//unnamed_geom_49" class="visual" mesh="left_hand_pitch"/>
                          <body name="left_jaw_link" pos="-0.00221369 -0.00151499 -0.0588835" quat="1 0.000742852 0.000120549 -0.000207579">
                            <inertial pos="0.00100079 0.00307547 -0.0338815" quat="0.709445 -0.0233939 0.0364014 0.703431" mass="0.0696764" diaginertia="4.78639e-05 0.000103848 2.42971e-05"/>
                            <joint name="left_jaw_joint" class="/" pos="0 0 0" axis="-0.999927 -0.00674071 -0.00998898" range="-1.00131 0.0219979" armature="0.10106" damping="0.000240688" frictionloss="0.100621"/>
                            <geom name="//unnamed_geom_50" class="visual" mesh="left_jaw_link"/>
                            <geom name="//unnamed_geom_51" class="collision" size="0.0358395"/>
                            <geom name="//unnamed_geom_52" class="reward_collision_sphere" size="0.0497771" pos="0 0 -0.018871"/>
                          </body>
                        </body>
                      </body>
                    </body>
                  </body>
                </body>
              </body>
            </body>
            <body name="right_upper_arm_pitch_link" pos="0.000528941 -0.11694 0.194948" quat="0.976679 -0.214704 -0.00012921 -0.000223835">
              <inertial pos="0.00203619 -0.0613365 0.0021831" quat="0.707309 0.705946 0.0292998 0.0222338" mass="0.790392" diaginertia="0.00116016 0.00379874 0.000363749"/>
              <joint name="right_shoulder_pitch_joint" class="/" pos="0 0 0" axis="-0.00353005 -0.999988 0.00346622" range="-1.95285 2.79731" armature="0.107448" damping="0.0179494" frictionloss="0.103372"/>
              <geom name="//unnamed_geom_53" class="visual" mesh="right_upper_arm_pitch_link"/>
              <body name="right_upper_arm_roll_link" pos="0.00176338 -0.106995 0.00286052" quat="0.976684 0.214681 -0.000320249 -0.000361134">
                <inertial pos="0.00565721 -0.0210731 -0.0232179" quat="0.887497 -0.265998 0.121018 0.3563" mass="0.63073" diaginertia="0.000627385 0.00191018 0.00027076"/>
                <joint name="right_shoulder_roll_joint" class="/" pos="0 0 0" axis="-1 -0.000217917 -4.98217e-05" stiffness="0.00377259" range="-0.532047 2.53077" armature="0.109274" damping="0" frictionloss="0.112473"/>
                <geom name="//unnamed_geom_54" class="visual" mesh="right_upper_arm_roll_link"/>
                <body name="right_upper_arm_yaw_link" pos="-0.000575242 -0.0422869 -0.0693143" quat="0.999999 -0.000135029 0.00103393 -0.000432852">
                  <inertial pos="0.00207948 -0.00227597 -0.0834289" quat="0.999901 -0.00362117 -0.0132355 -0.00322186" mass="0.534757" diaginertia="0.00207391 0.00688347 0.000192822"/>
                  <joint name="right_shoulder_yaw_joint" class="/" pos="0 0 0" axis="-0.00936271 0.0076384 0.999927" stiffness="0.00654617" range="-2.95671 2.97364" armature="0.0989238" damping="0.015633" frictionloss="0.105625"/>
                  <geom name="//unnamed_geom_55" class="visual" mesh="right_upper_arm_yaw_link"/>
                  <geom name="right_upper_arm_yaw_link.STL" class="collision" size="0.0360717 0.0845633" pos="3.565e-05 0.00101968 -0.0748612" type="cylinder" rgba="0.752941 0.752941 0.752941 1"/>
                  <body name="right_lower_arm_pitch_link" pos="8.96065e-05 -6.07092e-05 -0.170672" quat="1 -6.75478e-06 -0.000125636 2.46935e-05">
                    <inertial pos="-0.000206433 -0.00696174 -0.0258431" quat="0.702338 0.0914208 -0.0914852 0.699996" mass="0.332197" diaginertia="0.000182036 0.000557921 7.29099e-05"/>
                    <joint name="right_elbow_pitch_joint" class="/" pos="0 0 0" axis="-0.00676326 -0.999931 -0.00955779" range="-2.3274 2.27358" armature="0.0955436" damping="0.0107735" frictionloss="0.0974836"/>
                    <geom name="//unnamed_geom_57" class="visual" mesh="right_lower_arm_pitch_link"/>
                    <body name="right_hand_yaw_link" pos="0.00345661 0.00201632 -0.0534739" quat="1 -0.000166178 -0.000375466 -5.484e-05">
                      <inertial pos="0.00284347 0.000184525 -0.0654488" quat="0.999686 0.00123943 -4.12061e-06 0.0250258" mass="0.99536" diaginertia="0.00158528 0.00511723 0.000388662"/>
                      <joint name="right_wrist_yaw_joint" class="/" pos="0 0 0" axis="0.000139641 9.13243e-05 1" stiffness="0.00441318" range="-2.96276 2.97846" armature="0.111317" damping="0.000372641" frictionloss="0.0903118"/>
                      <geom name="//unnamed_geom_58" class="visual" mesh="right_hand_yaw_link"/>
                      <geom name="right_hand_yaw_link.STL" class="collision" size="0.0413866 0.0692835" pos="0.000983446 0.000731006 -0.0717502" type="cylinder" rgba="0.752941 0.752941 0.752941 1"/>
                      <geom name="//unnamed_geom_60" class="reward_collision_sphere" size="0.0497771"/>
                      <body name="right_hand_roll_link" pos="-0.00183835 0.000165349 -0.182472" quat="0.999999 0.00092501 -6.88758e-06 0.000983107">
                        <inertial pos="0.00192515 -0.00259645 0.00132688" quat="0.499505 0.500972 0.499898 0.499624" mass="0.00516381" diaginertia="2.19125e-07 6.63438e-07 5.12244e-08"/>
                        <joint name="right_wrist_roll_joint" class="/" pos="0 0 0" axis="-0.999953 0.00824346 0.00516553" range="-0.820686 1.01117" armature="0.0988277" damping="0.0222247" frictionloss="0.0861643"/>
                        <geom name="//unnamed_geom_61" class="visual" mesh="right_hand_roll_link"/>
                        <body name="right_hand_pitch_link" pos="0.00132599 -0.00302982 0.000431597" quat="1 -0.000174804 2.12308e-05 -4.15932e-05">
                          <inertial pos="0.00043482 0.00870203 -0.0495481" quat="0.721606 0.124078 -0.11455 0.671393" mass="0.218421" diaginertia="0.000184299 0.000536731 7.24812e-05"/>
                          <joint name="right_wrist_pitch_joint" class="/" pos="0 0 0" axis="-0.0170796 -0.999853 0.00142226" range="-0.598569 0.668105" armature="0.0937668" damping="0.0225132" frictionloss="0.104811"/>
                          <geom name="//unnamed_geom_62" class="visual" mesh="right_hand_pitch"/>
                          <body name="right_jaw_link" pos="0.000736799 -0.002497 -0.0579041" quat="1 -0.000335553 0.000364411 -4.57199e-05">
                            <inertial pos="0.00197276 -0.00564905 -0.0351205" quat="0.706703 0.0181685 -0.0301048 0.706636" mass="0.0709144" diaginertia="4.76523e-05 0.000109089 2.42433e-05"/>
                            <joint name="right_jaw_joint" class="/" pos="0 0 0" axis="-0.999999 -0.00108292 9.94393e-06" stiffness="0.00429249" range="0.0436411 1.01991" armature="0.101417" damping="0.00559577" frictionloss="0.10025"/>
                            <geom name="//unnamed_geom_63" class="visual" mesh="right_jaw_link"/>
                            <geom name="//unnamed_geom_64" class="collision" size="0.0358395"/>
                            <geom name="//unnamed_geom_65" class="reward_collision_sphere" size="0.0497771" pos="0 0 -0.018871"/>
                          </body>
                        </body>
                      </body>
                    </body>
                  </body>
                </body>
              </body>
            </body>
            <body name="head_roll_link" pos="-3.13688e-05 0.00140081 0.286811" quat="1 6.61821e-05 -7.3144e-05 8.44223e-05">
              <inertial pos="0.00262702 -0.0014135 0.00244901" quat="-0.00494658 0.698676 0.00540179 0.715401" mass="0.0102624" diaginertia="4.36018e-07 8.73724e-07 3.35577e-07"/>
              <joint name="head_roll_joint" class="/" pos="0 0 0" axis="-1 0.000173758 -0.000271649" stiffness="0.0061822" range="-0.314318 0.347319" armature="0.088984" damping="0" frictionloss="0.105558"/>
              <geom name="//unnamed_geom_66" class="visual" mesh="head_roll_link"/>
              <body name="head_pitch_link" pos="-0.000617411 0.000562652 0.00452371" quat="1 1.89377e-05 4.8805e-05 0.000159198">
                <inertial pos="-0.00138905 -0.00253666 0.0138289" quat="0.660728 0.672621 0.23494 -0.236268" mass="0.0585142" diaginertia="1.57103e-05 4.62929e-05 1.29382e-05"/>
                <joint name="head_pitch_joint" class="/" pos="0 0 0" axis="0.0115682 -0.999802 0.016205" range="-0.907451 0.891281" armature="0.0891652" damping="0" frictionloss="0.0861055"/>
                <geom name="//unnamed_geom_67" class="visual" mesh="head_pitch_link"/>
                <body name="head_yaw_link" pos="-8.16817e-05 -0.00186468 0.0519942" quat="1 3.565e-05 5.16751e-05 0.000140845">
                  <inertial pos="0.0245344 -0.00364493 0.0923581" quat="0.704835 -0.136396 -0.144207 0.681035" mass="1.52277" diaginertia="0.00617424 0.0151215 0.0038499"/>
                  <joint name="head_yaw_joint" class="/" pos="0 0 0" axis="0.000470125 0.000579792 1" range="-2.71869 2.70864" armature="0.101585" damping="0.00392924" frictionloss="0.11032"/>
                  <geom name="//unnamed_geom_68" class="visual" rgba="0.12 0.12 0.12 1" mesh="head_yaw_link"/>
                  <geom name="head_yaw_link.STL" class="collision" size="0.118158" pos="0.0165054 -0.00100341 0.0883353" rgba="0.752941 0.752941 0.752941 1"/>
                  <geom name="//unnamed_geom_70" class="reward_collision_sphere" size="0.0995542" pos="0.027086 0 0.0943549"/>
                  <camera name="ego_camera" class="/" pos="0.0993152 0 0.10379" quat="-0.5 -0.5 0.5 0.5"/>
                </body>
              </body>
            </body>
          </body>
        </body>
      </body>
    </body>
  </worldbody>

  <contact>
    <pair class="/" geom1="floor" geom2="left_foot" name="//unnamed_contact_0"/>
    <pair class="/" geom1="floor" geom2="right_foot" name="//unnamed_contact_1"/>
  </contact>

  <actuator>
    <general name="left_hip_roll" class="/" joint="left_hip_roll_joint" forcerange="-44.634 44.634" gainprm="119.465" biasprm="0 -119.465 -0.995542"/>
    <general name="left_hip_yaw" class="/" joint="left_hip_yaw_joint" forcerange="-58.0082 58.0082" gainprm="119.465" biasprm="0 -119.465 -0.995542"/>
    <general name="left_hip_pitch" class="/" joint="left_hip_pitch_joint" forcerange="-234.84 234.84" gainprm="119.465" biasprm="0 -119.465 -0.995542"/>
    <general name="left_knee_pitch" class="/" joint="left_knee_pitch_joint" forcerange="-217.17 217.17" gainprm="119.465" biasprm="0 -119.465 -0.995542"/>
    <general name="left_ankle_pitch" class="/" joint="left_ankle_pitch_joint" forcerange="-14.8351 14.8351" gainprm="119.465" biasprm="0 -119.465 -0.995542"/>
    <general name="left_ankle_roll" class="/" joint="left_ankle_roll_joint" forcerange="-28.9053 28.9053" gainprm="119.465" biasprm="0 -119.465 -0.995542"/>
    <general name="right_hip_roll" class="/" joint="right_hip_roll_joint" forcerange="-48.4677 48.4677" gainprm="119.465" biasprm="0 -119.465 -0.995542"/>
    <general name="right_hip_yaw" class="/" joint="right_hip_yaw_joint" forcerange="-72.0197 72.0197" gainprm="119.465" biasprm="0 -119.465 -0.995542"/>
    <general name="right_hip_pitch" class="/" joint="right_hip_pitch_joint" forcerange="-241.338 241.338" gainprm="119.465" biasprm="0 -119.465 -0.995542"/>
    <general name="right_knee_pitch" class="/" joint="right_knee_pitch_joint" forcerange="-226.715 226.715" gainprm="119.465" biasprm="0 -119.465 -0.995542"/>
    <general name="right_ankle_pitch" class="/" joint="right_ankle_pitch_joint" forcerange="-13.8078 13.8078" gainprm="119.465" biasprm="0 -119.465 -0.995542"/>
    <general name="right_ankle_roll" class="/" joint="right_ankle_roll_joint" forcerange="-32.1485 32.1485" gainprm="119.465" biasprm="0 -119.465 -0.995542"/>
    <general name="waist_yaw" class="/" joint="waist_yaw_joint" forcerange="-63.1644 63.1644" gainprm="119.465" biasprm="0 -119.465 -0.995542"/>
    <general name="waist_pitch" class="/" joint="waist_pitch_joint" forcerange="-64.0437 64.0437" gainprm="119.465" biasprm="0 -119.465 -0.995542"/>
    <general name="waist_roll" class="/" joint="waist_roll_joint" forcerange="-63.7003 63.7003" gainprm="119.465" biasprm="0 -119.465 -0.995542"/>
    <general name="left_shoulder_pitch" class="/" joint="left_shoulder_pitch_joint" forcerange="-40.5725 40.5725" gainprm="119.465" biasprm="0 -119.465 -0.995542"/>
    <general name="left_shoulder_roll" class="/" joint="left_shoulder_roll_joint" forcerange="-37.0832 37.0832" gainprm="119.465" biasprm="0 -119.465 -0.995542"/>
    <general name="left_shoulder_yaw" class="/" joint="left_shoulder_yaw_joint" forcerange="-31.5108 31.5108" gainprm="119.465" biasprm="0 -119.465 -0.995542"/>
    <general name="left_elbow_pitch" class="/" joint="left_elbow_pitch_joint" forcerange="-30.868 30.868" gainprm="119.465" biasprm="0 -119.465 -0.995542"/>
    <general name="left_wrist_yaw" class="/" joint="left_wrist_yaw_joint" forcerange="-9.80792 9.80792" gainprm="119.465" biasprm="0 -119.465 -0.995542"/>
    <general name="left_wrist_roll" class="/" joint="left_wrist_roll_joint" forcerange="-4.08531 4.08531" gainprm="119.465" biasprm="0 -119.465 -0.995542"/>
    <general name="left_wrist_pitch" class="/" joint="left_wrist_pitch_joint" forcerange="-4.12782 4.12782" gainprm="119.465" biasprm="0 -119.465 -0.995542"/>
    <general name="left_jaw" class="/" joint="left_jaw_joint" forcerange="-3.95792 3.95792" gainprm="119.465" biasprm="0 -119.465 -0.995542"/>
    <general name="right_shoulder_pitch" class="/" joint="right_shoulder_pitch_joint" forcerange="-38.0205 38.0205" gainprm="119.465" biasprm="0 -119.465 -0.995542"/>
    <general name="right_shoulder_roll" class="/" joint="right_shoulder_roll_joint" forcerange="-39.3329 39.3329" gainprm="119.465" biasprm="0 -119.465 -0.995542"/>
    <general name="right_shoulder_yaw" class="/" joint="right_shoulder_yaw_joint" forcerange="-32.4254 32.4254" gainprm="119.465" biasprm="0 -119.465 -0.995542"/>
    <general name="right_elbow_pitch" class="/" joint="right_elbow_pitch_joint" forcerange="-28.2318 28.2318" gainprm="119.465" biasprm="0 -119.465 -0.995542"/>
    <general name="right_wrist_yaw" class="/" joint="right_wrist_yaw_joint" forcerange="-10.2544 10.2544" gainprm="119.465" biasprm="0 -119.465 -0.995542"/>
    <general name="right_wrist_roll" class="/" joint="right_wrist_roll_joint" forcerange="-3.91499 3.91499" gainprm="119.465" biasprm="0 -119.465 -0.995542"/>
    <general name="right_wrist_pitch" class="/" joint="right_wrist_pitch_joint" forcerange="-4.12123 4.12123" gainprm="119.465" biasprm="0 -119.465 -0.995542"/>
    <general name="right_jaw" class="/" joint="right_jaw_joint" forcerange="-4.25294 4.25294" gainprm="119.465" biasprm="0 -119.465 -0.995542"/>
    <general name="head_roll" class="/" joint="head_roll_joint" forcerange="-4.00776 4.00776" gainprm="119.465" biasprm="0 -119.465 -0.995542"/>
    <general name="head_pitch" class="/" joint="head_pitch_joint" forcerange="-3.59215 3.59215" gainprm="119.465" biasprm="0 -119.465 -0.995542"/>
    <general name="head_yaw" class="/" joint="head_yaw_joint" forcerange="-3.87718 3.87718" gainprm="119.465" biasprm="0 -119.465 -0.995542"/>
  </actuator>

  <sensor>
    <gyro site="imu" name="imu_angular_velocity"/>
    <velocimeter site="imu" name="imu_linear_velocity"/>
    <framelinvel objtype="site" objname="left_foot" name="left_foot_global_linear_velocity"/>
    <framelinvel objtype="site" objname="right_foot" name="right_foot_global_linear_velocity"/>
  </sensor>

  <keyframe>
    <key name="home" qpos="0 0 0.8665 1 0 0 0 0 0 -0.4 0.8 -0.4 0 0 0 0.4 -0.8 0.4 0 0 0 0 0 -0.2 0 -0.785 0 0 0 0 0 0.2 0 0.785 0 0 0 0 0 0 0"/>
  </keyframe>
</mujoco>
