<mujoco model="GR1T2_jaw">
  <compiler angle="radian" assetdir="assets" balanceinertia="true" inertiafromgeom="false"/>

  <option timestep="0.005" density="1.2" viscosity="2e-05"/>

  <size nkey="1"/>

  <visual>
    <quality shadowsize="8192"/>
    <map shadowclip="0.5"/>
  </visual>

  <default>
    <default class="/">
      <joint armature="0.1" damping="0.01" frictionloss="0.1"/>
      <geom contype="0" conaffinity="0" group="1" solref="-1000 -80"/>
      <site size="0.01 0.005 0.005" group="5"/>
      <general forcelimited="true" biastype="affine" gainprm="80" biasprm="0 -80 -2"/>
      <default class="visual">
        <geom type="mesh" density="0" rgba="0.18 0.18 0.18 1"/>
      </default>
      <default class="collision">
        <geom group="3"/>
      </default>
      <default class="foot">
        <geom size="0.126 0.045 0.01" type="box" condim="6" group="4" priority="1" solimp="0.015 1 0.01"/>
      </default>
      <default class="reward_collision_sphere">
        <geom group="5" rgba="1 0 0 1"/>
      </default>
    </default>
  </default>

  <asset>
    <texture type="skybox" colorspace="auto" name="//unnamed_texture_0" builtin="gradient" rgb1="0.95 0.95 0.95" rgb2="0.95 0.95 0.95" width="100" height="600"/>
    <texture type="2d" colorspace="auto" name="texplane" builtin="checker" rgb1="0.345 0.575 0.748" rgb2="0.345 0.575 0.748" markrgb="1 1 1" width="512" height="512"/>
    <material name="MatPlane" class="/" texture="texplane" texuniform="true" texrepeat="2 2" specular="0.9"/>
    <mesh name="base_link" class="/" file="base_link.STL"/>
    <mesh name="left_thigh_roll_link" class="/" file="left_thigh_roll_link.STL"/>
    <mesh name="left_thigh_yaw_link" class="/" file="left_thigh_yaw_link.STL"/>
    <mesh name="left_thigh_pitch_link" class="/" file="left_thigh_pitch_link.STL"/>
    <mesh name="left_shank_pitch_link" class="/" file="left_shank_pitch_link.STL"/>
    <mesh name="left_foot_pitch_link" class="/" file="left_foot_pitch_link.STL"/>
    <mesh name="left_foot_roll_link" class="/" file="left_foot_roll_link.STL"/>
    <mesh name="right_thigh_roll_link" class="/" file="right_thigh_roll_link.STL"/>
    <mesh name="right_thigh_yaw_link" class="/" file="right_thigh_yaw_link.STL"/>
    <mesh name="right_thigh_pitch_link" class="/" file="right_thigh_pitch_link.STL"/>
    <mesh name="right_shank_pitch_link" class="/" file="right_shank_pitch_link.STL"/>
    <mesh name="right_foot_pitch_link" class="/" file="right_foot_pitch_link.STL"/>
    <mesh name="right_foot_roll_link" class="/" file="right_foot_roll_link.STL"/>
    <mesh name="waist_yaw_link" class="/" file="waist_yaw_link.STL"/>
    <mesh name="waist_pitch_link" class="/" file="waist_pitch_link.STL"/>
    <mesh name="waist_roll_link" class="/" file="waist_roll_link.STL"/>
    <mesh name="torso_link" class="/" file="torso_link.STL"/>
    <mesh name="left_upper_arm_pitch_link" class="/" file="left_upper_arm_pitch_link.STL"/>
    <mesh name="left_upper_arm_roll_link" class="/" file="left_upper_arm_roll_link.STL"/>
    <mesh name="left_upper_arm_yaw_link" class="/" file="left_upper_arm_yaw_link.STL"/>
    <mesh name="left_lower_arm_pitch_link" class="/" file="left_lower_arm_pitch_link.STL"/>
    <mesh name="left_hand_yaw_link" class="/" file="left_hand_yaw_link.STL"/>
    <mesh name="left_hand_roll_link" class="/" file="left_hand_roll_link.STL"/>
    <mesh name="left_hand_pitch" class="/" file="left_hand_pitch.STL"/>
    <mesh name="left_jaw_link" class="/" file="left_jaw_link.STL"/>
    <mesh name="right_upper_arm_pitch_link" class="/" file="right_upper_arm_pitch_link.STL"/>
    <mesh name="right_upper_arm_roll_link" class="/" file="right_upper_arm_roll_link.STL"/>
    <mesh name="right_upper_arm_yaw_link" class="/" file="right_upper_arm_yaw_link.STL"/>
    <mesh name="right_lower_arm_pitch_link" class="/" file="right_lower_arm_pitch_link.STL"/>
    <mesh name="right_hand_yaw_link" class="/" file="right_hand_yaw_link.STL"/>
    <mesh name="right_hand_roll_link" class="/" file="right_hand_roll_link.STL"/>
    <mesh name="right_hand_pitch" class="/" file="right_hand_pitch.STL"/>
    <mesh name="right_jaw_link" class="/" file="right_jaw_link.STL"/>
    <mesh name="head_roll_link" class="/" file="head_roll_link.STL"/>
    <mesh name="head_pitch_link" class="/" file="head_pitch_link.STL"/>
    <mesh name="head_yaw_link" class="/" file="head_yaw_link.STL"/>
    <mesh name="imu_link" class="/" file="imu_link.STL"/>
  </asset>

  <worldbody>
    <geom name="floor" class="/" size="100 100 0.125" type="plane" group="0" material="MatPlane"/>
    <light name="toplight_shadow" class="/" pos="0 0 5" dir="0.0990148 0.0990148 -0.990148" type="directional" ambient="0.04 0.04 0.04" diffuse="0.55 0.55 0.55" specular="0.12 0.12 0.12"/>
    <light name="toplight_fill" class="/" pos="0 0 5" dir="0.0990148 0.0990148 -0.990148" type="directional" castshadow="false" ambient="0.04 0.04 0.04" diffuse="0.3 0.3 0.3" specular="0.08 0.08 0.08"/>
    <body name="trunk" pos="-0.00796614 -0.0135733 0.000913187" quat="1 -4.18914e-05 -0.000185078 -4.15493e-05">
      <inertial pos="-0.0392605 -0.0127163 -0.00998893" quat="0.999995 0.00183649 0.000524054 -0.00237148" mass="6.10603" diaginertia="0.00889665 0.143605 0.020261"/>
      <joint name="//unnamed_joint_0" type="free"/>
      <geom name="//unnamed_geom_1" class="visual" rgba="0.12 0.12 0.12 1" mesh="base_link"/>
      <geom name="base_link.STL" class="collision" size="0.131558 0.0736828" pos="-0.0313951 0.000600098 0.00797262" quat="0.706838 -0.707359 0.00477667 0" type="cylinder" rgba="0.752941 0.752941 0.752941 1"/>
      <geom name="//unnamed_geom_3" class="visual" pos="0 0 -0.0515921" quat="1 0 0 0" rgba="0.12 0.12 0.12 1" mesh="imu_link"/>
      <geom name="//unnamed_geom_4" class="reward_collision_sphere" size="0.0859897" pos="0 0.16217 0.0865639"/>
      <geom name="//unnamed_geom_5" class="reward_collision_sphere" size="0.0859897" pos="0 -0.16217 0.0865639"/>
      <site name="imu" class="/" pos="0.061652 0.0628161 0.0190198" size="0.0107487"/>
      <camera name="track" class="/" pos="0 -3.24341 0" quat="0.707107 0.707107 0 0" mode="trackcom"/>
      <body name="left_thigh_roll_link" pos="-0.0291237 0.175566 -0.0182854" quat="0.999999 -0.000541157 0.00135298 0.00061968">
        <inertial pos="-0.00508027 -0.00921796 0.00212699" quat="-0.0258296 0.673901 -0.0753997 0.73451" mass="1.71117" diaginertia="0.000617453 0.0279059 0.000872636"/>
        <joint name="left_hip_roll_joint" class="/" pos="0 0 0" axis="-0.998513 -0.0476303 -0.0265074" range="-0.716759 0.0903282" armature="0.134553" damping="0.0119958" frictionloss="0.145663"/>
        <geom name="//unnamed_geom_6" class="visual" mesh="left_thigh_roll_link"/>
        <body name="left_thigh_yaw_link" pos="0.0307847 0.00394328 0.00140447" quat="0.999977 -0.00446454 -0.00162431 0.00491116">
          <inertial pos="0.00765886 0.0760731 -0.0964599" quat="0.564219 0.0931924 -0.237625 0.785179" mass="5.04425" diaginertia="0.00620473 0.233601 0.00411089"/>
          <joint name="left_hip_yaw_joint" class="/" pos="0 0 0" axis="0.0151446 -0.00111086 -0.999885" stiffness="0.000739986" range="-0.925057 0.986185" armature="0.0394449" damping="0" frictionloss="0.0326655"/>
          <geom name="//unnamed_geom_7" class="visual" mesh="left_thigh_yaw_link"/>
          <body name="left_thigh_pitch_link" pos="-0.00622373 0.0287392 -0.115734" quat="0.999977 0.00417579 0.000436811 0.00528352">
            <inertial pos="-0.000916633 -0.0347479 -0.0556062" quat="0.999729 0.00283504 -0.0228618 -0.00335025" mass="11.0763" diaginertia="0.019412 1.10488 0.0164329"/>
            <joint name="left_hip_pitch_joint" class="/" pos="0 0 0" axis="-0.0320932 0.999277 -0.0203926" range="-1.83931 0.632272" armature="0.0959344" damping="0.0648926" frictionloss="0.0823699"/>
            <geom name="//unnamed_geom_8" class="visual" mesh="left_thigh_pitch_link"/>
            <geom name="left_thigh_pitch_link.STL" class="collision" size="0.0881394 0.134266" pos="0.000516127 -0.0486511 -0.14461" type="cylinder" rgba="0.752941 0.752941 0.752941 1"/>
            <geom name="//unnamed_geom_10" class="reward_collision_sphere" size="0.107487" pos="0 -0.016217 -0.043282"/>
            <body name="left_shank_pitch_link" pos="0.00753844 -0.0411751 -0.317408" quat="1 0.000191691 -0.000515517 -0.000297819">
              <inertial pos="0.0103963 -0.00216187 -0.0850534" quat="0.999748 -0.0131873 0.00241358 -0.017984" mass="2.57127" diaginertia="0.00233649 0.109477 0.000610027"/>
              <joint name="left_knee_pitch_joint" class="/" pos="0 0 0" axis="0.0281916 0.999602 -0.000633923" range="-0.367699 1.93093" armature="0.117016" damping="0" frictionloss="0.165385"/>
              <geom name="//unnamed_geom_11" class="visual" mesh="left_shank_pitch_link"/>
              <geom name="left_shank_pitch_link.STL" class="collision" size="0.0573136 0.0971522" pos="-1.22314e-05 -0.00136636 -0.151219" quat="0.00125538 -0.202712 0.979238 0" type="cylinder" rgba="0.752941 0.752941 0.752941 1"/>
              <geom name="//unnamed_geom_13" class="reward_collision_sphere" size="0.0537435"/>
              <geom name="//unnamed_geom_14" class="reward_collision_sphere" size="0.0644922" pos="0 0 -0.0952203"/>
              <body name="left_foot_pitch_link" pos="-0.00214072 -0.00754798 -0.298487" quat="1 0.000109333 0.000454919 -9.67257e-05">
                <inertial pos="0.00432387 0.000217215 -0.00955155" quat="-0.00155915 0.706204 0.066387 0.704887" mass="0.0518869" diaginertia="1.03851e-06 5.46531e-05 2.52245e-06"/>
                <joint name="left_ankle_pitch_joint" class="/" pos="0 0 0" axis="-0.0390113 0.997209 -0.0636563" range="-1.16606 0.688318" armature="0.104243" damping="0.00768516" frictionloss="0.101194"/>
                <geom name="//unnamed_geom_15" class="visual" mesh="left_foot_pitch_link"/>
                <body name="left_foot_roll_link" pos="0.0121236 -0.00329367 0.0013729" quat="1 0.000186589 -0.000180629 0.00010426">
                  <inertial pos="0.0396541 -0.0134778 -0.04694" quat="0.000882431 0.725709 0.00369876 0.687992" mass="1.31389" diaginertia="0.00109667 0.0579194 0.000374017"/>
                  <joint name="left_ankle_roll_joint" class="/" pos="0 0 0" axis="-0.997753 -0.0371779 0.0557374" stiffness="0.0116919" range="-0.460222 0.519669" armature="0.0903735" damping="0" frictionloss="0.137821"/>
                  <geom name="//unnamed_geom_16" class="visual" mesh="left_foot_roll_link"/>
                  <geom name="left_foot" class="foot" size="0.131376 0.0297355 0.00529461" pos="0.0331772 0 -0.0385209"/>
                  <geom name="//unnamed_geom_18" class="reward_collision_sphere" size="0.0537435" pos="0 0 -0.0259692"/>
                  <geom name="//unnamed_geom_19" class="reward_collision_sphere" size="0.0537435" pos="0.0884724 0 -0.0259692"/>
                  <site name="left_foot" class="foot" pos="0.0331772 0 -0.0385209" size="0.0107487"/>
                </body>
              </body>
            </body>
          </body>
        </body>
      </body>
      <body name="right_thigh_roll_link" pos="-0.0237449 -0.172037 -0.0267743" quat="1 4.88286e-05 -6.3568e-05 3.55916e-05">
        <inertial pos="-0.0143678 0.00940443 0.00634436" quat="0.000555416 0.713468 0.0141642 0.700545" mass="1.694" diaginertia="0.000610733 0.0262409 0.000712035"/>
        <joint name="right_hip_roll_joint" class="/" pos="0 0 0" axis="-0.999915 -0.0031252 0.0126318" stiffness="0.0395535" range="-0.191241 0.826886" armature="0.103437" damping="0" frictionloss="0.0660803"/>
        <geom name="//unnamed_geom_20" class="visual" mesh="right_thigh_roll_link"/>
        <body name="right_thigh_yaw_link" pos="0.0249789 -0.0158822 -0.0108715" quat="1 -6.16414e-05 -3.09839e-05 -4.44651e-05">
          <inertial pos="-0.0141999 -0.0759755 -0.104933" quat="0.686676 -0.148118 0.150739 0.695568" mass="4.29555" diaginertia="0.00493808 0.188401 0.0034342"/>
          <joint name="right_hip_yaw_joint" class="/" pos="0 0 0" axis="0.0123696 -0.0588727 -0.998189" stiffness="0.0146012" range="-0.68419 0.540478" armature="0.105222" damping="0" frictionloss="0.162296"/>
          <geom name="//unnamed_geom_21" class="visual" mesh="right_thigh_yaw_link"/>
          <body name="right_thigh_pitch_link" pos="0.00766174 -0.0458278 -0.126066" quat="0.999999 0.00035914 -0.00114889 0.000204311">
            <inertial pos="0.00475939 0.0436551 -0.0469419" quat="0.999764 -0.016851 -0.0111583 0.00791524" mass="8.83145" diaginertia="0.0202182 0.898036 0.0140807"/>
            <joint name="right_hip_pitch_joint" class="/" pos="0 0 0" axis="-0.000984669 -0.999998 0.00179936" stiffness="0.0611768" range="-0.674752 1.7297" armature="0.139478" damping="0" frictionloss="0.0410562"/>
            <geom name="//unnamed_geom_22" class="visual" mesh="right_thigh_pitch_link"/>
            <geom name="right_thigh_pitch_link.STL" class="collision" size="0.0881394 0.134263" pos="-0.00156542 0.0486511 -0.14461" quat="0.999971 0.00269833 0.00706272 0" type="cylinder" rgba="0.752941 0.752941 0.752941 1"/>
            <geom name="//unnamed_geom_24" class="reward_collision_sphere" size="0.107487" pos="0 0.016217 -0.043282"/>
            <body name="right_shank_pitch_link" pos="0.00244985 0.0405487 -0.304468" quat="0.999996 -0.00089976 0.00212609 -0.001298">
              <inertial pos="0.0155552 0.0034059 -0.100026" quat="0.99967 0.0103056 0.00595818 0.0227673" mass="1.98648" diaginertia="0.00187625 0.0862096 0.000540981"/>
              <joint name="right_knee_pitch_joint" class="/" pos="0 0 0" axis="-0.00288953 -0.999984 -0.00493641" stiffness="0.0176276" range="-1.84393 0.0386393" armature="0.151702" damping="0.0042354" frictionloss="0.11447"/>
              <geom name="//unnamed_geom_25" class="visual" mesh="right_shank_pitch_link"/>
              <geom name="right_shank_pitch_link.STL" class="collision" size="0.0573133 0.0971512" pos="-1.22314e-05 -0.00136638 -0.151226" type="cylinder" rgba="0.752941 0.752941 0.752941 1"/>
              <geom name="//unnamed_geom_27" class="reward_collision_sphere" size="0.0537435"/>
              <geom name="//unnamed_geom_28" class="reward_collision_sphere" size="0.0644922" pos="0 0 -0.0952203"/>
              <body name="right_foot_pitch_link" pos="-0.0025677 0.00740046 -0.299477" quat="0.999989 -0.00450222 -0.00149382 -8.76228e-05">
                <inertial pos="0.0108663 -0.00512194 0.0048557" quat="0.0443841 0.677387 -0.0268176 0.733797" mass="0.0734793" diaginertia="1.62187e-06 8.25213e-05 2.91567e-06"/>
                <joint name="right_ankle_pitch_joint" class="/" pos="0 0 0" axis="-0.00144455 -0.999932 -0.0115879" range="-0.554109 1.04902" armature="0.136527" damping="0.0322839" frictionloss="0.0456637"/>
                <geom name="//unnamed_geom_29" class="visual" mesh="right_foot_pitch_link"/>
                <body name="right_foot_roll_link" pos="0.00812915 -0.0136519 -0.00575194" quat="1 -1.03074e-05 2.76517e-06 3.14535e-06">
                  <inertial pos="0.0125871 -0.00566856 -0.0313552" quat="-0.0150275 0.718168 0.0476547 0.694073" mass="1.3563" diaginertia="0.0010337 0.0567109 0.000365795"/>
                  <joint name="right_ankle_roll_joint" class="/" pos="0 0 0" axis="-0.999972 0.00479641 0.0058155" range="-0.221385 0.310197" armature="0.121891" damping="0" frictionloss="0.107116"/>
                  <geom name="//unnamed_geom_30" class="visual" mesh="right_foot_roll_link"/>
                  <geom name="right_foot" class="foot" size="0.114365 0.0408153 0.00941252" pos="0.0331772 0 -0.0385209"/>
                  <geom name="//unnamed_geom_32" class="reward_collision_sphere" size="0.0537435" pos="0 0 -0.0259692"/>
                  <geom name="//unnamed_geom_33" class="reward_collision_sphere" size="0.0537435" pos="0.0884724 0 -0.0259692"/>
                  <site name="right_foot" class="foot" pos="0.0331772 0 -0.0385209" size="0.0107487"/>
                </body>
              </body>
            </body>
          </body>
        </body>
      </body>
      <body name="waist_yaw_link" pos="-0.00576931 3.14341e-05 -0.0109566" quat="0.999991 0.00113516 0.00329029 0.00228473">
        <inertial pos="0.00483942 -0.0111274 0.0462758" quat="0.980032 0.188008 -0.0283633 0.0581969" mass="1.92058" diaginertia="0.000645074 0.0380809 0.00102548"/>
        <joint name="waist_yaw_joint" class="/" pos="0 0 0" axis="0.0671679 0.0132417 0.997654" range="-0.889707 1.21799" armature="0.14524" damping="0.056108" frictionloss="0.108416"/>
        <geom name="//unnamed_geom_34" class="visual" rgba="0.12 0.12 0.12 1" mesh="waist_yaw_link"/>
        <body name="waist_pitch_link" pos="0.0119576 -0.00256272 0.0760384" quat="1 0.000243983 3.30334e-06 0.000284142">
          <inertial pos="0.00930846 -0.00216094 0.0403975" quat="0.997416 -0.0386303 0.0602886 0.00584976" mass="1.88789" diaginertia="0.00111259 0.0518193 0.000930926"/>
          <joint name="waist_pitch_joint" class="/" pos="0 0 0" axis="-0.0179992 -0.99782 -0.0634956" stiffness="0.00844565" range="-1.43783 0.523665" armature="0.0983426" damping="0.0288891" frictionloss="0.054382"/>
          <geom name="//unnamed_geom_35" class="visual" rgba="0.12 0.12 0.12 1" mesh="waist_pitch_link"/>
          <body name="waist_roll_link" pos="-0.00868995 -0.000846425 0.0706601" quat="1 -0.000548426 -0.000665206 0.0004586">
            <inertial pos="0.00321932 -0.0116011 0.122966" quat="0.99661 0.0352821 -0.0734723 0.0112326" mass="8.71034" diaginertia="0.0142819 0.620825 0.017043"/>
            <joint name="waist_roll_joint" class="/" pos="0 0 0" axis="-0.999696 -0.0246366 0.000358708" stiffness="0.0787667" range="-0.926219 0.716792" armature="0.158077" damping="0.0295595" frictionloss="0.0826424"/>
            <geom name="//unnamed_geom_36" class="visual" rgba="0.12 0.12 0.12 1" mesh="waist_roll_link"/>
            <geom name="//unnamed_geom_37" class="visual" pos="-0.00165886 0.000931555 0.138805" quat="1 0 0 0" mesh="torso_link"/>
            <geom name="torso_link.STL" class="collision" size="0.169214 0.0324536" pos="-0.0133194 0.0093569 0.127967" type="cylinder" rgba="0.752941 0.752941 0.752941 1"/>
            <geom name="//unnamed_geom_39" class="reward_collision_sphere" size="0.139733" pos="0 0 0.173128"/>
            <body name="left_upper_arm_pitch_link" pos="-0.0158462 0.166685 0.18273" quat="0.975469 0.2201 0.00307245 0.00250676">
              <inertial pos="0.00812683 0.0987294 0.00981169" quat="0.703102 0.70901 0.00713543 -0.05387" mass="0.960392" diaginertia="0.000520076 0.0223935 0.000217411"/>
              <joint name="left_shoulder_pitch_joint" class="/" pos="0 0 0" axis="0.0207453 0.999339 0.029849" stiffness="0.0254127" range="-2.57703 2.18618" armature="0.0983706" damping="0" frictionloss="0.0388905"/>
              <geom name="//unnamed_geom_40" class="visual" mesh="left_upper_arm_pitch_link"/>
              <body name="left_upper_arm_roll_link" pos="0.00892036 0.15906 0.00684999" quat="0.976812 -0.214099 0.000265065 -0.000172593">
                <inertial pos="0.00477184 0.0361921 -0.0210292" quat="0.869349 0.302654 0.125851 -0.369858" mass="0.890294" diaginertia="0.000210681 0.0109129 0.000199607"/>
                <joint name="left_shoulder_roll_joint" class="/" pos="0 0 0" axis="-0.99852 -0.0126959 -0.0528755" range="-2.76896 0.296414" armature="0.159248" damping="0.029153" frictionloss="0.0946952"/>
                <geom name="//unnamed_geom_41" class="visual" mesh="left_upper_arm_roll_link"/>
                <body name="left_upper_arm_yaw_link" pos="0.00388993 0.0690831 -0.0614416" quat="0.999998 -0.000719177 0.00160961 -0.000735403">
                  <inertial pos="-0.0117821 0.00946395 -0.0756751" quat="0.998861 0.0122432 -0.0459526 0.0038119" mass="0.49561" diaginertia="0.000548836 0.0361759 0.000117343"/>
                  <joint name="left_shoulder_yaw_joint" class="/" pos="0 0 0" axis="-0.0032307 0.00167747 0.999993" range="-2.79864 2.66712" armature="0.134386" damping="0.0162175" frictionloss="0.0544079"/>
                  <geom name="//unnamed_geom_42" class="visual" mesh="left_upper_arm_yaw_link"/>
                  <geom name="left_upper_arm_yaw_link.STL" class="collision" size="0.038946 0.0913017" pos="2.91114e-05 -0.00145027 -0.0686798" quat="0.00803418 -0.995528 0.0941277 0" type="cylinder" rgba="0.752941 0.752941 0.752941 1"/>
                  <body name="left_lower_arm_pitch_link" pos="0.00243152 0.000133 -0.152896" quat="0.999991 0.00204991 0.0011357 0.00340579">
                    <inertial pos="-0.0154528 0.00537951 -0.0289457" quat="0.72042 -0.0810107 0.0895456 0.682945" mass="0.406372" diaginertia="7.5179e-05 0.00349768 4.7456e-05"/>
                    <joint name="left_elbow_pitch_joint" class="/" pos="0 0 0" axis="0.0491984 0.998603 0.0192965" range="-2.08432 2.26531" armature="0.111883" damping="0.0449484" frictionloss="0.0540096"/>
                    <geom name="//unnamed_geom_44" class="visual" mesh="left_lower_arm_pitch_link"/>
                    <body name="left_hand_yaw_link" pos="0.000303635 0.000416303 -0.0406009" quat="0.99998 -0.000321501 0.00349514 -0.00528976">
                      <inertial pos="-0.0132409 0.0176421 -0.062582" quat="0.999945 0.00471233 0.00937668 0.000657632" mass="1.17291" diaginertia="0.000585469 0.0290751 0.000189663"/>
                      <joint name="left_wrist_yaw_joint" class="/" pos="0 0 0" axis="0.0093152 -0.00382694 0.999949" stiffness="0.0251378" range="-2.92109 3.22748" armature="0.0539634" damping="0.0338372" frictionloss="0.0788825"/>
                      <geom name="//unnamed_geom_45" class="visual" mesh="left_hand_yaw_link"/>
                      <geom name="left_hand_yaw_link.STL" class="collision" size="0.0446844 0.0748042" pos="0.000803072 -0.00249922 -0.0658257" type="cylinder" rgba="0.752941 0.752941 0.752941 1"/>
                      <geom name="//unnamed_geom_47" class="reward_collision_sphere" size="0.0537435"/>
                      <body name="left_hand_roll_link" pos="0.00198531 0.000232869 -0.168409" quat="0.999993 -0.00343062 -0.00147039 -0.000532767">
                        <inertial pos="-0.00109662 2.99707e-06 0.0137585" quat="0.50021 0.499663 0.500023 0.500104" mass="0.00435156" diaginertia="5.0106e-08 2.84472e-06 3.22987e-08"/>
                        <joint name="left_wrist_roll_joint" class="/" pos="0 0 0" axis="-0.999805 -0.00908505 -0.0175458" range="-1.10391 0.960477" armature="0.122877" damping="0" frictionloss="0.0594667"/>
                        <geom name="//unnamed_geom_48" class="visual" mesh="left_hand_roll_link"/>
                        <body name="left_hand_pitch_link" pos="0.00459603 0.00592784 0.0122071" quat="0.999994 -0.00207745 -0.00177433 0.00224795">
                          <inertial pos="-0.000435935 -0.0193742 -0.0465399" quat="0.720915 -0.11263 0.125212 0.672248" mass="0.224371" diaginertia="5.51924e-05 0.00297709 3.98663e-05"/>
                          <joint name="left_wrist_pitch_joint" class="/" pos="0 0 0" axis="0.00157898 0.999998 0.000938856" stiffness="0.0214488" range="-0.618179 0.82296" armature="0.0553504" damping="0" frictionloss="0.17899"/>
                          <geom name="//unnamed_geom_49" class="visual" mesh="left_hand_pitch"/>
                          <body name="left_jaw_link" pos="-0.00298519 0.00261441 -0.0528983" quat="0.999977 2.87889e-06 -0.00391808 -0.00559576">
                            <inertial pos="-0.00359194 0.0134561 -0.0189144" quat="0.70859 -0.0174024 0.0325852 0.704653" mass="0.0717196" diaginertia="1.76354e-05 0.000613963 1.74101e-05"/>
                            <joint name="left_jaw_joint" class="/" pos="0 0 0" axis="-0.998762 0.0486693 0.0103254" range="-0.968161 0.103053" armature="0.0813286" damping="0" frictionloss="0.141916"/>
                            <geom name="//unnamed_geom_50" class="visual" mesh="left_jaw_link"/>
                            <geom name="//unnamed_geom_51" class="collision" size="0.0386953"/>
                            <geom name="//unnamed_geom_52" class="reward_collision_sphere" size="0.0537435" pos="0 0 -0.0173128"/>
                          </body>
                        </body>
                      </body>
                    </body>
                  </body>
                </body>
              </body>
            </body>
            <body name="right_upper_arm_pitch_link" pos="0.00597181 -0.164219 0.170448" quat="0.976412 -0.215911 -0.00109916 -0.000233531">
              <inertial pos="-0.00639213 -0.101815 0.0108806" quat="0.701557 0.711303 0.0312499 0.0298382" mass="0.997027" diaginertia="0.000445339 0.0258631 0.000266413"/>
              <joint name="right_shoulder_pitch_joint" class="/" pos="0 0 0" axis="0.0286311 -0.997684 0.0617058" stiffness="0.0241918" range="-1.6421 2.79288" armature="0.144957" damping="0" frictionloss="0.0315808"/>
              <geom name="//unnamed_geom_53" class="visual" mesh="right_upper_arm_pitch_link"/>
              <body name="right_upper_arm_roll_link" pos="0.00544213 -0.164773 0.00180235" quat="0.976657 0.214804 -0.000337006 0.000999669">
                <inertial pos="0.00538527 -0.0148648 -0.023437" quat="0.884788 -0.284301 0.0929192 0.357336" mass="0.764637" diaginertia="0.000270332 0.0109647 0.00016172"/>
                <joint name="right_shoulder_roll_joint" class="/" pos="0 0 0" axis="-0.998178 0.0564568 0.0212877" stiffness="0.00612569" range="-0.560221 2.2735" armature="0.114099" damping="0" frictionloss="0.0551999"/>
                <geom name="//unnamed_geom_54" class="visual" mesh="right_upper_arm_roll_link"/>
                <body name="right_upper_arm_yaw_link" pos="0.0156614 -0.053416 -0.0494711" quat="1 1.31331e-05 2.96039e-05 -7.72722e-05">
                  <inertial pos="-0.00809122 0.0123124 -0.0893576" quat="0.997349 -0.0688751 -0.0228488 -0.00542453" mass="0.677111" diaginertia="0.000807993 0.042444 0.000128991"/>
                  <joint name="right_shoulder_yaw_joint" class="/" pos="0 0 0" axis="0.0399028 -0.0574447 0.997551" stiffness="0.0269047" range="-2.78991 2.99363" armature="0.0775635" damping="0" frictionloss="0.178817"/>
                  <geom name="//unnamed_geom_55" class="visual" mesh="right_upper_arm_yaw_link"/>
                  <geom name="right_upper_arm_yaw_link.STL" class="collision" size="0.038946 0.0913017" pos="2.91114e-05 0.00145027 -0.0686798" type="cylinder" rgba="0.752941 0.752941 0.752941 1"/>
                  <body name="right_lower_arm_pitch_link" pos="-0.00708181 -0.0171034 -0.166981" quat="1 -0.000150879 5.92237e-06 -0.000441438">
                    <inertial pos="0.00737074 -0.00528129 -0.0122149" quat="0.684568 0.062905 -0.095649 0.719903" mass="0.344071" diaginertia="5.76152e-05 0.00308148 5.78565e-05"/>
                    <joint name="right_elbow_pitch_joint" class="/" pos="0 0 0" axis="-0.00328482 -0.999974 0.00643341" stiffness="0.0362271" range="-1.95463 2.23374" armature="0.180011" damping="0" frictionloss="0.102726"/>
                    <geom name="//unnamed_geom_57" class="visual" mesh="right_lower_arm_pitch_link"/>
                    <body name="right_hand_yaw_link" pos="0.00658658 0.0139539 -0.0363858" quat="0.999972 -0.00202905 0.0064686 0.00306025">
                      <inertial pos="0.000443582 -0.0102092 -0.0774828" quat="0.99953 0.0175495 0.000548013 0.0251227" mass="1.18564" diaginertia="0.000491122 0.0249105 0.000220911"/>
                      <joint name="right_wrist_yaw_joint" class="/" pos="0 0 0" axis="-0.00106482 -0.00171635 0.999998" range="-2.73319 2.98341" armature="0.03867" damping="0" frictionloss="0.11334"/>
                      <geom name="//unnamed_geom_58" class="visual" mesh="right_hand_yaw_link"/>
                      <geom name="right_hand_yaw_link.STL" class="collision" size="0.0446844 0.0748042" pos="0.000803072 0.0010397 -0.0658257" type="cylinder" rgba="0.752941 0.752941 0.752941 1"/>
                      <geom name="//unnamed_geom_60" class="reward_collision_sphere" size="0.0537435"/>
                      <body name="right_hand_roll_link" pos="0.00163113 0.00591153 -0.156737" quat="0.99997 -0.00651358 0.0034413 0.00228536">
                        <inertial pos="-0.000383989 0.0159163 -0.00230267" quat="0.478634 0.477396 0.516488 0.525587" mass="0.00515903" diaginertia="5.66928e-08 2.97732e-06 3.23482e-08"/>
                        <joint name="right_wrist_roll_joint" class="/" pos="0 0 0" axis="-0.999036 0.0428532 0.00957241" stiffness="0.0582067" range="-0.681629 0.790479" armature="0.145294" damping="0.0937279" frictionloss="0.0339341"/>
                        <geom name="//unnamed_geom_61" class="visual" mesh="right_hand_roll_link"/>
                        <body name="right_hand_pitch_link" pos="-0.0138082 0.000765924 0.00670087" quat="0.999998 0.000795692 -0.00147785 0.000911906">
                          <inertial pos="0.000753883 0.0067767 -0.0426971" quat="0.723068 0.120216 -0.114291 0.670566" mass="0.246103" diaginertia="6.00701e-05 0.00264018 5.07287e-05"/>
                          <joint name="right_wrist_pitch_joint" class="/" pos="0 0 0" axis="-0.0267678 -0.999122 0.0322209" stiffness="0.0177965" range="-0.871658 0.506177" armature="0.170535" damping="0" frictionloss="0.0348192"/>
                          <geom name="//unnamed_geom_62" class="visual" mesh="right_hand_pitch"/>
                          <body name="right_jaw_link" pos="-0.000513192 0.00239153 -0.0681521" quat="0.999999 -0.000439981 0.00150968 0.00030888">
                            <inertial pos="0.00940106 -0.011325 -0.0302471" quat="0.707897 0.0217453 -0.0274892 0.705445" mass="0.0841419" diaginertia="1.36648e-05 0.000554236 1.40004e-05"/>
                            <joint name="right_jaw_joint" class="/" pos="0 0 0" axis="-0.999953 -0.00467974 0.00846442" stiffness="0.00102785" range="0.186734 1.20612" armature="0.0624889" damping="0.0700373" frictionloss="0.109919"/>
                            <geom name="//unnamed_geom_63" class="visual" mesh="right_jaw_link"/>
                            <geom name="//unnamed_geom_64" class="collision" size="0.0386953"/>
                            <geom name="//unnamed_geom_65" class="reward_collision_sphere" size="0.0537435" pos="0 0 -0.0173128"/>
                          </body>
                        </body>
                      </body>
                    </body>
                  </body>
                </body>
              </body>
            </body>
            <body name="head_roll_link" pos="-0.00891672 -0.00840038 0.267355" quat="0.999997 -0.00119772 0.00190259 0.000179462">
              <inertial pos="-0.00194577 -0.00448765 -0.0139957" quat="0.0410175 0.71012 -0.00840067 0.702835" mass="0.0122258" diaginertia="1.30413e-07 4.06157e-06 2.22957e-07"/>
              <joint name="head_roll_joint" class="/" pos="0 0 0" axis="-0.999658 -0.00947736 0.0243681" stiffness="0.000955454" range="-0.541459 0.267413" armature="0.181542" damping="0.0647193" frictionloss="0.10626"/>
              <geom name="//unnamed_geom_66" class="visual" mesh="head_roll_link"/>
              <body name="head_pitch_link" pos="0.0132338 0.000599509 0.00561617" quat="0.999977 0.00494154 -0.000252214 0.00460678">
                <inertial pos="-0.001217 0.00967278 0.0215853" quat="0.667505 0.654038 0.2735 -0.227748" mass="0.0777565" diaginertia="5.01088e-06 0.000239927 9.54872e-06"/>
                <joint name="head_pitch_joint" class="/" pos="0 0 0" axis="-0.00238497 -0.999983 0.00527925" range="-0.828001 0.743292" armature="0.0544917" damping="0.0103039" frictionloss="0.0996209"/>
                <geom name="//unnamed_geom_67" class="visual" mesh="head_pitch_link"/>
                <body name="head_yaw_link" pos="-0.00352031 -0.0120232 0.0467681" quat="0.999995 -0.000360054 -0.000614524 0.00305736">
                  <inertial pos="0.0240871 -0.00403834 0.0828202" quat="0.698317 -0.11798 -0.141186 0.691737" mass="2.05999" diaginertia="0.00230947 0.108307 0.00310126"/>
                  <joint name="head_yaw_joint" class="/" pos="0 0 0" axis="0.00926493 -0.0110575 0.999896" range="-2.51822 2.9401" armature="0.0726774" damping="0.0799571" frictionloss="0.0291773"/>
                  <geom name="//unnamed_geom_68" class="visual" rgba="0.12 0.12 0.12 1" mesh="head_yaw_link"/>
                  <geom name="head_yaw_link.STL" class="collision" size="0.127573" pos="0.0134781 -0.00142714 0.0810413" rgba="0.752941 0.752941 0.752941 1"/>
                  <geom name="//unnamed_geom_70" class="reward_collision_sphere" size="0.107487" pos="0.0221181 0 0.0865639"/>
                  <camera name="ego_camera" class="/" pos="0.0810997 0 0.0952203" quat="-0.5 -0.5 0.5 0.5"/>
                </body>
              </body>
            </body>
          </body>
        </body>
      </body>
    </body>
  </worldbody>

  <contact>
    <pair class="/" geom1="floor" geom2="left_foot" name="//unnamed_contact_0"/>
    <pair class="/" geom1="floor" geom2="right_foot" name="//unnamed_contact_1"/>
  </contact>

  <actuator>
    <general name="left_hip_roll" class="/" joint="left_hip_roll_joint" forcerange="-57.7701 57.7701" gainprm="58.104" biasprm="0 -58.104 -1.2693"/>
    <general name="left_hip_yaw" class="/" joint="left_hip_yaw_joint" forcerange="-71.694 71.694" gainprm="58.104" biasprm="0 -58.104 -1.2693"/>
    <general name="left_hip_pitch" class="/" joint="left_hip_pitch_joint" forcerange="-244.318 244.318" gainprm="58.104" biasprm="0 -58.104 -1.2693"/>
    <general name="left_knee_pitch" class="/" joint="left_knee_pitch_joint" forcerange="-363.637 363.637" gainprm="58.104" biasprm="0 -58.104 -1.2693"/>
    <general name="left_ankle_pitch" class="/" joint="left_ankle_pitch_joint" forcerange="-10.4882 10.4882" gainprm="58.104" biasprm="0 -58.104 -1.2693"/>
    <general name="left_ankle_roll" class="/" joint="left_ankle_roll_joint" forcerange="-28.275 28.275" gainprm="58.104" biasprm="0 -58.104 -1.2693"/>
    <general name="right_hip_roll" class="/" joint="right_hip_roll_joint" forcerange="-74.2706 74.2706" gainprm="58.104" biasprm="0 -58.104 -1.2693"/>
    <general name="right_hip_yaw" class="/" joint="right_hip_yaw_joint" forcerange="-73.2575 73.2575" gainprm="58.104" biasprm="0 -58.104 -1.2693"/>
    <general name="right_hip_pitch" class="/" joint="right_hip_pitch_joint" forcerange="-284.396 284.396" gainprm="58.104" biasprm="0 -58.104 -1.2693"/>
    <general name="right_knee_pitch" class="/" joint="right_knee_pitch_joint" forcerange="-240.809 240.809" gainprm="58.104" biasprm="0 -58.104 -1.2693"/>
    <general name="right_ankle_pitch" class="/" joint="right_ankle_pitch_joint" forcerange="-13.4865 13.4865" gainprm="58.104" biasprm="0 -58.104 -1.2693"/>
    <general name="right_ankle_roll" class="/" joint="right_ankle_roll_joint" forcerange="-35.8421 35.8421" gainprm="58.104" biasprm="0 -58.104 -1.2693"/>
    <general name="waist_yaw" class="/" joint="waist_yaw_joint" forcerange="-78.5974 78.5974" gainprm="58.104" biasprm="0 -58.104 -1.2693"/>
    <general name="waist_pitch" class="/" joint="waist_pitch_joint" forcerange="-65.347 65.347" gainprm="58.104" biasprm="0 -58.104 -1.2693"/>
    <general name="waist_roll" class="/" joint="waist_roll_joint" forcerange="-79.3406 79.3406" gainprm="58.104" biasprm="0 -58.104 -1.2693"/>
    <general name="left_shoulder_pitch" class="/" joint="left_shoulder_pitch_joint" forcerange="-38.9921 38.9921" gainprm="58.104" biasprm="0 -58.104 -1.2693"/>
    <general name="left_shoulder_roll" class="/" joint="left_shoulder_roll_joint" forcerange="-43.3451 43.3451" gainprm="58.104" biasprm="0 -58.104 -1.2693"/>
    <general name="left_shoulder_yaw" class="/" joint="left_shoulder_yaw_joint" forcerange="-20.3511 20.3511" gainprm="58.104" biasprm="0 -58.104 -1.2693"/>
    <general name="left_elbow_pitch" class="/" joint="left_elbow_pitch_joint" forcerange="-14.7508 14.7508" gainprm="58.104" biasprm="0 -58.104 -1.2693"/>
    <general name="left_wrist_yaw" class="/" joint="left_wrist_yaw_joint" forcerange="-5.41214 5.41214" gainprm="58.104" biasprm="0 -58.104 -1.2693"/>
    <general name="left_wrist_roll" class="/" joint="left_wrist_roll_joint" forcerange="-4.31188 4.31188" gainprm="58.104" biasprm="0 -58.104 -1.2693"/>
    <general name="left_wrist_pitch" class="/" joint="left_wrist_pitch_joint" forcerange="-4.08694 4.08694" gainprm="58.104" biasprm="0 -58.104 -1.2693"/>
    <general name="left_jaw" class="/" joint="left_jaw_joint" forcerange="-5.4814 5.4814" gainprm="58.104" biasprm="0 -58.104 -1.2693"/>
    <general name="right_shoulder_pitch" class="/" joint="right_shoulder_pitch_joint" forcerange="-43.9339 43.9339" gainprm="58.104" biasprm="0 -58.104 -1.2693"/>
    <general name="right_shoulder_roll" class="/" joint="right_shoulder_roll_joint" forcerange="-55.7928 55.7928" gainprm="58.104" biasprm="0 -58.104 -1.2693"/>
    <general name="right_shoulder_yaw" class="/" joint="right_shoulder_yaw_joint" forcerange="-33.233 33.233" gainprm="58.104" biasprm="0 -58.104 -1.2693"/>
    <general name="right_elbow_pitch" class="/" joint="right_elbow_pitch_joint" forcerange="-17.2518 17.2518" gainprm="58.104" biasprm="0 -58.104 -1.2693"/>
    <general name="right_wrist_yaw" class="/" joint="right_wrist_yaw_joint" forcerange="-4.96557 4.96557" gainprm="58.104" biasprm="0 -58.104 -1.2693"/>
    <general name="right_wrist_roll" class="/" joint="right_wrist_roll_joint" forcerange="-4.31311 4.31311" gainprm="58.104" biasprm="0 -58.104 -1.2693"/>
    <general name="right_wrist_pitch" class="/" joint="right_wrist_pitch_joint" forcerange="-3.9139 3.9139" gainprm="58.104" biasprm="0 -58.104 -1.2693"/>
    <general name="right_jaw" class="/" joint="right_jaw_joint" forcerange="-2.29828 2.29828" gainprm="58.104" biasprm="0 -58.104 -1.2693"/>
    <general name="head_roll" class="/" joint="head_roll_joint" forcerange="-3.7926 3.7926" gainprm="58.104" biasprm="0 -58.104 -1.2693"/>
    <general name="head_pitch" class="/" joint="head_pitch_joint" forcerange="-5.43437 5.43437" gainprm="58.104" biasprm="0 -58.104 -1.2693"/>
    <general name="head_yaw" class="/" joint="head_yaw_joint" forcerange="-6.70432 6.70432" gainprm="58.104" biasprm="0 -58.104 -1.2693"/>
  </actuator>

  <sensor>
    <gyro site="imu" name="imu_angular_velocity"/>
    <velocimeter site="imu" name="imu_linear_velocity"/>
    <framelinvel objtype="site" objname="left_foot" name="left_foot_global_linear_velocity"/>
    <framelinvel objtype="site" objname="right_foot" name="right_foot_global_linear_velocity"/>
  </sensor>

  <keyframe>
    <key name="home" qpos="0 0 0.8665 1 0 0 0 0 0 -0.4 0.8 -0.4 0 0 0 0.4 -0.8 0.4 0 0 0 0 0 -0.2 0 -0.785 0 0 0 0 0 0.2 0 0.785 0 0 0 0 0 0 0"/>
  </keyframe>
</mujoco>
