<mujoco model="GR1T2_jaw">
  <compiler angle="radian" assetdir="assets" balanceinertia="true" inertiafromgeom="false"/>

  <option timestep="0.005" density="1.2" viscosity="2e-05"/>

  <size nkey="1"/>

  <visual>
    <quality shadowsize="8192"/>
    <map shadowclip="0.5"/>
  </visual>

  <default>
    <default class="/">
      <joint armature="0.1" damping="0.01" frictionloss="0.1"/>
      <geom contype="0" conaffinity="0" group="1" solref="-1000 -80"/>
      <site size="0.01 0.005 0.005" group="5"/>
      <general forcelimited="true" biastype="affine" gainprm="80" biasprm="0 -80 -2"/>
      <default class="visual">
        <geom type="mesh" density="0" rgba="0.18 0.18 0.18 1"/>
      </default>
      <default class="collision">
        <geom group="3"/>
      </default>
      <default class="foot">
        <geom size="0.126 0.045 0.01" type="box" condim="6" group="4" priority="1" solimp="0.015 1 0.01"/>
      </default>
      <default class="reward_collision_sphere">
        <geom group="5" rgba="1 0 0 1"/>
      </default>
    </default>
  </default>

  <asset>
    <texture type="skybox" colorspace="auto" name="//unnamed_texture_0" builtin="gradient" rgb1="0.95 0.95 0.95" rgb2="0.95 0.95 0.95" width="100" height="600"/>
    <texture type="2d" colorspace="auto" name="texplane" builtin="checker" rgb1="0.345 0.575 0.748" rgb2="0.345 0.575 0.748" markrgb="1 1 1" width="512" height="512"/>
    <material name="MatPlane" class="/" texture="texplane" texuniform="true" texrepeat="2 2" specular="0.9"/>
    <mesh name="base_link" class="/" file="base_link.STL"/>
    <mesh name="left_thigh_roll_link" class="/" file="left_thigh_roll_link.STL"/>
    <mesh name="left_thigh_yaw_link" class="/" file="left_thigh_yaw_link.STL"/>
    <mesh name="left_thigh_pitch_link" class="/" file="left_thigh_pitch_link.STL"/>
    <mesh name="left_shank_pitch_link" class="/" file="left_shank_pitch_link.STL"/>
    <mesh name="left_foot_pitch_link" class="/" file="left_foot_pitch_link.STL"/>
    <mesh name="left_foot_roll_link" class="/" file="left_foot_roll_link.STL"/>
    <mesh name="right_thigh_roll_link" class="/" file="right_thigh_roll_link.STL"/>
    <mesh name="right_thigh_yaw_link" class="/" file="right_thigh_yaw_link.STL"/>
    <mesh name="right_thigh_pitch_link" class="/" file="right_thigh_pitch_link.STL"/>
    <mesh name="right_shank_pitch_link" class="/" file="right_shank_pitch_link.STL"/>
    <mesh name="right_foot_pitch_link" class="/" file="right_foot_pitch_link.STL"/>
    <mesh name="right_foot_roll_link" class="/" file="right_foot_roll_link.STL"/>
    <mesh name="waist_yaw_link" class="/" file="waist_yaw_link.STL"/>
    <mesh name="waist_pitch_link" class="/" file="waist_pitch_link.STL"/>
    <mesh name="waist_roll_link" class="/" file="waist_roll_link.STL"/>
    <mesh name="torso_link" class="/" file="torso_link.STL"/>
    <mesh name="left_upper_arm_pitch_link" class="/" file="left_upper_arm_pitch_link.STL"/>
    <mesh name="left_upper_arm_roll_link" class="/" file="left_upper_arm_roll_link.STL"/>
    <mesh name="left_upper_arm_yaw_link" class="/" file="left_upper_arm_yaw_link.STL"/>
    <mesh name="left_lower_arm_pitch_link" class="/" file="left_lower_arm_pitch_link.STL"/>
    <mesh name="left_hand_yaw_link" class="/" file="left_hand_yaw_link.STL"/>
    <mesh name="left_hand_roll_link" class="/" file="left_hand_roll_link.STL"/>
    <mesh name="left_hand_pitch" class="/" file="left_hand_pitch.STL"/>
    <mesh name="left_jaw_link" class="/" file="left_jaw_link.STL"/>
    <mesh name="right_upper_arm_pitch_link" class="/" file="right_upper_arm_pitch_link.STL"/>
    <mesh name="right_upper_arm_roll_link" class="/" file="right_upper_arm_roll_link.STL"/>
    <mesh name="right_upper_arm_yaw_link" class="/" file="right_upper_arm_yaw_link.STL"/>
    <mesh name="right_lower_arm_pitch_link" class="/" file="right_lower_arm_pitch_link.STL"/>
    <mesh name="right_hand_yaw_link" class="/" file="right_hand_yaw_link.STL"/>
    <mesh name="right_hand_roll_link" class="/" file="right_hand_roll_link.STL"/>
    <mesh name="right_hand_pitch" class="/" file="right_hand_pitch.STL"/>
    <mesh name="right_jaw_link" class="/" file="right_jaw_link.STL"/>
    <mesh name="head_roll_link" class="/" file="head_roll_link.STL"/>
    <mesh name="head_pitch_link" class="/" file="head_pitch_link.STL"/>
    <mesh name="head_yaw_link" class="/" file="head_yaw_link.STL"/>
    <mesh name="imu_link" class="/" file="imu_link.STL"/>
  </asset>

  <worldbody>
    <geom name="floor" class="/" size="100 100 0.125" type="plane" group="0" material="MatPlane"/>
    <light name="toplight_shadow" class="/" pos="0 0 5" dir="0.0990148 0.0990148 -0.990148" type="directional" ambient="0.04 0.04 0.04" diffuse="0.55 0.55 0.55" specular="0.12 0.12 0.12"/>
    <light name="toplight_fill" class="/" pos="0 0 5" dir="0.0990148 0.0990148 -0.990148" type="directional" castshadow="false" ambient="0.04 0.04 0.04" diffuse="0.3 0.3 0.3" specular="0.08 0.08 0.08"/>
    <body name="trunk" pos="0.00101599 0.0027349 -0.000328874" quat="1 -2.42234e-05 -2.4301e-06 -6.87872e-06">
      <inertial pos="-0.0613403 0.00415446 -0.00768763" quat="0.999998 0.000678946 -0.000401247 0.00160056" mass="2.7626" diaginertia="0.0504821 0.00966299 0.00757284"/>
      <joint name="//unnamed_joint_0" type="free"/>
      <geom name="//unnamed_geom_1" class="visual" rgba="0.12 0.12 0.12 1" mesh="base_link"/>
      <geom name="base_link.STL" class="collision" size="0.109132 0.0611228" pos="-0.0442528 0.000344648 0.00648715" quat="0.706838 -0.707359 0.00477667 0" type="cylinder" rgba="0.752941 0.752941 0.752941 1"/>
      <geom name="//unnamed_geom_3" class="visual" pos="0 0 -0.0419794" quat="1 0 0 0" rgba="0.12 0.12 0.12 1" mesh="imu_link"/>
      <geom name="//unnamed_geom_4" class="reward_collision_sphere" size="0.0713319" pos="0 0.0931376 0.0704352"/>
      <geom name="//unnamed_geom_5" class="reward_collision_sphere" size="0.0713319" pos="0 -0.0931376 0.0704352"/>
      <site name="imu" class="/" pos="-0.0133476 -0.013487 -0.0555107" size="0.00891648"/>
      <camera name="track" class="/" pos="0 -1.86275 0" quat="0.707107 0.707107 0 0" mode="trackcom"/>
      <body name="left_thigh_roll_link" pos="-0.0362221 0.098093 -0.0192546" quat="1 -7.01023e-05 0.000926081 -8.53266e-05">
        <inertial pos="-0.000689592 0.00066118 0.00140747" quat="-0.0424481 0.701026 -0.0301509 0.711232" mass="1.04586" diaginertia="0.00300116 0.00172114 0.000265023"/>
        <joint name="left_hip_roll_joint" class="/" pos="0 0 0" axis="-0.999909 -0.00751323 0.0112144" range="-0.777494 0.0940215" armature="0.0930341" damping="0.012486" frictionloss="0.0872504"/>
        <geom name="//unnamed_geom_6" class="visual" mesh="left_thigh_roll_link"/>
        <body name="left_thigh_yaw_link" pos="0.0296086 0.000912071 0.00295054" quat="0.999999 -0.000700168 0.0010342 0.000761165">
          <inertial pos="-0.0060407 0.0327243 -0.0771679" quat="0.568843 0.0980175 -0.189629 0.794262" mass="2.39234" diaginertia="0.0285665 0.0138854 0.00153501"/>
          <joint name="left_hip_yaw_joint" class="/" pos="0 0 0" axis="0.00226711 0.0020304 -0.999995" range="-0.659347 0.644131" armature="0.103673" damping="0.0120517" frictionloss="0.101195"/>
          <geom name="//unnamed_geom_7" class="visual" mesh="left_thigh_yaw_link"/>
          <body name="left_thigh_pitch_link" pos="-0.00328122 0.0220591 -0.0985462" quat="0.999999 -0.000500899 -0.00100865 0.000977554">
            <inertial pos="-0.000641647 -0.0290903 -0.0433777" quat="0.999774 -0.0182103 -0.00922693 0.00596565" mass="5.97862" diaginertia="0.111157 0.0623052 0.00474401"/>
            <joint name="left_hip_pitch_joint" class="/" pos="0 0 0" axis="0.00427238 0.999991 0.000457905" range="-1.78515 0.680025" armature="0.0898942" damping="0" frictionloss="0.0853466"/>
            <geom name="//unnamed_geom_8" class="visual" mesh="left_thigh_pitch_link"/>
            <geom name="left_thigh_pitch_link.STL" class="collision" size="0.0731152 0.111379" pos="0.000727504 -0.0279413 -0.117666" type="cylinder" rgba="0.752941 0.752941 0.752941 1"/>
            <geom name="//unnamed_geom_10" class="reward_collision_sphere" size="0.0891648" pos="0 -0.00931376 -0.0352176"/>
            <body name="left_shank_pitch_link" pos="-0.00364513 -0.0167719 -0.251618" quat="1 -4.59734e-05 1.25556e-05 0.000262263">
              <inertial pos="-0.000473991 -0.00119465 -0.0833823" quat="0.99972 -0.00840456 0.00665138 -0.0210862" mass="1.21033" diaginertia="0.0130301 0.00746451 0.000218017"/>
              <joint name="left_knee_pitch_joint" class="/" pos="0 0 0" axis="0.00452945 0.999983 0.00369263" range="-0.0452226 1.91203" armature="0.0910445" damping="0.0220044" frictionloss="0.0788564"/>
              <geom name="//unnamed_geom_11" class="visual" mesh="left_shank_pitch_link"/>
              <geom name="left_shank_pitch_link.STL" class="collision" size="0.0475439 0.0805916" pos="-1.72407e-05 -0.000784728 -0.123044" quat="0.00125538 -0.202712 0.979238 0" type="cylinder" rgba="0.752941 0.752941 0.752941 1"/>
              <geom name="//unnamed_geom_13" class="reward_collision_sphere" size="0.0445824"/>
              <geom name="//unnamed_geom_14" class="reward_collision_sphere" size="0.0534989" pos="0 0 -0.0774788"/>
              <body name="left_foot_pitch_link" pos="-0.000485357 -0.00212711 -0.237804" quat="1 7.53839e-06 0.000119738 4.08537e-05">
                <inertial pos="0.00193378 -0.00067946 0.00158997" quat="0.000269092 0.705877 0.0135765 0.708204" mass="0.0429973" diaginertia="8.1496e-06 4.07214e-06 9.19837e-07"/>
                <joint name="left_ankle_pitch_joint" class="/" pos="0 0 0" axis="0.0121199 0.9999 -0.00721808" stiffness="0.00104339" range="-1.07977 0.514926" armature="0.0918617" damping="0.00463183" frictionloss="0.0898141"/>
                <geom name="//unnamed_geom_15" class="visual" mesh="left_foot_pitch_link"/>
                <body name="left_foot_roll_link" pos="-0.00278791 -0.000257781 0.00253048" quat="1 -0.00032727 -0.000277278 -0.00011484">
                  <inertial pos="0.0364364 0.00170128 -0.0242953" quat="-0.00102921 0.724717 -0.0017816 0.689043" mass="0.760829" diaginertia="0.00684365 0.00355358 0.000130931"/>
                  <joint name="left_ankle_roll_joint" class="/" pos="0 0 0" axis="-0.999773 0.00108144 -0.0212607" range="-0.452153 0.470366" armature="0.0861972" damping="0" frictionloss="0.0908436"/>
                  <geom name="//unnamed_geom_16" class="visual" mesh="left_foot_roll_link"/>
                  <geom name="left_foot" class="foot" size="0.152834 0.04344 0.00987086" pos="0.0467647 0 -0.0313437"/>
                  <geom name="//unnamed_geom_18" class="reward_collision_sphere" size="0.0445824" pos="0 0 -0.0211306"/>
                  <geom name="//unnamed_geom_19" class="reward_collision_sphere" size="0.0445824" pos="0.124706 0 -0.0211306"/>
                  <site name="left_foot" class="foot" pos="0.0467647 0 -0.0313437" size="0.00891648"/>
                </body>
              </body>
            </body>
          </body>
        </body>
      </body>
      <body name="right_thigh_roll_link" pos="-0.0363475 -0.103772 -0.0212909" quat="0.999999 -0.000131293 0.00125942 -0.00032524">
        <inertial pos="0.00333066 -0.00340431 0.00279072" quat="0.0269206 0.705613 0.0169631 0.707882" mass="1.04099" diaginertia="0.00303938 0.00175339 0.000271643"/>
        <joint name="right_hip_roll_joint" class="/" pos="0 0 0" axis="-0.999999 -0.00145424 -0.000510877" range="-0.114363 0.814785" armature="0.0829629" damping="0.0194317" frictionloss="0.0931324"/>
        <geom name="//unnamed_geom_20" class="visual" mesh="right_thigh_roll_link"/>
        <body name="right_thigh_yaw_link" pos="0.0320909 -2.14521e-05 0.00188559" quat="1 0.000248928 8.22559e-05 6.37096e-05">
          <inertial pos="-0.00123537 -0.0332672 -0.0764672" quat="0.684984 -0.147907 0.151062 0.697209" mass="2.45533" diaginertia="0.0289014 0.0131712 0.00159768"/>
          <joint name="right_hip_yaw_joint" class="/" pos="0 0 0" axis="0.00508823 0.00102963 -0.999987" range="-0.715021 0.72527" armature="0.0923437" damping="0.0200295" frictionloss="0.0794663"/>
          <geom name="//unnamed_geom_21" class="visual" mesh="right_thigh_yaw_link"/>
          <body name="right_thigh_pitch_link" pos="-0.00282492 -0.022523 -0.0986857" quat="1 0.000100387 -0.00011587 -0.000187208">
            <inertial pos="0.00122617 0.024301 -0.0450018" quat="0.999805 -0.0146271 -0.011306 0.00693746" mass="5.93206" diaginertia="0.112238 0.0639029 0.00474814"/>
            <joint name="right_hip_pitch_joint" class="/" pos="0 0 0" axis="-0.00424178 -0.999985 -0.00349466" range="-0.679279 1.75381" armature="0.0870608" damping="0.0340396" frictionloss="0.101147"/>
            <geom name="//unnamed_geom_22" class="visual" mesh="right_thigh_pitch_link"/>
            <geom name="right_thigh_pitch_link.STL" class="collision" size="0.0731152 0.111377" pos="-0.00220654 0.0279413 -0.117666" quat="0.999971 0.00269833 0.00706272 0" type="cylinder" rgba="0.752941 0.752941 0.752941 1"/>
            <geom name="//unnamed_geom_24" class="reward_collision_sphere" size="0.0891648" pos="0 0.00931376 -0.0352176"/>
            <body name="right_shank_pitch_link" pos="-0.00115484 0.0138729 -0.252954" quat="1 -0.000212868 0.000288839 -3.81517e-05">
              <inertial pos="-0.0013317 1.53377e-05 -0.0812443" quat="0.999639 0.00833126 0.00639355 0.0247157" mass="1.26535" diaginertia="0.0134487 0.00780099 0.000218205"/>
              <joint name="right_knee_pitch_joint" class="/" pos="0 0 0" axis="0.0039363 -0.999977 0.00556349" range="-1.9096 0.0924657" armature="0.0805226" damping="0.0193989" frictionloss="0.0891074"/>
              <geom name="//unnamed_geom_25" class="visual" mesh="right_shank_pitch_link"/>
              <geom name="right_shank_pitch_link.STL" class="collision" size="0.0475437 0.0805908" pos="-1.72407e-05 -0.000784738 -0.12305" type="cylinder" rgba="0.752941 0.752941 0.752941 1"/>
              <geom name="//unnamed_geom_27" class="reward_collision_sphere" size="0.0445824"/>
              <geom name="//unnamed_geom_28" class="reward_collision_sphere" size="0.0534989" pos="0 0 -0.0774788"/>
              <body name="right_foot_pitch_link" pos="-0.00186315 -0.000754221 -0.239042" quat="0.999999 5.39202e-05 -0.000772998 -0.000692747">
                <inertial pos="-0.00195618 -0.00248358 0.000554053" quat="0.0124946 0.705593 -0.00511417 0.708488" mass="0.0393494" diaginertia="7.66206e-06 3.71103e-06 9.07227e-07"/>
                <joint name="right_ankle_pitch_joint" class="/" pos="0 0 0" axis="-0.00271221 -0.999996 7.87e-05" range="-0.530815 1.06275" armature="0.0930031" damping="0.00468032" frictionloss="0.100316"/>
                <geom name="//unnamed_geom_29" class="visual" mesh="right_foot_pitch_link"/>
                <body name="right_foot_roll_link" pos="-0.00143022 0.00160672 0.00104584" quat="1 0.000241487 0.000167627 6.32865e-05">
                  <inertial pos="0.0412748 -0.00172342 -0.0267882" quat="-0.00330299 0.72268 -0.00751401 0.691134" mass="0.757627" diaginertia="0.00697986 0.00357909 0.000131444"/>
                  <joint name="right_ankle_roll_joint" class="/" pos="0 0 0" axis="-0.999983 0.00542209 0.00192426" range="-0.503262 0.453722" armature="0.0932817" damping="0" frictionloss="0.0868533"/>
                  <geom name="//unnamed_geom_30" class="visual" mesh="right_foot_roll_link"/>
                  <geom name="right_foot" class="foot" size="0.151184 0.0409536 0.00889942" pos="0.0467647 0 -0.0313437"/>
                  <geom name="//unnamed_geom_32" class="reward_collision_sphere" size="0.0445824" pos="0 0 -0.0211306"/>
                  <geom name="//unnamed_geom_33" class="reward_collision_sphere" size="0.0445824" pos="0.124706 0 -0.0211306"/>
                  <site name="right_foot" class="foot" pos="0.0467647 0 -0.0313437" size="0.00891648"/>
                </body>
              </body>
            </body>
          </body>
        </body>
      </body>
      <body name="waist_yaw_link" pos="0.00602809 0.00256482 0.00485152" quat="1 -2.13247e-06 5.39055e-05 4.32021e-05">
        <inertial pos="-0.00239946 -0.00736177 0.0368487" quat="0.97997 0.188087 -0.0285169 0.058904" mass="1.1735" diaginertia="0.00439644 0.00225957 0.000375438"/>
        <joint name="waist_yaw_joint" class="/" pos="0 0 0" axis="0.00111731 -0.000271342 0.999999" range="-1.08281 1.00742" armature="0.0894592" damping="4.40213e-05" frictionloss="0.0866548"/>
        <geom name="//unnamed_geom_34" class="visual" rgba="0.12 0.12 0.12 1" mesh="waist_yaw_link"/>
        <body name="waist_pitch_link" pos="0.00283766 0.00109504 0.0633953" quat="0.999999 -0.0004393 -5.20916e-05 0.000923917">
          <inertial pos="0.00311132 -0.00106854 0.0329532" quat="0.997664 -0.0477035 0.0479044 0.00977381" mass="1.08894" diaginertia="0.00549102 0.00318085 0.000319032"/>
          <joint name="waist_pitch_joint" class="/" pos="0 0 0" axis="0.0390637 -0.999236 -0.00103914" range="-1.15191 0.487628" armature="0.0865766" damping="0.000928976" frictionloss="0.0973437"/>
          <geom name="//unnamed_geom_35" class="visual" rgba="0.12 0.12 0.12 1" mesh="waist_pitch_link"/>
          <body name="waist_roll_link" pos="0.0100537 -0.000641178 0.0591226" quat="1 -0.000361764 -0.00049805 5.45813e-05">
            <inertial pos="-0.0162195 0.00341443 0.103383" quat="0.99856 0.00274155 -0.0533122 -0.00529606" mass="4.7369" diaginertia="0.0763825 0.0412925 0.0061202"/>
            <joint name="waist_roll_joint" class="/" pos="0 0 0" axis="-0.999977 -0.00234472 -0.0064044" range="-0.679236 0.692351" armature="0.0852516" damping="0.0205986" frictionloss="0.0854033"/>
            <geom name="//unnamed_geom_36" class="visual" rgba="0.12 0.12 0.12 1" mesh="waist_roll_link"/>
            <geom name="//unnamed_geom_37" class="visual" pos="-0.00233824 0.000535011 0.112943" quat="1 0 0 0" mesh="torso_link"/>
            <geom name="torso_link.STL" class="collision" size="0.14037 0.0269215" pos="-0.0187744 0.00537386 0.104124" type="cylinder" rgba="0.752941 0.752941 0.752941 1"/>
            <geom name="//unnamed_geom_39" class="reward_collision_sphere" size="0.115914" pos="0 0 0.14087"/>
            <body name="left_upper_arm_pitch_link" pos="0.00155289 0.0920737 0.147716" quat="0.976601 0.215057 -0.000398735 0.00114267">
              <inertial pos="0.00432283 0.046603 -0.00204021" quat="0.704383 0.707838 0.0035663 -0.0528905" mass="0.584965" diaginertia="0.00242548 0.00139708 8.81304e-05"/>
              <joint name="left_shoulder_pitch_joint" class="/" pos="0 0 0" axis="0.00117133 0.999999 -0.000981158" range="-2.83544 1.87417" armature="0.0896792" damping="0.00481503" frictionloss="0.101271"/>
              <geom name="//unnamed_geom_40" class="visual" mesh="left_upper_arm_pitch_link"/>
              <body name="left_upper_arm_roll_link" pos="0.00134264 0.0876703 0.0010624" quat="0.976628 -0.214937 0.000277106 0.000150986">
                <inertial pos="0.00492711 0.0138776 -0.0174018" quat="0.888378 0.276295 0.125199 -0.344632" mass="0.417898" diaginertia="0.00124778 0.000702386 5.86353e-05"/>
                <joint name="left_shoulder_roll_joint" class="/" pos="0 0 0" axis="-0.999974 0.00495408 0.00529564" stiffness="0.00167938" range="-2.4748 0.630157" armature="0.0862974" damping="0.00484793" frictionloss="0.0858598"/>
                <geom name="//unnamed_geom_41" class="visual" mesh="left_upper_arm_roll_link"/>
                <body name="left_upper_arm_yaw_link" pos="0.00231801 0.0364415 -0.048666" quat="1 -0.000484161 0.0003911 -3.61589e-05">
                  <inertial pos="0.0026374 -0.00302705 -0.061669" quat="0.999951 0.000463138 -0.00641952 -0.00746993" mass="0.405816" diaginertia="0.00456406 0.00258132 4.6604e-05"/>
                  <joint name="left_shoulder_yaw_joint" class="/" pos="0 0 0" axis="-0.000143361 7.71433e-05 1" range="-2.9971 3.02567" armature="0.0952105" damping="0.00756672" frictionloss="0.097891"/>
                  <geom name="//unnamed_geom_42" class="visual" mesh="left_upper_arm_yaw_link"/>
                  <geom name="left_upper_arm_yaw_link.STL" class="collision" size="0.0323073 0.0757384" pos="4.10339e-05 -0.000832921 -0.0558833" quat="0.00803418 -0.995528 0.0941277 0" type="cylinder" rgba="0.752941 0.752941 0.752941 1"/>
                  <body name="left_lower_arm_pitch_link" pos="0.00125932 -0.00179759 -0.12421" quat="1 0.000574157 0.00034743 -3.88218e-05">
                    <inertial pos="0.00251489 0.00726912 -0.0162412" quat="0.701004 -0.0935894 0.0915693 0.701034" mass="0.232731" diaginertia="0.000351848 0.000208221 1.7048e-05"/>
                    <joint name="left_elbow_pitch_joint" class="/" pos="0 0 0" axis="-0.00847474 0.999906 0.0107634" range="-2.30966 2.28077" armature="0.0936627" damping="0.00259339" frictionloss="0.0982712"/>
                    <geom name="//unnamed_geom_44" class="visual" mesh="left_lower_arm_pitch_link"/>
                    <body name="left_hand_yaw_link" pos="0.000617324 -0.0014563 -0.0447769" quat="0.999999 -0.000937719 0.000888508 -0.000409713">
                      <inertial pos="0.00301628 -0.00141051 -0.0519468" quat="0.99996 -0.00670562 0.00170056 0.00560212" mass="0.696151" diaginertia="0.00312441 0.00176663 8.82678e-05"/>
                      <joint name="left_wrist_yaw_joint" class="/" pos="0 0 0" axis="-0.000711119 0.000604066 1" range="-2.94986 2.92394" armature="0.102606" damping="0.00792917" frictionloss="0.0865011"/>
                      <geom name="//unnamed_geom_45" class="visual" mesh="left_hand_yaw_link"/>
                      <geom name="left_hand_yaw_link.STL" class="collision" size="0.0370675 0.0620531" pos="0.00113197 -0.00143535 -0.053561" type="cylinder" rgba="0.752941 0.752941 0.752941 1"/>
                      <geom name="//unnamed_geom_47" class="reward_collision_sphere" size="0.0445824"/>
                      <body name="left_hand_roll_link" pos="0.000757214 -0.00164963 -0.1365" quat="1 8.31766e-05 -0.000240259 0.000133099">
                        <inertial pos="3.13979e-05 -0.000955813 -0.00293006" quat="0.498137 0.500041 0.499899 0.501917" mass="0.00376141" diaginertia="4.51966e-07 2.56865e-07 1.20948e-08"/>
                        <joint name="left_wrist_roll_joint" class="/" pos="0 0 0" axis="-0.999966 0.00804773 -0.00201065" range="-0.936428 0.88041" armature="0.0937856" damping="0" frictionloss="0.0959907"/>
                        <geom name="//unnamed_geom_48" class="visual" mesh="left_hand_roll_link"/>
                        <body name="left_hand_pitch_link" pos="0.0012998 -0.000535878 -0.00281862" quat="1 -0.000181173 -0.000196828 0.000140889">
                          <inertial pos="-3.47683e-05 -0.0112264 -0.0381608" quat="0.722915 -0.125711 0.115719 0.669478" mass="0.157212" diaginertia="0.000356655 0.000188292 1.65487e-05"/>
                          <joint name="left_wrist_pitch_joint" class="/" pos="0 0 0" axis="-0.00485242 0.999986 -0.00211707" range="-0.598681 0.562559" armature="0.100528" damping="0" frictionloss="0.0768906"/>
                          <geom name="//unnamed_geom_49" class="visual" mesh="left_hand_pitch"/>
                          <body name="left_jaw_link" pos="-0.000944823 -0.002013 -0.0436056" quat="0.999999 -0.000341573 -0.0010942 -0.000740125">
                            <inertial pos="3.19217e-05 0.00258173 -0.0272524" quat="0.707521 -0.0246175 0.0330372 0.705491" mass="0.051477" diaginertia="9.74306e-05 3.94592e-05 5.548e-06"/>
                            <joint name="left_jaw_joint" class="/" pos="0 0 0" axis="-0.999958 0.00520823 -0.00754305" range="-0.969785 -0.00863665" armature="0.0896709" damping="0.0119796" frictionloss="0.0888007"/>
                            <geom name="//unnamed_geom_50" class="visual" mesh="left_jaw_link"/>
                            <geom name="//unnamed_geom_51" class="collision" size="0.0320993"/>
                            <geom name="//unnamed_geom_52" class="reward_collision_sphere" size="0.0445824" pos="0 0 -0.014087"/>
                          </body>
                        </body>
                      </body>
                    </body>
                  </body>
                </body>
              </body>
            </body>
            <body name="right_upper_arm_pitch_link" pos="-0.00139084 -0.0917642 0.14783" quat="0.976717 -0.214531 6.57149e-06 9.87669e-05">
              <inertial pos="0.00413135 -0.0474331 -0.0025027" quat="0.705799 0.707384 0.0290512 0.0247295" mass="0.585755" diaginertia="0.00250561 0.00134751 8.54771e-05"/>
              <joint name="right_shoulder_pitch_joint" class="/" pos="0 0 0" axis="-0.0089686 -0.99989 -0.0117846" range="-1.97199 2.80646" armature="0.0907764" damping="0.00106717" frictionloss="0.10111"/>
              <geom name="//unnamed_geom_53" class="visual" mesh="right_upper_arm_pitch_link"/>
              <body name="right_upper_arm_roll_link" pos="0.0021823 -0.0862105 0.00118748" quat="0.976677 0.214716 1.83349e-05 9.16904e-06">
                <inertial pos="0.00457896 -0.0193556 -0.0181299" quat="0.889648 -0.268385 0.123505 0.3482" mass="0.433246" diaginertia="0.00120511 0.000691448 6.00212e-05"/>
                <joint name="right_shoulder_roll_joint" class="/" pos="0 0 0" axis="-0.999854 -0.00346056 0.0167304" range="-0.558734 2.59759" armature="0.0920908" damping="0.0128314" frictionloss="0.0978011"/>
                <geom name="//unnamed_geom_54" class="visual" mesh="right_upper_arm_roll_link"/>
                <body name="right_upper_arm_yaw_link" pos="-0.00229301 -0.0393559 -0.0513387" quat="1 0.000476726 2.75613e-05 -0.000321461">
                  <inertial pos="0.000568068 -0.00324601 -0.0593855" quat="0.99993 0.000639499 -0.00844382 0.00820863" mass="0.382483" diaginertia="0.00435439 0.00251575 4.49795e-05"/>
                  <joint name="right_shoulder_yaw_joint" class="/" pos="0 0 0" axis="-0.0103535 -0.000762475 0.999946" range="-2.99776 2.98564" armature="0.090401" damping="0.00257163" frictionloss="0.0768903"/>
                  <geom name="//unnamed_geom_55" class="visual" mesh="right_upper_arm_yaw_link"/>
                  <geom name="right_upper_arm_yaw_link.STL" class="collision" size="0.0323073 0.0757384" pos="4.10339e-05 0.000832921 -0.0558833" type="cylinder" rgba="0.752941 0.752941 0.752941 1"/>
                  <body name="right_lower_arm_pitch_link" pos="0.00120045 0.00165222 -0.122127" quat="1 1.78395e-05 -1.79321e-05 -8.54804e-06">
                    <inertial pos="-0.000976172 -0.00890053 -0.0197272" quat="0.701175 0.0890903 -0.0883787 0.701859" mass="0.240337" diaginertia="0.000370861 0.000205382 1.64804e-05"/>
                    <joint name="right_elbow_pitch_joint" class="/" pos="0 0 0" axis="0.00214457 -0.999991 -0.00363066" range="-2.31623 2.25986" armature="0.0790465" damping="0.0175202" frictionloss="0.0903833"/>
                    <geom name="//unnamed_geom_57" class="visual" mesh="right_lower_arm_pitch_link"/>
                    <body name="right_hand_yaw_link" pos="0.00155868 -0.00259915 -0.0437857" quat="0.999999 0.00125868 -2.55516e-05 -0.000298064">
                      <inertial pos="0.000122018 -0.00243529 -0.0484843" quat="0.999657 0.00841703 -0.000474575 0.0247772" mass="0.713912" diaginertia="0.00312643 0.00176052 8.68948e-05"/>
                      <joint name="right_wrist_yaw_joint" class="/" pos="0 0 0" axis="1.24883e-05 3.97318e-05 1" range="-3.022 2.98655" armature="0.104269" damping="0.0124393" frictionloss="0.0893757"/>
                      <geom name="//unnamed_geom_58" class="visual" mesh="right_hand_yaw_link"/>
                      <geom name="right_hand_yaw_link.STL" class="collision" size="0.0370675 0.0620531" pos="0.00113197 0.000597118 -0.053561" type="cylinder" rgba="0.752941 0.752941 0.752941 1"/>
                      <geom name="//unnamed_geom_60" class="reward_collision_sphere" size="0.0445824"/>
                      <body name="right_hand_roll_link" pos="0.00102243 0.000581052 -0.134993" quat="0.999999 0.000951056 0.000650234 -0.000552791">
                        <inertial pos="-0.000976593 -0.00251045 -0.000388138" quat="0.500774 0.494723 0.499642 0.504809" mass="0.0035982" diaginertia="4.50017e-07 2.58816e-07 1.23447e-08"/>
                        <joint name="right_wrist_roll_joint" class="/" pos="0 0 0" axis="-0.999943 -0.0105534 -0.00175155" range="-0.905172 0.996528" armature="0.092964" damping="0" frictionloss="0.101282"/>
                        <geom name="//unnamed_geom_61" class="visual" mesh="right_hand_roll_link"/>
                        <body name="right_hand_pitch_link" pos="0.00294109 0.00174654 0.000524404" quat="1 0.000168056 -0.000175275 -0.000355353">
                          <inertial pos="0.000106435 0.0110376 -0.0364728" quat="0.722427 0.119234 -0.115527 0.67122" mass="0.151584" diaginertia="0.000344204 0.00018745 1.55467e-05"/>
                          <joint name="right_wrist_pitch_joint" class="/" pos="0 0 0" axis="-0.00269138 -0.999988 0.00405646" range="-0.563927 0.612238" armature="0.0792637" damping="0.00241949" frictionloss="0.101375"/>
                          <geom name="//unnamed_geom_62" class="visual" mesh="right_hand_pitch"/>
                          <body name="right_jaw_link" pos="-0.000322797 0.00102977 -0.0400388" quat="1 0.000100725 0.000137036 0.000499646">
                            <inertial pos="-0.00258068 -0.00638374 -0.0237734" quat="0.707745 0.0215571 -0.0305393 0.705478" mass="0.0494397" diaginertia="9.8593e-05 4.09761e-05 5.88002e-06"/>
                            <joint name="right_jaw_joint" class="/" pos="0 0 0" axis="-0.999999 -0.00132579 -0.000553923" range="-0.0397098 0.971737" armature="0.0974818" damping="0" frictionloss="0.0898527"/>
                            <geom name="//unnamed_geom_63" class="visual" mesh="right_jaw_link"/>
                            <geom name="//unnamed_geom_64" class="collision" size="0.0320993"/>
                            <geom name="//unnamed_geom_65" class="reward_collision_sphere" size="0.0445824" pos="0 0 -0.014087"/>
                          </body>
                        </body>
                      </body>
                    </body>
                  </body>
                </body>
              </body>
            </body>
            <body name="head_roll_link" pos="0.00109479 0.00282875 0.215185" quat="1 -1.92022e-05 6.9329e-05 -7.20591e-05">
              <inertial pos="0.00426413 -0.00180575 0.00255792" quat="0.00189511 0.710501 0.00385486 0.703683" mass="0.00703007" diaginertia="9.00466e-07 3.18443e-07 7.40871e-08"/>
              <joint name="head_roll_joint" class="/" pos="0 0 0" axis="-0.999995 -0.0029884 0.00125431" range="-0.318411 0.346566" armature="0.0796675" damping="0" frictionloss="0.0916205"/>
              <geom name="//unnamed_geom_66" class="visual" mesh="head_roll_link"/>
              <body name="head_pitch_link" pos="-0.00330916 -0.000132115 0.00117187" quat="0.999999 -0.00104127 0.000680592 -0.000406422">
                <inertial pos="-0.000568707 -0.00239773 0.0129319" quat="0.666068 0.66265 0.24312 -0.241122" mass="0.04306" diaginertia="3.2721e-05 1.67799e-05 2.87968e-06"/>
                <joint name="head_pitch_joint" class="/" pos="0 0 0" axis="-0.00453895 -0.999967 0.0067287" range="-0.854847 0.873373" armature="0.0998749" damping="0.00957794" frictionloss="0.088716"/>
                <geom name="//unnamed_geom_67" class="visual" mesh="head_pitch_link"/>
                <body name="head_yaw_link" pos="-0.000695761 0.00261004 0.0361576" quat="1 -4.4432e-05 -8.12657e-05 0.000120063">
                  <inertial pos="0.028845 -0.00219972 0.0670835" quat="0.705141 -0.132429 -0.146603 0.680989" mass="1.13202" diaginertia="0.0124281 0.00543785 0.000892461"/>
                  <joint name="head_yaw_joint" class="/" pos="0 0 0" axis="0.000803761 -0.000335152 1" range="-2.74363 2.66769" armature="0.0922714" damping="0" frictionloss="0.100951"/>
                  <geom name="//unnamed_geom_68" class="visual" rgba="0.12 0.12 0.12 1" mesh="head_yaw_link"/>
                  <geom name="head_yaw_link.STL" class="collision" size="0.105827" pos="0.018998 -0.000819634 0.0659416" rgba="0.752941 0.752941 0.752941 1"/>
                  <geom name="//unnamed_geom_70" class="reward_collision_sphere" size="0.0891648" pos="0.0311765 0 0.0704352"/>
                  <camera name="ego_camera" class="/" pos="0.114314 0 0.0774788" quat="-0.5 -0.5 0.5 0.5"/>
                </body>
              </body>
            </body>
          </body>
        </body>
      </body>
    </body>
  </worldbody>

  <contact>
    <pair class="/" geom1="floor" geom2="left_foot" name="//unnamed_contact_0"/>
    <pair class="/" geom1="floor" geom2="right_foot" name="//unnamed_contact_1"/>
  </contact>

  <actuator>
    <general name="left_hip_roll" class="/" joint="left_hip_roll_joint" forcerange="-45.1425 45.1425" gainprm="89.5971" biasprm="0 -89.5971 -0.891648"/>
    <general name="left_hip_yaw" class="/" joint="left_hip_yaw_joint" forcerange="-58.094 58.094" gainprm="89.5971" biasprm="0 -89.5971 -0.891648"/>
    <general name="left_hip_pitch" class="/" joint="left_hip_pitch_joint" forcerange="-205.476 205.476" gainprm="89.5971" biasprm="0 -89.5971 -0.891648"/>
    <general name="left_knee_pitch" class="/" joint="left_knee_pitch_joint" forcerange="-182.721 182.721" gainprm="89.5971" biasprm="0 -89.5971 -0.891648"/>
    <general name="left_ankle_pitch" class="/" joint="left_ankle_pitch_joint" forcerange="-14.2115 14.2115" gainprm="89.5971" biasprm="0 -89.5971 -0.891648"/>
    <general name="left_ankle_roll" class="/" joint="left_ankle_roll_joint" forcerange="-25.5946 25.5946" gainprm="89.5971" biasprm="0 -89.5971 -0.891648"/>
    <general name="right_hip_roll" class="/" joint="right_hip_roll_joint" forcerange="-37.7058 37.7058" gainprm="89.5971" biasprm="0 -89.5971 -0.891648"/>
    <general name="right_hip_yaw" class="/" joint="right_hip_yaw_joint" forcerange="-57.8927 57.8927" gainprm="89.5971" biasprm="0 -89.5971 -0.891648"/>
    <general name="right_hip_pitch" class="/" joint="right_hip_pitch_joint" forcerange="-212.068 212.068" gainprm="89.5971" biasprm="0 -89.5971 -0.891648"/>
    <general name="right_knee_pitch" class="/" joint="right_knee_pitch_joint" forcerange="-204.124 204.124" gainprm="89.5971" biasprm="0 -89.5971 -0.891648"/>
    <general name="right_ankle_pitch" class="/" joint="right_ankle_pitch_joint" forcerange="-12.8748 12.8748" gainprm="89.5971" biasprm="0 -89.5971 -0.891648"/>
    <general name="right_ankle_roll" class="/" joint="right_ankle_roll_joint" forcerange="-27.6512 27.6512" gainprm="89.5971" biasprm="0 -89.5971 -0.891648"/>
    <general name="waist_yaw" class="/" joint="waist_yaw_joint" forcerange="-58.5568 58.5568" gainprm="89.5971" biasprm="0 -89.5971 -0.891648"/>
    <general name="waist_pitch" class="/" joint="waist_pitch_joint" forcerange="-67.6573 67.6573" gainprm="89.5971" biasprm="0 -89.5971 -0.891648"/>
    <general name="waist_roll" class="/" joint="waist_roll_joint" forcerange="-58.8206 58.8206" gainprm="89.5971" biasprm="0 -89.5971 -0.891648"/>
    <general name="left_shoulder_pitch" class="/" joint="left_shoulder_pitch_joint" forcerange="-32.8981 32.8981" gainprm="89.5971" biasprm="0 -89.5971 -0.891648"/>
    <general name="left_shoulder_roll" class="/" joint="left_shoulder_roll_joint" forcerange="-33.8455 33.8455" gainprm="89.5971" biasprm="0 -89.5971 -0.891648"/>
    <general name="left_shoulder_yaw" class="/" joint="left_shoulder_yaw_joint" forcerange="-28.685 28.685" gainprm="89.5971" biasprm="0 -89.5971 -0.891648"/>
    <general name="left_elbow_pitch" class="/" joint="left_elbow_pitch_joint" forcerange="-29.1374 29.1374" gainprm="89.5971" biasprm="0 -89.5971 -0.891648"/>
    <general name="left_wrist_yaw" class="/" joint="left_wrist_yaw_joint" forcerange="-9.98838 9.98838" gainprm="89.5971" biasprm="0 -89.5971 -0.891648"/>
    <general name="left_wrist_roll" class="/" joint="left_wrist_roll_joint" forcerange="-3.54865 3.54865" gainprm="89.5971" biasprm="0 -89.5971 -0.891648"/>
    <general name="left_wrist_pitch" class="/" joint="left_wrist_pitch_joint" forcerange="-3.55573 3.55573" gainprm="89.5971" biasprm="0 -89.5971 -0.891648"/>
    <general name="left_jaw" class="/" joint="left_jaw_joint" forcerange="-3.40447 3.40447" gainprm="89.5971" biasprm="0 -89.5971 -0.891648"/>
    <general name="right_shoulder_pitch" class="/" joint="right_shoulder_pitch_joint" forcerange="-35.3073 35.3073" gainprm="89.5971" biasprm="0 -89.5971 -0.891648"/>
    <general name="right_shoulder_roll" class="/" joint="right_shoulder_roll_joint" forcerange="-31.6332 31.6332" gainprm="89.5971" biasprm="0 -89.5971 -0.891648"/>
    <general name="right_shoulder_yaw" class="/" joint="right_shoulder_yaw_joint" forcerange="-26.5065 26.5065" gainprm="89.5971" biasprm="0 -89.5971 -0.891648"/>
    <general name="right_elbow_pitch" class="/" joint="right_elbow_pitch_joint" forcerange="-29.2448 29.2448" gainprm="89.5971" biasprm="0 -89.5971 -0.891648"/>
    <general name="right_wrist_yaw" class="/" joint="right_wrist_yaw_joint" forcerange="-9.9706 9.9706" gainprm="89.5971" biasprm="0 -89.5971 -0.891648"/>
    <general name="right_wrist_roll" class="/" joint="right_wrist_roll_joint" forcerange="-3.53611 3.53611" gainprm="89.5971" biasprm="0 -89.5971 -0.891648"/>
    <general name="right_wrist_pitch" class="/" joint="right_wrist_pitch_joint" forcerange="-3.44507 3.44507" gainprm="89.5971" biasprm="0 -89.5971 -0.891648"/>
    <general name="right_jaw" class="/" joint="right_jaw_joint" forcerange="-3.87229 3.87229" gainprm="89.5971" biasprm="0 -89.5971 -0.891648"/>
    <general name="head_roll" class="/" joint="head_roll_joint" forcerange="-3.40258 3.40258" gainprm="89.5971" biasprm="0 -89.5971 -0.891648"/>
    <general name="head_pitch" class="/" joint="head_pitch_joint" forcerange="-3.37783 3.37783" gainprm="89.5971" biasprm="0 -89.5971 -0.891648"/>
    <general name="head_yaw" class="/" joint="head_yaw_joint" forcerange="-3.18865 3.18865" gainprm="89.5971" biasprm="0 -89.5971 -0.891648"/>
  </actuator>

  <sensor>
    <gyro site="imu" name="imu_angular_velocity"/>
    <velocimeter site="imu" name="imu_linear_velocity"/>
    <framelinvel objtype="site" objname="left_foot" name="left_foot_global_linear_velocity"/>
    <framelinvel objtype="site" objname="right_foot" name="right_foot_global_linear_velocity"/>
  </sensor>

  <keyframe>
    <key name="home" qpos="0 0 0.8665 1 0 0 0 0 0 -0.4 0.8 -0.4 0 0 0 0.4 -0.8 0.4 0 0 0 0 0 -0.2 0 -0.785 0 0 0 0 0 0.2 0 0.785 0 0 0 0 0 0 0"/>
  </keyframe>
</mujoco>
