<mujoco model="GR1T2_jaw">
  <compiler angle="radian" assetdir="assets" balanceinertia="true" inertiafromgeom="false"/>

  <option timestep="0.005" density="1.2" viscosity="2e-05"/>

  <size nkey="1"/>

  <visual>
    <quality shadowsize="8192"/>
    <map shadowclip="0.5"/>
  </visual>

  <default>
    <default class="/">
      <joint armature="0.1" damping="0.01" frictionloss="0.1"/>
      <geom contype="0" conaffinity="0" group="1" solref="-1000 -80"/>
      <site size="0.01 0.005 0.005" group="5"/>
      <general forcelimited="true" biastype="affine" gainprm="80" biasprm="0 -80 -2"/>
      <default class="visual">
        <geom type="mesh" density="0" rgba="0.18 0.18 0.18 1"/>
      </default>
      <default class="collision">
        <geom group="3"/>
      </default>
      <default class="foot">
        <geom size="0.126 0.045 0.01" type="box" condim="6" group="4" priority="1" solimp="0.015 1 0.01"/>
      </default>
      <default class="reward_collision_sphere">
        <geom group="5" rgba="1 0 0 1"/>
      </default>
    </default>
  </default>

  <asset>
    <texture type="skybox" colorspace="auto" name="//unnamed_texture_0" builtin="gradient" rgb1="0.95 0.95 0.95" rgb2="0.95 0.95 0.95" width="100" height="600"/>
    <texture type="2d" colorspace="auto" name="texplane" builtin="checker" rgb1="0.345 0.575 0.748" rgb2="0.345 0.575 0.748" markrgb="1 1 1" width="512" height="512"/>
    <material name="MatPlane" class="/" texture="texplane" texuniform="true" texrepeat="2 2" specular="0.9"/>
    <mesh name="base_link" class="/" file="base_link.STL"/>
    <mesh name="left_thigh_roll_link" class="/" file="left_thigh_roll_link.STL"/>
    <mesh name="left_thigh_yaw_link" class="/" file="left_thigh_yaw_link.STL"/>
    <mesh name="left_thigh_pitch_link" class="/" file="left_thigh_pitch_link.STL"/>
    <mesh name="left_shank_pitch_link" class="/" file="left_shank_pitch_link.STL"/>
    <mesh name="left_foot_pitch_link" class="/" file="left_foot_pitch_link.STL"/>
    <mesh name="left_foot_roll_link" class="/" file="left_foot_roll_link.STL"/>
    <mesh name="right_thigh_roll_link" class="/" file="right_thigh_roll_link.STL"/>
    <mesh name="right_thigh_yaw_link" class="/" file="right_thigh_yaw_link.STL"/>
    <mesh name="right_thigh_pitch_link" class="/" file="right_thigh_pitch_link.STL"/>
    <mesh name="right_shank_pitch_link" class="/" file="right_shank_pitch_link.STL"/>
    <mesh name="right_foot_pitch_link" class="/" file="right_foot_pitch_link.STL"/>
    <mesh name="right_foot_roll_link" class="/" file="right_foot_roll_link.STL"/>
    <mesh name="waist_yaw_link" class="/" file="waist_yaw_link.STL"/>
    <mesh name="waist_pitch_link" class="/" file="waist_pitch_link.STL"/>
    <mesh name="waist_roll_link" class="/" file="waist_roll_link.STL"/>
    <mesh name="torso_link" class="/" file="torso_link.STL"/>
    <mesh name="left_upper_arm_pitch_link" class="/" file="left_upper_arm_pitch_link.STL"/>
    <mesh name="left_upper_arm_roll_link" class="/" file="left_upper_arm_roll_link.STL"/>
    <mesh name="left_upper_arm_yaw_link" class="/" file="left_upper_arm_yaw_link.STL"/>
    <mesh name="left_lower_arm_pitch_link" class="/" file="left_lower_arm_pitch_link.STL"/>
    <mesh name="left_hand_yaw_link" class="/" file="left_hand_yaw_link.STL"/>
    <mesh name="left_hand_roll_link" class="/" file="left_hand_roll_link.STL"/>
    <mesh name="left_hand_pitch" class="/" file="left_hand_pitch.STL"/>
    <mesh name="left_jaw_link" class="/" file="left_jaw_link.STL"/>
    <mesh name="right_upper_arm_pitch_link" class="/" file="right_upper_arm_pitch_link.STL"/>
    <mesh name="right_upper_arm_roll_link" class="/" file="right_upper_arm_roll_link.STL"/>
    <mesh name="right_upper_arm_yaw_link" class="/" file="right_upper_arm_yaw_link.STL"/>
    <mesh name="right_lower_arm_pitch_link" class="/" file="right_lower_arm_pitch_link.STL"/>
    <mesh name="right_hand_yaw_link" class="/" file="right_hand_yaw_link.STL"/>
    <mesh name="right_hand_roll_link" class="/" file="right_hand_roll_link.STL"/>
    <mesh name="right_hand_pitch" class="/" file="right_hand_pitch.STL"/>
    <mesh name="right_jaw_link" class="/" file="right_jaw_link.STL"/>
    <mesh name="head_roll_link" class="/" file="head_roll_link.STL"/>
    <mesh name="head_pitch_link" class="/" file="head_pitch_link.STL"/>
    <mesh name="head_yaw_link" class="/" file="head_yaw_link.STL"/>
    <mesh name="imu_link" class="/" file="imu_link.STL"/>
  </asset>

  <worldbody>
    <geom name="floor" class="/" size="100 100 0.125" type="plane" group="0" material="MatPlane"/>
    <light name="toplight_shadow" class="/" pos="0 0 5" dir="0.0990148 0.0990148 -0.990148" type="directional" ambient="0.04 0.04 0.04" diffuse="0.55 0.55 0.55" specular="0.12 0.12 0.12"/>
    <light name="toplight_fill" class="/" pos="0 0 5" dir="0.0990148 0.0990148 -0.990148" type="directional" castshadow="false" ambient="0.04 0.04 0.04" diffuse="0.3 0.3 0.3" specular="0.08 0.08 0.08"/>
    <body name="trunk" pos="0.00272216 -0.00023639 -0.0024143" quat="1 -0.000798145 -9.54233e-05 -0.000552324">
      <inertial pos="-0.0611131 0.00368869 -0.00895488" quat="0.999928 -0.00200645 0.00688089 -0.00965537" mass="1.30751" diaginertia="0.0527423 7.75289e-05 0.0052511"/>
      <joint name="//unnamed_joint_0" type="free"/>
      <geom name="//unnamed_geom_1" class="visual" rgba="0.12 0.12 0.12 1" mesh="base_link"/>
      <geom name="base_link.STL" class="collision" size="0.0849562 0.0475822" pos="-0.0452857 0.000132597 0.00608381" quat="0.706838 -0.707359 0.00477667 0" type="cylinder" rgba="0.752941 0.752941 0.752941 1"/>
      <geom name="//unnamed_geom_3" class="visual" pos="0 0 -0.0393694" quat="1 0 0 0" rgba="0.12 0.12 0.12 1" mesh="imu_link"/>
      <geom name="//unnamed_geom_4" class="reward_collision_sphere" size="0.0555296" pos="0 0.0358331 0.066056"/>
      <geom name="//unnamed_geom_5" class="reward_collision_sphere" size="0.0555296" pos="0 -0.0358331 0.066056"/>
      <site name="imu" class="/" pos="0.00753094 0.013673 -0.0492832" size="0.0069412"/>
      <camera name="track" class="/" pos="0 -0.716661 0" quat="0.707107 0.707107 0 0" mode="trackcom"/>
      <body name="left_thigh_roll_link" pos="-0.0348799 0.0392581 -0.01574" quat="1 -0.000209486 -4.95091e-05 -0.000189732">
        <inertial pos="0.00187093 -0.00176977 0.00170631" quat="-0.0207724 0.705515 -0.0322511 0.707656" mass="0.492323" diaginertia="0.00329012 1.4238e-05 0.000191627"/>
        <joint name="left_hip_roll_joint" class="/" pos="0 0 0" axis="-0.999997 -0.000375938 0.00248988" range="-0.793253 0.060705" armature="0.0785449" damping="0" frictionloss="0.0635302"/>
        <geom name="//unnamed_geom_6" class="visual" mesh="left_thigh_roll_link"/>
        <body name="left_thigh_yaw_link" pos="0.0315505 -0.00139611 0.00367507" quat="1 -0.000684986 -3.84259e-05 -0.000688269">
          <inertial pos="0.000873148 0.0159063 -0.0735893" quat="0.56435 0.0863095 -0.20243 0.795665" mass="1.15885" diaginertia="0.0329536 0.000116605 0.00113762"/>
          <joint name="left_hip_yaw_joint" class="/" pos="0 0 0" axis="-5.36037e-05 0.000307264 -1" range="-0.655631 0.722916" armature="0.069046" damping="0" frictionloss="0.0784904"/>
          <geom name="//unnamed_geom_7" class="visual" mesh="left_thigh_yaw_link"/>
          <body name="left_thigh_pitch_link" pos="-0.000518476 0.0058315 -0.0918157" quat="0.999999 -0.000858025 0.000280231 0.000456744">
            <inertial pos="0.000168488 -0.01308 -0.0434233" quat="0.99982 -0.0117275 -0.0130694 0.00718128" mass="2.758" diaginertia="0.122305 0.000514893 0.00346256"/>
            <joint name="left_hip_pitch_joint" class="/" pos="0 0 0" axis="0.00490027 0.999988 0.000913125" range="-1.7414 0.711623" armature="0.0724662" damping="0" frictionloss="0.074621"/>
            <geom name="//unnamed_geom_8" class="visual" mesh="left_thigh_pitch_link"/>
            <geom name="left_thigh_pitch_link.STL" class="collision" size="0.0569179 0.0867053" pos="0.000744484 -0.0107499 -0.11035" type="cylinder" rgba="0.752941 0.752941 0.752941 1"/>
            <geom name="//unnamed_geom_10" class="reward_collision_sphere" size="0.069412" pos="0 -0.00358331 -0.033028"/>
            <body name="left_shank_pitch_link" pos="-0.00181114 -0.00761353 -0.234478" quat="1 -0.000741682 0.000200133 -0.000376568">
              <inertial pos="0.000782434 0.00025522 -0.0738257" quat="0.999782 -0.00749113 0.00339716 -0.0192148" mass="0.57131" diaginertia="0.0147609 6.11638e-05 0.000154661"/>
              <joint name="left_knee_pitch_joint" class="/" pos="0 0 0" axis="0.000399508 1 0.000590459" range="-0.107328 1.94239" armature="0.0657214" damping="0.0178284" frictionloss="0.0712099"/>
              <geom name="//unnamed_geom_11" class="visual" mesh="left_shank_pitch_link"/>
              <geom name="left_shank_pitch_link.STL" class="collision" size="0.0370115 0.0627381" pos="-1.76431e-05 -0.00030191 -0.115394" quat="0.00125538 -0.202712 0.979238 0" type="cylinder" rgba="0.752941 0.752941 0.752941 1"/>
              <geom name="//unnamed_geom_13" class="reward_collision_sphere" size="0.034706"/>
              <geom name="//unnamed_geom_14" class="reward_collision_sphere" size="0.0416472" pos="0 0 -0.0726616"/>
              <body name="left_foot_pitch_link" pos="-0.00151491 -0.00313706 -0.224542" quat="1 1.50004e-05 -9.96369e-06 1.81368e-05">
                <inertial pos="-0.00111936 -0.00105761 -0.00228571" quat="0.00195809 0.706285 0.000556334 0.707924" mass="0.0185006" diaginertia="8.26816e-06 3.14807e-08 6.48321e-07"/>
                <joint name="left_ankle_pitch_joint" class="/" pos="0 0 0" axis="0.0102675 0.999917 0.00776162" stiffness="0.00164032" range="-1.00826 0.536622" armature="0.0790888" damping="0.00193284" frictionloss="0.0788339"/>
                <geom name="//unnamed_geom_15" class="visual" mesh="left_foot_pitch_link"/>
                <body name="left_foot_roll_link" pos="0.00268216 0.000292495 0.00252667" quat="1 4.29798e-05 0.000135366 0.000351307">
                  <inertial pos="0.0422197 0.000480279 -0.0261039" quat="0.000295785 0.723599 -0.000250331 0.690221" mass="0.360001" diaginertia="0.00768907 2.89802e-05 9.26937e-05"/>
                  <joint name="left_ankle_roll_joint" class="/" pos="0 0 0" axis="-0.99997 0.00596894 -0.00486366" range="-0.395768 0.469723" armature="0.0665514" damping="0" frictionloss="0.078445"/>
                  <geom name="//unnamed_geom_16" class="visual" mesh="left_foot_roll_link"/>
                  <geom name="left_foot" class="foot" size="0.122527 0.030452 0.00763595" pos="0.0478562 0 -0.0293949"/>
                  <geom name="//unnamed_geom_18" class="reward_collision_sphere" size="0.034706" pos="0 0 -0.0198168"/>
                  <geom name="//unnamed_geom_19" class="reward_collision_sphere" size="0.034706" pos="0.127616 0 -0.0198168"/>
                  <site name="left_foot" class="foot" pos="0.0478562 0 -0.0293949" size="0.0069412"/>
                </body>
              </body>
            </body>
          </body>
        </body>
      </body>
      <body name="right_thigh_roll_link" pos="-0.0311647 -0.0371419 -0.0171251" quat="1 -9.34212e-05 -0.000776245 -0.000574388">
        <inertial pos="-0.00167685 0.00187283 0.00372694" quat="0.0278515 0.705035 0.0171342 0.708419" mass="0.475908" diaginertia="0.00354418 1.5001e-05 0.000191564"/>
        <joint name="right_hip_roll_joint" class="/" pos="0 0 0" axis="-0.999974 -0.00569049 -0.00436009" range="-0.118081 0.84977" armature="0.0746678" damping="0" frictionloss="0.0710841"/>
        <geom name="//unnamed_geom_20" class="visual" mesh="right_thigh_roll_link"/>
        <body name="right_thigh_yaw_link" pos="0.0370958 -0.000635523 0.000893115" quat="1 -5.34077e-05 -0.00027651 1.79691e-05">
          <inertial pos="-0.00638333 -0.0109709 -0.075856" quat="0.68664 -0.148215 0.150511 0.695632" mass="1.1731" diaginertia="0.0313118 0.000114534 0.00115307"/>
          <joint name="right_hip_yaw_joint" class="/" pos="0 0 0" axis="-0.00425013 -0.0074099 -0.999964" range="-0.754443 0.681084" armature="0.0679291" damping="0" frictionloss="0.0775717"/>
          <geom name="//unnamed_geom_21" class="visual" mesh="right_thigh_yaw_link"/>
          <body name="right_thigh_pitch_link" pos="3.7813e-05 -0.014122 -0.0911463" quat="1 0.000720981 0.000604001 -0.000178722">
            <inertial pos="0.00253188 0.00722933 -0.0441451" quat="0.999805 -0.014609 -0.0121377 0.0054065" mass="2.77394" diaginertia="0.118265 0.000510575 0.00328977"/>
            <joint name="right_hip_pitch_joint" class="/" pos="0 0 0" axis="-0.0172908 -0.999533 0.0251971" range="-0.683954 1.74367" armature="0.0627928" damping="0.00547249" frictionloss="0.0684408"/>
            <geom name="//unnamed_geom_22" class="visual" mesh="right_thigh_pitch_link"/>
            <geom name="right_thigh_pitch_link.STL" class="collision" size="0.0569179 0.0867033" pos="-0.00225804 0.0107499 -0.11035" quat="0.999971 0.00269833 0.00706272 0" type="cylinder" rgba="0.752941 0.752941 0.752941 1"/>
            <geom name="//unnamed_geom_24" class="reward_collision_sphere" size="0.069412" pos="0 0.00358331 -0.033028"/>
            <body name="right_shank_pitch_link" pos="0.00202087 0.00165778 -0.236023" quat="1 6.09628e-06 -9.38665e-07 -1.18674e-06">
              <inertial pos="0.00363822 -0.00358472 -0.0782156" quat="0.999452 0.00416902 0.0135652 0.029896" mass="0.581221" diaginertia="0.014695 6.33012e-05 0.000153704"/>
              <joint name="right_knee_pitch_joint" class="/" pos="0 0 0" axis="0.00172197 -0.999998 0.00117437" range="-1.93359 0.104054" armature="0.0686678" damping="0.0060359" frictionloss="0.06824"/>
              <geom name="//unnamed_geom_25" class="visual" mesh="right_shank_pitch_link"/>
              <geom name="right_shank_pitch_link.STL" class="collision" size="0.0370113 0.0627374" pos="-1.76431e-05 -0.000301914 -0.115399" type="cylinder" rgba="0.752941 0.752941 0.752941 1"/>
              <geom name="//unnamed_geom_27" class="reward_collision_sphere" size="0.034706"/>
              <geom name="//unnamed_geom_28" class="reward_collision_sphere" size="0.0416472" pos="0 0 -0.0726616"/>
              <body name="right_foot_pitch_link" pos="0.000305375 -0.00248634 -0.222801" quat="0.999999 0.000416268 0.000550906 -0.00124962">
                <inertial pos="9.96867e-05 0.000396855 -0.00249106" quat="0.000177227 0.705911 0.00295433 0.708294" mass="0.0198488" diaginertia="8.89997e-06 3.37691e-08 6.95847e-07"/>
                <joint name="right_ankle_pitch_joint" class="/" pos="0 0 0" axis="-0.000326223 -0.999998 0.00190514" range="-0.478021 1.11241" armature="0.0776059" damping="0.0061033" frictionloss="0.0712299"/>
                <geom name="//unnamed_geom_29" class="visual" mesh="right_foot_pitch_link"/>
                <body name="right_foot_roll_link" pos="-0.0019745 -0.00147215 0.00245434" quat="1 7.13084e-06 3.47587e-05 2.36947e-05">
                  <inertial pos="0.0389717 -0.00399966 -0.0232684" quat="-0.000811168 0.723909 0.00250672 0.689891" mass="0.357718" diaginertia="0.00726296 2.90275e-05 9.22509e-05"/>
                  <joint name="right_ankle_roll_joint" class="/" pos="0 0 0" axis="-0.999983 0.00578338 0.00077899" stiffness="0.000228752" range="-0.462122 0.456894" armature="0.0603516" damping="0" frictionloss="0.0685095"/>
                  <geom name="//unnamed_geom_30" class="visual" mesh="right_foot_roll_link"/>
                  <geom name="right_foot" class="foot" size="0.126202 0.0286132 0.0068593" pos="0.0478562 0 -0.0293949"/>
                  <geom name="//unnamed_geom_32" class="reward_collision_sphere" size="0.034706" pos="0 0 -0.0198168"/>
                  <geom name="//unnamed_geom_33" class="reward_collision_sphere" size="0.034706" pos="0.127616 0 -0.0198168"/>
                  <site name="right_foot" class="foot" pos="0.0478562 0 -0.0293949" size="0.0069412"/>
                </body>
              </body>
            </body>
          </body>
        </body>
      </body>
      <body name="waist_yaw_link" pos="8.92921e-05 -0.00314392 1.16287e-05" quat="1 3.08631e-05 -5.48745e-05 -0.000126607">
        <inertial pos="-0.00319864 -0.00222286 0.0342603" quat="0.980001 0.187858 -0.0282783 0.0592289" mass="0.581394" diaginertia="0.00499601 1.93135e-05 0.000285879"/>
        <joint name="waist_yaw_joint" class="/" pos="0 0 0" axis="0.00285772 0.00148343 0.999995" range="-1.04468 1.0865" armature="0.0611545" damping="0.00567177" frictionloss="0.0604234"/>
        <geom name="//unnamed_geom_34" class="visual" rgba="0.12 0.12 0.12 1" mesh="waist_yaw_link"/>
        <body name="waist_pitch_link" pos="0.00214492 0.000350029 0.0604871" quat="1 0.000380836 0.000589771 -0.000263876">
          <inertial pos="0.0064546 -0.000111655 0.0298694" quat="0.997842 -0.0494152 0.0425097 0.00792627" mass="0.483509" diaginertia="0.0059123 2.64206e-05 0.000229285"/>
          <joint name="waist_pitch_joint" class="/" pos="0 0 0" axis="0.00721377 -0.999775 -0.0199659" range="-1.17742 0.551349" armature="0.0778254" damping="0" frictionloss="0.0712723"/>
          <geom name="//unnamed_geom_35" class="visual" rgba="0.12 0.12 0.12 1" mesh="waist_pitch_link"/>
          <body name="waist_roll_link" pos="0.0066205 -0.00649553 0.053813" quat="1 0.000790195 0.000333181 -0.000135532">
            <inertial pos="-0.0155361 -0.00268706 0.0974328" quat="0.998732 -0.00221135 -0.0502733 0.00108088" mass="2.23459" diaginertia="0.0883473 0.000366782 0.00455283"/>
            <joint name="waist_roll_joint" class="/" pos="0 0 0" axis="-0.999991 0.00430834 0.000324179" range="-0.68716 0.673299" armature="0.0710385" damping="0.0203632" frictionloss="0.0744746"/>
            <geom name="//unnamed_geom_36" class="visual" rgba="0.12 0.12 0.12 1" mesh="waist_roll_link"/>
            <geom name="//unnamed_geom_37" class="visual" pos="-0.00239281 0.000205836 0.105921" quat="1 0 0 0" mesh="torso_link"/>
            <geom name="torso_link.STL" class="collision" size="0.109273 0.0209576" pos="-0.0192126 0.0020675 0.0976499" type="cylinder" rgba="0.752941 0.752941 0.752941 1"/>
            <geom name="//unnamed_geom_39" class="reward_collision_sphere" size="0.0902356" pos="0 0 0.132112"/>
            <body name="left_upper_arm_pitch_link" pos="-0.00377633 0.0356721 0.138699" quat="0.976529 0.215385 -0.000459988 0.00104702">
              <inertial pos="0.00336577 0.0216742 0.000221824" quat="0.704749 0.707502 0.00278334 -0.0525496" mass="0.25698" diaginertia="0.00269861 1.10924e-05 6.0635e-05"/>
              <joint name="left_shoulder_pitch_joint" class="/" pos="0 0 0" axis="0.00649582 0.999941 0.00871505" range="-2.77738 1.95946" armature="0.0615058" damping="0.0172546" frictionloss="0.0788381"/>
              <geom name="//unnamed_geom_40" class="visual" mesh="left_upper_arm_pitch_link"/>
              <body name="left_upper_arm_roll_link" pos="0.000898953 0.0348323 -0.00142292" quat="0.976595 -0.215089 -0.000151992 0.000272876">
                <inertial pos="0.0037832 0.00400207 -0.0155729" quat="0.890675 0.26641 0.113022 -0.350643" mass="0.217349" diaginertia="0.0014102 6.10924e-06 4.5431e-05"/>
                <joint name="left_shoulder_roll_joint" class="/" pos="0 0 0" axis="-0.999989 0.00376257 0.00288357" range="-2.5149 0.633463" armature="0.0799745" damping="0.0153561" frictionloss="0.077032"/>
                <geom name="//unnamed_geom_41" class="visual" mesh="left_upper_arm_roll_link"/>
                <body name="left_upper_arm_yaw_link" pos="-0.0030062 0.0124867 -0.0442544" quat="1 2.84685e-05 0.000223737 -0.000121702">
                  <inertial pos="-0.000225094 -0.00099958 -0.0596678" quat="0.999962 0.00667669 1.84878e-05 -0.00552394" mass="0.169119" diaginertia="0.00464388 2.09465e-05 3.05224e-05"/>
                  <joint name="left_shoulder_yaw_joint" class="/" pos="0 0 0" axis="0.00181655 0.000823343 0.999998" stiffness="0.000873175" range="-2.91728 2.99563" armature="0.0716928" damping="0" frictionloss="0.0784903"/>
                  <geom name="//unnamed_geom_42" class="visual" mesh="left_upper_arm_yaw_link"/>
                  <geom name="left_upper_arm_yaw_link.STL" class="collision" size="0.0251502 0.05896" pos="4.19916e-05 -0.000320452 -0.0524088" quat="0.00803418 -0.995528 0.0941277 0" type="cylinder" rgba="0.752941 0.752941 0.752941 1"/>
                  <body name="left_lower_arm_pitch_link" pos="-0.000368859 0.000330942 -0.120817" quat="0.999999 0.000820041 0.000253849 -0.00056639">
                    <inertial pos="-0.00336432 0.000665859 -0.0182158" quat="0.702598 -0.0934589 0.0875305 0.699971" mass="0.113083" diaginertia="0.000429811 1.82556e-06 1.31752e-05"/>
                    <joint name="left_elbow_pitch_joint" class="/" pos="0 0 0" axis="-0.000260154 1 7.90921e-05" stiffness="0.00615926" range="-2.31971 2.31466" armature="0.0813717" damping="0.0142382" frictionloss="0.0703388"/>
                    <geom name="//unnamed_geom_44" class="visual" mesh="left_lower_arm_pitch_link"/>
                    <body name="left_hand_yaw_link" pos="0.000222531 0.00273947 -0.0368051" quat="1 -0.000176282 -0.000339081 0.000492586">
                      <inertial pos="0.00315634 -0.000207789 -0.0498756" quat="0.999977 -0.00354257 -0.00112406 0.00570235" mass="0.329834" diaginertia="0.00356909 1.54607e-05 6.30963e-05"/>
                      <joint name="left_wrist_yaw_joint" class="/" pos="0 0 0" axis="0.000527922 -0.00048963 1" range="-2.93555 2.9656" armature="0.0742897" damping="0.00658875" frictionloss="0.0700806"/>
                      <geom name="//unnamed_geom_45" class="visual" mesh="left_hand_yaw_link"/>
                      <geom name="left_hand_yaw_link.STL" class="collision" size="0.0288559 0.0483064" pos="0.00115839 -0.000552227 -0.0502309" type="cylinder" rgba="0.752941 0.752941 0.752941 1"/>
                      <geom name="//unnamed_geom_47" class="reward_collision_sphere" size="0.034706"/>
                      <body name="left_hand_roll_link" pos="-0.00083142 0.00245403 -0.123871" quat="0.999999 0.00068975 -0.000406642 0.000784857">
                        <inertial pos="0.000859013 0.00219851 -0.00238059" quat="0.509162 0.49434 0.496284 0.500084" mass="0.00170082" diaginertia="4.85935e-07 2.05403e-09 8.62575e-09"/>
                        <joint name="left_wrist_roll_joint" class="/" pos="0 0 0" axis="-0.999922 0.012257 -0.00227973" range="-0.975055 0.916089" armature="0.0723406" damping="0.00243228" frictionloss="0.0708988"/>
                        <geom name="//unnamed_geom_48" class="visual" mesh="left_hand_roll_link"/>
                        <body name="left_hand_pitch_link" pos="0.00258453 -0.000520236 -0.000886386" quat="0.999999 0.000908926 0.000764338 -0.000554215">
                          <inertial pos="7.34816e-05 -0.00282788 -0.0358709" quat="0.721958 -0.117737 0.113098 0.672402" mass="0.0708468" diaginertia="0.000400837 1.64053e-06 1.15402e-05"/>
                          <joint name="left_wrist_pitch_joint" class="/" pos="0 0 0" axis="0.00236958 0.999997 -0.000794382" stiffness="0.0174275" range="-0.618456 0.619163" armature="0.0796654" damping="0.00743561" frictionloss="0.0785034"/>
                          <geom name="//unnamed_geom_49" class="visual" mesh="left_hand_pitch"/>
                          <body name="left_jaw_link" pos="0.000679165 -0.0001613 -0.0420424" quat="0.999999 0.000918938 0.000332654 -0.000875998">
                            <inertial pos="0.00304979 0.000333596 -0.0227365" quat="0.705994 -0.0233094 0.0353006 0.706953" mass="0.0225249" diaginertia="0.00010655 3.19916e-07 3.97477e-06"/>
                            <joint name="left_jaw_joint" class="/" pos="0 0 0" axis="-0.999998 0.00164541 -0.0014028" range="-1.03326 0.0394442" armature="0.0631588" damping="0.010762" frictionloss="0.0667348"/>
                            <geom name="//unnamed_geom_50" class="visual" mesh="left_jaw_link"/>
                            <geom name="//unnamed_geom_51" class="collision" size="0.0249883"/>
                            <geom name="//unnamed_geom_52" class="reward_collision_sphere" size="0.034706" pos="0 0 -0.0132112"/>
                          </body>
                        </body>
                      </body>
                    </body>
                  </body>
                </body>
              </body>
            </body>
            <body name="right_upper_arm_pitch_link" pos="-0.00219623 -0.0371081 0.139562" quat="0.976519 -0.215427 0.00076628 0.000928159">
              <inertial pos="0.00300975 -0.0183486 0.00281562" quat="0.712805 0.700687 0.020842 0.0226521" mass="0.275208" diaginertia="0.00277717 1.1511e-05 6.33959e-05"/>
              <joint name="right_shoulder_pitch_joint" class="/" pos="0 0 0" axis="-0.00123579 -0.999984 -0.00543708" stiffness="0.0116532" range="-1.89315 2.78872" armature="0.072477" damping="0.00102101" frictionloss="0.0601199"/>
              <geom name="//unnamed_geom_53" class="visual" mesh="right_upper_arm_pitch_link"/>
              <body name="right_upper_arm_roll_link" pos="-0.001314 -0.034456 -0.00104604" quat="0.976794 0.214176 -0.00105454 0.000231364">
                <inertial pos="0.00457799 -0.00563803 -0.0135761" quat="0.891129 -0.270348 0.129567 0.340607" mass="0.207523" diaginertia="0.00139766 5.94711e-06 4.46092e-05"/>
                <joint name="right_shoulder_roll_joint" class="/" pos="0 0 0" axis="-0.999937 -0.00955926 0.0058894" range="-0.572411 2.49468" armature="0.0769755" damping="0" frictionloss="0.0650969"/>
                <geom name="//unnamed_geom_54" class="visual" mesh="right_upper_arm_roll_link"/>
                <body name="right_upper_arm_yaw_link" pos="-0.000487622 -0.0150406 -0.0487889" quat="1 0.000440306 -0.000186516 -0.000423397">
                  <inertial pos="0.000521791 0.000272509 -0.0582274" quat="0.999975 -0.00685357 0.00159942 0.00110082" mass="0.180176" diaginertia="0.00491044 2.07341e-05 3.23017e-05"/>
                  <joint name="right_shoulder_yaw_joint" class="/" pos="0 0 0" axis="-0.00529814 -0.000142416 0.999986" stiffness="0.00184898" range="-2.96172 2.96727" armature="0.068997" damping="0.00396929" frictionloss="0.0703813"/>
                  <geom name="//unnamed_geom_55" class="visual" mesh="right_upper_arm_yaw_link"/>
                  <geom name="right_upper_arm_yaw_link.STL" class="collision" size="0.0251502 0.05896" pos="4.19916e-05 0.000320452 -0.0524088" type="cylinder" rgba="0.752941 0.752941 0.752941 1"/>
                  <body name="right_lower_arm_pitch_link" pos="0.000593388 -0.000307724 -0.114747" quat="1 -0.000889884 -0.000100363 -0.000372615">
                    <inertial pos="-0.00123928 -0.000921222 -0.0193499" quat="0.701112 0.0896462 -0.0899996 0.701645" mass="0.112464" diaginertia="0.000403346 1.76919e-06 1.24206e-05"/>
                    <joint name="right_elbow_pitch_joint" class="/" pos="0 0 0" axis="-0.00827213 -0.999939 0.00727074" range="-2.25672 2.2349" armature="0.0780178" damping="0.00757574" frictionloss="0.0666201"/>
                    <geom name="//unnamed_geom_57" class="visual" mesh="right_lower_arm_pitch_link"/>
                    <body name="right_hand_yaw_link" pos="0.000589226 0.000332907 -0.0403757" quat="0.999999 -0.000476842 0.000654647 -0.000804344">
                      <inertial pos="-0.00131402 -0.000536221 -0.045006" quat="0.999722 -0.00156142 -0.00440889 0.0231112" mass="0.323897" diaginertia="0.00352641 1.531e-05 6.2508e-05"/>
                      <joint name="right_wrist_yaw_joint" class="/" pos="0 0 0" axis="0.000429554 0.000402626 1" range="-2.99055 2.99899" armature="0.074767" damping="0.00706055" frictionloss="0.0678985"/>
                      <geom name="//unnamed_geom_58" class="visual" mesh="right_hand_yaw_link"/>
                      <geom name="right_hand_yaw_link.STL" class="collision" size="0.0288559 0.0483064" pos="0.00115839 0.000229731 -0.0502309" type="cylinder" rgba="0.752941 0.752941 0.752941 1"/>
                      <geom name="//unnamed_geom_60" class="reward_collision_sphere" size="0.034706"/>
                      <body name="right_hand_roll_link" pos="-0.00155049 0.00120872 -0.126566" quat="1 -1.05945e-05 2.05181e-05 3.9233e-05">
                        <inertial pos="-0.00300617 0.00130855 -0.00051934" quat="0.499904 0.50053 0.500088 0.499478" mass="0.00161702" diaginertia="4.61079e-07 2.05163e-09 8.85038e-09"/>
                        <joint name="right_wrist_roll_joint" class="/" pos="0 0 0" axis="-0.999915 0.00402244 0.012388" range="-0.821039 0.912844" armature="0.0723575" damping="0" frictionloss="0.0660713"/>
                        <geom name="//unnamed_geom_61" class="visual" mesh="right_hand_roll_link"/>
                        <body name="right_hand_pitch_link" pos="0.000276047 0.00243191 -0.000248853" quat="1 -0.000170427 0.000184467 -9.549e-06">
                          <inertial pos="-0.00119383 0.00225372 -0.0342519" quat="0.722585 0.122754 -0.112466 0.670935" mass="0.0705567" diaginertia="0.000376203 1.58492e-06 1.16659e-05"/>
                          <joint name="right_wrist_pitch_joint" class="/" pos="0 0 0" axis="0.000609752 -0.999988 0.00486192" range="-0.637337 0.607197" armature="0.0779733" damping="0.0128257" frictionloss="0.0627625"/>
                          <geom name="//unnamed_geom_62" class="visual" mesh="right_hand_pitch"/>
                          <body name="right_jaw_link" pos="7.07052e-05 -0.00175495 -0.0406745" quat="0.999999 -0.000753806 -0.000955517 7.72191e-05">
                            <inertial pos="0.00176519 -0.00334626 -0.0223616" quat="0.703974 0.0116344 -0.0231714 0.709752" mass="0.0236798" diaginertia="0.000110348 3.28968e-07 4.22521e-06"/>
                            <joint name="right_jaw_joint" class="/" pos="0 0 0" axis="-0.999966 0.00587004 -0.00578461" range="-0.0018243 1.04498" armature="0.0675566" damping="0.00461576" frictionloss="0.0704594"/>
                            <geom name="//unnamed_geom_63" class="visual" mesh="right_jaw_link"/>
                            <geom name="//unnamed_geom_64" class="collision" size="0.0249883"/>
                            <geom name="//unnamed_geom_65" class="reward_collision_sphere" size="0.034706" pos="0 0 -0.0132112"/>
                          </body>
                        </body>
                      </body>
                    </body>
                  </body>
                </body>
              </body>
            </body>
            <body name="head_roll_link" pos="0.00173481 -0.00261946 0.206203" quat="1 -0.000172925 -0.000282477 9.6825e-06">
              <inertial pos="0.0069405 -0.00135011 0.000994" quat="-0.000515626 0.707394 0.000550896 0.706819" mass="0.00334716" diaginertia="9.67893e-07 2.58777e-09 5.44081e-08"/>
              <joint name="head_roll_joint" class="/" pos="0 0 0" axis="-0.999993 -0.00152576 -0.00351077" range="-0.356879 0.385894" armature="0.068078" damping="0" frictionloss="0.0710605"/>
              <geom name="//unnamed_geom_66" class="visual" mesh="head_roll_link"/>
              <body name="head_pitch_link" pos="-0.00155582 0.00170792 0.00399572" quat="0.999999 0.000426266 0.000945939 -0.000799699">
                <inertial pos="-0.0039995 -0.00253516 0.0121352" quat="0.664754 0.66471 0.241072 -0.241137" mass="0.0202759" diaginertia="3.72346e-05 1.36405e-07 2.24633e-06"/>
                <joint name="head_pitch_joint" class="/" pos="0 0 0" axis="0.00421146 -0.99999 -0.00127141" stiffness="0.00430453" range="-0.911847 0.867935" armature="0.0714528" damping="0" frictionloss="0.0663041"/>
                <geom name="//unnamed_geom_67" class="visual" mesh="head_pitch_link"/>
                <body name="head_yaw_link" pos="-0.000851715 0.000524228 0.0388681" quat="0.999999 0.000305313 0.000640885 -0.00107592">
                  <inertial pos="0.0271939 -0.00218074 0.0629732" quat="0.715381 -0.128886 -0.144208 0.671433" mass="0.545165" diaginertia="0.0142031 4.84212e-05 0.000676482"/>
                  <joint name="head_yaw_joint" class="/" pos="0 0 0" axis="0.00436999 -0.010629 0.999934" stiffness="0.00672464" range="-2.75941 2.73865" armature="0.065215" damping="0" frictionloss="0.0667769"/>
                  <geom name="//unnamed_geom_68" class="visual" rgba="0.12 0.12 0.12 1" mesh="head_yaw_link"/>
                  <geom name="head_yaw_link.STL" class="collision" size="0.0823831" pos="0.0194414 -0.00031534 0.0618417" rgba="0.752941 0.752941 0.752941 1"/>
                  <geom name="//unnamed_geom_70" class="reward_collision_sphere" size="0.069412" pos="0.0319041 0 0.066056"/>
                  <camera name="ego_camera" class="/" pos="0.116982 0 0.0726616" quat="-0.5 -0.5 0.5 0.5"/>
                </body>
              </body>
            </body>
          </body>
        </body>
      </body>
    </body>
  </worldbody>

  <contact>
    <pair class="/" geom1="floor" geom2="left_foot" name="//unnamed_contact_0"/>
    <pair class="/" geom1="floor" geom2="right_foot" name="//unnamed_contact_1"/>
  </contact>

  <actuator>
    <general name="left_hip_roll" class="/" joint="left_hip_roll_joint" forcerange="-35.5965 35.5965" gainprm="61.9511" biasprm="0 -61.9511 -0.973047"/>
    <general name="left_hip_yaw" class="/" joint="left_hip_yaw_joint" forcerange="-45.9156 45.9156" gainprm="61.9511" biasprm="0 -61.9511 -0.973047"/>
    <general name="left_hip_pitch" class="/" joint="left_hip_pitch_joint" forcerange="-173.456 173.456" gainprm="61.9511" biasprm="0 -61.9511 -0.973047"/>
    <general name="left_knee_pitch" class="/" joint="left_knee_pitch_joint" forcerange="-172.448 172.448" gainprm="61.9511" biasprm="0 -61.9511 -0.973047"/>
    <general name="left_ankle_pitch" class="/" joint="left_ankle_pitch_joint" forcerange="-11.4191 11.4191" gainprm="61.9511" biasprm="0 -61.9511 -0.973047"/>
    <general name="left_ankle_roll" class="/" joint="left_ankle_roll_joint" forcerange="-19.4288 19.4288" gainprm="61.9511" biasprm="0 -61.9511 -0.973047"/>
    <general name="right_hip_roll" class="/" joint="right_hip_roll_joint" forcerange="-30.6848 30.6848" gainprm="61.9511" biasprm="0 -61.9511 -0.973047"/>
    <general name="right_hip_yaw" class="/" joint="right_hip_yaw_joint" forcerange="-47.0953 47.0953" gainprm="61.9511" biasprm="0 -61.9511 -0.973047"/>
    <general name="right_hip_pitch" class="/" joint="right_hip_pitch_joint" forcerange="-164.752 164.752" gainprm="61.9511" biasprm="0 -61.9511 -0.973047"/>
    <general name="right_knee_pitch" class="/" joint="right_knee_pitch_joint" forcerange="-145.045 145.045" gainprm="61.9511" biasprm="0 -61.9511 -0.973047"/>
    <general name="right_ankle_pitch" class="/" joint="right_ankle_pitch_joint" forcerange="-11.1286 11.1286" gainprm="61.9511" biasprm="0 -61.9511 -0.973047"/>
    <general name="right_ankle_roll" class="/" joint="right_ankle_roll_joint" forcerange="-21.3611 21.3611" gainprm="61.9511" biasprm="0 -61.9511 -0.973047"/>
    <general name="waist_yaw" class="/" joint="waist_yaw_joint" forcerange="-44.7716 44.7716" gainprm="61.9511" biasprm="0 -61.9511 -0.973047"/>
    <general name="waist_pitch" class="/" joint="waist_pitch_joint" forcerange="-45.62 45.62" gainprm="61.9511" biasprm="0 -61.9511 -0.973047"/>
    <general name="waist_roll" class="/" joint="waist_roll_joint" forcerange="-42.2882 42.2882" gainprm="61.9511" biasprm="0 -61.9511 -0.973047"/>
    <general name="left_shoulder_pitch" class="/" joint="left_shoulder_pitch_joint" forcerange="-26.7981 26.7981" gainprm="61.9511" biasprm="0 -61.9511 -0.973047"/>
    <general name="left_shoulder_roll" class="/" joint="left_shoulder_roll_joint" forcerange="-24.8864 24.8864" gainprm="61.9511" biasprm="0 -61.9511 -0.973047"/>
    <general name="left_shoulder_yaw" class="/" joint="left_shoulder_yaw_joint" forcerange="-22.8404 22.8404" gainprm="61.9511" biasprm="0 -61.9511 -0.973047"/>
    <general name="left_elbow_pitch" class="/" joint="left_elbow_pitch_joint" forcerange="-19.3012 19.3012" gainprm="61.9511" biasprm="0 -61.9511 -0.973047"/>
    <general name="left_wrist_yaw" class="/" joint="left_wrist_yaw_joint" forcerange="-7.06196 7.06196" gainprm="61.9511" biasprm="0 -61.9511 -0.973047"/>
    <general name="left_wrist_roll" class="/" joint="left_wrist_roll_joint" forcerange="-2.88021 2.88021" gainprm="61.9511" biasprm="0 -61.9511 -0.973047"/>
    <general name="left_wrist_pitch" class="/" joint="left_wrist_pitch_joint" forcerange="-2.64687 2.64687" gainprm="61.9511" biasprm="0 -61.9511 -0.973047"/>
    <general name="left_jaw" class="/" joint="left_jaw_joint" forcerange="-2.69988 2.69988" gainprm="61.9511" biasprm="0 -61.9511 -0.973047"/>
    <general name="right_shoulder_pitch" class="/" joint="right_shoulder_pitch_joint" forcerange="-24.6165 24.6165" gainprm="61.9511" biasprm="0 -61.9511 -0.973047"/>
    <general name="right_shoulder_roll" class="/" joint="right_shoulder_roll_joint" forcerange="-23.9543 23.9543" gainprm="61.9511" biasprm="0 -61.9511 -0.973047"/>
    <general name="right_shoulder_yaw" class="/" joint="right_shoulder_yaw_joint" forcerange="-21.3307 21.3307" gainprm="61.9511" biasprm="0 -61.9511 -0.973047"/>
    <general name="right_elbow_pitch" class="/" joint="right_elbow_pitch_joint" forcerange="-19.0797 19.0797" gainprm="61.9511" biasprm="0 -61.9511 -0.973047"/>
    <general name="right_wrist_yaw" class="/" joint="right_wrist_yaw_joint" forcerange="-7.01079 7.01079" gainprm="61.9511" biasprm="0 -61.9511 -0.973047"/>
    <general name="right_wrist_roll" class="/" joint="right_wrist_roll_joint" forcerange="-2.77867 2.77867" gainprm="61.9511" biasprm="0 -61.9511 -0.973047"/>
    <general name="right_wrist_pitch" class="/" joint="right_wrist_pitch_joint" forcerange="-3.00292 3.00292" gainprm="61.9511" biasprm="0 -61.9511 -0.973047"/>
    <general name="right_jaw" class="/" joint="right_jaw_joint" forcerange="-2.73285 2.73285" gainprm="61.9511" biasprm="0 -61.9511 -0.973047"/>
    <general name="head_roll" class="/" joint="head_roll_joint" forcerange="-2.48532 2.48532" gainprm="61.9511" biasprm="0 -61.9511 -0.973047"/>
    <general name="head_pitch" class="/" joint="head_pitch_joint" forcerange="-2.61572 2.61572" gainprm="61.9511" biasprm="0 -61.9511 -0.973047"/>
    <general name="head_yaw" class="/" joint="head_yaw_joint" forcerange="-2.65611 2.65611" gainprm="61.9511" biasprm="0 -61.9511 -0.973047"/>
  </actuator>

  <sensor>
    <gyro site="imu" name="imu_angular_velocity"/>
    <velocimeter site="imu" name="imu_linear_velocity"/>
    <framelinvel objtype="site" objname="left_foot" name="left_foot_global_linear_velocity"/>
    <framelinvel objtype="site" objname="right_foot" name="right_foot_global_linear_velocity"/>
  </sensor>

  <keyframe>
    <key name="home" qpos="0 0 0.8665 1 0 0 0 0 0 -0.4 0.8 -0.4 0 0 0 0.4 -0.8 0.4 0 0 0 0 0 -0.2 0 -0.785 0 0 0 0 0 0.2 0 0.785 0 0 0 0 0 0 0"/>
  </keyframe>
</mujoco>
