<mujoco model="GR1T2_jaw">
  <compiler angle="radian" assetdir="assets" balanceinertia="true" inertiafromgeom="false"/>

  <option timestep="0.005" density="1.2" viscosity="2e-05"/>

  <size nkey="1"/>

  <visual>
    <quality shadowsize="8192"/>
    <map shadowclip="0.5"/>
  </visual>

  <default>
    <default class="/">
      <joint armature="0.1" damping="0.01" frictionloss="0.1"/>
      <geom contype="0" conaffinity="0" group="1" solref="-1000 -80"/>
      <site size="0.01 0.005 0.005" group="5"/>
      <general forcelimited="true" biastype="affine" gainprm="80" biasprm="0 -80 -2"/>
      <default class="visual">
        <geom type="mesh" density="0" rgba="0.18 0.18 0.18 1"/>
      </default>
      <default class="collision">
        <geom group="3"/>
      </default>
      <default class="foot">
        <geom size="0.126 0.045 0.01" type="box" condim="6" group="4" priority="1" solimp="0.015 1 0.01"/>
      </default>
      <default class="reward_collision_sphere">
        <geom group="5" rgba="1 0 0 1"/>
      </default>
    </default>
  </default>

  <asset>
    <texture type="skybox" colorspace="auto" name="//unnamed_texture_0" builtin="gradient" rgb1="0.95 0.95 0.95" rgb2="0.95 0.95 0.95" width="100" height="600"/>
    <texture type="2d" colorspace="auto" name="texplane" builtin="checker" rgb1="0.345 0.575 0.748" rgb2="0.345 0.575 0.748" markrgb="1 1 1" width="512" height="512"/>
    <material name="MatPlane" class="/" texture="texplane" texuniform="true" texrepeat="2 2" specular="0.9"/>
    <mesh name="base_link" class="/" file="base_link.STL"/>
    <mesh name="left_thigh_roll_link" class="/" file="left_thigh_roll_link.STL"/>
    <mesh name="left_thigh_yaw_link" class="/" file="left_thigh_yaw_link.STL"/>
    <mesh name="left_thigh_pitch_link" class="/" file="left_thigh_pitch_link.STL"/>
    <mesh name="left_shank_pitch_link" class="/" file="left_shank_pitch_link.STL"/>
    <mesh name="left_foot_pitch_link" class="/" file="left_foot_pitch_link.STL"/>
    <mesh name="left_foot_roll_link" class="/" file="left_foot_roll_link.STL"/>
    <mesh name="right_thigh_roll_link" class="/" file="right_thigh_roll_link.STL"/>
    <mesh name="right_thigh_yaw_link" class="/" file="right_thigh_yaw_link.STL"/>
    <mesh name="right_thigh_pitch_link" class="/" file="right_thigh_pitch_link.STL"/>
    <mesh name="right_shank_pitch_link" class="/" file="right_shank_pitch_link.STL"/>
    <mesh name="right_foot_pitch_link" class="/" file="right_foot_pitch_link.STL"/>
    <mesh name="right_foot_roll_link" class="/" file="right_foot_roll_link.STL"/>
    <mesh name="waist_yaw_link" class="/" file="waist_yaw_link.STL"/>
    <mesh name="waist_pitch_link" class="/" file="waist_pitch_link.STL"/>
    <mesh name="waist_roll_link" class="/" file="waist_roll_link.STL"/>
    <mesh name="torso_link" class="/" file="torso_link.STL"/>
    <mesh name="left_upper_arm_pitch_link" class="/" file="left_upper_arm_pitch_link.STL"/>
    <mesh name="left_upper_arm_roll_link" class="/" file="left_upper_arm_roll_link.STL"/>
    <mesh name="left_upper_arm_yaw_link" class="/" file="left_upper_arm_yaw_link.STL"/>
    <mesh name="left_lower_arm_pitch_link" class="/" file="left_lower_arm_pitch_link.STL"/>
    <mesh name="left_hand_yaw_link" class="/" file="left_hand_yaw_link.STL"/>
    <mesh name="left_hand_roll_link" class="/" file="left_hand_roll_link.STL"/>
    <mesh name="left_hand_pitch" class="/" file="left_hand_pitch.STL"/>
    <mesh name="left_jaw_link" class="/" file="left_jaw_link.STL"/>
    <mesh name="right_upper_arm_pitch_link" class="/" file="right_upper_arm_pitch_link.STL"/>
    <mesh name="right_upper_arm_roll_link" class="/" file="right_upper_arm_roll_link.STL"/>
    <mesh name="right_upper_arm_yaw_link" class="/" file="right_upper_arm_yaw_link.STL"/>
    <mesh name="right_lower_arm_pitch_link" class="/" file="right_lower_arm_pitch_link.STL"/>
    <mesh name="right_hand_yaw_link" class="/" file="right_hand_yaw_link.STL"/>
    <mesh name="right_hand_roll_link" class="/" file="right_hand_roll_link.STL"/>
    <mesh name="right_hand_pitch" class="/" file="right_hand_pitch.STL"/>
    <mesh name="right_jaw_link" class="/" file="right_jaw_link.STL"/>
    <mesh name="head_roll_link" class="/" file="head_roll_link.STL"/>
    <mesh name="head_pitch_link" class="/" file="head_pitch_link.STL"/>
    <mesh name="head_yaw_link" class="/" file="head_yaw_link.STL"/>
    <mesh name="imu_link" class="/" file="imu_link.STL"/>
  </asset>

  <worldbody>
    <geom name="floor" class="/" size="100 100 0.125" type="plane" group="0" material="MatPlane"/>
    <light name="toplight_shadow" class="/" pos="0 0 5" dir="0.0990148 0.0990148 -0.990148" type="directional" ambient="0.04 0.04 0.04" diffuse="0.55 0.55 0.55" specular="0.12 0.12 0.12"/>
    <light name="toplight_fill" class="/" pos="0 0 5" dir="0.0990148 0.0990148 -0.990148" type="directional" castshadow="false" ambient="0.04 0.04 0.04" diffuse="0.3 0.3 0.3" specular="0.08 0.08 0.08"/>
    <body name="trunk" pos="-0.000989116 8.13075e-05 0.000969722" quat="1 -0.000299045 7.74059e-05 -9.11811e-05">
      <inertial pos="-0.0651466 0.00264694 -0.00814535" quat="1 -0.000113672 -0.000235928 -6.57845e-06" mass="2.183" diaginertia="0.0608339 0.00075917 0.01363"/>
      <joint name="//unnamed_joint_0" type="free"/>
      <geom name="//unnamed_geom_1" class="visual" rgba="0.12 0.12 0.12 1" mesh="base_link"/>
      <geom name="base_link.STL" class="collision" size="0.0992335 0.0555787" pos="-0.0458599 0.000208053 0.00730467" quat="0.706838 -0.707359 0.00477667 0" type="cylinder" rgba="0.752941 0.752941 0.752941 1"/>
      <geom name="//unnamed_geom_3" class="visual" pos="0 0 -0.0472697" quat="1 0 0 0" rgba="0.12 0.12 0.12 1" mesh="imu_link"/>
      <geom name="//unnamed_geom_4" class="reward_collision_sphere" size="0.0648617" pos="0 0.0562242 0.0793116"/>
      <geom name="//unnamed_geom_5" class="reward_collision_sphere" size="0.0648617" pos="0 -0.0562242 0.0793116"/>
      <site name="imu" class="/" pos="0.00446986 -0.00476392 -0.0439485" size="0.00810771"/>
      <camera name="track" class="/" pos="0 -1.12448 0" quat="0.707107 0.707107 0 0" mode="trackcom"/>
      <body name="left_thigh_roll_link" pos="-0.0380447 0.0612559 -0.0219832" quat="1 -0.000381699 -0.0005369 -8.97184e-07">
        <inertial pos="-0.00253921 -0.00233825 0.00196638" quat="-0.0334239 0.70213 -0.0329521 0.7105" mass="0.786664" diaginertia="0.0037917 0.000139966 0.000500165"/>
        <joint name="left_hip_roll_joint" class="/" pos="0 0 0" axis="-1 -0.000652755 0.000435251" stiffness="0.000326826" range="-0.809135 0.146479" armature="0.0759929" damping="0.0077317" frictionloss="0.0829779"/>
        <geom name="//unnamed_geom_6" class="visual" mesh="left_thigh_roll_link"/>
        <body name="left_thigh_yaw_link" pos="0.033214 0.000108834 0.00128186" quat="0.999999 0.000955734 -0.000415756 0.000676227">
          <inertial pos="-0.00600242 0.0203222 -0.087712" quat="0.571422 0.0921482 -0.199105 0.790786" mass="1.81554" diaginertia="0.0341276 0.00107553 0.0027321"/>
          <joint name="left_hip_yaw_joint" class="/" pos="0 0 0" axis="0.00425717 -0.00312983 -0.999986" range="-0.717802 0.652976" armature="0.0845355" damping="0.000898661" frictionloss="0.0787422"/>
          <geom name="//unnamed_geom_7" class="visual" mesh="left_thigh_yaw_link"/>
          <body name="left_thigh_pitch_link" pos="-0.00270584 0.0156785 -0.108491" quat="1 3.07366e-05 -0.000126384 9.42461e-05">
            <inertial pos="0.000572964 -0.0156621 -0.0490267" quat="0.999807 -0.0156853 -0.0095059 0.00698242" mass="4.35842" diaginertia="0.133004 0.00495877 0.00872906"/>
            <joint name="left_hip_pitch_joint" class="/" pos="0 0 0" axis="0.000111941 0.999998 -0.00187754" range="-1.7306 0.705953" armature="0.0841914" damping="0.0103419" frictionloss="0.0712377"/>
            <geom name="//unnamed_geom_8" class="visual" mesh="left_thigh_pitch_link"/>
            <geom name="left_thigh_pitch_link.STL" class="collision" size="0.0664832 0.101277" pos="0.000753923 -0.0168673 -0.132495" type="cylinder" rgba="0.752941 0.752941 0.752941 1"/>
            <geom name="//unnamed_geom_10" class="reward_collision_sphere" size="0.0810771" pos="0 -0.00562242 -0.0396558"/>
            <body name="left_shank_pitch_link" pos="0.0015029 -0.0127943 -0.284767" quat="0.999999 -0.000665383 0.000584883 0.000674359">
              <inertial pos="0.00196821 -0.00408092 -0.0931554" quat="0.999693 -0.00823222 0.00815046 -0.0219062" mass="0.92001" diaginertia="0.0152445 0.000591938 0.000387896"/>
              <joint name="left_knee_pitch_joint" class="/" pos="0 0 0" axis="-0.0114255 0.999918 -0.00579903" range="-0.102513 1.87602" armature="0.0875839" damping="0.00398592" frictionloss="0.0820756"/>
              <geom name="//unnamed_geom_11" class="visual" mesh="left_shank_pitch_link"/>
              <geom name="left_shank_pitch_link.STL" class="collision" size="0.0432314 0.0732815" pos="-1.78668e-05 -0.000473716 -0.13855" quat="0.00125538 -0.202712 0.979238 0" type="cylinder" rgba="0.752941 0.752941 0.752941 1"/>
              <geom name="//unnamed_geom_13" class="reward_collision_sphere" size="0.0405386"/>
              <geom name="//unnamed_geom_14" class="reward_collision_sphere" size="0.0486463" pos="0 0 -0.0872428"/>
              <body name="left_foot_pitch_link" pos="-0.00247836 -0.00252762 -0.26785" quat="1 -9.67721e-06 -4.47871e-07 5.20563e-07">
                <inertial pos="0.000590397 -0.0013785 -0.000536947" quat="-6.18663e-05 0.707237 -0.00046926 0.706976" mass="0.0321476" diaginertia="9.79356e-06 3.29561e-07 1.68145e-06"/>
                <joint name="left_ankle_pitch_joint" class="/" pos="0 0 0" axis="0.00184642 0.999997 0.00166249" range="-1.08442 0.520569" armature="0.0781387" damping="0.000262679" frictionloss="0.0771366"/>
                <geom name="//unnamed_geom_15" class="visual" mesh="left_foot_pitch_link"/>
                <body name="left_foot_roll_link" pos="-0.00218825 -0.00137866 0.000640555" quat="0.999999 -0.00103577 -0.000322161 0.00065166">
                  <inertial pos="0.0398488 -0.0025995 -0.0282773" quat="-0.000850418 0.724573 -0.00193191 0.689195" mass="0.554487" diaginertia="0.00805247 0.000289356 0.000234278"/>
                  <joint name="left_ankle_roll_joint" class="/" pos="0 0 0" axis="-0.999935 -0.0108447 0.00345789" range="-0.467082 0.453478" armature="0.0821742" damping="0.00125138" frictionloss="0.078896"/>
                  <geom name="//unnamed_geom_16" class="visual" mesh="left_foot_roll_link"/>
                  <geom name="left_foot" class="foot" size="0.149002 0.0403281 0.00808088" pos="0.048463 0 -0.0352937"/>
                  <geom name="//unnamed_geom_18" class="reward_collision_sphere" size="0.0405386" pos="0 0 -0.0237935"/>
                  <geom name="//unnamed_geom_19" class="reward_collision_sphere" size="0.0405386" pos="0.129235 0 -0.0237935"/>
                  <site name="left_foot" class="foot" pos="0.048463 0 -0.0352937" size="0.00810771"/>
                </body>
              </body>
            </body>
          </body>
        </body>
      </body>
      <body name="right_thigh_roll_link" pos="-0.0357059 -0.0638321 -0.022424" quat="0.999999 -0.000312303 -0.000777301 0.000783902">
        <inertial pos="0.00107491 -0.00416877 0.00114261" quat="0.0276612 0.70523 0.0179201 0.708212" mass="0.792334" diaginertia="0.00375647 0.000142956 0.000500192"/>
        <joint name="right_hip_roll_joint" class="/" pos="0 0 0" axis="-0.999886 0.0151205 0.000352017" range="-0.120176 0.78671" armature="0.0713681" damping="0.00663032" frictionloss="0.0725017"/>
        <geom name="//unnamed_geom_20" class="visual" mesh="right_thigh_roll_link"/>
        <body name="right_thigh_yaw_link" pos="0.033803 -0.00501599 0.00081435" quat="0.999999 -0.00034012 0.000346223 0.000879546">
          <inertial pos="-0.00248335 -0.0232429 -0.087441" quat="0.686814 -0.147771 0.150108 0.695642" mass="1.89096" diaginertia="0.0351097 0.00109567 0.0028722"/>
          <joint name="right_hip_yaw_joint" class="/" pos="0 0 0" axis="-0.000231468 0.0122939 -0.999924" range="-0.69762 0.676341" armature="0.0801574" damping="0.0100649" frictionloss="0.0805441"/>
          <geom name="//unnamed_geom_21" class="visual" mesh="right_thigh_yaw_link"/>
          <body name="right_thigh_pitch_link" pos="-0.00270445 -0.0152919 -0.109623" quat="1 0.00059771 0.000384908 0.00037369">
            <inertial pos="0.000728522 0.013891 -0.0494479" quat="0.999803 -0.0174645 -0.0034273 0.00874163" mass="4.59496" diaginertia="0.140641 0.00519487 0.00932603"/>
            <joint name="right_hip_pitch_joint" class="/" pos="0 0 0" axis="0.00101017 -0.999963 -0.00850162" range="-0.688915 1.75301" armature="0.0809604" damping="0.0285278" frictionloss="0.073939"/>
            <geom name="//unnamed_geom_22" class="visual" mesh="right_thigh_pitch_link"/>
            <geom name="right_thigh_pitch_link.STL" class="collision" size="0.0664832 0.101274" pos="-0.00228667 0.0168673 -0.132495" quat="0.999971 0.00269833 0.00706272 0" type="cylinder" rgba="0.752941 0.752941 0.752941 1"/>
            <geom name="//unnamed_geom_24" class="reward_collision_sphere" size="0.0810771" pos="0 0.00562242 -0.0396558"/>
            <body name="right_shank_pitch_link" pos="0.000586436 0.00775841 -0.285031" quat="1 -0.000288165 -0.000341024 1.01652e-05">
              <inertial pos="-0.000764868 -0.00110229 -0.0907418" quat="0.999369 0.0048558 0.0133921 0.0325386" mass="0.932937" diaginertia="0.0154682 0.000590098 0.000388225"/>
              <joint name="right_knee_pitch_joint" class="/" pos="0 0 0" axis="0.00115272 -0.999897 0.0143035" stiffness="0.00169819" range="-1.96384 0.12322" armature="0.0806991" damping="0.0190414" frictionloss="0.0740463"/>
              <geom name="//unnamed_geom_25" class="visual" mesh="right_shank_pitch_link"/>
              <geom name="right_shank_pitch_link.STL" class="collision" size="0.0432312 0.0732808" pos="-1.78668e-05 -0.000473721 -0.138557" type="cylinder" rgba="0.752941 0.752941 0.752941 1"/>
              <geom name="//unnamed_geom_27" class="reward_collision_sphere" size="0.0405386"/>
              <geom name="//unnamed_geom_28" class="reward_collision_sphere" size="0.0486463" pos="0 0 -0.0872428"/>
              <body name="right_foot_pitch_link" pos="0.00121815 -0.00314121 -0.271606" quat="1 3.11733e-05 0.000270882 -0.000246979">
                <inertial pos="2.52293e-05 -0.00268638 -0.000344194" quat="-0.000327763 0.708387 0.000431667 0.705824" mass="0.0294354" diaginertia="8.90721e-06 3.0259e-07 1.61503e-06"/>
                <joint name="right_ankle_pitch_joint" class="/" pos="0 0 0" axis="0.000356377 -0.999999 0.00169299" range="-0.576446 1.06105" armature="0.0785461" damping="0.0025648" frictionloss="0.0824943"/>
                <geom name="//unnamed_geom_29" class="visual" mesh="right_foot_pitch_link"/>
                <body name="right_foot_roll_link" pos="0.00128307 0.00022859 0.000234794" quat="1 0.000221161 -0.000482777 -0.000816327">
                  <inertial pos="0.0422842 -0.000648388 -0.0314414" quat="-0.00985832 0.723845 0.00191939 0.689889" mass="0.566253" diaginertia="0.00815132 0.00028781 0.000238631"/>
                  <joint name="right_ankle_roll_joint" class="/" pos="0 0 0" axis="-1 -0.000470392 -2.207e-05" range="-0.451536 0.441839" armature="0.0839232" damping="0.00739471" frictionloss="0.0801368"/>
                  <geom name="//unnamed_geom_30" class="visual" mesh="right_foot_roll_link"/>
                  <geom name="right_foot" class="foot" size="0.145288 0.0360865 0.00778743" pos="0.048463 0 -0.0352937"/>
                  <geom name="//unnamed_geom_32" class="reward_collision_sphere" size="0.0405386" pos="0 0 -0.0237935"/>
                  <geom name="//unnamed_geom_33" class="reward_collision_sphere" size="0.0405386" pos="0.129235 0 -0.0237935"/>
                  <site name="right_foot" class="foot" pos="0.048463 0 -0.0352937" size="0.00810771"/>
                </body>
              </body>
            </body>
          </body>
        </body>
      </body>
      <body name="waist_yaw_link" pos="0.00404682 0.000662089 0.00406454" quat="1 0.000924119 -0.000138026 0.000183442">
        <inertial pos="-0.000268243 -0.00548402 0.0414648" quat="0.980502 0.186449 -0.0346778 0.051479" mass="0.884007" diaginertia="0.00515666 0.000186367 0.000648924"/>
        <joint name="waist_yaw_joint" class="/" pos="0 0 0" axis="-0.0124811 -0.00595417 0.999904" range="-1.04858 1.03542" armature="0.0859957" damping="0.000459566" frictionloss="0.0852526"/>
        <geom name="//unnamed_geom_34" class="visual" rgba="0.12 0.12 0.12 1" mesh="waist_yaw_link"/>
        <body name="waist_pitch_link" pos="0.00150967 0.00215421 0.0684385" quat="1 -0.000362691 0.000158118 4.74648e-05">
          <inertial pos="0.004052 0.000738493 0.0327631" quat="0.997041 -0.051954 0.0556471 0.0106826" mass="0.838143" diaginertia="0.00686568 0.000261159 0.000561631"/>
          <joint name="waist_pitch_joint" class="/" pos="0 0 0" axis="-0.00487946 -0.999844 -0.0169951" range="-1.2171 0.475057" armature="0.0792307" damping="0.00294279" frictionloss="0.0819367"/>
          <geom name="//unnamed_geom_35" class="visual" rgba="0.12 0.12 0.12 1" mesh="waist_pitch_link"/>
          <body name="waist_roll_link" pos="0.0100992 0.000771675 0.0677195" quat="1 -2.55791e-05 5.11621e-05 2.92122e-05">
            <inertial pos="-0.0150142 0.000825803 0.117273" quat="0.99869 -0.0044891 -0.0509337 0.00195718" mass="3.5166" diaginertia="0.0912056 0.00321048 0.0110002"/>
            <joint name="waist_roll_joint" class="/" pos="0 0 0" axis="-0.999922 0.0121812 0.00292735" range="-0.732727 0.729721" armature="0.0755935" damping="0.00952004" frictionloss="0.0713807"/>
            <geom name="//unnamed_geom_36" class="visual" rgba="0.12 0.12 0.12 1" mesh="waist_roll_link"/>
            <geom name="//unnamed_geom_37" class="visual" pos="-0.00242315 0.000322969 0.127176" quat="1 0 0 0" mesh="torso_link"/>
            <geom name="torso_link.STL" class="collision" size="0.127637 0.0244796" pos="-0.0194562 0.00324403 0.117246" type="cylinder" rgba="0.752941 0.752941 0.752941 1"/>
            <geom name="//unnamed_geom_39" class="reward_collision_sphere" size="0.1054" pos="0 0 0.158623"/>
            <body name="left_upper_arm_pitch_link" pos="0.00107164 0.0545248 0.163975" quat="0.976734 0.214454 0.000384021 0.000153819">
              <inertial pos="0.00476173 0.0266566 -0.0001626" quat="0.704245 0.707962 0.00320385 -0.0530971" mass="0.443607" diaginertia="0.00300774 0.00011154 0.000156489"/>
              <joint name="left_shoulder_pitch_joint" class="/" pos="0 0 0" axis="-0.00357422 0.99999 -0.00275714" range="-2.80149 1.92145" armature="0.0863383" damping="0" frictionloss="0.0769852"/>
              <geom name="//unnamed_geom_40" class="visual" mesh="left_upper_arm_pitch_link"/>
              <body name="left_upper_arm_roll_link" pos="0.000102757 0.0482499 0.00103383" quat="0.976711 -0.214555 0.000763081 -0.000762102">
                <inertial pos="0.00508641 0.0069947 -0.0187657" quat="0.889598 0.268406 0.124714 -0.34788" mass="0.318741" diaginertia="0.001471 5.60065e-05 0.000108556"/>
                <joint name="left_shoulder_roll_joint" class="/" pos="0 0 0" axis="-0.999996 -0.00238379 0.00131055" range="-2.57384 0.556645" armature="0.0803872" damping="0" frictionloss="0.0816014"/>
                <geom name="//unnamed_geom_41" class="visual" mesh="left_upper_arm_roll_link"/>
                <body name="left_upper_arm_yaw_link" pos="0.0034348 0.0205284 -0.0571465" quat="1 0.000418428 0.000491295 -0.000428749">
                  <inertial pos="-0.000231477 -0.00137961 -0.0700414" quat="0.999952 0.00710228 0.000111737 -0.00673108" mass="0.293427" diaginertia="0.0051668 0.000198424 8.28641e-05"/>
                  <joint name="left_shoulder_yaw_joint" class="/" pos="0 0 0" axis="0.00132233 0.00070372 0.999999" stiffness="5.4147e-05" range="-2.98592 2.98388" armature="0.0811536" damping="0.0105092" frictionloss="0.0767639"/>
                  <geom name="//unnamed_geom_42" class="visual" mesh="left_upper_arm_yaw_link"/>
                  <geom name="left_upper_arm_yaw_link.STL" class="collision" size="0.0293768 0.0688685" pos="4.2524e-05 -0.000502808 -0.0629258" quat="0.00803418 -0.995528 0.0941277 0" type="cylinder" rgba="0.752941 0.752941 0.752941 1"/>
                  <body name="left_lower_arm_pitch_link" pos="0.001153 -0.000548486 -0.141444" quat="1 -0.000355854 0.000564778 -0.000369043">
                    <inertial pos="0.000180797 0.00268702 -0.0193845" quat="0.700355 -0.0910349 0.0981583 0.701128" mass="0.174785" diaginertia="0.000425165 1.6319e-05 2.94968e-05"/>
                    <joint name="left_elbow_pitch_joint" class="/" pos="0 0 0" axis="0.00229616 0.99998 -0.00586773" range="-2.22459 2.2688" armature="0.0807672" damping="0.000165703" frictionloss="0.0788169"/>
                    <geom name="//unnamed_geom_44" class="visual" mesh="left_lower_arm_pitch_link"/>
                    <body name="left_hand_yaw_link" pos="0.00163264 -0.00180841 -0.0491475" quat="0.999999 0.000466116 -0.000447319 0.000816598">
                      <inertial pos="-0.000716409 0.000621417 -0.057372" quat="0.999887 -0.00856788 0.00429021 0.0115426" mass="0.527196" diaginertia="0.00367609 0.000138837 0.000155878"/>
                      <joint name="left_wrist_yaw_joint" class="/" pos="0 0 0" axis="0.00097303 0.000375987 0.999999" stiffness="0.000873928" range="-2.95713 3.0219" armature="0.0891068" damping="0.00266475" frictionloss="0.0812305"/>
                      <geom name="//unnamed_geom_45" class="visual" mesh="left_hand_yaw_link"/>
                      <geom name="left_hand_yaw_link.STL" class="collision" size="0.0337053 0.0564246" pos="0.00117307 -0.000866477 -0.0603108" type="cylinder" rgba="0.752941 0.752941 0.752941 1"/>
                      <geom name="//unnamed_geom_47" class="reward_collision_sphere" size="0.0405386"/>
                      <body name="left_hand_roll_link" pos="-0.00165988 -0.00159818 -0.153787" quat="1 -0.000253288 1.8255e-06 4.10004e-05">
                        <inertial pos="0.000543273 -0.0022288 0.00262837" quat="0.49933 0.50376 0.506791 0.489957" mass="0.0026227" diaginertia="4.96647e-07 1.93007e-08 2.21676e-08"/>
                        <joint name="left_wrist_roll_joint" class="/" pos="0 0 0" axis="-0.999969 -0.00662484 0.00435507" range="-0.907396 0.840384" armature="0.0813277" damping="0.00102715" frictionloss="0.0724412"/>
                        <geom name="//unnamed_geom_48" class="visual" mesh="left_hand_roll_link"/>
                        <body name="left_hand_pitch_link" pos="-0.000699321 -0.00132101 -0.000598641" quat="1 -1.23828e-05 0.000281981 0.000453393">
                          <inertial pos="-0.00234607 -0.00834163 -0.0444175" quat="0.719955 -0.131805 0.116889 0.67129" mass="0.114431" diaginertia="0.000404036 1.46498e-05 2.89717e-05"/>
                          <joint name="left_wrist_pitch_joint" class="/" pos="0 0 0" axis="0.00361627 0.999992 0.00148648" range="-0.548332 0.606388" armature="0.0797371" damping="0.00557919" frictionloss="0.0706078"/>
                          <geom name="//unnamed_geom_49" class="visual" mesh="left_hand_pitch"/>
                          <body name="left_jaw_link" pos="-0.000605721 -0.000904713 -0.0479945" quat="1 -2.425e-05 -0.00044947 -0.000240242">
                            <inertial pos="-0.000972202 0.00107792 -0.0280643" quat="0.708198 -0.025571 0.0346702 0.704699" mass="0.0376474" diaginertia="0.000117613 3.19566e-06 1.03147e-05"/>
                            <joint name="left_jaw_joint" class="/" pos="0 0 0" axis="-0.999993 0.00340271 0.00122379" range="-0.979686 -0.0178531" armature="0.0821771" damping="0.00281384" frictionloss="0.075019"/>
                            <geom name="//unnamed_geom_50" class="visual" mesh="left_jaw_link"/>
                            <geom name="//unnamed_geom_51" class="collision" size="0.0291878"/>
                            <geom name="//unnamed_geom_52" class="reward_collision_sphere" size="0.0405386" pos="0 0 -0.0158623"/>
                          </body>
                        </body>
                      </body>
                    </body>
                  </body>
                </body>
              </body>
            </body>
            <body name="right_upper_arm_pitch_link" pos="-9.79293e-05 -0.0546179 0.163487" quat="0.976701 -0.214606 -0.000104833 0.00014538">
              <inertial pos="0.00319197 -0.0301049 -0.00277727" quat="0.705859 0.70746 0.0280053 0.0218876" mass="0.433241" diaginertia="0.00289927 0.000110766 0.000158151"/>
              <joint name="right_shoulder_pitch_joint" class="/" pos="0 0 0" axis="0.00747029 -0.999961 0.00474814" range="-1.8916 2.80811" armature="0.0847084" damping="0.00148508" frictionloss="0.0835884"/>
              <geom name="//unnamed_geom_53" class="visual" mesh="right_upper_arm_pitch_link"/>
              <body name="right_upper_arm_roll_link" pos="0.00299399 -0.0517443 0.00123792" quat="0.976685 0.214676 -1.39608e-05 1.02004e-05">
                <inertial pos="0.00266406 -0.0109478 -0.0204751" quat="0.887822 -0.26681 0.124273 0.353753" mass="0.317048" diaginertia="0.00144967 5.52469e-05 0.000107516"/>
                <joint name="right_shoulder_roll_joint" class="/" pos="0 0 0" axis="-0.999989 0.00322137 -0.00326631" range="-0.572191 2.53863" armature="0.0740787" damping="0.00622188" frictionloss="0.0906883"/>
                <geom name="//unnamed_geom_54" class="visual" mesh="right_upper_arm_roll_link"/>
                <body name="right_upper_arm_yaw_link" pos="0.000684642 -0.0230761 -0.0548835" quat="0.999999 0.000837153 -0.000134896 -0.000580976">
                  <inertial pos="-0.00296842 -0.00073472 -0.0681999" quat="0.999959 -0.0089096 0.0013133 -0.000684492" mass="0.292887" diaginertia="0.00538838 0.000203128 8.32539e-05"/>
                  <joint name="right_shoulder_yaw_joint" class="/" pos="0 0 0" axis="-0.000690016 0.000266116 1" range="-2.97532 2.95181" armature="0.0819263" damping="0" frictionloss="0.0819207"/>
                  <geom name="//unnamed_geom_55" class="visual" mesh="right_upper_arm_yaw_link"/>
                  <geom name="right_upper_arm_yaw_link.STL" class="collision" size="0.0293768 0.0688685" pos="4.2524e-05 0.000502808 -0.0629258" type="cylinder" rgba="0.752941 0.752941 0.752941 1"/>
                  <body name="right_lower_arm_pitch_link" pos="-0.000204798 0.00198677 -0.141838" quat="1 -1.2002e-05 5.83313e-06 1.7087e-05">
                    <inertial pos="-0.000490334 -0.00567154 -0.0174156" quat="0.701619 0.0913313 -0.0931046 0.700515" mass="0.176276" diaginertia="0.000437068 1.62321e-05 3.13692e-05"/>
                    <joint name="right_elbow_pitch_joint" class="/" pos="0 0 0" axis="-0.0060941 -0.999902 -0.0125723" range="-2.231 2.32076" armature="0.0802634" damping="0.00320271" frictionloss="0.0821397"/>
                    <geom name="//unnamed_geom_57" class="visual" mesh="right_lower_arm_pitch_link"/>
                    <body name="right_hand_yaw_link" pos="0.00121062 0.00234686 -0.0489065" quat="1 -2.48452e-05 2.80904e-05 2.28226e-05">
                      <inertial pos="7.49269e-05 -0.00168892 -0.0581739" quat="0.99962 0.00747155 0.00222288 0.0264215" mass="0.532758" diaginertia="0.00369032 0.000141266 0.000155876"/>
                      <joint name="right_wrist_yaw_joint" class="/" pos="0 0 0" axis="0.00255104 -0.00339209 0.999991" range="-2.9945 2.98037" armature="0.0855041" damping="0" frictionloss="0.0812467"/>
                      <geom name="//unnamed_geom_58" class="visual" mesh="right_hand_yaw_link"/>
                      <geom name="right_hand_yaw_link.STL" class="collision" size="0.0337053 0.0564246" pos="0.00117307 0.000360461 -0.0603108" type="cylinder" rgba="0.752941 0.752941 0.752941 1"/>
                      <geom name="//unnamed_geom_60" class="reward_collision_sphere" size="0.0405386"/>
                      <body name="right_hand_roll_link" pos="0.00385077 0.00253711 -0.153585" quat="1 0.000206915 5.42736e-05 0.000124973">
                        <inertial pos="-0.000100952 -0.00321788 -2.82851e-05" quat="0.500202 0.499962 0.499905 0.499931" mass="0.0027503" diaginertia="5.12772e-07 1.97017e-08 2.13674e-08"/>
                        <joint name="right_wrist_roll_joint" class="/" pos="0 0 0" axis="-0.99998 0.00172223 -0.00600487" range="-0.88577 0.977689" armature="0.0754662" damping="0.0120419" frictionloss="0.0805731"/>
                        <geom name="//unnamed_geom_61" class="visual" mesh="right_hand_roll_link"/>
                        <body name="right_hand_pitch_link" pos="0.00310272 -0.000306656 0.00233349" quat="1 -3.87839e-06 4.53914e-06 8.07309e-07">
                          <inertial pos="1.78685e-05 0.00653006 -0.0425226" quat="0.727344 0.118331 -0.108959 0.667155" mass="0.117823" diaginertia="0.000410544 1.49717e-05 2.94553e-05"/>
                          <joint name="right_wrist_pitch_joint" class="/" pos="0 0 0" axis="0.000522178 -0.999999 0.000978509" range="-0.572744 0.633274" armature="0.0824808" damping="0.00300218" frictionloss="0.0912253"/>
                          <geom name="//unnamed_geom_62" class="visual" mesh="right_hand_pitch"/>
                          <body name="right_jaw_link" pos="-0.000895327 0.00332023 -0.0478613" quat="1 3.26224e-05 -7.22854e-05 -1.13975e-05">
                            <inertial pos="-0.00172933 -0.00346556 -0.0251726" quat="0.710063 0.0193935 -0.0324665 0.703122" mass="0.0382111" diaginertia="0.00011421 3.1471e-06 1.03596e-05"/>
                            <joint name="right_jaw_joint" class="/" pos="0 0 0" axis="-0.999998 -0.0013269 0.00121247" range="-0.00717911 1.03206" armature="0.08181" damping="0.000818102" frictionloss="0.0820157"/>
                            <geom name="//unnamed_geom_63" class="visual" mesh="right_jaw_link"/>
                            <geom name="//unnamed_geom_64" class="collision" size="0.0291878"/>
                            <geom name="//unnamed_geom_65" class="reward_collision_sphere" size="0.0405386" pos="0 0 -0.0158623"/>
                          </body>
                        </body>
                      </body>
                    </body>
                  </body>
                </body>
              </body>
            </body>
            <body name="head_roll_link" pos="-0.00104703 0.00178007 0.244069" quat="1 -0.000560513 0.000294421 -0.000589066">
              <inertial pos="0.00373136 -0.00280526 -0.000179511" quat="8.4867e-05 0.707275 -9.65574e-05 0.706938" mass="0.00557257" diaginertia="1.0474e-06 2.55387e-08 1.40511e-07"/>
              <joint name="head_roll_joint" class="/" pos="0 0 0" axis="-0.999997 -0.00206895 -0.00100946" range="-0.358996 0.359332" armature="0.0824592" damping="0.00497766" frictionloss="0.0877843"/>
              <geom name="//unnamed_geom_66" class="visual" mesh="head_roll_link"/>
              <body name="head_pitch_link" pos="0.00145132 -0.000597641 0.00144624" quat="1 -0.00014932 -0.000199723 -1.26285e-05">
                <inertial pos="-0.00123221 0.000536685 0.0158391" quat="0.67163 0.660143 0.23685 -0.238802" mass="0.0317577" diaginertia="3.80532e-05 1.34799e-06 5.3781e-06"/>
                <joint name="head_pitch_joint" class="/" pos="0 0 0" axis="0.00617262 -0.999979 -0.00176247" range="-0.834842 0.868759" armature="0.0830783" damping="0.01795" frictionloss="0.0803476"/>
                <geom name="//unnamed_geom_67" class="visual" mesh="head_pitch_link"/>
                <body name="head_yaw_link" pos="0.00240319 -1.11055e-05 0.0420939" quat="1 -0.000505638 -6.64325e-06 3.10712e-05">
                  <inertial pos="0.0287508 -0.00243736 0.0756469" quat="0.704289 -0.137571 -0.14173 0.681883" mass="0.814709" diaginertia="0.0145017 0.00043226 0.00156134"/>
                  <joint name="head_yaw_joint" class="/" pos="0 0 0" axis="0.00113421 0.00606107 0.999981" range="-2.70254 2.74286" armature="0.0845018" damping="0.0143856" frictionloss="0.0822717"/>
                  <geom name="//unnamed_geom_68" class="visual" rgba="0.12 0.12 0.12 1" mesh="head_yaw_link"/>
                  <geom name="head_yaw_link.STL" class="collision" size="0.096228" pos="0.0196879 -0.000494787 0.0742517" rgba="0.752941 0.752941 0.752941 1"/>
                  <geom name="//unnamed_geom_70" class="reward_collision_sphere" size="0.0810771" pos="0.0323086 0 0.0793116"/>
                  <camera name="ego_camera" class="/" pos="0.118465 0 0.0872428" quat="-0.5 -0.5 0.5 0.5"/>
                </body>
              </body>
            </body>
          </body>
        </body>
      </body>
    </body>
  </worldbody>

  <contact>
    <pair class="/" geom1="floor" geom2="left_foot" name="//unnamed_contact_0"/>
    <pair class="/" geom1="floor" geom2="right_foot" name="//unnamed_contact_1"/>
  </contact>

  <actuator>
    <general name="left_hip_roll" class="/" joint="left_hip_roll_joint" forcerange="-39.4998 39.4998" gainprm="91.3851" biasprm="0 -91.3851 -0.810771"/>
    <general name="left_hip_yaw" class="/" joint="left_hip_yaw_joint" forcerange="-52.5624 52.5624" gainprm="91.3851" biasprm="0 -91.3851 -0.810771"/>
    <general name="left_hip_pitch" class="/" joint="left_hip_pitch_joint" forcerange="-185.592 185.592" gainprm="91.3851" biasprm="0 -91.3851 -0.810771"/>
    <general name="left_knee_pitch" class="/" joint="left_knee_pitch_joint" forcerange="-175.914 175.914" gainprm="91.3851" biasprm="0 -91.3851 -0.810771"/>
    <general name="left_ankle_pitch" class="/" joint="left_ankle_pitch_joint" forcerange="-11.6496 11.6496" gainprm="91.3851" biasprm="0 -91.3851 -0.810771"/>
    <general name="left_ankle_roll" class="/" joint="left_ankle_roll_joint" forcerange="-23.6399 23.6399" gainprm="91.3851" biasprm="0 -91.3851 -0.810771"/>
    <general name="right_hip_roll" class="/" joint="right_hip_roll_joint" forcerange="-42.4894 42.4894" gainprm="91.3851" biasprm="0 -91.3851 -0.810771"/>
    <general name="right_hip_yaw" class="/" joint="right_hip_yaw_joint" forcerange="-53.1224 53.1224" gainprm="91.3851" biasprm="0 -91.3851 -0.810771"/>
    <general name="right_hip_pitch" class="/" joint="right_hip_pitch_joint" forcerange="-186.806 186.806" gainprm="91.3851" biasprm="0 -91.3851 -0.810771"/>
    <general name="right_knee_pitch" class="/" joint="right_knee_pitch_joint" forcerange="-180.99 180.99" gainprm="91.3851" biasprm="0 -91.3851 -0.810771"/>
    <general name="right_ankle_pitch" class="/" joint="right_ankle_pitch_joint" forcerange="-12.3914 12.3914" gainprm="91.3851" biasprm="0 -91.3851 -0.810771"/>
    <general name="right_ankle_roll" class="/" joint="right_ankle_roll_joint" forcerange="-25.6536 25.6536" gainprm="91.3851" biasprm="0 -91.3851 -0.810771"/>
    <general name="waist_yaw" class="/" joint="waist_yaw_joint" forcerange="-50.0413 50.0413" gainprm="91.3851" biasprm="0 -91.3851 -0.810771"/>
    <general name="waist_pitch" class="/" joint="waist_pitch_joint" forcerange="-56.9495 56.9495" gainprm="91.3851" biasprm="0 -91.3851 -0.810771"/>
    <general name="waist_roll" class="/" joint="waist_roll_joint" forcerange="-52.8333 52.8333" gainprm="91.3851" biasprm="0 -91.3851 -0.810771"/>
    <general name="left_shoulder_pitch" class="/" joint="left_shoulder_pitch_joint" forcerange="-30.0046 30.0046" gainprm="91.3851" biasprm="0 -91.3851 -0.810771"/>
    <general name="left_shoulder_roll" class="/" joint="left_shoulder_roll_joint" forcerange="-31.2557 31.2557" gainprm="91.3851" biasprm="0 -91.3851 -0.810771"/>
    <general name="left_shoulder_yaw" class="/" joint="left_shoulder_yaw_joint" forcerange="-23.0439 23.0439" gainprm="91.3851" biasprm="0 -91.3851 -0.810771"/>
    <general name="left_elbow_pitch" class="/" joint="left_elbow_pitch_joint" forcerange="-25.2439 25.2439" gainprm="91.3851" biasprm="0 -91.3851 -0.810771"/>
    <general name="left_wrist_yaw" class="/" joint="left_wrist_yaw_joint" forcerange="-8.82856 8.82856" gainprm="91.3851" biasprm="0 -91.3851 -0.810771"/>
    <general name="left_wrist_roll" class="/" joint="left_wrist_roll_joint" forcerange="-3.18247 3.18247" gainprm="91.3851" biasprm="0 -91.3851 -0.810771"/>
    <general name="left_wrist_pitch" class="/" joint="left_wrist_pitch_joint" forcerange="-3.18303 3.18303" gainprm="91.3851" biasprm="0 -91.3851 -0.810771"/>
    <general name="left_jaw" class="/" joint="left_jaw_joint" forcerange="-3.26592 3.26592" gainprm="91.3851" biasprm="0 -91.3851 -0.810771"/>
    <general name="right_shoulder_pitch" class="/" joint="right_shoulder_pitch_joint" forcerange="-33.6916 33.6916" gainprm="91.3851" biasprm="0 -91.3851 -0.810771"/>
    <general name="right_shoulder_roll" class="/" joint="right_shoulder_roll_joint" forcerange="-33.6534 33.6534" gainprm="91.3851" biasprm="0 -91.3851 -0.810771"/>
    <general name="right_shoulder_yaw" class="/" joint="right_shoulder_yaw_joint" forcerange="-24.6219 24.6219" gainprm="91.3851" biasprm="0 -91.3851 -0.810771"/>
    <general name="right_elbow_pitch" class="/" joint="right_elbow_pitch_joint" forcerange="-24.8614 24.8614" gainprm="91.3851" biasprm="0 -91.3851 -0.810771"/>
    <general name="right_wrist_yaw" class="/" joint="right_wrist_yaw_joint" forcerange="-8.23771 8.23771" gainprm="91.3851" biasprm="0 -91.3851 -0.810771"/>
    <general name="right_wrist_roll" class="/" joint="right_wrist_roll_joint" forcerange="-3.22862 3.22862" gainprm="91.3851" biasprm="0 -91.3851 -0.810771"/>
    <general name="right_wrist_pitch" class="/" joint="right_wrist_pitch_joint" forcerange="-3.15047 3.15047" gainprm="91.3851" biasprm="0 -91.3851 -0.810771"/>
    <general name="right_jaw" class="/" joint="right_jaw_joint" forcerange="-3.26776 3.26776" gainprm="91.3851" biasprm="0 -91.3851 -0.810771"/>
    <general name="head_roll" class="/" joint="head_roll_joint" forcerange="-3.32341 3.32341" gainprm="91.3851" biasprm="0 -91.3851 -0.810771"/>
    <general name="head_pitch" class="/" joint="head_pitch_joint" forcerange="-3.04324 3.04324" gainprm="91.3851" biasprm="0 -91.3851 -0.810771"/>
    <general name="head_yaw" class="/" joint="head_yaw_joint" forcerange="-3.22777 3.22777" gainprm="91.3851" biasprm="0 -91.3851 -0.810771"/>
  </actuator>

  <sensor>
    <gyro site="imu" name="imu_angular_velocity"/>
    <velocimeter site="imu" name="imu_linear_velocity"/>
    <framelinvel objtype="site" objname="left_foot" name="left_foot_global_linear_velocity"/>
    <framelinvel objtype="site" objname="right_foot" name="right_foot_global_linear_velocity"/>
  </sensor>

  <keyframe>
    <key name="home" qpos="0 0 0.8665 1 0 0 0 0 0 -0.4 0.8 -0.4 0 0 0 0.4 -0.8 0.4 0 0 0 0 0 -0.2 0 -0.785 0 0 0 0 0 0.2 0 0.785 0 0 0 0 0 0 0"/>
  </keyframe>
</mujoco>
